<?xml version="1.0" ?><robot name="left_leg_XM430">  
  <link name="hip_yaw_link">    
    <visual>      
      <origin xyz="0 0 0" rpy="0 -0 0"/>      
      <geometry>        
        <mesh filename="package:///meshes/left_hip_yaw_link_visual.stl"/>        
      </geometry>      
      <material name="hip_yaw_link_material">        
        <color rgba="0.61568627450980395466 0.81176470588235294379 0.92941176470588238168 1.0"/>        
      </material>      
    </visual>    
    <collision>      
      <origin xyz="0 0 0" rpy="0 -0 0"/>      
      <geometry>        
        <mesh filename="package:///meshes/left_hip_yaw_link_collision.stl"/>        
      </geometry>      
    </collision>    
    <inertial>      
      <origin xyz="6.9994164697772127436e-19 -3.8999545121627272677e-19 -0.0098390489054829138871" rpy="0 0 0"/>      
      <mass value="0.017999999999999995171"/>      
      <inertia ixx="2.6385033891442540855e-06" ixy="0" ixz="0" iyy="7.6596731957046890345e-06" iyz="0" izz="7.7220708070894769837e-06"/>      
    </inertial>    
  </link>  

  <link name="hip_roll_link">    
    <visual>      
      <origin xyz="0 0 0" rpy="0 -0 0"/>      
      <geometry>        
        <mesh filename="package:///meshes/left_hip_roll_link_visual.stl"/>        
      </geometry>      
      <material name="hip_roll_link_material">        
        <color rgba="0.51698661238356047321 0.50347815951093488618 0.49050589017722012741 1.0"/>        
      </material>      
    </visual>    
    <collision>      
      <origin xyz="0 0 0" rpy="0 -0 0"/>      
      <geometry>        
        <mesh filename="package:///meshes/left_hip_roll_link_collision.stl"/>        
      </geometry>      
    </collision>    
    <inertial>      
      <origin xyz="-0.011999849582185678071 -0.00049598090794010681048 -0.018504111838598649026" rpy="0 0 0"/>      
      <mass value="0.11059999999836234164"/>      
      <inertia ixx="2.2818802599018682756e-05" ixy="-4.6520143286691176809e-08" ixz="-4.6888548260742845694e-08" iyy="3.087163208233903455e-05" iyz="-5.7477343899716666035e-07" izz="3.0871666424469295785e-05"/>      
    </inertial>    
  </link>  

  <link name="left_hip_pitch_link_xm430">    
    <visual>      
      <origin xyz="0 0 0" rpy="0 -0 0"/>      
      <geometry>        
        <mesh filename="package:///meshes/left_hip_pitch_link_xm430_visual.stl"/>        
      </geometry>      
      <material name="left_hip_pitch_link_xm430_material">        
        <color rgba="0.87072221357329560032 0.72641010956094287376 0.24785169615220703498 1.0"/>        
      </material>      
    </visual>    
    <collision>      
      <origin xyz="0 0 0" rpy="0 -0 0"/>      
      <geometry>        
        <mesh filename="package:///meshes/left_hip_pitch_link_xm430_collision.stl"/>        
      </geometry>      
    </collision>    
    <inertial>      
      <origin xyz="-0.00075729214155295329104 -0.050714785675264786868 -0.012656155119960033756" rpy="0 0 0"/>      
      <mass value="0.1148009013503056841"/>      
      <inertia ixx="6.6072773889429780268e-05" ixy="-4.6080149277698338478e-07" ixz="-1.8170739115316130752e-07" iyy="2.3633638685370093061e-05" iyz="1.412525392534511906e-06" izz="6.2221728804334047735e-05"/>      
    </inertial>    
  </link>  

  <link name="left_calf_link">    
    <visual>      
      <origin xyz="0 0 0" rpy="0 -0 0"/>      
      <geometry>        
        <mesh filename="package:///meshes/left_calf_link_visual.stl"/>        
      </geometry>      
      <material name="left_calf_link_material">        
        <color rgba="0.616547745550632742 0.7175754134247219751 0.74372657889541438081 1.0"/>        
      </material>      
    </visual>    
    <collision>      
      <origin xyz="0 0 0" rpy="0 -0 0"/>      
      <geometry>        
        <mesh filename="package:///meshes/left_calf_link_collision.stl"/>        
      </geometry>      
    </collision>    
    <inertial>      
      <origin xyz="0.001633055673954363898 -0.050045528174708892033 -0.0099079425125457917106" rpy="0 0 0"/>      
      <mass value="0.086799999986183581924"/>      
      <inertia ixx="4.9509459873200504219e-05" ixy="3.6911110041724544372e-06" ixz="4.1819058040000167512e-07" iyy="1.553122903796312626e-05" iyz="4.6309763568465605115e-07" izz="5.3138661991211913937e-05"/>      
    </inertial>    
  </link>  

  <link name="bearing_683">    
    <visual>      
      <origin xyz="0 0 0" rpy="0 -0 0"/>      
      <geometry>        
        <mesh filename="package:///meshes/left_bearing_683_visual.stl"/>        
      </geometry>      
      <material name="bearing_683_material">        
        <color rgba="0.64705882352941179736 0.64705882352941179736 0.64705882352941179736 1.0"/>        
      </material>      
    </visual>    
    <collision>      
      <origin xyz="0 0 0" rpy="0 -0 0"/>      
      <geometry>        
        <mesh filename="package:///meshes/left_bearing_683_collision.stl"/>        
      </geometry>      
    </collision>    
    <inertial>      
      <origin xyz="1.0732094295235117161e-19 6.2549399515679974435e-19 -0.0015500000000000003792" rpy="0 0 0"/>      
      <mass value="0.00048694686130641793437"/>      
      <inertia ixx="2.1551456503319879113e-09" ixy="2.3860364254964754589e-27" ixz="1.1214000884108555107e-37" iyy="2.1551456503319883249e-09" iyz="-2.5890704815542465569e-38" izz="3.5303647444715305817e-09"/>      
    </inertial>    
  </link>  

  <joint name="left_knee_front_rev_2" type="revolute">    
    <origin xyz="-0.0057402514854763735455 0.013858192987669520901 -0.026199999999998880434" rpy="-2.0198851465398702307e-14 -3.8607515872534395329e-14 1.5737070550412859404"/>    
    <parent link="left_calf_link"/>    
    <child link="bearing_683"/>    
    <axis xyz="0 0 1"/>    
    <limit effort="1" velocity="20" lower="-6.283185307179586232" upper="6.283185307179586232"/>    
    <joint_properties friction="0.0"/>    
  </joint>  

  <link name="bearing_683_2">    
    <visual>      
      <origin xyz="0 0 0" rpy="0 -0 0"/>      
      <geometry>        
        <mesh filename="package:///meshes/left_bearing_683_2_visual.stl"/>        
      </geometry>      
      <material name="bearing_683_2_material">        
        <color rgba="0.64705882352941179736 0.64705882352941179736 0.64705882352941179736 1.0"/>        
      </material>      
    </visual>    
    <collision>      
      <origin xyz="0 0 0" rpy="0 -0 0"/>      
      <geometry>        
        <mesh filename="package:///meshes/left_bearing_683_2_collision.stl"/>        
      </geometry>      
    </collision>    
    <inertial>      
      <origin xyz="1.0732094295233481325e-19 -1.1092294808199973352e-18 -0.0015500000000000003792" rpy="0 0 0"/>      
      <mass value="0.00048694686130641793437"/>      
      <inertia ixx="2.1551456503319887385e-09" ixy="1.3912489984452133502e-28" ixz="7.9233709950009322277e-38" iyy="2.1551456503319874977e-09" iyz="-4.6239177088477271353e-38" izz="3.5303647444715305817e-09"/>      
    </inertial>    
  </link>  

  <joint name="left_knee_back_rev_2" type="revolute">    
    <origin xyz="0.0057402514854763839539 -0.01385819298766921559 -0.026199999999999640243" rpy="-3.4995571909695562261e-16 -2.90815686857019016e-14 1.5739207094624192429"/>    
    <parent link="left_calf_link"/>    
    <child link="bearing_683_2"/>    
    <axis xyz="0 0 1"/>    
    <limit effort="1" velocity="20" lower="-6.283185307179586232" upper="6.283185307179586232"/>    
    <joint_properties friction="0.0"/>    
  </joint>  

  <link name="ank_pitch_link">    
    <visual>      
      <origin xyz="0 0 0" rpy="0 -0 0"/>      
      <geometry>        
        <mesh filename="package:///meshes/left_ank_pitch_link_visual.stl"/>        
      </geometry>      
      <material name="ank_pitch_link_material">        
        <color rgba="0.63189161126160264814 0.7266866879354088038 0.78356373393969258601 1.0"/>        
      </material>      
    </visual>    
    <collision>      
      <origin xyz="0 0 0" rpy="0 -0 0"/>      
      <geometry>        
        <mesh filename="package:///meshes/left_ank_pitch_link_collision.stl"/>        
      </geometry>      
    </collision>    
    <inertial>      
      <origin xyz="0.0005952828256592173576 -4.0269683181568689667e-08 7.7616092716332508893e-08" rpy="0 0 0"/>      
      <mass value="0.0042238381753791614387"/>      
      <inertia ixx="3.9782741364678456013e-07" ixy="-1.6834347828603229053e-13" ixz="2.0919188855107369529e-14" iyy="4.3705254067423072352e-07" iyz="-1.6428822181660838267e-12" izz="8.8858574534612975842e-08"/>      
    </inertial>    
  </link>  

  <link name="ank_roll_link">    
    <visual>      
      <origin xyz="0 0 0" rpy="0 -0 0"/>      
      <geometry>        
        <mesh filename="package:///meshes/left_ank_roll_link_visual.stl"/>        
      </geometry>      
      <material name="ank_roll_link_material">        
        <color rgba="0.61568627450980395466 0.81176470588235294379 0.92941176470588227065 1.0"/>        
      </material>      
    </visual>    
    <collision>      
      <origin xyz="0 0 0" rpy="0 -0 0"/>      
      <geometry>        
        <mesh filename="package:///meshes/left_ank_roll_link_collision.stl"/>        
      </geometry>      
    </collision>    
    <inertial>      
      <origin xyz="-3.3748977754987916802e-09 0.016071733707723686452 -0.0096236810250137777567" rpy="0 0 0"/>      
      <mass value="0.010900000000000003436"/>      
      <inertia ixx="2.6058536057764963368e-06" ixy="-5.4054321087398513321e-13" ixz="6.069254909621619699e-13" iyy="2.5928781338360468952e-06" iyz="3.9359839679282456802e-07" izz="1.6179884211196010928e-06"/>      
    </inertial>    
  </link>  

  <link name="ank_rr_link">    
    <visual>      
      <origin xyz="0 0 0" rpy="0 -0 0"/>      
      <geometry>        
        <mesh filename="package:///meshes/left_ank_rr_link_visual.stl"/>        
      </geometry>      
      <material name="ank_rr_link_material">        
        <color rgba="0.61568627450980395466 0.81176470588235294379 0.92941176470588238168 1.0"/>        
      </material>      
    </visual>    
    <collision>      
      <origin xyz="0 0 0" rpy="0 -0 0"/>      
      <geometry>        
        <mesh filename="package:///meshes/left_ank_rr_link_collision.stl"/>        
      </geometry>      
    </collision>    
    <inertial>      
      <origin xyz="-4.5249610960602584678e-05 0.0063096429836314582573 -2.0541493629085886652e-19" rpy="0 0 0"/>      
      <mass value="0.0014499999999999996832"/>      
      <inertia ixx="2.9739579267716143416e-08" ixy="2.4213146797977948196e-10" ixz="3.5523394884456569378e-14" iyy="2.7430027724071957055e-08" iyz="6.0453569845698011573e-32" izz="4.2921949116163665819e-08"/>      
    </inertial>    
  </link>  

  <link name="ank_motor_rod_long">    
    <visual>      
      <origin xyz="0 0 0" rpy="0 -0 0"/>      
      <geometry>        
        <mesh filename="package:///meshes/left_ank_motor_rod_long_visual.stl"/>        
      </geometry>      
      <material name="ank_motor_rod_long_material">        
        <color rgba="0.63549975559783222767 0.7077439301702044272 0.75109043491362770251 1.0"/>        
      </material>      
    </visual>    
    <collision>      
      <origin xyz="0 0 0" rpy="0 -0 0"/>      
      <geometry>        
        <mesh filename="package:///meshes/left_ank_motor_rod_long_collision.stl"/>        
      </geometry>      
    </collision>    
    <inertial>      
      <origin xyz="2.4855088813549552477e-10 0.034559019974062146763 0.00093851704878456236776" rpy="0 0 0"/>      
      <mass value="0.0021712857268636710437"/>      
      <inertia ixx="8.5350290057999892598e-07" ixy="1.488424486145758595e-14" ixz="4.5749525025198726908e-11" iyy="1.3237321792739390432e-08" iyz="-4.3668910960866295549e-09" izz="8.5812217519451080535e-07"/>      
    </inertial>    
  </link>  

  <joint name="left_ank_long_rev_2" type="revolute">    
    <origin xyz="-2.1579960041151480254e-15 0.0099999999999990651922 -8.08381139805192106e-16" rpy="-1.5707963267948954478 1.3320366994106502823 -1.5707963267948126251"/>    
    <parent link="ank_rr_link"/>    
    <child link="ank_motor_rod_long"/>    
    <axis xyz="0 0 1"/>    
    <limit effort="1" velocity="20" lower="-1.570796326794896558" upper="1.570796326794896558"/>    
    <joint_properties friction="0.0"/>    
  </joint>  

  <joint name="left_ank_long_rev_1" type="revolute">    
    <origin xyz="-0.018000000000002184392 0.015999999999998931743 -0.020599999999999191874" rpy="5.6928860135513275759e-16 -8.1605439123400921334e-16 3.1233695685467459668"/>    
    <parent link="ank_roll_link"/>    
    <child link="ank_rr_link"/>    
    <axis xyz="0 0 1"/>    
    <limit effort="1" velocity="20" lower="-1.570796326794896558" upper="1.570796326794896558"/>    
    <joint_properties friction="0.0"/>    
  </joint>  

  <link name="ank_rr_link_2">    
    <visual>      
      <origin xyz="0 0 0" rpy="0 -0 0"/>      
      <geometry>        
        <mesh filename="package:///meshes/left_ank_rr_link_2_visual.stl"/>        
      </geometry>      
      <material name="ank_rr_link_2_material">        
        <color rgba="0.61568627450980395466 0.81176470588235294379 0.92941176470588238168 1.0"/>        
      </material>      
    </visual>    
    <collision>      
      <origin xyz="0 0 0" rpy="0 -0 0"/>      
      <geometry>        
        <mesh filename="package:///meshes/left_ank_rr_link_2_collision.stl"/>        
      </geometry>      
    </collision>    
    <inertial>      
      <origin xyz="-4.5249610960599115231e-05 -0.0063096429836315120337 2.0541493629107726698e-19" rpy="0 0 0"/>      
      <mass value="0.0014499999999999996832"/>      
      <inertia ixx="2.9739579267716143416e-08" ixy="-2.4213146797977943026e-10" ixz="-3.5523394884456569378e-14" iyy="2.7430027724071950438e-08" iyz="1.9531260171098395433e-32" izz="4.2921949116163665819e-08"/>      
    </inertial>    
  </link>  

  <link name="ank_motor_rod_short">    
    <visual>      
      <origin xyz="0 0 0" rpy="0 -0 0"/>      
      <geometry>        
        <mesh filename="package:///meshes/left_ank_motor_rod_short_visual.stl"/>        
      </geometry>      
      <material name="ank_motor_rod_short_material">        
        <color rgba="0.41222606689734719865 0.58339100346020766885 0.8110726643598615837 1.0"/>        
      </material>      
    </visual>    
    <collision>      
      <origin xyz="0 0 0" rpy="0 -0 0"/>      
      <geometry>        
        <mesh filename="package:///meshes/left_ank_motor_rod_short_collision.stl"/>        
      </geometry>      
    </collision>    
    <inertial>      
      <origin xyz="2.6038941132517273255e-10 0.023830465465870746822 0.00090403506359631655414" rpy="0 0 0"/>      
      <mass value="0.001700000000000000339"/>      
      <inertia ixx="3.31534162526694895e-07" ixy="8.7419769213848246822e-15" ixz="4.5749941567520897592e-11" iyy="1.0947363610305454928e-08" iyz="-3.5863098646425486986e-09" izz="3.362134044786455377e-07"/>      
    </inertial>    
  </link>  

  <joint name="left_ank_short_rev_2" type="revolute">    
    <origin xyz="-3.4694469519536141888e-18 -0.010000000000000064393 -6.9388939039072283776e-18" rpy="-1.570796326794896558 -1.2119133862910156374 -1.570796326794871467"/>    
    <parent link="ank_rr_link_2"/>    
    <child link="ank_motor_rod_short"/>    
    <axis xyz="0 0 1"/>    
    <limit effort="1" velocity="20" lower="-1.570796326794896558" upper="1.570796326794896558"/>    
    <joint_properties friction="0.0"/>    
  </joint>  

  <joint name="left_ank_short_rev_1" type="revolute">    
    <origin xyz="0.017999999999999995171 0.015999999999999986455 -0.020600000000000000255" rpy="-3.244504776895705127e-16 1.1087098867936222379e-15 0.026118548507359652666"/>    
    <parent link="ank_roll_link"/>    
    <child link="ank_rr_link_2"/>    
    <axis xyz="0 0 1"/>    
    <limit effort="1" velocity="20" lower="-1.570796326794896558" upper="1.570796326794896558"/>    
    <joint_properties friction="0.0"/>    
  </joint>  

  <link name="left_sole_link">    
    <visual>      
      <origin xyz="0 0 0" rpy="0 -0 0"/>      
      <geometry>        
        <mesh filename="package:///meshes/left_sole_link_visual.stl"/>        
      </geometry>      
      <material name="left_sole_link_material">        
        <color rgba="0.61568627450980395466 0.81176470588235283277 0.92941176470588238168 1.0"/>        
      </material>      
    </visual>    
    <collision>      
      <origin xyz="0 0 0" rpy="0 -0 0"/>      
      <geometry>        
        <mesh filename="package:///meshes/left_sole_link_collision.stl"/>        
      </geometry>      
    </collision>    
    <inertial>      
      <origin xyz="-0.028268455053070309924 -2.3408773987406203758e-07 -0.010206307024274944434" rpy="0 0 0"/>      
      <mass value="0.013899999999999999162"/>      
      <inertia ixx="1.3160509347109561336e-06" ixy="3.0094161237480981899e-12" ixz="-2.3741900688425293673e-07" iyy="1.3575574544571530477e-05" iyz="-6.7706521654991170568e-12" izz="1.4673603612256135535e-05"/>      
    </inertial>    
  </link>  

  <joint name="left_sole" type="fixed">    
    <origin xyz="-9.1072982488782372457e-18 0.024999999999999994449 -0.022600000000000002032" rpy="1.570796326794896558 1.570796326794896336 0"/>    
    <parent link="ank_roll_link"/>    
    <child link="left_sole_link"/>    
    <axis xyz="0 0 1"/>    
    <limit effort="1" velocity="20"/>    
    <joint_properties friction="0.0"/>    
  </joint>  

  <joint name="left_ank_roll" type="revolute">    
    <origin xyz="0.0014999999999999241371 -2.7755575615628913511e-17 1.5796825653113799603e-16" rpy="2.1953071957139364813e-17 1.5707963267948659158 0"/>    
    <parent link="ank_pitch_link"/>    
    <child link="ank_roll_link"/>    
    <axis xyz="0 0 1"/>    
    <limit effort="1" velocity="20" lower="-0.785398163397448279" upper="0.785398163397448279"/>    
    <joint_properties friction="0.0"/>    
  </joint>  

  <joint name="left_ank_pitch" type="revolute">    
    <origin xyz="-5.8754783795495723237e-17 -0.10000000000000036637 -0.01040000000000218007" rpy="-6.6613494777492792143e-16 5.5008909826911396159e-25 3.141592653589793116"/>    
    <parent link="left_calf_link"/>    
    <child link="ank_pitch_link"/>    
    <axis xyz="0 0 1"/>    
    <limit effort="1" velocity="20" lower="-0.785398163397448279" upper="0.95993108859688125456"/>    
    <joint_properties friction="0.0"/>    
  </joint>  

  <link name="ank_motor_arm">    
    <visual>      
      <origin xyz="0 0 0" rpy="0 -0 0"/>      
      <geometry>        
        <mesh filename="package:///meshes/left_ank_motor_arm_visual.stl"/>        
      </geometry>      
      <material name="ank_motor_arm_material">        
        <color rgba="0.62517751827980905244 0.70593642422614044651 0.75978993426662766453 1.0"/>        
      </material>      
    </visual>    
    <collision>      
      <origin xyz="0 0 0" rpy="0 -0 0"/>      
      <geometry>        
        <mesh filename="package:///meshes/left_ank_motor_arm_collision.stl"/>        
      </geometry>      
    </collision>    
    <inertial>      
      <origin xyz="0.014511489101591688866 -1.3661063433491998512e-18 0.0040925443765950720101" rpy="0 0 0"/>      
      <mass value="0.0020595846677894939954"/>      
      <inertia ixx="2.759183675652207751e-08" ixy="1.3728927743830823072e-23" ixz="-3.027078820659488159e-08" iyy="1.6138599216238440584e-07" iyz="-1.5005615352829754492e-23" izz="1.643783676501628224e-07"/>      
    </inertial>    
  </link>  

  <joint name="left_ank_act_1" type="revolute">    
    <origin xyz="0.013499999999998150632 -0.044499999999994099831 0.004000000000003878925" rpy="-4.199339249962906148e-13 -1.7566169631614281426e-13 -0.21173394130241762756"/>    
    <parent link="left_calf_link"/>    
    <child link="ank_motor_arm"/>    
    <axis xyz="0 0 1"/>    
    <limit effort="1" velocity="20" lower="-1.3089969389957472057" upper="1.3089969389957472057"/>    
    <joint_properties friction="0.0"/>    
  </joint>  

  <link name="ank_motor_arm_2">    
    <visual>      
      <origin xyz="0 0 0" rpy="0 -0 0"/>      
      <geometry>        
        <mesh filename="package:///meshes/left_ank_motor_arm_2_visual.stl"/>        
      </geometry>      
      <material name="ank_motor_arm_2_material">        
        <color rgba="0.62517751827980905244 0.70593642422614044651 0.75978993426662766453 1.0"/>        
      </material>      
    </visual>    
    <collision>      
      <origin xyz="0 0 0" rpy="0 -0 0"/>      
      <geometry>        
        <mesh filename="package:///meshes/left_ank_motor_arm_2_collision.stl"/>        
      </geometry>      
    </collision>    
    <inertial>      
      <origin xyz="0.014511489101591685397 1.2132948235844081638e-17 0.0040925443765950659386" rpy="0 0 0"/>      
      <mass value="0.0020595846677894939954"/>      
      <inertia ixx="2.759183675652200141e-08" ixy="1.4447443099816966568e-22" ixz="-3.0270788206594848502e-08" iyy="1.6138599216238443231e-07" iyz="5.8537400859049381353e-23" izz="1.6437836765016287534e-07"/>      
    </inertial>    
  </link>  

  <joint name="left_ank_act_2" type="revolute">    
    <origin xyz="0.013500000000004789419 -0.064499999999987761568 -0.024800000000002139777" rpy="-3.1415926535893099469 1.5472440156112037689e-14 -0.22995607267390710815"/>    
    <parent link="left_calf_link"/>    
    <child link="ank_motor_arm_2"/>    
    <axis xyz="0 0 1"/>    
    <limit effort="1" velocity="20" lower="-1.3089969389957472057" upper="1.3089969389957472057"/>    
    <joint_properties friction="0.0"/>    
  </joint>  

  <joint name="left_knee_pitch" type="revolute">    
    <origin xyz="1.9837028473669800546e-17 -0.096000000000000015876 -0.0091999999999999738237" rpy="-2.9366522548798717986e-14 3.5724636926721053889e-16 4.1927868643308625526e-16"/>    
    <parent link="left_hip_pitch_link_xm430"/>    
    <child link="left_calf_link"/>    
    <axis xyz="0 0 1"/>    
    <limit effort="1" velocity="20" lower="0" upper="1.9198621771937625091"/>    
    <joint_properties friction="0.0"/>    
  </joint>  

  <link name="xm430_plate">    
    <visual>      
      <origin xyz="0 0 0" rpy="0 -0 0"/>      
      <geometry>        
        <mesh filename="package:///meshes/left_xm430_plate_visual.stl"/>        
      </geometry>      
      <material name="xm430_plate_material">        
        <color rgba="0.61568627450980395466 0.81176470588235294379 0.9294117647058824927 1.0"/>        
      </material>      
    </visual>    
    <collision>      
      <origin xyz="0 0 0" rpy="0 -0 0"/>      
      <geometry>        
        <mesh filename="package:///meshes/left_xm430_plate_collision.stl"/>        
      </geometry>      
    </collision>    
    <inertial>      
      <origin xyz="-1.0744839342516173804e-17 2.3911851510422750402e-18 -0.0024039046431217955119" rpy="0 0 0"/>      
      <mass value="0.0026999999999999992756"/>      
      <inertia ixx="1.2933116645363416124e-07" ixy="-6.8936588702566453648e-08" ixz="-1.8408351292855479299e-35" iyy="2.672043438587668303e-07" iyz="1.2415852302568489052e-35" izz="3.8533537562751439267e-07"/>      
    </inertial>    
  </link>  

  <link name="knee_rod">    
    <visual>      
      <origin xyz="0 0 0" rpy="0 -0 0"/>      
      <geometry>        
        <mesh filename="package:///meshes/left_knee_rod_visual.stl"/>        
      </geometry>      
      <material name="knee_rod_material">        
        <color rgba="0.62051618944235198416 0.78640765248647581664 0.88594253031295022716 1.0"/>        
      </material>      
    </visual>    
    <collision>      
      <origin xyz="0 0 0" rpy="0 -0 0"/>      
      <geometry>        
        <mesh filename="package:///meshes/left_knee_rod_collision.stl"/>        
      </geometry>      
    </collision>    
    <inertial>      
      <origin xyz="0.014594547204704258134 4.1946460598583926106e-05 -0.0015996227373173928839" rpy="0 0 0"/>      
      <mass value="0.0031629468613064179276"/>      
      <inertia ixx="2.5896135582861323238e-08" ixy="-3.523492118218595344e-10" ixz="4.1682974279785014807e-10" iyy="6.0153250889878618971e-07" iyz="1.1980181501036628568e-12" izz="6.2266858020374725112e-07"/>      
    </inertial>    
  </link>  

  <joint name="left_knee_front_rev_1" type="revolute">    
    <origin xyz="0.013858192987669312735 0.0057402514854763440552 -0.0050000000000000009714" rpy="-8.8273423888544989682e-15 5.9762404835944504039e-15 -3.1386819253434037336"/>    
    <parent link="xm430_plate"/>    
    <child link="knee_rod"/>    
    <axis xyz="0 0 1"/>    
    <limit effort="1" velocity="20" lower="-6.283185307179586232" upper="6.283185307179586232"/>    
    <joint_properties friction="0.0"/>    
  </joint>  

  <link name="knee_rod_2">    
    <visual>      
      <origin xyz="0 0 0" rpy="0 -0 0"/>      
      <geometry>        
        <mesh filename="package:///meshes/left_knee_rod_2_visual.stl"/>        
      </geometry>      
      <material name="knee_rod_2_material">        
        <color rgba="0.62051618944235198416 0.78640765248647581664 0.88594253031295022716 1.0"/>        
      </material>      
    </visual>    
    <collision>      
      <origin xyz="0 0 0" rpy="0 -0 0"/>      
      <geometry>        
        <mesh filename="package:///meshes/left_knee_rod_2_collision.stl"/>        
      </geometry>      
    </collision>    
    <inertial>      
      <origin xyz="0.014594555500542014462 3.5710133123464131357e-05 -0.0015996227373176105917" rpy="0 0 0"/>      
      <mass value="0.0031629468613064179276"/>      
      <inertia ixx="2.5895856845870582634e-08" ixy="-2.9996438872428646949e-10" ixz="4.1682997973827996187e-10" iyy="6.0153264826847845892e-07" iyz="1.0199045846546678738e-12" izz="6.226684408364528263e-07"/>      
    </inertial>    
  </link>  

  <joint name="left_knee_back_rev_1" type="revolute">    
    <origin xyz="-0.013858192987669298857 -0.0057402514854763440552 -0.0050000000000000009714" rpy="-2.9668697207277861891e-16 -3.5495245422933824495e-15 -3.1384682709222704311"/>    
    <parent link="xm430_plate"/>    
    <child link="knee_rod_2"/>    
    <axis xyz="0 0 1"/>    
    <limit effort="1" velocity="20" lower="-6.283185307179586232" upper="6.283185307179586232"/>    
    <joint_properties friction="0.0"/>    
  </joint>  

  <joint name="left_knee_act" type="revolute">    
    <origin xyz="-0.00015000000000003010057 -0.061500000000000082379 -0.030400000000000440559" rpy="-3.9687967765302122778e-16 -3.2670861344266613268e-15 1.570796326794896558"/>    
    <parent link="left_hip_pitch_link_xm430"/>    
    <child link="xm430_plate"/>    
    <axis xyz="0 0 1"/>    
    <limit effort="1" velocity="20" lower="0" upper="1.9198621771937625091"/>    
    <joint_properties friction="0.0"/>    
  </joint>  

  <joint name="left_hip_pitch" type="revolute">    
    <origin xyz="-0.024000000716151263791 -0.019000000152441045426 -0.019000000152457018759" rpy="1.5707963267952340658 1.5707963267945517227 0"/>    
    <parent link="hip_roll_link"/>    
    <child link="left_hip_pitch_link_xm430"/>    
    <axis xyz="0 0 1"/>    
    <limit effort="1" velocity="20" lower="-1.570796326794896558" upper="1.570796326794896558"/>    
    <joint_properties friction="0.0"/>    
  </joint>  

  <joint name="left_hip_roll" type="revolute">    
    <origin xyz="0.018999999999999194616 -8.636160306239192055e-16 -0.026000000000000224321" rpy="-3.141592653589793116 -1.5707963267948843455 0"/>    
    <parent link="hip_yaw_link"/>    
    <child link="hip_roll_link"/>    
    <axis xyz="0 0 1"/>    
    <limit effort="1" velocity="20" lower="-0.785398163397448279" upper="1.570796326794896558"/>    
    <joint_properties friction="0.0"/>    
  </joint>  


</robot>