<?xml version="1.0" ?><robot name="left_leg_XM430">  
  <link name="hip_yaw_link">    
    <visual>      
      <origin xyz="0 0 0" rpy="0 -0 0"/>      
      <geometry>        
        <mesh filename="package:///meshes/left_hip_yaw_link_visual.stl"/>        
      </geometry>      
      <material name="hip_yaw_link_material">        
        <color rgba="0.61568627450980395466 0.81176470588235294379 0.92941176470588238168 1.0"/>        
      </material>      
    </visual>    
    <collision>      
      <origin xyz="0 0 0" rpy="0 -0 0"/>      
      <geometry>        
        <mesh filename="package:///meshes/left_hip_yaw_link_collision.stl"/>        
      </geometry>      
    </collision>    
    <inertial>      
      <origin xyz="9.9406606246304012944e-19 -3.4936051057946191231e-19 -0.0098390489054829104176" rpy="0 0 0"/>      
      <mass value="0.018000000000000009048"/>      
      <inertia ixx="2.6385033891442549325e-06" ixy="0" ixz="0" iyy="7.6596731957046924227e-06" iyz="0" izz="7.7220708070894786778e-06"/>      
    </inertial>    
  </link>  

  <link name="hip_roll_link">    
    <visual>      
      <origin xyz="0 0 0" rpy="0 -0 0"/>      
      <geometry>        
        <mesh filename="package:///meshes/left_hip_roll_link_visual.stl"/>        
      </geometry>      
      <material name="hip_roll_link_material">        
        <color rgba="0.51698661238356047321 0.50347815951093488618 0.49050589017722012741 1.0"/>        
      </material>      
    </visual>    
    <collision>      
      <origin xyz="0 0 0" rpy="0 -0 0"/>      
      <geometry>        
        <mesh filename="package:///meshes/left_hip_roll_link_collision.stl"/>        
      </geometry>      
    </collision>    
    <inertial>      
      <origin xyz="-0.011999849582186344205 -0.00049598090793799955514 -0.018504111838598794743" rpy="0 0 0"/>      
      <mass value="0.11059999999836234164"/>      
      <inertia ixx="2.2818802599019123213e-05" ixy="-4.6520143286798432356e-08" ixz="-4.6888548260596792068e-08" iyy="3.0871632082339373363e-05" iyz="-5.7477343899716644859e-07" izz="3.0871666424470007293e-05"/>      
    </inertial>    
  </link>  

  <link name="left_hip_pitch_link_xm430">    
    <visual>      
      <origin xyz="0 0 0" rpy="0 -0 0"/>      
      <geometry>        
        <mesh filename="package:///meshes/left_hip_pitch_link_xm430_visual.stl"/>        
      </geometry>      
      <material name="left_hip_pitch_link_xm430_material">        
        <color rgba="0.87072221357329560032 0.72641010956094287376 0.24785169615220706274 1.0"/>        
      </material>      
    </visual>    
    <collision>      
      <origin xyz="0 0 0" rpy="0 -0 0"/>      
      <geometry>        
        <mesh filename="package:///meshes/left_hip_pitch_link_xm430_collision.stl"/>        
      </geometry>      
    </collision>    
    <inertial>      
      <origin xyz="-0.00075729214155315061584 -0.050714785675264828502 -0.012656155119959908856" rpy="0 0 0"/>      
      <mass value="0.1148009013503056841"/>      
      <inertia ixx="6.6072773889430024214e-05" ixy="-4.6080149277727741109e-07" ixz="-1.8170739115308308933e-07" iyy="2.3633638685369527243e-05" iyz="1.4125253925343132768e-06" izz="6.2221728804333383662e-05"/>      
    </inertial>    
  </link>  

  <link name="left_calf_link">    
    <visual>      
      <origin xyz="0 0 0" rpy="0 -0 0"/>      
      <geometry>        
        <mesh filename="package:///meshes/left_calf_link_visual.stl"/>        
      </geometry>      
      <material name="left_calf_link_material">        
        <color rgba="0.616547745550632742 0.7175754134247219751 0.74372657889541438081 1.0"/>        
      </material>      
    </visual>    
    <collision>      
      <origin xyz="0 0 0" rpy="0 -0 0"/>      
      <geometry>        
        <mesh filename="package:///meshes/left_calf_link_collision.stl"/>        
      </geometry>      
    </collision>    
    <inertial>      
      <origin xyz="0.0016330556739555517499 -0.050045528174708642233 -0.0099079425125447595502" rpy="0 0 0"/>      
      <mass value="0.086799999986183581924"/>      
      <inertia ixx="4.9509459873200334812e-05" ixy="3.6911110041724857774e-06" ixz="4.1819058039984036829e-07" iyy="1.5531229037964085102e-05" iyz="4.630976356842253349e-07" izz="5.3138661991212971035e-05"/>      
    </inertial>    
  </link>  

  <link name="bearing_683">    
    <visual>      
      <origin xyz="0 0 0" rpy="0 -0 0"/>      
      <geometry>        
        <mesh filename="package:///meshes/left_bearing_683_visual.stl"/>        
      </geometry>      
      <material name="bearing_683_material">        
        <color rgba="0.64705882352941179736 0.64705882352941179736 0.64705882352941179736 1.0"/>        
      </material>      
    </visual>    
    <collision>      
      <origin xyz="0 0 0" rpy="0 -0 0"/>      
      <geometry>        
        <mesh filename="package:///meshes/left_bearing_683_collision.stl"/>        
      </geometry>      
    </collision>    
    <inertial>      
      <origin xyz="1.0732094295242497084e-19 -2.4186774283160283989e-19 -0.0015500000000000003792" rpy="0 0 0"/>      
      <mass value="0.00048694686130641793437"/>      
      <inertia ixx="2.1551456503319879113e-09" ixy="2.3666528901256796113e-27" ixz="2.0889236366122119332e-38" iyy="2.1551456503319891521e-09" iyz="1.3744560845328921415e-38" izz="3.5303647444715305817e-09"/>      
    </inertial>    
  </link>  

  <joint name="left_knee_front_rev_2" type="revolute">    
    <origin xyz="-0.0057402514854770240668 0.013858192987668910279 -0.026200000000000563116" rpy="2.0453876360821841634e-16 7.1068359470475064937e-16 1.5765314753541341819"/>    
    <parent link="left_calf_link"/>    
    <child link="bearing_683"/>    
    <axis xyz="0 0 1"/>    
    <limit effort="1" velocity="20" lower="-6.283185307179586232" upper="6.283185307179586232"/>    
    <joint_properties friction="0.0"/>    
  </joint>  

  <link name="bearing_683_2">    
    <visual>      
      <origin xyz="0 0 0" rpy="0 -0 0"/>      
      <geometry>        
        <mesh filename="package:///meshes/left_bearing_683_2_visual.stl"/>        
      </geometry>      
      <material name="bearing_683_2_material">        
        <color rgba="0.64705882352941179736 0.64705882352941179736 0.64705882352941179736 1.0"/>        
      </material>      
    </visual>    
    <collision>      
      <origin xyz="0 0 0" rpy="0 -0 0"/>      
      <geometry>        
        <mesh filename="package:///meshes/left_bearing_683_2_collision.stl"/>        
      </geometry>      
    </collision>    
    <inertial>      
      <origin xyz="1.0732094295248846635e-19 -2.4186774283160375471e-19 -0.0015500000000000003792" rpy="0 0 0"/>      
      <mass value="0.00048694686130641793437"/>      
      <inertia ixx="2.1551456503319887385e-09" ixy="-1.3855900387721121507e-27" ixz="-1.9257410757015346214e-37" iyy="2.1551456503319874977e-09" iyz="-2.8124792185573659681e-39" izz="3.5303647444715305817e-09"/>      
    </inertial>    
  </link>  

  <joint name="left_knee_back_rev_2" type="revolute">    
    <origin xyz="0.0057402514854760517543 -0.013858192987669437635 -0.026200000000000216172" rpy="2.8877467674261435159e-16 -6.2660216643685709814e-15 1.5765686202203079702"/>    
    <parent link="left_calf_link"/>    
    <child link="bearing_683_2"/>    
    <axis xyz="0 0 1"/>    
    <limit effort="1" velocity="20" lower="-6.283185307179586232" upper="6.283185307179586232"/>    
    <joint_properties friction="0.0"/>    
  </joint>  

  <link name="ank_pitch_link">    
    <visual>      
      <origin xyz="0 0 0" rpy="0 -0 0"/>      
      <geometry>        
        <mesh filename="package:///meshes/left_ank_pitch_link_visual.stl"/>        
      </geometry>      
      <material name="ank_pitch_link_material">        
        <color rgba="0.63189161126160264814 0.7266866879354088038 0.78356373393969258601 1.0"/>        
      </material>      
    </visual>    
    <collision>      
      <origin xyz="0 0 0" rpy="0 -0 0"/>      
      <geometry>        
        <mesh filename="package:///meshes/left_ank_pitch_link_collision.stl"/>        
      </geometry>      
    </collision>    
    <inertial>      
      <origin xyz="0.00059528282565903347691 -4.0269677046895822506e-08 7.7616091227946370715e-08" rpy="0 0 0"/>      
      <mass value="0.0042238381753791614387"/>      
      <inertia ixx="3.9782741364681224752e-07" ixy="-1.6834347544690341436e-13" ixz="2.09191870411591794e-14" iyy="4.3705254067426624596e-07" iyz="-1.6428821654626687343e-12" izz="8.8858574534620810897e-08"/>      
    </inertial>    
  </link>  

  <link name="ank_roll_link">    
    <visual>      
      <origin xyz="0 0 0" rpy="0 -0 0"/>      
      <geometry>        
        <mesh filename="package:///meshes/left_ank_roll_link_visual.stl"/>        
      </geometry>      
      <material name="ank_roll_link_material">        
        <color rgba="0.61568627450980395466 0.81176470588235294379 0.9294117647058824927 1.0"/>        
      </material>      
    </visual>    
    <collision>      
      <origin xyz="0 0 0" rpy="0 -0 0"/>      
      <geometry>        
        <mesh filename="package:///meshes/left_ank_roll_link_collision.stl"/>        
      </geometry>      
    </collision>    
    <inertial>      
      <origin xyz="-4.1981619184736462352e-07 0.030184725631360178472 0.0011499367980602288528" rpy="0 0 0"/>      
      <mass value="0.019499999999999989564"/>      
      <inertia ixx="1.5150427967004380164e-05" ixy="-1.7320375879592309051e-11" ixz="-1.4084360959147989168e-09" iyy="1.4833697725294763299e-05" iyz="-1.1138856914308222552e-06" izz="3.1530217213419311558e-06"/>      
    </inertial>    
  </link>  

  <link name="ank_rr_link">    
    <visual>      
      <origin xyz="0 0 0" rpy="0 -0 0"/>      
      <geometry>        
        <mesh filename="package:///meshes/left_ank_rr_link_visual.stl"/>        
      </geometry>      
      <material name="ank_rr_link_material">        
        <color rgba="0.61568627450980395466 0.81176470588235294379 0.92941176470588238168 1.0"/>        
      </material>      
    </visual>    
    <collision>      
      <origin xyz="0 0 0" rpy="0 -0 0"/>      
      <geometry>        
        <mesh filename="package:///meshes/left_ank_rr_link_collision.stl"/>        
      </geometry>      
    </collision>    
    <inertial>      
      <origin xyz="-4.5249610960606142216e-05 0.0063096429836314582573 -1.9359077708108095498e-19" rpy="0 0 0"/>      
      <mass value="0.0014499999999999996832"/>      
      <inertia ixx="2.9739579267716140107e-08" ixy="2.4213146797977844798e-10" ixz="3.5523394884422313882e-14" iyy="2.7430027724071957055e-08" iyz="-9.8997471197627255128e-32" izz="4.2921949116163665819e-08"/>      
    </inertial>    
  </link>  

  <link name="ank_motor_rod_long">    
    <visual>      
      <origin xyz="0 0 0" rpy="0 -0 0"/>      
      <geometry>        
        <mesh filename="package:///meshes/left_ank_motor_rod_long_visual.stl"/>        
      </geometry>      
      <material name="ank_motor_rod_long_material">        
        <color rgba="0.63549975559783222767 0.70774393017020453822 0.75109043491362792455 1.0"/>        
      </material>      
    </visual>    
    <collision>      
      <origin xyz="0 0 0" rpy="0 -0 0"/>      
      <geometry>        
        <mesh filename="package:///meshes/left_ank_motor_rod_long_collision.stl"/>        
      </geometry>      
    </collision>    
    <inertial>      
      <origin xyz="2.4855088958918268157e-10 0.034559019974062257785 0.00093851704878453623849" rpy="0 0 0"/>      
      <mass value="0.0021712857268636710437"/>      
      <inertia ixx="8.5350290058000400818e-07" ixy="1.4884244671520068501e-14" ixz="4.5749525025589240168e-11" iyy="1.3237321792739536015e-08" iyz="-4.3668910960857659783e-09" izz="8.5812217519451768749e-07"/>      
    </inertial>    
  </link>  

  <joint name="left_ank_long_rev_2" type="revolute">    
    <origin xyz="2.4286128663675299322e-17 0.0099999999999992872368 1.3947176746853529039e-15" rpy="-1.5707963267948974462 1.3320366994105963254 -1.5707963267949054398"/>    
    <parent link="ank_rr_link"/>    
    <child link="ank_motor_rod_long"/>    
    <axis xyz="0 0 1"/>    
    <limit effort="1" velocity="20" lower="-1.570796326794896558" upper="1.570796326794896558"/>    
    <joint_properties friction="0.0"/>    
  </joint>  

  <joint name="left_ank_long_rev_1" type="revolute">    
    <origin xyz="-0.018000000000000015987 0.01599999999999926481 -0.020600000000001391504" rpy="-2.876394309884160705e-16 1.6317439732762683578e-16 3.1233695685467286474"/>    
    <parent link="ank_roll_link"/>    
    <child link="ank_rr_link"/>    
    <axis xyz="0 0 1"/>    
    <limit effort="1" velocity="20" lower="-1.570796326794896558" upper="1.570796326794896558"/>    
    <joint_properties friction="0.0"/>    
  </joint>  

  <link name="ank_rr_link_2">    
    <visual>      
      <origin xyz="0 0 0" rpy="0 -0 0"/>      
      <geometry>        
        <mesh filename="package:///meshes/left_ank_rr_link_2_visual.stl"/>        
      </geometry>      
      <material name="ank_rr_link_2_material">        
        <color rgba="0.61568627450980395466 0.81176470588235294379 0.92941176470588238168 1.0"/>        
      </material>      
    </visual>    
    <collision>      
      <origin xyz="0 0 0" rpy="0 -0 0"/>      
      <geometry>        
        <mesh filename="package:///meshes/left_ank_rr_link_2_collision.stl"/>        
      </geometry>      
    </collision>    
    <inertial>      
      <origin xyz="-4.524961096059918977e-05 -0.0063096429836314036135 3.6630377290350385853e-18" rpy="0 0 0"/>      
      <mass value="0.0014499999999999996832"/>      
      <inertia ixx="2.9739579267716146725e-08" ixy="-2.4213146797977865478e-10" ixz="-3.5523394884422320193e-14" iyy="2.7430027724071957055e-08" iyz="-6.0455732447522899156e-32" izz="4.2921949116163665819e-08"/>      
    </inertial>    
  </link>  

  <link name="ank_motor_rod_short">    
    <visual>      
      <origin xyz="0 0 0" rpy="0 -0 0"/>      
      <geometry>        
        <mesh filename="package:///meshes/left_ank_motor_rod_short_visual.stl"/>        
      </geometry>      
      <material name="ank_motor_rod_short_material">        
        <color rgba="0.41222606689734719865 0.58339100346020755783 0.8110726643598615837 1.0"/>        
      </material>      
    </visual>    
    <collision>      
      <origin xyz="0 0 0" rpy="0 -0 0"/>      
      <geometry>        
        <mesh filename="package:///meshes/left_ank_motor_rod_short_collision.stl"/>        
      </geometry>      
    </collision>    
    <inertial>      
      <origin xyz="2.6038941310109512801e-10 0.023830465465870951519 0.00090403506359622634852" rpy="0 0 0"/>      
      <mass value="0.0017000000000000005558"/>      
      <inertia ixx="3.3153416252670235948e-07" ixy="8.7419768622788139357e-15" ixz="4.5749941567727692746e-11" iyy="1.0947363610305772565e-08" iyz="-3.5863098646405767e-09" izz="3.3621340447865379628e-07"/>      
    </inertial>    
  </link>  

  <joint name="left_ank_short_rev_2" type="revolute">    
    <origin xyz="0 -0.0099999999999998978595 0" rpy="-1.570796326794896558 -1.2119133862909823307 -1.570796326794896336"/>    
    <parent link="ank_rr_link_2"/>    
    <child link="ank_motor_rod_short"/>    
    <axis xyz="0 0 1"/>    
    <limit effort="1" velocity="20" lower="-1.570796326794896558" upper="1.570796326794896558"/>    
    <joint_properties friction="0.0"/>    
  </joint>  

  <joint name="left_ank_short_rev_1" type="revolute">    
    <origin xyz="0.018000000000000002109 0.015999999999999986455 -0.020600000000000010664" rpy="4.2172831995673088897e-16 -4.4678623027074358005e-17 0.026118548507422217203"/>    
    <parent link="ank_roll_link"/>    
    <child link="ank_rr_link_2"/>    
    <axis xyz="0 0 1"/>    
    <limit effort="1" velocity="20" lower="-1.570796326794896558" upper="1.570796326794896558"/>    
    <joint_properties friction="0.0"/>    
  </joint>  

  <joint name="left_ank_roll" type="revolute">    
    <origin xyz="0.0015000000000000002481 2.7755575615628913511e-17 3.2742905609062233907e-17" rpy="9.9573127520767875392e-16 1.570796326794891673 0"/>    
    <parent link="ank_pitch_link"/>    
    <child link="ank_roll_link"/>    
    <axis xyz="0 0 1"/>    
    <limit effort="1" velocity="20" lower="-0.785398163397448279" upper="0.785398163397448279"/>    
    <joint_properties friction="0.0"/>    
  </joint>  

  <joint name="left_ank_pitch" type="revolute">    
    <origin xyz="1.5349482163618395221e-15 -0.099999999999999339417 -0.01039999999999923451" rpy="1.0427422814103565708e-14 3.7115492970717391096e-15 3.1415926535897922278"/>    
    <parent link="left_calf_link"/>    
    <child link="ank_pitch_link"/>    
    <axis xyz="0 0 1"/>    
    <limit effort="1" velocity="20" lower="-1.0471975511965976313" upper="0.785398163397448279"/>    
    <joint_properties friction="0.0"/>    
  </joint>  

  <link name="ank_motor_arm">    
    <visual>      
      <origin xyz="0 0 0" rpy="0 -0 0"/>      
      <geometry>        
        <mesh filename="package:///meshes/left_ank_motor_arm_visual.stl"/>        
      </geometry>      
      <material name="ank_motor_arm_material">        
        <color rgba="0.62483822591633164656 0.70971956673896574586 0.76585356440212004614 1.0"/>        
      </material>      
    </visual>    
    <collision>      
      <origin xyz="0 0 0" rpy="0 -0 0"/>      
      <geometry>        
        <mesh filename="package:///meshes/left_ank_motor_arm_collision.stl"/>        
      </geometry>      
    </collision>    
    <inertial>      
      <origin xyz="0.01403284295229351511 -1.1875681052001115344e-09 0.0040383546575275958146" rpy="0 0 0"/>      
      <mass value="0.0021359401157891211472"/>      
      <inertia ixx="2.9209776528328194436e-08" ixy="-4.6752002052117498744e-14" ixz="-3.1659407525131257438e-08" iyy="1.7718014185775917458e-07" iyz="-2.5844348438831366327e-15" izz="1.8139327643022061737e-07"/>      
    </inertial>    
  </link>  

  <joint name="left_ank_act_1" type="revolute">    
    <origin xyz="0.013500000000001635692 -0.044499999999992628785 0.0040000000000077733792" rpy="-5.7683923736819409867e-13 -7.5455504046046331278e-14 -0.21173394130254355461"/>    
    <parent link="left_calf_link"/>    
    <child link="ank_motor_arm"/>    
    <axis xyz="0 0 1"/>    
    <limit effort="1" velocity="20" lower="-1.3089969389957472057" upper="1.3089969389957472057"/>    
    <joint_properties friction="0.0"/>    
  </joint>  

  <link name="ank_motor_arm_2">    
    <visual>      
      <origin xyz="0 0 0" rpy="0 -0 0"/>      
      <geometry>        
        <mesh filename="package:///meshes/left_ank_motor_arm_2_visual.stl"/>        
      </geometry>      
      <material name="ank_motor_arm_2_material">        
        <color rgba="0.62483822591633164656 0.70971956673896574586 0.76585356440212004614 1.0"/>        
      </material>      
    </visual>    
    <collision>      
      <origin xyz="0 0 0" rpy="0 -0 0"/>      
      <geometry>        
        <mesh filename="package:///meshes/left_ank_motor_arm_2_collision.stl"/>        
      </geometry>      
    </collision>    
    <inertial>      
      <origin xyz="0.014032842952293502967 -1.1875680925201774133e-09 0.0040383546575276053556" rpy="0 0 0"/>      
      <mass value="0.0021359401157891211472"/>      
      <inertia ixx="2.9209776528328022382e-08" ixy="-4.6752001844263965639e-14" ixz="-3.165940752513130376e-08" iyy="1.7718014185775883047e-07" iyz="-2.5844347880206935532e-15" izz="1.8139327643022061737e-07"/>      
    </inertial>    
  </link>  

  <joint name="left_ank_act_2" type="revolute">    
    <origin xyz="0.013500000000005811171 -0.064499999999988344435 -0.024800000000003163264" rpy="-3.1415926535893312632 1.9218128864630526701e-14 -0.22995607267384915451"/>    
    <parent link="left_calf_link"/>    
    <child link="ank_motor_arm_2"/>    
    <axis xyz="0 0 1"/>    
    <limit effort="1" velocity="20" lower="-1.3089969389957472057" upper="1.3089969389957472057"/>    
    <joint_properties friction="0.0"/>    
  </joint>  

  <joint name="left_knee_pitch" type="revolute">    
    <origin xyz="3.1436708451941898537e-17 -0.096000000000000001998 -0.0092000000000000154571" rpy="5.2388648972145238601e-16 -5.3048676098335846568e-16 -5.5511151227572361317e-17"/>    
    <parent link="left_hip_pitch_link_xm430"/>    
    <child link="left_calf_link"/>    
    <axis xyz="0 0 1"/>    
    <limit effort="1" velocity="20" lower="0" upper="1.9198621771937625091"/>    
    <joint_properties friction="0.0"/>    
  </joint>  

  <link name="xm430_plate">    
    <visual>      
      <origin xyz="0 0 0" rpy="0 -0 0"/>      
      <geometry>        
        <mesh filename="package:///meshes/left_xm430_plate_visual.stl"/>        
      </geometry>      
      <material name="xm430_plate_material">        
        <color rgba="0.61568627450980395466 0.81176470588235294379 0.92941176470588227065 1.0"/>        
      </material>      
    </visual>    
    <collision>      
      <origin xyz="0 0 0" rpy="0 -0 0"/>      
      <geometry>        
        <mesh filename="package:///meshes/left_xm430_plate_collision.stl"/>        
      </geometry>      
    </collision>    
    <inertial>      
      <origin xyz="3.5545777148459568354e-18 1.8842264892612239035e-18 -0.0024039046431217955119" rpy="0 0 0"/>      
      <mass value="0.0026999999999999997093"/>      
      <inertia ixx="1.293311664536341083e-07" ixy="-6.8936588702566440413e-08" ixz="5.4735536363229128674e-35" iyy="2.6720434385876688324e-07" iyz="-6.5325103416929007063e-36" izz="3.8533537562751439267e-07"/>      
    </inertial>    
  </link>  

  <link name="knee_rod">    
    <visual>      
      <origin xyz="0 0 0" rpy="0 -0 0"/>      
      <geometry>        
        <mesh filename="package:///meshes/left_knee_rod_visual.stl"/>        
      </geometry>      
      <material name="knee_rod_material">        
        <color rgba="0.62051618944235198416 0.78640765248647581664 0.88594253031295022716 1.0"/>        
      </material>      
    </visual>    
    <collision>      
      <origin xyz="0 0 0" rpy="0 -0 0"/>      
      <geometry>        
        <mesh filename="package:///meshes/left_knee_rod_collision.stl"/>        
      </geometry>      
    </collision>    
    <inertial>      
      <origin xyz="0.014594549254227703189 -4.0495174182604806484e-05 -0.0015996227373190293787" rpy="0 0 0"/>      
      <mass value="0.0031629468613064179276"/>      
      <inertia ixx="2.5896066719679955718e-08" ixy="3.4015849028409635641e-10" ixz="4.1682980135095627253e-10" iyy="6.015325433306769779e-07" iyz="-1.1565684637535343696e-12" izz="6.2266854577246018566e-07"/>      
    </inertial>    
  </link>  

  <joint name="left_knee_front_rev_1" type="revolute">    
    <origin xyz="0.013858192987669312735 0.0057402514854763336469 -0.0049999999999999836242" rpy="-9.4192987622433650731e-16 3.8593656109062736187e-16 -3.1358575050305752541"/>    
    <parent link="xm430_plate"/>    
    <child link="knee_rod"/>    
    <axis xyz="0 0 1"/>    
    <limit effort="1" velocity="20" lower="-6.283185307179586232" upper="6.283185307179586232"/>    
    <joint_properties friction="0.0"/>    
  </joint>  

  <link name="knee_rod_2">    
    <visual>      
      <origin xyz="0 0 0" rpy="0 -0 0"/>      
      <geometry>        
        <mesh filename="package:///meshes/left_knee_rod_2_visual.stl"/>        
      </geometry>      
      <material name="knee_rod_2_material">        
        <color rgba="0.62051618944235198416 0.78640765248647581664 0.88594253031295022716 1.0"/>        
      </material>      
    </visual>    
    <collision>      
      <origin xyz="0 0 0" rpy="0 -0 0"/>      
      <geometry>        
        <mesh filename="package:///meshes/left_knee_rod_2_collision.stl"/>        
      </geometry>      
    </collision>    
    <inertial>      
      <origin xyz="0.014594547729902918737 -4.1579390108021769244e-05 -0.0015996227373185551487" rpy="0 0 0"/>      
      <mass value="0.0031629468613064179276"/>      
      <inertia ixx="2.589611793639640879e-08" ixy="3.4926584154272079581e-10" ixz="4.1682975780794631615e-10" iyy="6.0153251772212437219e-07" iyz="-1.1875343734383762945e-12" izz="6.2266857138059509825e-07"/>      
    </inertial>    
  </link>  

  <joint name="left_knee_back_rev_1" type="revolute">    
    <origin xyz="-0.013858192987669284979 -0.0057402514854763449226 -0.0050000000000000009714" rpy="-1.240696991414760872e-15 6.8873592505729608146e-15 -3.1358203601644016878"/>    
    <parent link="xm430_plate"/>    
    <child link="knee_rod_2"/>    
    <axis xyz="0 0 1"/>    
    <limit effort="1" velocity="20" lower="-6.283185307179586232" upper="6.283185307179586232"/>    
    <joint_properties friction="0.0"/>    
  </joint>  

  <joint name="left_knee_act" type="revolute">    
    <origin xyz="-0.00015000000000007682969 -0.061499999999999728495 -0.030399999999999843814" rpy="-1.3864621477766001324e-15 9.2520451941214004081e-17 1.5707963267949205388"/>    
    <parent link="left_hip_pitch_link_xm430"/>    
    <child link="xm430_plate"/>    
    <axis xyz="0 0 1"/>    
    <limit effort="1" velocity="20" lower="0" upper="1.9198621771937625091"/>    
    <joint_properties friction="0.0"/>    
  </joint>  

  <joint name="left_hip_pitch" type="revolute">    
    <origin xyz="-0.024000000716155701214 -0.019000000152439879691 -0.019000000152457872243" rpy="1.570796326795379283 1.5707963267945606045 0"/>    
    <parent link="hip_roll_link"/>    
    <child link="left_hip_pitch_link_xm430"/>    
    <axis xyz="0 0 1"/>    
    <limit effort="1" velocity="20" lower="-1.570796326794896558" upper="1.570796326794896558"/>    
    <joint_properties friction="0.0"/>    
  </joint>  

  <joint name="left_hip_roll" type="revolute">    
    <origin xyz="0.018999999999999999528 -3.3500438890366171686e-18 -0.026000000000000002276" rpy="3.141592653589793116 -1.5707963267948930053 0"/>    
    <parent link="hip_yaw_link"/>    
    <child link="hip_roll_link"/>    
    <axis xyz="0 0 1"/>    
    <limit effort="1" velocity="20" lower="-0.785398163397448279" upper="0.785398163397448279"/>    
    <joint_properties friction="0.0"/>    
  </joint>  


</robot>