<mujoco model="sysID_XC330">
  <compiler angle="radian" autolimits="true" />
  <asset>
    <mesh name="xc330_visual" file="../assemblies/sysID_XC330/meshes/xc330_visual.stl" />
    <mesh name="arm_330_visual" file="../assemblies/sysID_XC330/meshes/arm_330_visual.stl" />
  </asset>
  <worldbody>
    <geom rgba="0.662234 0.702983 0.666427 1" mesh="xc330_visual" class="visual" />
    <body name="arm_330" pos="0.0894 0.0219499 0.0034194" quat="0.5 0.5 0.5 0.5">
      <inertial pos="0.0699496 0 -0.0145" quat="0.5 0.5 0.5 0.5" mass="0.0945" diaginertia="0.000175559 9.80867e-05 9.66481e-05" />
      <joint name="joint_0" pos="0 0 0" axis="0 0 1" limited="true" range="-1.39626 1.39626" damping="0.117" armature="0.003" frictionloss="0.104" />
      <geom rgba="0.604714 0.667227 0.72422 1" mesh="arm_330_visual" class="visual" />
    </body>
  </worldbody>
  <actuator>
    <position name="joint_0_act" joint="joint_0" kp="18.75" ctrlrange="-1.39626 1.39626" class="XC330" />
  </actuator>
  <default>
    <default class="XM430">
      <position forcerange="-5 5" />
    </default>
    <default class="XC430">
      <position forcerange="-2 2" />
    </default>
    <default class="XL430">
      <position forcerange="-2 2" />
    </default>
    <default class="XC330">
      <position forcerange="-1 1" />
    </default>
    <geom type="mesh" solref=".004 1" />
    <default class="visual">
      <geom contype="0" conaffinity="0" group="2" />
    </default>
    <default class="collision">
      <geom group="3" />
    </default>
  </default>
  <contact />
</mujoco>