<robot name="sysID_XC330">
  <mujoco>
    <compiler strippath="false" balanceinertia="true" discardvisual="false" />
  </mujoco>
  <link name="xc330">
    <visual>
      <origin xyz="0 0 0" rpy="0 -0 0" />
      <geometry>
        <mesh filename="../assemblies/sysID_XC330/meshes/xc330_visual.stl" />
      </geometry>
      <material name="xc330_material">
        <color rgba="0.66291664961446195026 0.70549986616795345995 0.66729895251604320894 1.0" />
      </material>
    </visual>
    <inertial>
      <origin xyz="0.067523785979360526066 0.0091047662315145976714 0.0040548453010051102238" rpy="0 0 0" />
      <mass value="0.037349999993091763384" />
      <inertia ixx="7.1551666942363893246e-06" ixy="-4.4272140296375410597e-06" ixz="3.8860038520305930694e-07" iyy="1.6392155116973043254e-05" iyz="3.3646472662193783352e-07" izz="2.0987261801740477504e-05" />
    </inertial>
  </link>

  <link name="arm_330">
    <visual>
      <origin xyz="0 0 0" rpy="0 -0 0" />
      <geometry>
        <mesh filename="../assemblies/sysID_XC330/meshes/arm_330_visual.stl" />
      </geometry>
      <material name="arm_330_material">
        <color rgba="0.62999456499017514322 0.65518625360592031015 0.6781537689702749061 1.0" />
      </material>
    </visual>
    <inertial>
      <origin xyz="0.072210065882168897322 -1.7612505973611808695e-17 -0.014499999999999971245" rpy="0 0 0" />
      <mass value="0.23449999999999995848" />
      <inertia ixx="0.00023435139633067215851" ixy="1.6675961149069037925e-20" ixz="-2.4775713707188284918e-20" iyy="0.00036854228767419877589" iyz="3.8996083990519743445e-16" izz="0.00018502892766331601425" />
    </inertial>
  </link>

  <joint name="joint_0" type="revolute">
    <origin xyz="0.089400000000000034994 0.021949857927858890116 0.0034193959459662072627" rpy="1.57079632679489678 -2.3592239273285399858e-16 1.5707963267948961139" />
    <parent link="xc330" />
    <child link="arm_330" />
    <axis xyz="0 0 1" />
    <limit effort="1" velocity="20" lower="-1.570796326794896558" upper="1.570796326794896558" />
    <joint_properties friction="0.0" />
  </joint>


</robot>