<robot name="sysID_XC330">
  <mujoco>
    <compiler strippath="false" balanceinertia="true" discardvisual="false" />
  </mujoco>
  <link name="xc330">
    <visual>
      <origin xyz="0 0 0" rpy="0 -0 0" />
      <geometry>
        <mesh filename="../assemblies/sysID_XC330/meshes/xc330_visual.stl" />
      </geometry>
      <material name="xc330_material">
        <color rgba="0.66291664961446195026 0.70549986616795357097 0.66729895251604331996 1.0" />
      </material>
    </visual>
    <inertial>
      <origin xyz="0.067523785979360526066 0.0091047662315145976714 0.0040548453010051110912" rpy="0 0 0" />
      <mass value="0.037349999993091763384" />
      <inertia ixx="7.1551666942363893246e-06" ixy="-4.4272140296375427537e-06" ixz="3.886003852030595187e-07" iyy="1.639215511697305003e-05" iyz="3.364647266219379394e-07" izz="2.098726180174048428e-05" />
    </inertial>
  </link>

  <link name="arm_330">
    <visual>
      <origin xyz="0 0 0" rpy="0 -0 0" />
      <geometry>
        <mesh filename="../assemblies/sysID_XC330/meshes/arm_330_visual.stl" />
      </geometry>
      <material name="arm_330_material">
        <color rgba="0.604714181969083997 0.66722689075630248201 0.72422035480859026091 1.0" />
      </material>
    </visual>
    <inertial>
      <origin xyz="0.069949643575130407425 -1.8464421918982629366e-17 -0.014499999999999964306" rpy="0 0 0" />
      <mass value="0.094500000000000014544" />
      <inertia ixx="9.6648053576060865069e-05" ixy="1.6623021589865644154e-20" ixz="-2.308164781267968424e-20" iyy="0.00017555912455268293674" iyz="3.8996083990519743445e-16" izz="9.8086683715699977937e-05" />
    </inertial>
  </link>

  <joint name="joint_0" type="revolute">
    <origin xyz="0.089400000000000034994 0.021949857927858890116 0.0034193959459662072627" rpy="1.57079632679489678 -2.3592239273285399858e-16 1.5707963267948961139" />
    <parent link="xc330" />
    <child link="arm_330" />
    <axis xyz="0 0 1" />
    <limit effort="1" velocity="20" lower="-1.570796326794896558" upper="1.570796326794896558" />
    <joint_properties friction="0.0" />
  </joint>


</robot>