<mujoco model="sysID_XC330">
  <compiler angle="radian" autolimits="true" />

  <asset>
    <mesh name="xc330_visual" file="../assemblies/sysID_XC330/meshes/xc330_visual.stl" />
    <mesh name="arm_330_visual" file="../assemblies/sysID_XC330/meshes/arm_330_visual.stl" />
  </asset>

  <worldbody>
    <geom type="mesh" rgba="0.662917 0.7055 0.667299 1" mesh="xc330_visual" class="visual" />
    <body name="arm_330" pos="0.0894 0.0219499 0.0034194" quat="0.5 0.5 0.5 0.5">
      <inertial pos="0.0722101 0 -0.0145" quat="0.707107 0 0 0.707107" mass="0.2345" diaginertia="0.000368542 0.000234351 0.000185029" />
      <joint name="joint_0" pos="0 0 0" axis="0 0 1" range="-1.5708 1.5708" damping="0.133" armature="0.003" frictionloss="0.143" />
      <geom type="mesh" rgba="0.629995 0.655186 0.678154 1" mesh="arm_330_visual" class="visual" />
    </body>
  </worldbody>
  <option>
    <flag eulerdamp="disable" />
  </option>
  <actuator>
    <position name="joint_0" joint="joint_0" kp="7.03125" ctrlrange="-1.5708 1.5708" class="XC330" />
  </actuator>
  <equality />
  <default>
    <geom type="mesh" solref="0.004 1" />
    <default class="XM430">
      <position forcerange="-3 3" />
    </default>
    <default class="XC430">
      <position forcerange="-2 2" />
    </default>
    <default class="2XC430">
      <position forcerange="-2 2" />
    </default>
    <default class="XL430">
      <position forcerange="-2 2" />
    </default>
    <default class="2XL430">
      <position forcerange="-2 2" />
    </default>
    <default class="XC330">
      <position forcerange="-1 1" />
    </default>
    <default class="visual">
      <geom type="mesh" contype="0" conaffinity="0" group="2" />
    </default>
    <default class="collision">
      <geom group="3" />
    </default>
  </default>
  <contact />
</mujoco>