<?xml version="1.0" ?><robot name="right_arm_gripper">  
  <link name="sho_pitch_link">    
    <visual>      
      <origin xyz="0 0 0" rpy="0 -0 0"/>      
      <geometry>        
        <mesh filename="package:///meshes/right_sho_pitch_link_visual.stl"/>        
      </geometry>      
      <material name="sho_pitch_link_material">        
        <color rgba="0.61568627450980395466 0.81176470588235294379 0.92941176470588227065 1.0"/>        
      </material>      
    </visual>    
    <collision>      
      <origin xyz="0 0 0" rpy="0 -0 0"/>      
      <geometry>        
        <mesh filename="package:///meshes/right_sho_pitch_link_collision.stl"/>        
      </geometry>      
    </collision>    
    <inertial>      
      <origin xyz="5.8254247222434160976e-11 -5.1264642561120796335e-05 0.008244078812709491888" rpy="0 0 0"/>      
      <mass value="0.0085999999999999948014"/>      
      <inertia ixx="1.2272887040545787638e-06" ixy="-2.1429944208389056621e-14" ixz="-8.5847198118935726732e-15" iyy="2.9107306060364603147e-06" iyz="7.4623841398182819312e-09" izz="3.0803135950773474987e-06"/>      
    </inertial>    
  </link>  

  <link name="2xl430_gears">    
    <visual>      
      <origin xyz="0 0 0" rpy="0 -0 0"/>      
      <geometry>        
        <mesh filename="package:///meshes/right_2xl430_gears_visual.stl"/>        
      </geometry>      
      <material name="2xl430_gears_material">        
        <color rgba="0.75605985687944110563 0.85804695962693022793 0.91320266199377464478 1.0"/>        
      </material>      
    </visual>    
    <collision>      
      <origin xyz="0 0 0" rpy="0 -0 0"/>      
      <geometry>        
        <mesh filename="package:///meshes/right_2xl430_gears_collision.stl"/>        
      </geometry>      
    </collision>    
    <inertial>      
      <origin xyz="-0.011579403981033858581 -0.0024225766141437814725 -0.018551095523802619419" rpy="0 0 0"/>      
      <mass value="0.11800003674524908726"/>      
      <inertia ixx="2.7482298083236915328e-05" ixy="9.2729623433052167511e-07" ixz="-2.263451200438713483e-08" iyy="3.2770742486672533656e-05" iyz="-6.5708346020062267455e-07" izz="3.576795754405571586e-05"/>      
    </inertial>    
  </link>  

  <link name="spur_1m_24t_drive">    
    <visual>      
      <origin xyz="0 0 0" rpy="0 -0 0"/>      
      <geometry>        
        <mesh filename="package:///meshes/right_spur_1m_24t_drive_visual.stl"/>        
      </geometry>      
      <material name="spur_1m_24t_drive_material">        
        <color rgba="0.61568627450980406568 0.81176470588235294379 0.92941176470588238168 1.0"/>        
      </material>      
    </visual>    
    <collision>      
      <origin xyz="0 0 0" rpy="0 -0 0"/>      
      <geometry>        
        <mesh filename="package:///meshes/right_spur_1m_24t_drive_collision.stl"/>        
      </geometry>      
    </collision>    
    <inertial>      
      <origin xyz="-7.751745260151380687e-15 -1.2123861048092197842e-16 0.0047949116178401460231" rpy="0 0 0"/>      
      <mass value="0.0032000000000000001533"/>      
      <inertia ixx="1.4019331346159885055e-07" ixy="1.6002410021796695823e-15" ixz="1.3924985888997309856e-36" iyy="1.4019331260388786185e-07" iyz="-4.5951838781519388734e-36" izz="2.3838919844264060647e-07"/>      
    </inertial>    
  </link>  

  <joint name="right_sho_yaw_drive" type="revolute">    
    <origin xyz="-0.024000000716137483148 -0.019000000152449965374 -0.019000000152444667528" rpy="1.570796326794722475 -4.3999245160326114002e-14 5.9488666369146786408e-14"/>    
    <parent link="2xl430_gears"/>    
    <child link="spur_1m_24t_drive"/>    
    <axis xyz="0 0 1"/>    
    <limit effort="1" velocity="20" lower="-1.570796326794896558" upper="1.570796326794896558"/>    
    <joint_properties friction="0.0"/>    
  </joint>  

  <link name="spur_1m_24t_driven">    
    <visual>      
      <origin xyz="0 0 0" rpy="0 -0 0"/>      
      <geometry>        
        <mesh filename="package:///meshes/right_spur_1m_24t_driven_visual.stl"/>        
      </geometry>      
      <material name="spur_1m_24t_driven_material">        
        <color rgba="0.23137254901960788156 0.38039215686274502337 0.7058823529411765163 1.0"/>        
      </material>      
    </visual>    
    <collision>      
      <origin xyz="0 0 0" rpy="0 -0 0"/>      
      <geometry>        
        <mesh filename="package:///meshes/right_spur_1m_24t_driven_collision.stl"/>        
      </geometry>      
    </collision>    
    <inertial>      
      <origin xyz="2.4762432785981830856e-18 -5.8048491945228596449e-15 -0.00097054817521927832808" rpy="0 0 0"/>      
      <mass value="0.0026999999999999997093"/>      
      <inertia ixx="1.2036234079571063062e-07" ixy="1.587431019793314561e-37" ixz="-1.5461159006407193093e-36" iyy="1.203623407957104718e-07" iyz="-1.0082599683077304872e-36" izz="2.2847261745924530022e-07"/>      
    </inertial>    
  </link>  

  <link name="sho_yaw_link">    
    <visual>      
      <origin xyz="0 0 0" rpy="0 -0 0"/>      
      <geometry>        
        <mesh filename="package:///meshes/right_sho_yaw_link_visual.stl"/>        
      </geometry>      
      <material name="sho_yaw_link_material">        
        <color rgba="0.61568627450980395466 0.81176470588235294379 0.92941176470588238168 1.0"/>        
      </material>      
    </visual>    
    <collision>      
      <origin xyz="0 0 0" rpy="0 -0 0"/>      
      <geometry>        
        <mesh filename="package:///meshes/right_sho_yaw_link_collision.stl"/>        
      </geometry>      
    </collision>    
    <inertial>      
      <origin xyz="-1.2817564279969886208e-18 1.5206593873907567991e-18 -0.024303257848520158635" rpy="0 0 0"/>      
      <mass value="0.014500000000000009409"/>      
      <inertia ixx="9.0846670053041348901e-06" ixy="3.6224092806459835683e-13" ixz="5.6772952765067195751e-35" iyy="5.6910950712097508087e-06" iyz="-3.5185142106800999806e-35" izz="4.4819609845548975929e-06"/>      
    </inertial>    
  </link>  

  <link name="2xl430_gears_2">    
    <visual>      
      <origin xyz="0 0 0" rpy="0 -0 0"/>      
      <geometry>        
        <mesh filename="package:///meshes/right_2xl430_gears_2_visual.stl"/>        
      </geometry>      
      <material name="2xl430_gears_2_material">        
        <color rgba="0.75605985687944110563 0.85804695962693022793 0.91320266199377464478 1.0"/>        
      </material>      
    </visual>    
    <collision>      
      <origin xyz="0 0 0" rpy="0 -0 0"/>      
      <geometry>        
        <mesh filename="package:///meshes/right_2xl430_gears_2_collision.stl"/>        
      </geometry>      
    </collision>    
    <inertial>      
      <origin xyz="-0.011579403981039852051 -0.0024225766141425793092 -0.018551095523806137438" rpy="0 0 0"/>      
      <mass value="0.11800003674524908726"/>      
      <inertia ixx="2.7482298083239744418e-05" ixy="9.2729623432915117581e-07" ixz="-2.2634512003323466589e-08" iyy="3.2770742486673658516e-05" iyz="-6.5708346020140956816e-07" izz="3.5767957544057823278e-05"/>      
    </inertial>    
  </link>  

  <link name="spur_1m_24t_drive_2">    
    <visual>      
      <origin xyz="0 0 0" rpy="0 -0 0"/>      
      <geometry>        
        <mesh filename="package:///meshes/right_spur_1m_24t_drive_2_visual.stl"/>        
      </geometry>      
      <material name="spur_1m_24t_drive_2_material">        
        <color rgba="0.61568627450980406568 0.81176470588235294379 0.92941176470588238168 1.0"/>        
      </material>      
    </visual>    
    <collision>      
      <origin xyz="0 0 0" rpy="0 -0 0"/>      
      <geometry>        
        <mesh filename="package:///meshes/right_spur_1m_24t_drive_2_collision.stl"/>        
      </geometry>      
    </collision>    
    <inertial>      
      <origin xyz="-7.751745260151380687e-15 -1.2123861048092138677e-16 0.0047949116178401520946" rpy="0 0 0"/>      
      <mass value="0.0032000000000000001533"/>      
      <inertia ixx="1.4019331346159885055e-07" ixy="1.6002409968393611024e-15" ixz="-3.9348876968074062678e-37" iyy="1.4019331260388783538e-07" iyz="-2.6377672644807350883e-36" izz="2.3838919844264060647e-07"/>      
    </inertial>    
  </link>  

  <joint name="right_elbow_yaw_drive" type="revolute">    
    <origin xyz="-0.024000000716145945129 -0.019000000152452470314 -0.019000000152448241059" rpy="1.5707963267948983344 1.6899208920332882627e-13 -6.1373298874875490715e-14"/>    
    <parent link="2xl430_gears_2"/>    
    <child link="spur_1m_24t_drive_2"/>    
    <axis xyz="0 0 1"/>    
    <limit effort="1" velocity="20" lower="-1.570796326794896558" upper="1.570796326794896558"/>    
    <joint_properties friction="0.0"/>    
  </joint>  

  <link name="spur_1m_24t_driven_2">    
    <visual>      
      <origin xyz="0 0 0" rpy="0 -0 0"/>      
      <geometry>        
        <mesh filename="package:///meshes/right_spur_1m_24t_driven_2_visual.stl"/>        
      </geometry>      
      <material name="spur_1m_24t_driven_2_material">        
        <color rgba="0.23137254901960788156 0.38039215686274502337 0.7058823529411765163 1.0"/>        
      </material>      
    </visual>    
    <collision>      
      <origin xyz="0 0 0" rpy="0 -0 0"/>      
      <geometry>        
        <mesh filename="package:///meshes/right_spur_1m_24t_driven_2_collision.stl"/>        
      </geometry>      
    </collision>    
    <inertial>      
      <origin xyz="5.9456902305522602679e-18 -5.8048491945228580672e-15 -0.00097054817521927117235" rpy="0 0 0"/>      
      <mass value="0.0026999999999999997093"/>      
      <inertia ixx="1.2036234079571063062e-07" ixy="-8.9014824086108095032e-38" ixz="3.2067963391906028065e-36" iyy="1.203623407957104718e-07" iyz="2.7069667191504325644e-36" izz="2.2847261745924530022e-07"/>      
    </inertial>    
  </link>  

  <link name="elb_yaw_link">    
    <visual>      
      <origin xyz="0 0 0" rpy="0 -0 0"/>      
      <geometry>        
        <mesh filename="package:///meshes/right_elb_yaw_link_visual.stl"/>        
      </geometry>      
      <material name="elb_yaw_link_material">        
        <color rgba="0.61568627450980395466 0.81176470588235294379 0.92941176470588238168 1.0"/>        
      </material>      
    </visual>    
    <collision>      
      <origin xyz="0 0 0" rpy="0 -0 0"/>      
      <geometry>        
        <mesh filename="package:///meshes/right_elb_yaw_link_collision.stl"/>        
      </geometry>      
    </collision>    
    <inertial>      
      <origin xyz="5.3127688027570469941e-08 0.0019833638641961657233 -0.023416643551549945479" rpy="0 0 0"/>      
      <mass value="0.017500000000000012074"/>      
      <inertia ixx="1.4134344903109203164e-05" ixy="1.6945783921965302898e-12" ixz="-1.12863987218649646e-11" iyy="6.6435900776211348874e-06" iyz="1.0545227077253063932e-06" izz="8.9925290757999027595e-06"/>      
    </inertial>    
  </link>  

  <link name="spur_1m_24t_driven_3">    
    <visual>      
      <origin xyz="0 0 0" rpy="0 -0 0"/>      
      <geometry>        
        <mesh filename="package:///meshes/right_spur_1m_24t_driven_3_visual.stl"/>        
      </geometry>      
      <material name="spur_1m_24t_driven_3_material">        
        <color rgba="0.23137254901960788156 0.38039215686274502337 0.7058823529411765163 1.0"/>        
      </material>      
    </visual>    
    <collision>      
      <origin xyz="0 0 0" rpy="0 -0 0"/>      
      <geometry>        
        <mesh filename="package:///meshes/right_spur_1m_24t_driven_3_collision.stl"/>        
      </geometry>      
    </collision>    
    <inertial>      
      <origin xyz="2.476243278598654168e-18 -5.8048491945228628003e-15 -0.0025705481752192754774" rpy="0 0 0"/>      
      <mass value="0.0026999999999999997093"/>      
      <inertia ixx="1.2036234079571063062e-07" ixy="-2.9839012757031514303e-36" ixz="3.2821659039070559178e-36" iyy="1.203623407957104718e-07" iyz="4.6846362701733088034e-37" izz="2.2847261745924530022e-07"/>      
    </inertial>    
  </link>  

  <link name="2xl430_gears_3">    
    <visual>      
      <origin xyz="0 0 0" rpy="0 -0 0"/>      
      <geometry>        
        <mesh filename="package:///meshes/right_2xl430_gears_3_visual.stl"/>        
      </geometry>      
      <material name="2xl430_gears_3_material">        
        <color rgba="0.75605985687944110563 0.85804695962693022793 0.91320266199377464478 1.0"/>        
      </material>      
    </visual>    
    <collision>      
      <origin xyz="0 0 0" rpy="0 -0 0"/>      
      <geometry>        
        <mesh filename="package:///meshes/right_2xl430_gears_3_collision.stl"/>        
      </geometry>      
    </collision>    
    <inertial>      
      <origin xyz="0.00044890447619679480244 0.011579403622971209606 -0.024577423538311955059" rpy="0 0 0"/>      
      <mass value="0.11800003674524908726"/>      
      <inertia ixx="3.5767957544055776846e-05" ixy="2.2634512004663462785e-08" ixz="6.5708346020171238244e-07" iyy="2.7482298083237115228e-05" iyz="9.2729623432988004766e-07" izz="3.2770742486673848251e-05"/>      
    </inertial>    
  </link>  

  <link name="spur_1m_24t_drive_3">    
    <visual>      
      <origin xyz="0 0 0" rpy="0 -0 0"/>      
      <geometry>        
        <mesh filename="package:///meshes/right_spur_1m_24t_drive_3_visual.stl"/>        
      </geometry>      
      <material name="spur_1m_24t_drive_3_material">        
        <color rgba="0.61568627450980406568 0.81176470588235294379 0.92941176470588238168 1.0"/>        
      </material>      
    </visual>    
    <collision>      
      <origin xyz="0 0 0" rpy="0 -0 0"/>      
      <geometry>        
        <mesh filename="package:///meshes/right_spur_1m_24t_drive_3_collision.stl"/>        
      </geometry>      
    </collision>    
    <inertial>      
      <origin xyz="-7.751745260151380687e-15 -1.2123861048092158399e-16 0.0047949116178401416863" rpy="0 0 0"/>      
      <mass value="0.0032000000000000001533"/>      
      <inertia ixx="1.4019331346159885055e-07" ixy="1.6002409988709471321e-15" ixz="3.0142658632333987562e-37" iyy="1.4019331260388786185e-07" iyz="2.9847825549003112408e-37" izz="2.3838919844264060647e-07"/>      
    </inertial>    
  </link>  

  <joint name="right_wrist_pitch_drive" type="revolute">    
    <origin xyz="-1.5244730108012700873e-10 0.024000000358075063156 -0.0080000000000021147945" rpy="-2.3760361364596328788e-14 9.1171344708605480535e-14 -1.5707963267948272801"/>    
    <parent link="2xl430_gears_3"/>    
    <child link="spur_1m_24t_drive_3"/>    
    <axis xyz="0 0 1"/>    
    <limit effort="1" velocity="20" lower="-1.3962634015954635824" upper="1.9198621771937625091"/>    
    <joint_properties friction="0.0"/>    
  </joint>  

  <link name="gripper_connector">    
    <visual>      
      <origin xyz="0 0 0" rpy="0 -0 0"/>      
      <geometry>        
        <mesh filename="package:///meshes/right_gripper_connector_visual.stl"/>        
      </geometry>      
      <material name="gripper_connector_material">        
        <color rgba="0.61568627450980395466 0.81176470588235294379 0.92941176470588238168 1.0"/>        
      </material>      
    </visual>    
    <collision>      
      <origin xyz="0 0 0" rpy="0 -0 0"/>      
      <geometry>        
        <mesh filename="package:///meshes/right_gripper_connector_collision.stl"/>        
      </geometry>      
    </collision>    
    <inertial>      
      <origin xyz="-0.00020299682521053742787 0.023971521766976099793 -0.029403013850151985681" rpy="0 0 0"/>      
      <mass value="0.0099999999999999967387"/>      
      <inertia ixx="5.3001475666257289086e-06" ixy="2.3401437868255125384e-08" ixz="4.8115832997678172075e-08" iyy="3.8245954467071424711e-06" iyz="1.9316561248438259967e-08" izz="2.2623415168893606272e-06"/>      
    </inertial>    
  </link>  

  <link name="right_rail_guide">    
    <visual>      
      <origin xyz="0 0 0" rpy="0 -0 0"/>      
      <geometry>        
        <mesh filename="package:///meshes/right_rail_guide_visual.stl"/>        
      </geometry>      
      <material name="right_rail_guide_material">        
        <color rgba="0.62025753727489985057 0.81399173133201496722 0.93011503590051247681 1.0"/>        
      </material>      
    </visual>    
    <collision>      
      <origin xyz="0 0 0" rpy="0 -0 0"/>      
      <geometry>        
        <mesh filename="package:///meshes/right_rail_guide_collision.stl"/>        
      </geometry>      
    </collision>    
    <inertial>      
      <origin xyz="0.0092741550667162012123 -0.0022368973911260619375 1.1465282798790105357e-05" rpy="0 0 0"/>      
      <mass value="0.030111386261699939898"/>      
      <inertia ixx="7.0587141071297657626e-06" ixy="-2.0076614642548881315e-06" ixz="3.7679719233345454809e-06" iyy="2.5402123601769120974e-05" iyz="8.8191782705952307384e-07" izz="2.7857260235898915346e-05"/>      
    </inertial>    
  </link>  

  <link name="rail">    
    <visual>      
      <origin xyz="0 0 0" rpy="0 -0 0"/>      
      <geometry>        
        <mesh filename="package:///meshes/right_rail_visual.stl"/>        
      </geometry>      
      <material name="rail_material">        
        <color rgba="0.64705882352941179736 0.64705882352941179736 0.64705882352941179736 1.0"/>        
      </material>      
    </visual>    
    <collision>      
      <origin xyz="0 0 0" rpy="0 -0 0"/>      
      <geometry>        
        <mesh filename="package:///meshes/right_rail_collision.stl"/>        
      </geometry>      
    </collision>    
    <inertial>      
      <origin xyz="0.022744777800883849567 -0.014233439403357403541 -0.0079907133176532543772" rpy="0 0 0"/>      
      <mass value="0.01189999999999999912"/>      
      <inertia ixx="2.9161025366903515529e-06" ixy="4.4570835808164656273e-09" ixz="-7.5225164550604629609e-07" iyy="3.6201306422454496648e-06" iyz="2.6765050785959795044e-08" izz="4.4681807873990699658e-06"/>      
    </inertial>    
  </link>  

  <joint name="right_gripper_pinion_1" type="prismatic">    
    <origin xyz="-0.028872599999999963571 -0.014174999999999993161 -0.0053499999999999381384" rpy="3.141592653589793116 1.5707963267948958919 0"/>    
    <parent link="right_rail_guide"/>    
    <child link="rail"/>    
    <axis xyz="0 0 1"/>    
    <limit effort="1" velocity="20" lower="-0.036872599999999998432" upper="0"/>    
    <joint_properties friction="0.0"/>    
  </joint>  

  <link name="rail_2">    
    <visual>      
      <origin xyz="0 0 0" rpy="0 -0 0"/>      
      <geometry>        
        <mesh filename="package:///meshes/right_rail_2_visual.stl"/>        
      </geometry>      
      <material name="rail_2_material">        
        <color rgba="0.64705882352941179736 0.64705882352941179736 0.64705882352941179736 1.0"/>        
      </material>      
    </visual>    
    <collision>      
      <origin xyz="0 0 0" rpy="0 -0 0"/>      
      <geometry>        
        <mesh filename="package:///meshes/right_rail_2_collision.stl"/>        
      </geometry>      
    </collision>    
    <inertial>      
      <origin xyz="0.022744777800883849567 -0.01423343940335741048 -0.0079907133176532266217" rpy="0 0 0"/>      
      <mass value="0.01189999999999999912"/>      
      <inertia ixx="2.9161025366903515529e-06" ixy="4.4570835808164656273e-09" ixz="-7.5225164550604629609e-07" iyy="3.6201306422454496648e-06" iyz="2.6765050785959795044e-08" izz="4.4681807873990699658e-06"/>      
    </inertial>    
  </link>  

  <joint name="right_gripper_pinion_2" type="prismatic">    
    <origin xyz="0.062872600000000000708 0.0141750000000000001 -0.0053499999999999381384" rpy="-1.1235956670197897365e-25 1.5707963267948958919 0"/>    
    <parent link="right_rail_guide"/>    
    <child link="rail_2"/>    
    <axis xyz="0 0 1"/>    
    <limit effort="1" velocity="20" lower="-0.036872599999999998432" upper="0"/>    
    <joint_properties friction="0.0"/>    
  </joint>  

  <link name="xc330">    
    <visual>      
      <origin xyz="0 0 0" rpy="0 -0 0"/>      
      <geometry>        
        <mesh filename="package:///meshes/right_xc330_visual.stl"/>        
      </geometry>      
      <material name="xc330_material">        
        <color rgba="0.66932535752643762539 0.72911795671409951325 0.67547870389434383487 1.0"/>        
      </material>      
    </visual>    
    <collision>      
      <origin xyz="0 0 0" rpy="0 -0 0"/>      
      <geometry>        
        <mesh filename="package:///meshes/right_xc330_collision.stl"/>        
      </geometry>      
    </collision>    
    <inertial>      
      <origin xyz="0.0080045171539637003516 -0.015558009851631669079 -0.011717805512818117372" rpy="0 0 0"/>      
      <mass value="0.026599999993091760775"/>      
      <inertia ixx="3.8683410666514000779e-06" ixy="-7.7688424002216035119e-10" ixz="5.7969695832974809426e-10" iyy="2.162676790749446218e-06" iyz="8.3590274792902258621e-09" izz="3.3158761130056246679e-06"/>      
    </inertial>    
  </link>  

  <link name="spur_gear_(14_teeth)">    
    <visual>      
      <origin xyz="0 0 0" rpy="0 -0 0"/>      
      <geometry>        
        <mesh filename="package:///meshes/right_spur_gear_(14_teeth)_visual.stl"/>        
      </geometry>      
      <material name="spur_gear_(14_teeth)_material">        
        <color rgba="0.91764705882352926025 0.91764705882352926025 0.91764705882352926025 1.0"/>        
      </material>      
    </visual>    
    <collision>      
      <origin xyz="0 0 0" rpy="0 -0 0"/>      
      <geometry>        
        <mesh filename="package:///meshes/right_spur_gear_(14_teeth)_collision.stl"/>        
      </geometry>      
    </collision>    
    <inertial>      
      <origin xyz="5.0520117117480722868e-09 -3.0586955537814652928e-09 -0.006903728708833461146" rpy="0 0 0"/>      
      <mass value="0.0013000000000000001572"/>      
      <inertia ixx="2.644554736595136864e-08" ixy="2.5401821979637413651e-10" ixz="1.9678356781400304161e-14" iyy="2.6850679146645050879e-08" iyz="-1.1914086608124237975e-14" izz="3.4027434623053041057e-08"/>      
    </inertial>    
  </link>  

  <joint name="right_gripper_rack" type="revolute">    
    <origin xyz="0.0079999999999993375022 -0.022499999999995499295 -0.019999999999999656941" rpy="3.9513898910780635647e-26 -6.1232339957375240819e-17 -4.4058789844277850015e-17"/>    
    <parent link="xc330"/>    
    <child link="spur_gear_(14_teeth)"/>    
    <axis xyz="0 0 1"/>    
    <limit effort="1" velocity="20" lower="0" upper="5.2359877559829888227"/>    
    <joint_properties friction="0.0"/>    
  </joint>  

  <joint name="right_gripper_motor" type="fixed">    
    <origin xyz="-0.0059500000000000038969 -0.022599999999999981215 0.023300000000000042899" rpy="-1.4352268952473380085e-25 1.0940480200944162675e-30 3.141592653589793116"/>    
    <parent link="right_rail_guide"/>    
    <child link="xc330"/>    
    <axis xyz="0 0 1"/>    
    <limit effort="1" velocity="20"/>    
    <joint_properties friction="0.0"/>    
  </joint>  

  <joint name="right_gripper_fixed" type="fixed">    
    <origin xyz="3.4694469519536141888e-18 0.037000000000000005107 -0.001999999999999991368" rpy="1.5707963267949094366 1.5707963267948832353 0"/>    
    <parent link="gripper_connector"/>    
    <child link="right_rail_guide"/>    
    <axis xyz="0 0 1"/>    
    <limit effort="1" velocity="20"/>    
    <joint_properties friction="0.0"/>    
  </joint>  

  <joint name="right_wrist_roll" type="revolute">    
    <origin xyz="0.019000000000003156725 -3.5806391185388974918e-10 -0.027000000152454312757" rpy="-3.141592653589708739 -1.5707963267948066299 0"/>    
    <parent link="2xl430_gears_3"/>    
    <child link="gripper_connector"/>    
    <axis xyz="0 0 1"/>    
    <limit effort="1" velocity="20" lower="-1.3962634015954635824" upper="1.9198621771937625091"/>    
    <joint_properties friction="0.0"/>    
  </joint>  

  <link name="wrist_bearing_plate">    
    <visual>      
      <origin xyz="0 0 0" rpy="0 -0 0"/>      
      <geometry>        
        <mesh filename="package:///meshes/right_wrist_bearing_plate_visual.stl"/>        
      </geometry>      
      <material name="wrist_bearing_plate_material">        
        <color rgba="0.64496316278892629192 0.69011804996940528945 0.71706771073555886087 1.0"/>        
      </material>      
    </visual>    
    <collision>      
      <origin xyz="0 0 0" rpy="0 -0 0"/>      
      <geometry>        
        <mesh filename="package:///meshes/right_wrist_bearing_plate_collision.stl"/>        
      </geometry>      
    </collision>    
    <inertial>      
      <origin xyz="-0.0075835583121499801351 -0.015499999999999980807 -0.001838632370590335529" rpy="0 0 0"/>      
      <mass value="0.0049000367468305548388"/>      
      <inertia ixx="4.970743010915013972e-07" ixy="3.135435358762893339e-23" ixz="1.8100904820814058409e-08" iyy="7.1268523603538574235e-07" iyz="8.8804451676286627573e-24" izz="1.1919657811600111352e-06"/>      
    </inertial>    
  </link>  

  <joint name="right_wrist_pitch_fixed" type="fixed">    
    <origin xyz="0.01550000000000218911 9.9364960703951510368e-15 -0.045000000000006000478" rpy="-1.2645101217445535558e-15 1.2057022047428705255e-13 -1.5707963267947835373"/>    
    <parent link="2xl430_gears_3"/>    
    <child link="wrist_bearing_plate"/>    
    <axis xyz="0 0 1"/>    
    <limit effort="1" velocity="20"/>    
    <joint_properties friction="0.0"/>    
  </joint>  

  <joint name="right_wrist_pitch_driven" type="revolute">    
    <origin xyz="2.7755575615628913511e-17 -6.3108872417680944433e-30 -0.0015999999999999966072" rpy="-1.5154544286135535634e-14 1.7943243846840832321e-15 1.570796326794896558"/>    
    <parent link="spur_1m_24t_driven_3"/>    
    <child link="2xl430_gears_3"/>    
    <axis xyz="0 0 1"/>    
    <limit effort="1" velocity="20" lower="-1.9198621771937625091" upper="1.3962634015954635824"/>    
    <joint_properties friction="0.0"/>    
  </joint>  

  <joint name="right_wrist_roll_fixed" type="fixed">    
    <origin xyz="0 -0.025299999999999999573 -0.051999999999999990674" rpy="1.570796326794896558 1.570796326794896558 0"/>    
    <parent link="elb_yaw_link"/>    
    <child link="spur_1m_24t_driven_3"/>    
    <axis xyz="0 0 1"/>    
    <limit effort="1" velocity="20"/>    
    <joint_properties friction="0.0"/>    
  </joint>  

  <joint name="right_elbow_yaw_fixed" type="fixed">    
    <origin xyz="0 3.1554436208840472216e-30 0.0016000000000000180744" rpy="-3.1415926535897873428 3.3907091715322312159e-31 -1.570796326794896558"/>    
    <parent link="spur_1m_24t_driven_2"/>    
    <child link="elb_yaw_link"/>    
    <axis xyz="0 0 1"/>    
    <limit effort="1" velocity="20"/>    
    <joint_properties friction="0.0"/>    
  </joint>  

  <joint name="right_elbow_yaw_driven" type="revolute">    
    <origin xyz="-3.5806995563048005238e-10 -0.0270000001524559885 -0.01900000000000036729" rpy="1.5707963267948485964 8.4311697099246135987e-14 3.6920636757530582299e-14"/>    
    <parent link="2xl430_gears_2"/>    
    <child link="spur_1m_24t_driven_2"/>    
    <axis xyz="0 0 1"/>    
    <limit effort="1" velocity="20" lower="-2.6179938779914944114" upper="2.6179938779914944114"/>    
    <joint_properties friction="0.0"/>    
  </joint>  

  <joint name="right_elbow_roll" type="revolute">    
    <origin xyz="-5.2041704279304212832e-17 -0.018999999999999964834 -0.059000000000000114853" rpy="1.5707963267948974462 5.0352015639126703846e-15 2.5592341453658362349e-15"/>    
    <parent link="sho_yaw_link"/>    
    <child link="2xl430_gears_2"/>    
    <axis xyz="0 0 1"/>    
    <limit effort="1" velocity="20" lower="-1.570796326794896558" upper="1.570796326794896558"/>    
    <joint_properties friction="0.0"/>    
  </joint>  

  <joint name="right_sho_yaw_fixed" type="fixed">    
    <origin xyz="5.2041704279304212832e-17 3.787910703300854279e-17 0.0015999999999998966438" rpy="3.141592653589793116 1.6554645777787879748e-29 8.3603448337486833053e-32"/>    
    <parent link="spur_1m_24t_driven"/>    
    <child link="sho_yaw_link"/>    
    <axis xyz="0 0 1"/>    
    <limit effort="1" velocity="20"/>    
    <joint_properties friction="0.0"/>    
  </joint>  

  <joint name="right_sho_yaw_driven" type="revolute">    
    <origin xyz="-3.5806750273148502117e-10 -0.027000000152448928176 -0.018999999999998070516" rpy="1.5707963267947655517 -4.3564811365927410262e-14 2.9648675946254039113e-14"/>    
    <parent link="2xl430_gears"/>    
    <child link="spur_1m_24t_driven"/>    
    <axis xyz="0 0 1"/>    
    <limit effort="1" velocity="20" lower="-1.570796326794896558" upper="1.570796326794896558"/>    
    <joint_properties friction="0.0"/>    
  </joint>  

  <joint name="right_sho_roll" type="revolute">    
    <origin xyz="-0.01899999999999992667 0.0010000000000000069597 0.026999999999999999695" rpy="3.1415926535897922278 1.5707963267948588104 0"/>    
    <parent link="sho_pitch_link"/>    
    <child link="2xl430_gears"/>    
    <axis xyz="0 0 1"/>    
    <limit effort="1" velocity="20" lower="-1.570796326794896558" upper="0"/>    
    <joint_properties friction="0.0"/>    
  </joint>  


</robot>