<mujoco model="sbot">
  <compiler angle="radian"/>

  <asset>
    <mesh name="base_link" file="meshes/sbot/collision/base_link.STL"/>
    <mesh name="shoulder_link" file="meshes/sbot/collision/shoulder_link.STL"/>
    <mesh name="upper_arm_link" file="meshes/sbot/collision/upper_arm_link.STL"/>
    <mesh name="forearm_link" file="meshes/sbot/collision/forearm_link.STL"/>
    <mesh name="wrist_1_link" file="meshes/sbot/collision/wrist_1_link.STL"/>
    <mesh name="wrist_2_link" file="meshes/sbot/collision/wrist_2_link.STL"/>
    <mesh name="wrist_3_link" file="meshes/sbot/collision/wrist_3_link.STL"/>
  </asset>

  <worldbody>
    <body name="sbot" pos="0 0 0">
      <geom quat="0.707107 0 0 -0.707107" type="mesh" contype="0" conaffinity="0" group="1" density="0" rgba="0.86667 0.86667 0.8902 1" mesh="base_link"/>
      <geom quat="0.707107 0 0 -0.707107" type="mesh" rgba="0.86667 0.86667 0.8902 1" mesh="base_link"/>
      <!-- <geom size="0.15 0.15 0.15" pos="0 0 -0.1575" quat="0.707107 0 0 -0.707107" type="box"/>
      <geom size="0.15 0.15 0.15" pos="0 0 -0.1575" quat="0.707107 0 0 -0.707107" type="box" contype="0" conaffinity="0" group="1" density="0" rgba="0 0 1 0.1"/>
      <geom size="1 1 0.05" pos="0 0 -0.35" quat="0.707107 0 0 -0.707107" type="box" rgba="0 0 1 0.1"/>
      <geom size="1 1 0.05" pos="0 0 -0.35" quat="0.707107 0 0 -0.707107" type="box" contype="0" conaffinity="0" group="1" density="0" rgba="0 0 1 0.1"/> -->
      <body name="shoulder_link" pos="0 0 0.172" quat="0.707107 0 0 -0.707107">
        <inertial pos="-0.015506 5.31134e-06 0.00202666" quat="0.707744 0.00819027 0.00819366 0.706374" mass="7.48001" diaginertia="0.0296005 0.0290159 0.0236767"/>
        <joint name="joint0" pos="0 0 0" axis="0 0 1" range="-6.28319 6.28319" actuatorfrcrange="-346 346"/>
        <geom type="mesh" contype="0" conaffinity="0" group="1" density="0" rgba="0.866667 0.866667 0.890196 1" mesh="shoulder_link"/>
        <geom type="mesh" rgba="0.866667 0.866667 0.890196 1" mesh="shoulder_link"/>
        <body name="upper_arm_link" pos="-0.1885 0 0">
          <inertial pos="0.00037048 -1.0498e-06 0.24431" quat="0.707104 0.00419016 0.00419555 0.707085" mass="13.27" diaginertia="0.67925 0.673219 0.0370655"/>
          <joint name="joint1" pos="0 0 0" axis="-1 0 0" range="-2.35619 2.35619" actuatorfrcrange="-346 346"/>
          <geom type="mesh" contype="0" conaffinity="0" group="1" density="0" rgba="0.86667 0.86667 0.8902 1" mesh="upper_arm_link"/>
          <geom type="mesh" rgba="0.86667 0.86667 0.8902 1" mesh="upper_arm_link"/>
          <body name="forearm_link" pos="0.14635 0 0.5907">
            <inertial pos="-0.0085627 -0.000680804 0.284369" quat="0.71768 0.00484718 0.00408494 0.696344" mass="3.99016" diaginertia="0.185231 0.183525 0.00594995"/>
            <joint name="joint2" pos="0 0 0" axis="-1 0 0" range="-3.14159 3.14159" actuatorfrcrange="-163 163"/>
            <geom type="mesh" contype="0" conaffinity="0" group="1" density="0" rgba="0.866667 0.866667 0.890196 1" mesh="forearm_link"/>
            <geom type="mesh" rgba="0.866667 0.866667 0.890196 1" mesh="forearm_link"/>
            <body name="wrist_1_link" pos="-0.1498 0 0.5494">
              <inertial pos="0.00603382 5.30466e-05 0.00949427" quat="0.705615 -0.0107006 -0.0099924 0.708444" mass="2.34999" diaginertia="0.00569172 0.00536728 0.00279135"/>
              <joint name="joint3" pos="0 0 0" axis="-1 0 0" range="-6.28319 6.28319" actuatorfrcrange="-63 63"/>
              <geom type="mesh" contype="0" conaffinity="0" group="1" density="0" rgba="0.866667 0.866667 0.890196 1" mesh="wrist_1_link"/>
              <geom type="mesh" rgba="0.866667 0.866667 0.890196 1" mesh="wrist_1_link"/>
              <body name="wrist_2_link" pos="0 0 0.1498">
                <inertial pos="-0.00949427 -5.30466e-05 -0.00603382" quat="0.493379 0.506011 0.508512 0.491879" mass="2.34999" diaginertia="0.00569172 0.00536728 0.00279135"/>
                <joint name="joint4" pos="0 0 0" axis="0 0 1" range="-6.28319 6.28319" actuatorfrcrange="-63 63"/>
                <geom type="mesh" contype="0" conaffinity="0" group="1" density="0" rgba="0.866667 0.866667 0.890196 1" mesh="wrist_2_link"/>
                <geom type="mesh" rgba="0.866667 0.866667 0.890196 1" mesh="wrist_2_link"/>
                <body name="wrist_3_link" pos="-0.1767 0 0">
                  <inertial pos="-0.0596959 4.23114e-05 -0.000741538" quat="0.498223 0.500476 0.519237 0.481342" mass="3.84506" diaginertia="0.0208399 0.0207775 0.0121087"/>
                  <joint name="joint5" pos="0 0 0" axis="-1 0 0" range="-6.28319 6.28319" actuatorfrcrange="-63 63"/>
                  <geom type="mesh" contype="0" conaffinity="0" group="1" density="0" rgba="0.792157 0.819608 0.933333 1" mesh="wrist_3_link"/>
                  <geom type="mesh" rgba="0.792157 0.819608 0.933333 1" mesh="wrist_3_link"/>
                  <geom size="0.00723 0.00723 0.007825" pos="-0.0785 0 0" quat="0.5 0.5 -0.5 -0.5" type="box"/>
                  <body name="attachment" pos="0 0 0.045" quat="0 0 0 1">
                    <site name="attachment_site" rgba="1 0 0 1" size="0.01" group="1"/>
                  </body>
                </body>
              </body>
            </body>
          </body>
        </body>
      </body>
    </body>
  </worldbody>
  <actuator>
    <!-- <motor name="joint0" joint="joint0" ctrlrange="-320 320"/>
    <motor name="joint1" joint="joint1" ctrlrange="-320 320"/>
    <motor name="joint2" joint="joint2" ctrlrange="-176 176"/>
    <motor name="joint3" joint="joint3" ctrlrange="-176 176"/>
    <motor name="joint4" joint="joint4" ctrlrange="-110 110"/>
    <motor name="joint5" joint="joint5" ctrlrange="-40 40"/> -->
    <position name="joint0" joint="joint0" kp="3460" kv="200" forcerange="-346 346" ctrlrange="-6.283185307179586 6.283185307179586"/> <!-- velocity="4.71238898038469" -->
    <position name="joint1" joint="joint1" kp="3460" kv="200" forcerange="-346 346" ctrlrange="-2.356194490192345 2.356194490192345"/> <!-- velocity="4.71238898038469" -->
    <position name="joint2" joint="joint2" kp="1630" kv="200" forcerange="-163 163" ctrlrange="-3.141592653589793 3.141592653589793"/> <!-- velocity="5.026548245743669" -->
    <position name="joint3" joint="joint3" kp="630" kv="50" forcerange="-63 63" ctrlrange="-6.283185307179586 6.283185307179586"/> <!-- velocity="6.806784082777885" -->
    <position name="joint4" joint="joint4" kp="630" kv="50" forcerange="-63 63" ctrlrange="-6.283185307179586 6.283185307179586"/> <!-- velocity="6.806784082777885" -->
    <position name="joint5" joint="joint5" kp="630" kv="50" forcerange="-63 63" ctrlrange="-6.283185307179586 6.283185307179586"/> <!-- velocity="6.806784082777885" -->
  </actuator>

</mujoco>
