<robot name="toddlerbot_gripper">
  <mujoco>
    <compiler strippath="false" balanceinertia="true" discardvisual="false" />
  </mujoco>
  <link name="torso">
    <visual>
      <origin xyz="0 0 0" rpy="0 -0 0" />
      <geometry>
        <mesh filename="../assemblies/toddlerbot/meshes/torso_visual.stl" />
      </geometry>
      <material name="torso_material">
        <color rgba="0.63761324738265701129 0.79140018897832331568 0.89744804913511844191 1.0" />
      </material>
    </visual>
    <inertial>
      <origin xyz="-0.0045319089141771795592 -0.0033046849194456094992 0.065594108502291123552" rpy="0 0 0" />
      <mass value="1.1369659631011950207" />
      <inertia ixx="0.0029825917743578336458" ixy="8.173061428844131341e-05" ixz="2.1951370741855520289e-05" iyy="0.002396950639998903388" iyz="-2.9575017351929247349e-05" izz="0.002512635652390854922" />
    </inertial>
  </link>

  <link name="spur_1m_20t">
    <visual>
      <origin xyz="0 0 0" rpy="0 -0 0" />
      <geometry>
        <mesh filename="../assemblies/toddlerbot/meshes/spur_1m_20t_visual.stl" />
      </geometry>
      <material name="spur_1m_20t_material">
        <color rgba="0.64705882352941179736 0.64705882352941179736 0.64705882352941179736 1.0" />
      </material>
    </visual>
    <inertial>
      <origin xyz="-8.5753164114088250402e-20 -7.9823296359483900623e-18 0.003384232105434467619" rpy="0 0 0" />
      <mass value="0.0015778025963745997712" />
      <inertia ixx="4.5874424196602091527e-08" ixy="6.4004493355995885587e-24" ixz="-7.1097175513400442172e-39" iyy="4.5874424196602051822e-08" iyz="7.8419015231486103005e-38" izz="8.1737050837173876176e-08" />
    </inertial>
  </link>

  <joint name="neck_yaw_drive" type="revolute">
    <origin xyz="-0.0049999999999995221878 3.1860588521011854095e-18 0.12148651076281755112" rpy="1.1607298201443905188e-14 1.6509758832059179101e-15 -5.3832337592600790636e-15" />
    <parent link="torso" />
    <child link="spur_1m_20t" />
    <axis xyz="0 0 1" />
    <limit effort="1" velocity="20" lower="-2.8797932657906435416" upper="2.8797932657906435416" />
    <joint_properties friction="0.0" />
  </joint>

  <link name="neck_yaw_link_v2">
    <visual>
      <origin xyz="0 0 0" rpy="0 -0 0" />
      <geometry>
        <mesh filename="../assemblies/toddlerbot/meshes/neck_yaw_link_v2_visual.stl" />
      </geometry>
      <material name="neck_yaw_link_v2_material">
        <color rgba="0.2313725490196078538 0.38039215686274513439 0.70588235294117662733 1.0" />
      </material>
    </visual>
    <inertial>
      <origin xyz="-1.1403990895369016788e-06 -1.1841855615507243796e-10 0.0082571849701004972066" rpy="0 0 0" />
      <mass value="0.0067298837334394089049" />
      <inertia ixx="5.2266067624768086445e-07" ixy="-6.304640333713484386e-15" ixz="1.194940308446679452e-09" iyy="6.1218519979556588152e-07" iyz="-2.6012872022712980049e-15" izz="2.8062851709981924551e-07" />
    </inertial>
  </link>

  <link name="head">
    <visual>
      <origin xyz="0 0 0" rpy="0 -0 0" />
      <geometry>
        <mesh filename="../assemblies/toddlerbot/meshes/head_visual.stl" />
      </geometry>
      <material name="head_material">
        <color rgba="0.6268574946787414115 0.79455216272759310314 0.87652603342635460049 1.0" />
      </material>
    </visual>
    <inertial>
      <origin xyz="-0.043832613261137839955 -0.010490240883705334238 -0.00040226032898233875408" rpy="0 0 0" />
      <mass value="0.12772101760550838567" />
      <inertia ixx="0.00011508349125723207364" ixy="3.2199498087100644597e-06" ixz="3.6551948020729792515e-06" iyy="9.8737573554260306082e-05" iyz="-8.3059614999120740279e-06" izz="8.6247396675247217776e-05" />
    </inertial>
  </link>

  <link name="motor_plate">
    <visual>
      <origin xyz="0 0 0" rpy="0 -0 0" />
      <geometry>
        <mesh filename="../assemblies/toddlerbot/meshes/motor_plate_visual.stl" />
      </geometry>
      <material name="motor_plate_material">
        <color rgba="0.64705882352941179736 0.64705882352941179736 0.64705882352941179736 1.0" />
      </material>
    </visual>
    <inertial>
      <origin xyz="2.0816681711721682051e-17 -3.4694469519536141888e-18 -0.0028281768943845485807" rpy="0 0 0" />
      <mass value="0.0016999999999999996884" />
      <inertia ixx="4.8050290733103697128e-08" ixy="1.0773753257370404815e-09" ixz="-7.7581517390052640125e-36" iyy="5.1782428339099010347e-08" iyz="-3.489439624544232414e-37" izz="9.2194729037862183155e-08" />
    </inertial>
  </link>

  <link name="bearing_683">
    <visual>
      <origin xyz="0 0 0" rpy="0 -0 0" />
      <geometry>
        <mesh filename="../assemblies/toddlerbot/meshes/bearing_683_visual.stl" />
      </geometry>
      <material name="bearing_683_material">
        <color rgba="0.64705882352941179736 0.64705882352941179736 0.64705882352941179736 1.0" />
      </material>
    </visual>
    <inertial>
      <origin xyz="1.0732094295236813184e-19 2.4186774283162407327e-19 -0.0015499999999999999455" rpy="0 0 0" />
      <mass value="0.00048694686130641793437" />
      <inertia ixx="2.1551456503319879113e-09" ixy="8.8695722220542739607e-27" ixz="-3.990276490501307198e-38" iyy="2.1551456503319883249e-09" iyz="3.2614313712998011813e-38" izz="3.5303647444715305817e-09" />
    </inertial>
  </link>

  <joint name="neck_pitch_front_rev_2" type="revolute">
    <origin xyz="-0.0019411428382688777905 -0.0072444436971680140069 -0.0054999999999999996808" rpy="-7.8470437385325782231e-15 7.0575798498253499623e-15 0.88076594287801956984" />
    <parent link="motor_plate" />
    <child link="bearing_683" />
    <axis xyz="0 0 1" />
    <limit effort="1" velocity="20" lower="-6.283185307179586232" upper="6.283185307179586232" />
    <joint_properties friction="0.0" />
  </joint>

  <link name="bearing_683_2">
    <visual>
      <origin xyz="0 0 0" rpy="0 -0 0" />
      <geometry>
        <mesh filename="../assemblies/toddlerbot/meshes/bearing_683_2_visual.stl" />
      </geometry>
      <material name="bearing_683_2_material">
        <color rgba="0.64705882352941179736 0.64705882352941179736 0.64705882352941179736 1.0" />
      </material>
    </visual>
    <inertial>
      <origin xyz="1.0732094295237642537e-19 2.4186774283160221397e-19 -0.0015499999999999999455" rpy="0 0 0" />
      <mass value="0.00048694686130641793437" />
      <inertia ixx="2.1551456503319887385e-09" ixy="1.0355000413046178976e-25" ixz="-1.5012828586696551818e-39" iyy="2.1551456503319883249e-09" iyz="1.0909476690756370037e-40" izz="3.5303647444715305817e-09" />
    </inertial>
  </link>

  <joint name="neck_pitch_back_rev_2" type="revolute">
    <origin xyz="0.0019411428382689333016 0.007244443697168007068 -0.0054999999999999996808" rpy="-2.4312653183549898777e-13 -1.5948647674331375607e-13 0.87787101658573418739" />
    <parent link="motor_plate" />
    <child link="bearing_683_2" />
    <axis xyz="0 0 1" />
    <limit effort="1" velocity="20" lower="-6.283185307179586232" upper="6.283185307179586232" />
    <joint_properties friction="0.0" />
  </joint>

  <joint name="neck_pitch_act" type="revolute">
    <origin xyz="-0.032615697718559488738 -0.026999999999999642342 0.0024999999999980862184" rpy="-3.1415926535897824579 -3.0391096960732582093e-13 -3.1415926535895213334" />
    <parent link="head" />
    <child link="motor_plate" />
    <axis xyz="0 0 1" />
    <limit effort="1" velocity="20" lower="-1.3962634015954635824" upper="0.61086523819801530344" />
    <joint_properties friction="0.0" />
  </joint>

  <joint name="neck_pitch" type="revolute">
    <origin xyz="-1.1449174941446926823e-16 0.0040000000000001215139 0.019400000000000056088" rpy="-1.5707963267830740151 1.5671692223464293026 -3.1415926535855391855" />
    <parent link="neck_yaw_link_v2" />
    <child link="head" />
    <axis xyz="0 0 1" />
    <limit effort="1" velocity="20" lower="-1.3962634015954635824" upper="0.61086523819801530344" />
    <joint_properties friction="0.0" />
  </joint>

  <link name="neck_rod">
    <visual>
      <origin xyz="0 0 0" rpy="0 -0 0" />
      <geometry>
        <mesh filename="../assemblies/toddlerbot/meshes/neck_rod_visual.stl" />
      </geometry>
      <material name="neck_rod_material">
        <color rgba="0.62051618944235198416 0.78640765248647581664 0.88594253031295000511 1.0" />
      </material>
    </visual>
    <inertial>
      <origin xyz="0.017942953356021015821 -4.2302323072829437216e-05 -0.0016023848482615999506" rpy="0 0 0" />
      <mass value="0.0031629468613064183613" />
      <inertia ixx="1.6183187611801680574e-08" ixy="4.3686324092854543192e-10" ixz="5.4098718285268760504e-10" iyy="7.9430220338152821291e-07" iyz="-1.2754318230195799618e-12" izz="8.0573905690511895042e-07" />
    </inertial>
  </link>

  <joint name="neck_pitch_front_rev_1" type="revolute">
    <origin xyz="-0.0072444436971684077892 -0.0040000000000001085035 0.01745885716173128932" rpy="1.5707963267946412067 -0.88439304732620005467 -3.1415926535894236338" />
    <parent link="neck_yaw_link_v2" />
    <child link="neck_rod" />
    <axis xyz="0 0 1" />
    <limit effort="1" velocity="20" lower="-6.283185307179586232" upper="6.283185307179586232" />
    <joint_properties friction="0.0" />
  </joint>

  <link name="neck_rod_2">
    <visual>
      <origin xyz="0 0 0" rpy="0 -0 0" />
      <geometry>
        <mesh filename="../assemblies/toddlerbot/meshes/neck_rod_2_visual.stl" />
      </geometry>
      <material name="neck_rod_2_material">
        <color rgba="0.62051618944235198416 0.78640765248647581664 0.88594253031295000511 1.0" />
      </material>
    </visual>
    <inertial>
      <origin xyz="0.017901072327982776866 4.2302323075069154959e-05 -0.0016023848482707595074" rpy="0 0 0" />
      <mass value="0.0031629468613064183613" />
      <inertia ixx="1.618318761180254746e-08" ixy="-4.3584354919588693271e-10" ixz="5.3972445328623424802e-10" iyy="7.9343818800625431371e-07" iyz="1.275431872910489489e-12" izz="8.0487504152983107517e-07" />
    </inertial>
  </link>

  <joint name="neck_pitch_back_rev_1" type="revolute">
    <origin xyz="0.0072444436971681805404 -0.004000000000000133657 0.021341142838269128168" rpy="1.570796326794926312 -0.88149812103391333995 3.1415926535897837901" />
    <parent link="neck_yaw_link_v2" />
    <child link="neck_rod_2" />
    <axis xyz="0 0 1" />
    <limit effort="1" velocity="20" lower="-6.283185307179586232" upper="6.283185307179586232" />
    <joint_properties friction="0.0" />
  </joint>

  <joint name="neck_yaw_driven" type="revolute">
    <origin xyz="0.016000000000000621364 3.9122381713629107253e-19 0.12248651076281739936" rpy="1.5470695466536949876e-14 -3.0902695541116811913e-15 -8.6007558735577539147e-16" />
    <parent link="torso" />
    <child link="neck_yaw_link_v2" />
    <axis xyz="0 0 1" />
    <limit effort="1" velocity="20" lower="-2.6179938779914944114" upper="2.6179938779914944114" />
    <joint_properties friction="0.0" />
  </joint>

  <link name="waist_gears">
    <visual>
      <origin xyz="0 0 0" rpy="0 -0 0" />
      <geometry>
        <mesh filename="../assemblies/toddlerbot/meshes/waist_gears_visual.stl" />
      </geometry>
      <material name="waist_gears_material">
        <color rgba="0.26906161272592887812 0.5227921908325551259 0.70491767355474543866 1.0" />
      </material>
    </visual>
    <inertial>
      <origin xyz="-2.908902431013901755e-07 5.503555374520705726e-08 -0.012592985430860513182" rpy="0 0 0" />
      <mass value="0.026337180140419171048" />
      <inertia ixx="1.5367047941032976421e-06" ixy="1.8828487098179149512e-11" ixz="4.0600521958570796887e-10" iyy="7.3024712275448224835e-06" iyz="3.2911737831925686031e-12" izz="6.9859065635057444052e-06" />
    </inertial>
  </link>

  <link name="waist_link">
    <visual>
      <origin xyz="0 0 0" rpy="0 -0 0" />
      <geometry>
        <mesh filename="../assemblies/toddlerbot/meshes/waist_link_visual.stl" />
      </geometry>
      <material name="waist_link_material">
        <color rgba="0.64045710103832809157 0.77359797797318041734 0.8121440665002769288 1.0" />
      </material>
    </visual>
    <inertial>
      <origin xyz="-7.9462186464867303482e-18 -0.02366029304019734783 -0.02276276478536513187" rpy="0 0 0" />
      <mass value="0.11519999998618361825" />
      <inertia ixx="4.8136551023262806311e-05" ixy="-1.2581830707237827449e-20" ixz="-5.6250849574754699444e-09" iyy="0.00011032090752778278228" iyz="5.9362613986426644063e-08" izz="8.0980504503691129632e-05" />
    </inertial>
  </link>

  <link name="spiral_bevel_1m_14t_30deg">
    <visual>
      <origin xyz="0 0 0" rpy="0 -0 0" />
      <geometry>
        <mesh filename="../assemblies/toddlerbot/meshes/spiral_bevel_1m_14t_30deg_visual.stl" />
      </geometry>
      <material name="spiral_bevel_1m_14t_30deg_material">
        <color rgba="0.64705882352941179736 0.64705882352941179736 0.64705882352941179736 1.0" />
      </material>
    </visual>
    <inertial>
      <origin xyz="7.4971447279470481499e-10 7.1802237332913011122e-10 0.0066868955018979155808" rpy="0 0 0" />
      <mass value="0.00073261524436595492574" />
      <inertia ixx="1.3495056019478193356e-08" ixy="4.0596681708340680739e-17" ixz="8.5992550148967780827e-16" iyy="1.3495056150237198942e-08" iyz="-6.791300820279719016e-16" izz="1.4355986549816401791e-08" />
    </inertial>
  </link>

  <joint name="waist_act_1" type="revolute">
    <origin xyz="-2.4504607866288808614e-16 -0.019600000000000054878 -0.012750000000000320105" rpy="-1.5707963267948259478 1.5358897417550183562 6.0735050737511900929e-14" />
    <parent link="waist_link" />
    <child link="spiral_bevel_1m_14t_30deg" />
    <axis xyz="0 0 1" />
    <limit effort="1" velocity="20" lower="-4.6774823953448034786" upper="4.6774823953448034786" />
    <joint_properties friction="0.0" />
  </joint>

  <link name="spiral_bevel_1m_14t_30deg_2">
    <visual>
      <origin xyz="0 0 0" rpy="0 -0 0" />
      <geometry>
        <mesh filename="../assemblies/toddlerbot/meshes/spiral_bevel_1m_14t_30deg_2_visual.stl" />
      </geometry>
      <material name="spiral_bevel_1m_14t_30deg_2_material">
        <color rgba="0.64705882352941179736 0.64705882352941179736 0.64705882352941179736 1.0" />
      </material>
    </visual>
    <inertial>
      <origin xyz="3.6393116992217144912e-10 -9.7220472557862924745e-10 -0.0066868955018979069072" rpy="0 0 0" />
      <mass value="0.00073261524436595492574" />
      <inertia ixx="1.349505601235447918e-08" ixy="2.5804135905735602914e-17" ixz="-1.0694296048242906771e-15" iyy="1.3495056157360913119e-08" iyz="-2.3876736921528802276e-16" izz="1.43559865498164051e-08" />
    </inertial>
  </link>

  <joint name="waist_act_2" type="revolute">
    <origin xyz="1.9472970659157160941e-16 -0.019600000000000117328 -0.032749999999999668265" rpy="-1.57079632679489678 3.8965962276001972074e-16 3.1415926535897926719" />
    <parent link="waist_link" />
    <child link="spiral_bevel_1m_14t_30deg_2" />
    <axis xyz="0 0 1" />
    <limit effort="1" velocity="20" lower="-4.6774823953448034786" upper="4.6774823953448034786" />
    <joint_properties friction="0.0" />
  </joint>

  <joint name="left_hip_pitch" type="revolute">
    <origin xyz="0.056000000000000008105 -0.040100000000000003697 -0.022750000000000002859" rpy="-1.57079632679489678 7.6559821685211629859e-14 1.5707963267948958919" />
    <parent link="waist_link" />
    <child link="2xc430" />
    <axis xyz="0 0 1" />
    <limit effort="1" velocity="20" lower="-1.570796326794896558" upper="1.570796326794896558" />
    <joint_properties friction="0.0" />
  </joint>

  <joint name="right_hip_pitch" type="revolute">
    <origin xyz="-0.056000000000000028921 -0.040100000000000003697 -0.022750000000000002859" rpy="1.5707963267948974462 -3.2312277008054088096e-16 1.57079632679489678" />
    <parent link="waist_link" />
    <child link="2xc430_2" />
    <axis xyz="0 0 1" />
    <limit effort="1" velocity="20" lower="-1.570796326794896558" upper="1.570796326794896558" />
    <joint_properties friction="0.0" />
  </joint>

  <joint name="waist_roll" type="revolute">
    <origin xyz="-0.022707865260692041559 -1.3173316226474365908e-17 -0.013999999999999970801" rpy="1.5707963267948956698 -1.6844078265464242354e-15 -1.5707963267949138775" />
    <parent link="waist_gears" />
    <child link="waist_link" />
    <axis xyz="0 0 1" />
    <limit effort="1" velocity="20" lower="-0.52359877559829881566" upper="0.52359877559829881566" />
    <joint_properties friction="0.0" />
  </joint>

  <joint name="waist_yaw" type="revolute">
    <origin xyz="0 -9.8607613152626475676e-32 -2.4651903288156618919e-32" rpy="-4.2812126708735032307e-16 -4.1243331367303584415e-15 3.141592653589773132" />
    <parent link="torso" />
    <child link="waist_gears" />
    <axis xyz="0 0 1" />
    <limit effort="1" velocity="20" lower="-1.570796326794896558" upper="1.570796326794896558" />
    <joint_properties friction="0.0" />
  </joint>

  <joint name="left_sho_pitch" type="revolute">
    <origin xyz="-0.0035000000000004762545 0.067000000000001072586 0.10423651076281729988" rpy="-1.5707963267949092145 2.5785047081963992394e-15 3.4723733359249287712e-14" />
    <parent link="torso" />
    <child link="sho_pitch_link" />
    <axis xyz="0 0 1" />
    <limit effort="1" velocity="20" lower="-3.141592653589793116" upper="1.570796326794896558" />
    <joint_properties friction="0.0" />
  </joint>

  <joint name="right_sho_pitch" type="revolute">
    <origin xyz="-0.003499999999998689923 -0.067000000000001017075 0.10423651076281729988" rpy="-1.5707963267948874542 -6.5632891966464542239e-16 -3.1415926535897562566" />
    <parent link="torso" />
    <child link="sho_pitch_link_2" />
    <axis xyz="0 0 1" />
    <limit effort="1" velocity="20" lower="-1.570796326794896558" upper="3.141592653589793116" />
    <joint_properties friction="0.0" />
  </joint>


  <link name="2xc430">
    <visual>
      <origin xyz="0 0 0" rpy="0 -0 0" />
      <geometry>
        <mesh filename="../assemblies/left_leg_reorder/meshes/left_2xc430_visual.stl" />
      </geometry>
      <material name="2xc430_material">
        <color rgba="0.51698661238356047321 0.50347815951093488618 0.49050589017722012741 1.0" />
      </material>
    </visual>
    <inertial>
      <origin xyz="-0.01200015113396762749 0.0004958883138633488237 0.018504019244503604885" rpy="0 0 0" />
      <mass value="0.11059999999836234164" />
      <inertia ixx="2.2818802599020586886e-05" ixy="4.6888548259115596141e-08" ixz="4.6520143289450651333e-08" iyy="3.0871666424471342217e-05" iyz="-5.7477343899721928227e-07" izz="3.0871632082341778937e-05" />
    </inertial>
  </link>

  <link name="hip_yaw_link">
    <visual>
      <origin xyz="0 0 0" rpy="0 -0 0" />
      <geometry>
        <mesh filename="../assemblies/left_leg_reorder/meshes/left_hip_yaw_link_visual.stl" />
      </geometry>
      <material name="hip_yaw_link_material">
        <color rgba="0.61568627450980406568 0.81176470588235294379 0.92941176470588238168 1.0" />
      </material>
    </visual>
    <inertial>
      <origin xyz="-2.3680216970514443902e-18 -0.015800610849654266737 -0.019005670096647751116" rpy="0 0 0" />
      <mass value="0.013199999999999996458" />
      <inertia ixx="5.789461597517412337e-06" ixy="-8.8451194166101304062e-37" ixz="4.1982283429801239953e-35" iyy="5.0110144042848767847e-06" iyz="1.1826010760651343791e-09" izz="2.7344876354814335894e-06" />
    </inertial>
  </link>

  <link name="spur_gear_21_teeth">
    <visual>
      <origin xyz="0 0 0" rpy="0 -0 0" />
      <geometry>
        <mesh filename="../assemblies/left_leg_reorder/meshes/left_spur_gear_21_teeth_visual.stl" />
      </geometry>
      <material name="spur_gear_21_teeth_material">
        <color rgba="0.61568627450980395466 0.81176470588235294379 0.9294117647058824927 1.0" />
      </material>
    </visual>
    <inertial>
      <origin xyz="-4.5505289258681524915e-11 -1.6782163666153599156e-11 -0.00249241020062506086" rpy="0 0 0" />
      <mass value="0.0022000000000000001325" />
      <inertia ixx="7.0162310059594183647e-08" ixy="1.5323480502245093491e-37" ixz="2.0419298266348190126e-36" iyy="7.016231005804746178e-08" iyz="2.3761289098562133048e-37" izz="1.3125544198538289306e-07" />
    </inertial>
  </link>

  <link name="left_hip_pitch_link">
    <visual>
      <origin xyz="0 0 0" rpy="0 -0 0" />
      <geometry>
        <mesh filename="../assemblies/left_leg_reorder/meshes/left_hip_pitch_link_visual.stl" />
      </geometry>
      <material name="left_hip_pitch_link_material">
        <color rgba="0.79618318075804161982 0.72120748766551012743 0.38540937988910844991 1.0" />
      </material>
    </visual>
    <inertial>
      <origin xyz="-0.0092773123251561045305 -0.0054583150498877649678 0.039514738116742297025" rpy="0 0 0" />
      <mass value="0.15848965119785962674" />
      <inertia ixx="8.2188788742762299076e-05" ixy="-1.3373705321920405155e-06" ixz="-9.0917451363911978905e-06" iyy="9.9396334685482759888e-05" iyz="1.2989378994408091923e-06" izz="4.5892431466751867106e-05" />
    </inertial>
  </link>

  <link name="spur_gear_18_teeth">
    <visual>
      <origin xyz="0 0 0" rpy="0 -0 0" />
      <geometry>
        <mesh filename="../assemblies/left_leg_reorder/meshes/left_spur_gear_18_teeth_visual.stl" />
      </geometry>
      <material name="spur_gear_18_teeth_material">
        <color rgba="0.61568627450980395466 0.81176470588235294379 0.92941176470588238168 1.0" />
      </material>
    </visual>
    <inertial>
      <origin xyz="-7.751665190816056485e-14 -3.6849356901589274307e-13 0.0017500000000010276432" rpy="0 0 0" />
      <mass value="0.001199999999999999678" />
      <inertia ixx="2.9367899810799927978e-08" ixy="7.0238076837028216373e-19" ixz="-1.7820947532845549062e-36" iyy="2.9367899814659469999e-08" iyz="1.9030216118189840795e-37" izz="5.6306346207859581581e-08" />
    </inertial>
  </link>

  <joint name="left_hip_yaw_drive" type="revolute">
    <origin xyz="-0.0191999999999946519 0.00020000000000184453564 -3.2904234892328076967e-14" rpy="-3.141592653589733608 -4.3962917099195071057e-13 4.1575315394653814742e-13" />
    <parent link="left_hip_pitch_link" />
    <child link="spur_gear_18_teeth" />
    <axis xyz="0 0 1" />
    <limit effort="1" velocity="20" lower="-1.8325957145940461324" upper="1.8325957145940461324" />
    <joint_properties friction="0.0" />
  </joint>

  <link name="left_calf_link">
    <visual>
      <origin xyz="0 0 0" rpy="0 -0 0" />
      <geometry>
        <mesh filename="../assemblies/left_leg_reorder/meshes/left_calf_link_visual.stl" />
      </geometry>
      <material name="left_calf_link_material">
        <color rgba="0.522707147375079062 0.70740037950664136357 0.87533206831119547697 1.0" />
      </material>
    </visual>
    <inertial>
      <origin xyz="-0.0043450054391243712881 0.040752982165250695168 0.0087116093515534863412" rpy="0 0 0" />
      <mass value="0.0309999999999999859" />
      <inertia ixx="3.3069388685112603764e-05" ixy="-1.3783307153201173959e-06" ixz="-1.2742534026332619196e-07" iyy="7.7316525337315396819e-06" iyz="-7.3356500593865995165e-08" izz="2.8031377753987737732e-05" />
    </inertial>
  </link>

  <link name="bearing_683_3">
    <visual>
      <origin xyz="0 0 0" rpy="0 -0 0" />
      <geometry>
        <mesh filename="../assemblies/left_leg_reorder/meshes/left_bearing_683_visual.stl" />
      </geometry>
      <material name="bearing_683_material">
        <color rgba="0.64705882352941179736 0.64705882352941179736 0.64705882352941179736 1.0" />
      </material>
    </visual>
    <inertial>
      <origin xyz="2.7862896558581290791e-17 -2.4186774283160226211e-19 -0.0015500000000000003792" rpy="0 0 0" />
      <mass value="0.00048694686130641793437" />
      <inertia ixx="2.1551456503319887385e-09" ixy="7.9979134666926667977e-29" ixz="4.5256340208374437986e-57" iyy="2.1551456503319883249e-09" iyz="-2.7201762377664295864e-38" izz="3.5303647444715305817e-09" />
    </inertial>
  </link>

  <joint name="left_knee_front_rev_2" type="revolute">
    <origin xyz="-0.0057402514854763414531 -0.013858192987669298857 0.026200000000000004535" rpy="3.141592653589793116 -3.7766880977238118578e-16 -1.5720025967024178204" />
    <parent link="left_calf_link" />
    <child link="bearing_683_3" />
    <axis xyz="0 0 1" />
    <limit effort="1" velocity="20" />
    <joint_properties friction="0.0" />
  </joint>

  <link name="bearing_683_4">
    <visual>
      <origin xyz="0 0 0" rpy="0 -0 0" />
      <geometry>
        <mesh filename="../assemblies/left_leg_reorder/meshes/left_bearing_683_2_visual.stl" />
      </geometry>
      <material name="bearing_683_2_material">
        <color rgba="0.64705882352941179736 0.64705882352941179736 0.64705882352941179736 1.0" />
      </material>
    </visual>
    <inertial>
      <origin xyz="1.0732094295236786702e-19 6.2549399515680812214e-19 -0.0015500000000000008129" rpy="0 0 0" />
      <mass value="0.00048694686130641793437" />
      <inertia ixx="2.1551456503319887385e-09" ixy="8.7242790793507745107e-29" ixz="1.7509993145311511984e-38" iyy="2.1551456503319874977e-09" iyz="-2.102256980416053089e-38" izz="3.5303647444715322361e-09" />
    </inertial>
  </link>

  <joint name="left_knee_back_rev_2" type="revolute">
    <origin xyz="0.0057402514854763692087 0.013858192987669354368 0.026199999999999997596" rpy="3.141592653589793116 8.6814019947542712626e-16 -1.5703842366896261229" />
    <parent link="left_calf_link" />
    <child link="bearing_683_4" />
    <axis xyz="0 0 1" />
    <limit effort="1" velocity="20" />
    <joint_properties friction="0.0" />
  </joint>

  <link name="left_ank_pitch_link">
    <visual>
      <origin xyz="0 0 0" rpy="0 -0 0" />
      <geometry>
        <mesh filename="../assemblies/left_leg_reorder/meshes/left_ank_pitch_link_visual.stl" />
      </geometry>
      <material name="left_ank_pitch_link_material">
        <color rgba="0.70321688500203327621 0.64514870846184457776 0.40484735422826284568 1.0" />
      </material>
    </visual>
    <inertial>
      <origin xyz="0.017770241891400764822 0.01230133450857246423 0.018813528244421631741" rpy="0 0 0" />
      <mass value="0.17676376695067899658" />
      <inertia ixx="4.728331668025008525e-05" ixy="-1.338059859845293059e-06" ixz="-5.5304058905088719854e-07" iyy="0.00010706456048088677617" iyz="-5.3225137839546250485e-08" izz="0.00012185522397135889288" />
    </inertial>
  </link>

  <link name="ank_roll_link">
    <visual>
      <origin xyz="0 0 0" rpy="0 -0 0" />
      <geometry>
        <mesh filename="../assemblies/left_leg_reorder/meshes/left_ank_roll_link_visual.stl" />
      </geometry>
      <material name="ank_roll_link_material">
        <color rgba="0.61568627450980395466 0.81176470588235294379 0.92941176470588238168 1.0" />
      </material>
    </visual>
    <collision name="ank_roll_link_collision">
      <origin xyz="-0.014500000514090061 0.0 0.038999998942017555" rpy="0 0 0" />
      <geometry>
        <box size="0.04900000058114529 0.041999999433755875 0.12000000104308128" />
      </geometry>
    </collision>
    <inertial>
      <origin xyz="-0.027003372529275659203 -2.0047302511735465645e-12 0.033758582145829475751" rpy="0 0 0" />
      <mass value="0.042599999999999998979" />
      <inertia ixx="3.7273661670607261974e-05" ixy="-5.5170353166063861222e-16" ixz="2.3913171754436606354e-06" iyy="3.7580160445155170687e-05" iyz="5.090954402493235e-12" izz="1.0089086509198995752e-05" />
    </inertial>
  </link>

  <joint name="left_ank_roll" type="revolute">
    <origin xyz="0.022749999999984962806 -7.6327832942979512154e-15 0.018999999999999767075" rpy="-1.5707963267949844877 3.1448403190652545553e-14 1.5707963267951721154" />
    <parent link="left_ank_pitch_link" />
    <child link="ank_roll_link" />
    <axis xyz="0 0 1" />
    <limit effort="1" velocity="20" lower="-1.570796326794896558" upper="1.570796326794896558" />
    <joint_properties friction="0.0" />
  </joint>

  <joint name="left_ank_pitch" type="revolute">
    <origin xyz="-2.05623323897773339e-16 0.10000000000000064393 0.027749999999999951789" rpy="-3.1415926535897922278 -9.0821107709100049291e-16 -1.6409719904700665899e-15" />
    <parent link="left_calf_link" />
    <child link="left_ank_pitch_link" />
    <axis xyz="0 0 1" />
    <limit effort="1" velocity="20" lower="-1.7453292519943295336" upper="0.785398163397448279" />
    <joint_properties friction="0.0" />
  </joint>

  <joint name="left_knee" type="revolute">
    <origin xyz="-6.8796820822730287635e-17 -0.0087500000000000095063 0.085949999999999970868" rpy="1.5707963267948952257 6.6234719020746891706e-14 3.141592653589793116" />
    <parent link="left_hip_pitch_link" />
    <child link="left_calf_link" />
    <axis xyz="0 0 1" />
    <limit effort="1" velocity="20" lower="-2.0943951023931952626" upper="0" />
    <joint_properties friction="0.0" />
  </joint>

  <link name="xm430_plate">
    <visual>
      <origin xyz="0 0 0" rpy="0 -0 0" />
      <geometry>
        <mesh filename="../assemblies/left_leg_reorder/meshes/left_xm430_plate_visual.stl" />
      </geometry>
      <material name="xm430_plate_material">
        <color rgba="0.61568627450980395466 0.81176470588235294379 0.92941176470588227065 1.0" />
      </material>
    </visual>
    <inertial>
      <origin xyz="1.1002408056519082444e-18 -2.342027732526315209e-18 0.0025278513919583817798" rpy="0 0 0" />
      <mass value="0.0026999999999999997093" />
      <inertia ixx="1.2887178787151822041e-07" ixy="5.8739562556303586683e-08" ixz="-2.3305678459810425892e-36" iyy="2.4635091298412528789e-07" iyz="-1.82666306477077615e-36" izz="3.6467998413810316538e-07" />
    </inertial>
  </link>

  <link name="knee_rod">
    <visual>
      <origin xyz="0 0 0" rpy="0 -0 0" />
      <geometry>
        <mesh filename="../assemblies/left_leg_reorder/meshes/left_knee_rod_visual.stl" />
      </geometry>
      <material name="knee_rod_material">
        <color rgba="0.62051618944235198416 0.78640765248647581664 0.88594253031295022716 1.0" />
      </material>
    </visual>
    <inertial>
      <origin xyz="0.01753428740115734602 -4.2302217781369085784e-05 -0.0015987301647641353076" rpy="0 0 0" />
      <mass value="0.0031629468613064179276" />
      <inertia ixx="2.4225259084540128431e-08" ixy="4.2691224813027038159e-10" ixz="4.9178282563657369679e-10" iyy="8.1758847583180512571e-07" iyz="-1.1864470859413227238e-12" izz="8.3704925438106290589e-07" />
    </inertial>
  </link>

  <joint name="left_knee_front_rev_1" type="revolute">
    <origin xyz="0.013858192987669312735 -0.0057402514854763414531 0.0049999999999999905631" rpy="-3.1415926535897922278 -5.113493938169237319e-16 3.1403863836822059064" />
    <parent link="xm430_plate" />
    <child link="knee_rod" />
    <axis xyz="0 0 1" />
    <limit effort="1" velocity="20" />
    <joint_properties friction="0.0" />
  </joint>

  <link name="knee_rod_2">
    <visual>
      <origin xyz="0 0 0" rpy="0 -0 0" />
      <geometry>
        <mesh filename="../assemblies/left_leg_reorder/meshes/left_knee_rod_2_visual.stl" />
      </geometry>
      <material name="knee_rod_2_material">
        <color rgba="0.62051618944235198416 0.78640765248647581664 0.88594253031295022716 1.0" />
      </material>
    </visual>
    <inertial>
      <origin xyz="0.017534309937459600925 1.4451433299456303442e-05 -0.0015987301647641056004" rpy="0 0 0" />
      <mass value="0.0031629468613064179276" />
      <inertia ixx="2.4224349341805677951e-08" ixy="-1.4584346002684859382e-10" ixz="4.9178345771022968718e-10" iyy="8.1758893070297708835e-07" iyz="4.0531825102560710826e-13" izz="8.370487995094977082e-07" />
    </inertial>
  </link>

  <joint name="left_knee_back_rev_1" type="revolute">
    <origin xyz="-0.013858192987669298857 0.0057402514854763275753 0.004999999999999997502" rpy="-3.1415926535897922278 -5.1262553044799649998e-16 -3.1411805634845886281" />
    <parent link="xm430_plate" />
    <child link="knee_rod_2" />
    <axis xyz="0 0 1" />
    <limit effort="1" velocity="20" />
    <joint_properties friction="0.0" />
  </joint>

  <joint name="left_knee_act" type="revolute">
    <origin xyz="-8.1760517882940177631e-17 0.012450000000000002731 0.044500000000000004829" rpy="-1.5707963267948956698 1.5707963267948945596 0" />
    <parent link="left_hip_pitch_link" />
    <child link="xm430_plate" />
    <axis xyz="0 0 1" />
    <limit effort="1" velocity="20" lower="-2.0943951023931952626" upper="0" />
    <joint_properties friction="0.0" />
  </joint>

  <joint name="left_hip_yaw_driven" type="revolute">
    <origin xyz="-2.2803452489262563112e-16 -1.7000290064572709525e-15 -0.0049999999999998517852" rpy="3.141592653589793116 1.4731306807441078531e-15 -2.0440645018593486108e-16" />
    <parent link="spur_gear_21_teeth" />
    <child link="left_hip_pitch_link" />
    <axis xyz="0 0 1" />
    <limit effort="1" velocity="20" lower="-1.570796326794896558" upper="1.570796326794896558" />
    <joint_properties friction="0.0" />
  </joint>

  <joint name="left_hip_yaw_fixed" type="fixed">
    <origin xyz="-3.4694469519536141888e-18 -0.027999999999999993644 -0.018999999999999999528" rpy="-1.57079632679489678 1.5707963267948958919 0" />
    <parent link="hip_yaw_link" />
    <child link="spur_gear_21_teeth" />
    <axis xyz="0 0 1" />
    <limit effort="1" velocity="20" />
    <joint_properties friction="0.0" />
  </joint>

  <joint name="left_hip_roll" type="revolute">
    <origin xyz="-0.024000000716153727098 0.019000000152473658227 0.019000000152446051838" rpy="-1.5707963267952185227 -1.5707963267948228392 0" />
    <parent link="2xc430" />
    <child link="hip_yaw_link" />
    <axis xyz="0 0 1" />
    <limit effort="1" velocity="20" lower="-0.785398163397448279" upper="0.785398163397448279" />
    <joint_properties friction="0.0" />
  </joint>


  <link name="2xc430_2">
    <visual>
      <origin xyz="0 0 0" rpy="0 -0 0" />
      <geometry>
        <mesh filename="../assemblies/right_leg_reorder/meshes/right_2xc430_visual.stl" />
      </geometry>
      <material name="2xc430_material">
        <color rgba="0.51698661238356047321 0.50347815951093488618 0.49050589017722012741 1.0" />
      </material>
    </visual>
    <inertial>
      <origin xyz="-0.012000151133958485497 0.00049588831385534372538 0.018504019244502768748" rpy="0 0 0" />
      <mass value="0.11059999999836234164" />
      <inertia ixx="2.2818802599017520627e-05" ixy="4.6888548258513342481e-08" ixz="4.6520143290236539089e-08" iyy="3.0871666424468184478e-05" iyz="-5.7477343899707772189e-07" izz="3.0871632082337564101e-05" />
    </inertial>
  </link>

  <link name="hip_yaw_link_2">
    <visual>
      <origin xyz="0 0 0" rpy="0 -0 0" />
      <geometry>
        <mesh filename="../assemblies/right_leg_reorder/meshes/right_hip_yaw_link_visual.stl" />
      </geometry>
      <material name="hip_yaw_link_material">
        <color rgba="0.61568627450980406568 0.81176470588235294379 0.92941176470588238168 1.0" />
      </material>
    </visual>
    <inertial>
      <origin xyz="-2.3680216970514856051e-18 -0.015800610849654270207 -0.019005670096647751116" rpy="0 0 0" />
      <mass value="0.013199999999999996458" />
      <inertia ixx="5.789461597517412337e-06" ixy="-2.3742250663695664173e-35" ixz="-4.6269596476444098615e-35" iyy="5.0110144042848767847e-06" iyz="1.1826010760651343791e-09" izz="2.7344876354814335894e-06" />
    </inertial>
  </link>

  <link name="spur_gear_21_teeth_2">
    <visual>
      <origin xyz="0 0 0" rpy="0 -0 0" />
      <geometry>
        <mesh filename="../assemblies/right_leg_reorder/meshes/right_spur_gear_21_teeth_visual.stl" />
      </geometry>
      <material name="spur_gear_21_teeth_material">
        <color rgba="0.61568627450980395466 0.81176470588235294379 0.9294117647058824927 1.0" />
      </material>
    </visual>
    <inertial>
      <origin xyz="-4.5505289258681524915e-11 -1.678216713560055111e-11 -0.00249241020062506086" rpy="0 0 0" />
      <mass value="0.0022000000000000001325" />
      <inertia ixx="7.0162310059594183647e-08" ixy="-1.0728762253388190285e-37" ixz="3.6792812770337103725e-37" iyy="7.016231005804746178e-08" iyz="-3.0947447157486108646e-37" izz="1.3125544198538289306e-07" />
    </inertial>
  </link>

  <link name="right_hip_pitch_link">
    <visual>
      <origin xyz="0 0 0" rpy="0 -0 0" />
      <geometry>
        <mesh filename="../assemblies/right_leg_reorder/meshes/right_hip_pitch_link_visual.stl" />
      </geometry>
      <material name="right_hip_pitch_link_material">
        <color rgba="0.81231119922470318429 0.71311588921073154612 0.33680089849959454762 1.0" />
      </material>
    </visual>
    <inertial>
      <origin xyz="0.010187905578010039709 -0.0056188467228507526022 0.038815928333491248048" rpy="0 0 0" />
      <mass value="0.14548965119785953193" />
      <inertia ixx="7.0942049594862667018e-05" ixy="1.1158758975156964251e-06" ixz="7.6515558781276520701e-06" iyy="8.5157398802910574216e-05" iyz="1.0699337399079342026e-06" izz="4.0945306935230637994e-05" />
    </inertial>
  </link>

  <link name="spur_gear_18_teeth_2">
    <visual>
      <origin xyz="0 0 0" rpy="0 -0 0" />
      <geometry>
        <mesh filename="../assemblies/right_leg_reorder/meshes/right_spur_gear_18_teeth_visual.stl" />
      </geometry>
      <material name="spur_gear_18_teeth_material">
        <color rgba="0.61568627450980395466 0.81176470588235294379 0.92941176470588238168 1.0" />
      </material>
    </visual>
    <inertial>
      <origin xyz="-1.2350763045112093776e-14 -3.7635594904468420162e-13 0.0017500000000010207044" rpy="0 0 0" />
      <mass value="0.001199999999999999678" />
      <inertia ixx="2.9367899810676089115e-08" ixy="1.4794421482005667013e-36" ixz="7.9290692005870371421e-37" iyy="2.9367899814783318789e-08" iyz="1.0883211322458962962e-38" izz="5.6306346207859581581e-08" />
    </inertial>
  </link>

  <joint name="right_hip_yaw_drive" type="revolute">
    <origin xyz="0.019199999999998797889 0.00020000000000076900708 -3.943373405590477887e-14" rpy="-3.1415926535897589211 -2.643383809745412699e-13 4.477396955646764347e-13" />
    <parent link="right_hip_pitch_link" />
    <child link="spur_gear_18_teeth_2" />
    <axis xyz="0 0 1" />
    <limit effort="1" velocity="20" lower="-1.8325957145940461324" upper="1.8325957145940461324" />
    <joint_properties friction="0.0" />
  </joint>

  <link name="right_calf_link">
    <visual>
      <origin xyz="0 0 0" rpy="0 -0 0" />
      <geometry>
        <mesh filename="../assemblies/right_leg_reorder/meshes/right_calf_link_visual.stl" />
      </geometry>
      <material name="right_calf_link_material">
        <color rgba="0.522707147375079062 0.70740037950664136357 0.87533206831119547697 1.0" />
      </material>
    </visual>
    <inertial>
      <origin xyz="-0.0043450054394403450977 -0.040752982164757971251 0.008711609351474625812" rpy="0 0 0" />
      <mass value="0.03099999999999998937" />
      <inertia ixx="3.3069388685437017383e-05" ixy="1.3783307152004750509e-06" ixz="-1.2742534017146433063e-07" iyy="7.7316525337488462591e-06" iyz="7.3356500737895901032e-08" izz="2.803137775421218791e-05" />
    </inertial>
  </link>

  <link name="bearing_683_5">
    <visual>
      <origin xyz="0 0 0" rpy="0 -0 0" />
      <geometry>
        <mesh filename="../assemblies/right_leg_reorder/meshes/right_bearing_683_visual.stl" />
      </geometry>
      <material name="bearing_683_material">
        <color rgba="0.64705882352941179736 0.64705882352941179736 0.64705882352941179736 1.0" />
      </material>
    </visual>
    <inertial>
      <origin xyz="1.0732094295238145686e-19 -1.1092294808200013797e-18 -0.0015500000000000003792" rpy="0 0 0" />
      <mass value="0.00048694686130641793437" />
      <inertia ixx="2.1551456503319887385e-09" ixy="-6.6668633173968480065e-29" ixz="-6.6976010977422784746e-39" iyy="2.1551456503319883249e-09" iyz="-4.8570566893029709752e-40" izz="3.5303647444715305817e-09" />
    </inertial>
  </link>

  <joint name="right_knee_front_rev_2" type="revolute">
    <origin xyz="0.0057402514854742034064 -0.013858192987668938034 0.026200000000000018413" rpy="3.1415926535897722438 4.7179996935925796538e-15 1.5711344860216869268" />
    <parent link="right_calf_link" />
    <child link="bearing_683_5" />
    <axis xyz="0 0 1" />
    <limit effort="1" velocity="20" />
    <joint_properties friction="0.0" />
  </joint>

  <link name="bearing_683_6">
    <visual>
      <origin xyz="0 0 0" rpy="0 -0 0" />
      <geometry>
        <mesh filename="../assemblies/right_leg_reorder/meshes/right_bearing_683_2_visual.stl" />
      </geometry>
      <material name="bearing_683_2_material">
        <color rgba="0.64705882352941179736 0.64705882352941179736 0.64705882352941179736 1.0" />
      </material>
    </visual>
    <inertial>
      <origin xyz="-2.7648254672676526986e-17 -2.4186774283158136577e-19 -0.0015499999999999934403" rpy="0 0 0" />
      <mass value="0.00048694686130641793437" />
      <inertia ixx="2.1551456503319887385e-09" ixy="-5.0577878161698648695e-28" ixz="-3.3157168302044051229e-38" iyy="2.1551456503319883249e-09" iyz="-8.7202057003503599374e-39" izz="3.5303647444715305817e-09" />
    </inertial>
  </link>

  <joint name="right_knee_back_rev_2" type="revolute">
    <origin xyz="-0.0057402514854791031329 0.013858192987669687435 0.026199999999999560446" rpy="3.1415926535897704674 4.4232680729280782694e-15 1.5695900556931696723" />
    <parent link="right_calf_link" />
    <child link="bearing_683_6" />
    <axis xyz="0 0 1" />
    <limit effort="1" velocity="20" />
    <joint_properties friction="0.0" />
  </joint>

  <link name="right_ank_pitch_link">
    <visual>
      <origin xyz="0 0 0" rpy="0 -0 0" />
      <geometry>
        <mesh filename="../assemblies/right_leg_reorder/meshes/right_ank_pitch_link_visual.stl" />
      </geometry>
      <material name="right_ank_pitch_link_material">
        <color rgba="0.70321688500203327621 0.64514870846184457776 0.40484735422826284568 1.0" />
      </material>
    </visual>
    <inertial>
      <origin xyz="-0.017770241889542386787 0.012301334508572413923 0.018814514831173637793" rpy="0 0 0" />
      <mass value="0.17676376695067899658" />
      <inertia ixx="4.7283381546856725626e-05" ixy="1.3380598207247547293e-06" ixz="6.1532628607415478866e-07" iyy="0.00010706462535916967086" iyz="-5.1080086246313117039e-08" izz="0.00012185522398303564185" />
    </inertial>
  </link>

  <link name="ank_roll_link_2">
    <visual>
      <origin xyz="0 0 0" rpy="0 -0 0" />
      <geometry>
        <mesh filename="../assemblies/right_leg_reorder/meshes/right_ank_roll_link_visual.stl" />
      </geometry>
      <material name="ank_roll_link_material">
        <color rgba="0.61568627450980395466 0.81176470588235294379 0.92941176470588238168 1.0" />
      </material>
    </visual>
    <collision name="ank_roll_link_2_collision">
      <origin xyz="-0.014500000514090061 0.0 0.038999998942017555" rpy="0 0 0" />
      <geometry>
        <box size="0.04900000058114529 0.041999999433755875 0.12000000104308128" />
      </geometry>
    </collision>
    <inertial>
      <origin xyz="-0.027003372529275638386 -2.0047365059511700993e-12 0.03375858214582954514" rpy="0 0 0" />
      <mass value="0.042599999999999998979" />
      <inertia ixx="3.727366167060638106e-05" ixy="-5.514854815452962146e-16" ixz="2.3913171754435894846e-06" iyy="3.7580160445155685683e-05" iyz="5.0909541761820397003e-12" izz="1.008908650919919904e-05" />
    </inertial>
  </link>

  <joint name="right_ank_roll" type="revolute">
    <origin xyz="-0.022749999999988695931 -2.8033131371785202646e-15 0.018999999999998594402" rpy="1.5707963267948541475 5.4379089279736669552e-14 1.5707963267948139574" />
    <parent link="right_ank_pitch_link" />
    <child link="ank_roll_link_2" />
    <axis xyz="0 0 1" />
    <limit effort="1" velocity="20" lower="-1.570796326794896558" upper="1.570796326794896558" />
    <joint_properties friction="0.0" />
  </joint>

  <joint name="right_ank_pitch" type="revolute">
    <origin xyz="1.8856446270430988281e-16 -0.1000000000000017264 0.027749999999999722805" rpy="-3.141592653589788231 1.6734050971461921911e-16 -3.141592653589773132" />
    <parent link="right_calf_link" />
    <child link="right_ank_pitch_link" />
    <axis xyz="0 0 1" />
    <limit effort="1" velocity="20" lower="-0.785398163397448279" upper="1.7453292519943295336" />
    <joint_properties friction="0.0" />
  </joint>

  <joint name="right_knee" type="revolute">
    <origin xyz="7.4144790566904459971e-16 -0.0087499999999997232769 0.085949999999999721068" rpy="-1.5707963267948890085 -2.3653471613308375613e-14 -2.1214286820220117449e-14" />
    <parent link="right_hip_pitch_link" />
    <child link="right_calf_link" />
    <axis xyz="0 0 1" />
    <limit effort="1" velocity="20" lower="0" upper="2.0943951023931952626" />
    <joint_properties friction="0.0" />
  </joint>

  <link name="xm430_plate_2">
    <visual>
      <origin xyz="0 0 0" rpy="0 -0 0" />
      <geometry>
        <mesh filename="../assemblies/right_leg_reorder/meshes/right_xm430_plate_visual.stl" />
      </geometry>
      <material name="xm430_plate_material">
        <color rgba="0.61568627450980395466 0.81176470588235294379 0.92941176470588227065 1.0" />
      </material>
    </visual>
    <inertial>
      <origin xyz="-1.0043676434814568214e-18 -2.5603431127106792562e-18 0.0025278513919583817798" rpy="0 0 0" />
      <mass value="0.0026999999999999997093" />
      <inertia ixx="2.4635091298412534083e-07" ixy="5.8739562556303533743e-08" ixz="-2.7967409611692880242e-37" iyy="1.2887178787151819394e-07" iyz="-3.77804175844762081e-37" izz="3.6467998413810316538e-07" />
    </inertial>
  </link>

  <link name="knee_rod_3">
    <visual>
      <origin xyz="0 0 0" rpy="0 -0 0" />
      <geometry>
        <mesh filename="../assemblies/right_leg_reorder/meshes/right_knee_rod_visual.stl" />
      </geometry>
      <material name="knee_rod_material">
        <color rgba="0.62051618944235198416 0.78640765248647581664 0.88594253031295022716 1.0" />
      </material>
    </visual>
    <inertial>
      <origin xyz="0.017534310910028324398 1.1858779168447744682e-05 -0.0015987301647643213567" rpy="0 0 0" />
      <mass value="0.0031629468613064179276" />
      <inertia ixx="2.4224310081263181531e-08" ixy="-1.19678473801420875e-10" ixz="4.9178348498762066929e-10" iyy="8.1758895033324653827e-07" iyz="3.3260227710126747967e-13" izz="8.3704877987922338784e-07" />
    </inertial>
  </link>

  <joint name="right_knee_front_rev_1" type="revolute">
    <origin xyz="0.0057402514854760404786 -0.01385819298766884089 0.0049999999999999281131" rpy="-3.1415926535897917837 -5.7384150695760960971e-15 -1.5704581675681277275" />
    <parent link="xm430_plate_2" />
    <child link="knee_rod_3" />
    <axis xyz="0 0 1" />
    <limit effort="1" velocity="20" />
    <joint_properties friction="0.0" />
  </joint>

  <link name="knee_rod_4">
    <visual>
      <origin xyz="0 0 0" rpy="0 -0 0" />
      <geometry>
        <mesh filename="../assemblies/right_leg_reorder/meshes/right_knee_rod_2_visual.stl" />
      </geometry>
      <material name="knee_rod_2_material">
        <color rgba="0.62051618944235198416 0.78640765248647581664 0.88594253031295022716 1.0" />
      </material>
    </visual>
    <inertial>
      <origin xyz="0.017534287401105769222 -4.2302259657894445127e-05 -0.001598730164764422838" rpy="0 0 0" />
      <mass value="0.0031629468613064179276" />
      <inertia ixx="2.4225259086578056615e-08" ixy="4.2691267073938188428e-10" ixz="4.917828256368548348e-10" iyy="8.1758847583071986475e-07" iyz="-1.1864482602679777848e-12" izz="8.37049254382039429e-07" />
    </inertial>
  </link>

  <joint name="right_knee_back_rev_1" type="revolute">
    <origin xyz="-0.0057402514854762495128 0.013858192987669562535 0.0049999999999996921907" rpy="-3.1415926535897917837 -3.1239953065292545287e-15 -1.5720025978966456481" />
    <parent link="xm430_plate_2" />
    <child link="knee_rod_4" />
    <axis xyz="0 0 1" />
    <limit effort="1" velocity="20" />
    <joint_properties friction="0.0" />
  </joint>

  <joint name="right_knee_act" type="revolute">
    <origin xyz="-4.764191144156372037e-16 0.012449999999999978445 0.044499999999999984013" rpy="-1.5707963267948896746 -7.8970061496179386992e-16 -1.0625962670360234042e-15" />
    <parent link="right_hip_pitch_link" />
    <child link="xm430_plate_2" />
    <axis xyz="0 0 1" />
    <limit effort="1" velocity="20" lower="0" upper="2.0943951023931952626" />
    <joint_properties friction="0.0" />
  </joint>

  <joint name="right_hip_yaw_driven" type="revolute">
    <origin xyz="8.9193874740282010951e-19 -5.898059818321144121e-17 -0.0050000000000000391354" rpy="-3.1415926535897913396 7.6695369178734709544e-15 -3.2818087594098245613e-16" />
    <parent link="spur_gear_21_teeth_2" />
    <child link="right_hip_pitch_link" />
    <axis xyz="0 0 1" />
    <limit effort="1" velocity="20" lower="-1.570796326794896558" upper="1.570796326794896558" />
    <joint_properties friction="0.0" />
  </joint>

  <joint name="right_hip_yaw_fixed" type="fixed">
    <origin xyz="-1.0408340855860842566e-17 -0.027999999999999997113 -0.018999999999999992589" rpy="-1.5707963267948972241 1.5707963267948925612 0" />
    <parent link="hip_yaw_link_2" />
    <child link="spur_gear_21_teeth_2" />
    <axis xyz="0 0 1" />
    <limit effort="1" velocity="20" />
    <joint_properties friction="0.0" />
  </joint>

  <joint name="right_hip_roll" type="revolute">
    <origin xyz="-0.024000000716143103652 0.019000000152447567986 0.019000000152446624296" rpy="-1.5707963267948352737 -1.5707963267948257258 0" />
    <parent link="2xc430_2" />
    <child link="hip_yaw_link_2" />
    <axis xyz="0 0 1" />
    <limit effort="1" velocity="20" lower="-0.785398163397448279" upper="0.785398163397448279" />
    <joint_properties friction="0.0" />
  </joint>


  <link name="sho_pitch_link">
    <visual>
      <origin xyz="0 0 0" rpy="0 -0 0" />
      <geometry>
        <mesh filename="../assemblies/left_arm_gripper/meshes/left_sho_pitch_link_visual.stl" />
      </geometry>
      <material name="sho_pitch_link_material">
        <color rgba="0.61568627450980395466 0.81176470588235294379 0.92941176470588227065 1.0" />
      </material>
    </visual>
    <inertial>
      <origin xyz="5.8254246873150788375e-11 -5.126464256112076923e-05 0.0082440788127094623977" rpy="0 0 0" />
      <mass value="0.0085999999999999982708" />
      <inertia ixx="1.227288704054570717e-06" ixy="-2.1429936846936260149e-14" ixz="-8.5847198037466179854e-15" iyy="2.91073060603644168e-06" iyz="7.4623841398182339547e-09" izz="3.0803135950773271699e-06" />
    </inertial>
  </link>

  <link name="2xl430_gears">
    <visual>
      <origin xyz="0 0 0" rpy="0 -0 0" />
      <geometry>
        <mesh filename="../assemblies/left_arm_gripper/meshes/left_2xl430_gears_visual.stl" />
      </geometry>
      <material name="2xl430_gears_material">
        <color rgba="0.75605985687944088358 0.8580469596269301169 0.91320266199377464478 1.0" />
      </material>
    </visual>
    <inertial>
      <origin xyz="-0.011593155021925307877 -0.0024238821558110034554 -0.018551095523803389636" rpy="0 0 0" />
      <mass value="0.11800003674524907338" />
      <inertia ixx="2.751155493265798339e-05" ixy="8.9994756795164863381e-07" ixz="-2.3362914880703854757e-08" iyy="3.2796647067986400479e-05" iyz="-6.5715261571594833988e-07" izz="3.5775886684228084308e-05" />
    </inertial>
  </link>

  <link name="spur_1m_24t_drive">
    <visual>
      <origin xyz="0 0 0" rpy="0 -0 0" />
      <geometry>
        <mesh filename="../assemblies/left_arm_gripper/meshes/left_spur_1m_24t_drive_visual.stl" />
      </geometry>
      <material name="spur_1m_24t_drive_material">
        <color rgba="0.61568627450980406568 0.81176470588235294379 0.92941176470588238168 1.0" />
      </material>
    </visual>
    <inertial>
      <origin xyz="-7.751924474065288114e-15 -1.2114309579847422764e-16 0.0047949116178401416863" rpy="0 0 0" />
      <mass value="0.0032000000000000001533" />
      <inertia ixx="1.4019331346159890349e-07" ixy="1.6002410034001928083e-15" ixz="1.5136309552610142149e-39" iyy="1.4019331260388783538e-07" iyz="6.9662242597476870103e-37" izz="2.3838919844264060647e-07" />
    </inertial>
  </link>

  <joint name="left_sho_yaw_drive" type="revolute">
    <origin xyz="-0.024000000716138950724 -0.019000000152455242403 -0.019000000152449656593" rpy="1.5707963267949347497 -1.1101908380030466199e-13 1.6989069920292087694e-13" />
    <parent link="2xl430_gears" />
    <child link="spur_1m_24t_drive" />
    <axis xyz="0 0 1" />
    <limit effort="1" velocity="20" lower="-2.6179938779914944114" upper="2.6179938779914944114" />
    <joint_properties friction="0.0" />
  </joint>

  <link name="spur_1m_24t_driven">
    <visual>
      <origin xyz="0 0 0" rpy="0 -0 0" />
      <geometry>
        <mesh filename="../assemblies/left_arm_gripper/meshes/left_spur_1m_24t_driven_visual.stl" />
      </geometry>
      <material name="spur_1m_24t_driven_material">
        <color rgba="0.23137254901960788156 0.38039215686274502337 0.7058823529411765163 1.0" />
      </material>
    </visual>
    <inertial>
      <origin xyz="5.7091470979890261114e-18 -5.804960647391017135e-15 -0.00097054817521927832808" rpy="0 0 0" />
      <mass value="0.0026999999999999997093" />
      <inertia ixx="1.2036234079571065709e-07" ixy="1.6408341064672930469e-66" ixz="2.2551452241402898336e-55" iyy="1.203623407957104718e-07" iyz="2.7479639504561275735e-37" izz="2.2847261745924535316e-07" />
    </inertial>
  </link>

  <link name="sho_yaw_link">
    <visual>
      <origin xyz="0 0 0" rpy="0 -0 0" />
      <geometry>
        <mesh filename="../assemblies/left_arm_gripper/meshes/left_sho_yaw_link_visual.stl" />
      </geometry>
      <material name="sho_yaw_link_material">
        <color rgba="0.61568627450980395466 0.81176470588235294379 0.92941176470588238168 1.0" />
      </material>
    </visual>
    <inertial>
      <origin xyz="-4.751203379950773447e-18 4.0208771290527341071e-18 -0.024303257848520172513" rpy="0 0 0" />
      <mass value="0.014500000000000012879" />
      <inertia ixx="9.0846670053041365841e-06" ixy="3.6224092806453171386e-13" ixz="5.9333186453476727638e-36" iyy="5.6910950712097533498e-06" iyz="-1.9029679338117402528e-35" izz="4.48196098455489844e-06" />
    </inertial>
  </link>

  <link name="2xl430_gears_2">
    <visual>
      <origin xyz="0 0 0" rpy="0 -0 0" />
      <geometry>
        <mesh filename="../assemblies/left_arm_gripper/meshes/left_2xl430_gears_2_visual.stl" />
      </geometry>
      <material name="2xl430_gears_2_material">
        <color rgba="0.75605985687944088358 0.8580469596269301169 0.91320266199377464478 1.0" />
      </material>
    </visual>
    <inertial>
      <origin xyz="-0.011593155021926340037 -0.002423882155816466967 -0.018551095523806168663" rpy="0 0 0" />
      <mass value="0.11800003674524907338" />
      <inertia ixx="2.7511554932663722885e-05" ixy="8.9994756795153809601e-07" ixz="-2.3362914880347826295e-08" iyy="3.2796647067987172973e-05" iyz="-6.5715261571566765433e-07" izz="3.5775886684234135511e-05" />
    </inertial>
  </link>

  <link name="spur_1m_24t_drive_2">
    <visual>
      <origin xyz="0 0 0" rpy="0 -0 0" />
      <geometry>
        <mesh filename="../assemblies/left_arm_gripper/meshes/left_spur_1m_24t_drive_2_visual.stl" />
      </geometry>
      <material name="spur_1m_24t_drive_2_material">
        <color rgba="0.61568627450980406568 0.81176470588235294379 0.92941176470588238168 1.0" />
      </material>
    </visual>
    <inertial>
      <origin xyz="-7.7519244740652865362e-15 -1.2114309579847422764e-16 0.0047949116178401382168" rpy="0 0 0" />
      <mass value="0.0032000000000000001533" />
      <inertia ixx="1.4019331346159885055e-07" ixy="1.6002410034284993069e-15" ixz="-3.2416262881106824717e-38" iyy="1.4019331260388783538e-07" iyz="4.1976192478617136215e-37" izz="2.3838919844264060647e-07" />
    </inertial>
  </link>

  <joint name="left_elbow_yaw_drive" type="revolute">
    <origin xyz="-0.02400000071614135505 -0.019000000152460394531 -0.019000000152444573853" rpy="1.5707963267946161157 -5.9253031636290665624e-14 1.2139740875094224707e-13" />
    <parent link="2xl430_gears_2" />
    <child link="spur_1m_24t_drive_2" />
    <axis xyz="0 0 1" />
    <limit effort="1" velocity="20" lower="-2.6179938779914944114" upper="2.6179938779914944114" />
    <joint_properties friction="0.0" />
  </joint>

  <link name="spur_1m_24t_driven_2">
    <visual>
      <origin xyz="0 0 0" rpy="0 -0 0" />
      <geometry>
        <mesh filename="../assemblies/left_arm_gripper/meshes/left_spur_1m_24t_driven_2_visual.stl" />
      </geometry>
      <material name="spur_1m_24t_driven_2_material">
        <color rgba="0.23137254901960788156 0.38039215686274502337 0.7058823529411765163 1.0" />
      </material>
    </visual>
    <inertial>
      <origin xyz="5.7091470979893912677e-18 -5.8049606473910179238e-15 -0.00097054817521925740298" rpy="0 0 0" />
      <mass value="0.0026999999999999997093" />
      <inertia ixx="1.2036234079571065709e-07" ixy="-5.3408894126442329247e-38" ixz="3.3351189727368676324e-36" iyy="1.203623407957104718e-07" iyz="3.0056945361268646547e-36" izz="2.2847261745924535316e-07" />
    </inertial>
  </link>

  <link name="elb_yaw_link">
    <visual>
      <origin xyz="0 0 0" rpy="0 -0 0" />
      <geometry>
        <mesh filename="../assemblies/left_arm_gripper/meshes/left_elb_yaw_link_visual.stl" />
      </geometry>
      <material name="elb_yaw_link_material">
        <color rgba="0.61568627450980395466 0.81176470588235294379 0.92941176470588227065 1.0" />
      </material>
    </visual>
    <inertial>
      <origin xyz="5.3127688027384996195e-08 0.0019833638641961696264 -0.023416643551549952418" rpy="0 0 0" />
      <mass value="0.017500000000000001665" />
      <inertia ixx="1.4134344903109199776e-05" ixy="1.6945783921921611363e-12" ixz="-1.1286398721829634941e-11" iyy="6.6435900776211331934e-06" iyz="1.0545227077253057579e-06" izz="8.9925290757998976773e-06" />
    </inertial>
  </link>

  <link name="spur_1m_24t_driven_3">
    <visual>
      <origin xyz="0 0 0" rpy="0 -0 0" />
      <geometry>
        <mesh filename="../assemblies/left_arm_gripper/meshes/left_spur_1m_24t_driven_3_visual.stl" />
      </geometry>
      <material name="spur_1m_24t_driven_3_material">
        <color rgba="0.23137254901960788156 0.38039215686274502337 0.7058823529411765163 1.0" />
      </material>
    </visual>
    <inertial>
      <origin xyz="2.2397001460354111522e-18 -5.8049606473910210793e-15 -0.0025705481752192754774" rpy="0 0 0" />
      <mass value="0.0026999999999999997093" />
      <inertia ixx="1.2036234079571065709e-07" ixy="2.1796004720792485879e-36" ixz="0" iyy="1.203623407957104718e-07" iyz="0" izz="2.2847261745924535316e-07" />
    </inertial>
  </link>

  <link name="2xl430_gears_3">
    <visual>
      <origin xyz="0 0 0" rpy="0 -0 0" />
      <geometry>
        <mesh filename="../assemblies/left_arm_gripper/meshes/left_2xl430_gears_3_visual.stl" />
      </geometry>
      <material name="2xl430_gears_3_material">
        <color rgba="0.75605985687944088358 0.8580469596269301169 0.91320266199377464478 1.0" />
      </material>
    </visual>
    <inertial>
      <origin xyz="0.00044890447619516156029 0.011593154663849485411 -0.024576117996641503455" rpy="0 0 0" />
      <mass value="0.11800003674524907338" />
      <inertia ixx="3.5775886684226098863e-05" ixy="2.3362914880997275572e-08" ixz="6.5715261571779836571e-07" iyy="2.7511554932658664405e-05" iyz="8.9994756794793968829e-07" izz="3.2796647067986251401e-05" />
    </inertial>
  </link>

  <link name="spur_1m_24t_drive_3">
    <visual>
      <origin xyz="0 0 0" rpy="0 -0 0" />
      <geometry>
        <mesh filename="../assemblies/left_arm_gripper/meshes/left_spur_1m_24t_drive_3_visual.stl" />
      </geometry>
      <material name="spur_1m_24t_drive_3_material">
        <color rgba="0.61568627450980406568 0.81176470588235294379 0.92941176470588238168 1.0" />
      </material>
    </visual>
    <inertial>
      <origin xyz="-7.7519244740652865362e-15 -1.211430957726248335e-16 0.0047949116178401416863" rpy="0 0 0" />
      <mass value="0.0032000000000000001533" />
      <inertia ixx="1.4019331346159885055e-07" ixy="1.6002410034284993069e-15" ixz="2.2014519551203998152e-37" iyy="1.4019331260388783538e-07" iyz="3.8157944246850799043e-36" izz="2.3838919844264060647e-07" />
    </inertial>
  </link>

  <joint name="left_wrist_pitch_drive" type="revolute">
    <origin xyz="-1.524465101755677821e-10 0.024000000358068068751 -0.0080000000000026785796" rpy="-3.4898578787177992303e-14 -1.1183585769436423028e-13 -1.5707963267948532593" />
    <parent link="2xl430_gears_3" />
    <child link="spur_1m_24t_drive_3" />
    <axis xyz="0 0 1" />
    <limit effort="1" velocity="20" lower="-1.9198621771937625091" upper="1.3962634015954635824" />
    <joint_properties friction="0.0" />
  </joint>

  <link name="gripper_connector">
    <visual>
      <origin xyz="0 0 0" rpy="0 -0 0" />
      <geometry>
        <mesh filename="../assemblies/left_arm_gripper/meshes/left_gripper_connector_visual.stl" />
      </geometry>
      <material name="gripper_connector_material">
        <color rgba="0.61568627450980395466 0.81176470588235294379 0.92941176470588227065 1.0" />
      </material>
    </visual>
    <inertial>
      <origin xyz="-0.00020216391502726472869 -0.024011997737921234736 -0.008709915010078308345" rpy="0 0 0" />
      <mass value="0.0099999999999999880651" />
      <inertia ixx="5.3138306577478889962e-06" ixy="-2.3224171675565346272e-08" ixz="-4.7690345371182966176e-08" iyy="3.8402250096486075095e-06" iyz="8.1160112886319393595e-09" izz="2.257315404231779922e-06" />
    </inertial>
  </link>

  <link name="left_rail_guide">
    <visual>
      <origin xyz="0 0 0" rpy="0 -0 0" />
      <geometry>
        <mesh filename="../assemblies/left_arm_gripper/meshes/left_rail_guide_visual.stl" />
      </geometry>
      <material name="left_rail_guide_material">
        <color rgba="0.62010923588394006867 0.81391948193641916465 0.93009222030190319419 1.0" />
      </material>
    </visual>
    <inertial>
      <origin xyz="0.010819518839780863095 0.0021116106205359610332 -7.6871709864948780874e-05" rpy="0 0 0" />
      <mass value="0.031121017612416677217" />
      <inertia ixx="7.8532725551086577254e-06" ixy="2.0671876731375216749e-06" ixz="4.0098876287871823871e-06" iyy="2.7330594711584456634e-05" iyz="-8.9062740055664990295e-07" izz="3.0532648647413083228e-05" />
    </inertial>
  </link>

  <link name="rail">
    <visual>
      <origin xyz="0 0 0" rpy="0 -0 0" />
      <geometry>
        <mesh filename="../assemblies/left_arm_gripper/meshes/left_rail_visual.stl" />
      </geometry>
      <material name="rail_material">
        <color rgba="0.64705882352941179736 0.64705882352941179736 0.64705882352941179736 1.0" />
      </material>
    </visual>
    <inertial>
      <origin xyz="0.029554714214719193105 -0.015933051259988686987 -0.010638774525132295434" rpy="0 0 0" />
      <mass value="0.017100000000000000616" />
      <inertia ixx="3.6591938331681695171e-06" ixy="2.1013138412446668144e-08" ixz="-1.1335092663308587465e-07" iyy="4.7380338190523256316e-06" iyz="3.1225833654311333417e-08" izz="6.0956112819844617947e-06" />
    </inertial>
  </link>

  <joint name="left_gripper_pinion" type="prismatic">
    <origin xyz="-0.028871320518249775355 -0.015974999999999996148 -0.0053499999999999936495" rpy="3.141592653589793116 1.570796326794896558 0" />
    <parent link="left_rail_guide" />
    <child link="rail" />
    <axis xyz="0 0 1" />
    <limit effort="1" velocity="20" lower="-0.025000000000000001388" upper="0" />
    <joint_properties friction="0.0" />
  </joint>

  <link name="rail_2">
    <visual>
      <origin xyz="0 0 0" rpy="0 -0 0" />
      <geometry>
        <mesh filename="../assemblies/left_arm_gripper/meshes/left_rail_2_visual.stl" />
      </geometry>
      <material name="rail_2_material">
        <color rgba="0.64705882352941179736 0.64705882352941179736 0.64705882352941179736 1.0" />
      </material>
    </visual>
    <inertial>
      <origin xyz="0.029554714214719193105 -0.015933051259988697396 -0.010638774525132281557" rpy="0 0 0" />
      <mass value="0.017100000000000000616" />
      <inertia ixx="3.6591938331681695171e-06" ixy="2.1013138412446668144e-08" ixz="-1.1335092663308587465e-07" iyy="4.7380338190523256316e-06" iyz="3.1225833654311333417e-08" izz="6.0956112819844617947e-06" />
    </inertial>
  </link>

  <joint name="left_gripper_pinion_mirror" type="prismatic">
    <origin xyz="0.062871320518249770859 0.015974999999999985739 -0.0053500000000000214051" rpy="1.1102230221252498237e-15 1.5707963267948945596 0" />
    <parent link="left_rail_guide" />
    <child link="rail_2" />
    <axis xyz="0 0 1" />
    <limit effort="1" velocity="20" lower="-0.025000000000000001388" upper="0" />
    <joint_properties friction="0.0" />
  </joint>

  <link name="xc330">
    <visual>
      <origin xyz="0 0 0" rpy="0 -0 0" />
      <geometry>
        <mesh filename="../assemblies/left_arm_gripper/meshes/left_xc330_visual.stl" />
      </geometry>
      <material name="xc330_material">
        <color rgba="0.66932535752643773641 0.72911795671409962427 0.67547870389434394589 1.0" />
      </material>
    </visual>
    <inertial>
      <origin xyz="0.0080045171539631868735 -0.01555800985163530159 -0.011717805512819572805" rpy="0 0 0" />
      <mass value="0.026599999993091753836" />
      <inertia ixx="3.8683410666516236946e-06" ixy="-7.7688424002135933017e-10" ixz="5.7969695829235746263e-10" iyy="2.1626767907496969398e-06" iyz="8.3590274790162570258e-09" izz="3.3158761130056377969e-06" />
    </inertial>
  </link>

  <link name="spur_gear_(18_teeth)">
    <visual>
      <origin xyz="0 0 0" rpy="0 -0 0" />
      <geometry>
        <mesh filename="../assemblies/left_arm_gripper/meshes/left_spur_gear_(18_teeth)_visual.stl" />
      </geometry>
      <material name="spur_gear_(18_teeth)_material">
        <color rgba="0.9176470588235294823 0.9176470588235294823 0.9176470588235294823 1.0" />
      </material>
    </visual>
    <inertial>
      <origin xyz="5.0306980803327405738e-17 -3.4694469519536141888e-17 -0.0025000000000000078583" rpy="0 0 0" />
      <mass value="0.0012999999999999997235" />
      <inertia ixx="3.3282842836137704968e-08" ixy="-1.5826540657942491103e-22" ixz="-3.6198314729072587281e-36" iyy="3.3282842836137460123e-08" iyz="-3.4530272508340887177e-36" izz="6.1149428795799502273e-08" />
    </inertial>
  </link>

  <joint name="left_gripper_rack" type="revolute">
    <origin xyz="0.0079999999999981093179 -0.022499999999998899353 -0.026000000000001910472" rpy="-4.0807662443141075328e-13 -9.9724131645857233152e-14 -3.1414504889509453633" />
    <parent link="xc330" />
    <child link="spur_gear_(18_teeth)" />
    <axis xyz="0 0 1" />
    <limit effort="1" velocity="20" lower="0" upper="2.7052603405912107881" />
    <joint_properties friction="0.0" />
  </joint>

  <joint name="left_gripper_motor" type="fixed">
    <origin xyz="-0.021950000000000011169 0.022600000000000005501 0.023300000000000015143" rpy="-1.6486811914946399887e-14 2.2796676555695055158e-29 7.4715529378013142912e-30" />
    <parent link="left_rail_guide" />
    <child link="xc330" />
    <axis xyz="0 0 1" />
    <limit effort="1" velocity="20" />
    <joint_properties friction="0.0" />
  </joint>

  <joint name="left_gripper_fixed" type="fixed">
    <origin xyz="-3.4694469519536141888e-18 -0.037000000000000005107 -0.03599999999999999728" rpy="-1.5707963267949005548 -1.570796326794896558 0" />
    <parent link="gripper_connector" />
    <child link="left_rail_guide" />
    <axis xyz="0 0 1" />
    <limit effort="1" velocity="20" />
    <joint_properties friction="0.0" />
  </joint>

  <joint name="left_wrist_roll" type="revolute">
    <origin xyz="0.019000000000007195161 -3.5808220277822044864e-10 -0.027000000152449490226" rpy="-5.3970549458090308007e-14 1.5707963267947446795 0" />
    <parent link="2xl430_gears_3" />
    <child link="gripper_connector" />
    <axis xyz="0 0 1" />
    <limit effort="1" velocity="20" lower="-1.9198621771937625091" upper="1.3962634015954635824" />
    <joint_properties friction="0.0" />
  </joint>

  <link name="wrist_bearing_plate">
    <visual>
      <origin xyz="0 0 0" rpy="0 -0 0" />
      <geometry>
        <mesh filename="../assemblies/left_arm_gripper/meshes/left_wrist_bearing_plate_visual.stl" />
      </geometry>
      <material name="wrist_bearing_plate_material">
        <color rgba="0.64496316278892629192 0.69011804996940528945 0.71706771073555886087 1.0" />
      </material>
    </visual>
    <inertial>
      <origin xyz="-0.007583558312149987074 -0.015499999999999982542 -0.0018386323705903372637" rpy="0 0 0" />
      <mass value="0.0049000367468305539714" />
      <inertia ixx="4.9707430109150118544e-07" ixy="4.7110040070984789389e-23" ixz="1.8100904820814111348e-08" iyy="7.1268523603538584823e-07" iyz="4.2334274165733609005e-24" izz="1.1919657811600109234e-06" />
    </inertial>
  </link>

  <joint name="left_wrist_pitch_fixed" type="fixed">
    <origin xyz="0.015500000000001472669 -8.0768725041480138316e-15 -0.045000000000001538769" rpy="-1.2656542480600718277e-14 -1.2834178164666988836e-13 -1.5707963267947810948" />
    <parent link="2xl430_gears_3" />
    <child link="wrist_bearing_plate" />
    <axis xyz="0 0 1" />
    <limit effort="1" velocity="20" />
    <joint_properties friction="0.0" />
  </joint>

  <joint name="left_wrist_pitch_driven" type="revolute">
    <origin xyz="2.498001805406602216e-16 -5.6819448290618985486e-18 -0.0016000000000000941854" rpy="1.8490899618380516719e-26 6.1232339920953384913e-17 -1.570796326794896558" />
    <parent link="spur_1m_24t_driven_3" />
    <child link="2xl430_gears_3" />
    <axis xyz="0 0 1" />
    <limit effort="1" velocity="20" lower="-1.3962634015954635824" upper="1.9198621771937625091" />
    <joint_properties friction="0.0" />
  </joint>

  <joint name="left_wrist_roll_fixed" type="fixed">
    <origin xyz="6.3108872417680944433e-30 -0.025299999999999999573 -0.052000000000000004552" rpy="1.570796326794896558 -1.570796326794896558 0" />
    <parent link="elb_yaw_link" />
    <child link="spur_1m_24t_driven_3" />
    <axis xyz="0 0 1" />
    <limit effort="1" velocity="20" />
    <joint_properties friction="0.0" />
  </joint>

  <joint name="left_elbow_yaw_fixed" type="fixed">
    <origin xyz="9.7144514654701197287e-17 5.6819448291407846392e-18 0.0016000000000002539968" rpy="-3.1415926535897926719 1.2755178505055691328e-27 -1.570796326794896558" />
    <parent link="spur_1m_24t_driven_2" />
    <child link="elb_yaw_link" />
    <axis xyz="0 0 1" />
    <limit effort="1" velocity="20" />
    <joint_properties friction="0.0" />
  </joint>

  <joint name="left_elbow_yaw_driven" type="revolute">
    <origin xyz="-3.5806304796159871273e-10 -0.027000000152460831848 -0.018999999999996988048" rpy="1.5707963267946301045 -3.8036180281220305768e-14 1.8379912246256679584e-14" />
    <parent link="2xl430_gears_2" />
    <child link="spur_1m_24t_driven_2" />
    <axis xyz="0 0 1" />
    <limit effort="1" velocity="20" lower="-2.6179938779914944114" upper="2.6179938779914944114" />
    <joint_properties friction="0.0" />
  </joint>

  <joint name="left_elbow_roll" type="revolute">
    <origin xyz="-1.2143064331837649661e-16 -0.019000000000000016875 -0.058999999999999802602" rpy="1.570796326794896558 8.9045607763570843759e-14 2.3927006918192705097e-15" />
    <parent link="sho_yaw_link" />
    <child link="2xl430_gears_2" />
    <axis xyz="0 0 1" />
    <limit effort="1" velocity="20" lower="-1.9198621771937625091" upper="2.4434609527920612138" />
    <joint_properties friction="0.0" />
  </joint>

  <joint name="left_sho_yaw_fixed" type="fixed">
    <origin xyz="1.2143064331837649661e-16 -1.4233300923361624448e-17 0.0016000000000002158329" rpy="-3.1415926535897891192 -2.394464083135350357e-30 7.6661985808523846341e-30" />
    <parent link="spur_1m_24t_driven" />
    <child link="sho_yaw_link" />
    <axis xyz="0 0 1" />
    <limit effort="1" velocity="20" />
    <joint_properties friction="0.0" />
  </joint>

  <joint name="left_sho_yaw_driven" type="revolute">
    <origin xyz="-3.5806543841054860877e-10 -0.027000000152452467012 -0.019000000000003677142" rpy="1.5707963267949525132 -6.2878911843811245451e-14 8.8990096612435574527e-14" />
    <parent link="2xl430_gears" />
    <child link="spur_1m_24t_driven" />
    <axis xyz="0 0 1" />
    <limit effort="1" velocity="20" lower="-2.6179938779914944114" upper="2.6179938779914944114" />
    <joint_properties friction="0.0" />
  </joint>

  <joint name="left_sho_roll" type="revolute">
    <origin xyz="-0.01899999999999986422 0.00099999999999969275792 0.02700000000000003092" rpy="3.1415926535897900074 1.5707963267948166219 0" />
    <parent link="sho_pitch_link" />
    <child link="2xl430_gears" />
    <axis xyz="0 0 1" />
    <limit effort="1" velocity="20" lower="-1.570796326794896558" upper="0.34906585039886589561" />
    <joint_properties friction="0.0" />
  </joint>


  <link name="sho_pitch_link_2">
    <visual>
      <origin xyz="0 0 0" rpy="0 -0 0" />
      <geometry>
        <mesh filename="../assemblies/right_arm_gripper/meshes/right_sho_pitch_link_visual.stl" />
      </geometry>
      <material name="sho_pitch_link_material">
        <color rgba="0.61568627450980395466 0.81176470588235294379 0.92941176470588227065 1.0" />
      </material>
    </visual>
    <inertial>
      <origin xyz="5.8254246964215295881e-11 -5.1264642561120952189e-05 0.008244078812709491888" rpy="0 0 0" />
      <mass value="0.0085999999999999982708" />
      <inertia ixx="1.2272887040545796108e-06" ixy="-2.1429944197535315064e-14" ixz="-8.5847198170025356625e-15" iyy="2.9107306060364620088e-06" iyz="7.4623841398182868942e-09" izz="3.0803135950773491928e-06" />
    </inertial>
  </link>

  <link name="2xl430_gears_4">
    <visual>
      <origin xyz="0 0 0" rpy="0 -0 0" />
      <geometry>
        <mesh filename="../assemblies/right_arm_gripper/meshes/right_2xl430_gears_visual.stl" />
      </geometry>
      <material name="2xl430_gears_material">
        <color rgba="0.75605985687944088358 0.8580469596269301169 0.91320266199377464478 1.0" />
      </material>
    </visual>
    <inertial>
      <origin xyz="-0.011593155021923642542 -0.0024238821558115221377 -0.01855109552380418067" rpy="0 0 0" />
      <mass value="0.11800003674524907338" />
      <inertia ixx="2.7511554932656560375e-05" ixy="8.9994756795124576377e-07" ixz="-2.3362914880511697392e-08" iyy="3.2796647067986007455e-05" iyz="-6.5715261571553837593e-07" izz="3.5775886684226159849e-05" />
    </inertial>
  </link>

  <link name="spur_1m_24t_drive_4">
    <visual>
      <origin xyz="0 0 0" rpy="0 -0 0" />
      <geometry>
        <mesh filename="../assemblies/right_arm_gripper/meshes/right_spur_1m_24t_drive_visual.stl" />
      </geometry>
      <material name="spur_1m_24t_drive_material">
        <color rgba="0.61568627450980406568 0.81176470588235294379 0.92941176470588238168 1.0" />
      </material>
    </visual>
    <inertial>
      <origin xyz="-7.751924474065288114e-15 -1.211430957726248335e-16 0.0047949116178401416863" rpy="0 0 0" />
      <mass value="0.0032000000000000001533" />
      <inertia ixx="1.4019331346159890349e-07" ixy="1.6002410021513630837e-15" ixz="3.3976222871599421455e-36" iyy="1.4019331260388786185e-07" iyz="-3.6968693489158643946e-37" izz="2.3838919844264060647e-07" />
    </inertial>
  </link>

  <joint name="right_sho_yaw_drive" type="revolute">
    <origin xyz="-0.024000000716137899481 -0.019000000152449094543 -0.019000000152446464702" rpy="1.5707963267947575581 -1.6021123593593761996e-14 3.9927856220238265396e-14" />
    <parent link="2xl430_gears_4" />
    <child link="spur_1m_24t_drive_4" />
    <axis xyz="0 0 1" />
    <limit effort="1" velocity="20" lower="-2.6179938779914944114" upper="2.6179938779914944114" />
    <joint_properties friction="0.0" />
  </joint>

  <link name="spur_1m_24t_driven_4">
    <visual>
      <origin xyz="0 0 0" rpy="0 -0 0" />
      <geometry>
        <mesh filename="../assemblies/right_arm_gripper/meshes/right_spur_1m_24t_driven_visual.stl" />
      </geometry>
      <material name="spur_1m_24t_driven_material">
        <color rgba="0.23137254901960788156 0.38039215686274502337 0.7058823529411765163 1.0" />
      </material>
    </visual>
    <inertial>
      <origin xyz="2.2397001460351634776e-18 -5.804960647391017135e-15 -0.00097054817521927832808" rpy="0 0 0" />
      <mass value="0.0026999999999999997093" />
      <inertia ixx="1.2036234079571065709e-07" ixy="-4.8068006864718580788e-37" ixz="-3.7548680678340956839e-36" iyy="1.203623407957104718e-07" iyz="2.7377938088300361412e-37" izz="2.2847261745924535316e-07" />
    </inertial>
  </link>

  <link name="sho_yaw_link_2">
    <visual>
      <origin xyz="0 0 0" rpy="0 -0 0" />
      <geometry>
        <mesh filename="../assemblies/right_arm_gripper/meshes/right_sho_yaw_link_visual.stl" />
      </geometry>
      <material name="sho_yaw_link_material">
        <color rgba="0.61568627450980395466 0.81176470588235294379 0.92941176470588238168 1.0" />
      </material>
    </visual>
    <inertial>
      <origin xyz="-1.2817564279967688722e-18 4.0208771290521817504e-18 -0.024303257848520158635" rpy="0 0 0" />
      <mass value="0.014500000000000012879" />
      <inertia ixx="9.0846670053041365841e-06" ixy="3.6224092806453171386e-13" ixz="1.4255068536486918059e-34" iyy="5.6910950712097533498e-06" iyz="1.5897088116575402094e-35" izz="4.48196098455489844e-06" />
    </inertial>
  </link>

  <link name="2xl430_gears_5">
    <visual>
      <origin xyz="0 0 0" rpy="0 -0 0" />
      <geometry>
        <mesh filename="../assemblies/right_arm_gripper/meshes/right_2xl430_gears_2_visual.stl" />
      </geometry>
      <material name="2xl430_gears_2_material">
        <color rgba="0.75605985687944088358 0.8580469596269301169 0.91320266199377464478 1.0" />
      </material>
    </visual>
    <inertial>
      <origin xyz="-0.011593155021931275325 -0.002423882155810542019 -0.018551095523808777688" rpy="0 0 0" />
      <mass value="0.11800003674524907338" />
      <inertia ixx="2.7511554932660216169e-05" ixy="8.9994756794983164226e-07" ixz="-2.336291487988372834e-08" iyy="3.2796647067987294945e-05" iyz="-6.5715261571663126019e-07" izz="3.57758866842291143e-05" />
    </inertial>
  </link>

  <link name="spur_1m_24t_drive_5">
    <visual>
      <origin xyz="0 0 0" rpy="0 -0 0" />
      <geometry>
        <mesh filename="../assemblies/right_arm_gripper/meshes/right_spur_1m_24t_drive_2_visual.stl" />
      </geometry>
      <material name="spur_1m_24t_drive_2_material">
        <color rgba="0.61568627450980406568 0.81176470588235294379 0.92941176470588238168 1.0" />
      </material>
    </visual>
    <inertial>
      <origin xyz="-7.751924474065288114e-15 -1.2114309579847422764e-16 0.0047949116178401382168" rpy="0 0 0" />
      <mass value="0.0032000000000000001533" />
      <inertia ixx="1.4019331346159890349e-07" ixy="1.6002410021513630837e-15" ixz="-1.0876898409367052523e-36" iyy="1.4019331260388786185e-07" iyz="2.8326589331473283833e-37" izz="2.3838919844264060647e-07" />
    </inertial>
  </link>

  <joint name="right_elbow_yaw_drive" type="revolute">
    <origin xyz="-0.024000000716148744973 -0.01900000015245331686 -0.01900000015245205745" rpy="1.5707963267949269781 1.6255101888762571504e-13 -7.7038633886878518967e-14" />
    <parent link="2xl430_gears_5" />
    <child link="spur_1m_24t_drive_5" />
    <axis xyz="0 0 1" />
    <limit effort="1" velocity="20" lower="-2.6179938779914944114" upper="2.6179938779914944114" />
    <joint_properties friction="0.0" />
  </joint>

  <link name="spur_1m_24t_driven_5">
    <visual>
      <origin xyz="0 0 0" rpy="0 -0 0" />
      <geometry>
        <mesh filename="../assemblies/right_arm_gripper/meshes/right_spur_1m_24t_driven_2_visual.stl" />
      </geometry>
      <material name="spur_1m_24t_driven_2_material">
        <color rgba="0.23137254901960788156 0.38039215686274502337 0.7058823529411765163 1.0" />
      </material>
    </visual>
    <inertial>
      <origin xyz="5.7091470979890261114e-18 -5.8049606473910155572e-15 -0.00097054817521928168911" rpy="0 0 0" />
      <mass value="0.0026999999999999997093" />
      <inertia ixx="1.2036234079571065709e-07" ixy="-7.4179684800806379779e-38" ixz="6.4659171650319086526e-37" iyy="1.203623407957104718e-07" iyz="-1.7823790256373093551e-36" izz="2.2847261745924545904e-07" />
    </inertial>
  </link>

  <link name="elb_yaw_link_2">
    <visual>
      <origin xyz="0 0 0" rpy="0 -0 0" />
      <geometry>
        <mesh filename="../assemblies/right_arm_gripper/meshes/right_elb_yaw_link_visual.stl" />
      </geometry>
      <material name="elb_yaw_link_material">
        <color rgba="0.61568627450980395466 0.81176470588235294379 0.92941176470588227065 1.0" />
      </material>
    </visual>
    <inertial>
      <origin xyz="5.3127688027384996195e-08 0.0019833638641961665906 -0.023416643551549952418" rpy="0 0 0" />
      <mass value="0.017500000000000001665" />
      <inertia ixx="1.4134344903109199776e-05" ixy="1.6945783921921615402e-12" ixz="-1.1286398721829634941e-11" iyy="6.6435900776211365815e-06" iyz="1.0545227077253059697e-06" izz="8.9925290757998976773e-06" />
    </inertial>
  </link>

  <link name="spur_1m_24t_driven_6">
    <visual>
      <origin xyz="0 0 0" rpy="0 -0 0" />
      <geometry>
        <mesh filename="../assemblies/right_arm_gripper/meshes/right_spur_1m_24t_driven_3_visual.stl" />
      </geometry>
      <material name="spur_1m_24t_driven_3_material">
        <color rgba="0.23137254901960788156 0.38039215686274502337 0.7058823529411765163 1.0" />
      </material>
    </visual>
    <inertial>
      <origin xyz="2.9995275761664531893e-17 -5.8049606473910179238e-15 -0.0025705481752192754774" rpy="0 0 0" />
      <mass value="0.0026999999999999997093" />
      <inertia ixx="1.2036234079571065709e-07" ixy="-1.3806367110425286735e-36" ixz="9.070298151083200235e-37" iyy="1.203623407957104718e-07" iyz="3.0378272403323605098e-37" izz="2.2847261745924545904e-07" />
    </inertial>
  </link>

  <link name="2xl430_gears_6">
    <visual>
      <origin xyz="0 0 0" rpy="0 -0 0" />
      <geometry>
        <mesh filename="../assemblies/right_arm_gripper/meshes/right_2xl430_gears_3_visual.stl" />
      </geometry>
      <material name="2xl430_gears_3_material">
        <color rgba="0.75605985687944088358 0.8580469596269301169 0.91320266199377464478 1.0" />
      </material>
    </visual>
    <inertial>
      <origin xyz="0.00044890447619669565215 0.011593154663860445394 -0.024576117996643907782" rpy="0 0 0" />
      <mass value="0.11800003674524907338" />
      <inertia ixx="3.5775886684226132744e-05" ixy="2.3362914880833387932e-08" ixz="6.5715261571618688553e-07" iyy="2.7511554932656353699e-05" iyz="8.9994756795086396367e-07" izz="3.2796647067986874817e-05" />
    </inertial>
  </link>

  <link name="spur_1m_24t_drive_6">
    <visual>
      <origin xyz="0 0 0" rpy="0 -0 0" />
      <geometry>
        <mesh filename="../assemblies/right_arm_gripper/meshes/right_spur_1m_24t_drive_3_visual.stl" />
      </geometry>
      <material name="spur_1m_24t_drive_3_material">
        <color rgba="0.61568627450980406568 0.81176470588235294379 0.92941176470588238168 1.0" />
      </material>
    </visual>
    <inertial>
      <origin xyz="-7.7241688984496576227e-15 -1.2114309577262443907e-16 0.004794911617840143421" rpy="0 0 0" />
      <mass value="0.0032000000000000001533" />
      <inertia ixx="1.4019331346159885055e-07" ixy="1.6002410021513630837e-15" ixz="-1.29365709829275547e-36" iyy="1.4019331260388786185e-07" iyz="-1.8076585423776766936e-37" izz="2.3838919844264060647e-07" />
    </inertial>
  </link>

  <joint name="right_wrist_pitch_drive" type="revolute">
    <origin xyz="-1.5244753931023469169e-10 0.024000000358074063955 -0.0080000000000028659297" rpy="2.0921450023946095227e-14 5.319128891731015468e-14 -1.5707963267948152897" />
    <parent link="2xl430_gears_6" />
    <child link="spur_1m_24t_drive_6" />
    <axis xyz="0 0 1" />
    <limit effort="1" velocity="20" lower="-1.3962634015954635824" upper="1.9198621771937625091" />
    <joint_properties friction="0.0" />
  </joint>

  <link name="gripper_connector_2">
    <visual>
      <origin xyz="0 0 0" rpy="0 -0 0" />
      <geometry>
        <mesh filename="../assemblies/right_arm_gripper/meshes/right_gripper_connector_visual.stl" />
      </geometry>
      <material name="gripper_connector_material">
        <color rgba="0.61568627450980395466 0.81176470588235294379 0.92941176470588227065 1.0" />
      </material>
    </visual>
    <inertial>
      <origin xyz="-0.00020216391502726472869 0.024011997737921234736 -0.029290084989921687242" rpy="0 0 0" />
      <mass value="0.0099999999999999880651" />
      <inertia ixx="5.3138306577478889962e-06" ixy="2.3224171675565346272e-08" ixz="4.7690345371182966176e-08" iyy="3.8402250096486075095e-06" iyz="8.1160112886319393595e-09" izz="2.257315404231779922e-06" />
    </inertial>
  </link>

  <link name="right_rail_guide">
    <visual>
      <origin xyz="0 0 0" rpy="0 -0 0" />
      <geometry>
        <mesh filename="../assemblies/right_arm_gripper/meshes/right_rail_guide_visual.stl" />
      </geometry>
      <material name="right_rail_guide_material">
        <color rgba="0.6201144836561668372 0.81392203854340150482 0.93009302765147672254 1.0" />
      </material>
    </visual>
    <inertial>
      <origin xyz="0.010819769137967559167 -0.002111301198521865069 -7.7620928513503963803e-05" rpy="0 0 0" />
      <mass value="0.031084136786219580817" />
      <inertia ixx="7.843066623607029627e-06" ixy="-2.064451767957414831e-06" ixz="4.0045882799668551793e-06" iyy="2.7294704119451739579e-05" iyz="8.89490755300507747e-07" izz="3.0492488744516627947e-05" />
    </inertial>
  </link>

  <link name="rail_3">
    <visual>
      <origin xyz="0 0 0" rpy="0 -0 0" />
      <geometry>
        <mesh filename="../assemblies/right_arm_gripper/meshes/right_rail_visual.stl" />
      </geometry>
      <material name="rail_material">
        <color rgba="0.64705882352941179736 0.64705882352941179736 0.64705882352941179736 1.0" />
      </material>
    </visual>
    <inertial>
      <origin xyz="0.029554714214719193105 -0.015933051259988690457 -0.010638774525132295434" rpy="0 0 0" />
      <mass value="0.017100000000000000616" />
      <inertia ixx="3.6591938331681695171e-06" ixy="2.1013138412446668144e-08" ixz="-1.1335092663308587465e-07" iyy="4.7380338190523256316e-06" iyz="3.1225833654311333417e-08" izz="6.0956112819844617947e-06" />
    </inertial>
  </link>

  <joint name="right_gripper_pinion" type="prismatic">
    <origin xyz="-0.028872600000000556847 -0.015974999999999992678 -0.00535000000000218634" rpy="3.141592653589793116 1.570796326794896558 0" />
    <parent link="right_rail_guide" />
    <child link="rail_3" />
    <axis xyz="0 0 1" />
    <limit effort="1" velocity="20" lower="-0.025000000000000001388" upper="0" />
    <joint_properties friction="0.0" />
  </joint>

  <link name="rail_4">
    <visual>
      <origin xyz="0 0 0" rpy="0 -0 0" />
      <geometry>
        <mesh filename="../assemblies/right_arm_gripper/meshes/right_rail_2_visual.stl" />
      </geometry>
      <material name="rail_2_material">
        <color rgba="0.64705882352941179736 0.64705882352941179736 0.64705882352941179736 1.0" />
      </material>
    </visual>
    <inertial>
      <origin xyz="0.029554714214719193105 -0.015933051259988686987 -0.010638774525132295434" rpy="0 0 0" />
      <mass value="0.017100000000000000616" />
      <inertia ixx="3.6591938331681695171e-06" ixy="2.1013138412446668144e-08" ixz="-1.1335092663308587465e-07" iyy="4.7380338190523256316e-06" iyz="3.1225833654311333417e-08" izz="6.0956112819844617947e-06" />
    </inertial>
  </link>

  <joint name="right_gripper_pinion_mirror" type="prismatic">
    <origin xyz="0.062872599999997391684 0.015974999999999996148 -0.0053500000000021585844" rpy="-5.1375487870838840353e-26 1.5707963267948901187 0" />
    <parent link="right_rail_guide" />
    <child link="rail_4" />
    <axis xyz="0 0 1" />
    <limit effort="1" velocity="20" lower="-0.025000000000000001388" upper="0" />
    <joint_properties friction="0.0" />
  </joint>

  <link name="xc330_2">
    <visual>
      <origin xyz="0 0 0" rpy="0 -0 0" />
      <geometry>
        <mesh filename="../assemblies/right_arm_gripper/meshes/right_xc330_visual.stl" />
      </geometry>
      <material name="xc330_material">
        <color rgba="0.66932535752643773641 0.72911795671409962427 0.67547870389434394589 1.0" />
      </material>
    </visual>
    <inertial>
      <origin xyz="0.0080045171539636986169 -0.015558009851631672549 -0.011717805512818120842" rpy="0 0 0" />
      <mass value="0.026599999993091753836" />
      <inertia ixx="3.868341066651400925e-06" ixy="-7.7688424002223831296e-10" ixz="5.7969695832979731151e-10" iyy="2.1626767907494457945e-06" iyz="8.3590274792900736609e-09" izz="3.3158761130056259384e-06" />
    </inertial>
  </link>

  <link name="spur_gear_(18_teeth)_2">
    <visual>
      <origin xyz="0 0 0" rpy="0 -0 0" />
      <geometry>
        <mesh filename="../assemblies/right_arm_gripper/meshes/right_spur_gear_(18_teeth)_visual.stl" />
      </geometry>
      <material name="spur_gear_(18_teeth)_material">
        <color rgba="0.9176470588235294823 0.9176470588235294823 0.9176470588235294823 1.0" />
      </material>
    </visual>
    <inertial>
      <origin xyz="5.7245874707234634116e-17 -3.4694469519536141888e-17 -0.0025000000000000078583" rpy="0 0 0" />
      <mass value="0.0012999999999999997235" />
      <inertia ixx="3.3282842836137718203e-08" ixy="-1.6483175047912543603e-22" ixz="2.0134892040511168155e-37" iyy="3.3282842836137453506e-08" iyz="-1.4284978873565059479e-37" izz="6.1149428795799502273e-08" />
    </inertial>
  </link>

  <joint name="right_gripper_rack" type="revolute">
    <origin xyz="0.0079999999999993201549 -0.022499999999994794997 -0.025999999999999606759" rpy="2.4369395390407848563e-14 1.8923581380997412337e-14 3.1415926535897598093" />
    <parent link="xc330_2" />
    <child link="spur_gear_(18_teeth)_2" />
    <axis xyz="0 0 1" />
    <limit effort="1" velocity="20" lower="0" upper="2.7052603405912107881" />
    <joint_properties friction="0.0" />
  </joint>

  <joint name="right_gripper_motor" type="fixed">
    <origin xyz="-0.0059500000000000108358 -0.022599999999999998562 0.023299999999999959632" rpy="-1.0436096431306391491e-14 4.584660564324367864e-30 -3.141592653589793116" />
    <parent link="right_rail_guide" />
    <child link="xc330_2" />
    <axis xyz="0 0 1" />
    <limit effort="1" velocity="20" />
    <joint_properties friction="0.0" />
  </joint>

  <joint name="right_gripper_fixed" type="fixed">
    <origin xyz="3.4694469519536141888e-18 0.037000000000000032863 -0.0019999999999999983069" rpy="1.570796326794891673 1.570796326794896558 0" />
    <parent link="gripper_connector_2" />
    <child link="right_rail_guide" />
    <axis xyz="0 0 1" />
    <limit effort="1" velocity="20" />
    <joint_properties friction="0.0" />
  </joint>

  <joint name="right_wrist_roll" type="revolute">
    <origin xyz="0.019000000000002639777 -3.5806405063176782733e-10 -0.027000000152454364799" rpy="-3.1415926535897558125 -1.5707963267947788744 0" />
    <parent link="2xl430_gears_6" />
    <child link="gripper_connector_2" />
    <axis xyz="0 0 1" />
    <limit effort="1" velocity="20" lower="-1.3962634015954635824" upper="1.9198621771937625091" />
    <joint_properties friction="0.0" />
  </joint>

  <link name="wrist_bearing_plate_2">
    <visual>
      <origin xyz="0 0 0" rpy="0 -0 0" />
      <geometry>
        <mesh filename="../assemblies/right_arm_gripper/meshes/right_wrist_bearing_plate_visual.stl" />
      </geometry>
      <material name="wrist_bearing_plate_material">
        <color rgba="0.64496316278892629192 0.69011804996940528945 0.71706771073555886087 1.0" />
      </material>
    </visual>
    <inertial>
      <origin xyz="-0.0075835583121500096254 -0.015499999999999982542 -0.0018386323705903342279" rpy="0 0 0" />
      <mass value="0.0049000367468305539714" />
      <inertia ixx="4.970743010915013972e-07" ixy="6.835022250017547813e-23" ixz="1.8100904820814078261e-08" iyy="7.1268523603538605999e-07" iyz="1.3148545519931043656e-23" izz="1.1919657811600117705e-06" />
    </inertial>
  </link>

  <joint name="right_wrist_pitch_fixed" type="fixed">
    <origin xyz="0.01550000000000212666 9.7144514654701197287e-15 -0.045000000000006409873" rpy="1.7541523788970447002e-14 1.2040368702059279945e-13 -1.5707963267947835373" />
    <parent link="2xl430_gears_6" />
    <child link="wrist_bearing_plate_2" />
    <axis xyz="0 0 1" />
    <limit effort="1" velocity="20" />
    <joint_properties friction="0.0" />
  </joint>

  <joint name="right_wrist_pitch_driven" type="revolute">
    <origin xyz="2.7755575615628913511e-17 3.9443045261050590271e-31 -0.0015999999999999966072" rpy="1.3582904646488232485e-14 2.0737500615824777463e-14 1.570796326794896558" />
    <parent link="spur_1m_24t_driven_6" />
    <child link="2xl430_gears_6" />
    <axis xyz="0 0 1" />
    <limit effort="1" velocity="20" lower="-1.9198621771937625091" upper="1.3962634015954635824" />
    <joint_properties friction="0.0" />
  </joint>

  <joint name="right_wrist_roll_fixed" type="fixed">
    <origin xyz="1.0846837446788912324e-30 -0.025300000000000006511 -0.051999999999999976796" rpy="1.5707963267948952257 1.5707963267948956698 0" />
    <parent link="elb_yaw_link_2" />
    <child link="spur_1m_24t_driven_6" />
    <axis xyz="0 0 1" />
    <limit effort="1" velocity="20" />
    <joint_properties friction="0.0" />
  </joint>

  <joint name="right_elbow_yaw_fixed" type="fixed">
    <origin xyz="0 6.9025329206838532974e-31 0.0016000000000000041966" rpy="3.1415926535897904515 9.8876398673015319607e-16 -1.5707963267948961139" />
    <parent link="spur_1m_24t_driven_5" />
    <child link="elb_yaw_link_2" />
    <axis xyz="0 0 1" />
    <limit effort="1" velocity="20" />
    <joint_properties friction="0.0" />
  </joint>

  <joint name="right_elbow_yaw_driven" type="revolute">
    <origin xyz="-3.5807057666148445207e-10 -0.027000000152458084046 -0.019000000000001945888" rpy="1.5707963267949378583 3.9751140894689616291e-14 -4.8122446750143955108e-14" />
    <parent link="2xl430_gears_5" />
    <child link="spur_1m_24t_driven_5" />
    <axis xyz="0 0 1" />
    <limit effort="1" velocity="20" lower="-2.6179938779914944114" upper="2.6179938779914944114" />
    <joint_properties friction="0.0" />
  </joint>

  <joint name="right_elbow_roll" type="revolute">
    <origin xyz="-6.2450045135165055399e-17 -0.019000000000000055039 -0.058999999999999983014" rpy="1.5707963267948976682 -6.0447453237754791364e-15 3.4446905417540585232e-15" />
    <parent link="sho_yaw_link_2" />
    <child link="2xl430_gears_5" />
    <axis xyz="0 0 1" />
    <limit effort="1" velocity="20" lower="-1.9198621771937625091" upper="2.4434609527920612138" />
    <joint_properties friction="0.0" />
  </joint>

  <joint name="right_sho_yaw_fixed" type="fixed">
    <origin xyz="5.5511151231257827021e-17 -5.5955222556880518216e-17 0.0015999999999998862354" rpy="3.141592653589793116 1.024631402903628403e-29 3.0929606673668622441e-31" />
    <parent link="spur_1m_24t_driven_4" />
    <child link="sho_yaw_link_2" />
    <axis xyz="0 0 1" />
    <limit effort="1" velocity="20" />
    <joint_properties friction="0.0" />
  </joint>

  <joint name="right_sho_yaw_driven" type="revolute">
    <origin xyz="-3.5806703782559345939e-10 -0.027000000152449448593 -0.018999999999999434008" rpy="1.5707963267947753216 -5.6469601652704289819e-14 2.3773531644080762555e-14" />
    <parent link="2xl430_gears_4" />
    <child link="spur_1m_24t_driven_4" />
    <axis xyz="0 0 1" />
    <limit effort="1" velocity="20" lower="-2.6179938779914944114" upper="2.6179938779914944114" />
    <joint_properties friction="0.0" />
  </joint>

  <joint name="right_sho_roll" type="revolute">
    <origin xyz="-0.018999999999999912792 0.00099999999999999286508 0.027000000000000079492" rpy="3.141592653589793116 1.5707963267947739894 0" />
    <parent link="sho_pitch_link_2" />
    <child link="2xl430_gears_4" />
    <axis xyz="0 0 1" />
    <limit effort="1" velocity="20" lower="-1.570796326794896558" upper="0.34906585039886589561" />
    <joint_properties friction="0.0" />
  </joint>


</robot>