<?xml version="1.0" ?>
<robot name="toddlerbot_gripper">
  <mujoco>
    <compiler strippath="false" balanceinertia="true" discardvisual="false"/>
  </mujoco>
  <link name="torso">
    <visual>
      <origin xyz="0 0 0" rpy="0 -0 0"/>
      <geometry>
        <mesh filename="../assemblies/toddlerbot/meshes/torso_visual.stl"/>
      </geometry>
      <material name="torso_material">
        <color rgba="0.63761324738265878764 0.79140018897832431488 0.89744804913511877498 1.0"/>
      </material>
    </visual>
    <collision name="torso_collision">
      <origin xyz="-0.028500007465481758 -5.000084638595581e-05 0.07068824046291411" rpy="0 0 0"/>
      <geometry>
        <box size="0.14100001379847527 0.13759998977184296 0.1454972173087299"/>
      </geometry>
    </collision>
    <inertial>
      <origin xyz="-0.0045319089141771552731 -0.0033046849194455856467 0.065594108502290693341" rpy="0 0 0"/>
      <mass value="1.1369659631012025702"/>
      <inertia ixx="0.0029825917743578666055" ixy="8.1730614288441110122e-05" ixz="2.1951370741857685305e-05" iyy="0.0023969506399989372152" iyz="-2.9575017351927617657e-05" izz="0.0025126356523908575241"/>
    </inertial>
  </link>
  <link name="spur_1m_20t">
    <visual>
      <origin xyz="0 0 0" rpy="0 -0 0"/>
      <geometry>
        <mesh filename="../assemblies/toddlerbot/meshes/spur_1m_20t_visual.stl"/>
      </geometry>
      <material name="spur_1m_20t_material">
        <color rgba="0.64705882352941179736 0.64705882352941179736 0.64705882352941179736 1.0"/>
      </material>
    </visual>
    <inertial>
      <origin xyz="-2.9273600019542193503e-19 -8.407168954226882874e-18 0.003384232105434467619" rpy="0 0 0"/>
      <mass value="0.0015778025963745997712"/>
      <inertia ixx="4.5874424196602084909e-08" ixy="3.9290914639085633501e-24" ixz="-7.1097175513400442172e-39" iyy="4.5874424196602058439e-08" iyz="7.8419015231486113446e-38" izz="8.1737050837173876176e-08"/>
    </inertial>
  </link>
  <joint name="neck_yaw_drive" type="revolute">
    <origin xyz="-0.0049999999999995221878 3.1860588521011854095e-18 0.12148651076281755112" rpy="1.1607298201443905188e-14 1.6509758832059179101e-15 -5.3832337592600790636e-15"/>
    <parent link="torso"/>
    <child link="spur_1m_20t"/>
    <axis xyz="0 0 1"/>
    <limit effort="1" velocity="20" lower="-2.8797932657906435416" upper="2.8797932657906435416"/>
    <joint_properties friction="0.0"/>
  </joint>
  <link name="neck_yaw_link_v2">
    <visual>
      <origin xyz="0 0 0" rpy="0 -0 0"/>
      <geometry>
        <mesh filename="../assemblies/toddlerbot/meshes/neck_yaw_link_v2_visual.stl"/>
      </geometry>
      <material name="neck_yaw_link_v2_material">
        <color rgba="0.2313725490196078538 0.38039215686274507888 0.70588235294117662733 1.0"/>
      </material>
    </visual>
    <inertial>
      <origin xyz="-1.1403990895369493244e-06 -1.1841855614897924462e-10 0.0082571849701004972066" rpy="0 0 0"/>
      <mass value="0.0067298837334394089049"/>
      <inertia ixx="5.2266067624768086445e-07" ixy="-6.3046403327810586846e-15" ixz="1.1949403084466817268e-09" iyy="6.1218519979556588152e-07" iyz="-2.6012871962819705841e-15" izz="2.8062851709981924551e-07"/>
    </inertial>
  </link>
  <link name="head">
    <visual>
      <origin xyz="0 0 0" rpy="0 -0 0"/>
      <geometry>
        <mesh filename="../assemblies/toddlerbot/meshes/head_visual.stl"/>
      </geometry>
      <material name="head_material">
        <color rgba="0.62873939703496806164 0.79364291305093481732 0.87330110949792516539 1.0"/>
      </material>
    </visual>
    <inertial>
      <origin xyz="-0.045316002313821462932 -0.011276855645191824137 -0.0010251236602530945652" rpy="0 0 0"/>
      <mass value="0.13722101760550831084"/>
      <inertia ixx="0.000118808072940447212" ixy="1.1390016804751208719e-06" ixz="1.8378816154934639505e-06" iyy="0.00010489076115432989294" iyz="-9.2536559812160098181e-06" izz="9.1894624061612158465e-05"/>
    </inertial>
  </link>
  <link name="motor_plate">
    <visual>
      <origin xyz="0 0 0" rpy="0 -0 0"/>
      <geometry>
        <mesh filename="../assemblies/toddlerbot/meshes/motor_plate_visual.stl"/>
      </geometry>
      <material name="motor_plate_material">
        <color rgba="0.64705882352941179736 0.64705882352941179736 0.64705882352941179736 1.0"/>
      </material>
    </visual>
    <inertial>
      <origin xyz="-6.9388939039072283776e-18 -1.3877787807814456755e-17 -0.0028281768943845498818" rpy="0 0 0"/>
      <mass value="0.0017000000000000001221"/>
      <inertia ixx="4.805029073310371698e-08" ixy="1.0773753257370504076e-09" ixz="-3.1068233712543829119e-36" iyy="5.1782428339099010347e-08" iyz="8.7873943139860781386e-38" izz="9.2194729037862249329e-08"/>
    </inertial>
  </link>
  <link name="bearing_683">
    <visual>
      <origin xyz="0 0 0" rpy="0 -0 0"/>
      <geometry>
        <mesh filename="../assemblies/toddlerbot/meshes/bearing_683_visual.stl"/>
      </geometry>
      <material name="bearing_683_material">
        <color rgba="0.64705882352941179736 0.64705882352941179736 0.64705882352941179736 1.0"/>
      </material>
    </visual>
    <inertial>
      <origin xyz="1.3985108750766809383e-17 2.4186774283164997703e-19 -0.0015499999999999995118" rpy="0 0 0"/>
      <mass value="0.00048694686130641793437"/>
      <inertia ixx="2.1551456503319895657e-09" ixy="2.9047882901138312047e-26" ixz="-1.1228933808335255921e-37" iyy="2.1551456503319883249e-09" iyz="-1.3368752562953336429e-37" izz="3.5303647444715322361e-09"/>
    </inertial>
  </link>
  <joint name="neck_pitch_front_rev_2" type="revolute">
    <origin xyz="-0.0019411428382689055461 -0.0072444436971680192111 -0.0055000000000000005482" rpy="1.0718125710358602429e-14 -4.311384292830508141e-15 0.88076594287798393168"/>
    <parent link="motor_plate"/>
    <child link="bearing_683"/>
    <axis xyz="0 0 1"/>
    <limit effort="1" velocity="20" lower="-6.283185307179586232" upper="6.283185307179586232"/>
    <joint_properties friction="0.0"/>
  </joint>
  <link name="bearing_683_2">
    <visual>
      <origin xyz="0 0 0" rpy="0 -0 0"/>
      <geometry>
        <mesh filename="../assemblies/toddlerbot/meshes/bearing_683_2_visual.stl"/>
      </geometry>
      <material name="bearing_683_2_material">
        <color rgba="0.64705882352941179736 0.64705882352941179736 0.64705882352941179736 1.0"/>
      </material>
    </visual>
    <inertial>
      <origin xyz="1.3985108750766830954e-17 2.4186774283160303249e-19 -0.0015499999999999990782" rpy="0 0 0"/>
      <mass value="0.00048694686130641793437"/>
      <inertia ixx="2.1551456503319879113e-09" ixy="-2.1975945182776963045e-25" ixz="-2.7042340431588615727e-39" iyy="2.1551456503319883249e-09" iyz="2.2478231163415180367e-39" izz="3.5303647444715305817e-09"/>
    </inertial>
  </link>
  <joint name="neck_pitch_back_rev_2" type="revolute">
    <origin xyz="0.0019411428382688777905 0.007244443697168007068 -0.0055000000000000014155" rpy="-2.5111971789710972494e-13 -1.8026647498047445117e-13 0.87787101658584032471"/>
    <parent link="motor_plate"/>
    <child link="bearing_683_2"/>
    <axis xyz="0 0 1"/>
    <limit effort="1" velocity="20" lower="-6.283185307179586232" upper="6.283185307179586232"/>
    <joint_properties friction="0.0"/>
  </joint>
  <joint name="neck_pitch_act" type="revolute">
    <origin xyz="-0.032615697718560709983 -0.027000000000000058675 0.0024999999999998486974" rpy="-3.1415926535897655825 -3.1199051560142798919e-13 -3.141592653589449835"/>
    <parent link="head"/>
    <child link="motor_plate"/>
    <axis xyz="0 0 1"/>
    <limit effort="1" velocity="20" lower="-1.3962634015954635824" upper="0.61086523819801530344"/>
    <joint_properties friction="0.0"/>
  </joint>
  <joint name="neck_pitch" type="revolute">
    <origin xyz="-1.1796119636642288242e-16 0.0040000000000001215139 0.019400000000000056088" rpy="-1.5707963267904627713 1.5671692223466835436 -3.1415926535886637971"/>
    <parent link="neck_yaw_link_v2"/>
    <child link="head"/>
    <axis xyz="0 0 1"/>
    <limit effort="1" velocity="20" lower="-1.3962634015954635824" upper="0.61086523819801530344"/>
    <joint_properties friction="0.0"/>
  </joint>
  <link name="neck_rod">
    <visual>
      <origin xyz="0 0 0" rpy="0 -0 0"/>
      <geometry>
        <mesh filename="../assemblies/toddlerbot/meshes/neck_rod_visual.stl"/>
      </geometry>
      <material name="neck_rod_material">
        <color rgba="0.62051618944235187314 0.78640765248647570562 0.88594253031295011613 1.0"/>
      </material>
    </visual>
    <inertial>
      <origin xyz="0.017942953356019489264 -4.2302323070087306963e-05 -0.0016023848482628068844" rpy="0 0 0"/>
      <mass value="0.0031629468613064174939"/>
      <inertia ixx="1.6183187611801101548e-08" ixy="4.3686324090029618003e-10" ixz="5.4098718288322473511e-10" iyy="7.9430220338147421456e-07" iyz="-1.2754318974832872697e-12" izz="8.0573905690508686904e-07"/>
    </inertial>
  </link>
  <joint name="neck_pitch_front_rev_1" type="revolute">
    <origin xyz="-0.0072444436971684355447 -0.0040000000000001197792 0.017458857161731233809" rpy="1.5707963267946454256 -0.88439304732584833602 -3.1415926535894400651"/>
    <parent link="neck_yaw_link_v2"/>
    <child link="neck_rod"/>
    <axis xyz="0 0 1"/>
    <limit effort="1" velocity="20" lower="-6.283185307179586232" upper="6.283185307179586232"/>
    <joint_properties friction="0.0"/>
  </joint>
  <link name="neck_rod_2">
    <visual>
      <origin xyz="0 0 0" rpy="0 -0 0"/>
      <geometry>
        <mesh filename="../assemblies/toddlerbot/meshes/neck_rod_2_visual.stl"/>
      </geometry>
      <material name="neck_rod_2_material">
        <color rgba="0.62051618944235187314 0.78640765248647570562 0.88594253031295011613 1.0"/>
      </material>
    </visual>
    <inertial>
      <origin xyz="0.017901072327984525467 4.2302323074025779774e-05 -0.0016023848482717029801" rpy="0 0 0"/>
      <mass value="0.0031629468613064174939"/>
      <inertia ixx="1.6183187611802534225e-08" ixy="-4.3584354918256844597e-10" ixz="5.3972445329300678928e-10" iyy="7.9343818800628575981e-07" iyz="1.2754318717552505803e-12" izz="8.0487504152986580352e-07"/>
    </inertial>
  </link>
  <joint name="neck_pitch_back_rev_1" type="revolute">
    <origin xyz="0.0072444436971682013571 -0.0040000000000001362591 0.021341142838269100412" rpy="1.5707963267949220931 -0.8814981210337055062 3.1415926535897904515"/>
    <parent link="neck_yaw_link_v2"/>
    <child link="neck_rod_2"/>
    <axis xyz="0 0 1"/>
    <limit effort="1" velocity="20" lower="-6.283185307179586232" upper="6.283185307179586232"/>
    <joint_properties friction="0.0"/>
  </joint>
  <joint name="neck_yaw_driven" type="revolute">
    <origin xyz="0.016000000000000621364 3.9122381713629107253e-19 0.12248651076281739936" rpy="1.5470695466536949876e-14 -3.0902695541116811913e-15 -8.6007558735577539147e-16"/>
    <parent link="torso"/>
    <child link="neck_yaw_link_v2"/>
    <axis xyz="0 0 1"/>
    <limit effort="1" velocity="20" lower="-2.6179938779914944114" upper="2.6179938779914944114"/>
    <joint_properties friction="0.0"/>
  </joint>
  <link name="waist_gears">
    <visual>
      <origin xyz="0 0 0" rpy="0 -0 0"/>
      <geometry>
        <mesh filename="../assemblies/toddlerbot/meshes/waist_gears_visual.stl"/>
      </geometry>
      <material name="waist_gears_material">
        <color rgba="0.29673072126509869584 0.50090014891145351328 0.63316042503557934396 1.0"/>
      </material>
    </visual>
    <inertial>
      <origin xyz="-2.9089024309418600146e-07 5.5035553755051287407e-08 -0.012592985430860502774" rpy="0 0 0"/>
      <mass value="0.026337180140419174518"/>
      <inertia ixx="1.5367047941033374527e-06" ixy="1.8828487088222486339e-11" ixz="4.0600521957845183714e-10" iyy="7.302471227545066429e-06" iyz="3.2911737843456854381e-12" izz="6.9859065635059637868e-06"/>
    </inertial>
  </link>
  <link name="waist_link">
    <visual>
      <origin xyz="0 0 0" rpy="0 -0 0"/>
      <geometry>
        <mesh filename="../assemblies/toddlerbot/meshes/waist_link_visual.stl"/>
      </geometry>
      <material name="waist_link_material">
        <color rgba="0.64205964988973096563 0.77112878115803895618 0.80455743168009152821 1.0"/>
      </material>
    </visual>
    <collision name="waist_link_collision">
      <origin xyz="0.0 -0.021850000135600567 -0.022750000469386578" rpy="0 0 0"/>
      <geometry>
        <box size="0.11999999731779099 0.057499999180436134 0.07000000216066837"/>
      </geometry>
    </collision>
    <inertial>
      <origin xyz="-3.4876747961162537906e-18 -0.024647143936897920186 -0.024243097328499937232" rpy="0 0 0"/>
      <mass value="0.10819999998618363979"/>
      <inertia ixx="4.747970073566886237e-05" ixy="-9.3811587245404559892e-21" ixz="-5.6250747314438818848e-09" iyy="9.6352172992785340951e-05" iyz="1.5514215856083487346e-06" izz="6.7249246473027323736e-05"/>
    </inertial>
  </link>
  <link name="spiral_bevel_1m_14t_30deg">
    <visual>
      <origin xyz="0 0 0" rpy="0 -0 0"/>
      <geometry>
        <mesh filename="../assemblies/toddlerbot/meshes/spiral_bevel_1m_14t_30deg_visual.stl"/>
      </geometry>
      <material name="spiral_bevel_1m_14t_30deg_material">
        <color rgba="0.64705882352941179736 0.64705882352941179736 0.64705882352941179736 1.0"/>
      </material>
    </visual>
    <inertial>
      <origin xyz="7.4971447279470481499e-10 7.1802237593121532518e-10 0.006686895501897913846" rpy="0 0 0"/>
      <mass value="0.00073261524436595492574"/>
      <inertia ixx="1.3495056019478195011e-08" ixy="4.0596682073457136067e-17" ixz="8.5992550143797901999e-16" iyy="1.3495056150237195634e-08" iyz="-6.791300821815703182e-16" izz="1.4355986549816401791e-08"/>
    </inertial>
  </link>
  <joint name="waist_act_1" type="revolute">
    <origin xyz="-1.0950768566580540919e-18 -0.019600000000000002837 -0.012749999999999995712" rpy="1.570796326794896558 1.1603771602431690682e-14 -3.1415926535897926719"/>
    <parent link="waist_link"/>
    <child link="spiral_bevel_1m_14t_30deg"/>
    <axis xyz="0 0 1"/>
    <limit effort="1" velocity="20" lower="-4.6774823953448034786" upper="4.6774823953448034786"/>
    <joint_properties friction="0.0"/>
  </joint>
  <link name="spiral_bevel_1m_14t_30deg_2">
    <visual>
      <origin xyz="0 0 0" rpy="0 -0 0"/>
      <geometry>
        <mesh filename="../assemblies/toddlerbot/meshes/spiral_bevel_1m_14t_30deg_2_visual.stl"/>
      </geometry>
      <material name="spiral_bevel_1m_14t_30deg_2_material">
        <color rgba="0.64705882352941179736 0.64705882352941179736 0.64705882352941179736 1.0"/>
      </material>
    </visual>
    <inertial>
      <origin xyz="3.6393117165689492509e-10 -9.7220472384390577147e-10 -0.0066868955018979155808" rpy="0 0 0"/>
      <mass value="0.00073261524436595492574"/>
      <inertia ixx="1.3495056012354480834e-08" ixy="2.5804135905735602914e-17" ixz="-1.069429604882048706e-15" iyy="1.3495056157360909811e-08" iyz="-2.3876736936216327369e-16" izz="1.43559865498164051e-08"/>
    </inertial>
  </link>
  <joint name="waist_act_2" type="revolute">
    <origin xyz="1.3488415323837299524e-18 -0.019599999999999995898 -0.032750000000000001332" rpy="-1.570796326794896558 2.1438338568776302255e-14 -3.141592653589793116"/>
    <parent link="waist_link"/>
    <child link="spiral_bevel_1m_14t_30deg_2"/>
    <axis xyz="0 0 1"/>
    <limit effort="1" velocity="20" lower="-4.6774823953448034786" upper="4.6774823953448034786"/>
    <joint_properties friction="0.0"/>
  </joint>
  <joint name="left_hip_pitch" type="revolute">
    <origin xyz="0.056000000000000015044 -0.040099999999999996758 -0.022750000000000002859" rpy="-1.570796326794896558 -1.2750103475622600987e-14 1.5707963267948956698"/>
    <parent link="waist_link"/>
    <child link="2xc430"/>
    <axis xyz="0 0 1"/>
    <limit effort="1" velocity="20" lower="-1.570796326794896558" upper="2.356194490192344837"/>
    <joint_properties friction="0.0"/>
  </joint>
  <joint name="right_hip_pitch" type="revolute">
    <origin xyz="-0.056000000000000008105 -0.040100000000000010636 -0.022750000000000002859" rpy="1.570796326794896558 -4.6471944491513544759e-14 1.570796326794871689"/>
    <parent link="waist_link"/>
    <child link="2xc430_2"/>
    <axis xyz="0 0 1"/>
    <limit effort="1" velocity="20" lower="-2.356194490192344837" upper="1.570796326794896558"/>
    <joint_properties friction="0.0"/>
  </joint>
  <joint name="waist_roll" type="revolute">
    <origin xyz="-0.022707865260689970299 5.0992894772045551448e-17 -0.013999999999999354974" rpy="1.5707963267948972241 -1.2860661478503099299e-14 -1.570796326794896558"/>
    <parent link="waist_gears"/>
    <child link="waist_link"/>
    <axis xyz="0 0 1"/>
    <limit effort="1" velocity="20" lower="-0.52359877559829881566" upper="0.52359877559829881566"/>
    <joint_properties friction="0.0"/>
  </joint>
  <joint name="waist_yaw" type="revolute">
    <origin xyz="0 -5.3903211409646476972e-18 3.4694469519597032089e-18" rpy="-8.7262726250677497581e-16 -3.9724428353914665044e-15 -3.1415926535897766847"/>
    <parent link="torso"/>
    <child link="waist_gears"/>
    <axis xyz="0 0 1"/>
    <limit effort="1" velocity="20" lower="-1.570796326794896558" upper="1.570796326794896558"/>
    <joint_properties friction="0.0"/>
  </joint>
  <joint name="left_sho_pitch" type="revolute">
    <origin xyz="-0.0035000000000004437284 0.067000000000001058709 0.104236510762817286" rpy="-1.5707963267949092145 -4.1522341120980961897e-14 3.464089692039239269e-14"/>
    <parent link="torso"/>
    <child link="sho_pitch_link"/>
    <axis xyz="0 0 1"/>
    <limit effort="1" velocity="20" lower="-3.141592653589793116" upper="1.570796326794896558"/>
    <joint_properties friction="0.0"/>
  </joint>
  <joint name="right_sho_pitch" type="revolute">
    <origin xyz="-0.0034999999999986777799 -0.067000000000001072586 0.10423651076281732764" rpy="-1.5707963267948872321 3.624878175401132949e-14 -3.1415926535897562566"/>
    <parent link="torso"/>
    <child link="sho_pitch_link_2"/>
    <axis xyz="0 0 1"/>
    <limit effort="1" velocity="20" lower="-1.570796326794896558" upper="3.141592653589793116"/>
    <joint_properties friction="0.0"/>
  </joint>
  <link name="2xc430">
    <visual>
      <origin xyz="0 0 0" rpy="0 -0 0"/>
      <geometry>
        <mesh filename="../assemblies/left_leg_reorder/meshes/left_2xc430_visual.stl"/>
      </geometry>
      <material name="2xc430_material">
        <color rgba="0.51698661238356047321 0.50347815951093488618 0.49050589017722012741 1.0"/>
      </material>
    </visual>
    <inertial>
      <origin xyz="-0.012000151133967865147 0.00049588831386336226781 0.018504019244503618763" rpy="0 0 0"/>
      <mass value="0.11059999999836234164"/>
      <inertia ixx="2.2818802599021433919e-05" ixy="4.6888548259072258494e-08" ixz="4.6520143289445516196e-08" iyy="3.0871666424472358657e-05" iyz="-5.7477343899722563502e-07" izz="3.0871632082341921239e-05"/>
    </inertial>
  </link>
  <link name="hip_yaw_link">
    <visual>
      <origin xyz="0 0 0" rpy="0 -0 0"/>
      <geometry>
        <mesh filename="../assemblies/left_leg_reorder/meshes/left_hip_yaw_link_visual.stl"/>
      </geometry>
      <material name="hip_yaw_link_material">
        <color rgba="0.61568627450980395466 0.81176470588235283277 0.92941176470588238168 1.0"/>
      </material>
    </visual>
    <inertial>
      <origin xyz="-2.6529777091804280315e-18 -0.015800610849654266737 -0.019005670096647751116" rpy="0 0 0"/>
      <mass value="0.013199999999999994724"/>
      <inertia ixx="5.7894615975174157252e-06" ixy="-4.5096954887673693913e-35" ixz="-4.6860781276867837534e-35" iyy="5.0110144042848759377e-06" iyz="1.1826010760651800808e-09" izz="2.7344876354814335894e-06"/>
    </inertial>
  </link>
  <link name="spur_gear_21_teeth">
    <visual>
      <origin xyz="0 0 0" rpy="0 -0 0"/>
      <geometry>
        <mesh filename="../assemblies/left_leg_reorder/meshes/left_spur_gear_21_teeth_visual.stl"/>
      </geometry>
      <material name="spur_gear_21_teeth_material">
        <color rgba="0.61568627450980395466 0.81176470588235294379 0.9294117647058824927 1.0"/>
      </material>
    </visual>
    <inertial>
      <origin xyz="-4.5505289275732625397e-11 -1.6782160465261941845e-11 -0.00249241020062506086" rpy="0 0 0"/>
      <mass value="0.0022000000000000001325"/>
      <inertia ixx="7.0162310059594196881e-08" ixy="3.8801235249534522434e-48" ixz="2.812550158047784253e-36" iyy="7.016231005804746178e-08" iyz="3.6086829965958625889e-39" izz="1.3125544198538289306e-07"/>
    </inertial>
  </link>
  <link name="left_hip_pitch_link">
    <visual>
      <origin xyz="0 0 0" rpy="0 -0 0"/>
      <geometry>
        <mesh filename="../assemblies/left_leg_reorder/meshes/left_hip_pitch_link_visual.stl"/>
      </geometry>
      <material name="left_hip_pitch_link_material">
        <color rgba="0.79618318075804139777 0.72120748766550990538 0.38540937988910844991 1.0"/>
      </material>
    </visual>
    <collision name="left_hip_pitch_link_collision">
      <origin xyz="-0.005587761566049377 -0.004971450462434381 0.05247500166296959" rpy="0.0 0.0 0.0"/>
      <geometry>
        <capsule radius="0.035842919429443516" length="0.033264164467052146"/>
      </geometry>
    </collision>
    <inertial>
      <origin xyz="-0.0092773123251564133113 -0.0054583150498874076148 0.03951473811674113823" rpy="0 0 0"/>
      <mass value="0.15848965119785962674"/>
      <inertia ixx="8.2188788742760970928e-05" ixy="-1.3373705321924678437e-06" ixz="-9.0917451363903152822e-06" iyy="9.9396334685477745453e-05" iyz="1.298937899441436632e-06" izz="4.5892431466748451869e-05"/>
    </inertial>
  </link>
  <link name="spur_gear_18_teeth">
    <visual>
      <origin xyz="0 0 0" rpy="0 -0 0"/>
      <geometry>
        <mesh filename="../assemblies/left_leg_reorder/meshes/left_spur_gear_18_teeth_visual.stl"/>
      </geometry>
      <material name="spur_gear_18_teeth_material">
        <color rgba="0.61568627450980395466 0.81176470588235294379 0.92941176470588238168 1.0"/>
      </material>
    </visual>
    <inertial>
      <origin xyz="-7.7520300317166844125e-14 -3.6849386393036389205e-13 0.0017500000000010135486" rpy="0 0 0"/>
      <mass value="0.0011999999999999998949"/>
      <inertia ixx="2.9367899810799911435e-08" ixy="7.02382161729363821e-19" ixz="-3.9642189780159722141e-36" iyy="2.9367899814659476616e-08" iyz="7.4779432983140607212e-37" izz="5.6306346207859568346e-08"/>
    </inertial>
  </link>
  <joint name="left_hip_yaw_drive" type="revolute">
    <origin xyz="-0.019199999999993125344 0.00020000000000295475866 -3.3514857555871913064e-14" rpy="-3.1415926535896550043 -5.0131548558082056583e-13 4.8264233360682142308e-13"/>
    <parent link="left_hip_pitch_link"/>
    <child link="spur_gear_18_teeth"/>
    <axis xyz="0 0 1"/>
    <limit effort="1" velocity="20" lower="-1.8325957145940461324" upper="1.8325957145940461324"/>
    <joint_properties friction="0.0"/>
  </joint>
  <link name="left_calf_link">
    <visual>
      <origin xyz="0 0 0" rpy="0 -0 0"/>
      <geometry>
        <mesh filename="../assemblies/left_leg_reorder/meshes/left_calf_link_visual.stl"/>
      </geometry>
      <material name="left_calf_link_material">
        <color rgba="0.61568627450980395466 0.81176470588235283277 0.92941176470588238168 1.0"/>
      </material>
    </visual>
    <inertial>
      <origin xyz="-0.0043450054391248908378 0.040752982165250292712 0.0087116093515538506331" rpy="0 0 0"/>
      <mass value="0.030999999999999996309"/>
      <inertia ixx="3.3069388685110848712e-05" ixy="-1.3783307153200011406e-06" ixz="-1.2742534026335853803e-07" iyy="7.7316525337312940424e-06" iyz="-7.3356500593809455715e-08" izz="2.8031377753986189355e-05"/>
    </inertial>
  </link>
  <link name="bearing_683_3">
    <visual>
      <origin xyz="0 0 0" rpy="0 -0 0"/>
      <geometry>
        <mesh filename="../assemblies/left_leg_reorder/meshes/left_bearing_683_visual.stl"/>
      </geometry>
      <material name="bearing_683_material">
        <color rgba="0.64705882352941179736 0.64705882352941179736 0.64705882352941179736 1.0"/>
      </material>
    </visual>
    <inertial>
      <origin xyz="2.7862896558581284628e-17 -2.4186774283159373987e-19 -0.0015499999999999934403" rpy="0 0 0"/>
      <mass value="0.00048694686130641793437"/>
      <inertia ixx="2.1551456503319887385e-09" ixy="1.1914621380619801841e-28" ixz="1.5101308346925888839e-38" iyy="2.1551456503319891521e-09" iyz="1.9510753379696893624e-38" izz="3.5303647444715305817e-09"/>
    </inertial>
  </link>
  <joint name="left_knee_front_rev_2" type="revolute">
    <origin xyz="-0.0057402514854759043028 -0.013858192987668382923 0.026199999999997631434" rpy="-3.141592653589793116 5.8119982868751027369e-16 -1.5702375052298918057"/>
    <parent link="left_calf_link"/>
    <child link="bearing_683_3"/>
    <axis xyz="0 0 1"/>
    <limit effort="1" velocity="20"/>
    <joint_properties friction="0.0"/>
  </joint>
  <link name="bearing_683_4">
    <visual>
      <origin xyz="0 0 0" rpy="0 -0 0"/>
      <geometry>
        <mesh filename="../assemblies/left_leg_reorder/meshes/left_bearing_683_2_visual.stl"/>
      </geometry>
      <material name="bearing_683_2_material">
        <color rgba="0.64705882352941179736 0.64705882352941179736 0.64705882352941179736 1.0"/>
      </material>
    </visual>
    <inertial>
      <origin xyz="-2.7648254672676526986e-17 -2.4186774283159783248e-19 -0.0015500000000000003792" rpy="0 0 0"/>
      <mass value="0.00048694686130641793437"/>
      <inertia ixx="2.1551456503319887385e-09" ixy="-7.8866825289820444564e-28" ixz="-2.3651432074089930782e-38" iyy="2.1551456503319883249e-09" iyz="-6.4744944073117677257e-39" izz="3.5303647444715305817e-09"/>
    </inertial>
  </link>
  <joint name="left_knee_back_rev_2" type="revolute">
    <origin xyz="0.005740251485475959814 0.013858192987669604168 0.026199999999998637573" rpy="3.141592653589793116 1.5424497757392420363e-15 -1.5720025997049917876"/>
    <parent link="left_calf_link"/>
    <child link="bearing_683_4"/>
    <axis xyz="0 0 1"/>
    <limit effort="1" velocity="20"/>
    <joint_properties friction="0.0"/>
  </joint>
  <link name="left_ank_pitch_link">
    <visual>
      <origin xyz="0 0 0" rpy="0 -0 0"/>
      <geometry>
        <mesh filename="../assemblies/left_leg_reorder/meshes/left_ank_pitch_link_visual.stl"/>
      </geometry>
      <material name="left_ank_pitch_link_material">
        <color rgba="0.70321688500203327621 0.64514870846184446673 0.40484735422826279017 1.0"/>
      </material>
    </visual>
    <collision name="left_ank_pitch_link_collision">
      <origin xyz="0.01934999879449606 0.012000000104308128 0.016799999633803964" rpy="0 0 0"/>
      <geometry>
        <box size="0.084799999371171 0.04650000110268593 0.046639998117461806"/>
      </geometry>
    </collision>
    <inertial>
      <origin xyz="0.01777024189140121585 0.012301334508572171061 0.018813528244421770519" rpy="0 0 0"/>
      <mass value="0.17676376695067899658"/>
      <inertia ixx="4.7283316680251603133e-05" ixy="-1.3380598598440868841e-06" ixz="-5.5304058905135221963e-07" iyy="0.00010706456048089208876" iyz="-5.3225137839476522468e-08" izz="0.00012185522397136354139"/>
    </inertial>
  </link>
  <link name="ank_roll_link">
    <visual>
      <origin xyz="0 0 0" rpy="0 -0 0"/>
      <geometry>
        <mesh filename="../assemblies/left_leg_reorder/meshes/left_ank_roll_link_visual.stl"/>
      </geometry>
      <material name="ank_roll_link_material">
        <color rgba="0.61568627450980395466 0.81176470588235294379 0.92941176470588238168 1.0"/>
      </material>
    </visual>
    <collision name="ank_roll_link_collision">
      <origin xyz="-0.014500000514090061 0.0 0.038999998942017555" rpy="0 0 0"/>
      <geometry>
        <box size="0.04900000058114529 0.041999999433755875 0.12000000104308128"/>
      </geometry>
    </collision>
    <inertial>
      <origin xyz="-0.027003066516822105125 -2.005727129968961316e-12 0.033764011359896435593" rpy="0 0 0"/>
      <mass value="0.042599999999999998979"/>
      <inertia ixx="3.7284397827464328061e-05" ixy="-5.5173297572831528906e-16" ixz="2.3929183768080734033e-06" iyy="3.7589276943350436312e-05" iyz="5.093485532365750308e-12" izz="1.0090430906786797971e-05"/>
    </inertial>
  </link>
  <joint name="left_ank_roll" type="revolute">
    <origin xyz="0.022749999999985347915 -7.7438055967604668695e-15 0.019000000000000561579" rpy="-1.5707963267949487385 6.9598897929083939361e-14 1.5707963267951468023"/>
    <parent link="left_ank_pitch_link"/>
    <child link="ank_roll_link"/>
    <axis xyz="0 0 1"/>
    <limit effort="1" velocity="20" lower="-1.570796326794896558" upper="1.570796326794896558"/>
    <joint_properties friction="0.0"/>
  </joint>
  <joint name="left_ank_pitch" type="revolute">
    <origin xyz="-1.5860271119798389095e-15 0.099999999999998423483 0.027750000000001679573" rpy="-3.141592653589793116 2.6670249114811232296e-16 -3.8252904387067536217e-14"/>
    <parent link="left_calf_link"/>
    <child link="left_ank_pitch_link"/>
    <axis xyz="0 0 1"/>
    <limit effort="1" velocity="20" lower="-1.7453292519943295336" upper="0.785398163397448279"/>
    <joint_properties friction="0.0"/>
  </joint>
  <joint name="left_knee" type="revolute">
    <origin xyz="-9.150119726040088374e-16 -0.0087499999999997267464 0.085949999999997653277" rpy="1.5707963267948872321 4.8975632202997979707e-15 3.141592653589793116"/>
    <parent link="left_hip_pitch_link"/>
    <child link="left_calf_link"/>
    <axis xyz="0 0 1"/>
    <limit effort="1" velocity="20" lower="-2.0943951023931952626" upper="0"/>
    <joint_properties friction="0.0"/>
  </joint>
  <link name="xm430_plate">
    <visual>
      <origin xyz="0 0 0" rpy="0 -0 0"/>
      <geometry>
        <mesh filename="../assemblies/left_leg_reorder/meshes/left_xm430_plate_visual.stl"/>
      </geometry>
      <material name="xm430_plate_material">
        <color rgba="0.61568627450980395466 0.81176470588235294379 0.92941176470588227065 1.0"/>
      </material>
    </visual>
    <inertial>
      <origin xyz="1.2574180636021760909e-18 -2.454297176641402282e-18 0.002527851391958388285" rpy="0 0 0"/>
      <mass value="0.0027000000000000001429"/>
      <inertia ixx="1.2887178787151829982e-07" ixy="5.873956255630364624e-08" ixz="1.8999776467072272227e-37" iyy="2.4635091298412544671e-07" iyz="3.1227251026058173467e-36" izz="3.6467998413810321832e-07"/>
    </inertial>
  </link>
  <link name="knee_rod">
    <visual>
      <origin xyz="0 0 0" rpy="0 -0 0"/>
      <geometry>
        <mesh filename="../assemblies/left_leg_reorder/meshes/left_knee_rod_visual.stl"/>
      </geometry>
      <material name="knee_rod_material">
        <color rgba="0.62051618944235198416 0.78640765248647581664 0.88594253031295022716 1.0"/>
      </material>
    </visual>
    <inertial>
      <origin xyz="0.017534307439465060541 1.9597103348831170378e-05 -0.0015987301647619339435" rpy="0 0 0"/>
      <mass value="0.0031629468613064179276"/>
      <inertia ixx="2.4224450180623724587e-08" ixy="-1.9777338984408308296e-10" ixz="4.9178338762830809582e-10" iyy="8.1758888028360200094e-07" iyz="5.4963846751764537446e-13" izz="8.3704884992894945209e-07"/>
    </inertial>
  </link>
  <joint name="left_knee_front_rev_1" type="revolute">
    <origin xyz="0.013858192987669312735 -0.0057402514854763440552 0.004999999999999997502" rpy="-3.1415926535897784611 -7.4622057945515895608e-15 -3.1410338320247936927"/>
    <parent link="xm430_plate"/>
    <child link="knee_rod"/>
    <axis xyz="0 0 1"/>
    <limit effort="1" velocity="20"/>
    <joint_properties friction="0.0"/>
  </joint>
  <link name="knee_rod_2">
    <visual>
      <origin xyz="0 0 0" rpy="0 -0 0"/>
      <geometry>
        <mesh filename="../assemblies/left_leg_reorder/meshes/left_knee_rod_2_visual.stl"/>
      </geometry>
      <material name="knee_rod_2_material">
        <color rgba="0.62051618944235198416 0.78640765248647581664 0.88594253031295022716 1.0"/>
      </material>
    </visual>
    <inertial>
      <origin xyz="0.017534287401029989562 -4.2302323075187753124e-05 -0.0015987301647627436257" rpy="0 0 0"/>
      <mass value="0.0031629468613064179276"/>
      <inertia ixx="2.4225259089666954163e-08" ixy="4.2691331074777808525e-10" ixz="4.9178282561869325727e-10" iyy="8.1758847582921511072e-07" iyz="-1.1864500396169323768e-12" izz="8.370492543836071811e-07"/>
    </inertial>
  </link>
  <joint name="left_knee_back_rev_1" type="revolute">
    <origin xyz="-0.013858192987669298857 0.0057402514854763457899 0.0050000000000000044409" rpy="-3.1415926535897775729 -9.0463447639716938948e-15 3.1403863806796916691"/>
    <parent link="xm430_plate"/>
    <child link="knee_rod_2"/>
    <axis xyz="0 0 1"/>
    <limit effort="1" velocity="20"/>
    <joint_properties friction="0.0"/>
  </joint>
  <joint name="left_knee_act" type="revolute">
    <origin xyz="-7.4872906434390518473e-16 0.012449999999999808442 0.044499999999998832156" rpy="-1.5707963267948819031 1.5707963267948761299 0"/>
    <parent link="left_hip_pitch_link"/>
    <child link="xm430_plate"/>
    <axis xyz="0 0 1"/>
    <limit effort="1" velocity="20" lower="-2.0943951023931952626" upper="0"/>
    <joint_properties friction="0.0"/>
  </joint>
  <joint name="left_hip_yaw_driven" type="revolute">
    <origin xyz="6.1229146868660582384e-18 3.4694469519536141888e-18 -0.0050000000000000044409" rpy="3.1415926535897837901 1.1763977000879646623e-14 2.7749339408464486521e-29"/>
    <parent link="spur_gear_21_teeth"/>
    <child link="left_hip_pitch_link"/>
    <axis xyz="0 0 1"/>
    <limit effort="1" velocity="20" lower="-1.570796326794896558" upper="1.570796326794896558"/>
    <joint_properties friction="0.0"/>
  </joint>
  <joint name="left_hip_yaw_fixed" type="fixed">
    <origin xyz="-3.4694469519536141888e-18 -0.027999999999999986705 -0.018999999999999999528" rpy="-1.5707963267948950037 1.570796326794896336 0"/>
    <parent link="hip_yaw_link"/>
    <child link="spur_gear_21_teeth"/>
    <axis xyz="0 0 1"/>
    <limit effort="1" velocity="20"/>
    <joint_properties friction="0.0"/>
  </joint>
  <joint name="left_hip_roll" type="revolute">
    <origin xyz="-0.024000000716154074043 0.019000000152474230686 0.019000000152447748397" rpy="-1.5707963267952167463 -1.5707963267948206187 0"/>
    <parent link="2xc430"/>
    <child link="hip_yaw_link"/>
    <axis xyz="0 0 1"/>
    <limit effort="1" velocity="20" lower="-0.785398163397448279" upper="0.785398163397448279"/>
    <joint_properties friction="0.0"/>
  </joint>
  <link name="2xc430_2">
    <visual>
      <origin xyz="0 0 0" rpy="0 -0 0"/>
      <geometry>
        <mesh filename="../assemblies/right_leg_reorder/meshes/right_2xc430_visual.stl"/>
      </geometry>
      <material name="2xc430_material">
        <color rgba="0.51698661238356047321 0.50347815951093488618 0.49050589017722012741 1.0"/>
      </material>
    </visual>
    <inertial>
      <origin xyz="-0.012000151133958554886 0.00049588831385534079804 0.018504019244502921404" rpy="0 0 0"/>
      <mass value="0.11059999999836234164"/>
      <inertia ixx="2.2818802599017778125e-05" ixy="4.6888548258171730122e-08" ixz="4.6520143290256497303e-08" iyy="3.0871666424468414871e-05" iyz="-5.747734389970726397e-07" izz="3.087163208233809265e-05"/>
    </inertial>
  </link>
  <link name="hip_yaw_link_2">
    <visual>
      <origin xyz="0 0 0" rpy="0 -0 0"/>
      <geometry>
        <mesh filename="../assemblies/right_leg_reorder/meshes/right_hip_yaw_link_visual.stl"/>
      </geometry>
      <material name="hip_yaw_link_material">
        <color rgba="0.61568627450980395466 0.81176470588235283277 0.92941176470588238168 1.0"/>
      </material>
    </visual>
    <inertial>
      <origin xyz="-2.6529777091803952907e-18 -0.015800610849654270207 -0.019005670096647747647" rpy="0 0 0"/>
      <mass value="0.013199999999999994724"/>
      <inertia ixx="5.789461597517412337e-06" ixy="-3.2907588574144851931e-36" ixz="3.2286603810593676882e-35" iyy="5.0110144042848759377e-06" iyz="1.1826010760651800808e-09" izz="2.7344876354814335894e-06"/>
    </inertial>
  </link>
  <link name="spur_gear_21_teeth_2">
    <visual>
      <origin xyz="0 0 0" rpy="0 -0 0"/>
      <geometry>
        <mesh filename="../assemblies/right_leg_reorder/meshes/right_spur_gear_21_teeth_visual.stl"/>
      </geometry>
      <material name="spur_gear_21_teeth_material">
        <color rgba="0.61568627450980395466 0.81176470588235294379 0.9294117647058824927 1.0"/>
      </material>
    </visual>
    <inertial>
      <origin xyz="-4.5505289275732651246e-11 -1.6782167404155845752e-11 -0.00249241020062506086" rpy="0 0 0"/>
      <mass value="0.0022000000000000001325"/>
      <inertia ixx="7.0162310059594196881e-08" ixy="-5.4656449640042247183e-37" ixz="-4.3150666450744828066e-37" iyy="7.016231005804746178e-08" iyz="-6.9066436847920049312e-38" izz="1.3125544198538289306e-07"/>
    </inertial>
  </link>
  <link name="right_hip_pitch_link">
    <visual>
      <origin xyz="0 0 0" rpy="0 -0 0"/>
      <geometry>
        <mesh filename="../assemblies/right_leg_reorder/meshes/right_hip_pitch_link_visual.stl"/>
      </geometry>
      <material name="right_hip_pitch_link_material">
        <color rgba="0.81231119922470307326 0.71311588921073154612 0.33680089849959454762 1.0"/>
      </material>
    </visual>
    <collision name="right_hip_pitch_link_collision">
      <origin xyz="0.005910505318120873 -0.004269846160677242 0.05247500166296959" rpy="0.0 0.0 0.0"/>
      <geometry>
        <capsule radius="0.035830009896664204" length="0.03328998353261077"/>
      </geometry>
    </collision>
    <inertial>
      <origin xyz="0.010187905578010728394 -0.0056188467228508410731 0.038815928333491442337" rpy="0 0 0"/>
      <mass value="0.14548965119785950417"/>
      <inertia ixx="7.0942049594865431734e-05" ixy="1.1158758975156953663e-06" ixz="7.6515558781281230204e-06" iyy="8.5157398802913230511e-05" iyz="1.0699337399089805e-06" izz="4.0945306935231512132e-05"/>
    </inertial>
  </link>
  <link name="spur_gear_18_teeth_2">
    <visual>
      <origin xyz="0 0 0" rpy="0 -0 0"/>
      <geometry>
        <mesh filename="../assemblies/right_leg_reorder/meshes/right_spur_gear_18_teeth_visual.stl"/>
      </geometry>
      <material name="spur_gear_18_teeth_material">
        <color rgba="0.61568627450980395466 0.81176470588235294379 0.92941176470588238168 1.0"/>
      </material>
    </visual>
    <inertial>
      <origin xyz="-1.2350888076970198418e-14 -3.7635627055517647656e-13 0.0017500000000010135486" rpy="0 0 0"/>
      <mass value="0.0011999999999999998949"/>
      <inertia ixx="2.9367899810676062645e-08" ixy="-5.8641944654482965406e-38" ixz="5.3255683241419689376e-37" iyy="2.9367899814783318789e-08" iyz="1.3183913269072010735e-38" izz="5.6306346207859568346e-08"/>
    </inertial>
  </link>
  <joint name="right_hip_yaw_drive" type="revolute">
    <origin xyz="0.019199999999999432798 0.00020000000000077594597 -3.9572511933982923438e-14" rpy="-3.1415926535897544802 -2.6855722846812135811e-13 4.4780845698253311116e-13"/>
    <parent link="right_hip_pitch_link"/>
    <child link="spur_gear_18_teeth_2"/>
    <axis xyz="0 0 1"/>
    <limit effort="1" velocity="20" lower="-1.8325957145940461324" upper="1.8325957145940461324"/>
    <joint_properties friction="0.0"/>
  </joint>
  <link name="right_calf_link">
    <visual>
      <origin xyz="0 0 0" rpy="0 -0 0"/>
      <geometry>
        <mesh filename="../assemblies/right_leg_reorder/meshes/right_calf_link_visual.stl"/>
      </geometry>
      <material name="right_calf_link_material">
        <color rgba="0.61568627450980395466 0.81176470588235294379 0.9294117647058824927 1.0"/>
      </material>
    </visual>
    <inertial>
      <origin xyz="-0.0043450054394401473393 -0.040752982164757464711 0.0087116093514751895971" rpy="0 0 0"/>
      <mass value="0.030999999999999992839"/>
      <inertia ixx="3.306938868543694962e-05" ixy="1.3783307152005447193e-06" ixz="-1.274253401714876505e-07" iyy="7.7316525337490038072e-06" iyz="7.3356500737983568942e-08" izz="2.8031377754211947353e-05"/>
    </inertial>
  </link>
  <link name="bearing_683_5">
    <visual>
      <origin xyz="0 0 0" rpy="0 -0 0"/>
      <geometry>
        <mesh filename="../assemblies/right_leg_reorder/meshes/right_bearing_683_visual.stl"/>
      </geometry>
      <material name="bearing_683_material">
        <color rgba="0.64705882352941179736 0.64705882352941179736 0.64705882352941179736 1.0"/>
      </material>
    </visual>
    <inertial>
      <origin xyz="1.0732094295237755686e-19 -2.4186774283160312878e-19 -0.0015500000000000003792" rpy="0 0 0"/>
      <mass value="0.00048694686130641793437"/>
      <inertia ixx="2.1551456503319887385e-09" ixy="-1.7491155954423949016e-28" ixz="-1.4181088723102325815e-38" iyy="2.1551456503319883249e-09" iyz="2.7953863573959653405e-38" izz="3.5303647444715305817e-09"/>
    </inertial>
  </link>
  <joint name="right_knee_front_rev_2" type="revolute">
    <origin xyz="0.0057402514854763839539 -0.013858192987669326612 0.026200000000000188416" rpy="-3.1415926535897886751 -3.2616767361120603506e-15 1.5711344860216835961"/>
    <parent link="right_calf_link"/>
    <child link="bearing_683_5"/>
    <axis xyz="0 0 1"/>
    <limit effort="1" velocity="20"/>
    <joint_properties friction="0.0"/>
  </joint>
  <link name="bearing_683_6">
    <visual>
      <origin xyz="0 0 0" rpy="0 -0 0"/>
      <geometry>
        <mesh filename="../assemblies/right_leg_reorder/meshes/right_bearing_683_2_visual.stl"/>
      </geometry>
      <material name="bearing_683_2_material">
        <color rgba="0.64705882352941179736 0.64705882352941179736 0.64705882352941179736 1.0"/>
      </material>
    </visual>
    <inertial>
      <origin xyz="1.0732094295237708741e-19 -1.1092294808199861648e-18 -0.0015500000000000003792" rpy="0 0 0"/>
      <mass value="0.00048694686130641793437"/>
      <inertia ixx="2.1551456503319887385e-09" ixy="-5.2750838441507813886e-29" ixz="0" iyy="2.1551456503319883249e-09" iyz="-4.4559467649346522358e-38" izz="3.5303647444715305817e-09"/>
    </inertial>
  </link>
  <joint name="right_knee_back_rev_2" type="revolute">
    <origin xyz="-0.0057402514854757351673 0.013858192987668299656 0.026199999999999772082" rpy="-3.1415926535897873428 -1.7584330469580919838e-14 1.5695900556931792202"/>
    <parent link="right_calf_link"/>
    <child link="bearing_683_6"/>
    <axis xyz="0 0 1"/>
    <limit effort="1" velocity="20"/>
    <joint_properties friction="0.0"/>
  </joint>
  <link name="right_ank_pitch_link">
    <visual>
      <origin xyz="0 0 0" rpy="0 -0 0"/>
      <geometry>
        <mesh filename="../assemblies/right_leg_reorder/meshes/right_ank_pitch_link_visual.stl"/>
      </geometry>
      <material name="right_ank_pitch_link_material">
        <color rgba="0.70321688500203327621 0.64514870846184446673 0.40484735422826279017 1.0"/>
      </material>
    </visual>
    <collision name="right_ank_pitch_link_collision">
      <origin xyz="-0.01934999879449606 0.012000001966953278 0.016799999633803964" rpy="0 0 0"/>
      <geometry>
        <box size="0.084799999371171 0.04650000482797623 0.046639998117461806"/>
      </geometry>
    </collision>
    <inertial>
      <origin xyz="-0.017770241889542317398 0.012301334508572219634 0.018814514831173603099" rpy="0 0 0"/>
      <mass value="0.17676376695067899658"/>
      <inertia ixx="4.7283381546856786612e-05" ixy="1.3380598207240605858e-06" ixz="6.1532628607400666377e-07" iyy="0.0001070646253591693456" iyz="-5.1080086246266920656e-08" izz="0.00012185522398303507265"/>
    </inertial>
  </link>
  <link name="ank_roll_link_2">
    <visual>
      <origin xyz="0 0 0" rpy="0 -0 0"/>
      <geometry>
        <mesh filename="../assemblies/right_leg_reorder/meshes/right_ank_roll_link_visual.stl"/>
      </geometry>
      <material name="ank_roll_link_material">
        <color rgba="0.61568627450980395466 0.81176470588235294379 0.92941176470588238168 1.0"/>
      </material>
    </visual>
    <collision name="ank_roll_link_2_collision">
      <origin xyz="-0.014500000514090061 0.0 0.038999998942017555" rpy="0 0 0"/>
      <geometry>
        <box size="0.04900000058114529 0.041999999433755875 0.12000000104308128"/>
      </geometry>
    </collision>
    <inertial>
      <origin xyz="-0.027003066516822164106 -2.0057327605930640986e-12 0.033764011359896511921" rpy="0 0 0"/>
      <mass value="0.042599999999999998979"/>
      <inertia ixx="3.7284397827465391934e-05" ixy="-5.5176118208468573726e-16" ixz="2.3929183768081708121e-06" iyy="3.7589276943350449865e-05" iyz="5.0934855128918095395e-12" izz="1.0090430906787057163e-05"/>
    </inertial>
  </link>
  <joint name="right_ank_roll" type="revolute">
    <origin xyz="-0.022749999999988414906 -3.3306690738754696213e-15 0.01899999999999847991" rpy="1.5707963267948539254 5.2107940288300650017e-14 1.5707963267948161779"/>
    <parent link="right_ank_pitch_link"/>
    <child link="ank_roll_link_2"/>
    <axis xyz="0 0 1"/>
    <limit effort="1" velocity="20" lower="-1.570796326794896558" upper="1.570796326794896558"/>
    <joint_properties friction="0.0"/>
  </joint>
  <joint name="right_ank_pitch" type="revolute">
    <origin xyz="3.002118024832101527e-17 -0.10000000000000031086 0.027750000000000059341" rpy="-3.1415926535897926719 6.2448450038443343634e-16 -3.1415926535897926719"/>
    <parent link="right_calf_link"/>
    <child link="right_ank_pitch_link"/>
    <axis xyz="0 0 1"/>
    <limit effort="1" velocity="20" lower="-0.785398163397448279" upper="1.7453292519943295336"/>
    <joint_properties friction="0.0"/>
  </joint>
  <joint name="right_knee" type="revolute">
    <origin xyz="1.3574383152273289389e-16 -0.0087500000000006062512 0.085949999999999984746" rpy="-1.5707963267948805708 -3.7746952287071370984e-15 4.9902824220642934492e-15"/>
    <parent link="right_hip_pitch_link"/>
    <child link="right_calf_link"/>
    <axis xyz="0 0 1"/>
    <limit effort="1" velocity="20" lower="0" upper="2.0943951023931952626"/>
    <joint_properties friction="0.0"/>
  </joint>
  <link name="xm430_plate_2">
    <visual>
      <origin xyz="0 0 0" rpy="0 -0 0"/>
      <geometry>
        <mesh filename="../assemblies/right_leg_reorder/meshes/right_xm430_plate_visual.stl"/>
      </geometry>
      <material name="xm430_plate_material">
        <color rgba="0.61568627450980395466 0.81176470588235294379 0.92941176470588227065 1.0"/>
      </material>
    </visual>
    <inertial>
      <origin xyz="-9.7261304206861753998e-19 -2.7508707211877265003e-18 0.0025278513919583813462" rpy="0 0 0"/>
      <mass value="0.0027000000000000001429"/>
      <inertia ixx="2.4635091298412544671e-07" ixy="5.8739562556303566831e-08" ixz="3.1093856674988785691e-36" iyy="1.2887178787151822041e-07" iyz="7.4139751184723011127e-37" izz="3.6467998413810321832e-07"/>
    </inertial>
  </link>
  <link name="knee_rod_3">
    <visual>
      <origin xyz="0 0 0" rpy="0 -0 0"/>
      <geometry>
        <mesh filename="../assemblies/right_leg_reorder/meshes/right_knee_rod_visual.stl"/>
      </geometry>
      <material name="knee_rod_material">
        <color rgba="0.62051618944235198416 0.78640765248647581664 0.88594253031295022716 1.0"/>
      </material>
    </visual>
    <inertial>
      <origin xyz="0.017534310910028421543 1.185877916911817973e-05 -0.0015987301647647246799" rpy="0 0 0"/>
      <mass value="0.0031629468613064179276"/>
      <inertia ixx="2.4224310081263208001e-08" ixy="-1.196784738102416964e-10" ixz="4.9178348499397176204e-10" iyy="8.1758895033325342041e-07" iyz="3.3260227775621559853e-13" izz="8.3704877987923238757e-07"/>
    </inertial>
  </link>
  <joint name="right_knee_front_rev_1" type="revolute">
    <origin xyz="0.0057402514854763518615 -0.013858192987669257223 0.0050000000000000113798" rpy="3.141592653589793116 -1.111704857049913648e-15 -1.5704581675681130726"/>
    <parent link="xm430_plate_2"/>
    <child link="knee_rod_3"/>
    <axis xyz="0 0 1"/>
    <limit effort="1" velocity="20"/>
    <joint_properties friction="0.0"/>
  </joint>
  <link name="knee_rod_4">
    <visual>
      <origin xyz="0 0 0" rpy="0 -0 0"/>
      <geometry>
        <mesh filename="../assemblies/right_leg_reorder/meshes/right_knee_rod_2_visual.stl"/>
      </geometry>
      <material name="knee_rod_2_material">
        <color rgba="0.62051618944235198416 0.78640765248647581664 0.88594253031295022716 1.0"/>
      </material>
    </visual>
    <inertial>
      <origin xyz="0.017534287401106681686 -4.230225965767764535e-05 -0.0015987301647646889012" rpy="0 0 0"/>
      <mass value="0.0031629468613064179276"/>
      <inertia ixx="2.4225259086581160197e-08" ixy="4.269126707158853537e-10" ixz="4.9178282565450748946e-10" iyy="8.175884758307931331e-07" iyz="-1.186448257998784681e-12" izz="8.3704925438208728636e-07"/>
    </inertial>
  </link>
  <joint name="right_knee_back_rev_1" type="revolute">
    <origin xyz="-0.0057402514854763440552 0.013858192987669354368 0.0049999999999999905631" rpy="-3.141592653589793116 1.2542833298517128192e-14 -1.5720025978966174485"/>
    <parent link="xm430_plate_2"/>
    <child link="knee_rod_4"/>
    <axis xyz="0 0 1"/>
    <limit effort="1" velocity="20"/>
    <joint_properties friction="0.0"/>
  </joint>
  <joint name="right_knee_act" type="revolute">
    <origin xyz="3.9287971482105029401e-18 0.0124499999999997564 0.044500000000000400346" rpy="-1.5707963267948774622 -2.7749270113816245533e-16 5.4939032356427845754e-16"/>
    <parent link="right_hip_pitch_link"/>
    <child link="xm430_plate_2"/>
    <axis xyz="0 0 1"/>
    <limit effort="1" velocity="20" lower="0" upper="2.0943951023931952626"/>
    <joint_properties friction="0.0"/>
  </joint>
  <joint name="right_hip_yaw_driven" type="revolute">
    <origin xyz="-5.2457909251798218506e-18 -3.4694469519536141888e-18 -0.0050000000000000113798" rpy="3.1415926535897922278 -1.4272087055159576395e-14 -3.6758798213763643757e-30"/>
    <parent link="spur_gear_21_teeth_2"/>
    <child link="right_hip_pitch_link"/>
    <axis xyz="0 0 1"/>
    <limit effort="1" velocity="20" lower="-1.570796326794896558" upper="1.570796326794896558"/>
    <joint_properties friction="0.0"/>
  </joint>
  <joint name="right_hip_yaw_fixed" type="fixed">
    <origin xyz="6.9388939039072283776e-18 -0.027999999999999997113 -0.019000000000000002998" rpy="-1.5707963267948990005 1.5707963267948785724 0"/>
    <parent link="hip_yaw_link_2"/>
    <child link="spur_gear_21_teeth_2"/>
    <axis xyz="0 0 1"/>
    <limit effort="1" velocity="20"/>
    <joint_properties friction="0.0"/>
  </joint>
  <joint name="right_hip_roll" type="revolute">
    <origin xyz="-0.024000000716143506108 0.019000000152447637375 0.019000000152446804708" rpy="-1.5707963267948252817 -1.5707963267948190644 0"/>
    <parent link="2xc430_2"/>
    <child link="hip_yaw_link_2"/>
    <axis xyz="0 0 1"/>
    <limit effort="1" velocity="20" lower="-0.785398163397448279" upper="0.785398163397448279"/>
    <joint_properties friction="0.0"/>
  </joint>
  <link name="sho_pitch_link">
    <visual>
      <origin xyz="0 0 0" rpy="0 -0 0"/>
      <geometry>
        <mesh filename="../assemblies/left_arm_gripper/meshes/left_sho_pitch_link_visual.stl"/>
      </geometry>
      <material name="sho_pitch_link_material">
        <color rgba="0.61568627450980395466 0.81176470588235294379 0.92941176470588227065 1.0"/>
      </material>
    </visual>
    <inertial>
      <origin xyz="1.8449019812287164588e-18 -2.080223803955683775e-18 0.012913250798677554029" rpy="0 0 0"/>
      <mass value="0.0085999999999999982708"/>
      <inertia ixx="1.8365636406635691559e-06" ixy="1.0387514045979629962e-20" ixz="-1.6193093852519860617e-61" iyy="4.0110869076838864174e-06" iyz="-1.0800914119377960692e-46" izz="3.516051645049224817e-06"/>
    </inertial>
  </link>
  <link name="2xl430_gears">
    <visual>
      <origin xyz="0 0 0" rpy="0 -0 0"/>
      <geometry>
        <mesh filename="../assemblies/left_arm_gripper/meshes/left_2xl430_gears_visual.stl"/>
      </geometry>
      <material name="2xl430_gears_material">
        <color rgba="0.7591476792056923717 0.85560384745670914342 0.90519468321360618823 1.0"/>
      </material>
    </visual>
    <collision name="2xl430_gears_collision">
      <origin xyz="-0.011708624550579447 -0.002663159404643135 -0.01986897463774039" rpy="0 0 0"/>
      <geometry>
        <sphere radius="0.031173983743527804"/>
      </geometry>
    </collision>
    <inertial>
      <origin xyz="-0.011592905737981450826 -0.002423855364253546963 -0.01855109552380399679" rpy="0 0 0"/>
      <mass value="0.11800003674524908726"/>
      <inertia ixx="2.7511021050426360412e-05" ixy="9.0043904315238054324e-07" ixz="-2.3349710124000869682e-08" iyy="3.2796197843347020334e-05" iyz="-6.5715119654760767617e-07" izz="3.5775739835743296106e-05"/>
    </inertial>
  </link>
  <link name="spur_1m_24t_drive">
    <visual>
      <origin xyz="0 0 0" rpy="0 -0 0"/>
      <geometry>
        <mesh filename="../assemblies/left_arm_gripper/meshes/left_spur_1m_24t_drive_visual.stl"/>
      </geometry>
      <material name="spur_1m_24t_drive_material">
        <color rgba="0.61568627450980406568 0.81176470588235294379 0.92941176470588238168 1.0"/>
      </material>
    </visual>
    <inertial>
      <origin xyz="3.0326539266682488924e-15 -3.3909557259597738952e-16 0.0048096451474093039266" rpy="0 0 0"/>
      <mass value="0.0032000000000000001533"/>
      <inertia ixx="1.409759888701696132e-07" ixy="1.5562823081573231774e-15" ixz="1.8909116097027644629e-36" iyy="1.4097598803635998845e-07" iyz="8.7196449218219347336e-37" izz="2.4107776386988835496e-07"/>
    </inertial>
  </link>
  <joint name="left_sho_yaw_drive" type="revolute">
    <origin xyz="-0.024000000716140296869 -0.019000000152454142588 -0.019000000152450579466" rpy="1.5707963267950031394 -3.1434454584096845964e-14 1.6688855498804727815e-13"/>
    <parent link="2xl430_gears"/>
    <child link="spur_1m_24t_drive"/>
    <axis xyz="0 0 1"/>
    <limit effort="1" velocity="20" lower="-2.6179938779914944114" upper="2.6179938779914944114"/>
    <joint_properties friction="0.0"/>
  </joint>
  <link name="spur_1m_24t_driven">
    <visual>
      <origin xyz="0 0 0" rpy="0 -0 0"/>
      <geometry>
        <mesh filename="../assemblies/left_arm_gripper/meshes/left_spur_1m_24t_driven_visual.stl"/>
      </geometry>
      <material name="spur_1m_24t_driven_material">
        <color rgba="0.23137254901960788156 0.38039215686274502337 0.7058823529411765163 1.0"/>
      </material>
    </visual>
    <inertial>
      <origin xyz="-6.3908415917439005078e-18 -1.6886349105605204739e-15 -0.00097237500038396124102" rpy="0 0 0"/>
      <mass value="0.0026999999999999997093"/>
      <inertia ixx="1.2202334915684083145e-07" ixy="4.2715130792968527767e-37" ixz="-7.4298475334020377518e-37" iyy="1.2202334915684064616e-07" iyz="3.4121884323812485808e-36" izz="2.3180293204341257533e-07"/>
    </inertial>
  </link>
  <link name="sho_yaw_link">
    <visual>
      <origin xyz="0 0 0" rpy="0 -0 0"/>
      <geometry>
        <mesh filename="../assemblies/left_arm_gripper/meshes/left_sho_yaw_link_visual.stl"/>
      </geometry>
      <material name="sho_yaw_link_material">
        <color rgba="0.61568627450980395466 0.81176470588235294379 0.92941176470588238168 1.0"/>
      </material>
    </visual>
    <inertial>
      <origin xyz="-2.4352534325391168114e-18 2.8819643225844087237e-18 -0.024649285094360061377" rpy="0 0 0"/>
      <mass value="0.014500000000000004205"/>
      <inertia ixx="9.2365904614004439553e-06" ixy="3.5862833440690446869e-13" ixz="-1.2687936100387064119e-34" iyy="5.8163826335078791714e-06" iyz="-1.5023236319927603688e-35" izz="4.5074356741562113561e-06"/>
    </inertial>
  </link>
  <link name="2xl430_gears_2">
    <visual>
      <origin xyz="0 0 0" rpy="0 -0 0"/>
      <geometry>
        <mesh filename="../assemblies/left_arm_gripper/meshes/left_2xl430_gears_2_visual.stl"/>
      </geometry>
      <material name="2xl430_gears_2_material">
        <color rgba="0.7591476792056923717 0.85560384745670914342 0.90519468321360618823 1.0"/>
      </material>
    </visual>
    <collision name="2xl430_gears_2_collision">
      <origin xyz="-0.011708624550579465 -0.002663159404643134 -0.019868974637740424" rpy="0 0 0"/>
      <geometry>
        <sphere radius="0.031173983743527804"/>
      </geometry>
    </collision>
    <inertial>
      <origin xyz="-0.01159290573798117327 -0.0024238553642602004949 -0.018551095523806161725" rpy="0 0 0"/>
      <mass value="0.11800003674524908726"/>
      <inertia ixx="2.7511021050432340465e-05" ixy="9.0043904315261866538e-07" ixz="-2.3349710124131547675e-08" iyy="3.2796197843347521777e-05" iyz="-6.5715119654698193058e-07" izz="3.5775739835749923291e-05"/>
    </inertial>
  </link>
  <link name="spur_1m_24t_drive_2">
    <visual>
      <origin xyz="0 0 0" rpy="0 -0 0"/>
      <geometry>
        <mesh filename="../assemblies/left_arm_gripper/meshes/left_spur_1m_24t_drive_2_visual.stl"/>
      </geometry>
      <material name="spur_1m_24t_drive_2_material">
        <color rgba="0.61568627450980406568 0.81176470588235294379 0.92941176470588238168 1.0"/>
      </material>
    </visual>
    <inertial>
      <origin xyz="3.0395928205721561208e-15 -3.3909557259597763604e-16 0.0048096451474092995898" rpy="0 0 0"/>
      <mass value="0.0032000000000000001533"/>
      <inertia ixx="1.409759888701696132e-07" ixy="1.5562823101719447534e-15" ixz="4.5205440903615987127e-36" iyy="1.4097598803636001492e-07" iyz="4.1303952486303564848e-36" izz="2.4107776386988835496e-07"/>
    </inertial>
  </link>
  <joint name="left_elbow_yaw_drive" type="revolute">
    <origin xyz="-0.024000000716141486889 -0.01900000015246021412 -0.019000000152444587731" rpy="1.5707963267946158936 -5.9566245242711314536e-14 1.228127009104490865e-13"/>
    <parent link="2xl430_gears_2"/>
    <child link="spur_1m_24t_drive_2"/>
    <axis xyz="0 0 1"/>
    <limit effort="1" velocity="20" lower="-2.6179938779914944114" upper="2.6179938779914944114"/>
    <joint_properties friction="0.0"/>
  </joint>
  <link name="spur_1m_24t_driven_2">
    <visual>
      <origin xyz="0 0 0" rpy="0 -0 0"/>
      <geometry>
        <mesh filename="../assemblies/left_arm_gripper/meshes/left_spur_1m_24t_driven_2_visual.stl"/>
      </geometry>
      <material name="spur_1m_24t_driven_2_material">
        <color rgba="0.23137254901960788156 0.38039215686274502337 0.7058823529411765163 1.0"/>
      </material>
    </visual>
    <inertial>
      <origin xyz="-2.9213946397902759189e-18 -1.6886349105605200794e-15 -0.00097237500038395430213" rpy="0 0 0"/>
      <mass value="0.0026999999999999997093"/>
      <inertia ixx="1.2202334915684083145e-07" ixy="0" ixz="0" iyy="1.2202334915684064616e-07" iyz="5.6884209303599264861e-37" izz="2.3180293204341257533e-07"/>
    </inertial>
  </link>
  <link name="elb_yaw_link">
    <visual>
      <origin xyz="0 0 0" rpy="0 -0 0"/>
      <geometry>
        <mesh filename="../assemblies/left_arm_gripper/meshes/left_elb_yaw_link_visual.stl"/>
      </geometry>
      <material name="elb_yaw_link_material">
        <color rgba="0.61568627450980395466 0.81176470588235294379 0.92941176470588227065 1.0"/>
      </material>
    </visual>
    <inertial>
      <origin xyz="5.3127688027189133061e-08 0.0019833638641961665906 -0.023416643551549962826" rpy="0 0 0"/>
      <mass value="0.017500000000000001665"/>
      <inertia ixx="1.4134344903109196387e-05" ixy="1.6945783921929356084e-12" ixz="-1.1286398721892709078e-11" iyy="6.6435900776211340404e-06" iyz="1.0545227077253057579e-06" izz="8.9925290757998976773e-06"/>
    </inertial>
  </link>
  <link name="spur_1m_24t_driven_3">
    <visual>
      <origin xyz="0 0 0" rpy="0 -0 0"/>
      <geometry>
        <mesh filename="../assemblies/left_arm_gripper/meshes/left_spur_1m_24t_driven_3_visual.stl"/>
      </geometry>
      <material name="spur_1m_24t_driven_3_material">
        <color rgba="0.23137254901960788156 0.38039215686274502337 0.7058823529411765163 1.0"/>
      </material>
    </visual>
    <inertial>
      <origin xyz="-2.9213946397902759189e-18 -1.6886349105605200794e-15 -0.0025723750003839584988" rpy="0 0 0"/>
      <mass value="0.0026999999999999997093"/>
      <inertia ixx="1.2202334915684083145e-07" ixy="-3.9235082874827157071e-37" ixz="1.540151194783440735e-36" iyy="1.2202334915684064616e-07" iyz="1.0864894308623725195e-65" izz="2.3180293204341257533e-07"/>
    </inertial>
  </link>
  <link name="2xl430_gears_3">
    <visual>
      <origin xyz="0 0 0" rpy="0 -0 0"/>
      <geometry>
        <mesh filename="../assemblies/left_arm_gripper/meshes/left_2xl430_gears_3_visual.stl"/>
      </geometry>
      <material name="2xl430_gears_3_material">
        <color rgba="0.7591476792056923717 0.85560384745670914342 0.90519468321360618823 1.0"/>
      </material>
    </visual>
    <collision name="2xl430_gears_3_collision">
      <origin xyz="-0.0008533845367763252 0.011719140412504324 -0.02433735651741285" rpy="0 0 0"/>
      <geometry>
        <sphere radius="0.031160071864808042"/>
      </geometry>
    </collision>
    <inertial>
      <origin xyz="0.00044890447619516703551 0.011592905379904264868 -0.024576144788197775565" rpy="0 0 0"/>
      <mass value="0.11800003674524908726"/>
      <inertia ixx="3.5775739835741886643e-05" ixy="2.334971012477968339e-08" ixz="6.5715119654911433603e-07" iyy="2.7511021050427295537e-05" iyz="9.0043904314901125793e-07" izz="3.27961978433465731e-05"/>
    </inertial>
  </link>
  <link name="spur_1m_24t_drive_3">
    <visual>
      <origin xyz="0 0 0" rpy="0 -0 0"/>
      <geometry>
        <mesh filename="../assemblies/left_arm_gripper/meshes/left_spur_1m_24t_drive_3_visual.stl"/>
      </geometry>
      <material name="spur_1m_24t_drive_3_material">
        <color rgba="0.61568627450980406568 0.81176470588235294379 0.92941176470588238168 1.0"/>
      </material>
    </visual>
    <inertial>
      <origin xyz="3.0326539266682488924e-15 -3.3909557259597738952e-16 0.004809645147409304794" rpy="0 0 0"/>
      <mass value="0.0032000000000000001533"/>
      <inertia ixx="1.409759888701696132e-07" ixy="1.556282311437739129e-15" ixz="-1.8235547395955791874e-37" iyy="1.4097598803635998845e-07" iyz="-5.9472593219276696462e-37" izz="2.4107776386988835496e-07"/>
    </inertial>
  </link>
  <joint name="left_wrist_pitch_drive" type="revolute">
    <origin xyz="-1.5244671348201973698e-10 0.024000000358068290796 -0.0080000000000027861324" rpy="-4.3526989296690041628e-14 -1.012303054589254389e-13 -1.5707963267948548136"/>
    <parent link="2xl430_gears_3"/>
    <child link="spur_1m_24t_drive_3"/>
    <axis xyz="0 0 1"/>
    <limit effort="1" velocity="20" lower="-1.9198621771937625091" upper="1.3962634015954635824"/>
    <joint_properties friction="0.0"/>
  </joint>
  <link name="gripper_connector">
    <visual>
      <origin xyz="0 0 0" rpy="0 -0 0"/>
      <geometry>
        <mesh filename="../assemblies/left_arm_gripper/meshes/left_gripper_connector_visual.stl"/>
      </geometry>
      <material name="gripper_connector_material">
        <color rgba="0.61568627450980395466 0.81176470588235294379 0.92941176470588238168 1.0"/>
      </material>
    </visual>
    <collision name="gripper_connector_collision">
      <origin xyz="-0.001999999862164259 -0.013250000309199095 -0.008499999530613422" rpy="0 0 0"/>
      <geometry>
        <box size="0.024999999441206455 0.04750000033527613 0.0669999998062849"/>
      </geometry>
    </collision>
    <inertial>
      <origin xyz="-0.00018842170188954562057 -0.022508162473387258173 -0.010896047477464287576" rpy="0 0 0"/>
      <mass value="0.0099999999999999967387"/>
      <inertia ixx="5.9456375734536726584e-06" ixy="-2.4479055491886681531e-08" ixz="-4.0329437936864279052e-08" iyy="4.2603724874314054683e-06" iyz="4.585261274976229064e-07" izz="2.4669632528047159756e-06"/>
    </inertial>
  </link>
  <link name="left_rail_guide">
    <visual>
      <origin xyz="0 0 0" rpy="0 -0 0"/>
      <geometry>
        <mesh filename="../assemblies/left_arm_gripper/meshes/left_rail_guide_visual.stl"/>
      </geometry>
      <material name="left_rail_guide_material">
        <color rgba="0.63181718041513335038 0.80465605329635436771 0.89972875975946808857 1.0"/>
      </material>
    </visual>
    <collision name="left_rail_guide_collision">
      <origin xyz="0.017000000923871994 0.0029250001534819603 0.008150000125169754" rpy="0 0 0"/>
      <geometry>
        <box size="0.09000000357627869 0.04934999905526638 0.018149999901652336"/>
      </geometry>
    </collision>
    <inertial>
      <origin xyz="0.010819518839780870034 0.0021116106205359632016 -7.6871709864913219043e-05" rpy="0 0 0"/>
      <mass value="0.031121017612416673748"/>
      <inertia ixx="7.8532725551086577254e-06" ixy="2.0671876731375216749e-06" ixz="4.0098876287871815401e-06" iyy="2.7330594711584456634e-05" iyz="-8.9062740055664937356e-07" izz="3.0532648647413076451e-05"/>
    </inertial>
  </link>
  <link name="rail">
    <visual>
      <origin xyz="0 0 0" rpy="0 -0 0"/>
      <geometry>
        <mesh filename="../assemblies/left_arm_gripper/meshes/left_rail_visual.stl"/>
      </geometry>
      <material name="rail_material">
        <color rgba="0.64705882352941179736 0.64705882352941179736 0.64705882352941179736 1.0"/>
      </material>
    </visual>
    <collision name="rail_collision">
      <origin xyz="0 0 0" rpy="0 -0 0"/>
      <geometry>
        <mesh filename="../assemblies/left_arm_gripper/meshes/left_rail_visual.stl"/>
      </geometry>
    </collision>
    <inertial>
      <origin xyz="0.029554714214719168819 -0.015933051259988686987 -0.010638774525132309312" rpy="0 0 0"/>
      <mass value="0.017100000000000004086"/>
      <inertia ixx="3.6591938331681682466e-06" ixy="2.101313841244636705e-08" ixz="-1.1335092663308559672e-07" iyy="4.7380338190523213965e-06" iyz="3.1225833654311399591e-08" izz="6.0956112819844626417e-06"/>
    </inertial>
  </link>
  <joint name="left_gripper_pinion" type="prismatic">
    <origin xyz="-0.028872600000000164799 -0.015974999999999989209 -0.0053499999999998826272" rpy="-3.141592653589793116 1.5707963267948943376 0"/>
    <parent link="left_rail_guide"/>
    <child link="rail"/>
    <axis xyz="0 0 1"/>
    <limit effort="1" velocity="20" lower="-0.025000000000000001388" upper="0"/>
    <joint_properties friction="0.0"/>
  </joint>
  <link name="rail_2">
    <visual>
      <origin xyz="0 0 0" rpy="0 -0 0"/>
      <geometry>
        <mesh filename="../assemblies/left_arm_gripper/meshes/left_rail_2_visual.stl"/>
      </geometry>
      <material name="rail_2_material">
        <color rgba="0.64705882352941179736 0.64705882352941179736 0.64705882352941179736 1.0"/>
      </material>
    </visual>
    <collision name="rail_2_collision">
      <origin xyz="0 0 0" rpy="0 -0 0"/>
      <geometry>
        <mesh filename="../assemblies/left_arm_gripper/meshes/left_rail_2_visual.stl"/>
      </geometry>
    </collision>
    <inertial>
      <origin xyz="0.029554714214719168819 -0.015933051259988697396 -0.010638774525132309312" rpy="0 0 0"/>
      <mass value="0.017100000000000004086"/>
      <inertia ixx="3.6591938331681682466e-06" ixy="2.101313841244636705e-08" ixz="-1.1335092663308559672e-07" iyy="4.7380338190523213965e-06" iyz="3.1225833654311399591e-08" izz="6.0956112819844626417e-06"/>
    </inertial>
  </link>
  <joint name="left_gripper_pinion_mirror" type="prismatic">
    <origin xyz="0.062872600000000139486 0.015974999999999992678 -0.0053499999999998826272" rpy="4.5102810356081756005e-17 1.5707963267948943376 0"/>
    <parent link="left_rail_guide"/>
    <child link="rail_2"/>
    <axis xyz="0 0 1"/>
    <limit effort="1" velocity="20" lower="-0.025000000000000001388" upper="0"/>
    <joint_properties friction="0.0"/>
  </joint>
  <link name="xc330">
    <visual>
      <origin xyz="0 0 0" rpy="0 -0 0"/>
      <geometry>
        <mesh filename="../assemblies/left_arm_gripper/meshes/left_xc330_visual.stl"/>
      </geometry>
      <material name="xc330_material">
        <color rgba="0.66932535752643762539 0.72911795671409951325 0.67547870389434383487 1.0"/>
      </material>
    </visual>
    <inertial>
      <origin xyz="0.0080045171539637974961 -0.015558009851629327203 -0.011717805512823017966" rpy="0 0 0"/>
      <mass value="0.026599999993091757305"/>
      <inertia ixx="3.8683410666521895126e-06" ixy="-7.7688424003112006139e-10" ixz="5.7969695833402896073e-10" iyy="2.1626767907501911835e-06" iyz="8.3590274794495044522e-09" izz="3.3158761130057114888e-06"/>
    </inertial>
  </link>
  <link name="spur_gear_(18_teeth)">
    <visual>
      <origin xyz="0 0 0" rpy="0 -0 0"/>
      <geometry>
        <mesh filename="../assemblies/left_arm_gripper/meshes/left_spur_gear_(18_teeth)_visual.stl"/>
      </geometry>
      <material name="spur_gear_(18_teeth)_material">
        <color rgba="0.91764705882352926025 0.91764705882352926025 0.91764705882352926025 1.0"/>
      </material>
    </visual>
    <inertial>
      <origin xyz="6.4184768611141862493e-17 -3.8163916471489756077e-17 -0.0025000000000000351802" rpy="0 0 0"/>
      <mass value="0.0012999999999999999403"/>
      <inertia ixx="3.3282842836137718203e-08" ixy="-1.5693871188436038975e-22" ixz="-1.7407521658115461729e-36" iyy="3.3282842836137460123e-08" iyz="1.3305382458620200286e-36" izz="6.1149428795799489038e-08"/>
    </inertial>
  </link>
  <joint name="left_gripper_rack" type="revolute">
    <origin xyz="0.0079999999999991987243 -0.022499999999989410415 -0.026000000000007045253" rpy="-6.0998081585770428182e-13 -5.3836237079920826632e-14 3.1415926535897362726"/>
    <parent link="xc330"/>
    <child link="spur_gear_(18_teeth)"/>
    <axis xyz="0 0 1"/>
    <limit effort="1" velocity="20" lower="0" upper="2.7052603405912107881"/>
    <joint_properties friction="0.0"/>
  </joint>
  <joint name="left_gripper_motor" type="fixed">
    <origin xyz="-0.02195000000000000423 0.022600000000000005501 0.023300000000000015143" rpy="4.1904291285340139929e-27 -4.2723316019681090438e-30 3.8731841363269910881e-30"/>
    <parent link="left_rail_guide"/>
    <child link="xc330"/>
    <axis xyz="0 0 1"/>
    <limit effort="1" velocity="20"/>
    <joint_properties friction="0.0"/>
  </joint>
  <joint name="left_gripper_fixed" type="fixed">
    <origin xyz="3.4694469519536141888e-18 -0.037000000000000005107 -0.036000000000000004219" rpy="-1.5707963267948923392 -1.5707963267948945596 0"/>
    <parent link="gripper_connector"/>
    <child link="left_rail_guide"/>
    <axis xyz="0 0 1"/>
    <limit effort="1" velocity="20"/>
    <joint_properties friction="0.0"/>
  </joint>
  <joint name="left_wrist_roll" type="revolute">
    <origin xyz="0.0190000000000069523 -3.5808195297803990798e-10 -0.027000000152449583901" rpy="-5.2304162520204924206e-14 1.5707963267947342434 0"/>
    <parent link="2xl430_gears_3"/>
    <child link="gripper_connector"/>
    <axis xyz="0 0 1"/>
    <limit effort="1" velocity="20" lower="-1.9198621771937625091" upper="1.3962634015954635824"/>
    <joint_properties friction="0.0"/>
  </joint>
  <link name="wrist_bearing_plate">
    <visual>
      <origin xyz="0 0 0" rpy="0 -0 0"/>
      <geometry>
        <mesh filename="../assemblies/left_arm_gripper/meshes/left_wrist_bearing_plate_visual.stl"/>
      </geometry>
      <material name="wrist_bearing_plate_material">
        <color rgba="0.71932243125689065977 0.63128434304969727187 0.52422389360984933404 1.0"/>
      </material>
    </visual>
    <inertial>
      <origin xyz="-0.0075835583121500122275 -0.015499999999999973868 -0.0018386323705903270722" rpy="0 0 0"/>
      <mass value="0.0049000367468305548388"/>
      <inertia ixx="4.9707430109150065605e-07" ixy="8.6939968023150419247e-23" ixz="1.8100904820814035248e-08" iyy="7.126852360353850012e-07" iyz="2.1431646046406056847e-23" izz="1.1919657811600107117e-06"/>
    </inertial>
  </link>
  <joint name="left_wrist_pitch_fixed" type="fixed">
    <origin xyz="0.015500000000001491751 -8.0768725041480138316e-15 -0.045000000000001545708" rpy="-2.3964771139741255694e-14 -1.2834872054056844396e-13 -1.5707963267947808728"/>
    <parent link="2xl430_gears_3"/>
    <child link="wrist_bearing_plate"/>
    <axis xyz="0 0 1"/>
    <limit effort="1" velocity="20"/>
    <joint_properties friction="0.0"/>
  </joint>
  <joint name="left_wrist_pitch_driven" type="revolute">
    <origin xyz="0 6.3108872417680944433e-30 -0.0016000000000000005104" rpy="-1.1497747198776528831e-14 -1.1323324151998767252e-14 -1.570796326794896558"/>
    <parent link="spur_1m_24t_driven_3"/>
    <child link="2xl430_gears_3"/>
    <axis xyz="0 0 1"/>
    <limit effort="1" velocity="20" lower="-1.3962634015954635824" upper="1.9198621771937625091"/>
    <joint_properties friction="0.0"/>
  </joint>
  <joint name="left_wrist_roll_fixed" type="fixed">
    <origin xyz="0 -0.025299999999999999573 -0.05200000000000001843" rpy="1.570796326794896558 -1.570796326794896558 0"/>
    <parent link="elb_yaw_link"/>
    <child link="spur_1m_24t_driven_3"/>
    <axis xyz="0 0 1"/>
    <limit effort="1" velocity="20"/>
    <joint_properties friction="0.0"/>
  </joint>
  <joint name="left_elbow_yaw_fixed" type="fixed">
    <origin xyz="0 0 0.0016000000000000180744" rpy="3.141592653589793116 1.6076875098280159747e-30 -1.570796326794896558"/>
    <parent link="spur_1m_24t_driven_2"/>
    <child link="elb_yaw_link"/>
    <axis xyz="0 0 1"/>
    <limit effort="1" velocity="20"/>
    <joint_properties friction="0.0"/>
  </joint>
  <joint name="left_elbow_yaw_driven" type="revolute">
    <origin xyz="-3.5806306877828042445e-10 -0.027000000152460831848 -0.018999999999996998457" rpy="1.5707963267946301045 -3.8080649744640572174e-14 1.8610630468591325517e-14"/>
    <parent link="2xl430_gears_2"/>
    <child link="spur_1m_24t_driven_2"/>
    <axis xyz="0 0 1"/>
    <limit effort="1" velocity="20" lower="-2.6179938779914944114" upper="2.6179938779914944114"/>
    <joint_properties friction="0.0"/>
  </joint>
  <joint name="left_elbow_roll" type="revolute">
    <origin xyz="-3.4694469519536141888e-18 -0.019000000000000002998 -0.058999999999999976075" rpy="1.570796326794896558 6.8561441953598501935e-15 1.0275284166515774965e-14"/>
    <parent link="sho_yaw_link"/>
    <child link="2xl430_gears_2"/>
    <axis xyz="0 0 1"/>
    <limit effort="1" velocity="20" lower="-1.9198621771937625091" upper="2.4434609527920612138"/>
    <joint_properties friction="0.0"/>
  </joint>
  <joint name="left_sho_yaw_fixed" type="fixed">
    <origin xyz="0 7.8886090522101180541e-31 0.0016000000000000041966" rpy="3.1415926535897629179 2.2803010536375530635e-31 -2.1481139489452393748e-30"/>
    <parent link="spur_1m_24t_driven"/>
    <child link="sho_yaw_link"/>
    <axis xyz="0 0 1"/>
    <limit effort="1" velocity="20"/>
    <joint_properties friction="0.0"/>
  </joint>
  <joint name="left_sho_yaw_driven" type="revolute">
    <origin xyz="-3.5806558759676754278e-10 -0.027000000152452598851 -0.019000000000006039835" rpy="1.5707963267950022512 -1.1972614697765140736e-14 1.2707074635707766131e-13"/>
    <parent link="2xl430_gears"/>
    <child link="spur_1m_24t_driven"/>
    <axis xyz="0 0 1"/>
    <limit effort="1" velocity="20" lower="-2.6179938779914944114" upper="2.6179938779914944114"/>
    <joint_properties friction="0.0"/>
  </joint>
  <joint name="left_sho_roll" type="revolute">
    <origin xyz="-0.018999999999999933609 -2.4431845435657347395e-17 0.026999999999999909489" rpy="3.1415926535897913396 1.5707963267948392705 0"/>
    <parent link="sho_pitch_link"/>
    <child link="2xl430_gears"/>
    <axis xyz="0 0 1"/>
    <limit effort="1" velocity="20" lower="-1.570796326794896558" upper="0.34906585039886589561"/>
    <joint_properties friction="0.0"/>
  </joint>
  <link name="sho_pitch_link_2">
    <visual>
      <origin xyz="0 0 0" rpy="0 -0 0"/>
      <geometry>
        <mesh filename="../assemblies/right_arm_gripper/meshes/right_sho_pitch_link_visual.stl"/>
      </geometry>
      <material name="sho_pitch_link_material">
        <color rgba="0.61568627450980395466 0.81176470588235294379 0.92941176470588227065 1.0"/>
      </material>
    </visual>
    <inertial>
      <origin xyz="1.8449019812287260885e-18 -2.0802238039556934046e-18 0.012913250798677599132" rpy="0 0 0"/>
      <mass value="0.0085999999999999982708"/>
      <inertia ixx="1.8365636406635822849e-06" ixy="-6.8542962956938853498e-57" ixz="1.6528758011273076664e-97" iyy="4.0110869076839152165e-06" iyz="-2.646223959247617687e-46" izz="3.5160516450492493809e-06"/>
    </inertial>
  </link>
  <link name="2xl430_gears_4">
    <visual>
      <origin xyz="0 0 0" rpy="0 -0 0"/>
      <geometry>
        <mesh filename="../assemblies/right_arm_gripper/meshes/right_2xl430_gears_visual.stl"/>
      </geometry>
      <material name="2xl430_gears_material">
        <color rgba="0.7591476792056923717 0.85560384745670914342 0.90519468321360618823 1.0"/>
      </material>
    </visual>
    <collision name="2xl430_gears_4_collision">
      <origin xyz="-0.011708624550579444 -0.0026631594046431398 -0.019868974637740365" rpy="0 0 0"/>
      <geometry>
        <sphere radius="0.031173983743527797"/>
      </geometry>
    </collision>
    <inertial>
      <origin xyz="-0.01159290573797803689 -0.0024238553642550869638 -0.018551095523802667991" rpy="0 0 0"/>
      <mass value="0.11800003674524908726"/>
      <inertia ixx="2.7511021050424503716e-05" ixy="9.0043904315214347989e-07" ixz="-2.3349710124170355681e-08" iyy="3.2796197843345875145e-05" iyz="-6.5715119654636793758e-07" izz="3.5775739835741188688e-05"/>
    </inertial>
  </link>
  <link name="spur_1m_24t_drive_4">
    <visual>
      <origin xyz="0 0 0" rpy="0 -0 0"/>
      <geometry>
        <mesh filename="../assemblies/right_arm_gripper/meshes/right_spur_1m_24t_drive_visual.stl"/>
      </geometry>
      <material name="spur_1m_24t_drive_material">
        <color rgba="0.61568627450980406568 0.81176470588235294379 0.92941176470588238168 1.0"/>
      </material>
    </visual>
    <inertial>
      <origin xyz="3.0326539266682484979e-15 -3.3909557262182693158e-16 0.0048096451474092995898" rpy="0 0 0"/>
      <mass value="0.0032000000000000001533"/>
      <inertia ixx="1.4097598887016956026e-07" ixy="1.556282310200251252e-15" ixz="-1.8992294521396918766e-37" iyy="1.4097598803636001492e-07" iyz="-4.7745011531954772327e-37" izz="2.4107776386988835496e-07"/>
    </inertial>
  </link>
  <joint name="right_sho_yaw_drive" type="revolute">
    <origin xyz="-0.024000000716137347839 -0.019000000152448161261 -0.019000000152444761203" rpy="1.5707963267947397945 -3.199580565278813612e-14 1.8339090108977180652e-14"/>
    <parent link="2xl430_gears_4"/>
    <child link="spur_1m_24t_drive_4"/>
    <axis xyz="0 0 1"/>
    <limit effort="1" velocity="20" lower="-2.6179938779914944114" upper="2.6179938779914944114"/>
    <joint_properties friction="0.0"/>
  </joint>
  <link name="spur_1m_24t_driven_4">
    <visual>
      <origin xyz="0 0 0" rpy="0 -0 0"/>
      <geometry>
        <mesh filename="../assemblies/right_arm_gripper/meshes/right_spur_1m_24t_driven_visual.stl"/>
      </geometry>
      <material name="spur_1m_24t_driven_material">
        <color rgba="0.23137254901960788156 0.38039215686274502337 0.7058823529411765163 1.0"/>
      </material>
    </visual>
    <inertial>
      <origin xyz="-2.921394639790185015e-18 -1.6886349105605202767e-15 -0.00097237500038396460205" rpy="0 0 0"/>
      <mass value="0.0026999999999999997093"/>
      <inertia ixx="1.2202334915684083145e-07" ixy="-2.0003916890172096188e-37" ixz="1.9017102850262393928e-37" iyy="1.2202334915684064616e-07" iyz="-9.770592987438706564e-37" izz="2.3180293204341257533e-07"/>
    </inertial>
  </link>
  <link name="sho_yaw_link_2">
    <visual>
      <origin xyz="0 0 0" rpy="0 -0 0"/>
      <geometry>
        <mesh filename="../assemblies/right_arm_gripper/meshes/right_sho_yaw_link_visual.stl"/>
      </geometry>
      <material name="sho_yaw_link_material">
        <color rgba="0.61568627450980395466 0.81176470588235294379 0.92941176470588238168 1.0"/>
      </material>
    </visual>
    <inertial>
      <origin xyz="4.5036404713680668847e-18 2.8819643225832177286e-18 -0.024649285094360068316" rpy="0 0 0"/>
      <mass value="0.014500000000000004205"/>
      <inertia ixx="9.2365904614004439553e-06" ixy="3.5862833440690446869e-13" ixz="3.8159565285815172758e-35" iyy="5.8163826335078791714e-06" iyz="-1.0924832696280288326e-35" izz="4.5074356741562113561e-06"/>
    </inertial>
  </link>
  <link name="2xl430_gears_5">
    <visual>
      <origin xyz="0 0 0" rpy="0 -0 0"/>
      <geometry>
        <mesh filename="../assemblies/right_arm_gripper/meshes/right_2xl430_gears_2_visual.stl"/>
      </geometry>
      <material name="2xl430_gears_2_material">
        <color rgba="0.7591476792056923717 0.85560384745670914342 0.90519468321360618823 1.0"/>
      </material>
    </visual>
    <collision name="2xl430_gears_5_collision">
      <origin xyz="-0.011708624550579486 -0.0026631594046431346 -0.01986897463774047" rpy="0 0 0"/>
      <geometry>
        <sphere radius="0.031173983743527818"/>
      </geometry>
    </collision>
    <inertial>
      <origin xyz="-0.011592905737986073864 -0.0024238553642542347809 -0.018551095523808777688" rpy="0 0 0"/>
      <mass value="0.11800003674524908726"/>
      <inertia ixx="2.7511021050428857465e-05" ixy="9.0043904315091549388e-07" ixz="-2.3349710123664839139e-08" iyy="3.2796197843347636974e-05" iyz="-6.5715119654794606584e-07" izz="3.5775739835744908856e-05"/>
    </inertial>
  </link>
  <link name="spur_1m_24t_drive_5">
    <visual>
      <origin xyz="0 0 0" rpy="0 -0 0"/>
      <geometry>
        <mesh filename="../assemblies/right_arm_gripper/meshes/right_spur_1m_24t_drive_2_visual.stl"/>
      </geometry>
      <material name="spur_1m_24t_drive_2_material">
        <color rgba="0.61568627450980406568 0.81176470588235294379 0.92941176470588238168 1.0"/>
      </material>
    </visual>
    <inertial>
      <origin xyz="3.0395928205721565152e-15 -3.3909557262182688227e-16 0.0048096451474092995898" rpy="0 0 0"/>
      <mass value="0.0032000000000000001533"/>
      <inertia ixx="1.4097598887016963967e-07" ixy="1.5562823101719447534e-15" ixz="-1.8419223123432015677e-37" iyy="1.4097598803636001492e-07" iyz="-3.0576269564019315824e-36" izz="2.4107776386988835496e-07"/>
    </inertial>
  </link>
  <joint name="right_elbow_yaw_drive" type="revolute">
    <origin xyz="-0.024000000716148717217 -0.019000000152453275226 -0.01900000015245205745" rpy="1.5707963267949269781 1.6254659840047312022e-13 -8.5511976043092269184e-14"/>
    <parent link="2xl430_gears_5"/>
    <child link="spur_1m_24t_drive_5"/>
    <axis xyz="0 0 1"/>
    <limit effort="1" velocity="20" lower="-2.6179938779914944114" upper="2.6179938779914944114"/>
    <joint_properties friction="0.0"/>
  </joint>
  <link name="spur_1m_24t_driven_5">
    <visual>
      <origin xyz="0 0 0" rpy="0 -0 0"/>
      <geometry>
        <mesh filename="../assemblies/right_arm_gripper/meshes/right_spur_1m_24t_driven_2_visual.stl"/>
      </geometry>
      <material name="spur_1m_24t_driven_2_material">
        <color rgba="0.23137254901960788156 0.38039215686274502337 0.7058823529411765163 1.0"/>
      </material>
    </visual>
    <inertial>
      <origin xyz="-2.9213946397908421423e-18 -1.6886349105605210655e-15 -0.00097237500038396460205" rpy="0 0 0"/>
      <mass value="0.0026999999999999997093"/>
      <inertia ixx="1.2202334915684083145e-07" ixy="8.1931871200334274295e-66" ixz="-5.8515286657488374315e-36" iyy="1.2202334915684064616e-07" iyz="-7.8749785833428115979e-37" izz="2.3180293204341268121e-07"/>
    </inertial>
  </link>
  <link name="elb_yaw_link_2">
    <visual>
      <origin xyz="0 0 0" rpy="0 -0 0"/>
      <geometry>
        <mesh filename="../assemblies/right_arm_gripper/meshes/right_elb_yaw_link_visual.stl"/>
      </geometry>
      <material name="elb_yaw_link_material">
        <color rgba="0.61568627450980395466 0.81176470588235294379 0.92941176470588227065 1.0"/>
      </material>
    </visual>
    <inertial>
      <origin xyz="5.3127688027189133061e-08 0.0019833638641961665906 -0.023416643551549935071" rpy="0 0 0"/>
      <mass value="0.017500000000000001665"/>
      <inertia ixx="1.4134344903109196387e-05" ixy="1.6945783921929356084e-12" ixz="-1.1286398721892709078e-11" iyy="6.6435900776211340404e-06" iyz="1.0545227077253057579e-06" izz="8.9925290757998976773e-06"/>
    </inertial>
  </link>
  <link name="spur_1m_24t_driven_6">
    <visual>
      <origin xyz="0 0 0" rpy="0 -0 0"/>
      <geometry>
        <mesh filename="../assemblies/right_arm_gripper/meshes/right_spur_1m_24t_driven_3_visual.stl"/>
      </geometry>
      <material name="spur_1m_24t_driven_3_material">
        <color rgba="0.23137254901960788156 0.38039215686274502337 0.7058823529411765163 1.0"/>
      </material>
    </visual>
    <inertial>
      <origin xyz="-2.9213946397905324528e-18 -1.6886349105605188962e-15 -0.0025723750003839584988" rpy="0 0 0"/>
      <mass value="0.0026999999999999997093"/>
      <inertia ixx="1.2202334915684088439e-07" ixy="1.7934156310550399505e-36" ixz="-4.3202421904481218274e-36" iyy="1.2202334915684064616e-07" iyz="-9.0295837999359508427e-37" izz="2.3180293204341257533e-07"/>
    </inertial>
  </link>
  <link name="2xl430_gears_6">
    <visual>
      <origin xyz="0 0 0" rpy="0 -0 0"/>
      <geometry>
        <mesh filename="../assemblies/right_arm_gripper/meshes/right_2xl430_gears_3_visual.stl"/>
      </geometry>
      <material name="2xl430_gears_3_material">
        <color rgba="0.7591476792056923717 0.85560384745670914342 0.90519468321360618823 1.0"/>
      </material>
    </visual>
    <collision name="2xl430_gears_6_collision">
      <origin xyz="-0.0008533845367763513 0.011719140412504301 -0.0243373565174129" rpy="0 0 0"/>
      <geometry>
        <sphere radius="0.03116007186480805"/>
      </geometry>
    </collision>
    <inertial>
      <origin xyz="0.00044890447619846317274 0.011592905379916402728 -0.024576144788201300523" rpy="0 0 0"/>
      <mass value="0.11800003674524908726"/>
      <inertia ixx="3.5775739835743350316e-05" ixy="2.334971012439249338e-08" ixz="6.5715119654781382282e-07" iyy="2.7511021050426370577e-05" iyz="9.004390431514573832e-07" izz="3.279619784334753533e-05"/>
    </inertial>
  </link>
  <link name="spur_1m_24t_drive_6">
    <visual>
      <origin xyz="0 0 0" rpy="0 -0 0"/>
      <geometry>
        <mesh filename="../assemblies/right_arm_gripper/meshes/right_spur_1m_24t_drive_3_visual.stl"/>
      </geometry>
      <material name="spur_1m_24t_drive_3_material">
        <color rgba="0.61568627450980406568 0.81176470588235294379 0.92941176470588238168 1.0"/>
      </material>
    </visual>
    <inertial>
      <origin xyz="3.0326539266682488924e-15 -3.3909557259597738952e-16 0.0048096451474093021919" rpy="0 0 0"/>
      <mass value="0.0032000000000000001533"/>
      <inertia ixx="1.409759888701696132e-07" ixy="1.556282310200251252e-15" ixz="-1.0651936719748417848e-37" iyy="1.4097598803636001492e-07" iyz="-6.7795798897996087278e-37" izz="2.4107776386988846083e-07"/>
    </inertial>
  </link>
  <joint name="right_wrist_pitch_drive" type="revolute">
    <origin xyz="-1.5244632210886674996e-10 0.024000000358075396223 -0.0080000000000023368391" rpy="1.8404832493348406963e-14 1.1899813043699589138e-13 -1.5707963267947944175"/>
    <parent link="2xl430_gears_6"/>
    <child link="spur_1m_24t_drive_6"/>
    <axis xyz="0 0 1"/>
    <limit effort="1" velocity="20" lower="-1.3962634015954635824" upper="1.9198621771937625091"/>
    <joint_properties friction="0.0"/>
  </joint>
  <link name="gripper_connector_2">
    <visual>
      <origin xyz="0 0 0" rpy="0 -0 0"/>
      <geometry>
        <mesh filename="../assemblies/right_arm_gripper/meshes/right_gripper_connector_visual.stl"/>
      </geometry>
      <material name="gripper_connector_material">
        <color rgba="0.61568627450980395466 0.81176470588235294379 0.92941176470588238168 1.0"/>
      </material>
    </visual>
    <collision name="gripper_connector_2_collision">
      <origin xyz="-0.001999999862164259 0.013250000309199095 -0.029500000411644578" rpy="0 0 0"/>
      <geometry>
        <box size="0.024999999441206455 0.04750000033527613 0.06700000120326877"/>
      </geometry>
    </collision>
    <inertial>
      <origin xyz="-0.00018842170188954562057 0.022508162473387258173 -0.027103952522535709746" rpy="0 0 0"/>
      <mass value="0.0099999999999999967387"/>
      <inertia ixx="5.9456375734536726584e-06" ixy="2.4479055491886681531e-08" ixz="4.0329437936864279052e-08" iyy="4.2603724874314054683e-06" iyz="4.585261274976229064e-07" izz="2.4669632528047159756e-06"/>
    </inertial>
  </link>
  <link name="right_rail_guide">
    <visual>
      <origin xyz="0 0 0" rpy="0 -0 0"/>
      <geometry>
        <mesh filename="../assemblies/right_arm_gripper/meshes/right_rail_guide_visual.stl"/>
      </geometry>
      <material name="right_rail_guide_material">
        <color rgba="0.63183631947442864263 0.80464761899488657093 0.89969354135356638391 1.0"/>
      </material>
    </visual>
    <collision name="right_rail_guide_collision">
      <origin xyz="0.017000000923871994 -0.0029250001534819603 0.008150000125169754" rpy="0 0 0"/>
      <geometry>
        <box size="0.09000000357627869 0.04934999905526638 0.018149999901652336"/>
      </geometry>
    </collision>
    <inertial>
      <origin xyz="0.010819769137967562636 -0.0021113011985218615996 -7.7620928513509046e-05" rpy="0 0 0"/>
      <mass value="0.031084136786219594695"/>
      <inertia ixx="7.8430666236070228507e-06" ixy="-2.0644517679574144074e-06" ixz="4.0045882799668568733e-06" iyy="2.7294704119451736191e-05" iyz="8.8949075530050562942e-07" izz="3.0492488744516627947e-05"/>
    </inertial>
  </link>
  <link name="rail_3">
    <visual>
      <origin xyz="0 0 0" rpy="0 -0 0"/>
      <geometry>
        <mesh filename="../assemblies/right_arm_gripper/meshes/right_rail_visual.stl"/>
      </geometry>
      <material name="rail_material">
        <color rgba="0.64705882352941179736 0.64705882352941179736 0.64705882352941179736 1.0"/>
      </material>
    </visual>
    <collision name="rail_3_collision">
      <origin xyz="0 0 0" rpy="0 -0 0"/>
      <geometry>
        <mesh filename="../assemblies/right_arm_gripper/meshes/right_rail_visual.stl"/>
      </geometry>
    </collision>
    <inertial>
      <origin xyz="0.029554714214719168819 -0.015933051259988690457 -0.010638774525132295434" rpy="0 0 0"/>
      <mass value="0.017100000000000004086"/>
      <inertia ixx="3.6591938331681682466e-06" ixy="2.101313841244636705e-08" ixz="-1.1335092663308559672e-07" iyy="4.7380338190523213965e-06" iyz="3.1225833654311399591e-08" izz="6.0956112819844626417e-06"/>
    </inertial>
  </link>
  <joint name="right_gripper_pinion" type="prismatic">
    <origin xyz="-0.028872600000000046838 -0.01597499999999998227 -0.0053500000000018255175" rpy="-3.141592653589793116 1.570796326794896336 0"/>
    <parent link="right_rail_guide"/>
    <child link="rail_3"/>
    <axis xyz="0 0 1"/>
    <limit effort="1" velocity="20" lower="-0.025000000000000001388" upper="0"/>
    <joint_properties friction="0.0"/>
  </joint>
  <link name="rail_4">
    <visual>
      <origin xyz="0 0 0" rpy="0 -0 0"/>
      <geometry>
        <mesh filename="../assemblies/right_arm_gripper/meshes/right_rail_2_visual.stl"/>
      </geometry>
      <material name="rail_2_material">
        <color rgba="0.64705882352941179736 0.64705882352941179736 0.64705882352941179736 1.0"/>
      </material>
    </visual>
    <collision name="rail_4_collision">
      <origin xyz="0 0 0" rpy="0 -0 0"/>
      <geometry>
        <mesh filename="../assemblies/right_arm_gripper/meshes/right_rail_2_visual.stl"/>
      </geometry>
    </collision>
    <inertial>
      <origin xyz="0.029554714214719151472 -0.015933051259988690457 -0.010638774525132281557" rpy="0 0 0"/>
      <mass value="0.017100000000000004086"/>
      <inertia ixx="3.6591938331681699406e-06" ixy="2.1013138412446370359e-08" ixz="-1.1335092663308562319e-07" iyy="4.7380338190523213965e-06" iyz="3.1225833654311399591e-08" izz="6.0956112819844626417e-06"/>
    </inertial>
  </link>
  <joint name="right_gripper_pinion_mirror" type="prismatic">
    <origin xyz="0.062872600000000000708 0.015974999999999996148 -0.0053500000000018255175" rpy="-5.5077470362028772728e-17 1.570796326794896336 0"/>
    <parent link="right_rail_guide"/>
    <child link="rail_4"/>
    <axis xyz="0 0 1"/>
    <limit effort="1" velocity="20" lower="-0.025000000000000001388" upper="0"/>
    <joint_properties friction="0.0"/>
  </joint>
  <link name="xc330_2">
    <visual>
      <origin xyz="0 0 0" rpy="0 -0 0"/>
      <geometry>
        <mesh filename="../assemblies/right_arm_gripper/meshes/right_xc330_visual.stl"/>
      </geometry>
      <material name="xc330_material">
        <color rgba="0.66932535752643762539 0.72911795671409951325 0.67547870389434383487 1.0"/>
      </material>
    </visual>
    <inertial>
      <origin xyz="0.0080045171539636656571 -0.015558009851632038575 -0.011717805512818681157" rpy="0 0 0"/>
      <mass value="0.026599999993091757305"/>
      <inertia ixx="3.8683410666514873223e-06" ixy="-7.7688424001884118559e-10" ixz="5.7969695832743633125e-10" iyy="2.1626767907495288038e-06" iyz="8.3590274792655130141e-09" izz="3.3158761130056373734e-06"/>
    </inertial>
  </link>
  <link name="spur_gear_(18_teeth)_2">
    <visual>
      <origin xyz="0 0 0" rpy="0 -0 0"/>
      <geometry>
        <mesh filename="../assemblies/right_arm_gripper/meshes/right_spur_gear_(18_teeth)_visual.stl"/>
      </geometry>
      <material name="spur_gear_(18_teeth)_material">
        <color rgba="0.91764705882352926025 0.91764705882352926025 0.91764705882352926025 1.0"/>
      </material>
    </visual>
    <inertial>
      <origin xyz="5.5511151231257827021e-17 -3.1225022567582527699e-17 -0.0025000000000000074246" rpy="0 0 0"/>
      <mass value="0.0012999999999999999403"/>
      <inertia ixx="3.3282842836137718203e-08" ixy="-1.5837813884372199342e-22" ixz="-2.8752104509266030915e-38" iyy="3.3282842836137453506e-08" iyz="-1.0904371075711416333e-36" izz="6.1149428795799489038e-08"/>
    </inertial>
  </link>
  <joint name="right_gripper_rack" type="revolute">
    <origin xyz="0.0079999999999993201549 -0.022499999999995502764 -0.026000000000000439426" rpy="7.3432579397082090565e-14 3.5141900076851877937e-14 -3.1415926535897820138"/>
    <parent link="xc330_2"/>
    <child link="spur_gear_(18_teeth)_2"/>
    <axis xyz="0 0 1"/>
    <limit effort="1" velocity="20" lower="0" upper="2.7052603405912107881"/>
    <joint_properties friction="0.0"/>
  </joint>
  <joint name="right_gripper_motor" type="fixed">
    <origin xyz="-0.0059500000000000073663 -0.022600000000000008971 0.023299999999999987388" rpy="3.6776137690705712091e-16 1.2671612890944486003e-16 3.141592653589793116"/>
    <parent link="right_rail_guide"/>
    <child link="xc330_2"/>
    <axis xyz="0 0 1"/>
    <limit effort="1" velocity="20"/>
    <joint_properties friction="0.0"/>
  </joint>
  <joint name="right_gripper_fixed" type="fixed">
    <origin xyz="0 0.037000000000000005107 -0.0019999999999999983069" rpy="1.5707963267948970021 1.570796326794896558 0"/>
    <parent link="gripper_connector_2"/>
    <child link="right_rail_guide"/>
    <axis xyz="0 0 1"/>
    <limit effort="1" velocity="20"/>
    <joint_properties friction="0.0"/>
  </joint>
  <joint name="right_wrist_roll" type="revolute">
    <origin xyz="0.019000000000004482054 -3.580631624533481272e-10 -0.027000000152456495039" rpy="-3.141592653589758477 -1.5707963267948275021 0"/>
    <parent link="2xl430_gears_6"/>
    <child link="gripper_connector_2"/>
    <axis xyz="0 0 1"/>
    <limit effort="1" velocity="20" lower="-1.3962634015954635824" upper="1.9198621771937625091"/>
    <joint_properties friction="0.0"/>
  </joint>
  <link name="wrist_bearing_plate_2">
    <visual>
      <origin xyz="0 0 0" rpy="0 -0 0"/>
      <geometry>
        <mesh filename="../assemblies/right_arm_gripper/meshes/right_wrist_bearing_plate_visual.stl"/>
      </geometry>
      <material name="wrist_bearing_plate_material">
        <color rgba="0.71932243125689065977 0.63128434304969727187 0.52422389360984933404 1.0"/>
      </material>
    </visual>
    <inertial>
      <origin xyz="-0.0075835583121500052886 -0.015499999999999980807 -0.0018386323705903270722" rpy="0 0 0"/>
      <mass value="0.0049000367468305548388"/>
      <inertia ixx="4.9707430109150107956e-07" ixy="8.1070294502442220436e-23" ixz="1.8100904820814048483e-08" iyy="7.1268523603538595411e-07" iyz="1.2144016459131329602e-23" izz="1.1919657811600109234e-06"/>
    </inertial>
  </link>
  <joint name="right_wrist_pitch_fixed" type="fixed">
    <origin xyz="0.015500000000004740888 1.2045919817182948464e-14 -0.045000000000007915613" rpy="3.9795857581529944641e-14 1.8629542353210303453e-13 -1.5707963267947884223"/>
    <parent link="2xl430_gears_6"/>
    <child link="wrist_bearing_plate_2"/>
    <axis xyz="0 0 1"/>
    <limit effort="1" velocity="20"/>
    <joint_properties friction="0.0"/>
  </joint>
  <joint name="right_wrist_pitch_driven" type="revolute">
    <origin xyz="0 2.5637979419682883676e-30 -0.0015999999999999950893" rpy="1.5612511284236928353e-16 1.0061396160670370853e-16 1.570796326794896336"/>
    <parent link="spur_1m_24t_driven_6"/>
    <child link="2xl430_gears_6"/>
    <axis xyz="0 0 1"/>
    <limit effort="1" velocity="20" lower="-1.9198621771937625091" upper="1.3962634015954635824"/>
    <joint_properties friction="0.0"/>
  </joint>
  <joint name="right_wrist_roll_fixed" type="fixed">
    <origin xyz="-9.8607613152626475676e-31 -0.025300000000000003042 -0.051999999999999990674" rpy="1.570796326794896558 1.570796326794896558 0"/>
    <parent link="elb_yaw_link_2"/>
    <child link="spur_1m_24t_driven_6"/>
    <axis xyz="0 0 1"/>
    <limit effort="1" velocity="20"/>
    <joint_properties friction="0.0"/>
  </joint>
  <joint name="right_elbow_yaw_fixed" type="fixed">
    <origin xyz="0 -5.9164567891575885406e-31 0.0016000000000000041966" rpy="3.141592653589793116 -1.6415575270060996837e-29 -1.570796326794896558"/>
    <parent link="spur_1m_24t_driven_5"/>
    <child link="elb_yaw_link_2"/>
    <axis xyz="0 0 1"/>
    <limit effort="1" velocity="20"/>
    <joint_properties friction="0.0"/>
  </joint>
  <joint name="right_elbow_yaw_driven" type="revolute">
    <origin xyz="-3.5807057666148445207e-10 -0.027000000152458056291 -0.019000000000001949357" rpy="1.5707963267949378583 3.9690473130355310109e-14 -5.221292488511941966e-14"/>
    <parent link="2xl430_gears_5"/>
    <child link="spur_1m_24t_driven_5"/>
    <axis xyz="0 0 1"/>
    <limit effort="1" velocity="20" lower="-2.6179938779914944114" upper="2.6179938779914944114"/>
    <joint_properties friction="0.0"/>
  </joint>
  <joint name="right_elbow_roll" type="revolute">
    <origin xyz="6.9388939039072283776e-18 -0.018999999999999992589 -0.058999999999999983014" rpy="1.570796326794896558 1.8613243021562443989e-16 2.7317207594485797632e-14"/>
    <parent link="sho_yaw_link_2"/>
    <child link="2xl430_gears_5"/>
    <axis xyz="0 0 1"/>
    <limit effort="1" velocity="20" lower="-1.9198621771937625091" upper="2.4434609527920612138"/>
    <joint_properties friction="0.0"/>
  </joint>
  <joint name="right_sho_yaw_fixed" type="fixed">
    <origin xyz="0 1.9721522630525295135e-31 0.0016000000000000007272" rpy="-3.141592653589793116 6.0982645760524304742e-30 -1.2655675810200602945e-30"/>
    <parent link="spur_1m_24t_driven_4"/>
    <child link="sho_yaw_link_2"/>
    <axis xyz="0 0 1"/>
    <limit effort="1" velocity="20"/>
    <joint_properties friction="0.0"/>
  </joint>
  <joint name="right_sho_yaw_driven" type="revolute">
    <origin xyz="-3.5806868581289563735e-10 -0.027000000152448175306 -0.018999999999998452155" rpy="1.5707963267947739894 -2.7015357376462180631e-14 4.23468517903597816e-14"/>
    <parent link="2xl430_gears_4"/>
    <child link="spur_1m_24t_driven_4"/>
    <axis xyz="0 0 1"/>
    <limit effort="1" velocity="20" lower="-2.6179938779914944114" upper="2.6179938779914944114"/>
    <joint_properties friction="0.0"/>
  </joint>
  <joint name="right_sho_roll" type="revolute">
    <origin xyz="-0.018999999999999999528 9.324138683375341214e-18 0.027000000000000006634" rpy="-3.141592653589793116 1.5707963267947613328 0"/>
    <parent link="sho_pitch_link_2"/>
    <child link="2xl430_gears_4"/>
    <axis xyz="0 0 1"/>
    <limit effort="1" velocity="20" lower="-1.570796326794896558" upper="0.34906585039886589561"/>
    <joint_properties friction="0.0"/>
  </joint>
</robot>