<?xml version="1.0" ?><robot name="right_3R+RH5_leg">  
  <link name="hip_yaw_link">    
    <visual>      
      <origin xyz="0 0 0" rpy="0 -0 0"/>      
      <geometry>        
        <mesh filename="package:///meshes/right_hip_yaw_link_visual.stl"/>        
      </geometry>      
      <material name="hip_yaw_link_material">        
        <color rgba="0.61568627450980395466 0.81176470588235294379 0.9294117647058824927 1.0"/>        
      </material>      
    </visual>    
    <collision>      
      <origin xyz="0 0 0" rpy="0 -0 0"/>      
      <geometry>        
        <mesh filename="package:///meshes/right_hip_yaw_link_collision.stl"/>        
      </geometry>      
    </collision>    
    <inertial>      
      <origin xyz="-4.169865130963886892e-19 -3.0887186475841816035e-19 -0.0098390489054829121524" rpy="0 0 0"/>      
      <mass value="0.009025883737097921064"/>      
      <inertia ixx="1.3230458239085870108e-06" ixy="-6.4778545919079845884e-49" ixz="1.7322911775161982211e-33" iyy="3.8408510960330533338e-06" iyz="-1.4482241779965776345e-32" izz="3.8721396285793069258e-06"/>      
    </inertial>    
  </link>  

  <link name="hip_roll_link">    
    <visual>      
      <origin xyz="0 0 0" rpy="0 -0 0"/>      
      <geometry>        
        <mesh filename="package:///meshes/right_hip_roll_link_visual.stl"/>        
      </geometry>      
      <material name="hip_roll_link_material">        
        <color rgba="0.95018735644455842859 0.7067892720042843191 0.061612079402596720001 1.0"/>        
      </material>      
    </visual>    
    <collision>      
      <origin xyz="0 0 0" rpy="0 -0 0"/>      
      <geometry>        
        <mesh filename="package:///meshes/right_hip_roll_link_collision.stl"/>        
      </geometry>      
    </collision>    
    <inertial>      
      <origin xyz="0.012000150775886153295 -0.00049588816141173531604 -0.019495980755502462234" rpy="0 0 0"/>      
      <mass value="0.098012391483528665814"/>      
      <inertia ixx="2.022174876630707311e-05" ixy="4.1552068245377810553e-08" ixz="-4.1225592185579456384e-08" iyy="2.7358099958307288213e-05" iyz="5.09357317523834832e-07" izz="2.7358069524724191828e-05"/>      
    </inertial>    
  </link>  

  <link name="right_hip_pitch_link">    
    <visual>      
      <origin xyz="0 0 0" rpy="0 -0 0"/>      
      <geometry>        
        <mesh filename="package:///meshes/right_hip_pitch_link_visual.stl"/>        
      </geometry>      
      <material name="right_hip_pitch_link_material">        
        <color rgba="0.61654126330065672779 0.80727601473037591262 0.92171686558820720148 1.0"/>        
      </material>      
    </visual>    
    <collision>      
      <origin xyz="0 0 0" rpy="0 -0 0"/>      
      <geometry>        
        <mesh filename="package:///meshes/right_hip_pitch_link_collision.stl"/>        
      </geometry>      
    </collision>    
    <inertial>      
      <origin xyz="-1.3043817563642643711e-05 0.05286453419666208714 0.014710916112540836989" rpy="0 0 0"/>      
      <mass value="0.09353906475262946385"/>      
      <inertia ixx="6.2495912126891110935e-05" ixy="-2.2341467553068197509e-07" ixz="-1.1719709579613414289e-08" iyy="2.150063816786048604e-05" iyz="-1.4210875155541280677e-06" izz="6.2280434774102103241e-05"/>      
    </inertial>    
  </link>  

  <link name="right_calf_link">    
    <visual>      
      <origin xyz="0 0 0" rpy="0 -0 0"/>      
      <geometry>        
        <mesh filename="package:///meshes/right_calf_link_visual.stl"/>        
      </geometry>      
      <material name="right_calf_link_material">        
        <color rgba="0.55397247693546480818 0.73161364570947462482 0.87715709724734269859 1.0"/>        
      </material>      
    </visual>    
    <collision>      
      <origin xyz="0 0 0" rpy="0 -0 0"/>      
      <geometry>        
        <mesh filename="package:///meshes/right_calf_link_collision.stl"/>        
      </geometry>      
    </collision>    
    <inertial>      
      <origin xyz="-0.003913604828102311764 0.043639997035758548716 0.0081848996608063079305" rpy="0 0 0"/>      
      <mass value="0.016290630569901022595"/>      
      <inertia ixx="1.5543964735762044456e-05" ixy="2.160598930607913158e-07" ixz="7.0519548982948992512e-09" iyy="1.936456681341731096e-06" iyz="-1.9645570089530235659e-08" izz="1.4807205615850181385e-05"/>      
    </inertial>    
  </link>  

  <link name="ank_pitch_link">    
    <visual>      
      <origin xyz="0 0 0" rpy="0 -0 0"/>      
      <geometry>        
        <mesh filename="package:///meshes/right_ank_pitch_link_visual.stl"/>        
      </geometry>      
      <material name="ank_pitch_link_material">        
        <color rgba="0.63189161126160275916 0.7266866879354088038 0.78356373393969258601 1.0"/>        
      </material>      
    </visual>    
    <collision>      
      <origin xyz="0 0 0" rpy="0 -0 0"/>      
      <geometry>        
        <mesh filename="package:///meshes/right_ank_pitch_link_collision.stl"/>        
      </geometry>      
    </collision>    
    <inertial>      
      <origin xyz="4.0269686140343600389e-08 0.00059528282566766947247 -0.014599922383890030428" rpy="0 0 0"/>      
      <mass value="0.0042238381753791614387"/>      
      <inertia ixx="4.3705254067391488611e-07" ixy="1.6834347258744780147e-13" ixz="1.6428822909209012184e-12" iyy="3.9782741364655564948e-07" iyz="2.0919209916503936685e-14" izz="8.8858574534526009381e-08"/>      
    </inertial>    
  </link>  

  <link name="ank_roll_link">    
    <visual>      
      <origin xyz="0 0 0" rpy="0 -0 0"/>      
      <geometry>        
        <mesh filename="package:///meshes/right_ank_roll_link_visual.stl"/>        
      </geometry>      
      <material name="ank_roll_link_material">        
        <color rgba="0.61568627450980395466 0.81176470588235283277 0.92941176470588238168 1.0"/>        
      </material>      
    </visual>    
    <collision>      
      <origin xyz="0 0 0" rpy="0 -0 0"/>      
      <geometry>        
        <mesh filename="package:///meshes/right_ank_roll_link_collision.stl"/>        
      </geometry>      
    </collision>    
    <inertial>      
      <origin xyz="0.0067954316497290476878 0.030800108584191222827 -0.0019645929618398207117" rpy="0 0 0"/>      
      <mass value="0.021210604954423659119"/>      
      <inertia ixx="1.6673721051425443836e-05" ixy="-9.6458086620934640677e-07" ixz="-8.8407559558929386577e-07" iyy="1.8800607546624137172e-05" iyz="-1.299862513390140733e-06" izz="7.5433513644979433832e-06"/>      
    </inertial>    
  </link>  

  <link name="ank_rr_link">    
    <visual>      
      <origin xyz="0 0 0" rpy="0 -0 0"/>      
      <geometry>        
        <mesh filename="package:///meshes/right_ank_rr_link_visual.stl"/>        
      </geometry>      
      <material name="ank_rr_link_material">        
        <color rgba="0.61568627450980395466 0.81176470588235283277 0.92941176470588238168 1.0"/>        
      </material>      
    </visual>    
    <collision>      
      <origin xyz="0 0 0" rpy="0 -0 0"/>      
      <geometry>        
        <mesh filename="package:///meshes/right_ank_rr_link_collision.stl"/>        
      </geometry>      
    </collision>    
    <inertial>      
      <origin xyz="6.8909927486138587591e-18 -0.0061447686137497906783 2.0679252789697083566e-19" rpy="0 0 0"/>      
      <mass value="0.00042507093693768156772"/>      
      <inertia ixx="8.7843229279236022739e-09" ixy="-5.0134842627852916124e-26" ixz="-1.0879024114892056879e-14" iyy="8.0301730481463886798e-09" iyz="1.359744917393361523e-31" izz="1.2504379836120061674e-08"/>      
    </inertial>    
  </link>  

  <link name="12lf_rod_end">    
    <visual>      
      <origin xyz="0 0 0" rpy="0 -0 0"/>      
      <geometry>        
        <mesh filename="package:///meshes/right_12lf_rod_end_visual.stl"/>        
      </geometry>      
      <material name="12lf_rod_end_material">        
        <color rgba="0.92771758928836545177 0.61049283053223013518 0.21847658490585164515 1.0"/>        
      </material>      
    </visual>    
    <collision>      
      <origin xyz="0 0 0" rpy="0 -0 0"/>      
      <geometry>        
        <mesh filename="package:///meshes/right_12lf_rod_end_collision.stl"/>        
      </geometry>      
    </collision>    
    <inertial>      
      <origin xyz="-4.4735192473424715261e-11 -0.0038422185938245733902 6.4384187209510132161e-06" rpy="0 0 0"/>      
      <mass value="0.00085420491177815895123"/>      
      <inertia ixx="1.1840985264406789048e-08" ixy="2.0225978501517321813e-16" ixz="-9.2606419966761793191e-16" iyy="3.3549621576797214369e-09" iyz="7.4535631381829666329e-12" izz="1.2703522254419974962e-08"/>      
    </inertial>    
  </link>  

  <joint name="right_ank_R21" type="revolute">    
    <origin xyz="4.1633363423443370266e-17 -0.010000000000000119904 -2.7755575615628913511e-17" rpy="-1.5707963267949331954 -1.4285697747630743404 1.5707963267949289765"/>    
    <parent link="ank_rr_link"/>    
    <child link="12lf_rod_end"/>    
    <axis xyz="0 0 1"/>    
    <limit effort="1" velocity="20" lower="-1.570796326794896558" upper="1.570796326794896558"/>    
    <joint_properties friction="0.0"/>    
  </joint>  

  <joint name="right_ank_R11" type="revolute">    
    <origin xyz="-0.0099999999999998423483 0.012499999999999733546 -0.033599999999999782818" rpy="-1.4093527784308163928e-14 -9.1905749868284128401e-17 -0.10116031275663164846"/>    
    <parent link="ank_roll_link"/>    
    <child link="ank_rr_link"/>    
    <axis xyz="0 0 1"/>    
    <limit effort="1" velocity="20" lower="-1.570796326794896558" upper="1.570796326794896558"/>    
    <joint_properties friction="0.0"/>    
  </joint>  

  <link name="ank_rr_link_2">    
    <visual>      
      <origin xyz="0 0 0" rpy="0 -0 0"/>      
      <geometry>        
        <mesh filename="package:///meshes/right_ank_rr_link_2_visual.stl"/>        
      </geometry>      
      <material name="ank_rr_link_2_material">        
        <color rgba="0.61568627450980395466 0.81176470588235283277 0.92941176470588238168 1.0"/>        
      </material>      
    </visual>    
    <collision>      
      <origin xyz="0 0 0" rpy="0 -0 0"/>      
      <geometry>        
        <mesh filename="package:///meshes/right_ank_rr_link_2_collision.stl"/>        
      </geometry>      
    </collision>    
    <inertial>      
      <origin xyz="8.6203576652448308076e-20 -0.0061447686137497915457 7.1456864318040533482e-18" rpy="0 0 0"/>      
      <mass value="0.00042507093693768156772"/>      
      <inertia ixx="8.7843229279236022739e-09" ixy="-8.9018097796581265674e-26" ixz="-1.0879024114892056879e-14" iyy="8.0301730481463919886e-09" iyz="-3.2911339759020778731e-32" izz="1.2504379836120061674e-08"/>      
    </inertial>    
  </link>  

  <link name="12lf_rod_end_2">    
    <visual>      
      <origin xyz="0 0 0" rpy="0 -0 0"/>      
      <geometry>        
        <mesh filename="package:///meshes/right_12lf_rod_end_2_visual.stl"/>        
      </geometry>      
      <material name="12lf_rod_end_2_material">        
        <color rgba="0.92771758928836545177 0.6104928305322302462 0.21847658490585164515 1.0"/>        
      </material>      
    </visual>    
    <collision>      
      <origin xyz="0 0 0" rpy="0 -0 0"/>      
      <geometry>        
        <mesh filename="package:///meshes/right_12lf_rod_end_2_collision.stl"/>        
      </geometry>      
    </collision>    
    <inertial>      
      <origin xyz="-4.4735198829362294065e-11 -0.003842218593824576426 6.4384187209524209848e-06" rpy="0 0 0"/>      
      <mass value="0.00085420491177815895123"/>      
      <inertia ixx="1.1840985264406789048e-08" ixy="2.0225978682449014433e-16" ixz="-9.260642008304349966e-16" iyy="3.3549621576796995167e-09" iyz="7.4535631381750583339e-12" izz="1.2703522254420003086e-08"/>      
    </inertial>    
  </link>  

  <joint name="right_ank_R22" type="revolute">    
    <origin xyz="-5.5511151231257827021e-17 -0.0099999999999999811262 -1.3877787807814456755e-17" rpy="1.5707963267948956698 -1.4285463212684392786 -1.570796326794886566"/>    
    <parent link="ank_rr_link_2"/>    
    <child link="12lf_rod_end_2"/>    
    <axis xyz="0 0 1"/>    
    <limit effort="1" velocity="20" lower="-1.570796326794896558" upper="1.570796326794896558"/>    
    <joint_properties friction="0.0"/>    
  </joint>  

  <joint name="right_ank_R12" type="revolute">    
    <origin xyz="0.0099999999999997174482 0.012499999999999733546 -0.03359999999999976894" rpy="-3.1415926535897820138 -2.2156165769524474289e-15 -3.0405529889777027641"/>    
    <parent link="ank_roll_link"/>    
    <child link="ank_rr_link_2"/>    
    <axis xyz="0 0 1"/>    
    <limit effort="1" velocity="20" lower="-1.570796326794896558" upper="1.570796326794896558"/>    
    <joint_properties friction="0.0"/>    
  </joint>  

  <joint name="right_ank_roll" type="revolute">    
    <origin xyz="1.8041124150158793782e-15 0.0015000000000095273494 -0.014599999999994438607" rpy="-1.5707963267952527175 1.5707963267946807306 0"/>    
    <parent link="ank_pitch_link"/>    
    <child link="ank_roll_link"/>    
    <axis xyz="0 0 1"/>    
    <limit effort="1" velocity="20" lower="-0.785398163397448279" upper="0.785398163397448279"/>    
    <joint_properties friction="0.0"/>    
  </joint>  

  <joint name="right_ank_pitch" type="revolute">    
    <origin xyz="-2.423086741528762234e-18 0.10000000000000014433 -0.006200000000000555761" rpy="-3.1415926535897922278 -1.0275284166593592938e-14 -1.570796326794896558"/>    
    <parent link="right_calf_link"/>    
    <child link="ank_pitch_link"/>    
    <axis xyz="0 0 1"/>    
    <limit effort="1" velocity="20" lower="-0.52359877559829881566" upper="0.52359877559829881566"/>    
    <joint_properties friction="0.0"/>    
  </joint>  

  <link name="ball_joint_container">    
    <visual>      
      <origin xyz="0 0 0" rpy="0 -0 0"/>      
      <geometry>        
        <mesh filename="package:///meshes/right_ball_joint_container_visual.stl"/>        
      </geometry>      
      <material name="ball_joint_container_material">        
        <color rgba="0.61568627450980395466 0.81176470588235294379 0.9294117647058824927 1.0"/>        
      </material>      
    </visual>    
    <collision>      
      <origin xyz="0 0 0" rpy="0 -0 0"/>      
      <geometry>        
        <mesh filename="package:///meshes/right_ball_joint_container_collision.stl"/>        
      </geometry>      
    </collision>    
    <inertial>      
      <origin xyz="4.7221442975712102021e-19 -2.7876926753568478918e-17 -0.0097125341669083431473" rpy="0 0 0"/>      
      <mass value="4.8037356425330562243e-05"/>      
      <inertia ixx="7.1865480628741645687e-10" ixy="-2.1276536262898221805e-26" ixz="6.7377051491480635438e-39" iyy="8.475420427718555978e-10" iyz="-2.9779659754799928757e-39" izz="1.8625314111651911712e-10"/>      
    </inertial>    
  </link>  

  <link name="ball_joint_ball">    
    <visual>      
      <origin xyz="0 0 0" rpy="0 -0 0"/>      
      <geometry>        
        <mesh filename="package:///meshes/right_ball_joint_ball_visual.stl"/>        
      </geometry>      
      <material name="ball_joint_ball_material">        
        <color rgba="0.3291302810242056065 0.44310466418644928188 0.69204871161977121741 1.0"/>        
      </material>      
    </visual>    
    <collision>      
      <origin xyz="0 0 0" rpy="0 -0 0"/>      
      <geometry>        
        <mesh filename="package:///meshes/right_ball_joint_ball_collision.stl"/>        
      </geometry>      
    </collision>    
    <inertial>      
      <origin xyz="1.8393942021553128157e-17 -0.0010308669810016291794 -3.4073815427052736292e-20" rpy="0 0 0"/>      
      <mass value="4.4053796295264623832e-05"/>      
      <inertia ixx="3.128501134969055578e-10" ixy="-6.5207514975827964597e-26" ixz="-7.4537496808998083208e-25" iyy="6.2569568612795359557e-11" iyz="8.7215215474372494284e-25" izz="3.1285321460375345983e-10"/>      
    </inertial>    
  </link>  

  <link name="12lf">    
    <visual>      
      <origin xyz="0 0 0" rpy="0 -0 0"/>      
      <geometry>        
        <mesh filename="package:///meshes/right_12lf_visual.stl"/>        
      </geometry>      
      <material name="12lf_material">        
        <color rgba="0.62004392096503557763 0.58836684612040235365 0.49897069027350277048 1.0"/>        
      </material>      
    </visual>    
    <collision>      
      <origin xyz="0 0 0" rpy="0 -0 0"/>      
      <geometry>        
        <mesh filename="package:///meshes/right_12lf_collision.stl"/>        
      </geometry>      
    </collision>    
    <inertial>      
      <origin xyz="0.0049084207226893867768 -0.00013802440006467576929 -0.029947003575836465133" rpy="0 0 0"/>      
      <mass value="0.044782197690790462308"/>      
      <inertia ixx="1.526012842048131375e-05" ixy="2.2955774098320406135e-08" ixz="-8.1364204859547315133e-08" iyy="1.8188469777200056858e-05" iyz="-5.554224117026341229e-08" izz="5.1496273889319450724e-06"/>      
    </inertial>    
  </link>  

  <link name="12lf_rod">    
    <visual>      
      <origin xyz="0 0 0" rpy="0 -0 0"/>      
      <geometry>        
        <mesh filename="package:///meshes/right_12lf_rod_visual.stl"/>        
      </geometry>      
      <material name="12lf_rod_material">        
        <color rgba="0.80250260812861884396 0.89340612183512713163 0.94491811293548189088 1.0"/>        
      </material>      
    </visual>    
    <collision>      
      <origin xyz="0 0 0" rpy="0 -0 0"/>      
      <geometry>        
        <mesh filename="package:///meshes/right_12lf_rod_collision.stl"/>        
      </geometry>      
    </collision>    
    <inertial>      
      <origin xyz="-6.3222084065473323676e-07 4.6933255155138083222e-07 -0.012893387334329891106" rpy="0 0 0"/>      
      <mass value="0.0025088292483592144512"/>      
      <inertia ixx="2.6944521128615410617e-07" ixy="7.1389570383049494142e-15" ixz="1.3562243140338437122e-11" iyy="2.6944520001671945025e-07" iyz="-1.0089988380103096692e-11" izz="1.7809843599861098282e-08"/>      
    </inertial>    
  </link>  

  <joint name="right_ank_act1" type="prismatic">    
    <origin xyz="2.2722093427577499947e-06 1.727784582072899866e-15 -0.0726600316041042249" rpy="-3.1415926535897815697 1.0092007725908475977e-14 -2.2021168238260941941"/>    
    <parent link="12lf"/>    
    <child link="12lf_rod"/>    
    <axis xyz="0 0 1"/>    
    <limit effort="1" velocity="20" lower="0" upper="0.040000000000000000833"/>    
    <joint_properties friction="0.0"/>    
  </joint>  

  <joint name="right_ank_B31" type="revolute">    
    <origin xyz="9.5409791178724390193e-17 -0.0064387505004002698605 -5.5511151231257827021e-17" rpy="-1.5707963267948954478 0.16913440034172153026 -1.8050260774851149667e-15"/>    
    <parent link="ball_joint_ball"/>    
    <child link="12lf"/>    
    <axis xyz="0 0 1"/>    
    <limit effort="1" velocity="20" lower="-0.785398163397448279" upper="0.785398163397448279"/>    
    <joint_properties friction="0.0"/>    
  </joint>  

  <joint name="right_ank_B21" type="revolute">    
    <origin xyz="0 0 -0.011500000000000022357" rpy="1.5707963267948794606 -1.4285697747626477927 1.5707963267948803487"/>    
    <parent link="ball_joint_container"/>    
    <child link="ball_joint_ball"/>    
    <axis xyz="0 0 1"/>    
    <limit effort="1" velocity="20" lower="-0.785398163397448279" upper="0.785398163397448279"/>    
    <joint_properties friction="0.0"/>    
  </joint>  

  <joint name="right_ank_B11" type="revolute">    
    <origin xyz="0.0079999999999999238387 0.015000000000000124345 -0.01150000000000006746" rpy="1.5707963267949047736 -1.4696360140379067794 -1.5707963267948874542"/>    
    <parent link="right_calf_link"/>    
    <child link="ball_joint_container"/>    
    <axis xyz="0 0 1"/>    
    <limit effort="1" velocity="20" lower="-0.785398163397448279" upper="0.785398163397448279"/>    
    <joint_properties friction="0.0"/>    
  </joint>  

  <link name="ball_joint_container_2">    
    <visual>      
      <origin xyz="0 0 0" rpy="0 -0 0"/>      
      <geometry>        
        <mesh filename="package:///meshes/right_ball_joint_container_2_visual.stl"/>        
      </geometry>      
      <material name="ball_joint_container_2_material">        
        <color rgba="0.61568627450980395466 0.81176470588235294379 0.9294117647058824927 1.0"/>        
      </material>      
    </visual>    
    <collision>      
      <origin xyz="0 0 0" rpy="0 -0 0"/>      
      <geometry>        
        <mesh filename="package:///meshes/right_ball_joint_container_2_collision.stl"/>        
      </geometry>      
    </collision>    
    <inertial>      
      <origin xyz="4.7221442975709993128e-19 -2.7876926753568485081e-17 -0.0097125341669083396778" rpy="0 0 0"/>      
      <mass value="4.8037356425330562243e-05"/>      
      <inertia ixx="7.1865480628741666366e-10" ixy="-8.8579477000968401434e-27" ixz="1.6148781843625983881e-38" iyy="8.4754204277185539101e-10" iyz="4.6483058435882102207e-39" izz="1.8625314111651911712e-10"/>      
    </inertial>    
  </link>  

  <link name="ball_joint_ball_2">    
    <visual>      
      <origin xyz="0 0 0" rpy="0 -0 0"/>      
      <geometry>        
        <mesh filename="package:///meshes/right_ball_joint_ball_2_visual.stl"/>        
      </geometry>      
      <material name="ball_joint_ball_2_material">        
        <color rgba="0.3291302810242056065 0.44310466418644928188 0.69204871161977121741 1.0"/>        
      </material>      
    </visual>    
    <collision>      
      <origin xyz="0 0 0" rpy="0 -0 0"/>      
      <geometry>        
        <mesh filename="package:///meshes/right_ball_joint_ball_2_collision.stl"/>        
      </geometry>      
    </collision>    
    <inertial>      
      <origin xyz="6.5589330492613743757e-18 -0.0010308669810016346004 2.2610906665006864754e-18" rpy="0 0 0"/>      
      <mass value="4.4053796295264623832e-05"/>      
      <inertia ixx="3.1285011349692075725e-10" ixy="4.5293157501257737588e-26" ixz="2.3354674408829216367e-25" iyy="6.2569568612795049364e-11" iyz="-5.8366867949952536809e-25" izz="3.1285321460375444211e-10"/>      
    </inertial>    
  </link>  

  <link name="12lf_2">    
    <visual>      
      <origin xyz="0 0 0" rpy="0 -0 0"/>      
      <geometry>        
        <mesh filename="package:///meshes/right_12lf_2_visual.stl"/>        
      </geometry>      
      <material name="12lf_2_material">        
        <color rgba="0.62004392096503546661 0.5883668461204021316 0.49897069027350277048 1.0"/>        
      </material>      
    </visual>    
    <collision>      
      <origin xyz="0 0 0" rpy="0 -0 0"/>      
      <geometry>        
        <mesh filename="package:///meshes/right_12lf_2_collision.stl"/>        
      </geometry>      
    </collision>    
    <inertial>      
      <origin xyz="0.0049084207226859841167 -0.00013802440006700818632 -0.029947003575832308736" rpy="0 0 0"/>      
      <mass value="0.044782197690790476186"/>      
      <inertia ixx="1.5260128420478200057e-05" ixy="2.295577409853090044e-08" ixz="-8.1364204860999301658e-08" iyy="1.8188469777196414616e-05" iyz="-5.5542241171308300222e-08" izz="5.1496273889314241471e-06"/>      
    </inertial>    
  </link>  

  <link name="12lf_rod_2">    
    <visual>      
      <origin xyz="0 0 0" rpy="0 -0 0"/>      
      <geometry>        
        <mesh filename="package:///meshes/right_12lf_rod_2_visual.stl"/>        
      </geometry>      
      <material name="12lf_rod_2_material">        
        <color rgba="0.80250260812861884396 0.89340612183512713163 0.94491811293548189088 1.0"/>        
      </material>      
    </visual>    
    <collision>      
      <origin xyz="0 0 0" rpy="0 -0 0"/>      
      <geometry>        
        <mesh filename="package:///meshes/right_12lf_rod_2_collision.stl"/>        
      </geometry>      
    </collision>    
    <inertial>      
      <origin xyz="-6.3222084137003392599e-07 4.6933255068316888491e-07 -0.012893387334332135838" rpy="0 0 0"/>      
      <mass value="0.0025088292483592144512"/>      
      <inertia ixx="2.6944521128602990996e-07" ixy="7.1389570225541423729e-15" ixz="1.3562243159358267851e-11" iyy="2.694452000165954658e-07" iyz="-1.008998835460835139e-11" izz="1.7809843599861015564e-08"/>      
    </inertial>    
  </link>  

  <joint name="right_ank_act2" type="prismatic">    
    <origin xyz="2.2722093383550218126e-06 -2.4633073358870660741e-15 -0.07266003047881686161" rpy="3.141592653589793116 2.7467349934334640921e-15 -2.2021168238262860406"/>    
    <parent link="12lf_2"/>    
    <child link="12lf_rod_2"/>    
    <axis xyz="0 0 1"/>    
    <limit effort="1" velocity="20" lower="0" upper="0.040000000000000000833"/>    
    <joint_properties friction="0.0"/>    
  </joint>  

  <joint name="right_ank_B32" type="revolute">    
    <origin xyz="-7.3725747729014301513e-18 -0.0064387505004002698605 6.9388939039072283776e-18" rpy="-1.5707963267948981123 -0.17993145005746249976 -8.7955855822383372175e-16"/>    
    <parent link="ball_joint_ball_2"/>    
    <child link="12lf_2"/>    
    <axis xyz="0 0 1"/>    
    <limit effort="1" velocity="20" lower="-0.785398163397448279" upper="0.785398163397448279"/>    
    <joint_properties friction="0.0"/>    
  </joint>  

  <joint name="right_ank_B22" type="revolute">    
    <origin xyz="0 -5.5511151231257827021e-17 -0.01150000000000000501" rpy="1.5707963267948947816 -1.4285463212679219147 1.5707963267948921171"/>    
    <parent link="ball_joint_container_2"/>    
    <child link="ball_joint_ball_2"/>    
    <axis xyz="0 0 1"/>    
    <limit effort="1" velocity="20" lower="-0.785398163397448279" upper="0.785398163397448279"/>    
    <joint_properties friction="0.0"/>    
  </joint>  

  <joint name="right_ank_B12" type="revolute">    
    <origin xyz="0.0080000000000000192485 0.015000000000000068834 0.028300000000000900824" rpy="-1.5707963267949041075 -1.469756662182670981 1.5707963267948925612"/>    
    <parent link="right_calf_link"/>    
    <child link="ball_joint_container_2"/>    
    <axis xyz="0 0 1"/>    
    <limit effort="1" velocity="20" lower="-0.785398163397448279" upper="0.785398163397448279"/>    
    <joint_properties friction="0.0"/>    
  </joint>  

  <joint name="right_knee" type="revolute">    
    <origin xyz="-2.8905460953097867777e-15 0.095999999999999252598 0.027400000000001673017" rpy="-3.1415926535897824579 4.9746286444423846074e-17 -3.1415926535897891192"/>    
    <parent link="right_hip_pitch_link"/>    
    <child link="right_calf_link"/>    
    <axis xyz="0 0 1"/>    
    <limit effort="1" velocity="20" lower="-1.570796326794896558" upper="0"/>    
    <joint_properties friction="0.0"/>    
  </joint>  

  <joint name="right_hip_pitch" type="revolute">    
    <origin xyz="0.024000000358073016182 -0.019000000000011917078 -0.018999999847560563454" rpy="-1.5707963267950879604 -1.5707963267946316588 0"/>    
    <parent link="hip_roll_link"/>    
    <child link="right_hip_pitch_link"/>    
    <axis xyz="0 0 1"/>    
    <limit effort="1" velocity="20" lower="-1.570796326794896558" upper="1.570796326794896558"/>    
    <joint_properties friction="0.0"/>    
  </joint>  

  <joint name="right_hip_roll" type="revolute">    
    <origin xyz="0.018999999999999874628 7.643544883287250703e-16 -0.025999999999999960643" rpy="-1.300781512818313455e-27 1.5707963267948954478 0"/>    
    <parent link="hip_yaw_link"/>    
    <child link="hip_roll_link"/>    
    <axis xyz="0 0 1"/>    
    <limit effort="1" velocity="20" lower="-1.570796326794896558" upper="0.785398163397448279"/>    
    <joint_properties friction="0.0"/>    
  </joint>  


</robot>