<?xml version="1.0" ?><robot name="right_3R+RH5_leg">  
  <link name="hip_yaw_link">    
    <visual>      
      <origin xyz="0 0 0" rpy="0 -0 0"/>      
      <geometry>        
        <mesh filename="package:///meshes/right_hip_yaw_link_visual.stl"/>        
      </geometry>      
      <material name="hip_yaw_link_material">        
        <color rgba="0.61568627450980395466 0.81176470588235294379 0.92941176470588238168 1.0"/>        
      </material>      
    </visual>    
    <collision>      
      <origin xyz="0 0 0" rpy="0 -0 0"/>      
      <geometry>        
        <mesh filename="package:///meshes/right_hip_yaw_link_collision.stl"/>        
      </geometry>      
    </collision>    
    <inertial>      
      <origin xyz="6.366490512338090007e-19 -3.4284509631238065668e-19 -0.0098390489054829069482" rpy="0 0 0"/>      
      <mass value="0.0090258837370979175946"/>      
      <inertia ixx="1.323045823908586799e-06" ixy="-9.6363174149195392488e-49" ixz="2.5822652061387300435e-33" iyy="3.8408510960330524868e-06" iyz="-1.4423493090974197825e-32" izz="3.8721396285793069258e-06"/>      
    </inertial>    
  </link>  

  <link name="hip_roll_link">    
    <visual>      
      <origin xyz="0 0 0" rpy="0 -0 0"/>      
      <geometry>        
        <mesh filename="package:///meshes/right_hip_roll_link_visual.stl"/>        
      </geometry>      
      <material name="hip_roll_link_material">        
        <color rgba="0.95018735644455876166 0.70678927200428409705 0.06161207940259672694 1.0"/>        
      </material>      
    </visual>    
    <collision>      
      <origin xyz="0 0 0" rpy="0 -0 0"/>      
      <geometry>        
        <mesh filename="package:///meshes/right_hip_roll_link_collision.stl"/>        
      </geometry>      
    </collision>    
    <inertial>      
      <origin xyz="-0.011999849582182727306 -0.00049598090794501390952 -0.018504111838591762174" rpy="0 0 0"/>      
      <mass value="0.098012391483528651936"/>      
      <inertia ixx="2.02217487663054773e-05" ixy="-4.1225592187651471026e-08" ixz="-4.1552068246492221361e-08" iyy="2.735806952472197599e-05" iyz="-5.0935731752407962452e-07" izz="2.7358099958306159966e-05"/>      
    </inertial>    
  </link>  

  <link name="right_hip_pitch_link">    
    <visual>      
      <origin xyz="0 0 0" rpy="0 -0 0"/>      
      <geometry>        
        <mesh filename="package:///meshes/right_hip_pitch_link_visual.stl"/>        
      </geometry>      
      <material name="right_hip_pitch_link_material">        
        <color rgba="0.61654060031870661085 0.8072794953856136102 0.92172283242575780982 1.0"/>        
      </material>      
    </visual>    
    <collision>      
      <origin xyz="0 0 0" rpy="0 -0 0"/>      
      <geometry>        
        <mesh filename="package:///meshes/right_hip_pitch_link_collision.stl"/>        
      </geometry>      
    </collision>    
    <inertial>      
      <origin xyz="-1.3033690427602714275e-05 -0.052867196495286906954 0.023324771095030935597" rpy="0 0 0"/>      
      <mass value="0.09361165381749210479"/>      
      <inertia ixx="6.2575072115421303729e-05" ixy="2.2341794227176803023e-07" ixz="1.1676158767092466385e-08" iyy="2.158659825927508312e-05" iyz="-1.4343483925993865263e-06" izz="6.2296129928644748664e-05"/>      
    </inertial>    
  </link>  

  <link name="right_calf_link">    
    <visual>      
      <origin xyz="0 0 0" rpy="0 -0 0"/>      
      <geometry>        
        <mesh filename="package:///meshes/right_calf_link_visual.stl"/>        
      </geometry>      
      <material name="right_calf_link_material">        
        <color rgba="0.55183757703855651489 0.72973662124660387818 0.876696178325251263 1.0"/>        
      </material>      
    </visual>    
    <collision>      
      <origin xyz="0 0 0" rpy="0 -0 0"/>      
      <geometry>        
        <mesh filename="package:///meshes/right_calf_link_collision.stl"/>        
      </geometry>      
    </collision>    
    <inertial>      
      <origin xyz="-0.0038999626430269076355 0.042409395322589235611 0.0081838728113180578966" rpy="0 0 0"/>      
      <mass value="0.015779725212993943317"/>      
      <inertia ixx="1.4735397719668424476e-05" ixy="2.0283446246059699196e-07" ixz="9.1508417303721244284e-09" iyy="1.8964180016897433082e-06" iyz="-1.5463243486047164502e-08" izz="1.4035958490016417976e-05"/>      
    </inertial>    
  </link>  

  <link name="ank_pitch_link">    
    <visual>      
      <origin xyz="0 0 0" rpy="0 -0 0"/>      
      <geometry>        
        <mesh filename="package:///meshes/right_ank_pitch_link_visual.stl"/>        
      </geometry>      
      <material name="ank_pitch_link_material">        
        <color rgba="0.63189161126160275916 0.72668668793540891482 0.78356373393969258601 1.0"/>        
      </material>      
    </visual>    
    <collision>      
      <origin xyz="0 0 0" rpy="0 -0 0"/>      
      <geometry>        
        <mesh filename="package:///meshes/right_ank_pitch_link_collision.stl"/>        
      </geometry>      
    </collision>    
    <inertial>      
      <origin xyz="4.0269686744046064311e-08 0.0005952828256677747485 -0.014599922383890096347" rpy="0 0 0"/>      
      <mass value="0.0042238381753791605713"/>      
      <inertia ixx="4.3705254067390763339e-07" ixy="1.6834347123503678247e-13" ixz="1.6428822925662319172e-12" iyy="3.9782741364654897909e-07" iyz="2.091920170560600146e-14" izz="8.8858574534525519691e-08"/>      
    </inertial>    
  </link>  

  <link name="ank_roll_link">    
    <visual>      
      <origin xyz="0 0 0" rpy="0 -0 0"/>      
      <geometry>        
        <mesh filename="package:///meshes/right_ank_roll_link_visual.stl"/>        
      </geometry>      
      <material name="ank_roll_link_material">        
        <color rgba="0.61568627450980406568 0.81176470588235305481 0.9294117647058824927 1.0"/>        
      </material>      
    </visual>    
    <collision>      
      <origin xyz="0 0 0" rpy="0 -0 0"/>      
      <geometry>        
        <mesh filename="package:///meshes/right_ank_roll_link_collision.stl"/>        
      </geometry>      
    </collision>    
    <inertial>      
      <origin xyz="0.0070959174823323253184 0.031669497972650027806 0.0015447237307594132837" rpy="0 0 0"/>      
      <mass value="0.020312412236862385784"/>      
      <inertia ixx="1.4885431783124275423e-05" ixy="-7.6720412005443854687e-07" ixz="-8.1066503931638930107e-07" iyy="1.7915307614905201354e-05" iyz="-1.1563439864926758107e-06" izz="6.9141164362347843156e-06"/>      
    </inertial>    
  </link>  

  <link name="ank_rr_link">    
    <visual>      
      <origin xyz="0 0 0" rpy="0 -0 0"/>      
      <geometry>        
        <mesh filename="package:///meshes/right_ank_rr_link_visual.stl"/>        
      </geometry>      
      <material name="ank_rr_link_material">        
        <color rgba="0.61568627450980395466 0.81176470588235294379 0.92941176470588238168 1.0"/>        
      </material>      
    </visual>    
    <collision>      
      <origin xyz="0 0 0" rpy="0 -0 0"/>      
      <geometry>        
        <mesh filename="package:///meshes/right_ank_rr_link_collision.stl"/>        
      </geometry>      
    </collision>    
    <inertial>      
      <origin xyz="-1.8317486292791937667e-20 -0.0061447686137497906783 3.6638870517520113595e-18" rpy="0 0 0"/>      
      <mass value="0.00042507093693768162193"/>      
      <inertia ixx="8.7843229279236055827e-09" ixy="-1.5864380896313798257e-26" ixz="-1.0879024114877701188e-14" iyy="8.0301730481463919886e-09" iyz="4.5653393820769265932e-32" izz="1.2504379836120061674e-08"/>      
    </inertial>    
  </link>  

  <link name="12lf_rod_end">    
    <visual>      
      <origin xyz="0 0 0" rpy="0 -0 0"/>      
      <geometry>        
        <mesh filename="package:///meshes/right_12lf_rod_end_visual.stl"/>        
      </geometry>      
      <material name="12lf_rod_end_material">        
        <color rgba="0.92771758928836534075 0.61049283053223002415 0.2184765849058516729 1.0"/>        
      </material>      
    </visual>    
    <collision>      
      <origin xyz="0 0 0" rpy="0 -0 0"/>      
      <geometry>        
        <mesh filename="package:///meshes/right_12lf_rod_end_collision.stl"/>        
      </geometry>      
    </collision>    
    <inertial>      
      <origin xyz="-4.4735196695610147617e-11 -0.0038422185938245959416 6.4384187209476411779e-06" rpy="0 0 0"/>      
      <mass value="0.00085420491177815905965"/>      
      <inertia ixx="1.1840985264406750998e-08" ixy="2.0225977936654380285e-16" ixz="-9.2606419961864584135e-16" iyy="3.3549621576796866954e-09" iyz="7.4535631381826499778e-12" izz="1.2703522254419963381e-08"/>      
    </inertial>    
  </link>  

  <joint name="right_ank_R21" type="revolute">    
    <origin xyz="-3.4694469519536141888e-18 -0.010000000000000008882 1.0408340855860842566e-17" rpy="1.5707963267949234254 -1.5664147454868782017 -1.5707963267941609242"/>    
    <parent link="ank_rr_link"/>    
    <child link="12lf_rod_end"/>    
    <axis xyz="0 0 1"/>    
    <limit effort="1" velocity="20" lower="-1.570796326794896558" upper="1.570796326794896558"/>    
    <joint_properties friction="0.0"/>    
  </joint>  

  <joint name="right_ank_R11" type="revolute">    
    <origin xyz="-0.018000000000000009048 0.015999999999999986455 -0.020599999999999996786" rpy="2.1199056220120536536e-16 1.7337184392140691041e-15 -0.018779262484772244607"/>    
    <parent link="ank_roll_link"/>    
    <child link="ank_rr_link"/>    
    <axis xyz="0 0 1"/>    
    <limit effort="1" velocity="20" lower="-1.570796326794896558" upper="1.570796326794896558"/>    
    <joint_properties friction="0.0"/>    
  </joint>  

  <link name="ank_rr_link_2">    
    <visual>      
      <origin xyz="0 0 0" rpy="0 -0 0"/>      
      <geometry>        
        <mesh filename="package:///meshes/right_ank_rr_link_2_visual.stl"/>        
      </geometry>      
      <material name="ank_rr_link_2_material">        
        <color rgba="0.61568627450980395466 0.81176470588235294379 0.92941176470588238168 1.0"/>        
      </material>      
    </visual>    
    <collision>      
      <origin xyz="0 0 0" rpy="0 -0 0"/>      
      <geometry>        
        <mesh filename="package:///meshes/right_ank_rr_link_2_collision.stl"/>        
      </geometry>      
    </collision>    
    <inertial>      
      <origin xyz="6.5146200963277524714e-21 -0.0061447686137497351672 -3.2750068521547047208e-18" rpy="0 0 0"/>      
      <mass value="0.00042507093693768162193"/>      
      <inertia ixx="8.7843229279236055827e-09" ixy="5.7113621339313191808e-27" ixz="-1.0879024114877701188e-14" iyy="8.0301730481463919886e-09" iyz="-2.1258676875294024583e-32" izz="1.2504379836120061674e-08"/>      
    </inertial>    
  </link>  

  <link name="12lf_rod_end_2">    
    <visual>      
      <origin xyz="0 0 0" rpy="0 -0 0"/>      
      <geometry>        
        <mesh filename="package:///meshes/right_12lf_rod_end_2_visual.stl"/>        
      </geometry>      
      <material name="12lf_rod_end_2_material">        
        <color rgba="0.92771758928836534075 0.61049283053223002415 0.2184765849058516729 1.0"/>        
      </material>      
    </visual>    
    <collision>      
      <origin xyz="0 0 0" rpy="0 -0 0"/>      
      <geometry>        
        <mesh filename="package:///meshes/right_12lf_rod_end_2_collision.stl"/>        
      </geometry>      
    </collision>    
    <inertial>      
      <origin xyz="-4.473519593544271936e-11 -0.0038422185938245699208 6.4384187209475590157e-06" rpy="0 0 0"/>      
      <mass value="0.00085420491177815905965"/>      
      <inertia ixx="1.1840985264406777468e-08" ixy="2.0225978027478046506e-16" ixz="-9.260641977021974134e-16" iyy="3.3549621576797024118e-09" iyz="7.4535631381828147677e-12" izz="1.2703522254419948492e-08"/>      
    </inertial>    
  </link>  

  <joint name="right_ank_R22" type="revolute">    
    <origin xyz="-3.4694469519536141888e-18 -0.0099999999999998978595 1.0408340855860842566e-17" rpy="-1.570796326794896336 -1.5664376509751398725 1.5707963267966709164"/>    
    <parent link="ank_rr_link_2"/>    
    <child link="12lf_rod_end_2"/>    
    <axis xyz="0 0 1"/>    
    <limit effort="1" velocity="20" lower="-1.570796326794896558" upper="1.570796326794896558"/>    
    <joint_properties friction="0.0"/>    
  </joint>  

  <joint name="right_ank_R12" type="revolute">    
    <origin xyz="0.017999999999999995171 0.015999999999999930944 -0.020600000000000003725" rpy="-3.1415926535897855665 2.3670754779580369231e-15 -3.1229304365172758651"/>    
    <parent link="ank_roll_link"/>    
    <child link="ank_rr_link_2"/>    
    <axis xyz="0 0 1"/>    
    <limit effort="1" velocity="20" lower="-1.570796326794896558" upper="1.570796326794896558"/>    
    <joint_properties friction="0.0"/>    
  </joint>  

  <joint name="right_ank_roll" type="revolute">    
    <origin xyz="3.3584246494910985348e-15 0.0015000000000102613543 -0.014599999999994976371" rpy="-1.5707963267951949859 1.5707963267946882802 0"/>    
    <parent link="ank_pitch_link"/>    
    <child link="ank_roll_link"/>    
    <axis xyz="0 0 1"/>    
    <limit effort="1" velocity="20" lower="-0.785398163397448279" upper="0.785398163397448279"/>    
    <joint_properties friction="0.0"/>    
  </joint>  

  <joint name="right_ank_pitch" type="revolute">    
    <origin xyz="1.3701363056155178809e-18 0.10000000000000000555 -0.0061999999999999243216" rpy="-3.1415926535897917837 8.3351550965154899867e-16 -1.5707963267948104047"/>    
    <parent link="right_calf_link"/>    
    <child link="ank_pitch_link"/>    
    <axis xyz="0 0 1"/>    
    <limit effort="1" velocity="20" lower="-0.785398163397448279" upper="0.95993108859688125456"/>    
    <joint_properties friction="0.0"/>    
  </joint>  

  <link name="ball_joint_container">    
    <visual>      
      <origin xyz="0 0 0" rpy="0 -0 0"/>      
      <geometry>        
        <mesh filename="package:///meshes/right_ball_joint_container_visual.stl"/>        
      </geometry>      
      <material name="ball_joint_container_material">        
        <color rgba="0.61568627450980395466 0.81176470588235294379 0.9294117647058824927 1.0"/>        
      </material>      
    </visual>    
    <collision>      
      <origin xyz="0 0 0" rpy="0 -0 0"/>      
      <geometry>        
        <mesh filename="package:///meshes/right_ball_joint_container_collision.stl"/>        
      </geometry>      
    </collision>    
    <inertial>      
      <origin xyz="-2.9972325221965159909e-18 -1.3170636881704331284e-19 -0.0097125341669083414126" rpy="0 0 0"/>      
      <mass value="4.8037356425330562243e-05"/>      
      <inertia ixx="7.1865480628741707725e-10" ixy="4.7686823988665461978e-27" ixz="5.1372825832619971272e-40" iyy="8.475420427718555978e-10" iyz="-3.2723433928573531218e-38" izz="1.8625314111651911712e-10"/>      
    </inertial>    
  </link>  

  <link name="ball_joint_ball">    
    <visual>      
      <origin xyz="0 0 0" rpy="0 -0 0"/>      
      <geometry>        
        <mesh filename="package:///meshes/right_ball_joint_ball_visual.stl"/>        
      </geometry>      
      <material name="ball_joint_ball_material">        
        <color rgba="0.3291302810242056065 0.44310466418644928188 0.69204871161977121741 1.0"/>        
      </material>      
    </visual>    
    <collision>      
      <origin xyz="0 0 0" rpy="0 -0 0"/>      
      <geometry>        
        <mesh filename="package:///meshes/right_ball_joint_ball_collision.stl"/>        
      </geometry>      
    </collision>    
    <inertial>      
      <origin xyz="5.9030136108666568905e-18 -0.0010308669810016022911 -7.1252153088828868716e-20" rpy="0 0 0"/>      
      <mass value="4.4053796295264630609e-05"/>      
      <inertia ixx="3.1285011349692649581e-10" ixy="5.077154768211529188e-26" ixz="4.6798489160140480731e-26" iyy="6.2569568612795592202e-11" iyz="-1.1895451457969914525e-26" izz="3.1285321460376173164e-10"/>      
    </inertial>    
  </link>  

  <link name="12lf">    
    <visual>      
      <origin xyz="0 0 0" rpy="0 -0 0"/>      
      <geometry>        
        <mesh filename="package:///meshes/right_12lf_visual.stl"/>        
      </geometry>      
      <material name="12lf_material">        
        <color rgba="0.62004392100736027693 0.58836684613512635345 0.49897069021535683797 1.0"/>        
      </material>      
    </visual>    
    <collision>      
      <origin xyz="0 0 0" rpy="0 -0 0"/>      
      <geometry>        
        <mesh filename="package:///meshes/right_12lf_collision.stl"/>        
      </geometry>      
    </collision>    
    <inertial>      
      <origin xyz="0.0049084207243678019961 -0.00013802439943444823681 -0.029947003577154806403" rpy="0 0 0"/>      
      <mass value="0.044782197696050358993"/>      
      <inertia ixx="1.5260128421318422859e-05" ixy="2.2955773686503350099e-08" ixz="-8.1364204007312129745e-08" iyy="1.8188469778958859786e-05" iyz="-5.5542240842559937377e-08" izz="5.1496273901754478842e-06"/>      
    </inertial>    
  </link>  

  <link name="12lf_rod">    
    <visual>      
      <origin xyz="0 0 0" rpy="0 -0 0"/>      
      <geometry>        
        <mesh filename="package:///meshes/right_12lf_rod_visual.stl"/>        
      </geometry>      
      <material name="12lf_rod_material">        
        <color rgba="0.80250260812861884396 0.89340612183512713163 0.94491811293548189088 1.0"/>        
      </material>      
    </visual>    
    <collision>      
      <origin xyz="0 0 0" rpy="0 -0 0"/>      
      <geometry>        
        <mesh filename="package:///meshes/right_12lf_rod_collision.stl"/>        
      </geometry>      
    </collision>    
    <inertial>      
      <origin xyz="-6.3222084100391536949e-07 4.6933255118795287588e-07 -0.012893387334328484245" rpy="0 0 0"/>      
      <mass value="0.0025088292483592144512"/>      
      <inertia ixx="2.6944521128623250965e-07" ixy="7.1389570415193793204e-15" ixz="1.3562243150951720143e-11" iyy="2.6944520001679811843e-07" iyz="-1.0089988370044107076e-11" izz="1.7809843599861028799e-08"/>      
    </inertial>    
  </link>  

  <joint name="right_ank_act1" type="prismatic">    
    <origin xyz="2.2722093416596700344e-06 1.9567680809018384025e-15 -0.074779998095380800782" rpy="-3.1415926535897811256 5.9900329378763890994e-15 -2.2021168238260777628"/>    
    <parent link="12lf"/>    
    <child link="12lf_rod"/>    
    <axis xyz="0 0 1"/>    
    <limit effort="1" velocity="20" lower="0" upper="0.040000000000000000833"/>    
    <joint_properties friction="0.0"/>    
  </joint>  

  <joint name="right_ank_B31" type="revolute">    
    <origin xyz="-3.4694469519536141888e-18 -0.0064387505004003808828 0" rpy="-1.570796326794896558 0.16913440034157123382 1.0478833061949341326e-15"/>    
    <parent link="ball_joint_ball"/>    
    <child link="12lf"/>    
    <axis xyz="0 0 1"/>    
    <limit effort="1" velocity="20" lower="-0.785398163397448279" upper="0.785398163397448279"/>    
    <joint_properties friction="0.0"/>    
  </joint>  

  <joint name="right_ank_B21" type="revolute">    
    <origin xyz="-3.4694469519536141888e-18 0 -0.011499999999999996336" rpy="-1.5707963267952478326 -1.5664147454871724108 -1.5707963267955875608"/>    
    <parent link="ball_joint_container"/>    
    <child link="ball_joint_ball"/>    
    <axis xyz="0 0 1"/>    
    <limit effort="1" velocity="20" lower="-0.785398163397448279" upper="0.785398163397448279"/>    
    <joint_properties friction="0.0"/>    
  </joint>  

  <joint name="right_ank_B11" type="revolute">    
    <origin xyz="0.0080000000000000019013 0.014999999999999985567 -0.011500000000000003275" rpy="1.5707963267948470421 -1.5520170643097048746 -1.570796326794996034"/>    
    <parent link="right_calf_link"/>    
    <child link="ball_joint_container"/>    
    <axis xyz="0 0 1"/>    
    <limit effort="1" velocity="20" lower="-0.785398163397448279" upper="0.785398163397448279"/>    
    <joint_properties friction="0.0"/>    
  </joint>  

  <link name="ball_joint_container_2">    
    <visual>      
      <origin xyz="0 0 0" rpy="0 -0 0"/>      
      <geometry>        
        <mesh filename="package:///meshes/right_ball_joint_container_2_visual.stl"/>        
      </geometry>      
      <material name="ball_joint_container_2_material">        
        <color rgba="0.61568627450980395466 0.81176470588235294379 0.9294117647058824927 1.0"/>        
      </material>      
    </visual>    
    <collision>      
      <origin xyz="0 0 0" rpy="0 -0 0"/>      
      <geometry>        
        <mesh filename="package:///meshes/right_ball_joint_container_2_collision.stl"/>        
      </geometry>      
    </collision>    
    <inertial>      
      <origin xyz="4.7221442975710426462e-19 -1.3170636881703233504e-19 -0.0097125341669083431473" rpy="0 0 0"/>      
      <mass value="4.8037356425330562243e-05"/>      
      <inertia ixx="7.1865480628741645687e-10" ixy="2.3082551744305039966e-27" ixz="-1.9591983056907320695e-39" iyy="8.475420427718555978e-10" iyz="4.2854812084784726805e-38" izz="1.8625314111651911712e-10"/>      
    </inertial>    
  </link>  

  <link name="ball_joint_ball_2">    
    <visual>      
      <origin xyz="0 0 0" rpy="0 -0 0"/>      
      <geometry>        
        <mesh filename="package:///meshes/right_ball_joint_ball_2_visual.stl"/>        
      </geometry>      
      <material name="ball_joint_ball_2_material">        
        <color rgba="0.3291302810242056065 0.44310466418644928188 0.69204871161977121741 1.0"/>        
      </material>      
    </visual>    
    <collision>      
      <origin xyz="0 0 0" rpy="0 -0 0"/>      
      <geometry>        
        <mesh filename="package:///meshes/right_ball_joint_ball_2_collision.stl"/>        
      </geometry>      
    </collision>    
    <inertial>      
      <origin xyz="-6.395633123682807487e-18 -0.0010308669810016493455 -2.1718848700189737814e-18" rpy="0 0 0"/>      
      <mass value="4.4053796295264630609e-05"/>      
      <inertia ixx="3.1285011349692820187e-10" ixy="1.9037656967091037146e-25" ixz="1.1446951858299053379e-24" iyy="6.2569568612796238436e-11" iyz="-1.9178182979881764052e-25" izz="3.1285321460376478187e-10"/>      
    </inertial>    
  </link>  

  <link name="12lf_2">    
    <visual>      
      <origin xyz="0 0 0" rpy="0 -0 0"/>      
      <geometry>        
        <mesh filename="package:///meshes/right_12lf_2_visual.stl"/>        
      </geometry>      
      <material name="12lf_2_material">        
        <color rgba="0.62004392100736027693 0.58836684613512635345 0.49897069021535683797 1.0"/>        
      </material>      
    </visual>    
    <collision>      
      <origin xyz="0 0 0" rpy="0 -0 0"/>      
      <geometry>        
        <mesh filename="package:///meshes/right_12lf_2_collision.stl"/>        
      </geometry>      
    </collision>    
    <inertial>      
      <origin xyz="0.0049084207243634686568 -0.00013802439943656473497 -0.029947003577153203518" rpy="0 0 0"/>      
      <mass value="0.044782197696050358993"/>      
      <inertia ixx="1.5260128421317484346e-05" ixy="2.2955773686700811346e-08" ixz="-8.1364204009454104015e-08" iyy="1.8188469778957667164e-05" iyz="-5.5542240843571850581e-08" izz="5.149627390175211562e-06"/>      
    </inertial>    
  </link>  

  <link name="12lf_rod_2">    
    <visual>      
      <origin xyz="0 0 0" rpy="0 -0 0"/>      
      <geometry>        
        <mesh filename="package:///meshes/right_12lf_rod_2_visual.stl"/>        
      </geometry>      
      <material name="12lf_rod_2_material">        
        <color rgba="0.80250260812861884396 0.89340612183512713163 0.94491811293548189088 1.0"/>        
      </material>      
    </visual>    
    <collision>      
      <origin xyz="0 0 0" rpy="0 -0 0"/>      
      <geometry>        
        <mesh filename="package:///meshes/right_12lf_rod_2_collision.stl"/>        
      </geometry>      
    </collision>    
    <inertial>      
      <origin xyz="-6.3222084108049095957e-07 4.6933255050749711039e-07 -0.012893387334330222438" rpy="0 0 0"/>      
      <mass value="0.0025088292483592144512"/>      
      <inertia ixx="2.6944521128613451853e-07" ixy="7.1389570705527249389e-15" ixz="1.3562243151413031662e-11" iyy="2.6944520001670002143e-07" iyz="-1.0089988349642198099e-11" izz="1.7809843599861015564e-08"/>      
    </inertial>    
  </link>  

  <joint name="right_ank_act2" type="prismatic">    
    <origin xyz="2.2722093354597683312e-06 -2.3106516700011070498e-15 -0.074779996992745872975" rpy="3.1415926535897926719 1.5779374385287525465e-15 -2.2021168238262811556"/>    
    <parent link="12lf_2"/>    
    <child link="12lf_rod_2"/>    
    <axis xyz="0 0 1"/>    
    <limit effort="1" velocity="20" lower="0" upper="0.040000000000000000833"/>    
    <joint_properties friction="0.0"/>    
  </joint>  

  <joint name="right_ank_B32" type="revolute">    
    <origin xyz="-1.3877787807814456755e-17 -0.0064387505004004919051 3.4694469519536141888e-18" rpy="-1.57079632679489678 -0.17993145005742655629 -9.5188382896695163748e-16"/>    
    <parent link="ball_joint_ball_2"/>    
    <child link="12lf_2"/>    
    <axis xyz="0 0 1"/>    
    <limit effort="1" velocity="20" lower="-0.785398163397448279" upper="0.785398163397448279"/>    
    <joint_properties friction="0.0"/>    
  </joint>  

  <joint name="right_ank_B22" type="revolute">    
    <origin xyz="-3.4694469519536141888e-18 0 -0.01150000000000000154" rpy="-1.5707963267948972241 -1.5664376509754736055 -1.5707963267954201392"/>    
    <parent link="ball_joint_container_2"/>    
    <child link="ball_joint_ball_2"/>    
    <axis xyz="0 0 1"/>    
    <limit effort="1" velocity="20" lower="-0.785398163397448279" upper="0.785398163397448279"/>    
    <joint_properties friction="0.0"/>    
  </joint>  

  <joint name="right_ank_B12" type="revolute">    
    <origin xyz="0.007999999999999972411 0.015000000000000041078 0.028299999999999964073" rpy="-1.570796326794911435 -1.5521341097221474925 1.5707963267949895947"/>    
    <parent link="right_calf_link"/>    
    <child link="ball_joint_container_2"/>    
    <axis xyz="0 0 1"/>    
    <limit effort="1" velocity="20" lower="-0.785398163397448279" upper="0.785398163397448279"/>    
    <joint_properties friction="0.0"/>    
  </joint>  

  <joint name="right_knee" type="revolute">    
    <origin xyz="-8.6240005279115787276e-15 -0.096000000000003332667 0.0105999999999985689" rpy="-1.540481569708491688e-15 6.7185500345545200678e-16 3.1415926535894529437"/>    
    <parent link="right_hip_pitch_link"/>    
    <child link="right_calf_link"/>    
    <axis xyz="0 0 1"/>    
    <limit effort="1" velocity="20" lower="-1.570796326794896558" upper="0"/>    
    <joint_properties friction="0.0"/>    
  </joint>  

  <joint name="right_hip_pitch" type="revolute">    
    <origin xyz="-0.024000000716139988088 -0.01900000015244911189 -0.019000000152447529822" rpy="-1.5707963267949285324 -1.5707963267948303887 0"/>    
    <parent link="hip_roll_link"/>    
    <child link="right_hip_pitch_link"/>    
    <axis xyz="0 0 1"/>    
    <limit effort="1" velocity="20" lower="-1.570796326794896558" upper="1.570796326794896558"/>    
    <joint_properties friction="0.0"/>    
  </joint>  

  <joint name="right_hip_roll" type="revolute">    
    <origin xyz="0.018999999999999881567 -3.6837601416870012287e-18 -0.026000000000000002276" rpy="3.141592653589793116 -1.570796326794896336 0"/>    
    <parent link="hip_yaw_link"/>    
    <child link="hip_roll_link"/>    
    <axis xyz="0 0 1"/>    
    <limit effort="1" velocity="20" lower="-1.570796326794896558" upper="0.785398163397448279"/>    
    <joint_properties friction="0.0"/>    
  </joint>  


</robot>