<?xml version="1.0" ?><robot name="right_3R+RH5_leg">  
  <link name="hip_yaw_link">    
    <visual>      
      <origin xyz="0 0 0" rpy="0 -0 0"/>      
      <geometry>        
        <mesh filename="package:///meshes/right_hip_yaw_link_visual.stl"/>        
      </geometry>      
      <material name="hip_yaw_link_material">        
        <color rgba="0.61568627450980395466 0.81176470588235294379 0.9294117647058824927 1.0"/>        
      </material>      
    </visual>    
    <collision>      
      <origin xyz="0 0 0" rpy="0 -0 0"/>      
      <geometry>        
        <mesh filename="package:///meshes/right_hip_yaw_link_collision.stl"/>        
      </geometry>      
    </collision>    
    <inertial>      
      <origin xyz="2.1765780897354368682e-19 -3.0328722395806411214e-19 -0.0098390489054829086829" rpy="0 0 0"/>      
      <mass value="0.009025883737097921064"/>      
      <inertia ixx="1.3230458239085880696e-06" ixy="-6.4778545919079861077e-49" ixz="1.7322911775161989053e-33" iyy="3.8408510960330541809e-06" iyz="-1.4482241779965781819e-32" izz="3.8721396285793086199e-06"/>      
    </inertial>    
  </link>  

  <link name="hip_roll_link">    
    <visual>      
      <origin xyz="0 0 0" rpy="0 -0 0"/>      
      <geometry>        
        <mesh filename="package:///meshes/right_hip_roll_link_visual.stl"/>        
      </geometry>      
      <material name="hip_roll_link_material">        
        <color rgba="0.95018735644455853961 0.70678927200428420807 0.061612079402596685307 1.0"/>        
      </material>      
    </visual>    
    <collision>      
      <origin xyz="0 0 0" rpy="0 -0 0"/>      
      <geometry>        
        <mesh filename="package:///meshes/right_hip_roll_link_collision.stl"/>        
      </geometry>      
    </collision>    
    <inertial>      
      <origin xyz="-0.012000151133960917579 -0.00049588831385676847546 -0.018504019244507459441" rpy="0 0 0"/>      
      <mass value="0.09801239148352869357"/>      
      <inertia ixx="2.0221748766307408535e-05" ixy="-4.1552068245398642269e-08" ixz="-4.1225592188036493823e-08" iyy="2.7358099958307688013e-05" iyz="-5.0935731752404839018e-07" izz="2.7358069524724229097e-05"/>      
    </inertial>    
  </link>  

  <link name="right_hip_pitch_link">    
    <visual>      
      <origin xyz="0 0 0" rpy="0 -0 0"/>      
      <geometry>        
        <mesh filename="package:///meshes/right_hip_pitch_link_visual.stl"/>        
      </geometry>      
      <material name="right_hip_pitch_link_material">        
        <color rgba="0.6165363060683557439 0.80730204019995621678 0.92176148067891616744 1.0"/>        
      </material>      
    </visual>    
    <collision>      
      <origin xyz="0 0 0" rpy="0 -0 0"/>      
      <geometry>        
        <mesh filename="package:///meshes/right_hip_pitch_link_collision.stl"/>        
      </geometry>      
    </collision>    
    <inertial>      
      <origin xyz="-1.4741268609426623978e-05 0.052986690876698237795 0.014788127171305245899" rpy="0 0 0"/>      
      <mass value="0.094084567879581956773"/>      
      <inertia ixx="6.3099182122443713016e-05" ixy="-2.2045192591942831085e-07" ixz="-1.2728889936268710697e-08" iyy="2.1759163818497920495e-05" iyz="-1.4708395298810234192e-06" izz="6.2821853547821832043e-05"/>      
    </inertial>    
  </link>  

  <link name="right_calf_link">    
    <visual>      
      <origin xyz="0 0 0" rpy="0 -0 0"/>      
      <geometry>        
        <mesh filename="package:///meshes/right_calf_link_visual.stl"/>        
      </geometry>      
      <material name="right_calf_link_material">        
        <color rgba="0.55182153444277581844 0.72936705907288057471 0.87615824804808439819 1.0"/>        
      </material>      
    </visual>    
    <collision>      
      <origin xyz="0 0 0" rpy="0 -0 0"/>      
      <geometry>        
        <mesh filename="package:///meshes/right_calf_link_collision.stl"/>        
      </geometry>      
    </collision>    
    <inertial>      
      <origin xyz="-0.0038784271883378156585 0.043110179744828905357 0.0081688793093392352007" rpy="0 0 0"/>      
      <mass value="0.016616299594005391055"/>      
      <inertia ixx="1.5958223723938048889e-05" ixy="2.2918216583122531074e-07" ixz="5.9933409326354686853e-09" iyy="2.0657984790181373815e-06" iyz="-2.8480740343859627724e-08" izz="1.5100763145605012705e-05"/>      
    </inertial>    
  </link>  

  <link name="ank_pitch_link">    
    <visual>      
      <origin xyz="0 0 0" rpy="0 -0 0"/>      
      <geometry>        
        <mesh filename="package:///meshes/right_ank_pitch_link_visual.stl"/>        
      </geometry>      
      <material name="ank_pitch_link_material">        
        <color rgba="0.63189161126160275916 0.72668668793540891482 0.78356373393969258601 1.0"/>        
      </material>      
    </visual>    
    <collision>      
      <origin xyz="0 0 0" rpy="0 -0 0"/>      
      <geometry>        
        <mesh filename="package:///meshes/right_ank_pitch_link_collision.stl"/>        
      </geometry>      
    </collision>    
    <inertial>      
      <origin xyz="4.026968783825126577e-08 0.00059528282566478777152 -0.014599922383890177879" rpy="0 0 0"/>      
      <mass value="0.0042238381753791605713"/>      
      <inertia ixx="4.3705254067388915748e-07" ixy="1.6834346644559477147e-13" ixz="1.6428822746950188149e-12" iyy="3.9782741364654717915e-07" iyz="2.0919211860378376185e-14" izz="8.8858574534509015783e-08"/>      
    </inertial>    
  </link>  

  <link name="ank_roll_link">    
    <visual>      
      <origin xyz="0 0 0" rpy="0 -0 0"/>      
      <geometry>        
        <mesh filename="package:///meshes/right_ank_roll_link_visual.stl"/>        
      </geometry>      
      <material name="ank_roll_link_material">        
        <color rgba="0.61568627450980384364 0.81176470588235294379 0.92941176470588227065 1.0"/>        
      </material>      
    </visual>    
    <collision>      
      <origin xyz="0 0 0" rpy="0 -0 0"/>      
      <geometry>        
        <mesh filename="package:///meshes/right_ank_roll_link_collision.stl"/>        
      </geometry>      
    </collision>    
    <inertial>      
      <origin xyz="-6.3661537446033702237e-10 0.027240102316353740491 0.0019830147448535390478" rpy="0 0 0"/>      
      <mass value="0.013844478784760253648"/>      
      <inertia ixx="1.0150902309234951154e-05" ixy="6.8603302689735109411e-14" ixz="-3.2605547316574369192e-13" iyy="8.6636116663431484141e-06" iyz="-7.8151778926545186654e-07" izz="2.8991570356470512405e-06"/>      
    </inertial>    
  </link>  

  <link name="ank_rr_link">    
    <visual>      
      <origin xyz="0 0 0" rpy="0 -0 0"/>      
      <geometry>        
        <mesh filename="package:///meshes/right_ank_rr_link_visual.stl"/>        
      </geometry>      
      <material name="ank_rr_link_material">        
        <color rgba="0.61568627450980395466 0.81176470588235294379 0.92941176470588238168 1.0"/>        
      </material>      
    </visual>    
    <collision>      
      <origin xyz="0 0 0" rpy="0 -0 0"/>      
      <geometry>        
        <mesh filename="package:///meshes/right_ank_rr_link_collision.stl"/>        
      </geometry>      
    </collision>    
    <inertial>      
      <origin xyz="3.4593503690053864204e-05 0.0062999445222072132655 -0.0018999999999999921899" rpy="0 0 0"/>      
      <mass value="0.00044289790445047673732"/>      
      <inertia ixx="9.0894755004835256766e-09" ixy="-5.6689994077039463061e-11" ixz="1.0879024115038818139e-14" iyy="8.3785129146959922129e-09" iyz="-6.7148521063699618988e-32" izz="1.3107013728801488166e-08"/>      
    </inertial>    
  </link>  

  <link name="12lf_rod_end">    
    <visual>      
      <origin xyz="0 0 0" rpy="0 -0 0"/>      
      <geometry>        
        <mesh filename="package:///meshes/right_12lf_rod_end_visual.stl"/>        
      </geometry>      
      <material name="12lf_rod_end_material">        
        <color rgba="0.92771758928836534075 0.61049283053223002415 0.2184765849058516729 1.0"/>        
      </material>      
    </visual>    
    <collision>      
      <origin xyz="0 0 0" rpy="0 -0 0"/>      
      <geometry>        
        <mesh filename="package:///meshes/right_12lf_rod_end_collision.stl"/>        
      </geometry>      
    </collision>    
    <inertial>      
      <origin xyz="-4.4735201141172343971e-11 0.0038422185938245959416 -0.002006438418720947383" rpy="0 0 0"/>      
      <mass value="0.00085420491177815905965"/>      
      <inertia ixx="1.1840985264406777468e-08" ixy="-2.0225977980941024108e-16" ixz="9.2606419959974177583e-16" iyy="3.3549621576797280544e-09" iyz="7.4535631381848423295e-12" izz="1.2703522254419960073e-08"/>      
    </inertial>    
  </link>  

  <joint name="right_ank_R21" type="revolute">    
    <origin xyz="0.0021000000000000254574 0.010000000000000092149 -0.0018999999999999919731" rpy="-1.57079632679489678 1.4274562579811747032 -1.570796326794901665"/>    
    <parent link="ank_rr_link"/>    
    <child link="12lf_rod_end"/>    
    <axis xyz="0 0 1"/>    
    <limit effort="1" velocity="20" lower="-1.570796326794896558" upper="1.570796326794896558"/>    
    <joint_properties friction="0.0"/>    
  </joint>  

  <joint name="right_ank_R11" type="revolute">    
    <origin xyz="-0.0099999999999999932693 0.012500000000000038858 -0.02800000000000008038" rpy="-3.1415926535897926719 -7.9041717877712374794e-16 -0.10218566393336031561"/>    
    <parent link="ank_roll_link"/>    
    <child link="ank_rr_link"/>    
    <axis xyz="0 0 1"/>    
    <limit effort="1" velocity="20" lower="-1.570796326794896558" upper="1.570796326794896558"/>    
    <joint_properties friction="0.0"/>    
  </joint>  

  <link name="ank_rr_link_2">    
    <visual>      
      <origin xyz="0 0 0" rpy="0 -0 0"/>      
      <geometry>        
        <mesh filename="package:///meshes/right_ank_rr_link_2_visual.stl"/>        
      </geometry>      
      <material name="ank_rr_link_2_material">        
        <color rgba="0.61568627450980395466 0.81176470588235294379 0.92941176470588238168 1.0"/>        
      </material>      
    </visual>    
    <collision>      
      <origin xyz="0 0 0" rpy="0 -0 0"/>      
      <geometry>        
        <mesh filename="package:///meshes/right_ank_rr_link_2_collision.stl"/>        
      </geometry>      
    </collision>    
    <inertial>      
      <origin xyz="3.4593503690053864204e-05 -0.0062999445222071577544 -0.0018999999999999986951" rpy="0 0 0"/>      
      <mass value="0.00044289790445047673732"/>      
      <inertia ixx="9.0894755004835223679e-09" ixy="5.6689994077039430749e-11" ixz="-1.0879024115038816561e-14" iyy="8.3785129146959922129e-09" iyz="-5.6146655472116469382e-32" izz="1.3107013728801488166e-08"/>      
    </inertial>    
  </link>  

  <link name="12lf_rod_end_2">    
    <visual>      
      <origin xyz="0 0 0" rpy="0 -0 0"/>      
      <geometry>        
        <mesh filename="package:///meshes/right_12lf_rod_end_2_visual.stl"/>        
      </geometry>      
      <material name="12lf_rod_end_2_material">        
        <color rgba="0.92771758928836534075 0.61049283053223013518 0.2184765849058516729 1.0"/>        
      </material>      
    </visual>    
    <collision>      
      <origin xyz="0 0 0" rpy="0 -0 0"/>      
      <geometry>        
        <mesh filename="package:///meshes/right_12lf_rod_end_2_collision.stl"/>        
      </geometry>      
    </collision>    
    <inertial>      
      <origin xyz="-4.4735188340877362683e-11 0.0038422185938245798954 -0.0020064384187209456482" rpy="0 0 0"/>      
      <mass value="0.00085420491177815905965"/>      
      <inertia ixx="1.1840985264406800629e-08" ixy="-2.0225978056313929985e-16" ixz="9.2606419976476418024e-16" iyy="3.3549621576797251593e-09" iyz="7.4535631381830506434e-12" izz="1.2703522254419991506e-08"/>      
    </inertial>    
  </link>  

  <joint name="right_ank_R22" type="revolute">    
    <origin xyz="0.0021000000000000185185 -0.010000000000000203171 -0.0019000000000000336065" rpy="-1.5707963267948961139 -1.4274330297240631626 -1.5707963267948974462"/>    
    <parent link="ank_rr_link_2"/>    
    <child link="12lf_rod_end_2"/>    
    <axis xyz="0 0 1"/>    
    <limit effort="1" velocity="20" lower="-1.570796326794896558" upper="1.570796326794896558"/>    
    <joint_properties friction="0.0"/>    
  </joint>  

  <joint name="right_ank_R12" type="revolute">    
    <origin xyz="0.0099999999999999967387 0.012499999999999761302 -0.02800000000000008038" rpy="-3.141592653589793116 2.6793361964555018776e-16 -3.0395375511005577884"/>    
    <parent link="ank_roll_link"/>    
    <child link="ank_rr_link_2"/>    
    <axis xyz="0 0 1"/>    
    <limit effort="1" velocity="20" lower="-1.570796326794896558" upper="1.570796326794896558"/>    
    <joint_properties friction="0.0"/>    
  </joint>  

  <joint name="right_ank_roll" type="revolute">    
    <origin xyz="1.7763568394002504647e-15 -0.0061000000000006751946 -0.014600000000001986389" rpy="1.5707963281806591738 1.5707907166914047981 -3.1415926522336965476"/>    
    <parent link="ank_pitch_link"/>    
    <child link="ank_roll_link"/>    
    <axis xyz="0 0 1"/>    
    <limit effort="1" velocity="20" lower="-1.570796326794896558" upper="1.570796326794896558"/>    
    <joint_properties friction="0.0"/>    
  </joint>  

  <joint name="right_ank_pitch" type="revolute">    
    <origin xyz="1.1774009739933720541e-18 0.099999999999999922284 -0.0061999999999999937106" rpy="-3.141592653589793116 3.885801455584734555e-16 -1.5707963267948825692"/>    
    <parent link="right_calf_link"/>    
    <child link="ank_pitch_link"/>    
    <axis xyz="0 0 1"/>    
    <limit effort="1" velocity="20" lower="-1.570796326794896558" upper="1.570796326794896558"/>    
    <joint_properties friction="0.0"/>    
  </joint>  

  <link name="ball_joint_container">    
    <visual>      
      <origin xyz="0 0 0" rpy="0 -0 0"/>      
      <geometry>        
        <mesh filename="package:///meshes/right_ball_joint_container_visual.stl"/>        
      </geometry>      
      <material name="ball_joint_container_material">        
        <color rgba="0.61568627450980395466 0.81176470588235294379 0.92941176470588238168 1.0"/>        
      </material>      
    </visual>    
    <collision>      
      <origin xyz="0 0 0" rpy="0 -0 0"/>      
      <geometry>        
        <mesh filename="package:///meshes/right_ball_joint_container_collision.stl"/>        
      </geometry>      
    </collision>    
    <inertial>      
      <origin xyz="4.7221442975708442754e-19 -1.2157539084691741387e-19 -0.0097125341669083396778" rpy="0 0 0"/>      
      <mass value="4.803735642533054869e-05"/>      
      <inertia ixx="7.1865480628741666366e-10" ixy="1.1825814236451355974e-26" ixz="-5.9322125038070853293e-39" iyy="8.4754204277185539101e-10" iyz="-1.7674753249233014464e-39" izz="1.8625314111651911712e-10"/>      
    </inertial>    
  </link>  

  <link name="ball_joint_ball">    
    <visual>      
      <origin xyz="0 0 0" rpy="0 -0 0"/>      
      <geometry>        
        <mesh filename="package:///meshes/right_ball_joint_ball_visual.stl"/>        
      </geometry>      
      <material name="ball_joint_ball_material">        
        <color rgba="0.3291302810242056065 0.44310466418644928188 0.69204871161977121741 1.0"/>        
      </material>      
    </visual>    
    <collision>      
      <origin xyz="0 0 0" rpy="0 -0 0"/>      
      <geometry>        
        <mesh filename="package:///meshes/right_ball_joint_ball_collision.stl"/>        
      </geometry>      
    </collision>    
    <inertial>      
      <origin xyz="-4.1125153491071802599e-18 -0.0010308669810016226741 -1.8495092015533564433e-18" rpy="0 0 0"/>      
      <mass value="4.4053796295264630609e-05"/>      
      <inertia ixx="3.1285011349692525504e-10" ixy="4.808384477806169279e-26" ixz="-2.1466154830118600303e-27" iyy="6.2569568612795566352e-11" iyz="6.1358688430553467103e-26" izz="3.1285321460376379959e-10"/>      
    </inertial>    
  </link>  

  <link name="12lf">    
    <visual>      
      <origin xyz="0 0 0" rpy="0 -0 0"/>      
      <geometry>        
        <mesh filename="package:///meshes/right_12lf_visual.stl"/>        
      </geometry>      
      <material name="12lf_material">        
        <color rgba="0.62004392100736016591 0.58836684613512635345 0.49897069021535672695 1.0"/>        
      </material>      
    </visual>    
    <collision>      
      <origin xyz="0 0 0" rpy="0 -0 0"/>      
      <geometry>        
        <mesh filename="package:///meshes/right_12lf_collision.stl"/>        
      </geometry>      
    </collision>    
    <inertial>      
      <origin xyz="0.0049084207243671454032 -0.00013802439943487300011 -0.02994700357714817629" rpy="0 0 0"/>      
      <mass value="0.044782197696050352054"/>      
      <inertia ixx="1.5260128421313289839e-05" ixy="2.2955773686477098695e-08" ixz="-8.1364204007546704932e-08" iyy="1.8188469778952530756e-05" iyz="-5.5542240842734075439e-08" izz="5.14962739017425865e-06"/>      
    </inertial>    
  </link>  

  <link name="12lf_rod">    
    <visual>      
      <origin xyz="0 0 0" rpy="0 -0 0"/>      
      <geometry>        
        <mesh filename="package:///meshes/right_12lf_rod_visual.stl"/>        
      </geometry>      
      <material name="12lf_rod_material">        
        <color rgba="0.80250260812861884396 0.89340612183512713163 0.94491811293548189088 1.0"/>        
      </material>      
    </visual>    
    <collision>      
      <origin xyz="0 0 0" rpy="0 -0 0"/>      
      <geometry>        
        <mesh filename="package:///meshes/right_12lf_rod_collision.stl"/>        
      </geometry>      
    </collision>    
    <inertial>      
      <origin xyz="-6.3222084032511767099e-07 4.6933255135565751144e-07 -0.012893387334331114086" rpy="0 0 0"/>      
      <mass value="0.0025088292483592140175"/>      
      <inertia ixx="2.6944521128608337892e-07" ixy="7.1389570387314549512e-15" ixz="1.3562243131326297886e-11" iyy="2.6944520001664893476e-07" iyz="-1.0089988374153191392e-11" izz="1.7809843599861015564e-08"/>      
    </inertial>    
  </link>  

  <joint name="right_ank_act1" type="prismatic">    
    <origin xyz="2.2722093427785666764e-06 1.2698175844150227931e-15 -0.072674150483189009497" rpy="-3.1415926535897811256 9.814572829871540247e-15 -2.2021168238260906413"/>    
    <parent link="12lf"/>    
    <child link="12lf_rod"/>    
    <axis xyz="0 0 1"/>    
    <limit effort="1" velocity="20" lower="0" upper="0.040000000000000000833"/>    
    <joint_properties friction="0.0"/>    
  </joint>  

  <joint name="right_ank_B31" type="revolute">    
    <origin xyz="-1.3010426069826053208e-18 -0.0064387505004002698605 6.9388939039072283776e-18" rpy="-1.570796326794896558 0.16913440034154619829 2.2885625266571218396e-16"/>    
    <parent link="ball_joint_ball"/>    
    <child link="12lf"/>    
    <axis xyz="0 0 1"/>    
    <limit effort="1" velocity="20" lower="-0.785398163397448279" upper="0.785398163397448279"/>    
    <joint_properties friction="0.0"/>    
  </joint>  

  <joint name="right_ank_B21" type="revolute">    
    <origin xyz="-2.0816681711721685133e-17 1.1102230246251565404e-16 -0.011499999999999998071" rpy="1.570796326794896558 -1.4274562579810237128 1.5707963267948950037"/>    
    <parent link="ball_joint_container"/>    
    <child link="ball_joint_ball"/>    
    <axis xyz="0 0 1"/>    
    <limit effort="1" velocity="20" lower="-0.785398163397448279" upper="0.785398163397448279"/>    
    <joint_properties friction="0.0"/>    
  </joint>  

  <joint name="right_ank_B11" type="revolute">    
    <origin xyz="0.007999999999999972411 0.014999999999999957812 -0.011500000000000010214" rpy="1.5707963267948978903 -1.4686162729650020786 -1.5707963267948970021"/>    
    <parent link="right_calf_link"/>    
    <child link="ball_joint_container"/>    
    <axis xyz="0 0 1"/>    
    <limit effort="1" velocity="20" lower="-0.785398163397448279" upper="0.785398163397448279"/>    
    <joint_properties friction="0.0"/>    
  </joint>  

  <link name="ball_joint_container_2">    
    <visual>      
      <origin xyz="0 0 0" rpy="0 -0 0"/>      
      <geometry>        
        <mesh filename="package:///meshes/right_ball_joint_container_2_visual.stl"/>        
      </geometry>      
      <material name="ball_joint_container_2_material">        
        <color rgba="0.61568627450980395466 0.81176470588235294379 0.92941176470588238168 1.0"/>        
      </material>      
    </visual>    
    <collision>      
      <origin xyz="0 0 0" rpy="0 -0 0"/>      
      <geometry>        
        <mesh filename="package:///meshes/right_ball_joint_container_2_collision.stl"/>        
      </geometry>      
    </collision>    
    <inertial>      
      <origin xyz="-6.4666794741501532909e-18 -2.7877151006475826086e-17 -0.0097125341669083431473" rpy="0 0 0"/>      
      <mass value="4.803735642533054869e-05"/>      
      <inertia ixx="7.1865480628741707725e-10" ixy="-7.6356461259815175018e-27" ixz="-5.5405074936934095688e-39" iyy="8.475420427718555978e-10" iyz="-1.6847421608208367339e-39" izz="1.8625314111651911712e-10"/>      
    </inertial>    
  </link>  

  <link name="ball_joint_ball_2">    
    <visual>      
      <origin xyz="0 0 0" rpy="0 -0 0"/>      
      <geometry>        
        <mesh filename="package:///meshes/right_ball_joint_ball_2_visual.stl"/>        
      </geometry>      
      <material name="ball_joint_ball_2_material">        
        <color rgba="0.3291302810242056065 0.44310466418644928188 0.69204871161977121741 1.0"/>        
      </material>      
    </visual>    
    <collision>      
      <origin xyz="0 0 0" rpy="0 -0 0"/>      
      <geometry>        
        <mesh filename="package:///meshes/right_ball_joint_ball_2_collision.stl"/>        
      </geometry>      
    </collision>    
    <inertial>      
      <origin xyz="-3.1503615901221646949e-18 -0.0010308669810016504297 2.1306171358979874201e-18" rpy="0 0 0"/>      
      <mass value="4.4053796295264630609e-05"/>      
      <inertia ixx="3.1285011349692535844e-10" ixy="5.5990895141001096842e-26" ixz="-2.8128653674633218659e-27" iyy="6.2569568612795579277e-11" iyz="-1.4031925621215802366e-26" izz="3.1285321460376441998e-10"/>      
    </inertial>    
  </link>  

  <link name="12lf_2">    
    <visual>      
      <origin xyz="0 0 0" rpy="0 -0 0"/>      
      <geometry>        
        <mesh filename="package:///meshes/right_12lf_2_visual.stl"/>        
      </geometry>      
      <material name="12lf_2_material">        
        <color rgba="0.62004392100736027693 0.58836684613512624242 0.49897069021535683797 1.0"/>        
      </material>      
    </visual>    
    <collision>      
      <origin xyz="0 0 0" rpy="0 -0 0"/>      
      <geometry>        
        <mesh filename="package:///meshes/right_12lf_2_collision.stl"/>        
      </geometry>      
    </collision>    
    <inertial>      
      <origin xyz="0.0049084207243654436395 -0.00013802439943709924664 -0.029947003577146625447" rpy="0 0 0"/>      
      <mass value="0.044782197696050358993"/>      
      <inertia ixx="1.5260128421312164979e-05" ixy="2.2955773686777500915e-08" ixz="-8.136420400830112012e-08" iyy="1.8188469778949572917e-05" iyz="-5.5542240843715674128e-08" izz="5.1496273901724036478e-06"/>      
    </inertial>    
  </link>  

  <link name="12lf_rod_2">    
    <visual>      
      <origin xyz="0 0 0" rpy="0 -0 0"/>      
      <geometry>        
        <mesh filename="package:///meshes/right_12lf_rod_2_visual.stl"/>        
      </geometry>      
      <material name="12lf_rod_2_material">        
        <color rgba="0.80250260812861884396 0.89340612183512713163 0.94491811293548189088 1.0"/>        
      </material>      
    </visual>    
    <collision>      
      <origin xyz="0 0 0" rpy="0 -0 0"/>      
      <geometry>        
        <mesh filename="package:///meshes/right_12lf_rod_2_collision.stl"/>        
      </geometry>      
    </collision>    
    <inertial>      
      <origin xyz="-6.3222084132226656172e-07 4.6933255081341041789e-07 -0.012893387334332461966" rpy="0 0 0"/>      
      <mass value="0.0025088292483592140175"/>      
      <inertia ixx="2.6944521128601032232e-07" ixy="7.1389570449845313104e-15" ixz="1.3562243158147916823e-11" iyy="2.6944520001657577229e-07" iyz="-1.0089988358384868711e-11" izz="1.7809843599861015564e-08"/>      
    </inertial>    
  </link>  

  <joint name="right_ank_act2" type="prismatic">    
    <origin xyz="2.2722093417776312307e-06 -2.3800406090401793335e-15 -0.072674285805652133474" rpy="3.141592653589793116 -4.1997988128928857096e-16 -2.2021168238262838202"/>    
    <parent link="12lf_2"/>    
    <child link="12lf_rod_2"/>    
    <axis xyz="0 0 1"/>    
    <limit effort="1" velocity="20" lower="0" upper="0.040000000000000000833"/>    
    <joint_properties friction="0.0"/>    
  </joint>  

  <joint name="right_ank_B32" type="revolute">    
    <origin xyz="-1.5178830414797062076e-17 -0.006438750500400436394 1.3877787807814456755e-17" rpy="-1.5707963267948854558 -0.17993145005756266963 -2.2505490007573420062e-15"/>    
    <parent link="ball_joint_ball_2"/>    
    <child link="12lf_2"/>    
    <axis xyz="0 0 1"/>    
    <limit effort="1" velocity="20" lower="-0.785398163397448279" upper="0.785398163397448279"/>    
    <joint_properties friction="0.0"/>    
  </joint>  

  <joint name="right_ank_B22" type="revolute">    
    <origin xyz="-1.3877787807814456755e-17 -8.3266726846886740532e-17 -0.011499999999999991132" rpy="1.57079632679489678 -1.4274330297239778975 1.5707963267949012209"/>    
    <parent link="ball_joint_container_2"/>    
    <child link="ball_joint_ball_2"/>    
    <axis xyz="0 0 1"/>    
    <limit effort="1" velocity="20" lower="-0.785398163397448279" upper="0.785398163397448279"/>    
    <joint_properties friction="0.0"/>    
  </joint>  

  <joint name="right_ank_B12" type="revolute">    
    <origin xyz="0.0079999999999997000594 0.015000000000000290878 0.02830000000000029714" rpy="-1.5707963267948978903 -1.468735614201923223 1.5707963267949029973"/>    
    <parent link="right_calf_link"/>    
    <child link="ball_joint_container_2"/>    
    <axis xyz="0 0 1"/>    
    <limit effort="1" velocity="20" lower="-0.785398163397448279" upper="0.785398163397448279"/>    
    <joint_properties friction="0.0"/>    
  </joint>  

  <joint name="right_knee" type="revolute">    
    <origin xyz="-2.4109230505694711738e-15 0.095999999999999821587 0.027399999999999948702" rpy="3.141592653589793116 -1.6870185802395130185e-16 3.1415926535897922278"/>    
    <parent link="right_hip_pitch_link"/>    
    <child link="right_calf_link"/>    
    <axis xyz="0 0 1"/>    
    <limit effort="1" velocity="20" lower="-1.570796326794896558" upper="1.570796326794896558"/>    
    <joint_properties friction="0.0"/>    
  </joint>  

  <joint name="right_hip_pitch" type="revolute">    
    <origin xyz="-0.024000000716145986762 -0.019000000152457990205 -0.019000000152453774827" rpy="-1.5707963267951818853 1.5707963267947633312 0"/>    
    <parent link="hip_roll_link"/>    
    <child link="right_hip_pitch_link"/>    
    <axis xyz="0 0 1"/>    
    <limit effort="1" velocity="20" lower="-1.570796326794896558" upper="1.570796326794896558"/>    
    <joint_properties friction="0.0"/>    
  </joint>  

  <joint name="right_hip_roll" type="revolute">    
    <origin xyz="-0.018999999999999885036 -3.3499987806511678644e-18 -0.026000000000000002276" rpy="-1.5707963266839728433 -1.5707907166912637997 1.5707963266641831179"/>    
    <parent link="hip_yaw_link"/>    
    <child link="hip_roll_link"/>    
    <axis xyz="0 0 1"/>    
    <limit effort="1" velocity="20" lower="-1.570796326794896558" upper="1.570796326794896558"/>    
    <joint_properties friction="0.0"/>    
  </joint>  


</robot>