<?xml version="1.0" ?><robot name="right_3R+RH5_leg">  
  <link name="hip_yaw_link">    
    <visual>      
      <origin xyz="0 0 0" rpy="0 -0 0"/>      
      <geometry>        
        <mesh filename="package:///meshes/right_hip_yaw_link_visual.stl"/>        
      </geometry>      
      <material name="hip_yaw_link_material">        
        <color rgba="0.61568627450980395466 0.81176470588235294379 0.9294117647058824927 1.0"/>        
      </material>      
    </visual>    
    <collision>      
      <origin xyz="0 0 0" rpy="0 -0 0"/>      
      <geometry>        
        <mesh filename="package:///meshes/right_hip_yaw_link_collision.stl"/>        
      </geometry>      
    </collision>    
    <inertial>      
      <origin xyz="-1.4892375470891750296e-20 3.9665442301965273257e-19 -0.0098390489054829104176" rpy="0 0 0"/>      
      <mass value="0.0090258837370979193293"/>      
      <inertia ixx="1.3230458239085876461e-06" ixy="-6.4778545919079861077e-49" ixz="1.7322911775161985632e-33" iyy="3.8408510960330541809e-06" iyz="-1.4482241779965781819e-32" izz="3.8721396285793077728e-06"/>      
    </inertial>    
  </link>  

  <link name="hip_roll_link">    
    <visual>      
      <origin xyz="0 0 0" rpy="0 -0 0"/>      
      <geometry>        
        <mesh filename="package:///meshes/right_hip_roll_link_visual.stl"/>        
      </geometry>      
      <material name="hip_roll_link_material">        
        <color rgba="0.95018735644455853961 0.70678927200428420807 0.061612079402596685307 1.0"/>        
      </material>      
    </visual>    
    <collision>      
      <origin xyz="0 0 0" rpy="0 -0 0"/>      
      <geometry>        
        <mesh filename="package:///meshes/right_hip_roll_link_collision.stl"/>        
      </geometry>      
    </collision>    
    <inertial>      
      <origin xyz="-0.012000151133961673919 -0.00049588831385562702741 -0.018504019244505478387" rpy="0 0 0"/>      
      <mass value="0.09801239148352869357"/>      
      <inertia ixx="2.0221748766307252681e-05" ixy="-4.155206824515866063e-08" ixz="-4.1225592187110660342e-08" iyy="2.7358099958307355976e-05" iyz="-5.0935731752394092288e-07" izz="2.7358069524724032586e-05"/>      
    </inertial>    
  </link>  

  <link name="right_hip_pitch_link">    
    <visual>      
      <origin xyz="0 0 0" rpy="0 -0 0"/>      
      <geometry>        
        <mesh filename="package:///meshes/right_hip_pitch_link_visual.stl"/>        
      </geometry>      
      <material name="right_hip_pitch_link_material">        
        <color rgba="0.61653630606835563288 0.80730204019995621678 0.92176148067891638949 1.0"/>        
      </material>      
    </visual>    
    <collision>      
      <origin xyz="0 0 0" rpy="0 -0 0"/>      
      <geometry>        
        <mesh filename="package:///meshes/right_hip_pitch_link_collision.stl"/>        
      </geometry>      
    </collision>    
    <inertial>      
      <origin xyz="-1.4741268609435853249e-05 0.052986690876698258612 0.014788127171305258042" rpy="0 0 0"/>      
      <mass value="0.094084567879581970651"/>      
      <inertia ixx="6.3099182122443740121e-05" ixy="-2.2045192591945184249e-07" ixz="-1.2728889936301160993e-08" iyy="2.1759163818498411774e-05" iyz="-1.4708395298813209395e-06" izz="6.2821853547821466125e-05"/>      
    </inertial>    
  </link>  

  <link name="right_calf_link">    
    <visual>      
      <origin xyz="0 0 0" rpy="0 -0 0"/>      
      <geometry>        
        <mesh filename="package:///meshes/right_calf_link_visual.stl"/>        
      </geometry>      
      <material name="right_calf_link_material">        
        <color rgba="0.5539724769354649192 0.73161364570947462482 0.87715709724734280961 1.0"/>        
      </material>      
    </visual>    
    <collision>      
      <origin xyz="0 0 0" rpy="0 -0 0"/>      
      <geometry>        
        <mesh filename="package:///meshes/right_calf_link_collision.stl"/>        
      </geometry>      
    </collision>    
    <inertial>      
      <origin xyz="-0.0039136048281023325807 0.043639997035758611166 0.00818489966080624895" rpy="0 0 0"/>      
      <mass value="0.016290630569901022595"/>      
      <inertia ixx="1.5543964735761969917e-05" ixy="2.1605989306077937793e-07" ixz="7.0519548983021784406e-09" iyy="1.9364566813417001793e-06" iyz="-1.9645570089566446317e-08" izz="1.4807205615850120399e-05"/>      
    </inertial>    
  </link>  

  <link name="ank_pitch_link">    
    <visual>      
      <origin xyz="0 0 0" rpy="0 -0 0"/>      
      <geometry>        
        <mesh filename="package:///meshes/right_ank_pitch_link_visual.stl"/>        
      </geometry>      
      <material name="ank_pitch_link_material">        
        <color rgba="0.63189161126160275916 0.72668668793540891482 0.78356373393969258601 1.0"/>        
      </material>      
    </visual>    
    <collision>      
      <origin xyz="0 0 0" rpy="0 -0 0"/>      
      <geometry>        
        <mesh filename="package:///meshes/right_ank_pitch_link_collision.stl"/>        
      </geometry>      
    </collision>    
    <inertial>      
      <origin xyz="4.0269688365285938752e-08 0.0005952828256655856359 -0.014599922383890164002" rpy="0 0 0"/>      
      <mass value="0.0042238381753791605713"/>      
      <inertia ixx="4.3705254067389275737e-07" ixy="1.6834346808786572501e-13" ixz="1.6428822803056156771e-12" iyy="3.9782741364654728503e-07" iyz="2.0919225290482801595e-14" izz="8.8858574534512311271e-08"/>      
    </inertial>    
  </link>  

  <link name="ank_roll_link">    
    <visual>      
      <origin xyz="0 0 0" rpy="0 -0 0"/>      
      <geometry>        
        <mesh filename="package:///meshes/right_ank_roll_link_visual.stl"/>        
      </geometry>      
      <material name="ank_roll_link_material">        
        <color rgba="0.61568627450980395466 0.81176470588235305481 0.92941176470588227065 1.0"/>        
      </material>      
    </visual>    
    <collision>      
      <origin xyz="0 0 0" rpy="0 -0 0"/>      
      <geometry>        
        <mesh filename="package:///meshes/right_ank_roll_link_collision.stl"/>        
      </geometry>      
    </collision>    
    <inertial>      
      <origin xyz="-6.3661537441910651493e-10 0.027240102316353733553 -0.0056169852551464652737" rpy="0 0 0"/>      
      <mass value="0.013844478784760251913"/>      
      <inertia ixx="1.0150902309234939295e-05" ixy="6.8603302692161481473e-14" ixz="-3.2605547317950551556e-13" iyy="8.66361166634314672e-06" iyz="-7.8151778926544996072e-07" izz="2.8991570356470427702e-06"/>      
    </inertial>    
  </link>  

  <link name="ank_rr_link">    
    <visual>      
      <origin xyz="0 0 0" rpy="0 -0 0"/>      
      <geometry>        
        <mesh filename="package:///meshes/right_ank_rr_link_visual.stl"/>        
      </geometry>      
      <material name="ank_rr_link_material">        
        <color rgba="0.61568627450980395466 0.81176470588235294379 0.92941176470588238168 1.0"/>        
      </material>      
    </visual>    
    <collision>      
      <origin xyz="0 0 0" rpy="0 -0 0"/>      
      <geometry>        
        <mesh filename="package:///meshes/right_ank_rr_link_collision.stl"/>        
      </geometry>      
    </collision>    
    <inertial>      
      <origin xyz="3.4593503690053681245e-05 -0.0062999445222072123982 2.2902669769463616335e-19" rpy="0 0 0"/>      
      <mass value="0.00044289790445047673732"/>      
      <inertia ixx="9.0894755004835240223e-09" ixy="5.6689994077039850802e-11" ixz="-1.0879024115036757634e-14" iyy="8.3785129146959872498e-09" iyz="1.0964401565805926173e-31" izz="1.3107013728801488166e-08"/>      
    </inertial>    
  </link>  

  <link name="12lf_rod_end">    
    <visual>      
      <origin xyz="0 0 0" rpy="0 -0 0"/>      
      <geometry>        
        <mesh filename="package:///meshes/right_12lf_rod_end_visual.stl"/>        
      </geometry>      
      <material name="12lf_rod_end_material">        
        <color rgba="0.92771758928836534075 0.61049283053223002415 0.2184765849058516729 1.0"/>        
      </material>      
    </visual>    
    <collision>      
      <origin xyz="0 0 0" rpy="0 -0 0"/>      
      <geometry>        
        <mesh filename="package:///meshes/right_12lf_rod_end_collision.stl"/>        
      </geometry>      
    </collision>    
    <inertial>      
      <origin xyz="-4.4735193393311788837e-11 -0.0038422185938245738239 6.4384187209394376638e-06" rpy="0 0 0"/>      
      <mass value="0.00085420491177815905965"/>      
      <inertia ixx="1.1840985264406848605e-08" ixy="2.0225976206036175351e-16" ixz="-9.2606418917665753036e-16" iyy="3.3549621576797288816e-09" iyz="7.4535631381921884042e-12" izz="1.2703522254419973308e-08"/>      
    </inertial>    
  </link>  

  <joint name="right_ank_R21" type="revolute">    
    <origin xyz="1.3877787807814456755e-17 -0.010000000000000008882 1.3877787807814456755e-17" rpy="-1.570796326794896558 -1.4285697747627732479 1.5707963267950297848"/>    
    <parent link="ank_rr_link"/>    
    <child link="12lf_rod_end"/>    
    <axis xyz="0 0 1"/>    
    <limit effort="1" velocity="20" lower="-1.570796326794896558" upper="1.570796326794896558"/>    
    <joint_properties friction="0.0"/>    
  </joint>  

  <joint name="right_ank_R11" type="revolute">    
    <origin xyz="-0.0099999999999999707179 0.012500000000000066613 -0.033600000000000039557" rpy="2.8867109174417181635e-14 -3.1302655555270997905e-14 -0.10116031275652562216"/>    
    <parent link="ank_roll_link"/>    
    <child link="ank_rr_link"/>    
    <axis xyz="0 0 1"/>    
    <limit effort="1" velocity="20" lower="-1.570796326794896558" upper="1.570796326794896558"/>    
    <joint_properties friction="0.0"/>    
  </joint>  

  <link name="ank_rr_link_2">    
    <visual>      
      <origin xyz="0 0 0" rpy="0 -0 0"/>      
      <geometry>        
        <mesh filename="package:///meshes/right_ank_rr_link_2_visual.stl"/>        
      </geometry>      
      <material name="ank_rr_link_2_material">        
        <color rgba="0.61568627450980395466 0.81176470588235294379 0.92941176470588238168 1.0"/>        
      </material>      
    </visual>    
    <collision>      
      <origin xyz="0 0 0" rpy="0 -0 0"/>      
      <geometry>        
        <mesh filename="package:///meshes/right_ank_rr_link_2_collision.stl"/>        
      </geometry>      
    </collision>    
    <inertial>      
      <origin xyz="3.4593503690060660796e-05 -0.0062999445222072687767 2.2902669769472090426e-19" rpy="0 0 0"/>      
      <mass value="0.00044289790445047673732"/>      
      <inertia ixx="9.0894755004835240223e-09" ixy="5.6689994077039883114e-11" ixz="-1.0879024115036757634e-14" iyy="8.3785129146959905585e-09" iyz="8.7823246935337172874e-33" izz="1.3107013728801488166e-08"/>      
    </inertial>    
  </link>  

  <link name="12lf_rod_end_2">    
    <visual>      
      <origin xyz="0 0 0" rpy="0 -0 0"/>      
      <geometry>        
        <mesh filename="package:///meshes/right_12lf_rod_end_2_visual.stl"/>        
      </geometry>      
      <material name="12lf_rod_end_2_material">        
        <color rgba="0.92771758928836534075 0.61049283053223013518 0.2184765849058516729 1.0"/>        
      </material>      
    </visual>    
    <collision>      
      <origin xyz="0 0 0" rpy="0 -0 0"/>      
      <geometry>        
        <mesh filename="package:///meshes/right_12lf_rod_end_2_collision.stl"/>        
      </geometry>      
    </collision>    
    <inertial>      
      <origin xyz="-4.4735207267392748295e-11 -0.0038422185938245798954 6.4384187209450179169e-06" rpy="0 0 0"/>      
      <mass value="0.00085420491177815905965"/>      
      <inertia ixx="1.1840985264406812209e-08" ixy="2.0225978204782157323e-16" ixz="-9.2606419936537711735e-16" iyy="3.3549621576797268136e-09" iyz="7.4535631381815061421e-12" izz="1.2703522254420024593e-08"/>      
    </inertial>    
  </link>  

  <joint name="right_ank_R22" type="revolute">    
    <origin xyz="-1.3877787807814456755e-17 -0.010000000000000008882 2.7755575615628913511e-17" rpy="1.570796326794921649 -1.4285463212679851974 -1.5707963267949038855"/>    
    <parent link="ank_rr_link_2"/>    
    <child link="12lf_rod_end_2"/>    
    <axis xyz="0 0 1"/>    
    <limit effort="1" velocity="20" lower="-1.570796326794896558" upper="1.570796326794896558"/>    
    <joint_properties friction="0.0"/>    
  </joint>  

  <joint name="right_ank_R12" type="revolute">    
    <origin xyz="0.010000000000000003678 0.012500000000000011102 -0.033600000000000004863" rpy="-3.1415926535897917837 -1.5904604637588844751e-15 -3.0405529889774984831"/>    
    <parent link="ank_roll_link"/>    
    <child link="ank_rr_link_2"/>    
    <axis xyz="0 0 1"/>    
    <limit effort="1" velocity="20" lower="-1.570796326794896558" upper="1.570796326794896558"/>    
    <joint_properties friction="0.0"/>    
  </joint>  

  <joint name="right_ank_roll" type="revolute">    
    <origin xyz="1.1018963519404678664e-14 0.0015000000000008478773 -0.014599999999995005862" rpy="-1.5707963267950115771 1.5707963267945974639 0"/>    
    <parent link="ank_pitch_link"/>    
    <child link="ank_roll_link"/>    
    <axis xyz="0 0 1"/>    
    <limit effort="1" velocity="20" lower="-1.570796326794896558" upper="1.570796326794896558"/>    
    <joint_properties friction="0.0"/>    
  </joint>  

  <joint name="right_ank_pitch" type="revolute">    
    <origin xyz="-7.3090839045994630973e-18 0.099999999999999839018 -0.006199999999999821973" rpy="-3.1415926535897926719 3.8309199562601306947e-15 -1.57079632679489678"/>    
    <parent link="right_calf_link"/>    
    <child link="ank_pitch_link"/>    
    <axis xyz="0 0 1"/>    
    <limit effort="1" velocity="20" lower="-1.570796326794896558" upper="1.570796326794896558"/>    
    <joint_properties friction="0.0"/>    
  </joint>  

  <link name="ball_joint_container">    
    <visual>      
      <origin xyz="0 0 0" rpy="0 -0 0"/>      
      <geometry>        
        <mesh filename="package:///meshes/right_ball_joint_container_visual.stl"/>        
      </geometry>      
      <material name="ball_joint_container_material">        
        <color rgba="0.61568627450980395466 0.81176470588235294379 0.92941176470588238168 1.0"/>        
      </material>      
    </visual>    
    <collision>      
      <origin xyz="0 0 0" rpy="0 -0 0"/>      
      <geometry>        
        <mesh filename="package:///meshes/right_ball_joint_container_collision.stl"/>        
      </geometry>      
    </collision>    
    <inertial>      
      <origin xyz="4.7221442975712082762e-19 -1.2157539084691763054e-19 -0.0097125341669083396778" rpy="0 0 0"/>      
      <mass value="4.803735642533054869e-05"/>      
      <inertia ixx="7.1865480628741666366e-10" ixy="-4.6616368691501084609e-27" ixz="-1.1843682288965544046e-38" iyy="8.475420427718555978e-10" iyz="-9.2441920556660340881e-41" izz="1.8625314111651911712e-10"/>      
    </inertial>    
  </link>  

  <link name="ball_joint_ball">    
    <visual>      
      <origin xyz="0 0 0" rpy="0 -0 0"/>      
      <geometry>        
        <mesh filename="package:///meshes/right_ball_joint_ball_visual.stl"/>        
      </geometry>      
      <material name="ball_joint_ball_material">        
        <color rgba="0.3291302810242056065 0.44310466418644928188 0.69204871161977121741 1.0"/>        
      </material>      
    </visual>    
    <collision>      
      <origin xyz="0 0 0" rpy="0 -0 0"/>      
      <geometry>        
        <mesh filename="package:///meshes/right_ball_joint_ball_collision.stl"/>        
      </geometry>      
    </collision>    
    <inertial>      
      <origin xyz="-2.2282791851418327992e-18 -0.0010308669810016471771 -9.6201283872577752272e-18" rpy="0 0 0"/>      
      <mass value="4.4053796295264630609e-05"/>      
      <inertia ixx="3.1285011349692509995e-10" ixy="-1.7111341847049918391e-25" ixz="-4.0779831720173709577e-26" iyy="6.2569568612796160888e-11" iyz="2.8914593605368720733e-25" izz="3.1285321460375878481e-10"/>      
    </inertial>    
  </link>  

  <link name="12lf">    
    <visual>      
      <origin xyz="0 0 0" rpy="0 -0 0"/>      
      <geometry>        
        <mesh filename="package:///meshes/right_12lf_visual.stl"/>        
      </geometry>      
      <material name="12lf_material">        
        <color rgba="0.62004392100736016591 0.58836684613512635345 0.49897069021535672695 1.0"/>        
      </material>      
    </visual>    
    <collision>      
      <origin xyz="0 0 0" rpy="0 -0 0"/>      
      <geometry>        
        <mesh filename="package:///meshes/right_12lf_collision.stl"/>        
      </geometry>      
    </collision>    
    <inertial>      
      <origin xyz="0.004908420724367137597 -0.00013802439943486763331 -0.029947003577148190168" rpy="0 0 0"/>      
      <mass value="0.044782197696050352054"/>      
      <inertia ixx="1.5260128421313300004e-05" ixy="2.295577368647527228e-08" ixz="-8.1364204007548279884e-08" iyy="1.8188469778952544309e-05" iyz="-5.554224084273306297e-08" izz="5.14962739017425865e-06"/>      
    </inertial>    
  </link>  

  <link name="12lf_rod">    
    <visual>      
      <origin xyz="0 0 0" rpy="0 -0 0"/>      
      <geometry>        
        <mesh filename="package:///meshes/right_12lf_rod_visual.stl"/>        
      </geometry>      
      <material name="12lf_rod_material">        
        <color rgba="0.80250260812861884396 0.89340612183512713163 0.94491811293548189088 1.0"/>        
      </material>      
    </visual>    
    <collision>      
      <origin xyz="0 0 0" rpy="0 -0 0"/>      
      <geometry>        
        <mesh filename="package:///meshes/right_12lf_rod_collision.stl"/>        
      </geometry>      
    </collision>    
    <inertial>      
      <origin xyz="-6.322208404502051673e-07 4.6933255154484173787e-07 -0.01289338733433067867" rpy="0 0 0"/>      
      <mass value="0.0025088292483592140175"/>      
      <inertia ixx="2.6944521128611074867e-07" ixy="7.1389570414601342887e-15" ixz="1.3562243134960218639e-11" iyy="2.6944520001667630451e-07" iyz="-1.0089988379320780934e-11" izz="1.7809843599861015564e-08"/>      
    </inertial>    
  </link>  

  <joint name="right_ank_act1" type="prismatic">    
    <origin xyz="2.2722093427438722069e-06 1.6375789613221058971e-15 -0.072660031604109970305" rpy="-3.1415926535897806815 7.845419351877858644e-15 -2.2021168238260604433"/>    
    <parent link="12lf"/>    
    <child link="12lf_rod"/>    
    <axis xyz="0 0 1"/>    
    <limit effort="1" velocity="20" lower="0" upper="0.040000000000000000833"/>    
    <joint_properties friction="0.0"/>    
  </joint>  

  <joint name="right_ank_B31" type="revolute">    
    <origin xyz="-7.3725747729014301513e-18 -0.006438750500400436394 -1.3877787807814456755e-17" rpy="-1.5707963267948954478 0.16913440034160504011 5.0191724325132069355e-15"/>    
    <parent link="ball_joint_ball"/>    
    <child link="12lf"/>    
    <axis xyz="0 0 1"/>    
    <limit effort="1" velocity="20" lower="-0.785398163397448279" upper="0.785398163397448279"/>    
    <joint_properties friction="0.0"/>    
  </joint>  

  <joint name="right_ank_B21" type="revolute">    
    <origin xyz="0 5.5511151231257827021e-17 -0.011499999999999998071" rpy="1.570796326794896558 -1.4285697747625634157 1.5707963267948530373"/>    
    <parent link="ball_joint_container"/>    
    <child link="ball_joint_ball"/>    
    <axis xyz="0 0 1"/>    
    <limit effort="1" velocity="20" lower="-0.785398163397448279" upper="0.785398163397448279"/>    
    <joint_properties friction="0.0"/>    
  </joint>  

  <joint name="right_ank_B11" type="revolute">    
    <origin xyz="0.0079999999999999689415 0.015000000000000124345 -0.011500000000000058786" rpy="1.5707963267948932273 -1.4696360140379622905 -1.5707963267948383823"/>    
    <parent link="right_calf_link"/>    
    <child link="ball_joint_container"/>    
    <axis xyz="0 0 1"/>    
    <limit effort="1" velocity="20" lower="-0.785398163397448279" upper="0.785398163397448279"/>    
    <joint_properties friction="0.0"/>    
  </joint>  

  <link name="ball_joint_container_2">    
    <visual>      
      <origin xyz="0 0 0" rpy="0 -0 0"/>      
      <geometry>        
        <mesh filename="package:///meshes/right_ball_joint_container_2_visual.stl"/>        
      </geometry>      
      <material name="ball_joint_container_2_material">        
        <color rgba="0.61568627450980395466 0.81176470588235294379 0.92941176470588238168 1.0"/>        
      </material>      
    </visual>    
    <collision>      
      <origin xyz="0 0 0" rpy="0 -0 0"/>      
      <geometry>        
        <mesh filename="package:///meshes/right_ball_joint_container_2_collision.stl"/>        
      </geometry>      
    </collision>    
    <inertial>      
      <origin xyz="7.411108333664368946e-18 -1.2157539084692088054e-19 -0.0097125341669083414126" rpy="0 0 0"/>      
      <mass value="4.803735642533054869e-05"/>      
      <inertia ixx="7.1865480628741666366e-10" ixy="1.5305926664110400689e-26" ixz="-2.1269215237649641381e-38" iyy="8.475420427718555978e-10" iyz="-4.9412888723893671296e-40" izz="1.8625314111651911712e-10"/>      
    </inertial>    
  </link>  

  <link name="ball_joint_ball_2">    
    <visual>      
      <origin xyz="0 0 0" rpy="0 -0 0"/>      
      <geometry>        
        <mesh filename="package:///meshes/right_ball_joint_ball_2_visual.stl"/>        
      </geometry>      
      <material name="ball_joint_ball_2_material">        
        <color rgba="0.3291302810242056065 0.44310466418644928188 0.69204871161977121741 1.0"/>        
      </material>      
    </visual>    
    <collision>      
      <origin xyz="0 0 0" rpy="0 -0 0"/>      
      <geometry>        
        <mesh filename="package:///meshes/right_ball_joint_ball_2_collision.stl"/>        
      </geometry>      
    </collision>    
    <inertial>      
      <origin xyz="-1.1745444478152376815e-17 -0.0010308669810016662591 -9.0457845496231557146e-18" rpy="0 0 0"/>      
      <mass value="4.4053796295264630609e-05"/>      
      <inertia ixx="3.1285011349692649581e-10" ixy="-1.3889939894657838189e-25" ixz="-8.9287567351173089104e-26" iyy="6.2569568612796328909e-11" iyz="4.0147766172360753583e-25" izz="3.1285321460377295028e-10"/>      
    </inertial>    
  </link>  

  <link name="12lf_2">    
    <visual>      
      <origin xyz="0 0 0" rpy="0 -0 0"/>      
      <geometry>        
        <mesh filename="package:///meshes/right_12lf_2_visual.stl"/>        
      </geometry>      
      <material name="12lf_2_material">        
        <color rgba="0.62004392100736027693 0.58836684613512624242 0.49897069021535683797 1.0"/>        
      </material>      
    </visual>    
    <collision>      
      <origin xyz="0 0 0" rpy="0 -0 0"/>      
      <geometry>        
        <mesh filename="package:///meshes/right_12lf_2_collision.stl"/>        
      </geometry>      
    </collision>    
    <inertial>      
      <origin xyz="0.0049084207243654427721 -0.00013802439943709469299 -0.029947003577146556058" rpy="0 0 0"/>      
      <mass value="0.044782197696050358993"/>      
      <inertia ixx="1.5260128421312144651e-05" ixy="2.2955773686778020384e-08" ixz="-8.1364204008304137675e-08" iyy="1.81884697789495492e-05" iyz="-5.5542240843715157968e-08" izz="5.1496273901724053419e-06"/>      
    </inertial>    
  </link>  

  <link name="12lf_rod_2">    
    <visual>      
      <origin xyz="0 0 0" rpy="0 -0 0"/>      
      <geometry>        
        <mesh filename="package:///meshes/right_12lf_rod_2_visual.stl"/>        
      </geometry>      
      <material name="12lf_rod_2_material">        
        <color rgba="0.80250260812861884396 0.89340612183512713163 0.94491811293548189088 1.0"/>        
      </material>      
    </visual>    
    <collision>      
      <origin xyz="0 0 0" rpy="0 -0 0"/>      
      <geometry>        
        <mesh filename="package:///meshes/right_12lf_rod_2_collision.stl"/>        
      </geometry>      
    </collision>    
    <inertial>      
      <origin xyz="-6.3222084132303291478e-07 4.6933255080542819115e-07 -0.012893387334332477578" rpy="0 0 0"/>      
      <mass value="0.0025088292483592140175"/>      
      <inertia ixx="2.6944521128601101054e-07" ixy="7.1389570533233858797e-15" ixz="1.3562243158167733614e-11" iyy="2.694452000165764605e-07" iyz="-1.0089988358254545759e-11" izz="1.7809843599861035416e-08"/>      
    </inertial>    
  </link>  

  <joint name="right_ank_act2" type="prismatic">    
    <origin xyz="2.2722093418418159994e-06 -2.3939183968479937903e-15 -0.072660030478818443678" rpy="-3.1415926535897926719 -5.822843740105227622e-15 -2.202116823826253178"/>    
    <parent link="12lf_2"/>    
    <child link="12lf_rod_2"/>    
    <axis xyz="0 0 1"/>    
    <limit effort="1" velocity="20" lower="0" upper="0.040000000000000000833"/>    
    <joint_properties friction="0.0"/>    
  </joint>  

  <joint name="right_ank_B32" type="revolute">    
    <origin xyz="-1.6913553890773869171e-17 -0.0064387505004003531273 -1.3877787807814456755e-17" rpy="-1.5707963267948952257 -0.17993145005754265786 3.2634092460731900895e-15"/>    
    <parent link="ball_joint_ball_2"/>    
    <child link="12lf_2"/>    
    <axis xyz="0 0 1"/>    
    <limit effort="1" velocity="20" lower="-0.785398163397448279" upper="0.785398163397448279"/>    
    <joint_properties friction="0.0"/>    
  </joint>  

  <joint name="right_ank_B22" type="revolute">    
    <origin xyz="0 0 -0.011499999999999992867" rpy="1.5707963267949405228 -1.4285463212677880218 1.5707963267949816011"/>    
    <parent link="ball_joint_container_2"/>    
    <child link="ball_joint_ball_2"/>    
    <axis xyz="0 0 1"/>    
    <limit effort="1" velocity="20" lower="-0.785398163397448279" upper="0.785398163397448279"/>    
    <joint_properties friction="0.0"/>    
  </joint>  

  <joint name="right_ank_B12" type="revolute">    
    <origin xyz="0.0080000000000000730249 0.015000000000000263123 0.028299999999999901623" rpy="-1.5707963267948388264 -1.4697566621826396727 1.5707963267950122432"/>    
    <parent link="right_calf_link"/>    
    <child link="ball_joint_container_2"/>    
    <axis xyz="0 0 1"/>    
    <limit effort="1" velocity="20" lower="-0.785398163397448279" upper="0.785398163397448279"/>    
    <joint_properties friction="0.0"/>    
  </joint>  

  <joint name="right_knee" type="revolute">    
    <origin xyz="-1.8318267252532356178e-15 0.095999999999998836264 0.027400000000000895861" rpy="3.1415926535897895633 -1.5829351718147190682e-16 -3.141592653589793116"/>    
    <parent link="right_hip_pitch_link"/>    
    <child link="right_calf_link"/>    
    <axis xyz="0 0 1"/>    
    <limit effort="1" velocity="20" lower="-1.570796326794896558" upper="1.570796326794896558"/>    
    <joint_properties friction="0.0"/>    
  </joint>  

  <joint name="right_hip_pitch" type="revolute">    
    <origin xyz="-0.024000000716146767388 -0.019000000152456290176 -0.019000000152450020885" rpy="-1.5707963267951789987 1.5707963267947586683 0"/>    
    <parent link="hip_roll_link"/>    
    <child link="right_hip_pitch_link"/>    
    <axis xyz="0 0 1"/>    
    <limit effort="1" velocity="20" lower="-1.570796326794896558" upper="1.570796326794896558"/>    
    <joint_properties friction="0.0"/>    
  </joint>  

  <joint name="right_hip_roll" type="revolute">    
    <origin xyz="-0.018999999999999891975 2.3744804088669454642e-18 -0.025999999999999984929" rpy="-3.3306690738820289997e-16 -1.570796326794896558 0"/>    
    <parent link="hip_yaw_link"/>    
    <child link="hip_roll_link"/>    
    <axis xyz="0 0 1"/>    
    <limit effort="1" velocity="20" lower="-1.570796326794896558" upper="1.570796326794896558"/>    
    <joint_properties friction="0.0"/>    
  </joint>  


</robot>