<?xml version="1.0" ?><robot name="right_3R+RH5_leg">  
  <link name="hip_yaw_link">    
    <visual>      
      <origin xyz="0 0 0" rpy="0 -0 0"/>      
      <geometry>        
        <mesh filename="package:///meshes/right_hip_yaw_link_visual.stl"/>        
      </geometry>      
      <material name="hip_yaw_link_material">        
        <color rgba="0.61568627450980395466 0.81176470588235294379 0.92941176470588238168 1.0"/>        
      </material>      
    </visual>    
    <collision>      
      <origin xyz="0 0 0" rpy="0 -0 0"/>      
      <geometry>        
        <mesh filename="package:///meshes/right_hip_yaw_link_collision.stl"/>        
      </geometry>      
    </collision>    
    <inertial>      
      <origin xyz="2.029820145944484075e-18 -1.8141989800133138424e-18 -0.009914364922334070393" rpy="0 0 0"/>      
      <mass value="0.0081617461226117064832"/>      
      <inertia ixx="1.1860761935507006919e-06" ixy="-5.9926186954515463348e-49" ixz="1.6107676412647338601e-33" iyy="3.5910093036262736939e-06" iyz="-1.3585997135956544879e-32" izz="3.6446570722247264632e-06"/>      
    </inertial>    
  </link>  

  <link name="hip_roll_link">    
    <visual>      
      <origin xyz="0 0 0" rpy="0 -0 0"/>      
      <geometry>        
        <mesh filename="package:///meshes/right_hip_roll_link_visual.stl"/>        
      </geometry>      
      <material name="hip_roll_link_material">        
        <color rgba="0.95018735644455853961 0.70678927200428420807 0.061612079402596685307 1.0"/>        
      </material>      
    </visual>    
    <collision>      
      <origin xyz="0 0 0" rpy="0 -0 0"/>      
      <geometry>        
        <mesh filename="package:///meshes/right_hip_roll_link_collision.stl"/>        
      </geometry>      
    </collision>    
    <inertial>      
      <origin xyz="-0.012000151133960919314 -0.00049588831385676760809 -0.018504019244507452502" rpy="0 0 0"/>      
      <mass value="0.09801239148352869357"/>      
      <inertia ixx="2.0221748766307415311e-05" ixy="-4.155206824539892682e-08" ixz="-4.1225592188036341622e-08" iyy="2.7358099958307691401e-05" iyz="-5.0935731752404849606e-07" izz="2.7358069524724229097e-05"/>      
    </inertial>    
  </link>  

  <link name="hip_pitch_link">    
    <visual>      
      <origin xyz="0 0 0" rpy="0 -0 0"/>      
      <geometry>        
        <mesh filename="package:///meshes/right_hip_pitch_link_visual.stl"/>        
      </geometry>      
      <material name="hip_pitch_link_material">        
        <color rgba="0.61668199203816720377 0.80653718885844516429 0.92045030695061180737 1.0"/>        
      </material>      
    </visual>    
    <collision>      
      <origin xyz="0 0 0" rpy="0 -0 0"/>      
      <geometry>        
        <mesh filename="package:///meshes/right_hip_pitch_link_collision.stl"/>        
      </geometry>      
    </collision>    
    <inertial>      
      <origin xyz="-0.00012587895788703117234 0.055074320814802117663 0.012617712499788359681" rpy="0 0 0"/>      
      <mass value="0.086351012001622026726"/>      
      <inertia ixx="5.834301126562820109e-05" ixy="9.4663837750190953221e-08" ixz="-5.8892469185705517857e-08" iyy="1.666623693081575934e-05" iyz="-2.2101256957834618069e-06" izz="6.1357987984517252346e-05"/>      
    </inertial>    
  </link>  

  <link name="right_calf_link">    
    <visual>      
      <origin xyz="0 0 0" rpy="0 -0 0"/>      
      <geometry>        
        <mesh filename="package:///meshes/right_calf_link_visual.stl"/>        
      </geometry>      
      <material name="right_calf_link_material">        
        <color rgba="0.55189765308040628078 0.72942392078451900872 0.87615955180834892424 1.0"/>        
      </material>      
    </visual>    
    <collision>      
      <origin xyz="0 0 0" rpy="0 -0 0"/>      
      <geometry>        
        <mesh filename="package:///meshes/right_calf_link_collision.stl"/>        
      </geometry>      
    </collision>    
    <inertial>      
      <origin xyz="-0.0029316897488380426993 0.04270450136968612781 0.0081807348117400122828" rpy="0 0 0"/>      
      <mass value="0.016572091442033146796"/>      
      <inertia ixx="1.6369868920906258e-05" ixy="7.8679773438434804564e-07" ixz="2.4338269636588603142e-09" iyy="2.340491493087400491e-06" iyz="-2.046655738869471256e-08" izz="1.5866145485360937838e-05"/>      
    </inertial>    
  </link>  

  <link name="ank_pitch_link">    
    <visual>      
      <origin xyz="0 0 0" rpy="0 -0 0"/>      
      <geometry>        
        <mesh filename="package:///meshes/right_ank_pitch_link_visual.stl"/>        
      </geometry>      
      <material name="ank_pitch_link_material">        
        <color rgba="0.63189161126160275916 0.7266866879354088038 0.78356373393969258601 1.0"/>        
      </material>      
    </visual>    
    <collision>      
      <origin xyz="0 0 0" rpy="0 -0 0"/>      
      <geometry>        
        <mesh filename="package:///meshes/right_ank_pitch_link_collision.stl"/>        
      </geometry>      
    </collision>    
    <inertial>      
      <origin xyz="4.026968609944205358e-08 0.00059528282566540685096 -0.014599922383890200431" rpy="0 0 0"/>      
      <mass value="0.0042238381753791614387"/>      
      <inertia ixx="4.3705254067386385237e-07" ixy="1.6834346759389685387e-13" ixz="1.6428822476034498086e-12" iyy="3.9782741364652086819e-07" iyz="2.0919229113711592816e-14" izz="8.8858574534509902521e-08"/>      
    </inertial>    
  </link>  

  <link name="ank_roll_link">    
    <visual>      
      <origin xyz="0 0 0" rpy="0 -0 0"/>      
      <geometry>        
        <mesh filename="package:///meshes/right_ank_roll_link_visual.stl"/>        
      </geometry>      
      <material name="ank_roll_link_material">        
        <color rgba="0.61568627450980395466 0.81176470588235294379 0.92941176470588238168 1.0"/>        
      </material>      
    </visual>    
    <collision>      
      <origin xyz="0 0 0" rpy="0 -0 0"/>      
      <geometry>        
        <mesh filename="package:///meshes/right_ank_roll_link_collision.stl"/>        
      </geometry>      
    </collision>    
    <inertial>      
      <origin xyz="-6.278510285498596341e-10 0.027009707039944940571 0.00075275119182833724867" rpy="0 0 0"/>      
      <mass value="0.014299508637166613578"/>      
      <inertia ixx="1.0815330340622727581e-05" ixy="6.9415252628664503009e-14" ixz="-3.1620808578524381547e-13" iyy="9.3337296863724975618e-06" iyz="-9.1328070216937110825e-07" izz="2.9529318668467990654e-06"/>      
    </inertial>    
  </link>  

  <link name="ank_rr_link">    
    <visual>      
      <origin xyz="0 0 0" rpy="0 -0 0"/>      
      <geometry>        
        <mesh filename="package:///meshes/right_ank_rr_link_visual.stl"/>        
      </geometry>      
      <material name="ank_rr_link_material">        
        <color rgba="0.61568627450980395466 0.81176470588235294379 0.92941176470588238168 1.0"/>        
      </material>      
    </visual>    
    <collision>      
      <origin xyz="0 0 0" rpy="0 -0 0"/>      
      <geometry>        
        <mesh filename="package:///meshes/right_ank_rr_link_collision.stl"/>        
      </geometry>      
    </collision>    
    <inertial>      
      <origin xyz="3.4593503690053749007e-05 0.0062999445222072106634 -0.0019000000000000060677" rpy="0 0 0"/>      
      <mass value="0.00044289790445047684574"/>      
      <inertia ixx="9.0894755004835322941e-09" ixy="-5.6689994077040089909e-11" ixz="1.0879024115051245854e-14" iyy="8.3785129146959889042e-09" iyz="-1.37193687724047335e-31" izz="1.3107013728801491474e-08"/>      
    </inertial>    
  </link>  

  <link name="12lf_rod_end">    
    <visual>      
      <origin xyz="0 0 0" rpy="0 -0 0"/>      
      <geometry>        
        <mesh filename="package:///meshes/right_12lf_rod_end_visual.stl"/>        
      </geometry>      
      <material name="12lf_rod_end_material">        
        <color rgba="0.97254901960784312376 0.52941176470588235947 0.0039215686274509803377 1.0"/>        
      </material>      
    </visual>    
    <collision>      
      <origin xyz="0 0 0" rpy="0 -0 0"/>      
      <geometry>        
        <mesh filename="package:///meshes/right_12lf_rod_end_collision.stl"/>        
      </geometry>      
    </collision>    
    <inertial>      
      <origin xyz="-5.7828425815963129975e-11 0.0033987031118029101262 -0.0020055782443104621" rpy="0 0 0"/>      
      <mass value="0.00066080012085386230676"/>      
      <inertia ixx="1.067579410464855452e-08" ixy="-1.8531171284580357252e-16" ixz="9.2603132969677364083e-16" iyy="2.377371824966105234e-09" iyz="6.3401399719238955094e-12" izz="1.1538333246010974441e-08"/>      
    </inertial>    
  </link>  

  <joint name="right_ank_R21" type="revolute">    
    <origin xyz="0.0021000000000001434186 0.010000000000000230926 -0.0018999999999989442001" rpy="-1.5707963267948970021 1.4871995686198307141 -1.5707963267948983344"/>    
    <parent link="ank_rr_link"/>    
    <child link="12lf_rod_end"/>    
    <axis xyz="0 0 1"/>    
    <limit effort="1" velocity="20" lower="-1.570796326794896558" upper="1.570796326794896558"/>    
    <joint_properties friction="0.0"/>    
  </joint>  

  <joint name="right_ank_R11" type="revolute">    
    <origin xyz="-0.010000000000000112965 0.012500000000000233147 -0.032999999999998946842" rpy="3.1415926535897922278 -2.5232420665482256888e-16 -0.098830241914703576001"/>    
    <parent link="ank_roll_link"/>    
    <child link="ank_rr_link"/>    
    <axis xyz="0 0 1"/>    
    <limit effort="1" velocity="20" lower="-1.570796326794896558" upper="1.570796326794896558"/>    
    <joint_properties friction="0.0"/>    
  </joint>  

  <link name="ank_rr_link_2">    
    <visual>      
      <origin xyz="0 0 0" rpy="0 -0 0"/>      
      <geometry>        
        <mesh filename="package:///meshes/right_ank_rr_link_2_visual.stl"/>        
      </geometry>      
      <material name="ank_rr_link_2_material">        
        <color rgba="0.61568627450980395466 0.81176470588235294379 0.92941176470588238168 1.0"/>        
      </material>      
    </visual>    
    <collision>      
      <origin xyz="0 0 0" rpy="0 -0 0"/>      
      <geometry>        
        <mesh filename="package:///meshes/right_ank_rr_link_2_collision.stl"/>        
      </geometry>      
    </collision>    
    <inertial>      
      <origin xyz="3.4593503690060796322e-05 -0.0062999445222072679093 -0.0018999999999999986951" rpy="0 0 0"/>      
      <mass value="0.00044289790445047684574"/>      
      <inertia ixx="9.0894755004835256766e-09" ixy="5.6689994077039631082e-11" ixz="-1.0879024115051241121e-14" iyy="8.3785129146959922129e-09" iyz="1.9025809707218229306e-31" izz="1.3107013728801491474e-08"/>      
    </inertial>    
  </link>  

  <link name="12lf_rod_end_2">    
    <visual>      
      <origin xyz="0 0 0" rpy="0 -0 0"/>      
      <geometry>        
        <mesh filename="package:///meshes/right_12lf_rod_end_2_visual.stl"/>        
      </geometry>      
      <material name="12lf_rod_end_2_material">        
        <color rgba="0.97254901960784312376 0.52941176470588235947 0.0039215686274509803377 1.0"/>        
      </material>      
    </visual>    
    <collision>      
      <origin xyz="0 0 0" rpy="0 -0 0"/>      
      <geometry>        
        <mesh filename="package:///meshes/right_12lf_rod_end_2_collision.stl"/>        
      </geometry>      
    </collision>    
    <inertial>      
      <origin xyz="-5.7828418884995878158e-11 0.0033987031118029092588 -0.0020055782443104621" rpy="0 0 0"/>      
      <mass value="0.00066080012085386230676"/>      
      <inertia ixx="1.067579410464855452e-08" ixy="-1.8531171294194118822e-16" ixz="9.2603132969583371306e-16" iyy="2.3773718249661068884e-09" iyz="6.3401399719238018053e-12" izz="1.1538333246010974441e-08"/>      
    </inertial>    
  </link>  

  <joint name="right_ank_R22" type="revolute">    
    <origin xyz="0.0020999999999999074962 -0.010000000000000119904 -0.0018999999999989372612" rpy="-1.5707963267948956698 -1.487199838467331281 -1.5707963267948870101"/>    
    <parent link="ank_rr_link_2"/>    
    <child link="12lf_rod_end_2"/>    
    <axis xyz="0 0 1"/>    
    <limit effort="1" velocity="20" lower="-1.570796326794896558" upper="1.570796326794896558"/>    
    <joint_properties friction="0.0"/>    
  </joint>  

  <joint name="right_ank_R12" type="revolute">    
    <origin xyz="0.0099999999999998891859 0.012500000000000066613 -0.032999999999998946842" rpy="-3.141592653589793116 -1.1886010661269619878e-15 -3.0460894442739978594"/>    
    <parent link="ank_roll_link"/>    
    <child link="ank_rr_link_2"/>    
    <axis xyz="0 0 1"/>    
    <limit effort="1" velocity="20" lower="-1.570796326794896558" upper="1.570796326794896558"/>    
    <joint_properties friction="0.0"/>    
  </joint>  

  <joint name="right_ank_roll" type="revolute">    
    <origin xyz="1.1102230246251565404e-15 -0.006100000000001146172 -0.014600000000001599545" rpy="-1.5707963267948990005 1.5707963267948332753 0"/>    
    <parent link="ank_pitch_link"/>    
    <child link="ank_roll_link"/>    
    <axis xyz="0 0 1"/>    
    <limit effort="1" velocity="20" lower="-1.570796326794896558" upper="1.570796326794896558"/>    
    <joint_properties friction="0.0"/>    
  </joint>  

  <joint name="right_ank_pitch" type="revolute">    
    <origin xyz="-1.0422817820682455029e-15 0.10000000000000003331 -0.0062000000000001706524" rpy="-3.1415926535897900074 3.0234911913779407472e-15 -1.5707963267948836794"/>    
    <parent link="right_calf_link"/>    
    <child link="ank_pitch_link"/>    
    <axis xyz="0 0 1"/>    
    <limit effort="1" velocity="20" lower="-1.570796326794896558" upper="1.570796326794896558"/>    
    <joint_properties friction="0.0"/>    
  </joint>  

  <link name="ball_joint_container">    
    <visual>      
      <origin xyz="0 0 0" rpy="0 -0 0"/>      
      <geometry>        
        <mesh filename="package:///meshes/right_ball_joint_container_visual.stl"/>        
      </geometry>      
      <material name="ball_joint_container_material">        
        <color rgba="0.61568627450980395466 0.81176470588235294379 0.92941176470588238168 1.0"/>        
      </material>      
    </visual>    
    <collision>      
      <origin xyz="0 0 0" rpy="0 -0 0"/>      
      <geometry>        
        <mesh filename="package:///meshes/right_ball_joint_container_collision.stl"/>        
      </geometry>      
    </collision>    
    <inertial>      
      <origin xyz="-6.4666794741501355723e-18 -1.2829321646532240093e-19 -0.0097125341669083379431" rpy="0 0 0"/>      
      <mass value="4.803735642533054869e-05"/>      
      <inertia ixx="7.1865480628741645687e-10" ixy="-1.0473892724698395083e-26" ixz="-4.7877958335754960381e-39" iyy="8.475420427718555978e-10" iyz="1.5533046315172847589e-39" izz="1.8625314111651911712e-10"/>      
    </inertial>    
  </link>  

  <link name="ball_joint_ball">    
    <visual>      
      <origin xyz="0 0 0" rpy="0 -0 0"/>      
      <geometry>        
        <mesh filename="package:///meshes/right_ball_joint_ball_visual.stl"/>        
      </geometry>      
      <material name="ball_joint_ball_material">        
        <color rgba="0.3291302810242056065 0.44310466418644928188 0.69204871161977121741 1.0"/>        
      </material>      
    </visual>    
    <collision>      
      <origin xyz="0 0 0" rpy="0 -0 0"/>      
      <geometry>        
        <mesh filename="package:///meshes/right_ball_joint_ball_collision.stl"/>        
      </geometry>      
    </collision>    
    <inertial>      
      <origin xyz="-5.6706855612805381493e-18 -0.0010308669810016315646 5.1032803075002372958e-20" rpy="0 0 0"/>      
      <mass value="4.4053796295264623832e-05"/>      
      <inertia ixx="3.1285011349692541014e-10" ixy="-5.6694783476663120066e-26" ixz="-4.6590694561566615649e-27" iyy="6.2569568612795630976e-11" iyz="-4.9063930476096404349e-27" izz="3.1285321460376385129e-10"/>      
    </inertial>    
  </link>  

  <link name="12lf">    
    <visual>      
      <origin xyz="0 0 0" rpy="0 -0 0"/>      
      <geometry>        
        <mesh filename="package:///meshes/right_12lf_visual.stl"/>        
      </geometry>      
      <material name="12lf_material">        
        <color rgba="0.62004392100736038795 0.58836684613512635345 0.49897069021535678246 1.0"/>        
      </material>      
    </visual>    
    <collision>      
      <origin xyz="0 0 0" rpy="0 -0 0"/>      
      <geometry>        
        <mesh filename="package:///meshes/right_12lf_collision.stl"/>        
      </geometry>      
    </collision>    
    <inertial>      
      <origin xyz="0.0049084207243670118295 -0.00013802439943499188288 -0.02994700357714415867" rpy="0 0 0"/>      
      <mass value="0.044782197696050345115"/>      
      <inertia ixx="1.5260128421310199863e-05" ixy="2.2955773686520042603e-08" ixz="-8.1364204007639269751e-08" iyy="1.8188469778949162953e-05" iyz="-5.5542240842785307698e-08" izz="5.1496273901739647295e-06"/>      
    </inertial>    
  </link>  

  <link name="12lf_rod">    
    <visual>      
      <origin xyz="0 0 0" rpy="0 -0 0"/>      
      <geometry>        
        <mesh filename="package:///meshes/right_12lf_rod_visual.stl"/>        
      </geometry>      
      <material name="12lf_rod_material">        
        <color rgba="0.80016770676329840306 0.8929145636529542962 0.94547111589042631685 1.0"/>        
      </material>      
    </visual>    
    <collision>      
      <origin xyz="0 0 0" rpy="0 -0 0"/>      
      <geometry>        
        <mesh filename="package:///meshes/right_12lf_rod_collision.stl"/>        
      </geometry>      
    </collision>    
    <inertial>      
      <origin xyz="-2.7254954589838078389e-06 -1.2667795960740625948e-05 0.006005480722775354864" rpy="0 0 0"/>      
      <mass value="0.0026945559868381376359"/>      
      <inertia ixx="3.2231832056364365946e-07" ixy="-9.9380293173893699075e-13" ixz="1.049065490371580333e-10" iyy="3.2231218697785392448e-07" iyz="5.6317539917539904836e-10" izz="1.8746557075763388172e-08"/>      
    </inertial>    
  </link>  

  <joint name="right_ank_act1" type="prismatic">    
    <origin xyz="2.2722093427941791877e-06 9.92261828258733658e-16 -0.059356158967292543815" rpy="-3.1415926535897837901 -1.2238359105881652741e-14 -0.63671356441985882402"/>    
    <parent link="12lf"/>    
    <child link="12lf_rod"/>    
    <axis xyz="0 0 1"/>    
    <limit effort="1" velocity="20" lower="-0.01799999999999999864" upper="0.01799999999999999864"/>    
    <joint_properties friction="0.0"/>    
  </joint>  

  <joint name="right_ank_B31" type="revolute">    
    <origin xyz="0 -0.0064387505004004086384 6.9388939039072283776e-18" rpy="-1.570796326794896558 -5.4574696529115381853e-06 -1.2331483706146518492e-15"/>    
    <parent link="ball_joint_ball"/>    
    <child link="12lf"/>    
    <axis xyz="0 0 1"/>    
    <limit effort="1" velocity="20" lower="-0.785398163397448279" upper="0.785398163397448279"/>    
    <joint_properties friction="0.0"/>    
  </joint>  

  <joint name="right_ank_B21" type="revolute">    
    <origin xyz="-6.9388939039072283776e-18 0 -0.011499999999999992867" rpy="1.570796326794896558 -1.4871995686197141406 1.5707963267948958919"/>    
    <parent link="ball_joint_container"/>    
    <child link="ball_joint_ball"/>    
    <axis xyz="0 0 1"/>    
    <limit effort="1" velocity="20" lower="-0.785398163397448279" upper="0.785398163397448279"/>    
    <joint_properties friction="0.0"/>    
  </joint>  

  <joint name="right_ank_B11" type="revolute">    
    <origin xyz="0.018000000000000015987 0.010000000000000036637 -0.011499999999999994602" rpy="1.5707963267948974462 -1.4719660848800855124 -1.570796326794896336"/>    
    <parent link="right_calf_link"/>    
    <child link="ball_joint_container"/>    
    <axis xyz="0 0 1"/>    
    <limit effort="1" velocity="20" lower="-0.785398163397448279" upper="0.785398163397448279"/>    
    <joint_properties friction="0.0"/>    
  </joint>  

  <link name="ball_joint_container_2">    
    <visual>      
      <origin xyz="0 0 0" rpy="0 -0 0"/>      
      <geometry>        
        <mesh filename="package:///meshes/right_ball_joint_container_2_visual.stl"/>        
      </geometry>      
      <material name="ball_joint_container_2_material">        
        <color rgba="0.61568627450980395466 0.81176470588235294379 0.92941176470588238168 1.0"/>        
      </material>      
    </visual>    
    <collision>      
      <origin xyz="0 0 0" rpy="0 -0 0"/>      
      <geometry>        
        <mesh filename="package:///meshes/right_ball_joint_container_2_collision.stl"/>        
      </geometry>      
    </collision>    
    <inertial>      
      <origin xyz="4.7221442975708423495e-19 -1.2829321646532728797e-19 -0.0097125341669083414126" rpy="0 0 0"/>      
      <mass value="4.803735642533054869e-05"/>      
      <inertia ixx="7.1865480628741666366e-10" ixy="-1.0284698396851338305e-27" ixz="6.9431204756096617012e-39" iyy="8.475420427718555978e-10" iyz="-3.7182223934451989704e-39" izz="1.8625314111651911712e-10"/>      
    </inertial>    
  </link>  

  <link name="ball_joint_ball_2">    
    <visual>      
      <origin xyz="0 0 0" rpy="0 -0 0"/>      
      <geometry>        
        <mesh filename="package:///meshes/right_ball_joint_ball_2_visual.stl"/>        
      </geometry>      
      <material name="ball_joint_ball_2_material">        
        <color rgba="0.3291302810242056065 0.44310466418644928188 0.69204871161977121741 1.0"/>        
      </material>      
    </visual>    
    <collision>      
      <origin xyz="0 0 0" rpy="0 -0 0"/>      
      <geometry>        
        <mesh filename="package:///meshes/right_ball_joint_ball_2_collision.stl"/>        
      </geometry>      
    </collision>    
    <inertial>      
      <origin xyz="2.2784261896682323174e-18 -0.0010308669810016306972 -1.6992236520811434399e-18" rpy="0 0 0"/>      
      <mass value="4.4053796295264623832e-05"/>      
      <inertia ixx="3.1285011349692628902e-10" ixy="5.8377757527464378274e-26" ixz="-1.2947758642049301246e-26" iyy="6.2569568612795618051e-11" iyz="8.1979339800191834342e-26" izz="3.1285321460376405809e-10"/>      
    </inertial>    
  </link>  

  <link name="12lf_2">    
    <visual>      
      <origin xyz="0 0 0" rpy="0 -0 0"/>      
      <geometry>        
        <mesh filename="package:///meshes/right_12lf_2_visual.stl"/>        
      </geometry>      
      <material name="12lf_2_material">        
        <color rgba="0.62004392100736005489 0.58836684613512624242 0.49897069021535672695 1.0"/>        
      </material>      
    </visual>    
    <collision>      
      <origin xyz="0 0 0" rpy="0 -0 0"/>      
      <geometry>        
        <mesh filename="package:///meshes/right_12lf_2_collision.stl"/>        
      </geometry>      
    </collision>    
    <inertial>      
      <origin xyz="0.0049084207243648607724 -0.00013802439943722319806 -0.029947003577140699632" rpy="0 0 0"/>      
      <mass value="0.044782197696050365932"/>      
      <inertia ixx="1.5260128421307445312e-05" ixy="2.2955773686632962683e-08" ixz="-8.1364204008454486023e-08" iyy="1.8188469778944663514e-05" iyz="-5.5542240843674513621e-08" izz="5.1496273901721791841e-06"/>      
    </inertial>    
  </link>  

  <link name="12lf_rod_2">    
    <visual>      
      <origin xyz="0 0 0" rpy="0 -0 0"/>      
      <geometry>        
        <mesh filename="package:///meshes/right_12lf_rod_2_visual.stl"/>        
      </geometry>      
      <material name="12lf_rod_2_material">        
        <color rgba="0.80016770676329840306 0.8929145636529542962 0.94547111589042631685 1.0"/>        
      </material>      
    </visual>    
    <collision>      
      <origin xyz="0 0 0" rpy="0 -0 0"/>      
      <geometry>        
        <mesh filename="package:///meshes/right_12lf_rod_2_collision.stl"/>        
      </geometry>      
    </collision>    
    <inertial>      
      <origin xyz="-2.7254954597040649414e-06 -1.2667795961323570963e-05 0.006005480722772372007" rpy="0 0 0"/>      
      <mass value="0.0026945559868381376359"/>      
      <inertia ixx="3.22318320563456624e-07" ixy="-9.9380293185141901377e-13" ixz="1.0490654905967739217e-10" iyy="3.223121869776667302e-07" iyz="5.6317539919321134888e-10" izz="1.8746557075763560225e-08"/>      
    </inertial>    
  </link>  

  <joint name="right_ank_act2" type="prismatic">    
    <origin xyz="2.2722093411253752038e-06 -2.4008572907519010187e-15 -0.059356459443579534518" rpy="-3.1415926535897926719 9.0510831053370240348e-16 -0.63671356442005022647"/>    
    <parent link="12lf_2"/>    
    <child link="12lf_rod_2"/>    
    <axis xyz="0 0 1"/>    
    <limit effort="1" velocity="20" lower="-0.01799999999999999864" upper="0.01799999999999999864"/>    
    <joint_properties friction="0.0"/>    
  </joint>  

  <joint name="right_ank_B32" type="revolute">    
    <origin xyz="0 -0.0064387505004004086384 0" rpy="-1.570796326794896558 -5.4574689504429525655e-06 -5.0339227696192602828e-16"/>    
    <parent link="ball_joint_ball_2"/>    
    <child link="12lf_2"/>    
    <axis xyz="0 0 1"/>    
    <limit effort="1" velocity="20" lower="-0.785398163397448279" upper="0.785398163397448279"/>    
    <joint_properties friction="0.0"/>    
  </joint>  

  <joint name="right_ank_B22" type="revolute">    
    <origin xyz="0 -2.7755575615628913511e-17 -0.011500000000000003275" rpy="1.570796326794896558 -1.4871998384672124871 1.5707963267948923392"/>    
    <parent link="ball_joint_container_2"/>    
    <child link="ball_joint_ball_2"/>    
    <axis xyz="0 0 1"/>    
    <limit effort="1" velocity="20" lower="-0.785398163397448279" upper="0.785398163397448279"/>    
    <joint_properties friction="0.0"/>    
  </joint>  

  <joint name="right_ank_B12" type="revolute">    
    <origin xyz="0.018000000000000002109 0.010000000000000036637 0.028300000000000012645" rpy="-1.5707963267948974462 -1.4752931174794650104 1.5707963267948936714"/>    
    <parent link="right_calf_link"/>    
    <child link="ball_joint_container_2"/>    
    <axis xyz="0 0 1"/>    
    <limit effort="1" velocity="20" lower="-0.785398163397448279" upper="0.785398163397448279"/>    
    <joint_properties friction="0.0"/>    
  </joint>  

  <joint name="right_knee" type="revolute">    
    <origin xyz="-2.5483606178382506831e-15 0.097999999999999684586 0.027399999999999827272" rpy="3.1415926535897926719 -1.2487298519101510075e-16 -3.141592653589788231"/>    
    <parent link="hip_pitch_link"/>    
    <child link="right_calf_link"/>    
    <axis xyz="0 0 1"/>    
    <limit effort="1" velocity="20" lower="-1.570796326794896558" upper="1.570796326794896558"/>    
    <joint_properties friction="0.0"/>    
  </joint>  

  <joint name="right_hip_pitch" type="revolute">    
    <origin xyz="-0.024000000716145990232 -0.019000000152457986735 -0.019000000152453767888" rpy="-1.5707963267951823294 1.5707963267947557817 0"/>    
    <parent link="hip_roll_link"/>    
    <child link="hip_pitch_link"/>    
    <axis xyz="0 0 1"/>    
    <limit effort="1" velocity="20" lower="-1.570796326794896558" upper="1.570796326794896558"/>    
    <joint_properties friction="0.0"/>    
  </joint>  

  <joint name="right_hip_roll" type="revolute">    
    <origin xyz="-0.018999999999999885036 -5.020473408011439263e-18 -0.025000000000000001388" rpy="1.4827462901121851002e-29 -1.5707963267947766539 0"/>    
    <parent link="hip_yaw_link"/>    
    <child link="hip_roll_link"/>    
    <axis xyz="0 0 1"/>    
    <limit effort="1" velocity="20" lower="-1.570796326794896558" upper="1.570796326794896558"/>    
    <joint_properties friction="0.0"/>    
  </joint>  


</robot>