<?xml version="1.0" ?><robot name="right_3R+RH5_leg">  
  <link name="hip_yaw_link">    
    <visual>      
      <origin xyz="0 0 0" rpy="0 -0 0"/>      
      <geometry>        
        <mesh filename="package:///meshes/right_hip_yaw_link_visual.stl"/>        
      </geometry>      
      <material name="hip_yaw_link_material">        
        <color rgba="0.61568627450980395466 0.81176470588235294379 0.9294117647058824927 1.0"/>        
      </material>      
    </visual>    
    <collision>      
      <origin xyz="0 0 0" rpy="0 -0 0"/>      
      <geometry>        
        <mesh filename="package:///meshes/right_hip_yaw_link_collision.stl"/>        
      </geometry>      
    </collision>    
    <inertial>      
      <origin xyz="1.7870850560805124882e-19 -1.7856357941682210522e-19 -0.0098390489054829121524" rpy="0 0 0"/>      
      <mass value="0.009025883737097921064"/>      
      <inertia ixx="1.3230458239085874343e-06" ixy="-6.477854591907985348e-49" ixz="1.7322911775161982211e-33" iyy="3.8408510960330541809e-06" iyz="-1.4482241779965781819e-32" izz="3.8721396285793069258e-06"/>      
    </inertial>    
  </link>  

  <link name="hip_roll_link">    
    <visual>      
      <origin xyz="0 0 0" rpy="0 -0 0"/>      
      <geometry>        
        <mesh filename="package:///meshes/right_hip_roll_link_visual.stl"/>        
      </geometry>      
      <material name="hip_roll_link_material">        
        <color rgba="0.95018735644455842859 0.7067892720042843191 0.061612079402596720001 1.0"/>        
      </material>      
    </visual>    
    <collision>      
      <origin xyz="0 0 0" rpy="0 -0 0"/>      
      <geometry>        
        <mesh filename="package:///meshes/right_hip_roll_link_collision.stl"/>        
      </geometry>      
    </collision>    
    <inertial>      
      <origin xyz="0.012000150775887509849 -0.00049588816141320744574 -0.019495980755501008536" rpy="0 0 0"/>      
      <mass value="0.098012391483528665814"/>      
      <inertia ixx="2.0221748766306690251e-05" ixy="4.1552068245652282315e-08" ixz="-4.1225592185879438396e-08" iyy="2.7358099958307447456e-05" iyz="5.0935731752393255843e-07" izz="2.7358069524724117289e-05"/>      
    </inertial>    
  </link>  

  <link name="right_hip_pitch_link">    
    <visual>      
      <origin xyz="0 0 0" rpy="0 -0 0"/>      
      <geometry>        
        <mesh filename="package:///meshes/right_hip_pitch_link_visual.stl"/>        
      </geometry>      
      <material name="right_hip_pitch_link_material">        
        <color rgba="0.61654126330065683881 0.80727601473037591262 0.92171686558820720148 1.0"/>        
      </material>      
    </visual>    
    <collision>      
      <origin xyz="0 0 0" rpy="0 -0 0"/>      
      <geometry>        
        <mesh filename="package:///meshes/right_hip_pitch_link_collision.stl"/>        
      </geometry>      
    </collision>    
    <inertial>      
      <origin xyz="-1.3043817563868164539e-05 0.052864534196662107957 0.014710916112540835254" rpy="0 0 0"/>      
      <mass value="0.09353906475262946385"/>      
      <inertia ixx="6.2495912126891124488e-05" ixy="-2.2341467552985648854e-07" ixz="-1.1719709579435535716e-08" iyy="2.150063816786044877e-05" iyz="-1.4210875155541907482e-06" izz="6.2280434774102130346e-05"/>      
    </inertial>    
  </link>  

  <link name="right_calf_link">    
    <visual>      
      <origin xyz="0 0 0" rpy="0 -0 0"/>      
      <geometry>        
        <mesh filename="package:///meshes/right_calf_link_visual.stl"/>        
      </geometry>      
      <material name="right_calf_link_material">        
        <color rgba="0.55183757703855651489 0.72973662124660387818 0.87669617832525115197 1.0"/>        
      </material>      
    </visual>    
    <collision>      
      <origin xyz="0 0 0" rpy="0 -0 0"/>      
      <geometry>        
        <mesh filename="package:///meshes/right_calf_link_collision.stl"/>        
      </geometry>      
    </collision>    
    <inertial>      
      <origin xyz="-0.0038999626430269102376 0.042409395322589228672 0.0081838728113180648355" rpy="0 0 0"/>      
      <mass value="0.015779725212993943317"/>      
      <inertia ixx="1.4735397719668431253e-05" ixy="2.0283446246059437145e-07" ixz="9.1508417303720847237e-09" iyy="1.8964180016897454257e-06" iyz="-1.5463243486045364557e-08" izz="1.4035958490016423058e-05"/>      
    </inertial>    
  </link>  

  <link name="ank_pitch_link">    
    <visual>      
      <origin xyz="0 0 0" rpy="0 -0 0"/>      
      <geometry>        
        <mesh filename="package:///meshes/right_ank_pitch_link_visual.stl"/>        
      </geometry>      
      <material name="ank_pitch_link_material">        
        <color rgba="0.63189161126160275916 0.7266866879354088038 0.78356373393969258601 1.0"/>        
      </material>      
    </visual>    
    <collision>      
      <origin xyz="0 0 0" rpy="0 -0 0"/>      
      <geometry>        
        <mesh filename="package:///meshes/right_ank_pitch_link_collision.stl"/>        
      </geometry>      
    </collision>    
    <inertial>      
      <origin xyz="4.026968641285368054e-08 0.00059528282566746510036 -0.014599922383890091143" rpy="0 0 0"/>      
      <mass value="0.0042238381753791614387"/>      
      <inertia ixx="4.3705254067390922157e-07" ixy="1.6834347014799428057e-13" ixz="1.6428822916476734945e-12" iyy="3.978274136465558083e-07" iyz="2.0919205593658055483e-14" izz="8.8858574534520199265e-08"/>      
    </inertial>    
  </link>  

  <link name="ank_roll_link">    
    <visual>      
      <origin xyz="0 0 0" rpy="0 -0 0"/>      
      <geometry>        
        <mesh filename="package:///meshes/right_ank_roll_link_visual.stl"/>        
      </geometry>      
      <material name="ank_roll_link_material">        
        <color rgba="0.61568627450980406568 0.81176470588235305481 0.92941176470588238168 1.0"/>        
      </material>      
    </visual>    
    <collision>      
      <origin xyz="0 0 0" rpy="0 -0 0"/>      
      <geometry>        
        <mesh filename="package:///meshes/right_ank_roll_link_collision.stl"/>        
      </geometry>      
    </collision>    
    <inertial>      
      <origin xyz="0.0070959174823323235837 0.031669497972650013928 0.001544723730759410248" rpy="0 0 0"/>      
      <mass value="0.020312412236862385784"/>      
      <inertia ixx="1.4885431783124263564e-05" ixy="-7.6720412005443632341e-07" ixz="-8.1066503931638908931e-07" iyy="1.7915307614905197966e-05" iyz="-1.156343986492672846e-06" izz="6.9141164362347758452e-06"/>      
    </inertial>    
  </link>  

  <link name="ank_rr_link">    
    <visual>      
      <origin xyz="0 0 0" rpy="0 -0 0"/>      
      <geometry>        
        <mesh filename="package:///meshes/right_ank_rr_link_visual.stl"/>        
      </geometry>      
      <material name="ank_rr_link_material">        
        <color rgba="0.61568627450980395466 0.81176470588235283277 0.92941176470588238168 1.0"/>        
      </material>      
    </visual>    
    <collision>      
      <origin xyz="0 0 0" rpy="0 -0 0"/>      
      <geometry>        
        <mesh filename="package:///meshes/right_ank_rr_link_collision.stl"/>        
      </geometry>      
    </collision>    
    <inertial>      
      <origin xyz="3.5337942346598907057e-18 -0.0061447686137498470568 2.1667447037496360957e-19" rpy="0 0 0"/>      
      <mass value="0.00042507093693768156772"/>      
      <inertia ixx="8.7843229279236055827e-09" ixy="-1.7917817808540703063e-26" ixz="-1.0879024114875650149e-14" iyy="8.0301730481463919886e-09" iyz="4.2355501547414480888e-32" izz="1.2504379836120061674e-08"/>      
    </inertial>    
  </link>  

  <link name="12lf_rod_end">    
    <visual>      
      <origin xyz="0 0 0" rpy="0 -0 0"/>      
      <geometry>        
        <mesh filename="package:///meshes/right_12lf_rod_end_visual.stl"/>        
      </geometry>      
      <material name="12lf_rod_end_material">        
        <color rgba="0.92771758928836545177 0.61049283053223013518 0.21847658490585164515 1.0"/>        
      </material>      
    </visual>    
    <collision>      
      <origin xyz="0 0 0" rpy="0 -0 0"/>      
      <geometry>        
        <mesh filename="package:///meshes/right_12lf_rod_end_collision.stl"/>        
      </geometry>      
    </collision>    
    <inertial>      
      <origin xyz="-4.4735198745204001504e-11 -0.0038422185938246289014 6.4384187209446333639e-06" rpy="0 0 0"/>      
      <mass value="0.00085420491177815895123"/>      
      <inertia ixx="1.1840985264406785739e-08" ixy="2.0225978137273097662e-16" ixz="-9.2606419974807898323e-16" iyy="3.3549621576797185418e-09" iyz="7.4535631381838762084e-12" izz="1.2703522254419976616e-08"/>      
    </inertial>    
  </link>  

  <joint name="right_ank_R21" type="revolute">    
    <origin xyz="3.4694469519536141888e-18 -0.010000000000000008882 0" rpy="1.57079632679489678 -1.5664147454870704923 -1.5707963267947753216"/>    
    <parent link="ank_rr_link"/>    
    <child link="12lf_rod_end"/>    
    <axis xyz="0 0 1"/>    
    <limit effort="1" velocity="20" lower="-1.570796326794896558" upper="1.570796326794896558"/>    
    <joint_properties friction="0.0"/>    
  </joint>  

  <joint name="right_ank_R11" type="revolute">    
    <origin xyz="-0.018000000000000005579 0.016000000000000014211 -0.020599999999999996786" rpy="-3.5360359477892277706e-16 8.2839943819914169726e-16 -0.018779262484754637164"/>    
    <parent link="ank_roll_link"/>    
    <child link="ank_rr_link"/>    
    <axis xyz="0 0 1"/>    
    <limit effort="1" velocity="20" lower="-1.570796326794896558" upper="1.570796326794896558"/>    
    <joint_properties friction="0.0"/>    
  </joint>  

  <link name="ank_rr_link_2">    
    <visual>      
      <origin xyz="0 0 0" rpy="0 -0 0"/>      
      <geometry>        
        <mesh filename="package:///meshes/right_ank_rr_link_2_visual.stl"/>        
      </geometry>      
      <material name="ank_rr_link_2_material">        
        <color rgba="0.61568627450980395466 0.81176470588235283277 0.92941176470588238168 1.0"/>        
      </material>      
    </visual>    
    <collision>      
      <origin xyz="0 0 0" rpy="0 -0 0"/>      
      <geometry>        
        <mesh filename="package:///meshes/right_ank_rr_link_2_collision.stl"/>        
      </geometry>      
    </collision>    
    <inertial>      
      <origin xyz="-3.4061457083544488604e-18 -0.0061447686137497915457 -3.2527724815782340247e-18" rpy="0 0 0"/>      
      <mass value="0.00042507093693768156772"/>      
      <inertia ixx="8.7843229279236022739e-09" ixy="7.9077189809587699013e-27" ixz="-1.0879024114875648572e-14" iyy="8.0301730481463919886e-09" iyz="1.206439933899918516e-32" izz="1.2504379836120061674e-08"/>      
    </inertial>    
  </link>  

  <link name="12lf_rod_end_2">    
    <visual>      
      <origin xyz="0 0 0" rpy="0 -0 0"/>      
      <geometry>        
        <mesh filename="package:///meshes/right_12lf_rod_end_2_visual.stl"/>        
      </geometry>      
      <material name="12lf_rod_end_2_material">        
        <color rgba="0.92771758928836545177 0.6104928305322302462 0.21847658490585164515 1.0"/>        
      </material>      
    </visual>    
    <collision>      
      <origin xyz="0 0 0" rpy="0 -0 0"/>      
      <geometry>        
        <mesh filename="package:///meshes/right_12lf_rod_end_2_collision.stl"/>        
      </geometry>      
    </collision>    
    <inertial>      
      <origin xyz="-4.4735193276697242559e-11 -0.003842218593824629335 6.4384187209448959441e-06" rpy="0 0 0"/>      
      <mass value="0.00085420491177815895123"/>      
      <inertia ixx="1.1840985264406787394e-08" ixy="2.0225977929126142616e-16" ixz="-9.2606419983362799018e-16" iyy="3.3549621576797243321e-09" iyz="7.4535631381839666813e-12" izz="1.2703522254419978271e-08"/>      
    </inertial>    
  </link>  

  <joint name="right_ank_R22" type="revolute">    
    <origin xyz="-3.4694469519536141888e-18 -0.0099999999999999533706 -3.4694469519536141888e-18" rpy="-1.570796326794896336 -1.5664376509754269762 1.5707963267952340658"/>    
    <parent link="ank_rr_link_2"/>    
    <child link="12lf_rod_end_2"/>    
    <axis xyz="0 0 1"/>    
    <limit effort="1" velocity="20" lower="-1.570796326794896558" upper="1.570796326794896558"/>    
    <joint_properties friction="0.0"/>    
  </joint>  

  <joint name="right_ank_R12" type="revolute">    
    <origin xyz="0.01799999999999999864 0.016000000000000069722 -0.020600000000000003725" rpy="3.1415926535897922278 1.1785067659504147721e-15 -3.1229304365172114721"/>    
    <parent link="ank_roll_link"/>    
    <child link="ank_rr_link_2"/>    
    <axis xyz="0 0 1"/>    
    <limit effort="1" velocity="20" lower="-1.570796326794896558" upper="1.570796326794896558"/>    
    <joint_properties friction="0.0"/>    
  </joint>  

  <joint name="right_ank_roll" type="revolute">    
    <origin xyz="2.0816681711721685133e-15 0.0015000000000089284361 -0.014599999999994599936" rpy="-1.5707963267951812192 1.5707963267946736252 0"/>    
    <parent link="ank_pitch_link"/>    
    <child link="ank_roll_link"/>    
    <axis xyz="0 0 1"/>    
    <limit effort="1" velocity="20" lower="-0.785398163397448279" upper="0.785398163397448279"/>    
    <joint_properties friction="0.0"/>    
  </joint>  

  <joint name="right_ank_pitch" type="revolute">    
    <origin xyz="5.0979769291920753058e-19 0.099999999999999977796 -0.0062000000000000023842" rpy="-3.1415926535897926719 5.5511151131695266928e-17 -1.5707963267946121189"/>    
    <parent link="right_calf_link"/>    
    <child link="ank_pitch_link"/>    
    <axis xyz="0 0 1"/>    
    <limit effort="1" velocity="20" lower="-0.785398163397448279" upper="0.95993108859688125456"/>    
    <joint_properties friction="0.0"/>    
  </joint>  

  <link name="ball_joint_container">    
    <visual>      
      <origin xyz="0 0 0" rpy="0 -0 0"/>      
      <geometry>        
        <mesh filename="package:///meshes/right_ball_joint_container_visual.stl"/>        
      </geometry>      
      <material name="ball_joint_container_material">        
        <color rgba="0.61568627450980395466 0.81176470588235294379 0.9294117647058824927 1.0"/>        
      </material>      
    </visual>    
    <collision>      
      <origin xyz="0 0 0" rpy="0 -0 0"/>      
      <geometry>        
        <mesh filename="package:///meshes/right_ball_joint_container_collision.stl"/>        
      </geometry>      
    </collision>    
    <inertial>      
      <origin xyz="4.7221442975705582748e-19 -1.2135113793955736663e-19 -0.0097125341669083414126" rpy="0 0 0"/>      
      <mass value="4.8037356425330562243e-05"/>      
      <inertia ixx="7.1865480628741666366e-10" ixy="1.3454930950453311496e-27" ixz="2.222508382224999855e-38" iyy="8.475420427718555978e-10" iyz="-2.3425189133335363393e-38" izz="1.8625314111651911712e-10"/>      
    </inertial>    
  </link>  

  <link name="ball_joint_ball">    
    <visual>      
      <origin xyz="0 0 0" rpy="0 -0 0"/>      
      <geometry>        
        <mesh filename="package:///meshes/right_ball_joint_ball_visual.stl"/>        
      </geometry>      
      <material name="ball_joint_ball_material">        
        <color rgba="0.3291302810242056065 0.44310466418644928188 0.69204871161977121741 1.0"/>        
      </material>      
    </visual>    
    <collision>      
      <origin xyz="0 0 0" rpy="0 -0 0"/>      
      <geometry>        
        <mesh filename="package:///meshes/right_ball_joint_ball_collision.stl"/>        
      </geometry>      
    </collision>    
    <inertial>      
      <origin xyz="4.2858046684579815395e-18 -0.00103086698100160923 -2.3158593935613664431e-18" rpy="0 0 0"/>      
      <mass value="4.4053796295264623832e-05"/>      
      <inertia ixx="3.1285011349692401427e-10" ixy="1.4285863097047550493e-25" ixz="-1.0391917933769396806e-28" iyy="6.2569568612795605126e-11" iyz="1.3532407090833657174e-25" izz="3.1285321460376323091e-10"/>      
    </inertial>    
  </link>  

  <link name="12lf">    
    <visual>      
      <origin xyz="0 0 0" rpy="0 -0 0"/>      
      <geometry>        
        <mesh filename="package:///meshes/right_12lf_visual.stl"/>        
      </geometry>      
      <material name="12lf_material">        
        <color rgba="0.62004392096503557763 0.58836684612040235365 0.49897069027350277048 1.0"/>        
      </material>      
    </visual>    
    <collision>      
      <origin xyz="0 0 0" rpy="0 -0 0"/>      
      <geometry>        
        <mesh filename="package:///meshes/right_12lf_collision.stl"/>        
      </geometry>      
    </collision>    
    <inertial>      
      <origin xyz="0.0049084207226891846815 -0.0001380244000646913547 -0.02994700357584112807" rpy="0 0 0"/>      
      <mass value="0.044782197690790462308"/>      
      <inertia ixx="1.5260128420484905169e-05" ixy="2.2955774098311307148e-08" ixz="-8.1364204859661294004e-08" iyy="1.8188469777204471594e-05" iyz="-5.5542241170235400646e-08" izz="5.149627388932782788e-06"/>      
    </inertial>    
  </link>  

  <link name="12lf_rod">    
    <visual>      
      <origin xyz="0 0 0" rpy="0 -0 0"/>      
      <geometry>        
        <mesh filename="package:///meshes/right_12lf_rod_visual.stl"/>        
      </geometry>      
      <material name="12lf_rod_material">        
        <color rgba="0.80250260812861884396 0.89340612183512713163 0.94491811293548189088 1.0"/>        
      </material>      
    </visual>    
    <collision>      
      <origin xyz="0 0 0" rpy="0 -0 0"/>      
      <geometry>        
        <mesh filename="package:///meshes/right_12lf_rod_collision.stl"/>        
      </geometry>      
    </collision>    
    <inertial>      
      <origin xyz="-6.322208407866453834e-07 4.6933255150883510844e-07 -0.012893387334328704555" rpy="0 0 0"/>      
      <mass value="0.0025088292483592144512"/>      
      <inertia ixx="2.6944521128621895713e-07" ixy="7.1389570317464702887e-15" ixz="1.3562243144833394732e-11" iyy="2.6944520001678440709e-07" iyz="-1.0089988378804436055e-11" izz="1.7809843599861005638e-08"/>      
    </inertial>    
  </link>  

  <joint name="right_ank_act1" type="prismatic">    
    <origin xyz="2.2722093412017030367e-06 1.8804402479588588903e-15 -0.074779998095388988677" rpy="-3.1415926535897829019 8.526808676235474948e-15 -2.2021168238260906413"/>    
    <parent link="12lf"/>    
    <child link="12lf_rod"/>    
    <axis xyz="0 0 1"/>    
    <limit effort="1" velocity="20" lower="0" upper="0.040000000000000000833"/>    
    <joint_properties friction="0.0"/>    
  </joint>  

  <joint name="right_ank_B31" type="revolute">    
    <origin xyz="6.9388939039072283776e-18 -0.0064387505004004086384 6.9388939039072283776e-18" rpy="-1.5707963267948970021 0.1691344003416279107 3.6048302674885136887e-16"/>    
    <parent link="ball_joint_ball"/>    
    <child link="12lf"/>    
    <axis xyz="0 0 1"/>    
    <limit effort="1" velocity="20" lower="-0.785398163397448279" upper="0.785398163397448279"/>    
    <joint_properties friction="0.0"/>    
  </joint>  

  <joint name="right_ank_B21" type="revolute">    
    <origin xyz="0 -2.7755575615628913511e-17 -0.011500000000000006745" rpy="-1.570796326794896558 -1.5664147454871475418 -1.5707963267939402119"/>    
    <parent link="ball_joint_container"/>    
    <child link="ball_joint_ball"/>    
    <axis xyz="0 0 1"/>    
    <limit effort="1" velocity="20" lower="-0.785398163397448279" upper="0.785398163397448279"/>    
    <joint_properties friction="0.0"/>    
  </joint>  

  <joint name="right_ank_B11" type="revolute">    
    <origin xyz="0.0079999999999999984318 0.015000000000000041078 -0.01150000000000000154" rpy="1.570796326794896558 -1.5520170643097170871 -1.5707963267946734032"/>    
    <parent link="right_calf_link"/>    
    <child link="ball_joint_container"/>    
    <axis xyz="0 0 1"/>    
    <limit effort="1" velocity="20" lower="-0.785398163397448279" upper="0.785398163397448279"/>    
    <joint_properties friction="0.0"/>    
  </joint>  

  <link name="ball_joint_container_2">    
    <visual>      
      <origin xyz="0 0 0" rpy="0 -0 0"/>      
      <geometry>        
        <mesh filename="package:///meshes/right_ball_joint_container_2_visual.stl"/>        
      </geometry>      
      <material name="ball_joint_container_2_material">        
        <color rgba="0.61568627450980395466 0.81176470588235294379 0.9294117647058824927 1.0"/>        
      </material>      
    </visual>    
    <collision>      
      <origin xyz="0 0 0" rpy="0 -0 0"/>      
      <geometry>        
        <mesh filename="package:///meshes/right_ball_joint_container_2_collision.stl"/>        
      </geometry>      
    </collision>    
    <inertial>      
      <origin xyz="3.9416613817106338088e-18 -1.2135113793952178508e-19 -0.0097125341669083396778" rpy="0 0 0"/>      
      <mass value="4.8037356425330562243e-05"/>      
      <inertia ixx="7.1865480628741645687e-10" ixy="1.6457413421051102025e-27" ixz="2.8064713926205731665e-38" iyy="8.475420427718555978e-10" iyz="-5.5415728254535032661e-38" izz="1.8625314111651911712e-10"/>      
    </inertial>    
  </link>  

  <link name="ball_joint_ball_2">    
    <visual>      
      <origin xyz="0 0 0" rpy="0 -0 0"/>      
      <geometry>        
        <mesh filename="package:///meshes/right_ball_joint_ball_2_visual.stl"/>        
      </geometry>      
      <material name="ball_joint_ball_2_material">        
        <color rgba="0.3291302810242056065 0.44310466418644928188 0.69204871161977121741 1.0"/>        
      </material>      
    </visual>    
    <collision>      
      <origin xyz="0 0 0" rpy="0 -0 0"/>      
      <geometry>        
        <mesh filename="package:///meshes/right_ball_joint_ball_2_collision.stl"/>        
      </geometry>      
    </collision>    
    <inertial>      
      <origin xyz="-9.2721964255877919942e-20 -0.0010308669810016374193 -2.8882981434546580683e-18" rpy="0 0 0"/>      
      <mass value="4.4053796295264623832e-05"/>      
      <inertia ixx="3.1285011349692546184e-10" ixy="-1.2044196648625981514e-25" ixz="9.0333129686829541926e-29" iyy="6.2569568612795824846e-11" iyz="-6.0739966589080848352e-26" izz="3.1285321460376586754e-10"/>      
    </inertial>    
  </link>  

  <link name="12lf_2">    
    <visual>      
      <origin xyz="0 0 0" rpy="0 -0 0"/>      
      <geometry>        
        <mesh filename="package:///meshes/right_12lf_2_visual.stl"/>        
      </geometry>      
      <material name="12lf_2_material">        
        <color rgba="0.62004392096503546661 0.5883668461204021316 0.49897069027350277048 1.0"/>        
      </material>      
    </visual>    
    <collision>      
      <origin xyz="0 0 0" rpy="0 -0 0"/>      
      <geometry>        
        <mesh filename="package:///meshes/right_12lf_2_collision.stl"/>        
      </geometry>      
    </collision>    
    <inertial>      
      <origin xyz="0.0049084207226859476875 -0.00013802440006715249363 -0.029947003575835719202" rpy="0 0 0"/>      
      <mass value="0.044782197690790476186"/>      
      <inertia ixx="1.5260128420481137567e-05" ixy="2.295577409850246197e-08" ixz="-8.1364204861156651263e-08" iyy="1.8188469777200080575e-05" iyz="-5.5542241171383792034e-08" izz="5.149627388932166995e-06"/>      
    </inertial>    
  </link>  

  <link name="12lf_rod_2">    
    <visual>      
      <origin xyz="0 0 0" rpy="0 -0 0"/>      
      <geometry>        
        <mesh filename="package:///meshes/right_12lf_rod_2_visual.stl"/>        
      </geometry>      
      <material name="12lf_rod_2_material">        
        <color rgba="0.80250260812861884396 0.89340612183512713163 0.94491811293548189088 1.0"/>        
      </material>      
    </visual>    
    <collision>      
      <origin xyz="0 0 0" rpy="0 -0 0"/>      
      <geometry>        
        <mesh filename="package:///meshes/right_12lf_rod_2_collision.stl"/>        
      </geometry>      
    </collision>    
    <inertial>      
      <origin xyz="-6.3222084078698980818e-07 4.6933255123699131896e-07 -0.012893387334330494789" rpy="0 0 0"/>      
      <mass value="0.0025088292483592144512"/>      
      <inertia ixx="2.6944521128612086012e-07" ixy="7.1389570021050091532e-15" ixz="1.3562243142885940151e-11" iyy="2.6944520001668636302e-07" iyz="-1.008998837028744681e-11" izz="1.7809843599861015564e-08"/>      
    </inertial>    
  </link>  

  <joint name="right_ank_act2" type="prismatic">    
    <origin xyz="2.2722093371875529133e-06 -2.8553548414578244774e-15 -0.074779996992751840423" rpy="3.1415926535897922278 3.3072658899692120884e-15 -2.2021168238262864847"/>    
    <parent link="12lf_2"/>    
    <child link="12lf_rod_2"/>    
    <axis xyz="0 0 1"/>    
    <limit effort="1" velocity="20" lower="0" upper="0.040000000000000000833"/>    
    <joint_properties friction="0.0"/>    
  </joint>  

  <joint name="right_ank_B32" type="revolute">    
    <origin xyz="3.4694469519536141888e-18 -0.0064387505004004086384 -6.9388939039072283776e-18" rpy="-1.570796326794896558 -0.17993145005738314657 -8.7569826039094258121e-17"/>    
    <parent link="ball_joint_ball_2"/>    
    <child link="12lf_2"/>    
    <axis xyz="0 0 1"/>    
    <limit effort="1" velocity="20" lower="-0.785398163397448279" upper="0.785398163397448279"/>    
    <joint_properties friction="0.0"/>    
  </joint>  

  <joint name="right_ank_B22" type="revolute">    
    <origin xyz="3.4694469519536141888e-18 0 -0.011499999999999998071" rpy="-1.57079632679489678 -1.5664376509754476263 -1.5707963267945079799"/>    
    <parent link="ball_joint_container_2"/>    
    <child link="ball_joint_ball_2"/>    
    <axis xyz="0 0 1"/>    
    <limit effort="1" velocity="20" lower="-0.785398163397448279" upper="0.785398163397448279"/>    
    <joint_properties friction="0.0"/>    
  </joint>  

  <joint name="right_ank_B12" type="revolute">    
    <origin xyz="0.008000000000000003636 0.015000000000000041078 0.028300000000000019584" rpy="-1.570796326794896558 -1.5521341097221632577 1.5707963267948059638"/>    
    <parent link="right_calf_link"/>    
    <child link="ball_joint_container_2"/>    
    <axis xyz="0 0 1"/>    
    <limit effort="1" velocity="20" lower="-0.785398163397448279" upper="0.785398163397448279"/>    
    <joint_properties friction="0.0"/>    
  </joint>  

  <joint name="right_knee" type="revolute">    
    <origin xyz="-8.4133172564547814973e-15 0.095999999999998697486 0.027400000000003574274" rpy="3.1415926535897926719 9.3467860356166481656e-14 -3.1415926535895137839"/>    
    <parent link="right_hip_pitch_link"/>    
    <child link="right_calf_link"/>    
    <axis xyz="0 0 1"/>    
    <limit effort="1" velocity="20" lower="-1.570796326794896558" upper="0"/>    
    <joint_properties friction="0.0"/>    
  </joint>  

  <joint name="right_hip_pitch" type="revolute">    
    <origin xyz="0.024000000358075784801 -0.019000000000012132184 -0.01899999984755619542" rpy="-1.5707963267951119413 -1.5707963267945823649 0"/>    
    <parent link="hip_roll_link"/>    
    <child link="right_hip_pitch_link"/>    
    <axis xyz="0 0 1"/>    
    <limit effort="1" velocity="20" lower="-1.570796326794896558" upper="1.570796326794896558"/>    
    <joint_properties friction="0.0"/>    
  </joint>  

  <joint name="right_hip_roll" type="revolute">    
    <origin xyz="0.018999999999999881567 -3.350043888987566044e-18 -0.026000000000000002276" rpy="2.9582283942363596652e-30 1.5707963267948799047 0"/>    
    <parent link="hip_yaw_link"/>    
    <child link="hip_roll_link"/>    
    <axis xyz="0 0 1"/>    
    <limit effort="1" velocity="20" lower="-1.570796326794896558" upper="0.785398163397448279"/>    
    <joint_properties friction="0.0"/>    
  </joint>  


</robot>