<?xml version="1.0" ?><robot name="left_arm_umi">  
  <link name="sho_pitch_link">    
    <visual>      
      <origin xyz="0 0 0" rpy="0 -0 0"/>      
      <geometry>        
        <mesh filename="package:///meshes/left_sho_pitch_link_visual.stl"/>        
      </geometry>      
      <material name="sho_pitch_link_material">        
        <color rgba="0.61568627450980395466 0.81176470588235294379 0.92941176470588238168 1.0"/>        
      </material>      
    </visual>    
    <collision>      
      <origin xyz="0 0 0" rpy="0 -0 0"/>      
      <geometry>        
        <mesh filename="package:///meshes/left_sho_pitch_link_collision.stl"/>        
      </geometry>      
    </collision>    
    <inertial>      
      <origin xyz="5.8254248341382494532e-11 -5.1264642561121175806e-05 0.0082440788127094936227" rpy="0 0 0"/>      
      <mass value="0.0086000000000000017403"/>      
      <inertia ixx="1.2272887040545800343e-06" ixy="-2.142994419938170081e-14" ixz="-8.5847198770509101802e-15" iyy="2.9107306060364628558e-06" iyz="7.4623841398182984748e-09" izz="3.0803135950773500398e-06"/>      
    </inertial>    
  </link>  

  <link name="2xl430_gears">    
    <visual>      
      <origin xyz="0 0 0" rpy="0 -0 0"/>      
      <geometry>        
        <mesh filename="package:///meshes/left_2xl430_gears_visual.stl"/>        
      </geometry>      
      <material name="2xl430_gears_material">        
        <color rgba="0.75605985687944088358 0.8580469596269301169 0.91320266199377464478 1.0"/>        
      </material>      
    </visual>    
    <collision>      
      <origin xyz="0 0 0" rpy="0 -0 0"/>      
      <geometry>        
        <mesh filename="package:///meshes/left_2xl430_gears_collision.stl"/>        
      </geometry>      
    </collision>    
    <inertial>      
      <origin xyz="-0.011593155021926912496 -0.0024238821558102432129 -0.018551095523800652243" rpy="0 0 0"/>      
      <mass value="0.11800003674524907338"/>      
      <inertia ixx="2.751155493265647906e-05" ixy="8.9994756794951591073e-07" ixz="-2.3362914879653014433e-08" iyy="3.2796647067985431473e-05" iyz="-6.5715261571464242683e-07" izz="3.5775886684226098863e-05"/>      
    </inertial>    
  </link>  

  <link name="spur_1m_24t_drive">    
    <visual>      
      <origin xyz="0 0 0" rpy="0 -0 0"/>      
      <geometry>        
        <mesh filename="package:///meshes/left_spur_1m_24t_drive_visual.stl"/>        
      </geometry>      
      <material name="spur_1m_24t_drive_material">        
        <color rgba="0.61568627450980395466 0.81176470588235294379 0.92941176470588238168 1.0"/>        
      </material>      
    </visual>    
    <collision>      
      <origin xyz="0 0 0" rpy="0 -0 0"/>      
      <geometry>        
        <mesh filename="package:///meshes/left_spur_1m_24t_drive_collision.stl"/>        
      </geometry>      
    </collision>    
    <inertial>      
      <origin xyz="-7.7521288200634483028e-15 -1.2138469724092915918e-16 0.0047949116178401451557" rpy="0 0 0"/>      
      <mass value="0.003199999999999999286"/>      
      <inertia ixx="1.4019331346159885055e-07" ixy="1.6002409988992536307e-15" ixz="1.2970739157782480749e-36" iyy="1.4019331260388780891e-07" iyz="2.0673934083389124603e-36" izz="2.3838919844264052706e-07"/>      
    </inertial>    
  </link>  

  <joint name="left_sho_yaw_drive" type="revolute">    
    <origin xyz="-0.024000000716141004636 -0.019000000152450596813 -0.019000000152443286688" rpy="1.5707963267948328312 -1.2258104172924911424e-15 7.6362147953450801566e-14"/>    
    <parent link="2xl430_gears"/>    
    <child link="spur_1m_24t_drive"/>    
    <axis xyz="0 0 1"/>    
    <limit effort="1" velocity="20" lower="-2.6179938779914944114" upper="2.6179938779914944114"/>    
    <joint_properties friction="0.0"/>    
  </joint>  

  <link name="spur_1m_24t_driven">    
    <visual>      
      <origin xyz="0 0 0" rpy="0 -0 0"/>      
      <geometry>        
        <mesh filename="package:///meshes/left_spur_1m_24t_driven_visual.stl"/>        
      </geometry>      
      <material name="spur_1m_24t_driven_material">        
        <color rgba="0.23137254901960788156 0.38039215686274502337 0.7058823529411765163 1.0"/>        
      </material>      
    </visual>    
    <collision>      
      <origin xyz="0 0 0" rpy="0 -0 0"/>      
      <geometry>        
        <mesh filename="package:///meshes/left_spur_1m_24t_driven_collision.stl"/>        
      </geometry>      
    </collision>    
    <inertial>      
      <origin xyz="2.3631092538577092045e-18 -5.8047077769919345427e-15 -0.00097054817521927832808" rpy="0 0 0"/>      
      <mass value="0.0026999999999999997093"/>      
      <inertia ixx="1.2036234079571063062e-07" ixy="-5.3408894128227318454e-38" ixz="-1.2781954363449668068e-37" iyy="1.2036234079571044533e-07" iyz="-1.7534228904356342696e-37" izz="2.2847261745924530022e-07"/>      
    </inertial>    
  </link>  

  <link name="sho_yaw_link">    
    <visual>      
      <origin xyz="0 0 0" rpy="0 -0 0"/>      
      <geometry>        
        <mesh filename="package:///meshes/left_sho_yaw_link_visual.stl"/>        
      </geometry>      
      <material name="sho_yaw_link_material">        
        <color rgba="0.61568627450980395466 0.81176470588235294379 0.92941176470588238168 1.0"/>        
      </material>      
    </visual>    
    <collision>      
      <origin xyz="0 0 0" rpy="0 -0 0"/>      
      <geometry>        
        <mesh filename="package:///meshes/left_sho_yaw_link_collision.stl"/>        
      </geometry>      
    </collision>    
    <inertial>      
      <origin xyz="-6.9736191503192354276e-18 3.8819761434054477756e-18 -0.024303257848520158635" rpy="0 0 0"/>      
      <mass value="0.014500000000000016348"/>      
      <inertia ixx="9.0846670053041416663e-06" ixy="3.6224092800135937916e-13" ixz="2.4472316436879021842e-43" iyy="5.6910950712097533498e-06" iyz="1.6220788372704002964e-35" izz="4.4819609845549026751e-06"/>      
    </inertial>    
  </link>  

  <link name="2xl430_gears_2">    
    <visual>      
      <origin xyz="0 0 0" rpy="0 -0 0"/>      
      <geometry>        
        <mesh filename="package:///meshes/left_2xl430_gears_2_visual.stl"/>        
      </geometry>      
      <material name="2xl430_gears_2_material">        
        <color rgba="0.75605985687944088358 0.8580469596269301169 0.91320266199377464478 1.0"/>        
      </material>      
    </visual>    
    <collision>      
      <origin xyz="0 0 0" rpy="0 -0 0"/>      
      <geometry>        
        <mesh filename="package:///meshes/left_2xl430_gears_2_collision.stl"/>        
      </geometry>      
    </collision>    
    <inertial>      
      <origin xyz="-0.011593155021923005898 -0.0024238821558094001372 -0.018551095523810002402" rpy="0 0 0"/>      
      <mass value="0.11800003674524907338"/>      
      <inertia ixx="2.7511554932656817873e-05" ixy="8.999475679531490468e-07" ixz="-2.3362914881072982451e-08" iyy="3.2796647067987166196e-05" iyz="-6.5715261571836672482e-07" izz="3.5775886684226451229e-05"/>      
    </inertial>    
  </link>  

  <link name="spur_1m_24t_drive_2">    
    <visual>      
      <origin xyz="0 0 0" rpy="0 -0 0"/>      
      <geometry>        
        <mesh filename="package:///meshes/left_spur_1m_24t_drive_2_visual.stl"/>        
      </geometry>      
      <material name="spur_1m_24t_drive_2_material">        
        <color rgba="0.61568627450980395466 0.81176470588235294379 0.92941176470588238168 1.0"/>        
      </material>      
    </visual>    
    <collision>      
      <origin xyz="0 0 0" rpy="0 -0 0"/>      
      <geometry>        
        <mesh filename="package:///meshes/left_spur_1m_24t_drive_2_collision.stl"/>        
      </geometry>      
    </collision>    
    <inertial>      
      <origin xyz="-7.7451899261595410744e-15 -1.2138469726677875054e-16 0.0047949116178401373495" rpy="0 0 0"/>      
      <mass value="0.003199999999999999286"/>      
      <inertia ixx="1.4019331346159885055e-07" ixy="1.600241002207976081e-15" ixz="1.0203580191619788986e-37" iyy="1.4019331260388780891e-07" iyz="1.7790518002117816615e-36" izz="2.3838919844264052706e-07"/>      
    </inertial>    
  </link>  

  <joint name="left_elbow_yaw_drive" type="revolute">    
    <origin xyz="-0.024000000716137528251 -0.019000000152447529822 -0.019000000152459547986" rpy="1.570796326795050879 -2.4708842848455862195e-13 -6.0621939164177121919e-14"/>    
    <parent link="2xl430_gears_2"/>    
    <child link="spur_1m_24t_drive_2"/>    
    <axis xyz="0 0 1"/>    
    <limit effort="1" velocity="20" lower="-2.6179938779914944114" upper="2.6179938779914944114"/>    
    <joint_properties friction="0.0"/>    
  </joint>  

  <link name="spur_1m_24t_driven_2">    
    <visual>      
      <origin xyz="0 0 0" rpy="0 -0 0"/>      
      <geometry>        
        <mesh filename="package:///meshes/left_spur_1m_24t_driven_2_visual.stl"/>        
      </geometry>      
      <material name="spur_1m_24t_driven_2_material">        
        <color rgba="0.23137254901960788156 0.38039215686274502337 0.7058823529411765163 1.0"/>        
      </material>      
    </visual>    
    <collision>      
      <origin xyz="0 0 0" rpy="0 -0 0"/>      
      <geometry>        
        <mesh filename="package:///meshes/left_spur_1m_24t_driven_2_collision.stl"/>        
      </geometry>      
    </collision>    
    <inertial>      
      <origin xyz="2.3631092538563652906e-18 -5.8084160300697200678e-15 -0.00097054817521927117235" rpy="0 0 0"/>      
      <mass value="0.0026999999999999997093"/>      
      <inertia ixx="1.2036234079571063062e-07" ixy="7.3086750997471089944e-48" ixz="2.1898678400673001189e-36" iyy="1.2036234079571044533e-07" iyz="-3.2661869446708729184e-38" izz="2.2847261745924530022e-07"/>      
    </inertial>    
  </link>  

  <link name="elb_yaw_link">    
    <visual>      
      <origin xyz="0 0 0" rpy="0 -0 0"/>      
      <geometry>        
        <mesh filename="package:///meshes/left_elb_yaw_link_visual.stl"/>        
      </geometry>      
      <material name="elb_yaw_link_material">        
        <color rgba="0.61568627450980395466 0.81176470588235294379 0.92941176470588227065 1.0"/>        
      </material>      
    </visual>    
    <collision>      
      <origin xyz="0 0 0" rpy="0 -0 0"/>      
      <geometry>        
        <mesh filename="package:///meshes/left_elb_yaw_link_collision.stl"/>        
      </geometry>      
    </collision>    
    <inertial>      
      <origin xyz="5.3127688027619531677e-08 0.0019833638641961700601 -0.023416643551549966296" rpy="0 0 0"/>      
      <mass value="0.017500000000000008604"/>      
      <inertia ixx="1.4134344903109199776e-05" ixy="1.6945783921977629828e-12" ixz="-1.1286398721856847891e-11" iyy="6.6435900776211357345e-06" iyz="1.054522707725306605e-06" izz="8.9925290757999044535e-06"/>      
    </inertial>    
  </link>  

  <link name="spur_1m_24t_driven_3">    
    <visual>      
      <origin xyz="0 0 0" rpy="0 -0 0"/>      
      <geometry>        
        <mesh filename="package:///meshes/left_spur_1m_24t_driven_3_visual.stl"/>        
      </geometry>      
      <material name="spur_1m_24t_driven_3_material">        
        <color rgba="0.23137254901960788156 0.38039215686274502337 0.7058823529411765163 1.0"/>        
      </material>      
    </visual>    
    <collision>      
      <origin xyz="0 0 0" rpy="0 -0 0"/>      
      <geometry>        
        <mesh filename="package:///meshes/left_spur_1m_24t_driven_3_collision.stl"/>        
      </geometry>      
    </collision>    
    <inertial>      
      <origin xyz="2.3631092538576868638e-18 -5.8047077769919376981e-15 -0.0025705481752192754774" rpy="0 0 0"/>      
      <mass value="0.0026999999999999997093"/>      
      <inertia ixx="1.2036234079571068356e-07" ixy="7.4656354546063931248e-37" ixz="-3.914926905832806072e-37" iyy="1.2036234079571044533e-07" iyz="1.970873732535265324e-36" izz="2.284726174592454061e-07"/>      
    </inertial>    
  </link>  

  <link name="2xl430_gears_3">    
    <visual>      
      <origin xyz="0 0 0" rpy="0 -0 0"/>      
      <geometry>        
        <mesh filename="package:///meshes/left_2xl430_gears_3_visual.stl"/>        
      </geometry>      
      <material name="2xl430_gears_3_material">        
        <color rgba="0.75605985687944088358 0.8580469596269301169 0.91320266199377464478 1.0"/>        
      </material>      
    </visual>    
    <collision>      
      <origin xyz="0 0 0" rpy="0 -0 0"/>      
      <geometry>        
        <mesh filename="package:///meshes/left_2xl430_gears_3_collision.stl"/>        
      </geometry>      
    </collision>    
    <inertial>      
      <origin xyz="0.00044890447620203475154 0.011593154663843372246 -0.024576117996641427127" rpy="0 0 0"/>      
      <mass value="0.11800003674524907338"/>      
      <inertia ixx="3.5775886684225746497e-05" ixy="2.336291487979269546e-08" ixz="6.5715261571760174819e-07" iyy="2.7511554932657752997e-05" iyz="8.9994756795280197505e-07" izz="3.2796647067985411144e-05"/>      
    </inertial>    
  </link>  

  <link name="spur_1m_24t_drive_3">    
    <visual>      
      <origin xyz="0 0 0" rpy="0 -0 0"/>      
      <geometry>        
        <mesh filename="package:///meshes/left_spur_1m_24t_drive_3_visual.stl"/>        
      </geometry>      
      <material name="spur_1m_24t_drive_3_material">        
        <color rgba="0.61568627450980395466 0.81176470588235294379 0.92941176470588238168 1.0"/>        
      </material>      
    </visual>    
    <collision>      
      <origin xyz="0 0 0" rpy="0 -0 0"/>      
      <geometry>        
        <mesh filename="package:///meshes/left_spur_1m_24t_drive_3_collision.stl"/>        
      </geometry>      
    </collision>    
    <inertial>      
      <origin xyz="-7.7521288200634483028e-15 -1.2138469724092955362e-16 0.0047949116178401425536" rpy="0 0 0"/>      
      <mass value="0.003199999999999999286"/>      
      <inertia ixx="1.4019331346159887702e-07" ixy="1.6002410075199782595e-15" ixz="-7.0751418124497800165e-36" iyy="1.4019331260388786185e-07" iyz="4.8527069935814632135e-37" izz="2.3838919844264052706e-07"/>      
    </inertial>    
  </link>  

  <joint name="left_wrist_pitch_drive" type="revolute">    
    <origin xyz="-1.524411552671568168e-10 0.024000000358058659611 -0.0080000000000068835493" rpy="9.3688120281041050571e-15 -2.4754138690627644039e-13 -1.570796326794971387"/>    
    <parent link="2xl430_gears_3"/>    
    <child link="spur_1m_24t_drive_3"/>    
    <axis xyz="0 0 1"/>    
    <limit effort="1" velocity="20" lower="-1.9198621771937625091" upper="1.3962634015954635824"/>    
    <joint_properties friction="0.0"/>    
  </joint>  

  <link name="hand">    
    <visual>      
      <origin xyz="0 0 0" rpy="0 -0 0"/>      
      <geometry>        
        <mesh filename="package:///meshes/left_hand_visual.stl"/>        
      </geometry>      
      <material name="hand_material">        
        <color rgba="0.64149913129808899814 0.67624720774385715938 0.69709605361131798951 1.0"/>        
      </material>      
    </visual>    
    <collision>      
      <origin xyz="0 0 0" rpy="0 -0 0"/>      
      <geometry>        
        <mesh filename="package:///meshes/left_hand_collision.stl"/>        
      </geometry>      
    </collision>    
    <inertial>      
      <origin xyz="-0.00370786937874344278 0.042127339671143314292 -0.018490328271618894362" rpy="0 0 0"/>      
      <mass value="0.039499999999999979572"/>      
      <inertia ixx="2.4635502047218482176e-05" ixy="6.2323015589610943666e-07" ixz="1.4391446178023665249e-08" iyy="2.5475207220956888024e-05" iyz="-4.0870433587615386295e-08" izz="1.3466679248868380149e-05"/>      
    </inertial>    
  </link>  

  <joint name="left_wrist_roll" type="revolute">    
    <origin xyz="0.019000000000007889051 -3.5808161991113252043e-10 -0.027000000152448057344" rpy="3.141592653589793116 -1.5707963267945475039 0"/>    
    <parent link="2xl430_gears_3"/>    
    <child link="hand"/>    
    <axis xyz="0 0 1"/>    
    <limit effort="1" velocity="20" lower="-1.9198621771937625091" upper="1.3962634015954635824"/>    
    <joint_properties friction="0.0"/>    
  </joint>  

  <link name="wrist_bearing_plate">    
    <visual>      
      <origin xyz="0 0 0" rpy="0 -0 0"/>      
      <geometry>        
        <mesh filename="package:///meshes/left_wrist_bearing_plate_visual.stl"/>        
      </geometry>      
      <material name="wrist_bearing_plate_material">        
        <color rgba="0.64496316278892629192 0.69011804996940517842 0.71706771073555874985 1.0"/>        
      </material>      
    </visual>    
    <collision>      
      <origin xyz="0 0 0" rpy="0 -0 0"/>      
      <geometry>        
        <mesh filename="package:///meshes/left_wrist_bearing_plate_collision.stl"/>        
      </geometry>      
    </collision>    
    <inertial>      
      <origin xyz="-0.0075835583121500035539 -0.015499999999999982542 -0.0018386323705903340111" rpy="0 0 0"/>      
      <mass value="0.0049000367468305565735"/>      
      <inertia ixx="4.9707430109150129132e-07" ixy="4.8291928725878417577e-23" ixz="1.8100904820814005469e-08" iyy="7.1268523603538563647e-07" iyz="1.2467788443080162633e-23" izz="1.1919657811600107117e-06"/>      
    </inertial>    
  </link>  

  <joint name="left_wrist_pitch_fixed" type="fixed">    
    <origin xyz="0.015500000000007499099 -1.7430501486614957685e-14 -0.044999999999998915867" rpy="4.0578651550042264519e-14 -2.8213542612434331081e-13 -1.570796326794906328"/>    
    <parent link="2xl430_gears_3"/>    
    <child link="wrist_bearing_plate"/>    
    <axis xyz="0 0 1"/>    
    <limit effort="1" velocity="20"/>    
    <joint_properties friction="0.0"/>    
  </joint>  

  <joint name="left_wrist_pitch_driven" type="revolute">    
    <origin xyz="2.7755575615628913511e-17 -1.5777218104420236108e-30 -0.0015999999999999974746" rpy="-2.6917187154893159429e-14 -2.6645352591003750659e-14 -1.570796326794896558"/>    
    <parent link="spur_1m_24t_driven_3"/>    
    <child link="2xl430_gears_3"/>    
    <axis xyz="0 0 1"/>    
    <limit effort="1" velocity="20" lower="-1.3962634015954635824" upper="1.9198621771937625091"/>    
    <joint_properties friction="0.0"/>    
  </joint>  

  <joint name="left_wrist_roll_fixed" type="fixed">    
    <origin xyz="0 -0.025300000000000003042 -0.05200000000000001843" rpy="1.5707963267949236474 -1.5707963267948696906 0"/>    
    <parent link="elb_yaw_link"/>    
    <child link="spur_1m_24t_driven_3"/>    
    <axis xyz="0 0 1"/>    
    <limit effort="1" velocity="20"/>    
    <joint_properties friction="0.0"/>    
  </joint>  

  <joint name="left_elbow_yaw_fixed" type="fixed">    
    <origin xyz="1.5777218104420236108e-30 0 0.0015999999999999903189" rpy="-3.141592653589793116 6.8585119145426910438e-26 -7.6666465467942038555e-26"/>    
    <parent link="spur_1m_24t_driven_2"/>    
    <child link="elb_yaw_link"/>    
    <axis xyz="0 0 1"/>    
    <limit effort="1" velocity="20"/>    
    <joint_properties friction="0.0"/>    
  </joint>  

  <joint name="left_elbow_yaw_driven" type="revolute">    
    <origin xyz="-3.5806398471227574021e-10 -0.027000000152453157432 -0.0190000000000067025" rpy="1.5707963267949571762 1.5707963267947377961 0"/>    
    <parent link="2xl430_gears_2"/>    
    <child link="spur_1m_24t_driven_2"/>    
    <axis xyz="0 0 1"/>    
    <limit effort="1" velocity="20" lower="-2.6179938779914944114" upper="2.6179938779914944114"/>    
    <joint_properties friction="0.0"/>    
  </joint>  

  <joint name="left_elbow_roll" type="revolute">    
    <origin xyz="2.0816681711721685133e-16 -0.019000000000000002998 -0.059000000000000059341" rpy="1.570796326794896558 -8.2694607970959069176e-16 -2.2204460490005989148e-16"/>    
    <parent link="sho_yaw_link"/>    
    <child link="2xl430_gears_2"/>    
    <axis xyz="0 0 1"/>    
    <limit effort="1" velocity="20" lower="-1.9198621771937625091" upper="2.4434609527920612138"/>    
    <joint_properties friction="0.0"/>    
  </joint>  

  <joint name="left_sho_yaw_fixed" type="fixed">    
    <origin xyz="0 7.8886090522101180541e-31 0.0015999999999999868494" rpy="-3.1415926535897917837 7.7715611727616959238e-16 7.7715611725338728944e-16"/>    
    <parent link="spur_1m_24t_driven"/>    
    <child link="sho_yaw_link"/>    
    <axis xyz="0 0 1"/>    
    <limit effort="1" velocity="20"/>    
    <joint_properties friction="0.0"/>    
  </joint>  

  <joint name="left_sho_yaw_driven" type="revolute">    
    <origin xyz="-3.5807162096501699011e-10 -0.027000000152450989027 -0.01899999999999986075" rpy="1.5707963267948492625 8.0395273179087848749e-14 9.4924068605497912938e-14"/>    
    <parent link="2xl430_gears"/>    
    <child link="spur_1m_24t_driven"/>    
    <axis xyz="0 0 1"/>    
    <limit effort="1" velocity="20" lower="-2.6179938779914944114" upper="2.6179938779914944114"/>    
    <joint_properties friction="0.0"/>    
  </joint>  

  <joint name="left_sho_roll" type="revolute">    
    <origin xyz="-0.018999999999999999528 0.00099999999999997161472 0.026999999999999999695" rpy="-3.141592653589793116 1.5707963267948936714 0"/>    
    <parent link="sho_pitch_link"/>    
    <child link="2xl430_gears"/>    
    <axis xyz="0 0 1"/>    
    <limit effort="1" velocity="20" lower="-1.570796326794896558" upper="0.34906585039886589561"/>    
    <joint_properties friction="0.0"/>    
  </joint>  


</robot>