<?xml version="1.0" ?><robot name="right_arm_hand">  
  <link name="sho_pitch_link">    
    <visual>      
      <origin xyz="0 0 0" rpy="0 -0 0"/>      
      <geometry>        
        <mesh filename="package:///meshes/right_sho_pitch_link_visual.stl"/>        
      </geometry>      
      <material name="sho_pitch_link_material">        
        <color rgba="0.61568627450980395466 0.81176470588235294379 0.92941176470588238168 1.0"/>        
      </material>      
    </visual>    
    <collision>      
      <origin xyz="0 0 0" rpy="0 -0 0"/>      
      <geometry>        
        <mesh filename="package:///meshes/right_sho_pitch_link_collision.stl"/>        
      </geometry>      
    </collision>    
    <inertial>      
      <origin xyz="5.8254248833227925391e-11 -5.1264642561120870874e-05 0.0082440788127094936227" rpy="0 0 0"/>      
      <mass value="0.0086000000000000017403"/>      
      <inertia ixx="1.2272887040545796108e-06" ixy="-2.1429944210751515172e-14" ixz="-8.5847198977296208559e-15" iyy="2.9107306060364624323e-06" iyz="7.4623841398182868942e-09" izz="3.0803135950773496163e-06"/>      
    </inertial>    
  </link>  

  <link name="2xl430_gears">    
    <visual>      
      <origin xyz="0 0 0" rpy="0 -0 0"/>      
      <geometry>        
        <mesh filename="package:///meshes/right_2xl430_gears_visual.stl"/>        
      </geometry>      
      <material name="2xl430_gears_material">        
        <color rgba="0.7560598568794409946 0.8580469596269301169 0.91320266199377464478 1.0"/>        
      </material>      
    </visual>    
    <collision>      
      <origin xyz="0 0 0" rpy="0 -0 0"/>      
      <geometry>        
        <mesh filename="package:///meshes/right_2xl430_gears_collision.stl"/>        
      </geometry>      
    </collision>    
    <inertial>      
      <origin xyz="-0.011579403981034309609 -0.0024225766141400444445 -0.018551095523803729642" rpy="0 0 0"/>      
      <mass value="0.11800003674524910113"/>      
      <inertia ixx="2.74822980832362953e-05" ixy="9.2729623432968279486e-07" ixz="-2.2634512004040774455e-08" iyy="3.2770742486672703063e-05" iyz="-6.5708346020122078569e-07" izz="3.5767957544054489356e-05"/>      
    </inertial>    
  </link>  

  <link name="spur_1m_24t_drive">    
    <visual>      
      <origin xyz="0 0 0" rpy="0 -0 0"/>      
      <geometry>        
        <mesh filename="package:///meshes/right_spur_1m_24t_drive_visual.stl"/>        
      </geometry>      
      <material name="spur_1m_24t_drive_material">        
        <color rgba="0.61568627450980406568 0.81176470588235294379 0.92941176470588238168 1.0"/>        
      </material>      
    </visual>    
    <collision>      
      <origin xyz="0 0 0" rpy="0 -0 0"/>      
      <geometry>        
        <mesh filename="package:///meshes/right_spur_1m_24t_drive_collision.stl"/>        
      </geometry>      
    </collision>    
    <inertial>      
      <origin xyz="-7.7449201694380103674e-15 -1.2122842274909869457e-16 0.0047949116178401460231" rpy="0 0 0"/>      
      <mass value="0.0032000000000000001533"/>      
      <inertia ixx="1.4019331346159885055e-07" ixy="1.6002409988709471321e-15" ixz="1.6522681797794400838e-36" iyy="1.4019331260388783538e-07" iyz="-8.3216796199689772502e-37" izz="2.3838919844264060647e-07"/>      
    </inertial>    
  </link>  

  <joint name="right_sho_yaw_drive" type="revolute">    
    <origin xyz="-0.024000000716138239487 -0.019000000152445333662 -0.019000000152448428409" rpy="1.5707963267949289765 -7.4034293748640148514e-14 5.4343716361633809931e-15"/>    
    <parent link="2xl430_gears"/>    
    <child link="spur_1m_24t_drive"/>    
    <axis xyz="0 0 1"/>    
    <limit effort="1" velocity="20" lower="-2.6179938779914944114" upper="2.6179938779914944114"/>    
    <joint_properties friction="0.0"/>    
  </joint>  

  <link name="spur_1m_24t_driven">    
    <visual>      
      <origin xyz="0 0 0" rpy="0 -0 0"/>      
      <geometry>        
        <mesh filename="package:///meshes/right_spur_1m_24t_driven_visual.stl"/>        
      </geometry>      
      <material name="spur_1m_24t_driven_material">        
        <color rgba="0.23137254901960788156 0.38039215686274507888 0.7058823529411765163 1.0"/>        
      </material>      
    </visual>    
    <collision>      
      <origin xyz="0 0 0" rpy="0 -0 0"/>      
      <geometry>        
        <mesh filename="package:///meshes/right_spur_1m_24t_driven_collision.stl"/>        
      </geometry>      
    </collision>    
    <inertial>      
      <origin xyz="2.3351569794102434061e-18 -5.8049097389032844891e-15 -0.00097054817521928168911" rpy="0 0 0"/>      
      <mass value="0.0027000000000000001429"/>      
      <inertia ixx="1.2036234079571068356e-07" ixy="0" ixz="0" iyy="1.203623407957104718e-07" iyz="5.3440906710062121485e-38" izz="2.2847261745924543257e-07"/>      
    </inertial>    
  </link>  

  <link name="sho_yaw_link">    
    <visual>      
      <origin xyz="0 0 0" rpy="0 -0 0"/>      
      <geometry>        
        <mesh filename="package:///meshes/right_sho_yaw_link_visual.stl"/>        
      </geometry>      
      <material name="sho_yaw_link_material">        
        <color rgba="0.61568627450980395466 0.81176470588235294379 0.92941176470588238168 1.0"/>        
      </material>      
    </visual>    
    <collision>      
      <origin xyz="0 0 0" rpy="0 -0 0"/>      
      <geometry>        
        <mesh filename="package:///meshes/right_sho_yaw_link_collision.stl"/>        
      </geometry>      
    </collision>    
    <inertial>      
      <origin xyz="-4.69694518243200415e-18 3.1874712151647975612e-18 -0.024303257848520158635" rpy="0 0 0"/>      
      <mass value="0.014500000000000007674"/>      
      <inertia ixx="9.084667005304133196e-06" ixy="3.6224092806514836327e-13" ixz="4.2856349173707358141e-43" iyy="5.6910950712097499617e-06" iyz="4.9879708115840687513e-36" izz="4.4819609845548958989e-06"/>      
    </inertial>    
  </link>  

  <link name="2xl430_gears_2">    
    <visual>      
      <origin xyz="0 0 0" rpy="0 -0 0"/>      
      <geometry>        
        <mesh filename="package:///meshes/right_2xl430_gears_2_visual.stl"/>        
      </geometry>      
      <material name="2xl430_gears_2_material">        
        <color rgba="0.7560598568794409946 0.8580469596269301169 0.91320266199377464478 1.0"/>        
      </material>      
    </visual>    
    <collision>      
      <origin xyz="0 0 0" rpy="0 -0 0"/>      
      <geometry>        
        <mesh filename="package:///meshes/right_2xl430_gears_2_collision.stl"/>        
      </geometry>      
    </collision>    
    <inertial>      
      <origin xyz="-0.011579403981040218077 -0.0024225766141398393134 -0.018551095523805894577" rpy="0 0 0"/>      
      <mass value="0.11800003674524910113"/>      
      <inertia ixx="2.7482298083237697987e-05" ixy="9.2729623432884147938e-07" ixz="-2.2634512003741295368e-08" iyy="3.2770742486673692397e-05" iyz="-6.5708346020153291733e-07" izz="3.5767957544055736189e-05"/>      
    </inertial>    
  </link>  

  <link name="spur_1m_24t_drive_2">    
    <visual>      
      <origin xyz="0 0 0" rpy="0 -0 0"/>      
      <geometry>        
        <mesh filename="package:///meshes/right_spur_1m_24t_drive_2_visual.stl"/>        
      </geometry>      
      <material name="spur_1m_24t_drive_2_material">        
        <color rgba="0.61568627450980406568 0.81176470588235294379 0.92941176470588238168 1.0"/>        
      </material>      
    </visual>    
    <collision>      
      <origin xyz="0 0 0" rpy="0 -0 0"/>      
      <geometry>        
        <mesh filename="package:///meshes/right_spur_1m_24t_drive_2_collision.stl"/>        
      </geometry>      
    </collision>    
    <inertial>      
      <origin xyz="-7.7587979572458248242e-15 -1.2122842274909869457e-16 0.0047949116178401382168" rpy="0 0 0"/>      
      <mass value="0.0032000000000000001533"/>      
      <inertia ixx="1.4019331346159885055e-07" ixy="1.6002409988709471321e-15" ixz="-1.168170481262866476e-35" iyy="1.4019331260388783538e-07" iyz="2.4795678825907445192e-36" izz="2.3838919844264060647e-07"/>      
    </inertial>    
  </link>  

  <joint name="right_elbow_yaw_drive" type="revolute">    
    <origin xyz="-0.024000000716147155966 -0.019000000152450832736 -0.019000000152450298441" rpy="1.5707963267949571762 2.9595367256237359919e-14 -6.4343145465762955833e-14"/>    
    <parent link="2xl430_gears_2"/>    
    <child link="spur_1m_24t_drive_2"/>    
    <axis xyz="0 0 1"/>    
    <limit effort="1" velocity="20" lower="-2.6179938779914944114" upper="2.6179938779914944114"/>    
    <joint_properties friction="0.0"/>    
  </joint>  

  <link name="spur_1m_24t_driven_2">    
    <visual>      
      <origin xyz="0 0 0" rpy="0 -0 0"/>      
      <geometry>        
        <mesh filename="package:///meshes/right_spur_1m_24t_driven_2_visual.stl"/>        
      </geometry>      
      <material name="spur_1m_24t_driven_2_material">        
        <color rgba="0.23137254901960788156 0.38039215686274507888 0.7058823529411765163 1.0"/>        
      </material>      
    </visual>    
    <collision>      
      <origin xyz="0 0 0" rpy="0 -0 0"/>      
      <geometry>        
        <mesh filename="package:///meshes/right_spur_1m_24t_driven_2_collision.stl"/>        
      </geometry>      
    </collision>    
    <inertial>      
      <origin xyz="-1.1342899725433707827e-18 -5.8049097389032868557e-15 -0.000970548175219288628" rpy="0 0 0"/>      
      <mass value="0.0027000000000000001429"/>      
      <inertia ixx="1.2036234079571068356e-07" ixy="0" ixz="0" iyy="1.203623407957104718e-07" iyz="-8.2412659182369258854e-37" izz="2.2847261745924543257e-07"/>      
    </inertial>    
  </link>  

  <link name="elb_yaw_link">    
    <visual>      
      <origin xyz="0 0 0" rpy="0 -0 0"/>      
      <geometry>        
        <mesh filename="package:///meshes/right_elb_yaw_link_visual.stl"/>        
      </geometry>      
      <material name="elb_yaw_link_material">        
        <color rgba="0.61568627450980395466 0.81176470588235294379 0.92941176470588227065 1.0"/>        
      </material>      
    </visual>    
    <collision>      
      <origin xyz="0 0 0" rpy="0 -0 0"/>      
      <geometry>        
        <mesh filename="package:///meshes/right_elb_yaw_link_collision.stl"/>        
      </geometry>      
    </collision>    
    <inertial>      
      <origin xyz="5.3127688027648185214e-08 0.001983363864196168759 -0.023416643551549966296" rpy="0 0 0"/>      
      <mass value="0.017500000000000001665"/>      
      <inertia ixx="1.4134344903109199776e-05" ixy="1.694578392200579355e-12" ixz="-1.1286398721858038578e-11" iyy="6.6435900776211340404e-06" iyz="1.0545227077253057579e-06" izz="8.9925290757998976773e-06"/>      
    </inertial>    
  </link>  

  <link name="spur_1m_24t_driven_3">    
    <visual>      
      <origin xyz="0 0 0" rpy="0 -0 0"/>      
      <geometry>        
        <mesh filename="package:///meshes/right_spur_1m_24t_driven_3_visual.stl"/>        
      </geometry>      
      <material name="spur_1m_24t_driven_3_material">        
        <color rgba="0.23137254901960788156 0.38039215686274507888 0.7058823529411765163 1.0"/>        
      </material>      
    </visual>    
    <collision>      
      <origin xyz="0 0 0" rpy="0 -0 0"/>      
      <geometry>        
        <mesh filename="package:///meshes/right_spur_1m_24t_driven_3_collision.stl"/>        
      </geometry>      
    </collision>    
    <inertial>      
      <origin xyz="2.3351569794102441765e-18 -5.8049097389032868557e-15 -0.0025705481752192824163" rpy="0 0 0"/>      
      <mass value="0.0027000000000000001429"/>      
      <inertia ixx="1.2036234079571068356e-07" ixy="-7.6954038306055239825e-37" ixz="6.0796998427618674805e-36" iyy="1.203623407957104718e-07" iyz="2.9665199080575669822e-38" izz="2.2847261745924543257e-07"/>      
    </inertial>    
  </link>  

  <link name="2xl430_gears_3">    
    <visual>      
      <origin xyz="0 0 0" rpy="0 -0 0"/>      
      <geometry>        
        <mesh filename="package:///meshes/right_2xl430_gears_3_visual.stl"/>        
      </geometry>      
      <material name="2xl430_gears_3_material">        
        <color rgba="0.7560598568794409946 0.8580469596269301169 0.91320266199377464478 1.0"/>        
      </material>      
    </visual>    
    <collision>      
      <origin xyz="0 0 0" rpy="0 -0 0"/>      
      <geometry>        
        <mesh filename="package:///meshes/right_2xl430_gears_3_collision.stl"/>        
      </geometry>      
    </collision>    
    <inertial>      
      <origin xyz="0.00044890447620021274979 0.011579403622967100046 -0.024577423538309651346" rpy="0 0 0"/>      
      <mass value="0.11800003674524910113"/>      
      <inertia ixx="3.5767957544056081778e-05" ixy="2.2634512003692971477e-08" ixz="6.5708346020098224004e-07" iyy="2.7482298083237135557e-05" iyz="9.2729623433063051885e-07" izz="3.2770742486673123191e-05"/>      
    </inertial>    
  </link>  

  <link name="spur_1m_24t_drive_3">    
    <visual>      
      <origin xyz="0 0 0" rpy="0 -0 0"/>      
      <geometry>        
        <mesh filename="package:///meshes/right_spur_1m_24t_drive_3_visual.stl"/>        
      </geometry>      
      <material name="spur_1m_24t_drive_3_material">        
        <color rgba="0.61568627450980406568 0.81176470588235294379 0.92941176470588238168 1.0"/>        
      </material>      
    </visual>    
    <collision>      
      <origin xyz="0 0 0" rpy="0 -0 0"/>      
      <geometry>        
        <mesh filename="package:///meshes/right_spur_1m_24t_drive_3_collision.stl"/>        
      </geometry>      
    </collision>    
    <inertial>      
      <origin xyz="-7.7518590633419175958e-15 -1.2122842274909869457e-16 0.004794911617840143421" rpy="0 0 0"/>      
      <mass value="0.0032000000000000001533"/>      
      <inertia ixx="1.4019331346159885055e-07" ixy="1.6002410034284993069e-15" ixz="1.1686733432993132789e-36" iyy="1.4019331260388780891e-07" iyz="-2.1243526921822021829e-37" izz="2.3838919844264060647e-07"/>      
    </inertial>    
  </link>  

  <joint name="right_wrist_pitch_drive" type="revolute">    
    <origin xyz="-1.5244304577405686261e-10 0.024000000358071177375 -0.0080000000000011797785" rpy="-1.0519265191422955506e-14 5.4953979628752545946e-14 -1.5707963267949167641"/>    
    <parent link="2xl430_gears_3"/>    
    <child link="spur_1m_24t_drive_3"/>    
    <axis xyz="0 0 1"/>    
    <limit effort="1" velocity="20" lower="-1.3962634015954635824" upper="1.9198621771937625091"/>    
    <joint_properties friction="0.0"/>    
  </joint>  

  <link name="hand">    
    <visual>      
      <origin xyz="0 0 0" rpy="0 -0 0"/>      
      <geometry>        
        <mesh filename="package:///meshes/right_hand_visual.stl"/>        
      </geometry>      
      <material name="hand_material">        
        <color rgba="0.61568627450980395466 0.81176470588235294379 0.92941176470588238168 1.0"/>        
      </material>      
    </visual>    
    <collision>      
      <origin xyz="0 0 0" rpy="0 -0 0"/>      
      <geometry>        
        <mesh filename="package:///meshes/right_hand_collision.stl"/>        
      </geometry>      
    </collision>    
    <inertial>      
      <origin xyz="-2.4899508580538796352e-10 0.040594531666389044311 -0.018520936085747969485" rpy="0 0 0"/>      
      <mass value="0.017000000000001441042"/>      
      <inertia ixx="9.2187594185322302979e-06" ixy="-1.5922040707505719383e-15" ixz="-1.0539511468854035967e-13" iyy="6.6718567758212730107e-06" iyz="2.1533596775200976319e-08" izz="3.778869841187656458e-06"/>      
    </inertial>    
  </link>  

  <joint name="right_wrist_roll" type="revolute">    
    <origin xyz="0.019000000000001921602 -3.5806768661217347471e-10 -0.027000000152449948193" rpy="-3.141592653589793116 -1.5707963267945153074 0"/>    
    <parent link="2xl430_gears_3"/>    
    <child link="hand"/>    
    <axis xyz="0 0 1"/>    
    <limit effort="1" velocity="20" lower="-1.3962634015954635824" upper="1.9198621771937625091"/>    
    <joint_properties friction="0.0"/>    
  </joint>  

  <link name="wrist_bearing_plate">    
    <visual>      
      <origin xyz="0 0 0" rpy="0 -0 0"/>      
      <geometry>        
        <mesh filename="package:///meshes/right_wrist_bearing_plate_visual.stl"/>        
      </geometry>      
      <material name="wrist_bearing_plate_material">        
        <color rgba="0.64496316278892629192 0.69011804996940528945 0.71706771073555886087 1.0"/>        
      </material>      
    </visual>    
    <collision>      
      <origin xyz="0 0 0" rpy="0 -0 0"/>      
      <geometry>        
        <mesh filename="package:///meshes/right_wrist_bearing_plate_collision.stl"/>        
      </geometry>      
    </collision>    
    <inertial>      
      <origin xyz="-0.0075835583121499515122 -0.015499999999999980807 -0.0018386323705903381311" rpy="0 0 0"/>      
      <mass value="0.0049000367468305548388"/>      
      <inertia ixx="4.9707430109150129132e-07" ixy="1.7595307898691874558e-22" ixz="1.8100904820814074952e-08" iyy="7.1268523603538605999e-07" iyz="-6.8569550891497160807e-23" izz="1.1919657811600115587e-06"/>      
    </inertial>    
  </link>  

  <joint name="right_wrist_pitch_fixed" type="fixed">    
    <origin xyz="0.015500000000003951589 4.4686476741162550752e-15 -0.045000000000003870237" rpy="5.3290705180300300612e-15 1.2051470932306253475e-13 -1.570796326794896558"/>    
    <parent link="2xl430_gears_3"/>    
    <child link="wrist_bearing_plate"/>    
    <axis xyz="0 0 1"/>    
    <limit effort="1" velocity="20"/>    
    <joint_properties friction="0.0"/>    
  </joint>  

  <joint name="right_wrist_pitch_driven" type="revolute">    
    <origin xyz="-2.7755575615628913511e-17 5.5220263365470826379e-30 -0.0015999999999999970409" rpy="8.7209719320528352177e-15 6.1232339997705582035e-17 1.5707963267948947816"/>    
    <parent link="spur_1m_24t_driven_3"/>    
    <child link="2xl430_gears_3"/>    
    <axis xyz="0 0 1"/>    
    <limit effort="1" velocity="20" lower="-1.9198621771937625091" upper="1.3962634015954635824"/>    
    <joint_properties friction="0.0"/>    
  </joint>  

  <joint name="right_wrist_roll_fixed" type="fixed">    
    <origin xyz="-3.9443045261050590271e-30 -0.025299999999999999573 -0.05200000000000001843" rpy="1.5707963267949385244 1.570796326794896558 0"/>    
    <parent link="elb_yaw_link"/>    
    <child link="spur_1m_24t_driven_3"/>    
    <axis xyz="0 0 1"/>    
    <limit effort="1" velocity="20"/>    
    <joint_properties friction="0.0"/>    
  </joint>  

  <joint name="right_elbow_yaw_fixed" type="fixed">    
    <origin xyz="-6.9388939039072283776e-18 0 0.0015999999999999625633" rpy="-3.1415926535897917837 -5.545896421255929151e-30 -1.570796326794896558"/>    
    <parent link="spur_1m_24t_driven_2"/>    
    <child link="elb_yaw_link"/>    
    <axis xyz="0 0 1"/>    
    <limit effort="1" velocity="20"/>    
    <joint_properties friction="0.0"/>    
  </joint>  

  <joint name="right_elbow_yaw_driven" type="revolute">    
    <origin xyz="-3.5807115258967847637e-10 -0.027000000152453060287 -0.019000000000002816719" rpy="1.5707963267949573982 3.0852757707134402472e-14 -1.047495423780654911e-13"/>    
    <parent link="2xl430_gears_2"/>    
    <child link="spur_1m_24t_driven_2"/>    
    <axis xyz="0 0 1"/>    
    <limit effort="1" velocity="20" lower="-2.6179938779914944114" upper="2.6179938779914944114"/>    
    <joint_properties friction="0.0"/>    
  </joint>  

  <joint name="right_elbow_roll" type="revolute">    
    <origin xyz="-3.4694469519536141888e-18 -0.018999999999999999528 -0.058999999999999996891" rpy="1.570796326794896558 -3.2439825080223504913e-13 -2.9976021665407794952e-15"/>    
    <parent link="sho_yaw_link"/>    
    <child link="2xl430_gears_2"/>    
    <axis xyz="0 0 1"/>    
    <limit effort="1" velocity="20" lower="-1.9198621771937625091" upper="2.4434609527920612138"/>    
    <joint_properties friction="0.0"/>    
  </joint>  

  <joint name="right_sho_yaw_fixed" type="fixed">    
    <origin xyz="0 1.1832913578315177081e-30 0.0015999999999999903189" rpy="3.141592653589793116 -0 0"/>    
    <parent link="spur_1m_24t_driven"/>    
    <child link="sho_yaw_link"/>    
    <axis xyz="0 0 1"/>    
    <limit effort="1" velocity="20"/>    
    <joint_properties friction="0.0"/>    
  </joint>  

  <joint name="right_sho_yaw_driven" type="revolute">    
    <origin xyz="-3.5806817233474674822e-10 -0.027000000152446659157 -0.019000000000003357953" rpy="1.5707963267949260899 -2.2055090607972632104e-14 -2.2204460492023508308e-16"/>    
    <parent link="2xl430_gears"/>    
    <child link="spur_1m_24t_driven"/>    
    <axis xyz="0 0 1"/>    
    <limit effort="1" velocity="20" lower="-2.6179938779914944114" upper="2.6179938779914944114"/>    
    <joint_properties friction="0.0"/>    
  </joint>  

  <joint name="right_sho_roll" type="revolute">    
    <origin xyz="-0.018999999999999999528 0.0010000000000000076102 0.027000000000000003164" rpy="-3.1415926535897797933 1.5707963267948090724 0"/>    
    <parent link="sho_pitch_link"/>    
    <child link="2xl430_gears"/>    
    <axis xyz="0 0 1"/>    
    <limit effort="1" velocity="20" lower="-1.570796326794896558" upper="0.34906585039886589561"/>    
    <joint_properties friction="0.0"/>    
  </joint>  


</robot>