<?xml version="1.0" ?><robot name="left_3R+RH5_leg">  
  <link name="hip_yaw_link">    
    <visual>      
      <origin xyz="0 0 0" rpy="0 -0 0"/>      
      <geometry>        
        <mesh filename="package:///meshes/left_hip_yaw_link_visual.stl"/>        
      </geometry>      
      <material name="hip_yaw_link_material">        
        <color rgba="0.61568627450980395466 0.81176470588235294379 0.9294117647058824927 1.0"/>        
      </material>      
    </visual>    
    <collision>      
      <origin xyz="0 0 0" rpy="0 -0 0"/>      
      <geometry>        
        <mesh filename="package:///meshes/left_hip_yaw_link_collision.stl"/>        
      </geometry>      
    </collision>    
    <inertial>      
      <origin xyz="1.7870850561133597049e-19 -1.785635794355923629e-19 -0.0098390489054830162358" rpy="0 0 0"/>      
      <mass value="0.009025883737097921064"/>      
      <inertia ixx="1.3230458239086463031e-06" ixy="-3.3592249637948231893e-24" ixz="-1.1251788840973426872e-52" iyy="3.8408510960331422723e-06" iyz="2.3044956050358327818e-34" izz="3.872139628579389935e-06"/>      
    </inertial>    
  </link>  

  <link name="hip_roll_link">    
    <visual>      
      <origin xyz="0 0 0" rpy="0 -0 0"/>      
      <geometry>        
        <mesh filename="package:///meshes/left_hip_roll_link_visual.stl"/>        
      </geometry>      
      <material name="hip_roll_link_material">        
        <color rgba="0.95018735644455865064 0.7067892720042843191 0.061612079402596720001 1.0"/>        
      </material>      
    </visual>    
    <collision>      
      <origin xyz="0 0 0" rpy="0 -0 0"/>      
      <geometry>        
        <mesh filename="package:///meshes/left_hip_roll_link_collision.stl"/>        
      </geometry>      
    </collision>    
    <inertial>      
      <origin xyz="-0.012000151133963046085 -0.00049588831385030695577 -0.018504019244504354286" rpy="0 0 0"/>      
      <mass value="0.098012391483528651936"/>      
      <inertia ixx="2.0221748766306544561e-05" ixy="-4.155206824338300164e-08" ixz="-4.122559218785909336e-08" iyy="2.7358099958307369529e-05" iyz="-5.0935731752375891667e-07" izz="2.7358069524723443051e-05"/>      
    </inertial>    
  </link>  

  <link name="left_hip_pitch_link">    
    <visual>      
      <origin xyz="0 0 0" rpy="0 -0 0"/>      
      <geometry>        
        <mesh filename="package:///meshes/left_hip_pitch_link_visual.stl"/>        
      </geometry>      
      <material name="left_hip_pitch_link_material">        
        <color rgba="0.61654126329715297494 0.80727601474877130894 0.92171686561974230933 1.0"/>        
      </material>      
    </visual>    
    <collision>      
      <origin xyz="0 0 0" rpy="0 -0 0"/>      
      <geometry>        
        <mesh filename="package:///meshes/left_hip_pitch_link_collision.stl"/>        
      </geometry>      
    </collision>    
    <inertial>      
      <origin xyz="-0.00021937270136342836685 0.052864534275054879398 0.014710916171980384023" rpy="0 0 0"/>      
      <mass value="0.093539065135968837983"/>      
      <inertia ixx="6.2495911267233984635e-05" ixy="4.2816836354857426374e-07" ixz="-1.5156170028210166404e-07" iyy="2.1496152188538117389e-05" iyz="-1.4210874963076972095e-06" izz="6.2275948339171632211e-05"/>      
    </inertial>    
  </link>  

  <link name="left_calf_link">    
    <visual>      
      <origin xyz="0 0 0" rpy="0 -0 0"/>      
      <geometry>        
        <mesh filename="package:///meshes/left_calf_link_visual.stl"/>        
      </geometry>      
      <material name="left_calf_link_material">        
        <color rgba="0.55185394916441454782 0.72972232177804008391 0.87665656864243646229 1.0"/>        
      </material>      
    </visual>    
    <collision>      
      <origin xyz="0 0 0" rpy="0 -0 0"/>      
      <geometry>        
        <mesh filename="package:///meshes/left_calf_link_collision.stl"/>        
      </geometry>      
    </collision>    
    <inertial>      
      <origin xyz="-0.0038993024960581384661 -0.042419338531024732009 0.0081864888082305280886" rpy="0 0 0"/>      
      <mass value="0.015782434194230747504"/>      
      <inertia ixx="1.4745030589956163153e-05" ixy="-2.0221927128075094588e-07" ixz="8.9866943649240032147e-09" iyy="1.8970750490643143955e-06" iyz="1.7803237244175938131e-08" izz="1.4045051134993895314e-05"/>      
    </inertial>    
  </link>  

  <link name="ank_pitch_link">    
    <visual>      
      <origin xyz="0 0 0" rpy="0 -0 0"/>      
      <geometry>        
        <mesh filename="package:///meshes/left_ank_pitch_link_visual.stl"/>        
      </geometry>      
      <material name="ank_pitch_link_material">        
        <color rgba="0.63189161126160264814 0.7266866879354088038 0.78356373393969258601 1.0"/>        
      </material>      
    </visual>    
    <collision>      
      <origin xyz="0 0 0" rpy="0 -0 0"/>      
      <geometry>        
        <mesh filename="package:///meshes/left_ank_pitch_link_collision.stl"/>        
      </geometry>      
    </collision>    
    <inertial>      
      <origin xyz="4.0269685029020114529e-08 0.00059528282566723492424 -0.01459992238389042768" rpy="0 0 0"/>      
      <mass value="0.0042238381753791614387"/>      
      <inertia ixx="4.370525406739012277e-07" ixy="1.6834347239425813868e-13" ixz="1.6428822387952857182e-12" iyy="3.9782741364650853327e-07" iyz="2.0919243889297784017e-14" izz="8.8858574534559453948e-08"/>      
    </inertial>    
  </link>  

  <link name="ank_roll_link">    
    <visual>      
      <origin xyz="0 0 0" rpy="0 -0 0"/>      
      <geometry>        
        <mesh filename="package:///meshes/left_ank_roll_link_visual.stl"/>        
      </geometry>      
      <material name="ank_roll_link_material">        
        <color rgba="0.61568627450980395466 0.81176470588235305481 0.9294117647058824927 1.0"/>        
      </material>      
    </visual>    
    <collision>      
      <origin xyz="0 0 0" rpy="0 -0 0"/>      
      <geometry>        
        <mesh filename="package:///meshes/left_ank_roll_link_collision.stl"/>        
      </geometry>      
    </collision>    
    <inertial>      
      <origin xyz="-0.0070959190440405247105 0.031669497990247645614 0.001544723586574429236" rpy="0 0 0"/>      
      <mass value="0.020312412324461778801"/>      
      <inertia ixx="1.4885431871170690606e-05" ixy="7.6720315169413908931e-07" ixz="8.1066474591240201501e-07" iyy="1.7915307273613421089e-05" iyz="-1.1563439729789050706e-06" izz="6.9141159895670469319e-06"/>      
    </inertial>    
  </link>  

  <link name="ank_rr_link">    
    <visual>      
      <origin xyz="0 0 0" rpy="0 -0 0"/>      
      <geometry>        
        <mesh filename="package:///meshes/left_ank_rr_link_visual.stl"/>        
      </geometry>      
      <material name="ank_rr_link_material">        
        <color rgba="0.61568627450980395466 0.81176470588235283277 0.92941176470588238168 1.0"/>        
      </material>      
    </visual>    
    <collision>      
      <origin xyz="0 0 0" rpy="0 -0 0"/>      
      <geometry>        
        <mesh filename="package:///meshes/left_ank_rr_link_collision.stl"/>        
      </geometry>      
    </collision>    
    <inertial>      
      <origin xyz="8.9446519574371840559e-20 -0.0061447686137497915457 2.166744703752639102e-19" rpy="0 0 0"/>      
      <mass value="0.00042507093693768156772"/>      
      <inertia ixx="8.7843229279236022739e-09" ixy="-2.2425252682654232171e-26" ixz="-1.0879024114875648572e-14" iyy="8.0301730481463919886e-09" iyz="7.3151635311327051496e-33" izz="1.2504379836120061674e-08"/>      
    </inertial>    
  </link>  

  <link name="12lf_rod_end">    
    <visual>      
      <origin xyz="0 0 0" rpy="0 -0 0"/>      
      <geometry>        
        <mesh filename="package:///meshes/left_12lf_rod_end_visual.stl"/>        
      </geometry>      
      <material name="12lf_rod_end_material">        
        <color rgba="0.92771758928836545177 0.61049283053223013518 0.21847658490585164515 1.0"/>        
      </material>      
    </visual>    
    <collision>      
      <origin xyz="0 0 0" rpy="0 -0 0"/>      
      <geometry>        
        <mesh filename="package:///meshes/left_12lf_rod_end_collision.stl"/>        
      </geometry>      
    </collision>    
    <inertial>      
      <origin xyz="-4.4735192496414894993e-11 -0.0038422185938246020132 6.4384187209429587798e-06" rpy="0 0 0"/>      
      <mass value="0.00085420491177815895123"/>      
      <inertia ixx="1.1840985264406792357e-08" ixy="2.0225978027959712649e-16" ixz="-9.2606419949056756807e-16" iyy="3.3549621576797276408e-09" iyz="7.4535631381859263885e-12" izz="1.2703522254419981579e-08"/>      
    </inertial>    
  </link>  

  <joint name="left_ank_R21" type="revolute">    
    <origin xyz="0 -0.0099999999999999533706 0" rpy="1.570796326794896558 -1.5664147454868542209 -1.5707963267948135133"/>    
    <parent link="ank_rr_link"/>    
    <child link="12lf_rod_end"/>    
    <axis xyz="0 0 1"/>    
    <limit effort="1" velocity="20" lower="-1.570796326794896558" upper="1.570796326794896558"/>    
    <joint_properties friction="0.0"/>    
  </joint>  

  <joint name="left_ank_R11" type="revolute">    
    <origin xyz="-0.018000000000000009048 0.016000000000000014211 -0.020599999999999996786" rpy="-4.1594268726375658989e-17 6.5315524930102152625e-16 -0.01877926248499593373"/>    
    <parent link="ank_roll_link"/>    
    <child link="ank_rr_link"/>    
    <axis xyz="0 0 1"/>    
    <limit effort="1" velocity="20" lower="-1.570796326794896558" upper="1.570796326794896558"/>    
    <joint_properties friction="0.0"/>    
  </joint>  

  <link name="ank_rr_link_2">    
    <visual>      
      <origin xyz="0 0 0" rpy="0 -0 0"/>      
      <geometry>        
        <mesh filename="package:///meshes/left_ank_rr_link_2_visual.stl"/>        
      </geometry>      
      <material name="ank_rr_link_2_material">        
        <color rgba="0.61568627450980395466 0.81176470588235283277 0.92941176470588238168 1.0"/>        
      </material>      
    </visual>    
    <collision>      
      <origin xyz="0 0 0" rpy="0 -0 0"/>      
      <geometry>        
        <mesh filename="package:///meshes/left_ank_rr_link_2_collision.stl"/>        
      </geometry>      
    </collision>    
    <inertial>      
      <origin xyz="-3.4015524252031873681e-18 -0.0061447686137497915457 2.1667447037527045836e-19" rpy="0 0 0"/>      
      <mass value="0.00042507093693768156772"/>      
      <inertia ixx="8.7843229279236055827e-09" ixy="3.2381784308691485543e-27" ixz="-1.0879024114875650149e-14" iyy="8.0301730481463919886e-09" iyz="1.0413059140256246147e-32" izz="1.2504379836120061674e-08"/>      
    </inertial>    
  </link>  

  <link name="12lf_rod_end_2">    
    <visual>      
      <origin xyz="0 0 0" rpy="0 -0 0"/>      
      <geometry>        
        <mesh filename="package:///meshes/left_12lf_rod_end_2_visual.stl"/>        
      </geometry>      
      <material name="12lf_rod_end_2_material">        
        <color rgba="0.92771758928836545177 0.61049283053223013518 0.21847658490585164515 1.0"/>        
      </material>      
    </visual>    
    <collision>      
      <origin xyz="0 0 0" rpy="0 -0 0"/>      
      <geometry>        
        <mesh filename="package:///meshes/left_12lf_rod_end_2_collision.stl"/>        
      </geometry>      
    </collision>    
    <inertial>      
      <origin xyz="-4.4735192535559737604e-11 -0.0038422185938245686197 6.438418720946820403e-06" rpy="0 0 0"/>      
      <mass value="0.00085420491177815895123"/>      
      <inertia ixx="1.1840985264406782431e-08" ixy="2.0225977889760795223e-16" ixz="-9.2606419871776195442e-16" iyy="3.3549621576797305359e-09" iyz="7.4535631381846032227e-12" izz="1.2703522254419958418e-08"/>      
    </inertial>    
  </link>  

  <joint name="left_ank_R22" type="revolute">    
    <origin xyz="0 -0.0099999999999999533706 0" rpy="-1.570796326794896558 -1.5664376509758224376 1.570796326795195208"/>    
    <parent link="ank_rr_link_2"/>    
    <child link="12lf_rod_end_2"/>    
    <axis xyz="0 0 1"/>    
    <limit effort="1" velocity="20" lower="-1.570796326794896558" upper="1.570796326794896558"/>    
    <joint_properties friction="0.0"/>    
  </joint>  

  <joint name="left_ank_R12" type="revolute">    
    <origin xyz="0.017999999999999995171 0.016000000000000014211 -0.020600000000000000255" rpy="3.1415926535897922278 7.4438972302667006905e-16 -3.1229304365180685643"/>    
    <parent link="ank_roll_link"/>    
    <child link="ank_rr_link_2"/>    
    <axis xyz="0 0 1"/>    
    <limit effort="1" velocity="20" lower="-1.570796326794896558" upper="1.570796326794896558"/>    
    <joint_properties friction="0.0"/>    
  </joint>  

  <joint name="left_ank_roll" type="revolute">    
    <origin xyz="3.0531133177191804862e-15 0.001500000000004121951 -0.014599999999997613151" rpy="-1.5707963267949702768 -1.5707963267946758457 0"/>    
    <parent link="ank_pitch_link"/>    
    <child link="ank_roll_link"/>    
    <axis xyz="0 0 1"/>    
    <limit effort="1" velocity="20" lower="-0.785398163397448279" upper="0.785398163397448279"/>    
    <joint_properties friction="0.0"/>    
  </joint>  

  <joint name="left_ank_pitch" type="revolute">    
    <origin xyz="5.9135023084202893979e-19 -0.10000000000000006106 -0.0061999999999999989148" rpy="3.141592653589793116 3.3306690738944506007e-16 -1.5707963267948974462"/>    
    <parent link="left_calf_link"/>    
    <child link="ank_pitch_link"/>    
    <axis xyz="0 0 1"/>    
    <limit effort="1" velocity="20" lower="-0.785398163397448279" upper="0.95993108859688125456"/>    
    <joint_properties friction="0.0"/>    
  </joint>  

  <link name="ball_joint_container">    
    <visual>      
      <origin xyz="0 0 0" rpy="0 -0 0"/>      
      <geometry>        
        <mesh filename="package:///meshes/left_ball_joint_container_visual.stl"/>        
      </geometry>      
      <material name="ball_joint_container_material">        
        <color rgba="0.61568627450980395466 0.81176470588235294379 0.9294117647058824927 1.0"/>        
      </material>      
    </visual>    
    <collision>      
      <origin xyz="0 0 0" rpy="0 -0 0"/>      
      <geometry>        
        <mesh filename="package:///meshes/left_ball_joint_container_collision.stl"/>        
      </geometry>      
    </collision>    
    <inertial>      
      <origin xyz="4.7221442975710667203e-19 -2.7876926753568472755e-17 -0.0097125341669083414126" rpy="0 0 0"/>      
      <mass value="4.8037356425330562243e-05"/>      
      <inertia ixx="7.1865480628741666366e-10" ixy="2.1201121793586067148e-27" ixz="7.7507869186274003536e-39" iyy="8.475420427718555978e-10" iyz="-5.4122729222198885996e-39" izz="1.8625314111651911712e-10"/>      
    </inertial>    
  </link>  

  <link name="ball_joint_ball">    
    <visual>      
      <origin xyz="0 0 0" rpy="0 -0 0"/>      
      <geometry>        
        <mesh filename="package:///meshes/left_ball_joint_ball_visual.stl"/>        
      </geometry>      
      <material name="ball_joint_ball_material">        
        <color rgba="0.3291302810242056065 0.44310466418644928188 0.69204871161977121741 1.0"/>        
      </material>      
    </visual>    
    <collision>      
      <origin xyz="0 0 0" rpy="0 -0 0"/>      
      <geometry>        
        <mesh filename="package:///meshes/left_ball_joint_ball_collision.stl"/>        
      </geometry>      
    </collision>    
    <inertial>      
      <origin xyz="-1.1042142579256435702e-18 -0.0010308669810016035922 -2.0834195949858446323e-18" rpy="0 0 0"/>      
      <mass value="4.4053796295264623832e-05"/>      
      <inertia ixx="3.1285011349692453126e-10" ixy="4.4666440021609585016e-26" ixz="-4.9778106113950895167e-30" iyy="6.2569568612795618051e-11" iyz="2.364805574972257922e-26" izz="3.1285321460376416148e-10"/>      
    </inertial>    
  </link>  

  <link name="12lf">    
    <visual>      
      <origin xyz="0 0 0" rpy="0 -0 0"/>      
      <geometry>        
        <mesh filename="package:///meshes/left_12lf_visual.stl"/>        
      </geometry>      
      <material name="12lf_material">        
        <color rgba="0.62004392096503557763 0.58836684612040224263 0.49897069027350271497 1.0"/>        
      </material>      
    </visual>    
    <collision>      
      <origin xyz="0 0 0" rpy="0 -0 0"/>      
      <geometry>        
        <mesh filename="package:///meshes/left_12lf_collision.stl"/>        
      </geometry>      
    </collision>    
    <inertial>      
      <origin xyz="0.0049084207226956708126 -0.00013802440006612125474 -0.029947003575852761126" rpy="0 0 0"/>      
      <mass value="0.044782197690790462308"/>      
      <inertia ixx="1.5260128420493741417e-05" ixy="2.2955774098747942706e-08" ixz="-8.1364204856713619348e-08" iyy="1.8188469777214642765e-05" iyz="-5.5542241170898124517e-08" izz="5.1496273889341803923e-06"/>      
    </inertial>    
  </link>  

  <link name="12lf_rod">    
    <visual>      
      <origin xyz="0 0 0" rpy="0 -0 0"/>      
      <geometry>        
        <mesh filename="package:///meshes/left_12lf_rod_visual.stl"/>        
      </geometry>      
      <material name="12lf_rod_material">        
        <color rgba="0.80250260812861884396 0.89340612183512713163 0.94491811293548189088 1.0"/>        
      </material>      
    </visual>    
    <collision>      
      <origin xyz="0 0 0" rpy="0 -0 0"/>      
      <geometry>        
        <mesh filename="package:///meshes/left_12lf_rod_collision.stl"/>        
      </geometry>      
    </collision>    
    <inertial>      
      <origin xyz="-6.3222084034124210782e-07 4.6933255258507321245e-07 -0.012893387334326648908" rpy="0 0 0"/>      
      <mass value="0.0025088292483592144512"/>      
      <inertia ixx="2.6944521128633399479e-07" ixy="7.1389570406007791952e-15" ixz="1.3562243132892060313e-11" iyy="2.6944520001689944475e-07" iyz="-1.0089988408671651612e-11" izz="1.7809843599861028799e-08"/>      
    </inertial>    
  </link>  

  <joint name="left_ank_act1" type="prismatic">    
    <origin xyz="2.2722093531019060819e-06 5.1000870193718128576e-16 -0.074779998095377359091" rpy="-3.1415926535896590011 8.6569212672158331644e-14 -2.2021168238262673889"/>    
    <parent link="12lf"/>    
    <child link="12lf_rod"/>    
    <axis xyz="0 0 1"/>    
    <limit effort="1" velocity="20" lower="0" upper="0.040000000000000000833"/>    
    <joint_properties friction="0.0"/>    
  </joint>  

  <joint name="left_ank_B31" type="revolute">    
    <origin xyz="0 -0.0064387505004003531273 -3.4694469519536141888e-18" rpy="-1.57079632679489678 0.16913440034090146402 5.8375589418798256921e-16"/>    
    <parent link="ball_joint_ball"/>    
    <child link="12lf"/>    
    <axis xyz="0 0 1"/>    
    <limit effort="1" velocity="20" lower="-0.785398163397448279" upper="0.785398163397448279"/>    
    <joint_properties friction="0.0"/>    
  </joint>  

  <joint name="left_ank_B21" type="revolute">    
    <origin xyz="-3.4694469519536141888e-18 -2.7755575615628913511e-17 -0.011499999999999999806" rpy="-1.570796326794896558 -1.5664147454872627829 -1.5707963267957041342"/>    
    <parent link="ball_joint_container"/>    
    <child link="ball_joint_ball"/>    
    <axis xyz="0 0 1"/>    
    <limit effort="1" velocity="20" lower="-0.785398163397448279" upper="0.785398163397448279"/>    
    <joint_properties friction="0.0"/>    
  </joint>  

  <joint name="left_ank_B11" type="revolute">    
    <origin xyz="0.0079999999999999949624 -0.015000000000000096589 0.028299999999999991829" rpy="-1.570796326794896558 1.5520170643097057628 1.5707963267950826314"/>    
    <parent link="left_calf_link"/>    
    <child link="ball_joint_container"/>    
    <axis xyz="0 0 1"/>    
    <limit effort="1" velocity="20" lower="-0.785398163397448279" upper="0.785398163397448279"/>    
    <joint_properties friction="0.0"/>    
  </joint>  

  <link name="ball_joint_container_2">    
    <visual>      
      <origin xyz="0 0 0" rpy="0 -0 0"/>      
      <geometry>        
        <mesh filename="package:///meshes/left_ball_joint_container_2_visual.stl"/>        
      </geometry>      
      <material name="ball_joint_container_2_material">        
        <color rgba="0.61568627450980395466 0.81176470588235294379 0.9294117647058824927 1.0"/>        
      </material>      
    </visual>    
    <collision>      
      <origin xyz="0 0 0" rpy="0 -0 0"/>      
      <geometry>        
        <mesh filename="package:///meshes/left_ball_joint_container_2_collision.stl"/>        
      </geometry>      
    </collision>    
    <inertial>      
      <origin xyz="3.9416613817107039127e-18 -1.2135113793955300922e-19 -0.0097125341669083431473" rpy="0 0 0"/>      
      <mass value="4.8037356425330562243e-05"/>      
      <inertia ixx="7.1865480628741666366e-10" ixy="-6.1917919542544475962e-27" ixz="3.828988233046999765e-39" iyy="8.475420427718555978e-10" iyz="-9.2370882590247428667e-40" izz="1.8625314111651911712e-10"/>      
    </inertial>    
  </link>  

  <link name="ball_joint_ball_2">    
    <visual>      
      <origin xyz="0 0 0" rpy="0 -0 0"/>      
      <geometry>        
        <mesh filename="package:///meshes/left_ball_joint_ball_2_visual.stl"/>        
      </geometry>      
      <material name="ball_joint_ball_2_material">        
        <color rgba="0.3291302810242056065 0.44310466418644928188 0.69204871161977121741 1.0"/>        
      </material>      
    </visual>    
    <collision>      
      <origin xyz="0 0 0" rpy="0 -0 0"/>      
      <geometry>        
        <mesh filename="package:///meshes/left_ball_joint_ball_2_collision.stl"/>        
      </geometry>      
    </collision>    
    <inertial>      
      <origin xyz="6.8264363430260785831e-17 -0.0010308669810016380698 -2.7183759330352604902e-18" rpy="0 0 0"/>      
      <mass value="4.4053796295264623832e-05"/>      
      <inertia ixx="3.1285011349692970114e-10" ixy="-1.8171500499872905553e-25" ixz="-3.5933554087797809692e-24" iyy="6.2569568612796768349e-11" iyz="-2.1997460966267609494e-24" izz="3.1285321460377052043e-10"/>      
    </inertial>    
  </link>  

  <link name="12lf_2">    
    <visual>      
      <origin xyz="0 0 0" rpy="0 -0 0"/>      
      <geometry>        
        <mesh filename="package:///meshes/left_12lf_2_visual.stl"/>        
      </geometry>      
      <material name="12lf_2_material">        
        <color rgba="0.62004392096503546661 0.58836684612040224263 0.49897069027350271497 1.0"/>        
      </material>      
    </visual>    
    <collision>      
      <origin xyz="0 0 0" rpy="0 -0 0"/>      
      <geometry>        
        <mesh filename="package:///meshes/left_12lf_2_collision.stl"/>        
      </geometry>      
    </collision>    
    <inertial>      
      <origin xyz="0.0049084207226890346279 -0.00013802440006905114848 -0.029947003575852521734" rpy="0 0 0"/>      
      <mass value="0.044782197690790462308"/>      
      <inertia ixx="1.5260128420493765134e-05" ixy="2.2955774098694655731e-08" ixz="-8.1364204859471055698e-08" iyy="1.8188469777217068668e-05" iyz="-5.554224117237536983e-08" izz="5.149627388936613918e-06"/>      
    </inertial>    
  </link>  

  <link name="12lf_rod_2">    
    <visual>      
      <origin xyz="0 0 0" rpy="0 -0 0"/>      
      <geometry>        
        <mesh filename="package:///meshes/left_12lf_rod_2_visual.stl"/>        
      </geometry>      
      <material name="12lf_rod_2_material">        
        <color rgba="0.80250260812861884396 0.89340612183512713163 0.94491811293548189088 1.0"/>        
      </material>      
    </visual>    
    <collision>      
      <origin xyz="0 0 0" rpy="0 -0 0"/>      
      <geometry>        
        <mesh filename="package:///meshes/left_12lf_rod_2_collision.stl"/>        
      </geometry>      
    </collision>    
    <inertial>      
      <origin xyz="-6.3222083727921726234e-07 4.6933255265304607122e-07 -0.012893387334327922195" rpy="0 0 0"/>      
      <mass value="0.0025088292483592144512"/>      
      <inertia ixx="2.6944521128626231463e-07" ixy="7.1389570130985463294e-15" ixz="1.3562243041946392165e-11" iyy="2.6944520001682776459e-07" iyz="-1.0089988409599651324e-11" izz="1.7809843599860995711e-08"/>      
    </inertial>    
  </link>  

  <joint name="left_ank_act2" type="prismatic">    
    <origin xyz="2.2722093474362992094e-06 -8.9372953482325101504e-15 -0.074779996992751340823" rpy="-3.1415926535895000171 6.172537580306697636e-14 -2.2021168238262789352"/>    
    <parent link="12lf_2"/>    
    <child link="12lf_rod_2"/>    
    <axis xyz="0 0 1"/>    
    <limit effort="1" velocity="20" lower="0" upper="0.040000000000000000833"/>    
    <joint_properties friction="0.0"/>    
  </joint>  

  <joint name="left_ank_B32" type="revolute">    
    <origin xyz="2.498001805406602216e-16 -0.0064387505004004919051 -3.4694469519536141888e-18" rpy="-1.570796326794896558 -0.17993145005756983057 3.0408221168269646133e-14"/>    
    <parent link="ball_joint_ball_2"/>    
    <child link="12lf_2"/>    
    <axis xyz="0 0 1"/>    
    <limit effort="1" velocity="20" lower="-0.785398163397448279" upper="0.785398163397448279"/>    
    <joint_properties friction="0.0"/>    
  </joint>  

  <joint name="left_ank_B22" type="revolute">    
    <origin xyz="3.4694469519536141888e-18 0 -0.01150000000000000154" rpy="-1.570796326794896336 -1.5664376509754431854 1.570796326794866582"/>    
    <parent link="ball_joint_container_2"/>    
    <child link="ball_joint_ball_2"/>    
    <axis xyz="0 0 1"/>    
    <limit effort="1" velocity="20" lower="-0.785398163397448279" upper="0.785398163397448279"/>    
    <joint_properties friction="0.0"/>    
  </joint>  

  <joint name="left_ank_B12" type="revolute">    
    <origin xyz="0.0080000000000000019013 -0.015000000000000041078 -0.011499999999999999806" rpy="-1.570796326794896558 -1.5521341097218244176 1.5707963267948896746"/>    
    <parent link="left_calf_link"/>    
    <child link="ball_joint_container_2"/>    
    <axis xyz="0 0 1"/>    
    <limit effort="1" velocity="20" lower="-0.785398163397448279" upper="0.785398163397448279"/>    
    <joint_properties friction="0.0"/>    
  </joint>  

  <joint name="left_knee" type="revolute">    
    <origin xyz="-8.1569325594195215653e-15 0.095999999999999391376 0.027400000000002110168" rpy="3.1415926535897917837 1.6653345451476814222e-16 -5.2069203968451419987e-17"/>    
    <parent link="left_hip_pitch_link"/>    
    <child link="left_calf_link"/>    
    <axis xyz="0 0 1"/>    
    <limit effort="1" velocity="20" lower="0" upper="1.570796326794896558"/>    
    <joint_properties friction="0.0"/>    
  </joint>  

  <joint name="left_hip_pitch" type="revolute">    
    <origin xyz="-0.024000000716155274472 -0.019000000152442689944 -0.019000000152446339802" rpy="-1.5707963267945199703 1.5707963267948246155 0"/>    
    <parent link="hip_roll_link"/>    
    <child link="left_hip_pitch_link"/>    
    <axis xyz="0 0 1"/>    
    <limit effort="1" velocity="20" lower="-1.570796326794896558" upper="1.570796326794896558"/>    
    <joint_properties friction="0.0"/>    
  </joint>  

  <joint name="left_hip_roll" type="revolute">    
    <origin xyz="0.01900000000000030137 5.3821911112507180559e-16 -0.026000000000000168809" rpy="3.141592653589793116 -1.5707963267936781993 0"/>    
    <parent link="hip_yaw_link"/>    
    <child link="hip_roll_link"/>    
    <axis xyz="0 0 1"/>    
    <limit effort="1" velocity="20" lower="-0.785398163397448279" upper="1.570796326794896558"/>    
    <joint_properties friction="0.0"/>    
  </joint>  


</robot>