<?xml version="1.0" ?><robot name="left_3R+RH5_leg">  
  <link name="hip_yaw_link">    
    <visual>      
      <origin xyz="0 0 0" rpy="0 -0 0"/>      
      <geometry>        
        <mesh filename="package:///meshes/left_hip_yaw_link_visual.stl"/>        
      </geometry>      
      <material name="hip_yaw_link_material">        
        <color rgba="0.61568627450980395466 0.81176470588235294379 0.9294117647058824927 1.0"/>        
      </material>      
    </visual>    
    <collision>      
      <origin xyz="0 0 0" rpy="0 -0 0"/>      
      <geometry>        
        <mesh filename="package:///meshes/left_hip_yaw_link_collision.stl"/>        
      </geometry>      
    </collision>    
    <inertial>      
      <origin xyz="-4.169865130931172083e-19 -3.0887186477718995878e-19 -0.0098390489054830162358" rpy="0 0 0"/>      
      <mass value="0.009025883737097921064"/>      
      <inertia ixx="1.3230458239086458796e-06" ixy="-3.3592249637948224546e-24" ixz="-1.1251788840973426872e-52" iyy="3.8408510960331414253e-06" iyz="2.3044956050358323542e-34" izz="3.872139628579389935e-06"/>      
    </inertial>    
  </link>  

  <link name="hip_roll_link">    
    <visual>      
      <origin xyz="0 0 0" rpy="0 -0 0"/>      
      <geometry>        
        <mesh filename="package:///meshes/left_hip_roll_link_visual.stl"/>        
      </geometry>      
      <material name="hip_roll_link_material">        
        <color rgba="0.95018735644455865064 0.7067892720042843191 0.061612079402596720001 1.0"/>        
      </material>      
    </visual>    
    <collision>      
      <origin xyz="0 0 0" rpy="0 -0 0"/>      
      <geometry>        
        <mesh filename="package:///meshes/left_hip_roll_link_collision.stl"/>        
      </geometry>      
    </collision>    
    <inertial>      
      <origin xyz="-0.012000151133962999248 -0.00049588831384913981213 -0.018504019244505703901" rpy="0 0 0"/>      
      <mass value="0.098012391483528651936"/>      
      <inertia ixx="2.0221748766306741073e-05" ixy="-4.1552068242669349912e-08" ixz="-4.1225592188564757832e-08" iyy="2.7358099958307667684e-05" iyz="-5.0935731752368183668e-07" izz="2.7358069524723720877e-05"/>      
    </inertial>    
  </link>  

  <link name="left_hip_pitch_link">    
    <visual>      
      <origin xyz="0 0 0" rpy="0 -0 0"/>      
      <geometry>        
        <mesh filename="package:///meshes/left_hip_pitch_link_visual.stl"/>        
      </geometry>      
      <material name="left_hip_pitch_link_material">        
        <color rgba="0.61654126329715286392 0.80727601474877119792 0.92171686561974230933 1.0"/>        
      </material>      
    </visual>    
    <collision>      
      <origin xyz="0 0 0" rpy="0 -0 0"/>      
      <geometry>        
        <mesh filename="package:///meshes/left_hip_pitch_link_collision.stl"/>        
      </geometry>      
    </collision>    
    <inertial>      
      <origin xyz="-0.00021937270136341549195 0.052864534275054879398 0.014710916171980347594" rpy="0 0 0"/>      
      <mass value="0.093539065135968851861"/>      
      <inertia ixx="6.249591126723395753e-05" ixy="4.281683635485886633e-07" ixz="-1.5156170028218607617e-07" iyy="2.1496152188537947982e-05" iyz="-1.4210874963077317261e-06" izz="6.2275948339171713526e-05"/>      
    </inertial>    
  </link>  

  <link name="left_calf_link">    
    <visual>      
      <origin xyz="0 0 0" rpy="0 -0 0"/>      
      <geometry>        
        <mesh filename="package:///meshes/left_calf_link_visual.stl"/>        
      </geometry>      
      <material name="left_calf_link_material">        
        <color rgba="0.55397243078540503447 0.73161358475427695769 0.87715705664081478066 1.0"/>        
      </material>      
    </visual>    
    <collision>      
      <origin xyz="0 0 0" rpy="0 -0 0"/>      
      <geometry>        
        <mesh filename="package:///meshes/left_calf_link_collision.stl"/>        
      </geometry>      
    </collision>    
    <inertial>      
      <origin xyz="-0.0039136163069529907726 -0.043640010796484503264 0.0081849279519870064142" rpy="0 0 0"/>      
      <mass value="0.016290616864051549878"/>      
      <inertia ixx="1.5543943584208692903e-05" ixy="-2.1605519114066079532e-07" ixz="7.0470291476179005247e-09" iyy="1.9364407917964668321e-06" iyz="1.9633933099776931725e-08" izz="1.480719700352702444e-05"/>      
    </inertial>    
  </link>  

  <link name="ank_pitch_link">    
    <visual>      
      <origin xyz="0 0 0" rpy="0 -0 0"/>      
      <geometry>        
        <mesh filename="package:///meshes/left_ank_pitch_link_visual.stl"/>        
      </geometry>      
      <material name="ank_pitch_link_material">        
        <color rgba="0.63189161126160264814 0.7266866879354088038 0.78356373393969258601 1.0"/>        
      </material>      
    </visual>    
    <collision>      
      <origin xyz="0 0 0" rpy="0 -0 0"/>      
      <geometry>        
        <mesh filename="package:///meshes/left_ank_pitch_link_collision.stl"/>        
      </geometry>      
    </collision>    
    <inertial>      
      <origin xyz="4.026968501271137525e-08 0.0005952828256672347074 -0.01459992238389042768" rpy="0 0 0"/>      
      <mass value="0.0042238381753791614387"/>      
      <inertia ixx="4.370525406739012277e-07" ixy="1.6834347233230279547e-13" ixz="1.6428822384382108713e-12" iyy="3.9782741364650853327e-07" iyz="2.091924389243752615e-14" izz="8.8858574534559493653e-08"/>      
    </inertial>    
  </link>  

  <link name="ank_roll_link">    
    <visual>      
      <origin xyz="0 0 0" rpy="0 -0 0"/>      
      <geometry>        
        <mesh filename="package:///meshes/left_ank_roll_link_visual.stl"/>        
      </geometry>      
      <material name="ank_roll_link_material">        
        <color rgba="0.61568627450980395466 0.81176470588235283277 0.92941176470588238168 1.0"/>        
      </material>      
    </visual>    
    <collision>      
      <origin xyz="0 0 0" rpy="0 -0 0"/>      
      <geometry>        
        <mesh filename="package:///meshes/left_ank_roll_link_collision.stl"/>        
      </geometry>      
    </collision>    
    <inertial>      
      <origin xyz="-0.0067954317064110765501 0.030800108605150408603 -0.0019645930978156190411" rpy="0 0 0"/>      
      <mass value="0.021210605042023062544"/>      
      <inertia ixx="1.6673721136783793185e-05" ixy="9.6458085135773307807e-07" ixz="8.8407513061355861413e-07" iyy="1.8800607636409439845e-05" iyz="-1.299862496909490135e-06" izz="7.5433513527220517403e-06"/>      
    </inertial>    
  </link>  

  <link name="ank_rr_link">    
    <visual>      
      <origin xyz="0 0 0" rpy="0 -0 0"/>      
      <geometry>        
        <mesh filename="package:///meshes/left_ank_rr_link_visual.stl"/>        
      </geometry>      
      <material name="ank_rr_link_material">        
        <color rgba="0.61568627450980395466 0.81176470588235283277 0.92941176470588238168 1.0"/>        
      </material>      
    </visual>    
    <collision>      
      <origin xyz="0 0 0" rpy="0 -0 0"/>      
      <geometry>        
        <mesh filename="package:///meshes/left_ank_rr_link_collision.stl"/>        
      </geometry>      
    </collision>    
    <inertial>      
      <origin xyz="-4.5867096565122424962e-20 -0.0061447686137497915457 2.067925278967512315e-19" rpy="0 0 0"/>      
      <mass value="0.00042507093693768156772"/>      
      <inertia ixx="8.7843229279236055827e-09" ixy="1.0068738557702793332e-25" ixz="-1.0879024114892058456e-14" iyy="8.0301730481463919886e-09" iyz="-5.4103617476780574479e-32" izz="1.2504379836120061674e-08"/>      
    </inertial>    
  </link>  

  <link name="12lf_rod_end">    
    <visual>      
      <origin xyz="0 0 0" rpy="0 -0 0"/>      
      <geometry>        
        <mesh filename="package:///meshes/left_12lf_rod_end_visual.stl"/>        
      </geometry>      
      <material name="12lf_rod_end_material">        
        <color rgba="0.92771758928836545177 0.61049283053223013518 0.21847658490585164515 1.0"/>        
      </material>      
    </visual>    
    <collision>      
      <origin xyz="0 0 0" rpy="0 -0 0"/>      
      <geometry>        
        <mesh filename="package:///meshes/left_12lf_rod_end_collision.stl"/>        
      </geometry>      
    </collision>    
    <inertial>      
      <origin xyz="-4.4735204920354271635e-11 -0.0038422185938246028805 6.4384187209446452224e-06" rpy="0 0 0"/>      
      <mass value="0.00085420491177815895123"/>      
      <inertia ixx="1.1840985264406779122e-08" ixy="2.0225977398266190056e-16" ixz="-9.2606420347592441568e-16" iyy="3.3549621576797309495e-09" iyz="7.4535631381823026266e-12" izz="1.2703522254419988197e-08"/>      
    </inertial>    
  </link>  

  <joint name="left_ank_R21" type="revolute">    
    <origin xyz="-6.9388939039072283776e-18 -0.0099999999999999533706 6.9388939039072283776e-18" rpy="-1.570796326794896558 -1.4285697747629295673 1.5707963267948288344"/>    
    <parent link="ank_rr_link"/>    
    <child link="12lf_rod_end"/>    
    <axis xyz="0 0 1"/>    
    <limit effort="1" velocity="20" lower="-1.570796326794896558" upper="1.570796326794896558"/>    
    <joint_properties friction="0.0"/>    
  </joint>  

  <joint name="left_ank_R11" type="revolute">    
    <origin xyz="-0.0099999999999999967387 0.012500000000000038858 -0.033600000000000004863" rpy="-1.3295317856339465751e-14 8.7994714049036524006e-15 -0.1011603127570600974"/>    
    <parent link="ank_roll_link"/>    
    <child link="ank_rr_link"/>    
    <axis xyz="0 0 1"/>    
    <limit effort="1" velocity="20" lower="-1.570796326794896558" upper="1.570796326794896558"/>    
    <joint_properties friction="0.0"/>    
  </joint>  

  <link name="ank_rr_link_2">    
    <visual>      
      <origin xyz="0 0 0" rpy="0 -0 0"/>      
      <geometry>        
        <mesh filename="package:///meshes/left_ank_rr_link_2_visual.stl"/>        
      </geometry>      
      <material name="ank_rr_link_2_material">        
        <color rgba="0.61568627450980395466 0.81176470588235283277 0.92941176470588238168 1.0"/>        
      </material>      
    </visual>    
    <collision>      
      <origin xyz="0 0 0" rpy="0 -0 0"/>      
      <geometry>        
        <mesh filename="package:///meshes/left_ank_rr_link_2_collision.stl"/>        
      </geometry>      
    </collision>    
    <inertial>      
      <origin xyz="1.5443686748867368788e-20 -0.0061447686137497915457 2.0679252789668002024e-19" rpy="0 0 0"/>      
      <mass value="0.00042507093693768156772"/>      
      <inertia ixx="8.7843229279236022739e-09" ixy="-1.1926575209540821264e-25" ixz="-1.0879024114892056879e-14" iyy="8.0301730481463919886e-09" iyz="1.1907065342322363564e-31" izz="1.2504379836120061674e-08"/>      
    </inertial>    
  </link>  

  <link name="12lf_rod_end_2">    
    <visual>      
      <origin xyz="0 0 0" rpy="0 -0 0"/>      
      <geometry>        
        <mesh filename="package:///meshes/left_12lf_rod_end_2_visual.stl"/>        
      </geometry>      
      <material name="12lf_rod_end_2_material">        
        <color rgba="0.92771758928836545177 0.61049283053223013518 0.21847658490585164515 1.0"/>        
      </material>      
    </visual>    
    <collision>      
      <origin xyz="0 0 0" rpy="0 -0 0"/>      
      <geometry>        
        <mesh filename="package:///meshes/left_12lf_rod_end_2_collision.stl"/>        
      </geometry>      
    </collision>    
    <inertial>      
      <origin xyz="-4.4735200965666421951e-11 -0.0038422185938245733902 6.4384187209432781112e-06" rpy="0 0 0"/>      
      <mass value="0.00085420491177815895123"/>      
      <inertia ixx="1.1840985264406779122e-08" ixy="2.022597801403895296e-16" ixz="-9.2606419810299811503e-16" iyy="3.3549621576797268136e-09" iyz="7.4535631381847340852e-12" izz="1.2703522254419961727e-08"/>      
    </inertial>    
  </link>  

  <joint name="left_ank_R22" type="revolute">    
    <origin xyz="-6.9388939039072283776e-18 -0.0099999999999999811262 6.9388939039072283776e-18" rpy="1.570796326794896558 -1.4285463212677005362 -1.5707963267950528774"/>    
    <parent link="ank_rr_link_2"/>    
    <child link="12lf_rod_end_2"/>    
    <axis xyz="0 0 1"/>    
    <limit effort="1" velocity="20" lower="-1.570796326794896558" upper="1.570796326794896558"/>    
    <joint_properties friction="0.0"/>    
  </joint>  

  <joint name="left_ank_R12" type="revolute">    
    <origin xyz="0.010000000000000003678 0.012500000000000038858 -0.033600000000000004863" rpy="3.1415926535897802374 2.5015582227113039382e-14 -3.0405529889788152076"/>    
    <parent link="ank_roll_link"/>    
    <child link="ank_rr_link_2"/>    
    <axis xyz="0 0 1"/>    
    <limit effort="1" velocity="20" lower="-1.570796326794896558" upper="1.570796326794896558"/>    
    <joint_properties friction="0.0"/>    
  </joint>  

  <joint name="left_ank_roll" type="revolute">    
    <origin xyz="2.9976021664879226591e-15 0.0015000000000041202163 -0.014599999999997613151" rpy="-1.5707963267949680564 -1.5707963267944098362 0"/>    
    <parent link="ank_pitch_link"/>    
    <child link="ank_roll_link"/>    
    <axis xyz="0 0 1"/>    
    <limit effort="1" velocity="20" lower="-0.785398163397448279" upper="0.785398163397448279"/>    
    <joint_properties friction="0.0"/>    
  </joint>  

  <joint name="left_ank_pitch" type="revolute">    
    <origin xyz="1.1074470850715867721e-18 -0.10000000000000006106 -0.0062000000000000023842" rpy="3.141592653589793116 1.7874590696523099396e-14 -1.5707963267948983344"/>    
    <parent link="left_calf_link"/>    
    <child link="ank_pitch_link"/>    
    <axis xyz="0 0 1"/>    
    <limit effort="1" velocity="20" lower="-0.52359877559829881566" upper="0.52359877559829881566"/>    
    <joint_properties friction="0.0"/>    
  </joint>  

  <link name="ball_joint_container">    
    <visual>      
      <origin xyz="0 0 0" rpy="0 -0 0"/>      
      <geometry>        
        <mesh filename="package:///meshes/left_ball_joint_container_visual.stl"/>        
      </geometry>      
      <material name="ball_joint_container_material">        
        <color rgba="0.61568627450980395466 0.81176470588235294379 0.9294117647058824927 1.0"/>        
      </material>      
    </visual>    
    <collision>      
      <origin xyz="0 0 0" rpy="0 -0 0"/>      
      <geometry>        
        <mesh filename="package:///meshes/left_ball_joint_container_collision.stl"/>        
      </geometry>      
    </collision>    
    <inertial>      
      <origin xyz="4.7221442975707412382e-19 -1.2135113793955168514e-19 -0.0097125341669083379431" rpy="0 0 0"/>      
      <mass value="4.8037356425330562243e-05"/>      
      <inertia ixx="7.1865480628741666366e-10" ixy="1.9093875420966183797e-26" ixz="-9.6567327904192743482e-39" iyy="8.4754204277185539101e-10" iyz="-2.0669447749008773941e-39" izz="1.8625314111651911712e-10"/>      
    </inertial>    
  </link>  

  <link name="ball_joint_ball">    
    <visual>      
      <origin xyz="0 0 0" rpy="0 -0 0"/>      
      <geometry>        
        <mesh filename="package:///meshes/left_ball_joint_ball_visual.stl"/>        
      </geometry>      
      <material name="ball_joint_ball_material">        
        <color rgba="0.3291302810242056065 0.44310466418644928188 0.69204871161977121741 1.0"/>        
      </material>      
    </visual>    
    <collision>      
      <origin xyz="0 0 0" rpy="0 -0 0"/>      
      <geometry>        
        <mesh filename="package:///meshes/left_ball_joint_ball_collision.stl"/>        
      </geometry>      
    </collision>    
    <inertial>      
      <origin xyz="2.0943472813681118712e-18 -0.001030866981001647394 1.6698556129646054768e-19" rpy="0 0 0"/>      
      <mass value="4.4053796295264623832e-05"/>      
      <inertia ixx="3.1285011349692334219e-10" ixy="-2.5137115013999161135e-25" ixz="2.1861546352690670189e-26" iyy="6.2569568612796147963e-11" iyz="-3.7415045053218497172e-26" izz="3.1285321460376891777e-10"/>      
    </inertial>    
  </link>  

  <link name="12lf">    
    <visual>      
      <origin xyz="0 0 0" rpy="0 -0 0"/>      
      <geometry>        
        <mesh filename="package:///meshes/left_12lf_visual.stl"/>        
      </geometry>      
      <material name="12lf_material">        
        <color rgba="0.62004392096503557763 0.58836684612040224263 0.49897069027350271497 1.0"/>        
      </material>      
    </visual>    
    <collision>      
      <origin xyz="0 0 0" rpy="0 -0 0"/>      
      <geometry>        
        <mesh filename="package:///meshes/left_12lf_collision.stl"/>        
      </geometry>      
    </collision>    
    <inertial>      
      <origin xyz="0.0049084207226956725473 -0.00013802440006612445313 -0.029947003575852778473" rpy="0 0 0"/>      
      <mass value="0.044782197690790462308"/>      
      <inertia ixx="1.5260128420493731253e-05" ixy="2.2955774098748075055e-08" ixz="-8.1364204856709940048e-08" iyy="1.8188469777214632601e-05" iyz="-5.5542241170901426622e-08" izz="5.1496273889341820864e-06"/>      
    </inertial>    
  </link>  

  <link name="12lf_rod">    
    <visual>      
      <origin xyz="0 0 0" rpy="0 -0 0"/>      
      <geometry>        
        <mesh filename="package:///meshes/left_12lf_rod_visual.stl"/>        
      </geometry>      
      <material name="12lf_rod_material">        
        <color rgba="0.80250260812861884396 0.89340612183512713163 0.94491811293548189088 1.0"/>        
      </material>      
    </visual>    
    <collision>      
      <origin xyz="0 0 0" rpy="0 -0 0"/>      
      <geometry>        
        <mesh filename="package:///meshes/left_12lf_rod_collision.stl"/>        
      </geometry>      
    </collision>    
    <inertial>      
      <origin xyz="-6.3222084029212129078e-07 4.6933255311519471172e-07 -0.012893387334327143304" rpy="0 0 0"/>      
      <mass value="0.0025088292483592144512"/>      
      <inertia ixx="2.6944521128630530155e-07" ixy="7.1389570424753761856e-15" ixz="1.3562243131762661509e-11" iyy="2.6944520001687085739e-07" iyz="-1.0089988423546690317e-11" izz="1.7809843599861022181e-08"/>      
    </inertial>    
  </link>  

  <joint name="left_ank_act1" type="prismatic">    
    <origin xyz="2.2722093528972087118e-06 4.2327252813834093104e-16 -0.072660031604101171787" rpy="-3.1415926535896590011 1.0257376628608333772e-13 -2.2021168238262784911"/>    
    <parent link="12lf"/>    
    <child link="12lf_rod"/>    
    <axis xyz="0 0 1"/>    
    <limit effort="1" velocity="20" lower="0" upper="0.040000000000000000833"/>    
    <joint_properties friction="0.0"/>    
  </joint>  

  <joint name="left_ank_B31" type="revolute">    
    <origin xyz="1.3010426069826053208e-18 -0.006438750500400436394 0" rpy="-1.57079632679489678 0.16913440034098886633 2.9529351978209400659e-15"/>    
    <parent link="ball_joint_ball"/>    
    <child link="12lf"/>    
    <axis xyz="0 0 1"/>    
    <limit effort="1" velocity="20" lower="-0.785398163397448279" upper="0.785398163397448279"/>    
    <joint_properties friction="0.0"/>    
  </joint>  

  <joint name="left_ank_B21" type="revolute">    
    <origin xyz="0 0 -0.011499999999999996336" rpy="1.570796326794896558 -1.4285697747625691889 1.5707963267948952257"/>    
    <parent link="ball_joint_container"/>    
    <child link="ball_joint_ball"/>    
    <axis xyz="0 0 1"/>    
    <limit effort="1" velocity="20" lower="-0.785398163397448279" upper="0.785398163397448279"/>    
    <joint_properties friction="0.0"/>    
  </joint>  

  <joint name="left_ank_B11" type="revolute">    
    <origin xyz="0.0080000000000000643513 -0.015000000000000235367 0.028299999999999957134" rpy="-1.570796326794896558 1.4696360140379425285 1.5707963267949005548"/>    
    <parent link="left_calf_link"/>    
    <child link="ball_joint_container"/>    
    <axis xyz="0 0 1"/>    
    <limit effort="1" velocity="20" lower="-0.785398163397448279" upper="0.785398163397448279"/>    
    <joint_properties friction="0.0"/>    
  </joint>  

  <link name="ball_joint_container_2">    
    <visual>      
      <origin xyz="0 0 0" rpy="0 -0 0"/>      
      <geometry>        
        <mesh filename="package:///meshes/left_ball_joint_container_2_visual.stl"/>        
      </geometry>      
      <material name="ball_joint_container_2_material">        
        <color rgba="0.61568627450980395466 0.81176470588235294379 0.9294117647058824927 1.0"/>        
      </material>      
    </visual>    
    <collision>      
      <origin xyz="0 0 0" rpy="0 -0 0"/>      
      <geometry>        
        <mesh filename="package:///meshes/left_ball_joint_container_2_collision.stl"/>        
      </geometry>      
    </collision>    
    <inertial>      
      <origin xyz="4.7221442975707797568e-19 -1.213511379395562833e-19 -0.0097125341669083396778" rpy="0 0 0"/>      
      <mass value="4.8037356425330562243e-05"/>      
      <inertia ixx="7.1865480628741666366e-10" ixy="-1.3182905845697921914e-26" ixz="-5.2568208926315324602e-39" iyy="8.475420427718555978e-10" iyz="6.7704469493154371076e-39" izz="1.8625314111651911712e-10"/>      
    </inertial>    
  </link>  

  <link name="ball_joint_ball_2">    
    <visual>      
      <origin xyz="0 0 0" rpy="0 -0 0"/>      
      <geometry>        
        <mesh filename="package:///meshes/left_ball_joint_ball_2_visual.stl"/>        
      </geometry>      
      <material name="ball_joint_ball_2_material">        
        <color rgba="0.3291302810242056065 0.44310466418644928188 0.69204871161977121741 1.0"/>        
      </material>      
    </visual>    
    <collision>      
      <origin xyz="0 0 0" rpy="0 -0 0"/>      
      <geometry>        
        <mesh filename="package:///meshes/left_ball_joint_ball_2_collision.stl"/>        
      </geometry>      
    </collision>    
    <inertial>      
      <origin xyz="-1.9482490896205589329e-18 -0.0010308669810016116153 9.9849008278937369588e-19" rpy="0 0 0"/>      
      <mass value="4.4053796295264623832e-05"/>      
      <inertia ixx="3.1285011349692675431e-10" ixy="-2.75805796047439135e-25" ixz="7.5294038721744216784e-26" iyy="6.2569568612795876545e-11" iyz="2.6034928009046818791e-26" izz="3.1285321460376922796e-10"/>      
    </inertial>    
  </link>  

  <link name="12lf_2">    
    <visual>      
      <origin xyz="0 0 0" rpy="0 -0 0"/>      
      <geometry>        
        <mesh filename="package:///meshes/left_12lf_2_visual.stl"/>        
      </geometry>      
      <material name="12lf_2_material">        
        <color rgba="0.62004392096503546661 0.58836684612040224263 0.49897069027350271497 1.0"/>        
      </material>      
    </visual>    
    <collision>      
      <origin xyz="0 0 0" rpy="0 -0 0"/>      
      <geometry>        
        <mesh filename="package:///meshes/left_12lf_2_collision.stl"/>        
      </geometry>      
    </collision>    
    <inertial>      
      <origin xyz="0.004908420722688886309 -0.00013802440006871068189 -0.029947003575850877216" rpy="0 0 0"/>      
      <mass value="0.044782197690790462308"/>      
      <inertia ixx="1.5260128420492460703e-05" ixy="2.2955774098712135712e-08" ixz="-8.1364204859482847985e-08" iyy="1.8188469777215621935e-05" iyz="-5.5542241172242279778e-08" izz="5.1496273889364783927e-06"/>      
    </inertial>    
  </link>  

  <link name="12lf_rod_2">    
    <visual>      
      <origin xyz="0 0 0" rpy="0 -0 0"/>      
      <geometry>        
        <mesh filename="package:///meshes/left_12lf_rod_2_visual.stl"/>        
      </geometry>      
      <material name="12lf_rod_2_material">        
        <color rgba="0.80250260812861884396 0.89340612183512713163 0.94491811293548189088 1.0"/>        
      </material>      
    </visual>    
    <collision>      
      <origin xyz="0 0 0" rpy="0 -0 0"/>      
      <geometry>        
        <mesh filename="package:///meshes/left_12lf_rod_2_collision.stl"/>        
      </geometry>      
    </collision>    
    <inertial>      
      <origin xyz="-6.3222083690836262699e-07 4.6933255276162283075e-07 -0.012893387334328331589" rpy="0 0 0"/>      
      <mass value="0.0025088292483592144512"/>      
      <inertia ixx="2.6944521128623944474e-07" ixy="7.1389570123641515365e-15" ixz="1.3562243031473196704e-11" iyy="2.6944520001680500058e-07" iyz="-1.0089988412646377239e-11" izz="1.7809843599860992403e-08"/>      
    </inertial>    
  </link>  

  <joint name="left_ank_act2" type="prismatic">    
    <origin xyz="2.2722093472333365627e-06 -8.396061623727746337e-15 -0.072660030478823994793" rpy="-3.1415926535895000171 4.7380615214810755067e-14 -2.2021168238262500694"/>    
    <parent link="12lf_2"/>    
    <child link="12lf_rod_2"/>    
    <axis xyz="0 0 1"/>    
    <limit effort="1" velocity="20" lower="0" upper="0.040000000000000000833"/>    
    <joint_properties friction="0.0"/>    
  </joint>  

  <joint name="left_ank_B32" type="revolute">    
    <origin xyz="1.7347234759768070944e-17 -0.006438750500400436394 0" rpy="-1.570796326794896336 -0.17993145005780261658 1.3200513083700388182e-15"/>    
    <parent link="ball_joint_ball_2"/>    
    <child link="12lf_2"/>    
    <axis xyz="0 0 1"/>    
    <limit effort="1" velocity="20" lower="-0.785398163397448279" upper="0.785398163397448279"/>    
    <joint_properties friction="0.0"/>    
  </joint>  

  <joint name="left_ank_B22" type="revolute">    
    <origin xyz="0 0 -0.011499999999999998071" rpy="1.570796326794896558 -1.4285463212681039913 -1.5707963267948852337"/>    
    <parent link="ball_joint_container_2"/>    
    <child link="ball_joint_ball_2"/>    
    <axis xyz="0 0 1"/>    
    <limit effort="1" velocity="20" lower="-0.785398163397448279" upper="0.785398163397448279"/>    
    <joint_properties friction="0.0"/>    
  </joint>  

  <joint name="left_ank_B12" type="revolute">    
    <origin xyz="0.008000000000000003636 -0.015000000000000013323 -0.011500000000000003275" rpy="-1.5707963267949294206 -1.4697566621822577559 1.5707963267949305308"/>    
    <parent link="left_calf_link"/>    
    <child link="ball_joint_container_2"/>    
    <axis xyz="0 0 1"/>    
    <limit effort="1" velocity="20" lower="-0.785398163397448279" upper="0.785398163397448279"/>    
    <joint_properties friction="0.0"/>    
  </joint>  

  <joint name="left_knee" type="revolute">    
    <origin xyz="-8.1704984642832938552e-15 0.095999999999999391376 0.027400000000000819533" rpy="3.1415926535897753524 1.6653345376122616675e-16 -1.6536824015790017811e-15"/>    
    <parent link="left_hip_pitch_link"/>    
    <child link="left_calf_link"/>    
    <axis xyz="0 0 1"/>    
    <limit effort="1" velocity="20" lower="0" upper="1.570796326794896558"/>    
    <joint_properties friction="0.0"/>    
  </joint>  

  <joint name="left_hip_pitch" type="revolute">    
    <origin xyz="-0.024000000716157210423 -0.019000000152441316043 -0.019000000152448022483" rpy="-1.5707963267944322627 1.570796326794811959 0"/>    
    <parent link="hip_roll_link"/>    
    <child link="left_hip_pitch_link"/>    
    <axis xyz="0 0 1"/>    
    <limit effort="1" velocity="20" lower="-1.570796326794896558" upper="1.570796326794896558"/>    
    <joint_properties friction="0.0"/>    
  </joint>  

  <joint name="left_hip_roll" type="revolute">    
    <origin xyz="0.019000000000000304839 -3.362403793834428631e-18 -0.026000000000000279832" rpy="3.141592653589793116 -1.5707963267945577179 0"/>    
    <parent link="hip_yaw_link"/>    
    <child link="hip_roll_link"/>    
    <axis xyz="0 0 1"/>    
    <limit effort="1" velocity="20" lower="-0.785398163397448279" upper="1.570796326794896558"/>    
    <joint_properties friction="0.0"/>    
  </joint>  


</robot>