<?xml version="1.0" ?><robot name="left_3R+RH5_leg">  
  <link name="hip_yaw_link">    
    <visual>      
      <origin xyz="0 0 0" rpy="0 -0 0"/>      
      <geometry>        
        <mesh filename="package:///meshes/left_hip_yaw_link_visual.stl"/>        
      </geometry>      
      <material name="hip_yaw_link_material">        
        <color rgba="0.61568627450980395466 0.81176470588235294379 0.92941176470588238168 1.0"/>        
      </material>      
    </visual>    
    <collision>      
      <origin xyz="0 0 0" rpy="0 -0 0"/>      
      <geometry>        
        <mesh filename="package:///meshes/left_hip_yaw_link_collision.stl"/>        
      </geometry>      
    </collision>    
    <inertial>      
      <origin xyz="2.0298201459478351931e-18 -1.8141989800322495856e-18 -0.0099143649223341762111" rpy="0 0 0"/>      
      <mass value="0.0081617461226117064832"/>      
      <inertia ixx="1.1860761935507536315e-06" ixy="-3.1075958922279281846e-24" ixz="-1.0500552021549525753e-52" iyy="3.5910093036263567032e-06" iyz="2.1618801264009314157e-34" izz="3.6446570722248043903e-06"/>      
    </inertial>    
  </link>  

  <link name="hip_roll_link">    
    <visual>      
      <origin xyz="0 0 0" rpy="0 -0 0"/>      
      <geometry>        
        <mesh filename="package:///meshes/left_hip_roll_link_visual.stl"/>        
      </geometry>      
      <material name="hip_roll_link_material">        
        <color rgba="0.95018735644455865064 0.70678927200428420807 0.061612079402596699185 1.0"/>        
      </material>      
    </visual>    
    <collision>      
      <origin xyz="0 0 0" rpy="0 -0 0"/>      
      <geometry>        
        <mesh filename="package:///meshes/left_hip_roll_link_collision.stl"/>        
      </geometry>      
    </collision>    
    <inertial>      
      <origin xyz="-0.01200015113395626852 -0.00049588831385389273761 -0.018504019244504309183" rpy="0 0 0"/>      
      <mass value="0.098012391483528679692"/>      
      <inertia ixx="2.0221748766305619601e-05" ixy="-4.1552068246176185428e-08" ixz="-4.122559218789387465e-08" iyy="2.735809995830613286e-05" iyz="-5.0935731752412652897e-07" izz="2.735806952472188451e-05"/>      
    </inertial>    
  </link>  

  <link name="hip_pitch_link">    
    <visual>      
      <origin xyz="0 0 0" rpy="0 -0 0"/>      
      <geometry>        
        <mesh filename="package:///meshes/left_hip_pitch_link_visual.stl"/>        
      </geometry>      
      <material name="hip_pitch_link_material">        
        <color rgba="0.61668199203816709275 0.80653718885844505326 0.92045030695061169634 1.0"/>        
      </material>      
    </visual>    
    <collision>      
      <origin xyz="0 0 0" rpy="0 -0 0"/>      
      <geometry>        
        <mesh filename="package:///meshes/left_hip_pitch_link_collision.stl"/>        
      </geometry>      
    </collision>    
    <inertial>      
      <origin xyz="-0.00012587895788720025367 0.055074320814802096846 0.012617712499788545297" rpy="0 0 0"/>      
      <mass value="0.086351012001622040604"/>      
      <inertia ixx="5.8343011265628729638e-05" ixy="9.4663837750473544588e-08" ixz="-5.8892469185564109677e-08" iyy="1.6666236930815888089e-05" iyz="-2.2101256957836672124e-06" izz="6.1357987984517875762e-05"/>      
    </inertial>    
  </link>  

  <link name="left_calf_link">    
    <visual>      
      <origin xyz="0 0 0" rpy="0 -0 0"/>      
      <geometry>        
        <mesh filename="package:///meshes/left_calf_link_visual.stl"/>        
      </geometry>      
      <material name="left_calf_link_material">        
        <color rgba="0.55189755139050244992 0.72942380840907361517 0.87615949531796932792 1.0"/>        
      </material>      
    </visual>    
    <collision>      
      <origin xyz="0 0 0" rpy="0 -0 0"/>      
      <geometry>        
        <mesh filename="package:///meshes/left_calf_link_collision.stl"/>        
      </geometry>      
    </collision>    
    <inertial>      
      <origin xyz="-0.0029316794405327959751 -0.042704493856076802816 0.008180733931406947157" rpy="0 0 0"/>      
      <mass value="0.016572094167120694774"/>      
      <inertia ixx="1.6369870837950075933e-05" ixy="-7.8680088417863454523e-07" ixz="2.4353243389132039138e-09" iyy="2.3404958543794316602e-06" iyz="2.046559878707221647e-08" izz="1.5866147842764249162e-05"/>      
    </inertial>    
  </link>  

  <link name="ank_pitch_link">    
    <visual>      
      <origin xyz="0 0 0" rpy="0 -0 0"/>      
      <geometry>        
        <mesh filename="package:///meshes/left_ank_pitch_link_visual.stl"/>        
      </geometry>      
      <material name="ank_pitch_link_material">        
        <color rgba="0.63189161126160264814 0.7266866879354088038 0.78356373393969258601 1.0"/>        
      </material>      
    </visual>    
    <collision>      
      <origin xyz="0 0 0" rpy="0 -0 0"/>      
      <geometry>        
        <mesh filename="package:///meshes/left_ank_pitch_link_collision.stl"/>        
      </geometry>      
    </collision>    
    <inertial>      
      <origin xyz="4.0269683941709913463e-08 0.00059528282566513883618 -0.014599922383890337474" rpy="0 0 0"/>      
      <mass value="0.0042238381753791614387"/>      
      <inertia ixx="4.370525406738216066e-07" ixy="1.6834347023014569988e-13" ixz="1.642882232191860681e-12" iyy="3.9782741364648243407e-07" iyz="2.0919220022487145065e-14" izz="8.8858574534506024698e-08"/>      
    </inertial>    
  </link>  

  <link name="ank_roll_link">    
    <visual>      
      <origin xyz="0 0 0" rpy="0 -0 0"/>      
      <geometry>        
        <mesh filename="package:///meshes/left_ank_roll_link_visual.stl"/>        
      </geometry>      
      <material name="ank_roll_link_material">        
        <color rgba="0.61568627450980395466 0.81176470588235294379 0.92941176470588238168 1.0"/>        
      </material>      
    </visual>    
    <collision>      
      <origin xyz="0 0 0" rpy="0 -0 0"/>      
      <geometry>        
        <mesh filename="package:///meshes/left_ank_roll_link_collision.stl"/>        
      </geometry>      
    </collision>    
    <inertial>      
      <origin xyz="-6.2785102912654534854e-10 0.027009707039944940571 0.00075275119182833399607" rpy="0 0 0"/>      
      <mass value="0.014299508637166613578"/>      
      <inertia ixx="1.0815330340622712334e-05" ixy="6.9415252939905975958e-14" ixz="-3.1620808586111628063e-13" iyy="9.3337296863724890914e-06" iyz="-9.1328070216937089649e-07" izz="2.9529318668467990654e-06"/>      
    </inertial>    
  </link>  

  <link name="ank_rr_link">    
    <visual>      
      <origin xyz="0 0 0" rpy="0 -0 0"/>      
      <geometry>        
        <mesh filename="package:///meshes/left_ank_rr_link_visual.stl"/>        
      </geometry>      
      <material name="ank_rr_link_material">        
        <color rgba="0.61568627450980395466 0.81176470588235294379 0.92941176470588238168 1.0"/>        
      </material>      
    </visual>    
    <collision>      
      <origin xyz="0 0 0" rpy="0 -0 0"/>      
      <geometry>        
        <mesh filename="package:///meshes/left_ank_rr_link_collision.stl"/>        
      </geometry>      
    </collision>    
    <inertial>      
      <origin xyz="3.4593503690053769336e-05 0.0062999445222072123982 -0.0018999999999999924068" rpy="0 0 0"/>      
      <mass value="0.00044289790445047684574"/>      
      <inertia ixx="9.0894755004835289854e-09" ixy="-5.6689994077039947737e-11" ixz="1.0879024115051242698e-14" iyy="8.3785129146959922129e-09" iyz="-2.7528865571156618587e-32" izz="1.3107013728801491474e-08"/>      
    </inertial>    
  </link>  

  <link name="12lf_rod_end">    
    <visual>      
      <origin xyz="0 0 0" rpy="0 -0 0"/>      
      <geometry>        
        <mesh filename="package:///meshes/left_12lf_rod_end_visual.stl"/>        
      </geometry>      
      <material name="12lf_rod_end_material">        
        <color rgba="0.97254901960784312376 0.52941176470588235947 0.0039215686274509803377 1.0"/>        
      </material>      
    </visual>    
    <collision>      
      <origin xyz="0 0 0" rpy="0 -0 0"/>      
      <geometry>        
        <mesh filename="package:///meshes/left_12lf_rod_end_collision.stl"/>        
      </geometry>      
    </collision>    
    <inertial>      
      <origin xyz="-5.7828408473085873663e-11 0.0033987031118028819369 -0.0020055782443104621" rpy="0 0 0"/>      
      <mass value="0.00066080012085386230676"/>      
      <inertia ixx="1.0675794104648557829e-08" ixy="-1.8531171270105454825e-16" ixz="9.2603132970771869145e-16" iyy="2.377371824966105234e-09" iyz="6.3401399719236717506e-12" izz="1.1538333246010974441e-08"/>      
    </inertial>    
  </link>  

  <joint name="left_ank_R21" type="revolute">    
    <origin xyz="0.0021000000000002752576 0.010000000000000036637 -0.0019000000000000058509" rpy="-1.570796326794896558 1.4871995686199779296 -1.5707963267949018871"/>    
    <parent link="ank_rr_link"/>    
    <child link="12lf_rod_end"/>    
    <axis xyz="0 0 1"/>    
    <limit effort="1" velocity="20" lower="-1.570796326794896558" upper="1.570796326794896558"/>    
    <joint_properties friction="0.0"/>    
  </joint>  

  <joint name="left_ank_R11" type="revolute">    
    <origin xyz="-0.0099999999999999984734 0.012500000000000011102 -0.033000000000000008493" rpy="3.1415926535897908956 7.3034946203131872804e-17 -0.098830241914560454375"/>    
    <parent link="ank_roll_link"/>    
    <child link="ank_rr_link"/>    
    <axis xyz="0 0 1"/>    
    <limit effort="1" velocity="20" lower="-1.570796326794896558" upper="1.570796326794896558"/>    
    <joint_properties friction="0.0"/>    
  </joint>  

  <link name="ank_rr_link_2">    
    <visual>      
      <origin xyz="0 0 0" rpy="0 -0 0"/>      
      <geometry>        
        <mesh filename="package:///meshes/left_ank_rr_link_2_visual.stl"/>        
      </geometry>      
      <material name="ank_rr_link_2_material">        
        <color rgba="0.61568627450980395466 0.81176470588235294379 0.92941176470588238168 1.0"/>        
      </material>      
    </visual>    
    <collision>      
      <origin xyz="0 0 0" rpy="0 -0 0"/>      
      <geometry>        
        <mesh filename="package:///meshes/left_ank_rr_link_2_collision.stl"/>        
      </geometry>      
    </collision>    
    <inertial>      
      <origin xyz="3.4593503690060769216e-05 -0.0062999445222072106634 -0.001900000000000005634" rpy="0 0 0"/>      
      <mass value="0.00044289790445047684574"/>      
      <inertia ixx="9.0894755004835289854e-09" ixy="5.6689994077039908963e-11" ixz="-1.0879024115051242698e-14" iyy="8.3785129146959889042e-09" iyz="-8.796707713197679947e-32" izz="1.3107013728801491474e-08"/>      
    </inertial>    
  </link>  

  <link name="12lf_rod_end_2">    
    <visual>      
      <origin xyz="0 0 0" rpy="0 -0 0"/>      
      <geometry>        
        <mesh filename="package:///meshes/left_12lf_rod_end_2_visual.stl"/>        
      </geometry>      
      <material name="12lf_rod_end_2_material">        
        <color rgba="0.97254901960784312376 0.52941176470588235947 0.0039215686274509803377 1.0"/>        
      </material>      
    </visual>    
    <collision>      
      <origin xyz="0 0 0" rpy="0 -0 0"/>      
      <geometry>        
        <mesh filename="package:///meshes/left_12lf_rod_end_2_collision.stl"/>        
      </geometry>      
    </collision>    
    <inertial>      
      <origin xyz="-5.7828411926067356084e-11 0.0033987031118029092588 -0.0020055782443104621" rpy="0 0 0"/>      
      <mass value="0.00066080012085386230676"/>      
      <inertia ixx="1.0675794104648551211e-08" ixy="-1.8531171295507229568e-16" ixz="9.2603132969909723062e-16" iyy="2.3773718249661060612e-09" iyz="6.3401399719239472082e-12" izz="1.1538333246010971133e-08"/>      
    </inertial>    
  </link>  

  <joint name="left_ank_R22" type="revolute">    
    <origin xyz="0.0021000000000000115796 -0.010000000000000036637 -0.001899999999999998912" rpy="-1.5707963267950195707 -1.4871998384676159422 -1.5707963267947853137"/>    
    <parent link="ank_rr_link_2"/>    
    <child link="12lf_rod_end_2"/>    
    <axis xyz="0 0 1"/>    
    <limit effort="1" velocity="20" lower="-1.570796326794896558" upper="1.570796326794896558"/>    
    <joint_properties friction="0.0"/>    
  </joint>  

  <joint name="left_ank_R12" type="revolute">    
    <origin xyz="0.010000000000000003678 0.012500000000000066613 -0.033000000000000008493" rpy="-3.141592653589793116 4.6545838516711603543e-17 -3.0460894442741315302"/>    
    <parent link="ank_roll_link"/>    
    <child link="ank_rr_link_2"/>    
    <axis xyz="0 0 1"/>    
    <limit effort="1" velocity="20" lower="-1.570796326794896558" upper="1.570796326794896558"/>    
    <joint_properties friction="0.0"/>    
  </joint>  

  <joint name="left_ank_roll" type="revolute">    
    <origin xyz="3.3306690738754696213e-16 -0.0061000000000003698833 -0.014600000000000704428" rpy="-1.5707963267949007768 -1.5707963267947875341 0"/>    
    <parent link="ank_pitch_link"/>    
    <child link="ank_roll_link"/>    
    <axis xyz="0 0 1"/>    
    <limit effort="1" velocity="20" lower="-1.570796326794896558" upper="1.570796326794896558"/>    
    <joint_properties friction="0.0"/>    
  </joint>  

  <joint name="left_ank_pitch" type="revolute">    
    <origin xyz="4.2143614023597344721e-19 -0.09999999999999995004 -0.0062000000000000023842" rpy="3.1415926535897074068 -7.168818208916126976e-14 -1.5707963267948470421"/>    
    <parent link="left_calf_link"/>    
    <child link="ank_pitch_link"/>    
    <axis xyz="0 0 1"/>    
    <limit effort="1" velocity="20" lower="-1.570796326794896558" upper="1.570796326794896558"/>    
    <joint_properties friction="0.0"/>    
  </joint>  

  <link name="ball_joint_container">    
    <visual>      
      <origin xyz="0 0 0" rpy="0 -0 0"/>      
      <geometry>        
        <mesh filename="package:///meshes/left_ball_joint_container_visual.stl"/>        
      </geometry>      
      <material name="ball_joint_container_material">        
        <color rgba="0.61568627450980395466 0.81176470588235294379 0.92941176470588238168 1.0"/>        
      </material>      
    </visual>    
    <collision>      
      <origin xyz="0 0 0" rpy="0 -0 0"/>      
      <geometry>        
        <mesh filename="package:///meshes/left_ball_joint_container_collision.stl"/>        
      </geometry>      
    </collision>    
    <inertial>      
      <origin xyz="4.7221442975710079795e-19 -1.2829321646531987314e-19 -0.009712534166908344882" rpy="0 0 0"/>      
      <mass value="4.803735642533054869e-05"/>      
      <inertia ixx="7.1865480628741666366e-10" ixy="1.5342810458366841061e-26" ixz="-5.9271524154695110967e-39" iyy="8.4754204277185539101e-10" iyz="4.6412055237153116593e-40" izz="1.8625314111651911712e-10"/>      
    </inertial>    
  </link>  

  <link name="ball_joint_ball">    
    <visual>      
      <origin xyz="0 0 0" rpy="0 -0 0"/>      
      <geometry>        
        <mesh filename="package:///meshes/left_ball_joint_ball_visual.stl"/>        
      </geometry>      
      <material name="ball_joint_ball_material">        
        <color rgba="0.3291302810242056065 0.44310466418644928188 0.69204871161977121741 1.0"/>        
      </material>      
    </visual>    
    <collision>      
      <origin xyz="0 0 0" rpy="0 -0 0"/>      
      <geometry>        
        <mesh filename="package:///meshes/left_ball_joint_ball_collision.stl"/>        
      </geometry>      
    </collision>    
    <inertial>      
      <origin xyz="-2.883384257533859293e-18 -0.0010308669810016287457 9.6846152567142738835e-20" rpy="0 0 0"/>      
      <mass value="4.4053796295264623832e-05"/>      
      <inertia ixx="3.1285011349692204972e-10" ixy="-2.0452848555806012723e-26" ixz="-4.8751370978256719508e-25" iyy="6.2569568612795553427e-11" iyz="-1.3384425639988252684e-25" izz="3.1285321460375842292e-10"/>      
    </inertial>    
  </link>  

  <link name="12lf">    
    <visual>      
      <origin xyz="0 0 0" rpy="0 -0 0"/>      
      <geometry>        
        <mesh filename="package:///meshes/left_12lf_visual.stl"/>        
      </geometry>      
      <material name="12lf_material">        
        <color rgba="0.62004392100736027693 0.58836684613512635345 0.49897069021535678246 1.0"/>        
      </material>      
    </visual>    
    <collision>      
      <origin xyz="0 0 0" rpy="0 -0 0"/>      
      <geometry>        
        <mesh filename="package:///meshes/left_12lf_collision.stl"/>        
      </geometry>      
    </collision>    
    <inertial>      
      <origin xyz="0.0049084207243674958174 -0.0001380243994378267192 -0.029947003577149716724" rpy="0 0 0"/>      
      <mass value="0.044782197696050352054"/>      
      <inertia ixx="1.5260128421314346936e-05" ixy="2.2955773686970078488e-08" ixz="-8.136420400742620126e-08" iyy="1.8188469778953841963e-05" iyz="-5.5542240843948833182e-08" izz="5.1496273901745025955e-06"/>      
    </inertial>    
  </link>  

  <link name="12lf_rod">    
    <visual>      
      <origin xyz="0 0 0" rpy="0 -0 0"/>      
      <geometry>        
        <mesh filename="package:///meshes/left_12lf_rod_visual.stl"/>        
      </geometry>      
      <material name="12lf_rod_material">        
        <color rgba="0.80016770676329840306 0.8929145636529542962 0.94547111589042631685 1.0"/>        
      </material>      
    </visual>    
    <collision>      
      <origin xyz="0 0 0" rpy="0 -0 0"/>      
      <geometry>        
        <mesh filename="package:///meshes/left_12lf_rod_collision.stl"/>        
      </geometry>      
    </collision>    
    <inertial>      
      <origin xyz="-2.7254954573436195926e-06 -1.2667795959534603497e-05 0.0060054807227737979497" rpy="0 0 0"/>      
      <mass value="0.0026945559868381376359"/>      
      <inertia ixx="3.223183205635478918e-07" ixy="-9.9380293157033229797e-13" ixz="1.0490654898536706608e-10" iyy="3.2231218697775831564e-07" iyz="5.6317539913801979045e-10" izz="1.8746557075763014286e-08"/>      
    </inertial>    
  </link>  

  <joint name="left_ank_act1" type="prismatic">    
    <origin xyz="2.272209342117637032e-06 -2.1996293675385913957e-15 -0.059356158967298844331" rpy="-3.141592653589793116 -9.2921664633026457838e-16 -0.63671356442004722886"/>    
    <parent link="12lf"/>    
    <child link="12lf_rod"/>    
    <axis xyz="0 0 1"/>    
    <limit effort="1" velocity="20" lower="-0.01799999999999999864" upper="0.01799999999999999864"/>    
    <joint_properties friction="0.0"/>    
  </joint>  

  <joint name="left_ank_B31" type="revolute">    
    <origin xyz="-3.4694469519536141888e-18 -0.0064387505004004086384 0" rpy="-1.570796326794896558 -5.457469122271992718e-06 -4.1571660558495781323e-16"/>    
    <parent link="ball_joint_ball"/>    
    <child link="12lf"/>    
    <axis xyz="0 0 1"/>    
    <limit effort="1" velocity="20" lower="-0.785398163397448279" upper="0.785398163397448279"/>    
    <joint_properties friction="0.0"/>    
  </joint>  

  <joint name="left_ank_B21" type="revolute">    
    <origin xyz="7.8409501114151680667e-16 -1.1102230246251565404e-16 -0.011500000000000044909" rpy="1.5707963267948958919 -1.4871995686196806119 1.5707963267948610309"/>    
    <parent link="ball_joint_container"/>    
    <child link="ball_joint_ball"/>    
    <axis xyz="0 0 1"/>    
    <limit effort="1" velocity="20" lower="-0.785398163397448279" upper="0.785398163397448279"/>    
    <joint_properties friction="0.0"/>    
  </joint>  

  <joint name="left_ank_B11" type="revolute">    
    <origin xyz="0.017999999999999957007 -0.01000000000000014766 0.028300000000000765515" rpy="-1.5707963267948972241 1.4719660848801743303 1.570796326794891451"/>    
    <parent link="left_calf_link"/>    
    <child link="ball_joint_container"/>    
    <axis xyz="0 0 1"/>    
    <limit effort="1" velocity="20" lower="-0.785398163397448279" upper="0.785398163397448279"/>    
    <joint_properties friction="0.0"/>    
  </joint>  

  <link name="ball_joint_container_2">    
    <visual>      
      <origin xyz="0 0 0" rpy="0 -0 0"/>      
      <geometry>        
        <mesh filename="package:///meshes/left_ball_joint_container_2_visual.stl"/>        
      </geometry>      
      <material name="ball_joint_container_2_material">        
        <color rgba="0.61568627450980395466 0.81176470588235294379 0.92941176470588238168 1.0"/>        
      </material>      
    </visual>    
    <collision>      
      <origin xyz="0 0 0" rpy="0 -0 0"/>      
      <geometry>        
        <mesh filename="package:///meshes/left_ball_joint_container_2_collision.stl"/>        
      </geometry>      
    </collision>    
    <inertial>      
      <origin xyz="-6.4666794741501178538e-18 -2.7883868832094236273e-17 -0.0097125341669083414126" rpy="0 0 0"/>      
      <mass value="4.803735642533054869e-05"/>      
      <inertia ixx="7.1865480628741645687e-10" ixy="2.7446666238406894861e-27" ixz="-1.4518458374078259081e-39" iyy="8.4754204277185539101e-10" iyz="-1.6278928790628168441e-39" izz="1.8625314111651911712e-10"/>      
    </inertial>    
  </link>  

  <link name="ball_joint_ball_2">    
    <visual>      
      <origin xyz="0 0 0" rpy="0 -0 0"/>      
      <geometry>        
        <mesh filename="package:///meshes/left_ball_joint_ball_2_visual.stl"/>        
      </geometry>      
      <material name="ball_joint_ball_2_material">        
        <color rgba="0.3291302810242056065 0.44310466418644928188 0.69204871161977121741 1.0"/>        
      </material>      
    </visual>    
    <collision>      
      <origin xyz="0 0 0" rpy="0 -0 0"/>      
      <geometry>        
        <mesh filename="package:///meshes/left_ball_joint_ball_2_collision.stl"/>        
      </geometry>      
    </collision>    
    <inertial>      
      <origin xyz="8.4461971253435996092e-18 -0.0010308669810016712464 -7.7256784713035522871e-18" rpy="0 0 0"/>      
      <mass value="4.4053796295264623832e-05"/>      
      <inertia ixx="3.1285011349692877056e-10" ixy="1.2425429650797161432e-25" ixz="7.6189985658313210026e-25" iyy="6.2569568612796005792e-11" iyz="1.8731834763223846337e-25" izz="3.1285321460377558692e-10"/>      
    </inertial>    
  </link>  

  <link name="12lf_2">    
    <visual>      
      <origin xyz="0 0 0" rpy="0 -0 0"/>      
      <geometry>        
        <mesh filename="package:///meshes/left_12lf_2_visual.stl"/>        
      </geometry>      
      <material name="12lf_2_material">        
        <color rgba="0.62004392100736016591 0.58836684613512635345 0.49897069021535672695 1.0"/>        
      </material>      
    </visual>    
    <collision>      
      <origin xyz="0 0 0" rpy="0 -0 0"/>      
      <geometry>        
        <mesh filename="package:///meshes/left_12lf_2_collision.stl"/>        
      </geometry>      
    </collision>    
    <inertial>      
      <origin xyz="0.0049084207243658851266 -0.00013802439943711049524 -0.02994700357714754832" rpy="0 0 0"/>      
      <mass value="0.044782197696050345115"/>      
      <inertia ixx="1.5260128421312866323e-05" ixy="2.2955773686805343814e-08" ixz="-8.1364204008054368835e-08" iyy="1.8188469778951988655e-05" iyz="-5.5542240843652093718e-08" izz="5.1496273901741282069e-06"/>      
    </inertial>    
  </link>  

  <link name="12lf_rod_2">    
    <visual>      
      <origin xyz="0 0 0" rpy="0 -0 0"/>      
      <geometry>        
        <mesh filename="package:///meshes/left_12lf_rod_2_visual.stl"/>        
      </geometry>      
      <material name="12lf_rod_2_material">        
        <color rgba="0.80016770676329840306 0.8929145636529542962 0.94547111589042631685 1.0"/>        
      </material>      
    </visual>    
    <collision>      
      <origin xyz="0 0 0" rpy="0 -0 0"/>      
      <geometry>        
        <mesh filename="package:///meshes/left_12lf_rod_2_collision.stl"/>        
      </geometry>      
    </collision>    
    <inertial>      
      <origin xyz="-2.7254954555105344156e-06 -1.2667795960388387297e-05 0.006005480722775477162" rpy="0 0 0"/>      
      <mass value="0.0026945559868381376359"/>      
      <inertia ixx="3.2231832056365117688e-07" ixy="-9.9380293141111679177e-13" ixz="1.0490654892595063098e-10" iyy="3.223121869778614419e-07" iyz="5.6317539916469222931e-10" izz="1.8746557075763166488e-08"/>      
    </inertial>    
  </link>  

  <joint name="left_ank_act2" type="prismatic">    
    <origin xyz="2.2722093409414945153e-06 -1.7347234759768070944e-15 -0.05935645944356465753" rpy="3.141592653589793116 2.5208502705617295898e-15 -0.63671356442004545251"/>    
    <parent link="12lf_2"/>    
    <child link="12lf_rod_2"/>    
    <axis xyz="0 0 1"/>    
    <limit effort="1" velocity="20" lower="-0.01799999999999999864" upper="0.01799999999999999864"/>    
    <joint_properties friction="0.0"/>    
  </joint>  

  <joint name="left_ank_B32" type="revolute">    
    <origin xyz="3.4694469519536141888e-18 -0.0064387505004004641496 -1.3877787807814456755e-17" rpy="-1.5707963267948961139 -5.457468730707960001e-06 -1.2951865632219856922e-15"/>    
    <parent link="ball_joint_ball_2"/>    
    <child link="12lf_2"/>    
    <axis xyz="0 0 1"/>    
    <limit effort="1" velocity="20" lower="-0.785398163397448279" upper="0.785398163397448279"/>    
    <joint_properties friction="0.0"/>    
  </joint>  

  <joint name="left_ank_B22" type="revolute">    
    <origin xyz="-6.9388939039072283776e-18 -2.7755575615628913511e-17 -0.011499999999999999806" rpy="1.5707963267948872321 -1.4871998384670954696 -1.5707963267948854558"/>    
    <parent link="ball_joint_container_2"/>    
    <child link="ball_joint_ball_2"/>    
    <axis xyz="0 0 1"/>    
    <limit effort="1" velocity="20" lower="-0.785398163397448279" upper="0.785398163397448279"/>    
    <joint_properties friction="0.0"/>    
  </joint>  

  <joint name="left_ank_B12" type="revolute">    
    <origin xyz="0.018000000000000002109 -0.010000000000000008882 -0.011499999999999999806" rpy="-1.570796326794896558 -1.4752931174793231239 1.5707963267948954478"/>    
    <parent link="left_calf_link"/>    
    <child link="ball_joint_container_2"/>    
    <axis xyz="0 0 1"/>    
    <limit effort="1" velocity="20" lower="-0.785398163397448279" upper="0.785398163397448279"/>    
    <joint_properties friction="0.0"/>    
  </joint>  

  <joint name="left_knee" type="revolute">    
    <origin xyz="-4.686453338044572818e-15 0.097999999999999976019 0.027400000000003393863" rpy="-3.1415926535897620298 -6.106988965093026078e-15 -6.2039230811899877997e-14"/>    
    <parent link="hip_pitch_link"/>    
    <child link="left_calf_link"/>    
    <axis xyz="0 0 1"/>    
    <limit effort="1" velocity="20" lower="-1.570796326794896558" upper="1.570796326794896558"/>    
    <joint_properties friction="0.0"/>    
  </joint>  

  <joint name="left_hip_pitch" type="revolute">    
    <origin xyz="-0.024000000716140678508 -0.019000000152444841001 -0.019000000152450791102" rpy="-1.5707963267948210628 1.5707963267948126251 0"/>    
    <parent link="hip_roll_link"/>    
    <child link="hip_pitch_link"/>    
    <axis xyz="0 0 1"/>    
    <limit effort="1" velocity="20" lower="-1.570796326794896558" upper="1.570796326794896558"/>    
    <joint_properties friction="0.0"/>    
  </joint>  

  <joint name="left_hip_roll" type="revolute">    
    <origin xyz="0.019000000000000304839 -5.0328333128562291641e-18 -0.025000000000000268535" rpy="3.141592653589793116 -1.5707963267948947816 0"/>    
    <parent link="hip_yaw_link"/>    
    <child link="hip_roll_link"/>    
    <axis xyz="0 0 1"/>    
    <limit effort="1" velocity="20" lower="-1.570796326794896558" upper="1.570796326794896558"/>    
    <joint_properties friction="0.0"/>    
  </joint>  


</robot>