<?xml version="1.0" ?><robot name="left_3R+RH5_leg">  
  <link name="hip_yaw_link">    
    <visual>      
      <origin xyz="0 0 0" rpy="0 -0 0"/>      
      <geometry>        
        <mesh filename="package:///meshes/left_hip_yaw_link_visual.stl"/>        
      </geometry>      
      <material name="hip_yaw_link_material">        
        <color rgba="0.61568627450980395466 0.81176470588235294379 0.9294117647058824927 1.0"/>        
      </material>      
    </visual>    
    <collision>      
      <origin xyz="0 0 0" rpy="0 -0 0"/>      
      <geometry>        
        <mesh filename="package:///meshes/left_hip_yaw_link_collision.stl"/>        
      </geometry>      
    </collision>    
    <inertial>      
      <origin xyz="-3.2018607255364363686e-19 -2.3813308130603722097e-19 -0.009839048905483014501" rpy="0 0 0"/>      
      <mass value="0.0090258837370979193293"/>      
      <inertia ixx="1.3230458239086465149e-06" ixy="-3.3592249637948231893e-24" ixz="-1.1251788840973426872e-52" iyy="3.8408510960331422723e-06" iyz="2.3044956050358332095e-34" izz="3.8721396285793907821e-06"/>      
    </inertial>    
  </link>  

  <link name="hip_roll_link">    
    <visual>      
      <origin xyz="0 0 0" rpy="0 -0 0"/>      
      <geometry>        
        <mesh filename="package:///meshes/left_hip_roll_link_visual.stl"/>        
      </geometry>      
      <material name="hip_roll_link_material">        
        <color rgba="0.95018735644455865064 0.70678927200428420807 0.061612079402596699185 1.0"/>        
      </material>      
    </visual>    
    <collision>      
      <origin xyz="0 0 0" rpy="0 -0 0"/>      
      <geometry>        
        <mesh filename="package:///meshes/left_hip_roll_link_collision.stl"/>        
      </geometry>      
    </collision>    
    <inertial>      
      <origin xyz="-0.012000151133961396363 -0.00049588831384953402804 -0.018504019244504728986" rpy="0 0 0"/>      
      <mass value="0.098012391483528679692"/>      
      <inertia ixx="2.0221748766306463246e-05" ixy="-4.1552068243118092086e-08" ixz="-4.1225592188160160633e-08" iyy="2.7358099958307189958e-05" iyz="-5.0935731752381037393e-07" izz="2.7358069524723229598e-05"/>      
    </inertial>    
  </link>  

  <link name="left_hip_pitch_link">    
    <visual>      
      <origin xyz="0 0 0" rpy="0 -0 0"/>      
      <geometry>        
        <mesh filename="package:///meshes/left_hip_pitch_link_visual.stl"/>        
      </geometry>      
      <material name="left_hip_pitch_link_material">        
        <color rgba="0.61653630588246988165 0.80730204117585691037 0.92176148235188937186 1.0"/>        
      </material>      
    </visual>    
    <collision>      
      <origin xyz="0 0 0" rpy="0 -0 0"/>      
      <geometry>        
        <mesh filename="package:///meshes/left_hip_pitch_link_collision.stl"/>        
      </geometry>      
    </collision>    
    <inertial>      
      <origin xyz="-0.00021632240618359049899 0.052986695633820024565 0.014788126099014522671" rpy="0 0 0"/>      
      <mass value="0.094084588454108858402"/>      
      <inertia ixx="6.3099190805816147737e-05" ixy="4.2254461504176696551e-07" ixz="-1.5223568275357069527e-07" iyy="2.1754782765193072386e-05" iyz="-1.4708367336520551889e-06" izz="6.2817482611037591409e-05"/>      
    </inertial>    
  </link>  

  <link name="left_calf_link">    
    <visual>      
      <origin xyz="0 0 0" rpy="0 -0 0"/>      
      <geometry>        
        <mesh filename="package:///meshes/left_calf_link_visual.stl"/>        
      </geometry>      
      <material name="left_calf_link_material">        
        <color rgba="0.55206810638185987994 0.72966543427568708591 0.87633415637236466988 1.0"/>        
      </material>      
    </visual>    
    <collision>      
      <origin xyz="0 0 0" rpy="0 -0 0"/>      
      <geometry>        
        <mesh filename="package:///meshes/left_calf_link_collision.stl"/>        
      </geometry>      
    </collision>    
    <inertial>      
      <origin xyz="-0.0039024894179555125184 -0.043134364817539981585 0.0081627588179090451725" rpy="0 0 0"/>      
      <mass value="0.016579149141633314074"/>      
      <inertia ixx="1.590573070035246312e-05" ixy="-2.204522528800703112e-07" ixz="6.1290259940321994327e-09" iyy="2.0589441701201891296e-06" iyz="3.1188726814138092768e-08" izz="1.5050357385364998179e-05"/>      
    </inertial>    
  </link>  

  <link name="ank_pitch_link">    
    <visual>      
      <origin xyz="0 0 0" rpy="0 -0 0"/>      
      <geometry>        
        <mesh filename="package:///meshes/left_ank_pitch_link_visual.stl"/>        
      </geometry>      
      <material name="ank_pitch_link_material">        
        <color rgba="0.63189161126160275916 0.72668668793540891482 0.78356373393969258601 1.0"/>        
      </material>      
    </visual>    
    <collision>      
      <origin xyz="0 0 0" rpy="0 -0 0"/>      
      <geometry>        
        <mesh filename="package:///meshes/left_ank_pitch_link_collision.stl"/>        
      </geometry>      
    </collision>    
    <inertial>      
      <origin xyz="4.0269685049619320532e-08 0.00059528282566739039883 -0.014599922383890481456" rpy="0 0 0"/>      
      <mass value="0.0042238381753791605713"/>      
      <inertia ixx="4.3705254067385321152e-07" ixy="1.6834346764733785093e-13" ixz="1.6428822472656162005e-12" iyy="3.9782741364647126382e-07" iyz="2.0919252884264439613e-14" izz="8.8858574534548839566e-08"/>      
    </inertial>    
  </link>  

  <link name="ank_roll_link">    
    <visual>      
      <origin xyz="0 0 0" rpy="0 -0 0"/>      
      <geometry>        
        <mesh filename="package:///meshes/left_ank_roll_link_visual.stl"/>        
      </geometry>      
      <material name="ank_roll_link_material">        
        <color rgba="0.61568627450980406568 0.81176470588235294379 0.92941176470588238168 1.0"/>        
      </material>      
    </visual>    
    <collision>      
      <origin xyz="0 0 0" rpy="0 -0 0"/>      
      <geometry>        
        <mesh filename="package:///meshes/left_ank_roll_link_collision.stl"/>        
      </geometry>      
    </collision>    
    <inertial>      
      <origin xyz="-6.3661537535036433633e-10 0.027240102316353698858 0.0019830147448535368794" rpy="0 0 0"/>      
      <mass value="0.013844478784760250178"/>      
      <inertia ixx="1.0150902309234932519e-05" ixy="6.8603302700575787432e-14" ixz="-3.2605547319755288602e-13" iyy="8.66361166634314672e-06" iyz="-7.8151778926544826665e-07" izz="2.8991570356470342998e-06"/>      
    </inertial>    
  </link>  

  <link name="ank_rr_link">    
    <visual>      
      <origin xyz="0 0 0" rpy="0 -0 0"/>      
      <geometry>        
        <mesh filename="package:///meshes/left_ank_rr_link_visual.stl"/>        
      </geometry>      
      <material name="ank_rr_link_material">        
        <color rgba="0.61568627450980395466 0.81176470588235294379 0.92941176470588238168 1.0"/>        
      </material>      
    </visual>    
    <collision>      
      <origin xyz="0 0 0" rpy="0 -0 0"/>      
      <geometry>        
        <mesh filename="package:///meshes/left_ank_rr_link_collision.stl"/>        
      </geometry>      
    </collision>    
    <inertial>      
      <origin xyz="3.459350369005387098e-05 0.0062999445222072132655 -0.0018999999999999991288" rpy="0 0 0"/>      
      <mass value="0.00044289790445047668311"/>      
      <inertia ixx="9.0894755004835223679e-09" ixy="-5.6689994077039773254e-11" ixz="1.0879024115047049114e-14" iyy="8.3785129146959922129e-09" iyz="1.6438750918789287233e-32" izz="1.3107013728801488166e-08"/>      
    </inertial>    
  </link>  

  <link name="12lf_rod_end">    
    <visual>      
      <origin xyz="0 0 0" rpy="0 -0 0"/>      
      <geometry>        
        <mesh filename="package:///meshes/left_12lf_rod_end_visual.stl"/>        
      </geometry>      
      <material name="12lf_rod_end_material">        
        <color rgba="0.92771758928836534075 0.61049283053223002415 0.2184765849058516729 1.0"/>        
      </material>      
    </visual>    
    <collision>      
      <origin xyz="0 0 0" rpy="0 -0 0"/>      
      <geometry>        
        <mesh filename="package:///meshes/left_12lf_rod_end_collision.stl"/>        
      </geometry>      
    </collision>    
    <inertial>      
      <origin xyz="-4.4735200503803263918e-11 -0.0038422185938246028805 6.4384187209442598224e-06" rpy="0 0 0"/>      
      <mass value="0.00085420491177815905965"/>      
      <inertia ixx="1.1840985264406794011e-08" ixy="2.0225977808669542648e-16" ixz="-9.260641994085930871e-16" iyy="3.3549621576797379806e-09" iyz="7.4535631381823397851e-12" izz="1.270352225441999316e-08"/>      
    </inertial>    
  </link>  

  <joint name="left_ank_R21" type="revolute">    
    <origin xyz="0 0.010000000000000036637 -0.001899999999999998912" rpy="1.570796326794896558 1.428569774762729061 -1.570796326794896558"/>    
    <parent link="ank_rr_link"/>    
    <child link="12lf_rod_end"/>    
    <axis xyz="0 0 1"/>    
    <limit effort="1" velocity="20" lower="-1.570796326794896558" upper="1.570796326794896558"/>    
    <joint_properties friction="0.0"/>    
  </joint>  

  <joint name="left_ank_R11" type="revolute">    
    <origin xyz="-0.01000000000000001929 0.012500000000000011102 -0.027899999999999692407" rpy="-3.141592653589793116 3.5006616330671580104e-18 -0.10116031275702692949"/>    
    <parent link="ank_roll_link"/>    
    <child link="ank_rr_link"/>    
    <axis xyz="0 0 1"/>    
    <limit effort="1" velocity="20" lower="-1.570796326794896558" upper="1.570796326794896558"/>    
    <joint_properties friction="0.0"/>    
  </joint>  

  <link name="ank_rr_link_2">    
    <visual>      
      <origin xyz="0 0 0" rpy="0 -0 0"/>      
      <geometry>        
        <mesh filename="package:///meshes/left_ank_rr_link_2_visual.stl"/>        
      </geometry>      
      <material name="ank_rr_link_2_material">        
        <color rgba="0.61568627450980395466 0.81176470588235294379 0.92941176470588238168 1.0"/>        
      </material>      
    </visual>    
    <collision>      
      <origin xyz="0 0 0" rpy="0 -0 0"/>      
      <geometry>        
        <mesh filename="package:///meshes/left_ank_rr_link_2_collision.stl"/>        
      </geometry>      
    </collision>    
    <inertial>      
      <origin xyz="3.4593503690046986296e-05 -0.0062999445222071577544 -0.0018999999999999917562" rpy="0 0 0"/>      
      <mass value="0.00044289790445047668311"/>      
      <inertia ixx="9.0894755004835256766e-09" ixy="5.6689994077039740942e-11" ixz="-1.0879024115047050692e-14" iyy="8.3785129146959922129e-09" iyz="-1.4073262332570122483e-32" izz="1.3107013728801488166e-08"/>      
    </inertial>    
  </link>  

  <link name="12lf_rod_end_2">    
    <visual>      
      <origin xyz="0 0 0" rpy="0 -0 0"/>      
      <geometry>        
        <mesh filename="package:///meshes/left_12lf_rod_end_2_visual.stl"/>        
      </geometry>      
      <material name="12lf_rod_end_2_material">        
        <color rgba="0.92771758928836534075 0.61049283053223002415 0.2184765849058516729 1.0"/>        
      </material>      
    </visual>    
    <collision>      
      <origin xyz="0 0 0" rpy="0 -0 0"/>      
      <geometry>        
        <mesh filename="package:///meshes/left_12lf_rod_end_2_collision.stl"/>        
      </geometry>      
    </collision>    
    <inertial>      
      <origin xyz="-4.4735193074030483235e-11 -0.003842218593824545201 6.4384187209441048154e-06" rpy="0 0 0"/>      
      <mass value="0.00085420491177815905965"/>      
      <inertia ixx="1.1840985264406749344e-08" ixy="2.0225978115032554807e-16" ixz="-9.2606419674121376397e-16" iyy="3.3549621576796854546e-09" iyz="7.4535631381834933143e-12" izz="1.2703522254419956764e-08"/>      
    </inertial>    
  </link>  

  <joint name="left_ank_R22" type="revolute">    
    <origin xyz="1.3877787807814456755e-17 -0.010000000000000036637 -0.0019000000000000058509" rpy="1.5707963267949061059 -1.4285463212675062472 -1.5707963267949052177"/>    
    <parent link="ank_rr_link_2"/>    
    <child link="12lf_rod_end_2"/>    
    <axis xyz="0 0 1"/>    
    <limit effort="1" velocity="20" lower="-1.570796326794896558" upper="1.570796326794896558"/>    
    <joint_properties friction="0.0"/>    
  </joint>  

  <joint name="left_ank_R12" type="revolute">    
    <origin xyz="0.0099999999999999932693 0.012500000000000066613 -0.027900000000000039352" rpy="3.1415926535897904515 2.6926878995557896255e-15 -3.0405529889787885622"/>    
    <parent link="ank_roll_link"/>    
    <child link="ank_rr_link_2"/>    
    <axis xyz="0 0 1"/>    
    <limit effort="1" velocity="20" lower="-1.570796326794896558" upper="1.570796326794896558"/>    
    <joint_properties friction="0.0"/>    
  </joint>  

  <joint name="left_ank_roll" type="revolute">    
    <origin xyz="1.193489751472043281e-15 -0.00610000000000079836 -0.014600000000000288095" rpy="-1.5707963267948288344 -1.5707963267944542451 0"/>    
    <parent link="ank_pitch_link"/>    
    <child link="ank_roll_link"/>    
    <axis xyz="0 0 1"/>    
    <limit effort="1" velocity="20" lower="-1.570796326794896558" upper="1.570796326794896558"/>    
    <joint_properties friction="0.0"/>    
  </joint>  

  <joint name="left_ank_pitch" type="revolute">    
    <origin xyz="1.0842022241842927186e-18 -0.10000000000000006106 -0.0061999999999999867717" rpy="-3.141592653589793116 -1.9981846038921943663e-15 -1.570796326794896558"/>    
    <parent link="left_calf_link"/>    
    <child link="ank_pitch_link"/>    
    <axis xyz="0 0 1"/>    
    <limit effort="1" velocity="20" lower="-1.570796326794896558" upper="1.570796326794896558"/>    
    <joint_properties friction="0.0"/>    
  </joint>  

  <link name="ball_joint_container">    
    <visual>      
      <origin xyz="0 0 0" rpy="0 -0 0"/>      
      <geometry>        
        <mesh filename="package:///meshes/left_ball_joint_container_visual.stl"/>        
      </geometry>      
      <material name="ball_joint_container_material">        
        <color rgba="0.61568627450980395466 0.81176470588235294379 0.92941176470588238168 1.0"/>        
      </material>      
    </visual>    
    <collision>      
      <origin xyz="0 0 0" rpy="0 -0 0"/>      
      <geometry>        
        <mesh filename="package:///meshes/left_ball_joint_container_collision.stl"/>        
      </geometry>      
    </collision>    
    <inertial>      
      <origin xyz="4.7221442975709636831e-19 -1.2157539084691861758e-19 -0.0097125341669083414126" rpy="0 0 0"/>      
      <mass value="4.803735642533054869e-05"/>      
      <inertia ixx="7.1865480628741666366e-10" ixy="-1.421490150844785112e-26" ixz="-1.4530380721804784323e-39" iyy="8.475420427718555978e-10" iyz="-1.8243249785865228861e-39" izz="1.8625314111651911712e-10"/>      
    </inertial>    
  </link>  

  <link name="ball_joint_ball">    
    <visual>      
      <origin xyz="0 0 0" rpy="0 -0 0"/>      
      <geometry>        
        <mesh filename="package:///meshes/left_ball_joint_ball_visual.stl"/>        
      </geometry>      
      <material name="ball_joint_ball_material">        
        <color rgba="0.3291302810242056065 0.44310466418644928188 0.69204871161977121741 1.0"/>        
      </material>      
    </visual>    
    <collision>      
      <origin xyz="0 0 0" rpy="0 -0 0"/>      
      <geometry>        
        <mesh filename="package:///meshes/left_ball_joint_ball_collision.stl"/>        
      </geometry>      
    </collision>    
    <inertial>      
      <origin xyz="-1.2187840768435616288e-18 -0.0010308669810016346004 1.3240902759699828661e-19" rpy="0 0 0"/>      
      <mass value="4.4053796295264630609e-05"/>      
      <inertia ixx="3.1285011349692541014e-10" ixy="5.8769689062812943358e-26" ixz="2.2290409120613672916e-26" iyy="6.2569568612795747298e-11" iyz="-5.3035962353690109681e-26" izz="3.1285321460376643623e-10"/>      
    </inertial>    
  </link>  

  <link name="12lf">    
    <visual>      
      <origin xyz="0 0 0" rpy="0 -0 0"/>      
      <geometry>        
        <mesh filename="package:///meshes/left_12lf_visual.stl"/>        
      </geometry>      
      <material name="12lf_material">        
        <color rgba="0.62004392100736027693 0.58836684613512635345 0.49897069021535678246 1.0"/>        
      </material>      
    </visual>    
    <collision>      
      <origin xyz="0 0 0" rpy="0 -0 0"/>      
      <geometry>        
        <mesh filename="package:///meshes/left_12lf_collision.stl"/>        
      </geometry>      
    </collision>    
    <inertial>      
      <origin xyz="0.0049084207243746558885 -0.0001380243994355282377 -0.02994700357716316777" rpy="0 0 0"/>      
      <mass value="0.044782197696050352054"/>      
      <inertia ixx="1.5260128421324721396e-05" ixy="2.2955773687015434455e-08" ixz="-8.1364204004104932134e-08" iyy="1.8188469778966113777e-05" iyz="-5.554224084309430267e-08" izz="5.1496273901764499242e-06"/>      
    </inertial>    
  </link>  

  <link name="12lf_rod">    
    <visual>      
      <origin xyz="0 0 0" rpy="0 -0 0"/>      
      <geometry>        
        <mesh filename="package:///meshes/left_12lf_rod_visual.stl"/>        
      </geometry>      
      <material name="12lf_rod_material">        
        <color rgba="0.80250260812861884396 0.89340612183512713163 0.94491811293548189088 1.0"/>        
      </material>      
    </visual>    
    <collision>      
      <origin xyz="0 0 0" rpy="0 -0 0"/>      
      <geometry>        
        <mesh filename="package:///meshes/left_12lf_rod_collision.stl"/>        
      </geometry>      
    </collision>    
    <inertial>      
      <origin xyz="-6.3222084044030599913e-07 4.6933255325242463709e-07 -0.012893387334327651578" rpy="0 0 0"/>      
      <mass value="0.0025088292483592140175"/>      
      <inertia ixx="2.6944521128627872589e-07" ixy="7.1389570352208077751e-15" ixz="1.3562243135683134105e-11" iyy="2.6944520001684417585e-07" iyz="-1.0089988427242790173e-11" izz="1.7809843599861032107e-08"/>      
    </inertial>    
  </link>  

  <joint name="left_ank_act1" type="prismatic">    
    <origin xyz="2.2722093542849874925e-06 9.5062846483529028774e-16 -0.072660031604104974301" rpy="-3.1415926535896594451 8.6956799327801851499e-14 -2.2021168238262722738"/>    
    <parent link="12lf"/>    
    <child link="12lf_rod"/>    
    <axis xyz="0 0 1"/>    
    <limit effort="1" velocity="20" lower="0" upper="0.040000000000000000833"/>    
    <joint_properties friction="0.0"/>    
  </joint>  

  <joint name="left_ank_B31" type="revolute">    
    <origin xyz="-3.4694469519536141888e-18 -0.0064387505004004086384 -6.9388939039072283776e-18" rpy="-1.570796326794896558 0.16913440034103149889 1.5363542389808260585e-15"/>    
    <parent link="ball_joint_ball"/>    
    <child link="12lf"/>    
    <axis xyz="0 0 1"/>    
    <limit effort="1" velocity="20" lower="-0.785398163397448279" upper="0.785398163397448279"/>    
    <joint_properties friction="0.0"/>    
  </joint>  

  <joint name="left_ank_B21" type="revolute">    
    <origin xyz="0 0 -0.011499999999999996336" rpy="1.570796326794896558 -1.4285697747625092369 1.5707963267948912289"/>    
    <parent link="ball_joint_container"/>    
    <child link="ball_joint_ball"/>    
    <axis xyz="0 0 1"/>    
    <limit effort="1" velocity="20" lower="-0.785398163397448279" upper="0.785398163397448279"/>    
    <joint_properties friction="0.0"/>    
  </joint>  

  <joint name="left_ank_B11" type="revolute">    
    <origin xyz="0.008000000000000053943 -0.014999999999999985567 0.028299999999999915501" rpy="-1.57079632679489678 1.4696360140379260972 1.5707963267948892305"/>    
    <parent link="left_calf_link"/>    
    <child link="ball_joint_container"/>    
    <axis xyz="0 0 1"/>    
    <limit effort="1" velocity="20" lower="-0.785398163397448279" upper="0.785398163397448279"/>    
    <joint_properties friction="0.0"/>    
  </joint>  

  <link name="ball_joint_container_2">    
    <visual>      
      <origin xyz="0 0 0" rpy="0 -0 0"/>      
      <geometry>        
        <mesh filename="package:///meshes/left_ball_joint_container_2_visual.stl"/>        
      </geometry>      
      <material name="ball_joint_container_2_material">        
        <color rgba="0.61568627450980395466 0.81176470588235294379 0.92941176470588238168 1.0"/>        
      </material>      
    </visual>    
    <collision>      
      <origin xyz="0 0 0" rpy="0 -0 0"/>      
      <geometry>        
        <mesh filename="package:///meshes/left_ball_joint_container_2_collision.stl"/>        
      </geometry>      
    </collision>    
    <inertial>      
      <origin xyz="4.7221442975707527938e-19 -2.7877151006475838412e-17 -0.0097125341669083414126" rpy="0 0 0"/>      
      <mass value="4.803735642533054869e-05"/>      
      <inertia ixx="7.1865480628741645687e-10" ixy="-7.8479576573146159873e-27" ixz="-5.4661027899486823274e-39" iyy="8.4754204277185539101e-10" iyz="-3.6300291765716983297e-39" izz="1.8625314111651911712e-10"/>      
    </inertial>    
  </link>  

  <link name="ball_joint_ball_2">    
    <visual>      
      <origin xyz="0 0 0" rpy="0 -0 0"/>      
      <geometry>        
        <mesh filename="package:///meshes/left_ball_joint_ball_2_visual.stl"/>        
      </geometry>      
      <material name="ball_joint_ball_2_material">        
        <color rgba="0.3291302810242056065 0.44310466418644928188 0.69204871161977121741 1.0"/>        
      </material>      
    </visual>    
    <collision>      
      <origin xyz="0 0 0" rpy="0 -0 0"/>      
      <geometry>        
        <mesh filename="package:///meshes/left_ball_joint_ball_2_collision.stl"/>        
      </geometry>      
    </collision>    
    <inertial>      
      <origin xyz="7.0933134036350132379e-19 -0.0010308669810016209394 -6.4355432276454393889e-18" rpy="0 0 0"/>      
      <mass value="4.4053796295264630609e-05"/>      
      <inertia ixx="3.1285011349692447956e-10" ixy="-1.2221233653671682663e-25" ixz="1.3874524286390583258e-27" iyy="6.2569568612795979942e-11" iyz="-7.383691167246965188e-26" izz="3.1285321460376555735e-10"/>      
    </inertial>    
  </link>  

  <link name="12lf_2">    
    <visual>      
      <origin xyz="0 0 0" rpy="0 -0 0"/>      
      <geometry>        
        <mesh filename="package:///meshes/left_12lf_2_visual.stl"/>        
      </geometry>      
      <material name="12lf_2_material">        
        <color rgba="0.62004392100736005489 0.58836684613512635345 0.49897069021535678246 1.0"/>        
      </material>      
    </visual>    
    <collision>      
      <origin xyz="0 0 0" rpy="0 -0 0"/>      
      <geometry>        
        <mesh filename="package:///meshes/left_12lf_2_collision.stl"/>        
      </geometry>      
    </collision>    
    <inertial>      
      <origin xyz="0.0049084207243678852628 -0.00013802439943754287507 -0.029947003577162144283" rpy="0 0 0"/>      
      <mass value="0.044782197696050352054"/>      
      <inertia ixx="1.526012842132411492e-05" ixy="2.2955773686902024684e-08" ixz="-8.1364204006934829506e-08" iyy="1.8188469778966909988e-05" iyz="-5.5542240844160366426e-08" izz="5.149627390177910209e-06"/>      
    </inertial>    
  </link>  

  <link name="12lf_rod_2">    
    <visual>      
      <origin xyz="0 0 0" rpy="0 -0 0"/>      
      <geometry>        
        <mesh filename="package:///meshes/left_12lf_rod_2_visual.stl"/>        
      </geometry>      
      <material name="12lf_rod_2_material">        
        <color rgba="0.80250260812861884396 0.89340612183512713163 0.94491811293548189088 1.0"/>        
      </material>      
    </visual>    
    <collision>      
      <origin xyz="0 0 0" rpy="0 -0 0"/>      
      <geometry>        
        <mesh filename="package:///meshes/left_12lf_rod_2_collision.stl"/>        
      </geometry>      
    </collision>    
    <inertial>      
      <origin xyz="-6.3222083682940327443e-07 4.6933255273116294363e-07 -0.012893387334328737515" rpy="0 0 0"/>      
      <mass value="0.0025088292483592140175"/>      
      <inertia ixx="2.6944521128621848067e-07" ixy="7.1389570380698167996e-15" ixz="1.3562243029622056966e-11" iyy="2.6944520001678393063e-07" iyz="-1.0089988411801239376e-11" izz="1.7809843599861002329e-08"/>      
    </inertial>    
  </link>  

  <joint name="left_ank_act2" type="prismatic">    
    <origin xyz="2.2722093491103073637e-06 -6.5433769513845163601e-15 -0.072660030478827297706" rpy="-3.1415926535895009053 6.1538805987964111831e-14 -2.2021168238262798234"/>    
    <parent link="12lf_2"/>    
    <child link="12lf_rod_2"/>    
    <axis xyz="0 0 1"/>    
    <limit effort="1" velocity="20" lower="0" upper="0.040000000000000000833"/>    
    <joint_properties friction="0.0"/>    
  </joint>  

  <joint name="left_ank_B32" type="revolute">    
    <origin xyz="1.9949319973733281586e-17 -0.0064387505004002698605 1.3877787807814456755e-17" rpy="-1.5707963267948970021 -0.17993145005780439294 -1.804382386805444098e-17"/>    
    <parent link="ball_joint_ball_2"/>    
    <child link="12lf_2"/>    
    <axis xyz="0 0 1"/>    
    <limit effort="1" velocity="20" lower="-0.785398163397448279" upper="0.785398163397448279"/>    
    <joint_properties friction="0.0"/>    
  </joint>  

  <joint name="left_ank_B22" type="revolute">    
    <origin xyz="-6.9388939039072283776e-18 -8.3266726846886740532e-17 -0.011499999999999996336" rpy="1.5707963267948961139 -1.4285463212680367118 -1.5707963267948970021"/>    
    <parent link="ball_joint_container_2"/>    
    <child link="ball_joint_ball_2"/>    
    <axis xyz="0 0 1"/>    
    <limit effort="1" velocity="20" lower="-0.785398163397448279" upper="0.785398163397448279"/>    
    <joint_properties friction="0.0"/>    
  </joint>  

  <joint name="left_ank_B12" type="revolute">    
    <origin xyz="0.0080000000000000504735 -0.014999999999999930056 -0.011500000000000076134" rpy="-1.5707963267948958919 -1.4697566621822790722 1.5707963267948983344"/>    
    <parent link="left_calf_link"/>    
    <child link="ball_joint_container_2"/>    
    <axis xyz="0 0 1"/>    
    <limit effort="1" velocity="20" lower="-0.785398163397448279" upper="0.785398163397448279"/>    
    <joint_properties friction="0.0"/>    
  </joint>  

  <joint name="left_knee" type="revolute">    
    <origin xyz="-6.5714384231211065113e-15 0.09599999999999973832 0.027400000000000167277" rpy="-3.1415926535897891192 1.5325113271907731669e-16 -5.5621661637730288381e-17"/>    
    <parent link="left_hip_pitch_link"/>    
    <child link="left_calf_link"/>    
    <axis xyz="0 0 1"/>    
    <limit effort="1" velocity="20" lower="-1.570796326794896558" upper="2.2689280275926284602"/>    
    <joint_properties friction="0.0"/>    
  </joint>  

  <joint name="left_hip_pitch" type="revolute">    
    <origin xyz="-0.02400000071615384506 -0.019000000152441031548 -0.019000000152448098811" rpy="-1.570796326794478226 1.5707963267948008568 0"/>    
    <parent link="hip_roll_link"/>    
    <child link="left_hip_pitch_link"/>    
    <axis xyz="0 0 1"/>    
    <limit effort="1" velocity="20" lower="-1.570796326794896558" upper="1.570796326794896558"/>    
    <joint_properties friction="0.0"/>    
  </joint>  

  <joint name="left_hip_roll" type="revolute">    
    <origin xyz="0.019000000000000273614 -2.891526265917987331e-16 -0.026000000000000279832" rpy="-3.141592653589793116 -1.5707963267945983521 0"/>    
    <parent link="hip_yaw_link"/>    
    <child link="hip_roll_link"/>    
    <axis xyz="0 0 1"/>    
    <limit effort="1" velocity="20" lower="-1.570796326794896558" upper="1.570796326794896558"/>    
    <joint_properties friction="0.0"/>    
  </joint>  


</robot>