<robot name="toddlerbot_legs">
  <mujoco>
    <compiler strippath="false" balanceinertia="true" discardvisual="false" />
  </mujoco>
  <link name="body_link">
    <visual>
      <origin xyz="0 0 0" rpy="0 -0 0" />
      <geometry>
        <mesh filename="../assemblies/no_body/meshes/body_link_visual.stl" />
      </geometry>
      <material name="body_link_material">
        <color rgba="0.60265235106909254004 0.74758186619713706822 0.82292492068132760963 1.0" />
      </material>
    </visual>
    <collision>
      <origin xyz="0 0 0" rpy="0 -0 0" />
      <geometry>
        <mesh filename="collisions/body_link_collision.stl" />
      </geometry>
    </collision>
    <inertial>
      <origin xyz="-0.014403523331510958982 -0.00023164401215090967977 0.31153288519557337244" rpy="0 0 0" />
      <mass value="0.1326329205818372603" />
      <inertia ixx="0.00012163093315384152372" ixy="1.4038303149150823224e-07" ixz="1.0872278951927058559e-05" iyy="8.4970137932106160972e-05" iyz="3.8740821289234436463e-07" izz="0.00015647103471607424" />
    </inertial>
  </link>

  <joint name="left_hip_yaw" type="revolute">
    <origin xyz="-0.0063999999999966063202 0.033999999999999308553 0.28550000000000003153" rpy="2.3275728331677864905e-16 1.1102230242191363653e-16 -1.222458086656465435e-13" />
    <parent link="body_link" />
    <child link="hip_yaw_link" />
    <axis xyz="0 0 1" />
    <limit effort="1" velocity="20" lower="-0.785398163397448279" upper="0.785398163397448279" />
    <joint_properties friction="0.0" />
  </joint>

  <joint name="right_hip_yaw" type="revolute">
    <origin xyz="-0.0063999999999967980072 -0.034000000000000668576 0.28549999999999992051" rpy="1.2173498094825229595e-16 9.8900267199457111713e-23 -3.0336177719551955022e-13" />
    <parent link="body_link" />
    <child link="hip_yaw_link_2" />
    <axis xyz="0 0 1" />
    <limit effort="1" velocity="20" lower="-0.785398163397448279" upper="0.785398163397448279" />
    <joint_properties friction="0.0" />
  </joint>


  <link name="hip_yaw_link">
    <visual>
      <origin xyz="0 0 0" rpy="0 -0 0" />
      <geometry>
        <mesh filename="../assemblies/left_3R+RH5_leg/meshes/left_hip_yaw_link_visual.stl" />
      </geometry>
      <material name="hip_yaw_link_material">
        <color rgba="0.61568627450980395466 0.81176470588235294379 0.9294117647058824927 1.0" />
      </material>
    </visual>
    <inertial>
      <origin xyz="1.7870850561133597049e-19 -1.785635794355923629e-19 -0.0098390489054830162358" rpy="0 0 0" />
      <mass value="0.009025883737097921064" />
      <inertia ixx="1.3230458239086463031e-06" ixy="-3.3592249637948231893e-24" ixz="-1.1251788840973426872e-52" iyy="3.8408510960331422723e-06" iyz="2.3044956050358327818e-34" izz="3.872139628579389935e-06" />
    </inertial>
  </link>

  <link name="hip_roll_link">
    <visual>
      <origin xyz="0 0 0" rpy="0 -0 0" />
      <geometry>
        <mesh filename="../assemblies/left_3R+RH5_leg/meshes/left_hip_roll_link_visual.stl" />
      </geometry>
      <material name="hip_roll_link_material">
        <color rgba="0.95018735644455865064 0.7067892720042843191 0.061612079402596720001 1.0" />
      </material>
    </visual>
    <collision>
      <origin xyz="0 0 0" rpy="0 -0 0" />
      <geometry>
        <mesh filename="collisions/left_hip_roll_link_collision.stl" />
      </geometry>
    </collision>
    <inertial>
      <origin xyz="-0.012000151133963046085 -0.00049588831385030695577 -0.018504019244504354286" rpy="0 0 0" />
      <mass value="0.098012391483528651936" />
      <inertia ixx="2.0221748766306544561e-05" ixy="-4.155206824338300164e-08" ixz="-4.122559218785909336e-08" iyy="2.7358099958307369529e-05" iyz="-5.0935731752375891667e-07" izz="2.7358069524723443051e-05" />
    </inertial>
  </link>

  <link name="left_hip_pitch_link">
    <visual>
      <origin xyz="0 0 0" rpy="0 -0 0" />
      <geometry>
        <mesh filename="../assemblies/left_3R+RH5_leg/meshes/left_hip_pitch_link_visual.stl" />
      </geometry>
      <material name="left_hip_pitch_link_material">
        <color rgba="0.61654126329715297494 0.80727601474877130894 0.92171686561974230933 1.0" />
      </material>
    </visual>
    <collision>
      <origin xyz="0 0 0" rpy="0 -0 0" />
      <geometry>
        <mesh filename="collisions/left_hip_pitch_link_collision.stl" />
      </geometry>
    </collision>
    <inertial>
      <origin xyz="-0.00021937270136342836685 0.052864534275054879398 0.014710916171980384023" rpy="0 0 0" />
      <mass value="0.093539065135968837983" />
      <inertia ixx="6.2495911267233984635e-05" ixy="4.2816836354857426374e-07" ixz="-1.5156170028210166404e-07" iyy="2.1496152188538117389e-05" iyz="-1.4210874963076972095e-06" izz="6.2275948339171632211e-05" />
    </inertial>
  </link>

  <link name="left_calf_link">
    <visual>
      <origin xyz="0 0 0" rpy="0 -0 0" />
      <geometry>
        <mesh filename="../assemblies/left_3R+RH5_leg/meshes/left_calf_link_visual.stl" />
      </geometry>
      <material name="left_calf_link_material">
        <color rgba="0.55185394916441454782 0.72972232177804008391 0.87665656864243646229 1.0" />
      </material>
    </visual>
    <collision>
      <origin xyz="0 0 0" rpy="0 -0 0" />
      <geometry>
        <mesh filename="collisions/left_calf_link_collision.stl" />
      </geometry>
    </collision>
    <inertial>
      <origin xyz="-0.0038993024960581384661 -0.042419338531024732009 0.0081864888082305280886" rpy="0 0 0" />
      <mass value="0.015782434194230747504" />
      <inertia ixx="1.4745030589956163153e-05" ixy="-2.0221927128075094588e-07" ixz="8.9866943649240032147e-09" iyy="1.8970750490643143955e-06" iyz="1.7803237244175938131e-08" izz="1.4045051134993895314e-05" />
    </inertial>
  </link>

  <link name="ank_pitch_link">
    <visual>
      <origin xyz="0 0 0" rpy="0 -0 0" />
      <geometry>
        <mesh filename="../assemblies/left_3R+RH5_leg/meshes/left_ank_pitch_link_visual.stl" />
      </geometry>
      <material name="ank_pitch_link_material">
        <color rgba="0.63189161126160264814 0.7266866879354088038 0.78356373393969258601 1.0" />
      </material>
    </visual>
    <inertial>
      <origin xyz="4.0269685029020114529e-08 0.00059528282566723492424 -0.01459992238389042768" rpy="0 0 0" />
      <mass value="0.0042238381753791614387" />
      <inertia ixx="4.370525406739012277e-07" ixy="1.6834347239425813868e-13" ixz="1.6428822387952857182e-12" iyy="3.9782741364650853327e-07" iyz="2.0919243889297784017e-14" izz="8.8858574534559453948e-08" />
    </inertial>
  </link>

  <link name="ank_roll_link">
    <visual>
      <origin xyz="0 0 0" rpy="0 -0 0" />
      <geometry>
        <mesh filename="../assemblies/left_3R+RH5_leg/meshes/left_ank_roll_link_visual.stl" />
      </geometry>
      <material name="ank_roll_link_material">
        <color rgba="0.61568627450980395466 0.81176470588235305481 0.9294117647058824927 1.0" />
      </material>
    </visual>
    <collision>
      <origin xyz="0 0 0" rpy="0 -0 0" />
      <geometry>
        <mesh filename="collisions/left_ank_roll_link_collision.stl" />
      </geometry>
    </collision>
    <inertial>
      <origin xyz="-0.0070959190440405247105 0.031669497990247645614 0.001544723586574429236" rpy="0 0 0" />
      <mass value="0.020312412324461778801" />
      <inertia ixx="1.4885431871170690606e-05" ixy="7.6720315169413908931e-07" ixz="8.1066474591240201501e-07" iyy="1.7915307273613421089e-05" iyz="-1.1563439729789050706e-06" izz="6.9141159895670469319e-06" />
    </inertial>
  </link>

  <link name="ank_rr_link">
    <visual>
      <origin xyz="0 0 0" rpy="0 -0 0" />
      <geometry>
        <mesh filename="../assemblies/left_3R+RH5_leg/meshes/left_ank_rr_link_visual.stl" />
      </geometry>
      <material name="ank_rr_link_material">
        <color rgba="0.61568627450980395466 0.81176470588235283277 0.92941176470588238168 1.0" />
      </material>
    </visual>
    <inertial>
      <origin xyz="8.9446519574371840559e-20 -0.0061447686137497915457 2.166744703752639102e-19" rpy="0 0 0" />
      <mass value="0.00042507093693768156772" />
      <inertia ixx="8.7843229279236022739e-09" ixy="-2.2425252682654232171e-26" ixz="-1.0879024114875648572e-14" iyy="8.0301730481463919886e-09" iyz="7.3151635311327051496e-33" izz="1.2504379836120061674e-08" />
    </inertial>
  </link>

  <link name="12lf_rod_end">
    <visual>
      <origin xyz="0 0 0" rpy="0 -0 0" />
      <geometry>
        <mesh filename="../assemblies/left_3R+RH5_leg/meshes/left_12lf_rod_end_visual.stl" />
      </geometry>
      <material name="12lf_rod_end_material">
        <color rgba="0.92771758928836545177 0.61049283053223013518 0.21847658490585164515 1.0" />
      </material>
    </visual>
    <inertial>
      <origin xyz="-4.4735192496414894993e-11 -0.0038422185938246020132 6.4384187209429587798e-06" rpy="0 0 0" />
      <mass value="0.00085420491177815895123" />
      <inertia ixx="1.1840985264406792357e-08" ixy="2.0225978027959712649e-16" ixz="-9.2606419949056756807e-16" iyy="3.3549621576797276408e-09" iyz="7.4535631381859263885e-12" izz="1.2703522254419981579e-08" />
    </inertial>
  </link>

  <joint name="left_ank_R21" type="fixed">
    <origin xyz="0 -0.0099999999999999533706 0" rpy="1.570796326794896558 -1.5664147454868542209 -1.5707963267948135133" />
    <parent link="ank_rr_link" />
    <child link="12lf_rod_end" />
    <axis xyz="0 0 1" />
    <limit effort="1" velocity="20" lower="-1.570796326794896558" upper="1.570796326794896558" />
    <joint_properties friction="0.0" />
  </joint>

  <joint name="left_ank_R11" type="fixed">
    <origin xyz="-0.018000000000000009048 0.016000000000000014211 -0.020599999999999996786" rpy="-4.1594268726375658989e-17 6.5315524930102152625e-16 -0.01877926248499593373" />
    <parent link="ank_roll_link" />
    <child link="ank_rr_link" />
    <axis xyz="0 0 1" />
    <limit effort="1" velocity="20" lower="-1.570796326794896558" upper="1.570796326794896558" />
    <joint_properties friction="0.0" />
  </joint>

  <link name="ank_rr_link_2">
    <visual>
      <origin xyz="0 0 0" rpy="0 -0 0" />
      <geometry>
        <mesh filename="../assemblies/left_3R+RH5_leg/meshes/left_ank_rr_link_2_visual.stl" />
      </geometry>
      <material name="ank_rr_link_2_material">
        <color rgba="0.61568627450980395466 0.81176470588235283277 0.92941176470588238168 1.0" />
      </material>
    </visual>
    <inertial>
      <origin xyz="-3.4015524252031873681e-18 -0.0061447686137497915457 2.1667447037527045836e-19" rpy="0 0 0" />
      <mass value="0.00042507093693768156772" />
      <inertia ixx="8.7843229279236055827e-09" ixy="3.2381784308691485543e-27" ixz="-1.0879024114875650149e-14" iyy="8.0301730481463919886e-09" iyz="1.0413059140256246147e-32" izz="1.2504379836120061674e-08" />
    </inertial>
  </link>

  <link name="12lf_rod_end_2">
    <visual>
      <origin xyz="0 0 0" rpy="0 -0 0" />
      <geometry>
        <mesh filename="../assemblies/left_3R+RH5_leg/meshes/left_12lf_rod_end_2_visual.stl" />
      </geometry>
      <material name="12lf_rod_end_2_material">
        <color rgba="0.92771758928836545177 0.61049283053223013518 0.21847658490585164515 1.0" />
      </material>
    </visual>
    <inertial>
      <origin xyz="-4.4735192535559737604e-11 -0.0038422185938245686197 6.438418720946820403e-06" rpy="0 0 0" />
      <mass value="0.00085420491177815895123" />
      <inertia ixx="1.1840985264406782431e-08" ixy="2.0225977889760795223e-16" ixz="-9.2606419871776195442e-16" iyy="3.3549621576797305359e-09" iyz="7.4535631381846032227e-12" izz="1.2703522254419958418e-08" />
    </inertial>
  </link>

  <joint name="left_ank_R22" type="fixed">
    <origin xyz="0 -0.0099999999999999533706 0" rpy="-1.570796326794896558 -1.5664376509758224376 1.570796326795195208" />
    <parent link="ank_rr_link_2" />
    <child link="12lf_rod_end_2" />
    <axis xyz="0 0 1" />
    <limit effort="1" velocity="20" lower="-1.570796326794896558" upper="1.570796326794896558" />
    <joint_properties friction="0.0" />
  </joint>

  <joint name="left_ank_R12" type="fixed">
    <origin xyz="0.017999999999999995171 0.016000000000000014211 -0.020600000000000000255" rpy="3.1415926535897922278 7.4438972302667006905e-16 -3.1229304365180685643" />
    <parent link="ank_roll_link" />
    <child link="ank_rr_link_2" />
    <axis xyz="0 0 1" />
    <limit effort="1" velocity="20" lower="-1.570796326794896558" upper="1.570796326794896558" />
    <joint_properties friction="0.0" />
  </joint>

  <joint name="left_ank_roll" type="revolute">
    <origin xyz="3.0531133177191804862e-15 0.001500000000004121951 -0.014599999999997613151" rpy="-1.5707963267949702768 -1.5707963267946758457 0" />
    <parent link="ank_pitch_link" />
    <child link="ank_roll_link" />
    <axis xyz="0 0 1" />
    <limit effort="1" velocity="20" lower="-0.785398163397448279" upper="0.785398163397448279" />
    <joint_properties friction="0.0" />
  </joint>

  <joint name="left_ank_pitch" type="revolute">
    <origin xyz="5.9135023084202893979e-19 -0.10000000000000006106 -0.0061999999999999989148" rpy="3.141592653589793116 3.3306690738944506007e-16 -1.5707963267948974462" />
    <parent link="left_calf_link" />
    <child link="ank_pitch_link" />
    <axis xyz="0 0 1" />
    <limit effort="1" velocity="20" lower="-0.785398163397448279" upper="0.95993108859688125456" />
    <joint_properties friction="0.0" />
  </joint>

  <link name="ball_joint_container">
    <visual>
      <origin xyz="0 0 0" rpy="0 -0 0" />
      <geometry>
        <mesh filename="../assemblies/left_3R+RH5_leg/meshes/left_ball_joint_container_visual.stl" />
      </geometry>
      <material name="ball_joint_container_material">
        <color rgba="0.61568627450980395466 0.81176470588235294379 0.9294117647058824927 1.0" />
      </material>
    </visual>
    <inertial>
      <origin xyz="4.7221442975710667203e-19 -2.7876926753568472755e-17 -0.0097125341669083414126" rpy="0 0 0" />
      <mass value="4.8037356425330562243e-05" />
      <inertia ixx="7.1865480628741666366e-10" ixy="2.1201121793586067148e-27" ixz="7.7507869186274003536e-39" iyy="8.475420427718555978e-10" iyz="-5.4122729222198885996e-39" izz="1.8625314111651911712e-10" />
    </inertial>
  </link>

  <link name="ball_joint_ball">
    <visual>
      <origin xyz="0 0 0" rpy="0 -0 0" />
      <geometry>
        <mesh filename="../assemblies/left_3R+RH5_leg/meshes/left_ball_joint_ball_visual.stl" />
      </geometry>
      <material name="ball_joint_ball_material">
        <color rgba="0.3291302810242056065 0.44310466418644928188 0.69204871161977121741 1.0" />
      </material>
    </visual>
    <inertial>
      <origin xyz="-1.1042142579256435702e-18 -0.0010308669810016035922 -2.0834195949858446323e-18" rpy="0 0 0" />
      <mass value="4.4053796295264623832e-05" />
      <inertia ixx="3.1285011349692453126e-10" ixy="4.4666440021609585016e-26" ixz="-4.9778106113950895167e-30" iyy="6.2569568612795618051e-11" iyz="2.364805574972257922e-26" izz="3.1285321460376416148e-10" />
    </inertial>
  </link>

  <link name="12lf">
    <visual>
      <origin xyz="0 0 0" rpy="0 -0 0" />
      <geometry>
        <mesh filename="../assemblies/left_3R+RH5_leg/meshes/left_12lf_visual.stl" />
      </geometry>
      <material name="12lf_material">
        <color rgba="0.62004392096503557763 0.58836684612040224263 0.49897069027350271497 1.0" />
      </material>
    </visual>
    <inertial>
      <origin xyz="0.0049084207226956708126 -0.00013802440006612125474 -0.029947003575852761126" rpy="0 0 0" />
      <mass value="0.044782197690790462308" />
      <inertia ixx="1.5260128420493741417e-05" ixy="2.2955774098747942706e-08" ixz="-8.1364204856713619348e-08" iyy="1.8188469777214642765e-05" iyz="-5.5542241170898124517e-08" izz="5.1496273889341803923e-06" />
    </inertial>
  </link>

  <link name="12lf_rod">
    <visual>
      <origin xyz="0 0 0" rpy="0 -0 0" />
      <geometry>
        <mesh filename="../assemblies/left_3R+RH5_leg/meshes/left_12lf_rod_visual.stl" />
      </geometry>
      <material name="12lf_rod_material">
        <color rgba="0.80250260812861884396 0.89340612183512713163 0.94491811293548189088 1.0" />
      </material>
    </visual>
    <inertial>
      <origin xyz="-6.3222084034124210782e-07 4.6933255258507321245e-07 -0.012893387334326648908" rpy="0 0 0" />
      <mass value="0.0025088292483592144512" />
      <inertia ixx="2.6944521128633399479e-07" ixy="7.1389570406007791952e-15" ixz="1.3562243132892060313e-11" iyy="2.6944520001689944475e-07" iyz="-1.0089988408671651612e-11" izz="1.7809843599861028799e-08" />
    </inertial>
  </link>

  <joint name="left_ank_act1" type="fixed">
    <origin xyz="2.2722093531019060819e-06 5.1000870193718128576e-16 -0.074779998095377359091" rpy="-3.1415926535896590011 8.6569212672158331644e-14 -2.2021168238262673889" />
    <parent link="12lf" />
    <child link="12lf_rod" />
    <axis xyz="0 0 1" />
    <limit effort="1" velocity="20" lower="0" upper="0.040000000000000000833" />
    <joint_properties friction="0.0" />
  </joint>

  <joint name="left_ank_B31" type="fixed">
    <origin xyz="0 -0.0064387505004003531273 -3.4694469519536141888e-18" rpy="-1.57079632679489678 0.16913440034090146402 5.8375589418798256921e-16" />
    <parent link="ball_joint_ball" />
    <child link="12lf" />
    <axis xyz="0 0 1" />
    <limit effort="1" velocity="20" lower="-0.785398163397448279" upper="0.785398163397448279" />
    <joint_properties friction="0.0" />
  </joint>

  <joint name="left_ank_B21" type="fixed">
    <origin xyz="-3.4694469519536141888e-18 -2.7755575615628913511e-17 -0.011499999999999999806" rpy="-1.570796326794896558 -1.5664147454872627829 -1.5707963267957041342" />
    <parent link="ball_joint_container" />
    <child link="ball_joint_ball" />
    <axis xyz="0 0 1" />
    <limit effort="1" velocity="20" lower="-0.785398163397448279" upper="0.785398163397448279" />
    <joint_properties friction="0.0" />
  </joint>

  <joint name="left_ank_B11" type="fixed">
    <origin xyz="0.0079999999999999949624 -0.015000000000000096589 0.028299999999999991829" rpy="-1.570796326794896558 1.5520170643097057628 1.5707963267950826314" />
    <parent link="left_calf_link" />
    <child link="ball_joint_container" />
    <axis xyz="0 0 1" />
    <limit effort="1" velocity="20" lower="-0.785398163397448279" upper="0.785398163397448279" />
    <joint_properties friction="0.0" />
  </joint>

  <link name="ball_joint_container_2">
    <visual>
      <origin xyz="0 0 0" rpy="0 -0 0" />
      <geometry>
        <mesh filename="../assemblies/left_3R+RH5_leg/meshes/left_ball_joint_container_2_visual.stl" />
      </geometry>
      <material name="ball_joint_container_2_material">
        <color rgba="0.61568627450980395466 0.81176470588235294379 0.9294117647058824927 1.0" />
      </material>
    </visual>
    <inertial>
      <origin xyz="3.9416613817107039127e-18 -1.2135113793955300922e-19 -0.0097125341669083431473" rpy="0 0 0" />
      <mass value="4.8037356425330562243e-05" />
      <inertia ixx="7.1865480628741666366e-10" ixy="-6.1917919542544475962e-27" ixz="3.828988233046999765e-39" iyy="8.475420427718555978e-10" iyz="-9.2370882590247428667e-40" izz="1.8625314111651911712e-10" />
    </inertial>
  </link>

  <link name="ball_joint_ball_2">
    <visual>
      <origin xyz="0 0 0" rpy="0 -0 0" />
      <geometry>
        <mesh filename="../assemblies/left_3R+RH5_leg/meshes/left_ball_joint_ball_2_visual.stl" />
      </geometry>
      <material name="ball_joint_ball_2_material">
        <color rgba="0.3291302810242056065 0.44310466418644928188 0.69204871161977121741 1.0" />
      </material>
    </visual>
    <inertial>
      <origin xyz="6.8264363430260785831e-17 -0.0010308669810016380698 -2.7183759330352604902e-18" rpy="0 0 0" />
      <mass value="4.4053796295264623832e-05" />
      <inertia ixx="3.1285011349692970114e-10" ixy="-1.8171500499872905553e-25" ixz="-3.5933554087797809692e-24" iyy="6.2569568612796768349e-11" iyz="-2.1997460966267609494e-24" izz="3.1285321460377052043e-10" />
    </inertial>
  </link>

  <link name="12lf_2">
    <visual>
      <origin xyz="0 0 0" rpy="0 -0 0" />
      <geometry>
        <mesh filename="../assemblies/left_3R+RH5_leg/meshes/left_12lf_2_visual.stl" />
      </geometry>
      <material name="12lf_2_material">
        <color rgba="0.62004392096503546661 0.58836684612040224263 0.49897069027350271497 1.0" />
      </material>
    </visual>
    <inertial>
      <origin xyz="0.0049084207226890346279 -0.00013802440006905114848 -0.029947003575852521734" rpy="0 0 0" />
      <mass value="0.044782197690790462308" />
      <inertia ixx="1.5260128420493765134e-05" ixy="2.2955774098694655731e-08" ixz="-8.1364204859471055698e-08" iyy="1.8188469777217068668e-05" iyz="-5.554224117237536983e-08" izz="5.149627388936613918e-06" />
    </inertial>
  </link>

  <link name="12lf_rod_2">
    <visual>
      <origin xyz="0 0 0" rpy="0 -0 0" />
      <geometry>
        <mesh filename="../assemblies/left_3R+RH5_leg/meshes/left_12lf_rod_2_visual.stl" />
      </geometry>
      <material name="12lf_rod_2_material">
        <color rgba="0.80250260812861884396 0.89340612183512713163 0.94491811293548189088 1.0" />
      </material>
    </visual>
    <inertial>
      <origin xyz="-6.3222083727921726234e-07 4.6933255265304607122e-07 -0.012893387334327922195" rpy="0 0 0" />
      <mass value="0.0025088292483592144512" />
      <inertia ixx="2.6944521128626231463e-07" ixy="7.1389570130985463294e-15" ixz="1.3562243041946392165e-11" iyy="2.6944520001682776459e-07" iyz="-1.0089988409599651324e-11" izz="1.7809843599860995711e-08" />
    </inertial>
  </link>

  <joint name="left_ank_act2" type="fixed">
    <origin xyz="2.2722093474362992094e-06 -8.9372953482325101504e-15 -0.074779996992751340823" rpy="-3.1415926535895000171 6.172537580306697636e-14 -2.2021168238262789352" />
    <parent link="12lf_2" />
    <child link="12lf_rod_2" />
    <axis xyz="0 0 1" />
    <limit effort="1" velocity="20" lower="0" upper="0.040000000000000000833" />
    <joint_properties friction="0.0" />
  </joint>

  <joint name="left_ank_B32" type="fixed">
    <origin xyz="2.498001805406602216e-16 -0.0064387505004004919051 -3.4694469519536141888e-18" rpy="-1.570796326794896558 -0.17993145005756983057 3.0408221168269646133e-14" />
    <parent link="ball_joint_ball_2" />
    <child link="12lf_2" />
    <axis xyz="0 0 1" />
    <limit effort="1" velocity="20" lower="-0.785398163397448279" upper="0.785398163397448279" />
    <joint_properties friction="0.0" />
  </joint>

  <joint name="left_ank_B22" type="fixed">
    <origin xyz="3.4694469519536141888e-18 0 -0.01150000000000000154" rpy="-1.570796326794896336 -1.5664376509754431854 1.570796326794866582" />
    <parent link="ball_joint_container_2" />
    <child link="ball_joint_ball_2" />
    <axis xyz="0 0 1" />
    <limit effort="1" velocity="20" lower="-0.785398163397448279" upper="0.785398163397448279" />
    <joint_properties friction="0.0" />
  </joint>

  <joint name="left_ank_B12" type="fixed">
    <origin xyz="0.0080000000000000019013 -0.015000000000000041078 -0.011499999999999999806" rpy="-1.570796326794896558 -1.5521341097218244176 1.5707963267948896746" />
    <parent link="left_calf_link" />
    <child link="ball_joint_container_2" />
    <axis xyz="0 0 1" />
    <limit effort="1" velocity="20" lower="-0.785398163397448279" upper="0.785398163397448279" />
    <joint_properties friction="0.0" />
  </joint>

  <joint name="left_knee" type="revolute">
    <origin xyz="-8.1569325594195215653e-15 0.095999999999999391376 0.027400000000002110168" rpy="3.1415926535897917837 1.6653345451476814222e-16 -5.2069203968451419987e-17" />
    <parent link="left_hip_pitch_link" />
    <child link="left_calf_link" />
    <axis xyz="0 0 1" />
    <limit effort="1" velocity="20" lower="0" upper="1.570796326794896558" />
    <joint_properties friction="0.0" />
  </joint>

  <joint name="left_hip_pitch" type="revolute">
    <origin xyz="-0.024000000716155274472 -0.019000000152442689944 -0.019000000152446339802" rpy="-1.5707963267945199703 1.5707963267948246155 0" />
    <parent link="hip_roll_link" />
    <child link="left_hip_pitch_link" />
    <axis xyz="0 0 1" />
    <limit effort="1" velocity="20" lower="-1.570796326794896558" upper="1.570796326794896558" />
    <joint_properties friction="0.0" />
  </joint>

  <joint name="left_hip_roll" type="revolute">
    <origin xyz="0.01900000000000030137 5.3821911112507180559e-16 -0.026000000000000168809" rpy="3.141592653589793116 -1.5707963267936781993 0" />
    <parent link="hip_yaw_link" />
    <child link="hip_roll_link" />
    <axis xyz="0 0 1" />
    <limit effort="1" velocity="20" lower="-0.785398163397448279" upper="1.570796326794896558" />
    <joint_properties friction="0.0" />
  </joint>


  <link name="hip_yaw_link_2">
    <visual>
      <origin xyz="0 0 0" rpy="0 -0 0" />
      <geometry>
        <mesh filename="../assemblies/right_3R+RH5_leg/meshes/right_hip_yaw_link_visual.stl" />
      </geometry>
      <material name="hip_yaw_link_material">
        <color rgba="0.61568627450980395466 0.81176470588235294379 0.9294117647058824927 1.0" />
      </material>
    </visual>
    <inertial>
      <origin xyz="1.7870850560805124882e-19 -1.7856357941682210522e-19 -0.0098390489054829121524" rpy="0 0 0" />
      <mass value="0.009025883737097921064" />
      <inertia ixx="1.3230458239085874343e-06" ixy="-6.477854591907985348e-49" ixz="1.7322911775161982211e-33" iyy="3.8408510960330541809e-06" iyz="-1.4482241779965781819e-32" izz="3.8721396285793069258e-06" />
    </inertial>
  </link>

  <link name="hip_roll_link_2">
    <visual>
      <origin xyz="0 0 0" rpy="0 -0 0" />
      <geometry>
        <mesh filename="../assemblies/right_3R+RH5_leg/meshes/right_hip_roll_link_visual.stl" />
      </geometry>
      <material name="hip_roll_link_material">
        <color rgba="0.95018735644455842859 0.7067892720042843191 0.061612079402596720001 1.0" />
      </material>
    </visual>
    <collision>
      <origin xyz="0 0 0" rpy="0 -0 0" />
      <geometry>
        <mesh filename="collisions/right_hip_roll_link_collision.stl" />
      </geometry>
    </collision>
    <inertial>
      <origin xyz="0.012000150775887509849 -0.00049588816141320744574 -0.019495980755501008536" rpy="0 0 0" />
      <mass value="0.098012391483528665814" />
      <inertia ixx="2.0221748766306690251e-05" ixy="4.1552068245652282315e-08" ixz="-4.1225592185879438396e-08" iyy="2.7358099958307447456e-05" iyz="5.0935731752393255843e-07" izz="2.7358069524724117289e-05" />
    </inertial>
  </link>

  <link name="right_hip_pitch_link">
    <visual>
      <origin xyz="0 0 0" rpy="0 -0 0" />
      <geometry>
        <mesh filename="../assemblies/right_3R+RH5_leg/meshes/right_hip_pitch_link_visual.stl" />
      </geometry>
      <material name="right_hip_pitch_link_material">
        <color rgba="0.61654126330065683881 0.80727601473037591262 0.92171686558820720148 1.0" />
      </material>
    </visual>
    <collision>
      <origin xyz="0 0 0" rpy="0 -0 0" />
      <geometry>
        <mesh filename="collisions/right_hip_pitch_link_collision.stl" />
      </geometry>
    </collision>
    <inertial>
      <origin xyz="-1.3043817563868164539e-05 0.052864534196662107957 0.014710916112540835254" rpy="0 0 0" />
      <mass value="0.09353906475262946385" />
      <inertia ixx="6.2495912126891124488e-05" ixy="-2.2341467552985648854e-07" ixz="-1.1719709579435535716e-08" iyy="2.150063816786044877e-05" iyz="-1.4210875155541907482e-06" izz="6.2280434774102130346e-05" />
    </inertial>
  </link>

  <link name="right_calf_link">
    <visual>
      <origin xyz="0 0 0" rpy="0 -0 0" />
      <geometry>
        <mesh filename="../assemblies/right_3R+RH5_leg/meshes/right_calf_link_visual.stl" />
      </geometry>
      <material name="right_calf_link_material">
        <color rgba="0.55183757703855651489 0.72973662124660387818 0.87669617832525115197 1.0" />
      </material>
    </visual>
    <collision>
      <origin xyz="0 0 0" rpy="0 -0 0" />
      <geometry>
        <mesh filename="collisions/right_calf_link_collision.stl" />
      </geometry>
    </collision>
    <inertial>
      <origin xyz="-0.0038999626430269102376 0.042409395322589228672 0.0081838728113180648355" rpy="0 0 0" />
      <mass value="0.015779725212993943317" />
      <inertia ixx="1.4735397719668431253e-05" ixy="2.0283446246059437145e-07" ixz="9.1508417303720847237e-09" iyy="1.8964180016897454257e-06" iyz="-1.5463243486045364557e-08" izz="1.4035958490016423058e-05" />
    </inertial>
  </link>

  <link name="ank_pitch_link_2">
    <visual>
      <origin xyz="0 0 0" rpy="0 -0 0" />
      <geometry>
        <mesh filename="../assemblies/right_3R+RH5_leg/meshes/right_ank_pitch_link_visual.stl" />
      </geometry>
      <material name="ank_pitch_link_material">
        <color rgba="0.63189161126160275916 0.7266866879354088038 0.78356373393969258601 1.0" />
      </material>
    </visual>
    <inertial>
      <origin xyz="4.026968641285368054e-08 0.00059528282566746510036 -0.014599922383890091143" rpy="0 0 0" />
      <mass value="0.0042238381753791614387" />
      <inertia ixx="4.3705254067390922157e-07" ixy="1.6834347014799428057e-13" ixz="1.6428822916476734945e-12" iyy="3.978274136465558083e-07" iyz="2.0919205593658055483e-14" izz="8.8858574534520199265e-08" />
    </inertial>
  </link>

  <link name="ank_roll_link_2">
    <visual>
      <origin xyz="0 0 0" rpy="0 -0 0" />
      <geometry>
        <mesh filename="../assemblies/right_3R+RH5_leg/meshes/right_ank_roll_link_visual.stl" />
      </geometry>
      <material name="ank_roll_link_material">
        <color rgba="0.61568627450980406568 0.81176470588235305481 0.92941176470588238168 1.0" />
      </material>
    </visual>
    <collision>
      <origin xyz="0 0 0" rpy="0 -0 0" />
      <geometry>
        <mesh filename="collisions/right_ank_roll_link_collision.stl" />
      </geometry>
    </collision>
    <inertial>
      <origin xyz="0.0070959174823323235837 0.031669497972650013928 0.001544723730759410248" rpy="0 0 0" />
      <mass value="0.020312412236862385784" />
      <inertia ixx="1.4885431783124263564e-05" ixy="-7.6720412005443632341e-07" ixz="-8.1066503931638908931e-07" iyy="1.7915307614905197966e-05" iyz="-1.156343986492672846e-06" izz="6.9141164362347758452e-06" />
    </inertial>
  </link>

  <link name="ank_rr_link_3">
    <visual>
      <origin xyz="0 0 0" rpy="0 -0 0" />
      <geometry>
        <mesh filename="../assemblies/right_3R+RH5_leg/meshes/right_ank_rr_link_visual.stl" />
      </geometry>
      <material name="ank_rr_link_material">
        <color rgba="0.61568627450980395466 0.81176470588235283277 0.92941176470588238168 1.0" />
      </material>
    </visual>
    <inertial>
      <origin xyz="3.5337942346598907057e-18 -0.0061447686137498470568 2.1667447037496360957e-19" rpy="0 0 0" />
      <mass value="0.00042507093693768156772" />
      <inertia ixx="8.7843229279236055827e-09" ixy="-1.7917817808540703063e-26" ixz="-1.0879024114875650149e-14" iyy="8.0301730481463919886e-09" iyz="4.2355501547414480888e-32" izz="1.2504379836120061674e-08" />
    </inertial>
  </link>

  <link name="12lf_rod_end_3">
    <visual>
      <origin xyz="0 0 0" rpy="0 -0 0" />
      <geometry>
        <mesh filename="../assemblies/right_3R+RH5_leg/meshes/right_12lf_rod_end_visual.stl" />
      </geometry>
      <material name="12lf_rod_end_material">
        <color rgba="0.92771758928836545177 0.61049283053223013518 0.21847658490585164515 1.0" />
      </material>
    </visual>
    <inertial>
      <origin xyz="-4.4735198745204001504e-11 -0.0038422185938246289014 6.4384187209446333639e-06" rpy="0 0 0" />
      <mass value="0.00085420491177815895123" />
      <inertia ixx="1.1840985264406785739e-08" ixy="2.0225978137273097662e-16" ixz="-9.2606419974807898323e-16" iyy="3.3549621576797185418e-09" iyz="7.4535631381838762084e-12" izz="1.2703522254419976616e-08" />
    </inertial>
  </link>

  <joint name="right_ank_R21" type="fixed">
    <origin xyz="3.4694469519536141888e-18 -0.010000000000000008882 0" rpy="1.57079632679489678 -1.5664147454870704923 -1.5707963267947753216" />
    <parent link="ank_rr_link_3" />
    <child link="12lf_rod_end_3" />
    <axis xyz="0 0 1" />
    <limit effort="1" velocity="20" lower="-1.570796326794896558" upper="1.570796326794896558" />
    <joint_properties friction="0.0" />
  </joint>

  <joint name="right_ank_R11" type="fixed">
    <origin xyz="-0.018000000000000005579 0.016000000000000014211 -0.020599999999999996786" rpy="-3.5360359477892277706e-16 8.2839943819914169726e-16 -0.018779262484754637164" />
    <parent link="ank_roll_link_2" />
    <child link="ank_rr_link_3" />
    <axis xyz="0 0 1" />
    <limit effort="1" velocity="20" lower="-1.570796326794896558" upper="1.570796326794896558" />
    <joint_properties friction="0.0" />
  </joint>

  <link name="ank_rr_link_4">
    <visual>
      <origin xyz="0 0 0" rpy="0 -0 0" />
      <geometry>
        <mesh filename="../assemblies/right_3R+RH5_leg/meshes/right_ank_rr_link_2_visual.stl" />
      </geometry>
      <material name="ank_rr_link_2_material">
        <color rgba="0.61568627450980395466 0.81176470588235283277 0.92941176470588238168 1.0" />
      </material>
    </visual>
    <inertial>
      <origin xyz="-3.4061457083544488604e-18 -0.0061447686137497915457 -3.2527724815782340247e-18" rpy="0 0 0" />
      <mass value="0.00042507093693768156772" />
      <inertia ixx="8.7843229279236022739e-09" ixy="7.9077189809587699013e-27" ixz="-1.0879024114875648572e-14" iyy="8.0301730481463919886e-09" iyz="1.206439933899918516e-32" izz="1.2504379836120061674e-08" />
    </inertial>
  </link>

  <link name="12lf_rod_end_4">
    <visual>
      <origin xyz="0 0 0" rpy="0 -0 0" />
      <geometry>
        <mesh filename="../assemblies/right_3R+RH5_leg/meshes/right_12lf_rod_end_2_visual.stl" />
      </geometry>
      <material name="12lf_rod_end_2_material">
        <color rgba="0.92771758928836545177 0.6104928305322302462 0.21847658490585164515 1.0" />
      </material>
    </visual>
    <inertial>
      <origin xyz="-4.4735193276697242559e-11 -0.003842218593824629335 6.4384187209448959441e-06" rpy="0 0 0" />
      <mass value="0.00085420491177815895123" />
      <inertia ixx="1.1840985264406787394e-08" ixy="2.0225977929126142616e-16" ixz="-9.2606419983362799018e-16" iyy="3.3549621576797243321e-09" iyz="7.4535631381839666813e-12" izz="1.2703522254419978271e-08" />
    </inertial>
  </link>

  <joint name="right_ank_R22" type="fixed">
    <origin xyz="-3.4694469519536141888e-18 -0.0099999999999999533706 -3.4694469519536141888e-18" rpy="-1.570796326794896336 -1.5664376509754269762 1.5707963267952340658" />
    <parent link="ank_rr_link_4" />
    <child link="12lf_rod_end_4" />
    <axis xyz="0 0 1" />
    <limit effort="1" velocity="20" lower="-1.570796326794896558" upper="1.570796326794896558" />
    <joint_properties friction="0.0" />
  </joint>

  <joint name="right_ank_R12" type="fixed">
    <origin xyz="0.01799999999999999864 0.016000000000000069722 -0.020600000000000003725" rpy="3.1415926535897922278 1.1785067659504147721e-15 -3.1229304365172114721" />
    <parent link="ank_roll_link_2" />
    <child link="ank_rr_link_4" />
    <axis xyz="0 0 1" />
    <limit effort="1" velocity="20" lower="-1.570796326794896558" upper="1.570796326794896558" />
    <joint_properties friction="0.0" />
  </joint>

  <joint name="right_ank_roll" type="revolute">
    <origin xyz="2.0816681711721685133e-15 0.0015000000000089284361 -0.014599999999994599936" rpy="-1.5707963267951812192 1.5707963267946736252 0" />
    <parent link="ank_pitch_link_2" />
    <child link="ank_roll_link_2" />
    <axis xyz="0 0 1" />
    <limit effort="1" velocity="20" lower="-0.785398163397448279" upper="0.785398163397448279" />
    <joint_properties friction="0.0" />
  </joint>

  <joint name="right_ank_pitch" type="revolute">
    <origin xyz="5.0979769291920753058e-19 0.099999999999999977796 -0.0062000000000000023842" rpy="-3.1415926535897926719 5.5511151131695266928e-17 -1.5707963267946121189" />
    <parent link="right_calf_link" />
    <child link="ank_pitch_link_2" />
    <axis xyz="0 0 1" />
    <limit effort="1" velocity="20" lower="-0.785398163397448279" upper="0.95993108859688125456" />
    <joint_properties friction="0.0" />
  </joint>

  <link name="ball_joint_container_3">
    <visual>
      <origin xyz="0 0 0" rpy="0 -0 0" />
      <geometry>
        <mesh filename="../assemblies/right_3R+RH5_leg/meshes/right_ball_joint_container_visual.stl" />
      </geometry>
      <material name="ball_joint_container_material">
        <color rgba="0.61568627450980395466 0.81176470588235294379 0.9294117647058824927 1.0" />
      </material>
    </visual>
    <inertial>
      <origin xyz="4.7221442975705582748e-19 -1.2135113793955736663e-19 -0.0097125341669083414126" rpy="0 0 0" />
      <mass value="4.8037356425330562243e-05" />
      <inertia ixx="7.1865480628741666366e-10" ixy="1.3454930950453311496e-27" ixz="2.222508382224999855e-38" iyy="8.475420427718555978e-10" iyz="-2.3425189133335363393e-38" izz="1.8625314111651911712e-10" />
    </inertial>
  </link>

  <link name="ball_joint_ball_3">
    <visual>
      <origin xyz="0 0 0" rpy="0 -0 0" />
      <geometry>
        <mesh filename="../assemblies/right_3R+RH5_leg/meshes/right_ball_joint_ball_visual.stl" />
      </geometry>
      <material name="ball_joint_ball_material">
        <color rgba="0.3291302810242056065 0.44310466418644928188 0.69204871161977121741 1.0" />
      </material>
    </visual>
    <inertial>
      <origin xyz="4.2858046684579815395e-18 -0.00103086698100160923 -2.3158593935613664431e-18" rpy="0 0 0" />
      <mass value="4.4053796295264623832e-05" />
      <inertia ixx="3.1285011349692401427e-10" ixy="1.4285863097047550493e-25" ixz="-1.0391917933769396806e-28" iyy="6.2569568612795605126e-11" iyz="1.3532407090833657174e-25" izz="3.1285321460376323091e-10" />
    </inertial>
  </link>

  <link name="12lf_3">
    <visual>
      <origin xyz="0 0 0" rpy="0 -0 0" />
      <geometry>
        <mesh filename="../assemblies/right_3R+RH5_leg/meshes/right_12lf_visual.stl" />
      </geometry>
      <material name="12lf_material">
        <color rgba="0.62004392096503557763 0.58836684612040235365 0.49897069027350277048 1.0" />
      </material>
    </visual>
    <inertial>
      <origin xyz="0.0049084207226891846815 -0.0001380244000646913547 -0.02994700357584112807" rpy="0 0 0" />
      <mass value="0.044782197690790462308" />
      <inertia ixx="1.5260128420484905169e-05" ixy="2.2955774098311307148e-08" ixz="-8.1364204859661294004e-08" iyy="1.8188469777204471594e-05" iyz="-5.5542241170235400646e-08" izz="5.149627388932782788e-06" />
    </inertial>
  </link>

  <link name="12lf_rod_3">
    <visual>
      <origin xyz="0 0 0" rpy="0 -0 0" />
      <geometry>
        <mesh filename="../assemblies/right_3R+RH5_leg/meshes/right_12lf_rod_visual.stl" />
      </geometry>
      <material name="12lf_rod_material">
        <color rgba="0.80250260812861884396 0.89340612183512713163 0.94491811293548189088 1.0" />
      </material>
    </visual>
    <inertial>
      <origin xyz="-6.322208407866453834e-07 4.6933255150883510844e-07 -0.012893387334328704555" rpy="0 0 0" />
      <mass value="0.0025088292483592144512" />
      <inertia ixx="2.6944521128621895713e-07" ixy="7.1389570317464702887e-15" ixz="1.3562243144833394732e-11" iyy="2.6944520001678440709e-07" iyz="-1.0089988378804436055e-11" izz="1.7809843599861005638e-08" />
    </inertial>
  </link>

  <joint name="right_ank_act1" type="fixed">
    <origin xyz="2.2722093412017030367e-06 1.8804402479588588903e-15 -0.074779998095388988677" rpy="-3.1415926535897829019 8.526808676235474948e-15 -2.2021168238260906413" />
    <parent link="12lf_3" />
    <child link="12lf_rod_3" />
    <axis xyz="0 0 1" />
    <limit effort="1" velocity="20" lower="0" upper="0.040000000000000000833" />
    <joint_properties friction="0.0" />
  </joint>

  <joint name="right_ank_B31" type="fixed">
    <origin xyz="6.9388939039072283776e-18 -0.0064387505004004086384 6.9388939039072283776e-18" rpy="-1.5707963267948970021 0.1691344003416279107 3.6048302674885136887e-16" />
    <parent link="ball_joint_ball_3" />
    <child link="12lf_3" />
    <axis xyz="0 0 1" />
    <limit effort="1" velocity="20" lower="-0.785398163397448279" upper="0.785398163397448279" />
    <joint_properties friction="0.0" />
  </joint>

  <joint name="right_ank_B21" type="fixed">
    <origin xyz="0 -2.7755575615628913511e-17 -0.011500000000000006745" rpy="-1.570796326794896558 -1.5664147454871475418 -1.5707963267939402119" />
    <parent link="ball_joint_container_3" />
    <child link="ball_joint_ball_3" />
    <axis xyz="0 0 1" />
    <limit effort="1" velocity="20" lower="-0.785398163397448279" upper="0.785398163397448279" />
    <joint_properties friction="0.0" />
  </joint>

  <joint name="right_ank_B11" type="fixed">
    <origin xyz="0.0079999999999999984318 0.015000000000000041078 -0.01150000000000000154" rpy="1.570796326794896558 -1.5520170643097170871 -1.5707963267946734032" />
    <parent link="right_calf_link" />
    <child link="ball_joint_container_3" />
    <axis xyz="0 0 1" />
    <limit effort="1" velocity="20" lower="-0.785398163397448279" upper="0.785398163397448279" />
    <joint_properties friction="0.0" />
  </joint>

  <link name="ball_joint_container_4">
    <visual>
      <origin xyz="0 0 0" rpy="0 -0 0" />
      <geometry>
        <mesh filename="../assemblies/right_3R+RH5_leg/meshes/right_ball_joint_container_2_visual.stl" />
      </geometry>
      <material name="ball_joint_container_2_material">
        <color rgba="0.61568627450980395466 0.81176470588235294379 0.9294117647058824927 1.0" />
      </material>
    </visual>
    <inertial>
      <origin xyz="3.9416613817106338088e-18 -1.2135113793952178508e-19 -0.0097125341669083396778" rpy="0 0 0" />
      <mass value="4.8037356425330562243e-05" />
      <inertia ixx="7.1865480628741645687e-10" ixy="1.6457413421051102025e-27" ixz="2.8064713926205731665e-38" iyy="8.475420427718555978e-10" iyz="-5.5415728254535032661e-38" izz="1.8625314111651911712e-10" />
    </inertial>
  </link>

  <link name="ball_joint_ball_4">
    <visual>
      <origin xyz="0 0 0" rpy="0 -0 0" />
      <geometry>
        <mesh filename="../assemblies/right_3R+RH5_leg/meshes/right_ball_joint_ball_2_visual.stl" />
      </geometry>
      <material name="ball_joint_ball_2_material">
        <color rgba="0.3291302810242056065 0.44310466418644928188 0.69204871161977121741 1.0" />
      </material>
    </visual>
    <inertial>
      <origin xyz="-9.2721964255877919942e-20 -0.0010308669810016374193 -2.8882981434546580683e-18" rpy="0 0 0" />
      <mass value="4.4053796295264623832e-05" />
      <inertia ixx="3.1285011349692546184e-10" ixy="-1.2044196648625981514e-25" ixz="9.0333129686829541926e-29" iyy="6.2569568612795824846e-11" iyz="-6.0739966589080848352e-26" izz="3.1285321460376586754e-10" />
    </inertial>
  </link>

  <link name="12lf_4">
    <visual>
      <origin xyz="0 0 0" rpy="0 -0 0" />
      <geometry>
        <mesh filename="../assemblies/right_3R+RH5_leg/meshes/right_12lf_2_visual.stl" />
      </geometry>
      <material name="12lf_2_material">
        <color rgba="0.62004392096503546661 0.5883668461204021316 0.49897069027350277048 1.0" />
      </material>
    </visual>
    <inertial>
      <origin xyz="0.0049084207226859476875 -0.00013802440006715249363 -0.029947003575835719202" rpy="0 0 0" />
      <mass value="0.044782197690790476186" />
      <inertia ixx="1.5260128420481137567e-05" ixy="2.295577409850246197e-08" ixz="-8.1364204861156651263e-08" iyy="1.8188469777200080575e-05" iyz="-5.5542241171383792034e-08" izz="5.149627388932166995e-06" />
    </inertial>
  </link>

  <link name="12lf_rod_4">
    <visual>
      <origin xyz="0 0 0" rpy="0 -0 0" />
      <geometry>
        <mesh filename="../assemblies/right_3R+RH5_leg/meshes/right_12lf_rod_2_visual.stl" />
      </geometry>
      <material name="12lf_rod_2_material">
        <color rgba="0.80250260812861884396 0.89340612183512713163 0.94491811293548189088 1.0" />
      </material>
    </visual>
    <inertial>
      <origin xyz="-6.3222084078698980818e-07 4.6933255123699131896e-07 -0.012893387334330494789" rpy="0 0 0" />
      <mass value="0.0025088292483592144512" />
      <inertia ixx="2.6944521128612086012e-07" ixy="7.1389570021050091532e-15" ixz="1.3562243142885940151e-11" iyy="2.6944520001668636302e-07" iyz="-1.008998837028744681e-11" izz="1.7809843599861015564e-08" />
    </inertial>
  </link>

  <joint name="right_ank_act2" type="fixed">
    <origin xyz="2.2722093371875529133e-06 -2.8553548414578244774e-15 -0.074779996992751840423" rpy="3.1415926535897922278 3.3072658899692120884e-15 -2.2021168238262864847" />
    <parent link="12lf_4" />
    <child link="12lf_rod_4" />
    <axis xyz="0 0 1" />
    <limit effort="1" velocity="20" lower="0" upper="0.040000000000000000833" />
    <joint_properties friction="0.0" />
  </joint>

  <joint name="right_ank_B32" type="fixed">
    <origin xyz="3.4694469519536141888e-18 -0.0064387505004004086384 -6.9388939039072283776e-18" rpy="-1.570796326794896558 -0.17993145005738314657 -8.7569826039094258121e-17" />
    <parent link="ball_joint_ball_4" />
    <child link="12lf_4" />
    <axis xyz="0 0 1" />
    <limit effort="1" velocity="20" lower="-0.785398163397448279" upper="0.785398163397448279" />
    <joint_properties friction="0.0" />
  </joint>

  <joint name="right_ank_B22" type="fixed">
    <origin xyz="3.4694469519536141888e-18 0 -0.011499999999999998071" rpy="-1.57079632679489678 -1.5664376509754476263 -1.5707963267945079799" />
    <parent link="ball_joint_container_4" />
    <child link="ball_joint_ball_4" />
    <axis xyz="0 0 1" />
    <limit effort="1" velocity="20" lower="-0.785398163397448279" upper="0.785398163397448279" />
    <joint_properties friction="0.0" />
  </joint>

  <joint name="right_ank_B12" type="fixed">
    <origin xyz="0.008000000000000003636 0.015000000000000041078 0.028300000000000019584" rpy="-1.570796326794896558 -1.5521341097221632577 1.5707963267948059638" />
    <parent link="right_calf_link" />
    <child link="ball_joint_container_4" />
    <axis xyz="0 0 1" />
    <limit effort="1" velocity="20" lower="-0.785398163397448279" upper="0.785398163397448279" />
    <joint_properties friction="0.0" />
  </joint>

  <joint name="right_knee" type="revolute">
    <origin xyz="-8.4133172564547814973e-15 0.095999999999998697486 0.027400000000003574274" rpy="3.1415926535897926719 9.3467860356166481656e-14 -3.1415926535895137839" />
    <parent link="right_hip_pitch_link" />
    <child link="right_calf_link" />
    <axis xyz="0 0 1" />
    <limit effort="1" velocity="20" lower="-1.570796326794896558" upper="0" />
    <joint_properties friction="0.0" />
  </joint>

  <joint name="right_hip_pitch" type="revolute">
    <origin xyz="0.024000000358075784801 -0.019000000000012132184 -0.01899999984755619542" rpy="-1.5707963267951119413 -1.5707963267945823649 0" />
    <parent link="hip_roll_link_2" />
    <child link="right_hip_pitch_link" />
    <axis xyz="0 0 1" />
    <limit effort="1" velocity="20" lower="-1.570796326794896558" upper="1.570796326794896558" />
    <joint_properties friction="0.0" />
  </joint>

  <joint name="right_hip_roll" type="revolute">
    <origin xyz="0.018999999999999881567 -3.350043888987566044e-18 -0.026000000000000002276" rpy="2.9582283942363596652e-30 1.5707963267948799047 0" />
    <parent link="hip_yaw_link_2" />
    <child link="hip_roll_link_2" />
    <axis xyz="0 0 1" />
    <limit effort="1" velocity="20" lower="-1.570796326794896558" upper="0.785398163397448279" />
    <joint_properties friction="0.0" />
  </joint>


</robot>