<robot name="toddlerbot_legs">
  <mujoco>
    <compiler strippath="false" balanceinertia="true" discardvisual="false" />
  </mujoco>
  <link name="body_link">
    <visual>
      <origin xyz="0 0 0" rpy="0 -0 0" />
      <geometry>
        <mesh filename="../assemblies/no_body/meshes/body_link_visual.stl" />
      </geometry>
      <material name="body_link_material">
        <color rgba="0.61397237829351869465 0.80332498114502748354 0.91540927344620071082 1.0" />
      </material>
    </visual>
    <collision>
      <origin xyz="0 0 0" rpy="0 -0 0" />
      <geometry>
        <mesh filename="collisions/body_link_collision.stl" />
      </geometry>
    </collision>
    <inertial>
      <origin xyz="-0.01499364327886279491 -0.00061666227763491530088 0.37865534467571948518" rpy="0 0 0" />
      <mass value="1.0086534506317459403" />
      <inertia ixx="0.0046858218276694544105" ixy="9.5066545070522087891e-06" ixz="-0.00033041186495409415264" iyy="0.0039734105446477419737" iyz="-2.4960818033478732468e-05" izz="0.0024171325638287608113" />
    </inertial>
  </link>

  <joint name="left_hip_yaw" type="revolute">
    <origin xyz="-0.0093999999999961926511 0.033999999999999301614 0.28500000000000003109" rpy="9.5014891068790173158e-14 -1.7824800733959379972e-14 -7.7962407392327512346e-15" />
    <parent link="body_link" />
    <child link="hip_yaw_link" />
    <axis xyz="0 0 1" />
    <limit effort="10" velocity="20" lower="-0.785398163397448279" upper="0.785398163397448279" />
    <dynamics damping="0.088" friction="0.0001" />
  </joint>

  <joint name="right_hip_yaw" type="revolute">
    <origin xyz="-0.009399999999996381736 -0.034000000000000807354 0.28499999999999969802" rpy="9.1462148145194911492e-14 -1.7824800733940560906e-14 -2.1356041234847096424e-13" />
    <parent link="body_link" />
    <child link="hip_yaw_link_2" />
    <axis xyz="0 0 1" />
    <limit effort="10" velocity="20" lower="-0.785398163397448279" upper="0.785398163397448279" />
    <dynamics damping="0.088" friction="0.0001" />
  </joint>


  <link name="hip_yaw_link">
    <visual>
      <origin xyz="0 0 0" rpy="0 -0 0" />
      <geometry>
        <mesh filename="../assemblies/left_3R+RH5_leg/meshes/left_hip_yaw_link_visual.stl" />
      </geometry>
      <material name="hip_yaw_link_material">
        <color rgba="0.61568627450980395466 0.81176470588235294379 0.9294117647058824927 1.0" />
      </material>
    </visual>
    <inertial>
      <origin xyz="1.10948197233704379e-18 -1.4747449291869228925e-20 -0.0098390489054830162358" rpy="0 0 0" />
      <mass value="0.0090258837370979227988" />
      <inertia ixx="1.3230458239086465149e-06" ixy="-3.3592249637948231893e-24" ixz="-1.1251788840973426872e-52" iyy="3.8408510960331422723e-06" iyz="2.3044956050358332095e-34" izz="3.8721396285793907821e-06" />
    </inertial>
  </link>

  <link name="hip_roll_link">
    <visual>
      <origin xyz="0 0 0" rpy="0 -0 0" />
      <geometry>
        <mesh filename="../assemblies/left_3R+RH5_leg/meshes/left_hip_roll_link_visual.stl" />
      </geometry>
      <material name="hip_roll_link_material">
        <color rgba="0.95018735644455876166 0.70678927200428409705 0.06161207940259672694 1.0" />
      </material>
    </visual>
    <collision>
      <origin xyz="0 0 0" rpy="0 -0 0" />
      <geometry>
        <mesh filename="collisions/left_hip_roll_link_collision.stl" />
      </geometry>
    </collision>
    <inertial>
      <origin xyz="-0.011999849582183506197 -0.0004959809079445483531 -0.018504111838591498496" rpy="0 0 0" />
      <mass value="0.098012391483528651936" />
      <inertia ixx="2.0221748766305362103e-05" ixy="-4.1225592188065617198e-08" ixz="-4.1552068246469907337e-08" iyy="2.735806952472204714e-05" iyz="-5.0935731752410196502e-07" izz="2.735809995830597023e-05" />
    </inertial>
  </link>

  <link name="left_hip_pitch_link">
    <visual>
      <origin xyz="0 0 0" rpy="0 -0 0" />
      <geometry>
        <mesh filename="../assemblies/left_3R+RH5_leg/meshes/left_hip_pitch_link_visual.stl" />
      </geometry>
      <material name="left_hip_pitch_link_material">
        <color rgba="0.6165406003152082981 0.80727949540398069583 0.92172283245724406786 1.0" />
      </material>
    </visual>
    <collision>
      <origin xyz="0 0 0" rpy="0 -0 0" />
      <geometry>
        <mesh filename="collisions/left_hip_pitch_link_collision.stl" />
      </geometry>
    </collision>
    <inertial>
      <origin xyz="-0.00021920258110594894327 0.05286719657360781921 0.014675228964508648527" rpy="0 0 0" />
      <mass value="0.093611654200831312389" />
      <inertia ixx="6.2575071270170513796e-05" ixy="4.2811371494834821184e-07" ixz="-1.5082939311367743614e-07" iyy="2.1582115763274171131e-05" iyz="-1.4343483800239936136e-06" izz="6.2291646982280619903e-05" />
    </inertial>
  </link>

  <link name="left_calf_link">
    <visual>
      <origin xyz="0 0 0" rpy="0 -0 0" />
      <geometry>
        <mesh filename="../assemblies/left_3R+RH5_leg/meshes/left_calf_link_visual.stl" />
      </geometry>
      <material name="left_calf_link_material">
        <color rgba="0.5518539491644144368 0.72972232177803997288 0.87665656864243635127 1.0" />
      </material>
    </visual>
    <collision>
      <origin xyz="0 0 0" rpy="0 -0 0" />
      <geometry>
        <mesh filename="collisions/left_calf_link_collision.stl" />
      </geometry>
    </collision>
    <inertial>
      <origin xyz="-0.0038993024960581375987 -0.042419338531024676497 0.0081864888082305280886" rpy="0 0 0" />
      <mass value="0.015782434194230747504" />
      <inertia ixx="1.4745030589956152988e-05" ixy="-2.0221927128075060177e-07" ixz="8.9866943649239635101e-09" iyy="1.8970750490643131249e-06" iyz="1.7803237244175249917e-08" izz="1.4045051134993881761e-05" />
    </inertial>
  </link>

  <link name="ank_pitch_link">
    <visual>
      <origin xyz="0 0 0" rpy="0 -0 0" />
      <geometry>
        <mesh filename="../assemblies/left_3R+RH5_leg/meshes/left_ank_pitch_link_visual.stl" />
      </geometry>
      <material name="ank_pitch_link_material">
        <color rgba="0.63189161126160275916 0.72668668793540891482 0.78356373393969258601 1.0" />
      </material>
    </visual>
    <inertial>
      <origin xyz="4.026968510017828702e-08 0.00059528282566723481582 -0.014599922383890413802" rpy="0 0 0" />
      <mass value="0.0042238381753791605713" />
      <inertia ixx="4.370525406739006983e-07" ixy="1.6834347249770690916e-13" ixz="1.642882239843461889e-12" iyy="3.9782741364650800388e-07" iyz="2.091924400200778153e-14" izz="8.8858574534559480418e-08" />
    </inertial>
  </link>

  <link name="ank_roll_link">
    <visual>
      <origin xyz="0 0 0" rpy="0 -0 0" />
      <geometry>
        <mesh filename="../assemblies/left_3R+RH5_leg/meshes/left_ank_roll_link_visual.stl" />
      </geometry>
      <material name="ank_roll_link_material">
        <color rgba="0.61568627450980395466 0.81176470588235294379 0.92941176470588238168 1.0" />
      </material>
    </visual>
    <collision>
      <origin xyz="0 0 0" rpy="0 -0 0" />
      <geometry>
        <mesh filename="../assemblies/left_3R+RH5_leg/meshes/left_ank_roll_link_collision.stl" />
      </geometry>
    </collision>
    <inertial>
      <origin xyz="-3.2802577105233733705e-07 0.028922633965180369331 0.0017500478240274539282" rpy="0 0 0" />
      <mass value="0.013974994209528749517" />
      <inertia ixx="1.0212114188424671225e-05" ixy="2.6491564884490763232e-11" ixz="-3.3865984334665517738e-11" iyy="9.7374672793563848158e-06" iyz="-1.1464163905345513743e-06" izz="2.7373100775715029295e-06" />
    </inertial>
  </link>

  <link name="ank_rr_link">
    <visual>
      <origin xyz="0 0 0" rpy="0 -0 0" />
      <geometry>
        <mesh filename="../assemblies/left_3R+RH5_leg/meshes/left_ank_rr_link_visual.stl" />
      </geometry>
      <material name="ank_rr_link_material">
        <color rgba="0.61568627450980395466 0.81176470588235283277 0.92941176470588238168 1.0" />
      </material>
    </visual>
    <inertial>
      <origin xyz="3.4099664995694346149e-18 -0.0061447686137497906783 1.9876344963298898127e-19" rpy="0 0 0" />
      <mass value="0.00042507093693768156772" />
      <inertia ixx="8.7843229279236022739e-09" ixy="9.2395644930576724516e-27" ixz="-1.0879024114909492282e-14" iyy="8.0301730481463886798e-09" iyz="1.2159468208298068424e-33" izz="1.2504379836120061674e-08" />
    </inertial>
  </link>

  <link name="12lf_rod_end">
    <visual>
      <origin xyz="0 0 0" rpy="0 -0 0" />
      <geometry>
        <mesh filename="../assemblies/left_3R+RH5_leg/meshes/left_12lf_rod_end_visual.stl" />
      </geometry>
      <material name="12lf_rod_end_material">
        <color rgba="0.92771758928836534075 0.61049283053223002415 0.2184765849058516729 1.0" />
      </material>
    </visual>
    <inertial>
      <origin xyz="-4.4735197461788878331e-11 -0.0038422185938245751249 6.4384187209446181173e-06" rpy="0 0 0" />
      <mass value="0.00085420491177815905965" />
      <inertia ixx="1.1840985264406837025e-08" ixy="2.0225977863212776003e-16" ixz="-9.2606419976881419213e-16" iyy="3.3549621576797694134e-09" iyz="7.4535631381847453943e-12" izz="1.2703522254420009704e-08" />
    </inertial>
  </link>

  <joint name="left_ank_R21" type="fixed">
    <origin xyz="6.9388939039072283776e-18 -0.0099999999999999533706 0" rpy="1.5707963267999907053 -1.5664147454868477816 -1.5707963267999944801" />
    <parent link="ank_rr_link" />
    <child link="12lf_rod_end" />
    <axis xyz="0 0 1" />
    <limit effort="10" velocity="20" lower="-1.570796326794896558" upper="1.570796326794896558" />
  </joint>

  <joint name="left_ank_R11" type="fixed">
    <origin xyz="-0.018000000000000009048 0.015999999999999986455 -0.020599999999999996786" rpy="7.372266899210394361e-15 1.2457991987000034509e-14 -0.018779262484739548539" />
    <parent link="ank_roll_link" />
    <child link="ank_rr_link" />
    <axis xyz="0 0 1" />
    <limit effort="10" velocity="20" lower="-1.570796326794896558" upper="1.570796326794896558" />
  </joint>

  <link name="ank_rr_link_2">
    <visual>
      <origin xyz="0 0 0" rpy="0 -0 0" />
      <geometry>
        <mesh filename="../assemblies/left_3R+RH5_leg/meshes/left_ank_rr_link_2_visual.stl" />
      </geometry>
      <material name="ank_rr_link_2_material">
        <color rgba="0.61568627450980395466 0.81176470588235283277 0.92941176470588238168 1.0" />
      </material>
    </visual>
    <inertial>
      <origin xyz="-5.2731046575155459729e-20 -0.0061447686137497915457 1.9876344963294454044e-19" rpy="0 0 0" />
      <mass value="0.00042507093693768156772" />
      <inertia ixx="8.7843229279236022739e-09" ixy="-1.9930731724410727403e-26" ixz="-1.0879024114909492282e-14" iyy="8.0301730481463919886e-09" iyz="2.6418116530504380233e-32" izz="1.2504379836120061674e-08" />
    </inertial>
  </link>

  <link name="12lf_rod_end_2">
    <visual>
      <origin xyz="0 0 0" rpy="0 -0 0" />
      <geometry>
        <mesh filename="../assemblies/left_3R+RH5_leg/meshes/left_12lf_rod_end_2_visual.stl" />
      </geometry>
      <material name="12lf_rod_end_2_material">
        <color rgba="0.92771758928836534075 0.61049283053223002415 0.2184765849058516729 1.0" />
      </material>
    </visual>
    <inertial>
      <origin xyz="-4.4735200137138648835e-11 -0.0038422185938246011458 6.4384187209440810984e-06" rpy="0 0 0" />
      <mass value="0.00085420491177815905965" />
      <inertia ixx="1.1840985264406790703e-08" ixy="2.022597794602806683e-16" ixz="-9.2606419945989251455e-16" iyy="3.3549621576797272272e-09" iyz="7.4535631381828438483e-12" izz="1.2703522254419978271e-08" />
    </inertial>
  </link>

  <joint name="left_ank_R22" type="fixed">
    <origin xyz="-3.4694469519536141888e-18 -0.0099999999999999533706 6.9388939039072283776e-18" rpy="-1.570796326795200093 -1.5664376509758415335 1.5707963267972691046" />
    <parent link="ank_rr_link_2" />
    <child link="12lf_rod_end_2" />
    <axis xyz="0 0 1" />
    <limit effort="10" velocity="20" lower="-1.570796326794896558" upper="1.570796326794896558" />
  </joint>

  <joint name="left_ank_R12" type="fixed">
    <origin xyz="0.017999999999999991701 0.015999999999999986455 -0.020600000000000003725" rpy="3.1415926535897837901 5.7200784449866098119e-15 -3.1229304365178514047" />
    <parent link="ank_roll_link" />
    <child link="ank_rr_link_2" />
    <axis xyz="0 0 1" />
    <limit effort="10" velocity="20" lower="-1.570796326794896558" upper="1.570796326794896558" />
  </joint>

  <joint name="left_ank_roll" type="revolute">
    <origin xyz="3.0808688933348093997e-15 0.00150000000000412065 -0.014599999999997594069" rpy="-1.5707963267949904829 -1.5707963267947890884 0" />
    <parent link="ank_pitch_link" />
    <child link="ank_roll_link" />
    <axis xyz="0 0 1" />
    <limit effort="10" velocity="20" lower="-0.785398163397448279" upper="0.785398163397448279" />
    <dynamics damping="0.2" friction="0.0537" />
  </joint>

  <joint name="left_ank_pitch" type="revolute">
    <origin xyz="9.1041832417877273971e-19 -0.099999999999999977796 -0.0062000000000000006495" rpy="3.1415926535897913396 3.2973623831365823964e-14 -1.5707963267949118791" />
    <parent link="left_calf_link" />
    <child link="ank_pitch_link" />
    <axis xyz="0 0 1" />
    <limit effort="10" velocity="20" lower="-0.785398163397448279" upper="0.95993108859688125456" />
    <dynamics damping="0.327" friction="0.0553" />
  </joint>

  <link name="ball_joint_container">
    <visual>
      <origin xyz="0 0 0" rpy="0 -0 0" />
      <geometry>
        <mesh filename="../assemblies/left_3R+RH5_leg/meshes/left_ball_joint_container_visual.stl" />
      </geometry>
      <material name="ball_joint_container_material">
        <color rgba="0.61568627450980395466 0.81176470588235294379 0.9294117647058824927 1.0" />
      </material>
    </visual>
    <inertial>
      <origin xyz="4.722144297570993535e-19 -1.3170636881708645367e-19 -0.0097125341669083396778" rpy="0 0 0" />
      <mass value="4.8037356425330562243e-05" />
      <inertia ixx="7.1865480628741666366e-10" ixy="1.5073670243190848269e-27" ixz="-1.2986299746004074171e-40" iyy="8.475420427718555978e-10" iyz="8.2465578470855891955e-39" izz="1.8625314111651911712e-10" />
    </inertial>
  </link>

  <link name="ball_joint_ball">
    <visual>
      <origin xyz="0 0 0" rpy="0 -0 0" />
      <geometry>
        <mesh filename="../assemblies/left_3R+RH5_leg/meshes/left_ball_joint_ball_visual.stl" />
      </geometry>
      <material name="ball_joint_ball_material">
        <color rgba="0.3291302810242056065 0.44310466418644928188 0.69204871161977121741 1.0" />
      </material>
    </visual>
    <inertial>
      <origin xyz="-1.6430372793130515128e-19 -0.0010308669810015407085 -4.0999987757038908845e-18" rpy="0 0 0" />
      <mass value="4.4053796295264630609e-05" />
      <inertia ixx="3.1285011349691274394e-10" ixy="-2.0899298178486533495e-27" ixz="-8.5615105329201482222e-27" iyy="6.2569568612793382078e-11" iyz="8.404326343174790715e-25" izz="3.1285321460374022494e-10" />
    </inertial>
  </link>

  <link name="12lf">
    <visual>
      <origin xyz="0 0 0" rpy="0 -0 0" />
      <geometry>
        <mesh filename="../assemblies/left_3R+RH5_leg/meshes/left_12lf_visual.stl" />
      </geometry>
      <material name="12lf_material">
        <color rgba="0.62004392100736027693 0.58836684613512635345 0.49897069021535683797 1.0" />
      </material>
    </visual>
    <inertial>
      <origin xyz="0.0049084207243738318949 -0.00013802439943632547866 -0.029947003577167913974" rpy="0 0 0" />
      <mass value="0.044782197696050358993" />
      <inertia ixx="1.5260128421328397519e-05" ixy="2.2955773687010726143e-08" ixz="-8.1364204004619861992e-08" iyy="1.818846977897047769e-05" iyz="-5.5542240843365280421e-08" izz="5.1496273901771792196e-06" />
    </inertial>
  </link>

  <link name="12lf_rod">
    <visual>
      <origin xyz="0 0 0" rpy="0 -0 0" />
      <geometry>
        <mesh filename="../assemblies/left_3R+RH5_leg/meshes/left_12lf_rod_visual.stl" />
      </geometry>
      <material name="12lf_rod_material">
        <color rgba="0.80250260812861884396 0.89340612183512713163 0.94491811293548189088 1.0" />
      </material>
    </visual>
    <inertial>
      <origin xyz="-6.3222084039857236818e-07 4.6933255243327257339e-07 -0.012893387334326454619" rpy="0 0 0" />
      <mass value="0.0025088292483592144512" />
      <inertia ixx="2.6944521128634527092e-07" ixy="7.1389570232101606794e-15" ixz="1.3562243134670508323e-11" iyy="2.6944520001691072088e-07" iyz="-1.0089988404311650457e-11" izz="1.7809843599861018872e-08" />
    </inertial>
  </link>

  <joint name="left_ank_act1" type="fixed">
    <origin xyz="2.272209352376791669e-06 3.4694469519536141888e-16 -0.074779998095385435963" rpy="-3.1415926535896594451 8.836582611277305623e-14 -2.2021168238262687211" />
    <parent link="12lf" />
    <child link="12lf_rod" />
    <axis xyz="0 0 1" />
    <limit effort="10" velocity="20" lower="0" upper="0.040000000000000000833" />
  </joint>

  <joint name="left_ank_B31" type="fixed">
    <origin xyz="3.4694469519536141888e-18 -0.0064387505004001588382 -2.0816681711721685133e-17" rpy="-1.5707963267948947816 0.16913440034089716191 -5.6137304953543511113e-16" />
    <parent link="ball_joint_ball" />
    <child link="12lf" />
    <axis xyz="0 0 1" />
    <limit effort="10" velocity="20" lower="-0.785398163397448279" upper="0.785398163397448279" />
  </joint>

  <joint name="left_ank_B21" type="fixed">
    <origin xyz="-2.3592239273284576484e-16 0 -0.011499999999999998071" rpy="-1.5707963267921956074 -1.5664147454872743292 -1.5707963267976534638" />
    <parent link="ball_joint_container" />
    <child link="ball_joint_ball" />
    <axis xyz="0 0 1" />
    <limit effort="10" velocity="20" lower="-0.785398163397448279" upper="0.785398163397448279" />
  </joint>

  <joint name="left_ank_B11" type="fixed">
    <origin xyz="0.0080000000000000140443 -0.015000000000000041078 0.028299999999999991829" rpy="-1.570796326794896558 1.5520170643096702356 1.5707963267949236474" />
    <parent link="left_calf_link" />
    <child link="ball_joint_container" />
    <axis xyz="0 0 1" />
    <limit effort="10" velocity="20" lower="-0.785398163397448279" upper="0.785398163397448279" />
  </joint>

  <link name="ball_joint_container_2">
    <visual>
      <origin xyz="0 0 0" rpy="0 -0 0" />
      <geometry>
        <mesh filename="../assemblies/left_3R+RH5_leg/meshes/left_ball_joint_container_2_visual.stl" />
      </geometry>
      <material name="ball_joint_container_2_material">
        <color rgba="0.61568627450980395466 0.81176470588235294379 0.9294117647058824927 1.0" />
      </material>
    </visual>
    <inertial>
      <origin xyz="4.7221442975709848683e-19 -5.5642857600074875847e-17 -0.0097125341669083431473" rpy="0 0 0" />
      <mass value="4.8037356425330562243e-05" />
      <inertia ixx="7.1865480628741666366e-10" ixy="4.5696914826368578443e-27" ixz="-1.4147572309371857382e-40" iyy="8.475420427718555978e-10" iyz="-1.9747038838995359871e-38" izz="1.8625314111651911712e-10" />
    </inertial>
  </link>

  <link name="ball_joint_ball_2">
    <visual>
      <origin xyz="0 0 0" rpy="0 -0 0" />
      <geometry>
        <mesh filename="../assemblies/left_3R+RH5_leg/meshes/left_ball_joint_ball_2_visual.stl" />
      </geometry>
      <material name="ball_joint_ball_2_material">
        <color rgba="0.3291302810242056065 0.44310466418644928188 0.69204871161977121741 1.0" />
      </material>
    </visual>
    <inertial>
      <origin xyz="-2.3236895893562296795e-19 -0.0010308669810016014238 6.4827775509755075537e-20" rpy="0 0 0" />
      <mass value="4.4053796295264630609e-05" />
      <inertia ixx="3.1285011349692463466e-10" ixy="1.3539051973757832705e-26" ixz="5.3959041490459282864e-30" iyy="6.2569568612795566352e-11" iyz="-1.5871332946531641882e-27" izz="3.128532146037635928e-10" />
    </inertial>
  </link>

  <link name="12lf_2">
    <visual>
      <origin xyz="0 0 0" rpy="0 -0 0" />
      <geometry>
        <mesh filename="../assemblies/left_3R+RH5_leg/meshes/left_12lf_2_visual.stl" />
      </geometry>
      <material name="12lf_2_material">
        <color rgba="0.62004392100736027693 0.58836684613512635345 0.49897069021535683797 1.0" />
      </material>
    </visual>
    <inertial>
      <origin xyz="0.0049084207243672572929 -0.00013802439943878569602 -0.029947003577168580107" rpy="0 0 0" />
      <mass value="0.044782197696050358993" />
      <inertia ixx="1.5260128421329105638e-05" ixy="2.2955773686919269746e-08" ixz="-8.1364204007394755162e-08" iyy="1.8188469778973503292e-05" iyz="-5.554224084467693741e-08" izz="5.149627390179528889e-06" />
    </inertial>
  </link>

  <link name="12lf_rod_2">
    <visual>
      <origin xyz="0 0 0" rpy="0 -0 0" />
      <geometry>
        <mesh filename="../assemblies/left_3R+RH5_leg/meshes/left_12lf_rod_2_visual.stl" />
      </geometry>
      <material name="12lf_rod_2_material">
        <color rgba="0.80250260812861884396 0.89340612183512713163 0.94491811293548189088 1.0" />
      </material>
    </visual>
    <inertial>
      <origin xyz="-6.3222083717250307532e-07 4.6933255289754562546e-07 -0.012893387334327655047" rpy="0 0 0" />
      <mass value="0.0025088292483592144512" />
      <inertia ixx="2.6944521128627830237e-07" ixy="7.1389569972798120533e-15" ixz="1.3562243038875907425e-11" iyy="2.6944520001684385821e-07" iyz="-1.0089988416517761836e-11" izz="1.7809843599861012255e-08" />
    </inertial>
  </link>

  <joint name="left_ank_act2" type="fixed">
    <origin xyz="2.2722093472628268618e-06 -8.4585116688629113924e-15 -0.074779996992748620777" rpy="-3.1415926535895000171 6.2101951664430066723e-14 -2.2021168238262793793" />
    <parent link="12lf_2" />
    <child link="12lf_rod_2" />
    <axis xyz="0 0 1" />
    <limit effort="10" velocity="20" lower="0" upper="0.040000000000000000833" />
  </joint>

  <joint name="left_ank_B32" type="fixed">
    <origin xyz="-3.4694469519536141888e-18 -0.0064387505004003808828 0" rpy="-1.570796326794896558 -0.17993145005761934652 -1.52442862826419765e-18" />
    <parent link="ball_joint_ball_2" />
    <child link="12lf_2" />
    <axis xyz="0 0 1" />
    <limit effort="10" velocity="20" lower="-0.785398163397448279" upper="0.785398163397448279" />
  </joint>

  <joint name="left_ank_B22" type="fixed">
    <origin xyz="3.4694469519536141888e-18 -1.1102230246251565404e-16 -0.01150000000000000154" rpy="-1.570796326794896558 -1.5664376509753994426 1.5707963267946438712" />
    <parent link="ball_joint_container_2" />
    <child link="ball_joint_ball_2" />
    <axis xyz="0 0 1" />
    <limit effort="10" velocity="20" lower="-0.785398163397448279" upper="0.785398163397448279" />
  </joint>

  <joint name="left_ank_B12" type="fixed">
    <origin xyz="0.0080000000000000019013 -0.014999999999999985567 -0.011499999999999999806" rpy="-1.570796326794896558 -1.5521341097218652738 1.5707963267948228392" />
    <parent link="left_calf_link" />
    <child link="ball_joint_container_2" />
    <axis xyz="0 0 1" />
    <limit effort="10" velocity="20" lower="-0.785398163397448279" upper="0.785398163397448279" />
  </joint>

  <joint name="left_knee" type="revolute">
    <origin xyz="-9.0379327827951061674e-15 0.095999999999999793832 0.027400000000001221989" rpy="3.1415926535896594451 -8.0881482058163985808e-17 -1.573475576799148449e-15" />
    <parent link="left_hip_pitch_link" />
    <child link="left_calf_link" />
    <axis xyz="0 0 1" />
    <limit effort="10" velocity="20" lower="0" upper="1.570796326794896558" />
    <dynamics damping="0.819" friction="0.0085" />
  </joint>

  <joint name="left_hip_pitch" type="revolute">
    <origin xyz="-0.024000000716140019313 -0.019000000152447748397 -0.019000000152447786561" rpy="-1.570796326794896336 1.5707963267947404606 0" />
    <parent link="hip_roll_link" />
    <child link="left_hip_pitch_link" />
    <axis xyz="0 0 1" />
    <limit effort="10" velocity="20" lower="-1.570796326794896558" upper="1.570796326794896558" />
    <dynamics damping="0.76" friction="0.018" />
  </joint>

  <joint name="left_hip_roll" type="revolute">
    <origin xyz="0.019000000000000304839 -3.3624037938337684222e-18 -0.026000000000000279832" rpy="3.141592653589793116 -1.5707963267948858999 0" />
    <parent link="hip_yaw_link" />
    <child link="hip_roll_link" />
    <axis xyz="0 0 1" />
    <limit effort="10" velocity="20" lower="-0.785398163397448279" upper="1.570796326794896558" />
    <dynamics damping="0.399" friction="0.0909" />
  </joint>


  <link name="hip_yaw_link_2">
    <visual>
      <origin xyz="0 0 0" rpy="0 -0 0" />
      <geometry>
        <mesh filename="../assemblies/right_3R+RH5_leg/meshes/right_hip_yaw_link_visual.stl" />
      </geometry>
      <material name="hip_yaw_link_material">
        <color rgba="0.61568627450980395466 0.81176470588235294379 0.9294117647058824927 1.0" />
      </material>
    </visual>
    <inertial>
      <origin xyz="1.1094819723304576874e-18 -1.4747449291575112339e-20 -0.0098390489054829121524" rpy="0 0 0" />
      <mass value="0.0090258837370979227988" />
      <inertia ixx="1.3230458239085876461e-06" ixy="-9.6363174149195438067e-49" ixz="2.5822652061387307278e-33" iyy="3.8408510960330541809e-06" iyz="-1.4423493090974203298e-32" izz="3.8721396285793077728e-06" />
    </inertial>
  </link>

  <link name="hip_roll_link_2">
    <visual>
      <origin xyz="0 0 0" rpy="0 -0 0" />
      <geometry>
        <mesh filename="../assemblies/right_3R+RH5_leg/meshes/right_hip_roll_link_visual.stl" />
      </geometry>
      <material name="hip_roll_link_material">
        <color rgba="0.95018735644455876166 0.70678927200428409705 0.06161207940259672694 1.0" />
      </material>
    </visual>
    <collision>
      <origin xyz="0 0 0" rpy="0 -0 0" />
      <geometry>
        <mesh filename="collisions/right_hip_roll_link_collision.stl" />
      </geometry>
    </collision>
    <inertial>
      <origin xyz="-0.011999849582182727306 -0.00049598090794501390952 -0.018504111838591762174" rpy="0 0 0" />
      <mass value="0.098012391483528651936" />
      <inertia ixx="2.02217487663054773e-05" ixy="-4.1225592187651471026e-08" ixz="-4.1552068246492221361e-08" iyy="2.735806952472197599e-05" iyz="-5.0935731752407962452e-07" izz="2.7358099958306159966e-05" />
    </inertial>
  </link>

  <link name="right_hip_pitch_link">
    <visual>
      <origin xyz="0 0 0" rpy="0 -0 0" />
      <geometry>
        <mesh filename="../assemblies/right_3R+RH5_leg/meshes/right_hip_pitch_link_visual.stl" />
      </geometry>
      <material name="right_hip_pitch_link_material">
        <color rgba="0.61654060031870661085 0.8072794953856136102 0.92172283242575780982 1.0" />
      </material>
    </visual>
    <collision>
      <origin xyz="0 0 0" rpy="0 -0 0" />
      <geometry>
        <mesh filename="collisions/right_hip_pitch_link_collision.stl" />
      </geometry>
    </collision>
    <inertial>
      <origin xyz="-1.3033690427602677005e-05 -0.052867196495286906954 0.023324771095030935597" rpy="0 0 0" />
      <mass value="0.09361165381749210479" />
      <inertia ixx="6.2575072115421317281e-05" ixy="2.2341794227176792435e-07" ixz="1.1676158767092474657e-08" iyy="2.1586598259275086508e-05" iyz="-1.4343483925993869498e-06" izz="6.2296129928644748664e-05" />
    </inertial>
  </link>

  <link name="right_calf_link">
    <visual>
      <origin xyz="0 0 0" rpy="0 -0 0" />
      <geometry>
        <mesh filename="../assemblies/right_3R+RH5_leg/meshes/right_calf_link_visual.stl" />
      </geometry>
      <material name="right_calf_link_material">
        <color rgba="0.55183757703855651489 0.72973662124660387818 0.87669617832525115197 1.0" />
      </material>
    </visual>
    <collision>
      <origin xyz="0 0 0" rpy="0 -0 0" />
      <geometry>
        <mesh filename="collisions/right_calf_link_collision.stl" />
      </geometry>
    </collision>
    <inertial>
      <origin xyz="-0.0038999626430269085028 0.042409395322589235611 0.0081838728113180578966" rpy="0 0 0" />
      <mass value="0.015779725212993939848" />
      <inertia ixx="1.4735397719668421088e-05" ixy="2.0283446246059693902e-07" ixz="9.1508417303722038378e-09" iyy="1.8964180016897424611e-06" iyz="-1.5463243486048329172e-08" izz="1.4035958490016414588e-05" />
    </inertial>
  </link>

  <link name="ank_pitch_link_2">
    <visual>
      <origin xyz="0 0 0" rpy="0 -0 0" />
      <geometry>
        <mesh filename="../assemblies/right_3R+RH5_leg/meshes/right_ank_pitch_link_visual.stl" />
      </geometry>
      <material name="ank_pitch_link_material">
        <color rgba="0.63189161126160275916 0.72668668793540891482 0.78356373393969258601 1.0" />
      </material>
    </visual>
    <inertial>
      <origin xyz="4.0269686744046064311e-08 0.0005952828256677747485 -0.014599922383890096347" rpy="0 0 0" />
      <mass value="0.0042238381753791605713" />
      <inertia ixx="4.3705254067390763339e-07" ixy="1.6834347123503678247e-13" ixz="1.6428822925662319172e-12" iyy="3.9782741364654897909e-07" iyz="2.091920170560600146e-14" izz="8.8858574534525519691e-08" />
    </inertial>
  </link>

  <link name="ank_roll_link_2">
    <visual>
      <origin xyz="0 0 0" rpy="0 -0 0" />
      <geometry>
        <mesh filename="../assemblies/right_3R+RH5_leg/meshes/right_ank_roll_link_visual.stl" />
      </geometry>
      <material name="ank_roll_link_material">
        <color rgba="0.61568627450980395466 0.81176470588235305481 0.92941176470588238168 1.0" />
      </material>
    </visual>
    <collision>
      <origin xyz="0 0 0" rpy="0 -0 0" />
      <geometry>
        <mesh filename="../assemblies/right_3R+RH5_leg/meshes/right_ank_roll_link_collision.stl" />
      </geometry>
    </collision>
    <inertial>
      <origin xyz="-1.7281349848514604191e-07 0.028922633802874186948 0.0017501343014607161769" rpy="0 0 0" />
      <mass value="0.013974995537312767668" />
      <inertia ixx="1.0212111185421585496e-05" ixy="2.0476240133048706539e-11" ixz="-5.6455705812461185897e-11" iyy="9.7374705570554639e-06" iyz="-1.1464250625723700305e-06" izz="2.7373162145496292839e-06" />
    </inertial>
  </link>

  <link name="ank_rr_link_3">
    <visual>
      <origin xyz="0 0 0" rpy="0 -0 0" />
      <geometry>
        <mesh filename="../assemblies/right_3R+RH5_leg/meshes/right_ank_rr_link_visual.stl" />
      </geometry>
      <material name="ank_rr_link_material">
        <color rgba="0.61568627450980395466 0.81176470588235283277 0.92941176470588238168 1.0" />
      </material>
    </visual>
    <inertial>
      <origin xyz="-6.772719868553408757e-20 -0.0061447686137497915457 3.6682104015863762715e-18" rpy="0 0 0" />
      <mass value="0.00042507093693768156772" />
      <inertia ixx="8.7843229279236022739e-09" ixy="-1.5864380896313781037e-26" ixz="-1.0879024114909492282e-14" iyy="8.0301730481463919886e-09" iyz="4.5653393820902673925e-32" izz="1.2504379836120061674e-08" />
    </inertial>
  </link>

  <link name="12lf_rod_end_3">
    <visual>
      <origin xyz="0 0 0" rpy="0 -0 0" />
      <geometry>
        <mesh filename="../assemblies/right_3R+RH5_leg/meshes/right_12lf_rod_end_visual.stl" />
      </geometry>
      <material name="12lf_rod_end_material">
        <color rgba="0.92771758928836534075 0.61049283053223002415 0.2184765849058516729 1.0" />
      </material>
    </visual>
    <inertial>
      <origin xyz="-4.4735196695610147617e-11 -0.0038422185938245959416 6.4384187209476411779e-06" rpy="0 0 0" />
      <mass value="0.00085420491177815905965" />
      <inertia ixx="1.1840985264406750998e-08" ixy="2.0225977936654380285e-16" ixz="-9.2606419961864584135e-16" iyy="3.3549621576796866954e-09" iyz="7.4535631381826499778e-12" izz="1.2703522254419963381e-08" />
    </inertial>
  </link>

  <joint name="right_ank_R21" type="fixed">
    <origin xyz="-3.4694469519536141888e-18 -0.010000000000000008882 1.0408340855860842566e-17" rpy="1.5707963267949234254 -1.5664147454868782017 -1.5707963267941609242" />
    <parent link="ank_rr_link_3" />
    <child link="12lf_rod_end_3" />
    <axis xyz="0 0 1" />
    <limit effort="10" velocity="20" lower="-1.570796326794896558" upper="1.570796326794896558" />
  </joint>

  <joint name="right_ank_R11" type="fixed">
    <origin xyz="-0.018000000000000009048 0.015999999999999986455 -0.020599999999999996786" rpy="2.1199056220120536536e-16 1.7337184392140691041e-15 -0.018779262484772244607" />
    <parent link="ank_roll_link_2" />
    <child link="ank_rr_link_3" />
    <axis xyz="0 0 1" />
    <limit effort="10" velocity="20" lower="-1.570796326794896558" upper="1.570796326794896558" />
  </joint>

  <link name="ank_rr_link_4">
    <visual>
      <origin xyz="0 0 0" rpy="0 -0 0" />
      <geometry>
        <mesh filename="../assemblies/right_3R+RH5_leg/meshes/right_ank_rr_link_2_visual.stl" />
      </geometry>
      <material name="ank_rr_link_2_material">
        <color rgba="0.61568627450980395466 0.81176470588235283277 0.92941176470588238168 1.0" />
      </material>
    </visual>
    <inertial>
      <origin xyz="-4.2895092296414386899e-20 -0.0061447686137497360345 -3.2706835023203394236e-18" rpy="0 0 0" />
      <mass value="0.00042507093693768156772" />
      <inertia ixx="8.7843229279236022739e-09" ixy="5.711362133931313441e-27" ixz="-1.0879024114909492282e-14" iyy="8.0301730481463919886e-09" iyz="-2.1258676875356141517e-32" izz="1.2504379836120061674e-08" />
    </inertial>
  </link>

  <link name="12lf_rod_end_4">
    <visual>
      <origin xyz="0 0 0" rpy="0 -0 0" />
      <geometry>
        <mesh filename="../assemblies/right_3R+RH5_leg/meshes/right_12lf_rod_end_2_visual.stl" />
      </geometry>
      <material name="12lf_rod_end_2_material">
        <color rgba="0.92771758928836534075 0.61049283053223002415 0.2184765849058516729 1.0" />
      </material>
    </visual>
    <inertial>
      <origin xyz="-4.473519593544271936e-11 -0.0038422185938245699208 6.4384187209475590157e-06" rpy="0 0 0" />
      <mass value="0.00085420491177815905965" />
      <inertia ixx="1.1840985264406777468e-08" ixy="2.0225978027478046506e-16" ixz="-9.260641977021974134e-16" iyy="3.3549621576797024118e-09" iyz="7.4535631381828147677e-12" izz="1.2703522254419948492e-08" />
    </inertial>
  </link>

  <joint name="right_ank_R22" type="fixed">
    <origin xyz="-3.4694469519536141888e-18 -0.0099999999999998978595 1.0408340855860842566e-17" rpy="-1.570796326794896336 -1.5664376509751398725 1.5707963267966709164" />
    <parent link="ank_rr_link_4" />
    <child link="12lf_rod_end_4" />
    <axis xyz="0 0 1" />
    <limit effort="10" velocity="20" lower="-1.570796326794896558" upper="1.570796326794896558" />
  </joint>

  <joint name="right_ank_R12" type="fixed">
    <origin xyz="0.017999999999999995171 0.015999999999999930944 -0.020600000000000003725" rpy="-3.1415926535897855665 2.3670754779580369231e-15 -3.1229304365172758651" />
    <parent link="ank_roll_link_2" />
    <child link="ank_rr_link_4" />
    <axis xyz="0 0 1" />
    <limit effort="10" velocity="20" lower="-1.570796326794896558" upper="1.570796326794896558" />
  </joint>

  <joint name="right_ank_roll" type="revolute">
    <origin xyz="3.3584246494910985348e-15 0.0015000000000102613543 -0.014599999999994976371" rpy="-1.5707963267951949859 1.5707963267946882802 0" />
    <parent link="ank_pitch_link_2" />
    <child link="ank_roll_link_2" />
    <axis xyz="0 0 1" />
    <limit effort="10" velocity="20" lower="-0.785398163397448279" upper="0.785398163397448279" />
    <dynamics damping="0.2" friction="0.0537" />
  </joint>

  <joint name="right_ank_pitch" type="revolute">
    <origin xyz="1.3701363056155178809e-18 0.10000000000000000555 -0.0061999999999999243216" rpy="-3.1415926535897917837 8.3351550965154899867e-16 -1.5707963267948104047" />
    <parent link="right_calf_link" />
    <child link="ank_pitch_link_2" />
    <axis xyz="0 0 1" />
    <limit effort="10" velocity="20" lower="-0.785398163397448279" upper="0.95993108859688125456" />
    <dynamics damping="0.327" friction="0.0553" />
  </joint>

  <link name="ball_joint_container_3">
    <visual>
      <origin xyz="0 0 0" rpy="0 -0 0" />
      <geometry>
        <mesh filename="../assemblies/right_3R+RH5_leg/meshes/right_ball_joint_container_visual.stl" />
      </geometry>
      <material name="ball_joint_container_material">
        <color rgba="0.61568627450980395466 0.81176470588235294379 0.9294117647058824927 1.0" />
      </material>
    </visual>
    <inertial>
      <origin xyz="-2.9972325221965159909e-18 -1.3170636881704331284e-19 -0.0097125341669083414126" rpy="0 0 0" />
      <mass value="4.8037356425330562243e-05" />
      <inertia ixx="7.1865480628741707725e-10" ixy="4.7686823988665461978e-27" ixz="5.1372825832619971272e-40" iyy="8.475420427718555978e-10" iyz="-3.2723433928573531218e-38" izz="1.8625314111651911712e-10" />
    </inertial>
  </link>

  <link name="ball_joint_ball_3">
    <visual>
      <origin xyz="0 0 0" rpy="0 -0 0" />
      <geometry>
        <mesh filename="../assemblies/right_3R+RH5_leg/meshes/right_ball_joint_ball_visual.stl" />
      </geometry>
      <material name="ball_joint_ball_material">
        <color rgba="0.3291302810242056065 0.44310466418644928188 0.69204871161977121741 1.0" />
      </material>
    </visual>
    <inertial>
      <origin xyz="5.9030136108666568905e-18 -0.0010308669810016022911 -7.1252153088828868716e-20" rpy="0 0 0" />
      <mass value="4.4053796295264630609e-05" />
      <inertia ixx="3.1285011349692649581e-10" ixy="5.077154768211529188e-26" ixz="4.6798489160140480731e-26" iyy="6.2569568612795592202e-11" iyz="-1.1895451457969914525e-26" izz="3.1285321460376173164e-10" />
    </inertial>
  </link>

  <link name="12lf_3">
    <visual>
      <origin xyz="0 0 0" rpy="0 -0 0" />
      <geometry>
        <mesh filename="../assemblies/right_3R+RH5_leg/meshes/right_12lf_visual.stl" />
      </geometry>
      <material name="12lf_material">
        <color rgba="0.62004392100736027693 0.58836684613512635345 0.49897069021535683797 1.0" />
      </material>
    </visual>
    <inertial>
      <origin xyz="0.0049084207243678019961 -0.00013802439943444823681 -0.029947003577154806403" rpy="0 0 0" />
      <mass value="0.044782197696050358993" />
      <inertia ixx="1.5260128421318422859e-05" ixy="2.2955773686503350099e-08" ixz="-8.1364204007312129745e-08" iyy="1.8188469778958859786e-05" iyz="-5.5542240842559937377e-08" izz="5.1496273901754478842e-06" />
    </inertial>
  </link>

  <link name="12lf_rod_3">
    <visual>
      <origin xyz="0 0 0" rpy="0 -0 0" />
      <geometry>
        <mesh filename="../assemblies/right_3R+RH5_leg/meshes/right_12lf_rod_visual.stl" />
      </geometry>
      <material name="12lf_rod_material">
        <color rgba="0.80250260812861884396 0.89340612183512713163 0.94491811293548189088 1.0" />
      </material>
    </visual>
    <inertial>
      <origin xyz="-6.3222084100391536949e-07 4.6933255118795287588e-07 -0.012893387334328484245" rpy="0 0 0" />
      <mass value="0.0025088292483592144512" />
      <inertia ixx="2.6944521128623250965e-07" ixy="7.1389570415193793204e-15" ixz="1.3562243150951720143e-11" iyy="2.6944520001679811843e-07" iyz="-1.0089988370044107076e-11" izz="1.7809843599861028799e-08" />
    </inertial>
  </link>

  <joint name="right_ank_act1" type="fixed">
    <origin xyz="2.2722093416596700344e-06 1.9567680809018384025e-15 -0.074779998095380800782" rpy="-3.1415926535897811256 5.9900329378763890994e-15 -2.2021168238260777628" />
    <parent link="12lf_3" />
    <child link="12lf_rod_3" />
    <axis xyz="0 0 1" />
    <limit effort="10" velocity="20" lower="0" upper="0.040000000000000000833" />
  </joint>

  <joint name="right_ank_B31" type="fixed">
    <origin xyz="-3.4694469519536141888e-18 -0.0064387505004003808828 0" rpy="-1.570796326794896558 0.16913440034157123382 1.0478833061949341326e-15" />
    <parent link="ball_joint_ball_3" />
    <child link="12lf_3" />
    <axis xyz="0 0 1" />
    <limit effort="10" velocity="20" lower="-0.785398163397448279" upper="0.785398163397448279" />
  </joint>

  <joint name="right_ank_B21" type="fixed">
    <origin xyz="-3.4694469519536141888e-18 0 -0.011499999999999996336" rpy="-1.5707963267952478326 -1.5664147454871724108 -1.5707963267955875608" />
    <parent link="ball_joint_container_3" />
    <child link="ball_joint_ball_3" />
    <axis xyz="0 0 1" />
    <limit effort="10" velocity="20" lower="-0.785398163397448279" upper="0.785398163397448279" />
  </joint>

  <joint name="right_ank_B11" type="fixed">
    <origin xyz="0.0080000000000000019013 0.014999999999999985567 -0.011500000000000003275" rpy="1.5707963267948470421 -1.5520170643097048746 -1.570796326794996034" />
    <parent link="right_calf_link" />
    <child link="ball_joint_container_3" />
    <axis xyz="0 0 1" />
    <limit effort="10" velocity="20" lower="-0.785398163397448279" upper="0.785398163397448279" />
  </joint>

  <link name="ball_joint_container_4">
    <visual>
      <origin xyz="0 0 0" rpy="0 -0 0" />
      <geometry>
        <mesh filename="../assemblies/right_3R+RH5_leg/meshes/right_ball_joint_container_2_visual.stl" />
      </geometry>
      <material name="ball_joint_container_2_material">
        <color rgba="0.61568627450980395466 0.81176470588235294379 0.9294117647058824927 1.0" />
      </material>
    </visual>
    <inertial>
      <origin xyz="4.7221442975710426462e-19 -1.3170636881703233504e-19 -0.0097125341669083431473" rpy="0 0 0" />
      <mass value="4.8037356425330562243e-05" />
      <inertia ixx="7.1865480628741645687e-10" ixy="2.3082551744305039966e-27" ixz="-1.9591983056907320695e-39" iyy="8.475420427718555978e-10" iyz="4.2854812084784726805e-38" izz="1.8625314111651911712e-10" />
    </inertial>
  </link>

  <link name="ball_joint_ball_4">
    <visual>
      <origin xyz="0 0 0" rpy="0 -0 0" />
      <geometry>
        <mesh filename="../assemblies/right_3R+RH5_leg/meshes/right_ball_joint_ball_2_visual.stl" />
      </geometry>
      <material name="ball_joint_ball_2_material">
        <color rgba="0.3291302810242056065 0.44310466418644928188 0.69204871161977121741 1.0" />
      </material>
    </visual>
    <inertial>
      <origin xyz="-6.395633123682807487e-18 -0.0010308669810016493455 -2.1718848700189737814e-18" rpy="0 0 0" />
      <mass value="4.4053796295264630609e-05" />
      <inertia ixx="3.1285011349692820187e-10" ixy="1.9037656967091037146e-25" ixz="1.1446951858299053379e-24" iyy="6.2569568612796238436e-11" iyz="-1.9178182979881764052e-25" izz="3.1285321460376478187e-10" />
    </inertial>
  </link>

  <link name="12lf_4">
    <visual>
      <origin xyz="0 0 0" rpy="0 -0 0" />
      <geometry>
        <mesh filename="../assemblies/right_3R+RH5_leg/meshes/right_12lf_2_visual.stl" />
      </geometry>
      <material name="12lf_2_material">
        <color rgba="0.62004392100736027693 0.58836684613512635345 0.49897069021535683797 1.0" />
      </material>
    </visual>
    <inertial>
      <origin xyz="0.0049084207243634686568 -0.00013802439943656473497 -0.029947003577153203518" rpy="0 0 0" />
      <mass value="0.044782197696050358993" />
      <inertia ixx="1.5260128421317484346e-05" ixy="2.2955773686700811346e-08" ixz="-8.1364204009454104015e-08" iyy="1.8188469778957667164e-05" iyz="-5.5542240843571850581e-08" izz="5.149627390175211562e-06" />
    </inertial>
  </link>

  <link name="12lf_rod_4">
    <visual>
      <origin xyz="0 0 0" rpy="0 -0 0" />
      <geometry>
        <mesh filename="../assemblies/right_3R+RH5_leg/meshes/right_12lf_rod_2_visual.stl" />
      </geometry>
      <material name="12lf_rod_2_material">
        <color rgba="0.80250260812861884396 0.89340612183512713163 0.94491811293548189088 1.0" />
      </material>
    </visual>
    <inertial>
      <origin xyz="-6.3222084108049095957e-07 4.6933255050749711039e-07 -0.012893387334330222438" rpy="0 0 0" />
      <mass value="0.0025088292483592144512" />
      <inertia ixx="2.6944521128613451853e-07" ixy="7.1389570705527249389e-15" ixz="1.3562243151413031662e-11" iyy="2.6944520001670002143e-07" iyz="-1.0089988349642198099e-11" izz="1.7809843599861015564e-08" />
    </inertial>
  </link>

  <joint name="right_ank_act2" type="fixed">
    <origin xyz="2.2722093354597683312e-06 -2.3106516700011070498e-15 -0.074779996992745872975" rpy="3.1415926535897926719 1.5779374385287525465e-15 -2.2021168238262811556" />
    <parent link="12lf_4" />
    <child link="12lf_rod_4" />
    <axis xyz="0 0 1" />
    <limit effort="10" velocity="20" lower="0" upper="0.040000000000000000833" />
  </joint>

  <joint name="right_ank_B32" type="fixed">
    <origin xyz="-1.3877787807814456755e-17 -0.0064387505004004919051 3.4694469519536141888e-18" rpy="-1.57079632679489678 -0.17993145005742655629 -9.5188382896695163748e-16" />
    <parent link="ball_joint_ball_4" />
    <child link="12lf_4" />
    <axis xyz="0 0 1" />
    <limit effort="10" velocity="20" lower="-0.785398163397448279" upper="0.785398163397448279" />
  </joint>

  <joint name="right_ank_B22" type="fixed">
    <origin xyz="-3.4694469519536141888e-18 0 -0.01150000000000000154" rpy="-1.5707963267948972241 -1.5664376509754736055 -1.5707963267954201392" />
    <parent link="ball_joint_container_4" />
    <child link="ball_joint_ball_4" />
    <axis xyz="0 0 1" />
    <limit effort="10" velocity="20" lower="-0.785398163397448279" upper="0.785398163397448279" />
  </joint>

  <joint name="right_ank_B12" type="fixed">
    <origin xyz="0.007999999999999972411 0.015000000000000041078 0.028299999999999964073" rpy="-1.570796326794911435 -1.5521341097221474925 1.5707963267949895947" />
    <parent link="right_calf_link" />
    <child link="ball_joint_container_4" />
    <axis xyz="0 0 1" />
    <limit effort="10" velocity="20" lower="-0.785398163397448279" upper="0.785398163397448279" />
  </joint>

  <joint name="right_knee" type="revolute">
    <origin xyz="-8.6240005279115787276e-15 -0.096000000000003332667 0.0105999999999985689" rpy="-1.540481569708491688e-15 6.7185500345545200678e-16 3.1415926535894529437" />
    <parent link="right_hip_pitch_link" />
    <child link="right_calf_link" />
    <axis xyz="0 0 1" />
    <limit effort="10" velocity="20" lower="-1.570796326794896558" upper="0" />
    <dynamics damping="0.819" friction="0.0085" />
  </joint>

  <joint name="right_hip_pitch" type="revolute">
    <origin xyz="-0.024000000716139988088 -0.01900000015244911189 -0.019000000152447529822" rpy="-1.5707963267949285324 -1.5707963267948303887 0" />
    <parent link="hip_roll_link_2" />
    <child link="right_hip_pitch_link" />
    <axis xyz="0 0 1" />
    <limit effort="10" velocity="20" lower="-1.570796326794896558" upper="1.570796326794896558" />
    <dynamics damping="0.76" friction="0.018" />
  </joint>

  <joint name="right_hip_roll" type="revolute">
    <origin xyz="0.018999999999999881567 -3.6837601416870012287e-18 -0.026000000000000002276" rpy="3.141592653589793116 -1.570796326794896336 0" />
    <parent link="hip_yaw_link_2" />
    <child link="hip_roll_link_2" />
    <axis xyz="0 0 1" />
    <limit effort="10" velocity="20" lower="-1.570796326794896558" upper="0.785398163397448279" />
    <dynamics damping="0.399" friction="0.0909" />
  </joint>


</robot>