<robot name="toddlerbot_legs">
  <mujoco>
    <compiler strippath="false" balanceinertia="true" discardvisual="false" />
  </mujoco>
  <link name="body_link">
    <visual>
      <origin xyz="0 0 0" rpy="0 -0 0" />
      <geometry>
        <mesh filename="../assemblies/no_body/meshes/body_link_visual.stl" />
      </geometry>
      <material name="body_link_material">
        <color rgba="0.60265235106909254004 0.74758186619713706822 0.82292492068132760963 1.0" />
      </material>
    </visual>
    <collision>
      <origin xyz="0 0 0" rpy="0 -0 0" />
      <geometry>
        <mesh filename="collisions/body_link_collision.stl" />
      </geometry>
    </collision>
    <inertial>
      <origin xyz="-0.014403523331510958982 -0.00023164401215091008635 0.31153288519557337244" rpy="0 0 0" />
      <mass value="0.1326329205818372603" />
      <inertia ixx="0.00012163093315384152372" ixy="1.4038303149150653818e-07" ixz="1.0872278951927060253e-05" iyy="8.4970137932106160972e-05" iyz="3.8740821289234436463e-07" izz="0.00015647103471607424" />
    </inertial>
  </link>

  <joint name="left_hip_yaw" type="revolute">
    <origin xyz="-0.0063999999999966063202 0.033999999999999308553 0.28550000000000003153" rpy="2.3275728331677864905e-16 1.1102230242191183694e-16 -1.1455751422015388711e-13" />
    <parent link="body_link" />
    <child link="hip_yaw_link" />
    <axis xyz="0 0 1" />
    <limit effort="1" velocity="20" lower="-0.785398163397448279" upper="0.785398163397448279" />
    <joint_properties friction="0.0" />
  </joint>

  <joint name="right_hip_yaw" type="revolute">
    <origin xyz="-0.0063999999999967980072 -0.034000000000000668576 0.28549999999999992051" rpy="1.2173498094825229595e-16 9.8900267199457111713e-23 -3.0336177719551955022e-13" />
    <parent link="body_link" />
    <child link="hip_yaw_link_2" />
    <axis xyz="0 0 1" />
    <limit effort="1" velocity="20" lower="-0.785398163397448279" upper="0.785398163397448279" />
    <joint_properties friction="0.0" />
  </joint>


  <link name="hip_yaw_link">
    <visual>
      <origin xyz="0 0 0" rpy="0 -0 0" />
      <geometry>
        <mesh filename="../assemblies/left_3R+RH5_leg/meshes/left_hip_yaw_link_visual.stl" />
      </geometry>
      <material name="hip_yaw_link_material">
        <color rgba="0.61568627450980395466 0.81176470588235294379 0.9294117647058824927 1.0" />
      </material>
    </visual>
    <inertial>
      <origin xyz="-4.169865130931172083e-19 -3.0887186477718995878e-19 -0.0098390489054830162358" rpy="0 0 0" />
      <mass value="0.009025883737097921064" />
      <inertia ixx="1.3230458239086458796e-06" ixy="-3.3592249637948224546e-24" ixz="-1.1251788840973426872e-52" iyy="3.8408510960331414253e-06" iyz="2.3044956050358323542e-34" izz="3.872139628579389935e-06" />
    </inertial>
  </link>

  <link name="hip_roll_link">
    <visual>
      <origin xyz="0 0 0" rpy="0 -0 0" />
      <geometry>
        <mesh filename="../assemblies/left_3R+RH5_leg/meshes/left_hip_roll_link_visual.stl" />
      </geometry>
      <material name="hip_roll_link_material">
        <color rgba="0.95018735644455865064 0.7067892720042843191 0.061612079402596720001 1.0" />
      </material>
    </visual>
    <collision>
      <origin xyz="0 0 0" rpy="0 -0 0" />
      <geometry>
        <mesh filename="collisions/left_hip_roll_link_collision.stl" />
      </geometry>
    </collision>
    <inertial>
      <origin xyz="-0.012000151133962999248 -0.00049588831384913981213 -0.018504019244505703901" rpy="0 0 0" />
      <mass value="0.098012391483528651936" />
      <inertia ixx="2.0221748766306741073e-05" ixy="-4.1552068242669349912e-08" ixz="-4.1225592188564757832e-08" iyy="2.7358099958307667684e-05" iyz="-5.0935731752368183668e-07" izz="2.7358069524723720877e-05" />
    </inertial>
  </link>

  <link name="left_hip_pitch_link">
    <visual>
      <origin xyz="0 0 0" rpy="0 -0 0" />
      <geometry>
        <mesh filename="../assemblies/left_3R+RH5_leg/meshes/left_hip_pitch_link_visual.stl" />
      </geometry>
      <material name="left_hip_pitch_link_material">
        <color rgba="0.61654126329715286392 0.80727601474877119792 0.92171686561974230933 1.0" />
      </material>
    </visual>
    <collision>
      <origin xyz="0 0 0" rpy="0 -0 0" />
      <geometry>
        <mesh filename="collisions/left_hip_pitch_link_collision.stl" />
      </geometry>
    </collision>
    <inertial>
      <origin xyz="-0.00021937270136341549195 0.052864534275054879398 0.014710916171980347594" rpy="0 0 0" />
      <mass value="0.093539065135968851861" />
      <inertia ixx="6.249591126723395753e-05" ixy="4.281683635485886633e-07" ixz="-1.5156170028218607617e-07" iyy="2.1496152188537947982e-05" iyz="-1.4210874963077317261e-06" izz="6.2275948339171713526e-05" />
    </inertial>
  </link>

  <link name="left_calf_link">
    <visual>
      <origin xyz="0 0 0" rpy="0 -0 0" />
      <geometry>
        <mesh filename="../assemblies/left_3R+RH5_leg/meshes/left_calf_link_visual.stl" />
      </geometry>
      <material name="left_calf_link_material">
        <color rgba="0.55397243078540503447 0.73161358475427695769 0.87715705664081478066 1.0" />
      </material>
    </visual>
    <collision>
      <origin xyz="0 0 0" rpy="0 -0 0" />
      <geometry>
        <mesh filename="collisions/left_calf_link_collision.stl" />
      </geometry>
    </collision>
    <inertial>
      <origin xyz="-0.0039136163069529907726 -0.043640010796484503264 0.0081849279519870064142" rpy="0 0 0" />
      <mass value="0.016290616864051549878" />
      <inertia ixx="1.5543943584208692903e-05" ixy="-2.1605519114066079532e-07" ixz="7.0470291476179005247e-09" iyy="1.9364407917964668321e-06" iyz="1.9633933099776931725e-08" izz="1.480719700352702444e-05" />
    </inertial>
  </link>

  <link name="ank_pitch_link">
    <visual>
      <origin xyz="0 0 0" rpy="0 -0 0" />
      <geometry>
        <mesh filename="../assemblies/left_3R+RH5_leg/meshes/left_ank_pitch_link_visual.stl" />
      </geometry>
      <material name="ank_pitch_link_material">
        <color rgba="0.63189161126160264814 0.7266866879354088038 0.78356373393969258601 1.0" />
      </material>
    </visual>
    <inertial>
      <origin xyz="4.026968501271137525e-08 0.0005952828256672347074 -0.01459992238389042768" rpy="0 0 0" />
      <mass value="0.0042238381753791614387" />
      <inertia ixx="4.370525406739012277e-07" ixy="1.6834347233230279547e-13" ixz="1.6428822384382108713e-12" iyy="3.9782741364650853327e-07" iyz="2.091924389243752615e-14" izz="8.8858574534559493653e-08" />
    </inertial>
  </link>

  <link name="ank_roll_link">
    <visual>
      <origin xyz="0 0 0" rpy="0 -0 0" />
      <geometry>
        <mesh filename="../assemblies/left_3R+RH5_leg/meshes/left_ank_roll_link_visual.stl" />
      </geometry>
      <material name="ank_roll_link_material">
        <color rgba="0.61568627450980395466 0.81176470588235283277 0.92941176470588238168 1.0" />
      </material>
    </visual>
    <collision>
      <origin xyz="0 0 0" rpy="0 -0 0" />
      <geometry>
        <mesh filename="collisions/left_ank_roll_link_collision.stl" />
      </geometry>
    </collision>
    <inertial>
      <origin xyz="-0.0067954317064110765501 0.030800108605150408603 -0.0019645930978156190411" rpy="0 0 0" />
      <mass value="0.021210605042023062544" />
      <inertia ixx="1.6673721136783793185e-05" ixy="9.6458085135773307807e-07" ixz="8.8407513061355861413e-07" iyy="1.8800607636409439845e-05" iyz="-1.299862496909490135e-06" izz="7.5433513527220517403e-06" />
    </inertial>
  </link>

  <link name="ank_rr_link">
    <visual>
      <origin xyz="0 0 0" rpy="0 -0 0" />
      <geometry>
        <mesh filename="../assemblies/left_3R+RH5_leg/meshes/left_ank_rr_link_visual.stl" />
      </geometry>
      <material name="ank_rr_link_material">
        <color rgba="0.61568627450980395466 0.81176470588235283277 0.92941176470588238168 1.0" />
      </material>
    </visual>
    <inertial>
      <origin xyz="-4.5867096565122424962e-20 -0.0061447686137497915457 2.067925278967512315e-19" rpy="0 0 0" />
      <mass value="0.00042507093693768156772" />
      <inertia ixx="8.7843229279236055827e-09" ixy="1.0068738557702793332e-25" ixz="-1.0879024114892058456e-14" iyy="8.0301730481463919886e-09" iyz="-5.4103617476780574479e-32" izz="1.2504379836120061674e-08" />
    </inertial>
  </link>

  <link name="12lf_rod_end">
    <visual>
      <origin xyz="0 0 0" rpy="0 -0 0" />
      <geometry>
        <mesh filename="../assemblies/left_3R+RH5_leg/meshes/left_12lf_rod_end_visual.stl" />
      </geometry>
      <material name="12lf_rod_end_material">
        <color rgba="0.92771758928836545177 0.61049283053223013518 0.21847658490585164515 1.0" />
      </material>
    </visual>
    <inertial>
      <origin xyz="-4.4735204920354271635e-11 -0.0038422185938246028805 6.4384187209446452224e-06" rpy="0 0 0" />
      <mass value="0.00085420491177815895123" />
      <inertia ixx="1.1840985264406779122e-08" ixy="2.0225977398266190056e-16" ixz="-9.2606420347592441568e-16" iyy="3.3549621576797309495e-09" iyz="7.4535631381823026266e-12" izz="1.2703522254419988197e-08" />
    </inertial>
  </link>

  <joint name="left_ank_R21" type="revolute">
    <origin xyz="-6.9388939039072283776e-18 -0.0099999999999999533706 6.9388939039072283776e-18" rpy="-1.570796326794896558 -1.4285697747629295673 1.5707963267948288344" />
    <parent link="ank_rr_link" />
    <child link="12lf_rod_end" />
    <axis xyz="0 0 1" />
    <limit effort="1" velocity="20" lower="-1.570796326794896558" upper="1.570796326794896558" />
    <joint_properties friction="0.0" />
  </joint>

  <joint name="left_ank_R11" type="revolute">
    <origin xyz="-0.0099999999999999967387 0.012500000000000038858 -0.033600000000000004863" rpy="-1.3295317856339465751e-14 8.7994714049036524006e-15 -0.1011603127570600974" />
    <parent link="ank_roll_link" />
    <child link="ank_rr_link" />
    <axis xyz="0 0 1" />
    <limit effort="1" velocity="20" lower="-1.570796326794896558" upper="1.570796326794896558" />
    <joint_properties friction="0.0" />
  </joint>

  <link name="ank_rr_link_2">
    <visual>
      <origin xyz="0 0 0" rpy="0 -0 0" />
      <geometry>
        <mesh filename="../assemblies/left_3R+RH5_leg/meshes/left_ank_rr_link_2_visual.stl" />
      </geometry>
      <material name="ank_rr_link_2_material">
        <color rgba="0.61568627450980395466 0.81176470588235283277 0.92941176470588238168 1.0" />
      </material>
    </visual>
    <inertial>
      <origin xyz="1.5443686748867368788e-20 -0.0061447686137497915457 2.0679252789668002024e-19" rpy="0 0 0" />
      <mass value="0.00042507093693768156772" />
      <inertia ixx="8.7843229279236022739e-09" ixy="-1.1926575209540821264e-25" ixz="-1.0879024114892056879e-14" iyy="8.0301730481463919886e-09" iyz="1.1907065342322363564e-31" izz="1.2504379836120061674e-08" />
    </inertial>
  </link>

  <link name="12lf_rod_end_2">
    <visual>
      <origin xyz="0 0 0" rpy="0 -0 0" />
      <geometry>
        <mesh filename="../assemblies/left_3R+RH5_leg/meshes/left_12lf_rod_end_2_visual.stl" />
      </geometry>
      <material name="12lf_rod_end_2_material">
        <color rgba="0.92771758928836545177 0.61049283053223013518 0.21847658490585164515 1.0" />
      </material>
    </visual>
    <inertial>
      <origin xyz="-4.4735200965666421951e-11 -0.0038422185938245733902 6.4384187209432781112e-06" rpy="0 0 0" />
      <mass value="0.00085420491177815895123" />
      <inertia ixx="1.1840985264406779122e-08" ixy="2.022597801403895296e-16" ixz="-9.2606419810299811503e-16" iyy="3.3549621576797268136e-09" iyz="7.4535631381847340852e-12" izz="1.2703522254419961727e-08" />
    </inertial>
  </link>

  <joint name="left_ank_R22" type="revolute">
    <origin xyz="-6.9388939039072283776e-18 -0.0099999999999999811262 6.9388939039072283776e-18" rpy="1.570796326794896558 -1.4285463212677005362 -1.5707963267950528774" />
    <parent link="ank_rr_link_2" />
    <child link="12lf_rod_end_2" />
    <axis xyz="0 0 1" />
    <limit effort="1" velocity="20" lower="-1.570796326794896558" upper="1.570796326794896558" />
    <joint_properties friction="0.0" />
  </joint>

  <joint name="left_ank_R12" type="revolute">
    <origin xyz="0.010000000000000003678 0.012500000000000038858 -0.033600000000000004863" rpy="3.1415926535897802374 2.5015582227113039382e-14 -3.0405529889788152076" />
    <parent link="ank_roll_link" />
    <child link="ank_rr_link_2" />
    <axis xyz="0 0 1" />
    <limit effort="1" velocity="20" lower="-1.570796326794896558" upper="1.570796326794896558" />
    <joint_properties friction="0.0" />
  </joint>

  <joint name="left_ank_roll" type="revolute">
    <origin xyz="2.9976021664879226591e-15 0.0015000000000041202163 -0.014599999999997613151" rpy="-1.5707963267949680564 -1.5707963267944098362 0" />
    <parent link="ank_pitch_link" />
    <child link="ank_roll_link" />
    <axis xyz="0 0 1" />
    <limit effort="1" velocity="20" lower="-0.785398163397448279" upper="0.785398163397448279" />
    <joint_properties friction="0.0" />
  </joint>

  <joint name="left_ank_pitch" type="revolute">
    <origin xyz="1.1074470850715867721e-18 -0.10000000000000006106 -0.0062000000000000023842" rpy="3.141592653589793116 1.7874590696523099396e-14 -1.5707963267948983344" />
    <parent link="left_calf_link" />
    <child link="ank_pitch_link" />
    <axis xyz="0 0 1" />
    <limit effort="1" velocity="20" lower="-0.52359877559829881566" upper="0.52359877559829881566" />
    <joint_properties friction="0.0" />
  </joint>

  <link name="ball_joint_container">
    <visual>
      <origin xyz="0 0 0" rpy="0 -0 0" />
      <geometry>
        <mesh filename="../assemblies/left_3R+RH5_leg/meshes/left_ball_joint_container_visual.stl" />
      </geometry>
      <material name="ball_joint_container_material">
        <color rgba="0.61568627450980395466 0.81176470588235294379 0.9294117647058824927 1.0" />
      </material>
    </visual>
    <inertial>
      <origin xyz="4.7221442975707412382e-19 -1.2135113793955168514e-19 -0.0097125341669083379431" rpy="0 0 0" />
      <mass value="4.8037356425330562243e-05" />
      <inertia ixx="7.1865480628741666366e-10" ixy="1.9093875420966183797e-26" ixz="-9.6567327904192743482e-39" iyy="8.4754204277185539101e-10" iyz="-2.0669447749008773941e-39" izz="1.8625314111651911712e-10" />
    </inertial>
  </link>

  <link name="ball_joint_ball">
    <visual>
      <origin xyz="0 0 0" rpy="0 -0 0" />
      <geometry>
        <mesh filename="../assemblies/left_3R+RH5_leg/meshes/left_ball_joint_ball_visual.stl" />
      </geometry>
      <material name="ball_joint_ball_material">
        <color rgba="0.3291302810242056065 0.44310466418644928188 0.69204871161977121741 1.0" />
      </material>
    </visual>
    <inertial>
      <origin xyz="2.0943472813681118712e-18 -0.001030866981001647394 1.6698556129646054768e-19" rpy="0 0 0" />
      <mass value="4.4053796295264623832e-05" />
      <inertia ixx="3.1285011349692334219e-10" ixy="-2.5137115013999161135e-25" ixz="2.1861546352690670189e-26" iyy="6.2569568612796147963e-11" iyz="-3.7415045053218497172e-26" izz="3.1285321460376891777e-10" />
    </inertial>
  </link>

  <link name="12lf">
    <visual>
      <origin xyz="0 0 0" rpy="0 -0 0" />
      <geometry>
        <mesh filename="../assemblies/left_3R+RH5_leg/meshes/left_12lf_visual.stl" />
      </geometry>
      <material name="12lf_material">
        <color rgba="0.62004392096503557763 0.58836684612040224263 0.49897069027350271497 1.0" />
      </material>
    </visual>
    <inertial>
      <origin xyz="0.0049084207226956725473 -0.00013802440006612445313 -0.029947003575852778473" rpy="0 0 0" />
      <mass value="0.044782197690790462308" />
      <inertia ixx="1.5260128420493731253e-05" ixy="2.2955774098748075055e-08" ixz="-8.1364204856709940048e-08" iyy="1.8188469777214632601e-05" iyz="-5.5542241170901426622e-08" izz="5.1496273889341820864e-06" />
    </inertial>
  </link>

  <link name="12lf_rod">
    <visual>
      <origin xyz="0 0 0" rpy="0 -0 0" />
      <geometry>
        <mesh filename="../assemblies/left_3R+RH5_leg/meshes/left_12lf_rod_visual.stl" />
      </geometry>
      <material name="12lf_rod_material">
        <color rgba="0.80250260812861884396 0.89340612183512713163 0.94491811293548189088 1.0" />
      </material>
    </visual>
    <inertial>
      <origin xyz="-6.3222084029212129078e-07 4.6933255311519471172e-07 -0.012893387334327143304" rpy="0 0 0" />
      <mass value="0.0025088292483592144512" />
      <inertia ixx="2.6944521128630530155e-07" ixy="7.1389570424753761856e-15" ixz="1.3562243131762661509e-11" iyy="2.6944520001687085739e-07" iyz="-1.0089988423546690317e-11" izz="1.7809843599861022181e-08" />
    </inertial>
  </link>

  <joint name="left_ank_act1" type="prismatic">
    <origin xyz="2.2722093528972087118e-06 4.2327252813834093104e-16 -0.072660031604101171787" rpy="-3.1415926535896590011 1.0257376628608333772e-13 -2.2021168238262784911" />
    <parent link="12lf" />
    <child link="12lf_rod" />
    <axis xyz="0 0 1" />
    <limit effort="1" velocity="20" lower="0" upper="0.040000000000000000833" />
    <joint_properties friction="0.0" />
  </joint>

  <joint name="left_ank_B31" type="revolute">
    <origin xyz="1.3010426069826053208e-18 -0.006438750500400436394 0" rpy="-1.57079632679489678 0.16913440034098886633 2.9529351978209400659e-15" />
    <parent link="ball_joint_ball" />
    <child link="12lf" />
    <axis xyz="0 0 1" />
    <limit effort="1" velocity="20" lower="-0.785398163397448279" upper="0.785398163397448279" />
    <joint_properties friction="0.0" />
  </joint>

  <joint name="left_ank_B21" type="revolute">
    <origin xyz="0 0 -0.011499999999999996336" rpy="1.570796326794896558 -1.4285697747625691889 1.5707963267948952257" />
    <parent link="ball_joint_container" />
    <child link="ball_joint_ball" />
    <axis xyz="0 0 1" />
    <limit effort="1" velocity="20" lower="-0.785398163397448279" upper="0.785398163397448279" />
    <joint_properties friction="0.0" />
  </joint>

  <joint name="left_ank_B11" type="revolute">
    <origin xyz="0.0080000000000000643513 -0.015000000000000235367 0.028299999999999957134" rpy="-1.570796326794896558 1.4696360140379425285 1.5707963267949005548" />
    <parent link="left_calf_link" />
    <child link="ball_joint_container" />
    <axis xyz="0 0 1" />
    <limit effort="1" velocity="20" lower="-0.785398163397448279" upper="0.785398163397448279" />
    <joint_properties friction="0.0" />
  </joint>

  <link name="ball_joint_container_2">
    <visual>
      <origin xyz="0 0 0" rpy="0 -0 0" />
      <geometry>
        <mesh filename="../assemblies/left_3R+RH5_leg/meshes/left_ball_joint_container_2_visual.stl" />
      </geometry>
      <material name="ball_joint_container_2_material">
        <color rgba="0.61568627450980395466 0.81176470588235294379 0.9294117647058824927 1.0" />
      </material>
    </visual>
    <inertial>
      <origin xyz="4.7221442975707797568e-19 -1.213511379395562833e-19 -0.0097125341669083396778" rpy="0 0 0" />
      <mass value="4.8037356425330562243e-05" />
      <inertia ixx="7.1865480628741666366e-10" ixy="-1.3182905845697921914e-26" ixz="-5.2568208926315324602e-39" iyy="8.475420427718555978e-10" iyz="6.7704469493154371076e-39" izz="1.8625314111651911712e-10" />
    </inertial>
  </link>

  <link name="ball_joint_ball_2">
    <visual>
      <origin xyz="0 0 0" rpy="0 -0 0" />
      <geometry>
        <mesh filename="../assemblies/left_3R+RH5_leg/meshes/left_ball_joint_ball_2_visual.stl" />
      </geometry>
      <material name="ball_joint_ball_2_material">
        <color rgba="0.3291302810242056065 0.44310466418644928188 0.69204871161977121741 1.0" />
      </material>
    </visual>
    <inertial>
      <origin xyz="-1.9482490896205589329e-18 -0.0010308669810016116153 9.9849008278937369588e-19" rpy="0 0 0" />
      <mass value="4.4053796295264623832e-05" />
      <inertia ixx="3.1285011349692675431e-10" ixy="-2.75805796047439135e-25" ixz="7.5294038721744216784e-26" iyy="6.2569568612795876545e-11" iyz="2.6034928009046818791e-26" izz="3.1285321460376922796e-10" />
    </inertial>
  </link>

  <link name="12lf_2">
    <visual>
      <origin xyz="0 0 0" rpy="0 -0 0" />
      <geometry>
        <mesh filename="../assemblies/left_3R+RH5_leg/meshes/left_12lf_2_visual.stl" />
      </geometry>
      <material name="12lf_2_material">
        <color rgba="0.62004392096503546661 0.58836684612040224263 0.49897069027350271497 1.0" />
      </material>
    </visual>
    <inertial>
      <origin xyz="0.004908420722688886309 -0.00013802440006871068189 -0.029947003575850877216" rpy="0 0 0" />
      <mass value="0.044782197690790462308" />
      <inertia ixx="1.5260128420492460703e-05" ixy="2.2955774098712135712e-08" ixz="-8.1364204859482847985e-08" iyy="1.8188469777215621935e-05" iyz="-5.5542241172242279778e-08" izz="5.1496273889364783927e-06" />
    </inertial>
  </link>

  <link name="12lf_rod_2">
    <visual>
      <origin xyz="0 0 0" rpy="0 -0 0" />
      <geometry>
        <mesh filename="../assemblies/left_3R+RH5_leg/meshes/left_12lf_rod_2_visual.stl" />
      </geometry>
      <material name="12lf_rod_2_material">
        <color rgba="0.80250260812861884396 0.89340612183512713163 0.94491811293548189088 1.0" />
      </material>
    </visual>
    <inertial>
      <origin xyz="-6.3222083690836262699e-07 4.6933255276162283075e-07 -0.012893387334328331589" rpy="0 0 0" />
      <mass value="0.0025088292483592144512" />
      <inertia ixx="2.6944521128623944474e-07" ixy="7.1389570123641515365e-15" ixz="1.3562243031473196704e-11" iyy="2.6944520001680500058e-07" iyz="-1.0089988412646377239e-11" izz="1.7809843599860992403e-08" />
    </inertial>
  </link>

  <joint name="left_ank_act2" type="prismatic">
    <origin xyz="2.2722093472333365627e-06 -8.396061623727746337e-15 -0.072660030478823994793" rpy="-3.1415926535895000171 4.7380615214810755067e-14 -2.2021168238262500694" />
    <parent link="12lf_2" />
    <child link="12lf_rod_2" />
    <axis xyz="0 0 1" />
    <limit effort="1" velocity="20" lower="0" upper="0.040000000000000000833" />
    <joint_properties friction="0.0" />
  </joint>

  <joint name="left_ank_B32" type="revolute">
    <origin xyz="1.7347234759768070944e-17 -0.006438750500400436394 0" rpy="-1.570796326794896336 -0.17993145005780261658 1.3200513083700388182e-15" />
    <parent link="ball_joint_ball_2" />
    <child link="12lf_2" />
    <axis xyz="0 0 1" />
    <limit effort="1" velocity="20" lower="-0.785398163397448279" upper="0.785398163397448279" />
    <joint_properties friction="0.0" />
  </joint>

  <joint name="left_ank_B22" type="revolute">
    <origin xyz="0 0 -0.011499999999999998071" rpy="1.570796326794896558 -1.4285463212681039913 -1.5707963267948852337" />
    <parent link="ball_joint_container_2" />
    <child link="ball_joint_ball_2" />
    <axis xyz="0 0 1" />
    <limit effort="1" velocity="20" lower="-0.785398163397448279" upper="0.785398163397448279" />
    <joint_properties friction="0.0" />
  </joint>

  <joint name="left_ank_B12" type="revolute">
    <origin xyz="0.008000000000000003636 -0.015000000000000013323 -0.011500000000000003275" rpy="-1.5707963267949294206 -1.4697566621822577559 1.5707963267949305308" />
    <parent link="left_calf_link" />
    <child link="ball_joint_container_2" />
    <axis xyz="0 0 1" />
    <limit effort="1" velocity="20" lower="-0.785398163397448279" upper="0.785398163397448279" />
    <joint_properties friction="0.0" />
  </joint>

  <joint name="left_knee" type="revolute">
    <origin xyz="-8.1704984642832938552e-15 0.095999999999999391376 0.027400000000000819533" rpy="3.1415926535897753524 1.6653345376122616675e-16 -1.6536824015790017811e-15" />
    <parent link="left_hip_pitch_link" />
    <child link="left_calf_link" />
    <axis xyz="0 0 1" />
    <limit effort="1" velocity="20" lower="0" upper="1.570796326794896558" />
    <joint_properties friction="0.0" />
  </joint>

  <joint name="left_hip_pitch" type="revolute">
    <origin xyz="-0.024000000716157210423 -0.019000000152441316043 -0.019000000152448022483" rpy="-1.5707963267944322627 1.570796326794811959 0" />
    <parent link="hip_roll_link" />
    <child link="left_hip_pitch_link" />
    <axis xyz="0 0 1" />
    <limit effort="1" velocity="20" lower="-1.570796326794896558" upper="1.570796326794896558" />
    <joint_properties friction="0.0" />
  </joint>

  <joint name="left_hip_roll" type="revolute">
    <origin xyz="0.019000000000000304839 -3.362403793834428631e-18 -0.026000000000000279832" rpy="3.141592653589793116 -1.5707963267945577179 0" />
    <parent link="hip_yaw_link" />
    <child link="hip_roll_link" />
    <axis xyz="0 0 1" />
    <limit effort="1" velocity="20" lower="-0.785398163397448279" upper="1.570796326794896558" />
    <joint_properties friction="0.0" />
  </joint>


  <link name="hip_yaw_link_2">
    <visual>
      <origin xyz="0 0 0" rpy="0 -0 0" />
      <geometry>
        <mesh filename="../assemblies/right_3R+RH5_leg/meshes/right_hip_yaw_link_visual.stl" />
      </geometry>
      <material name="hip_yaw_link_material">
        <color rgba="0.61568627450980395466 0.81176470588235294379 0.9294117647058824927 1.0" />
      </material>
    </visual>
    <inertial>
      <origin xyz="-4.169865130963886892e-19 -3.0887186475841816035e-19 -0.0098390489054829121524" rpy="0 0 0" />
      <mass value="0.009025883737097921064" />
      <inertia ixx="1.3230458239085870108e-06" ixy="-6.4778545919079845884e-49" ixz="1.7322911775161982211e-33" iyy="3.8408510960330533338e-06" iyz="-1.4482241779965776345e-32" izz="3.8721396285793069258e-06" />
    </inertial>
  </link>

  <link name="hip_roll_link_2">
    <visual>
      <origin xyz="0 0 0" rpy="0 -0 0" />
      <geometry>
        <mesh filename="../assemblies/right_3R+RH5_leg/meshes/right_hip_roll_link_visual.stl" />
      </geometry>
      <material name="hip_roll_link_material">
        <color rgba="0.95018735644455842859 0.7067892720042843191 0.061612079402596720001 1.0" />
      </material>
    </visual>
    <collision>
      <origin xyz="0 0 0" rpy="0 -0 0" />
      <geometry>
        <mesh filename="collisions/right_hip_roll_link_collision.stl" />
      </geometry>
    </collision>
    <inertial>
      <origin xyz="0.012000150775886153295 -0.00049588816141173531604 -0.019495980755502462234" rpy="0 0 0" />
      <mass value="0.098012391483528665814" />
      <inertia ixx="2.022174876630707311e-05" ixy="4.1552068245377810553e-08" ixz="-4.1225592185579456384e-08" iyy="2.7358099958307288213e-05" iyz="5.09357317523834832e-07" izz="2.7358069524724191828e-05" />
    </inertial>
  </link>

  <link name="right_hip_pitch_link">
    <visual>
      <origin xyz="0 0 0" rpy="0 -0 0" />
      <geometry>
        <mesh filename="../assemblies/right_3R+RH5_leg/meshes/right_hip_pitch_link_visual.stl" />
      </geometry>
      <material name="right_hip_pitch_link_material">
        <color rgba="0.61654126330065672779 0.80727601473037591262 0.92171686558820720148 1.0" />
      </material>
    </visual>
    <collision>
      <origin xyz="0 0 0" rpy="0 -0 0" />
      <geometry>
        <mesh filename="collisions/right_hip_pitch_link_collision.stl" />
      </geometry>
    </collision>
    <inertial>
      <origin xyz="-1.3043817563642643711e-05 0.05286453419666208714 0.014710916112540836989" rpy="0 0 0" />
      <mass value="0.09353906475262946385" />
      <inertia ixx="6.2495912126891110935e-05" ixy="-2.2341467553068197509e-07" ixz="-1.1719709579613414289e-08" iyy="2.150063816786048604e-05" iyz="-1.4210875155541280677e-06" izz="6.2280434774102103241e-05" />
    </inertial>
  </link>

  <link name="right_calf_link">
    <visual>
      <origin xyz="0 0 0" rpy="0 -0 0" />
      <geometry>
        <mesh filename="../assemblies/right_3R+RH5_leg/meshes/right_calf_link_visual.stl" />
      </geometry>
      <material name="right_calf_link_material">
        <color rgba="0.55397247693546480818 0.73161364570947462482 0.87715709724734269859 1.0" />
      </material>
    </visual>
    <collision>
      <origin xyz="0 0 0" rpy="0 -0 0" />
      <geometry>
        <mesh filename="collisions/right_calf_link_collision.stl" />
      </geometry>
    </collision>
    <inertial>
      <origin xyz="-0.003913604828102311764 0.043639997035758548716 0.0081848996608063079305" rpy="0 0 0" />
      <mass value="0.016290630569901022595" />
      <inertia ixx="1.5543964735762044456e-05" ixy="2.160598930607913158e-07" ixz="7.0519548982948992512e-09" iyy="1.936456681341731096e-06" iyz="-1.9645570089530235659e-08" izz="1.4807205615850181385e-05" />
    </inertial>
  </link>

  <link name="ank_pitch_link_2">
    <visual>
      <origin xyz="0 0 0" rpy="0 -0 0" />
      <geometry>
        <mesh filename="../assemblies/right_3R+RH5_leg/meshes/right_ank_pitch_link_visual.stl" />
      </geometry>
      <material name="ank_pitch_link_material">
        <color rgba="0.63189161126160275916 0.7266866879354088038 0.78356373393969258601 1.0" />
      </material>
    </visual>
    <inertial>
      <origin xyz="4.0269686140343600389e-08 0.00059528282566766947247 -0.014599922383890030428" rpy="0 0 0" />
      <mass value="0.0042238381753791614387" />
      <inertia ixx="4.3705254067391488611e-07" ixy="1.6834347258744780147e-13" ixz="1.6428822909209012184e-12" iyy="3.9782741364655564948e-07" iyz="2.0919209916503936685e-14" izz="8.8858574534526009381e-08" />
    </inertial>
  </link>

  <link name="ank_roll_link_2">
    <visual>
      <origin xyz="0 0 0" rpy="0 -0 0" />
      <geometry>
        <mesh filename="../assemblies/right_3R+RH5_leg/meshes/right_ank_roll_link_visual.stl" />
      </geometry>
      <material name="ank_roll_link_material">
        <color rgba="0.61568627450980395466 0.81176470588235283277 0.92941176470588238168 1.0" />
      </material>
    </visual>
    <collision>
      <origin xyz="0 0 0" rpy="0 -0 0" />
      <geometry>
        <mesh filename="collisions/right_ank_roll_link_collision.stl" />
      </geometry>
    </collision>
    <inertial>
      <origin xyz="0.0067954316497290476878 0.030800108584191222827 -0.0019645929618398207117" rpy="0 0 0" />
      <mass value="0.021210604954423659119" />
      <inertia ixx="1.6673721051425443836e-05" ixy="-9.6458086620934640677e-07" ixz="-8.8407559558929386577e-07" iyy="1.8800607546624137172e-05" iyz="-1.299862513390140733e-06" izz="7.5433513644979433832e-06" />
    </inertial>
  </link>

  <link name="ank_rr_link_3">
    <visual>
      <origin xyz="0 0 0" rpy="0 -0 0" />
      <geometry>
        <mesh filename="../assemblies/right_3R+RH5_leg/meshes/right_ank_rr_link_visual.stl" />
      </geometry>
      <material name="ank_rr_link_material">
        <color rgba="0.61568627450980395466 0.81176470588235283277 0.92941176470588238168 1.0" />
      </material>
    </visual>
    <inertial>
      <origin xyz="6.8909927486138587591e-18 -0.0061447686137497906783 2.0679252789697083566e-19" rpy="0 0 0" />
      <mass value="0.00042507093693768156772" />
      <inertia ixx="8.7843229279236022739e-09" ixy="-5.0134842627852916124e-26" ixz="-1.0879024114892056879e-14" iyy="8.0301730481463886798e-09" iyz="1.359744917393361523e-31" izz="1.2504379836120061674e-08" />
    </inertial>
  </link>

  <link name="12lf_rod_end_3">
    <visual>
      <origin xyz="0 0 0" rpy="0 -0 0" />
      <geometry>
        <mesh filename="../assemblies/right_3R+RH5_leg/meshes/right_12lf_rod_end_visual.stl" />
      </geometry>
      <material name="12lf_rod_end_material">
        <color rgba="0.92771758928836545177 0.61049283053223013518 0.21847658490585164515 1.0" />
      </material>
    </visual>
    <inertial>
      <origin xyz="-4.4735192473424715261e-11 -0.0038422185938245733902 6.4384187209510132161e-06" rpy="0 0 0" />
      <mass value="0.00085420491177815895123" />
      <inertia ixx="1.1840985264406789048e-08" ixy="2.0225978501517321813e-16" ixz="-9.2606419966761793191e-16" iyy="3.3549621576797214369e-09" iyz="7.4535631381829666329e-12" izz="1.2703522254419974962e-08" />
    </inertial>
  </link>

  <joint name="right_ank_R21" type="revolute">
    <origin xyz="4.1633363423443370266e-17 -0.010000000000000119904 -2.7755575615628913511e-17" rpy="-1.5707963267949331954 -1.4285697747630743404 1.5707963267949289765" />
    <parent link="ank_rr_link_3" />
    <child link="12lf_rod_end_3" />
    <axis xyz="0 0 1" />
    <limit effort="1" velocity="20" lower="-1.570796326794896558" upper="1.570796326794896558" />
    <joint_properties friction="0.0" />
  </joint>

  <joint name="right_ank_R11" type="revolute">
    <origin xyz="-0.0099999999999998423483 0.012499999999999733546 -0.033599999999999782818" rpy="-1.4093527784308163928e-14 -9.1905749868284128401e-17 -0.10116031275663164846" />
    <parent link="ank_roll_link_2" />
    <child link="ank_rr_link_3" />
    <axis xyz="0 0 1" />
    <limit effort="1" velocity="20" lower="-1.570796326794896558" upper="1.570796326794896558" />
    <joint_properties friction="0.0" />
  </joint>

  <link name="ank_rr_link_4">
    <visual>
      <origin xyz="0 0 0" rpy="0 -0 0" />
      <geometry>
        <mesh filename="../assemblies/right_3R+RH5_leg/meshes/right_ank_rr_link_2_visual.stl" />
      </geometry>
      <material name="ank_rr_link_2_material">
        <color rgba="0.61568627450980395466 0.81176470588235283277 0.92941176470588238168 1.0" />
      </material>
    </visual>
    <inertial>
      <origin xyz="8.6203576652448308076e-20 -0.0061447686137497915457 7.1456864318040533482e-18" rpy="0 0 0" />
      <mass value="0.00042507093693768156772" />
      <inertia ixx="8.7843229279236022739e-09" ixy="-8.9018097796581265674e-26" ixz="-1.0879024114892056879e-14" iyy="8.0301730481463919886e-09" iyz="-3.2911339759020778731e-32" izz="1.2504379836120061674e-08" />
    </inertial>
  </link>

  <link name="12lf_rod_end_4">
    <visual>
      <origin xyz="0 0 0" rpy="0 -0 0" />
      <geometry>
        <mesh filename="../assemblies/right_3R+RH5_leg/meshes/right_12lf_rod_end_2_visual.stl" />
      </geometry>
      <material name="12lf_rod_end_2_material">
        <color rgba="0.92771758928836545177 0.6104928305322302462 0.21847658490585164515 1.0" />
      </material>
    </visual>
    <inertial>
      <origin xyz="-4.4735198829362294065e-11 -0.003842218593824576426 6.4384187209524209848e-06" rpy="0 0 0" />
      <mass value="0.00085420491177815895123" />
      <inertia ixx="1.1840985264406789048e-08" ixy="2.0225978682449014433e-16" ixz="-9.260642008304349966e-16" iyy="3.3549621576796995167e-09" iyz="7.4535631381750583339e-12" izz="1.2703522254420003086e-08" />
    </inertial>
  </link>

  <joint name="right_ank_R22" type="revolute">
    <origin xyz="-5.5511151231257827021e-17 -0.0099999999999999811262 -1.3877787807814456755e-17" rpy="1.5707963267948956698 -1.4285463212684392786 -1.570796326794886566" />
    <parent link="ank_rr_link_4" />
    <child link="12lf_rod_end_4" />
    <axis xyz="0 0 1" />
    <limit effort="1" velocity="20" lower="-1.570796326794896558" upper="1.570796326794896558" />
    <joint_properties friction="0.0" />
  </joint>

  <joint name="right_ank_R12" type="revolute">
    <origin xyz="0.0099999999999997174482 0.012499999999999733546 -0.03359999999999976894" rpy="-3.1415926535897820138 -2.2156165769524474289e-15 -3.0405529889777027641" />
    <parent link="ank_roll_link_2" />
    <child link="ank_rr_link_4" />
    <axis xyz="0 0 1" />
    <limit effort="1" velocity="20" lower="-1.570796326794896558" upper="1.570796326794896558" />
    <joint_properties friction="0.0" />
  </joint>

  <joint name="right_ank_roll" type="revolute">
    <origin xyz="1.8041124150158793782e-15 0.0015000000000095273494 -0.014599999999994438607" rpy="-1.5707963267952527175 1.5707963267946807306 0" />
    <parent link="ank_pitch_link_2" />
    <child link="ank_roll_link_2" />
    <axis xyz="0 0 1" />
    <limit effort="1" velocity="20" lower="-0.785398163397448279" upper="0.785398163397448279" />
    <joint_properties friction="0.0" />
  </joint>

  <joint name="right_ank_pitch" type="revolute">
    <origin xyz="-2.423086741528762234e-18 0.10000000000000014433 -0.006200000000000555761" rpy="-3.1415926535897922278 -1.0275284166593592938e-14 -1.570796326794896558" />
    <parent link="right_calf_link" />
    <child link="ank_pitch_link_2" />
    <axis xyz="0 0 1" />
    <limit effort="1" velocity="20" lower="-0.52359877559829881566" upper="0.52359877559829881566" />
    <joint_properties friction="0.0" />
  </joint>

  <link name="ball_joint_container_3">
    <visual>
      <origin xyz="0 0 0" rpy="0 -0 0" />
      <geometry>
        <mesh filename="../assemblies/right_3R+RH5_leg/meshes/right_ball_joint_container_visual.stl" />
      </geometry>
      <material name="ball_joint_container_material">
        <color rgba="0.61568627450980395466 0.81176470588235294379 0.9294117647058824927 1.0" />
      </material>
    </visual>
    <inertial>
      <origin xyz="4.7221442975712102021e-19 -2.7876926753568478918e-17 -0.0097125341669083431473" rpy="0 0 0" />
      <mass value="4.8037356425330562243e-05" />
      <inertia ixx="7.1865480628741645687e-10" ixy="-2.1276536262898221805e-26" ixz="6.7377051491480635438e-39" iyy="8.475420427718555978e-10" iyz="-2.9779659754799928757e-39" izz="1.8625314111651911712e-10" />
    </inertial>
  </link>

  <link name="ball_joint_ball_3">
    <visual>
      <origin xyz="0 0 0" rpy="0 -0 0" />
      <geometry>
        <mesh filename="../assemblies/right_3R+RH5_leg/meshes/right_ball_joint_ball_visual.stl" />
      </geometry>
      <material name="ball_joint_ball_material">
        <color rgba="0.3291302810242056065 0.44310466418644928188 0.69204871161977121741 1.0" />
      </material>
    </visual>
    <inertial>
      <origin xyz="1.8393942021553128157e-17 -0.0010308669810016291794 -3.4073815427052736292e-20" rpy="0 0 0" />
      <mass value="4.4053796295264623832e-05" />
      <inertia ixx="3.128501134969055578e-10" ixy="-6.5207514975827964597e-26" ixz="-7.4537496808998083208e-25" iyy="6.2569568612795359557e-11" iyz="8.7215215474372494284e-25" izz="3.1285321460375345983e-10" />
    </inertial>
  </link>

  <link name="12lf_3">
    <visual>
      <origin xyz="0 0 0" rpy="0 -0 0" />
      <geometry>
        <mesh filename="../assemblies/right_3R+RH5_leg/meshes/right_12lf_visual.stl" />
      </geometry>
      <material name="12lf_material">
        <color rgba="0.62004392096503557763 0.58836684612040235365 0.49897069027350277048 1.0" />
      </material>
    </visual>
    <inertial>
      <origin xyz="0.0049084207226893867768 -0.00013802440006467576929 -0.029947003575836465133" rpy="0 0 0" />
      <mass value="0.044782197690790462308" />
      <inertia ixx="1.526012842048131375e-05" ixy="2.2955774098320406135e-08" ixz="-8.1364204859547315133e-08" iyy="1.8188469777200056858e-05" iyz="-5.554224117026341229e-08" izz="5.1496273889319450724e-06" />
    </inertial>
  </link>

  <link name="12lf_rod_3">
    <visual>
      <origin xyz="0 0 0" rpy="0 -0 0" />
      <geometry>
        <mesh filename="../assemblies/right_3R+RH5_leg/meshes/right_12lf_rod_visual.stl" />
      </geometry>
      <material name="12lf_rod_material">
        <color rgba="0.80250260812861884396 0.89340612183512713163 0.94491811293548189088 1.0" />
      </material>
    </visual>
    <inertial>
      <origin xyz="-6.3222084065473323676e-07 4.6933255155138083222e-07 -0.012893387334329891106" rpy="0 0 0" />
      <mass value="0.0025088292483592144512" />
      <inertia ixx="2.6944521128615410617e-07" ixy="7.1389570383049494142e-15" ixz="1.3562243140338437122e-11" iyy="2.6944520001671945025e-07" iyz="-1.0089988380103096692e-11" izz="1.7809843599861098282e-08" />
    </inertial>
  </link>

  <joint name="right_ank_act1" type="prismatic">
    <origin xyz="2.2722093427577499947e-06 1.727784582072899866e-15 -0.0726600316041042249" rpy="-3.1415926535897815697 1.0092007725908475977e-14 -2.2021168238260941941" />
    <parent link="12lf_3" />
    <child link="12lf_rod_3" />
    <axis xyz="0 0 1" />
    <limit effort="1" velocity="20" lower="0" upper="0.040000000000000000833" />
    <joint_properties friction="0.0" />
  </joint>

  <joint name="right_ank_B31" type="revolute">
    <origin xyz="9.5409791178724390193e-17 -0.0064387505004002698605 -5.5511151231257827021e-17" rpy="-1.5707963267948954478 0.16913440034172153026 -1.8050260774851149667e-15" />
    <parent link="ball_joint_ball_3" />
    <child link="12lf_3" />
    <axis xyz="0 0 1" />
    <limit effort="1" velocity="20" lower="-0.785398163397448279" upper="0.785398163397448279" />
    <joint_properties friction="0.0" />
  </joint>

  <joint name="right_ank_B21" type="revolute">
    <origin xyz="0 0 -0.011500000000000022357" rpy="1.5707963267948794606 -1.4285697747626477927 1.5707963267948803487" />
    <parent link="ball_joint_container_3" />
    <child link="ball_joint_ball_3" />
    <axis xyz="0 0 1" />
    <limit effort="1" velocity="20" lower="-0.785398163397448279" upper="0.785398163397448279" />
    <joint_properties friction="0.0" />
  </joint>

  <joint name="right_ank_B11" type="revolute">
    <origin xyz="0.0079999999999999238387 0.015000000000000124345 -0.01150000000000006746" rpy="1.5707963267949047736 -1.4696360140379067794 -1.5707963267948874542" />
    <parent link="right_calf_link" />
    <child link="ball_joint_container_3" />
    <axis xyz="0 0 1" />
    <limit effort="1" velocity="20" lower="-0.785398163397448279" upper="0.785398163397448279" />
    <joint_properties friction="0.0" />
  </joint>

  <link name="ball_joint_container_4">
    <visual>
      <origin xyz="0 0 0" rpy="0 -0 0" />
      <geometry>
        <mesh filename="../assemblies/right_3R+RH5_leg/meshes/right_ball_joint_container_2_visual.stl" />
      </geometry>
      <material name="ball_joint_container_2_material">
        <color rgba="0.61568627450980395466 0.81176470588235294379 0.9294117647058824927 1.0" />
      </material>
    </visual>
    <inertial>
      <origin xyz="4.7221442975709993128e-19 -2.7876926753568485081e-17 -0.0097125341669083396778" rpy="0 0 0" />
      <mass value="4.8037356425330562243e-05" />
      <inertia ixx="7.1865480628741666366e-10" ixy="-8.8579477000968401434e-27" ixz="1.6148781843625983881e-38" iyy="8.4754204277185539101e-10" iyz="4.6483058435882102207e-39" izz="1.8625314111651911712e-10" />
    </inertial>
  </link>

  <link name="ball_joint_ball_4">
    <visual>
      <origin xyz="0 0 0" rpy="0 -0 0" />
      <geometry>
        <mesh filename="../assemblies/right_3R+RH5_leg/meshes/right_ball_joint_ball_2_visual.stl" />
      </geometry>
      <material name="ball_joint_ball_2_material">
        <color rgba="0.3291302810242056065 0.44310466418644928188 0.69204871161977121741 1.0" />
      </material>
    </visual>
    <inertial>
      <origin xyz="6.5589330492613743757e-18 -0.0010308669810016346004 2.2610906665006864754e-18" rpy="0 0 0" />
      <mass value="4.4053796295264623832e-05" />
      <inertia ixx="3.1285011349692075725e-10" ixy="4.5293157501257737588e-26" ixz="2.3354674408829216367e-25" iyy="6.2569568612795049364e-11" iyz="-5.8366867949952536809e-25" izz="3.1285321460375444211e-10" />
    </inertial>
  </link>

  <link name="12lf_4">
    <visual>
      <origin xyz="0 0 0" rpy="0 -0 0" />
      <geometry>
        <mesh filename="../assemblies/right_3R+RH5_leg/meshes/right_12lf_2_visual.stl" />
      </geometry>
      <material name="12lf_2_material">
        <color rgba="0.62004392096503546661 0.5883668461204021316 0.49897069027350277048 1.0" />
      </material>
    </visual>
    <inertial>
      <origin xyz="0.0049084207226859841167 -0.00013802440006700818632 -0.029947003575832308736" rpy="0 0 0" />
      <mass value="0.044782197690790476186" />
      <inertia ixx="1.5260128420478200057e-05" ixy="2.295577409853090044e-08" ixz="-8.1364204860999301658e-08" iyy="1.8188469777196414616e-05" iyz="-5.5542241171308300222e-08" izz="5.1496273889314241471e-06" />
    </inertial>
  </link>

  <link name="12lf_rod_4">
    <visual>
      <origin xyz="0 0 0" rpy="0 -0 0" />
      <geometry>
        <mesh filename="../assemblies/right_3R+RH5_leg/meshes/right_12lf_rod_2_visual.stl" />
      </geometry>
      <material name="12lf_rod_2_material">
        <color rgba="0.80250260812861884396 0.89340612183512713163 0.94491811293548189088 1.0" />
      </material>
    </visual>
    <inertial>
      <origin xyz="-6.3222084137003392599e-07 4.6933255068316888491e-07 -0.012893387334332135838" rpy="0 0 0" />
      <mass value="0.0025088292483592144512" />
      <inertia ixx="2.6944521128602990996e-07" ixy="7.1389570225541423729e-15" ixz="1.3562243159358267851e-11" iyy="2.694452000165954658e-07" iyz="-1.008998835460835139e-11" izz="1.7809843599861015564e-08" />
    </inertial>
  </link>

  <joint name="right_ank_act2" type="prismatic">
    <origin xyz="2.2722093383550218126e-06 -2.4633073358870660741e-15 -0.07266003047881686161" rpy="3.141592653589793116 2.7467349934334640921e-15 -2.2021168238262860406" />
    <parent link="12lf_4" />
    <child link="12lf_rod_4" />
    <axis xyz="0 0 1" />
    <limit effort="1" velocity="20" lower="0" upper="0.040000000000000000833" />
    <joint_properties friction="0.0" />
  </joint>

  <joint name="right_ank_B32" type="revolute">
    <origin xyz="-7.3725747729014301513e-18 -0.0064387505004002698605 6.9388939039072283776e-18" rpy="-1.5707963267948981123 -0.17993145005746249976 -8.7955855822383372175e-16" />
    <parent link="ball_joint_ball_4" />
    <child link="12lf_4" />
    <axis xyz="0 0 1" />
    <limit effort="1" velocity="20" lower="-0.785398163397448279" upper="0.785398163397448279" />
    <joint_properties friction="0.0" />
  </joint>

  <joint name="right_ank_B22" type="revolute">
    <origin xyz="0 -5.5511151231257827021e-17 -0.01150000000000000501" rpy="1.5707963267948947816 -1.4285463212679219147 1.5707963267948921171" />
    <parent link="ball_joint_container_4" />
    <child link="ball_joint_ball_4" />
    <axis xyz="0 0 1" />
    <limit effort="1" velocity="20" lower="-0.785398163397448279" upper="0.785398163397448279" />
    <joint_properties friction="0.0" />
  </joint>

  <joint name="right_ank_B12" type="revolute">
    <origin xyz="0.0080000000000000192485 0.015000000000000068834 0.028300000000000900824" rpy="-1.5707963267949041075 -1.469756662182670981 1.5707963267948925612" />
    <parent link="right_calf_link" />
    <child link="ball_joint_container_4" />
    <axis xyz="0 0 1" />
    <limit effort="1" velocity="20" lower="-0.785398163397448279" upper="0.785398163397448279" />
    <joint_properties friction="0.0" />
  </joint>

  <joint name="right_knee" type="revolute">
    <origin xyz="-2.8905460953097867777e-15 0.095999999999999252598 0.027400000000001673017" rpy="-3.1415926535897824579 4.9746286444423846074e-17 -3.1415926535897891192" />
    <parent link="right_hip_pitch_link" />
    <child link="right_calf_link" />
    <axis xyz="0 0 1" />
    <limit effort="1" velocity="20" lower="-1.570796326794896558" upper="0" />
    <joint_properties friction="0.0" />
  </joint>

  <joint name="right_hip_pitch" type="revolute">
    <origin xyz="0.024000000358073016182 -0.019000000000011917078 -0.018999999847560563454" rpy="-1.5707963267950879604 -1.5707963267946316588 0" />
    <parent link="hip_roll_link_2" />
    <child link="right_hip_pitch_link" />
    <axis xyz="0 0 1" />
    <limit effort="1" velocity="20" lower="-1.570796326794896558" upper="1.570796326794896558" />
    <joint_properties friction="0.0" />
  </joint>

  <joint name="right_hip_roll" type="revolute">
    <origin xyz="0.018999999999999874628 7.643544883287250703e-16 -0.025999999999999960643" rpy="-1.300781512818313455e-27 1.5707963267948954478 0" />
    <parent link="hip_yaw_link_2" />
    <child link="hip_roll_link_2" />
    <axis xyz="0 0 1" />
    <limit effort="1" velocity="20" lower="-1.570796326794896558" upper="0.785398163397448279" />
    <joint_properties friction="0.0" />
  </joint>


</robot>