<mujoco model="toddlerbot_legs">
  <compiler angle="radian" autolimits="true" />

  <asset>
    <mesh name="torso_visual" file="../assemblies/toddlerbot_legs/meshes/torso_visual.stl" />
    <mesh name="waist_gears_visual" file="../assemblies/toddlerbot_legs/meshes/waist_gears_visual.stl" />
    <mesh name="waist_link_visual" file="../assemblies/toddlerbot_legs/meshes/waist_link_visual.stl" />
    <mesh name="spiral_bevel_1m_14t_30deg_visual" file="../assemblies/toddlerbot_legs/meshes/spiral_bevel_1m_14t_30deg_visual.stl" />
    <mesh name="spiral_bevel_1m_14t_30deg_2_visual" file="../assemblies/toddlerbot_legs/meshes/spiral_bevel_1m_14t_30deg_2_visual.stl" />
    <mesh name="spur_gear_19_teeth_visual" file="../assemblies/toddlerbot_legs/meshes/spur_gear_19_teeth_visual.stl" />
    <mesh name="spur_gear_21_teeth_visual" file="../assemblies/toddlerbot_legs/meshes/spur_gear_21_teeth_visual.stl" />
    <mesh name="spur_gear_19_teeth_2_visual" file="../assemblies/toddlerbot_legs/meshes/spur_gear_19_teeth_2_visual.stl" />
    <mesh name="spur_gear_21_teeth_2_visual" file="../assemblies/toddlerbot_legs/meshes/spur_gear_21_teeth_2_visual.stl" />
    <mesh name="left_hip_yaw_link_visual" file="../assemblies/left_leg_XM430/meshes/left_hip_yaw_link_visual.stl" />
    <mesh name="left_hip_roll_link_visual" file="../assemblies/left_leg_XM430/meshes/left_hip_roll_link_visual.stl" />
    <mesh name="left_hip_pitch_link_xm430_visual" file="../assemblies/left_leg_XM430/meshes/left_hip_pitch_link_xm430_visual.stl" />
    <mesh name="left_calf_link_visual" file="../assemblies/left_leg_XM430/meshes/left_calf_link_visual.stl" />
    <mesh name="left_bearing_683_visual" file="../assemblies/left_leg_XM430/meshes/left_bearing_683_visual.stl" />
    <mesh name="left_bearing_683_2_visual" file="../assemblies/left_leg_XM430/meshes/left_bearing_683_2_visual.stl" />
    <mesh name="left_ank_pitch_link_visual" file="../assemblies/left_leg_XM430/meshes/left_ank_pitch_link_visual.stl" />
    <mesh name="left_ank_roll_link_visual" file="../assemblies/left_leg_XM430/meshes/left_ank_roll_link_visual.stl" />
    <mesh name="left_ank_rr_link_visual" file="../assemblies/left_leg_XM430/meshes/left_ank_rr_link_visual.stl" />
    <mesh name="left_ank_motor_rod_long_visual" file="../assemblies/left_leg_XM430/meshes/left_ank_motor_rod_long_visual.stl" />
    <mesh name="left_ank_rr_link_2_visual" file="../assemblies/left_leg_XM430/meshes/left_ank_rr_link_2_visual.stl" />
    <mesh name="left_ank_motor_rod_short_visual" file="../assemblies/left_leg_XM430/meshes/left_ank_motor_rod_short_visual.stl" />
    <mesh name="left_ank_motor_arm_visual" file="../assemblies/left_leg_XM430/meshes/left_ank_motor_arm_visual.stl" />
    <mesh name="left_ank_motor_arm_2_visual" file="../assemblies/left_leg_XM430/meshes/left_ank_motor_arm_2_visual.stl" />
    <mesh name="left_xm430_plate_visual" file="../assemblies/left_leg_XM430/meshes/left_xm430_plate_visual.stl" />
    <mesh name="left_knee_rod_visual" file="../assemblies/left_leg_XM430/meshes/left_knee_rod_visual.stl" />
    <mesh name="left_knee_rod_2_visual" file="../assemblies/left_leg_XM430/meshes/left_knee_rod_2_visual.stl" />
    <mesh name="right_hip_yaw_link_visual" file="../assemblies/right_leg_XM430/meshes/right_hip_yaw_link_visual.stl" />
    <mesh name="right_hip_roll_link_visual" file="../assemblies/right_leg_XM430/meshes/right_hip_roll_link_visual.stl" />
    <mesh name="right_hip_pitch_link_xm430_visual" file="../assemblies/right_leg_XM430/meshes/right_hip_pitch_link_xm430_visual.stl" />
    <mesh name="right_calf_link_visual" file="../assemblies/right_leg_XM430/meshes/right_calf_link_visual.stl" />
    <mesh name="right_bearing_683_visual" file="../assemblies/right_leg_XM430/meshes/right_bearing_683_visual.stl" />
    <mesh name="right_bearing_683_2_visual" file="../assemblies/right_leg_XM430/meshes/right_bearing_683_2_visual.stl" />
    <mesh name="right_ank_pitch_link_visual" file="../assemblies/right_leg_XM430/meshes/right_ank_pitch_link_visual.stl" />
    <mesh name="right_ank_roll_link_visual" file="../assemblies/right_leg_XM430/meshes/right_ank_roll_link_visual.stl" />
    <mesh name="right_ank_rr_link_visual" file="../assemblies/right_leg_XM430/meshes/right_ank_rr_link_visual.stl" />
    <mesh name="right_ank_motor_rod_long_visual" file="../assemblies/right_leg_XM430/meshes/right_ank_motor_rod_long_visual.stl" />
    <mesh name="right_ank_rr_link_2_visual" file="../assemblies/right_leg_XM430/meshes/right_ank_rr_link_2_visual.stl" />
    <mesh name="right_ank_motor_rod_short_visual" file="../assemblies/right_leg_XM430/meshes/right_ank_motor_rod_short_visual.stl" />
    <mesh name="right_ank_motor_arm_visual" file="../assemblies/right_leg_XM430/meshes/right_ank_motor_arm_visual.stl" />
    <mesh name="right_ank_motor_arm_2_visual" file="../assemblies/right_leg_XM430/meshes/right_ank_motor_arm_2_visual.stl" />
    <mesh name="right_xm430_plate_visual" file="../assemblies/right_leg_XM430/meshes/right_xm430_plate_visual.stl" />
    <mesh name="right_knee_rod_visual" file="../assemblies/right_leg_XM430/meshes/right_knee_rod_visual.stl" />
    <mesh name="right_knee_rod_2_visual" file="../assemblies/right_leg_XM430/meshes/right_knee_rod_2_visual.stl" />
  </asset>

  <worldbody>
    <site name="imu" size="0.01" pos="0.0 0 0.0" />
    <site name="torso" fromto="0.01 0 0.4 -0.01 0 0.4" type="cylinder" size="0.005 0.005 1" group="3" />
    <geom type="mesh" rgba="0.58594 0.732003 0.846222 1" mesh="torso_visual" class="visual" />
    <body name="waist_gears" pos="0 0 0" quat="0 0 0 -1">
      <inertial pos="-2.96888e-07 5.64643e-08 -0.0125882" quat="0.49998 0.500022 0.500015 0.499983" mass="0.02581" diaginertia="7.25404e-06 6.93797e-06 1.51213e-06" />
      <joint name="waist_yaw" pos="0 0 0" axis="0 0 1" range="-1.5708 1.5708" damping="0.0" armature="0.0" />
      <geom type="mesh" rgba="0.263277 0.517464 0.701287 1" mesh="waist_gears_visual" class="visual" />
      <body name="waist_link" pos="-0.0227079 0 -0.014" quat="0.5 -0.5 -0.5 0.5">
        <inertial pos="-9.10862e-07 0.0262045 -0.0301904" quat="0.531459 0.467704 0.510522 0.488028" mass="0.16632" diaginertia="0.000200893 0.000157531 6.84712e-05" />
        <joint name="waist_roll" pos="0 0 0" axis="0 0 1" range="-0.523599 0.523599" damping="0.0" armature="0.0" />
        <geom type="mesh" rgba="0.634012 0.682047 0.669102 1" mesh="waist_link_visual" class="visual" />
        <body name="spiral_bevel_1m_14t_30deg" pos="0 0.0196 -0.01275" quat="0.5 0.5 0.5 -0.5">
          <inertial pos="8.26411e-10 3.40558e-10 0.00686126" quat="0.5 0.5 -0.5 0.5" mass="0.000679976" diaginertia="1.31787e-08 1.21746e-08 1.21746e-08" />
          <joint name="waist_act_1" pos="0 0 0" axis="0 0 1" range="-2.78255 2.78255" damping="0.099" armature="0.002" />
          <geom type="mesh" rgba="0.647059 0.647059 0.647059 1" mesh="spiral_bevel_1m_14t_30deg_visual" class="visual" />
        </body>
        <body name="spiral_bevel_1m_14t_30deg_2" pos="0 0.0196 -0.03275" quat="0.552838 0.552838 0.440874 -0.440874">
          <inertial pos="7.2991e-10 5.15913e-10 0.00686126" quat="0.5 0.5 -0.5 0.5" mass="0.000679976" diaginertia="1.31787e-08 1.21746e-08 1.21746e-08" />
          <joint name="waist_act_2" pos="0 0 0" axis="0 0 1" range="-2.78255 2.78255" damping="0.099" armature="0.002" />
          <geom type="mesh" rgba="0.647059 0.647059 0.647059 1" mesh="spiral_bevel_1m_14t_30deg_2_visual" class="visual" />
        </body>
        <body name="spur_gear_19_teeth" pos="-0.037 0.0371 -0.0395" quat="0.707107 -0.707107 0 0">
          <inertial pos="-4.99681e-09 -7.92422e-11 0.00452952" quat="0.5 0.5 -0.5 0.5" mass="0.00109937" diaginertia="4.571e-08 2.9215e-08 2.9215e-08" />
          <joint name="left_hip_yaw_drive" pos="0 0 0" axis="0 0 1" range="-1.4212 1.4212" damping="0.099" armature="0.002" />
          <geom type="mesh" rgba="0.615686 0.811765 0.929412 1" mesh="spur_gear_19_teeth_visual" class="visual" />
        </body>
        <body name="spur_gear_21_teeth" pos="-0.037 0.0411 -0.0195" quat="0.5 -0.5 -0.5 -0.5">
          <inertial pos="-2.5316e-11 0 0.0141855" quat="0.5 0.5 0.5 0.5" mass="0.0190063" diaginertia="7.83675e-06 7.7816e-06 2.81558e-06" />
          <joint name="left_hip_yaw_driven" pos="0 0 0" axis="0 0 1" range="-1.5708 1.5708" damping="0.120939" armature="0.00244321" />
          <geom type="mesh" rgba="0.615686 0.811765 0.929412 1" mesh="spur_gear_21_teeth_visual" class="visual" />
          <geom pos="0 0 0.005" quat="0 1 0 0" type="mesh" rgba="0.615686 0.811765 0.929412 1" mesh="left_hip_yaw_link_visual" class="visual" />
          <body name="hip_roll_link" pos="0.019 0 0.031" quat="-0.707107 0 -0.707107 0">
            <inertial pos="-0.0119998 -0.000495981 -0.0185041" quat="-0.273471 0.652073 -0.267709 0.654482" mass="0.1106" diaginertia="3.14464e-05 3.02975e-05 2.28182e-05" />
            <joint name="left_hip_roll" pos="0 0 0" axis="0 0 1" range="-0.785398 1.5708" damping="0.218" armature="0.002" />
            <geom type="mesh" rgba="0.516987 0.503478 0.490506 1" mesh="left_hip_roll_link_visual" class="visual" />
            <body name="left_hip_pitch_link_xm430" pos="-0.024 -0.019 -0.019" quat="0.5 0.5 0.5 -0.5">
              <inertial pos="-0.000757292 -0.0507148 -0.0126562" quat="0.719538 0.693946 0.0141894 -0.0224076" mass="0.114801" diaginertia="6.60879e-05 6.2263e-05 2.35772e-05" />
              <joint name="left_hip_pitch" pos="0 0 0" axis="0 0 1" range="-1.5708 1.5708" damping="0.218" armature="0.002" />
              <geom type="mesh" rgba="0.870722 0.72641 0.247852 1" mesh="left_hip_pitch_link_xm430_visual" class="visual" />
              <body name="left_calf_link" pos="0 -0.096 -0.0092" quat="1 0 0 0">
                <inertial pos="0.00163306 -0.0500455 -0.00990794" quat="0.51098 0.554671 -0.432284 0.494338" mass="0.0868" diaginertia="5.32087e-05 4.98403e-05 1.51303e-05" />
                <joint name="left_knee_pitch" pos="0 0 0" axis="0 0 1" range="0 1.91986" damping="0.0" armature="0.0" />
                <geom type="mesh" rgba="0.616548 0.717575 0.743727 1" mesh="left_calf_link_visual" class="visual" />
                <body name="bearing_683" pos="-0.00574025 0.0138582 -0.0262" quat="0.705076 0 0 0.709132">
                  <inertial pos="0 0 -0.00155" quat="0.5 0.5 -0.5 0.5" mass="0.000486947" diaginertia="3.53036e-09 2.15515e-09 2.15515e-09" />
                  <joint name="left_knee_front_rev_2" pos="0 0 0" axis="0 0 1" range="-6.28319 6.28319" damping="0.0" armature="0.0" />
                  <geom type="mesh" rgba="0.647059 0.647059 0.647059 1" mesh="left_bearing_683_visual" class="visual" />
                </body>
                <body name="bearing_683_2" pos="0.00574025 -0.0138582 -0.0262" quat="0.705063 0 0 0.709145">
                  <inertial pos="0 0 -0.00155" quat="0.5 0.5 -0.5 0.5" mass="0.000486947" diaginertia="3.53036e-09 2.15515e-09 2.15515e-09" />
                  <joint name="left_knee_back_rev_2" pos="0 0 0" axis="0 0 1" range="-6.28319 6.28319" damping="0.0" armature="0.0" />
                  <geom type="mesh" rgba="0.647059 0.647059 0.647059 1" mesh="left_bearing_683_2_visual" class="visual" />
                </body>
                <body name="ank_pitch_link" pos="0 -0.1 -0.0104" quat="0 0 0 1">
                  <inertial pos="0.000595283 -4.02697e-08 7.76161e-08" quat="0.707107 -1.66816e-06 1.66816e-06 0.707107" mass="0.00422384" diaginertia="4.37053e-07 3.97827e-07 8.88586e-08" />
                  <joint name="left_ank_pitch" pos="0 0 0" axis="0 0 1" range="-1.0472 0.785398" damping="0.0" armature="0.0" />
                  <geom type="mesh" rgba="0.631892 0.726687 0.783564 1" mesh="left_ank_pitch_link_visual" class="visual" />
                  <body name="ank_roll_link" pos="0.0015 0 0" quat="0.707107 0 0.707107 0">
                    <inertial pos="-4.19816e-07 0.0301847 0.00114994" quat="0.99889 -0.0470974 7.07694e-05 0.000269543" mass="0.0195" diaginertia="1.51504e-05 1.4939e-05 3.04775e-06" />
                    <joint name="left_ank_roll" pos="0 0 0" axis="0 0 1" range="-0.785398 0.785398" damping="0.0" armature="0.0" />
                    <geom type="mesh" rgba="0.615686 0.811765 0.929412 1" mesh="left_ank_roll_link_visual" class="visual" />
                    <geom name="ank_roll_link_collision" size="0.021 0.0225 0.06" pos="0 0.0165 0.0074" type="box" rgba="0.615686 0.811765 0.929412 1" class="collision" />
                    <body name="ank_rr_link" pos="-0.018 0.016 -0.0206" quat="0.00911142 0 0 0.999958">
                      <inertial pos="-4.52496e-05 0.00630964 0" quat="0.473509 0.525157 -0.473509 0.525157" mass="0.00145" diaginertia="4.29219e-08 2.97647e-08 2.74049e-08" />
                      <joint name="left_ank_long_rev_1" pos="0 0 0" axis="0 0 1" range="-1.5708 1.5708" damping="0.0" armature="0.0" />
                      <geom type="mesh" rgba="0.615686 0.811765 0.929412 1" mesh="left_ank_rr_link_visual" class="visual" />
                      <body name="ank_motor_rod_long" pos="0 0.01 0" quat="0.702074 -0.0842139 0.702074 -0.0842139">
                        <inertial pos="2.48551e-10 0.034559 0.000938517" quat="0.501157 0.503754 -0.498814 0.496243" mass="0.00217129" diaginertia="8.58145e-07 8.53502e-07 1.32148e-08" />
                        <joint name="left_ank_long_rev_2" pos="0 0 0" axis="0 0 1" range="-1.5708 1.5708" damping="0.0" armature="0.0" />
                        <geom type="mesh" rgba="0.6355 0.707744 0.75109 1" mesh="left_ank_motor_rod_long_visual" class="visual" />
                      </body>
                    </body>
                    <body name="ank_rr_link_2" pos="0.018 0.016 -0.0206" quat="0.999915 0 0 0.0130589">
                      <inertial pos="-4.52496e-05 -0.00630964 0" quat="0.525157 0.473509 -0.525157 0.473509" mass="0.00145" diaginertia="4.29219e-08 2.97647e-08 2.74049e-08" />
                      <joint name="left_ank_short_rev_1" pos="0 0 0" axis="0 0 1" range="-1.5708 1.5708" damping="0.0" armature="0.0" />
                      <geom type="mesh" rgba="0.615686 0.811765 0.929412 1" mesh="left_ank_rr_link_2_visual" class="visual" />
                      <body name="ank_motor_rod_short" pos="0 -0.01 0" quat="0.126204 -0.695753 0.126204 -0.695753">
                        <inertial pos="2.60389e-10 0.0238305 0.000904035" quat="0.499641 0.505179 -0.500306 0.494821" mass="0.0017" diaginertia="3.36253e-07 3.31534e-07 1.09078e-08" />
                        <joint name="left_ank_short_rev_2" pos="0 0 0" axis="0 0 1" range="-1.5708 1.5708" damping="0.0" armature="0.0" />
                        <geom type="mesh" rgba="0.412226 0.583391 0.811073 1" mesh="left_ank_motor_rod_short_visual" class="visual" />
                      </body>
                    </body>
                  </body>
                </body>
                <body name="ank_motor_arm" pos="0.0135 -0.0445 0.004" quat="0.994401 0 0 -0.105669">
                  <inertial pos="0.0140328 -1.18757e-09 0.00403835" quat="0 0.634087 0 0.773261" mass="0.00213594" diaginertia="1.87717e-07 1.7718e-07 2.28863e-08" />
                  <joint name="left_ank_act_1" pos="0 0 0" axis="0 0 1" range="-1.309 1.309" damping="0.099" armature="0.002" />
                  <geom type="mesh" rgba="0.624838 0.70972 0.765854 1" mesh="left_ank_motor_arm_visual" class="visual" />
                </body>
                <body name="ank_motor_arm_2" pos="0.0135 -0.0645 -0.0248" quat="0 -0.993397 0.114725 0">
                  <inertial pos="0.0140328 -1.18757e-09 0.00403835" quat="0 0.634087 0 0.773261" mass="0.00213594" diaginertia="1.87717e-07 1.7718e-07 2.28863e-08" />
                  <joint name="left_ank_act_2" pos="0 0 0" axis="0 0 1" range="-1.309 1.309" damping="0.099" armature="0.002" />
                  <geom type="mesh" rgba="0.624838 0.70972 0.765854 1" mesh="left_ank_motor_arm_2_visual" class="visual" />
                </body>
              </body>
              <body name="xm430_plate" pos="-0.00015 -0.0615 -0.0304" quat="0.707107 0 0 0.707107">
                <inertial pos="0 0 -0.0024039" quat="-0.13795 0.69352 0.13795 0.69352" mass="0.0027" diaginertia="3.85335e-07 2.95759e-07 1.00777e-07" />
                <joint name="left_knee_act" pos="0 0 0" axis="0 0 1" range="0 1.91986" damping="0.369" armature="0.002" />
                <geom type="mesh" rgba="0.615686 0.811765 0.929412 1" mesh="left_xm430_plate_visual" class="visual" />
                <body name="knee_rod" pos="0.0138582 0.00574025 -0.005" quat="0.00286757 0 0 -0.999996">
                  <inertial pos="0.0145945 -4.04952e-05 -0.00159962" quat="0.000208997 0.707354 -0.000208851 0.70686" mass="0.00316295" diaginertia="6.22669e-07 6.01533e-07 2.58956e-08" />
                  <joint name="left_knee_front_rev_1" pos="0 0 0" axis="0 0 1" range="-6.28319 6.28319" damping="0.0" armature="0.0" />
                  <geom type="mesh" rgba="0.620516 0.786408 0.885943 1" mesh="left_knee_rod_visual" class="visual" />
                </body>
                <body name="knee_rod_2" pos="-0.0138582 -0.00574025 -0.005" quat="0.00288614 0 0 -0.999996">
                  <inertial pos="0.0145945 -4.15794e-05 -0.00159962" quat="0.000214593 0.707354 -0.000214443 0.70686" mass="0.00316295" diaginertia="6.22669e-07 6.01533e-07 2.58956e-08" />
                  <joint name="left_knee_back_rev_1" pos="0 0 0" axis="0 0 1" range="-6.28319 6.28319" damping="0.0" armature="0.0" />
                  <geom type="mesh" rgba="0.620516 0.786408 0.885943 1" mesh="left_knee_rod_2_visual" class="visual" />
                </body>
              </body>
            </body>
          </body>
        </body>
        <body name="spur_gear_19_teeth_2" pos="0.037 0.0371 -0.0395" quat="0.707107 -0.707107 0 0">
          <inertial pos="-4.99681e-09 -7.92422e-11 0.00452952" quat="0.5 0.5 -0.5 0.5" mass="0.00109937" diaginertia="4.571e-08 2.9215e-08 2.9215e-08" />
          <joint name="right_hip_yaw_drive" pos="0 0 0" axis="0 0 1" range="-1.4212 1.4212" damping="0.099" armature="0.002" />
          <geom type="mesh" rgba="0.615686 0.811765 0.929412 1" mesh="spur_gear_19_teeth_2_visual" class="visual" />
        </body>
        <body name="spur_gear_21_teeth_2" pos="0.037 0.0411 -0.0195" quat="0.5 -0.5 -0.5 -0.5">
          <inertial pos="-2.5316e-11 0 0.014186" quat="0.5 0.5 0.5 0.5" mass="0.0190063" diaginertia="7.83649e-06 7.7816e-06 2.81532e-06" />
          <joint name="right_hip_yaw_driven" pos="0 0 0" axis="0 0 1" range="-1.5708 1.5708" damping="0.120939" armature="0.00244321" />
          <geom type="mesh" rgba="0.615686 0.811765 0.929412 1" mesh="spur_gear_21_teeth_2_visual" class="visual" />
          <geom pos="0 0 0.005" quat="0 -1 0 0" type="mesh" rgba="0.615686 0.811765 0.929412 1" mesh="right_hip_yaw_link_visual" class="visual" />
          <body name="hip_roll_link_2" pos="-0.019 0 0.031" quat="0 -0.707107 0 0.707107">
            <inertial pos="-0.0119998 -0.000495981 -0.0185041" quat="-0.273471 0.652073 -0.267709 0.654482" mass="0.1106" diaginertia="3.14464e-05 3.02975e-05 2.28182e-05" />
            <joint name="right_hip_roll" pos="0 0 0" axis="0 0 1" range="-0.785398 1.5708" damping="0.218" armature="0.002" />
            <geom type="mesh" rgba="0.516987 0.503478 0.490506 1" mesh="right_hip_roll_link_visual" class="visual" />
            <body name="right_hip_pitch_link_xm430" pos="-0.024 -0.019 -0.019" quat="0.5 0.5 0.5 -0.5">
              <inertial pos="0.000757159 -0.0507148 -0.0126562" quat="0.719539 0.693946 -0.0141939 0.0224005" mass="0.114801" diaginertia="6.60879e-05 6.22631e-05 2.35772e-05" />
              <joint name="right_hip_pitch" pos="0 0 0" axis="0 0 1" range="-1.5708 1.5708" damping="0.218" armature="0.002" />
              <geom type="mesh" rgba="0.870722 0.72641 0.247852 1" mesh="right_hip_pitch_link_xm430_visual" class="visual" />
              <body name="right_calf_link" pos="0 -0.096 -0.0092" quat="0 0 0 1">
                <inertial pos="0.00163306 0.0500455 -0.00990794" quat="0.554666 0.510951 -0.494335 0.432328" mass="0.0868" diaginertia="5.32182e-05 4.98499e-05 1.51305e-05" />
                <joint name="right_knee_pitch" pos="0 0 0" axis="0 0 1" range="-1.91986 0" damping="0.0" armature="0.0" />
                <geom type="mesh" rgba="0.616548 0.717575 0.743727 1" mesh="right_calf_link_visual" class="visual" />
                <body name="bearing_683_3" pos="-0.00574025 -0.0138582 -0.0262" quat="0.0028127 0 0 0.999996">
                  <inertial pos="0 0 -0.00155" quat="0.5 0.5 -0.5 0.5" mass="0.000486947" diaginertia="3.53036e-09 2.15515e-09 2.15515e-09" />
                  <joint name="right_knee_front_rev_2" pos="0 0 0" axis="0 0 1" range="-6.28319 6.28319" damping="0.0" armature="0.0" />
                  <geom type="mesh" rgba="0.647059 0.647059 0.647059 1" mesh="right_bearing_683_visual" class="visual" />
                </body>
                <body name="bearing_683_4" pos="0.00574025 0.0138582 -0.0262" quat="0.0027627 0 0 0.999996">
                  <inertial pos="0 0 -0.00155" quat="0.5 0.5 -0.5 0.5" mass="0.000486947" diaginertia="3.53036e-09 2.15515e-09 2.15515e-09" />
                  <joint name="right_knee_back_rev_2" pos="0 0 0" axis="0 0 1" range="-6.28319 6.28319" damping="0.0" armature="0.0" />
                  <geom type="mesh" rgba="0.647059 0.647059 0.647059 1" mesh="right_bearing_683_2_visual" class="visual" />
                </body>
                <body name="ank_pitch_link_2" pos="0 0.1 -0.0104" quat="0 0 1 0">
                  <inertial pos="0.000595283 4.02697e-08 -7.76161e-08" quat="0.707107 -1.66816e-06 1.66816e-06 0.707107" mass="0.00422384" diaginertia="4.37053e-07 3.97827e-07 8.88586e-08" />
                  <joint name="right_ank_pitch" pos="0 0 0" axis="0 0 1" range="-1.0472 0.785398" damping="0.0" armature="0.0" />
                  <geom type="mesh" rgba="0.631892 0.726687 0.783564 1" mesh="right_ank_pitch_link_visual" class="visual" />
                  <body name="ank_roll_link_2" pos="0.0015 0 0" quat="0.707107 0 0.707107 0">
                    <inertial pos="-4.19816e-07 0.0301847 0.00114994" quat="0.99889 -0.0470974 7.07694e-05 0.000269543" mass="0.0195" diaginertia="1.51504e-05 1.4939e-05 3.04775e-06" />
                    <joint name="right_ank_roll" pos="0 0 0" axis="0 0 1" range="-0.785398 0.785398" damping="0.0" armature="0.0" />
                    <geom type="mesh" rgba="0.615686 0.811765 0.929412 1" mesh="right_ank_roll_link_visual" class="visual" />
                    <geom name="ank_roll_link_2_collision" size="0.021 0.0225 0.06" pos="0 0.0165 0.0074" type="box" rgba="0.615686 0.811765 0.929412 1" class="collision" />
                    <body name="ank_rr_link_3" pos="0.018 0.016 -0.0206" quat="0.999958 0 0 0.00911142">
                      <inertial pos="-4.52496e-05 -0.00630964 0" quat="0.525157 0.473509 -0.525157 0.473509" mass="0.00145" diaginertia="4.29219e-08 2.97647e-08 2.74049e-08" />
                      <joint name="right_ank_long_rev_1" pos="0 0 0" axis="0 0 1" range="-1.5708 1.5708" damping="0.0" armature="0.0" />
                      <geom type="mesh" rgba="0.615686 0.811765 0.929412 1" mesh="right_ank_rr_link_visual" class="visual" />
                      <body name="ank_motor_rod_long_2" pos="0 -0.01 0" quat="0.0842139 -0.702074 0.0842139 -0.702074">
                        <inertial pos="2.48551e-10 0.034559 0.000938517" quat="0.501157 0.503754 -0.498814 0.496243" mass="0.00217129" diaginertia="8.58145e-07 8.53502e-07 1.32148e-08" />
                        <joint name="right_ank_long_rev_2" pos="0 0 0" axis="0 0 1" range="-1.5708 1.5708" damping="0.0" armature="0.0" />
                        <geom type="mesh" rgba="0.6355 0.707744 0.75109 1" mesh="right_ank_motor_rod_long_visual" class="visual" />
                      </body>
                    </body>
                    <body name="ank_rr_link_4" pos="-0.018 0.016 -0.0206" quat="0.0130589 0 0 0.999915">
                      <inertial pos="-4.52496e-05 0.00630964 0" quat="0.473509 0.525157 -0.473509 0.525157" mass="0.00145" diaginertia="4.29219e-08 2.97647e-08 2.74049e-08" />
                      <joint name="right_ank_short_rev_1" pos="0 0 0" axis="0 0 1" range="-1.5708 1.5708" damping="0.0" armature="0.0" />
                      <geom type="mesh" rgba="0.615686 0.811765 0.929412 1" mesh="right_ank_rr_link_2_visual" class="visual" />
                      <body name="ank_motor_rod_short_2" pos="0 0.01 0" quat="0.695753 -0.126204 0.695753 -0.126204">
                        <inertial pos="2.60389e-10 0.0238305 0.000904035" quat="0.499641 0.505179 -0.500306 0.494821" mass="0.0017" diaginertia="3.36253e-07 3.31534e-07 1.09078e-08" />
                        <joint name="right_ank_short_rev_2" pos="0 0 0" axis="0 0 1" range="-1.5708 1.5708" damping="0.0" armature="0.0" />
                        <geom type="mesh" rgba="0.412226 0.583391 0.811073 1" mesh="right_ank_motor_rod_short_visual" class="visual" />
                      </body>
                    </body>
                  </body>
                </body>
                <body name="ank_motor_arm_3" pos="0.0135 0.0445 0.004" quat="0.994401 0 0 0.105669">
                  <inertial pos="0.0140328 -1.18757e-09 0.00403835" quat="0 0.634087 0 0.773261" mass="0.00213594" diaginertia="1.87717e-07 1.7718e-07 2.28863e-08" />
                  <joint name="right_ank_act_1" pos="0 0 0" axis="0 0 1" range="-1.309 1.309" damping="0.099" armature="0.002" />
                  <geom type="mesh" rgba="0.624838 0.70972 0.765854 1" mesh="right_ank_motor_arm_visual" class="visual" />
                </body>
                <body name="ank_motor_arm_4" pos="0.0135 0.0645 -0.0248" quat="0 -0.993397 -0.114725 0">
                  <inertial pos="0.0140328 -1.18757e-09 0.00403835" quat="0 0.634087 0 0.773261" mass="0.00213594" diaginertia="1.87717e-07 1.7718e-07 2.28863e-08" />
                  <joint name="right_ank_act_2" pos="0 0 0" axis="0 0 1" range="-1.309 1.309" damping="0.099" armature="0.002" />
                  <geom type="mesh" rgba="0.624838 0.70972 0.765854 1" mesh="right_ank_motor_arm_2_visual" class="visual" />
                </body>
              </body>
              <body name="xm430_plate_2" pos="0.00015 -0.0615 -0.0304" quat="0 0 0 1">
                <inertial pos="0 0 -0.0024039" quat="0.587938 0.392847 -0.587938 0.392847" mass="0.0027" diaginertia="3.85335e-07 2.95759e-07 1.00777e-07" />
                <joint name="right_knee_act" pos="0 0 0" axis="0 0 1" range="-1.91986 0" damping="0.369" armature="0.002" />
                <geom type="mesh" rgba="0.615686 0.811765 0.929412 1" mesh="right_xm430_plate_visual" class="visual" />
                <body name="knee_rod_3" pos="-0.00574025 -0.0138582 -0.005" quat="0.709093 0 0 0.705115">
                  <inertial pos="0.0145946 3.72921e-05 -0.00159962" quat="-0.000192466 0.707354 0.000192331 0.70686" mass="0.00316295" diaginertia="6.22669e-07 6.01533e-07 2.58955e-08" />
                  <joint name="right_knee_front_rev_1" pos="0 0 0" axis="0 0 1" range="-6.28319 6.28319" damping="0.0" armature="0.0" />
                  <geom type="mesh" rgba="0.620516 0.786408 0.885943 1" mesh="right_knee_rod_visual" class="visual" />
                </body>
                <body name="knee_rod_4" pos="0.00574025 0.0138582 -0.005" quat="0.709058 0 0 0.705151">
                  <inertial pos="0.0145946 3.43732e-05 -0.00159962" quat="-0.000177401 0.707354 0.000177277 0.70686" mass="0.00316295" diaginertia="6.22669e-07 6.01533e-07 2.58954e-08" />
                  <joint name="right_knee_back_rev_1" pos="0 0 0" axis="0 0 1" range="-6.28319 6.28319" damping="0.0" armature="0.0" />
                  <geom type="mesh" rgba="0.620516 0.786408 0.885943 1" mesh="right_knee_rod_2_visual" class="visual" />
                </body>
              </body>
            </body>
          </body>
        </body>
      </body>
    </body>
  </worldbody>
  <option>
    <flag eulerdamp="disable" />
  </option>
  <sensor>
    <framequat name="orientation" objtype="site" noise="0.001" objname="imu" />
    <framepos name="position" objtype="site" noise="0.001" objname="imu" />
    <gyro name="angular_velocity" site="imu" noise="0.005" cutoff="34.9" />
    <velocimeter name="linear_velocity" site="imu" noise="0.001" cutoff="30" />
    <accelerometer name="linear_acceleration" site="imu" noise="0.005" cutoff="157" />
    <magnetometer name="magnetometer" site="imu" />
  </sensor>
  <actuator>
    <position name="waist_act_1" joint="waist_act_1" kp="18.75" ctrlrange="-2.78255 2.78255" class="XC330" />
    <position name="waist_act_2" joint="waist_act_2" kp="18.75" ctrlrange="-2.78255 2.78255" class="XC330" />
    <position name="left_hip_yaw_drive" joint="left_hip_yaw_driven" kp="18.75" gear="0.904762" ctrlrange="-1.5708 1.5708" class="XC330" />
    <position name="left_hip_roll" joint="left_hip_roll" kp="18.75" ctrlrange="-0.785398 1.5708" class="2XC430" />
    <position name="left_hip_pitch" joint="left_hip_pitch" kp="18.75" ctrlrange="-1.5708 1.5708" class="2XC430" />
    <position name="left_knee_act" joint="left_knee_act" kp="18.75" ctrlrange="0 1.91986" class="XM430" />
    <position name="left_ank_act_1" joint="left_ank_act_1" kp="18.75" ctrlrange="-1.309 1.309" class="XC330" />
    <position name="left_ank_act_2" joint="left_ank_act_2" kp="18.75" ctrlrange="-1.309 1.309" class="XC330" />
    <position name="right_hip_yaw_drive" joint="right_hip_yaw_driven" kp="18.75" gear="0.904762" ctrlrange="-1.5708 1.5708" class="XC330" />
    <position name="right_hip_roll" joint="right_hip_roll" kp="18.75" ctrlrange="-0.785398 1.5708" class="2XC430" />
    <position name="right_hip_pitch" joint="right_hip_pitch" kp="18.75" ctrlrange="-1.5708 1.5708" class="2XC430" />
    <position name="right_knee_act" joint="right_knee_act" kp="18.75" ctrlrange="-1.91986 0" class="XM430" />
    <position name="right_ank_act_1" joint="right_ank_act_1" kp="18.75" ctrlrange="-1.309 1.309" class="XC330" />
    <position name="right_ank_act_2" joint="right_ank_act_2" kp="18.75" ctrlrange="-1.309 1.309" class="XC330" />
  </actuator>
  <tendon>
    <fixed name="waist_roll_coupling" limited="true" range="0 0.001">
      <joint joint="waist_act_1" coef="0.291667" />
      <joint joint="waist_act_2" coef="-0.291667" />
      <joint joint="waist_roll" coef="1" />
    </fixed>
    <fixed name="waist_yaw_coupling" limited="true" range="0 0.001">
      <joint joint="waist_act_1" coef="0.416667" />
      <joint joint="waist_act_2" coef="0.416667" />
      <joint joint="waist_yaw" coef="1" />
    </fixed>
  </tendon>
  <equality>
    <weld body1="knee_rod" body2="bearing_683" solimp="0.9999 0.9999 0.001 0.5 2" solref="0.0001 1" />
    <weld body1="knee_rod_2" body2="bearing_683_2" solimp="0.9999 0.9999 0.001 0.5 2" solref="0.0001 1" />
    <weld body1="knee_rod_3" body2="bearing_683_3" solimp="0.9999 0.9999 0.001 0.5 2" solref="0.0001 1" />
    <weld body1="knee_rod_4" body2="bearing_683_4" solimp="0.9999 0.9999 0.001 0.5 2" solref="0.0001 1" />
    <connect body1="ank_motor_arm" body2="ank_motor_rod_long" solimp="0.9999 0.9999 0.001 0.5 2" solref="0.0001 1" anchor="0.02 0 0.00582666" />
    <connect body1="ank_motor_arm_2" body2="ank_motor_rod_short" solimp="0.9999 0.9999 0.001 0.5 2" solref="0.0001 1" anchor="0.02 0 0.00582666" />
    <connect body1="ank_motor_arm_3" body2="ank_motor_rod_long_2" solimp="0.9999 0.9999 0.001 0.5 2" solref="0.0001 1" anchor="0.02 0 0.00582666" />
    <connect body1="ank_motor_arm_4" body2="ank_motor_rod_short_2" solimp="0.9999 0.9999 0.001 0.5 2" solref="0.0001 1" anchor="0.02 0 0.00582666" />
  </equality>
  <keyframe>
    <key name="home" qpos="0 0 0 0 0 0 0 -0.2672678 0.523599 -0.523599 -0.523599 -0.25637 0 0 0.248043 0 -0.246445 -0.253132 0.256023 0.523599 -0.523599 -0.523599 0 0 0 0.2672678 -0.523599 0.523599 0.523599 -0.25637 0 0 -0.248043 0 0.246445 0.253132 -0.256023 -0.523599 0.523599 0.523599 " ctrl="0 0 0 0 -0.2672678 0.523599 -0.253132 0.256023 0 0 0.2672678 -0.523599 0.253132 -0.256023 " />
  </keyframe>
  <default>
    <default class="XM430">
      <position forcerange="-3 3" />
    </default>
    <default class="XC430">
      <position forcerange="-2 2" />
    </default>
    <default class="2XC430">
      <position forcerange="-2 2" />
    </default>
    <default class="XL430">
      <position forcerange="-2 2" />
    </default>
    <default class="2XL430">
      <position forcerange="-2 2" />
    </default>
    <default class="XC330">
      <position forcerange="-1 1" />
    </default>
    <default class="visual">
      <geom type="mesh" contype="0" conaffinity="0" group="2" />
    </default>
    <default class="collision">
      <geom type="sphere" group="3" />
    </default>
  </default>
  <contact>
    <exclude body1="ank_roll_link" body2="ank_roll_link_2" />
    <exclude body1="ank_roll_link_2" body2="ank_roll_link" />
  </contact>
</mujoco>