<robot name="toddlerbot_legs">
  <mujoco>
    <compiler strippath="false" balanceinertia="true" discardvisual="false" />
  </mujoco>
  <link name="body_link">
    <visual>
      <origin xyz="0 0 0" rpy="0 -0 0" />
      <geometry>
        <mesh filename="../assemblies/no_body/meshes/body_link_visual.stl" />
      </geometry>
      <material name="body_link_material">
        <color rgba="0.60265235106909265106 0.74758186619713717924 0.82292492068132783167 1.0" />
      </material>
    </visual>
    <collision>
      <origin xyz="0 0 0" rpy="0 -0 0" />
      <geometry>
        <mesh filename="collisions/body_link_collision.stl" />
      </geometry>
    </collision>
    <inertial>
      <origin xyz="-0.014403523331510962452 -0.00023164401215090967977 0.31153288519557342795" rpy="0 0 0" />
      <mass value="0.1326329205818372603" />
      <inertia ixx="0.00012163093315384155082" ixy="1.4038303149150714698e-07" ixz="1.0872278951927053477e-05" iyy="8.497013793210614742e-05" iyz="3.8740821289234341171e-07" izz="0.00015647103471607424" />
    </inertial>
  </link>

  <joint name="left_hip_yaw" type="revolute">
    <origin xyz="-0.0063999999999966045855 0.03399999999999939182 0.28550000000000008704" rpy="2.327572832560927136e-16 4.9789962508008699149e-17 -1.0650377544034614197e-13" />
    <parent link="body_link" />
    <child link="hip_yaw_link" />
    <axis xyz="0 0 1" />
    <limit effort="1" velocity="20" lower="-0.785398163397448279" upper="0.785398163397448279" />
    <joint_properties friction="0.0" />
  </joint>

  <joint name="right_hip_yaw" type="revolute">
    <origin xyz="-0.0063999999999967962724 -0.034000000000000661637 0.28549999999999992051" rpy="1.2173498094910643509e-16 -6.1232339957301087894e-17 -5.033057304260250785e-13" />
    <parent link="body_link" />
    <child link="hip_yaw_link_2" />
    <axis xyz="0 0 1" />
    <limit effort="1" velocity="20" lower="-0.785398163397448279" upper="0.785398163397448279" />
    <joint_properties friction="0.0" />
  </joint>


  <link name="hip_yaw_link">
    <visual>
      <origin xyz="0 0 0" rpy="0 -0 0" />
      <geometry>
        <mesh filename="../assemblies/left_3R+RH5_leg/meshes/left_hip_yaw_link_visual.stl" />
      </geometry>
      <material name="hip_yaw_link_material">
        <color rgba="0.61568627450980395466 0.81176470588235294379 0.9294117647058824927 1.0" />
      </material>
    </visual>
    <inertial>
      <origin xyz="-4.318788885607285492e-19 -2.3813308130603736541e-19 -0.0098390489054830127663" rpy="0 0 0" />
      <mass value="0.0090258837370979193293" />
      <inertia ixx="1.3230458239086465149e-06" ixy="-3.3592249637948224546e-24" ixz="-1.1251788840973426872e-52" iyy="3.8408510960331414253e-06" iyz="2.3044956050358327818e-34" izz="3.8721396285793907821e-06" />
    </inertial>
  </link>

  <link name="hip_roll_link">
    <visual>
      <origin xyz="0 0 0" rpy="0 -0 0" />
      <geometry>
        <mesh filename="../assemblies/left_3R+RH5_leg/meshes/left_hip_roll_link_visual.stl" />
      </geometry>
      <material name="hip_roll_link_material">
        <color rgba="0.95018735644455865064 0.70678927200428420807 0.061612079402596699185 1.0" />
      </material>
    </visual>
    <collision>
      <origin xyz="0 0 0" rpy="0 -0 0" />
      <geometry>
        <mesh filename="collisions/left_hip_roll_link_collision.stl" />
      </geometry>
    </collision>
    <inertial>
      <origin xyz="-0.012000151133961880351 -0.0004958883138492458471 -0.018504019244505585939" rpy="0 0 0" />
      <mass value="0.098012391483528679692" />
      <inertia ixx="2.0221748766306646205e-05" ixy="-4.1552068242967637858e-08" ixz="-4.1225592188433030974e-08" iyy="2.7358099958307437291e-05" iyz="-5.0935731752375478739e-07" izz="2.7358069524723449827e-05" />
    </inertial>
  </link>

  <link name="left_hip_pitch_link">
    <visual>
      <origin xyz="0 0 0" rpy="0 -0 0" />
      <geometry>
        <mesh filename="../assemblies/left_3R+RH5_leg/meshes/left_hip_pitch_link_visual.stl" />
      </geometry>
      <material name="left_hip_pitch_link_material">
        <color rgba="0.61653813877273688782 0.80729241850195565533 0.92174498633948687143 1.0" />
      </material>
    </visual>
    <collision>
      <origin xyz="0 0 0" rpy="0 -0 0" />
      <geometry>
        <mesh filename="collisions/left_hip_pitch_link_collision.stl" />
      </geometry>
    </collision>
    <inertial>
      <origin xyz="-0.00026813789113049719091 0.052916501848365597727 0.014786698994483196343" rpy="0 0 0" />
      <mass value="0.093882153942003054858" />
      <inertia ixx="6.2803219617714261223e-05" ixy="4.9869151542720510748e-07" ixz="-5.6084901037867845853e-08" iyy="2.1711933812584210333e-05" iyz="-1.515682308592801446e-06" izz="6.2502032342773186473e-05" />
    </inertial>
  </link>

  <link name="left_calf_link">
    <visual>
      <origin xyz="0 0 0" rpy="0 -0 0" />
      <geometry>
        <mesh filename="../assemblies/left_3R+RH5_leg/meshes/left_calf_link_visual.stl" />
      </geometry>
      <material name="left_calf_link_material">
        <color rgba="0.55397243078540514549 0.73161358475427706871 0.87715705664081489168 1.0" />
      </material>
    </visual>
    <collision>
      <origin xyz="0 0 0" rpy="0 -0 0" />
      <geometry>
        <mesh filename="collisions/left_calf_link_collision.stl" />
      </geometry>
    </collision>
    <inertial>
      <origin xyz="-0.0039136163069529838338 -0.043640010796484475508 0.008184927951986989067" rpy="0 0 0" />
      <mass value="0.016290616864051549878" />
      <inertia ixx="1.554394358420871662e-05" ixy="-2.1605519114066550694e-07" ixz="7.0470291476171262836e-09" iyy="1.9364407917964655615e-06" iyz="1.9633933099790907768e-08" izz="1.4807197003527056627e-05" />
    </inertial>
  </link>

  <link name="ank_pitch_link">
    <visual>
      <origin xyz="0 0 0" rpy="0 -0 0" />
      <geometry>
        <mesh filename="../assemblies/left_3R+RH5_leg/meshes/left_ank_pitch_link_visual.stl" />
      </geometry>
      <material name="ank_pitch_link_material">
        <color rgba="0.63189161126160275916 0.72668668793540891482 0.78356373393969258601 1.0" />
      </material>
    </visual>
    <inertial>
      <origin xyz="4.0269685034916668217e-08 0.00059528282566742747855 -0.014599922383890413802" rpy="0 0 0" />
      <mass value="0.0042238381753791605713" />
      <inertia ixx="4.3705254067389826308e-07" ixy="1.6834346868313279298e-13" ixz="1.6428822472590724668e-12" iyy="3.9782741364651398605e-07" iyz="2.0919251965470696455e-14" izz="8.8858574534551155672e-08" />
    </inertial>
  </link>

  <link name="ank_roll_link">
    <visual>
      <origin xyz="0 0 0" rpy="0 -0 0" />
      <geometry>
        <mesh filename="../assemblies/left_3R+RH5_leg/meshes/left_ank_roll_link_visual.stl" />
      </geometry>
      <material name="ank_roll_link_material">
        <color rgba="0.61568627450980395466 0.81176470588235294379 0.92941176470588238168 1.0" />
      </material>
    </visual>
    <collision>
      <origin xyz="0 0 0" rpy="0 -0 0" />
      <geometry>
        <mesh filename="collisions/left_ank_roll_link_collision.stl" />
      </geometry>
    </collision>
    <inertial>
      <origin xyz="-6.3661537660312296339e-10 0.027240102316353702328 -0.0056169852551464592022" rpy="0 0 0" />
      <mass value="0.013844478784760248444" />
      <inertia ixx="1.0150902309234930825e-05" ixy="6.8603299830454522673e-14" ixz="-3.2605547372804313931e-13" iyy="8.66361166634314672e-06" iyz="-7.8151778926544773726e-07" izz="2.8991570356470334528e-06" />
    </inertial>
  </link>

  <link name="ank_rr_link">
    <visual>
      <origin xyz="0 0 0" rpy="0 -0 0" />
      <geometry>
        <mesh filename="../assemblies/left_3R+RH5_leg/meshes/left_ank_rr_link_visual.stl" />
      </geometry>
      <material name="ank_rr_link_material">
        <color rgba="0.61568627450980395466 0.81176470588235294379 0.92941176470588238168 1.0" />
      </material>
    </visual>
    <inertial>
      <origin xyz="3.4593503690053898085e-05 -0.0062999445222072132655 -6.7128310146504586675e-18" rpy="0 0 0" />
      <mass value="0.00044289790445047673732" />
      <inertia ixx="9.0894755004835289854e-09" ixy="5.6689994077039863727e-11" ixz="-1.0879024115049112774e-14" iyy="8.3785129146959905585e-09" iyz="-1.3342618452415281022e-31" izz="1.3107013728801488166e-08" />
    </inertial>
  </link>

  <link name="12lf_rod_end">
    <visual>
      <origin xyz="0 0 0" rpy="0 -0 0" />
      <geometry>
        <mesh filename="../assemblies/left_3R+RH5_leg/meshes/left_12lf_rod_end_visual.stl" />
      </geometry>
      <material name="12lf_rod_end_material">
        <color rgba="0.92771758928836534075 0.61049283053223002415 0.2184765849058516729 1.0" />
      </material>
    </visual>
    <inertial>
      <origin xyz="-4.4735199444099544538e-11 -0.0038422185938245759923 6.4384187209413587345e-06" rpy="0 0 0" />
      <mass value="0.00085420491177815905965" />
      <inertia ixx="1.1840985264406779122e-08" ixy="2.0225978174399016856e-16" ixz="-9.2606419813419283067e-16" iyy="3.3549621576797388077e-09" iyz="7.4535631381886163411e-12" izz="1.2703522254419979925e-08" />
    </inertial>
  </link>

  <joint name="left_ank_R21" type="fixed">
    <origin xyz="-6.9388939039072283776e-18 -0.0099999999999999533706 0" rpy="-1.570796326794896558 -1.4285697747629988452 1.5707963267949092145" />
    <parent link="ank_rr_link" />
    <child link="12lf_rod_end" />
    <axis xyz="0 0 1" />
    <limit effort="1" velocity="20" lower="-1.570796326794896558" upper="1.570796326794896558" />
    <joint_properties friction="0.0" />
  </joint>

  <joint name="left_ank_R11" type="fixed">
    <origin xyz="-0.0099999999999999967387 0.012500000000000011102 -0.033600000000000011802" rpy="-3.5821358734369027029e-16 -2.0703583441380111793e-15 -0.1011603127571137628" />
    <parent link="ank_roll_link" />
    <child link="ank_rr_link" />
    <axis xyz="0 0 1" />
    <limit effort="1" velocity="20" lower="-1.570796326794896558" upper="1.570796326794896558" />
    <joint_properties friction="0.0" />
  </joint>

  <link name="ank_rr_link_2">
    <visual>
      <origin xyz="0 0 0" rpy="0 -0 0" />
      <geometry>
        <mesh filename="../assemblies/left_3R+RH5_leg/meshes/left_ank_rr_link_2_visual.stl" />
      </geometry>
      <material name="ank_rr_link_2_material">
        <color rgba="0.61568627450980395466 0.81176470588235294379 0.92941176470588238168 1.0" />
      </material>
    </visual>
    <inertial>
      <origin xyz="3.4593503690060877637e-05 -0.0062999445222072687767 2.2606288925691882524e-19" rpy="0 0 0" />
      <mass value="0.00044289790445047673732" />
      <inertia ixx="9.0894755004835289854e-09" ixy="5.6689994077039773254e-11" ixz="-1.0879024115049112774e-14" iyy="8.3785129146959905585e-09" iyz="-8.5987112218601748743e-32" izz="1.3107013728801488166e-08" />
    </inertial>
  </link>

  <link name="12lf_rod_end_2">
    <visual>
      <origin xyz="0 0 0" rpy="0 -0 0" />
      <geometry>
        <mesh filename="../assemblies/left_3R+RH5_leg/meshes/left_12lf_rod_end_2_visual.stl" />
      </geometry>
      <material name="12lf_rod_end_2_material">
        <color rgba="0.92771758928836534075 0.61049283053223002415 0.2184765849058516729 1.0" />
      </material>
    </visual>
    <inertial>
      <origin xyz="-4.4735202914756461395e-11 -0.0038422185938245491041 6.4384187209514621435e-06" rpy="0 0 0" />
      <mass value="0.00085420491177815905965" />
      <inertia ixx="1.1840985264406812209e-08" ixy="2.0225978118758458261e-16" ixz="-9.2606419780188261055e-16" iyy="3.3549621576797421165e-09" iyz="7.4535631381815820747e-12" izz="1.2703522254419999777e-08" />
    </inertial>
  </link>

  <joint name="left_ank_R22" type="fixed">
    <origin xyz="6.9388939039072283776e-18 -0.010000000000000036637 6.9388939039072283776e-18" rpy="1.5707963267949194286 -1.4285463212677806943 -1.5707963267950313391" />
    <parent link="ank_rr_link_2" />
    <child link="12lf_rod_end_2" />
    <axis xyz="0 0 1" />
    <limit effort="1" velocity="20" lower="-1.570796326794896558" upper="1.570796326794896558" />
    <joint_properties friction="0.0" />
  </joint>

  <joint name="left_ank_R12" type="fixed">
    <origin xyz="0.010000000000000003678 0.012499999999999955591 -0.033600000000000004863" rpy="3.1415926535897606975 1.5562027335348888578e-14 -3.0405529889788582842" />
    <parent link="ank_roll_link" />
    <child link="ank_rr_link_2" />
    <axis xyz="0 0 1" />
    <limit effort="1" velocity="20" lower="-1.570796326794896558" upper="1.570796326794896558" />
    <joint_properties friction="0.0" />
  </joint>

  <joint name="left_ank_roll" type="revolute">
    <origin xyz="1.9984014443252817728e-15 0.0015000000000042093377 -0.014599999999997269676" rpy="-1.5707963267950535435 -1.5707963267944073937 0" />
    <parent link="ank_pitch_link" />
    <child link="ank_roll_link" />
    <axis xyz="0 0 1" />
    <limit effort="1" velocity="20" lower="-0.785398163397448279" upper="0.785398163397448279" />
    <joint_properties friction="0.0" />
  </joint>

  <joint name="left_ank_pitch" type="revolute">
    <origin xyz="7.2631635415802528961e-19 -0.099999999999999977796 -0.0061999999999999989148" rpy="-3.1415926535897922278 -4.216693940517171266e-15 -1.5707963267948972241" />
    <parent link="left_calf_link" />
    <child link="ank_pitch_link" />
    <axis xyz="0 0 1" />
    <limit effort="1" velocity="20" lower="-0.785398163397448279" upper="0.785398163397448279" />
    <joint_properties friction="0.0" />
  </joint>

  <link name="ball_joint_container">
    <visual>
      <origin xyz="0 0 0" rpy="0 -0 0" />
      <geometry>
        <mesh filename="../assemblies/left_3R+RH5_leg/meshes/left_ball_joint_container_visual.stl" />
      </geometry>
      <material name="ball_joint_container_material">
        <color rgba="0.61568627450980395466 0.81176470588235294379 0.92941176470588238168 1.0" />
      </material>
    </visual>
    <inertial>
      <origin xyz="7.4111083336643258052e-18 -2.7877151006475832249e-17 -0.0097125341669083431473" rpy="0 0 0" />
      <mass value="4.803735642533054869e-05" />
      <inertia ixx="7.1865480628741666366e-10" ixy="-1.5334131096366129387e-26" ixz="3.7095034000073398816e-39" iyy="8.475420427718555978e-10" iyz="-7.5565609735293539879e-40" izz="1.8625314111651911712e-10" />
    </inertial>
  </link>

  <link name="ball_joint_ball">
    <visual>
      <origin xyz="0 0 0" rpy="0 -0 0" />
      <geometry>
        <mesh filename="../assemblies/left_3R+RH5_leg/meshes/left_ball_joint_ball_visual.stl" />
      </geometry>
      <material name="ball_joint_ball_material">
        <color rgba="0.3291302810242056065 0.44310466418644928188 0.69204871161977121741 1.0" />
      </material>
    </visual>
    <inertial>
      <origin xyz="6.1268384324663097933e-18 -0.0010308669810016606212 -4.4723473307868694828e-18" rpy="0 0 0" />
      <mass value="4.4053796295264630609e-05" />
      <inertia ixx="3.1285011349693058002e-10" ixy="5.4808644628151858982e-25" ixz="3.2739550940849536208e-26" iyy="6.2569568612795217385e-11" iyz="6.803221837785697648e-25" izz="3.1285321460376043917e-10" />
    </inertial>
  </link>

  <link name="12lf">
    <visual>
      <origin xyz="0 0 0" rpy="0 -0 0" />
      <geometry>
        <mesh filename="../assemblies/left_3R+RH5_leg/meshes/left_12lf_visual.stl" />
      </geometry>
      <material name="12lf_material">
        <color rgba="0.62004392100736027693 0.58836684613512635345 0.49897069021535678246 1.0" />
      </material>
    </visual>
    <inertial>
      <origin xyz="0.0049084207243745873669 -0.00013802439943561456729 -0.029947003577164808819" rpy="0 0 0" />
      <mass value="0.044782197696050352054" />
      <inertia ixx="1.5260128421325961452e-05" ixy="2.2955773686971514473e-08" ixz="-8.1364204004176638767e-08" iyy="1.8188469778967502911e-05" iyz="-5.554224084312636419e-08" izz="5.1496273901766125545e-06" />
    </inertial>
  </link>

  <link name="12lf_rod">
    <visual>
      <origin xyz="0 0 0" rpy="0 -0 0" />
      <geometry>
        <mesh filename="../assemblies/left_3R+RH5_leg/meshes/left_12lf_rod_visual.stl" />
      </geometry>
      <material name="12lf_rod_material">
        <color rgba="0.80250260812861884396 0.89340612183512713163 0.94491811293548189088 1.0" />
      </material>
    </visual>
    <inertial>
      <origin xyz="-6.3222084031083288386e-07 4.6933255323597298085e-07 -0.012893387334327275143" rpy="0 0 0" />
      <mass value="0.0025088292483592140175" />
      <inertia ixx="2.6944521128629799589e-07" ixy="7.138957015453196735e-15" ixz="1.3562243131778639665e-11" iyy="2.6944520001686344585e-07" iyz="-1.0089988426776572116e-11" izz="1.7809843599861032107e-08" />
    </inertial>
  </link>

  <joint name="left_ank_act1" type="fixed">
    <origin xyz="2.2722093540906984632e-06 7.7021722333370234992e-16 -0.072660031604095037805" rpy="-3.1415926535896590011 8.173835939810196213e-14 -2.2021168238262767147" />
    <parent link="12lf" />
    <child link="12lf_rod" />
    <axis xyz="0 0 1" />
    <limit effort="1" velocity="20" lower="0" upper="0.040000000000000000833" />
    <joint_properties friction="0.0" />
  </joint>

  <joint name="left_ank_B31" type="fixed">
    <origin xyz="4.336808689942017736e-19 -0.0064387505004003808828 0" rpy="-1.5707963267948970021 0.1691344003409792629 1.2463746926904215167e-14" />
    <parent link="ball_joint_ball" />
    <child link="12lf" />
    <axis xyz="0 0 1" />
    <limit effort="1" velocity="20" lower="-0.785398163397448279" upper="0.785398163397448279" />
    <joint_properties friction="0.0" />
  </joint>

  <joint name="left_ank_B21" type="fixed">
    <origin xyz="6.9388939039072283776e-18 -2.7755575615628913511e-17 -0.01150000000000000154" rpy="1.570796326794896558 -1.4285697747625525356 1.5707963267948994446" />
    <parent link="ball_joint_container" />
    <child link="ball_joint_ball" />
    <axis xyz="0 0 1" />
    <limit effort="1" velocity="20" lower="-0.785398163397448279" upper="0.785398163397448279" />
    <joint_properties friction="0.0" />
  </joint>

  <joint name="left_ank_B11" type="fixed">
    <origin xyz="0.0080000000000000123096 -0.014999999999999985567 0.028299999999999790601" rpy="-1.5707963267948918951 1.4696360140379163273 1.570796326794891673" />
    <parent link="left_calf_link" />
    <child link="ball_joint_container" />
    <axis xyz="0 0 1" />
    <limit effort="1" velocity="20" lower="-0.785398163397448279" upper="0.785398163397448279" />
    <joint_properties friction="0.0" />
  </joint>

  <link name="ball_joint_container_2">
    <visual>
      <origin xyz="0 0 0" rpy="0 -0 0" />
      <geometry>
        <mesh filename="../assemblies/left_3R+RH5_leg/meshes/left_ball_joint_container_2_visual.stl" />
      </geometry>
      <material name="ball_joint_container_2_material">
        <color rgba="0.61568627450980395466 0.81176470588235294379 0.92941176470588238168 1.0" />
      </material>
    </visual>
    <inertial>
      <origin xyz="4.7221442975709136089e-19 -1.2157539084691628239e-19 -0.0097125341669083431473" rpy="0 0 0" />
      <mass value="4.803735642533054869e-05" />
      <inertia ixx="7.1865480628741645687e-10" ixy="5.1910092342469106746e-27" ixz="2.1073186093729025111e-39" iyy="8.4754204277185539101e-10" iyz="-1.0547311575958656898e-39" izz="1.8625314111651911712e-10" />
    </inertial>
  </link>

  <link name="ball_joint_ball_2">
    <visual>
      <origin xyz="0 0 0" rpy="0 -0 0" />
      <geometry>
        <mesh filename="../assemblies/left_3R+RH5_leg/meshes/left_ball_joint_ball_2_visual.stl" />
      </geometry>
      <material name="ball_joint_ball_2_material">
        <color rgba="0.3291302810242056065 0.44310466418644928188 0.69204871161977121741 1.0" />
      </material>
    </visual>
    <inertial>
      <origin xyz="-3.6765871463107604191e-18 -0.0010308669810016246257 3.0781075239625374772e-20" rpy="0 0 0" />
      <mass value="4.4053796295264630609e-05" />
      <inertia ixx="3.1285011349692427277e-10" ixy="2.7095523077383332723e-25" ixz="1.9231619516313110786e-25" iyy="6.2569568612795437105e-11" iyz="-1.9538987127058110521e-24" izz="3.1285321460375630327e-10" />
    </inertial>
  </link>

  <link name="12lf_2">
    <visual>
      <origin xyz="0 0 0" rpy="0 -0 0" />
      <geometry>
        <mesh filename="../assemblies/left_3R+RH5_leg/meshes/left_12lf_2_visual.stl" />
      </geometry>
      <material name="12lf_2_material">
        <color rgba="0.62004392100736005489 0.58836684613512635345 0.49897069021535678246 1.0" />
      </material>
    </visual>
    <inertial>
      <origin xyz="0.0049084207243679251614 -0.00013802439943822565139 -0.029947003577164819227" rpy="0 0 0" />
      <mass value="0.044782197696050352054" />
      <inertia ixx="1.5260128421326124082e-05" ixy="2.2955773686915329057e-08" ixz="-8.1364204006958678778e-08" iyy="1.8188469778969349442e-05" iyz="-5.5542240844436532254e-08" izz="5.1496273901783413488e-06" />
    </inertial>
  </link>

  <link name="12lf_rod_2">
    <visual>
      <origin xyz="0 0 0" rpy="0 -0 0" />
      <geometry>
        <mesh filename="../assemblies/left_3R+RH5_leg/meshes/left_12lf_rod_2_visual.stl" />
      </geometry>
      <material name="12lf_rod_2_material">
        <color rgba="0.80250260812861884396 0.89340612183512713163 0.94491811293548189088 1.0" />
      </material>
    </visual>
    <inertial>
      <origin xyz="-6.3222083685070858828e-07 4.6933255279040845137e-07 -0.012893387334328574451" rpy="0 0 0" />
      <mass value="0.0025088292483592140175" />
      <inertia ixx="2.6944521128622583927e-07" ixy="7.1389570263391490609e-15" ixz="1.3562243030126121768e-11" iyy="2.6944520001679128923e-07" iyz="-1.0089988413385311252e-11" izz="1.7809843599861008946e-08" />
    </inertial>
  </link>

  <joint name="left_ank_act2" type="fixed">
    <origin xyz="2.2722093490027545082e-06 -7.7229889150487451843e-15 -0.07266003047881974819" rpy="-3.1415926535895000171 4.7493922909940523358e-14 -2.2021168238262776029" />
    <parent link="12lf_2" />
    <child link="12lf_rod_2" />
    <axis xyz="0 0 1" />
    <limit effort="1" velocity="20" lower="0" upper="0.040000000000000000833" />
    <joint_properties friction="0.0" />
  </joint>

  <joint name="left_ank_B32" type="fixed">
    <origin xyz="-2.4286128663675299322e-17 -0.0064387505004003808828 0" rpy="-1.570796326794896558 -0.17993145005786467805 5.6818279199863494045e-15" />
    <parent link="ball_joint_ball_2" />
    <child link="12lf_2" />
    <axis xyz="0 0 1" />
    <limit effort="1" velocity="20" lower="-0.785398163397448279" upper="0.785398163397448279" />
    <joint_properties friction="0.0" />
  </joint>

  <joint name="left_ank_B22" type="fixed">
    <origin xyz="0 0 -0.01150000000000000154" rpy="1.5707963267949021091 -1.4285463212680715728 -1.5707963267948938935" />
    <parent link="ball_joint_container_2" />
    <child link="ball_joint_ball_2" />
    <axis xyz="0 0 1" />
    <limit effort="1" velocity="20" lower="-0.785398163397448279" upper="0.785398163397448279" />
    <joint_properties friction="0.0" />
  </joint>

  <joint name="left_ank_B12" type="fixed">
    <origin xyz="0.0080000000000000001665 -0.014999999999999985567 -0.011500000000000003275" rpy="-1.5707963267949205388 -1.469756662182277962 1.5707963267949025532" />
    <parent link="left_calf_link" />
    <child link="ball_joint_container_2" />
    <axis xyz="0 0 1" />
    <limit effort="1" velocity="20" lower="-0.785398163397448279" upper="0.785398163397448279" />
    <joint_properties friction="0.0" />
  </joint>

  <joint name="left_knee" type="revolute">
    <origin xyz="-6.5473275179360459098e-15 0.096000000000000071387 0.027400000000000535039" rpy="-3.141592653589783346 1.4838131564395688657e-16 6.5779908238917364858e-16" />
    <parent link="left_hip_pitch_link" />
    <child link="left_calf_link" />
    <axis xyz="0 0 1" />
    <limit effort="1" velocity="20" lower="0" upper="1.570796326794896558" />
    <joint_properties friction="0.0" />
  </joint>

  <joint name="left_hip_pitch" type="revolute">
    <origin xyz="-0.024000000716154958752 -0.019000000152441291756 -0.019000000152448955765" rpy="-1.5707963267944653474 1.5707963267948226171 0" />
    <parent link="hip_roll_link" />
    <child link="left_hip_pitch_link" />
    <axis xyz="0 0 1" />
    <limit effort="1" velocity="20" lower="-1.570796326794896558" upper="1.570796326794896558" />
    <joint_properties friction="0.0" />
  </joint>

  <joint name="left_hip_roll" type="revolute">
    <origin xyz="0.01900000000000030137 -3.3624037938346747648e-18 -0.026000000000000279832" rpy="3.141592653589793116 -1.570796326794573039 0" />
    <parent link="hip_yaw_link" />
    <child link="hip_roll_link" />
    <axis xyz="0 0 1" />
    <limit effort="1" velocity="20" lower="-0.785398163397448279" upper="1.570796326794896558" />
    <joint_properties friction="0.0" />
  </joint>


  <link name="hip_yaw_link_2">
    <visual>
      <origin xyz="0 0 0" rpy="0 -0 0" />
      <geometry>
        <mesh filename="../assemblies/right_3R+RH5_leg/meshes/right_hip_yaw_link_visual.stl" />
      </geometry>
      <material name="hip_yaw_link_material">
        <color rgba="0.61568627450980395466 0.81176470588235294379 0.9294117647058824927 1.0" />
      </material>
    </visual>
    <inertial>
      <origin xyz="-4.3187888856399974121e-19 -2.3813308128726633736e-19 -0.0098390489054829086829" rpy="0 0 0" />
      <mass value="0.0090258837370979193293" />
      <inertia ixx="1.3230458239085876461e-06" ixy="-6.477854591907985348e-49" ixz="1.7322911775161985632e-33" iyy="3.8408510960330533338e-06" iyz="-1.4482241779965779082e-32" izz="3.8721396285793077728e-06" />
    </inertial>
  </link>

  <link name="hip_roll_link_2">
    <visual>
      <origin xyz="0 0 0" rpy="0 -0 0" />
      <geometry>
        <mesh filename="../assemblies/right_3R+RH5_leg/meshes/right_hip_roll_link_visual.stl" />
      </geometry>
      <material name="hip_roll_link_material">
        <color rgba="0.95018735644455853961 0.70678927200428420807 0.061612079402596685307 1.0" />
      </material>
    </visual>
    <collision>
      <origin xyz="0 0 0" rpy="0 -0 0" />
      <geometry>
        <mesh filename="collisions/right_hip_roll_link_collision.stl" />
      </geometry>
    </collision>
    <inertial>
      <origin xyz="0.01200015077588615503 -0.0004958881614117356413 -0.019495980755502469173" rpy="0 0 0" />
      <mass value="0.09801239148352869357" />
      <inertia ixx="2.0221748766307069722e-05" ixy="4.1552068245377294392e-08" ixz="-4.1225592185578874049e-08" iyy="2.7358099958307281437e-05" iyz="5.09357317523834832e-07" izz="2.735806952472418844e-05" />
    </inertial>
  </link>

  <link name="right_hip_pitch_link">
    <visual>
      <origin xyz="0 0 0" rpy="0 -0 0" />
      <geometry>
        <mesh filename="../assemblies/right_3R+RH5_leg/meshes/right_hip_pitch_link_visual.stl" />
      </geometry>
      <material name="right_hip_pitch_link_material">
        <color rgba="0.61653813877621499451 0.80729241848369426293 0.92174498630818169076 1.0" />
      </material>
    </visual>
    <collision>
      <origin xyz="0 0 0" rpy="0 -0 0" />
      <geometry>
        <mesh filename="collisions/right_hip_pitch_link_collision.stl" />
      </geometry>
    </collision>
    <inertial>
      <origin xyz="-6.256302869060054487e-05 0.052916501770471441324 0.014786698935570370336" rpy="0 0 0" />
      <mass value="0.093882153558663708481" />
      <inertia ixx="6.2803220478972943868e-05" ixy="-1.5188855895177002946e-07" ixz="8.5219684082544667618e-08" iyy="2.1718316663094208762e-05" iyz="-1.5156823286823309952e-06" izz="6.2508415648811422238e-05" />
    </inertial>
  </link>

  <link name="right_calf_link">
    <visual>
      <origin xyz="0 0 0" rpy="0 -0 0" />
      <geometry>
        <mesh filename="../assemblies/right_3R+RH5_leg/meshes/right_calf_link_visual.stl" />
      </geometry>
      <material name="right_calf_link_material">
        <color rgba="0.5539724769354649192 0.73161364570947462482 0.87715709724734280961 1.0" />
      </material>
    </visual>
    <collision>
      <origin xyz="0 0 0" rpy="0 -0 0" />
      <geometry>
        <mesh filename="collisions/right_calf_link_collision.stl" />
      </geometry>
    </collision>
    <inertial>
      <origin xyz="-0.0039136048281023004883 0.043639997035758562594 0.0081848996608062715014" rpy="0 0 0" />
      <mass value="0.016290630569901022595" />
      <inertia ixx="1.5543964735761997022e-05" ixy="2.1605989306079570978e-07" ixz="7.0519548982942639765e-09" iyy="1.9364566813417137318e-06" iyz="-1.9645570089551623241e-08" izz="1.4807205615850149198e-05" />
    </inertial>
  </link>

  <link name="ank_pitch_link_2">
    <visual>
      <origin xyz="0 0 0" rpy="0 -0 0" />
      <geometry>
        <mesh filename="../assemblies/right_3R+RH5_leg/meshes/right_ank_pitch_link_visual.stl" />
      </geometry>
      <material name="ank_pitch_link_material">
        <color rgba="0.63189161126160275916 0.72668668793540891482 0.78356373393969258601 1.0" />
      </material>
    </visual>
    <inertial>
      <origin xyz="4.0269686143543419549e-08 0.00059528282566766936405 -0.014599922383890028693" rpy="0 0 0" />
      <mass value="0.0042238381753791605713" />
      <inertia ixx="4.3705254067391478023e-07" ixy="1.6834347265698873017e-13" ixz="1.6428822909209008145e-12" iyy="3.9782741364655564948e-07" iyz="2.0919209909886491784e-14" izz="8.8858574534525996147e-08" />
    </inertial>
  </link>

  <link name="ank_roll_link_2">
    <visual>
      <origin xyz="0 0 0" rpy="0 -0 0" />
      <geometry>
        <mesh filename="../assemblies/right_3R+RH5_leg/meshes/right_ank_roll_link_visual.stl" />
      </geometry>
      <material name="ank_roll_link_material">
        <color rgba="0.61568627450980395466 0.81176470588235294379 0.92941176470588238168 1.0" />
      </material>
    </visual>
    <collision>
      <origin xyz="0 0 0" rpy="0 -0 0" />
      <geometry>
        <mesh filename="collisions/right_ank_roll_link_collision.stl" />
      </geometry>
    </collision>
    <inertial>
      <origin xyz="-6.3661537440592166956e-10 0.02724010231635349763 -0.005616985255146218943" rpy="0 0 0" />
      <mass value="0.013844478784760248444" />
      <inertia ixx="1.0150902309235183241e-05" ixy="6.8603275784607887557e-14" ixz="-3.2605548017928885523e-13" iyy="8.6636116663432619165e-06" iyz="-7.8151778926548754781e-07" izz="2.8991570356470071948e-06" />
    </inertial>
  </link>

  <link name="ank_rr_link_3">
    <visual>
      <origin xyz="0 0 0" rpy="0 -0 0" />
      <geometry>
        <mesh filename="../assemblies/right_3R+RH5_leg/meshes/right_ank_rr_link_visual.stl" />
      </geometry>
      <material name="ank_rr_link_material">
        <color rgba="0.61568627450980395466 0.81176470588235294379 0.92941176470588238168 1.0" />
      </material>
    </visual>
    <inertial>
      <origin xyz="3.4593503690054026834e-05 -0.0062999445222072132655 7.1649567931648254673e-18" rpy="0 0 0" />
      <mass value="0.00044289790445047673732" />
      <inertia ixx="9.0894755004835256766e-09" ixy="5.6689994077039605233e-11" ixz="-1.0879024115049109618e-14" iyy="8.3785129146959905585e-09" iyz="-4.8234349692160675239e-32" izz="1.3107013728801488166e-08" />
    </inertial>
  </link>

  <link name="12lf_rod_end_3">
    <visual>
      <origin xyz="0 0 0" rpy="0 -0 0" />
      <geometry>
        <mesh filename="../assemblies/right_3R+RH5_leg/meshes/right_12lf_rod_end_visual.stl" />
      </geometry>
      <material name="12lf_rod_end_material">
        <color rgba="0.92771758928836534075 0.61049283053223002415 0.2184765849058516729 1.0" />
      </material>
    </visual>
    <inertial>
      <origin xyz="-4.4735190985970578902e-11 -0.0038422185938245443336 6.4384187209450280813e-06" rpy="0 0 0" />
      <mass value="0.00085420491177815905965" />
      <inertia ixx="1.1840985264406790703e-08" ixy="2.0225978084394166068e-16" ixz="-9.2606420003034406474e-16" iyy="3.3549621576797135787e-09" iyz="7.4535631381808631384e-12" izz="1.2703522254419991506e-08" />
    </inertial>
  </link>

  <joint name="right_ank_R21" type="fixed">
    <origin xyz="0 -0.010000000000000008882 1.3877787807814456755e-17" rpy="-1.570796326794896558 -1.4285697747630956567 1.5707963267948958919" />
    <parent link="ank_rr_link_3" />
    <child link="12lf_rod_end_3" />
    <axis xyz="0 0 1" />
    <limit effort="1" velocity="20" lower="-1.570796326794896558" upper="1.570796326794896558" />
    <joint_properties friction="0.0" />
  </joint>

  <joint name="right_ank_R11" type="fixed">
    <origin xyz="-0.0099999999999999984734 0.012500000000000011102 -0.033599999999999997924" rpy="-2.3897964054427488116e-14 -3.8273675914490832965e-16 -0.10116031275657462463" />
    <parent link="ank_roll_link_2" />
    <child link="ank_rr_link_3" />
    <axis xyz="0 0 1" />
    <limit effort="1" velocity="20" lower="-1.570796326794896558" upper="1.570796326794896558" />
    <joint_properties friction="0.0" />
  </joint>

  <link name="ank_rr_link_4">
    <visual>
      <origin xyz="0 0 0" rpy="0 -0 0" />
      <geometry>
        <mesh filename="../assemblies/right_3R+RH5_leg/meshes/right_ank_rr_link_2_visual.stl" />
      </geometry>
      <material name="ank_rr_link_2_material">
        <color rgba="0.61568627450980395466 0.81176470588235294379 0.92941176470588238168 1.0" />
      </material>
    </visual>
    <inertial>
      <origin xyz="3.4593503690053884533e-05 -0.0062999445222072123982 2.2606288925624816828e-19" rpy="0 0 0" />
      <mass value="0.00044289790445047673732" />
      <inertia ixx="9.0894755004835256766e-09" ixy="5.6689994077039669856e-11" ixz="-1.0879024115049109618e-14" iyy="8.3785129146959872498e-09" iyz="7.5081772743372048851e-32" izz="1.3107013728801488166e-08" />
    </inertial>
  </link>

  <link name="12lf_rod_end_4">
    <visual>
      <origin xyz="0 0 0" rpy="0 -0 0" />
      <geometry>
        <mesh filename="../assemblies/right_3R+RH5_leg/meshes/right_12lf_rod_end_2_visual.stl" />
      </geometry>
      <material name="12lf_rod_end_2_material">
        <color rgba="0.92771758928836534075 0.61049283053223013518 0.2184765849058516729 1.0" />
      </material>
    </visual>
    <inertial>
      <origin xyz="-4.4735193475670595212e-11 -0.0038422185938245447673 6.4384187209447282316e-06" rpy="0 0 0" />
      <mass value="0.00085420491177815905965" />
      <inertia ixx="1.1840985264406785739e-08" ixy="2.0225978169827040359e-16" ixz="-9.2606419985584231327e-16" iyy="3.3549621576797189554e-09" iyz="7.4535631381809956166e-12" izz="1.2703522254419981579e-08" />
    </inertial>
  </link>

  <joint name="right_ank_R22" type="fixed">
    <origin xyz="-6.9388939039072283776e-18 -0.0099999999999999811262 1.3877787807814456755e-17" rpy="1.570796326794896558 -1.428546321268451269 -1.570796326794896558" />
    <parent link="ank_rr_link_4" />
    <child link="12lf_rod_end_4" />
    <axis xyz="0 0 1" />
    <limit effort="1" velocity="20" lower="-1.570796326794896558" upper="1.570796326794896558" />
    <joint_properties friction="0.0" />
  </joint>

  <joint name="right_ank_R12" type="fixed">
    <origin xyz="0.010000000000000003678 0.012499999999999955591 -0.033600000000000004863" rpy="-3.1415926535897709115 -4.1620274661327994973e-15 -3.0405529889776490293" />
    <parent link="ank_roll_link_2" />
    <child link="ank_rr_link_4" />
    <axis xyz="0 0 1" />
    <limit effort="1" velocity="20" lower="-1.570796326794896558" upper="1.570796326794896558" />
    <joint_properties friction="0.0" />
  </joint>

  <joint name="right_ank_roll" type="revolute">
    <origin xyz="1.7486012637846215512e-15 0.001500000000009214015 -0.014599999999994360544" rpy="-1.5707963267952413933 1.570796326794632769 0" />
    <parent link="ank_pitch_link_2" />
    <child link="ank_roll_link_2" />
    <axis xyz="0 0 1" />
    <limit effort="1" velocity="20" lower="-0.785398163397448279" upper="0.785398163397448279" />
    <joint_properties friction="0.0" />
  </joint>

  <joint name="right_ank_pitch" type="revolute">
    <origin xyz="1.0774845611827788694e-18 0.10000000000000003331 -0.0062000000000000006495" rpy="3.141592653589783346 -6.5431213406603904361e-15 -1.57079632679491632" />
    <parent link="right_calf_link" />
    <child link="ank_pitch_link_2" />
    <axis xyz="0 0 1" />
    <limit effort="1" velocity="20" lower="-0.785398163397448279" upper="0.785398163397448279" />
    <joint_properties friction="0.0" />
  </joint>

  <link name="ball_joint_container_3">
    <visual>
      <origin xyz="0 0 0" rpy="0 -0 0" />
      <geometry>
        <mesh filename="../assemblies/right_3R+RH5_leg/meshes/right_ball_joint_container_visual.stl" />
      </geometry>
      <material name="ball_joint_container_material">
        <color rgba="0.61568627450980395466 0.81176470588235294379 0.92941176470588238168 1.0" />
      </material>
    </visual>
    <inertial>
      <origin xyz="7.4111083336643103978e-18 -1.2157539084690571385e-19 -0.0097125341669083431473" rpy="0 0 0" />
      <mass value="4.803735642533054869e-05" />
      <inertia ixx="7.1865480628741707725e-10" ixy="9.6933317168373938153e-27" ixz="-9.9239391302425895974e-39" iyy="8.475420427718555978e-10" iyz="6.0361493199448903822e-39" izz="1.8625314111651911712e-10" />
    </inertial>
  </link>

  <link name="ball_joint_ball_3">
    <visual>
      <origin xyz="0 0 0" rpy="0 -0 0" />
      <geometry>
        <mesh filename="../assemblies/right_3R+RH5_leg/meshes/right_ball_joint_ball_visual.stl" />
      </geometry>
      <material name="ball_joint_ball_material">
        <color rgba="0.3291302810242056065 0.44310466418644928188 0.69204871161977121741 1.0" />
      </material>
    </visual>
    <inertial>
      <origin xyz="2.102705507952400475e-18 -0.0010308669810015988217 -8.5379702467387550553e-19" rpy="0 0 0" />
      <mass value="4.4053796295264630609e-05" />
      <inertia ixx="3.128501134969185859e-10" ixy="-2.7497498577527635089e-25" ixz="-2.486452261547247297e-25" iyy="6.2569568612795488804e-11" iyz="1.7524664799694679158e-25" izz="3.1285321460376033577e-10" />
    </inertial>
  </link>

  <link name="12lf_3">
    <visual>
      <origin xyz="0 0 0" rpy="0 -0 0" />
      <geometry>
        <mesh filename="../assemblies/right_3R+RH5_leg/meshes/right_12lf_visual.stl" />
      </geometry>
      <material name="12lf_material">
        <color rgba="0.62004392100736016591 0.58836684613512635345 0.49897069021535672695 1.0" />
      </material>
    </visual>
    <inertial>
      <origin xyz="0.0049084207243677048516 -0.00013802439943466461645 -0.029947003577151735942" rpy="0 0 0" />
      <mass value="0.044782197696050352054" />
      <inertia ixx="1.5260128421316017285e-05" ixy="2.2955773686542551842e-08" ixz="-8.1364204007397759482e-08" iyy="1.818846977895560718e-05" iyz="-5.5542240842657299843e-08" izz="5.1496273901745983102e-06" />
    </inertial>
  </link>

  <link name="12lf_rod_3">
    <visual>
      <origin xyz="0 0 0" rpy="0 -0 0" />
      <geometry>
        <mesh filename="../assemblies/right_3R+RH5_leg/meshes/right_12lf_rod_visual.stl" />
      </geometry>
      <material name="12lf_rod_material">
        <color rgba="0.80250260812861884396 0.89340612183512713163 0.94491811293548189088 1.0" />
      </material>
    </visual>
    <inertial>
      <origin xyz="-6.3222084064713895111e-07 4.6933255154741661215e-07 -0.01289338733432986335" rpy="0 0 0" />
      <mass value="0.0025088292483592140175" />
      <inertia ixx="2.6944521128615405323e-07" ixy="7.1389570792316811103e-15" ixz="1.3562243140343849339e-11" iyy="2.6944520001671950319e-07" iyz="-1.0089988380127149553e-11" izz="1.7809843599861101591e-08" />
    </inertial>
  </link>

  <joint name="right_ank_act1" type="fixed">
    <origin xyz="2.2722093427646888886e-06 1.7902346272080649214e-15 -0.072660031604104419189" rpy="-3.1415926535897806815 9.7899118131350707255e-15 -2.2021168238260933059" />
    <parent link="12lf_3" />
    <child link="12lf_rod_3" />
    <axis xyz="0 0 1" />
    <limit effort="1" velocity="20" lower="0" upper="0.040000000000000000833" />
    <joint_properties friction="0.0" />
  </joint>

  <joint name="right_ank_B31" type="fixed">
    <origin xyz="9.1072982488782372457e-18 -0.0064387505004003808828 0" rpy="-1.5707963267948961139 0.16913440034171131621 -1.7599215475487529123e-15" />
    <parent link="ball_joint_ball_3" />
    <child link="12lf_3" />
    <axis xyz="0 0 1" />
    <limit effort="1" velocity="20" lower="-0.785398163397448279" upper="0.785398163397448279" />
    <joint_properties friction="0.0" />
  </joint>

  <joint name="right_ank_B21" type="fixed">
    <origin xyz="6.9388939039072283776e-18 0 -0.01150000000000000154" rpy="1.570796326794896558 -1.4285697747626475707 1.5707963267948843455" />
    <parent link="ball_joint_container_3" />
    <child link="ball_joint_ball_3" />
    <axis xyz="0 0 1" />
    <limit effort="1" velocity="20" lower="-0.785398163397448279" upper="0.785398163397448279" />
    <joint_properties friction="0.0" />
  </joint>

  <joint name="right_ank_B11" type="fixed">
    <origin xyz="0.008000000000000003636 0.015000000000000013323 -0.011499999999999998071" rpy="1.570796326794896558 -1.469636014037899896 -1.5707963267948905628" />
    <parent link="right_calf_link" />
    <child link="ball_joint_container_3" />
    <axis xyz="0 0 1" />
    <limit effort="1" velocity="20" lower="-0.785398163397448279" upper="0.785398163397448279" />
    <joint_properties friction="0.0" />
  </joint>

  <link name="ball_joint_container_4">
    <visual>
      <origin xyz="0 0 0" rpy="0 -0 0" />
      <geometry>
        <mesh filename="../assemblies/right_3R+RH5_leg/meshes/right_ball_joint_container_2_visual.stl" />
      </geometry>
      <material name="ball_joint_container_2_material">
        <color rgba="0.61568627450980395466 0.81176470588235294379 0.92941176470588238168 1.0" />
      </material>
    </visual>
    <inertial>
      <origin xyz="4.7221442975708616088e-19 -2.7877151006475832249e-17 -0.0097125341669083414126" rpy="0 0 0" />
      <mass value="4.803735642533054869e-05" />
      <inertia ixx="7.1865480628741707725e-10" ixy="-2.4050570183801507371e-26" ixz="-2.0651419609287427911e-38" iyy="8.475420427718555978e-10" iyz="-2.6992806497327300279e-39" izz="1.8625314111651911712e-10" />
    </inertial>
  </link>

  <link name="ball_joint_ball_4">
    <visual>
      <origin xyz="0 0 0" rpy="0 -0 0" />
      <geometry>
        <mesh filename="../assemblies/right_3R+RH5_leg/meshes/right_ball_joint_ball_2_visual.stl" />
      </geometry>
      <material name="ball_joint_ball_2_material">
        <color rgba="0.3291302810242056065 0.44310466418644928188 0.69204871161977121741 1.0" />
      </material>
    </visual>
    <inertial>
      <origin xyz="-4.7219599415428803594e-18 -0.0010308669810015738851 -1.2233621409697471745e-17" rpy="0 0 0" />
      <mass value="4.4053796295264630609e-05" />
      <inertia ixx="3.1285011349692256671e-10" ixy="-6.3066245504998141573e-28" ixz="7.7510099720051280566e-26" iyy="6.2569568612795359557e-11" iyz="-3.6168133526406630072e-25" izz="3.1285321460375961199e-10" />
    </inertial>
  </link>

  <link name="12lf_4">
    <visual>
      <origin xyz="0 0 0" rpy="0 -0 0" />
      <geometry>
        <mesh filename="../assemblies/right_3R+RH5_leg/meshes/right_12lf_2_visual.stl" />
      </geometry>
      <material name="12lf_2_material">
        <color rgba="0.62004392100736027693 0.58836684613512624242 0.49897069021535683797 1.0" />
      </material>
    </visual>
    <inertial>
      <origin xyz="0.0049084207243643221408 -0.00013802439943700681841 -0.029947003577147596892" rpy="0 0 0" />
      <mass value="0.044782197696050358993" />
      <inertia ixx="1.5260128421312900204e-05" ixy="2.2955773686753228127e-08" ixz="-8.1364204008841844778e-08" iyy="1.818846977895196155e-05" iyz="-5.5542240843702287037e-08" izz="5.149627390174079079e-06" />
    </inertial>
  </link>

  <link name="12lf_rod_4">
    <visual>
      <origin xyz="0 0 0" rpy="0 -0 0" />
      <geometry>
        <mesh filename="../assemblies/right_3R+RH5_leg/meshes/right_12lf_rod_2_visual.stl" />
      </geometry>
      <material name="12lf_rod_2_material">
        <color rgba="0.80250260812861884396 0.89340612183512713163 0.94491811293548189088 1.0" />
      </material>
    </visual>
    <inertial>
      <origin xyz="-6.3222084136853753641e-07 4.6933255068747964734e-07 -0.012893387334332108082" rpy="0 0 0" />
      <mass value="0.0025088292483592140175" />
      <inertia ixx="2.6944521128602990996e-07" ixy="7.1389569787271430483e-15" ixz="1.356224315943006939e-11" iyy="2.6944520001659541286e-07" iyz="-1.0089988354535278384e-11" izz="1.7809843599861018872e-08" />
    </inertial>
  </link>

  <joint name="right_ank_act2" type="fixed">
    <origin xyz="2.2722093383654301535e-06 -2.5118795932144166727e-15 -0.07266003047881591792" rpy="3.1415926535897926719 5.7157557368585280826e-16 -2.2021168238262842642" />
    <parent link="12lf_4" />
    <child link="12lf_rod_4" />
    <axis xyz="0 0 1" />
    <limit effort="1" velocity="20" lower="0" upper="0.040000000000000000833" />
    <joint_properties friction="0.0" />
  </joint>

  <joint name="right_ank_B32" type="fixed">
    <origin xyz="-8.6736173798840354721e-18 -0.0064387505004003531273 -1.3877787807814456755e-17" rpy="-1.5707963267948854558 -0.17993145005747521181 -6.9806032607149013267e-15" />
    <parent link="ball_joint_ball_4" />
    <child link="12lf_4" />
    <axis xyz="0 0 1" />
    <limit effort="1" velocity="20" lower="-0.785398163397448279" upper="0.785398163397448279" />
    <joint_properties friction="0.0" />
  </joint>

  <joint name="right_ank_B22" type="fixed">
    <origin xyz="0 0 -0.011499999999999999806" rpy="1.57079632679489678 -1.4285463212679265776 1.5707963267948943376" />
    <parent link="ball_joint_container_4" />
    <child link="ball_joint_ball_4" />
    <axis xyz="0 0 1" />
    <limit effort="1" velocity="20" lower="-0.785398163397448279" upper="0.785398163397448279" />
    <joint_properties friction="0.0" />
  </joint>

  <joint name="right_ank_B12" type="fixed">
    <origin xyz="0.0080000000000000365957 0.014999999999999985567 0.028300000000000158362" rpy="-1.570796326794896558 -1.469756662182680973 1.570796326794891451" />
    <parent link="right_calf_link" />
    <child link="ball_joint_container_4" />
    <axis xyz="0 0 1" />
    <limit effort="1" velocity="20" lower="-0.785398163397448279" upper="0.785398163397448279" />
    <joint_properties friction="0.0" />
  </joint>

  <joint name="right_knee" type="revolute">
    <origin xyz="-2.892603788276459435e-15 0.095999999999999294231 0.027400000000000382383" rpy="-3.141592653589788231 -2.6961419186663855904e-16 -3.141592653589793116" />
    <parent link="right_hip_pitch_link" />
    <child link="right_calf_link" />
    <axis xyz="0 0 1" />
    <limit effort="1" velocity="20" lower="-1.570796326794896558" upper="0" />
    <joint_properties friction="0.0" />
  </joint>

  <joint name="right_hip_pitch" type="revolute">
    <origin xyz="0.024000000358073002305 -0.019000000000011920548 -0.018999999847560570393" rpy="-1.5707963267950890707 -1.5707963267946420949 0" />
    <parent link="hip_roll_link_2" />
    <child link="right_hip_pitch_link" />
    <axis xyz="0 0 1" />
    <limit effort="1" velocity="20" lower="-1.570796326794896558" upper="1.570796326794896558" />
    <joint_properties friction="0.0" />
  </joint>

  <joint name="right_hip_roll" type="revolute">
    <origin xyz="0.018999999999999881567 -3.3500438889873688288e-18 -0.026000000000000002276" rpy="1.4130847605241333966e-30 1.5707963267948645836 0" />
    <parent link="hip_yaw_link_2" />
    <child link="hip_roll_link_2" />
    <axis xyz="0 0 1" />
    <limit effort="1" velocity="20" lower="-1.570796326794896558" upper="0.785398163397448279" />
    <joint_properties friction="0.0" />
  </joint>


</robot>