<robot name="toddlerbot_OP3">
  <mujoco>
    <compiler strippath="false" balanceinertia="true" discardvisual="false" />
  </mujoco>
  <link name="torso">
    <visual>
      <origin xyz="0 0 0" rpy="0 -0 0" />
      <geometry>
        <mesh filename="../assemblies/toddlerbot/meshes/torso_visual.stl" />
      </geometry>
      <material name="torso_material">
        <color rgba="0.5756764758149645056 0.73345309646743483967 0.85630877307465791404 1.0" />
      </material>
    </visual>
    <inertial>
      <origin xyz="-0.0091211546187125406432 0.0036055430201103995727 0.074702081176469287138" rpy="0 0 0" />
      <mass value="0.60012685450989189384" />
      <inertia ixx="0.0016762683716637551828" ixy="-3.7956721963544869667e-05" ixz="-8.3172104272568887339e-05" iyy="0.0013163016250066178307" iyz="5.6371331396665507135e-05" izz="0.0012676048753457814025" />
    </inertial>
  </link>

  <link name="spur_1m_20t">
    <visual>
      <origin xyz="0 0 0" rpy="0 -0 0" />
      <geometry>
        <mesh filename="../assemblies/toddlerbot/meshes/spur_1m_20t_visual.stl" />
      </geometry>
      <material name="spur_1m_20t_material">
        <color rgba="0.64705882352941179736 0.64705882352941179736 0.64705882352941179736 1.0" />
      </material>
    </visual>
    <inertial>
      <origin xyz="-2.264600315585787176e-18 -7.587391431216789923e-18 0.0033745971730663147647" rpy="0 0 0" />
      <mass value="0.0015534950290892286448" />
      <inertia ixx="4.4726508287871812856e-08" ixy="2.6608965793107671434e-24" ixz="-4.0749910772758008994e-38" iyy="4.4726508287871779768e-08" iyz="-7.464720539392493928e-38" izz="7.9558906764902019844e-08" />
    </inertial>
  </link>

  <joint name="neck_yaw_drive" type="revolute">
    <origin xyz="-0.004999999999999517851 2.6555840535020396321e-18 0.121486510762817565" rpy="1.1318451824181020002e-14 2.6985403517595457696e-15 -5.3863140912757267331e-15" />
    <parent link="torso" />
    <child link="spur_1m_20t" />
    <axis xyz="0 0 1" />
    <limit effort="1" velocity="20" lower="-2.8797932657906435416" upper="2.8797932657906435416" />
    <joint_properties friction="0.0" />
  </joint>

  <link name="neck_yaw_link">
    <visual>
      <origin xyz="0 0 0" rpy="0 -0 0" />
      <geometry>
        <mesh filename="../assemblies/toddlerbot/meshes/neck_yaw_link_visual.stl" />
      </geometry>
      <material name="neck_yaw_link_material">
        <color rgba="0.33636252417476658616 0.48680769190259876034 0.74976123534949778993 1.0" />
      </material>
    </visual>
    <inertial>
      <origin xyz="2.7291286461005574991e-05 -0.00019798992283532067032 0.011527412037194510394" rpy="0 0 0" />
      <mass value="0.0085168305947458267796" />
      <inertia ixx="1.0407116999274246609e-06" ixy="2.4210150466101252425e-11" ixz="-4.7246803217895962011e-10" iyy="1.124000995411045041e-06" iyz="3.0834841754639543074e-08" izz="3.1587565167291430716e-07" />
    </inertial>
  </link>

  <link name="neck_pitch_link">
    <visual>
      <origin xyz="0 0 0" rpy="0 -0 0" />
      <geometry>
        <mesh filename="../assemblies/toddlerbot/meshes/neck_pitch_link_visual.stl" />
      </geometry>
      <material name="neck_pitch_link_material">
        <color rgba="0.74911126277760042846 0.80002799398726853752 0.87441258869524285391 1.0" />
      </material>
    </visual>
    <inertial>
      <origin xyz="-0.0034370497615720967989 0.032876793988991216688 -0.00036476492134677904145" rpy="0 0 0" />
      <mass value="0.11211553874797881847" />
      <inertia ixx="7.7015755459845837709e-05" ixy="-2.1757968319815265661e-06" ixz="-2.8732209413513131827e-06" iyy="6.3502636688153170732e-05" iyz="-1.2492352737634845265e-05" izz="2.8610002383974730313e-05" />
    </inertial>
  </link>

  <link name="spur_gear_(13_teeth)">
    <visual>
      <origin xyz="0 0 0" rpy="0 -0 0" />
      <geometry>
        <mesh filename="../assemblies/toddlerbot/meshes/spur_gear_(13_teeth)_visual.stl" />
      </geometry>
      <material name="spur_gear_(13_teeth)_material">
        <color rgba="0.64705882352941179736 0.64705882352941179736 0.64705882352941179736 1.0" />
      </material>
    </visual>
    <inertial>
      <origin xyz="9.1521555160253732313e-10 -5.4872578733911464024e-10 0.0092751511485596373902" rpy="0 0 0" />
      <mass value="0.00081469437497230865874" />
      <inertia ixx="2.0244841463618380872e-08" ixy="2.9781775007011560058e-15" ixz="-8.2976066071190312301e-15" iyy="2.0244839778533682582e-08" iyz="1.3142117785017221878e-15" izz="1.8905472907863310999e-08" />
    </inertial>
  </link>

  <joint name="neck_pitch_drive" type="revolute">
    <origin xyz="-6.9735883734267645195e-16 0.015649999999999053557 -0.0087999999999970532349" rpy="-1.1409718301987536487e-15 4.409645192886135633e-16 -1.5707963267948976682" />
    <parent link="neck_pitch_link" />
    <child link="spur_gear_(13_teeth)" />
    <axis xyz="0 0 1" />
    <limit effort="1" velocity="20" lower="-2.174948760177549012" upper="2.174948760177549012" />
    <joint_properties friction="0.0" />
  </joint>

  <joint name="neck_pitch_driven" type="revolute">
    <origin xyz="3.7499979510524639181e-10 -0.0051500000614751947903 0.027499999999999941158" rpy="1.5707963267948978903 -2.0825786444073518345e-16 3.141592653589793116" />
    <parent link="neck_yaw_link" />
    <child link="neck_pitch_link" />
    <axis xyz="0 0 1" />
    <limit effort="1" velocity="20" lower="-1.570796326794896558" upper="1.570796326794896558" />
    <joint_properties friction="0.0" />
  </joint>

  <joint name="neck_yaw_driven" type="revolute">
    <origin xyz="0.016000000000001235456 2.2310681558151314601e-17 0.12248651076281746874" rpy="-4.8668742840765556337e-16 -4.0649010562893427138e-15 3.141592653589793116" />
    <parent link="torso" />
    <child link="neck_yaw_link" />
    <axis xyz="0 0 1" />
    <limit effort="1" velocity="20" lower="-2.6179938779914944114" upper="2.6179938779914944114" />
    <joint_properties friction="0.0" />
  </joint>

  <link name="waist_gears">
    <visual>
      <origin xyz="0 0 0" rpy="0 -0 0" />
      <geometry>
        <mesh filename="../assemblies/toddlerbot/meshes/waist_gears_visual.stl" />
      </geometry>
      <material name="waist_gears_material">
        <color rgba="0.26285745258304310523 0.51761993404322359513 0.70089950218325269837 1.0" />
      </material>
    </visual>
    <inertial>
      <origin xyz="-2.9615196346148577302e-07 5.6324425198301108519e-08 -0.012591728437027502677" rpy="0 0 0" />
      <mass value="0.025874065810895640477" />
      <inertia ixx="1.5221462961926445333e-06" ixy="1.8766602079766916675e-11" ixz="4.0586927770605968901e-10" iyy="7.280142068668490794e-06" iyz="3.1229108550824058464e-12" izz="6.9639458993359299767e-06" />
    </inertial>
  </link>

  <link name="waist_link">
    <visual>
      <origin xyz="0 0 0" rpy="0 -0 0" />
      <geometry>
        <mesh filename="../assemblies/toddlerbot/meshes/waist_link_visual.stl" />
      </geometry>
      <material name="waist_link_material">
        <color rgba="0.63401200025306059249 0.68204699127249923674 0.6691019398503622595 1.0" />
      </material>
    </visual>
    <inertial>
      <origin xyz="-9.1086191337257426703e-07 0.026204483755308753679 -0.030190392008842579369" rpy="0 0 0" />
      <mass value="0.16631953490612461088" />
      <inertia ixx="6.8622997376114634803e-05" ixy="-6.1328048461882665927e-10" ixz="-3.6786792027265062734e-06" iyy="0.00020057117429216644823" iyz="-3.7255079147358398249e-06" izz="0.00015770127977213132457" />
    </inertial>
  </link>

  <link name="spiral_bevel_1m_14t_30deg">
    <visual>
      <origin xyz="0 0 0" rpy="0 -0 0" />
      <geometry>
        <mesh filename="../assemblies/toddlerbot/meshes/spiral_bevel_1m_14t_30deg_visual.stl" />
      </geometry>
      <material name="spiral_bevel_1m_14t_30deg_material">
        <color rgba="0.64705882352941179736 0.64705882352941179736 0.64705882352941179736 1.0" />
      </material>
    </visual>
    <inertial>
      <origin xyz="7.4971447279470481499e-10 7.1802237332913011122e-10 0.0066868955018979103766" rpy="0 0 0" />
      <mass value="0.00073261524436595492574" />
      <inertia ixx="1.3495056019478195011e-08" ixy="4.0596681656909248509e-17" ixz="8.599255017511676462e-16" iyy="1.3495056150237195634e-08" iyz="-6.7913008233741570648e-16" izz="1.4355986549816408408e-08" />
    </inertial>
  </link>

  <joint name="waist_act_1" type="revolute">
    <origin xyz="5.7457652915638341522e-17 0.019599999999999964673 -0.012750000000000025202" rpy="1.5707963267948954478 1.570796326794896336 0" />
    <parent link="waist_link" />
    <child link="spiral_bevel_1m_14t_30deg" />
    <axis xyz="0 0 1" />
    <limit effort="1" velocity="20" lower="-4.6774823953448034786" upper="4.6774823953448034786" />
    <joint_properties friction="0.0" />
  </joint>

  <link name="spiral_bevel_1m_14t_30deg_2">
    <visual>
      <origin xyz="0 0 0" rpy="0 -0 0" />
      <geometry>
        <mesh filename="../assemblies/toddlerbot/meshes/spiral_bevel_1m_14t_30deg_2_visual.stl" />
      </geometry>
      <material name="spiral_bevel_1m_14t_30deg_2_material">
        <color rgba="0.64705882352941179736 0.64705882352941179736 0.64705882352941179736 1.0" />
      </material>
    </visual>
    <inertial>
      <origin xyz="5.711425533905245544e-10 8.6684721906479195987e-10 0.0066868955018979190502" rpy="0 0 0" />
      <mass value="0.00073261524436595492574" />
      <inertia ixx="1.3495056008338566936e-08" ixy="8.2092443034011452773e-18" ixz="9.8948603423502891461e-16" iyy="1.3495056161376838597e-08" iyz="-4.7075144749766452119e-16" izz="1.43559865498164051e-08" />
    </inertial>
  </link>

  <joint name="waist_act_2" type="revolute">
    <origin xyz="4.2745485696894321379e-17 0.019600000000000013245 -0.032749999999999994393" rpy="1.5707963267948956698 1.3463968515392303882 6.7698458176426589005e-15" />
    <parent link="waist_link" />
    <child link="spiral_bevel_1m_14t_30deg_2" />
    <axis xyz="0 0 1" />
    <limit effort="1" velocity="20" lower="-4.6774823953448034786" upper="4.6774823953448034786" />
    <joint_properties friction="0.0" />
  </joint>

  <link name="spur_gear_19_teeth">
    <visual>
      <origin xyz="0 0 0" rpy="0 -0 0" />
      <geometry>
        <mesh filename="../assemblies/toddlerbot/meshes/spur_gear_19_teeth_visual.stl" />
      </geometry>
      <material name="spur_gear_19_teeth_material">
        <color rgba="0.61568627450980395466 0.81176470588235294379 0.92941176470588238168 1.0" />
      </material>
    </visual>
    <inertial>
      <origin xyz="-4.7403242595143773768e-08 1.5460070764038637399e-08 0.0045456071298370023803" rpy="0 0 0" />
      <mass value="0.0011084409433758843876" />
      <inertia ixx="2.9582691212226700665e-08" ixy="-2.8904821292895135249e-14" ixz="7.8892082291036886091e-14" iyy="2.9582612758414119977e-08" iyz="-2.5767358059768096423e-14" izz="4.6351510704080136144e-08" />
    </inertial>
  </link>

  <joint name="left_hip_yaw_drive" type="revolute">
    <origin xyz="-0.036999999999998457734 0.037100000000005961542 -0.03950000000000024325" rpy="-1.5707963267949545116 -4.8003070743589248247e-13 -3.5749181392930616155e-13" />
    <parent link="waist_link" />
    <child link="spur_gear_19_teeth" />
    <axis xyz="0 0 1" />
    <limit effort="1" velocity="20" lower="-1.7361433085627806516" upper="1.7361433085627806516" />
    <joint_properties friction="0.0" />
  </joint>

  <link name="spur_gear_21_teeth">
    <visual>
      <origin xyz="0 0 0" rpy="0 -0 0" />
      <geometry>
        <mesh filename="../assemblies/toddlerbot/meshes/spur_gear_21_teeth_visual.stl" />
      </geometry>
      <material name="spur_gear_21_teeth_material">
        <color rgba="0.61568627450980395466 0.81176470588235294379 0.92941176470588238168 1.0" />
      </material>
    </visual>
    <inertial>
      <origin xyz="-6.7030730388797144104e-12 1.7758939849553634854e-11 0.0024945285429905615648" rpy="0 0 0" />
      <mass value="0.0010185686142775147826" />
      <inertia ixx="3.2410681505051109819e-08" ixy="-5.0070048685720157271e-39" ixz="-1.6778767679075106483e-38" iyy="3.2410681506302329683e-08" iyz="-2.1489356052918171638e-38" izz="6.0614091765677406549e-08" />
    </inertial>
  </link>

  <joint name="left_leg_fixed" type="fixed">
    <origin xyz="0 0 0.004999999999999997502" rpy="3.1415926535897926719 -1.9428902930939016723e-16 -7.6327832942984196016e-16" />
    <parent link="spur_gear_21_teeth" />
    <child link="hip_yaw_link" />
    <axis xyz="0 0 1" />
    <limit effort="1" velocity="20" />
    <joint_properties friction="0.0" />
  </joint>

  <joint name="left_hip_yaw_driven" type="revolute">
    <origin xyz="-0.036999999999999998168 0.041100000000000011524 -0.019500000000000027728" rpy="-1.5707963267948947816 -1.570796326794896558 0" />
    <parent link="waist_link" />
    <child link="spur_gear_21_teeth" />
    <axis xyz="0 0 1" />
    <limit effort="1" velocity="20" lower="-1.570796326794896558" upper="1.570796326794896558" />
    <joint_properties friction="0.0" />
  </joint>

  <link name="spur_gear_19_teeth_2">
    <visual>
      <origin xyz="0 0 0" rpy="0 -0 0" />
      <geometry>
        <mesh filename="../assemblies/toddlerbot/meshes/spur_gear_19_teeth_2_visual.stl" />
      </geometry>
      <material name="spur_gear_19_teeth_2_material">
        <color rgba="0.61568627450980395466 0.81176470588235294379 0.92941176470588238168 1.0" />
      </material>
    </visual>
    <inertial>
      <origin xyz="-4.7403242595143773768e-08 1.5460070764038640708e-08 0.0045456071298370023803" rpy="0 0 0" />
      <mass value="0.0011084409433758843876" />
      <inertia ixx="2.9582691212226700665e-08" ixy="-2.8904821292766292175e-14" ixz="7.8892082291036886091e-14" iyy="2.9582612758414133212e-08" iyz="-2.5767358059768102734e-14" izz="4.6351510704080136144e-08" />
    </inertial>
  </link>

  <joint name="right_hip_yaw_drive" type="revolute">
    <origin xyz="0.037000000000001719014 0.03710000000000327619 -0.0394999999999998061" rpy="-1.5707963267949545116 -4.8002361403961149694e-13 -3.5216274341110541015e-13" />
    <parent link="waist_link" />
    <child link="spur_gear_19_teeth_2" />
    <axis xyz="0 0 1" />
    <limit effort="1" velocity="20" lower="-1.7361433085627806516" upper="1.7361433085627806516" />
    <joint_properties friction="0.0" />
  </joint>

  <link name="spur_gear_21_teeth_2">
    <visual>
      <origin xyz="0 0 0" rpy="0 -0 0" />
      <geometry>
        <mesh filename="../assemblies/toddlerbot/meshes/spur_gear_21_teeth_2_visual.stl" />
      </geometry>
      <material name="spur_gear_21_teeth_2_material">
        <color rgba="0.61568627450980395466 0.81176470588235294379 0.92941176470588238168 1.0" />
      </material>
    </visual>
    <inertial>
      <origin xyz="-6.7030730388797144104e-12 -1.7758939849553634854e-11 0.0025054714570094428761" rpy="0 0 0" />
      <mass value="0.0010185686142775147826" />
      <inertia ixx="3.2410681505051109819e-08" ixy="8.7148977985253644487e-40" ixz="1.7387576366417533163e-38" iyy="3.2410681506302329683e-08" iyz="2.053667615524067426e-38" izz="6.0614091765677406549e-08" />
    </inertial>
  </link>

  <joint name="right_leg_fixed" type="fixed">
    <origin xyz="0 -6.9388939039072283776e-18 0.0050000000000000044409" rpy="-3.1415926535897926719 1.8281169925220331315e-17 -3.5772536718062127375e-16" />
    <parent link="spur_gear_21_teeth_2" />
    <child link="hip_yaw_link_2" />
    <axis xyz="0 0 1" />
    <limit effort="1" velocity="20" />
    <joint_properties friction="0.0" />
  </joint>

  <joint name="right_hip_yaw_driven" type="revolute">
    <origin xyz="0.036999999999999991229 0.041100000000000011524 -0.019500000000000017319" rpy="-1.570796326794896558 -1.5707963267948961139 0" />
    <parent link="waist_link" />
    <child link="spur_gear_21_teeth_2" />
    <axis xyz="0 0 1" />
    <limit effort="1" velocity="20" lower="-1.570796326794896558" upper="1.570796326794896558" />
    <joint_properties friction="0.0" />
  </joint>

  <joint name="waist_roll" type="revolute">
    <origin xyz="-0.022707865260692617487 -2.4393502827093082036e-16 -0.013999999999999814676" rpy="-1.5707963267948974462 1.8675461532229772614e-15 1.5707963267948952257" />
    <parent link="waist_gears" />
    <child link="waist_link" />
    <axis xyz="0 0 1" />
    <limit effort="1" velocity="20" lower="-0.52359877559829881566" upper="0.52359877559829881566" />
    <joint_properties friction="0.0" />
  </joint>

  <joint name="waist_yaw" type="revolute">
    <origin xyz="0 -3.1104917983741196655e-18 -7.5188305028877687703e-30" rpy="-1.4111145075746007461e-16 -4.1376224834060906822e-15 3.1415926535897922278" />
    <parent link="torso" />
    <child link="waist_gears" />
    <axis xyz="0 0 1" />
    <limit effort="1" velocity="20" lower="-1.570796326794896558" upper="1.570796326794896558" />
    <joint_properties friction="0.0" />
  </joint>

  <joint name="left_sho_pitch" type="revolute">
    <origin xyz="-0.0030000000000002949654 0.062000000000001082023 0.10423651076281743866" rpy="-1.5707963267949081043 -4.127643409825574977e-14 3.4723733359249779961e-14" />
    <parent link="torso" />
    <child link="sho_pitch_link" />
    <axis xyz="0 0 1" />
    <limit effort="1" velocity="20" lower="-3.141592653589793116" upper="1.570796326794896558" />
    <joint_properties friction="0.0" />
  </joint>

  <joint name="right_sho_pitch" type="revolute">
    <origin xyz="-0.0029999999999986998872 -0.06200000000000097794 0.10423651076281731376" rpy="-1.5707963267948885644 3.4812325502379109658e-14 -3.1415926535897562566" />
    <parent link="torso" />
    <child link="sho_pitch_link_2" />
    <axis xyz="0 0 1" />
    <limit effort="1" velocity="20" lower="-1.570796326794896558" upper="3.141592653589793116" />
    <joint_properties friction="0.0" />
  </joint>


  <link name="hip_yaw_link">
    <visual>
      <origin xyz="0 0 0" rpy="0 -0 0" />
      <geometry>
        <mesh filename="../assemblies/left_leg_OP3/meshes/left_hip_yaw_link_visual.stl" />
      </geometry>
      <material name="hip_yaw_link_material">
        <color rgba="0.61568627450980395466 0.81176470588235294379 0.92941176470588238168 1.0" />
      </material>
    </visual>
    <inertial>
      <origin xyz="-1.6124133946295534145e-19 -5.1127973666334958827e-19 -0.0098919667346054462181" rpy="0 0 0" />
      <mass value="0.01799999999999999864" />
      <inertia ixx="2.6483505271519540317e-06" ixy="0" ixz="0" iyy="7.7055357996008251511e-06" iyz="0" izz="7.7736682806805358371e-06" />
    </inertial>
  </link>

  <link name="hip_roll_link">
    <visual>
      <origin xyz="0 0 0" rpy="0 -0 0" />
      <geometry>
        <mesh filename="../assemblies/left_leg_OP3/meshes/left_hip_roll_link_visual.stl" />
      </geometry>
      <material name="hip_roll_link_material">
        <color rgba="0.51698661238356058423 0.5034781595109349972 0.49050589017722023844 1.0" />
      </material>
    </visual>
    <inertial>
      <origin xyz="-0.011999849582186212366 -0.00049598090793881194783 -0.018504111838599408835" rpy="0 0 0" />
      <mass value="0.11059999999836234164" />
      <inertia ixx="2.2818802599019004628e-05" ixy="-4.6520143286869794882e-08" ixz="-4.6888548260596878095e-08" iyy="3.0871632082339529218e-05" iyz="-5.7477343899715755475e-07" izz="3.0871666424470027622e-05" />
    </inertial>
  </link>

  <link name="left_hip_pitch_link_xm430">
    <visual>
      <origin xyz="0 0 0" rpy="0 -0 0" />
      <geometry>
        <mesh filename="../assemblies/left_leg_OP3/meshes/left_hip_pitch_link_xm430_visual.stl" />
      </geometry>
      <material name="left_hip_pitch_link_xm430_material">
        <color rgba="0.87072221357329560032 0.72641010956094287376 0.24785169615220703498 1.0" />
      </material>
    </visual>
    <inertial>
      <origin xyz="-0.00075729214155312188448 -0.050714785675264786868 -0.012656155119959877631" rpy="0 0 0" />
      <mass value="0.1148009013503056841" />
      <inertia ixx="6.6072773889429766716e-05" ixy="-4.6080149277706459406e-07" ixz="-1.817073911531639545e-07" iyy="2.3633638685369937207e-05" iyz="1.4125253925344530372e-06" izz="6.2221728804333288794e-05" />
    </inertial>
  </link>

  <link name="left_calf_link">
    <visual>
      <origin xyz="0 0 0" rpy="0 -0 0" />
      <geometry>
        <mesh filename="../assemblies/left_leg_OP3/meshes/left_calf_link_visual.stl" />
      </geometry>
      <material name="left_calf_link_material">
        <color rgba="0.52270714737507917302 0.70740037950664147459 0.87533206831119547697 1.0" />
      </material>
    </visual>
    <inertial>
      <origin xyz="-0.0044698992063320801618 -0.040537655000345430845 -0.0094043191617602540228" rpy="0 0 0" />
      <mass value="0.030999999999999999778" />
      <inertia ixx="3.2349006752263256706e-05" ixy="1.4910956274417595751e-06" ixz="1.9651815973586297743e-07" iyy="7.7183393965098499287e-06" iyz="-6.268607715511545786e-07" izz="2.7323441483284109904e-05" />
    </inertial>
  </link>

  <link name="bearing_683">
    <visual>
      <origin xyz="0 0 0" rpy="0 -0 0" />
      <geometry>
        <mesh filename="../assemblies/left_leg_OP3/meshes/left_bearing_683_visual.stl" />
      </geometry>
      <material name="bearing_683_material">
        <color rgba="0.64705882352941179736 0.64705882352941179736 0.64705882352941179736 1.0" />
      </material>
    </visual>
    <inertial>
      <origin xyz="1.0732094295242863011e-19 6.2549399515679300359e-19 -0.0015500000000000042823" rpy="0 0 0" />
      <mass value="0.00048694686130641793437" />
      <inertia ixx="2.1551456503319887385e-09" ixy="-2.5117832293793330346e-27" ixz="1.2351863617911424991e-37" iyy="2.1551456503319874977e-09" iyz="3.5328244942237977619e-38" izz="3.5303647444715322361e-09" />
    </inertial>
  </link>

  <joint name="left_knee_front_rev_2" type="revolute">
    <origin xyz="-0.0057402514854767707972 0.013858192987668854768 -0.026199999999999168399" rpy="9.6260126850146175027e-15 -2.5081324750790058604e-14 1.5765933876572388872" />
    <parent link="left_calf_link" />
    <child link="bearing_683" />
    <axis xyz="0 0 1" />
    <limit effort="1" velocity="20" lower="-6.283185307179586232" upper="6.283185307179586232" />
    <joint_properties friction="0.0" />
  </joint>

  <link name="bearing_683_2">
    <visual>
      <origin xyz="0 0 0" rpy="0 -0 0" />
      <geometry>
        <mesh filename="../assemblies/left_leg_OP3/meshes/left_bearing_683_2_visual.stl" />
      </geometry>
      <material name="bearing_683_2_material">
        <color rgba="0.64705882352941179736 0.64705882352941179736 0.64705882352941179736 1.0" />
      </material>
    </visual>
    <inertial>
      <origin xyz="1.0732094295230777801e-19 -2.418677428316055362e-19 -0.0015500000000000042823" rpy="0 0 0" />
      <mass value="0.00048694686130641793437" />
      <inertia ixx="2.1551456503319887385e-09" ixy="-1.3780027454701905363e-27" ixz="1.7697072896735004236e-37" iyy="2.1551456503319883249e-09" iyz="9.4913848506895919628e-39" izz="3.5303647444715322361e-09" />
    </inertial>
  </link>

  <joint name="left_knee_back_rev_2" type="revolute">
    <origin xyz="0.0057402514854756501658 -0.013858192987669437635 -0.026199999999999720041" rpy="4.9560921740722585935e-15 -2.1168138603303528903e-14 1.5736949077299444699" />
    <parent link="left_calf_link" />
    <child link="bearing_683_2" />
    <axis xyz="0 0 1" />
    <limit effort="1" velocity="20" lower="-6.283185307179586232" upper="6.283185307179586232" />
    <joint_properties friction="0.0" />
  </joint>

  <link name="ank_pitch_link">
    <visual>
      <origin xyz="0 0 0" rpy="0 -0 0" />
      <geometry>
        <mesh filename="../assemblies/left_leg_OP3/meshes/left_ank_pitch_link_visual.stl" />
      </geometry>
      <material name="ank_pitch_link_material">
        <color rgba="0.42838831031765539636 0.55128652208657225042 0.74128917770314906033 1.0" />
      </material>
    </visual>
    <inertial>
      <origin xyz="-0.012383885521092090343 0.019663604311318874651 0.018862066178914671521" rpy="0 0 0" />
      <mass value="0.15976376693924948524" />
      <inertia ixx="9.8184006245898269296e-05" ixy="1.0738445982480728578e-06" ixz="4.3555854013565407518e-08" iyy="4.223718185419924996e-05" iyz="-4.1061630166343525614e-07" izz="0.0001116832406067800454" />
    </inertial>
  </link>

  <link name="ank_roll_link">
    <visual>
      <origin xyz="0 0 0" rpy="0 -0 0" />
      <geometry>
        <mesh filename="../assemblies/left_leg_OP3/meshes/left_ank_roll_link_visual.stl" />
      </geometry>
      <material name="ank_roll_link_material">
        <color rgba="0.61568627450980395466 0.81176470588235305481 0.9294117647058824927 1.0" />
      </material>
    </visual>
    <collision name="ank_roll_link_collision">
      <origin xyz="-0.014500000514090061 0.0 -0.038999998942017555" rpy="0 0 0" />
      <geometry>
        <box size="0.04900000058114529 0.041999999433755875 0.12000000104308128" />
      </geometry>
    </collision>
    <inertial>
      <origin xyz="-0.026981230777523998454 2.0010901539705145943e-12 -0.033733185742545857" rpy="0 0 0" />
      <mass value="0.042599999999999998979" />
      <inertia ixx="3.7270477448018181083e-05" ixy="5.5380108492315631755e-16" ixz="-2.3925937758710058273e-06" iyy="3.7621548160201323551e-05" iyz="5.0816858853237229248e-12" izz="1.012619291415873911e-05" />
    </inertial>
  </link>

  <joint name="left_ank_roll" type="revolute">
    <origin xyz="-7.771561172376095783e-16 0.022750000000003930273 0.019000000000007229856" rpy="1.5707963267949729413 8.7734350778775080161e-14 3.1415926535897842342" />
    <parent link="ank_pitch_link" />
    <child link="ank_roll_link" />
    <axis xyz="0 0 1" />
    <limit effort="1" velocity="20" lower="-1.570796326794896558" upper="1.570796326794896558" />
    <joint_properties friction="0.0" />
  </joint>

  <joint name="left_ank_pitch" type="revolute">
    <origin xyz="0.00050000000000004402902 -0.099999999999997202238 -0.029400000000001407646" rpy="-2.1321242293024632049e-15 1.8823484437772641304e-14 -1.5707963267948981123" />
    <parent link="left_calf_link" />
    <child link="ank_pitch_link" />
    <axis xyz="0 0 1" />
    <limit effort="1" velocity="20" lower="-0.785398163397448279" upper="1.8325957145940461324" />
    <joint_properties friction="0.0" />
  </joint>

  <joint name="left_knee_pitch" type="revolute">
    <origin xyz="2.6591951153791853136e-17 -0.096000000000000029754 -0.0091999999999999634154" rpy="-1.3783391157486681965e-14 -1.4843341659320182562e-14 4.5251917072955735634e-15" />
    <parent link="left_hip_pitch_link_xm430" />
    <child link="left_calf_link" />
    <axis xyz="0 0 1" />
    <limit effort="1" velocity="20" lower="0" upper="1.9198621771937625091" />
    <joint_properties friction="0.0" />
  </joint>

  <link name="xm430_plate">
    <visual>
      <origin xyz="0 0 0" rpy="0 -0 0" />
      <geometry>
        <mesh filename="../assemblies/left_leg_OP3/meshes/left_xm430_plate_visual.stl" />
      </geometry>
      <material name="xm430_plate_material">
        <color rgba="0.61568627450980395466 0.81176470588235294379 0.92941176470588227065 1.0" />
      </material>
    </visual>
    <inertial>
      <origin xyz="3.3086273192764551093e-18 2.0177424182845293718e-18 -0.0024039046431217937771" rpy="0 0 0" />
      <mass value="0.0026999999999999997093" />
      <inertia ixx="1.293311664536341083e-07" ixy="-6.8936588702566453648e-08" ixz="1.4861959830666080916e-35" iyy="2.6720434385876693618e-07" iyz="-5.8703791399741623603e-36" izz="3.8533537562751439267e-07" />
    </inertial>
  </link>

  <link name="knee_rod">
    <visual>
      <origin xyz="0 0 0" rpy="0 -0 0" />
      <geometry>
        <mesh filename="../assemblies/left_leg_OP3/meshes/left_knee_rod_visual.stl" />
      </geometry>
      <material name="knee_rod_material">
        <color rgba="0.62051618944235198416 0.78640765248647581664 0.88594253031295000511 1.0" />
      </material>
    </visual>
    <inertial>
      <origin xyz="0.014594546691135086569 -4.23023230762537407e-05 -0.0015996227373175258071" rpy="0 0 0" />
      <mass value="0.0031629468613064183613" />
      <inertia ixx="2.5896152838585326758e-08" ixy="3.5533843516683890995e-10" ixz="4.1682972813638103646e-10" iyy="6.0153250027083944991e-07" iyz="-1.2081818132196025465e-12" izz="6.2266858883152744307e-07" />
    </inertial>
  </link>

  <joint name="left_knee_front_rev_1" type="revolute">
    <origin xyz="0.013858192987669312735 0.0057402514854763449226 -0.0049999999999999992367" rpy="2.3955576787343955856e-15 2.4557124758423299065e-14 -3.1357955927274510088" />
    <parent link="xm430_plate" />
    <child link="knee_rod" />
    <axis xyz="0 0 1" />
    <limit effort="1" velocity="20" lower="-6.283185307179586232" upper="6.283185307179586232" />
    <joint_properties friction="0.0" />
  </joint>

  <link name="knee_rod_2">
    <visual>
      <origin xyz="0 0 0" rpy="0 -0 0" />
      <geometry>
        <mesh filename="../assemblies/left_leg_OP3/meshes/left_knee_rod_2_visual.stl" />
      </geometry>
      <material name="knee_rod_2_material">
        <color rgba="0.62051618944235198416 0.78640765248647581664 0.88594253031295000511 1.0" />
      </material>
    </visual>
    <inertial>
      <origin xyz="0.014594546693013455557 4.2301026627630812212e-05 -0.0015996227373180340811" rpy="0 0 0" />
      <mass value="0.0031629468613064183613" />
      <inertia ixx="2.5896152775454644328e-08" ixy="-3.5532754507239285723e-10" ixz="4.1682972818975915649e-10" iyy="6.0153250030238083928e-07" iyz="1.2081447851119857907e-12" izz="6.2266858879995280765e-07" />
    </inertial>
  </link>

  <joint name="left_knee_back_rev_1" type="revolute">
    <origin xyz="-0.013858192987669284979 -0.0057402514854763466573 -0.0050000000000000027062" rpy="-1.7626513399117519762e-14 2.0655748330454469805e-14 -3.1386940726547454261" />
    <parent link="xm430_plate" />
    <child link="knee_rod_2" />
    <axis xyz="0 0 1" />
    <limit effort="1" velocity="20" lower="-6.283185307179586232" upper="6.283185307179586232" />
    <joint_properties friction="0.0" />
  </joint>

  <joint name="left_knee_act" type="revolute">
    <origin xyz="-0.00015000000000014844124 -0.06150000000000001299 -0.030399999999999711975" rpy="-1.0766672541727743252e-14 1.3282815320613851332e-14 1.5707963267949027752" />
    <parent link="left_hip_pitch_link_xm430" />
    <child link="xm430_plate" />
    <axis xyz="0 0 1" />
    <limit effort="1" velocity="20" lower="0" upper="1.9198621771937625091" />
    <joint_properties friction="0.0" />
  </joint>

  <joint name="left_hip_pitch" type="revolute">
    <origin xyz="-0.024000000716156176528 -0.019000000152439990714 -0.019000000152458156738" rpy="1.5707963267953688469 1.5707963267944595742 0" />
    <parent link="hip_roll_link" />
    <child link="left_hip_pitch_link_xm430" />
    <axis xyz="0 0 1" />
    <limit effort="1" velocity="20" lower="-1.570796326794896558" upper="1.570796326794896558" />
    <joint_properties friction="0.0" />
  </joint>

  <joint name="left_hip_roll" type="revolute">
    <origin xyz="0.018999999999999434008 3.7043493321931432202e-16 -0.026000000000000141054" rpy="-3.141592653589793116 -1.5707963267948932273 0" />
    <parent link="hip_yaw_link" />
    <child link="hip_roll_link" />
    <axis xyz="0 0 1" />
    <limit effort="1" velocity="20" lower="-0.785398163397448279" upper="0.785398163397448279" />
    <joint_properties friction="0.0" />
  </joint>


  <link name="hip_yaw_link_2">
    <visual>
      <origin xyz="0 0 0" rpy="0 -0 0" />
      <geometry>
        <mesh filename="../assemblies/right_leg_OP3/meshes/right_hip_yaw_link_visual.stl" />
      </geometry>
      <material name="hip_yaw_link_material">
        <color rgba="0.61568627450980395466 0.81176470588235294379 0.92941176470588238168 1.0" />
      </material>
    </visual>
    <inertial>
      <origin xyz="1.6124133946295534145e-19 5.1127973666334958827e-19 -0.0098919667346054462181" rpy="0 0 0" />
      <mass value="0.01799999999999999864" />
      <inertia ixx="2.6483505271519540317e-06" ixy="0" ixz="0" iyy="7.7055357996008251511e-06" iyz="0" izz="7.7736682806805358371e-06" />
    </inertial>
  </link>

  <link name="hip_roll_link_2">
    <visual>
      <origin xyz="0 0 0" rpy="0 -0 0" />
      <geometry>
        <mesh filename="../assemblies/right_leg_OP3/meshes/right_hip_roll_link_visual.stl" />
      </geometry>
      <material name="hip_roll_link_material">
        <color rgba="0.51698661238356058423 0.5034781595109349972 0.49050589017722023844 1.0" />
      </material>
    </visual>
    <inertial>
      <origin xyz="-0.011999849582182841798 -0.00049598090794352096312 -0.018504111838597715745" rpy="0 0 0" />
      <mass value="0.11059999999836234164" />
      <inertia ixx="2.2818802599018581112e-05" ixy="-4.6520143285862249191e-08" ixz="-4.6888548259042824099e-08" iyy="3.087163208233820107e-05" iyz="-5.7477343899720054167e-07" izz="3.08716664244684352e-05" />
    </inertial>
  </link>

  <link name="right_hip_pitch_link_xm430">
    <visual>
      <origin xyz="0 0 0" rpy="0 -0 0" />
      <geometry>
        <mesh filename="../assemblies/right_leg_OP3/meshes/right_hip_pitch_link_xm430_visual.stl" />
      </geometry>
      <material name="right_hip_pitch_link_xm430_material">
        <color rgba="0.87072221357329571134 0.72641010956094276274 0.24785169615220697947 1.0" />
      </material>
    </visual>
    <inertial>
      <origin xyz="0.0007571588137130364762 -0.050714784778880764304 -0.012656153620121854755" rpy="0 0 0" />
      <mass value="0.11480090135030567022" />
      <inertia ixx="6.6072786489384158193e-05" ixy="4.601068290601230276e-07" ixz="1.8171597853303241767e-07" iyy="2.3633665181581449356e-05" iyz="1.4125296519935310156e-06" izz="6.2221763055416812009e-05" />
    </inertial>
  </link>

  <link name="right_calf_link">
    <visual>
      <origin xyz="0 0 0" rpy="0 -0 0" />
      <geometry>
        <mesh filename="../assemblies/right_leg_OP3/meshes/right_calf_link_visual.stl" />
      </geometry>
      <material name="right_calf_link_material">
        <color rgba="0.522707147375079062 0.70740037950664136357 0.87533206831119547697 1.0" />
      </material>
    </visual>
    <inertial>
      <origin xyz="-0.0044698992063320081708 0.040537655000345548806 -0.0094043191617598255461" rpy="0 0 0" />
      <mass value="0.03099999999999998937" />
      <inertia ixx="3.2349006752264496763e-05" ixy="-1.4910956274418425843e-06" ixz="1.9651815973590485263e-07" iyy="7.718339396509856705e-06" iyz="6.2686077155121111805e-07" izz="2.7323441483284174278e-05" />
    </inertial>
  </link>

  <link name="bearing_683_3">
    <visual>
      <origin xyz="0 0 0" rpy="0 -0 0" />
      <geometry>
        <mesh filename="../assemblies/right_leg_OP3/meshes/right_bearing_683_visual.stl" />
      </geometry>
      <material name="bearing_683_material">
        <color rgba="0.64705882352941179736 0.64705882352941179736 0.64705882352941179736 1.0" />
      </material>
    </visual>
    <inertial>
      <origin xyz="9.7468268094076349384e-19 2.4186774283157871762e-19 -0.0015499999999999982108" rpy="0 0 0" />
      <mass value="0.00048694686130641793437" />
      <inertia ixx="2.1551456503319887385e-09" ixy="1.1974543606876073238e-27" ixz="2.5960211429906896931e-40" iyy="2.1551456503319883249e-09" iyz="-1.0536891599728111288e-37" izz="3.5303647444715305817e-09" />
    </inertial>
  </link>

  <joint name="right_knee_front_rev_2" type="revolute">
    <origin xyz="-0.0057402514854764195157 -0.013858192987669049057 -0.026200000000000209233" rpy="-4.792276793618950313e-15 -7.4425542615262678023e-15 3.1386680923234981933" />
    <parent link="right_calf_link" />
    <child link="bearing_683_3" />
    <axis xyz="0 0 1" />
    <limit effort="1" velocity="20" lower="-6.283185307179586232" upper="6.283185307179586232" />
    <joint_properties friction="0.0" />
  </joint>

  <link name="bearing_683_4">
    <visual>
      <origin xyz="0 0 0" rpy="0 -0 0" />
      <geometry>
        <mesh filename="../assemblies/right_leg_OP3/meshes/right_bearing_683_2_visual.stl" />
      </geometry>
      <material name="bearing_683_2_material">
        <color rgba="0.64705882352941179736 0.64705882352941179736 0.64705882352941179736 1.0" />
      </material>
    </visual>
    <inertial>
      <origin xyz="1.0732094295234320308e-19 -2.7513707872797298537e-17 -0.0015499999999999977771" rpy="0 0 0" />
      <mass value="0.00048694686130641793437" />
      <inertia ixx="2.1551456503319887385e-09" ixy="5.5200346050157064306e-28" ixz="-6.8631381869404202707e-38" iyy="2.1551456503319883249e-09" iyz="-3.8635622103068727551e-38" izz="3.5303647444715322361e-09" />
    </inertial>
  </link>

  <joint name="right_knee_back_rev_2" type="revolute">
    <origin xyz="0.005740251485476185328 0.013858192987669409879 -0.026200000000000056577" rpy="-6.2585939741374333299e-15 -1.0479387378889103051e-16 3.1385914305327817786" />
    <parent link="right_calf_link" />
    <child link="bearing_683_4" />
    <axis xyz="0 0 1" />
    <limit effort="1" velocity="20" lower="-6.283185307179586232" upper="6.283185307179586232" />
    <joint_properties friction="0.0" />
  </joint>

  <link name="ank_pitch_link_2">
    <visual>
      <origin xyz="0 0 0" rpy="0 -0 0" />
      <geometry>
        <mesh filename="../assemblies/right_leg_OP3/meshes/right_ank_pitch_link_visual.stl" />
      </geometry>
      <material name="ank_pitch_link_material">
        <color rgba="0.42838831031765539636 0.55128652208657225042 0.74128917770314906033 1.0" />
      </material>
    </visual>
    <inertial>
      <origin xyz="-0.012383885521091249002 0.01966360431131712605 0.018862066178909241837" rpy="0 0 0" />
      <mass value="0.15976376693924948524" />
      <inertia ixx="9.8184006245882968493e-05" ixy="1.0738445982480588818e-06" ixz="4.3555854012722967078e-08" iyy="4.2237181854197494908e-05" iyz="-4.1061630166170852654e-07" izz="0.00011168324060676464973" />
    </inertial>
  </link>

  <link name="ank_roll_link_2">
    <visual>
      <origin xyz="0 0 0" rpy="0 -0 0" />
      <geometry>
        <mesh filename="../assemblies/right_leg_OP3/meshes/right_ank_roll_link_visual.stl" />
      </geometry>
      <material name="ank_roll_link_material">
        <color rgba="0.61568627450980395466 0.81176470588235305481 0.9294117647058824927 1.0" />
      </material>
    </visual>
    <collision name="ank_roll_link_2_collision">
      <origin xyz="-0.014500000514090061 0.0 -0.038999998942017555" rpy="0 0 0" />
      <geometry>
        <box size="0.04900000058114529 0.041999999433755875 0.12000000104308128" />
      </geometry>
    </collision>
    <inertial>
      <origin xyz="-0.026981230777523942943 2.0010897630468602634e-12 -0.033733185742545759855" rpy="0 0 0" />
      <mass value="0.042599999999999998979" />
      <inertia ixx="3.7270477448017821941e-05" ixy="5.541641696149723301e-16" ixz="-2.3925937758709770282e-06" iyy="3.7621548160199975075e-05" iyz="5.0816858811652129512e-12" izz="1.0126192914158457895e-05" />
    </inertial>
  </link>

  <joint name="right_ank_roll" type="revolute">
    <origin xyz="-2.2204460492503130808e-16 0.02275000000000106104 0.019000000000002178341" rpy="1.5707963267949220931 -3.6775852931107809278e-14 3.1415926535897313876" />
    <parent link="ank_pitch_link_2" />
    <child link="ank_roll_link_2" />
    <axis xyz="0 0 1" />
    <limit effort="1" velocity="20" lower="-1.570796326794896558" upper="1.570796326794896558" />
    <joint_properties friction="0.0" />
  </joint>

  <joint name="right_ank_pitch" type="revolute">
    <origin xyz="0.00049999999999975335441 0.099999999999999561462 0.0086000000000000676598" rpy="3.1415926535897877869 -1.4928027344634987948e-14 1.5707963267948785724" />
    <parent link="right_calf_link" />
    <child link="ank_pitch_link_2" />
    <axis xyz="0 0 1" />
    <limit effort="1" velocity="20" lower="-0.785398163397448279" upper="1.8325957145940461324" />
    <joint_properties friction="0.0" />
  </joint>

  <joint name="right_knee_pitch" type="revolute">
    <origin xyz="-1.4425300025281195314e-16 -0.095999999999999197087 -0.009200000000000072703" rpy="-4.4507648457556451305e-14 -3.3964226209539856629e-15 3.1415926535897926719" />
    <parent link="right_hip_pitch_link_xm430" />
    <child link="right_calf_link" />
    <axis xyz="0 0 1" />
    <limit effort="1" velocity="20" lower="-1.9198621771937625091" upper="0" />
    <joint_properties friction="0.0" />
  </joint>

  <link name="xm430_plate_2">
    <visual>
      <origin xyz="0 0 0" rpy="0 -0 0" />
      <geometry>
        <mesh filename="../assemblies/right_leg_OP3/meshes/right_xm430_plate_visual.stl" />
      </geometry>
      <material name="xm430_plate_material">
        <color rgba="0.61568627450980395466 0.81176470588235294379 0.92941176470588227065 1.0" />
      </material>
    </visual>
    <inertial>
      <origin xyz="7.9779646097136977501e-19 3.8813091667873471619e-18 -0.0024039046431217937771" rpy="0 0 0" />
      <mass value="0.0026999999999999997093" />
      <inertia ixx="2.6720434385876693618e-07" ixy="-6.8936588702566387474e-08" ixz="-6.4147267181799705475e-36" iyy="1.2933116645363405536e-07" iyz="6.7767426916190795618e-37" izz="3.8533537562751439267e-07" />
    </inertial>
  </link>

  <link name="knee_rod_3">
    <visual>
      <origin xyz="0 0 0" rpy="0 -0 0" />
      <geometry>
        <mesh filename="../assemblies/right_leg_OP3/meshes/right_knee_rod_visual.stl" />
      </geometry>
      <material name="knee_rod_material">
        <color rgba="0.62051618944235198416 0.78640765248647581664 0.88594253031295000511 1.0" />
      </material>
    </visual>
    <inertial>
      <origin xyz="0.014594547782157867369 -4.1542690670034378305e-05 -0.0015996227373180807018" rpy="0 0 0" />
      <mass value="0.0031629468613064183613" />
      <inertia ixx="2.589611618064318261e-08" ixy="3.4895756842141165546e-10" ixz="4.1682975930458834178e-10" iyy="6.0153251859997735439e-07" iyz="-1.1864862087162977201e-12" izz="6.226685705027195638e-07" />
    </inertial>
  </link>

  <joint name="right_knee_front_rev_1" type="revolute">
    <origin xyz="-0.0057402514854763501267 -0.013858192987669284979 -0.0049999999999999957673" rpy="-5.0313204613631514412e-15 -1.1212819345950018642e-16 1.5678717655286047439" />
    <parent link="xm430_plate_2" />
    <child link="knee_rod_3" />
    <axis xyz="0 0 1" />
    <limit effort="1" velocity="20" lower="-6.283185307179586232" upper="6.283185307179586232" />
    <joint_properties friction="0.0" />
  </joint>

  <link name="knee_rod_4">
    <visual>
      <origin xyz="0 0 0" rpy="0 -0 0" />
      <geometry>
        <mesh filename="../assemblies/right_leg_OP3/meshes/right_knee_rod_2_visual.stl" />
      </geometry>
      <material name="knee_rod_2_material">
        <color rgba="0.62051618944235198416 0.78640765248647581664 0.88594253031295000511 1.0" />
      </material>
    </visual>
    <inertial>
      <origin xyz="0.014594550881123264166 -3.9305021098133457514e-05 -0.0015996227373180275759" rpy="0 0 0" />
      <mass value="0.0031629468613064183613" />
      <inertia ixx="2.5896012056594737581e-08" ixy="3.3016126977403441595e-10" ixz="4.1682984780892858046e-10" iyy="6.0153257066243997601e-07" iyz="-1.1225769169763295707e-12" izz="6.2266851844113933875e-07" />
    </inertial>
  </link>

  <joint name="right_knee_back_rev_1" type="revolute">
    <origin xyz="0.0057402514854763535962 0.013858192987669271101 -0.0050000000000000061756" rpy="-1.919569185352210123e-15 -1.6455897748865722783e-15 1.5677951037378847765" />
    <parent link="xm430_plate_2" />
    <child link="knee_rod_4" />
    <axis xyz="0 0 1" />
    <limit effort="1" velocity="20" lower="-6.283185307179586232" upper="6.283185307179586232" />
    <joint_properties friction="0.0" />
  </joint>

  <joint name="right_knee_act" type="revolute">
    <origin xyz="0.00014999999999996659343 -0.061499999999998652966 -0.030399999999999018085" rpy="-3.9472982174462490613e-14 8.7088539502980777788e-16 3.141592653589793116" />
    <parent link="right_hip_pitch_link_xm430" />
    <child link="xm430_plate_2" />
    <axis xyz="0 0 1" />
    <limit effort="1" velocity="20" lower="-1.9198621771937625091" upper="0" />
    <joint_properties friction="0.0" />
  </joint>

  <joint name="right_hip_pitch" type="revolute">
    <origin xyz="-0.024000000716143346513 -0.019000000152445729179 -0.019000000152453181551" rpy="1.5707963267950966202 1.5707963267947326891 0" />
    <parent link="hip_roll_link_2" />
    <child link="right_hip_pitch_link_xm430" />
    <axis xyz="0 0 1" />
    <limit effort="1" velocity="20" lower="-1.570796326794896558" upper="1.570796326794896558" />
    <joint_properties friction="0.0" />
  </joint>

  <joint name="right_hip_roll" type="revolute">
    <origin xyz="-0.018999999999999916261 3.1092928099478391072e-16 -0.025999999999999925948" rpy="3.0774993384580180772e-19 -1.5707963267948932273 0" />
    <parent link="hip_yaw_link_2" />
    <child link="hip_roll_link_2" />
    <axis xyz="0 0 1" />
    <limit effort="1" velocity="20" lower="-0.785398163397448279" upper="0.785398163397448279" />
    <joint_properties friction="0.0" />
  </joint>


  <link name="sho_pitch_link">
    <visual>
      <origin xyz="0 0 0" rpy="0 -0 0" />
      <geometry>
        <mesh filename="../assemblies/left_arm_gripper/meshes/left_sho_pitch_link_visual.stl" />
      </geometry>
      <material name="sho_pitch_link_material">
        <color rgba="0.61568627450980395466 0.81176470588235294379 0.92941176470588238168 1.0" />
      </material>
    </visual>
    <inertial>
      <origin xyz="5.8254246946927595895e-11 -5.1264642561121060609e-05 0.0082440788127094641324" rpy="0 0 0" />
      <mass value="0.0086000000000000000056" />
      <inertia ixx="1.227288704054570717e-06" ixy="-2.1429936863904790749e-14" ixz="-8.5847198110204645787e-15" iyy="2.9107306060364421035e-06" iyz="7.4623841398182488439e-09" izz="3.0803135950773271699e-06" />
    </inertial>
  </link>

  <link name="2xl430_gears">
    <visual>
      <origin xyz="0 0 0" rpy="0 -0 0" />
      <geometry>
        <mesh filename="../assemblies/left_arm_gripper/meshes/left_2xl430_gears_visual.stl" />
      </geometry>
      <material name="2xl430_gears_material">
        <color rgba="0.7560598568794409946 0.8580469596269301169 0.91320266199377464478 1.0" />
      </material>
    </visual>
    <inertial>
      <origin xyz="-0.011579403981035758103 -0.0024225766141424860678 -0.018551095523803400045" rpy="0 0 0" />
      <mass value="0.11800003674524910113" />
      <inertia ixx="2.7482298083238270581e-05" ixy="9.2729623433106271741e-07" ixz="-2.2634512004565670184e-08" iyy="3.277074248667325194e-05" iyz="-6.5708346020155028151e-07" izz="3.5767957544057342163e-05" />
    </inertial>
  </link>

  <link name="spur_1m_24t_drive">
    <visual>
      <origin xyz="0 0 0" rpy="0 -0 0" />
      <geometry>
        <mesh filename="../assemblies/left_arm_gripper/meshes/left_spur_1m_24t_drive_visual.stl" />
      </geometry>
      <material name="spur_1m_24t_drive_material">
        <color rgba="0.61568627450980406568 0.81176470588235294379 0.92941176470588238168 1.0" />
      </material>
    </visual>
    <inertial>
      <origin xyz="-7.7516116741234976791e-15 -1.2124421064949640411e-16 0.0047949116178401399516" rpy="0 0 0" />
      <mass value="0.0032000000000000001533" />
      <inertia ixx="1.4019331346159892996e-07" ixy="1.6002409902219162019e-15" ixz="1.2418303191241970223e-36" iyy="1.4019331260388780891e-07" iyz="4.4948724812246596416e-37" izz="2.3838919844264071235e-07" />
    </inertial>
  </link>

  <joint name="left_sho_yaw_drive" type="revolute">
    <origin xyz="-0.024000000716139110318 -0.019000000152454975255 -0.019000000152449778024" rpy="1.5707963267949334174 -1.1191795890472901541e-13 1.4055336229792838361e-13" />
    <parent link="2xl430_gears" />
    <child link="spur_1m_24t_drive" />
    <axis xyz="0 0 1" />
    <limit effort="1" velocity="20" lower="-2.6179938779914944114" upper="2.6179938779914944114" />
    <joint_properties friction="0.0" />
  </joint>

  <link name="spur_1m_24t_driven">
    <visual>
      <origin xyz="0 0 0" rpy="0 -0 0" />
      <geometry>
        <mesh filename="../assemblies/left_arm_gripper/meshes/left_spur_1m_24t_driven_visual.stl" />
      </geometry>
      <material name="spur_1m_24t_driven_material">
        <color rgba="0.23137254901960788156 0.38039215686274502337 0.7058823529411765163 1.0" />
      </material>
    </visual>
    <inertial>
      <origin xyz="1.9637778540992548441e-18 -5.8049057615352288969e-15 -0.00097054817521927832808" rpy="0 0 0" />
      <mass value="0.0026999999999999997093" />
      <inertia ixx="1.2036234079571065709e-07" ixy="6.0233363989413072236e-37" ixz="4.2452965972389379691e-36" iyy="1.203623407957104718e-07" iyz="1.6094626499063888535e-36" izz="2.2847261745924535316e-07" />
    </inertial>
  </link>

  <link name="sho_yaw_link">
    <visual>
      <origin xyz="0 0 0" rpy="0 -0 0" />
      <geometry>
        <mesh filename="../assemblies/left_arm_gripper/meshes/left_sho_yaw_link_visual.stl" />
      </geometry>
      <material name="sho_yaw_link_material">
        <color rgba="0.61568627450980395466 0.81176470588235294379 0.92941176470588238168 1.0" />
      </material>
    </visual>
    <inertial>
      <origin xyz="-1.2817564279969982505e-18 -4.2395441168349757852e-19 -0.024303257848520158635" rpy="0 0 0" />
      <mass value="0.014500000000000016348" />
      <inertia ixx="9.0846670053041382782e-06" ixy="3.6224092806404002001e-13" ixz="-2.2549862058730217891e-35" iyy="5.6910950712097533498e-06" iyz="-3.7044100730248461845e-36" izz="4.481960984554899287e-06" />
    </inertial>
  </link>

  <link name="2xl430_gears_2">
    <visual>
      <origin xyz="0 0 0" rpy="0 -0 0" />
      <geometry>
        <mesh filename="../assemblies/left_arm_gripper/meshes/left_2xl430_gears_2_visual.stl" />
      </geometry>
      <material name="2xl430_gears_2_material">
        <color rgba="0.7560598568794409946 0.8580469596269301169 0.91320266199377464478 1.0" />
      </material>
    </visual>
    <inertial>
      <origin xyz="-0.011579403981035940249 -0.0024225766141466515725 -0.018551095523804794762" rpy="0 0 0" />
      <mass value="0.11800003674524910113" />
      <inertia ixx="2.7482298083242519298e-05" ixy="9.2729623433074825643e-07" ixz="-2.2634512004084773846e-08" iyy="3.2770742486673638187e-05" iyz="-6.5708346020082733889e-07" izz="3.5767957544061780616e-05" />
    </inertial>
  </link>

  <link name="spur_1m_24t_drive_2">
    <visual>
      <origin xyz="0 0 0" rpy="0 -0 0" />
      <geometry>
        <mesh filename="../assemblies/left_arm_gripper/meshes/left_spur_1m_24t_drive_2_visual.stl" />
      </geometry>
      <material name="spur_1m_24t_drive_2_material">
        <color rgba="0.61568627450980406568 0.81176470588235294379 0.92941176470588238168 1.0" />
      </material>
    </visual>
    <inertial>
      <origin xyz="-7.744672780219588873e-15 -1.2124421062364700997e-16 0.0047949116178401382168" rpy="0 0 0" />
      <mass value="0.0032000000000000001533" />
      <inertia ixx="1.4019331346159887702e-07" ixy="1.6002409922818087303e-15" ixz="2.3547439486243088255e-36" iyy="1.4019331260388783538e-07" iyz="3.8710779976498571709e-36" izz="2.3838919844264060647e-07" />
    </inertial>
  </link>

  <joint name="left_elbow_yaw_drive" type="revolute">
    <origin xyz="-0.02400000071614073055 -0.019000000152457841018 -0.019000000152442970969" rpy="1.5707963267946287722 -5.6790261222308772362e-14 9.8859639154170636391e-14" />
    <parent link="2xl430_gears_2" />
    <child link="spur_1m_24t_drive_2" />
    <axis xyz="0 0 1" />
    <limit effort="1" velocity="20" lower="-2.6179938779914944114" upper="2.6179938779914944114" />
    <joint_properties friction="0.0" />
  </joint>

  <link name="spur_1m_24t_driven_2">
    <visual>
      <origin xyz="0 0 0" rpy="0 -0 0" />
      <geometry>
        <mesh filename="../assemblies/left_arm_gripper/meshes/left_spur_1m_24t_driven_2_visual.stl" />
      </geometry>
      <material name="spur_1m_24t_driven_2_material">
        <color rgba="0.23137254901960788156 0.38039215686274502337 0.7058823529411765163 1.0" />
      </material>
    </visual>
    <inertial>
      <origin xyz="1.9637778540993942815e-18 -5.8049057615352241637e-15 -0.00097054817521927117235" rpy="0 0 0" />
      <mass value="0.0026999999999999997093" />
      <inertia ixx="1.2036234079571065709e-07" ixy="3.6792793727059434211e-37" ixz="1.8249753104761457119e-36" iyy="1.203623407957104718e-07" iyz="2.1366319123049580012e-36" izz="2.2847261745924535316e-07" />
    </inertial>
  </link>

  <link name="elb_yaw_link">
    <visual>
      <origin xyz="0 0 0" rpy="0 -0 0" />
      <geometry>
        <mesh filename="../assemblies/left_arm_gripper/meshes/left_elb_yaw_link_visual.stl" />
      </geometry>
      <material name="elb_yaw_link_material">
        <color rgba="0.61568627450980395466 0.81176470588235294379 0.92941176470588227065 1.0" />
      </material>
    </visual>
    <inertial>
      <origin xyz="5.3127688027391931278e-08 0.0019833638641961644222 -0.023416643551549959357" rpy="0 0 0" />
      <mass value="0.017500000000000001665" />
      <inertia ixx="1.4134344903109194693e-05" ixy="1.6945783921965038345e-12" ixz="-1.128639872187510241e-11" iyy="6.6435900776211323463e-06" iyz="1.0545227077253055462e-06" izz="8.9925290757998976773e-06" />
    </inertial>
  </link>

  <link name="spur_1m_24t_driven_3">
    <visual>
      <origin xyz="0 0 0" rpy="0 -0 0" />
      <geometry>
        <mesh filename="../assemblies/left_arm_gripper/meshes/left_spur_1m_24t_driven_3_visual.stl" />
      </geometry>
      <material name="spur_1m_24t_driven_3_material">
        <color rgba="0.23137254901960788156 0.38039215686274502337 0.7058823529411765163 1.0" />
      </material>
    </visual>
    <inertial>
      <origin xyz="-2.5791797761529668296e-17 -5.8049057615352249526e-15 -0.0025705481752192754774" rpy="0 0 0" />
      <mass value="0.0026999999999999997093" />
      <inertia ixx="1.2036234079571065709e-07" ixy="-2.4130930452109170601e-36" ixz="0" iyy="1.203623407957104718e-07" iyz="0" izz="2.2847261745924535316e-07" />
    </inertial>
  </link>

  <link name="2xl430_gears_3">
    <visual>
      <origin xyz="0 0 0" rpy="0 -0 0" />
      <geometry>
        <mesh filename="../assemblies/left_arm_gripper/meshes/left_2xl430_gears_3_visual.stl" />
      </geometry>
      <material name="2xl430_gears_3_material">
        <color rgba="0.7560598568794409946 0.8580469596269301169 0.91320266199377464478 1.0" />
      </material>
    </visual>
    <inertial>
      <origin xyz="0.00044890447619850030667 0.011579403622961071882 -0.024577423538310830958" rpy="0 0 0" />
      <mass value="0.11800003674524910113" />
      <inertia ixx="3.5767957544053940479e-05" ixy="2.2634512004662083048e-08" ixz="6.5708346020372133283e-07" iyy="2.7482298083236996643e-05" iyz="9.2729623432844559736e-07" izz="3.2770742486673238387e-05" />
    </inertial>
  </link>

  <link name="spur_1m_24t_drive_3">
    <visual>
      <origin xyz="0 0 0" rpy="0 -0 0" />
      <geometry>
        <mesh filename="../assemblies/left_arm_gripper/meshes/left_spur_1m_24t_drive_3_visual.stl" />
      </geometry>
      <material name="spur_1m_24t_drive_3_material">
        <color rgba="0.61568627450980406568 0.81176470588235294379 0.92941176470588238168 1.0" />
      </material>
    </visual>
    <inertial>
      <origin xyz="-7.7516116741234976791e-15 -1.2124421062364700997e-16 0.004794911617840143421" rpy="0 0 0" />
      <mass value="0.0032000000000000001533" />
      <inertia ixx="1.4019331346159892996e-07" ixy="1.6002409922535022317e-15" ixz="-1.7637142966041434778e-36" iyy="1.4019331260388783538e-07" iyz="-4.1141582459556894849e-37" izz="2.3838919844264060647e-07" />
    </inertial>
  </link>

  <joint name="left_wrist_pitch_drive" type="revolute">
    <origin xyz="-1.5244435917471112579e-10 0.024000000358067929973 -0.0080000000000045659587" rpy="-6.8143291540626782613e-14 -7.3946574628751046645e-14 -1.5707963267947160357" />
    <parent link="2xl430_gears_3" />
    <child link="spur_1m_24t_drive_3" />
    <axis xyz="0 0 1" />
    <limit effort="1" velocity="20" lower="-1.9198621771937625091" upper="1.3962634015954635824" />
    <joint_properties friction="0.0" />
  </joint>

  <link name="gripper_connector">
    <visual>
      <origin xyz="0 0 0" rpy="0 -0 0" />
      <geometry>
        <mesh filename="../assemblies/left_arm_gripper/meshes/left_gripper_connector_visual.stl" />
      </geometry>
      <material name="gripper_connector_material">
        <color rgba="0.61568627450980395466 0.81176470588235294379 0.92941176470588238168 1.0" />
      </material>
    </visual>
    <inertial>
      <origin xyz="-0.00020299682521053422947 -0.023971521766976103263 -0.008596986149848028988" rpy="0 0 0" />
      <mass value="0.0099999999999999915345" />
      <inertia ixx="5.3001475666257246734e-06" ixy="-2.3401437868255261042e-08" ixz="-4.811583299767815884e-08" iyy="3.824595446707140777e-06" iyz="1.9316561248438799289e-08" izz="2.2623415168893576625e-06" />
    </inertial>
  </link>

  <link name="left_rail_guide">
    <visual>
      <origin xyz="0 0 0" rpy="0 -0 0" />
      <geometry>
        <mesh filename="../assemblies/left_arm_gripper/meshes/left_rail_guide_visual.stl" />
      </geometry>
      <material name="left_rail_guide_material">
        <color rgba="0.61996873695689813655 0.81385103374119360797 0.93007060508235839258 1.0" />
      </material>
    </visual>
    <inertial>
      <origin xyz="0.0092700665834928343279 0.0022613527845001661111 6.7965382068801947503e-05" rpy="0 0 0" />
      <mass value="0.032142035224833366558" />
      <inertia ixx="7.5992490868921785228e-06" ixy="2.1661862170734318126e-06" ixz="4.0652418928980975783e-06" iyy="2.7370569943527415298e-05" iyz="-9.475778314087232407e-07" izz="3.0022397080929719777e-05" />
    </inertial>
  </link>

  <link name="rail">
    <visual>
      <origin xyz="0 0 0" rpy="0 -0 0" />
      <geometry>
        <mesh filename="../assemblies/left_arm_gripper/meshes/left_rail_visual.stl" />
      </geometry>
      <material name="rail_material">
        <color rgba="0.64705882352941179736 0.64705882352941179736 0.64705882352941179736 1.0" />
      </material>
    </visual>
    <inertial>
      <origin xyz="0.022744777800883877322 -0.01423343940335741048 -0.0079907133176532613161" rpy="0 0 0" />
      <mass value="0.011900000000000000855" />
      <inertia ixx="2.9161025366903536705e-06" ixy="4.4570835808162340167e-09" ixz="-7.5225164550604629609e-07" iyy="3.6201306422454505118e-06" iyz="2.6765050785959864527e-08" izz="4.4681807873990699658e-06" />
    </inertial>
  </link>

  <joint name="left_gripper_pinion" type="prismatic">
    <origin xyz="-0.028872599999999620096 -0.014175000000000003569 -0.0053500000000002712053" rpy="3.141592653589793116 1.5707963267948952257 0" />
    <parent link="left_rail_guide" />
    <child link="rail" />
    <axis xyz="0 0 1" />
    <limit effort="1" velocity="20" lower="-0.036872599999999998432" upper="0" />
    <joint_properties friction="0.0" />
  </joint>

  <link name="rail_2">
    <visual>
      <origin xyz="0 0 0" rpy="0 -0 0" />
      <geometry>
        <mesh filename="../assemblies/left_arm_gripper/meshes/left_rail_2_visual.stl" />
      </geometry>
      <material name="rail_2_material">
        <color rgba="0.64705882352941179736 0.64705882352941179736 0.64705882352941179736 1.0" />
      </material>
    </visual>
    <inertial>
      <origin xyz="0.022744777800883825281 -0.01423343940335741048 -0.0079907133176532335606" rpy="0 0 0" />
      <mass value="0.011900000000000000855" />
      <inertia ixx="2.9161025366903536705e-06" ixy="4.4570835808162340167e-09" ixz="-7.5225164550604629609e-07" iyy="3.6201306422454505118e-06" iyz="2.6765050785959864527e-08" izz="4.4681807873990699658e-06" />
    </inertial>
  </link>

  <joint name="left_gripper_pinion_mirror" type="prismatic">
    <origin xyz="0.062872600000000888887 0.014174999999999993161 -0.0053500000000002434497" rpy="-1.1034025256268857111e-29 1.5707963267948952257 0" />
    <parent link="left_rail_guide" />
    <child link="rail_2" />
    <axis xyz="0 0 1" />
    <limit effort="1" velocity="20" lower="-0.036872599999999998432" upper="0" />
    <joint_properties friction="0.0" />
  </joint>

  <link name="xc330">
    <visual>
      <origin xyz="0 0 0" rpy="0 -0 0" />
      <geometry>
        <mesh filename="../assemblies/left_arm_gripper/meshes/left_xc330_visual.stl" />
      </geometry>
      <material name="xc330_material">
        <color rgba="0.66932535752643762539 0.72911795671409951325 0.67547870389434383487 1.0" />
      </material>
    </visual>
    <inertial>
      <origin xyz="0.0080045171539631747304 -0.015558009851635308529 -0.011717805512819661276" rpy="0 0 0" />
      <mass value="0.026599999993091760775" />
      <inertia ixx="3.8683410666516304709e-06" ixy="-7.7688424002126317042e-10" ixz="5.7969695829202793455e-10" iyy="2.1626767907497041396e-06" iyz="8.3590274790162801869e-09" izz="3.3158761130056369499e-06" />
    </inertial>
  </link>

  <link name="spur_gear_(14_teeth)">
    <visual>
      <origin xyz="0 0 0" rpy="0 -0 0" />
      <geometry>
        <mesh filename="../assemblies/left_arm_gripper/meshes/left_spur_gear_(14_teeth)_visual.stl" />
      </geometry>
      <material name="spur_gear_(14_teeth)_material">
        <color rgba="0.91764705882352926025 0.91764705882352926025 0.91764705882352926025 1.0" />
      </material>
    </visual>
    <inertial>
      <origin xyz="5.0520117134827957628e-09 -3.0586955572509122447e-09 -0.0069037287088334897689" rpy="0 0 0" />
      <mass value="0.0012999999999999999403" />
      <inertia ixx="2.6445547365951358714e-08" ixy="2.5401821979637465349e-10" ixz="1.9678356781359983902e-14" iyy="2.685067914664504757e-08" iyz="-1.1914086607927021171e-14" izz="3.4027434623053041057e-08" />
    </inertial>
  </link>

  <joint name="left_gripper_rack" type="revolute">
    <origin xyz="0.0079999999999986540211 -0.022500000000000068556 -0.020000000000001683098" rpy="-2.5268845972633189624e-15 -1.3993704652363439234e-15 1.9862277411454370245e-15" />
    <parent link="xc330" />
    <child link="spur_gear_(14_teeth)" />
    <axis xyz="0 0 1" />
    <limit effort="1" velocity="20" lower="0" upper="5.2359877559829888227" />
    <joint_properties friction="0.0" />
  </joint>

  <joint name="left_gripper_motor" type="fixed">
    <origin xyz="-0.021949999999999993822 0.022600000000000002032 0.023300000000000042899" rpy="-3.3306690738376151447e-16 -1.8578007987304439296e-17 1.8327083470280543311e-17" />
    <parent link="left_rail_guide" />
    <child link="xc330" />
    <axis xyz="0 0 1" />
    <limit effort="1" velocity="20" />
    <joint_properties friction="0.0" />
  </joint>

  <joint name="left_gripper_fixed" type="fixed">
    <origin xyz="0 -0.037000000000000005107 -0.036000000000000004219" rpy="-1.57079632679489678 -1.570796326794896558 0" />
    <parent link="gripper_connector" />
    <child link="left_rail_guide" />
    <axis xyz="0 0 1" />
    <limit effort="1" velocity="20" />
    <joint_properties friction="0.0" />
  </joint>

  <joint name="left_wrist_roll" type="revolute">
    <origin xyz="0.019000000000008621104 -3.5807914966490272946e-10 -0.02700000015245084678" rpy="-5.342948306010493038e-15 1.5707963267948528152 0" />
    <parent link="2xl430_gears_3" />
    <child link="gripper_connector" />
    <axis xyz="0 0 1" />
    <limit effort="1" velocity="20" lower="-1.9198621771937625091" upper="1.3962634015954635824" />
    <joint_properties friction="0.0" />
  </joint>

  <link name="wrist_bearing_plate">
    <visual>
      <origin xyz="0 0 0" rpy="0 -0 0" />
      <geometry>
        <mesh filename="../assemblies/left_arm_gripper/meshes/left_wrist_bearing_plate_visual.stl" />
      </geometry>
      <material name="wrist_bearing_plate_material">
        <color rgba="0.64496316278892629192 0.69011804996940528945 0.71706771073555886087 1.0" />
      </material>
    </visual>
    <inertial>
      <origin xyz="-0.0075835583121500052886 -0.015499999999999980807 -0.0018386323705903342279" rpy="0 0 0" />
      <mass value="0.0049000367468305548388" />
      <inertia ixx="4.9707430109150150308e-07" ixy="1.0480461077229452081e-22" ixz="1.8100904820813892973e-08" iyy="7.1268523603538616587e-07" iyz="7.4313337734771095754e-24" izz="1.1919657811600115587e-06" />
    </inertial>
  </link>

  <joint name="left_wrist_pitch_fixed" type="fixed">
    <origin xyz="0.015500000000004772113 -6.3837823915946501074e-15 -0.045000000000001996736" rpy="-3.5027536426602388959e-14 -1.2834178164666087642e-13 -1.5707963267947810948" />
    <parent link="2xl430_gears_3" />
    <child link="wrist_bearing_plate" />
    <axis xyz="0 0 1" />
    <limit effort="1" velocity="20" />
    <joint_properties friction="0.0" />
  </joint>

  <joint name="left_wrist_pitch_driven" type="revolute">
    <origin xyz="-2.7755575615628913511e-17 -3.1554436208840472216e-30 -0.0015999999999999972577" rpy="1.8707257964927463223e-14 -2.230976160592272071e-14 -1.570796326794896558" />
    <parent link="spur_1m_24t_driven_3" />
    <child link="2xl430_gears_3" />
    <axis xyz="0 0 1" />
    <limit effort="1" velocity="20" lower="-1.3962634015954635824" upper="1.9198621771937625091" />
    <joint_properties friction="0.0" />
  </joint>

  <joint name="left_wrist_roll_fixed" type="fixed">
    <origin xyz="3.1554436208840472216e-30 -0.025300000000000003042 -0.052000000000000032307" rpy="1.570796326794896558 -1.570796326794896558 0" />
    <parent link="elb_yaw_link" />
    <child link="spur_1m_24t_driven_3" />
    <axis xyz="0 0 1" />
    <limit effort="1" velocity="20" />
    <joint_properties friction="0.0" />
  </joint>

  <joint name="left_elbow_yaw_fixed" type="fixed">
    <origin xyz="0 3.1554436208840472216e-30 0.0016000000000000041966" rpy="-3.1415926535897926719 -1.6686716652751508178e-29 -1.570796326794896558" />
    <parent link="spur_1m_24t_driven_2" />
    <child link="elb_yaw_link" />
    <axis xyz="0 0 1" />
    <limit effort="1" velocity="20" />
    <joint_properties friction="0.0" />
  </joint>

  <joint name="left_elbow_yaw_driven" type="revolute">
    <origin xyz="-3.5806481391009725712e-10 -0.027000000152458666913 -0.018999999999996696615" rpy="1.5707963267946756236 9.436895709310436914e-15 -7.5767000241948220497e-14" />
    <parent link="2xl430_gears_2" />
    <child link="spur_1m_24t_driven_2" />
    <axis xyz="0 0 1" />
    <limit effort="1" velocity="20" lower="-2.6179938779914944114" upper="2.6179938779914944114" />
    <joint_properties friction="0.0" />
  </joint>

  <joint name="left_elbow_roll" type="revolute">
    <origin xyz="0 -0.018999999999999996059 -0.058999999999999983014" rpy="1.570796326794896558 5.5516872419979014276e-14 -4.4351709097753281525e-15" />
    <parent link="sho_yaw_link" />
    <child link="2xl430_gears_2" />
    <axis xyz="0 0 1" />
    <limit effort="1" velocity="20" lower="-1.9198621771937625091" upper="2.4434609527920612138" />
    <joint_properties friction="0.0" />
  </joint>

  <joint name="left_sho_yaw_fixed" type="fixed">
    <origin xyz="-3.4694469519536141888e-18 1.5777218104420236108e-30 0.0016000000000000041966" rpy="3.1415926535897771288 -2.9902758688536131143e-29 -1.1367870242563646532e-30" />
    <parent link="spur_1m_24t_driven" />
    <child link="sho_yaw_link" />
    <axis xyz="0 0 1" />
    <limit effort="1" velocity="20" />
    <joint_properties friction="0.0" />
  </joint>

  <joint name="left_sho_yaw_driven" type="revolute">
    <origin xyz="-3.5806544534944251268e-10 -0.027000000152452456603 -0.01900000000000368755" rpy="1.5707963267949525132 -6.2878911843812520251e-14 1.1213824667586519115e-13" />
    <parent link="2xl430_gears" />
    <child link="spur_1m_24t_driven" />
    <axis xyz="0 0 1" />
    <limit effort="1" velocity="20" lower="-2.6179938779914944114" upper="2.6179938779914944114" />
    <joint_properties friction="0.0" />
  </joint>

  <joint name="left_sho_roll" type="revolute">
    <origin xyz="-0.01899999999999992667 0.00099999999999997031368 0.026999999999999909489" rpy="3.1415926535897913396 1.5707963267948474861 0" />
    <parent link="sho_pitch_link" />
    <child link="2xl430_gears" />
    <axis xyz="0 0 1" />
    <limit effort="1" velocity="20" lower="-1.570796326794896558" upper="0.34906585039886589561" />
    <joint_properties friction="0.0" />
  </joint>


  <link name="sho_pitch_link_2">
    <visual>
      <origin xyz="0 0 0" rpy="0 -0 0" />
      <geometry>
        <mesh filename="../assemblies/right_arm_gripper/meshes/right_sho_pitch_link_visual.stl" />
      </geometry>
      <material name="sho_pitch_link_material">
        <color rgba="0.61568627450980395466 0.81176470588235294379 0.92941176470588238168 1.0" />
      </material>
    </visual>
    <inertial>
      <origin xyz="5.8254247037992103401e-11 -5.1264642561121243568e-05 0.0082440788127094936227" rpy="0 0 0" />
      <mass value="0.0086000000000000000056" />
      <inertia ixx="1.2272887040545796108e-06" ixy="-2.1429944214503845664e-14" ixz="-8.5847198242763822559e-15" iyy="2.9107306060364624323e-06" iyz="7.4623841398183017835e-09" izz="3.0803135950773491928e-06" />
    </inertial>
  </link>

  <link name="2xl430_gears_4">
    <visual>
      <origin xyz="0 0 0" rpy="0 -0 0" />
      <geometry>
        <mesh filename="../assemblies/right_arm_gripper/meshes/right_2xl430_gears_visual.stl" />
      </geometry>
      <material name="2xl430_gears_material">
        <color rgba="0.7560598568794409946 0.8580469596269301169 0.91320266199377464478 1.0" />
      </material>
    </visual>
    <inertial>
      <origin xyz="-0.011579403981033875928 -0.0024225766141437866767 -0.018551095523802622889" rpy="0 0 0" />
      <mass value="0.11800003674524910113" />
      <inertia ixx="2.7482298083236928881e-05" ixy="9.2729623433052696907e-07" ixz="-2.2634512004386817192e-08" iyy="3.2770742486672553985e-05" iyz="-6.5708346020062489801e-07" izz="3.576795754405571586e-05" />
    </inertial>
  </link>

  <link name="spur_1m_24t_drive_4">
    <visual>
      <origin xyz="0 0 0" rpy="0 -0 0" />
      <geometry>
        <mesh filename="../assemblies/right_arm_gripper/meshes/right_spur_1m_24t_drive_visual.stl" />
      </geometry>
      <material name="spur_1m_24t_drive_material">
        <color rgba="0.61568627450980406568 0.81176470588235294379 0.92941176470588238168 1.0" />
      </material>
    </visual>
    <inertial>
      <origin xyz="-7.7516116741234976791e-15 -1.2124421062364720718e-16 0.0047949116178401416863" rpy="0 0 0" />
      <mass value="0.0032000000000000001533" />
      <inertia ixx="1.4019331346159892996e-07" ixy="1.6002409922818087303e-15" ixz="1.5512658169588909582e-36" iyy="1.4019331260388783538e-07" iyz="6.832589472426229927e-37" izz="2.3838919844264060647e-07" />
    </inertial>
  </link>

  <joint name="right_sho_yaw_drive" type="revolute">
    <origin xyz="-0.02400000071613753172 -0.019000000152449930679 -0.01900000015244478202" rpy="1.5707963267947220309 -4.4297106944168913575e-14 6.810646137204639124e-14" />
    <parent link="2xl430_gears_4" />
    <child link="spur_1m_24t_drive_4" />
    <axis xyz="0 0 1" />
    <limit effort="1" velocity="20" lower="-2.6179938779914944114" upper="2.6179938779914944114" />
    <joint_properties friction="0.0" />
  </joint>

  <link name="spur_1m_24t_driven_4">
    <visual>
      <origin xyz="0 0 0" rpy="0 -0 0" />
      <geometry>
        <mesh filename="../assemblies/right_arm_gripper/meshes/right_spur_1m_24t_driven_visual.stl" />
      </geometry>
      <material name="spur_1m_24t_driven_material">
        <color rgba="0.23137254901960788156 0.38039215686274502337 0.7058823529411765163 1.0" />
      </material>
    </visual>
    <inertial>
      <origin xyz="1.9637778540991893625e-18 -5.8049057615352288969e-15 -0.00097054817521927832808" rpy="0 0 0" />
      <mass value="0.0026999999999999997093" />
      <inertia ixx="1.2036234079571065709e-07" ixy="3.0459387528081630637e-37" ixz="-3.0332648475783403611e-37" iyy="1.203623407957104718e-07" iyz="-2.0908704881522101161e-36" izz="2.2847261745924535316e-07" />
    </inertial>
  </link>

  <link name="sho_yaw_link_2">
    <visual>
      <origin xyz="0 0 0" rpy="0 -0 0" />
      <geometry>
        <mesh filename="../assemblies/right_arm_gripper/meshes/right_sho_yaw_link_visual.stl" />
      </geometry>
      <material name="sho_yaw_link_material">
        <color rgba="0.61568627450980395466 0.81176470588235294379 0.92941176470588238168 1.0" />
      </material>
    </visual>
    <inertial>
      <origin xyz="-1.2817564279970693173e-18 -4.2395441168324980763e-19 -0.024303257848520172513" rpy="0 0 0" />
      <mass value="0.014500000000000016348" />
      <inertia ixx="9.0846670053041382782e-06" ixy="3.6224092806404002001e-13" ixz="-7.3094158734906374592e-36" iyy="5.6910950712097533498e-06" iyz="-4.7266869952784907348e-35" izz="4.481960984554899287e-06" />
    </inertial>
  </link>

  <link name="2xl430_gears_5">
    <visual>
      <origin xyz="0 0 0" rpy="0 -0 0" />
      <geometry>
        <mesh filename="../assemblies/right_arm_gripper/meshes/right_2xl430_gears_2_visual.stl" />
      </geometry>
      <material name="2xl430_gears_2_material">
        <color rgba="0.7560598568794409946 0.8580469596269301169 0.91320266199377464478 1.0" />
      </material>
    </visual>
    <inertial>
      <origin xyz="-0.011579403981039848581 -0.0024225766141426031616 -0.018551095523806133969" rpy="0 0 0" />
      <mass value="0.11800003674524910113" />
      <inertia ixx="2.7482298083239717313e-05" ixy="9.2729623432914789355e-07" ixz="-2.2634512003324065467e-08" iyy="3.2770742486673665292e-05" iyz="-6.570834602014093564e-07" izz="3.5767957544057796173e-05" />
    </inertial>
  </link>

  <link name="spur_1m_24t_drive_5">
    <visual>
      <origin xyz="0 0 0" rpy="0 -0 0" />
      <geometry>
        <mesh filename="../assemblies/right_arm_gripper/meshes/right_spur_1m_24t_drive_2_visual.stl" />
      </geometry>
      <material name="spur_1m_24t_drive_2_material">
        <color rgba="0.61568627450980406568 0.81176470588235294379 0.92941176470588238168 1.0" />
      </material>
    </visual>
    <inertial>
      <origin xyz="-7.7516116741234961014e-15 -1.2124421064949660133e-16 0.0047949116178401382168" rpy="0 0 0" />
      <mass value="0.0032000000000000001533" />
      <inertia ixx="1.4019331346159887702e-07" ixy="1.6002409935589451508e-15" ixz="3.4217861399280605448e-38" iyy="1.4019331260388780891e-07" iyz="-5.6275823426893574842e-37" izz="2.3838919844264060647e-07" />
    </inertial>
  </link>

  <joint name="right_elbow_yaw_drive" type="revolute">
    <origin xyz="-0.02400000071614593472 -0.019000000152452525826 -0.019000000152448241059" rpy="1.5707963267948983344 1.6898711261348466559e-13 -7.2725329301663980295e-14" />
    <parent link="2xl430_gears_5" />
    <child link="spur_1m_24t_drive_5" />
    <axis xyz="0 0 1" />
    <limit effort="1" velocity="20" lower="-2.6179938779914944114" upper="2.6179938779914944114" />
    <joint_properties friction="0.0" />
  </joint>

  <link name="spur_1m_24t_driven_5">
    <visual>
      <origin xyz="0 0 0" rpy="0 -0 0" />
      <geometry>
        <mesh filename="../assemblies/right_arm_gripper/meshes/right_spur_1m_24t_driven_2_visual.stl" />
      </geometry>
      <material name="spur_1m_24t_driven_2_material">
        <color rgba="0.23137254901960788156 0.38039215686274502337 0.7058823529411765163 1.0" />
      </material>
    </visual>
    <inertial>
      <origin xyz="1.9637778540993164739e-18 -5.8049057615352265303e-15 -0.00097054817521928168911" rpy="0 0 0" />
      <mass value="0.0026999999999999997093" />
      <inertia ixx="1.2036234079571071003e-07" ixy="2.8999630800741879349e-37" ixz="1.3128544367748221718e-36" iyy="1.203623407957104718e-07" iyz="-2.5130632054411367083e-36" izz="2.2847261745924545904e-07" />
    </inertial>
  </link>

  <link name="elb_yaw_link_2">
    <visual>
      <origin xyz="0 0 0" rpy="0 -0 0" />
      <geometry>
        <mesh filename="../assemblies/right_arm_gripper/meshes/right_elb_yaw_link_visual.stl" />
      </geometry>
      <material name="elb_yaw_link_material">
        <color rgba="0.61568627450980395466 0.81176470588235294379 0.92941176470588227065 1.0" />
      </material>
    </visual>
    <inertial>
      <origin xyz="5.3127688027391931278e-08 0.0019833638641961644222 -0.023416643551549931601" rpy="0 0 0" />
      <mass value="0.017500000000000001665" />
      <inertia ixx="1.4134344903109194693e-05" ixy="1.6945783921965038345e-12" ixz="-1.128639872187510241e-11" iyy="6.6435900776211323463e-06" iyz="1.0545227077253055462e-06" izz="8.9925290757998976773e-06" />
    </inertial>
  </link>

  <link name="spur_1m_24t_driven_6">
    <visual>
      <origin xyz="0 0 0" rpy="0 -0 0" />
      <geometry>
        <mesh filename="../assemblies/right_arm_gripper/meshes/right_spur_1m_24t_driven_3_visual.stl" />
      </geometry>
      <material name="spur_1m_24t_driven_3_material">
        <color rgba="0.23137254901960788156 0.38039215686274502337 0.7058823529411765163 1.0" />
      </material>
    </visual>
    <inertial>
      <origin xyz="-2.5791797761529692948e-17 -5.8049057615352265303e-15 -0.0025705481752192754774" rpy="0 0 0" />
      <mass value="0.0026999999999999997093" />
      <inertia ixx="1.2036234079571065709e-07" ixy="2.3695488040715002324e-36" ixz="-1.6418916509117533046e-37" iyy="1.203623407957104718e-07" iyz="2.6219923247193895907e-37" izz="2.2847261745924535316e-07" />
    </inertial>
  </link>

  <link name="2xl430_gears_6">
    <visual>
      <origin xyz="0 0 0" rpy="0 -0 0" />
      <geometry>
        <mesh filename="../assemblies/right_arm_gripper/meshes/right_2xl430_gears_3_visual.stl" />
      </geometry>
      <material name="2xl430_gears_3_material">
        <color rgba="0.7560598568794409946 0.8580469596269301169 0.91320266199377464478 1.0" />
      </material>
    </visual>
    <inertial>
      <origin xyz="0.00044890447619669408006 0.011579403622970779394 -0.024577423538312447721" rpy="0 0 0" />
      <mass value="0.11800003674524910113" />
      <inertia ixx="3.5767957544055424481e-05" ixy="2.2634512004688532975e-08" ixz="6.5708346020178840365e-07" iyy="2.748229808323665783e-05" iyz="9.2729623433030875221e-07" izz="3.2770742486673733055e-05" />
    </inertial>
  </link>

  <link name="spur_1m_24t_drive_6">
    <visual>
      <origin xyz="0 0 0" rpy="0 -0 0" />
      <geometry>
        <mesh filename="../assemblies/right_arm_gripper/meshes/right_spur_1m_24t_drive_3_visual.stl" />
      </geometry>
      <material name="spur_1m_24t_drive_3_material">
        <color rgba="0.61568627450980406568 0.81176470588235294379 0.92941176470588238168 1.0" />
      </material>
    </visual>
    <inertial>
      <origin xyz="-7.7516116741234961014e-15 -1.2124421064949640411e-16 0.0047949116178401460231" rpy="0 0 0" />
      <mass value="0.0032000000000000001533" />
      <inertia ixx="1.4019331346159887702e-07" ixy="1.6002409922818087303e-15" ixz="-3.3317537353747163282e-37" iyy="1.4019331260388783538e-07" iyz="3.0918437697492268121e-37" izz="2.3838919844264060647e-07" />
    </inertial>
  </link>

  <joint name="right_wrist_pitch_drive" type="revolute">
    <origin xyz="-1.5244750094239886385e-10 0.0240000003580740362 -0.0080000000000028936853" rpy="-2.6466654378983997098e-14 5.3007428237114777825e-14 -1.5707963267948148456" />
    <parent link="2xl430_gears_6" />
    <child link="spur_1m_24t_drive_6" />
    <axis xyz="0 0 1" />
    <limit effort="1" velocity="20" lower="-1.3962634015954635824" upper="1.9198621771937625091" />
    <joint_properties friction="0.0" />
  </joint>

  <link name="gripper_connector_2">
    <visual>
      <origin xyz="0 0 0" rpy="0 -0 0" />
      <geometry>
        <mesh filename="../assemblies/right_arm_gripper/meshes/right_gripper_connector_visual.stl" />
      </geometry>
      <material name="gripper_connector_material">
        <color rgba="0.61568627450980395466 0.81176470588235294379 0.92941176470588238168 1.0" />
      </material>
    </visual>
    <inertial>
      <origin xyz="-0.00020299682521053769892 0.023971521766976103263 -0.029403013850151978742" rpy="0 0 0" />
      <mass value="0.0099999999999999915345" />
      <inertia ixx="5.3001475666257246734e-06" ixy="2.3401437868255261042e-08" ixz="4.811583299767815884e-08" iyy="3.824595446707140777e-06" iyz="1.9316561248438799289e-08" izz="2.2623415168893576625e-06" />
    </inertial>
  </link>

  <link name="right_rail_guide">
    <visual>
      <origin xyz="0 0 0" rpy="0 -0 0" />
      <geometry>
        <mesh filename="../assemblies/right_arm_gripper/meshes/right_rail_guide_visual.stl" />
      </geometry>
      <material name="right_rail_guide_material">
        <color rgba="0.62025753727489985057 0.81399173133201496722 0.93011503590051236579 1.0" />
      </material>
    </visual>
    <inertial>
      <origin xyz="0.0092741550667162046817 -0.0022368973911260671417 1.1465282798785714338e-05" rpy="0 0 0" />
      <mass value="0.030111386261699946837" />
      <inertia ixx="7.0587141071297691507e-06" ixy="-2.0076614642548894021e-06" ixz="3.7679719233345471749e-06" iyy="2.5402123601769114198e-05" iyz="8.8191782705952159154e-07" izz="2.785726023589890857e-05" />
    </inertial>
  </link>

  <link name="rail_3">
    <visual>
      <origin xyz="0 0 0" rpy="0 -0 0" />
      <geometry>
        <mesh filename="../assemblies/right_arm_gripper/meshes/right_rail_visual.stl" />
      </geometry>
      <material name="rail_material">
        <color rgba="0.64705882352941179736 0.64705882352941179736 0.64705882352941179736 1.0" />
      </material>
    </visual>
    <inertial>
      <origin xyz="0.022744777800883853036 -0.01423343940335741048 -0.0079907133176532335606" rpy="0 0 0" />
      <mass value="0.011900000000000000855" />
      <inertia ixx="2.9161025366903536705e-06" ixy="4.4570835808162340167e-09" ixz="-7.5225164550604629609e-07" iyy="3.6201306422454505118e-06" iyz="2.6765050785959864527e-08" izz="4.4681807873990699658e-06" />
    </inertial>
  </link>

  <joint name="right_gripper_pinion" type="prismatic">
    <origin xyz="-0.028872600000001191756 -0.014174999999999993161 -0.005350000000001076117" rpy="-3.141592653589793116 1.5707963267948954478 0" />
    <parent link="right_rail_guide" />
    <child link="rail_3" />
    <axis xyz="0 0 1" />
    <limit effort="1" velocity="20" lower="-0.036872599999999998432" upper="0" />
    <joint_properties friction="0.0" />
  </joint>

  <link name="rail_4">
    <visual>
      <origin xyz="0 0 0" rpy="0 -0 0" />
      <geometry>
        <mesh filename="../assemblies/right_arm_gripper/meshes/right_rail_2_visual.stl" />
      </geometry>
      <material name="rail_2_material">
        <color rgba="0.64705882352941179736 0.64705882352941179736 0.64705882352941179736 1.0" />
      </material>
    </visual>
    <inertial>
      <origin xyz="0.022744777800883853036 -0.014233439403357413949 -0.0079907133176532613161" rpy="0 0 0" />
      <mass value="0.011900000000000000855" />
      <inertia ixx="2.9161025366903536705e-06" ixy="4.4570835808162340167e-09" ixz="-7.5225164550604629609e-07" iyy="3.6201306422454505118e-06" iyz="2.6765050785959864527e-08" izz="4.4681807873990699658e-06" />
    </inertial>
  </link>

  <joint name="right_gripper_pinion_mirror" type="prismatic">
    <origin xyz="0.062872599999998834974 0.01417499999999999663 -0.0053500000000010206058" rpy="9.1593399531549520226e-16 1.5707963267948945596 0" />
    <parent link="right_rail_guide" />
    <child link="rail_4" />
    <axis xyz="0 0 1" />
    <limit effort="1" velocity="20" lower="-0.036872599999999998432" upper="0" />
    <joint_properties friction="0.0" />
  </joint>

  <link name="xc330_2">
    <visual>
      <origin xyz="0 0 0" rpy="0 -0 0" />
      <geometry>
        <mesh filename="../assemblies/right_arm_gripper/meshes/right_xc330_visual.stl" />
      </geometry>
      <material name="xc330_material">
        <color rgba="0.66932535752643762539 0.72911795671409951325 0.67547870389434383487 1.0" />
      </material>
    </visual>
    <inertial>
      <origin xyz="0.0080045171539637055558 -0.015558009851631656936 -0.011717805512818139924" rpy="0 0 0" />
      <mass value="0.026599999993091760775" />
      <inertia ixx="3.868341066651401772e-06" ixy="-7.7688424002228949476e-10" ixz="5.7969695833036041471e-10" iyy="2.1626767907494474886e-06" iyz="8.3590274792902258621e-09" izz="3.3158761130056255149e-06" />
    </inertial>
  </link>

  <link name="spur_gear_(14_teeth)_2">
    <visual>
      <origin xyz="0 0 0" rpy="0 -0 0" />
      <geometry>
        <mesh filename="../assemblies/right_arm_gripper/meshes/right_spur_gear_(14_teeth)_visual.stl" />
      </geometry>
      <material name="spur_gear_(14_teeth)_material">
        <color rgba="0.91764705882352926025 0.91764705882352926025 0.91764705882352926025 1.0" />
      </material>
    </visual>
    <inertial>
      <origin xyz="5.0520117152175192388e-09 -3.0586955537814648792e-09 -0.0069037287088334628807" rpy="0 0 0" />
      <mass value="0.0012999999999999999403" />
      <inertia ixx="2.644554736595136864e-08" ixy="2.5401821979637413651e-10" ixz="1.9678356781359987057e-14" iyy="2.6850679146645054187e-08" iyz="-1.1914086607927024327e-14" izz="3.4027434623053041057e-08" />
    </inertial>
  </link>

  <joint name="right_gripper_rack" type="revolute">
    <origin xyz="0.0079999999999993270938 -0.022499999999995481947 -0.019999999999999684697" rpy="5.6483726968237356019e-16 2.1632341620255480784e-16 1.8833104111286173228e-17" />
    <parent link="xc330_2" />
    <child link="spur_gear_(14_teeth)_2" />
    <axis xyz="0 0 1" />
    <limit effort="1" velocity="20" lower="0" upper="5.2359877559829888227" />
    <joint_properties friction="0.0" />
  </joint>

  <joint name="right_gripper_motor" type="fixed">
    <origin xyz="-0.005949999999999996958 -0.022599999999999995093 0.023299999999999931877" rpy="-3.3306690738751713332e-16 -9.4115114089812621852e-30 -3.141592653589793116" />
    <parent link="right_rail_guide" />
    <child link="xc330_2" />
    <axis xyz="0 0 1" />
    <limit effort="1" velocity="20" />
    <joint_properties friction="0.0" />
  </joint>

  <joint name="right_gripper_fixed" type="fixed">
    <origin xyz="3.4694469519536141888e-18 0.036999999999999977351 -0.0020000000000000017764" rpy="1.570796326794896336 1.570796326794896558 0" />
    <parent link="gripper_connector_2" />
    <child link="right_rail_guide" />
    <axis xyz="0 0 1" />
    <limit effort="1" velocity="20" />
    <joint_properties friction="0.0" />
  </joint>

  <joint name="right_wrist_roll" type="revolute">
    <origin xyz="0.019000000000002677941 -3.5806407838734344296e-10 -0.027000000152454406432" rpy="-3.1415926535897558125 -1.570796326794831721 0" />
    <parent link="2xl430_gears_6" />
    <child link="gripper_connector_2" />
    <axis xyz="0 0 1" />
    <limit effort="1" velocity="20" lower="-1.3962634015954635824" upper="1.9198621771937625091" />
    <joint_properties friction="0.0" />
  </joint>

  <link name="wrist_bearing_plate_2">
    <visual>
      <origin xyz="0 0 0" rpy="0 -0 0" />
      <geometry>
        <mesh filename="../assemblies/right_arm_gripper/meshes/right_wrist_bearing_plate_visual.stl" />
      </geometry>
      <material name="wrist_bearing_plate_material">
        <color rgba="0.64496316278892629192 0.69011804996940528945 0.71706771073555886087 1.0" />
      </material>
    </visual>
    <inertial>
      <origin xyz="-0.0075835583121500035539 -0.015499999999999982542 -0.0018386323705903435521" rpy="0 0 0" />
      <mass value="0.0049000367468305548388" />
      <inertia ixx="4.9707430109150150308e-07" ixy="7.8908790833106419086e-23" ixz="1.8100904820814068335e-08" iyy="7.1268523603538584823e-07" iyz="4.3653874061918244677e-24" izz="1.1919657811600107117e-06" />
    </inertial>
  </link>

  <joint name="right_wrist_pitch_fixed" type="fixed">
    <origin xyz="0.015500000000002131864 9.6866958898544908152e-15 -0.045000000000006430689" rpy="-2.6645352590932944871e-15 1.1984857550828037264e-13 -1.5707963267947835373" />
    <parent link="2xl430_gears_6" />
    <child link="wrist_bearing_plate_2" />
    <axis xyz="0 0 1" />
    <limit effort="1" velocity="20" />
    <joint_properties friction="0.0" />
  </joint>

  <joint name="right_wrist_pitch_driven" type="revolute">
    <origin xyz="-2.7755575615628913511e-17 6.3108872417680944433e-30 -0.0015999999999999992093" rpy="5.5511151231243844462e-16 1.2547220914404902092e-15 1.570796326794896558" />
    <parent link="spur_1m_24t_driven_6" />
    <child link="2xl430_gears_6" />
    <axis xyz="0 0 1" />
    <limit effort="1" velocity="20" lower="-1.9198621771937625091" upper="1.3962634015954635824" />
    <joint_properties friction="0.0" />
  </joint>

  <joint name="right_wrist_roll_fixed" type="fixed">
    <origin xyz="1.5777218104420236108e-30 -0.025299999999999999573 -0.052000000000000004552" rpy="1.5707963267948974462 1.570796326794896558 0" />
    <parent link="elb_yaw_link_2" />
    <child link="spur_1m_24t_driven_6" />
    <axis xyz="0 0 1" />
    <limit effort="1" velocity="20" />
    <joint_properties friction="0.0" />
  </joint>

  <joint name="right_elbow_yaw_fixed" type="fixed">
    <origin xyz="0 7.8886090522101180541e-30 0.0015999999999999764411" rpy="3.141592653589793116 -4.1526642731421539574e-29 -1.570796326794896558" />
    <parent link="spur_1m_24t_driven_5" />
    <child link="elb_yaw_link_2" />
    <axis xyz="0 0 1" />
    <limit effort="1" velocity="20" />
    <joint_properties friction="0.0" />
  </joint>

  <joint name="right_elbow_yaw_driven" type="revolute">
    <origin xyz="-3.5806997991660871605e-10 -0.027000000152456016256 -0.01900000000000036729" rpy="1.5707963267948485964 8.4311697099245782578e-14 3.098094357577576486e-14" />
    <parent link="2xl430_gears_5" />
    <child link="spur_1m_24t_driven_5" />
    <axis xyz="0 0 1" />
    <limit effort="1" velocity="20" lower="-2.6179938779914944114" upper="2.6179938779914944114" />
    <joint_properties friction="0.0" />
  </joint>

  <joint name="right_elbow_roll" type="revolute">
    <origin xyz="-3.4694469519536141888e-18 -0.018999999999999999528 -0.059000000000000010769" rpy="1.570796326794896558 5.4458140093899203203e-15 -1.8535314627675585241e-14" />
    <parent link="sho_yaw_link_2" />
    <child link="2xl430_gears_5" />
    <axis xyz="0 0 1" />
    <limit effort="1" velocity="20" lower="-1.9198621771937625091" upper="2.4434609527920612138" />
    <joint_properties friction="0.0" />
  </joint>

  <joint name="right_sho_yaw_fixed" type="fixed">
    <origin xyz="0 1.1832913578315177081e-30 0.0015999999999999937883" rpy="3.141592653589793116 -1.9721522629860631248e-30 4.8102873877572434203e-28" />
    <parent link="spur_1m_24t_driven_4" />
    <child link="sho_yaw_link_2" />
    <axis xyz="0 0 1" />
    <limit effort="1" velocity="20" />
    <joint_properties friction="0.0" />
  </joint>

  <joint name="right_sho_yaw_driven" type="revolute">
    <origin xyz="-3.5806749579259111727e-10 -0.027000000152448931645 -0.018999999999998073985" rpy="1.5707963267947655517 -4.3564811365923459647e-14 5.9791231064775441371e-14" />
    <parent link="2xl430_gears_4" />
    <child link="spur_1m_24t_driven_4" />
    <axis xyz="0 0 1" />
    <limit effort="1" velocity="20" lower="-2.6179938779914944114" upper="2.6179938779914944114" />
    <joint_properties friction="0.0" />
  </joint>

  <joint name="right_sho_roll" type="revolute">
    <origin xyz="-0.019000000000000002998 0.0010000000000000076102 0.027000000000000003164" rpy="3.141592653589793116 1.5707963267948827912 0" />
    <parent link="sho_pitch_link_2" />
    <child link="2xl430_gears_4" />
    <axis xyz="0 0 1" />
    <limit effort="1" velocity="20" lower="-1.570796326794896558" upper="0.34906585039886589561" />
    <joint_properties friction="0.0" />
  </joint>


</robot>