<?xml version="1.0" ?><robot name="left_arm_gripper">  
  <link name="sho_pitch_link">    
    <visual>      
      <origin xyz="0 0 0" rpy="0 -0 0"/>      
      <geometry>        
        <mesh filename="package:///meshes/left_sho_pitch_link_visual.stl"/>        
      </geometry>      
      <material name="sho_pitch_link_material">        
        <color rgba="0.61568627450980395466 0.81176470588235294379 0.92941176470588227065 1.0"/>        
      </material>      
    </visual>    
    <collision>      
      <origin xyz="0 0 0" rpy="0 -0 0"/>      
      <geometry>        
        <mesh filename="package:///meshes/left_sho_pitch_link_collision.stl"/>        
      </geometry>      
    </collision>    
    <inertial>      
      <origin xyz="5.8254246873150788375e-11 -5.126464256112076923e-05 0.0082440788127094623977" rpy="0 0 0"/>      
      <mass value="0.0085999999999999982708"/>      
      <inertia ixx="1.227288704054570717e-06" ixy="-2.1429936846936260149e-14" ixz="-8.5847198037466179854e-15" iyy="2.91073060603644168e-06" iyz="7.4623841398182339547e-09" izz="3.0803135950773271699e-06"/>      
    </inertial>    
  </link>  

  <link name="2xl430_gears">    
    <visual>      
      <origin xyz="0 0 0" rpy="0 -0 0"/>      
      <geometry>        
        <mesh filename="package:///meshes/left_2xl430_gears_visual.stl"/>        
      </geometry>      
      <material name="2xl430_gears_material">        
        <color rgba="0.75605985687944088358 0.8580469596269301169 0.91320266199377464478 1.0"/>        
      </material>      
    </visual>    
    <collision>      
      <origin xyz="0 0 0" rpy="0 -0 0"/>      
      <geometry>        
        <mesh filename="package:///meshes/left_2xl430_gears_collision.stl"/>        
      </geometry>      
    </collision>    
    <inertial>      
      <origin xyz="-0.011593155021925307877 -0.0024238821558110034554 -0.018551095523803389636" rpy="0 0 0"/>      
      <mass value="0.11800003674524907338"/>      
      <inertia ixx="2.751155493265798339e-05" ixy="8.9994756795164863381e-07" ixz="-2.3362914880703854757e-08" iyy="3.2796647067986400479e-05" iyz="-6.5715261571594833988e-07" izz="3.5775886684228084308e-05"/>      
    </inertial>    
  </link>  

  <link name="spur_1m_24t_drive">    
    <visual>      
      <origin xyz="0 0 0" rpy="0 -0 0"/>      
      <geometry>        
        <mesh filename="package:///meshes/left_spur_1m_24t_drive_visual.stl"/>        
      </geometry>      
      <material name="spur_1m_24t_drive_material">        
        <color rgba="0.61568627450980406568 0.81176470588235294379 0.92941176470588238168 1.0"/>        
      </material>      
    </visual>    
    <collision>      
      <origin xyz="0 0 0" rpy="0 -0 0"/>      
      <geometry>        
        <mesh filename="package:///meshes/left_spur_1m_24t_drive_collision.stl"/>        
      </geometry>      
    </collision>    
    <inertial>      
      <origin xyz="-7.751924474065288114e-15 -1.2114309579847422764e-16 0.0047949116178401416863" rpy="0 0 0"/>      
      <mass value="0.0032000000000000001533"/>      
      <inertia ixx="1.4019331346159890349e-07" ixy="1.6002410034001928083e-15" ixz="1.5136309552610142149e-39" iyy="1.4019331260388783538e-07" iyz="6.9662242597476870103e-37" izz="2.3838919844264060647e-07"/>      
    </inertial>    
  </link>  

  <joint name="left_sho_yaw_drive" type="revolute">    
    <origin xyz="-0.024000000716138950724 -0.019000000152455242403 -0.019000000152449656593" rpy="1.5707963267949347497 -1.1101908380030466199e-13 1.6989069920292087694e-13"/>    
    <parent link="2xl430_gears"/>    
    <child link="spur_1m_24t_drive"/>    
    <axis xyz="0 0 1"/>    
    <limit effort="1" velocity="20" lower="-2.6179938779914944114" upper="2.6179938779914944114"/>    
    <joint_properties friction="0.0"/>    
  </joint>  

  <link name="spur_1m_24t_driven">    
    <visual>      
      <origin xyz="0 0 0" rpy="0 -0 0"/>      
      <geometry>        
        <mesh filename="package:///meshes/left_spur_1m_24t_driven_visual.stl"/>        
      </geometry>      
      <material name="spur_1m_24t_driven_material">        
        <color rgba="0.23137254901960788156 0.38039215686274502337 0.7058823529411765163 1.0"/>        
      </material>      
    </visual>    
    <collision>      
      <origin xyz="0 0 0" rpy="0 -0 0"/>      
      <geometry>        
        <mesh filename="package:///meshes/left_spur_1m_24t_driven_collision.stl"/>        
      </geometry>      
    </collision>    
    <inertial>      
      <origin xyz="5.7091470979890261114e-18 -5.804960647391017135e-15 -0.00097054817521927832808" rpy="0 0 0"/>      
      <mass value="0.0026999999999999997093"/>      
      <inertia ixx="1.2036234079571065709e-07" ixy="1.6408341064672930469e-66" ixz="2.2551452241402898336e-55" iyy="1.203623407957104718e-07" iyz="2.7479639504561275735e-37" izz="2.2847261745924535316e-07"/>      
    </inertial>    
  </link>  

  <link name="sho_yaw_link">    
    <visual>      
      <origin xyz="0 0 0" rpy="0 -0 0"/>      
      <geometry>        
        <mesh filename="package:///meshes/left_sho_yaw_link_visual.stl"/>        
      </geometry>      
      <material name="sho_yaw_link_material">        
        <color rgba="0.61568627450980395466 0.81176470588235294379 0.92941176470588238168 1.0"/>        
      </material>      
    </visual>    
    <collision>      
      <origin xyz="0 0 0" rpy="0 -0 0"/>      
      <geometry>        
        <mesh filename="package:///meshes/left_sho_yaw_link_collision.stl"/>        
      </geometry>      
    </collision>    
    <inertial>      
      <origin xyz="-4.751203379950773447e-18 4.0208771290527341071e-18 -0.024303257848520172513" rpy="0 0 0"/>      
      <mass value="0.014500000000000012879"/>      
      <inertia ixx="9.0846670053041365841e-06" ixy="3.6224092806453171386e-13" ixz="5.9333186453476727638e-36" iyy="5.6910950712097533498e-06" iyz="-1.9029679338117402528e-35" izz="4.48196098455489844e-06"/>      
    </inertial>    
  </link>  

  <link name="2xl430_gears_2">    
    <visual>      
      <origin xyz="0 0 0" rpy="0 -0 0"/>      
      <geometry>        
        <mesh filename="package:///meshes/left_2xl430_gears_2_visual.stl"/>        
      </geometry>      
      <material name="2xl430_gears_2_material">        
        <color rgba="0.75605985687944088358 0.8580469596269301169 0.91320266199377464478 1.0"/>        
      </material>      
    </visual>    
    <collision>      
      <origin xyz="0 0 0" rpy="0 -0 0"/>      
      <geometry>        
        <mesh filename="package:///meshes/left_2xl430_gears_2_collision.stl"/>        
      </geometry>      
    </collision>    
    <inertial>      
      <origin xyz="-0.011593155021926340037 -0.002423882155816466967 -0.018551095523806168663" rpy="0 0 0"/>      
      <mass value="0.11800003674524907338"/>      
      <inertia ixx="2.7511554932663722885e-05" ixy="8.9994756795153809601e-07" ixz="-2.3362914880347826295e-08" iyy="3.2796647067987172973e-05" iyz="-6.5715261571566765433e-07" izz="3.5775886684234135511e-05"/>      
    </inertial>    
  </link>  

  <link name="spur_1m_24t_drive_2">    
    <visual>      
      <origin xyz="0 0 0" rpy="0 -0 0"/>      
      <geometry>        
        <mesh filename="package:///meshes/left_spur_1m_24t_drive_2_visual.stl"/>        
      </geometry>      
      <material name="spur_1m_24t_drive_2_material">        
        <color rgba="0.61568627450980406568 0.81176470588235294379 0.92941176470588238168 1.0"/>        
      </material>      
    </visual>    
    <collision>      
      <origin xyz="0 0 0" rpy="0 -0 0"/>      
      <geometry>        
        <mesh filename="package:///meshes/left_spur_1m_24t_drive_2_collision.stl"/>        
      </geometry>      
    </collision>    
    <inertial>      
      <origin xyz="-7.7519244740652865362e-15 -1.2114309579847422764e-16 0.0047949116178401382168" rpy="0 0 0"/>      
      <mass value="0.0032000000000000001533"/>      
      <inertia ixx="1.4019331346159885055e-07" ixy="1.6002410034284993069e-15" ixz="-3.2416262881106824717e-38" iyy="1.4019331260388783538e-07" iyz="4.1976192478617136215e-37" izz="2.3838919844264060647e-07"/>      
    </inertial>    
  </link>  

  <joint name="left_elbow_yaw_drive" type="revolute">    
    <origin xyz="-0.02400000071614135505 -0.019000000152460394531 -0.019000000152444573853" rpy="1.5707963267946161157 -5.9253031636290665624e-14 1.2139740875094224707e-13"/>    
    <parent link="2xl430_gears_2"/>    
    <child link="spur_1m_24t_drive_2"/>    
    <axis xyz="0 0 1"/>    
    <limit effort="1" velocity="20" lower="-2.6179938779914944114" upper="2.6179938779914944114"/>    
    <joint_properties friction="0.0"/>    
  </joint>  

  <link name="spur_1m_24t_driven_2">    
    <visual>      
      <origin xyz="0 0 0" rpy="0 -0 0"/>      
      <geometry>        
        <mesh filename="package:///meshes/left_spur_1m_24t_driven_2_visual.stl"/>        
      </geometry>      
      <material name="spur_1m_24t_driven_2_material">        
        <color rgba="0.23137254901960788156 0.38039215686274502337 0.7058823529411765163 1.0"/>        
      </material>      
    </visual>    
    <collision>      
      <origin xyz="0 0 0" rpy="0 -0 0"/>      
      <geometry>        
        <mesh filename="package:///meshes/left_spur_1m_24t_driven_2_collision.stl"/>        
      </geometry>      
    </collision>    
    <inertial>      
      <origin xyz="5.7091470979893912677e-18 -5.8049606473910179238e-15 -0.00097054817521925740298" rpy="0 0 0"/>      
      <mass value="0.0026999999999999997093"/>      
      <inertia ixx="1.2036234079571065709e-07" ixy="-5.3408894126442329247e-38" ixz="3.3351189727368676324e-36" iyy="1.203623407957104718e-07" iyz="3.0056945361268646547e-36" izz="2.2847261745924535316e-07"/>      
    </inertial>    
  </link>  

  <link name="elb_yaw_link">    
    <visual>      
      <origin xyz="0 0 0" rpy="0 -0 0"/>      
      <geometry>        
        <mesh filename="package:///meshes/left_elb_yaw_link_visual.stl"/>        
      </geometry>      
      <material name="elb_yaw_link_material">        
        <color rgba="0.61568627450980395466 0.81176470588235294379 0.92941176470588227065 1.0"/>        
      </material>      
    </visual>    
    <collision>      
      <origin xyz="0 0 0" rpy="0 -0 0"/>      
      <geometry>        
        <mesh filename="package:///meshes/left_elb_yaw_link_collision.stl"/>        
      </geometry>      
    </collision>    
    <inertial>      
      <origin xyz="5.3127688027384996195e-08 0.0019833638641961696264 -0.023416643551549952418" rpy="0 0 0"/>      
      <mass value="0.017500000000000001665"/>      
      <inertia ixx="1.4134344903109199776e-05" ixy="1.6945783921921611363e-12" ixz="-1.1286398721829634941e-11" iyy="6.6435900776211331934e-06" iyz="1.0545227077253057579e-06" izz="8.9925290757998976773e-06"/>      
    </inertial>    
  </link>  

  <link name="spur_1m_24t_driven_3">    
    <visual>      
      <origin xyz="0 0 0" rpy="0 -0 0"/>      
      <geometry>        
        <mesh filename="package:///meshes/left_spur_1m_24t_driven_3_visual.stl"/>        
      </geometry>      
      <material name="spur_1m_24t_driven_3_material">        
        <color rgba="0.23137254901960788156 0.38039215686274502337 0.7058823529411765163 1.0"/>        
      </material>      
    </visual>    
    <collision>      
      <origin xyz="0 0 0" rpy="0 -0 0"/>      
      <geometry>        
        <mesh filename="package:///meshes/left_spur_1m_24t_driven_3_collision.stl"/>        
      </geometry>      
    </collision>    
    <inertial>      
      <origin xyz="2.2397001460354111522e-18 -5.8049606473910210793e-15 -0.0025705481752192754774" rpy="0 0 0"/>      
      <mass value="0.0026999999999999997093"/>      
      <inertia ixx="1.2036234079571065709e-07" ixy="2.1796004720792485879e-36" ixz="0" iyy="1.203623407957104718e-07" iyz="0" izz="2.2847261745924535316e-07"/>      
    </inertial>    
  </link>  

  <link name="2xl430_gears_3">    
    <visual>      
      <origin xyz="0 0 0" rpy="0 -0 0"/>      
      <geometry>        
        <mesh filename="package:///meshes/left_2xl430_gears_3_visual.stl"/>        
      </geometry>      
      <material name="2xl430_gears_3_material">        
        <color rgba="0.75605985687944088358 0.8580469596269301169 0.91320266199377464478 1.0"/>        
      </material>      
    </visual>    
    <collision>      
      <origin xyz="0 0 0" rpy="0 -0 0"/>      
      <geometry>        
        <mesh filename="package:///meshes/left_2xl430_gears_3_collision.stl"/>        
      </geometry>      
    </collision>    
    <inertial>      
      <origin xyz="0.00044890447619516156029 0.011593154663849485411 -0.024576117996641503455" rpy="0 0 0"/>      
      <mass value="0.11800003674524907338"/>      
      <inertia ixx="3.5775886684226098863e-05" ixy="2.3362914880997275572e-08" ixz="6.5715261571779836571e-07" iyy="2.7511554932658664405e-05" iyz="8.9994756794793968829e-07" izz="3.2796647067986251401e-05"/>      
    </inertial>    
  </link>  

  <link name="spur_1m_24t_drive_3">    
    <visual>      
      <origin xyz="0 0 0" rpy="0 -0 0"/>      
      <geometry>        
        <mesh filename="package:///meshes/left_spur_1m_24t_drive_3_visual.stl"/>        
      </geometry>      
      <material name="spur_1m_24t_drive_3_material">        
        <color rgba="0.61568627450980406568 0.81176470588235294379 0.92941176470588238168 1.0"/>        
      </material>      
    </visual>    
    <collision>      
      <origin xyz="0 0 0" rpy="0 -0 0"/>      
      <geometry>        
        <mesh filename="package:///meshes/left_spur_1m_24t_drive_3_collision.stl"/>        
      </geometry>      
    </collision>    
    <inertial>      
      <origin xyz="-7.7519244740652865362e-15 -1.211430957726248335e-16 0.0047949116178401416863" rpy="0 0 0"/>      
      <mass value="0.0032000000000000001533"/>      
      <inertia ixx="1.4019331346159885055e-07" ixy="1.6002410034284993069e-15" ixz="2.2014519551203998152e-37" iyy="1.4019331260388783538e-07" iyz="3.8157944246850799043e-36" izz="2.3838919844264060647e-07"/>      
    </inertial>    
  </link>  

  <joint name="left_wrist_pitch_drive" type="revolute">    
    <origin xyz="-1.524465101755677821e-10 0.024000000358068068751 -0.0080000000000026785796" rpy="-3.4898578787177992303e-14 -1.1183585769436423028e-13 -1.5707963267948532593"/>    
    <parent link="2xl430_gears_3"/>    
    <child link="spur_1m_24t_drive_3"/>    
    <axis xyz="0 0 1"/>    
    <limit effort="1" velocity="20" lower="-1.9198621771937625091" upper="1.3962634015954635824"/>    
    <joint_properties friction="0.0"/>    
  </joint>  

  <link name="gripper_connector">    
    <visual>      
      <origin xyz="0 0 0" rpy="0 -0 0"/>      
      <geometry>        
        <mesh filename="package:///meshes/left_gripper_connector_visual.stl"/>        
      </geometry>      
      <material name="gripper_connector_material">        
        <color rgba="0.61568627450980395466 0.81176470588235294379 0.92941176470588227065 1.0"/>        
      </material>      
    </visual>    
    <collision>      
      <origin xyz="0 0 0" rpy="0 -0 0"/>      
      <geometry>        
        <mesh filename="package:///meshes/left_gripper_connector_collision.stl"/>        
      </geometry>      
    </collision>    
    <inertial>      
      <origin xyz="-0.00020216391502726472869 -0.024011997737921234736 -0.008709915010078308345" rpy="0 0 0"/>      
      <mass value="0.0099999999999999880651"/>      
      <inertia ixx="5.3138306577478889962e-06" ixy="-2.3224171675565346272e-08" ixz="-4.7690345371182966176e-08" iyy="3.8402250096486075095e-06" iyz="8.1160112886319393595e-09" izz="2.257315404231779922e-06"/>      
    </inertial>    
  </link>  

  <link name="left_rail_guide">    
    <visual>      
      <origin xyz="0 0 0" rpy="0 -0 0"/>      
      <geometry>        
        <mesh filename="package:///meshes/left_rail_guide_visual.stl"/>        
      </geometry>      
      <material name="left_rail_guide_material">        
        <color rgba="0.62010923588394006867 0.81391948193641916465 0.93009222030190319419 1.0"/>        
      </material>      
    </visual>    
    <collision>      
      <origin xyz="0 0 0" rpy="0 -0 0"/>      
      <geometry>        
        <mesh filename="package:///meshes/left_rail_guide_collision.stl"/>        
      </geometry>      
    </collision>    
    <inertial>      
      <origin xyz="0.010819518839780863095 0.0021116106205359610332 -7.6871709864948780874e-05" rpy="0 0 0"/>      
      <mass value="0.031121017612416677217"/>      
      <inertia ixx="7.8532725551086577254e-06" ixy="2.0671876731375216749e-06" ixz="4.0098876287871823871e-06" iyy="2.7330594711584456634e-05" iyz="-8.9062740055664990295e-07" izz="3.0532648647413083228e-05"/>      
    </inertial>    
  </link>  

  <link name="rail">    
    <visual>      
      <origin xyz="0 0 0" rpy="0 -0 0"/>      
      <geometry>        
        <mesh filename="package:///meshes/left_rail_visual.stl"/>        
      </geometry>      
      <material name="rail_material">        
        <color rgba="0.64705882352941179736 0.64705882352941179736 0.64705882352941179736 1.0"/>        
      </material>      
    </visual>    
    <collision>      
      <origin xyz="0 0 0" rpy="0 -0 0"/>      
      <geometry>        
        <mesh filename="package:///meshes/left_rail_collision.stl"/>        
      </geometry>      
    </collision>    
    <inertial>      
      <origin xyz="0.029554714214719193105 -0.015933051259988686987 -0.010638774525132295434" rpy="0 0 0"/>      
      <mass value="0.017100000000000000616"/>      
      <inertia ixx="3.6591938331681695171e-06" ixy="2.1013138412446668144e-08" ixz="-1.1335092663308587465e-07" iyy="4.7380338190523256316e-06" iyz="3.1225833654311333417e-08" izz="6.0956112819844617947e-06"/>      
    </inertial>    
  </link>  

  <joint name="left_gripper_pinion" type="prismatic">    
    <origin xyz="-0.028871320518249775355 -0.015974999999999996148 -0.0053499999999999936495" rpy="3.141592653589793116 1.570796326794896558 0"/>    
    <parent link="left_rail_guide"/>    
    <child link="rail"/>    
    <axis xyz="0 0 1"/>    
    <limit effort="1" velocity="20" lower="-0.025000000000000001388" upper="0"/>    
    <joint_properties friction="0.0"/>    
  </joint>  

  <link name="rail_2">    
    <visual>      
      <origin xyz="0 0 0" rpy="0 -0 0"/>      
      <geometry>        
        <mesh filename="package:///meshes/left_rail_2_visual.stl"/>        
      </geometry>      
      <material name="rail_2_material">        
        <color rgba="0.64705882352941179736 0.64705882352941179736 0.64705882352941179736 1.0"/>        
      </material>      
    </visual>    
    <collision>      
      <origin xyz="0 0 0" rpy="0 -0 0"/>      
      <geometry>        
        <mesh filename="package:///meshes/left_rail_2_collision.stl"/>        
      </geometry>      
    </collision>    
    <inertial>      
      <origin xyz="0.029554714214719193105 -0.015933051259988697396 -0.010638774525132281557" rpy="0 0 0"/>      
      <mass value="0.017100000000000000616"/>      
      <inertia ixx="3.6591938331681695171e-06" ixy="2.1013138412446668144e-08" ixz="-1.1335092663308587465e-07" iyy="4.7380338190523256316e-06" iyz="3.1225833654311333417e-08" izz="6.0956112819844617947e-06"/>      
    </inertial>    
  </link>  

  <joint name="left_gripper_pinion_mirror" type="prismatic">    
    <origin xyz="0.062871320518249770859 0.015974999999999985739 -0.0053500000000000214051" rpy="1.1102230221252498237e-15 1.5707963267948945596 0"/>    
    <parent link="left_rail_guide"/>    
    <child link="rail_2"/>    
    <axis xyz="0 0 1"/>    
    <limit effort="1" velocity="20" lower="-0.025000000000000001388" upper="0"/>    
    <joint_properties friction="0.0"/>    
  </joint>  

  <link name="xc330">    
    <visual>      
      <origin xyz="0 0 0" rpy="0 -0 0"/>      
      <geometry>        
        <mesh filename="package:///meshes/left_xc330_visual.stl"/>        
      </geometry>      
      <material name="xc330_material">        
        <color rgba="0.66932535752643773641 0.72911795671409962427 0.67547870389434394589 1.0"/>        
      </material>      
    </visual>    
    <collision>      
      <origin xyz="0 0 0" rpy="0 -0 0"/>      
      <geometry>        
        <mesh filename="package:///meshes/left_xc330_collision.stl"/>        
      </geometry>      
    </collision>    
    <inertial>      
      <origin xyz="0.0080045171539631868735 -0.01555800985163530159 -0.011717805512819572805" rpy="0 0 0"/>      
      <mass value="0.026599999993091753836"/>      
      <inertia ixx="3.8683410666516236946e-06" ixy="-7.7688424002135933017e-10" ixz="5.7969695829235746263e-10" iyy="2.1626767907496969398e-06" iyz="8.3590274790162570258e-09" izz="3.3158761130056377969e-06"/>      
    </inertial>    
  </link>  

  <link name="spur_gear_(18_teeth)">    
    <visual>      
      <origin xyz="0 0 0" rpy="0 -0 0"/>      
      <geometry>        
        <mesh filename="package:///meshes/left_spur_gear_(18_teeth)_visual.stl"/>        
      </geometry>      
      <material name="spur_gear_(18_teeth)_material">        
        <color rgba="0.9176470588235294823 0.9176470588235294823 0.9176470588235294823 1.0"/>        
      </material>      
    </visual>    
    <collision>      
      <origin xyz="0 0 0" rpy="0 -0 0"/>      
      <geometry>        
        <mesh filename="package:///meshes/left_spur_gear_(18_teeth)_collision.stl"/>        
      </geometry>      
    </collision>    
    <inertial>      
      <origin xyz="5.0306980803327405738e-17 -3.4694469519536141888e-17 -0.0025000000000000078583" rpy="0 0 0"/>      
      <mass value="0.0012999999999999997235"/>      
      <inertia ixx="3.3282842836137704968e-08" ixy="-1.5826540657942491103e-22" ixz="-3.6198314729072587281e-36" iyy="3.3282842836137460123e-08" iyz="-3.4530272508340887177e-36" izz="6.1149428795799502273e-08"/>      
    </inertial>    
  </link>  

  <joint name="left_gripper_rack" type="revolute">    
    <origin xyz="0.0079999999999981093179 -0.022499999999998899353 -0.026000000000001910472" rpy="-4.0807662443141075328e-13 -9.9724131645857233152e-14 -3.1414504889509453633"/>    
    <parent link="xc330"/>    
    <child link="spur_gear_(18_teeth)"/>    
    <axis xyz="0 0 1"/>    
    <limit effort="1" velocity="20" lower="0" upper="2.7052603405912107881"/>    
    <joint_properties friction="0.0"/>    
  </joint>  

  <joint name="left_gripper_motor" type="fixed">    
    <origin xyz="-0.021950000000000011169 0.022600000000000005501 0.023300000000000015143" rpy="-1.6486811914946399887e-14 2.2796676555695055158e-29 7.4715529378013142912e-30"/>    
    <parent link="left_rail_guide"/>    
    <child link="xc330"/>    
    <axis xyz="0 0 1"/>    
    <limit effort="1" velocity="20"/>    
    <joint_properties friction="0.0"/>    
  </joint>  

  <joint name="left_gripper_fixed" type="fixed">    
    <origin xyz="-3.4694469519536141888e-18 -0.037000000000000005107 -0.03599999999999999728" rpy="-1.5707963267949005548 -1.570796326794896558 0"/>    
    <parent link="gripper_connector"/>    
    <child link="left_rail_guide"/>    
    <axis xyz="0 0 1"/>    
    <limit effort="1" velocity="20"/>    
    <joint_properties friction="0.0"/>    
  </joint>  

  <joint name="left_wrist_roll" type="revolute">    
    <origin xyz="0.019000000000007195161 -3.5808220277822044864e-10 -0.027000000152449490226" rpy="-5.3970549458090308007e-14 1.5707963267947446795 0"/>    
    <parent link="2xl430_gears_3"/>    
    <child link="gripper_connector"/>    
    <axis xyz="0 0 1"/>    
    <limit effort="1" velocity="20" lower="-1.9198621771937625091" upper="1.3962634015954635824"/>    
    <joint_properties friction="0.0"/>    
  </joint>  

  <link name="wrist_bearing_plate">    
    <visual>      
      <origin xyz="0 0 0" rpy="0 -0 0"/>      
      <geometry>        
        <mesh filename="package:///meshes/left_wrist_bearing_plate_visual.stl"/>        
      </geometry>      
      <material name="wrist_bearing_plate_material">        
        <color rgba="0.64496316278892629192 0.69011804996940528945 0.71706771073555886087 1.0"/>        
      </material>      
    </visual>    
    <collision>      
      <origin xyz="0 0 0" rpy="0 -0 0"/>      
      <geometry>        
        <mesh filename="package:///meshes/left_wrist_bearing_plate_collision.stl"/>        
      </geometry>      
    </collision>    
    <inertial>      
      <origin xyz="-0.007583558312149987074 -0.015499999999999982542 -0.0018386323705903372637" rpy="0 0 0"/>      
      <mass value="0.0049000367468305539714"/>      
      <inertia ixx="4.9707430109150118544e-07" ixy="4.7110040070984789389e-23" ixz="1.8100904820814111348e-08" iyy="7.1268523603538584823e-07" iyz="4.2334274165733609005e-24" izz="1.1919657811600109234e-06"/>      
    </inertial>    
  </link>  

  <joint name="left_wrist_pitch_fixed" type="fixed">    
    <origin xyz="0.015500000000001472669 -8.0768725041480138316e-15 -0.045000000000001538769" rpy="-1.2656542480600718277e-14 -1.2834178164666988836e-13 -1.5707963267947810948"/>    
    <parent link="2xl430_gears_3"/>    
    <child link="wrist_bearing_plate"/>    
    <axis xyz="0 0 1"/>    
    <limit effort="1" velocity="20"/>    
    <joint_properties friction="0.0"/>    
  </joint>  

  <joint name="left_wrist_pitch_driven" type="revolute">    
    <origin xyz="2.498001805406602216e-16 -5.6819448290618985486e-18 -0.0016000000000000941854" rpy="1.8490899618380516719e-26 6.1232339920953384913e-17 -1.570796326794896558"/>    
    <parent link="spur_1m_24t_driven_3"/>    
    <child link="2xl430_gears_3"/>    
    <axis xyz="0 0 1"/>    
    <limit effort="1" velocity="20" lower="-1.3962634015954635824" upper="1.9198621771937625091"/>    
    <joint_properties friction="0.0"/>    
  </joint>  

  <joint name="left_wrist_roll_fixed" type="fixed">    
    <origin xyz="6.3108872417680944433e-30 -0.025299999999999999573 -0.052000000000000004552" rpy="1.570796326794896558 -1.570796326794896558 0"/>    
    <parent link="elb_yaw_link"/>    
    <child link="spur_1m_24t_driven_3"/>    
    <axis xyz="0 0 1"/>    
    <limit effort="1" velocity="20"/>    
    <joint_properties friction="0.0"/>    
  </joint>  

  <joint name="left_elbow_yaw_fixed" type="fixed">    
    <origin xyz="9.7144514654701197287e-17 5.6819448291407846392e-18 0.0016000000000002539968" rpy="-3.1415926535897926719 1.2755178505055691328e-27 -1.570796326794896558"/>    
    <parent link="spur_1m_24t_driven_2"/>    
    <child link="elb_yaw_link"/>    
    <axis xyz="0 0 1"/>    
    <limit effort="1" velocity="20"/>    
    <joint_properties friction="0.0"/>    
  </joint>  

  <joint name="left_elbow_yaw_driven" type="revolute">    
    <origin xyz="-3.5806304796159871273e-10 -0.027000000152460831848 -0.018999999999996988048" rpy="1.5707963267946301045 -3.8036180281220305768e-14 1.8379912246256679584e-14"/>    
    <parent link="2xl430_gears_2"/>    
    <child link="spur_1m_24t_driven_2"/>    
    <axis xyz="0 0 1"/>    
    <limit effort="1" velocity="20" lower="-2.6179938779914944114" upper="2.6179938779914944114"/>    
    <joint_properties friction="0.0"/>    
  </joint>  

  <joint name="left_elbow_roll" type="revolute">    
    <origin xyz="-1.2143064331837649661e-16 -0.019000000000000016875 -0.058999999999999802602" rpy="1.570796326794896558 8.9045607763570843759e-14 2.3927006918192705097e-15"/>    
    <parent link="sho_yaw_link"/>    
    <child link="2xl430_gears_2"/>    
    <axis xyz="0 0 1"/>    
    <limit effort="1" velocity="20" lower="-1.9198621771937625091" upper="2.4434609527920612138"/>    
    <joint_properties friction="0.0"/>    
  </joint>  

  <joint name="left_sho_yaw_fixed" type="fixed">    
    <origin xyz="1.2143064331837649661e-16 -1.4233300923361624448e-17 0.0016000000000002158329" rpy="-3.1415926535897891192 -2.394464083135350357e-30 7.6661985808523846341e-30"/>    
    <parent link="spur_1m_24t_driven"/>    
    <child link="sho_yaw_link"/>    
    <axis xyz="0 0 1"/>    
    <limit effort="1" velocity="20"/>    
    <joint_properties friction="0.0"/>    
  </joint>  

  <joint name="left_sho_yaw_driven" type="revolute">    
    <origin xyz="-3.5806543841054860877e-10 -0.027000000152452467012 -0.019000000000003677142" rpy="1.5707963267949525132 -6.2878911843811245451e-14 8.8990096612435574527e-14"/>    
    <parent link="2xl430_gears"/>    
    <child link="spur_1m_24t_driven"/>    
    <axis xyz="0 0 1"/>    
    <limit effort="1" velocity="20" lower="-2.6179938779914944114" upper="2.6179938779914944114"/>    
    <joint_properties friction="0.0"/>    
  </joint>  

  <joint name="left_sho_roll" type="revolute">    
    <origin xyz="-0.01899999999999986422 0.00099999999999969275792 0.02700000000000003092" rpy="3.1415926535897900074 1.5707963267948166219 0"/>    
    <parent link="sho_pitch_link"/>    
    <child link="2xl430_gears"/>    
    <axis xyz="0 0 1"/>    
    <limit effort="1" velocity="20" lower="-1.570796326794896558" upper="0.34906585039886589561"/>    
    <joint_properties friction="0.0"/>    
  </joint>  


</robot>