<robot name="toddlerbot_arms">
  <mujoco>
    <compiler strippath="false" balanceinertia="true" discardvisual="false" />
  </mujoco>
  <link name="torso">
    <visual>
      <origin xyz="0 0 0" rpy="0 -0 0" />
      <geometry>
        <mesh filename="../assemblies/toddlerbot_arms/meshes/torso_visual.stl" />
      </geometry>
      <material name="torso_material">
        <color rgba="0.57568355636757850835 0.73346695530923944339 0.85632171014496005768 1.0" />
      </material>
    </visual>
    <inertial>
      <origin xyz="-0.009112547361055770706 0.003604904945319456315 0.074699753823106354589" rpy="0 0 0" />
      <mass value="0.60023307803583569875" />
      <inertia ixx="0.0016765069535889785303" ixy="-3.7938097719290492563e-05" ixz="-8.3104173875696863154e-05" iyy="0.0013166750851799557606" iyz="5.6366295515428055016e-05" izz="0.0012679724848085589892" />
    </inertial>
  </link>

  <joint name="left_sho_pitch" type="revolute">
    <origin xyz="-0.0030000000000002949654 0.062000000000001082023 0.10423651076281742478" rpy="-1.5707963267949081043 -4.0958527081001641839e-14 3.5234047634505718213e-14" />
    <parent link="torso" />
    <child link="sho_pitch_link" />
    <axis xyz="0 0 1" />
    <limit effort="1" velocity="20" lower="-3.141592653589793116" upper="1.570796326794896558" />
    <joint_properties friction="0.0" />
  </joint>

  <joint name="right_sho_pitch" type="revolute">
    <origin xyz="-0.0029999999999986998872 -0.06200000000000097794 0.10423651076281731376" rpy="-1.5707963267948885644 3.4812325502379109658e-14 -3.1415926535897562566" />
    <parent link="torso" />
    <child link="sho_pitch_link_2" />
    <axis xyz="0 0 1" />
    <limit effort="1" velocity="20" lower="-1.570796326794896558" upper="3.141592653589793116" />
    <joint_properties friction="0.0" />
  </joint>


  <link name="sho_pitch_link">
    <visual>
      <origin xyz="0 0 0" rpy="0 -0 0" />
      <geometry>
        <mesh filename="../assemblies/left_arm_hand/meshes/left_sho_pitch_link_visual.stl" />
      </geometry>
      <material name="sho_pitch_link_material">
        <color rgba="0.61568627450980395466 0.81176470588235294379 0.92941176470588227065 1.0" />
      </material>
    </visual>
    <inertial>
      <origin xyz="5.8254247124065067049e-11 -5.1264642561121189358e-05 0.008244078812709491888" rpy="0 0 0" />
      <mass value="0.0085999999999999948014" />
      <inertia ixx="1.2272887040545791873e-06" ixy="-2.1429944214128713904e-14" ixz="-8.5847197933828805347e-15" iyy="2.9107306060364615853e-06" iyz="7.4623841398183150184e-09" izz="3.0803135950773483457e-06" />
    </inertial>
  </link>

  <link name="2xl430_gears">
    <visual>
      <origin xyz="0 0 0" rpy="0 -0 0" />
      <geometry>
        <mesh filename="../assemblies/left_arm_hand/meshes/left_2xl430_gears_visual.stl" />
      </geometry>
      <material name="2xl430_gears_material">
        <color rgba="0.7560598568794409946 0.8580469596269301169 0.91320266199377464478 1.0" />
      </material>
    </visual>
    <inertial>
      <origin xyz="-0.011579403981037360988 -0.0024225766141417266926 -0.018551095523800655712" rpy="0 0 0" />
      <mass value="0.11800003674524910113" />
      <inertia ixx="2.7482298083236793355e-05" ixy="9.27296234328931159e-07" ixz="-2.2634512003524385451e-08" iyy="3.2770742486672269382e-05" iyz="-6.5708346020024807423e-07" izz="3.5767957544055383823e-05" />
    </inertial>
  </link>

  <link name="spur_1m_24t_drive">
    <visual>
      <origin xyz="0 0 0" rpy="0 -0 0" />
      <geometry>
        <mesh filename="../assemblies/left_arm_hand/meshes/left_spur_1m_24t_drive_visual.stl" />
      </geometry>
      <material name="spur_1m_24t_drive_material">
        <color rgba="0.61568627450980406568 0.81176470588235294379 0.92941176470588238168 1.0" />
      </material>
    </visual>
    <inertial>
      <origin xyz="-7.7521299884412313712e-15 -1.2124789402396008467e-16 0.0047949116178401416863" rpy="0 0 0" />
      <mass value="0.0032000000000000001533" />
      <inertia ixx="1.4019331346159887702e-07" ixy="1.6002409981164973256e-15" ixz="4.7946470804245936281e-36" iyy="1.4019331260388780891e-07" iyz="5.8892187466235131117e-38" izz="2.3838919844264060647e-07" />
    </inertial>
  </link>

  <joint name="left_sho_yaw_drive" type="revolute">
    <origin xyz="-0.024000000716141008106 -0.019000000152450610691 -0.019000000152443286688" rpy="1.5707963267948328312 -1.2293716347296049066e-15 1.010090991001174754e-13" />
    <parent link="2xl430_gears" />
    <child link="spur_1m_24t_drive" />
    <axis xyz="0 0 1" />
    <limit effort="1" velocity="20" lower="-2.6179938779914944114" upper="2.6179938779914944114" />
    <joint_properties friction="0.0" />
  </joint>

  <link name="spur_1m_24t_driven">
    <visual>
      <origin xyz="0 0 0" rpy="0 -0 0" />
      <geometry>
        <mesh filename="../assemblies/left_arm_hand/meshes/left_spur_1m_24t_driven_visual.stl" />
      </geometry>
      <material name="spur_1m_24t_driven_material">
        <color rgba="0.23137254901960788156 0.38039215686274507888 0.7058823529411765163 1.0" />
      </material>
    </visual>
    <inertial>
      <origin xyz="2.2397001460355586784e-18 -5.8049232035347791036e-15 -0.00097054817521928168911" rpy="0 0 0" />
      <mass value="0.0027000000000000001429" />
      <inertia ixx="1.2036234079571068356e-07" ixy="2.3143854122158616772e-37" ixz="1.997945151452848074e-36" iyy="1.203623407957104718e-07" iyz="7.4023932797854780927e-38" izz="2.2847261745924537963e-07" />
    </inertial>
  </link>

  <link name="sho_yaw_link">
    <visual>
      <origin xyz="0 0 0" rpy="0 -0 0" />
      <geometry>
        <mesh filename="../assemblies/left_arm_hand/meshes/left_sho_yaw_link_visual.stl" />
      </geometry>
      <material name="sho_yaw_link_material">
        <color rgba="0.61568627450980395466 0.81176470588235294379 0.92941176470588238168 1.0" />
      </material>
    </visual>
    <inertial>
      <origin xyz="-1.2817564279971507841e-18 4.7153820572931408839e-18 -0.024303257848520172513" rpy="0 0 0" />
      <mass value="0.014500000000000011144" />
      <inertia ixx="9.0846670053041365841e-06" ixy="3.6224092806394641693e-13" ixz="-1.1169724140036854531e-42" iyy="5.6910950712097533498e-06" iyz="-1.6823666350894933297e-35" izz="4.481960984554900134e-06" />
    </inertial>
  </link>

  <link name="2xl430_gears_2">
    <visual>
      <origin xyz="0 0 0" rpy="0 -0 0" />
      <geometry>
        <mesh filename="../assemblies/left_arm_hand/meshes/left_2xl430_gears_2_visual.stl" />
      </geometry>
      <material name="2xl430_gears_2_material">
        <color rgba="0.7560598568794409946 0.8580469596269301169 0.91320266199377464478 1.0" />
      </material>
    </visual>
    <inertial>
      <origin xyz="-0.011579403981035896881 -0.0024225766141403115919 -0.018551095523804770476" rpy="0 0 0" />
      <mass value="0.11800003674524910113" />
      <inertia ixx="2.7482298083236654442e-05" ixy="9.2729623433076445593e-07" ixz="-2.2634512003936003758e-08" iyy="3.2770742486673190954e-05" iyz="-6.5708346020168083046e-07" izz="3.5767957544054929813e-05" />
    </inertial>
  </link>

  <link name="spur_1m_24t_drive_2">
    <visual>
      <origin xyz="0 0 0" rpy="0 -0 0" />
      <geometry>
        <mesh filename="../assemblies/left_arm_hand/meshes/left_spur_1m_24t_drive_2_visual.stl" />
      </geometry>
      <material name="spur_1m_24t_drive_2_material">
        <color rgba="0.61568627450980406568 0.81176470588235294379 0.92941176470588238168 1.0" />
      </material>
    </visual>
    <inertial>
      <origin xyz="-7.7451910945373241428e-15 -1.2124789399811088775e-16 0.0047949116178401382168" rpy="0 0 0" />
      <mass value="0.0032000000000000001533" />
      <inertia ixx="1.4019331346159882408e-07" ixy="1.6002410021796695823e-15" ixz="7.2624323102412275718e-37" iyy="1.4019331260388786185e-07" iyz="-1.913237371173209661e-36" izz="2.3838919844264060647e-07" />
    </inertial>
  </link>

  <joint name="left_elbow_yaw_drive" type="revolute">
    <origin xyz="-0.024000000716141021984 -0.019000000152448556778 -0.019000000152448459634" rpy="1.5707963267949303088 5.3222446619528222415e-15 1.3540958880671982531e-14" />
    <parent link="2xl430_gears_2" />
    <child link="spur_1m_24t_drive_2" />
    <axis xyz="0 0 1" />
    <limit effort="1" velocity="20" lower="-2.6179938779914944114" upper="2.6179938779914944114" />
    <joint_properties friction="0.0" />
  </joint>

  <link name="spur_1m_24t_driven_2">
    <visual>
      <origin xyz="0 0 0" rpy="0 -0 0" />
      <geometry>
        <mesh filename="../assemblies/left_arm_hand/meshes/left_spur_1m_24t_driven_2_visual.stl" />
      </geometry>
      <material name="spur_1m_24t_driven_2_material">
        <color rgba="0.23137254901960788156 0.38039215686274507888 0.7058823529411765163 1.0" />
      </material>
    </visual>
    <inertial>
      <origin xyz="2.2397001460329243915e-18 -5.8016925627086605558e-15 -0.00097054817521926087243" rpy="0 0 0" />
      <mass value="0.0027000000000000001429" />
      <inertia ixx="1.2036234079571068356e-07" ixy="9.9602247399529490245e-51" ixz="-1.0366477169058966631e-36" iyy="1.203623407957104718e-07" iyz="-1.2085112922539601106e-37" izz="2.2847261745924537963e-07" />
    </inertial>
  </link>

  <link name="elb_yaw_link">
    <visual>
      <origin xyz="0 0 0" rpy="0 -0 0" />
      <geometry>
        <mesh filename="../assemblies/left_arm_hand/meshes/left_elb_yaw_link_visual.stl" />
      </geometry>
      <material name="elb_yaw_link_material">
        <color rgba="0.61568627450980395466 0.81176470588235294379 0.92941176470588238168 1.0" />
      </material>
    </visual>
    <inertial>
      <origin xyz="5.3127688027629610046e-08 0.0019833638641961717948 -0.023416643551549959357" rpy="0 0 0" />
      <mass value="0.017500000000000012074" />
      <inertia ixx="1.4134344903109206552e-05" ixy="1.6945783921985188756e-12" ixz="-1.128639872184044645e-11" iyy="6.6435900776211374285e-06" iyz="1.054522707725306605e-06" izz="8.9925290757999027595e-06" />
    </inertial>
  </link>

  <link name="spur_1m_24t_driven_3">
    <visual>
      <origin xyz="0 0 0" rpy="0 -0 0" />
      <geometry>
        <mesh filename="../assemblies/left_arm_hand/meshes/left_spur_1m_24t_driven_3_visual.stl" />
      </geometry>
      <material name="spur_1m_24t_driven_3_material">
        <color rgba="0.23137254901960788156 0.38039215686274507888 0.7058823529411765163 1.0" />
      </material>
    </visual>
    <inertial>
      <origin xyz="2.2397001460355906489e-18 -5.8049232035347830479e-15 -0.0025705481752192789469" rpy="0 0 0" />
      <mass value="0.0027000000000000001429" />
      <inertia ixx="1.203623407957107365e-07" ixy="-7.335444030144370941e-37" ixz="2.7470302194174380249e-36" iyy="1.203623407957104718e-07" iyz="1.1009077040348589054e-36" izz="2.2847261745924548551e-07" />
    </inertial>
  </link>

  <link name="2xl430_gears_3">
    <visual>
      <origin xyz="0 0 0" rpy="0 -0 0" />
      <geometry>
        <mesh filename="../assemblies/left_arm_hand/meshes/left_2xl430_gears_3_visual.stl" />
      </geometry>
      <material name="2xl430_gears_3_material">
        <color rgba="0.7560598568794409946 0.8580469596269301169 0.91320266199377464478 1.0" />
      </material>
    </visual>
    <inertial>
      <origin xyz="0.00044890447620269448856 0.011579403622953165012 -0.02457742353830994278" rpy="0 0 0" />
      <mass value="0.11800003674524910113" />
      <inertia ixx="3.5767957544054848498e-05" ixy="2.2634512003715232562e-08" ixz="6.5708346020249281742e-07" iyy="2.7482298083237877558e-05" iyz="9.272962343322649748e-07" izz="3.2770742486671869582e-05" />
    </inertial>
  </link>

  <link name="spur_1m_24t_drive_3">
    <visual>
      <origin xyz="0 0 0" rpy="0 -0 0" />
      <geometry>
        <mesh filename="../assemblies/left_arm_hand/meshes/left_spur_1m_24t_drive_3_visual.stl" />
      </geometry>
      <material name="spur_1m_24t_drive_3_material">
        <color rgba="0.61568627450980406568 0.81176470588235294379 0.92941176470588238168 1.0" />
      </material>
    </visual>
    <inertial>
      <origin xyz="-7.7521299884412313712e-15 -1.2124789402396008467e-16 0.0047949116178401416863" rpy="0 0 0" />
      <mass value="0.0032000000000000001533" />
      <inertia ixx="1.4019331346159887702e-07" ixy="1.6002410001197768567e-15" ixz="1.603015804855940346e-36" iyy="1.4019331260388783538e-07" iyz="-1.0287878595714031604e-36" izz="2.3838919844264060647e-07" />
    </inertial>
  </link>

  <joint name="left_wrist_pitch_drive" type="revolute">
    <origin xyz="-1.5244060454932558359e-10 0.024000000358057327343 -0.0080000000000068800798" rpy="3.9435158482369467881e-14 -2.1741514499400786903e-13 -1.5707963267949176522" />
    <parent link="2xl430_gears_3" />
    <child link="spur_1m_24t_drive_3" />
    <axis xyz="0 0 1" />
    <limit effort="1" velocity="20" lower="-1.9198621771937625091" upper="1.3962634015954635824" />
    <joint_properties friction="0.0" />
  </joint>

  <link name="hand">
    <visual>
      <origin xyz="0 0 0" rpy="0 -0 0" />
      <geometry>
        <mesh filename="../assemblies/left_arm_hand/meshes/left_hand_visual.stl" />
      </geometry>
      <material name="hand_material">
        <color rgba="0.61568627450980395466 0.81176470588235294379 0.9294117647058824927 1.0" />
      </material>
    </visual>
    <inertial>
      <origin xyz="-2.489950859175186028e-10 0.040594531666389023494 0.019479063914252029571" rpy="0 0 0" />
      <mass value="0.017000000000001444511" />
      <inertia ixx="9.218759418532233686e-06" ixy="-1.5922040974697183607e-15" ixz="-1.0539511471482342536e-13" iyy="6.6718567758212696226e-06" iyz="2.1533596775200800956e-08" izz="3.7788698411876589991e-06" />
    </inertial>
  </link>

  <joint name="left_wrist_roll" type="revolute">
    <origin xyz="0.019000000000007042505 -3.5808098153289336096e-10 -0.027000000152448057344" rpy="-3.1415926535897193972 1.5707963267946853936 0" />
    <parent link="2xl430_gears_3" />
    <child link="hand" />
    <axis xyz="0 0 1" />
    <limit effort="1" velocity="20" lower="-1.9198621771937625091" upper="1.3962634015954635824" />
    <joint_properties friction="0.0" />
  </joint>

  <link name="wrist_bearing_plate">
    <visual>
      <origin xyz="0 0 0" rpy="0 -0 0" />
      <geometry>
        <mesh filename="../assemblies/left_arm_hand/meshes/left_wrist_bearing_plate_visual.stl" />
      </geometry>
      <material name="wrist_bearing_plate_material">
        <color rgba="0.64496316278892629192 0.69011804996940528945 0.71706771073555886087 1.0" />
      </material>
    </visual>
    <inertial>
      <origin xyz="-0.0075835583121499827372 -0.015499999999999982542 -0.0018386323705903337943" rpy="0 0 0" />
      <mass value="0.0049000367468305539714" />
      <inertia ixx="4.9707430109150118544e-07" ixy="1.0162545076855676242e-22" ixz="1.8100904820814134509e-08" iyy="7.1268523603538510707e-07" iyz="-1.077720286065327804e-22" izz="1.1919657811600104999e-06" />
    </inertial>
  </link>

  <joint name="left_wrist_pitch_fixed" type="fixed">
    <origin xyz="0.015500000000007823492 -1.8068879725774422695e-14 -0.044999999999998908928" rpy="5.4234394758357771884e-14 -2.8213542612434265448e-13 -1.570796326794906328" />
    <parent link="2xl430_gears_3" />
    <child link="wrist_bearing_plate" />
    <axis xyz="0 0 1" />
    <limit effort="1" velocity="20" />
    <joint_properties friction="0.0" />
  </joint>

  <joint name="left_wrist_pitch_driven" type="revolute">
    <origin xyz="-2.7755575615628913511e-17 -2.6687419884003641171e-18 -0.0015999999999999992093" rpy="-1.2490008944217178404e-15 -8.8817841970011517436e-16 -1.570796326794896558" />
    <parent link="spur_1m_24t_driven_3" />
    <child link="2xl430_gears_3" />
    <axis xyz="0 0 1" />
    <limit effort="1" velocity="20" lower="-1.3962634015954635824" upper="1.9198621771937625091" />
    <joint_properties friction="0.0" />
  </joint>

  <joint name="left_wrist_roll_fixed" type="fixed">
    <origin xyz="-2.6687419884121970307e-18 -0.025299999999999999573 -0.052000000000000032307" rpy="1.5707963267948976682 -1.5707963267948956698 0" />
    <parent link="elb_yaw_link" />
    <child link="spur_1m_24t_driven_3" />
    <axis xyz="0 0 1" />
    <limit effort="1" velocity="20" />
    <joint_properties friction="0.0" />
  </joint>

  <joint name="left_elbow_yaw_fixed" type="fixed">
    <origin xyz="2.6687419884145636134e-18 3.4694469519536141888e-18 0.0015999999999999903189" rpy="-3.141592653589793116 -7.7295713056774243222e-29 -3.8634032214012514384e-29" />
    <parent link="spur_1m_24t_driven_2" />
    <child link="elb_yaw_link" />
    <axis xyz="0 0 1" />
    <limit effort="1" velocity="20" />
    <joint_properties friction="0.0" />
  </joint>

  <joint name="left_elbow_yaw_driven" type="revolute">
    <origin xyz="-3.5806928949666527728e-10 -0.027000000152451103519 -0.019000000000003354483" rpy="1.5707963267948781283 1.57079632679478709 0" />
    <parent link="2xl430_gears_2" />
    <child link="spur_1m_24t_driven_2" />
    <axis xyz="0 0 1" />
    <limit effort="1" velocity="20" lower="-2.6179938779914944114" upper="2.6179938779914944114" />
    <joint_properties friction="0.0" />
  </joint>

  <joint name="left_elbow_roll" type="revolute">
    <origin xyz="1.1865508575681360526e-15 -0.018999999999999999528 -0.059000000000000024647" rpy="1.570796326794896558 -3.0035063655217005852e-13 -8.0812793815154920791e-14" />
    <parent link="sho_yaw_link" />
    <child link="2xl430_gears_2" />
    <axis xyz="0 0 1" />
    <limit effort="1" velocity="20" lower="-1.9198621771937625091" upper="2.4434609527920612138" />
    <joint_properties friction="0.0" />
  </joint>

  <joint name="left_sho_yaw_fixed" type="fixed">
    <origin xyz="-3.4694469519536141888e-18 3.9443045261050590271e-31 0.0016000000000000007272" rpy="3.1415926535897873428 -0 0" />
    <parent link="spur_1m_24t_driven" />
    <child link="sho_yaw_link" />
    <axis xyz="0 0 1" />
    <limit effort="1" velocity="20" />
    <joint_properties friction="0.0" />
  </joint>

  <joint name="left_sho_yaw_driven" type="revolute">
    <origin xyz="-3.5806878642685724401e-10 -0.027000000152450916169 -0.018999999999999881567" rpy="1.5707963267948492625 7.9618117061835143528e-14 1.0891287871571481832e-13" />
    <parent link="2xl430_gears" />
    <child link="spur_1m_24t_driven" />
    <axis xyz="0 0 1" />
    <limit effort="1" velocity="20" lower="-2.6179938779914944114" upper="2.6179938779914944114" />
    <joint_properties friction="0.0" />
  </joint>

  <joint name="left_sho_roll" type="revolute">
    <origin xyz="-0.018999999999999999528 0.0010000000000000084776 0.027000000000001016243" rpy="-3.141592653589793116 1.5707963267945652674 0" />
    <parent link="sho_pitch_link" />
    <child link="2xl430_gears" />
    <axis xyz="0 0 1" />
    <limit effort="1" velocity="20" lower="-1.570796326794896558" upper="0.34906585039886589561" />
    <joint_properties friction="0.0" />
  </joint>


  <link name="sho_pitch_link_2">
    <visual>
      <origin xyz="0 0 0" rpy="0 -0 0" />
      <geometry>
        <mesh filename="../assemblies/right_arm_hand/meshes/right_sho_pitch_link_visual.stl" />
      </geometry>
      <material name="sho_pitch_link_material">
        <color rgba="0.61568627450980395466 0.81176470588235294379 0.92941176470588227065 1.0" />
      </material>
    </visual>
    <inertial>
      <origin xyz="5.8254247124065067049e-11 -5.1264642561121189358e-05 0.008244078812709491888" rpy="0 0 0" />
      <mass value="0.0085999999999999948014" />
      <inertia ixx="1.2272887040545791873e-06" ixy="-2.1429944214128713904e-14" ixz="-8.5847197933828805347e-15" iyy="2.9107306060364615853e-06" iyz="7.4623841398183150184e-09" izz="3.0803135950773483457e-06" />
    </inertial>
  </link>

  <link name="2xl430_gears_4">
    <visual>
      <origin xyz="0 0 0" rpy="0 -0 0" />
      <geometry>
        <mesh filename="../assemblies/right_arm_hand/meshes/right_2xl430_gears_visual.stl" />
      </geometry>
      <material name="2xl430_gears_material">
        <color rgba="0.7560598568794409946 0.8580469596269301169 0.91320266199377464478 1.0" />
      </material>
    </visual>
    <inertial>
      <origin xyz="-0.011579403981034309609 -0.0024225766141400444445 -0.018551095523803729642" rpy="0 0 0" />
      <mass value="0.11800003674524910113" />
      <inertia ixx="2.74822980832362953e-05" ixy="9.2729623432968279486e-07" ixz="-2.2634512004040774455e-08" iyy="3.2770742486672703063e-05" iyz="-6.5708346020122078569e-07" izz="3.5767957544054489356e-05" />
    </inertial>
  </link>

  <link name="spur_1m_24t_drive_4">
    <visual>
      <origin xyz="0 0 0" rpy="0 -0 0" />
      <geometry>
        <mesh filename="../assemblies/right_arm_hand/meshes/right_spur_1m_24t_drive_visual.stl" />
      </geometry>
      <material name="spur_1m_24t_drive_material">
        <color rgba="0.61568627450980406568 0.81176470588235294379 0.92941176470588238168 1.0" />
      </material>
    </visual>
    <inertial>
      <origin xyz="-7.7451910945373241428e-15 -1.2124789402396028189e-16 0.0047949116178401460231" rpy="0 0 0" />
      <mass value="0.0032000000000000001533" />
      <inertia ixx="1.4019331346159882408e-07" ixy="1.6002410021796695823e-15" ixz="1.6522681797794394156e-36" iyy="1.4019331260388786185e-07" iyz="-8.3216796199689805911e-37" izz="2.3838919844264060647e-07" />
    </inertial>
  </link>

  <joint name="right_sho_yaw_drive" type="revolute">
    <origin xyz="-0.024000000716138239487 -0.019000000152445333662 -0.019000000152448428409" rpy="1.5707963267949289765 -7.4034293748640148514e-14 5.4343716361633809931e-15" />
    <parent link="2xl430_gears_4" />
    <child link="spur_1m_24t_drive_4" />
    <axis xyz="0 0 1" />
    <limit effort="1" velocity="20" lower="-2.6179938779914944114" upper="2.6179938779914944114" />
    <joint_properties friction="0.0" />
  </joint>

  <link name="spur_1m_24t_driven_4">
    <visual>
      <origin xyz="0 0 0" rpy="0 -0 0" />
      <geometry>
        <mesh filename="../assemblies/right_arm_hand/meshes/right_spur_1m_24t_driven_visual.stl" />
      </geometry>
      <material name="spur_1m_24t_driven_material">
        <color rgba="0.23137254901960788156 0.38039215686274507888 0.7058823529411765163 1.0" />
      </material>
    </visual>
    <inertial>
      <origin xyz="2.2397001460354111522e-18 -5.8049232035347791036e-15 -0.00097054817521928168911" rpy="0 0 0" />
      <mass value="0.0027000000000000001429" />
      <inertia ixx="1.2036234079571068356e-07" ixy="0" ixz="0" iyy="1.203623407957104718e-07" iyz="5.3440906710062142366e-38" izz="2.2847261745924537963e-07" />
    </inertial>
  </link>

  <link name="sho_yaw_link_2">
    <visual>
      <origin xyz="0 0 0" rpy="0 -0 0" />
      <geometry>
        <mesh filename="../assemblies/right_arm_hand/meshes/right_sho_yaw_link_visual.stl" />
      </geometry>
      <material name="sho_yaw_link_material">
        <color rgba="0.61568627450980395466 0.81176470588235294379 0.92941176470588238168 1.0" />
      </material>
    </visual>
    <inertial>
      <origin xyz="-4.7512033799507649729e-18 4.7153820572931216247e-18 -0.024303257848520158635" rpy="0 0 0" />
      <mass value="0.014500000000000011144" />
      <inertia ixx="9.0846670053041365841e-06" ixy="3.6224092806394641693e-13" ixz="4.2856349173565158757e-43" iyy="5.6910950712097533498e-06" iyz="4.9879708115840714241e-36" izz="4.481960984554900134e-06" />
    </inertial>
  </link>

  <link name="2xl430_gears_5">
    <visual>
      <origin xyz="0 0 0" rpy="0 -0 0" />
      <geometry>
        <mesh filename="../assemblies/right_arm_hand/meshes/right_2xl430_gears_2_visual.stl" />
      </geometry>
      <material name="2xl430_gears_2_material">
        <color rgba="0.7560598568794409946 0.8580469596269301169 0.91320266199377464478 1.0" />
      </material>
    </visual>
    <inertial>
      <origin xyz="-0.011579403981040218077 -0.0024225766141398393134 -0.018551095523805894577" rpy="0 0 0" />
      <mass value="0.11800003674524910113" />
      <inertia ixx="2.7482298083237697987e-05" ixy="9.2729623432884147938e-07" ixz="-2.2634512003741295368e-08" iyy="3.2770742486673699173e-05" iyz="-6.5708346020153291733e-07" izz="3.5767957544055736189e-05" />
    </inertial>
  </link>

  <link name="spur_1m_24t_drive_5">
    <visual>
      <origin xyz="0 0 0" rpy="0 -0 0" />
      <geometry>
        <mesh filename="../assemblies/right_arm_hand/meshes/right_spur_1m_24t_drive_2_visual.stl" />
      </geometry>
      <material name="spur_1m_24t_drive_2_material">
        <color rgba="0.61568627450980406568 0.81176470588235294379 0.92941176470588238168 1.0" />
      </material>
    </visual>
    <inertial>
      <origin xyz="-7.7590688823451385996e-15 -1.2124789402396028189e-16 0.0047949116178401382168" rpy="0 0 0" />
      <mass value="0.0032000000000000001533" />
      <inertia ixx="1.4019331346159882408e-07" ixy="1.6002410021796695823e-15" ixz="-1.1681704812628662087e-35" iyy="1.4019331260388786185e-07" iyz="2.4795678825907445192e-36" izz="2.3838919844264060647e-07" />
    </inertial>
  </link>

  <joint name="right_elbow_yaw_drive" type="revolute">
    <origin xyz="-0.024000000716147155966 -0.019000000152450832736 -0.019000000152450298441" rpy="1.5707963267949571762 2.9595367256237359919e-14 -6.4343145465762955833e-14" />
    <parent link="2xl430_gears_5" />
    <child link="spur_1m_24t_drive_5" />
    <axis xyz="0 0 1" />
    <limit effort="1" velocity="20" lower="-2.6179938779914944114" upper="2.6179938779914944114" />
    <joint_properties friction="0.0" />
  </joint>

  <link name="spur_1m_24t_driven_5">
    <visual>
      <origin xyz="0 0 0" rpy="0 -0 0" />
      <geometry>
        <mesh filename="../assemblies/right_arm_hand/meshes/right_spur_1m_24t_driven_2_visual.stl" />
      </geometry>
      <material name="spur_1m_24t_driven_2_material">
        <color rgba="0.23137254901960788156 0.38039215686274507888 0.7058823529411765163 1.0" />
      </material>
    </visual>
    <inertial>
      <origin xyz="-1.2297468059182030366e-18 -5.8049232035347814702e-15 -0.000970548175219288628" rpy="0 0 0" />
      <mass value="0.0027000000000000001429" />
      <inertia ixx="1.2036234079571068356e-07" ixy="0" ixz="0" iyy="1.203623407957104718e-07" iyz="-8.2412659182369258854e-37" izz="2.2847261745924537963e-07" />
    </inertial>
  </link>

  <link name="elb_yaw_link_2">
    <visual>
      <origin xyz="0 0 0" rpy="0 -0 0" />
      <geometry>
        <mesh filename="../assemblies/right_arm_hand/meshes/right_elb_yaw_link_visual.stl" />
      </geometry>
      <material name="elb_yaw_link_material">
        <color rgba="0.61568627450980395466 0.81176470588235294379 0.92941176470588238168 1.0" />
      </material>
    </visual>
    <inertial>
      <origin xyz="5.3127688027629610046e-08 0.0019833638641961683254 -0.023416643551549973234" rpy="0 0 0" />
      <mass value="0.017500000000000012074" />
      <inertia ixx="1.4134344903109206552e-05" ixy="1.6945783921985188756e-12" ixz="-1.128639872184044645e-11" iyy="6.6435900776211374285e-06" iyz="1.054522707725306605e-06" izz="8.9925290757999027595e-06" />
    </inertial>
  </link>

  <link name="spur_1m_24t_driven_6">
    <visual>
      <origin xyz="0 0 0" rpy="0 -0 0" />
      <geometry>
        <mesh filename="../assemblies/right_arm_hand/meshes/right_spur_1m_24t_driven_3_visual.stl" />
      </geometry>
      <material name="spur_1m_24t_driven_3_material">
        <color rgba="0.23137254901960788156 0.38039215686274507888 0.7058823529411765163 1.0" />
      </material>
    </visual>
    <inertial>
      <origin xyz="2.2397001460354119226e-18 -5.8049232035347814702e-15 -0.0025705481752192824163" rpy="0 0 0" />
      <mass value="0.0027000000000000001429" />
      <inertia ixx="1.2036234079571068356e-07" ixy="-7.6954038306055239825e-37" ixz="6.0796998427618674805e-36" iyy="1.203623407957104718e-07" iyz="2.9665199080575648941e-38" izz="2.2847261745924537963e-07" />
    </inertial>
  </link>

  <link name="2xl430_gears_6">
    <visual>
      <origin xyz="0 0 0" rpy="0 -0 0" />
      <geometry>
        <mesh filename="../assemblies/right_arm_hand/meshes/right_2xl430_gears_3_visual.stl" />
      </geometry>
      <material name="2xl430_gears_3_material">
        <color rgba="0.7560598568794409946 0.8580469596269301169 0.91320266199377464478 1.0" />
      </material>
    </visual>
    <inertial>
      <origin xyz="0.00044890447620021274979 0.011579403622967100046 -0.024577423538309651346" rpy="0 0 0" />
      <mass value="0.11800003674524910113" />
      <inertia ixx="3.5767957544056081778e-05" ixy="2.2634512003692971477e-08" ixz="6.5708346020098224004e-07" iyy="2.7482298083237135557e-05" iyz="9.2729623433063051885e-07" izz="3.2770742486673123191e-05" />
    </inertial>
  </link>

  <link name="spur_1m_24t_drive_6">
    <visual>
      <origin xyz="0 0 0" rpy="0 -0 0" />
      <geometry>
        <mesh filename="../assemblies/right_arm_hand/meshes/right_spur_1m_24t_drive_3_visual.stl" />
      </geometry>
      <material name="spur_1m_24t_drive_3_material">
        <color rgba="0.61568627450980406568 0.81176470588235294379 0.92941176470588238168 1.0" />
      </material>
    </visual>
    <inertial>
      <origin xyz="-7.7521299884412313712e-15 -1.2124789402396028189e-16 0.004794911617840143421" rpy="0 0 0" />
      <mass value="0.0032000000000000001533" />
      <inertia ixx="1.4019331346159882408e-07" ixy="1.6002410067372217571e-15" ixz="1.168673343299313613e-36" iyy="1.4019331260388783538e-07" iyz="-2.1243526921822030181e-37" izz="2.3838919844264060647e-07" />
    </inertial>
  </link>

  <joint name="right_wrist_pitch_drive" type="revolute">
    <origin xyz="-1.5244304577405686261e-10 0.024000000358071177375 -0.0080000000000011797785" rpy="-1.0519265191422955506e-14 5.4953979628752545946e-14 -1.5707963267949167641" />
    <parent link="2xl430_gears_6" />
    <child link="spur_1m_24t_drive_6" />
    <axis xyz="0 0 1" />
    <limit effort="1" velocity="20" lower="-1.3962634015954635824" upper="1.9198621771937625091" />
    <joint_properties friction="0.0" />
  </joint>

  <link name="hand_2">
    <visual>
      <origin xyz="0 0 0" rpy="0 -0 0" />
      <geometry>
        <mesh filename="../assemblies/right_arm_hand/meshes/right_hand_visual.stl" />
      </geometry>
      <material name="hand_material">
        <color rgba="0.61568627450980395466 0.81176470588235294379 0.9294117647058824927 1.0" />
      </material>
    </visual>
    <inertial>
      <origin xyz="-2.489950859175186028e-10 0.040594531666389030433 -0.018520936085747969485" rpy="0 0 0" />
      <mass value="0.017000000000001444511" />
      <inertia ixx="9.218759418532233686e-06" ixy="-1.5922040974697187551e-15" ixz="-1.0539511471482342536e-13" iyy="6.6718567758212730107e-06" iyz="2.1533596775200804265e-08" izz="3.7788698411876589991e-06" />
    </inertial>
  </link>

  <joint name="right_wrist_roll" type="revolute">
    <origin xyz="0.019000000000001921602 -3.5806768661217347471e-10 -0.027000000152449948193" rpy="-3.141592653589793116 -1.5707963267945153074 0" />
    <parent link="2xl430_gears_6" />
    <child link="hand_2" />
    <axis xyz="0 0 1" />
    <limit effort="1" velocity="20" lower="-1.3962634015954635824" upper="1.9198621771937625091" />
    <joint_properties friction="0.0" />
  </joint>

  <link name="wrist_bearing_plate_2">
    <visual>
      <origin xyz="0 0 0" rpy="0 -0 0" />
      <geometry>
        <mesh filename="../assemblies/right_arm_hand/meshes/right_wrist_bearing_plate_visual.stl" />
      </geometry>
      <material name="wrist_bearing_plate_material">
        <color rgba="0.64496316278892629192 0.69011804996940528945 0.71706771073555886087 1.0" />
      </material>
    </visual>
    <inertial>
      <origin xyz="-0.0075835583121499497775 -0.015499999999999980807 -0.0018386323705903383479" rpy="0 0 0" />
      <mass value="0.0049000367468305539714" />
      <inertia ixx="4.970743010915013972e-07" ixy="1.7926180143713080926e-22" ixz="1.8100904820814078261e-08" iyy="7.1268523603538584823e-07" iyz="-6.8569550891497149052e-23" izz="1.1919657811600113469e-06" />
    </inertial>
  </link>

  <joint name="right_wrist_pitch_fixed" type="fixed">
    <origin xyz="0.015500000000003951589 4.4686476741162550752e-15 -0.045000000000003870237" rpy="5.3290705180300300612e-15 1.2051470932306253475e-13 -1.570796326794896558" />
    <parent link="2xl430_gears_6" />
    <child link="wrist_bearing_plate_2" />
    <axis xyz="0 0 1" />
    <limit effort="1" velocity="20" />
    <joint_properties friction="0.0" />
  </joint>

  <joint name="right_wrist_pitch_driven" type="revolute">
    <origin xyz="-2.7755575615628913511e-17 5.5220263365470826379e-30 -0.0015999999999999970409" rpy="8.7209719320528352177e-15 6.1232339997705582035e-17 1.5707963267948947816" />
    <parent link="spur_1m_24t_driven_6" />
    <child link="2xl430_gears_6" />
    <axis xyz="0 0 1" />
    <limit effort="1" velocity="20" lower="-1.9198621771937625091" upper="1.3962634015954635824" />
    <joint_properties friction="0.0" />
  </joint>

  <joint name="right_wrist_roll_fixed" type="fixed">
    <origin xyz="-3.9443045261050590271e-30 -0.025299999999999999573 -0.05200000000000001843" rpy="1.5707963267949385244 1.570796326794896558 0" />
    <parent link="elb_yaw_link_2" />
    <child link="spur_1m_24t_driven_6" />
    <axis xyz="0 0 1" />
    <limit effort="1" velocity="20" />
    <joint_properties friction="0.0" />
  </joint>

  <joint name="right_elbow_yaw_fixed" type="fixed">
    <origin xyz="-6.9388939039072283776e-18 0 0.0015999999999999625633" rpy="-3.1415926535897917837 -5.545896421255929151e-30 -1.570796326794896558" />
    <parent link="spur_1m_24t_driven_5" />
    <child link="elb_yaw_link_2" />
    <axis xyz="0 0 1" />
    <limit effort="1" velocity="20" />
    <joint_properties friction="0.0" />
  </joint>

  <joint name="right_elbow_yaw_driven" type="revolute">
    <origin xyz="-3.5807115258967847637e-10 -0.027000000152453060287 -0.019000000000002816719" rpy="1.5707963267949573982 3.0852757707134402472e-14 -1.047495423780654911e-13" />
    <parent link="2xl430_gears_5" />
    <child link="spur_1m_24t_driven_5" />
    <axis xyz="0 0 1" />
    <limit effort="1" velocity="20" lower="-2.6179938779914944114" upper="2.6179938779914944114" />
    <joint_properties friction="0.0" />
  </joint>

  <joint name="right_elbow_roll" type="revolute">
    <origin xyz="-3.4694469519536141888e-18 -0.018999999999999999528 -0.058999999999999996891" rpy="1.570796326794896558 -3.2439825080223504913e-13 -2.9976021665407794952e-15" />
    <parent link="sho_yaw_link_2" />
    <child link="2xl430_gears_5" />
    <axis xyz="0 0 1" />
    <limit effort="1" velocity="20" lower="-1.9198621771937625091" upper="2.4434609527920612138" />
    <joint_properties friction="0.0" />
  </joint>

  <joint name="right_sho_yaw_fixed" type="fixed">
    <origin xyz="0 1.1832913578315177081e-30 0.0015999999999999903189" rpy="3.141592653589793116 -0 0" />
    <parent link="spur_1m_24t_driven_4" />
    <child link="sho_yaw_link_2" />
    <axis xyz="0 0 1" />
    <limit effort="1" velocity="20" />
    <joint_properties friction="0.0" />
  </joint>

  <joint name="right_sho_yaw_driven" type="revolute">
    <origin xyz="-3.5806817233474674822e-10 -0.027000000152446659157 -0.019000000000003357953" rpy="1.5707963267949260899 -2.2055090607972632104e-14 -2.2204460492023508308e-16" />
    <parent link="2xl430_gears_4" />
    <child link="spur_1m_24t_driven_4" />
    <axis xyz="0 0 1" />
    <limit effort="1" velocity="20" lower="-2.6179938779914944114" upper="2.6179938779914944114" />
    <joint_properties friction="0.0" />
  </joint>

  <joint name="right_sho_roll" type="revolute">
    <origin xyz="-0.018999999999999999528 0.0010000000000000076102 0.027000000000000003164" rpy="-3.1415926535897797933 1.5707963267948090724 0" />
    <parent link="sho_pitch_link_2" />
    <child link="2xl430_gears_4" />
    <axis xyz="0 0 1" />
    <limit effort="1" velocity="20" lower="-1.570796326794896558" upper="0.34906585039886589561" />
    <joint_properties friction="0.0" />
  </joint>


</robot>