<mujoco model="toddlerbot_arms">
  <compiler angle="radian" autolimits="true" />

  <asset>
    <mesh name="torso_visual" file="../assemblies/toddlerbot_arms/meshes/torso_visual.stl" />
    <mesh name="left_sho_pitch_link_visual" file="../assemblies/left_arm_hand/meshes/left_sho_pitch_link_visual.stl" />
    <mesh name="left_2xl430_gears_visual" file="../assemblies/left_arm_hand/meshes/left_2xl430_gears_visual.stl" />
    <mesh name="left_spur_1m_24t_drive_visual" file="../assemblies/left_arm_hand/meshes/left_spur_1m_24t_drive_visual.stl" />
    <mesh name="left_spur_1m_24t_driven_visual" file="../assemblies/left_arm_hand/meshes/left_spur_1m_24t_driven_visual.stl" />
    <mesh name="left_sho_yaw_link_visual" file="../assemblies/left_arm_hand/meshes/left_sho_yaw_link_visual.stl" />
    <mesh name="left_2xl430_gears_2_visual" file="../assemblies/left_arm_hand/meshes/left_2xl430_gears_2_visual.stl" />
    <mesh name="left_spur_1m_24t_drive_2_visual" file="../assemblies/left_arm_hand/meshes/left_spur_1m_24t_drive_2_visual.stl" />
    <mesh name="left_spur_1m_24t_driven_2_visual" file="../assemblies/left_arm_hand/meshes/left_spur_1m_24t_driven_2_visual.stl" />
    <mesh name="left_elb_yaw_link_visual" file="../assemblies/left_arm_hand/meshes/left_elb_yaw_link_visual.stl" />
    <mesh name="left_spur_1m_24t_driven_3_visual" file="../assemblies/left_arm_hand/meshes/left_spur_1m_24t_driven_3_visual.stl" />
    <mesh name="left_2xl430_gears_3_visual" file="../assemblies/left_arm_hand/meshes/left_2xl430_gears_3_visual.stl" />
    <mesh name="left_spur_1m_24t_drive_3_visual" file="../assemblies/left_arm_hand/meshes/left_spur_1m_24t_drive_3_visual.stl" />
    <mesh name="left_hand_visual" file="../assemblies/left_arm_hand/meshes/left_hand_visual.stl" />
    <mesh name="left_wrist_bearing_plate_visual" file="../assemblies/left_arm_hand/meshes/left_wrist_bearing_plate_visual.stl" />
    <mesh name="right_sho_pitch_link_visual" file="../assemblies/right_arm_hand/meshes/right_sho_pitch_link_visual.stl" />
    <mesh name="right_2xl430_gears_visual" file="../assemblies/right_arm_hand/meshes/right_2xl430_gears_visual.stl" />
    <mesh name="right_spur_1m_24t_drive_visual" file="../assemblies/right_arm_hand/meshes/right_spur_1m_24t_drive_visual.stl" />
    <mesh name="right_spur_1m_24t_driven_visual" file="../assemblies/right_arm_hand/meshes/right_spur_1m_24t_driven_visual.stl" />
    <mesh name="right_sho_yaw_link_visual" file="../assemblies/right_arm_hand/meshes/right_sho_yaw_link_visual.stl" />
    <mesh name="right_2xl430_gears_2_visual" file="../assemblies/right_arm_hand/meshes/right_2xl430_gears_2_visual.stl" />
    <mesh name="right_spur_1m_24t_drive_2_visual" file="../assemblies/right_arm_hand/meshes/right_spur_1m_24t_drive_2_visual.stl" />
    <mesh name="right_spur_1m_24t_driven_2_visual" file="../assemblies/right_arm_hand/meshes/right_spur_1m_24t_driven_2_visual.stl" />
    <mesh name="right_elb_yaw_link_visual" file="../assemblies/right_arm_hand/meshes/right_elb_yaw_link_visual.stl" />
    <mesh name="right_spur_1m_24t_driven_3_visual" file="../assemblies/right_arm_hand/meshes/right_spur_1m_24t_driven_3_visual.stl" />
    <mesh name="right_2xl430_gears_3_visual" file="../assemblies/right_arm_hand/meshes/right_2xl430_gears_3_visual.stl" />
    <mesh name="right_spur_1m_24t_drive_3_visual" file="../assemblies/right_arm_hand/meshes/right_spur_1m_24t_drive_3_visual.stl" />
    <mesh name="right_hand_visual" file="../assemblies/right_arm_hand/meshes/right_hand_visual.stl" />
    <mesh name="right_wrist_bearing_plate_visual" file="../assemblies/right_arm_hand/meshes/right_wrist_bearing_plate_visual.stl" />
  </asset>

  <worldbody>
    <geom type="mesh" rgba="0.575684 0.733467 0.856322 1" mesh="torso_visual" class="visual" />
    <body name="sho_pitch_link" pos="-0.003 0.062 0.104237" quat="0.707107 -0.707107 0 0">
      <inertial pos="5.82542e-11 -5.12646e-05 0.00824408" quat="0.0155166 0.706937 0.0155166 0.706937" mass="0.0086" diaginertia="3.08064e-06 2.9104e-06 1.22729e-06" />
      <joint name="left_sho_pitch" pos="0 0 0" axis="0 0 1" range="-3.14159 1.5708" damping="0.195" armature="0.002" />
      <geom type="mesh" rgba="0.615686 0.811765 0.929412 1" mesh="left_sho_pitch_link_visual" class="visual" />
      <body name="2xl430_gears" pos="-0.019 0.001 0.027" quat="0 -0.707107 0 0.707107">
        <inertial pos="-0.0115794 -0.00242258 -0.0185511" quat="-0.0158908 0.69769 -0.13596 0.703201" mass="0.118" diaginertia="3.59112e-05 3.27863e-05 2.73235e-05" />
        <joint name="left_sho_roll" pos="0 0 0" axis="0 0 1" range="-1.5708 0" damping="0.153" armature="0.008" />
        <geom type="mesh" rgba="0.75606 0.858047 0.913203 1" mesh="left_2xl430_gears_visual" class="visual" />
        <body name="spur_1m_24t_drive" pos="-0.024 -0.019 -0.019" quat="0.707107 0.707107 0 0">
          <inertial pos="0 0 0.00479491" quat="0.5 0.5 -0.5 0.5" mass="0.0032" diaginertia="2.38389e-07 1.40193e-07 1.40193e-07" />
          <joint name="left_sho_yaw_drive" pos="0 0 0" axis="0 0 1" range="-1.5708 1.5708" damping="0.153" armature="0.008" />
          <geom type="mesh" rgba="0.615686 0.811765 0.929412 1" mesh="left_spur_1m_24t_drive_visual" class="visual" />
        </body>
        <body name="spur_1m_24t_driven" pos="-3.58071e-10 -0.027 -0.019" quat="0.707107 0.707107 0 0">
          <inertial pos="0 0 0.0216102" mass="0.0172" diaginertia="1.08021e-05 7.42977e-06 4.68733e-06" />
          <joint name="left_sho_yaw_driven" pos="0 0 0" axis="0 0 1" range="-1.5708 1.5708" damping="0.153" armature="0.008" />
          <geom type="mesh" rgba="0.231373 0.380392 0.705882 1" mesh="left_spur_1m_24t_driven_visual" class="visual" />
          <geom pos="0 0 0.0016" quat="0 -1 0 0" type="mesh" rgba="0.615686 0.811765 0.929412 1" mesh="left_sho_yaw_link_visual" class="visual" />
          <body name="2xl430_gears_2" pos="0 0.019 0.0606" quat="0.707107 -0.707107 0 0">
            <inertial pos="-0.0115794 -0.00242258 -0.0185511" quat="-0.0158908 0.69769 -0.13596 0.703201" mass="0.118" diaginertia="3.59112e-05 3.27863e-05 2.73235e-05" />
            <joint name="left_elbow_roll" pos="0 0 0" axis="0 0 1" range="-1.5708 1.5708" damping="0.153" armature="0.008" />
            <geom type="mesh" rgba="0.75606 0.858047 0.913203 1" mesh="left_2xl430_gears_2_visual" class="visual" />
            <body name="spur_1m_24t_drive_2" pos="-0.024 -0.019 -0.019" quat="0.707107 0.707107 0 0">
              <inertial pos="0 0 0.00479491" quat="0.5 0.5 -0.5 0.5" mass="0.0032" diaginertia="2.38389e-07 1.40193e-07 1.40193e-07" />
              <joint name="left_elbow_yaw_drive" pos="0 0 0" axis="0 0 1" range="-1.5708 1.5708" damping="0.153" armature="0.008" />
              <geom type="mesh" rgba="0.615686 0.811765 0.929412 1" mesh="left_spur_1m_24t_drive_2_visual" class="visual" />
            </body>
            <body name="spur_1m_24t_driven_2" pos="-3.58069e-10 -0.027 -0.019" quat="0.5 0.5 0.5 -0.5">
              <inertial pos="0.00116139 -4.04035e-08 0.025284" quat="0.665601 0.238694 0.238694 0.665601" mass="0.0229" diaginertia="1.97992e-05 1.15815e-05 1.01733e-05" />
              <joint name="left_elbow_yaw_driven" pos="0 0 0" axis="0 0 1" range="-1.5708 1.5708" damping="0.153" armature="0.008" />
              <geom type="mesh" rgba="0.231373 0.380392 0.705882 1" mesh="left_spur_1m_24t_driven_2_visual" class="visual" />
              <geom pos="0 0 0.0016" quat="0 0.707107 -0.707107 0" type="mesh" rgba="0.615686 0.811765 0.929412 1" mesh="left_elb_yaw_link_visual" class="visual" />
              <geom pos="0.0253 0 0.0536" quat="-0.707107 0 -0.707107 0" type="mesh" rgba="0.231373 0.380392 0.705882 1" mesh="left_spur_1m_24t_driven_3_visual" class="visual" />
              <body name="2xl430_gears_3" pos="0.0237 0 0.0536" quat="-0.5 0.5 -0.5 0.5">
                <inertial pos="0.000431007 0.0114203 -0.025465" quat="0.750271 0.658201 -0.0437595 0.0441611" mass="0.1229" diaginertia="3.89635e-05 3.40271e-05 3.0248e-05" />
                <joint name="left_wrist_roll_driven" pos="0 0 0" axis="0 0 1" range="-1.5708 1.5708" damping="0.153" armature="0.008" />
                <geom type="mesh" rgba="0.75606 0.858047 0.913203 1" mesh="left_2xl430_gears_3_visual" class="visual" />
                <geom pos="0.0155 0 -0.045" quat="0.707107 0 0 -0.707107" type="mesh" rgba="0.644963 0.690118 0.717068 1" mesh="left_wrist_bearing_plate_visual" class="visual" />
                <body name="spur_1m_24t_drive_3" pos="-1.52441e-10 0.024 -0.008" quat="0.707107 0 0 -0.707107">
                  <inertial pos="0 0 0.00479491" quat="0.5 0.5 -0.5 0.5" mass="0.0032" diaginertia="2.38389e-07 1.40193e-07 1.40193e-07" />
                  <joint name="left_wrist_roll_drive" pos="0 0 0" axis="0 0 1" range="-1.5708 1.5708" damping="0.153" armature="0.008" />
                  <geom type="mesh" rgba="0.615686 0.811765 0.929412 1" mesh="left_spur_1m_24t_drive_3_visual" class="visual" />
                </body>
                <body name="hand" pos="0.019 -3.58081e-10 -0.027" quat="0.707107 0 0.707107 0">
                  <inertial pos="-4.30384e-08 -0.0497238 -0.0179336" quat="0.739676 0.672963 4.83075e-07 -2.50564e-06" mass="0.017" diaginertia="9.49214e-06 6.68579e-06 4.0511e-06" />
                  <joint name="left_wrist_pitch" pos="0 0 0" axis="0 0 1" range="-1.5708 1.5708" damping="0.153" armature="0.008" />
                  <geom type="mesh" rgba="0.615686 0.811765 0.929412 1" mesh="left_hand_visual" class="visual" />
                </body>
              </body>
            </body>
          </body>
        </body>
      </body>
    </body>
    <body name="sho_pitch_link_2" pos="-0.003 -0.062 0.104237" quat="0 0 0.707107 -0.707107">
      <inertial pos="5.82542e-11 -5.12646e-05 0.00824408" quat="0.0155166 0.706937 0.0155166 0.706937" mass="0.0086" diaginertia="3.08064e-06 2.9104e-06 1.22729e-06" />
      <joint name="right_sho_pitch" pos="0 0 0" axis="0 0 1" range="-1.5708 3.14159" damping="0.195" armature="0.002" />
      <geom type="mesh" rgba="0.615686 0.811765 0.929412 1" mesh="right_sho_pitch_link_visual" class="visual" />
      <body name="2xl430_gears_4" pos="-0.019 0.001 0.027" quat="0 0.707107 0 -0.707107">
        <inertial pos="-0.0115794 -0.00242258 -0.0185511" quat="-0.0158908 0.69769 -0.13596 0.703201" mass="0.118" diaginertia="3.59112e-05 3.27863e-05 2.73235e-05" />
        <joint name="right_sho_roll" pos="0 0 0" axis="0 0 1" range="-1.5708 0" damping="0.153" armature="0.008" />
        <geom type="mesh" rgba="0.75606 0.858047 0.913203 1" mesh="right_2xl430_gears_visual" class="visual" />
        <body name="spur_1m_24t_drive_4" pos="-0.024 -0.019 -0.019" quat="0.707107 0.707107 0 0">
          <inertial pos="0 0 0.00479491" quat="0.5 0.5 -0.5 0.5" mass="0.0032" diaginertia="2.38389e-07 1.40193e-07 1.40193e-07" />
          <joint name="right_sho_yaw_drive" pos="0 0 0" axis="0 0 1" range="-1.5708 1.5708" damping="0.153" armature="0.008" />
          <geom type="mesh" rgba="0.615686 0.811765 0.929412 1" mesh="right_spur_1m_24t_drive_visual" class="visual" />
        </body>
        <body name="spur_1m_24t_driven_4" pos="-3.58067e-10 -0.027 -0.019" quat="0.707107 0.707107 0 0">
          <inertial pos="0 0 0.0216102" mass="0.0172" diaginertia="1.08021e-05 7.42977e-06 4.68733e-06" />
          <joint name="right_sho_yaw_driven" pos="0 0 0" axis="0 0 1" range="-1.5708 1.5708" damping="0.153" armature="0.008" />
          <geom type="mesh" rgba="0.231373 0.380392 0.705882 1" mesh="right_spur_1m_24t_driven_visual" class="visual" />
          <geom pos="0 0 0.0016" quat="0 -1 0 0" type="mesh" rgba="0.615686 0.811765 0.929412 1" mesh="right_sho_yaw_link_visual" class="visual" />
          <body name="2xl430_gears_5" pos="0 0.019 0.0606" quat="0.707107 -0.707107 0 0">
            <inertial pos="-0.0115794 -0.00242258 -0.0185511" quat="-0.0158908 0.69769 -0.13596 0.703201" mass="0.118" diaginertia="3.59112e-05 3.27863e-05 2.73235e-05" />
            <joint name="right_elbow_roll" pos="0 0 0" axis="0 0 1" range="-1.5708 1.5708" damping="0.153" armature="0.008" />
            <geom type="mesh" rgba="0.75606 0.858047 0.913203 1" mesh="right_2xl430_gears_2_visual" class="visual" />
            <body name="spur_1m_24t_drive_5" pos="-0.024 -0.019 -0.019" quat="0.707107 0.707107 0 0">
              <inertial pos="0 0 0.00479491" quat="0.5 0.5 -0.5 0.5" mass="0.0032" diaginertia="2.38389e-07 1.40193e-07 1.40193e-07" />
              <joint name="right_elbow_yaw_drive" pos="0 0 0" axis="0 0 1" range="-1.5708 1.5708" damping="0.153" armature="0.008" />
              <geom type="mesh" rgba="0.615686 0.811765 0.929412 1" mesh="right_spur_1m_24t_drive_2_visual" class="visual" />
            </body>
            <body name="spur_1m_24t_driven_5" pos="-3.58071e-10 -0.027 -0.019" quat="0.707107 0.707107 0 0">
              <inertial pos="4.04035e-08 0.00116139 0.025284" quat="0.941302 -0.337564 0 0" mass="0.0229" diaginertia="1.97992e-05 1.15815e-05 1.01733e-05" />
              <joint name="right_elbow_yaw_driven" pos="0 0 0" axis="0 0 1" range="-1.5708 1.5708" damping="0.153" armature="0.008" />
              <geom type="mesh" rgba="0.231373 0.380392 0.705882 1" mesh="right_spur_1m_24t_driven_2_visual" class="visual" />
              <geom pos="0 0 0.0016" quat="0 -1 0 0" type="mesh" rgba="0.615686 0.811765 0.929412 1" mesh="right_elb_yaw_link_visual" class="visual" />
              <geom pos="0 0.0253 0.0536" quat="0.5 -0.5 -0.5 -0.5" type="mesh" rgba="0.231373 0.380392 0.705882 1" mesh="right_spur_1m_24t_driven_3_visual" class="visual" />
              <body name="2xl430_gears_6" pos="0 0.0237 0.0536" quat="0.707107 -0.707107 0 0">
                <inertial pos="0.000431007 0.0114203 -0.025465" quat="0.750271 0.658201 -0.0437595 0.0441611" mass="0.1229" diaginertia="3.89635e-05 3.40271e-05 3.0248e-05" />
                <joint name="right_wrist_roll_driven" pos="0 0 0" axis="0 0 1" range="-1.5708 1.5708" damping="0.153" armature="0.008" />
                <geom type="mesh" rgba="0.75606 0.858047 0.913203 1" mesh="right_2xl430_gears_3_visual" class="visual" />
                <geom pos="0.0155 0 -0.045" quat="0.707107 0 0 -0.707107" type="mesh" rgba="0.644963 0.690118 0.717068 1" mesh="right_wrist_bearing_plate_visual" class="visual" />
                <body name="spur_1m_24t_drive_6" pos="-1.52443e-10 0.024 -0.008" quat="0.707107 0 0 -0.707107">
                  <inertial pos="0 0 0.00479491" quat="0.5 0.5 -0.5 0.5" mass="0.0032" diaginertia="2.38389e-07 1.40193e-07 1.40193e-07" />
                  <joint name="right_wrist_roll_drive" pos="0 0 0" axis="0 0 1" range="-1.5708 1.5708" damping="0.153" armature="0.008" />
                  <geom type="mesh" rgba="0.615686 0.811765 0.929412 1" mesh="right_spur_1m_24t_drive_3_visual" class="visual" />
                </body>
                <body name="hand_2" pos="0.019 -3.58068e-10 -0.027" quat="0 0.707107 0 0.707107">
                  <inertial pos="-4.30384e-08 0.0497238 -0.0200664" quat="0.739676 0.672963 -4.83075e-07 2.50564e-06" mass="0.017" diaginertia="9.49214e-06 6.68579e-06 4.0511e-06" />
                  <joint name="right_wrist_pitch" pos="0 0 0" axis="0 0 1" range="-1.5708 1.5708" damping="0.153" armature="0.008" />
                  <geom type="mesh" rgba="0.615686 0.811765 0.929412 1" mesh="right_hand_visual" class="visual" />
                </body>
              </body>
            </body>
          </body>
        </body>
      </body>
    </body>
  </worldbody>
  <option>
    <flag eulerdamp="disable" />
  </option>
  <actuator>
    <position name="left_sho_pitch" joint="left_sho_pitch" kp="14.0625" ctrlrange="-3.14159 1.5708" class="XC430" />
    <position name="left_sho_roll" joint="left_sho_roll" kp="14.0625" ctrlrange="-1.5708 0" class="2XL430" />
    <position name="left_sho_yaw_drive" joint="left_sho_yaw_drive" kp="14.0625" ctrlrange="-1.5708 1.5708" class="2XL430" />
    <position name="left_elbow_roll" joint="left_elbow_roll" kp="14.0625" ctrlrange="-1.5708 1.5708" class="2XL430" />
    <position name="left_elbow_yaw_drive" joint="left_elbow_yaw_drive" kp="14.0625" ctrlrange="-1.5708 1.5708" class="2XL430" />
    <position name="left_wrist_roll_drive" joint="left_wrist_roll_drive" kp="14.0625" ctrlrange="-1.5708 1.5708" class="2XL430" />
    <position name="left_wrist_pitch" joint="left_wrist_pitch" kp="14.0625" ctrlrange="-1.5708 1.5708" class="2XL430" />
    <position name="right_sho_pitch" joint="right_sho_pitch" kp="14.0625" ctrlrange="-1.5708 3.14159" class="XC430" />
    <position name="right_sho_roll" joint="right_sho_roll" kp="14.0625" ctrlrange="-1.5708 0" class="2XL430" />
    <position name="right_sho_yaw_drive" joint="right_sho_yaw_drive" kp="14.0625" ctrlrange="-1.5708 1.5708" class="2XL430" />
    <position name="right_elbow_roll" joint="right_elbow_roll" kp="14.0625" ctrlrange="-1.5708 1.5708" class="2XL430" />
    <position name="right_elbow_yaw_drive" joint="right_elbow_yaw_drive" kp="14.0625" ctrlrange="-1.5708 1.5708" class="2XL430" />
    <position name="right_wrist_roll_drive" joint="right_wrist_roll_drive" kp="14.0625" ctrlrange="-1.5708 1.5708" class="2XL430" />
    <position name="right_wrist_pitch" joint="right_wrist_pitch" kp="14.0625" ctrlrange="-1.5708 1.5708" class="2XL430" />
  </actuator>
  <equality>
    <joint joint1="left_sho_yaw_driven" joint2="left_sho_yaw_drive" polycoef="0 -1.0 0 0 0" solimp="0.9999 0.9999 0.001 0.5 2" solref="0.004 1" />
    <joint joint1="left_elbow_yaw_driven" joint2="left_elbow_yaw_drive" polycoef="0 -1.0 0 0 0" solimp="0.9999 0.9999 0.001 0.5 2" solref="0.004 1" />
    <joint joint1="left_wrist_roll_driven" joint2="left_wrist_roll_drive" polycoef="0 -1.0 0 0 0" solimp="0.9999 0.9999 0.001 0.5 2" solref="0.004 1" />
    <joint joint1="right_sho_yaw_driven" joint2="right_sho_yaw_drive" polycoef="0 -1.0 0 0 0" solimp="0.9999 0.9999 0.001 0.5 2" solref="0.004 1" />
    <joint joint1="right_elbow_yaw_driven" joint2="right_elbow_yaw_drive" polycoef="0 -1.0 0 0 0" solimp="0.9999 0.9999 0.001 0.5 2" solref="0.004 1" />
    <joint joint1="right_wrist_roll_driven" joint2="right_wrist_roll_drive" polycoef="0 -1.0 0 0 0" solimp="0.9999 0.9999 0.001 0.5 2" solref="0.004 1" />
  </equality>
  <keyframe>
    <key name="home" qpos="0.174533 -0.261799 1.0472 -1.0472 0.523599 0.5235990 -0.5235990 -1.0472 1.0472 0 -0.174533 -0.261799 -1.0472 1.0472 0.523599 -0.523599 0.523599 1.0472 -1.0472 0" ctrl="0.174533 -0.261799 1.0472 0.523599 0.523599 1.0472 0 -0.174533 -0.261799 -1.0472 0.523599 -0.523599 -1.0472 0" />
  </keyframe>
  <default>
    <geom type="mesh" solref="0.004 1" />
    <default class="XM430">
      <position forcerange="-3 3" />
    </default>
    <default class="XC430">
      <position forcerange="-2 2" />
    </default>
    <default class="2XC430">
      <position forcerange="-2 2" />
    </default>
    <default class="XL430">
      <position forcerange="-2 2" />
    </default>
    <default class="2XL430">
      <position forcerange="-2 2" />
    </default>
    <default class="XC330">
      <position forcerange="-1 1" />
    </default>
    <default class="visual">
      <geom type="mesh" contype="0" conaffinity="0" group="2" />
    </default>
    <default class="collision">
      <geom group="3" />
    </default>
  </default>
  <contact />
</mujoco>