<?xml version="1.0" ?><robot name="left_leg_2xm">  
  <link name="left_hip_pitch_link">    
    <visual>      
      <origin xyz="0 0 0" rpy="0 -0 0"/>      
      <geometry>        
        <mesh filename="package:///meshes/left_hip_pitch_link_visual.stl"/>        
      </geometry>      
      <material name="left_hip_pitch_link_material">        
        <color rgba="0.92982090412552342862 0.72254076531321620447 0.12744144951766170348 1.0"/>        
      </material>      
    </visual>    
    <collision>      
      <origin xyz="0 0 0" rpy="0 -0 0"/>      
      <geometry>        
        <mesh filename="package:///meshes/left_hip_pitch_link_collision.stl"/>        
      </geometry>      
    </collision>    
    <inertial>      
      <origin xyz="-0.011956351386334163056 0.019992757838958687133 0.018858249912120171599" rpy="0 0 0"/>      
      <mass value="0.19376376696210850792"/>      
      <inertia ixx="0.00011804182389326814742" ixy="-1.5895078464739870033e-06" ixz="3.0802177008905698097e-08" iyy="5.1585603979825938974e-05" iyz="-5.5648114095088296861e-07" izz="0.00013525831068322244658"/>      
    </inertial>    
  </link>  

  <link name="hip_yaw_link">    
    <visual>      
      <origin xyz="0 0 0" rpy="0 -0 0"/>      
      <geometry>        
        <mesh filename="package:///meshes/left_hip_yaw_link_visual.stl"/>        
      </geometry>      
      <material name="hip_yaw_link_material">        
        <color rgba="0.61568627450980395466 0.81176470588235283277 0.92941176470588238168 1.0"/>        
      </material>      
    </visual>    
    <collision>      
      <origin xyz="0 0 0" rpy="0 -0 0"/>      
      <geometry>        
        <mesh filename="package:///meshes/left_hip_yaw_link_collision.stl"/>        
      </geometry>      
    </collision>    
    <inertial>      
      <origin xyz="-1.1351340770202997733e-06 0.016382481946049860799 0.024904960957045255837" rpy="0 0 0"/>      
      <mass value="0.013199999999999994724"/>      
      <inertia ixx="6.2164630245752423339e-06" ixy="1.7112227929958450346e-10" ixz="2.3737014581359500122e-10" iyy="5.5106440267526426166e-06" iyz="8.1727857918859183648e-08" izz="2.6855910648547497853e-06"/>      
    </inertial>    
  </link>  

  <link name="spur_gear_21_teeth">    
    <visual>      
      <origin xyz="0 0 0" rpy="0 -0 0"/>      
      <geometry>        
        <mesh filename="package:///meshes/left_spur_gear_21_teeth_visual.stl"/>        
      </geometry>      
      <material name="spur_gear_21_teeth_material">        
        <color rgba="0.61568627450980395466 0.81176470588235294379 0.9294117647058824927 1.0"/>        
      </material>      
    </visual>    
    <collision>      
      <origin xyz="0 0 0" rpy="0 -0 0"/>      
      <geometry>        
        <mesh filename="package:///meshes/left_spur_gear_21_teeth_collision.stl"/>        
      </geometry>      
    </collision>    
    <inertial>      
      <origin xyz="-4.5505289565601863496e-11 -1.6782163591954541783e-11 -0.0024924102006250539211" rpy="0 0 0"/>      
      <mass value="0.0022000000000000001325"/>      
      <inertia ixx="7.0162310059594196881e-08" ixy="0" ixz="2.9253435663285707174e-36" iyy="7.016231005804746178e-08" iyz="0" izz="1.3125544198538289306e-07"/>      
    </inertial>    
  </link>  

  <link name="left_thigh_link">    
    <visual>      
      <origin xyz="0 0 0" rpy="0 -0 0"/>      
      <geometry>        
        <mesh filename="package:///meshes/left_thigh_link_visual.stl"/>        
      </geometry>      
      <material name="left_thigh_link_material">        
        <color rgba="0.8077380222132878318 0.71541030077254164077 0.35058406659986918186 1.0"/>        
      </material>      
    </visual>    
    <collision>      
      <origin xyz="0 0 0" rpy="0 -0 0"/>      
      <geometry>        
        <mesh filename="package:///meshes/left_thigh_link_collision.stl"/>        
      </geometry>      
    </collision>    
    <inertial>      
      <origin xyz="-0.0099310748247876286243 -0.005573326863873521303 0.039014117054800519224" rpy="0 0 0"/>      
      <mass value="0.14895408167669121902"/>      
      <inertia ixx="7.3955327919484486771e-05" ixy="-1.1805488631449509199e-06" ixz="-8.0603251552292177242e-06" iyy="8.8995102919697759007e-05" iyz="1.127566988858133854e-06" izz="4.2292269256454420698e-05"/>      
    </inertial>    
  </link>  

  <link name="spur_gear_18_teeth">    
    <visual>      
      <origin xyz="0 0 0" rpy="0 -0 0"/>      
      <geometry>        
        <mesh filename="package:///meshes/left_spur_gear_18_teeth_visual.stl"/>        
      </geometry>      
      <material name="spur_gear_18_teeth_material">        
        <color rgba="0.61568627450980395466 0.81176470588235283277 0.92941176470588238168 1.0"/>        
      </material>      
    </visual>    
    <collision>      
      <origin xyz="0 0 0" rpy="0 -0 0"/>      
      <geometry>        
        <mesh filename="package:///meshes/left_spur_gear_18_teeth_collision.stl"/>        
      </geometry>      
    </collision>    
    <inertial>      
      <origin xyz="-5.1952850524387505531e-14 -2.4693775189390798433e-13 0.007151312231623232693" rpy="0 0 0"/>      
      <mass value="0.0008039935629263021688"/>      
      <inertia ixx="2.0123636882888892681e-08" ixy="2.1553335600797640032e-16" ixz="1.5735503606513793539e-37" iyy="2.012363672795583975e-08" iyz="-8.7651236522689225493e-38" izz="3.1595601997159143493e-08"/>      
    </inertial>    
  </link>  

  <joint name="left_hip_yaw_drive" type="revolute">    
    <origin xyz="-0.019199999999995876615 0.00020000000000328088667 0.0064999999999706473131" rpy="-3.1415926535897922278 -1.8640355840337264655e-15 3.1415926535897926719"/>    
    <parent link="left_thigh_link"/>    
    <child link="spur_gear_18_teeth"/>    
    <axis xyz="0 0 1"/>    
    <limit effort="1" velocity="20" lower="-1.8325957145940461324" upper="1.8325957145940461324"/>    
    <joint_properties friction="0.0"/>    
  </joint>  

  <link name="left_calf_link">    
    <visual>      
      <origin xyz="0 0 0" rpy="0 -0 0"/>      
      <geometry>        
        <mesh filename="package:///meshes/left_calf_link_visual.stl"/>        
      </geometry>      
      <material name="left_calf_link_material">        
        <color rgba="0.61568627450980395466 0.81176470588235305481 0.92941176470588238168 1.0"/>        
      </material>      
    </visual>    
    <collision>      
      <origin xyz="0 0 0" rpy="0 -0 0"/>      
      <geometry>        
        <mesh filename="package:///meshes/left_calf_link_collision.stl"/>        
      </geometry>      
    </collision>    
    <inertial>      
      <origin xyz="-0.0043450054391243496041 0.040752982165250660473 0.0087116093515534342995" rpy="0 0 0"/>      
      <mass value="0.030999999999999999778"/>      
      <inertia ixx="3.3069388685112522449e-05" ixy="-1.3783307153200307867e-06" ixz="-1.2742534026332333322e-07" iyy="7.7316525337314329558e-06" iyz="-7.335650059388335934e-08" izz="2.803137775398737859e-05"/>      
    </inertial>    
  </link>  

  <link name="bearing_683">    
    <visual>      
      <origin xyz="0 0 0" rpy="0 -0 0"/>      
      <geometry>        
        <mesh filename="package:///meshes/left_bearing_683_visual.stl"/>        
      </geometry>      
      <material name="bearing_683_material">        
        <color rgba="0.64705882352941179736 0.64705882352941179736 0.64705882352941179736 1.0"/>        
      </material>      
    </visual>    
    <collision>      
      <origin xyz="0 0 0" rpy="0 -0 0"/>      
      <geometry>        
        <mesh filename="package:///meshes/left_bearing_683_collision.stl"/>        
      </geometry>      
    </collision>    
    <inertial>      
      <origin xyz="-2.7648254672676530068e-17 -2.4186774283160221397e-19 -0.0015500000000000003792" rpy="0 0 0"/>      
      <mass value="0.00048694686130641793437"/>      
      <inertia ixx="2.1551456503319879113e-09" ixy="-2.3958813912389835261e-29" ixz="-4.3394263179205566234e-39" iyy="2.1551456503319874977e-09" iyz="8.1941607241242520458e-58" izz="3.5303647444715305817e-09"/>      
    </inertial>    
  </link>  

  <joint name="left_knee_front_rev_2" type="revolute">    
    <origin xyz="-0.0057402514854764073726 -0.01385819298766896579 0.026199999999999803307" rpy="3.141592653589793116 1.9636585933148879161e-17 -1.5720018459275957312"/>    
    <parent link="left_calf_link"/>    
    <child link="bearing_683"/>    
    <axis xyz="0 0 1"/>    
    <limit effort="1" velocity="20"/>    
    <joint_properties friction="0.0"/>    
  </joint>  

  <link name="bearing_683_2">    
    <visual>      
      <origin xyz="0 0 0" rpy="0 -0 0"/>      
      <geometry>        
        <mesh filename="package:///meshes/left_bearing_683_2_visual.stl"/>        
      </geometry>      
      <material name="bearing_683_2_material">        
        <color rgba="0.64705882352941179736 0.64705882352941179736 0.64705882352941179736 1.0"/>        
      </material>      
    </visual>    
    <collision>      
      <origin xyz="0 0 0" rpy="0 -0 0"/>      
      <geometry>        
        <mesh filename="package:///meshes/left_bearing_683_2_collision.stl"/>        
      </geometry>      
    </collision>    
    <inertial>      
      <origin xyz="-5.5403830288305443578e-17 -2.4186774283158271393e-19 -0.0015500000000000003792" rpy="0 0 0"/>      
      <mass value="0.00048694686130641793437"/>      
      <inertia ixx="2.1551456503319887385e-09" ixy="-7.0491200393230587585e-29" ixz="-4.3394263179205553183e-39" iyy="2.1551456503319883249e-09" iyz="-4.4559467649346522358e-38" izz="3.5303647444715305817e-09"/>      
    </inertial>    
  </link>  

  <joint name="left_knee_back_rev_2" type="revolute">    
    <origin xyz="0.0057402514854763128302 0.013858192987669548657 0.026199999999999803307" rpy="3.1415926535897926719 -1.0795076530726939777e-15 -1.5719345627640688434"/>    
    <parent link="left_calf_link"/>    
    <child link="bearing_683_2"/>    
    <axis xyz="0 0 1"/>    
    <limit effort="1" velocity="20"/>    
    <joint_properties friction="0.0"/>    
  </joint>  

  <link name="left_ank_pitch_link">    
    <visual>      
      <origin xyz="0 0 0" rpy="0 -0 0"/>      
      <geometry>        
        <mesh filename="package:///meshes/left_ank_pitch_link_visual.stl"/>        
      </geometry>      
      <material name="left_ank_pitch_link_material">        
        <color rgba="0.70321688500203327621 0.64514870846184446673 0.40484735422826279017 1.0"/>        
      </material>      
    </visual>    
    <collision>      
      <origin xyz="0 0 0" rpy="0 -0 0"/>      
      <geometry>        
        <mesh filename="package:///meshes/left_ank_pitch_link_collision.stl"/>        
      </geometry>      
    </collision>    
    <inertial>      
      <origin xyz="0.017770422751691550278 0.012417933919336246809 0.018813528244421728886" rpy="0 0 0"/>      
      <mass value="0.17676376695067899658"/>      
      <inertia ixx="4.703321427354667522e-05" ixy="-5.8981911382288417884e-07" ixz="-5.5304655046863677838e-07" iyy="0.00010706748281468987693" iyz="-5.9543689050499949278e-08" izz="0.00012159782211822963468"/>      
    </inertial>    
  </link>  

  <link name="ank_roll_link">    
    <visual>      
      <origin xyz="0 0 0" rpy="0 -0 0"/>      
      <geometry>        
        <mesh filename="package:///meshes/left_ank_roll_link_visual.stl"/>        
      </geometry>      
      <material name="ank_roll_link_material">        
        <color rgba="0.61568627450980395466 0.81176470588235294379 0.92941176470588238168 1.0"/>        
      </material>      
    </visual>    
    <collision>      
      <origin xyz="0 0 0" rpy="0 -0 0"/>      
      <geometry>        
        <mesh filename="package:///meshes/left_ank_roll_link_collision.stl"/>        
      </geometry>      
    </collision>    
    <inertial>      
      <origin xyz="-0.026987231947660682979 5.653279883933316606e-13 0.033766671354451598119" rpy="0 0 0"/>      
      <mass value="0.042599999999999998979"/>      
      <inertia ixx="3.7149943594119187924e-05" ixy="1.9604824081119910118e-17" ixz="2.3895918372293315155e-06" iyy="3.7472718057541652291e-05" iyz="7.825868036044176796e-12" izz="1.005168512915340147e-05"/>      
    </inertial>    
  </link>  

  <joint name="left_ank_roll" type="revolute">    
    <origin xyz="0.022749999999983006038 -8.8540286213856234099e-15 0.019000000000000970973" rpy="-1.5707963267949500707 -9.3226942268794927216e-15 1.5707963267952123054"/>    
    <parent link="left_ank_pitch_link"/>    
    <child link="ank_roll_link"/>    
    <axis xyz="0 0 1"/>    
    <limit effort="1" velocity="20" lower="-1.570796326794896558" upper="1.570796326794896558"/>    
    <joint_properties friction="0.0"/>    
  </joint>  

  <joint name="left_ank_pitch" type="revolute">    
    <origin xyz="1.5046216775048590637e-16 0.099999999999999783507 0.027749999999999604844" rpy="3.141592653589793116 -4.9446121195035926866e-18 1.1657341758499214505e-15"/>    
    <parent link="left_calf_link"/>    
    <child link="left_ank_pitch_link"/>    
    <axis xyz="0 0 1"/>    
    <limit effort="1" velocity="20" lower="-1.7453292519943295336" upper="0.785398163397448279"/>    
    <joint_properties friction="0.0"/>    
  </joint>  

  <joint name="left_knee" type="revolute">    
    <origin xyz="2.8177799257657431582e-18 -0.0087500000000000563438 0.085949999999999887601" rpy="1.5707963267948985564 1.8042036078715074883e-15 3.1415926535897926719"/>    
    <parent link="left_thigh_link"/>    
    <child link="left_calf_link"/>    
    <axis xyz="0 0 1"/>    
    <limit effort="1" velocity="20" lower="-2.0943951023931952626" upper="0"/>    
    <joint_properties friction="0.0"/>    
  </joint>  

  <link name="xm430_plate">    
    <visual>      
      <origin xyz="0 0 0" rpy="0 -0 0"/>      
      <geometry>        
        <mesh filename="package:///meshes/left_xm430_plate_visual.stl"/>        
      </geometry>      
      <material name="xm430_plate_material">        
        <color rgba="0.61568627450980395466 0.81176470588235294379 0.92941176470588227065 1.0"/>        
      </material>      
    </visual>    
    <collision>      
      <origin xyz="0 0 0" rpy="0 -0 0"/>      
      <geometry>        
        <mesh filename="package:///meshes/left_xm430_plate_collision.stl"/>        
      </geometry>      
    </collision>    
    <inertial>      
      <origin xyz="1.5374714074007520109e-17 -2.6938053792322955155e-18 0.0025278513919583817798" rpy="0 0 0"/>      
      <mass value="0.0026999999999999997093"/>      
      <inertia ixx="1.2887178787151819394e-07" ixy="5.8739562556303566831e-08" ixz="6.9722681737095646431e-38" iyy="2.4635091298412523495e-07" iyz="-5.9460142808870420612e-37" izz="3.646799841381030595e-07"/>      
    </inertial>    
  </link>  

  <link name="knee_rod">    
    <visual>      
      <origin xyz="0 0 0" rpy="0 -0 0"/>      
      <geometry>        
        <mesh filename="package:///meshes/left_knee_rod_visual.stl"/>        
      </geometry>      
      <material name="knee_rod_material">        
        <color rgba="0.62051618944235198416 0.78640765248647581664 0.88594253031295011613 1.0"/>        
      </material>      
    </visual>    
    <collision>      
      <origin xyz="0 0 0" rpy="0 -0 0"/>      
      <geometry>        
        <mesh filename="package:///meshes/left_knee_rod_collision.stl"/>        
      </geometry>      
    </collision>    
    <inertial>      
      <origin xyz="0.017534287432906674881 -4.2275889155942901964e-05 -0.0015987301647641587263" rpy="0 0 0"/>      
      <mass value="0.0031629468613064166266"/>      
      <inertia ixx="2.422525780287841614e-08" ixy="4.2664654149405399812e-10" ixz="4.9178282652728157359e-10" iyy="8.1758847647263901927e-07" iyz="-1.1857086489860728948e-12" izz="8.3704925374022657712e-07"/>      
    </inertial>    
  </link>  

  <joint name="left_knee_front_rev_1" type="revolute">    
    <origin xyz="0.013858192987669326612 -0.0057402514854763405858 0.0049999999999999142353" rpy="-3.1415926535897926719 -7.0790895644363073118e-16 3.1403871344570966073"/>    
    <parent link="xm430_plate"/>    
    <child link="knee_rod"/>    
    <axis xyz="0 0 1"/>    
    <limit effort="1" velocity="20"/>    
    <joint_properties friction="0.0"/>    
  </joint>  

  <link name="knee_rod_2">    
    <visual>      
      <origin xyz="0 0 0" rpy="0 -0 0"/>      
      <geometry>        
        <mesh filename="package:///meshes/left_knee_rod_2_visual.stl"/>        
      </geometry>      
      <material name="knee_rod_2_material">        
        <color rgba="0.62051618944235198416 0.78640765248647581664 0.88594253031295011613 1.0"/>        
      </material>      
    </visual>    
    <collision>      
      <origin xyz="0 0 0" rpy="0 -0 0"/>      
      <geometry>        
        <mesh filename="package:///meshes/left_knee_rod_2_collision.stl"/>        
      </geometry>      
    </collision>    
    <inertial>      
      <origin xyz="0.017534290197983807419 -3.9916362690174648381e-05 -0.0015987301647641409454" rpy="0 0 0"/>      
      <mass value="0.0031629468613064166266"/>      
      <inertia ixx="2.4225146182602357337e-08" ixy="4.0283436058624397028e-10" ixz="4.9178290407901188148e-10" iyy="8.1758853228271336569e-07" iyz="-1.1195311895983018054e-12" izz="8.3704919793004592806e-07"/>      
    </inertial>    
  </link>  

  <joint name="left_knee_back_rev_1" type="revolute">    
    <origin xyz="-0.013858192987669243346 0.0057402514854763518615 0.0049999999999999836242" rpy="-3.1415926535897926719 2.8925793879955221593e-16 3.1404544176206239392"/>    
    <parent link="xm430_plate"/>    
    <child link="knee_rod_2"/>    
    <axis xyz="0 0 1"/>    
    <limit effort="1" velocity="20"/>    
    <joint_properties friction="0.0"/>    
  </joint>  

  <joint name="left_knee_act" type="revolute">    
    <origin xyz="4.9996245779180309423e-17 0.012450000000000013139 0.044500000000000046463" rpy="-1.5707963267948956698 1.5707963267948954478 0"/>    
    <parent link="left_thigh_link"/>    
    <child link="xm430_plate"/>    
    <axis xyz="0 0 1"/>    
    <limit effort="1" velocity="20" lower="-2.0943951023931952626" upper="0"/>    
    <joint_properties friction="0.0"/>    
  </joint>  

  <joint name="left_hip_yaw_driven" type="revolute">    
    <origin xyz="6.7133798344526554386e-18 2.4286128663675299322e-17 -0.0050000000000001085243" rpy="-3.1415926535897922278 -4.1724555867713866127e-17 7.2164496631611534065e-16"/>    
    <parent link="spur_gear_21_teeth"/>    
    <child link="left_thigh_link"/>    
    <axis xyz="0 0 1"/>    
    <limit effort="1" velocity="20" lower="-1.570796326794896558" upper="1.570796326794896558"/>    
    <joint_properties friction="0.0"/>    
  </joint>  

  <joint name="left_hip_yaw_fixed" type="fixed">    
    <origin xyz="-6.9388939039072283776e-18 0.028000000000000004052 0.023000000000000003081" rpy="1.570796326794896558 -1.5707963267948945596 0"/>    
    <parent link="hip_yaw_link"/>    
    <child link="spur_gear_21_teeth"/>    
    <axis xyz="0 0 1"/>    
    <limit effort="1" velocity="20"/>    
    <joint_properties friction="0.0"/>    
  </joint>  

  <joint name="left_hip_roll" type="revolute">    
    <origin xyz="-0.024000000716155295288 0.023000000152476038351 0.019000000152447446555" rpy="1.5707963267945725949 -1.5707963267948183983 0"/>    
    <parent link="left_hip_pitch_link"/>    
    <child link="hip_yaw_link"/>    
    <axis xyz="0 0 1"/>    
    <limit effort="1" velocity="20" lower="-1.570796326794896558" upper="1.570796326794896558"/>    
    <joint_properties friction="0.0"/>    
  </joint>  


</robot>