<?xml version="1.0" ?><robot name="left_leg_2xm">  
  <link name="left_hip_pitch_link">    
    <visual>      
      <origin xyz="0 0 0" rpy="0 -0 0"/>      
      <geometry>        
        <mesh filename="package:///meshes/left_hip_pitch_link_visual.stl"/>        
      </geometry>      
      <material name="left_hip_pitch_link_material">        
        <color rgba="0.92982090412552342862 0.72254076531321620447 0.12744144951766167573 1.0"/>        
      </material>      
    </visual>    
    <collision>      
      <origin xyz="0 0 0" rpy="0 -0 0"/>      
      <geometry>        
        <mesh filename="package:///meshes/left_hip_pitch_link_collision.stl"/>        
      </geometry>      
    </collision>    
    <inertial>      
      <origin xyz="-0.011706350670177599962 0.019742757684791095024 -0.018852427217597104991" rpy="0 0 0"/>      
      <mass value="0.19376376696210850792"/>      
      <inertia ixx="0.00011804472850814715546" ixy="-1.5895078857706018834e-06" ixz="-3.4383747953545210347e-08" iyy="5.1588508581731065325e-05" iyz="7.4157570294140530861e-07" izz="0.00013525831069619408532"/>      
    </inertial>    
  </link>  

  <link name="hip_yaw_link">    
    <visual>      
      <origin xyz="0 0 0" rpy="0 -0 0"/>      
      <geometry>        
        <mesh filename="package:///meshes/left_hip_yaw_link_visual.stl"/>        
      </geometry>      
      <material name="hip_yaw_link_material">        
        <color rgba="0.61568627450980395466 0.81176470588235294379 0.92941176470588238168 1.0"/>        
      </material>      
    </visual>    
    <collision>      
      <origin xyz="0 0 0" rpy="0 -0 0"/>      
      <geometry>        
        <mesh filename="package:///meshes/left_hip_yaw_link_collision.stl"/>        
      </geometry>      
    </collision>    
    <inertial>      
      <origin xyz="-1.1351340770169766513e-06 0.016382481946049850391 0.024904960957045248898" rpy="0 0 0"/>      
      <mass value="0.013199999999999989519"/>      
      <inertia ixx="6.2164630245752423339e-06" ixy="1.711222792995632811e-10" ixz="2.3737014581360032619e-10" iyy="5.5106440267526434637e-06" iyz="8.1727857918858932185e-08" izz="2.6855910648547497853e-06"/>      
    </inertial>    
  </link>  

  <link name="spur_gear_21_teeth">    
    <visual>      
      <origin xyz="0 0 0" rpy="0 -0 0"/>      
      <geometry>        
        <mesh filename="package:///meshes/left_spur_gear_21_teeth_visual.stl"/>        
      </geometry>      
      <material name="spur_gear_21_teeth_material">        
        <color rgba="0.61568627450980395466 0.81176470588235294379 0.9294117647058824927 1.0"/>        
      </material>      
    </visual>    
    <collision>      
      <origin xyz="0 0 0" rpy="0 -0 0"/>      
      <geometry>        
        <mesh filename="package:///meshes/left_spur_gear_21_teeth_collision.stl"/>        
      </geometry>      
    </collision>    
    <inertial>      
      <origin xyz="-4.5505288977337882293e-11 -1.6782163717306987843e-11 -0.00249241020062506086" rpy="0 0 0"/>      
      <mass value="0.0021999999999999996989"/>      
      <inertia ixx="7.0162310059594183647e-08" ixy="3.0428041711026148533e-41" ixz="-6.0897863866794247362e-39" iyy="7.016231005804743531e-08" iyz="8.2010274057603441653e-39" izz="1.3125544198538286659e-07"/>      
    </inertial>    
  </link>  

  <link name="left_thigh_link">    
    <visual>      
      <origin xyz="0 0 0" rpy="0 -0 0"/>      
      <geometry>        
        <mesh filename="package:///meshes/left_thigh_link_visual.stl"/>        
      </geometry>      
      <material name="left_thigh_link_material">        
        <color rgba="0.8077380222132878318 0.71541030077254164077 0.35058406659986918186 1.0"/>        
      </material>      
    </visual>    
    <collision>      
      <origin xyz="0 0 0" rpy="0 -0 0"/>      
      <geometry>        
        <mesh filename="package:///meshes/left_thigh_link_collision.stl"/>        
      </geometry>      
    </collision>    
    <inertial>      
      <origin xyz="-0.009931074824787505459 -0.0055733268638735152314 0.039014117054800664941" rpy="0 0 0"/>      
      <mass value="0.14895408167669121902"/>      
      <inertia ixx="7.3955327919484757822e-05" ixy="-1.1805488631448604991e-06" ixz="-8.0603251552292583818e-06" iyy="8.899510291969826045e-05" iyz="1.1275669888580036226e-06" izz="4.2292269256454549447e-05"/>      
    </inertial>    
  </link>  

  <link name="spur_gear_18_teeth">    
    <visual>      
      <origin xyz="0 0 0" rpy="0 -0 0"/>      
      <geometry>        
        <mesh filename="package:///meshes/left_spur_gear_18_teeth_visual.stl"/>        
      </geometry>      
      <material name="spur_gear_18_teeth_material">        
        <color rgba="0.61568627450980395466 0.81176470588235294379 0.92941176470588238168 1.0"/>        
      </material>      
    </visual>    
    <collision>      
      <origin xyz="0 0 0" rpy="0 -0 0"/>      
      <geometry>        
        <mesh filename="package:///meshes/left_spur_gear_18_teeth_collision.stl"/>        
      </geometry>      
    </collision>    
    <inertial>      
      <origin xyz="2.6439001777770671405e-18 8.5434987333314918169e-18 0.0017500000000000108785" rpy="0 0 0"/>      
      <mass value="0.0012000000000000001117"/>      
      <inertia ixx="2.9545593202975793532e-08" ixy="1.2314171653707795068e-23" ixz="-9.4023651664732437708e-36" iyy="2.9545593202975863016e-08" iyz="1.5954477302672659434e-36" izz="5.6662838285388571446e-08"/>      
    </inertial>    
  </link>  

  <joint name="left_hip_yaw_drive" type="revolute">    
    <origin xyz="-0.019199999999993382083 0.00020000000000426967905 -3.438915818776422384e-14" rpy="-3.1415926535896581129 -4.9090714472496588269e-13 4.6739125815344266384e-13"/>    
    <parent link="left_thigh_link"/>    
    <child link="spur_gear_18_teeth"/>    
    <axis xyz="0 0 1"/>    
    <limit effort="1" velocity="20" lower="-1.8325957145940461324" upper="1.8325957145940461324"/>    
    <joint_properties friction="0.0"/>    
  </joint>  

  <link name="left_calf_link">    
    <visual>      
      <origin xyz="0 0 0" rpy="0 -0 0"/>      
      <geometry>        
        <mesh filename="package:///meshes/left_calf_link_visual.stl"/>        
      </geometry>      
      <material name="left_calf_link_material">        
        <color rgba="0.61568627450980395466 0.81176470588235283277 0.92941176470588238168 1.0"/>        
      </material>      
    </visual>    
    <collision>      
      <origin xyz="0 0 0" rpy="0 -0 0"/>      
      <geometry>        
        <mesh filename="package:///meshes/left_calf_link_collision.stl"/>        
      </geometry>      
    </collision>    
    <inertial>      
      <origin xyz="-0.004345005439123867351 0.04075298216524993189 0.0087116093515531897035" rpy="0 0 0"/>      
      <mass value="0.03099999999999998937"/>      
      <inertia ixx="3.3069388685111919361e-05" ixy="-1.3783307153201250192e-06" ixz="-1.2742534026333974449e-07" iyy="7.7316525337312093391e-06" iyz="-7.3356500593832537363e-08" izz="2.8031377753986202908e-05"/>      
    </inertial>    
  </link>  

  <link name="bearing_683">    
    <visual>      
      <origin xyz="0 0 0" rpy="0 -0 0"/>      
      <geometry>        
        <mesh filename="package:///meshes/left_bearing_683_visual.stl"/>        
      </geometry>      
      <material name="bearing_683_material">        
        <color rgba="0.64705882352941179736 0.64705882352941179736 0.64705882352941179736 1.0"/>        
      </material>      
    </visual>    
    <collision>      
      <origin xyz="0 0 0" rpy="0 -0 0"/>      
      <geometry>        
        <mesh filename="package:///meshes/left_bearing_683_collision.stl"/>        
      </geometry>      
    </collision>    
    <inertial>      
      <origin xyz="1.0732094295237694297e-19 -2.4186774283160226211e-19 -0.0015500000000000003792" rpy="0 0 0"/>      
      <mass value="0.00048694686130641793437"/>      
      <inertia ixx="2.1551456503319879113e-09" ixy="-6.2799976202677632124e-28" ixz="5.1534174171568426072e-40" iyy="2.1551456503319883249e-09" iyz="-5.0160366256123927433e-41" izz="3.5303647444715305817e-09"/>      
    </inertial>    
  </link>  

  <joint name="left_knee_front_rev_2" type="revolute">    
    <origin xyz="-0.0057402514854763136976 -0.013858192987669076812 0.026199999999999178807" rpy="3.141592653589793116 -3.6846712218145297232e-15 -1.5696597423400153737"/>    
    <parent link="left_calf_link"/>    
    <child link="bearing_683"/>    
    <axis xyz="0 0 1"/>    
    <limit effort="1" velocity="20"/>    
    <joint_properties friction="0.0"/>    
  </joint>  

  <link name="bearing_683_2">    
    <visual>      
      <origin xyz="0 0 0" rpy="0 -0 0"/>      
      <geometry>        
        <mesh filename="package:///meshes/left_bearing_683_2_visual.stl"/>        
      </geometry>      
      <material name="bearing_683_2_material">        
        <color rgba="0.64705882352941179736 0.64705882352941179736 0.64705882352941179736 1.0"/>        
      </material>      
    </visual>    
    <collision>      
      <origin xyz="0 0 0" rpy="0 -0 0"/>      
      <geometry>        
        <mesh filename="package:///meshes/left_bearing_683_2_collision.stl"/>        
      </geometry>      
    </collision>    
    <inertial>      
      <origin xyz="1.0732094295237709945e-19 6.2549399515680022583e-19 -0.0015500000000000001624" rpy="0 0 0"/>      
      <mass value="0.00048694686130641793437"/>      
      <inertia ixx="2.1551456503319887385e-09" ixy="1.5334993719773141702e-28" ixz="-4.3380717671628368304e-42" iyy="2.1551456503319891521e-09" iyz="2.8653118878668096225e-39" izz="3.5303647444715305817e-09"/>      
    </inertial>    
  </link>  

  <joint name="left_knee_back_rev_2" type="revolute">    
    <origin xyz="0.0057402514854765652325 0.013858192987669493146 0.026199999999999244726" rpy="-3.1415926535897873428 -6.1642758581299746636e-16 -1.569659900865386204"/>    
    <parent link="left_calf_link"/>    
    <child link="bearing_683_2"/>    
    <axis xyz="0 0 1"/>    
    <limit effort="1" velocity="20"/>    
    <joint_properties friction="0.0"/>    
  </joint>  

  <link name="left_ank_pitch_link">    
    <visual>      
      <origin xyz="0 0 0" rpy="0 -0 0"/>      
      <geometry>        
        <mesh filename="package:///meshes/left_ank_pitch_link_visual.stl"/>        
      </geometry>      
      <material name="left_ank_pitch_link_material">        
        <color rgba="0.70321688500203327621 0.64514870846184446673 0.40484735422826279017 1.0"/>        
      </material>      
    </visual>    
    <collision>      
      <origin xyz="0 0 0" rpy="0 -0 0"/>      
      <geometry>        
        <mesh filename="package:///meshes/left_ank_pitch_link_collision.stl"/>        
      </geometry>      
    </collision>    
    <inertial>      
      <origin xyz="0.017770422751691619667 0.012417933919336193033 0.018813528244421732355" rpy="0 0 0"/>      
      <mass value="0.17676376695067899658"/>      
      <inertia ixx="4.7033214273546878508e-05" ixy="-5.8981911382268089093e-07" ixz="-5.5304655046867245964e-07" iyy="0.00010706748281469059521" iyz="-5.954368905048644969e-08" izz="0.00012159782211823027165"/>      
    </inertial>    
  </link>  

  <link name="ank_roll_link">    
    <visual>      
      <origin xyz="0 0 0" rpy="0 -0 0"/>      
      <geometry>        
        <mesh filename="package:///meshes/left_ank_roll_link_visual.stl"/>        
      </geometry>      
      <material name="ank_roll_link_material">        
        <color rgba="0.61568627450980395466 0.81176470588235294379 0.92941176470588238168 1.0"/>        
      </material>      
    </visual>    
    <collision>      
      <origin xyz="0 0 0" rpy="0 -0 0"/>      
      <geometry>        
        <mesh filename="package:///meshes/left_ank_roll_link_collision.stl"/>        
      </geometry>      
    </collision>    
    <inertial>      
      <origin xyz="-0.026987231947660717674 5.653272469623604523e-13 0.033766671354451605058" rpy="0 0 0"/>      
      <mass value="0.042599999999999998979"/>      
      <inertia ixx="3.7149943594120509295e-05" ixy="1.94807275579421073e-17" ixz="2.3895918372294030898e-06" iyy="3.7472718057542804256e-05" iyz="7.8258680835538914296e-12" izz="1.0051685129153406552e-05"/>      
    </inertial>    
  </link>  

  <joint name="left_ank_roll" type="revolute">    
    <origin xyz="0.022749999999981843773 -7.882583474838611437e-15 0.01900000000000073852" rpy="-1.5707963267949500707 -9.3641111455497678285e-15 1.5707963267951978725"/>    
    <parent link="left_ank_pitch_link"/>    
    <child link="ank_roll_link"/>    
    <axis xyz="0 0 1"/>    
    <limit effort="1" velocity="20" lower="-1.570796326794896558" upper="1.570796326794896558"/>    
    <joint_properties friction="0.0"/>    
  </joint>  

  <joint name="left_ank_pitch" type="revolute">    
    <origin xyz="1.3731962615615156409e-15 0.099999999999997951639 0.02774999999999918851" rpy="3.141592653589793116 -4.9446121211182754037e-18 -2.0452759225209035521e-15"/>    
    <parent link="left_calf_link"/>    
    <child link="left_ank_pitch_link"/>    
    <axis xyz="0 0 1"/>    
    <limit effort="1" velocity="20" lower="-1.7453292519943295336" upper="0.785398163397448279"/>    
    <joint_properties friction="0.0"/>    
  </joint>  

  <joint name="left_knee" type="revolute">    
    <origin xyz="3.2303803729205604611e-16 -0.0087500000000000285882 0.085950000000000484346" rpy="1.5707963267948998887 9.1903399882501304125e-17 -3.1415926535897926719"/>    
    <parent link="left_thigh_link"/>    
    <child link="left_calf_link"/>    
    <axis xyz="0 0 1"/>    
    <limit effort="1" velocity="20" lower="-1.570796326794896558" upper="0"/>    
    <joint_properties friction="0.0"/>    
  </joint>  

  <link name="xm430_plate">    
    <visual>      
      <origin xyz="0 0 0" rpy="0 -0 0"/>      
      <geometry>        
        <mesh filename="package:///meshes/left_xm430_plate_visual.stl"/>        
      </geometry>      
      <material name="xm430_plate_material">        
        <color rgba="0.61568627450980395466 0.81176470588235294379 0.92941176470588227065 1.0"/>        
      </material>      
    </visual>    
    <collision>      
      <origin xyz="0 0 0" rpy="0 -0 0"/>      
      <geometry>        
        <mesh filename="package:///meshes/left_xm430_plate_collision.stl"/>        
      </geometry>      
    </collision>    
    <inertial>      
      <origin xyz="1.2199949069473465797e-18 -2.5675705000662896147e-18 0.0025278513919583852493" rpy="0 0 0"/>      
      <mass value="0.0026999999999999997093"/>      
      <inertia ixx="1.2887178787151819394e-07" ixy="5.8739562556303553596e-08" ixz="8.8620754357183379589e-39" iyy="2.4635091298412528789e-07" iyz="4.4470047921031726444e-38" izz="3.646799841381030595e-07"/>      
    </inertial>    
  </link>  

  <link name="knee_rod">    
    <visual>      
      <origin xyz="0 0 0" rpy="0 -0 0"/>      
      <geometry>        
        <mesh filename="package:///meshes/left_knee_rod_visual.stl"/>        
      </geometry>      
      <material name="knee_rod_material">        
        <color rgba="0.62051618944235198416 0.78640765248647581664 0.88594253031295022716 1.0"/>        
      </material>      
    </visual>    
    <collision>      
      <origin xyz="0 0 0" rpy="0 -0 0"/>      
      <geometry>        
        <mesh filename="package:///meshes/left_knee_rod_collision.stl"/>        
      </geometry>      
    </collision>    
    <inertial>      
      <origin xyz="0.017534290263858352821 3.9858446391435727811e-05 -0.0015981336617514451531" rpy="0 0 0"/>      
      <mass value="0.0031629468613064179276"/>      
      <inertia ixx="2.7978945925001967021e-08" ixy="-4.0224987309131433355e-10" ixz="4.8576302098649207963e-10" iyy="8.7495154957252311209e-07" iyz="1.1042225844322773014e-12" izz="8.9816306921226656837e-07"/>      
    </inertial>    
  </link>  

  <joint name="left_knee_front_rev_1" type="revolute">    
    <origin xyz="0.013858192987669049057 -0.0057402514854763527288 0.0049999999999999914305" rpy="-3.1415926535897908956 3.4964474193337374653e-15 -3.1404560691349008295"/>    
    <parent link="xm430_plate"/>    
    <child link="knee_rod"/>    
    <axis xyz="0 0 1"/>    
    <limit effort="1" velocity="20"/>    
    <joint_properties friction="0.0"/>    
  </joint>  

  <link name="knee_rod_2">    
    <visual>      
      <origin xyz="0 0 0" rpy="0 -0 0"/>      
      <geometry>        
        <mesh filename="package:///meshes/left_knee_rod_2_visual.stl"/>        
      </geometry>      
      <material name="knee_rod_2_material">        
        <color rgba="0.62051618944235198416 0.78640765248647581664 0.88594253031295022716 1.0"/>        
      </material>      
    </visual>    
    <collision>      
      <origin xyz="0 0 0" rpy="0 -0 0"/>      
      <geometry>        
        <mesh filename="package:///meshes/left_knee_rod_2_collision.stl"/>        
      </geometry>      
    </collision>    
    <inertial>      
      <origin xyz="0.017534290270177187165 3.9852887128006895645e-05 -0.0015981336617513928946" rpy="0 0 0"/>      
      <mass value="0.0031629468613064179276"/>      
      <inertia ixx="2.7978945669952882124e-08" ixy="-4.0219376936919183332e-10" ixz="4.8576302116128196051e-10" iyy="8.7495154970007240378e-07" iyz="1.1040685742798436999e-12" izz="8.9816306908475899306e-07"/>      
    </inertial>    
  </link>  

  <joint name="left_knee_back_rev_1" type="revolute">    
    <origin xyz="-0.013858192987669118446 0.0057402514854763457899 0.0049999999999999888284" rpy="3.1415926535897873428 1.9452985330695691049e-16 -3.1404562276602714377"/>    
    <parent link="xm430_plate"/>    
    <child link="knee_rod_2"/>    
    <axis xyz="0 0 1"/>    
    <limit effort="1" velocity="20"/>    
    <joint_properties friction="0.0"/>    
  </joint>  

  <joint name="left_knee_act" type="revolute">    
    <origin xyz="1.4647571350279164903e-16 0.012449999999999985384 0.044500000000000053402" rpy="-1.57079632679489678 1.5707963267948930053 0"/>    
    <parent link="left_thigh_link"/>    
    <child link="xm430_plate"/>    
    <axis xyz="0 0 1"/>    
    <limit effort="1" velocity="20" lower="-1.570796326794896558" upper="0"/>    
    <joint_properties friction="0.0"/>    
  </joint>  

  <joint name="left_hip_yaw_driven" type="revolute">    
    <origin xyz="-1.5720931501039814293e-18 -3.4694469519536141888e-18 -0.0050000000000000044409" rpy="-3.1415926535897904515 -2.6731719319053922034e-15 1.0531803182873569707e-15"/>    
    <parent link="spur_gear_21_teeth"/>    
    <child link="left_thigh_link"/>    
    <axis xyz="0 0 1"/>    
    <limit effort="1" velocity="20" lower="-1.570796326794896558" upper="1.570796326794896558"/>    
    <joint_properties friction="0.0"/>    
  </joint>  

  <joint name="left_hip_yaw_fixed" type="fixed">    
    <origin xyz="0 0.027999999999999993644 0.02300000000000000655" rpy="1.570796326794896336 -1.5707963267948870101 0"/>    
    <parent link="hip_yaw_link"/>    
    <child link="spur_gear_21_teeth"/>    
    <axis xyz="0 0 1"/>    
    <limit effort="1" velocity="20"/>    
    <joint_properties friction="0.0"/>    
  </joint>  

  <joint name="left_hip_roll" type="revolute">    
    <origin xyz="-0.023749999999998987199 0.022750000000000013267 -0.019050000000000236883" rpy="1.5707963267948872321 -1.5707963267948945596 0"/>    
    <parent link="left_hip_pitch_link"/>    
    <child link="hip_yaw_link"/>    
    <axis xyz="0 0 1"/>    
    <limit effort="1" velocity="20" lower="-1.570796326794896558" upper="1.570796326794896558"/>    
    <joint_properties friction="0.0"/>    
  </joint>  


</robot>