<?xml version="1.0" ?><robot name="right_OP3_arm">  
  <link name="sho_pitch_link">    
    <visual>      
      <origin xyz="0 0 0" rpy="0 -0 0"/>      
      <geometry>        
        <mesh filename="package:///meshes/right_sho_pitch_link_visual.stl"/>        
      </geometry>      
      <material name="sho_pitch_link_material">        
        <color rgba="0.61568627450980395466 0.81176470588235283277 0.92941176470588238168 1.0"/>        
      </material>      
    </visual>    
    <collision>      
      <origin xyz="0 0 0" rpy="0 -0 0"/>      
      <geometry>        
        <mesh filename="package:///meshes/right_sho_pitch_link_collision.stl"/>        
      </geometry>      
    </collision>    
    <inertial>      
      <origin xyz="-3.0491385338904537031e-09 0.0021980515983192261062 -0.0084441034778715822612" rpy="0 0 0"/>      
      <mass value="0.0053168741776095261239"/>      
      <inertia ixx="8.0042368361712706536e-07" ixy="1.1695537504103055586e-13" ixz="1.0217073767473516258e-14" iyy="1.8515753414330769355e-06" iyz="1.1638006198091067038e-07" izz="1.9553421197543842139e-06"/>      
    </inertial>    
  </link>  

  <link name="sho_roll_link">    
    <visual>      
      <origin xyz="0 0 0" rpy="0 -0 0"/>      
      <geometry>        
        <mesh filename="package:///meshes/right_sho_roll_link_visual.stl"/>        
      </geometry>      
      <material name="sho_roll_link_material">        
        <color rgba="0.41316897434350025042 0.53241982866399861773 0.72828535557147189294 1.0"/>        
      </material>      
    </visual>    
    <collision>      
      <origin xyz="0 0 0" rpy="0 -0 0"/>      
      <geometry>        
        <mesh filename="package:///meshes/right_sho_roll_link_collision.stl"/>        
      </geometry>      
    </collision>    
    <inertial>      
      <origin xyz="-0.044750001376316621282 -2.2393423855571851573e-09 -0.018770420156104725834" rpy="0 0 0"/>      
      <mass value="0.14104718485994710564"/>      
      <inertia ixx="2.5744677667987917141e-05" ixy="3.3646118925509001552e-08" ixz="-3.0796450647143969183e-12" iyy="0.0001830323819042464458" iyz="-7.9852776609896073213e-12" izz="0.00017803089038969863167"/>      
    </inertial>    
  </link>  

  <link name="elb_link">    
    <visual>      
      <origin xyz="0 0 0" rpy="0 -0 0"/>      
      <geometry>        
        <mesh filename="package:///meshes/right_elb_link_visual.stl"/>        
      </geometry>      
      <material name="elb_link_material">        
        <color rgba="0.63276333362436720797 0.72211014553089525325 0.77571823267481210262 1.0"/>        
      </material>      
    </visual>    
    <collision>      
      <origin xyz="0 0 0" rpy="0 -0 0"/>      
      <geometry>        
        <mesh filename="package:///meshes/right_elb_link_collision.stl"/>        
      </geometry>      
    </collision>    
    <inertial>      
      <origin xyz="0.0035809919318979602232 -0.051692930824585016369 0.019000000360375912667" rpy="0 0 0"/>      
      <mass value="0.012147845014428806237"/>      
      <inertia ixx="1.0275070466017683832e-05" ixy="8.3735105743541414978e-07" ixz="-2.4555242187884462621e-13" iyy="3.0584432934239362214e-06" iyz="2.6985065806980363975e-14" izz="8.4465004716583801325e-06"/>      
    </inertial>    
  </link>  

  <joint name="right_elb" type="revolute">    
    <origin xyz="-0.08949999999999827538 -7.2650219173908681114e-15 1.0956513474269513608e-14" rpy="-3.1415926535897145122 9.187667647645342109e-14 1.5707963267949796027"/>    
    <parent link="sho_roll_link"/>    
    <child link="elb_link"/>    
    <axis xyz="0 0 1"/>    
    <limit effort="1" velocity="20" lower="-1.570796326794896558" upper="1.570796326794896558"/>    
    <joint_properties friction="0.0"/>    
  </joint>  

  <joint name="right_sho_roll" type="revolute">    
    <origin xyz="0.018999999999999954425 0.0089999999999999576866 -0.027499999999999899525" rpy="-3.1415926535896976368 -1.5707963267948958919 0"/>    
    <parent link="sho_pitch_link"/>    
    <child link="sho_roll_link"/>    
    <axis xyz="0 0 1"/>    
    <limit effort="1" velocity="20" lower="-1.570796326794896558" upper="1.570796326794896558"/>    
    <joint_properties friction="0.0"/>    
  </joint>  


</robot>