<robot name="base">
  <mujoco>
    <compiler strippath="false" balanceinertia="true" discardvisual="false" />
  </mujoco>
  <link name="base_link" />
  <joint name="base_link_to_base" type="fixed">
    <parent link="base_link" />
    <child link="body_link" />
    <origin rpy="0.0 0 0" xyz="0 0 0" />
  </joint>
  <link name="body_link">
    <visual>
      <origin xyz="0 0 0" rpy="0 -0 0" />
      <geometry>
        <mesh filename="../assemblies/4R_body/meshes/body_link_visual.stl" />
      </geometry>
      <material name="body_link_material">
        <color rgba="0.59240232552230254193 0.77493742445477609149 0.89675162167089739196 1.0" />
      </material>
    </visual>
    <collision>
      <origin xyz="0 0 0" rpy="0 -0 0" />
      <geometry>
        <mesh filename="../assemblies/4R_body/meshes/body_link_collision.stl" />
      </geometry>
    </collision>
    <inertial>
      <origin xyz="-0.016892539113329187866 1.8329806416324712319e-07 0.37034501400110930724" rpy="0 0 0" />
      <mass value="1.3010345634555096073" />
      <inertia ixx="0.0047624725171278572619" ixy="1.2254736467156452913e-09" ixz="2.5710312085007233488e-05" iyy="0.0036676689183223276994" iyz="7.2555792615729098813e-09" izz="0.003205257716390450852" />
    </inertial>
  </link>

  <link name="neck_link">
    <visual>
      <origin xyz="0 0 0" rpy="0 -0 0" />
      <geometry>
        <mesh filename="../assemblies/4R_body/meshes/neck_link_visual.stl" />
      </geometry>
      <material name="neck_link_material">
        <color rgba="0.61568627450980395466 0.81176470588235294379 0.92941176470588238168 1.0" />
      </material>
    </visual>
    <collision>
      <origin xyz="0 0 0" rpy="0 -0 0" />
      <geometry>
        <mesh filename="../assemblies/4R_body/meshes/neck_link_collision.stl" />
      </geometry>
    </collision>
    <inertial>
      <origin xyz="3.067903593042405049e-19 -5.1123361372111250322e-20 -0.020000000000000000416" rpy="0 0 0" />
      <mass value="0.018378317023500286703" />
      <inertia ixx="3.4842226023719301187e-06" ixy="2.6492046803872183431e-38" ixz="-4.2946359314041097936e-38" iyy="3.4842226023719301187e-06" iyz="-3.2653968785718786279e-70" izz="2.06756066514378241e-06" />
    </inertial>
  </link>

  <link name="head_link">
    <visual>
      <origin xyz="0 0 0" rpy="0 -0 0" />
      <geometry>
        <mesh filename="../assemblies/4R_body/meshes/head_link_visual.stl" />
      </geometry>
      <material name="head_link_material">
        <color rgba="0.79607843137254907795 0.82352941176470584317 0.93725490196078442562 1.0" />
      </material>
    </visual>
    <collision>
      <origin xyz="0 0 0" rpy="0 -0 0" />
      <geometry>
        <mesh filename="../assemblies/4R_body/meshes/head_link_collision.stl" />
      </geometry>
    </collision>
    <inertial>
      <origin xyz="0.0011121374382810683603 0.002300308913386693143 -0.012472157860955830275" rpy="0 0 0" />
      <mass value="0.075015538754887006734" />
      <inertia ixx="6.8018019107715040579e-06" ixy="6.7244456377383520563e-07" ixz="2.3059386910262087019e-09" iyy="4.5222250439264427752e-05" iyz="-1.2119065455131472216e-08" izz="4.5708811148256761484e-05" />
    </inertial>
  </link>

  <joint name="head" type="fixed">
    <origin xyz="-4.1826855620466421722e-19 -2.6020852139652106416e-18 -0.039999999999999980016" rpy="-3.6199375412562401434e-16 -2.4218742848029192401e-16 -5.5511151231257722251e-17" />
    <parent link="neck_link" />
    <child link="head_link" />
    <axis xyz="0 0 1" />
    <limit effort="1" velocity="20" />
    <joint_properties friction="0.0" />
  </joint>

  <joint name="neck" type="fixed">
    <origin xyz="-0.0063999999999999838268 -5.2372852656669075105e-18 0.43249999999999999556" rpy="-3.141592653589793116 8.5053965662326763145e-17 1.57079632679489678" />
    <parent link="body_link" />
    <child link="neck_link" />
    <axis xyz="0 0 1" />
    <limit effort="1" velocity="20" />
    <joint_properties friction="0.0" />
  </joint>

  <joint name="left_hip_yaw" type="revolute">
    <origin xyz="-0.011900000000000068509 0.033999999999999967748 0.27720000000000005747" rpy="-2.2204460494576350945e-16 2.2204460491537123791e-16 -1.0069344447037368454e-13" />
    <parent link="body_link" />
    <child link="hip_yaw_link" />
    <axis xyz="0 0 1" />
    <limit effort="1" velocity="20" lower="-1.570796326794896558" upper="1.570796326794896558" />
    <joint_properties friction="0.0" />
  </joint>

  <joint name="right_hip_yaw" type="revolute">
    <origin xyz="-0.011900000000000259329 -0.033999999999999974687 0.27720000000000000195" rpy="-2.2204460561717224569e-16 2.2204460926237942003e-16 -6.0840221749459209504e-14" />
    <parent link="body_link" />
    <child link="hip_yaw_link_2" />
    <axis xyz="0 0 1" />
    <limit effort="1" velocity="20" lower="-1.570796326794896558" upper="1.570796326794896558" />
    <joint_properties friction="0.0" />
  </joint>

  <joint name="left_sho_pitch" type="revolute">
    <origin xyz="-0.0064000000000001278089 0.057999999999999600486 0.41249999999999986677" rpy="-1.570796326794871911 3.5360603334311235812e-14 -3.1415926535897371608" />
    <parent link="body_link" />
    <child link="sho_pitch_link" />
    <axis xyz="0 0 1" />
    <limit effort="1" velocity="20" lower="-1.570796326794896558" upper="1.570796326794896558" />
    <joint_properties friction="0.0" />
  </joint>

  <joint name="right_sho_pitch" type="revolute">
    <origin xyz="-0.0063999999999999916331 -0.057999999999999989064 0.4124999999999999778" rpy="-1.5707963267948972241 1.3877787807856806753e-15 6.3545304591998415249e-17" />
    <parent link="body_link" />
    <child link="sho_pitch_link_2" />
    <axis xyz="0 0 1" />
    <limit effort="1" velocity="20" lower="-1.570796326794896558" upper="1.570796326794896558" />
    <joint_properties friction="0.0" />
  </joint>


  <link name="hip_yaw_link">
    <visual>
      <origin xyz="0 0 0" rpy="0 -0 0" />
      <geometry>
        <mesh filename="../assemblies/left_3R+RH5_leg/meshes/left_hip_yaw_link_visual.stl" />
      </geometry>
      <material name="hip_yaw_link_material">
        <color rgba="0.61568627450980395466 0.81176470588235294379 0.9294117647058824927 1.0" />
      </material>
    </visual>
    <collision>
      <origin xyz="0 0 0" rpy="0 -0 0" />
      <geometry>
        <mesh filename="../assemblies/left_3R+RH5_leg/meshes/left_hip_yaw_link_collision.stl" />
      </geometry>
    </collision>
    <inertial>
      <origin xyz="-3.2018607255364363686e-19 -2.3813308130603722097e-19 -0.009839048905483014501" rpy="0 0 0" />
      <mass value="0.0090258837370979193293" />
      <inertia ixx="1.3230458239086465149e-06" ixy="-3.3592249637948231893e-24" ixz="-1.1251788840973426872e-52" iyy="3.8408510960331422723e-06" iyz="2.3044956050358332095e-34" izz="3.8721396285793907821e-06" />
    </inertial>
  </link>

  <link name="hip_roll_link">
    <visual>
      <origin xyz="0 0 0" rpy="0 -0 0" />
      <geometry>
        <mesh filename="../assemblies/left_3R+RH5_leg/meshes/left_hip_roll_link_visual.stl" />
      </geometry>
      <material name="hip_roll_link_material">
        <color rgba="0.95018735644455865064 0.70678927200428420807 0.061612079402596699185 1.0" />
      </material>
    </visual>
    <collision>
      <origin xyz="0 0 0" rpy="0 -0 0" />
      <geometry>
        <mesh filename="../assemblies/left_3R+RH5_leg/meshes/left_hip_roll_link_collision.stl" />
      </geometry>
    </collision>
    <inertial>
      <origin xyz="-0.012000151133961396363 -0.00049588831384953402804 -0.018504019244504728986" rpy="0 0 0" />
      <mass value="0.098012391483528679692" />
      <inertia ixx="2.0221748766306463246e-05" ixy="-4.1552068243118092086e-08" ixz="-4.1225592188160160633e-08" iyy="2.7358099958307189958e-05" iyz="-5.0935731752381037393e-07" izz="2.7358069524723229598e-05" />
    </inertial>
  </link>

  <link name="left_hip_pitch_link">
    <visual>
      <origin xyz="0 0 0" rpy="0 -0 0" />
      <geometry>
        <mesh filename="../assemblies/left_3R+RH5_leg/meshes/left_hip_pitch_link_visual.stl" />
      </geometry>
      <material name="left_hip_pitch_link_material">
        <color rgba="0.61653630588246988165 0.80730204117585691037 0.92176148235188937186 1.0" />
      </material>
    </visual>
    <collision>
      <origin xyz="0 0 0" rpy="0 -0 0" />
      <geometry>
        <mesh filename="../assemblies/left_3R+RH5_leg/meshes/left_hip_pitch_link_collision.stl" />
      </geometry>
    </collision>
    <inertial>
      <origin xyz="-0.00021632240618359049899 0.052986695633820024565 0.014788126099014522671" rpy="0 0 0" />
      <mass value="0.094084588454108858402" />
      <inertia ixx="6.3099190805816147737e-05" ixy="4.2254461504176696551e-07" ixz="-1.5223568275357069527e-07" iyy="2.1754782765193072386e-05" iyz="-1.4708367336520551889e-06" izz="6.2817482611037591409e-05" />
    </inertial>
  </link>

  <link name="left_calf_link">
    <visual>
      <origin xyz="0 0 0" rpy="0 -0 0" />
      <geometry>
        <mesh filename="../assemblies/left_3R+RH5_leg/meshes/left_calf_link_visual.stl" />
      </geometry>
      <material name="left_calf_link_material">
        <color rgba="0.55206810638185987994 0.72966543427568708591 0.87633415637236466988 1.0" />
      </material>
    </visual>
    <collision>
      <origin xyz="0 0 0" rpy="0 -0 0" />
      <geometry>
        <mesh filename="../assemblies/left_3R+RH5_leg/meshes/left_calf_link_collision.stl" />
      </geometry>
    </collision>
    <inertial>
      <origin xyz="-0.0039024894179555125184 -0.043134364817539981585 0.0081627588179090451725" rpy="0 0 0" />
      <mass value="0.016579149141633314074" />
      <inertia ixx="1.590573070035246312e-05" ixy="-2.204522528800703112e-07" ixz="6.1290259940321994327e-09" iyy="2.0589441701201891296e-06" iyz="3.1188726814138092768e-08" izz="1.5050357385364998179e-05" />
    </inertial>
  </link>

  <link name="ank_pitch_link">
    <visual>
      <origin xyz="0 0 0" rpy="0 -0 0" />
      <geometry>
        <mesh filename="../assemblies/left_3R+RH5_leg/meshes/left_ank_pitch_link_visual.stl" />
      </geometry>
      <material name="ank_pitch_link_material">
        <color rgba="0.63189161126160275916 0.72668668793540891482 0.78356373393969258601 1.0" />
      </material>
    </visual>
    <collision>
      <origin xyz="0 0 0" rpy="0 -0 0" />
      <geometry>
        <mesh filename="../assemblies/left_3R+RH5_leg/meshes/left_ank_pitch_link_collision.stl" />
      </geometry>
    </collision>
    <inertial>
      <origin xyz="4.0269685049619320532e-08 0.00059528282566739039883 -0.014599922383890481456" rpy="0 0 0" />
      <mass value="0.0042238381753791605713" />
      <inertia ixx="4.3705254067385321152e-07" ixy="1.6834346764733785093e-13" ixz="1.6428822472656162005e-12" iyy="3.9782741364647126382e-07" iyz="2.0919252884264439613e-14" izz="8.8858574534548839566e-08" />
    </inertial>
  </link>

  <link name="ank_roll_link">
    <visual>
      <origin xyz="0 0 0" rpy="0 -0 0" />
      <geometry>
        <mesh filename="../assemblies/left_3R+RH5_leg/meshes/left_ank_roll_link_visual.stl" />
      </geometry>
      <material name="ank_roll_link_material">
        <color rgba="0.61568627450980406568 0.81176470588235294379 0.92941176470588238168 1.0" />
      </material>
    </visual>
    <collision>
      <origin xyz="0 0 0" rpy="0 -0 0" />
      <geometry>
        <mesh filename="../assemblies/left_3R+RH5_leg/meshes/left_ank_roll_link_collision.stl" />
      </geometry>
    </collision>
    <inertial>
      <origin xyz="-6.3661537535036433633e-10 0.027240102316353698858 0.0019830147448535368794" rpy="0 0 0" />
      <mass value="0.013844478784760250178" />
      <inertia ixx="1.0150902309234932519e-05" ixy="6.8603302700575787432e-14" ixz="-3.2605547319755288602e-13" iyy="8.66361166634314672e-06" iyz="-7.8151778926544826665e-07" izz="2.8991570356470342998e-06" />
    </inertial>
  </link>

  <link name="ank_rr_link">
    <visual>
      <origin xyz="0 0 0" rpy="0 -0 0" />
      <geometry>
        <mesh filename="../assemblies/left_3R+RH5_leg/meshes/left_ank_rr_link_visual.stl" />
      </geometry>
      <material name="ank_rr_link_material">
        <color rgba="0.61568627450980395466 0.81176470588235294379 0.92941176470588238168 1.0" />
      </material>
    </visual>
    <collision>
      <origin xyz="0 0 0" rpy="0 -0 0" />
      <geometry>
        <mesh filename="../assemblies/left_3R+RH5_leg/meshes/left_ank_rr_link_collision.stl" />
      </geometry>
    </collision>
    <inertial>
      <origin xyz="3.459350369005387098e-05 0.0062999445222072132655 -0.0018999999999999991288" rpy="0 0 0" />
      <mass value="0.00044289790445047668311" />
      <inertia ixx="9.0894755004835223679e-09" ixy="-5.6689994077039773254e-11" ixz="1.0879024115047049114e-14" iyy="8.3785129146959922129e-09" iyz="1.6438750918789287233e-32" izz="1.3107013728801488166e-08" />
    </inertial>
  </link>

  <link name="12lf_rod_end">
    <visual>
      <origin xyz="0 0 0" rpy="0 -0 0" />
      <geometry>
        <mesh filename="../assemblies/left_3R+RH5_leg/meshes/left_12lf_rod_end_visual.stl" />
      </geometry>
      <material name="12lf_rod_end_material">
        <color rgba="0.92771758928836534075 0.61049283053223002415 0.2184765849058516729 1.0" />
      </material>
    </visual>
    <collision>
      <origin xyz="0 0 0" rpy="0 -0 0" />
      <geometry>
        <mesh filename="../assemblies/left_3R+RH5_leg/meshes/left_12lf_rod_end_collision.stl" />
      </geometry>
    </collision>
    <inertial>
      <origin xyz="-4.4735200503803263918e-11 -0.0038422185938246028805 6.4384187209442598224e-06" rpy="0 0 0" />
      <mass value="0.00085420491177815905965" />
      <inertia ixx="1.1840985264406794011e-08" ixy="2.0225977808669542648e-16" ixz="-9.260641994085930871e-16" iyy="3.3549621576797379806e-09" iyz="7.4535631381823397851e-12" izz="1.270352225441999316e-08" />
    </inertial>
  </link>

  <joint name="left_ank_R21" type="revolute">
    <origin xyz="0 0.010000000000000036637 -0.001899999999999998912" rpy="1.570796326794896558 1.428569774762729061 -1.570796326794896558" />
    <parent link="ank_rr_link" />
    <child link="12lf_rod_end" />
    <axis xyz="0 0 1" />
    <limit effort="1" velocity="20" lower="-1.570796326794896558" upper="1.570796326794896558" />
    <joint_properties friction="0.0" />
  </joint>

  <joint name="left_ank_R11" type="revolute">
    <origin xyz="-0.01000000000000001929 0.012500000000000011102 -0.027899999999999692407" rpy="-3.141592653589793116 3.5006616330671580104e-18 -0.10116031275702692949" />
    <parent link="ank_roll_link" />
    <child link="ank_rr_link" />
    <axis xyz="0 0 1" />
    <limit effort="1" velocity="20" lower="-1.570796326794896558" upper="1.570796326794896558" />
    <joint_properties friction="0.0" />
  </joint>

  <link name="ank_rr_link_2">
    <visual>
      <origin xyz="0 0 0" rpy="0 -0 0" />
      <geometry>
        <mesh filename="../assemblies/left_3R+RH5_leg/meshes/left_ank_rr_link_2_visual.stl" />
      </geometry>
      <material name="ank_rr_link_2_material">
        <color rgba="0.61568627450980395466 0.81176470588235294379 0.92941176470588238168 1.0" />
      </material>
    </visual>
    <collision>
      <origin xyz="0 0 0" rpy="0 -0 0" />
      <geometry>
        <mesh filename="../assemblies/left_3R+RH5_leg/meshes/left_ank_rr_link_2_collision.stl" />
      </geometry>
    </collision>
    <inertial>
      <origin xyz="3.4593503690046986296e-05 -0.0062999445222071577544 -0.0018999999999999917562" rpy="0 0 0" />
      <mass value="0.00044289790445047668311" />
      <inertia ixx="9.0894755004835256766e-09" ixy="5.6689994077039740942e-11" ixz="-1.0879024115047050692e-14" iyy="8.3785129146959922129e-09" iyz="-1.4073262332570122483e-32" izz="1.3107013728801488166e-08" />
    </inertial>
  </link>

  <link name="12lf_rod_end_2">
    <visual>
      <origin xyz="0 0 0" rpy="0 -0 0" />
      <geometry>
        <mesh filename="../assemblies/left_3R+RH5_leg/meshes/left_12lf_rod_end_2_visual.stl" />
      </geometry>
      <material name="12lf_rod_end_2_material">
        <color rgba="0.92771758928836534075 0.61049283053223002415 0.2184765849058516729 1.0" />
      </material>
    </visual>
    <collision>
      <origin xyz="0 0 0" rpy="0 -0 0" />
      <geometry>
        <mesh filename="../assemblies/left_3R+RH5_leg/meshes/left_12lf_rod_end_2_collision.stl" />
      </geometry>
    </collision>
    <inertial>
      <origin xyz="-4.4735193074030483235e-11 -0.003842218593824545201 6.4384187209441048154e-06" rpy="0 0 0" />
      <mass value="0.00085420491177815905965" />
      <inertia ixx="1.1840985264406749344e-08" ixy="2.0225978115032554807e-16" ixz="-9.2606419674121376397e-16" iyy="3.3549621576796854546e-09" iyz="7.4535631381834933143e-12" izz="1.2703522254419956764e-08" />
    </inertial>
  </link>

  <joint name="left_ank_R22" type="revolute">
    <origin xyz="1.3877787807814456755e-17 -0.010000000000000036637 -0.0019000000000000058509" rpy="1.5707963267949061059 -1.4285463212675062472 -1.5707963267949052177" />
    <parent link="ank_rr_link_2" />
    <child link="12lf_rod_end_2" />
    <axis xyz="0 0 1" />
    <limit effort="1" velocity="20" lower="-1.570796326794896558" upper="1.570796326794896558" />
    <joint_properties friction="0.0" />
  </joint>

  <joint name="left_ank_R12" type="revolute">
    <origin xyz="0.0099999999999999932693 0.012500000000000066613 -0.027900000000000039352" rpy="3.1415926535897904515 2.6926878995557896255e-15 -3.0405529889787885622" />
    <parent link="ank_roll_link" />
    <child link="ank_rr_link_2" />
    <axis xyz="0 0 1" />
    <limit effort="1" velocity="20" lower="-1.570796326794896558" upper="1.570796326794896558" />
    <joint_properties friction="0.0" />
  </joint>

  <joint name="left_ank_roll" type="revolute">
    <origin xyz="1.193489751472043281e-15 -0.00610000000000079836 -0.014600000000000288095" rpy="-1.5707963267948288344 -1.5707963267944542451 0" />
    <parent link="ank_pitch_link" />
    <child link="ank_roll_link" />
    <axis xyz="0 0 1" />
    <limit effort="1" velocity="20" lower="-1.570796326794896558" upper="1.570796326794896558" />
    <joint_properties friction="0.0" />
  </joint>

  <joint name="left_ank_pitch" type="revolute">
    <origin xyz="1.0842022241842927186e-18 -0.10000000000000006106 -0.0061999999999999867717" rpy="-3.141592653589793116 -1.9981846038921943663e-15 -1.570796326794896558" />
    <parent link="left_calf_link" />
    <child link="ank_pitch_link" />
    <axis xyz="0 0 1" />
    <limit effort="1" velocity="20" lower="-1.570796326794896558" upper="1.570796326794896558" />
    <joint_properties friction="0.0" />
  </joint>

  <link name="ball_joint_container">
    <visual>
      <origin xyz="0 0 0" rpy="0 -0 0" />
      <geometry>
        <mesh filename="../assemblies/left_3R+RH5_leg/meshes/left_ball_joint_container_visual.stl" />
      </geometry>
      <material name="ball_joint_container_material">
        <color rgba="0.61568627450980395466 0.81176470588235294379 0.92941176470588238168 1.0" />
      </material>
    </visual>
    <collision>
      <origin xyz="0 0 0" rpy="0 -0 0" />
      <geometry>
        <mesh filename="../assemblies/left_3R+RH5_leg/meshes/left_ball_joint_container_collision.stl" />
      </geometry>
    </collision>
    <inertial>
      <origin xyz="4.7221442975709636831e-19 -1.2157539084691861758e-19 -0.0097125341669083414126" rpy="0 0 0" />
      <mass value="4.803735642533054869e-05" />
      <inertia ixx="7.1865480628741666366e-10" ixy="-1.421490150844785112e-26" ixz="-1.4530380721804784323e-39" iyy="8.475420427718555978e-10" iyz="-1.8243249785865228861e-39" izz="1.8625314111651911712e-10" />
    </inertial>
  </link>

  <link name="ball_joint_ball">
    <visual>
      <origin xyz="0 0 0" rpy="0 -0 0" />
      <geometry>
        <mesh filename="../assemblies/left_3R+RH5_leg/meshes/left_ball_joint_ball_visual.stl" />
      </geometry>
      <material name="ball_joint_ball_material">
        <color rgba="0.3291302810242056065 0.44310466418644928188 0.69204871161977121741 1.0" />
      </material>
    </visual>
    <collision>
      <origin xyz="0 0 0" rpy="0 -0 0" />
      <geometry>
        <mesh filename="../assemblies/left_3R+RH5_leg/meshes/left_ball_joint_ball_collision.stl" />
      </geometry>
    </collision>
    <inertial>
      <origin xyz="-1.2187840768435616288e-18 -0.0010308669810016346004 1.3240902759699828661e-19" rpy="0 0 0" />
      <mass value="4.4053796295264630609e-05" />
      <inertia ixx="3.1285011349692541014e-10" ixy="5.8769689062812943358e-26" ixz="2.2290409120613672916e-26" iyy="6.2569568612795747298e-11" iyz="-5.3035962353690109681e-26" izz="3.1285321460376643623e-10" />
    </inertial>
  </link>

  <link name="12lf">
    <visual>
      <origin xyz="0 0 0" rpy="0 -0 0" />
      <geometry>
        <mesh filename="../assemblies/left_3R+RH5_leg/meshes/left_12lf_visual.stl" />
      </geometry>
      <material name="12lf_material">
        <color rgba="0.62004392100736027693 0.58836684613512635345 0.49897069021535678246 1.0" />
      </material>
    </visual>
    <collision>
      <origin xyz="0 0 0" rpy="0 -0 0" />
      <geometry>
        <mesh filename="../assemblies/left_3R+RH5_leg/meshes/left_12lf_collision.stl" />
      </geometry>
    </collision>
    <inertial>
      <origin xyz="0.0049084207243746558885 -0.0001380243994355282377 -0.02994700357716316777" rpy="0 0 0" />
      <mass value="0.044782197696050352054" />
      <inertia ixx="1.5260128421324721396e-05" ixy="2.2955773687015434455e-08" ixz="-8.1364204004104932134e-08" iyy="1.8188469778966113777e-05" iyz="-5.554224084309430267e-08" izz="5.1496273901764499242e-06" />
    </inertial>
  </link>

  <link name="12lf_rod">
    <visual>
      <origin xyz="0 0 0" rpy="0 -0 0" />
      <geometry>
        <mesh filename="../assemblies/left_3R+RH5_leg/meshes/left_12lf_rod_visual.stl" />
      </geometry>
      <material name="12lf_rod_material">
        <color rgba="0.80250260812861884396 0.89340612183512713163 0.94491811293548189088 1.0" />
      </material>
    </visual>
    <collision>
      <origin xyz="0 0 0" rpy="0 -0 0" />
      <geometry>
        <mesh filename="../assemblies/left_3R+RH5_leg/meshes/left_12lf_rod_collision.stl" />
      </geometry>
    </collision>
    <inertial>
      <origin xyz="-6.3222084044030599913e-07 4.6933255325242463709e-07 -0.012893387334327651578" rpy="0 0 0" />
      <mass value="0.0025088292483592140175" />
      <inertia ixx="2.6944521128627872589e-07" ixy="7.1389570352208077751e-15" ixz="1.3562243135683134105e-11" iyy="2.6944520001684417585e-07" iyz="-1.0089988427242790173e-11" izz="1.7809843599861032107e-08" />
    </inertial>
  </link>

  <joint name="left_ank_act1" type="prismatic">
    <origin xyz="2.2722093542849874925e-06 9.5062846483529028774e-16 -0.072660031604104974301" rpy="-3.1415926535896594451 8.6956799327801851499e-14 -2.2021168238262722738" />
    <parent link="12lf" />
    <child link="12lf_rod" />
    <axis xyz="0 0 1" />
    <limit effort="1" velocity="20" lower="0" upper="0.040000000000000000833" />
    <joint_properties friction="0.0" />
  </joint>

  <joint name="left_ank_B31" type="revolute">
    <origin xyz="-3.4694469519536141888e-18 -0.0064387505004004086384 -6.9388939039072283776e-18" rpy="-1.570796326794896558 0.16913440034103149889 1.5363542389808260585e-15" />
    <parent link="ball_joint_ball" />
    <child link="12lf" />
    <axis xyz="0 0 1" />
    <limit effort="1" velocity="20" lower="-0.785398163397448279" upper="0.785398163397448279" />
    <joint_properties friction="0.0" />
  </joint>

  <joint name="left_ank_B21" type="revolute">
    <origin xyz="0 0 -0.011499999999999996336" rpy="1.570796326794896558 -1.4285697747625092369 1.5707963267948912289" />
    <parent link="ball_joint_container" />
    <child link="ball_joint_ball" />
    <axis xyz="0 0 1" />
    <limit effort="1" velocity="20" lower="-0.785398163397448279" upper="0.785398163397448279" />
    <joint_properties friction="0.0" />
  </joint>

  <joint name="left_ank_B11" type="revolute">
    <origin xyz="0.008000000000000053943 -0.014999999999999985567 0.028299999999999915501" rpy="-1.57079632679489678 1.4696360140379260972 1.5707963267948892305" />
    <parent link="left_calf_link" />
    <child link="ball_joint_container" />
    <axis xyz="0 0 1" />
    <limit effort="1" velocity="20" lower="-0.785398163397448279" upper="0.785398163397448279" />
    <joint_properties friction="0.0" />
  </joint>

  <link name="ball_joint_container_2">
    <visual>
      <origin xyz="0 0 0" rpy="0 -0 0" />
      <geometry>
        <mesh filename="../assemblies/left_3R+RH5_leg/meshes/left_ball_joint_container_2_visual.stl" />
      </geometry>
      <material name="ball_joint_container_2_material">
        <color rgba="0.61568627450980395466 0.81176470588235294379 0.92941176470588238168 1.0" />
      </material>
    </visual>
    <collision>
      <origin xyz="0 0 0" rpy="0 -0 0" />
      <geometry>
        <mesh filename="../assemblies/left_3R+RH5_leg/meshes/left_ball_joint_container_2_collision.stl" />
      </geometry>
    </collision>
    <inertial>
      <origin xyz="4.7221442975707527938e-19 -2.7877151006475838412e-17 -0.0097125341669083414126" rpy="0 0 0" />
      <mass value="4.803735642533054869e-05" />
      <inertia ixx="7.1865480628741645687e-10" ixy="-7.8479576573146159873e-27" ixz="-5.4661027899486823274e-39" iyy="8.4754204277185539101e-10" iyz="-3.6300291765716983297e-39" izz="1.8625314111651911712e-10" />
    </inertial>
  </link>

  <link name="ball_joint_ball_2">
    <visual>
      <origin xyz="0 0 0" rpy="0 -0 0" />
      <geometry>
        <mesh filename="../assemblies/left_3R+RH5_leg/meshes/left_ball_joint_ball_2_visual.stl" />
      </geometry>
      <material name="ball_joint_ball_2_material">
        <color rgba="0.3291302810242056065 0.44310466418644928188 0.69204871161977121741 1.0" />
      </material>
    </visual>
    <collision>
      <origin xyz="0 0 0" rpy="0 -0 0" />
      <geometry>
        <mesh filename="../assemblies/left_3R+RH5_leg/meshes/left_ball_joint_ball_2_collision.stl" />
      </geometry>
    </collision>
    <inertial>
      <origin xyz="7.0933134036350132379e-19 -0.0010308669810016209394 -6.4355432276454393889e-18" rpy="0 0 0" />
      <mass value="4.4053796295264630609e-05" />
      <inertia ixx="3.1285011349692447956e-10" ixy="-1.2221233653671682663e-25" ixz="1.3874524286390583258e-27" iyy="6.2569568612795979942e-11" iyz="-7.383691167246965188e-26" izz="3.1285321460376555735e-10" />
    </inertial>
  </link>

  <link name="12lf_2">
    <visual>
      <origin xyz="0 0 0" rpy="0 -0 0" />
      <geometry>
        <mesh filename="../assemblies/left_3R+RH5_leg/meshes/left_12lf_2_visual.stl" />
      </geometry>
      <material name="12lf_2_material">
        <color rgba="0.62004392100736005489 0.58836684613512635345 0.49897069021535678246 1.0" />
      </material>
    </visual>
    <collision>
      <origin xyz="0 0 0" rpy="0 -0 0" />
      <geometry>
        <mesh filename="../assemblies/left_3R+RH5_leg/meshes/left_12lf_2_collision.stl" />
      </geometry>
    </collision>
    <inertial>
      <origin xyz="0.0049084207243678852628 -0.00013802439943754287507 -0.029947003577162144283" rpy="0 0 0" />
      <mass value="0.044782197696050352054" />
      <inertia ixx="1.526012842132411492e-05" ixy="2.2955773686902024684e-08" ixz="-8.1364204006934829506e-08" iyy="1.8188469778966909988e-05" iyz="-5.5542240844160366426e-08" izz="5.149627390177910209e-06" />
    </inertial>
  </link>

  <link name="12lf_rod_2">
    <visual>
      <origin xyz="0 0 0" rpy="0 -0 0" />
      <geometry>
        <mesh filename="../assemblies/left_3R+RH5_leg/meshes/left_12lf_rod_2_visual.stl" />
      </geometry>
      <material name="12lf_rod_2_material">
        <color rgba="0.80250260812861884396 0.89340612183512713163 0.94491811293548189088 1.0" />
      </material>
    </visual>
    <collision>
      <origin xyz="0 0 0" rpy="0 -0 0" />
      <geometry>
        <mesh filename="../assemblies/left_3R+RH5_leg/meshes/left_12lf_rod_2_collision.stl" />
      </geometry>
    </collision>
    <inertial>
      <origin xyz="-6.3222083682940327443e-07 4.6933255273116294363e-07 -0.012893387334328737515" rpy="0 0 0" />
      <mass value="0.0025088292483592140175" />
      <inertia ixx="2.6944521128621848067e-07" ixy="7.1389570380698167996e-15" ixz="1.3562243029622056966e-11" iyy="2.6944520001678393063e-07" iyz="-1.0089988411801239376e-11" izz="1.7809843599861002329e-08" />
    </inertial>
  </link>

  <joint name="left_ank_act2" type="prismatic">
    <origin xyz="2.2722093491103073637e-06 -6.5433769513845163601e-15 -0.072660030478827297706" rpy="-3.1415926535895009053 6.1538805987964111831e-14 -2.2021168238262798234" />
    <parent link="12lf_2" />
    <child link="12lf_rod_2" />
    <axis xyz="0 0 1" />
    <limit effort="1" velocity="20" lower="0" upper="0.040000000000000000833" />
    <joint_properties friction="0.0" />
  </joint>

  <joint name="left_ank_B32" type="revolute">
    <origin xyz="1.9949319973733281586e-17 -0.0064387505004002698605 1.3877787807814456755e-17" rpy="-1.5707963267948970021 -0.17993145005780439294 -1.804382386805444098e-17" />
    <parent link="ball_joint_ball_2" />
    <child link="12lf_2" />
    <axis xyz="0 0 1" />
    <limit effort="1" velocity="20" lower="-0.785398163397448279" upper="0.785398163397448279" />
    <joint_properties friction="0.0" />
  </joint>

  <joint name="left_ank_B22" type="revolute">
    <origin xyz="-6.9388939039072283776e-18 -8.3266726846886740532e-17 -0.011499999999999996336" rpy="1.5707963267948961139 -1.4285463212680367118 -1.5707963267948970021" />
    <parent link="ball_joint_container_2" />
    <child link="ball_joint_ball_2" />
    <axis xyz="0 0 1" />
    <limit effort="1" velocity="20" lower="-0.785398163397448279" upper="0.785398163397448279" />
    <joint_properties friction="0.0" />
  </joint>

  <joint name="left_ank_B12" type="revolute">
    <origin xyz="0.0080000000000000504735 -0.014999999999999930056 -0.011500000000000076134" rpy="-1.5707963267948958919 -1.4697566621822790722 1.5707963267948983344" />
    <parent link="left_calf_link" />
    <child link="ball_joint_container_2" />
    <axis xyz="0 0 1" />
    <limit effort="1" velocity="20" lower="-0.785398163397448279" upper="0.785398163397448279" />
    <joint_properties friction="0.0" />
  </joint>

  <joint name="left_knee" type="revolute">
    <origin xyz="-6.5714384231211065113e-15 0.09599999999999973832 0.027400000000000167277" rpy="-3.1415926535897891192 1.5325113271907731669e-16 -5.5621661637730288381e-17" />
    <parent link="left_hip_pitch_link" />
    <child link="left_calf_link" />
    <axis xyz="0 0 1" />
    <limit effort="1" velocity="20" lower="-1.570796326794896558" upper="2.2689280275926284602" />
    <joint_properties friction="0.0" />
  </joint>

  <joint name="left_hip_pitch" type="revolute">
    <origin xyz="-0.02400000071615384506 -0.019000000152441031548 -0.019000000152448098811" rpy="-1.570796326794478226 1.5707963267948008568 0" />
    <parent link="hip_roll_link" />
    <child link="left_hip_pitch_link" />
    <axis xyz="0 0 1" />
    <limit effort="1" velocity="20" lower="-1.570796326794896558" upper="1.570796326794896558" />
    <joint_properties friction="0.0" />
  </joint>

  <joint name="left_hip_roll" type="revolute">
    <origin xyz="0.019000000000000273614 -2.891526265917987331e-16 -0.026000000000000279832" rpy="-3.141592653589793116 -1.5707963267945983521 0" />
    <parent link="hip_yaw_link" />
    <child link="hip_roll_link" />
    <axis xyz="0 0 1" />
    <limit effort="1" velocity="20" lower="-1.570796326794896558" upper="1.570796326794896558" />
    <joint_properties friction="0.0" />
  </joint>


  <link name="hip_yaw_link_2">
    <visual>
      <origin xyz="0 0 0" rpy="0 -0 0" />
      <geometry>
        <mesh filename="../assemblies/right_3R+RH5_leg/meshes/right_hip_yaw_link_visual.stl" />
      </geometry>
      <material name="hip_yaw_link_material">
        <color rgba="0.61568627450980395466 0.81176470588235294379 0.9294117647058824927 1.0" />
      </material>
    </visual>
    <collision>
      <origin xyz="0 0 0" rpy="0 -0 0" />
      <geometry>
        <mesh filename="../assemblies/right_3R+RH5_leg/meshes/right_hip_yaw_link_collision.stl" />
      </geometry>
    </collision>
    <inertial>
      <origin xyz="-3.2018607255691728443e-19 -2.3813308128726619291e-19 -0.0098390489054829104176" rpy="0 0 0" />
      <mass value="0.0090258837370979193293" />
      <inertia ixx="1.3230458239085876461e-06" ixy="-6.4778545919079861077e-49" ixz="1.7322911775161985632e-33" iyy="3.8408510960330541809e-06" iyz="-1.4482241779965781819e-32" izz="3.8721396285793077728e-06" />
    </inertial>
  </link>

  <link name="hip_roll_link_2">
    <visual>
      <origin xyz="0 0 0" rpy="0 -0 0" />
      <geometry>
        <mesh filename="../assemblies/right_3R+RH5_leg/meshes/right_hip_roll_link_visual.stl" />
      </geometry>
      <material name="hip_roll_link_material">
        <color rgba="0.95018735644455853961 0.70678927200428420807 0.061612079402596685307 1.0" />
      </material>
    </visual>
    <collision>
      <origin xyz="0 0 0" rpy="0 -0 0" />
      <geometry>
        <mesh filename="../assemblies/right_3R+RH5_leg/meshes/right_hip_roll_link_collision.stl" />
      </geometry>
    </collision>
    <inertial>
      <origin xyz="-0.012000151133961673919 -0.00049588831385562702741 -0.018504019244505474917" rpy="0 0 0" />
      <mass value="0.09801239148352869357" />
      <inertia ixx="2.0221748766307252681e-05" ixy="-4.1552068245158521664e-08" ixz="-4.1225592187110666959e-08" iyy="2.7358099958307355976e-05" iyz="-5.09357317523940817e-07" izz="2.7358069524724029197e-05" />
    </inertial>
  </link>

  <link name="right_hip_pitch_link">
    <visual>
      <origin xyz="0 0 0" rpy="0 -0 0" />
      <geometry>
        <mesh filename="../assemblies/right_3R+RH5_leg/meshes/right_hip_pitch_link_visual.stl" />
      </geometry>
      <material name="right_hip_pitch_link_material">
        <color rgba="0.6165363060683557439 0.80730204019995621678 0.92176148067891638949 1.0" />
      </material>
    </visual>
    <collision>
      <origin xyz="0 0 0" rpy="0 -0 0" />
      <geometry>
        <mesh filename="../assemblies/right_3R+RH5_leg/meshes/right_hip_pitch_link_collision.stl" />
      </geometry>
    </collision>
    <inertial>
      <origin xyz="-1.4741268609430317041e-05 0.052986690876698230857 0.014788127171305285798" rpy="0 0 0" />
      <mass value="0.094084567879581956773" />
      <inertia ixx="6.3099182122443523281e-05" ixy="-2.2045192591950457029e-07" ixz="-1.2728889936275053518e-08" iyy="2.1759163818498174605e-05" iyz="-1.4708395298811945199e-06" izz="6.2821853547821560992e-05" />
    </inertial>
  </link>

  <link name="right_calf_link">
    <visual>
      <origin xyz="0 0 0" rpy="0 -0 0" />
      <geometry>
        <mesh filename="../assemblies/right_3R+RH5_leg/meshes/right_calf_link_visual.stl" />
      </geometry>
      <material name="right_calf_link_material">
        <color rgba="0.55397247693546480818 0.73161364570947462482 0.87715709724734269859 1.0" />
      </material>
    </visual>
    <collision>
      <origin xyz="0 0 0" rpy="0 -0 0" />
      <geometry>
        <mesh filename="../assemblies/right_3R+RH5_leg/meshes/right_calf_link_collision.stl" />
      </geometry>
    </collision>
    <inertial>
      <origin xyz="-0.0039136048281022978862 0.043639997035758590349 0.00818489966080624895" rpy="0 0 0" />
      <mass value="0.016290630569901022595" />
      <inertia ixx="1.5543964735761986858e-05" ixy="2.1605989306079682151e-07" ixz="7.0519548982950051303e-09" iyy="1.9364566813417035674e-06" iyz="-1.9645570089561787636e-08" izz="1.4807205615850144116e-05" />
    </inertial>
  </link>

  <link name="ank_pitch_link_2">
    <visual>
      <origin xyz="0 0 0" rpy="0 -0 0" />
      <geometry>
        <mesh filename="../assemblies/right_3R+RH5_leg/meshes/right_ank_pitch_link_visual.stl" />
      </geometry>
      <material name="ank_pitch_link_material">
        <color rgba="0.63189161126160275916 0.72668668793540891482 0.78356373393969258601 1.0" />
      </material>
    </visual>
    <collision>
      <origin xyz="0 0 0" rpy="0 -0 0" />
      <geometry>
        <mesh filename="../assemblies/right_3R+RH5_leg/meshes/right_ank_pitch_link_collision.stl" />
      </geometry>
    </collision>
    <inertial>
      <origin xyz="4.0269688367567309498e-08 0.00059528282566558574432 -0.014599922383890164002" rpy="0 0 0" />
      <mass value="0.0042238381753791605713" />
      <inertia ixx="4.3705254067389275737e-07" ixy="1.6834346806134810889e-13" ixz="1.6428822803056261784e-12" iyy="3.9782741364654728503e-07" iyz="2.0919225298754607721e-14" izz="8.885857453451233774e-08" />
    </inertial>
  </link>

  <link name="ank_roll_link_2">
    <visual>
      <origin xyz="0 0 0" rpy="0 -0 0" />
      <geometry>
        <mesh filename="../assemblies/right_3R+RH5_leg/meshes/right_ank_roll_link_visual.stl" />
      </geometry>
      <material name="ank_roll_link_material">
        <color rgba="0.61568627450980406568 0.81176470588235294379 0.92941176470588238168 1.0" />
      </material>
    </visual>
    <collision>
      <origin xyz="0 0 0" rpy="0 -0 0" />
      <geometry>
        <mesh filename="../assemblies/right_3R+RH5_leg/meshes/right_ank_roll_link_collision.stl" />
      </geometry>
    </collision>
    <inertial>
      <origin xyz="-6.3661537447489043807e-10 0.027240102316353698858 0.0019830147448535368794" rpy="0 0 0" />
      <mass value="0.013844478784760250178" />
      <inertia ixx="1.0150902309234932519e-05" ixy="6.8603302703203350579e-14" ixz="-3.2605547319693936681e-13" iyy="8.66361166634314672e-06" iyz="-7.8151778926544826665e-07" izz="2.8991570356470342998e-06" />
    </inertial>
  </link>

  <link name="ank_rr_link_3">
    <visual>
      <origin xyz="0 0 0" rpy="0 -0 0" />
      <geometry>
        <mesh filename="../assemblies/right_3R+RH5_leg/meshes/right_ank_rr_link_visual.stl" />
      </geometry>
      <material name="ank_rr_link_material">
        <color rgba="0.61568627450980395466 0.81176470588235294379 0.92941176470588238168 1.0" />
      </material>
    </visual>
    <collision>
      <origin xyz="0 0 0" rpy="0 -0 0" />
      <geometry>
        <mesh filename="../assemblies/right_3R+RH5_leg/meshes/right_ank_rr_link_collision.stl" />
      </geometry>
    </collision>
    <inertial>
      <origin xyz="3.459350369005387098e-05 0.0062999445222072687767 -0.0019000000000000060677" rpy="0 0 0" />
      <mass value="0.00044289790445047668311" />
      <inertia ixx="9.0894755004835289854e-09" ixy="-5.6689994077039824953e-11" ixz="1.0879024115047053847e-14" iyy="8.3785129146959922129e-09" iyz="-1.3636225223714339418e-33" izz="1.3107013728801488166e-08" />
    </inertial>
  </link>

  <link name="12lf_rod_end_3">
    <visual>
      <origin xyz="0 0 0" rpy="0 -0 0" />
      <geometry>
        <mesh filename="../assemblies/right_3R+RH5_leg/meshes/right_12lf_rod_end_visual.stl" />
      </geometry>
      <material name="12lf_rod_end_material">
        <color rgba="0.92771758928836534075 0.61049283053223002415 0.2184765849058516729 1.0" />
      </material>
    </visual>
    <collision>
      <origin xyz="0 0 0" rpy="0 -0 0" />
      <geometry>
        <mesh filename="../assemblies/right_3R+RH5_leg/meshes/right_12lf_rod_end_collision.stl" />
      </geometry>
    </collision>
    <inertial>
      <origin xyz="-4.4735189197312852573e-11 -0.0038422185938246015795 6.4384187209424954528e-06" rpy="0 0 0" />
      <mass value="0.00085420491177815905965" />
      <inertia ixx="1.1840985264406813864e-08" ixy="2.0225977154373117355e-16" ixz="-9.2606419595995018092e-16" iyy="3.3549621576797297088e-09" iyz="7.4535631381859457756e-12" izz="1.2703522254419979925e-08" />
    </inertial>
  </link>

  <joint name="right_ank_R21" type="revolute">
    <origin xyz="0 0.010000000000000092149 -0.0019000000000000058509" rpy="1.570796326794896558 1.4285697747627268406 -1.5707963267948945596" />
    <parent link="ank_rr_link_3" />
    <child link="12lf_rod_end_3" />
    <axis xyz="0 0 1" />
    <limit effort="1" velocity="20" lower="-1.570796326794896558" upper="1.570796326794896558" />
    <joint_properties friction="0.0" />
  </joint>

  <joint name="right_ank_R11" type="revolute">
    <origin xyz="-0.0099999999999999984734 0.012500000000000066613 -0.027900000000000015066" rpy="-3.1415926535897860106 -4.3778626236368231385e-15 -0.10116031275681484913" />
    <parent link="ank_roll_link_2" />
    <child link="ank_rr_link_3" />
    <axis xyz="0 0 1" />
    <limit effort="1" velocity="20" lower="-1.570796326794896558" upper="1.570796326794896558" />
    <joint_properties friction="0.0" />
  </joint>

  <link name="ank_rr_link_4">
    <visual>
      <origin xyz="0 0 0" rpy="0 -0 0" />
      <geometry>
        <mesh filename="../assemblies/right_3R+RH5_leg/meshes/right_ank_rr_link_2_visual.stl" />
      </geometry>
      <material name="ank_rr_link_2_material">
        <color rgba="0.61568627450980395466 0.81176470588235294379 0.92941176470588238168 1.0" />
      </material>
    </visual>
    <collision>
      <origin xyz="0 0 0" rpy="0 -0 0" />
      <geometry>
        <mesh filename="../assemblies/right_3R+RH5_leg/meshes/right_ank_rr_link_2_collision.stl" />
      </geometry>
    </collision>
    <inertial>
      <origin xyz="3.4593503690060884413e-05 -0.0062999445222072132655 -0.0018999999999999986951" rpy="0 0 0" />
      <mass value="0.00044289790445047668311" />
      <inertia ixx="9.0894755004835223679e-09" ixy="5.6689994077039740942e-11" ixz="-1.0879024115047049114e-14" iyy="8.3785129146959922129e-09" iyz="-6.0612730259481631136e-32" izz="1.3107013728801488166e-08" />
    </inertial>
  </link>

  <link name="12lf_rod_end_4">
    <visual>
      <origin xyz="0 0 0" rpy="0 -0 0" />
      <geometry>
        <mesh filename="../assemblies/right_3R+RH5_leg/meshes/right_12lf_rod_end_2_visual.stl" />
      </geometry>
      <material name="12lf_rod_end_2_material">
        <color rgba="0.92771758928836534075 0.61049283053223013518 0.2184765849058516729 1.0" />
      </material>
    </visual>
    <collision>
      <origin xyz="0 0 0" rpy="0 -0 0" />
      <geometry>
        <mesh filename="../assemblies/right_3R+RH5_leg/meshes/right_12lf_rod_end_2_collision.stl" />
      </geometry>
    </collision>
    <inertial>
      <origin xyz="-4.4735204136892274106e-11 -0.0038422185938245530072 6.4384187209516840662e-06" rpy="0 0 0" />
      <mass value="0.00085420491177815905965" />
      <inertia ixx="1.1840985264406808901e-08" ixy="2.0225978134093855094e-16" ixz="-9.2606419947073501327e-16" iyy="3.3549621576797280544e-09" iyz="7.4535631381824383359e-12" izz="1.2703522254420001432e-08" />
    </inertial>
  </link>

  <joint name="right_ank_R22" type="revolute">
    <origin xyz="6.9388939039072283776e-18 -0.010000000000000064393 -0.001899999999999998912" rpy="1.570796326794896558 -1.4285463212679276879 -1.5707963267948938935" />
    <parent link="ank_rr_link_4" />
    <child link="12lf_rod_end_4" />
    <axis xyz="0 0 1" />
    <limit effort="1" velocity="20" lower="-1.570796326794896558" upper="1.570796326794896558" />
    <joint_properties friction="0.0" />
  </joint>

  <joint name="right_ank_R12" type="revolute">
    <origin xyz="0.010000000000000000208 0.012500000000000011102 -0.027900000000000001188" rpy="-3.1415926535897829019 -8.8337259752553850467e-15 -3.040552988977761828" />
    <parent link="ank_roll_link_2" />
    <child link="ank_rr_link_4" />
    <axis xyz="0 0 1" />
    <limit effort="1" velocity="20" lower="-1.570796326794896558" upper="1.570796326794896558" />
    <joint_properties friction="0.0" />
  </joint>

  <joint name="right_ank_roll" type="revolute">
    <origin xyz="2.1926904736346841673e-15 -0.0061000000000001799311 -0.014600000000002237924" rpy="-1.5707963267949249797 1.5707963267947928632 0" />
    <parent link="ank_pitch_link_2" />
    <child link="ank_roll_link_2" />
    <axis xyz="0 0 1" />
    <limit effort="1" velocity="20" lower="-1.570796326794896558" upper="1.570796326794896558" />
    <joint_properties friction="0.0" />
  </joint>

  <joint name="right_ank_pitch" type="revolute">
    <origin xyz="7.5714896865366240827e-19 0.10000000000000003331 -0.00619999999999999718" rpy="-3.141592653589793116 1.998618284759728781e-15 -1.57079632679489678" />
    <parent link="right_calf_link" />
    <child link="ank_pitch_link_2" />
    <axis xyz="0 0 1" />
    <limit effort="1" velocity="20" lower="-1.570796326794896558" upper="1.570796326794896558" />
    <joint_properties friction="0.0" />
  </joint>

  <link name="ball_joint_container_3">
    <visual>
      <origin xyz="0 0 0" rpy="0 -0 0" />
      <geometry>
        <mesh filename="../assemblies/right_3R+RH5_leg/meshes/right_ball_joint_container_visual.stl" />
      </geometry>
      <material name="ball_joint_container_material">
        <color rgba="0.61568627450980395466 0.81176470588235294379 0.92941176470588238168 1.0" />
      </material>
    </visual>
    <collision>
      <origin xyz="0 0 0" rpy="0 -0 0" />
      <geometry>
        <mesh filename="../assemblies/right_3R+RH5_leg/meshes/right_ball_joint_container_collision.stl" />
      </geometry>
    </collision>
    <inertial>
      <origin xyz="4.7221442975710628685e-19 -1.2157539084691885832e-19 -0.0097125341669083414126" rpy="0 0 0" />
      <mass value="4.803735642533054869e-05" />
      <inertia ixx="7.1865480628741645687e-10" ixy="3.1140965352978280468e-27" ixz="1.4328660807762231563e-39" iyy="8.475420427718555978e-10" iyz="2.8401411200500544021e-39" izz="1.8625314111651911712e-10" />
    </inertial>
  </link>

  <link name="ball_joint_ball_3">
    <visual>
      <origin xyz="0 0 0" rpy="0 -0 0" />
      <geometry>
        <mesh filename="../assemblies/right_3R+RH5_leg/meshes/right_ball_joint_ball_visual.stl" />
      </geometry>
      <material name="ball_joint_ball_material">
        <color rgba="0.3291302810242056065 0.44310466418644928188 0.69204871161977121741 1.0" />
      </material>
    </visual>
    <collision>
      <origin xyz="0 0 0" rpy="0 -0 0" />
      <geometry>
        <mesh filename="../assemblies/right_3R+RH5_leg/meshes/right_ball_joint_ball_collision.stl" />
      </geometry>
    </collision>
    <inertial>
      <origin xyz="5.6428119846086643469e-18 -0.0010308669810016194215 4.365579381130705669e-18" rpy="0 0 0" />
      <mass value="4.4053796295264630609e-05" />
      <inertia ixx="3.1285011349692354898e-10" ixy="1.415450016100750243e-26" ixz="-1.3091779433564061785e-26" iyy="6.2569568612795721448e-11" iyz="1.4597275321104013589e-25" izz="3.1285321460376069766e-10" />
    </inertial>
  </link>

  <link name="12lf_3">
    <visual>
      <origin xyz="0 0 0" rpy="0 -0 0" />
      <geometry>
        <mesh filename="../assemblies/right_3R+RH5_leg/meshes/right_12lf_visual.stl" />
      </geometry>
      <material name="12lf_material">
        <color rgba="0.62004392100736016591 0.58836684613512635345 0.49897069021535672695 1.0" />
      </material>
    </visual>
    <collision>
      <origin xyz="0 0 0" rpy="0 -0 0" />
      <geometry>
        <mesh filename="../assemblies/right_3R+RH5_leg/meshes/right_12lf_collision.stl" />
      </geometry>
    </collision>
    <inertial>
      <origin xyz="0.0049084207243671419338 -0.00013802439943486974751 -0.029947003577148179759" rpy="0 0 0" />
      <mass value="0.044782197696050352054" />
      <inertia ixx="1.5260128421313293227e-05" ixy="2.2955773686476013434e-08" ixz="-8.1364204007545407912e-08" iyy="1.8188469778952530756e-05" iyz="-5.5542240842733737949e-08" izz="5.1496273901742569559e-06" />
    </inertial>
  </link>

  <link name="12lf_rod_3">
    <visual>
      <origin xyz="0 0 0" rpy="0 -0 0" />
      <geometry>
        <mesh filename="../assemblies/right_3R+RH5_leg/meshes/right_12lf_rod_visual.stl" />
      </geometry>
      <material name="12lf_rod_material">
        <color rgba="0.80250260812861884396 0.89340612183512713163 0.94491811293548189088 1.0" />
      </material>
    </visual>
    <collision>
      <origin xyz="0 0 0" rpy="0 -0 0" />
      <geometry>
        <mesh filename="../assemblies/right_3R+RH5_leg/meshes/right_12lf_rod_collision.stl" />
      </geometry>
    </collision>
    <inertial>
      <origin xyz="-6.3222084032422818052e-07 4.6933255136373052952e-07 -0.012893387334331167862" rpy="0 0 0" />
      <mass value="0.0025088292483592140175" />
      <inertia ixx="2.6944521128608380243e-07" ixy="7.1389570185008819562e-15" ixz="1.356224313133588478e-11" iyy="2.6944520001664930533e-07" iyz="-1.0089988374182569229e-11" izz="1.7809843599861008946e-08" />
    </inertial>
  </link>

  <joint name="right_ank_act1" type="prismatic">
    <origin xyz="2.2722093427473416538e-06 1.2559397966072083364e-15 -0.07266003160412204398" rpy="-3.1415926535897895633 9.1629640935489764995e-15 -2.2021168238260711014" />
    <parent link="12lf_3" />
    <child link="12lf_rod_3" />
    <axis xyz="0 0 1" />
    <limit effort="1" velocity="20" lower="0" upper="0.040000000000000000833" />
    <joint_properties friction="0.0" />
  </joint>

  <joint name="right_ank_B31" type="revolute">
    <origin xyz="1.4745149545802860303e-17 -0.006438750500400436394 0" rpy="-1.5707963267948961139 0.16913440034159002434 1.9223858256087746368e-15" />
    <parent link="ball_joint_ball_3" />
    <child link="12lf_3" />
    <axis xyz="0 0 1" />
    <limit effort="1" velocity="20" lower="-0.785398163397448279" upper="0.785398163397448279" />
    <joint_properties friction="0.0" />
  </joint>

  <joint name="right_ank_B21" type="revolute">
    <origin xyz="-6.9388939039072283776e-18 0 -0.011500000000000006745" rpy="1.570796326794896558 -1.4285697747625620835 1.5707963267948821251" />
    <parent link="ball_joint_container_3" />
    <child link="ball_joint_ball_3" />
    <axis xyz="0 0 1" />
    <limit effort="1" velocity="20" lower="-0.785398163397448279" upper="0.785398163397448279" />
    <joint_properties friction="0.0" />
  </joint>

  <joint name="right_ank_B11" type="revolute">
    <origin xyz="0.0080000000000000001665 0.015000000000000041078 -0.011499999999999994602" rpy="1.570796326794896558 -1.469636014037949634 -1.5707963267948781283" />
    <parent link="right_calf_link" />
    <child link="ball_joint_container_3" />
    <axis xyz="0 0 1" />
    <limit effort="1" velocity="20" lower="-0.785398163397448279" upper="0.785398163397448279" />
    <joint_properties friction="0.0" />
  </joint>

  <link name="ball_joint_container_4">
    <visual>
      <origin xyz="0 0 0" rpy="0 -0 0" />
      <geometry>
        <mesh filename="../assemblies/right_3R+RH5_leg/meshes/right_ball_joint_container_2_visual.stl" />
      </geometry>
      <material name="ball_joint_container_2_material">
        <color rgba="0.61568627450980395466 0.81176470588235294379 0.92941176470588238168 1.0" />
      </material>
    </visual>
    <collision>
      <origin xyz="0 0 0" rpy="0 -0 0" />
      <geometry>
        <mesh filename="../assemblies/right_3R+RH5_leg/meshes/right_ball_joint_container_2_collision.stl" />
      </geometry>
    </collision>
    <inertial>
      <origin xyz="-6.4666794741500939722e-18 -2.7877151006475875389e-17 -0.0097125341669083414126" rpy="0 0 0" />
      <mass value="4.803735642533054869e-05" />
      <inertia ixx="7.1865480628741666366e-10" ixy="-2.0783391115791823941e-26" ixz="3.1652999021518679796e-39" iyy="8.475420427718555978e-10" iyz="-3.9494410211107681417e-39" izz="1.8625314111651911712e-10" />
    </inertial>
  </link>

  <link name="ball_joint_ball_4">
    <visual>
      <origin xyz="0 0 0" rpy="0 -0 0" />
      <geometry>
        <mesh filename="../assemblies/right_3R+RH5_leg/meshes/right_ball_joint_ball_2_visual.stl" />
      </geometry>
      <material name="ball_joint_ball_2_material">
        <color rgba="0.3291302810242056065 0.44310466418644928188 0.69204871161977121741 1.0" />
      </material>
    </visual>
    <collision>
      <origin xyz="0 0 0" rpy="0 -0 0" />
      <geometry>
        <mesh filename="../assemblies/right_3R+RH5_leg/meshes/right_ball_joint_ball_2_collision.stl" />
      </geometry>
    </collision>
    <inertial>
      <origin xyz="3.3502121566618523985e-18 -0.0010308669810016289625 4.9241549307208647846e-18" rpy="0 0 0" />
      <mass value="4.4053796295264630609e-05" />
      <inertia ixx="3.1285011349692546184e-10" ixy="9.4860751699672687948e-26" ixz="-2.9478649192256477463e-26" iyy="6.2569568612795773147e-11" iyz="2.4978453668081973161e-25" izz="3.1285321460376669472e-10" />
    </inertial>
  </link>

  <link name="12lf_4">
    <visual>
      <origin xyz="0 0 0" rpy="0 -0 0" />
      <geometry>
        <mesh filename="../assemblies/right_3R+RH5_leg/meshes/right_12lf_2_visual.stl" />
      </geometry>
      <material name="12lf_2_material">
        <color rgba="0.62004392100736027693 0.58836684613512624242 0.49897069021535683797 1.0" />
      </material>
    </visual>
    <collision>
      <origin xyz="0 0 0" rpy="0 -0 0" />
      <geometry>
        <mesh filename="../assemblies/right_3R+RH5_leg/meshes/right_12lf_2_collision.stl" />
      </geometry>
    </collision>
    <inertial>
      <origin xyz="0.0049084207243654410374 -0.00013802439943710355635 -0.029947003577146587283" rpy="0 0 0" />
      <mass value="0.044782197696050358993" />
      <inertia ixx="1.5260128421312154815e-05" ixy="2.2955773686777639881e-08" ixz="-8.1364204008306268492e-08" iyy="1.8188469778949566141e-05" iyz="-5.5542240843717149819e-08" izz="5.1496273901724044948e-06" />
    </inertial>
  </link>

  <link name="12lf_rod_4">
    <visual>
      <origin xyz="0 0 0" rpy="0 -0 0" />
      <geometry>
        <mesh filename="../assemblies/right_3R+RH5_leg/meshes/right_12lf_rod_2_visual.stl" />
      </geometry>
      <material name="12lf_rod_2_material">
        <color rgba="0.80250260812861884396 0.89340612183512713163 0.94491811293548189088 1.0" />
      </material>
    </visual>
    <collision>
      <origin xyz="0 0 0" rpy="0 -0 0" />
      <geometry>
        <mesh filename="../assemblies/right_3R+RH5_leg/meshes/right_12lf_rod_2_collision.stl" />
      </geometry>
    </collision>
    <inertial>
      <origin xyz="-6.3222084132559095428e-07 4.6933255080501092155e-07 -0.012893387334332481048" rpy="0 0 0" />
      <mass value="0.0025088292483592140175" />
      <inertia ixx="2.6944521128601101054e-07" ixy="7.1389570226419978119e-15" ixz="1.3562243158150225497e-11" iyy="2.6944520001657651344e-07" iyz="-1.0089988358335071468e-11" izz="1.7809843599861012255e-08" />
    </inertial>
  </link>

  <joint name="right_ank_act2" type="prismatic">
    <origin xyz="2.2722093417394673143e-06 -2.3939183968479937903e-15 -0.072660030478831599821" rpy="3.141592653589793116 -2.0657592427741678223e-15 -2.2021168238262744943" />
    <parent link="12lf_4" />
    <child link="12lf_rod_4" />
    <axis xyz="0 0 1" />
    <limit effort="1" velocity="20" lower="0" upper="0.040000000000000000833" />
    <joint_properties friction="0.0" />
  </joint>

  <joint name="right_ank_B32" type="revolute">
    <origin xyz="5.6378512969246230568e-18 -0.006438750500400436394 0" rpy="-1.570796326794896336 -0.17993145005752267385 1.8689858510975082391e-15" />
    <parent link="ball_joint_ball_4" />
    <child link="12lf_4" />
    <axis xyz="0 0 1" />
    <limit effort="1" velocity="20" lower="-0.785398163397448279" upper="0.785398163397448279" />
    <joint_properties friction="0.0" />
  </joint>

  <joint name="right_ank_B22" type="revolute">
    <origin xyz="-6.9388939039072283776e-18 -2.7755575615628913511e-17 -0.011499999999999999806" rpy="1.570796326794896558 -1.4285463212677993461 1.5707963267949389685" />
    <parent link="ball_joint_container_4" />
    <child link="ball_joint_ball_4" />
    <axis xyz="0 0 1" />
    <limit effort="1" velocity="20" lower="-0.785398163397448279" upper="0.785398163397448279" />
    <joint_properties friction="0.0" />
  </joint>

  <joint name="right_ank_B12" type="revolute">
    <origin xyz="0.0080000000000000088402 0.015000000000000068834 0.02829999999999998489" rpy="-1.5707963267948383823 -1.4697566621827073963 1.5707963267948992225" />
    <parent link="right_calf_link" />
    <child link="ball_joint_container_4" />
    <axis xyz="0 0 1" />
    <limit effort="1" velocity="20" lower="-0.785398163397448279" upper="0.785398163397448279" />
    <joint_properties friction="0.0" />
  </joint>

  <joint name="right_knee" type="revolute">
    <origin xyz="-1.8821214288092669642e-15 0.096000000000001001199 0.027399999999998970318" rpy="3.1415926535897220617 -3.0356441407590551802e-14 3.1415926535897846783" />
    <parent link="right_hip_pitch_link" />
    <child link="right_calf_link" />
    <axis xyz="0 0 1" />
    <limit effort="1" velocity="20" lower="-1.570796326794896558" upper="1.570796326794896558" />
    <joint_properties friction="0.0" />
  </joint>

  <joint name="right_hip_pitch" type="revolute">
    <origin xyz="-0.024000000716146760449 -0.019000000152456297114 -0.019000000152450020885" rpy="-1.5707963267951789987 1.5707963267947411268 0" />
    <parent link="hip_roll_link_2" />
    <child link="right_hip_pitch_link" />
    <axis xyz="0 0 1" />
    <limit effort="1" velocity="20" lower="-1.570796326794896558" upper="1.570796326794896558" />
    <joint_properties friction="0.0" />
  </joint>

  <joint name="right_hip_roll" type="revolute">
    <origin xyz="-0.018999999999999881567 -3.3500438889867783387e-18 -0.026000000000000002276" rpy="3.0518439807331778725e-31 -1.5707963267948181763 0" />
    <parent link="hip_yaw_link_2" />
    <child link="hip_roll_link_2" />
    <axis xyz="0 0 1" />
    <limit effort="1" velocity="20" lower="-1.570796326794896558" upper="1.570796326794896558" />
    <joint_properties friction="0.0" />
  </joint>


  <link name="sho_pitch_link">
    <visual>
      <origin xyz="0 0 0" rpy="0 -0 0" />
      <geometry>
        <mesh filename="../assemblies/left_OP3_arm/meshes/left_sho_pitch_link_visual.stl" />
      </geometry>
      <material name="sho_pitch_link_material">
        <color rgba="0.61568627450980395466 0.81176470588235283277 0.92941176470588227065 1.0" />
      </material>
    </visual>
    <collision>
      <origin xyz="0 0 0" rpy="0 -0 0" />
      <geometry>
        <mesh filename="../assemblies/left_OP3_arm/meshes/left_sho_pitch_link_collision.stl" />
      </geometry>
    </collision>
    <inertial>
      <origin xyz="-3.0491385322450835177e-09 0.0021980515983192182999 -0.0084441034778716152209" rpy="0 0 0" />
      <mass value="0.0053168741776095304608" />
      <inertia ixx="8.004236836171299241e-07" ixy="1.1695537858705935527e-13" ixz="1.0217073886595013911e-14" iyy="1.8515753414330839236e-06" iyz="1.1638006198091620256e-07" izz="1.9553421197543973429e-06" />
    </inertial>
  </link>

  <link name="sho_roll_link">
    <visual>
      <origin xyz="0 0 0" rpy="0 -0 0" />
      <geometry>
        <mesh filename="../assemblies/left_OP3_arm/meshes/left_sho_roll_link_visual.stl" />
      </geometry>
      <material name="sho_roll_link_material">
        <color rgba="0.41316897434350019491 0.53241982866399872876 0.7282853555714716709 1.0" />
      </material>
    </visual>
    <collision>
      <origin xyz="0 0 0" rpy="0 -0 0" />
      <geometry>
        <mesh filename="../assemblies/left_OP3_arm/meshes/left_sho_roll_link_collision.stl" />
      </geometry>
    </collision>
    <inertial>
      <origin xyz="-0.044750001376316579649 -2.2393377634863600994e-09 -0.018770420156107039955" rpy="0 0 0" />
      <mass value="0.14104718485994710564" />
      <inertia ixx="2.5744677667987862931e-05" ixy="3.3646118940713150311e-08" ixz="-3.0796530997963203869e-12" iyy="0.00018303238190424636449" iyz="-7.9852770998995561417e-12" izz="0.00017803089038969846904" />
    </inertial>
  </link>

  <link name="elb_link">
    <visual>
      <origin xyz="0 0 0" rpy="0 -0 0" />
      <geometry>
        <mesh filename="../assemblies/left_OP3_arm/meshes/left_elb_link_visual.stl" />
      </geometry>
      <material name="elb_link_material">
        <color rgba="0.632763333624367319 0.72211014553089536427 0.77571823267481221365 1.0" />
      </material>
    </visual>
    <collision>
      <origin xyz="0 0 0" rpy="0 -0 0" />
      <geometry>
        <mesh filename="../assemblies/left_OP3_arm/meshes/left_elb_link_collision.stl" />
      </geometry>
    </collision>
    <inertial>
      <origin xyz="0.0035809919318981042052 0.051692930824585224536 0.01899999963962420782" rpy="0 0 0" />
      <mass value="0.012147845014428809707" />
      <inertia ixx="1.027507046601793286e-05" ixy="-8.3735105743537730385e-07" ixz="2.4555248808517769692e-13" iyy="3.0584432934239921256e-06" iyz="2.6984977430863263703e-14" izz="8.4465004716585834205e-06" />
    </inertial>
  </link>

  <joint name="left_elb" type="revolute">
    <origin xyz="-0.089499999999999663158 -3.2265856653168611956e-16 5.9049987122250513494e-15" rpy="3.1415926535897367167 2.2793048768987009608e-14 -1.5707963267948858999" />
    <parent link="sho_roll_link" />
    <child link="elb_link" />
    <axis xyz="0 0 1" />
    <limit effort="1" velocity="20" lower="-1.570796326794896558" upper="1.570796326794896558" />
    <joint_properties friction="0.0" />
  </joint>

  <joint name="left_sho_roll" type="revolute">
    <origin xyz="-0.018999999999999999528 0.0089999999999999646255 -0.027499999999999986261" rpy="-6.3254956828146051492e-14 -1.5707963267948947816 0" />
    <parent link="sho_pitch_link" />
    <child link="sho_roll_link" />
    <axis xyz="0 0 1" />
    <limit effort="1" velocity="20" lower="-1.570796326794896558" upper="1.570796326794896558" />
    <joint_properties friction="0.0" />
  </joint>


  <link name="sho_pitch_link_2">
    <visual>
      <origin xyz="0 0 0" rpy="0 -0 0" />
      <geometry>
        <mesh filename="../assemblies/right_OP3_arm/meshes/right_sho_pitch_link_visual.stl" />
      </geometry>
      <material name="sho_pitch_link_material">
        <color rgba="0.61568627450980395466 0.81176470588235283277 0.92941176470588227065 1.0" />
      </material>
    </visual>
    <collision>
      <origin xyz="0 0 0" rpy="0 -0 0" />
      <geometry>
        <mesh filename="../assemblies/right_OP3_arm/meshes/right_sho_pitch_link_collision.stl" />
      </geometry>
    </collision>
    <inertial>
      <origin xyz="-3.0491385351734712174e-09 0.0021980515983192256725 -0.0084441034778715892001" rpy="0 0 0" />
      <mass value="0.0053168741776095304608" />
      <inertia ixx="8.0042368361712717124e-07" ixy="1.1695537505388646426e-13" ixz="1.0217073731545412732e-14" iyy="1.8515753414330767238e-06" iyz="1.1638006198091051156e-07" izz="1.9553421197543837904e-06" />
    </inertial>
  </link>

  <link name="sho_roll_link_2">
    <visual>
      <origin xyz="0 0 0" rpy="0 -0 0" />
      <geometry>
        <mesh filename="../assemblies/right_OP3_arm/meshes/right_sho_roll_link_visual.stl" />
      </geometry>
      <material name="sho_roll_link_material">
        <color rgba="0.41316897434350019491 0.53241982866399850671 0.7282853555714716709 1.0" />
      </material>
    </visual>
    <collision>
      <origin xyz="0 0 0" rpy="0 -0 0" />
      <geometry>
        <mesh filename="../assemblies/right_OP3_arm/meshes/right_sho_roll_link_collision.stl" />
      </geometry>
    </collision>
    <inertial>
      <origin xyz="-0.044750001376316607404 -2.2393423855841148494e-09 -0.018770420156104722365" rpy="0 0 0" />
      <mass value="0.1410471848599471334" />
      <inertia ixx="2.5744677667987917141e-05" ixy="3.3646118925508730236e-08" ixz="-3.0796450636638775403e-12" iyy="0.0001830323819042464458" iyz="-7.9852776609581744581e-12" izz="0.00017803089038969868588" />
    </inertial>
  </link>

  <link name="elb_link_2">
    <visual>
      <origin xyz="0 0 0" rpy="0 -0 0" />
      <geometry>
        <mesh filename="../assemblies/right_OP3_arm/meshes/right_elb_link_visual.stl" />
      </geometry>
      <material name="elb_link_material">
        <color rgba="0.632763333624367319 0.72211014553089536427 0.77571823267481221365 1.0" />
      </material>
    </visual>
    <collision>
      <origin xyz="0 0 0" rpy="0 -0 0" />
      <geometry>
        <mesh filename="../assemblies/right_OP3_arm/meshes/right_elb_link_collision.stl" />
      </geometry>
    </collision>
    <inertial>
      <origin xyz="0.0035809919318979593558 -0.051692930824585030247 0.019000000360375912667" rpy="0 0 0" />
      <mass value="0.012147845014428809707" />
      <inertia ixx="1.0275070466017685526e-05" ixy="8.3735105743541351451e-07" ixz="-2.4555242187966786883e-13" iyy="3.0584432934239370684e-06" iyz="2.6985065764368432904e-14" izz="8.4465004716583818266e-06" />
    </inertial>
  </link>

  <joint name="right_elb" type="revolute">
    <origin xyz="-0.08949999999999827538 -7.2650219173908681114e-15 1.0956513474269513608e-14" rpy="-3.1415926535897145122 9.187667647645342109e-14 1.5707963267949796027" />
    <parent link="sho_roll_link_2" />
    <child link="elb_link_2" />
    <axis xyz="0 0 1" />
    <limit effort="1" velocity="20" lower="-1.570796326794896558" upper="1.570796326794896558" />
    <joint_properties friction="0.0" />
  </joint>

  <joint name="right_sho_roll" type="revolute">
    <origin xyz="0.018999999999999954425 0.0089999999999999576866 -0.027499999999999899525" rpy="-3.1415926535896976368 -1.5707963267948958919 0" />
    <parent link="sho_pitch_link_2" />
    <child link="sho_roll_link_2" />
    <axis xyz="0 0 1" />
    <limit effort="1" velocity="20" lower="-1.570796326794896558" upper="1.570796326794896558" />
    <joint_properties friction="0.0" />
  </joint>


</robot>