<robot name="base">
  <mujoco>
    <compiler strippath="false" balanceinertia="true" discardvisual="false" />
  </mujoco>
  <link name="base_link" />
  <joint name="base_link_to_base" type="fixed">
    <parent link="base_link" />
    <child link="body_link" />
    <origin rpy="0.0 0 0" xyz="0 0 0" />
  </joint>
  <link name="body_link">
    <visual>
      <origin xyz="0 0 0" rpy="0 -0 0" />
      <geometry>
        <mesh filename="../assemblies/4R_body/meshes/body_link_visual.stl" />
      </geometry>
      <material name="body_link_material">
        <color rgba="0.5924023255223024309 0.77493742445477598046 0.89675162167089705889 1.0" />
      </material>
    </visual>
    <collision>
      <origin xyz="0 0 0" rpy="0 -0 0" />
      <geometry>
        <mesh filename="../assemblies/4R_body/meshes/body_link_collision.stl" />
      </geometry>
    </collision>
    <inertial>
      <origin xyz="-0.016892539113329191336 1.8329806416258032297e-07 0.37034501400110925173" rpy="0 0 0" />
      <mass value="1.3010345634555104954" />
      <inertia ixx="0.0047624725171278572619" ixy="1.225473646717127599e-09" ixz="2.5710312085007236876e-05" iyy="0.003667668918322326832" iyz="7.2555792615186997727e-09" izz="0.003205257716390450852" />
    </inertial>
  </link>

  <link name="neck_link">
    <visual>
      <origin xyz="0 0 0" rpy="0 -0 0" />
      <geometry>
        <mesh filename="../assemblies/4R_body/meshes/neck_link_visual.stl" />
      </geometry>
      <material name="neck_link_material">
        <color rgba="0.61568627450980395466 0.81176470588235294379 0.92941176470588238168 1.0" />
      </material>
    </visual>
    <collision>
      <origin xyz="0 0 0" rpy="0 -0 0" />
      <geometry>
        <mesh filename="../assemblies/4R_body/meshes/neck_link_collision.stl" />
      </geometry>
    </collision>
    <inertial>
      <origin xyz="3.067903593042405049e-19 -5.1123361372111250322e-20 -0.020000000000000000416" rpy="0 0 0" />
      <mass value="0.018378317023500286703" />
      <inertia ixx="3.4842226023719301187e-06" ixy="2.6492046803872183431e-38" ixz="-4.2946359314041097936e-38" iyy="3.4842226023719301187e-06" iyz="-3.2653968785718786279e-70" izz="2.06756066514378241e-06" />
    </inertial>
  </link>

  <link name="head_link">
    <visual>
      <origin xyz="0 0 0" rpy="0 -0 0" />
      <geometry>
        <mesh filename="../assemblies/4R_body/meshes/head_link_visual.stl" />
      </geometry>
      <material name="head_link_material">
        <color rgba="0.79607843137254907795 0.82352941176470584317 0.93725490196078442562 1.0" />
      </material>
    </visual>
    <collision>
      <origin xyz="0 0 0" rpy="0 -0 0" />
      <geometry>
        <mesh filename="../assemblies/4R_body/meshes/head_link_collision.stl" />
      </geometry>
    </collision>
    <inertial>
      <origin xyz="0.0011121374382810683603 0.002300308913386693143 -0.012472157860955830275" rpy="0 0 0" />
      <mass value="0.075015538754887006734" />
      <inertia ixx="6.8018019107715040579e-06" ixy="6.7244456377383520563e-07" ixz="2.3059386910262087019e-09" iyy="4.5222250439264427752e-05" iyz="-1.2119065455131472216e-08" izz="4.5708811148256761484e-05" />
    </inertial>
  </link>

  <joint name="head" type="fixed">
    <origin xyz="-4.1826855620466421722e-19 -2.6020852139652106416e-18 -0.039999999999999980016" rpy="-3.6199375412562401434e-16 -2.4218742848029192401e-16 -5.5511151231257722251e-17" />
    <parent link="neck_link" />
    <child link="head_link" />
    <axis xyz="0 0 1" />
    <limit effort="1" velocity="20" />
    <joint_properties friction="0.0" />
  </joint>

  <joint name="neck" type="fixed">
    <origin xyz="-0.0063999999999999838268 -5.2372852656669075105e-18 0.43249999999999999556" rpy="-3.141592653589793116 8.5053965662326763145e-17 1.57079632679489678" />
    <parent link="body_link" />
    <child link="neck_link" />
    <axis xyz="0 0 1" />
    <limit effort="1" velocity="20" />
    <joint_properties friction="0.0" />
  </joint>

  <joint name="left_hip_yaw" type="revolute">
    <origin xyz="-0.011900000000000070244 0.033999999999999974687 0.27720000000000011298" rpy="-2.2204460494577687078e-16 2.2204460491536837829e-16 -1.0069344447037764778e-13" />
    <parent link="body_link" />
    <child link="hip_yaw_link" />
    <axis xyz="0 0 1" />
    <limit effort="1" velocity="20" lower="-1.570796326794896558" upper="1.570796326794896558" />
    <joint_properties friction="0.0" />
  </joint>

  <joint name="right_hip_yaw" type="revolute">
    <origin xyz="-0.011900000000000259329 -0.033999999999999981626 0.27720000000000000195" rpy="-2.2204460717259335277e-16 2.2204461793479381443e-16 -6.6849266279598662255e-15" />
    <parent link="body_link" />
    <child link="hip_yaw_link_2" />
    <axis xyz="0 0 1" />
    <limit effort="1" velocity="20" lower="-1.570796326794896558" upper="1.570796326794896558" />
    <joint_properties friction="0.0" />
  </joint>

  <joint name="left_sho_pitch" type="revolute">
    <origin xyz="-0.0064000000000001278089 0.057999999999999600486 0.41249999999999986677" rpy="-1.570796326794871911 3.5360603334311235812e-14 -3.1415926535897371608" />
    <parent link="body_link" />
    <child link="sho_pitch_link" />
    <axis xyz="0 0 1" />
    <limit effort="1" velocity="20" lower="-1.570796326794896558" upper="1.570796326794896558" />
    <joint_properties friction="0.0" />
  </joint>

  <joint name="right_sho_pitch" type="revolute">
    <origin xyz="-0.0063999999999999916331 -0.057999999999999989064 0.4124999999999999778" rpy="-1.5707963267948972241 1.3877787807856806753e-15 6.3545304591998415249e-17" />
    <parent link="body_link" />
    <child link="sho_pitch_link_2" />
    <axis xyz="0 0 1" />
    <limit effort="1" velocity="20" lower="-1.570796326794896558" upper="1.570796326794896558" />
    <joint_properties friction="0.0" />
  </joint>


  <link name="hip_yaw_link">
    <visual>
      <origin xyz="0 0 0" rpy="0 -0 0" />
      <geometry>
        <mesh filename="../assemblies/left_3R+RH5_leg/meshes/left_hip_yaw_link_visual.stl" />
      </geometry>
      <material name="hip_yaw_link_material">
        <color rgba="0.61568627450980395466 0.81176470588235294379 0.9294117647058824927 1.0" />
      </material>
    </visual>
    <collision>
      <origin xyz="0 0 0" rpy="0 -0 0" />
      <geometry>
        <mesh filename="../assemblies/left_3R+RH5_leg/meshes/left_hip_yaw_link_collision.stl" />
      </geometry>
    </collision>
    <inertial>
      <origin xyz="-1.4892375467611331877e-20 3.966544230008890712e-19 -0.009839048905483014501" rpy="0 0 0" />
      <mass value="0.0090258837370979193293" />
      <inertia ixx="1.3230458239086465149e-06" ixy="-3.3592249637948231893e-24" ixz="-1.1251788840973426872e-52" iyy="3.8408510960331422723e-06" iyz="2.3044956050358332095e-34" izz="3.8721396285793907821e-06" />
    </inertial>
  </link>

  <link name="hip_roll_link">
    <visual>
      <origin xyz="0 0 0" rpy="0 -0 0" />
      <geometry>
        <mesh filename="../assemblies/left_3R+RH5_leg/meshes/left_hip_roll_link_visual.stl" />
      </geometry>
      <material name="hip_roll_link_material">
        <color rgba="0.95018735644455865064 0.70678927200428420807 0.061612079402596699185 1.0" />
      </material>
    </visual>
    <collision>
      <origin xyz="0 0 0" rpy="0 -0 0" />
      <geometry>
        <mesh filename="../assemblies/left_3R+RH5_leg/meshes/left_hip_roll_link_collision.stl" />
      </geometry>
    </collision>
    <inertial>
      <origin xyz="-0.012000151133961396363 -0.00049588831384953402804 -0.018504019244504728986" rpy="0 0 0" />
      <mass value="0.098012391483528679692" />
      <inertia ixx="2.0221748766306463246e-05" ixy="-4.1552068243118092086e-08" ixz="-4.1225592188160160633e-08" iyy="2.7358099958307189958e-05" iyz="-5.0935731752381037393e-07" izz="2.7358069524723229598e-05" />
    </inertial>
  </link>

  <link name="left_hip_pitch_link">
    <visual>
      <origin xyz="0 0 0" rpy="0 -0 0" />
      <geometry>
        <mesh filename="../assemblies/left_3R+RH5_leg/meshes/left_hip_pitch_link_visual.stl" />
      </geometry>
      <material name="left_hip_pitch_link_material">
        <color rgba="0.61653630588246988165 0.80730204117585691037 0.92176148235188926083 1.0" />
      </material>
    </visual>
    <collision>
      <origin xyz="0 0 0" rpy="0 -0 0" />
      <geometry>
        <mesh filename="../assemblies/left_3R+RH5_leg/meshes/left_hip_pitch_link_collision.stl" />
      </geometry>
    </collision>
    <inertial>
      <origin xyz="-0.00021632240618358220484 0.052986695633820024565 0.014788126099014515732" rpy="0 0 0" />
      <mass value="0.094084588454108858402" />
      <inertia ixx="6.3099190805816174842e-05" ixy="4.2254461504174176627e-07" ixz="-1.5223568275358377134e-07" iyy="2.1754782765193058833e-05" iyz="-1.4708367336520467186e-06" izz="6.2817482611037618514e-05" />
    </inertial>
  </link>

  <link name="left_calf_link">
    <visual>
      <origin xyz="0 0 0" rpy="0 -0 0" />
      <geometry>
        <mesh filename="../assemblies/left_3R+RH5_leg/meshes/left_calf_link_visual.stl" />
      </geometry>
      <material name="left_calf_link_material">
        <color rgba="0.55397243078540503447 0.73161358475427695769 0.87715705664081478066 1.0" />
      </material>
    </visual>
    <collision>
      <origin xyz="0 0 0" rpy="0 -0 0" />
      <geometry>
        <mesh filename="../assemblies/left_3R+RH5_leg/meshes/left_calf_link_collision.stl" />
      </geometry>
    </collision>
    <inertial>
      <origin xyz="-0.0039136163069529794969 -0.043640010796484503264 0.0081849279519870133531" rpy="0 0 0" />
      <mass value="0.016290616864051549878" />
      <inertia ixx="1.5543943584208743725e-05" ixy="-2.1605519114066121883e-07" ixz="7.0470291476150814932e-09" iyy="1.9364407917964761494e-06" iyz="1.9633933099789637219e-08" izz="1.4807197003527088815e-05" />
    </inertial>
  </link>

  <link name="ank_pitch_link">
    <visual>
      <origin xyz="0 0 0" rpy="0 -0 0" />
      <geometry>
        <mesh filename="../assemblies/left_3R+RH5_leg/meshes/left_ank_pitch_link_visual.stl" />
      </geometry>
      <material name="ank_pitch_link_material">
        <color rgba="0.63189161126160275916 0.72668668793540891482 0.78356373393969258601 1.0" />
      </material>
    </visual>
    <collision>
      <origin xyz="0 0 0" rpy="0 -0 0" />
      <geometry>
        <mesh filename="../assemblies/left_3R+RH5_leg/meshes/left_ank_pitch_link_collision.stl" />
      </geometry>
    </collision>
    <inertial>
      <origin xyz="4.026968507737488953e-08 0.00059528282566739039883 -0.014599922383890481456" rpy="0 0 0" />
      <mass value="0.0042238381753791605713" />
      <inertia ixx="4.3705254067385321152e-07" ixy="1.6834346764733790142e-13" ixz="1.6428822479797578164e-12" iyy="3.9782741364647126382e-07" iyz="2.0919252888484807591e-14" izz="8.8858574534548839566e-08" />
    </inertial>
  </link>

  <link name="ank_roll_link">
    <visual>
      <origin xyz="0 0 0" rpy="0 -0 0" />
      <geometry>
        <mesh filename="../assemblies/left_3R+RH5_leg/meshes/left_ank_roll_link_visual.stl" />
      </geometry>
      <material name="ank_roll_link_material">
        <color rgba="0.61568627450980395466 0.81176470588235305481 0.92941176470588227065 1.0" />
      </material>
    </visual>
    <collision>
      <origin xyz="0 0 0" rpy="0 -0 0" />
      <geometry>
        <mesh filename="../assemblies/left_3R+RH5_leg/meshes/left_ank_roll_link_collision.stl" />
      </geometry>
    </collision>
    <inertial>
      <origin xyz="-6.3661537441910641154e-10 0.027240102316353705797 -0.0056169852551464618043" rpy="0 0 0" />
      <mass value="0.013844478784760251913" />
      <inertia ixx="1.015090230923494099e-05" ixy="6.8603302692161456229e-14" ixz="-3.2605547317950546507e-13" iyy="8.66361166634314672e-06" iyz="-7.8151778926544985484e-07" izz="2.8991570356470427702e-06" />
    </inertial>
  </link>

  <link name="ank_rr_link">
    <visual>
      <origin xyz="0 0 0" rpy="0 -0 0" />
      <geometry>
        <mesh filename="../assemblies/left_3R+RH5_leg/meshes/left_ank_rr_link_visual.stl" />
      </geometry>
      <material name="ank_rr_link_material">
        <color rgba="0.61568627450980395466 0.81176470588235294379 0.92941176470588238168 1.0" />
      </material>
    </visual>
    <collision>
      <origin xyz="0 0 0" rpy="0 -0 0" />
      <geometry>
        <mesh filename="../assemblies/left_3R+RH5_leg/meshes/left_ank_rr_link_collision.stl" />
      </geometry>
    </collision>
    <inertial>
      <origin xyz="3.4593503690053688021e-05 -0.0062999445222071577544 2.2902669769463380408e-19" rpy="0 0 0" />
      <mass value="0.00044289790445047673732" />
      <inertia ixx="9.089475500483527331e-09" ixy="5.668999407703981849e-11" ixz="-1.0879024115036759212e-14" iyy="8.3785129146959905585e-09" iyz="1.6391214081100160018e-31" izz="1.3107013728801488166e-08" />
    </inertial>
  </link>

  <link name="12lf_rod_end">
    <visual>
      <origin xyz="0 0 0" rpy="0 -0 0" />
      <geometry>
        <mesh filename="../assemblies/left_3R+RH5_leg/meshes/left_12lf_rod_end_visual.stl" />
      </geometry>
      <material name="12lf_rod_end_material">
        <color rgba="0.92771758928836534075 0.61049283053223002415 0.2184765849058516729 1.0" />
      </material>
    </visual>
    <collision>
      <origin xyz="0 0 0" rpy="0 -0 0" />
      <geometry>
        <mesh filename="../assemblies/left_3R+RH5_leg/meshes/left_12lf_rod_end_collision.stl" />
      </geometry>
    </collision>
    <inertial>
      <origin xyz="-4.473520001561125718e-11 -0.0038422185938246067836 6.4384187209444402404e-06" rpy="0 0 0" />
      <mass value="0.00085420491177815905965" />
      <inertia ixx="1.1840985264406803937e-08" ixy="2.022597843744187292e-16" ixz="-9.2606419918934951166e-16" iyy="3.3549621576797603144e-09" iyz="7.4535631381817743296e-12" izz="1.2703522254420022938e-08" />
    </inertial>
  </link>

  <joint name="left_ank_R21" type="revolute">
    <origin xyz="0 -0.010000000000000036637 -2.0816681711721685133e-17" rpy="-1.5707963267949025532 -1.4285697747629921839 1.5707963267949025532" />
    <parent link="ank_rr_link" />
    <child link="12lf_rod_end" />
    <axis xyz="0 0 1" />
    <limit effort="1" velocity="20" lower="-1.570796326794896558" upper="1.570796326794896558" />
    <joint_properties friction="0.0" />
  </joint>

  <joint name="left_ank_R11" type="revolute">
    <origin xyz="-0.0099999999999999915345 0.012499999999999872324 -0.033600000000000004863" rpy="1.6323812772036896109e-17 1.4002646486553138019e-17 -0.10116031275705798798" />
    <parent link="ank_roll_link" />
    <child link="ank_rr_link" />
    <axis xyz="0 0 1" />
    <limit effort="1" velocity="20" lower="-1.570796326794896558" upper="1.570796326794896558" />
    <joint_properties friction="0.0" />
  </joint>

  <link name="ank_rr_link_2">
    <visual>
      <origin xyz="0 0 0" rpy="0 -0 0" />
      <geometry>
        <mesh filename="../assemblies/left_3R+RH5_leg/meshes/left_ank_rr_link_2_visual.stl" />
      </geometry>
      <material name="ank_rr_link_2_material">
        <color rgba="0.61568627450980395466 0.81176470588235294379 0.92941176470588238168 1.0" />
      </material>
    </visual>
    <collision>
      <origin xyz="0 0 0" rpy="0 -0 0" />
      <geometry>
        <mesh filename="../assemblies/left_3R+RH5_leg/meshes/left_ank_rr_link_2_collision.stl" />
      </geometry>
    </collision>
    <inertial>
      <origin xyz="3.4593503690053674468e-05 -0.0062999445222072123982 -6.7098672062125900958e-18" rpy="0 0 0" />
      <mass value="0.00044289790445047673732" />
      <inertia ixx="9.0894755004835306397e-09" ixy="5.6689994077040018823e-11" ixz="-1.0879024115036762368e-14" iyy="8.3785129146959872498e-09" iyz="-2.6982978837278030063e-32" izz="1.3107013728801488166e-08" />
    </inertial>
  </link>

  <link name="12lf_rod_end_2">
    <visual>
      <origin xyz="0 0 0" rpy="0 -0 0" />
      <geometry>
        <mesh filename="../assemblies/left_3R+RH5_leg/meshes/left_12lf_rod_end_2_visual.stl" />
      </geometry>
      <material name="12lf_rod_end_2_material">
        <color rgba="0.92771758928836534075 0.61049283053223002415 0.2184765849058516729 1.0" />
      </material>
    </visual>
    <collision>
      <origin xyz="0 0 0" rpy="0 -0 0" />
      <geometry>
        <mesh filename="../assemblies/left_3R+RH5_leg/meshes/left_12lf_rod_end_2_collision.stl" />
      </geometry>
    </collision>
    <inertial>
      <origin xyz="-4.4735189715912923357e-11 -0.0038422185938245820638 6.4384187209439091508e-06" rpy="0 0 0" />
      <mass value="0.00085420491177815905965" />
      <inertia ixx="1.1840985264406810555e-08" ixy="2.0225977934550601649e-16" ixz="-9.2606419851216231998e-16" iyy="3.354962157679735499e-09" iyz="7.4535631381822606213e-12" izz="1.2703522254420004741e-08" />
    </inertial>
  </link>

  <joint name="left_ank_R22" type="revolute">
    <origin xyz="-6.9388939039072283776e-18 -0.010000000000000008882 0" rpy="1.570796326794896558 -1.4285463212677487199 -1.5707963267948970021" />
    <parent link="ank_rr_link_2" />
    <child link="12lf_rod_end_2" />
    <axis xyz="0 0 1" />
    <limit effort="1" velocity="20" lower="-1.570796326794896558" upper="1.570796326794896558" />
    <joint_properties friction="0.0" />
  </joint>

  <joint name="left_ank_R12" type="revolute">
    <origin xyz="0.0099999999999999984734 0.012499999999999761302 -0.033599999999999997924" rpy="3.1415926535897824579 9.4861357133311978266e-15 -3.0405529889788134312" />
    <parent link="ank_roll_link" />
    <child link="ank_rr_link_2" />
    <axis xyz="0 0 1" />
    <limit effort="1" velocity="20" lower="-1.570796326794896558" upper="1.570796326794896558" />
    <joint_properties friction="0.0" />
  </joint>

  <joint name="left_ank_roll" type="revolute">
    <origin xyz="2.2759572004815709079e-15 0.0015000000000041896053 -0.014599999999999611552" rpy="-1.570796326795051101 -1.5707963267944144992 0" />
    <parent link="ank_pitch_link" />
    <child link="ank_roll_link" />
    <axis xyz="0 0 1" />
    <limit effort="1" velocity="20" lower="-1.570796326794896558" upper="1.570796326794896558" />
    <joint_properties friction="0.0" />
  </joint>

  <joint name="left_ank_pitch" type="revolute">
    <origin xyz="9.1534583908775112557e-19 -0.10000000000000003331 -0.0061999999999999989148" rpy="3.1415926535897926719 -8.7927079361011792447e-15 -1.5707963267948961139" />
    <parent link="left_calf_link" />
    <child link="ank_pitch_link" />
    <axis xyz="0 0 1" />
    <limit effort="1" velocity="20" lower="-1.570796326794896558" upper="1.570796326794896558" />
    <joint_properties friction="0.0" />
  </joint>

  <link name="ball_joint_container">
    <visual>
      <origin xyz="0 0 0" rpy="0 -0 0" />
      <geometry>
        <mesh filename="../assemblies/left_3R+RH5_leg/meshes/left_ball_joint_container_visual.stl" />
      </geometry>
      <material name="ball_joint_container_material">
        <color rgba="0.61568627450980395466 0.81176470588235294379 0.92941176470588238168 1.0" />
      </material>
    </visual>
    <collision>
      <origin xyz="0 0 0" rpy="0 -0 0" />
      <geometry>
        <mesh filename="../assemblies/left_3R+RH5_leg/meshes/left_ball_joint_container_collision.stl" />
      </geometry>
    </collision>
    <inertial>
      <origin xyz="4.7221442975709424979e-19 2.7634000224781997854e-17 -0.0097125341669083414126" rpy="0 0 0" />
      <mass value="4.803735642533054869e-05" />
      <inertia ixx="7.1865480628741666366e-10" ixy="-3.4743251124436435837e-27" ixz="3.7630329617305141944e-39" iyy="8.475420427718555978e-10" iyz="-3.491409188473297406e-39" izz="1.8625314111651911712e-10" />
    </inertial>
  </link>

  <link name="ball_joint_ball">
    <visual>
      <origin xyz="0 0 0" rpy="0 -0 0" />
      <geometry>
        <mesh filename="../assemblies/left_3R+RH5_leg/meshes/left_ball_joint_ball_visual.stl" />
      </geometry>
      <material name="ball_joint_ball_material">
        <color rgba="0.3291302810242056065 0.44310466418644928188 0.69204871161977121741 1.0" />
      </material>
    </visual>
    <collision>
      <origin xyz="0 0 0" rpy="0 -0 0" />
      <geometry>
        <mesh filename="../assemblies/left_3R+RH5_leg/meshes/left_ball_joint_ball_collision.stl" />
      </geometry>
    </collision>
    <inertial>
      <origin xyz="-2.3253468712152024354e-18 -0.0010308669810016202889 7.5370947834070964575e-18" rpy="0 0 0" />
      <mass value="4.4053796295264630609e-05" />
      <inertia ixx="3.128501134969269094e-10" ixy="2.3037156279423985182e-26" ixz="6.8350401001252389427e-26" iyy="6.2569568612796186738e-11" iyz="-1.2712568099819904986e-25" izz="3.1285321460377238159e-10" />
    </inertial>
  </link>

  <link name="12lf">
    <visual>
      <origin xyz="0 0 0" rpy="0 -0 0" />
      <geometry>
        <mesh filename="../assemblies/left_3R+RH5_leg/meshes/left_12lf_visual.stl" />
      </geometry>
      <material name="12lf_material">
        <color rgba="0.62004392100736027693 0.58836684613512635345 0.49897069021535678246 1.0" />
      </material>
    </visual>
    <collision>
      <origin xyz="0 0 0" rpy="0 -0 0" />
      <geometry>
        <mesh filename="../assemblies/left_3R+RH5_leg/meshes/left_12lf_collision.stl" />
      </geometry>
    </collision>
    <inertial>
      <origin xyz="0.0049084207243746619601 -0.00013802439943551156809 -0.02994700357716317124" rpy="0 0 0" />
      <mass value="0.044782197696050352054" />
      <inertia ixx="1.5260128421324704455e-05" ixy="2.295577368701645685e-08" ixz="-8.1364204004110954009e-08" iyy="1.8188469778966096836e-05" iyz="-5.5542240843093171087e-08" izz="5.1496273901764499242e-06" />
    </inertial>
  </link>

  <link name="12lf_rod">
    <visual>
      <origin xyz="0 0 0" rpy="0 -0 0" />
      <geometry>
        <mesh filename="../assemblies/left_3R+RH5_leg/meshes/left_12lf_rod_visual.stl" />
      </geometry>
      <material name="12lf_rod_material">
        <color rgba="0.80250260812861884396 0.89340612183512713163 0.94491811293548189088 1.0" />
      </material>
    </visual>
    <collision>
      <origin xyz="0 0 0" rpy="0 -0 0" />
      <geometry>
        <mesh filename="../assemblies/left_3R+RH5_leg/meshes/left_12lf_rod_collision.stl" />
      </geometry>
    </collision>
    <inertial>
      <origin xyz="-6.3222084044054274484e-07 4.6933255325336066144e-07 -0.012893387334327629026" rpy="0 0 0" />
      <mass value="0.0025088292483592140175" />
      <inertia ixx="2.6944521128627835531e-07" ixy="7.1389570161813106174e-15" ixz="1.3562243135674815447e-11" iyy="2.6944520001684380527e-07" iyz="-1.0089988427266287272e-11" izz="1.7809843599861032107e-08" />
    </inertial>
  </link>

  <joint name="left_ank_act1" type="prismatic">
    <origin xyz="2.2722093543023347273e-06 9.5756735873919751612e-16 -0.072660031604096092517" rpy="-3.1415926535896594451 8.5062006308179150635e-14 -2.2021168238262847083" />
    <parent link="12lf" />
    <child link="12lf_rod" />
    <axis xyz="0 0 1" />
    <limit effort="1" velocity="20" lower="0" upper="0.040000000000000000833" />
    <joint_properties friction="0.0" />
  </joint>

  <joint name="left_ank_B31" type="revolute">
    <origin xyz="4.336808689942017736e-19 -0.0064387505004004641496 6.9388939039072283776e-18" rpy="-1.57079632679489678 0.16913440034102095177 4.5559338426713504067e-15" />
    <parent link="ball_joint_ball" />
    <child link="12lf" />
    <axis xyz="0 0 1" />
    <limit effort="1" velocity="20" lower="-0.785398163397448279" upper="0.785398163397448279" />
    <joint_properties friction="0.0" />
  </joint>

  <joint name="left_ank_B21" type="revolute">
    <origin xyz="0 2.7755575615628913511e-17 -0.011499999999999999806" rpy="1.570796326794896558 -1.4285697747625467624 1.5707963267948807928" />
    <parent link="ball_joint_container" />
    <child link="ball_joint_ball" />
    <axis xyz="0 0 1" />
    <limit effort="1" velocity="20" lower="-0.785398163397448279" upper="0.785398163397448279" />
    <joint_properties friction="0.0" />
  </joint>

  <joint name="left_ank_B11" type="revolute">
    <origin xyz="0.0079999999999999880235 -0.015000000000000041078 0.028300000000000005707" rpy="-1.570796326794896558 1.469636014037934757 1.5707963267948754638" />
    <parent link="left_calf_link" />
    <child link="ball_joint_container" />
    <axis xyz="0 0 1" />
    <limit effort="1" velocity="20" lower="-0.785398163397448279" upper="0.785398163397448279" />
    <joint_properties friction="0.0" />
  </joint>

  <link name="ball_joint_container_2">
    <visual>
      <origin xyz="0 0 0" rpy="0 -0 0" />
      <geometry>
        <mesh filename="../assemblies/left_3R+RH5_leg/meshes/left_ball_joint_container_2_visual.stl" />
      </geometry>
      <material name="ball_joint_container_2_material">
        <color rgba="0.61568627450980395466 0.81176470588235294379 0.92941176470588238168 1.0" />
      </material>
    </visual>
    <collision>
      <origin xyz="0 0 0" rpy="0 -0 0" />
      <geometry>
        <mesh filename="../assemblies/left_3R+RH5_leg/meshes/left_ball_joint_container_2_collision.stl" />
      </geometry>
    </collision>
    <inertial>
      <origin xyz="4.7221442975709357571e-19 -1.2157539084691921943e-19 -0.0097125341669083431473" rpy="0 0 0" />
      <mass value="4.803735642533054869e-05" />
      <inertia ixx="7.1865480628741666366e-10" ixy="5.8900531446197729655e-29" ixz="8.3848741101523981788e-39" iyy="8.475420427718555978e-10" iyz="-8.9837792996627276308e-39" izz="1.8625314111651911712e-10" />
    </inertial>
  </link>

  <link name="ball_joint_ball_2">
    <visual>
      <origin xyz="0 0 0" rpy="0 -0 0" />
      <geometry>
        <mesh filename="../assemblies/left_3R+RH5_leg/meshes/left_ball_joint_ball_2_visual.stl" />
      </geometry>
      <material name="ball_joint_ball_2_material">
        <color rgba="0.3291302810242056065 0.44310466418644928188 0.69204871161977121741 1.0" />
      </material>
    </visual>
    <collision>
      <origin xyz="0 0 0" rpy="0 -0 0" />
      <geometry>
        <mesh filename="../assemblies/left_3R+RH5_leg/meshes/left_ball_joint_ball_2_collision.stl" />
      </geometry>
    </collision>
    <inertial>
      <origin xyz="6.6925217834688338703e-18 -0.001030866981001670379 1.5569977136113586989e-18" rpy="0 0 0" />
      <mass value="4.4053796295264630609e-05" />
      <inertia ixx="3.1285011349692577203e-10" ixy="-3.4626890209578548396e-25" ixz="3.7795285763919379621e-27" iyy="6.2569568612796910521e-11" iyz="-2.0455197868117900813e-25" izz="3.1285321460377165781e-10" />
    </inertial>
  </link>

  <link name="12lf_2">
    <visual>
      <origin xyz="0 0 0" rpy="0 -0 0" />
      <geometry>
        <mesh filename="../assemblies/left_3R+RH5_leg/meshes/left_12lf_2_visual.stl" />
      </geometry>
      <material name="12lf_2_material">
        <color rgba="0.62004392100736005489 0.58836684613512635345 0.49897069021535678246 1.0" />
      </material>
    </visual>
    <collision>
      <origin xyz="0 0 0" rpy="0 -0 0" />
      <geometry>
        <mesh filename="../assemblies/left_3R+RH5_leg/meshes/left_12lf_2_collision.stl" />
      </geometry>
    </collision>
    <inertial>
      <origin xyz="0.0049084207243678913343 -0.00013802439943754352559 -0.0299470035771621651" rpy="0 0 0" />
      <mass value="0.044782197696050352054" />
      <inertia ixx="1.5260128421324108144e-05" ixy="2.2955773686901508523e-08" ixz="-8.1364204006931719307e-08" iyy="1.8188469778966906599e-05" iyz="-5.5542240844159843648e-08" izz="5.149627390177911056e-06" />
    </inertial>
  </link>

  <link name="12lf_rod_2">
    <visual>
      <origin xyz="0 0 0" rpy="0 -0 0" />
      <geometry>
        <mesh filename="../assemblies/left_3R+RH5_leg/meshes/left_12lf_rod_2_visual.stl" />
      </geometry>
      <material name="12lf_rod_2_material">
        <color rgba="0.80250260812861884396 0.89340612183512713163 0.94491811293548189088 1.0" />
      </material>
    </visual>
    <collision>
      <origin xyz="0 0 0" rpy="0 -0 0" />
      <geometry>
        <mesh filename="../assemblies/left_3R+RH5_leg/meshes/left_12lf_rod_2_collision.stl" />
      </geometry>
    </collision>
    <inertial>
      <origin xyz="-6.3222083682058968486e-07 4.6933255272327976681e-07 -0.012893387334328714963" rpy="0 0 0" />
      <mass value="0.0025088292483592140175" />
      <inertia ixx="2.6944521128621816303e-07" ixy="7.1389570398540213743e-15" ixz="1.3562243029603674816e-11" iyy="2.6944520001678361299e-07" iyz="-1.008998841178227723e-11" izz="1.7809843599861002329e-08" />
    </inertial>
  </link>

  <joint name="left_ank_act2" type="prismatic">
    <origin xyz="2.2722093491519407271e-06 -6.5988881026157741871e-15 -0.072660030478819720434" rpy="-3.1415926535895000171 5.9263713871214940499e-14 -2.2021168238262815997" />
    <parent link="12lf_2" />
    <child link="12lf_rod_2" />
    <axis xyz="0 0 1" />
    <limit effort="1" velocity="20" lower="0" upper="0.040000000000000000833" />
    <joint_properties friction="0.0" />
  </joint>

  <joint name="left_ank_B32" type="revolute">
    <origin xyz="1.4311468676808658529e-17 -0.0064387505004005751719 6.9388939039072283776e-18" rpy="-1.5707963267948972241 -0.17993145005787733459 6.7429791500468328215e-16" />
    <parent link="ball_joint_ball_2" />
    <child link="12lf_2" />
    <axis xyz="0 0 1" />
    <limit effort="1" velocity="20" lower="-0.785398163397448279" upper="0.785398163397448279" />
    <joint_properties friction="0.0" />
  </joint>

  <joint name="left_ank_B22" type="revolute">
    <origin xyz="-3.4694469519536141888e-17 -2.7755575615628913511e-16 -0.01149999999999988011" rpy="1.570796326794896558 -1.4285463212680655776 -1.5707963267948985564" />
    <parent link="ball_joint_container_2" />
    <child link="ball_joint_ball_2" />
    <axis xyz="0 0 1" />
    <limit effort="1" velocity="20" lower="-0.785398163397448279" upper="0.785398163397448279" />
    <joint_properties friction="0.0" />
  </joint>

  <joint name="left_ank_B12" type="revolute">
    <origin xyz="0.0080000000000001268013 -0.014999999999999791278 -0.011499999999999987663" rpy="-1.570796326794896558 -1.4697566621822597543 1.5707963267949038855" />
    <parent link="left_calf_link" />
    <child link="ball_joint_container_2" />
    <axis xyz="0 0 1" />
    <limit effort="1" velocity="20" lower="-0.785398163397448279" upper="0.785398163397448279" />
    <joint_properties friction="0.0" />
  </joint>

  <joint name="left_knee" type="revolute">
    <origin xyz="-6.5356617016366259295e-15 0.095999999999999696687 0.027400000000000260952" rpy="-3.1415926535897842342 1.6653345304510526278e-16 2.2176671495670943584e-16" />
    <parent link="left_hip_pitch_link" />
    <child link="left_calf_link" />
    <axis xyz="0 0 1" />
    <limit effort="1" velocity="20" lower="-1.570796326794896558" upper="2.2689280275926284602" />
    <joint_properties friction="0.0" />
  </joint>

  <joint name="left_hip_pitch" type="revolute">
    <origin xyz="-0.024000000716153851998 -0.019000000152441028078 -0.019000000152448098811" rpy="-1.570796326794478226 1.5707963267948015229 0" />
    <parent link="hip_roll_link" />
    <child link="left_hip_pitch_link" />
    <axis xyz="0 0 1" />
    <limit effort="1" velocity="20" lower="-1.570796326794896558" upper="1.570796326794896558" />
    <joint_properties friction="0.0" />
  </joint>

  <joint name="left_hip_roll" type="revolute">
    <origin xyz="0.019000000000000284023 -8.3919669538584410836e-16 -0.026000000000000463712" rpy="-3.1415926535897922278 -1.5707963267945732611 0" />
    <parent link="hip_yaw_link" />
    <child link="hip_roll_link" />
    <axis xyz="0 0 1" />
    <limit effort="1" velocity="20" lower="-1.570796326794896558" upper="1.570796326794896558" />
    <joint_properties friction="0.0" />
  </joint>


  <link name="hip_yaw_link_2">
    <visual>
      <origin xyz="0 0 0" rpy="0 -0 0" />
      <geometry>
        <mesh filename="../assemblies/right_3R+RH5_leg/meshes/right_hip_yaw_link_visual.stl" />
      </geometry>
      <material name="hip_yaw_link_material">
        <color rgba="0.61568627450980395466 0.81176470588235294379 0.9294117647058824927 1.0" />
      </material>
    </visual>
    <collision>
      <origin xyz="0 0 0" rpy="0 -0 0" />
      <geometry>
        <mesh filename="../assemblies/right_3R+RH5_leg/meshes/right_hip_yaw_link_collision.stl" />
      </geometry>
    </collision>
    <inertial>
      <origin xyz="-1.4892375470891750296e-20 3.9665442301965273257e-19 -0.0098390489054829104176" rpy="0 0 0" />
      <mass value="0.0090258837370979193293" />
      <inertia ixx="1.3230458239085876461e-06" ixy="-6.4778545919079861077e-49" ixz="1.7322911775161985632e-33" iyy="3.8408510960330541809e-06" iyz="-1.4482241779965781819e-32" izz="3.8721396285793077728e-06" />
    </inertial>
  </link>

  <link name="hip_roll_link_2">
    <visual>
      <origin xyz="0 0 0" rpy="0 -0 0" />
      <geometry>
        <mesh filename="../assemblies/right_3R+RH5_leg/meshes/right_hip_roll_link_visual.stl" />
      </geometry>
      <material name="hip_roll_link_material">
        <color rgba="0.95018735644455853961 0.70678927200428420807 0.061612079402596685307 1.0" />
      </material>
    </visual>
    <collision>
      <origin xyz="0 0 0" rpy="0 -0 0" />
      <geometry>
        <mesh filename="../assemblies/right_3R+RH5_leg/meshes/right_hip_roll_link_collision.stl" />
      </geometry>
    </collision>
    <inertial>
      <origin xyz="-0.012000151133961673919 -0.00049588831385562702741 -0.018504019244505478387" rpy="0 0 0" />
      <mass value="0.09801239148352869357" />
      <inertia ixx="2.0221748766307252681e-05" ixy="-4.155206824515866063e-08" ixz="-4.1225592187110660342e-08" iyy="2.7358099958307355976e-05" iyz="-5.0935731752394092288e-07" izz="2.7358069524724032586e-05" />
    </inertial>
  </link>

  <link name="right_hip_pitch_link">
    <visual>
      <origin xyz="0 0 0" rpy="0 -0 0" />
      <geometry>
        <mesh filename="../assemblies/right_3R+RH5_leg/meshes/right_hip_pitch_link_visual.stl" />
      </geometry>
      <material name="right_hip_pitch_link_material">
        <color rgba="0.61653630606835563288 0.80730204019995621678 0.92176148067891638949 1.0" />
      </material>
    </visual>
    <collision>
      <origin xyz="0 0 0" rpy="0 -0 0" />
      <geometry>
        <mesh filename="../assemblies/right_3R+RH5_leg/meshes/right_hip_pitch_link_collision.stl" />
      </geometry>
    </collision>
    <inertial>
      <origin xyz="-1.4741268609435853249e-05 0.052986690876698258612 0.014788127171305258042" rpy="0 0 0" />
      <mass value="0.094084567879581970651" />
      <inertia ixx="6.3099182122443740121e-05" ixy="-2.2045192591945184249e-07" ixz="-1.2728889936301160993e-08" iyy="2.1759163818498411774e-05" iyz="-1.4708395298813209395e-06" izz="6.2821853547821466125e-05" />
    </inertial>
  </link>

  <link name="right_calf_link">
    <visual>
      <origin xyz="0 0 0" rpy="0 -0 0" />
      <geometry>
        <mesh filename="../assemblies/right_3R+RH5_leg/meshes/right_calf_link_visual.stl" />
      </geometry>
      <material name="right_calf_link_material">
        <color rgba="0.5539724769354649192 0.73161364570947462482 0.87715709724734280961 1.0" />
      </material>
    </visual>
    <collision>
      <origin xyz="0 0 0" rpy="0 -0 0" />
      <geometry>
        <mesh filename="../assemblies/right_3R+RH5_leg/meshes/right_calf_link_collision.stl" />
      </geometry>
    </collision>
    <inertial>
      <origin xyz="-0.0039136048281023325807 0.043639997035758611166 0.00818489966080624895" rpy="0 0 0" />
      <mass value="0.016290630569901022595" />
      <inertia ixx="1.5543964735761969917e-05" ixy="2.1605989306077937793e-07" ixz="7.0519548983021784406e-09" iyy="1.9364566813417001793e-06" iyz="-1.9645570089566446317e-08" izz="1.4807205615850120399e-05" />
    </inertial>
  </link>

  <link name="ank_pitch_link_2">
    <visual>
      <origin xyz="0 0 0" rpy="0 -0 0" />
      <geometry>
        <mesh filename="../assemblies/right_3R+RH5_leg/meshes/right_ank_pitch_link_visual.stl" />
      </geometry>
      <material name="ank_pitch_link_material">
        <color rgba="0.63189161126160275916 0.72668668793540891482 0.78356373393969258601 1.0" />
      </material>
    </visual>
    <collision>
      <origin xyz="0 0 0" rpy="0 -0 0" />
      <geometry>
        <mesh filename="../assemblies/right_3R+RH5_leg/meshes/right_ank_pitch_link_collision.stl" />
      </geometry>
    </collision>
    <inertial>
      <origin xyz="4.0269688365285938752e-08 0.0005952828256655856359 -0.014599922383890164002" rpy="0 0 0" />
      <mass value="0.0042238381753791605713" />
      <inertia ixx="4.3705254067389275737e-07" ixy="1.6834346808786572501e-13" ixz="1.6428822803056156771e-12" iyy="3.9782741364654728503e-07" iyz="2.0919225290482801595e-14" izz="8.8858574534512311271e-08" />
    </inertial>
  </link>

  <link name="ank_roll_link_2">
    <visual>
      <origin xyz="0 0 0" rpy="0 -0 0" />
      <geometry>
        <mesh filename="../assemblies/right_3R+RH5_leg/meshes/right_ank_roll_link_visual.stl" />
      </geometry>
      <material name="ank_roll_link_material">
        <color rgba="0.61568627450980395466 0.81176470588235305481 0.92941176470588227065 1.0" />
      </material>
    </visual>
    <collision>
      <origin xyz="0 0 0" rpy="0 -0 0" />
      <geometry>
        <mesh filename="../assemblies/right_3R+RH5_leg/meshes/right_ank_roll_link_collision.stl" />
      </geometry>
    </collision>
    <inertial>
      <origin xyz="-6.3661537441910651493e-10 0.027240102316353733553 -0.0056169852551464652737" rpy="0 0 0" />
      <mass value="0.013844478784760251913" />
      <inertia ixx="1.0150902309234939295e-05" ixy="6.8603302692161481473e-14" ixz="-3.2605547317950551556e-13" iyy="8.66361166634314672e-06" iyz="-7.8151778926544996072e-07" izz="2.8991570356470427702e-06" />
    </inertial>
  </link>

  <link name="ank_rr_link_3">
    <visual>
      <origin xyz="0 0 0" rpy="0 -0 0" />
      <geometry>
        <mesh filename="../assemblies/right_3R+RH5_leg/meshes/right_ank_rr_link_visual.stl" />
      </geometry>
      <material name="ank_rr_link_material">
        <color rgba="0.61568627450980395466 0.81176470588235294379 0.92941176470588238168 1.0" />
      </material>
    </visual>
    <collision>
      <origin xyz="0 0 0" rpy="0 -0 0" />
      <geometry>
        <mesh filename="../assemblies/right_3R+RH5_leg/meshes/right_ank_rr_link_collision.stl" />
      </geometry>
    </collision>
    <inertial>
      <origin xyz="3.4593503690053681245e-05 -0.0062999445222072123982 2.2902669769463616335e-19" rpy="0 0 0" />
      <mass value="0.00044289790445047673732" />
      <inertia ixx="9.0894755004835240223e-09" ixy="5.6689994077039850802e-11" ixz="-1.0879024115036757634e-14" iyy="8.3785129146959872498e-09" iyz="1.0964401565805926173e-31" izz="1.3107013728801488166e-08" />
    </inertial>
  </link>

  <link name="12lf_rod_end_3">
    <visual>
      <origin xyz="0 0 0" rpy="0 -0 0" />
      <geometry>
        <mesh filename="../assemblies/right_3R+RH5_leg/meshes/right_12lf_rod_end_visual.stl" />
      </geometry>
      <material name="12lf_rod_end_material">
        <color rgba="0.92771758928836534075 0.61049283053223002415 0.2184765849058516729 1.0" />
      </material>
    </visual>
    <collision>
      <origin xyz="0 0 0" rpy="0 -0 0" />
      <geometry>
        <mesh filename="../assemblies/right_3R+RH5_leg/meshes/right_12lf_rod_end_collision.stl" />
      </geometry>
    </collision>
    <inertial>
      <origin xyz="-4.4735193393311788837e-11 -0.0038422185938245738239 6.4384187209394376638e-06" rpy="0 0 0" />
      <mass value="0.00085420491177815905965" />
      <inertia ixx="1.1840985264406848605e-08" ixy="2.0225976206036175351e-16" ixz="-9.2606418917665753036e-16" iyy="3.3549621576797288816e-09" iyz="7.4535631381921884042e-12" izz="1.2703522254419973308e-08" />
    </inertial>
  </link>

  <joint name="right_ank_R21" type="revolute">
    <origin xyz="1.3877787807814456755e-17 -0.010000000000000008882 1.3877787807814456755e-17" rpy="-1.570796326794896558 -1.4285697747627732479 1.5707963267950297848" />
    <parent link="ank_rr_link_3" />
    <child link="12lf_rod_end_3" />
    <axis xyz="0 0 1" />
    <limit effort="1" velocity="20" lower="-1.570796326794896558" upper="1.570796326794896558" />
    <joint_properties friction="0.0" />
  </joint>

  <joint name="right_ank_R11" type="revolute">
    <origin xyz="-0.0099999999999999707179 0.012500000000000066613 -0.033600000000000039557" rpy="2.8867109174417181635e-14 -3.1302655555270997905e-14 -0.10116031275652562216" />
    <parent link="ank_roll_link_2" />
    <child link="ank_rr_link_3" />
    <axis xyz="0 0 1" />
    <limit effort="1" velocity="20" lower="-1.570796326794896558" upper="1.570796326794896558" />
    <joint_properties friction="0.0" />
  </joint>

  <link name="ank_rr_link_4">
    <visual>
      <origin xyz="0 0 0" rpy="0 -0 0" />
      <geometry>
        <mesh filename="../assemblies/right_3R+RH5_leg/meshes/right_ank_rr_link_2_visual.stl" />
      </geometry>
      <material name="ank_rr_link_2_material">
        <color rgba="0.61568627450980395466 0.81176470588235294379 0.92941176470588238168 1.0" />
      </material>
    </visual>
    <collision>
      <origin xyz="0 0 0" rpy="0 -0 0" />
      <geometry>
        <mesh filename="../assemblies/right_3R+RH5_leg/meshes/right_ank_rr_link_2_collision.stl" />
      </geometry>
    </collision>
    <inertial>
      <origin xyz="3.4593503690060660796e-05 -0.0062999445222072687767 2.2902669769472090426e-19" rpy="0 0 0" />
      <mass value="0.00044289790445047673732" />
      <inertia ixx="9.0894755004835240223e-09" ixy="5.6689994077039883114e-11" ixz="-1.0879024115036757634e-14" iyy="8.3785129146959905585e-09" iyz="8.7823246935337172874e-33" izz="1.3107013728801488166e-08" />
    </inertial>
  </link>

  <link name="12lf_rod_end_4">
    <visual>
      <origin xyz="0 0 0" rpy="0 -0 0" />
      <geometry>
        <mesh filename="../assemblies/right_3R+RH5_leg/meshes/right_12lf_rod_end_2_visual.stl" />
      </geometry>
      <material name="12lf_rod_end_2_material">
        <color rgba="0.92771758928836534075 0.61049283053223013518 0.2184765849058516729 1.0" />
      </material>
    </visual>
    <collision>
      <origin xyz="0 0 0" rpy="0 -0 0" />
      <geometry>
        <mesh filename="../assemblies/right_3R+RH5_leg/meshes/right_12lf_rod_end_2_collision.stl" />
      </geometry>
    </collision>
    <inertial>
      <origin xyz="-4.4735207267392748295e-11 -0.0038422185938245798954 6.4384187209450179169e-06" rpy="0 0 0" />
      <mass value="0.00085420491177815905965" />
      <inertia ixx="1.1840985264406812209e-08" ixy="2.0225978204782157323e-16" ixz="-9.2606419936537711735e-16" iyy="3.3549621576797268136e-09" iyz="7.4535631381815061421e-12" izz="1.2703522254420024593e-08" />
    </inertial>
  </link>

  <joint name="right_ank_R22" type="revolute">
    <origin xyz="-1.3877787807814456755e-17 -0.010000000000000008882 2.7755575615628913511e-17" rpy="1.570796326794921649 -1.4285463212679851974 -1.5707963267949038855" />
    <parent link="ank_rr_link_4" />
    <child link="12lf_rod_end_4" />
    <axis xyz="0 0 1" />
    <limit effort="1" velocity="20" lower="-1.570796326794896558" upper="1.570796326794896558" />
    <joint_properties friction="0.0" />
  </joint>

  <joint name="right_ank_R12" type="revolute">
    <origin xyz="0.010000000000000003678 0.012500000000000011102 -0.033600000000000004863" rpy="-3.1415926535897917837 -1.5904604637588844751e-15 -3.0405529889774984831" />
    <parent link="ank_roll_link_2" />
    <child link="ank_rr_link_4" />
    <axis xyz="0 0 1" />
    <limit effort="1" velocity="20" lower="-1.570796326794896558" upper="1.570796326794896558" />
    <joint_properties friction="0.0" />
  </joint>

  <joint name="right_ank_roll" type="revolute">
    <origin xyz="1.1018963519404678664e-14 0.0015000000000008478773 -0.014599999999995005862" rpy="-1.5707963267950115771 1.5707963267945974639 0" />
    <parent link="ank_pitch_link_2" />
    <child link="ank_roll_link_2" />
    <axis xyz="0 0 1" />
    <limit effort="1" velocity="20" lower="-1.570796326794896558" upper="1.570796326794896558" />
    <joint_properties friction="0.0" />
  </joint>

  <joint name="right_ank_pitch" type="revolute">
    <origin xyz="-7.3090839045994630973e-18 0.099999999999999839018 -0.006199999999999821973" rpy="-3.1415926535897926719 3.8309199562601306947e-15 -1.57079632679489678" />
    <parent link="right_calf_link" />
    <child link="ank_pitch_link_2" />
    <axis xyz="0 0 1" />
    <limit effort="1" velocity="20" lower="-1.570796326794896558" upper="1.570796326794896558" />
    <joint_properties friction="0.0" />
  </joint>

  <link name="ball_joint_container_3">
    <visual>
      <origin xyz="0 0 0" rpy="0 -0 0" />
      <geometry>
        <mesh filename="../assemblies/right_3R+RH5_leg/meshes/right_ball_joint_container_visual.stl" />
      </geometry>
      <material name="ball_joint_container_material">
        <color rgba="0.61568627450980395466 0.81176470588235294379 0.92941176470588238168 1.0" />
      </material>
    </visual>
    <collision>
      <origin xyz="0 0 0" rpy="0 -0 0" />
      <geometry>
        <mesh filename="../assemblies/right_3R+RH5_leg/meshes/right_ball_joint_container_collision.stl" />
      </geometry>
    </collision>
    <inertial>
      <origin xyz="4.7221442975712082762e-19 -1.2157539084691763054e-19 -0.0097125341669083396778" rpy="0 0 0" />
      <mass value="4.803735642533054869e-05" />
      <inertia ixx="7.1865480628741666366e-10" ixy="-4.6616368691501084609e-27" ixz="-1.1843682288965544046e-38" iyy="8.475420427718555978e-10" iyz="-9.2441920556660340881e-41" izz="1.8625314111651911712e-10" />
    </inertial>
  </link>

  <link name="ball_joint_ball_3">
    <visual>
      <origin xyz="0 0 0" rpy="0 -0 0" />
      <geometry>
        <mesh filename="../assemblies/right_3R+RH5_leg/meshes/right_ball_joint_ball_visual.stl" />
      </geometry>
      <material name="ball_joint_ball_material">
        <color rgba="0.3291302810242056065 0.44310466418644928188 0.69204871161977121741 1.0" />
      </material>
    </visual>
    <collision>
      <origin xyz="0 0 0" rpy="0 -0 0" />
      <geometry>
        <mesh filename="../assemblies/right_3R+RH5_leg/meshes/right_ball_joint_ball_collision.stl" />
      </geometry>
    </collision>
    <inertial>
      <origin xyz="-2.2282791851418327992e-18 -0.0010308669810016471771 -9.6201283872577752272e-18" rpy="0 0 0" />
      <mass value="4.4053796295264630609e-05" />
      <inertia ixx="3.1285011349692509995e-10" ixy="-1.7111341847049918391e-25" ixz="-4.0779831720173709577e-26" iyy="6.2569568612796160888e-11" iyz="2.8914593605368720733e-25" izz="3.1285321460375878481e-10" />
    </inertial>
  </link>

  <link name="12lf_3">
    <visual>
      <origin xyz="0 0 0" rpy="0 -0 0" />
      <geometry>
        <mesh filename="../assemblies/right_3R+RH5_leg/meshes/right_12lf_visual.stl" />
      </geometry>
      <material name="12lf_material">
        <color rgba="0.62004392100736016591 0.58836684613512635345 0.49897069021535672695 1.0" />
      </material>
    </visual>
    <collision>
      <origin xyz="0 0 0" rpy="0 -0 0" />
      <geometry>
        <mesh filename="../assemblies/right_3R+RH5_leg/meshes/right_12lf_collision.stl" />
      </geometry>
    </collision>
    <inertial>
      <origin xyz="0.004908420724367137597 -0.00013802439943486763331 -0.029947003577148190168" rpy="0 0 0" />
      <mass value="0.044782197696050352054" />
      <inertia ixx="1.5260128421313300004e-05" ixy="2.295577368647527228e-08" ixz="-8.1364204007548279884e-08" iyy="1.8188469778952544309e-05" iyz="-5.554224084273306297e-08" izz="5.14962739017425865e-06" />
    </inertial>
  </link>

  <link name="12lf_rod_3">
    <visual>
      <origin xyz="0 0 0" rpy="0 -0 0" />
      <geometry>
        <mesh filename="../assemblies/right_3R+RH5_leg/meshes/right_12lf_rod_visual.stl" />
      </geometry>
      <material name="12lf_rod_material">
        <color rgba="0.80250260812861884396 0.89340612183512713163 0.94491811293548189088 1.0" />
      </material>
    </visual>
    <collision>
      <origin xyz="0 0 0" rpy="0 -0 0" />
      <geometry>
        <mesh filename="../assemblies/right_3R+RH5_leg/meshes/right_12lf_rod_collision.stl" />
      </geometry>
    </collision>
    <inertial>
      <origin xyz="-6.322208404502051673e-07 4.6933255154484173787e-07 -0.01289338733433067867" rpy="0 0 0" />
      <mass value="0.0025088292483592140175" />
      <inertia ixx="2.6944521128611074867e-07" ixy="7.1389570414601342887e-15" ixz="1.3562243134960218639e-11" iyy="2.6944520001667630451e-07" iyz="-1.0089988379320780934e-11" izz="1.7809843599861015564e-08" />
    </inertial>
  </link>

  <joint name="right_ank_act1" type="prismatic">
    <origin xyz="2.2722093427438722069e-06 1.6375789613221058971e-15 -0.072660031604109970305" rpy="-3.1415926535897806815 7.845419351877858644e-15 -2.2021168238260604433" />
    <parent link="12lf_3" />
    <child link="12lf_rod_3" />
    <axis xyz="0 0 1" />
    <limit effort="1" velocity="20" lower="0" upper="0.040000000000000000833" />
    <joint_properties friction="0.0" />
  </joint>

  <joint name="right_ank_B31" type="revolute">
    <origin xyz="-7.3725747729014301513e-18 -0.006438750500400436394 -1.3877787807814456755e-17" rpy="-1.5707963267948954478 0.16913440034160504011 5.0191724325132069355e-15" />
    <parent link="ball_joint_ball_3" />
    <child link="12lf_3" />
    <axis xyz="0 0 1" />
    <limit effort="1" velocity="20" lower="-0.785398163397448279" upper="0.785398163397448279" />
    <joint_properties friction="0.0" />
  </joint>

  <joint name="right_ank_B21" type="revolute">
    <origin xyz="0 5.5511151231257827021e-17 -0.011499999999999998071" rpy="1.570796326794896558 -1.4285697747625634157 1.5707963267948530373" />
    <parent link="ball_joint_container_3" />
    <child link="ball_joint_ball_3" />
    <axis xyz="0 0 1" />
    <limit effort="1" velocity="20" lower="-0.785398163397448279" upper="0.785398163397448279" />
    <joint_properties friction="0.0" />
  </joint>

  <joint name="right_ank_B11" type="revolute">
    <origin xyz="0.0079999999999999689415 0.015000000000000124345 -0.011500000000000058786" rpy="1.5707963267948932273 -1.4696360140379622905 -1.5707963267948383823" />
    <parent link="right_calf_link" />
    <child link="ball_joint_container_3" />
    <axis xyz="0 0 1" />
    <limit effort="1" velocity="20" lower="-0.785398163397448279" upper="0.785398163397448279" />
    <joint_properties friction="0.0" />
  </joint>

  <link name="ball_joint_container_4">
    <visual>
      <origin xyz="0 0 0" rpy="0 -0 0" />
      <geometry>
        <mesh filename="../assemblies/right_3R+RH5_leg/meshes/right_ball_joint_container_2_visual.stl" />
      </geometry>
      <material name="ball_joint_container_2_material">
        <color rgba="0.61568627450980395466 0.81176470588235294379 0.92941176470588238168 1.0" />
      </material>
    </visual>
    <collision>
      <origin xyz="0 0 0" rpy="0 -0 0" />
      <geometry>
        <mesh filename="../assemblies/right_3R+RH5_leg/meshes/right_ball_joint_container_2_collision.stl" />
      </geometry>
    </collision>
    <inertial>
      <origin xyz="7.411108333664368946e-18 -1.2157539084692088054e-19 -0.0097125341669083414126" rpy="0 0 0" />
      <mass value="4.803735642533054869e-05" />
      <inertia ixx="7.1865480628741666366e-10" ixy="1.5305926664110400689e-26" ixz="-2.1269215237649641381e-38" iyy="8.475420427718555978e-10" iyz="-4.9412888723893671296e-40" izz="1.8625314111651911712e-10" />
    </inertial>
  </link>

  <link name="ball_joint_ball_4">
    <visual>
      <origin xyz="0 0 0" rpy="0 -0 0" />
      <geometry>
        <mesh filename="../assemblies/right_3R+RH5_leg/meshes/right_ball_joint_ball_2_visual.stl" />
      </geometry>
      <material name="ball_joint_ball_2_material">
        <color rgba="0.3291302810242056065 0.44310466418644928188 0.69204871161977121741 1.0" />
      </material>
    </visual>
    <collision>
      <origin xyz="0 0 0" rpy="0 -0 0" />
      <geometry>
        <mesh filename="../assemblies/right_3R+RH5_leg/meshes/right_ball_joint_ball_2_collision.stl" />
      </geometry>
    </collision>
    <inertial>
      <origin xyz="-1.1745444478152376815e-17 -0.0010308669810016662591 -9.0457845496231557146e-18" rpy="0 0 0" />
      <mass value="4.4053796295264630609e-05" />
      <inertia ixx="3.1285011349692649581e-10" ixy="-1.3889939894657838189e-25" ixz="-8.9287567351173089104e-26" iyy="6.2569568612796328909e-11" iyz="4.0147766172360753583e-25" izz="3.1285321460377295028e-10" />
    </inertial>
  </link>

  <link name="12lf_4">
    <visual>
      <origin xyz="0 0 0" rpy="0 -0 0" />
      <geometry>
        <mesh filename="../assemblies/right_3R+RH5_leg/meshes/right_12lf_2_visual.stl" />
      </geometry>
      <material name="12lf_2_material">
        <color rgba="0.62004392100736027693 0.58836684613512624242 0.49897069021535683797 1.0" />
      </material>
    </visual>
    <collision>
      <origin xyz="0 0 0" rpy="0 -0 0" />
      <geometry>
        <mesh filename="../assemblies/right_3R+RH5_leg/meshes/right_12lf_2_collision.stl" />
      </geometry>
    </collision>
    <inertial>
      <origin xyz="0.0049084207243654427721 -0.00013802439943709469299 -0.029947003577146556058" rpy="0 0 0" />
      <mass value="0.044782197696050358993" />
      <inertia ixx="1.5260128421312144651e-05" ixy="2.2955773686778020384e-08" ixz="-8.1364204008304137675e-08" iyy="1.81884697789495492e-05" iyz="-5.5542240843715157968e-08" izz="5.1496273901724053419e-06" />
    </inertial>
  </link>

  <link name="12lf_rod_4">
    <visual>
      <origin xyz="0 0 0" rpy="0 -0 0" />
      <geometry>
        <mesh filename="../assemblies/right_3R+RH5_leg/meshes/right_12lf_rod_2_visual.stl" />
      </geometry>
      <material name="12lf_rod_2_material">
        <color rgba="0.80250260812861884396 0.89340612183512713163 0.94491811293548189088 1.0" />
      </material>
    </visual>
    <collision>
      <origin xyz="0 0 0" rpy="0 -0 0" />
      <geometry>
        <mesh filename="../assemblies/right_3R+RH5_leg/meshes/right_12lf_rod_2_collision.stl" />
      </geometry>
    </collision>
    <inertial>
      <origin xyz="-6.3222084132303291478e-07 4.6933255080542819115e-07 -0.012893387334332477578" rpy="0 0 0" />
      <mass value="0.0025088292483592140175" />
      <inertia ixx="2.6944521128601101054e-07" ixy="7.1389570533233858797e-15" ixz="1.3562243158167733614e-11" iyy="2.694452000165764605e-07" iyz="-1.0089988358254545759e-11" izz="1.7809843599861035416e-08" />
    </inertial>
  </link>

  <joint name="right_ank_act2" type="prismatic">
    <origin xyz="2.2722093418418159994e-06 -2.3939183968479937903e-15 -0.072660030478818443678" rpy="-3.1415926535897926719 -5.822843740105227622e-15 -2.202116823826253178" />
    <parent link="12lf_4" />
    <child link="12lf_rod_4" />
    <axis xyz="0 0 1" />
    <limit effort="1" velocity="20" lower="0" upper="0.040000000000000000833" />
    <joint_properties friction="0.0" />
  </joint>

  <joint name="right_ank_B32" type="revolute">
    <origin xyz="-1.6913553890773869171e-17 -0.0064387505004003531273 -1.3877787807814456755e-17" rpy="-1.5707963267948952257 -0.17993145005754265786 3.2634092460731900895e-15" />
    <parent link="ball_joint_ball_4" />
    <child link="12lf_4" />
    <axis xyz="0 0 1" />
    <limit effort="1" velocity="20" lower="-0.785398163397448279" upper="0.785398163397448279" />
    <joint_properties friction="0.0" />
  </joint>

  <joint name="right_ank_B22" type="revolute">
    <origin xyz="0 0 -0.011499999999999992867" rpy="1.5707963267949405228 -1.4285463212677880218 1.5707963267949816011" />
    <parent link="ball_joint_container_4" />
    <child link="ball_joint_ball_4" />
    <axis xyz="0 0 1" />
    <limit effort="1" velocity="20" lower="-0.785398163397448279" upper="0.785398163397448279" />
    <joint_properties friction="0.0" />
  </joint>

  <joint name="right_ank_B12" type="revolute">
    <origin xyz="0.0080000000000000730249 0.015000000000000263123 0.028299999999999901623" rpy="-1.5707963267948388264 -1.4697566621826396727 1.5707963267950122432" />
    <parent link="right_calf_link" />
    <child link="ball_joint_container_4" />
    <axis xyz="0 0 1" />
    <limit effort="1" velocity="20" lower="-0.785398163397448279" upper="0.785398163397448279" />
    <joint_properties friction="0.0" />
  </joint>

  <joint name="right_knee" type="revolute">
    <origin xyz="-1.8318267252532356178e-15 0.095999999999998836264 0.027400000000000895861" rpy="3.1415926535897895633 -1.5829351718147190682e-16 -3.141592653589793116" />
    <parent link="right_hip_pitch_link" />
    <child link="right_calf_link" />
    <axis xyz="0 0 1" />
    <limit effort="1" velocity="20" lower="-1.570796326794896558" upper="1.570796326794896558" />
    <joint_properties friction="0.0" />
  </joint>

  <joint name="right_hip_pitch" type="revolute">
    <origin xyz="-0.024000000716146767388 -0.019000000152456290176 -0.019000000152450020885" rpy="-1.5707963267951789987 1.5707963267947586683 0" />
    <parent link="hip_roll_link_2" />
    <child link="right_hip_pitch_link" />
    <axis xyz="0 0 1" />
    <limit effort="1" velocity="20" lower="-1.570796326794896558" upper="1.570796326794896558" />
    <joint_properties friction="0.0" />
  </joint>

  <joint name="right_hip_roll" type="revolute">
    <origin xyz="-0.018999999999999891975 2.3744804088669454642e-18 -0.025999999999999984929" rpy="-3.3306690738820289997e-16 -1.570796326794896558 0" />
    <parent link="hip_yaw_link_2" />
    <child link="hip_roll_link_2" />
    <axis xyz="0 0 1" />
    <limit effort="1" velocity="20" lower="-1.570796326794896558" upper="1.570796326794896558" />
    <joint_properties friction="0.0" />
  </joint>


  <link name="sho_pitch_link">
    <visual>
      <origin xyz="0 0 0" rpy="0 -0 0" />
      <geometry>
        <mesh filename="../assemblies/left_OP3_arm/meshes/left_sho_pitch_link_visual.stl" />
      </geometry>
      <material name="sho_pitch_link_material">
        <color rgba="0.61568627450980395466 0.81176470588235283277 0.92941176470588227065 1.0" />
      </material>
    </visual>
    <collision>
      <origin xyz="0 0 0" rpy="0 -0 0" />
      <geometry>
        <mesh filename="../assemblies/left_OP3_arm/meshes/left_sho_pitch_link_collision.stl" />
      </geometry>
    </collision>
    <inertial>
      <origin xyz="-3.0491385322450835177e-09 0.0021980515983192182999 -0.0084441034778716152209" rpy="0 0 0" />
      <mass value="0.0053168741776095304608" />
      <inertia ixx="8.004236836171299241e-07" ixy="1.1695537858705935527e-13" ixz="1.0217073886595013911e-14" iyy="1.8515753414330839236e-06" iyz="1.1638006198091620256e-07" izz="1.9553421197543973429e-06" />
    </inertial>
  </link>

  <link name="sho_roll_link">
    <visual>
      <origin xyz="0 0 0" rpy="0 -0 0" />
      <geometry>
        <mesh filename="../assemblies/left_OP3_arm/meshes/left_sho_roll_link_visual.stl" />
      </geometry>
      <material name="sho_roll_link_material">
        <color rgba="0.41316897434350019491 0.53241982866399872876 0.7282853555714716709 1.0" />
      </material>
    </visual>
    <collision>
      <origin xyz="0 0 0" rpy="0 -0 0" />
      <geometry>
        <mesh filename="../assemblies/left_OP3_arm/meshes/left_sho_roll_link_collision.stl" />
      </geometry>
    </collision>
    <inertial>
      <origin xyz="-0.044750001376316579649 -2.2393377634863600994e-09 -0.018770420156107039955" rpy="0 0 0" />
      <mass value="0.14104718485994710564" />
      <inertia ixx="2.5744677667987862931e-05" ixy="3.3646118940713150311e-08" ixz="-3.0796530997963203869e-12" iyy="0.00018303238190424636449" iyz="-7.9852770998995561417e-12" izz="0.00017803089038969846904" />
    </inertial>
  </link>

  <link name="elb_link">
    <visual>
      <origin xyz="0 0 0" rpy="0 -0 0" />
      <geometry>
        <mesh filename="../assemblies/left_OP3_arm/meshes/left_elb_link_visual.stl" />
      </geometry>
      <material name="elb_link_material">
        <color rgba="0.632763333624367319 0.72211014553089536427 0.77571823267481221365 1.0" />
      </material>
    </visual>
    <collision>
      <origin xyz="0 0 0" rpy="0 -0 0" />
      <geometry>
        <mesh filename="../assemblies/left_OP3_arm/meshes/left_elb_link_collision.stl" />
      </geometry>
    </collision>
    <inertial>
      <origin xyz="0.0035809919318981042052 0.051692930824585224536 0.01899999963962420782" rpy="0 0 0" />
      <mass value="0.012147845014428809707" />
      <inertia ixx="1.027507046601793286e-05" ixy="-8.3735105743537730385e-07" ixz="2.4555248808517769692e-13" iyy="3.0584432934239921256e-06" iyz="2.6984977430863263703e-14" izz="8.4465004716585834205e-06" />
    </inertial>
  </link>

  <joint name="left_elb" type="revolute">
    <origin xyz="-0.089499999999999663158 -3.2265856653168611956e-16 5.9049987122250513494e-15" rpy="3.1415926535897367167 2.2793048768987009608e-14 -1.5707963267948858999" />
    <parent link="sho_roll_link" />
    <child link="elb_link" />
    <axis xyz="0 0 1" />
    <limit effort="1" velocity="20" lower="-1.570796326794896558" upper="1.570796326794896558" />
    <joint_properties friction="0.0" />
  </joint>

  <joint name="left_sho_roll" type="revolute">
    <origin xyz="-0.018999999999999999528 0.0089999999999999646255 -0.027499999999999986261" rpy="-6.3254956828146051492e-14 -1.5707963267948947816 0" />
    <parent link="sho_pitch_link" />
    <child link="sho_roll_link" />
    <axis xyz="0 0 1" />
    <limit effort="1" velocity="20" lower="-1.570796326794896558" upper="1.570796326794896558" />
    <joint_properties friction="0.0" />
  </joint>


  <link name="sho_pitch_link_2">
    <visual>
      <origin xyz="0 0 0" rpy="0 -0 0" />
      <geometry>
        <mesh filename="../assemblies/right_OP3_arm/meshes/right_sho_pitch_link_visual.stl" />
      </geometry>
      <material name="sho_pitch_link_material">
        <color rgba="0.61568627450980395466 0.81176470588235283277 0.92941176470588227065 1.0" />
      </material>
    </visual>
    <collision>
      <origin xyz="0 0 0" rpy="0 -0 0" />
      <geometry>
        <mesh filename="../assemblies/right_OP3_arm/meshes/right_sho_pitch_link_collision.stl" />
      </geometry>
    </collision>
    <inertial>
      <origin xyz="-3.0491385351734712174e-09 0.0021980515983192256725 -0.0084441034778715892001" rpy="0 0 0" />
      <mass value="0.0053168741776095304608" />
      <inertia ixx="8.0042368361712717124e-07" ixy="1.1695537505388646426e-13" ixz="1.0217073731545412732e-14" iyy="1.8515753414330767238e-06" iyz="1.1638006198091051156e-07" izz="1.9553421197543837904e-06" />
    </inertial>
  </link>

  <link name="sho_roll_link_2">
    <visual>
      <origin xyz="0 0 0" rpy="0 -0 0" />
      <geometry>
        <mesh filename="../assemblies/right_OP3_arm/meshes/right_sho_roll_link_visual.stl" />
      </geometry>
      <material name="sho_roll_link_material">
        <color rgba="0.41316897434350019491 0.53241982866399850671 0.7282853555714716709 1.0" />
      </material>
    </visual>
    <collision>
      <origin xyz="0 0 0" rpy="0 -0 0" />
      <geometry>
        <mesh filename="../assemblies/right_OP3_arm/meshes/right_sho_roll_link_collision.stl" />
      </geometry>
    </collision>
    <inertial>
      <origin xyz="-0.044750001376316607404 -2.2393423855841148494e-09 -0.018770420156104722365" rpy="0 0 0" />
      <mass value="0.1410471848599471334" />
      <inertia ixx="2.5744677667987917141e-05" ixy="3.3646118925508730236e-08" ixz="-3.0796450636638775403e-12" iyy="0.0001830323819042464458" iyz="-7.9852776609581744581e-12" izz="0.00017803089038969868588" />
    </inertial>
  </link>

  <link name="elb_link_2">
    <visual>
      <origin xyz="0 0 0" rpy="0 -0 0" />
      <geometry>
        <mesh filename="../assemblies/right_OP3_arm/meshes/right_elb_link_visual.stl" />
      </geometry>
      <material name="elb_link_material">
        <color rgba="0.632763333624367319 0.72211014553089536427 0.77571823267481221365 1.0" />
      </material>
    </visual>
    <collision>
      <origin xyz="0 0 0" rpy="0 -0 0" />
      <geometry>
        <mesh filename="../assemblies/right_OP3_arm/meshes/right_elb_link_collision.stl" />
      </geometry>
    </collision>
    <inertial>
      <origin xyz="0.0035809919318979593558 -0.051692930824585030247 0.019000000360375912667" rpy="0 0 0" />
      <mass value="0.012147845014428809707" />
      <inertia ixx="1.0275070466017685526e-05" ixy="8.3735105743541351451e-07" ixz="-2.4555242187966786883e-13" iyy="3.0584432934239370684e-06" iyz="2.6985065764368432904e-14" izz="8.4465004716583818266e-06" />
    </inertial>
  </link>

  <joint name="right_elb" type="revolute">
    <origin xyz="-0.08949999999999827538 -7.2650219173908681114e-15 1.0956513474269513608e-14" rpy="-3.1415926535897145122 9.187667647645342109e-14 1.5707963267949796027" />
    <parent link="sho_roll_link_2" />
    <child link="elb_link_2" />
    <axis xyz="0 0 1" />
    <limit effort="1" velocity="20" lower="-1.570796326794896558" upper="1.570796326794896558" />
    <joint_properties friction="0.0" />
  </joint>

  <joint name="right_sho_roll" type="revolute">
    <origin xyz="0.018999999999999954425 0.0089999999999999576866 -0.027499999999999899525" rpy="-3.1415926535896976368 -1.5707963267948958919 0" />
    <parent link="sho_pitch_link_2" />
    <child link="sho_roll_link_2" />
    <axis xyz="0 0 1" />
    <limit effort="1" velocity="20" lower="-1.570796326794896558" upper="1.570796326794896558" />
    <joint_properties friction="0.0" />
  </joint>


</robot>