<?xml version="1.0" ?><robot name="sysID_2XC430">  
  <link name="2xc430">    
    <visual>      
      <origin xyz="0 0 0" rpy="0 -0 0"/>      
      <geometry>        
        <mesh filename="package:///meshes/2xc430_visual.stl"/>        
      </geometry>      
      <material name="2xc430_material">        
        <color rgba="0.53778433395328428812 0.5264357970166424483 0.5155377112718237953 1.0"/>        
      </material>      
    </visual>    
    <collision>      
      <origin xyz="0 0 0" rpy="0 -0 0"/>      
      <geometry>        
        <mesh filename="package:///meshes/2xc430_collision.stl"/>        
      </geometry>      
    </collision>    
    <inertial>      
      <origin xyz="0.075524953696132254843 0.017886243519076066438 0.0056748822304184699111" rpy="0 0 0"/>      
      <mass value="0.13164999999836235478"/>      
      <inertia ixx="4.5973499788565142952e-05" ixy="-6.3707692171101749411e-06" ixz="-6.4106848464462829903e-07" iyy="4.4966269289965492164e-05" iyz="-1.4151876066262552453e-07" izz="5.894200547616510697e-05"/>      
    </inertial>    
  </link>  

  <link name="arm_430">    
    <visual>      
      <origin xyz="0 0 0" rpy="0 -0 0"/>      
      <geometry>        
        <mesh filename="package:///meshes/arm_430_visual.stl"/>        
      </geometry>      
      <material name="arm_430_material">        
        <color rgba="0.62999456499017503219 0.65518625360592019913 0.6781537689702749061 1.0"/>        
      </material>      
    </visual>    
    <collision>      
      <origin xyz="0 0 0" rpy="0 -0 0"/>      
      <geometry>        
        <mesh filename="package:///meshes/arm_430_collision.stl"/>        
      </geometry>      
    </collision>    
    <inertial>      
      <origin xyz="-0.072230555077122768348 -2.4728305146707639804e-17 -0.019000000000000041162" rpy="0 0 0"/>      
      <mass value="0.23449999999999993072"/>      
      <inertia ixx="0.00023538980795506262789" ixy="-4.1186977060240353987e-20" ixz="-3.7692966152816365089e-20" iyy="0.00036901840263902155326" iyz="1.4653489992998104327e-16" izz="0.00018448272046932699306"/>      
    </inertial>    
  </link>  

  <joint name="joint_0" type="revolute">    
    <origin xyz="0.096000000152447806379 0.032699858643998935825 0.0062193960984139899303" rpy="-1.5707963267948961139 1.0547118733939117296e-15 -1.5707963267948950037"/>    
    <parent link="2xc430"/>    
    <child link="arm_430"/>    
    <axis xyz="0 0 1"/>    
    <limit effort="1" velocity="20" lower="-1.570796326794896558" upper="1.570796326794896558"/>    
    <joint_properties friction="0.0"/>    
  </joint>  


</robot>