<robot name="toddlerbot_OP3">
  <mujoco>
    <compiler strippath="false" balanceinertia="true" discardvisual="false" />
  </mujoco>
  <link name="torso">
    <visual>
      <origin xyz="0 0 0" rpy="0 -0 0" />
      <geometry>
        <mesh filename="../assemblies/toddlerbot/meshes/torso_visual.stl" />
      </geometry>
      <material name="torso_material">
        <color rgba="0.63516273151698243726 0.78981928681973512241 0.89663049964256791302 1.0" />
      </material>
    </visual>
    <inertial>
      <origin xyz="-0.0048722525217245026691 -0.003034303452353634932 0.065731716369313880621" rpy="0 0 0" />
      <mass value="1.1229659631011945642" />
      <inertia ixx="0.0029864200494844057691" ixy="7.6544013873600596316e-05" ixz="1.6162160592159903103e-05" iyy="0.0024009089586494794522" iyz="-2.6100607927069047675e-05" izz="0.0025052134874968133744" />
    </inertial>
  </link>

  <link name="spur_1m_20t">
    <visual>
      <origin xyz="0 0 0" rpy="0 -0 0" />
      <geometry>
        <mesh filename="../assemblies/toddlerbot/meshes/spur_1m_20t_visual.stl" />
      </geometry>
      <material name="spur_1m_20t_material">
        <color rgba="0.64705882352941179736 0.64705882352941179736 0.64705882352941179736 1.0" />
      </material>
    </visual>
    <inertial>
      <origin xyz="-1.7411803694581147988e-19 -8.1718749464796366429e-18 0.003384232105434467619" rpy="0 0 0" />
      <mass value="0.0015778025963745997712" />
      <inertia ixx="4.5874424196602078292e-08" ixy="3.9189074979405055341e-24" ixz="-7.1097175513400442172e-39" iyy="4.5874424196602051822e-08" iyz="7.8419015231486103005e-38" izz="8.1737050837173862941e-08" />
    </inertial>
  </link>

  <joint name="neck_yaw_drive" type="revolute">
    <origin xyz="-0.0049999999999995221878 3.1860588521011854095e-18 0.12148651076281755112" rpy="1.1607298201443905188e-14 1.6509758832059179101e-15 -5.3832337592600790636e-15" />
    <parent link="torso" />
    <child link="spur_1m_20t" />
    <axis xyz="0 0 1" />
    <limit effort="1" velocity="20" lower="-2.8797932657906435416" upper="2.8797932657906435416" />
    <joint_properties friction="0.0" />
  </joint>

  <link name="neck_yaw_link_v2">
    <visual>
      <origin xyz="0 0 0" rpy="0 -0 0" />
      <geometry>
        <mesh filename="../assemblies/toddlerbot/meshes/neck_yaw_link_v2_visual.stl" />
      </geometry>
      <material name="neck_yaw_link_v2_material">
        <color rgba="0.2313725490196078538 0.38039215686274507888 0.70588235294117662733 1.0" />
      </material>
    </visual>
    <inertial>
      <origin xyz="-1.1403990894989882723e-06 -1.1841855022748836188e-10 0.008257184970100570065" rpy="0 0 0" />
      <mass value="0.0067298837334394089049" />
      <inertia ixx="5.2266067624768509962e-07" ixy="-6.3046404852550345303e-15" ixz="1.194940308445471148e-09" iyy="6.121851997955700108e-07" iyz="-2.6012874340399422568e-15" izz="2.8062851709981919258e-07" />
    </inertial>
  </link>

  <link name="head">
    <visual>
      <origin xyz="0 0 0" rpy="0 -0 0" />
      <geometry>
        <mesh filename="../assemblies/toddlerbot/meshes/head_visual.stl" />
      </geometry>
      <material name="head_material">
        <color rgba="0.6268574946787414115 0.79455216272759310314 0.87652603342635482253 1.0" />
      </material>
    </visual>
    <inertial>
      <origin xyz="-0.043832613261137853833 -0.010490240883705313421 -0.00040226032898233550147" rpy="0 0 0" />
      <mass value="0.12772101760550844118" />
      <inertia ixx="0.0001150834912572321143" ixy="3.2199498087100703889e-06" ixz="3.6551948020729733223e-06" iyy="9.8737573554260360293e-05" iyz="-8.3059614999120791101e-06" izz="8.6247396675247271986e-05" />
    </inertial>
  </link>

  <link name="motor_plate">
    <visual>
      <origin xyz="0 0 0" rpy="0 -0 0" />
      <geometry>
        <mesh filename="../assemblies/toddlerbot/meshes/motor_plate_visual.stl" />
      </geometry>
      <material name="motor_plate_material">
        <color rgba="0.64705882352941179736 0.64705882352941179736 0.64705882352941179736 1.0" />
      </material>
    </visual>
    <inertial>
      <origin xyz="-1.3877787807814456755e-17 1.0408340855860841026e-17 -0.0028281768943845485807" rpy="0 0 0" />
      <mass value="0.0016999999999999996884" />
      <inertia ixx="4.805029073310371698e-08" ixy="1.0773753257370470989e-09" ixz="8.6222375027022660753e-36" iyy="5.1782428339099016964e-08" iyz="8.5565076078426530076e-37" izz="9.2194729037862183155e-08" />
    </inertial>
  </link>

  <link name="bearing_683">
    <visual>
      <origin xyz="0 0 0" rpy="0 -0 0" />
      <geometry>
        <mesh filename="../assemblies/toddlerbot/meshes/bearing_683_visual.stl" />
      </geometry>
      <material name="bearing_683_material">
        <color rgba="0.64705882352941179736 0.64705882352941179736 0.64705882352941179736 1.0" />
      </material>
    </visual>
    <inertial>
      <origin xyz="2.7862896558581346257e-17 -2.7513707872797354004e-17 -0.0015499999999999999455" rpy="0 0 0" />
      <mass value="0.00048694686130641793437" />
      <inertia ixx="2.1551456503319895657e-09" ixy="-2.2349065165105563807e-25" ixz="1.5117363048316738963e-37" iyy="2.1551456503319883249e-09" iyz="-1.4991787593073694529e-37" izz="3.5303647444715305817e-09" />
    </inertial>
  </link>

  <joint name="neck_pitch_front_rev_2" type="revolute">
    <origin xyz="-0.0019411428382688777905 -0.0072444436971680140069 -0.0055000000000000014155" rpy="-6.4149072816529488098e-15 7.6581010280206250727e-15 0.88076594287809084616" />
    <parent link="motor_plate" />
    <child link="bearing_683" />
    <axis xyz="0 0 1" />
    <limit effort="1" velocity="20" lower="-6.283185307179586232" upper="6.283185307179586232" />
    <joint_properties friction="0.0" />
  </joint>

  <link name="bearing_683_2">
    <visual>
      <origin xyz="0 0 0" rpy="0 -0 0" />
      <geometry>
        <mesh filename="../assemblies/toddlerbot/meshes/bearing_683_2_visual.stl" />
      </geometry>
      <material name="bearing_683_2_material">
        <color rgba="0.64705882352941179736 0.64705882352941179736 0.64705882352941179736 1.0" />
      </material>
    </visual>
    <inertial>
      <origin xyz="1.0732094295237683463e-19 2.4186774283160240656e-19 -0.0015499999999999999455" rpy="0 0 0" />
      <mass value="0.00048694686130641793437" />
      <inertia ixx="2.1551456503319887385e-09" ixy="9.7578640621250777055e-26" ixz="-6.152730879482004974e-40" iyy="2.1551456503319874977e-09" iyz="4.3097633785012721201e-40" izz="3.5303647444715305817e-09" />
    </inertial>
  </link>

  <joint name="neck_pitch_back_rev_2" type="revolute">
    <origin xyz="0.0019411428382689055461 0.0072444436971680157417 -0.0055000000000000014155" rpy="-2.6894721862809934635e-13 -1.70427982545233833e-13 0.87787101658577615382" />
    <parent link="motor_plate" />
    <child link="bearing_683_2" />
    <axis xyz="0 0 1" />
    <limit effort="1" velocity="20" lower="-6.283185307179586232" upper="6.283185307179586232" />
    <joint_properties friction="0.0" />
  </joint>

  <joint name="neck_pitch_act" type="revolute">
    <origin xyz="-0.032615697718559516494 -0.026999999999999642342 0.0024999999999980927236" rpy="-3.1415926535897824579 -3.0391096960732561898e-13 -3.1415926535894773686" />
    <parent link="head" />
    <child link="motor_plate" />
    <axis xyz="0 0 1" />
    <limit effort="1" velocity="20" lower="-1.3962634015954635824" upper="0.61086523819801530344" />
    <joint_properties friction="0.0" />
  </joint>

  <joint name="neck_pitch" type="revolute">
    <origin xyz="-1.0061396160665481148e-16 0.0040000000000000607986 0.019400000000000028333" rpy="-1.570796326790486086 1.567169222346451507 3.1415926535866449676" />
    <parent link="neck_yaw_link_v2" />
    <child link="head" />
    <axis xyz="0 0 1" />
    <limit effort="1" velocity="20" lower="-1.3962634015954635824" upper="0.61086523819801530344" />
    <joint_properties friction="0.0" />
  </joint>

  <link name="neck_rod">
    <visual>
      <origin xyz="0 0 0" rpy="0 -0 0" />
      <geometry>
        <mesh filename="../assemblies/toddlerbot/meshes/neck_rod_visual.stl" />
      </geometry>
      <material name="neck_rod_material">
        <color rgba="0.62051618944235198416 0.78640765248647581664 0.88594253031295000511 1.0" />
      </material>
    </visual>
    <inertial>
      <origin xyz="0.017942953356020419076 -4.2302323073851487499e-05 -0.0016023848482616159968" rpy="0 0 0" />
      <mass value="0.0031629468613064183613" />
      <inertia ixx="1.6183187611801733514e-08" ixy="4.3686324093919476193e-10" ixz="5.4098718285286100278e-10" iyy="7.9430220338151571918e-07" iyz="-1.2754318247154742971e-12" izz="8.0573905690510645668e-07" />
    </inertial>
  </link>

  <joint name="neck_pitch_front_rev_1" type="revolute">
    <origin xyz="-0.0072444436971683887072 -0.0040000000000001223813 0.01745885716173128932" rpy="1.5707963267944309305 -0.8843930473262051617 -3.1415926535893787808" />
    <parent link="neck_yaw_link_v2" />
    <child link="neck_rod" />
    <axis xyz="0 0 1" />
    <limit effort="1" velocity="20" lower="-6.283185307179586232" upper="6.283185307179586232" />
    <joint_properties friction="0.0" />
  </joint>

  <link name="neck_rod_2">
    <visual>
      <origin xyz="0 0 0" rpy="0 -0 0" />
      <geometry>
        <mesh filename="../assemblies/toddlerbot/meshes/neck_rod_2_visual.stl" />
      </geometry>
      <material name="neck_rod_2_material">
        <color rgba="0.62051618944235198416 0.78640765248647581664 0.88594253031295000511 1.0" />
      </material>
    </visual>
    <inertial>
      <origin xyz="0.017901072327983016258 4.2302323075204747993e-05 -0.0016023848482717385419" rpy="0 0 0" />
      <mass value="0.0031629468613064183613" />
      <inertia ixx="1.6183187611802643413e-08" ixy="-4.3584354919634348471e-10" ixz="5.3972445329632657527e-10" iyy="7.9343818800625886651e-07" iyz="1.2754318729384124892e-12" izz="8.0487504152983531034e-07" />
    </inertial>
  </link>

  <joint name="neck_pitch_back_rev_1" type="revolute">
    <origin xyz="0.007244443697168208296 -0.0040000000000001215139 0.021341142838269100412" rpy="1.570796326794926312 -0.88149812103389046936 3.1415926535897855665" />
    <parent link="neck_yaw_link_v2" />
    <child link="neck_rod_2" />
    <axis xyz="0 0 1" />
    <limit effort="1" velocity="20" lower="-6.283185307179586232" upper="6.283185307179586232" />
    <joint_properties friction="0.0" />
  </joint>

  <joint name="neck_yaw_driven" type="revolute">
    <origin xyz="0.016000000000000621364 3.9122381713629107253e-19 0.12248651076281739936" rpy="1.5470695466536949876e-14 -3.0902695541116811913e-15 -8.6007558735577539147e-16" />
    <parent link="torso" />
    <child link="neck_yaw_link_v2" />
    <axis xyz="0 0 1" />
    <limit effort="1" velocity="20" lower="-2.6179938779914944114" upper="2.6179938779914944114" />
    <joint_properties friction="0.0" />
  </joint>

  <link name="waist_gears">
    <visual>
      <origin xyz="0 0 0" rpy="0 -0 0" />
      <geometry>
        <mesh filename="../assemblies/toddlerbot/meshes/waist_gears_visual.stl" />
      </geometry>
      <material name="waist_gears_material">
        <color rgba="0.26906161272592882261 0.52279219083255490386 0.70491767355474521661 1.0" />
      </material>
    </visual>
    <inertial>
      <origin xyz="-2.9089024310344835968e-07 5.5035553745212688705e-08 -0.012592985430860511448" rpy="0 0 0" />
      <mass value="0.026337180140419174518" />
      <inertia ixx="1.5367047941032976421e-06" ixy="1.8828487098075703468e-11" ixz="4.0600521958548964489e-10" iyy="7.3024712275448216365e-06" iyz="3.291173783196110374e-12" izz="6.9859065635057444052e-06" />
    </inertial>
  </link>

  <link name="waist_link">
    <visual>
      <origin xyz="0 0 0" rpy="0 -0 0" />
      <geometry>
        <mesh filename="../assemblies/toddlerbot/meshes/waist_link_visual.stl" />
      </geometry>
      <material name="waist_link_material">
        <color rgba="0.63430343020834178969 0.68126545235342628182 0.66860955758476403599 1.0" />
      </material>
    </visual>
    <inertial>
      <origin xyz="-7.9740521616280326004e-06 0.026228931551963423352 -0.02998428051279712972" rpy="0 0 0" />
      <mass value="0.1701195349061245532" />
      <inertia ixx="7.0275024401906955045e-05" ixy="6.4268611259925317636e-09" ixz="-3.6642841622762010822e-06" iyy="0.00020583820676506133407" iyz="-3.5576438610758414332e-06" izz="0.00016218669765393208351" />
    </inertial>
  </link>

  <link name="spiral_bevel_1m_14t_30deg">
    <visual>
      <origin xyz="0 0 0" rpy="0 -0 0" />
      <geometry>
        <mesh filename="../assemblies/toddlerbot/meshes/spiral_bevel_1m_14t_30deg_visual.stl" />
      </geometry>
      <material name="spiral_bevel_1m_14t_30deg_material">
        <color rgba="0.64705882352941179736 0.64705882352941179736 0.64705882352941179736 1.0" />
      </material>
    </visual>
    <inertial>
      <origin xyz="7.4971447279470471159e-10 7.1802237332913031801e-10 0.0066868955018979155808" rpy="0 0 0" />
      <mass value="0.00073261524436595481732" />
      <inertia ixx="1.3495056019478193356e-08" ixy="4.0596681197802678729e-17" ixz="8.5992550167062356727e-16" iyy="1.3495056150237190671e-08" iyz="-6.7913008216864562113e-16" izz="1.4355986549816400137e-08" />
    </inertial>
  </link>

  <joint name="waist_act_1" type="revolute">
    <origin xyz="-2.3414432044644055064e-17 0.019600000000000124267 -0.01275000000000019347" rpy="1.5707963267948936714 1.5707963267948950037 0" />
    <parent link="waist_link" />
    <child link="spiral_bevel_1m_14t_30deg" />
    <axis xyz="0 0 1" />
    <limit effort="1" velocity="20" lower="-4.6774823953448034786" upper="4.6774823953448034786" />
    <joint_properties friction="0.0" />
  </joint>

  <link name="spiral_bevel_1m_14t_30deg_2">
    <visual>
      <origin xyz="0 0 0" rpy="0 -0 0" />
      <geometry>
        <mesh filename="../assemblies/toddlerbot/meshes/spiral_bevel_1m_14t_30deg_2_visual.stl" />
      </geometry>
      <material name="spiral_bevel_1m_14t_30deg_2_material">
        <color rgba="0.64705882352941179736 0.64705882352941179736 0.64705882352941179736 1.0" />
      </material>
    </visual>
    <inertial>
      <origin xyz="5.7114255512524803038e-10 8.6684721775822544076e-10 0.0066868955018979155808" rpy="0 0 0" />
      <mass value="0.00073261524436595481732" />
      <inertia ixx="1.3495056008338566936e-08" ixy="8.2092430901240935917e-18" ixz="9.8948603407504713417e-16" iyy="1.3495056161376833634e-08" iyz="-4.707514473443887487e-16" izz="1.4355986549816406754e-08" />
    </inertial>
  </link>

  <joint name="waist_act_2" type="revolute">
    <origin xyz="-1.4470390030684367241e-17 0.019600000000000561418 -0.032750000000000556444" rpy="1.5707963267948972241 1.3463968515392352732 -2.5409194566005071493e-16" />
    <parent link="waist_link" />
    <child link="spiral_bevel_1m_14t_30deg_2" />
    <axis xyz="0 0 1" />
    <limit effort="1" velocity="20" lower="-4.6774823953448034786" upper="4.6774823953448034786" />
    <joint_properties friction="0.0" />
  </joint>

  <link name="spur_gear_19_teeth">
    <visual>
      <origin xyz="0 0 0" rpy="0 -0 0" />
      <geometry>
        <mesh filename="../assemblies/toddlerbot/meshes/spur_gear_19_teeth_visual.stl" />
      </geometry>
      <material name="spur_gear_19_teeth_material">
        <color rgba="0.61568627450980395466 0.81176470588235294379 0.92941176470588238168 1.0" />
      </material>
    </visual>
    <inertial>
      <origin xyz="3.982620680117638602e-10 -1.6001614920402937169e-10 0.010108515802794645205" rpy="0 0 0" />
      <mass value="0.0010324984452316548957" />
      <inertia ixx="3.3238560252068683086e-08" ixy="-2.6893322161694212647e-16" ixz="-1.3807194537611751814e-15" iyy="3.3238560155295367385e-08" iyz="1.5293509724853463311e-16" izz="4.0687617484182906052e-08" />
    </inertial>
  </link>

  <joint name="left_hip_yaw_drive" type="revolute">
    <origin xyz="-0.03700000000000004674 0.03110000000000001652 -0.039199999999999998734" rpy="1.570796326794896558 -6.0440960687789003209e-17 3.141592653589793116" />
    <parent link="waist_link" />
    <child link="spur_gear_19_teeth" />
    <axis xyz="0 0 1" />
    <limit effort="1" velocity="20" lower="-1.7361433085627806516" upper="1.7361433085627806516" />
    <joint_properties friction="0.0" />
  </joint>

  <link name="spur_gear_21_teeth">
    <visual>
      <origin xyz="0 0 0" rpy="0 -0 0" />
      <geometry>
        <mesh filename="../assemblies/toddlerbot/meshes/spur_gear_21_teeth_visual.stl" />
      </geometry>
      <material name="spur_gear_21_teeth_material">
        <color rgba="0.61568627450980395466 0.81176470588235294379 0.92941176470588238168 1.0" />
      </material>
    </visual>
    <inertial>
      <origin xyz="-4.3729139591556703921e-11 1.6127119597199833502e-11 0.002494565097368564837" rpy="0 0 0" />
      <mass value="0.0010254193609188259288" />
      <inertia ixx="3.2524278733440935307e-08" ixy="-1.4914712189193835363e-38" ixz="2.2080265684851786227e-38" iyy="3.2524278732748135148e-08" iyz="4.3384451924501422335e-37" izz="6.0814076151188752603e-08" />
    </inertial>
  </link>

  <joint name="left_leg_fixed" type="fixed">
    <origin xyz="2.168404344971008868e-18 -1.3877787807814456755e-17 0.0049999999999999905631" rpy="-3.1415926535897704674 -7.7860248023657121854e-31 -1.137084089218072634e-30" />
    <parent link="spur_gear_21_teeth" />
    <child link="hip_yaw_link" />
    <axis xyz="0 0 1" />
    <limit effort="1" velocity="20" />
    <joint_properties friction="0.0" />
  </joint>

  <joint name="left_hip_yaw_driven" type="revolute">
    <origin xyz="-0.037000000000000012046 0.04109999999999997683 -0.019500000000000017319" rpy="-1.5707963267949192065 -1.5707963267948790165 0" />
    <parent link="waist_link" />
    <child link="spur_gear_21_teeth" />
    <axis xyz="0 0 1" />
    <limit effort="1" velocity="20" lower="-1.570796326794896558" upper="1.570796326794896558" />
    <joint_properties friction="0.0" />
  </joint>

  <link name="spur_gear_19_teeth_2">
    <visual>
      <origin xyz="0 0 0" rpy="0 -0 0" />
      <geometry>
        <mesh filename="../assemblies/toddlerbot/meshes/spur_gear_19_teeth_2_visual.stl" />
      </geometry>
      <material name="spur_gear_19_teeth_2_material">
        <color rgba="0.61568627450980395466 0.81176470588235294379 0.92941176470588238168 1.0" />
      </material>
    </visual>
    <inertial>
      <origin xyz="3.9826206801176391189e-10 -1.6001614920402937169e-10 0.010108515802794638266" rpy="0 0 0" />
      <mass value="0.0010324984452316548957" />
      <inertia ixx="3.3238560252068689703e-08" ixy="-2.6893322161694212647e-16" ixz="-1.3807194537611753786e-15" iyy="3.3238560155295367385e-08" iyz="1.5293509724853463311e-16" izz="4.0687617484182906052e-08" />
    </inertial>
  </link>

  <joint name="right_hip_yaw_drive" type="revolute">
    <origin xyz="0.036999999999999942657 0.031100000000000009581 -0.039200000000000005673" rpy="1.57079632679489678 3.044498544160610484e-18 3.141592653589793116" />
    <parent link="waist_link" />
    <child link="spur_gear_19_teeth_2" />
    <axis xyz="0 0 1" />
    <limit effort="1" velocity="20" lower="-1.7361433085627806516" upper="1.7361433085627806516" />
    <joint_properties friction="0.0" />
  </joint>

  <link name="spur_gear_21_teeth_2">
    <visual>
      <origin xyz="0 0 0" rpy="0 -0 0" />
      <geometry>
        <mesh filename="../assemblies/toddlerbot/meshes/spur_gear_21_teeth_2_visual.stl" />
      </geometry>
      <material name="spur_gear_21_teeth_2_material">
        <color rgba="0.61568627450980395466 0.81176470588235294379 0.92941176470588238168 1.0" />
      </material>
    </visual>
    <inertial>
      <origin xyz="-4.3729139591556703921e-11 -1.6127126536093737409e-11 0.0025054349026314465428" rpy="0 0 0" />
      <mass value="0.0010254193609188259288" />
      <inertia ixx="3.2524278733440935307e-08" ixy="9.6694257117435395665e-39" ixz="-2.1402570621690166588e-39" iyy="3.2524278732748135148e-08" iyz="-1.7530161696327481842e-38" izz="6.0814076151188752603e-08" />
    </inertial>
  </link>

  <joint name="right_leg_fixed" type="fixed">
    <origin xyz="-4.336808689942017736e-19 -6.9388939039072283776e-18 0.0050000000000000113798" rpy="-3.141592653589793116 9.3906761299382808154e-30 1.9103766403509957361e-30" />
    <parent link="spur_gear_21_teeth_2" />
    <child link="hip_yaw_link_2" />
    <axis xyz="0 0 1" />
    <limit effort="1" velocity="20" />
    <joint_properties friction="0.0" />
  </joint>

  <joint name="right_hip_yaw_driven" type="revolute">
    <origin xyz="0.03699999999999998429 0.041099999999999969891 -0.019500000000000017319" rpy="-1.570796326794896558 -1.570796326794896558 0" />
    <parent link="waist_link" />
    <child link="spur_gear_21_teeth_2" />
    <axis xyz="0 0 1" />
    <limit effort="1" velocity="20" lower="-1.570796326794896558" upper="1.570796326794896558" />
    <joint_properties friction="0.0" />
  </joint>

  <joint name="waist_roll" type="revolute">
    <origin xyz="-0.022707865260692055437 -1.3063957582126781116e-17 -0.013999999999999981209" rpy="-1.5707963267948956698 -5.9937357430034153564e-14 1.5707963267948785724" />
    <parent link="waist_gears" />
    <child link="waist_link" />
    <axis xyz="0 0 1" />
    <limit effort="1" velocity="20" lower="-0.52359877559829881566" upper="0.52359877559829881566" />
    <joint_properties friction="0.0" />
  </joint>

  <joint name="waist_yaw" type="revolute">
    <origin xyz="0 3.6977854932234928379e-32 -2.4651903288156618919e-32" rpy="-3.0322117681687121616e-16 -4.1243331367303576527e-15 3.1415926535897904515" />
    <parent link="torso" />
    <child link="waist_gears" />
    <axis xyz="0 0 1" />
    <limit effort="1" velocity="20" lower="-1.570796326794896558" upper="1.570796326794896558" />
    <joint_properties friction="0.0" />
  </joint>

  <joint name="left_sho_pitch" type="revolute">
    <origin xyz="-0.0035000000000004693156 0.067000000000001086464 0.104236510762817286" rpy="-1.5707963267949081043 -4.127643409825574977e-14 3.4723733359249779961e-14" />
    <parent link="torso" />
    <child link="sho_pitch_link" />
    <axis xyz="0 0 1" />
    <limit effort="1" velocity="20" lower="-3.141592653589793116" upper="1.570796326794896558" />
    <joint_properties friction="0.0" />
  </joint>

  <joint name="right_sho_pitch" type="revolute">
    <origin xyz="-0.003499999999998689923 -0.067000000000001030953 0.10423651076281729988" rpy="-1.5707963267948885644 3.4812325502379109658e-14 -3.1415926535897562566" />
    <parent link="torso" />
    <child link="sho_pitch_link_2" />
    <axis xyz="0 0 1" />
    <limit effort="1" velocity="20" lower="-1.570796326794896558" upper="3.141592653589793116" />
    <joint_properties friction="0.0" />
  </joint>


  <link name="hip_yaw_link">
    <visual>
      <origin xyz="0 0 0" rpy="0 -0 0" />
      <geometry>
        <mesh filename="../assemblies/left_leg_OP3/meshes/left_hip_yaw_link_visual.stl" />
      </geometry>
      <material name="hip_yaw_link_material">
        <color rgba="0.61568627450980395466 0.81176470588235294379 0.92941176470588238168 1.0" />
      </material>
    </visual>
    <inertial>
      <origin xyz="-5.0317609858570523212e-19 -1.2926900508687134748e-19 -0.0098919667346054444834" rpy="0 0 0" />
      <mass value="0.017999999999999991701" />
      <inertia ixx="2.6483505271519531846e-06" ixy="0" ixz="0" iyy="7.705535799600823457e-06" iyz="0" izz="7.773668280680534143e-06" />
    </inertial>
  </link>

  <link name="hip_roll_link">
    <visual>
      <origin xyz="0 0 0" rpy="0 -0 0" />
      <geometry>
        <mesh filename="../assemblies/left_leg_OP3/meshes/left_hip_roll_link_visual.stl" />
      </geometry>
      <material name="hip_roll_link_material">
        <color rgba="0.51698661238356058423 0.5034781595109349972 0.49050589017722023844 1.0" />
      </material>
    </visual>
    <inertial>
      <origin xyz="-0.011999849582186215835 -0.00049598090793881183941 -0.018504111838599408835" rpy="0 0 0" />
      <mass value="0.11059999999836234164" />
      <inertia ixx="2.2818802599019004628e-05" ixy="-4.6520143286870324278e-08" ixz="-4.6888548260596004592e-08" iyy="3.0871632082339549546e-05" iyz="-5.7477343899715776651e-07" izz="3.0871666424470034398e-05" />
    </inertial>
  </link>

  <link name="left_hip_pitch_link_xm430">
    <visual>
      <origin xyz="0 0 0" rpy="0 -0 0" />
      <geometry>
        <mesh filename="../assemblies/left_leg_OP3/meshes/left_hip_pitch_link_xm430_visual.stl" />
      </geometry>
      <material name="left_hip_pitch_link_xm430_material">
        <color rgba="0.87072221357329560032 0.72641010956094276274 0.24785169615220703498 1.0" />
      </material>
    </visual>
    <inertial>
      <origin xyz="-0.00075729214155279597331 -0.050714785675264821563 -0.012656155119959955693" rpy="0 0 0" />
      <mass value="0.11480090135030569798" />
      <inertia ixx="6.6072773889430674735e-05" ixy="-4.6080149277692711003e-07" ixz="-1.8170739115337579215e-07" iyy="2.3633638685370120166e-05" iyz="1.4125253925346806773e-06" izz="6.2221728804333939315e-05" />
    </inertial>
  </link>

  <link name="left_calf_link">
    <visual>
      <origin xyz="0 0 0" rpy="0 -0 0" />
      <geometry>
        <mesh filename="../assemblies/left_leg_OP3/meshes/left_calf_link_visual.stl" />
      </geometry>
      <material name="left_calf_link_material">
        <color rgba="0.522707147375079062 0.70740037950664136357 0.87533206831119547697 1.0" />
      </material>
    </visual>
    <inertial>
      <origin xyz="-0.0044523204300165606165 -0.040710500523439684117 -0.0093961650094225284552" rpy="0 0 0" />
      <mass value="0.031000000000000006717" />
      <inertia ixx="3.2664188400786654766e-05" ixy="1.524181598795210102e-06" ixz="1.969108326945668396e-07" iyy="7.7419254139686195619e-06" iyz="-6.3917470175188994997e-07" izz="2.7619943894572126516e-05" />
    </inertial>
  </link>

  <link name="bearing_683_3">
    <visual>
      <origin xyz="0 0 0" rpy="0 -0 0" />
      <geometry>
        <mesh filename="../assemblies/left_leg_OP3/meshes/left_bearing_683_visual.stl" />
      </geometry>
      <material name="bearing_683_material">
        <color rgba="0.64705882352941179736 0.64705882352941179736 0.64705882352941179736 1.0" />
      </material>
    </visual>
    <inertial>
      <origin xyz="2.786289655858141405e-17 6.2549399515683277405e-19 -0.0015499999999999969098" rpy="0 0 0" />
      <mass value="0.00048694686130641793437" />
      <inertia ixx="2.1551456503319887385e-09" ixy="7.2107569177297456117e-29" ixz="-4.2547428541669468398e-37" iyy="2.1551456503319883249e-09" iyz="-6.7488489126465339793e-38" izz="3.5303647444715305817e-09" />
    </inertial>
  </link>

  <joint name="left_knee_front_rev_2" type="revolute">
    <origin xyz="-0.0057402514854763509941 0.013858192987669243346 -0.026199999999999896982" rpy="3.0668764952338581412e-14 -2.4824741237762853711e-14 1.5765933876572135741" />
    <parent link="left_calf_link" />
    <child link="bearing_683_3" />
    <axis xyz="0 0 1" />
    <limit effort="1" velocity="20" lower="-6.283185307179586232" upper="6.283185307179586232" />
    <joint_properties friction="0.0" />
  </joint>

  <link name="bearing_683_4">
    <visual>
      <origin xyz="0 0 0" rpy="0 -0 0" />
      <geometry>
        <mesh filename="../assemblies/left_leg_OP3/meshes/left_bearing_683_2_visual.stl" />
      </geometry>
      <material name="bearing_683_2_material">
        <color rgba="0.64705882352941179736 0.64705882352941179736 0.64705882352941179736 1.0" />
      </material>
    </visual>
    <inertial>
      <origin xyz="2.7862896558581346257e-17 -2.4186774283158170281e-19 -0.0015500000000000003792" rpy="0 0 0" />
      <mass value="0.00048694686130641793437" />
      <inertia ixx="2.1551456503319887385e-09" ixy="-2.2779494082281898878e-28" ixz="-1.0479705396393147779e-37" iyy="2.1551456503319883249e-09" iyz="-5.2276028325327961159e-38" izz="3.5303647444715305817e-09" />
    </inertial>
  </link>

  <joint name="left_knee_back_rev_2" type="revolute">
    <origin xyz="0.0057402514854763535962 -0.013858192987669326612 -0.026199999999999907391" rpy="4.2802438278248956281e-17 2.6960450327599089653e-16 1.5736949077299307032" />
    <parent link="left_calf_link" />
    <child link="bearing_683_4" />
    <axis xyz="0 0 1" />
    <limit effort="1" velocity="20" lower="-6.283185307179586232" upper="6.283185307179586232" />
    <joint_properties friction="0.0" />
  </joint>

  <link name="ank_pitch_link">
    <visual>
      <origin xyz="0 0 0" rpy="0 -0 0" />
      <geometry>
        <mesh filename="../assemblies/left_leg_OP3/meshes/left_ank_pitch_link_visual.stl" />
      </geometry>
      <material name="ank_pitch_link_material">
        <color rgba="0.42838831031765528534 0.55128652208657225042 0.74128917770314917135 1.0" />
      </material>
    </visual>
    <inertial>
      <origin xyz="-0.012383885521092499737 0.019663604311318850365 0.018862066178914262127" rpy="0 0 0" />
      <mass value="0.15976376693924948524" />
      <inertia ixx="9.8184006245900559673e-05" ixy="1.073844598249208729e-06" ixz="4.3555854014056521191e-08" iyy="4.2237181854198985686e-05" iyz="-4.106163016637546405e-07" izz="0.00011168324060678237644" />
    </inertial>
  </link>

  <link name="ank_roll_link">
    <visual>
      <origin xyz="0 0 0" rpy="0 -0 0" />
      <geometry>
        <mesh filename="../assemblies/left_leg_OP3/meshes/left_ank_roll_link_visual.stl" />
      </geometry>
      <material name="ank_roll_link_material">
        <color rgba="0.61568627450980395466 0.81176470588235305481 0.9294117647058824927 1.0" />
      </material>
    </visual>
    <collision name="ank_roll_link_collision">
      <origin xyz="-0.014500000514090061 0.0 -0.038999998942017555" rpy="0 0 0" />
      <geometry>
        <box size="0.04900000058114529 0.041999999433755875 0.12000000104308128" />
      </geometry>
    </collision>
    <inertial>
      <origin xyz="-0.027036578607873049118 2.0295425010639498373e-12 -0.033620165726269739259" rpy="0 0 0" />
      <mass value="0.042599999999999998979" />
      <inertia ixx="3.7520823109405206e-05" ixy="5.6486071512894428643e-16" ixz="-2.4055359385055607348e-06" iyy="3.7854332370874123326e-05" iyz="5.153948614239147917e-12" izz="1.0182523770087351924e-05" />
    </inertial>
  </link>

  <joint name="left_ank_roll" type="revolute">
    <origin xyz="-1.3877787807814456755e-15 0.022750000000004225176 0.019000000000006383311" rpy="1.5707963267949556219 8.2263916424954431126e-14 3.1415926535897686911" />
    <parent link="ank_pitch_link" />
    <child link="ank_roll_link" />
    <axis xyz="0 0 1" />
    <limit effort="1" velocity="20" lower="-1.570796326794896558" upper="1.570796326794896558" />
    <joint_properties friction="0.0" />
  </joint>

  <joint name="left_ank_pitch" type="revolute">
    <origin xyz="0.00050000000000001020191 -0.099999999999999866773 -0.029399999999999901906" rpy="1.3838214396829414281e-15 2.3817753328472465846e-15 -1.5707963267948936714" />
    <parent link="left_calf_link" />
    <child link="ank_pitch_link" />
    <axis xyz="0 0 1" />
    <limit effort="1" velocity="20" lower="-1.7453292519943295336" upper="0.785398163397448279" />
    <joint_properties friction="0.0" />
  </joint>

  <joint name="left_knee" type="revolute">
    <origin xyz="3.2091917465512721632e-17 -0.09600000000000005751 -0.0091999999999999877015" rpy="2.8679386715174528955e-15 -1.3560834537223585781e-14 2.8113261283774143445e-14" />
    <parent link="left_hip_pitch_link_xm430" />
    <child link="left_calf_link" />
    <axis xyz="0 0 1" />
    <limit effort="1" velocity="20" lower="0" upper="2.0943951023931952626" />
    <joint_properties friction="0.0" />
  </joint>

  <link name="xm430_plate">
    <visual>
      <origin xyz="0 0 0" rpy="0 -0 0" />
      <geometry>
        <mesh filename="../assemblies/left_leg_OP3/meshes/left_xm430_plate_visual.stl" />
      </geometry>
      <material name="xm430_plate_material">
        <color rgba="0.61568627450980395466 0.81176470588235283277 0.9294117647058824927 1.0" />
      </material>
    </visual>
    <inertial>
      <origin xyz="3.6389035647550338571e-18 2.2496385055355271394e-18 -0.0024039046431217933435" rpy="0 0 0" />
      <mass value="0.0026999999999999988419" />
      <inertia ixx="1.293311664536341083e-07" ixy="-6.8936588702566413944e-08" ixz="-8.8133175774101294106e-36" iyy="2.672043438587668303e-07" iyz="5.3565246011124026295e-36" izz="3.8533537562751428679e-07" />
    </inertial>
  </link>

  <link name="knee_rod">
    <visual>
      <origin xyz="0 0 0" rpy="0 -0 0" />
      <geometry>
        <mesh filename="../assemblies/left_leg_OP3/meshes/left_knee_rod_visual.stl" />
      </geometry>
      <material name="knee_rod_material">
        <color rgba="0.62051618944235198416 0.78640765248647581664 0.88594253031295000511 1.0" />
      </material>
    </visual>
    <inertial>
      <origin xyz="0.014594546691135041466 -4.2302323076297562796e-05 -0.0015996227373176728249" rpy="0 0 0" />
      <mass value="0.0031629468613064183613" />
      <inertia ixx="2.5896152838584684866e-08" ixy="3.5533843514980953588e-10" ixz="4.1682972814068149677e-10" iyy="6.0153250027081128606e-07" iyz="-1.208181825755578448e-12" izz="6.226685888315019262e-07" />
    </inertial>
  </link>

  <joint name="left_knee_front_rev_1" type="revolute">
    <origin xyz="0.013858192987669312735 0.0057402514854763414531 -0.0049999999999999992367" rpy="2.7406072773284573378e-15 2.7806511995613255269e-14 -3.1357955927274727692" />
    <parent link="xm430_plate" />
    <child link="knee_rod" />
    <axis xyz="0 0 1" />
    <limit effort="1" velocity="20" lower="-6.283185307179586232" upper="6.283185307179586232" />
    <joint_properties friction="0.0" />
  </joint>

  <link name="knee_rod_2">
    <visual>
      <origin xyz="0 0 0" rpy="0 -0 0" />
      <geometry>
        <mesh filename="../assemblies/left_leg_OP3/meshes/left_knee_rod_2_visual.stl" />
      </geometry>
      <material name="knee_rod_2_material">
        <color rgba="0.62051618944235198416 0.78640765248647581664 0.88594253031295000511 1.0" />
      </material>
    </visual>
    <inertial>
      <origin xyz="0.014594546693013380964 4.2301026627575788951e-05 -0.0015996227373184610399" rpy="0 0 0" />
      <mass value="0.0031629468613064183613" />
      <inertia ixx="2.5896152775456440964e-08" ixy="-3.553275450803429935e-10" ixz="4.1682972819532933903e-10" iyy="6.0153250030240402681e-07" iyz="1.2081447832308833737e-12" izz="6.2266858879995746633e-07" />
    </inertial>
  </link>

  <joint name="left_knee_back_rev_1" type="revolute">
    <origin xyz="-0.013858192987669507024 -0.0057402514854763657393 -0.0049999999999999992367" rpy="-4.5070697379485943445e-17 2.6946050681063704762e-15 -3.1386940726547556402" />
    <parent link="xm430_plate" />
    <child link="knee_rod_2" />
    <axis xyz="0 0 1" />
    <limit effort="1" velocity="20" lower="-6.283185307179586232" upper="6.283185307179586232" />
    <joint_properties friction="0.0" />
  </joint>

  <joint name="left_knee_act" type="revolute">
    <origin xyz="-0.00014999999999969307633 -0.061500000000000415445 -0.030400000000000086675" rpy="-1.3551714611180039898e-14 9.6309787132097184291e-17 1.5707963267949209829" />
    <parent link="left_hip_pitch_link_xm430" />
    <child link="xm430_plate" />
    <axis xyz="0 0 1" />
    <limit effort="1" velocity="20" lower="0" upper="2.0943951023931952626" />
    <joint_properties friction="0.0" />
  </joint>

  <joint name="left_hip_pitch" type="revolute">
    <origin xyz="-0.024000000716156173058 -0.019000000152439983775 -0.019000000152458156738" rpy="1.5707963267953681807 1.570796326794433817 0" />
    <parent link="hip_roll_link" />
    <child link="left_hip_pitch_link_xm430" />
    <axis xyz="0 0 1" />
    <limit effort="1" velocity="20" lower="-1.570796326794896558" upper="1.570796326794896558" />
    <joint_properties friction="0.0" />
  </joint>

  <joint name="left_hip_roll" type="revolute">
    <origin xyz="0.018999999999999999528 -3.3408590380433372139e-18 -0.026000000000000002276" rpy="3.141592653589793116 -1.5707963267948821251 0" />
    <parent link="hip_yaw_link" />
    <child link="hip_roll_link" />
    <axis xyz="0 0 1" />
    <limit effort="1" velocity="20" lower="-0.785398163397448279" upper="0.785398163397448279" />
    <joint_properties friction="0.0" />
  </joint>


  <link name="hip_yaw_link_2">
    <visual>
      <origin xyz="0 0 0" rpy="0 -0 0" />
      <geometry>
        <mesh filename="../assemblies/right_leg_OP3/meshes/right_hip_yaw_link_visual.stl" />
      </geometry>
      <material name="hip_yaw_link_material">
        <color rgba="0.61568627450980395466 0.81176470588235294379 0.92941176470588238168 1.0" />
      </material>
    </visual>
    <inertial>
      <origin xyz="5.0317609858570523212e-19 1.2926900508687134748e-19 -0.0098919667346054444834" rpy="0 0 0" />
      <mass value="0.017999999999999991701" />
      <inertia ixx="2.6483505271519531846e-06" ixy="0" ixz="0" iyy="7.705535799600823457e-06" iyz="0" izz="7.773668280680534143e-06" />
    </inertial>
  </link>

  <link name="hip_roll_link_2">
    <visual>
      <origin xyz="0 0 0" rpy="0 -0 0" />
      <geometry>
        <mesh filename="../assemblies/right_leg_OP3/meshes/right_hip_roll_link_visual.stl" />
      </geometry>
      <material name="hip_roll_link_material">
        <color rgba="0.51698661238356058423 0.5034781595109349972 0.49050589017722023844 1.0" />
      </material>
    </visual>
    <inertial>
      <origin xyz="-0.011999849582184064778 -0.00049598090794076004229 -0.018504111838597528394" rpy="0 0 0" />
      <mass value="0.11059999999836234164" />
      <inertia ixx="2.2818802599018411705e-05" ixy="-4.6520143285804386253e-08" ixz="-4.6888548259794082767e-08" iyy="3.0871632082338458568e-05" iyz="-5.7477343899718413041e-07" izz="3.0871666424468855328e-05" />
    </inertial>
  </link>

  <link name="right_hip_pitch_link_xm430">
    <visual>
      <origin xyz="0 0 0" rpy="0 -0 0" />
      <geometry>
        <mesh filename="../assemblies/right_leg_OP3/meshes/right_hip_pitch_link_xm430_visual.stl" />
      </geometry>
      <material name="right_hip_pitch_link_xm430_material">
        <color rgba="0.87072221357329560032 0.72641010956094276274 0.24785169615220692396 1.0" />
      </material>
    </visual>
    <inertial>
      <origin xyz="0.00075715881371278168869 -0.050714784778880625526 -0.01265615362012198486" rpy="0 0 0" />
      <mass value="0.11480090135030569798" />
      <inertia ixx="6.6072786489385418578e-05" ixy="4.6010682906016040293e-07" ixz="1.8171597853316619593e-07" iyy="2.3633665181582011786e-05" iyz="1.4125296519935106868e-06" izz="6.2221763055418302787e-05" />
    </inertial>
  </link>

  <link name="right_calf_link">
    <visual>
      <origin xyz="0 0 0" rpy="0 -0 0" />
      <geometry>
        <mesh filename="../assemblies/right_leg_OP3/meshes/right_calf_link_visual.stl" />
      </geometry>
      <material name="right_calf_link_material">
        <color rgba="0.522707147375079062 0.70740037950664136357 0.87533206831119547697 1.0" />
      </material>
    </visual>
    <inertial>
      <origin xyz="-0.0044523204300165337283 0.040710500523439663301 -0.0093961650094225614149" rpy="0 0 0" />
      <mass value="0.03099999999999998937" />
      <inertia ixx="3.2664188400786587003e-05" ixy="-1.5241815987951603388e-06" ixz="1.969108326945254938e-07" iyy="7.7419254139686449729e-06" iyz="6.391747017518933381e-07" izz="2.7619943894572211219e-05" />
    </inertial>
  </link>

  <link name="bearing_683_5">
    <visual>
      <origin xyz="0 0 0" rpy="0 -0 0" />
      <geometry>
        <mesh filename="../assemblies/right_leg_OP3/meshes/right_bearing_683_visual.stl" />
      </geometry>
      <material name="bearing_683_material">
        <color rgba="0.64705882352941179736 0.64705882352941179736 0.64705882352941179736 1.0" />
      </material>
    </visual>
    <inertial>
      <origin xyz="9.7468268094077909387e-19 2.4186774283159932507e-19 -0.0015500000000000016803" rpy="0 0 0" />
      <mass value="0.00048694686130641793437" />
      <inertia ixx="2.1551456503319887385e-09" ixy="-1.008605192603736898e-27" ixz="-1.0935573393225559951e-38" iyy="2.1551456503319883249e-09" iyz="-4.9832977110102519673e-39" izz="3.5303647444715305817e-09" />
    </inertial>
  </link>

  <joint name="right_knee_front_rev_2" type="revolute">
    <origin xyz="-0.0057402514854764195157 -0.013858192987669160079 -0.026200000000000063516" rpy="-5.1439183405559488125e-16 -2.9685331931264604348e-15 3.1359629690793391354" />
    <parent link="right_calf_link" />
    <child link="bearing_683_5" />
    <axis xyz="0 0 1" />
    <limit effort="1" velocity="20" lower="-6.283185307179586232" upper="6.283185307179586232" />
    <joint_properties friction="0.0" />
  </joint>

  <link name="bearing_683_6">
    <visual>
      <origin xyz="0 0 0" rpy="0 -0 0" />
      <geometry>
        <mesh filename="../assemblies/right_leg_OP3/meshes/right_bearing_683_2_visual.stl" />
      </geometry>
      <material name="bearing_683_2_material">
        <color rgba="0.64705882352941179736 0.64705882352941179736 0.64705882352941179736 1.0" />
      </material>
    </visual>
    <inertial>
      <origin xyz="-7.6004079503603214129e-19 2.799744335846054081e-17 -0.0015499999999999982108" rpy="0 0 0" />
      <mass value="0.00048694686130641793437" />
      <inertia ixx="2.1551456503319887385e-09" ixy="-7.063165403686602894e-28" ixz="-7.8235602228308242713e-39" iyy="2.1551456503319874977e-09" iyz="3.988323221680714685e-38" izz="3.5303647444715305817e-09" />
    </inertial>
  </link>

  <joint name="right_knee_back_rev_2" type="revolute">
    <origin xyz="0.0057402514854763960969 0.013858192987669354368 -0.026200000000000014944" rpy="2.0307557008913139329e-14 -1.7771544142448121049e-15 3.1358994637118597915" />
    <parent link="right_calf_link" />
    <child link="bearing_683_6" />
    <axis xyz="0 0 1" />
    <limit effort="1" velocity="20" lower="-6.283185307179586232" upper="6.283185307179586232" />
    <joint_properties friction="0.0" />
  </joint>

  <link name="ank_pitch_link_2">
    <visual>
      <origin xyz="0 0 0" rpy="0 -0 0" />
      <geometry>
        <mesh filename="../assemblies/right_leg_OP3/meshes/right_ank_pitch_link_visual.stl" />
      </geometry>
      <material name="ank_pitch_link_material">
        <color rgba="0.42838831031765528534 0.55128652208657225042 0.74128917770314917135 1.0" />
      </material>
    </visual>
    <inertial>
      <origin xyz="-0.012383885521089788365 0.019663604311316376649 0.018862066178908145492" rpy="0 0 0" />
      <mass value="0.15976376693924948524" />
      <inertia ixx="9.8184006245880149568e-05" ixy="1.0738445982411045295e-06" ixz="4.3555854012401220289e-08" iyy="4.2237181854197420369e-05" iyz="-4.1061630166184405181e-07" izz="0.00011168324060676199344" />
    </inertial>
  </link>

  <link name="ank_roll_link_2">
    <visual>
      <origin xyz="0 0 0" rpy="0 -0 0" />
      <geometry>
        <mesh filename="../assemblies/right_leg_OP3/meshes/right_ank_roll_link_visual.stl" />
      </geometry>
      <material name="ank_roll_link_material">
        <color rgba="0.61568627450980395466 0.81176470588235305481 0.9294117647058824927 1.0" />
      </material>
    </visual>
    <collision name="ank_roll_link_2_collision">
      <origin xyz="-0.014500000514090061 0.0 -0.038999998942017555" rpy="0 0 0" />
      <geometry>
        <box size="0.04900000058114529 0.041999999433755875 0.12000000104308128" />
      </geometry>
    </collision>
    <inertial>
      <origin xyz="-0.027036578607873073404 2.0295514592385940646e-12 -0.033620165726269704565" rpy="0 0 0" />
      <mass value="0.042599999999999998979" />
      <inertia ixx="3.7520823109403898181e-05" ixy="5.648313175904063284e-16" ixz="-2.4055359385054904311e-06" iyy="3.7854332370874455363e-05" iyz="5.1539486143754679281e-12" izz="1.0182523770087201153e-05" />
    </inertial>
  </link>

  <joint name="right_ank_roll" type="revolute">
    <origin xyz="1.9151347174783950322e-15 0.022749999999999825917 0.019000000000001193018" rpy="1.5707963267949667241 3.4534200721523706957e-14 3.1415926535897917837" />
    <parent link="ank_pitch_link_2" />
    <child link="ank_roll_link_2" />
    <axis xyz="0 0 1" />
    <limit effort="1" velocity="20" lower="-1.570796326794896558" upper="1.570796326794896558" />
    <joint_properties friction="0.0" />
  </joint>

  <joint name="right_ank_pitch" type="revolute">
    <origin xyz="0.00050000000000040452624 0.10000000000000006106 0.0086000000000003035822" rpy="3.141592653589793116 -9.7384055572523312245e-16 1.5707963267948936714" />
    <parent link="right_calf_link" />
    <child link="ank_pitch_link_2" />
    <axis xyz="0 0 1" />
    <limit effort="1" velocity="20" lower="-1.7453292519943295336" upper="0.785398163397448279" />
    <joint_properties friction="0.0" />
  </joint>

  <joint name="right_knee" type="revolute">
    <origin xyz="6.6012271456357184538e-18 -0.095999999999999877098 -0.009199999999999972089" rpy="-9.138977281102487298e-16 5.7742659530791861042e-17 3.141592653589793116" />
    <parent link="right_hip_pitch_link_xm430" />
    <child link="right_calf_link" />
    <axis xyz="0 0 1" />
    <limit effort="1" velocity="20" lower="-2.0943951023931952626" upper="0" />
    <joint_properties friction="0.0" />
  </joint>

  <link name="xm430_plate_2">
    <visual>
      <origin xyz="0 0 0" rpy="0 -0 0" />
      <geometry>
        <mesh filename="../assemblies/right_leg_OP3/meshes/right_xm430_plate_visual.stl" />
      </geometry>
      <material name="xm430_plate_material">
        <color rgba="0.61568627450980395466 0.81176470588235283277 0.9294117647058824927 1.0" />
      </material>
    </visual>
    <inertial>
      <origin xyz="8.9446679230054346917e-19 4.2788250354559065454e-18 -0.0024039046431217933435" rpy="0 0 0" />
      <mass value="0.0026999999999999988419" />
      <inertia ixx="2.6720434385876688324e-07" ixy="-6.8936588702566387474e-08" ixz="-2.5953127236483238605e-36" iyy="1.2933116645363408183e-07" iyz="-2.0427625516522109671e-36" izz="3.8533537562751428679e-07" />
    </inertial>
  </link>

  <link name="knee_rod_3">
    <visual>
      <origin xyz="0 0 0" rpy="0 -0 0" />
      <geometry>
        <mesh filename="../assemblies/right_leg_OP3/meshes/right_knee_rod_visual.stl" />
      </geometry>
      <material name="knee_rod_material">
        <color rgba="0.62051618944235198416 0.78640765248647581664 0.88594253031295000511 1.0" />
      </material>
    </visual>
    <inertial>
      <origin xyz="0.014594553362682958011 3.7416799586905911664e-05 -0.0015996227373187301389" rpy="0 0 0" />
      <mass value="0.0031629468613064183613" />
      <inertia ixx="2.589592867711170848e-08" ixy="-3.1430030611629388961e-10" ixz="4.1682991868437187467e-10" iyy="6.0153261235254296022e-07" iyz="1.0686480871972224134e-12" izz="6.2266847675176395585e-07" />
    </inertial>
  </link>

  <joint name="right_knee_front_rev_1" type="revolute">
    <origin xyz="-0.0057402514854763735455 -0.013858192987669271101 -0.0049999999999999992367" rpy="3.7594106814525390121e-15 -6.9096598398549006487e-16 1.5651666422844430215" />
    <parent link="xm430_plate_2" />
    <child link="knee_rod_3" />
    <axis xyz="0 0 1" />
    <limit effort="1" velocity="20" lower="-6.283185307179586232" upper="6.283185307179586232" />
    <joint_properties friction="0.0" />
  </joint>

  <link name="knee_rod_4">
    <visual>
      <origin xyz="0 0 0" rpy="0 -0 0" />
      <geometry>
        <mesh filename="../assemblies/right_leg_OP3/meshes/right_knee_rod_2_visual.stl" />
      </geometry>
      <material name="knee_rod_2_material">
        <color rgba="0.62051618944235198416 0.78640765248647581664 0.88594253031295000511 1.0" />
      </material>
    </visual>
    <inertial>
      <origin xyz="0.014594550927656917833 3.9270448462004343537e-05 -0.0015996227373180189023" rpy="0 0 0" />
      <mass value="0.0031629468613064183613" />
      <inertia ixx="2.5896010493062238455e-08" ixy="-3.2987086147587118383e-10" ixz="4.1682984914096585179e-10" iyy="6.0153257144418870589e-07" iyz="1.1215895049805158445e-12" izz="6.2266851765936265679e-07" />
    </inertial>
  </link>

  <joint name="right_knee_back_rev_1" type="revolute">
    <origin xyz="0.0057402514854763666066 0.01385819298766934049 -0.005000000000000016584" rpy="-5.9721322899995738745e-15 2.1763425120495147882e-14 1.5651031369169621232" />
    <parent link="xm430_plate_2" />
    <child link="knee_rod_4" />
    <axis xyz="0 0 1" />
    <limit effort="1" velocity="20" lower="-6.283185307179586232" upper="6.283185307179586232" />
    <joint_properties friction="0.0" />
  </joint>

  <joint name="right_knee_act" type="revolute">
    <origin xyz="0.00015000000000000958205 -0.061499999999999971356 -0.030399999999999996469" rpy="1.8480226030005917304e-16 2.0301725913858999669e-15 3.1415926535897922278" />
    <parent link="right_hip_pitch_link_xm430" />
    <child link="xm430_plate_2" />
    <axis xyz="0 0 1" />
    <limit effort="1" velocity="20" lower="-2.0943951023931952626" upper="0" />
    <joint_properties friction="0.0" />
  </joint>

  <joint name="right_hip_pitch" type="revolute">
    <origin xyz="-0.024000000716147704138 -0.019000000152441253592 -0.01900000015245582527" rpy="1.570796326795185216 1.5707963267947977481 0" />
    <parent link="hip_roll_link_2" />
    <child link="right_hip_pitch_link_xm430" />
    <axis xyz="0 0 1" />
    <limit effort="1" velocity="20" lower="-1.570796326794896558" upper="1.570796326794896558" />
    <joint_properties friction="0.0" />
  </joint>

  <joint name="right_hip_roll" type="revolute">
    <origin xyz="-0.018999999999999999528 -1.7604701631262654893e-16 -0.025999999999999919009" rpy="-2.8481848693987683332e-20 -1.5707963267948954478 0" />
    <parent link="hip_yaw_link_2" />
    <child link="hip_roll_link_2" />
    <axis xyz="0 0 1" />
    <limit effort="1" velocity="20" lower="-0.785398163397448279" upper="0.785398163397448279" />
    <joint_properties friction="0.0" />
  </joint>


  <link name="sho_pitch_link">
    <visual>
      <origin xyz="0 0 0" rpy="0 -0 0" />
      <geometry>
        <mesh filename="../assemblies/left_arm_umi/meshes/left_sho_pitch_link_visual.stl" />
      </geometry>
      <material name="sho_pitch_link_material">
        <color rgba="0.61568627450980395466 0.81176470588235294379 0.92941176470588238168 1.0" />
      </material>
    </visual>
    <inertial>
      <origin xyz="5.8254248341382494532e-11 -5.1264642561121175806e-05 0.0082440788127094936227" rpy="0 0 0" />
      <mass value="0.0086000000000000017403" />
      <inertia ixx="1.2272887040545800343e-06" ixy="-2.142994419938170081e-14" ixz="-8.5847198770509101802e-15" iyy="2.9107306060364628558e-06" iyz="7.4623841398182984748e-09" izz="3.0803135950773500398e-06" />
    </inertial>
  </link>

  <link name="2xl430_gears">
    <visual>
      <origin xyz="0 0 0" rpy="0 -0 0" />
      <geometry>
        <mesh filename="../assemblies/left_arm_umi/meshes/left_2xl430_gears_visual.stl" />
      </geometry>
      <material name="2xl430_gears_material">
        <color rgba="0.75605985687944088358 0.8580469596269301169 0.91320266199377464478 1.0" />
      </material>
    </visual>
    <inertial>
      <origin xyz="-0.011593155021926912496 -0.0024238821558102432129 -0.018551095523800652243" rpy="0 0 0" />
      <mass value="0.11800003674524907338" />
      <inertia ixx="2.751155493265647906e-05" ixy="8.9994756794951591073e-07" ixz="-2.3362914879653014433e-08" iyy="3.2796647067985431473e-05" iyz="-6.5715261571464242683e-07" izz="3.5775886684226098863e-05" />
    </inertial>
  </link>

  <link name="spur_1m_24t_drive">
    <visual>
      <origin xyz="0 0 0" rpy="0 -0 0" />
      <geometry>
        <mesh filename="../assemblies/left_arm_umi/meshes/left_spur_1m_24t_drive_visual.stl" />
      </geometry>
      <material name="spur_1m_24t_drive_material">
        <color rgba="0.61568627450980395466 0.81176470588235294379 0.92941176470588238168 1.0" />
      </material>
    </visual>
    <inertial>
      <origin xyz="-7.7521288200634483028e-15 -1.2138469724092915918e-16 0.0047949116178401451557" rpy="0 0 0" />
      <mass value="0.003199999999999999286" />
      <inertia ixx="1.4019331346159885055e-07" ixy="1.6002409988992536307e-15" ixz="1.2970739157782480749e-36" iyy="1.4019331260388780891e-07" iyz="2.0673934083389124603e-36" izz="2.3838919844264052706e-07" />
    </inertial>
  </link>

  <joint name="left_sho_yaw_drive" type="revolute">
    <origin xyz="-0.024000000716141004636 -0.019000000152450596813 -0.019000000152443286688" rpy="1.5707963267948328312 -1.2258104172924911424e-15 7.6362147953450801566e-14" />
    <parent link="2xl430_gears" />
    <child link="spur_1m_24t_drive" />
    <axis xyz="0 0 1" />
    <limit effort="1" velocity="20" lower="-2.6179938779914944114" upper="2.6179938779914944114" />
    <joint_properties friction="0.0" />
  </joint>

  <link name="spur_1m_24t_driven">
    <visual>
      <origin xyz="0 0 0" rpy="0 -0 0" />
      <geometry>
        <mesh filename="../assemblies/left_arm_umi/meshes/left_spur_1m_24t_driven_visual.stl" />
      </geometry>
      <material name="spur_1m_24t_driven_material">
        <color rgba="0.23137254901960788156 0.38039215686274502337 0.7058823529411765163 1.0" />
      </material>
    </visual>
    <inertial>
      <origin xyz="2.3631092538577092045e-18 -5.8047077769919345427e-15 -0.00097054817521927832808" rpy="0 0 0" />
      <mass value="0.0026999999999999997093" />
      <inertia ixx="1.2036234079571063062e-07" ixy="-5.3408894128227318454e-38" ixz="-1.2781954363449668068e-37" iyy="1.2036234079571044533e-07" iyz="-1.7534228904356342696e-37" izz="2.2847261745924530022e-07" />
    </inertial>
  </link>

  <link name="sho_yaw_link">
    <visual>
      <origin xyz="0 0 0" rpy="0 -0 0" />
      <geometry>
        <mesh filename="../assemblies/left_arm_umi/meshes/left_sho_yaw_link_visual.stl" />
      </geometry>
      <material name="sho_yaw_link_material">
        <color rgba="0.61568627450980395466 0.81176470588235294379 0.92941176470588238168 1.0" />
      </material>
    </visual>
    <inertial>
      <origin xyz="-6.9736191503192354276e-18 3.8819761434054477756e-18 -0.024303257848520158635" rpy="0 0 0" />
      <mass value="0.014500000000000016348" />
      <inertia ixx="9.0846670053041416663e-06" ixy="3.6224092800135937916e-13" ixz="2.4472316436879021842e-43" iyy="5.6910950712097533498e-06" iyz="1.6220788372704002964e-35" izz="4.4819609845549026751e-06" />
    </inertial>
  </link>

  <link name="2xl430_gears_2">
    <visual>
      <origin xyz="0 0 0" rpy="0 -0 0" />
      <geometry>
        <mesh filename="../assemblies/left_arm_umi/meshes/left_2xl430_gears_2_visual.stl" />
      </geometry>
      <material name="2xl430_gears_2_material">
        <color rgba="0.75605985687944088358 0.8580469596269301169 0.91320266199377464478 1.0" />
      </material>
    </visual>
    <inertial>
      <origin xyz="-0.011593155021923005898 -0.0024238821558094001372 -0.018551095523810002402" rpy="0 0 0" />
      <mass value="0.11800003674524907338" />
      <inertia ixx="2.7511554932656817873e-05" ixy="8.999475679531490468e-07" ixz="-2.3362914881072982451e-08" iyy="3.2796647067987166196e-05" iyz="-6.5715261571836672482e-07" izz="3.5775886684226451229e-05" />
    </inertial>
  </link>

  <link name="spur_1m_24t_drive_2">
    <visual>
      <origin xyz="0 0 0" rpy="0 -0 0" />
      <geometry>
        <mesh filename="../assemblies/left_arm_umi/meshes/left_spur_1m_24t_drive_2_visual.stl" />
      </geometry>
      <material name="spur_1m_24t_drive_2_material">
        <color rgba="0.61568627450980395466 0.81176470588235294379 0.92941176470588238168 1.0" />
      </material>
    </visual>
    <inertial>
      <origin xyz="-7.7451899261595410744e-15 -1.2138469726677875054e-16 0.0047949116178401373495" rpy="0 0 0" />
      <mass value="0.003199999999999999286" />
      <inertia ixx="1.4019331346159885055e-07" ixy="1.600241002207976081e-15" ixz="1.0203580191619788986e-37" iyy="1.4019331260388780891e-07" iyz="1.7790518002117816615e-36" izz="2.3838919844264052706e-07" />
    </inertial>
  </link>

  <joint name="left_elbow_yaw_drive" type="revolute">
    <origin xyz="-0.024000000716137528251 -0.019000000152447529822 -0.019000000152459547986" rpy="1.570796326795050879 -2.4708842848455862195e-13 -6.0621939164177121919e-14" />
    <parent link="2xl430_gears_2" />
    <child link="spur_1m_24t_drive_2" />
    <axis xyz="0 0 1" />
    <limit effort="1" velocity="20" lower="-2.6179938779914944114" upper="2.6179938779914944114" />
    <joint_properties friction="0.0" />
  </joint>

  <link name="spur_1m_24t_driven_2">
    <visual>
      <origin xyz="0 0 0" rpy="0 -0 0" />
      <geometry>
        <mesh filename="../assemblies/left_arm_umi/meshes/left_spur_1m_24t_driven_2_visual.stl" />
      </geometry>
      <material name="spur_1m_24t_driven_2_material">
        <color rgba="0.23137254901960788156 0.38039215686274502337 0.7058823529411765163 1.0" />
      </material>
    </visual>
    <inertial>
      <origin xyz="2.3631092538563652906e-18 -5.8084160300697200678e-15 -0.00097054817521927117235" rpy="0 0 0" />
      <mass value="0.0026999999999999997093" />
      <inertia ixx="1.2036234079571063062e-07" ixy="7.3086750997471089944e-48" ixz="2.1898678400673001189e-36" iyy="1.2036234079571044533e-07" iyz="-3.2661869446708729184e-38" izz="2.2847261745924530022e-07" />
    </inertial>
  </link>

  <link name="elb_yaw_link">
    <visual>
      <origin xyz="0 0 0" rpy="0 -0 0" />
      <geometry>
        <mesh filename="../assemblies/left_arm_umi/meshes/left_elb_yaw_link_visual.stl" />
      </geometry>
      <material name="elb_yaw_link_material">
        <color rgba="0.61568627450980395466 0.81176470588235294379 0.92941176470588227065 1.0" />
      </material>
    </visual>
    <inertial>
      <origin xyz="5.3127688027619531677e-08 0.0019833638641961700601 -0.023416643551549966296" rpy="0 0 0" />
      <mass value="0.017500000000000008604" />
      <inertia ixx="1.4134344903109199776e-05" ixy="1.6945783921977629828e-12" ixz="-1.1286398721856847891e-11" iyy="6.6435900776211357345e-06" iyz="1.054522707725306605e-06" izz="8.9925290757999044535e-06" />
    </inertial>
  </link>

  <link name="spur_1m_24t_driven_3">
    <visual>
      <origin xyz="0 0 0" rpy="0 -0 0" />
      <geometry>
        <mesh filename="../assemblies/left_arm_umi/meshes/left_spur_1m_24t_driven_3_visual.stl" />
      </geometry>
      <material name="spur_1m_24t_driven_3_material">
        <color rgba="0.23137254901960788156 0.38039215686274502337 0.7058823529411765163 1.0" />
      </material>
    </visual>
    <inertial>
      <origin xyz="2.3631092538576868638e-18 -5.8047077769919376981e-15 -0.0025705481752192754774" rpy="0 0 0" />
      <mass value="0.0026999999999999997093" />
      <inertia ixx="1.2036234079571068356e-07" ixy="7.4656354546063931248e-37" ixz="-3.914926905832806072e-37" iyy="1.2036234079571044533e-07" iyz="1.970873732535265324e-36" izz="2.284726174592454061e-07" />
    </inertial>
  </link>

  <link name="2xl430_gears_3">
    <visual>
      <origin xyz="0 0 0" rpy="0 -0 0" />
      <geometry>
        <mesh filename="../assemblies/left_arm_umi/meshes/left_2xl430_gears_3_visual.stl" />
      </geometry>
      <material name="2xl430_gears_3_material">
        <color rgba="0.75605985687944088358 0.8580469596269301169 0.91320266199377464478 1.0" />
      </material>
    </visual>
    <inertial>
      <origin xyz="0.00044890447620203475154 0.011593154663843372246 -0.024576117996641427127" rpy="0 0 0" />
      <mass value="0.11800003674524907338" />
      <inertia ixx="3.5775886684225746497e-05" ixy="2.336291487979269546e-08" ixz="6.5715261571760174819e-07" iyy="2.7511554932657752997e-05" iyz="8.9994756795280197505e-07" izz="3.2796647067985411144e-05" />
    </inertial>
  </link>

  <link name="spur_1m_24t_drive_3">
    <visual>
      <origin xyz="0 0 0" rpy="0 -0 0" />
      <geometry>
        <mesh filename="../assemblies/left_arm_umi/meshes/left_spur_1m_24t_drive_3_visual.stl" />
      </geometry>
      <material name="spur_1m_24t_drive_3_material">
        <color rgba="0.61568627450980395466 0.81176470588235294379 0.92941176470588238168 1.0" />
      </material>
    </visual>
    <inertial>
      <origin xyz="-7.7521288200634483028e-15 -1.2138469724092955362e-16 0.0047949116178401425536" rpy="0 0 0" />
      <mass value="0.003199999999999999286" />
      <inertia ixx="1.4019331346159887702e-07" ixy="1.6002410075199782595e-15" ixz="-7.0751418124497800165e-36" iyy="1.4019331260388786185e-07" iyz="4.8527069935814632135e-37" izz="2.3838919844264052706e-07" />
    </inertial>
  </link>

  <joint name="left_wrist_pitch_drive" type="revolute">
    <origin xyz="-1.524411552671568168e-10 0.024000000358058659611 -0.0080000000000068835493" rpy="9.3688120281041050571e-15 -2.4754138690627644039e-13 -1.570796326794971387" />
    <parent link="2xl430_gears_3" />
    <child link="spur_1m_24t_drive_3" />
    <axis xyz="0 0 1" />
    <limit effort="1" velocity="20" lower="-1.9198621771937625091" upper="1.3962634015954635824" />
    <joint_properties friction="0.0" />
  </joint>

  <link name="hand">
    <visual>
      <origin xyz="0 0 0" rpy="0 -0 0" />
      <geometry>
        <mesh filename="../assemblies/left_arm_umi/meshes/left_hand_visual.stl" />
      </geometry>
      <material name="hand_material">
        <color rgba="0.64149913129808899814 0.67624720774385715938 0.69709605361131798951 1.0" />
      </material>
    </visual>
    <inertial>
      <origin xyz="-0.00370786937874344278 0.042127339671143314292 -0.018490328271618894362" rpy="0 0 0" />
      <mass value="0.039499999999999979572" />
      <inertia ixx="2.4635502047218482176e-05" ixy="6.2323015589610943666e-07" ixz="1.4391446178023665249e-08" iyy="2.5475207220956888024e-05" iyz="-4.0870433587615386295e-08" izz="1.3466679248868380149e-05" />
    </inertial>
  </link>

  <joint name="left_wrist_roll" type="revolute">
    <origin xyz="0.019000000000007889051 -3.5808161991113252043e-10 -0.027000000152448057344" rpy="3.141592653589793116 -1.5707963267945475039 0" />
    <parent link="2xl430_gears_3" />
    <child link="hand" />
    <axis xyz="0 0 1" />
    <limit effort="1" velocity="20" lower="-1.9198621771937625091" upper="1.3962634015954635824" />
    <joint_properties friction="0.0" />
  </joint>

  <link name="wrist_bearing_plate">
    <visual>
      <origin xyz="0 0 0" rpy="0 -0 0" />
      <geometry>
        <mesh filename="../assemblies/left_arm_umi/meshes/left_wrist_bearing_plate_visual.stl" />
      </geometry>
      <material name="wrist_bearing_plate_material">
        <color rgba="0.64496316278892629192 0.69011804996940517842 0.71706771073555874985 1.0" />
      </material>
    </visual>
    <inertial>
      <origin xyz="-0.0075835583121500035539 -0.015499999999999982542 -0.0018386323705903340111" rpy="0 0 0" />
      <mass value="0.0049000367468305565735" />
      <inertia ixx="4.9707430109150129132e-07" ixy="4.8291928725878417577e-23" ixz="1.8100904820814005469e-08" iyy="7.1268523603538563647e-07" iyz="1.2467788443080162633e-23" izz="1.1919657811600107117e-06" />
    </inertial>
  </link>

  <joint name="left_wrist_pitch_fixed" type="fixed">
    <origin xyz="0.015500000000007499099 -1.7430501486614957685e-14 -0.044999999999998915867" rpy="4.0578651550042264519e-14 -2.8213542612434331081e-13 -1.570796326794906328" />
    <parent link="2xl430_gears_3" />
    <child link="wrist_bearing_plate" />
    <axis xyz="0 0 1" />
    <limit effort="1" velocity="20" />
    <joint_properties friction="0.0" />
  </joint>

  <joint name="left_wrist_pitch_driven" type="revolute">
    <origin xyz="2.7755575615628913511e-17 -1.5777218104420236108e-30 -0.0015999999999999974746" rpy="-2.6917187154893159429e-14 -2.6645352591003750659e-14 -1.570796326794896558" />
    <parent link="spur_1m_24t_driven_3" />
    <child link="2xl430_gears_3" />
    <axis xyz="0 0 1" />
    <limit effort="1" velocity="20" lower="-1.3962634015954635824" upper="1.9198621771937625091" />
    <joint_properties friction="0.0" />
  </joint>

  <joint name="left_wrist_roll_fixed" type="fixed">
    <origin xyz="0 -0.025300000000000003042 -0.05200000000000001843" rpy="1.5707963267949236474 -1.5707963267948696906 0" />
    <parent link="elb_yaw_link" />
    <child link="spur_1m_24t_driven_3" />
    <axis xyz="0 0 1" />
    <limit effort="1" velocity="20" />
    <joint_properties friction="0.0" />
  </joint>

  <joint name="left_elbow_yaw_fixed" type="fixed">
    <origin xyz="1.5777218104420236108e-30 0 0.0015999999999999903189" rpy="-3.141592653589793116 6.8585119145426910438e-26 -7.6666465467942038555e-26" />
    <parent link="spur_1m_24t_driven_2" />
    <child link="elb_yaw_link" />
    <axis xyz="0 0 1" />
    <limit effort="1" velocity="20" />
    <joint_properties friction="0.0" />
  </joint>

  <joint name="left_elbow_yaw_driven" type="revolute">
    <origin xyz="-3.5806398471227574021e-10 -0.027000000152453157432 -0.0190000000000067025" rpy="1.5707963267949571762 1.5707963267947377961 0" />
    <parent link="2xl430_gears_2" />
    <child link="spur_1m_24t_driven_2" />
    <axis xyz="0 0 1" />
    <limit effort="1" velocity="20" lower="-2.6179938779914944114" upper="2.6179938779914944114" />
    <joint_properties friction="0.0" />
  </joint>

  <joint name="left_elbow_roll" type="revolute">
    <origin xyz="2.0816681711721685133e-16 -0.019000000000000002998 -0.059000000000000059341" rpy="1.570796326794896558 -8.2694607970959069176e-16 -2.2204460490005989148e-16" />
    <parent link="sho_yaw_link" />
    <child link="2xl430_gears_2" />
    <axis xyz="0 0 1" />
    <limit effort="1" velocity="20" lower="-1.9198621771937625091" upper="2.4434609527920612138" />
    <joint_properties friction="0.0" />
  </joint>

  <joint name="left_sho_yaw_fixed" type="fixed">
    <origin xyz="0 7.8886090522101180541e-31 0.0015999999999999868494" rpy="-3.1415926535897917837 7.7715611727616959238e-16 7.7715611725338728944e-16" />
    <parent link="spur_1m_24t_driven" />
    <child link="sho_yaw_link" />
    <axis xyz="0 0 1" />
    <limit effort="1" velocity="20" />
    <joint_properties friction="0.0" />
  </joint>

  <joint name="left_sho_yaw_driven" type="revolute">
    <origin xyz="-3.5807162096501699011e-10 -0.027000000152450989027 -0.01899999999999986075" rpy="1.5707963267948492625 8.0395273179087848749e-14 9.4924068605497912938e-14" />
    <parent link="2xl430_gears" />
    <child link="spur_1m_24t_driven" />
    <axis xyz="0 0 1" />
    <limit effort="1" velocity="20" lower="-2.6179938779914944114" upper="2.6179938779914944114" />
    <joint_properties friction="0.0" />
  </joint>

  <joint name="left_sho_roll" type="revolute">
    <origin xyz="-0.018999999999999999528 0.00099999999999997161472 0.026999999999999999695" rpy="-3.141592653589793116 1.5707963267948936714 0" />
    <parent link="sho_pitch_link" />
    <child link="2xl430_gears" />
    <axis xyz="0 0 1" />
    <limit effort="1" velocity="20" lower="-1.570796326794896558" upper="0.34906585039886589561" />
    <joint_properties friction="0.0" />
  </joint>


  <link name="sho_pitch_link_2">
    <visual>
      <origin xyz="0 0 0" rpy="0 -0 0" />
      <geometry>
        <mesh filename="../assemblies/right_arm_umi/meshes/right_sho_pitch_link_visual.stl" />
      </geometry>
      <material name="sho_pitch_link_material">
        <color rgba="0.61568627450980395466 0.81176470588235294379 0.92941176470588227065 1.0" />
      </material>
    </visual>
    <inertial>
      <origin xyz="5.8254248488936148346e-11 -5.1264642561121013175e-05 0.0082440788127094866838" rpy="0 0 0" />
      <mass value="0.0085999999999999948014" />
      <inertia ixx="1.2272887040545789755e-06" ixy="-2.1429944218861188293e-14" ixz="-8.5847198874678704984e-15" iyy="2.9107306060364611617e-06" iyz="7.4623841398182935117e-09" izz="3.0803135950773483457e-06" />
    </inertial>
  </link>

  <link name="2xl430_gears_4">
    <visual>
      <origin xyz="0 0 0" rpy="0 -0 0" />
      <geometry>
        <mesh filename="../assemblies/right_arm_umi/meshes/right_2xl430_gears_visual.stl" />
      </geometry>
      <material name="2xl430_gears_material">
        <color rgba="0.75605985687944088358 0.8580469596269301169 0.91320266199377453376 1.0" />
      </material>
    </visual>
    <inertial>
      <origin xyz="-0.01157940398103430267 -0.0024225766141400448782 -0.018551095523803726173" rpy="0 0 0" />
      <mass value="0.11800003674524907338" />
      <inertia ixx="2.7482298083236302076e-05" ixy="9.2729623432968067728e-07" ixz="-2.2634512004040956434e-08" iyy="3.2770742486672703063e-05" iyz="-6.5708346020122205624e-07" izz="3.576795754405448258e-05" />
    </inertial>
  </link>

  <link name="spur_1m_24t_drive_4">
    <visual>
      <origin xyz="0 0 0" rpy="0 -0 0" />
      <geometry>
        <mesh filename="../assemblies/right_arm_umi/meshes/right_spur_1m_24t_drive_visual.stl" />
      </geometry>
      <material name="spur_1m_24t_drive_material">
        <color rgba="0.61568627450980406568 0.81176470588235294379 0.92941176470588238168 1.0" />
      </material>
    </visual>
    <inertial>
      <origin xyz="-7.7519812112133453554e-15 -1.211739839181388264e-16 0.0047949116178401416863" rpy="0 0 0" />
      <mass value="0.0032000000000000001533" />
      <inertia ixx="1.4019331346159887702e-07" ixy="1.6002409988709471321e-15" ixz="3.9304399768732877458e-37" iyy="1.4019331260388783538e-07" iyz="-1.2977944534665672243e-36" izz="2.3838919844264055353e-07" />
    </inertial>
  </link>

  <joint name="right_sho_yaw_drive" type="revolute">
    <origin xyz="-0.024000000716138260304 -0.019000000152445337132 -0.019000000152448428409" rpy="1.5707963267949289765 -7.4062049324254792929e-14 1.9645226351351914911e-14" />
    <parent link="2xl430_gears_4" />
    <child link="spur_1m_24t_drive_4" />
    <axis xyz="0 0 1" />
    <limit effort="1" velocity="20" lower="-2.6179938779914944114" upper="2.6179938779914944114" />
    <joint_properties friction="0.0" />
  </joint>

  <link name="spur_1m_24t_driven_4">
    <visual>
      <origin xyz="0 0 0" rpy="0 -0 0" />
      <geometry>
        <mesh filename="../assemblies/right_arm_umi/meshes/right_spur_1m_24t_driven_visual.stl" />
      </geometry>
      <material name="spur_1m_24t_driven_material">
        <color rgba="0.23137254901960788156 0.38039215686274507888 0.7058823529411765163 1.0" />
      </material>
    </visual>
    <inertial>
      <origin xyz="1.9568650841840569678e-18 -5.8047591274094464977e-15 -0.00097054817521928168911" rpy="0 0 0" />
      <mass value="0.0027000000000000001429" />
      <inertia ixx="1.2036234079571068356e-07" ixy="0" ixz="0" iyy="1.203623407957104718e-07" iyz="-3.1156039432683315858e-37" izz="2.2847261745924537963e-07" />
    </inertial>
  </link>

  <link name="sho_yaw_link_2">
    <visual>
      <origin xyz="0 0 0" rpy="0 -0 0" />
      <geometry>
        <mesh filename="../assemblies/right_arm_umi/meshes/right_sho_yaw_link_visual.stl" />
      </geometry>
      <material name="sho_yaw_link_material">
        <color rgba="0.61568627450980395466 0.81176470588235294379 0.92941176470588238168 1.0" />
      </material>
    </visual>
    <inertial>
      <origin xyz="-1.2817564279971509767e-18 3.4652731864608208346e-18 -0.024303257848520165574" rpy="0 0 0" />
      <mass value="0.01450000000000000594" />
      <inertia ixx="9.084667005304133196e-06" ixy="3.6224092806478127158e-13" ixz="3.9531863547364856443e-44" iyy="5.6910950712097499617e-06" iyz="-5.7484978336446655927e-36" izz="4.4819609845548958989e-06" />
    </inertial>
  </link>

  <link name="2xl430_gears_5">
    <visual>
      <origin xyz="0 0 0" rpy="0 -0 0" />
      <geometry>
        <mesh filename="../assemblies/right_arm_umi/meshes/right_2xl430_gears_2_visual.stl" />
      </geometry>
      <material name="2xl430_gears_2_material">
        <color rgba="0.75605985687944088358 0.8580469596269301169 0.91320266199377453376 1.0" />
      </material>
    </visual>
    <inertial>
      <origin xyz="-0.011579403981040211138 -0.0024225766141398297725 -0.018551095523805887638" rpy="0 0 0" />
      <mass value="0.11800003674524907338" />
      <inertia ixx="2.7482298083237701375e-05" ixy="9.2729623432883406785e-07" ixz="-2.2634512003742370703e-08" iyy="3.2770742486673692397e-05" iyz="-6.5708346020153175266e-07" izz="3.5767957544055729413e-05" />
    </inertial>
  </link>

  <link name="spur_1m_24t_drive_5">
    <visual>
      <origin xyz="0 0 0" rpy="0 -0 0" />
      <geometry>
        <mesh filename="../assemblies/right_arm_umi/meshes/right_spur_1m_24t_drive_2_visual.stl" />
      </geometry>
      <material name="spur_1m_24t_drive_2_material">
        <color rgba="0.61568627450980406568 0.81176470588235294379 0.92941176470588238168 1.0" />
      </material>
    </visual>
    <inertial>
      <origin xyz="-7.7519812112133453554e-15 -1.2117398391813862919e-16 0.0047949116178401382168" rpy="0 0 0" />
      <mass value="0.0032000000000000001533" />
      <inertia ixx="1.4019331346159887702e-07" ixy="1.6002409935589451508e-15" ixz="1.166776181933880567e-37" iyy="1.4019331260388780891e-07" iyz="2.2883938147335335647e-36" izz="2.3838919844264055353e-07" />
    </inertial>
  </link>

  <joint name="right_elbow_yaw_drive" type="revolute">
    <origin xyz="-0.024000000716147166374 -0.019000000152450874369 -0.019000000152450291502" rpy="1.5707963267949573982 3.0456550330441217593e-14 -3.9968028886506279166e-14" />
    <parent link="2xl430_gears_5" />
    <child link="spur_1m_24t_drive_5" />
    <axis xyz="0 0 1" />
    <limit effort="1" velocity="20" lower="-2.6179938779914944114" upper="2.6179938779914944114" />
    <joint_properties friction="0.0" />
  </joint>

  <link name="spur_1m_24t_driven_5">
    <visual>
      <origin xyz="0 0 0" rpy="0 -0 0" />
      <geometry>
        <mesh filename="../assemblies/right_arm_umi/meshes/right_spur_1m_24t_driven_2_visual.stl" />
      </geometry>
      <material name="spur_1m_24t_driven_2_material">
        <color rgba="0.23137254901960788156 0.38039215686274507888 0.7058823529411765163 1.0" />
      </material>
    </visual>
    <inertial>
      <origin xyz="5.4263120361376707715e-18 -5.8047591274094472866e-15 -0.000970548175219288628" rpy="0 0 0" />
      <mass value="0.0027000000000000001429" />
      <inertia ixx="1.2036234079571068356e-07" ixy="3.7979658045849632459e-37" ixz="-4.956848099685618152e-67" iyy="1.203623407957104718e-07" iyz="-1.5073873856093740603e-36" izz="2.2847261745924537963e-07" />
    </inertial>
  </link>

  <link name="elb_yaw_link_2">
    <visual>
      <origin xyz="0 0 0" rpy="0 -0 0" />
      <geometry>
        <mesh filename="../assemblies/right_arm_umi/meshes/right_elb_yaw_link_visual.stl" />
      </geometry>
      <material name="elb_yaw_link_material">
        <color rgba="0.61568627450980395466 0.81176470588235294379 0.9294117647058824927 1.0" />
      </material>
    </visual>
    <inertial>
      <origin xyz="5.3127688027867315284e-08 0.0019833638641961652896 -0.023416643551549955887" rpy="0 0 0" />
      <mass value="0.017499999999999998196" />
      <inertia ixx="1.4134344903109199776e-05" ixy="1.6945783922045876267e-12" ixz="-1.1286398721773278415e-11" iyy="6.6435900776211331934e-06" iyz="1.0545227077253057579e-06" izz="8.9925290757998976773e-06" />
    </inertial>
  </link>

  <link name="spur_1m_24t_driven_6">
    <visual>
      <origin xyz="0 0 0" rpy="0 -0 0" />
      <geometry>
        <mesh filename="../assemblies/right_arm_umi/meshes/right_spur_1m_24t_driven_3_visual.stl" />
      </geometry>
      <material name="spur_1m_24t_driven_3_material">
        <color rgba="0.23137254901960788156 0.38039215686274507888 0.7058823529411765163 1.0" />
      </material>
    </visual>
    <inertial>
      <origin xyz="2.9712440699812971634e-17 -5.80475912740944492e-15 -0.0025705481752192789469" rpy="0 0 0" />
      <mass value="0.0027000000000000001429" />
      <inertia ixx="1.2036234079571068356e-07" ixy="1.1860558623246110089e-36" ixz="-1.8989829022924849639e-37" iyy="1.203623407957104718e-07" iyz="-6.4797105157282552736e-67" izz="2.2847261745924537963e-07" />
    </inertial>
  </link>

  <link name="2xl430_gears_6">
    <visual>
      <origin xyz="0 0 0" rpy="0 -0 0" />
      <geometry>
        <mesh filename="../assemblies/right_arm_umi/meshes/right_2xl430_gears_3_visual.stl" />
      </geometry>
      <material name="2xl430_gears_3_material">
        <color rgba="0.75605985687944088358 0.8580469596269301169 0.91320266199377453376 1.0" />
      </material>
    </visual>
    <inertial>
      <origin xyz="0.00044890447620014861923 0.011579403622967368928 -0.024577423538309432771" rpy="0 0 0" />
      <mass value="0.11800003674524907338" />
      <inertia ixx="3.5767957544056257961e-05" ixy="2.26345120036786414e-08" ixz="6.5708346020106620218e-07" iyy="2.7482298083237542132e-05" iyz="9.2729623433015798034e-07" izz="3.277074248667319773e-05" />
    </inertial>
  </link>

  <link name="spur_1m_24t_drive_6">
    <visual>
      <origin xyz="0 0 0" rpy="0 -0 0" />
      <geometry>
        <mesh filename="../assemblies/right_arm_umi/meshes/right_spur_1m_24t_drive_3_visual.stl" />
      </geometry>
      <material name="spur_1m_24t_drive_3_material">
        <color rgba="0.61568627450980406568 0.81176470588235294379 0.92941176470588238168 1.0" />
      </material>
    </visual>
    <inertial>
      <origin xyz="-7.7519812112133469331e-15 -1.2117398394398822055e-16 0.004794911617840143421" rpy="0 0 0" />
      <mass value="0.0032000000000000001533" />
      <inertia ixx="1.4019331346159890349e-07" ixy="1.600241000902533359e-15" ixz="5.2970568590852521004e-37" iyy="1.4019331260388788832e-07" iyz="-7.8193745626505839794e-37" izz="2.3838919844264055353e-07" />
    </inertial>
  </link>

  <joint name="right_wrist_pitch_drive" type="revolute">
    <origin xyz="-1.524431251168157451e-10 0.024000000358071760242 -0.0080000000000008727324" rpy="1.2483159056318501391e-14 7.3485321852726251993e-14 -1.5707963267948599206" />
    <parent link="2xl430_gears_6" />
    <child link="spur_1m_24t_drive_6" />
    <axis xyz="0 0 1" />
    <limit effort="1" velocity="20" lower="-1.3962634015954635824" upper="1.9198621771937625091" />
    <joint_properties friction="0.0" />
  </joint>

  <link name="hand_2">
    <visual>
      <origin xyz="0 0 0" rpy="0 -0 0" />
      <geometry>
        <mesh filename="../assemblies/right_arm_umi/meshes/right_hand_visual.stl" />
      </geometry>
      <material name="hand_material">
        <color rgba="0.6414991312980887761 0.67624720774385704836 0.69709605361131787848 1.0" />
      </material>
    </visual>
    <inertial>
      <origin xyz="0.0037078693754091771907 -0.042127339671143439193 -0.019509671728381142858" rpy="0 0 0" />
      <mass value="0.039500000000000000389" />
      <inertia ixx="2.4635502047219017501e-05" ixy="6.2323015740443360545e-07" ixz="1.439144773675223025e-08" iyy="2.5475207221933727077e-05" iyz="-4.0870433587618317823e-08" izz="1.3466679249845197179e-05" />
    </inertial>
  </link>

  <joint name="right_wrist_roll" type="revolute">
    <origin xyz="0.019000000000002757738 -3.5806788090120278412e-10 -0.02700000015244990309" rpy="-1.9648186021258132771e-29 1.570796326794851927 0" />
    <parent link="2xl430_gears_6" />
    <child link="hand_2" />
    <axis xyz="0 0 1" />
    <limit effort="1" velocity="20" lower="-1.3962634015954635824" upper="1.9198621771937625091" />
    <joint_properties friction="0.0" />
  </joint>

  <link name="wrist_bearing_plate_2">
    <visual>
      <origin xyz="0 0 0" rpy="0 -0 0" />
      <geometry>
        <mesh filename="../assemblies/right_arm_umi/meshes/right_wrist_bearing_plate_visual.stl" />
      </geometry>
      <material name="wrist_bearing_plate_material">
        <color rgba="0.64496316278892629192 0.69011804996940517842 0.71706771073555874985 1.0" />
      </material>
    </visual>
    <inertial>
      <origin xyz="-0.0075835583121499801351 -0.015499999999999973868 -0.0018386323705903296743" rpy="0 0 0" />
      <mass value="0.0049000367468305557062" />
      <inertia ixx="4.9707430109150118544e-07" ixy="4.4786224830671674947e-23" ixz="1.8100904820814101422e-08" iyy="7.1268523603538584823e-07" iyz="3.6315498546128718786e-24" izz="1.1919657811600109234e-06" />
    </inertial>
  </link>

  <joint name="right_wrist_pitch_fixed" type="fixed">
    <origin xyz="0.015500000000003956793 4.5519144009631418157e-15 -0.045000000000003724521" rpy="-3.0531133177156822825e-15 1.2051470932306205513e-13 -1.570796326794896558" />
    <parent link="2xl430_gears_6" />
    <child link="wrist_bearing_plate_2" />
    <axis xyz="0 0 1" />
    <limit effort="1" velocity="20" />
    <joint_properties friction="0.0" />
  </joint>

  <joint name="right_wrist_pitch_driven" type="revolute">
    <origin xyz="2.7755575615628913511e-17 7.0997481469891062487e-30 -0.0015999999999999970409" rpy="-3.8285686988021856593e-16 -1.2621774483536197294e-29 1.570796326794896558" />
    <parent link="spur_1m_24t_driven_6" />
    <child link="2xl430_gears_6" />
    <axis xyz="0 0 1" />
    <limit effort="1" velocity="20" lower="-1.9198621771937625091" upper="1.3962634015954635824" />
    <joint_properties friction="0.0" />
  </joint>

  <joint name="right_wrist_roll_fixed" type="fixed">
    <origin xyz="-7.8886090522101180541e-31 -0.025299999999999999573 -0.051999999999999976796" rpy="1.570796326794896558 1.570796326794896558 0" />
    <parent link="elb_yaw_link_2" />
    <child link="spur_1m_24t_driven_6" />
    <axis xyz="0 0 1" />
    <limit effort="1" velocity="20" />
    <joint_properties friction="0.0" />
  </joint>

  <joint name="right_elbow_yaw_fixed" type="fixed">
    <origin xyz="0 7.8886090522101180541e-31 0.0015999999999999903189" rpy="3.141592653589793116 5.5511151240344703462e-17 -1.57079632679489678" />
    <parent link="spur_1m_24t_driven_5" />
    <child link="elb_yaw_link_2" />
    <axis xyz="0 0 1" />
    <limit effort="1" velocity="20" />
    <joint_properties friction="0.0" />
  </joint>

  <joint name="right_elbow_yaw_driven" type="revolute">
    <origin xyz="-3.5807123932585227521e-10 -0.027000000152452963142 -0.019000000000002556511" rpy="1.5707963267949576203 3.0519690799675378401e-14 -4.0239863453830675462e-14" />
    <parent link="2xl430_gears_5" />
    <child link="spur_1m_24t_driven_5" />
    <axis xyz="0 0 1" />
    <limit effort="1" velocity="20" lower="-2.6179938779914944114" upper="2.6179938779914944114" />
    <joint_properties friction="0.0" />
  </joint>

  <joint name="right_elbow_roll" type="revolute">
    <origin xyz="-1.7347234759768070944e-17 -0.019000000000000159123 -0.059000000000000135669" rpy="1.5707963267948952257 -4.3465231414242792334e-14 -2.6978419498660684154e-14" />
    <parent link="sho_yaw_link_2" />
    <child link="2xl430_gears_5" />
    <axis xyz="0 0 1" />
    <limit effort="1" velocity="20" lower="-1.9198621771937625091" upper="2.4434609527920612138" />
    <joint_properties friction="0.0" />
  </joint>

  <joint name="right_sho_yaw_fixed" type="fixed">
    <origin xyz="-3.4694469519536141888e-18 3.9443045261050590271e-31 0.0016000000000000041966" rpy="3.141592653589793116 -5.0487097934144755546e-29 -1.8301573001127473886e-28" />
    <parent link="spur_1m_24t_driven_4" />
    <child link="sho_yaw_link_2" />
    <axis xyz="0 0 1" />
    <limit effort="1" velocity="20" />
    <joint_properties friction="0.0" />
  </joint>

  <joint name="right_sho_yaw_driven" type="revolute">
    <origin xyz="-3.5806844642105595256e-10 -0.02700000015244657936 -0.019000000000003233053" rpy="1.5707963267949260899 -2.2055090607973039157e-14 7.6050277186033683693e-15" />
    <parent link="2xl430_gears_4" />
    <child link="spur_1m_24t_driven_4" />
    <axis xyz="0 0 1" />
    <limit effort="1" velocity="20" lower="-2.6179938779914944114" upper="2.6179938779914944114" />
    <joint_properties friction="0.0" />
  </joint>

  <joint name="right_sho_roll" type="revolute">
    <origin xyz="-0.0190000000000000481 0.0010000000000000234396 0.026999999999999982347" rpy="3.141592653589793116 1.5707963267948952257 0" />
    <parent link="sho_pitch_link_2" />
    <child link="2xl430_gears_4" />
    <axis xyz="0 0 1" />
    <limit effort="1" velocity="20" lower="-1.570796326794896558" upper="0.34906585039886589561" />
    <joint_properties friction="0.0" />
  </joint>


</robot>