<?xml version="1.0" ?><robot name="right_leg_XM430">  
  <link name="hip_yaw_link">    
    <visual>      
      <origin xyz="0 0 0" rpy="0 -0 0"/>      
      <geometry>        
        <mesh filename="package:///meshes/right_hip_yaw_link_visual.stl"/>        
      </geometry>      
      <material name="hip_yaw_link_material">        
        <color rgba="0.61568627450980395466 0.81176470588235294379 0.92941176470588238168 1.0"/>        
      </material>      
    </visual>    
    <collision>      
      <origin xyz="0 0 0" rpy="0 -0 0"/>      
      <geometry>        
        <mesh filename="package:///meshes/right_hip_yaw_link_collision.stl"/>        
      </geometry>      
    </collision>    
    <inertial>      
      <origin xyz="-6.9994164697772127436e-19 3.8999545121627272677e-19 -0.0098390489054829138871" rpy="0 0 0"/>      
      <mass value="0.017999999999999995171"/>      
      <inertia ixx="2.6385033891442540855e-06" ixy="0" ixz="0" iyy="7.6596731957046890345e-06" iyz="0" izz="7.7220708070894769837e-06"/>      
    </inertial>    
  </link>  

  <link name="hip_roll_link">    
    <visual>      
      <origin xyz="0 0 0" rpy="0 -0 0"/>      
      <geometry>        
        <mesh filename="package:///meshes/right_hip_roll_link_visual.stl"/>        
      </geometry>      
      <material name="hip_roll_link_material">        
        <color rgba="0.51698661238356047321 0.50347815951093488618 0.49050589017722012741 1.0"/>        
      </material>      
    </visual>    
    <collision>      
      <origin xyz="0 0 0" rpy="0 -0 0"/>      
      <geometry>        
        <mesh filename="package:///meshes/right_hip_roll_link_collision.stl"/>        
      </geometry>      
    </collision>    
    <inertial>      
      <origin xyz="-0.011999849582182770674 -0.00049598090794319277513 -0.018504111838597465944" rpy="0 0 0"/>      
      <mass value="0.11059999999836234164"/>      
      <inertia ixx="2.2818802599018211805e-05" ixy="-4.6520143286279624676e-08" ixz="-4.6888548259070842361e-08" iyy="3.0871632082338072321e-05" iyz="-5.7477343899720911788e-07" izz="3.0871666424467954085e-05"/>      
    </inertial>    
  </link>  

  <link name="right_hip_pitch_link_xm430">    
    <visual>      
      <origin xyz="0 0 0" rpy="0 -0 0"/>      
      <geometry>        
        <mesh filename="package:///meshes/right_hip_pitch_link_xm430_visual.stl"/>        
      </geometry>      
      <material name="right_hip_pitch_link_xm430_material">        
        <color rgba="0.87072221357329571134 0.72641010956094276274 0.24785169615220697947 1.0"/>        
      </material>      
    </visual>    
    <collision>      
      <origin xyz="0 0 0" rpy="0 -0 0"/>      
      <geometry>        
        <mesh filename="package:///meshes/right_hip_pitch_link_xm430_collision.stl"/>        
      </geometry>      
    </collision>    
    <inertial>      
      <origin xyz="0.00075715881371275360785 -0.050714784778880674099 -0.012656153620121986594" rpy="0 0 0"/>      
      <mass value="0.11480090135030567022"/>      
      <inertia ixx="6.6072786489385133975e-05" ixy="4.6010682906023012432e-07" ixz="1.8171597853316402541e-07" iyy="2.3633665181581899978e-05" iyz="1.4125296519934367832e-06" izz="6.2221763055417950421e-05"/>      
    </inertial>    
  </link>  

  <link name="right_calf_link">    
    <visual>      
      <origin xyz="0 0 0" rpy="0 -0 0"/>      
      <geometry>        
        <mesh filename="package:///meshes/right_calf_link_visual.stl"/>        
      </geometry>      
      <material name="right_calf_link_material">        
        <color rgba="0.616547745550632742 0.71757541342472208612 0.74372657889541449183 1.0"/>        
      </material>      
    </visual>    
    <collision>      
      <origin xyz="0 0 0" rpy="0 -0 0"/>      
      <geometry>        
        <mesh filename="package:///meshes/right_calf_link_collision.stl"/>        
      </geometry>      
    </collision>    
    <inertial>      
      <origin xyz="0.0016330560292397253586 0.050045526484800359479 -0.0099079425237751303501" rpy="0 0 0"/>      
      <mass value="0.086799999986183568046"/>      
      <inertia ixx="4.9519076588877538128e-05" ixy="-3.6911123877149621398e-06" ixz="4.1819052274329280094e-07" iyy="1.5531229308366383744e-05" iyz="-4.6072292079373447431e-07" izz="5.3148278062060573122e-05"/>      
    </inertial>    
  </link>  

  <link name="bearing_683">    
    <visual>      
      <origin xyz="0 0 0" rpy="0 -0 0"/>      
      <geometry>        
        <mesh filename="package:///meshes/right_bearing_683_visual.stl"/>        
      </geometry>      
      <material name="bearing_683_material">        
        <color rgba="0.64705882352941179736 0.64705882352941179736 0.64705882352941179736 1.0"/>        
      </material>      
    </visual>    
    <collision>      
      <origin xyz="0 0 0" rpy="0 -0 0"/>      
      <geometry>        
        <mesh filename="package:///meshes/right_bearing_683_collision.stl"/>        
      </geometry>      
    </collision>    
    <inertial>      
      <origin xyz="1.0732094295240964766e-19 2.4186774283163086217e-19 -0.0015499999999999977771" rpy="0 0 0"/>      
      <mass value="0.00048694686130641793437"/>      
      <inertia ixx="2.1551456503319879113e-09" ixy="-3.3628103926129874696e-28" ixz="7.6066353359661959036e-38" iyy="2.1551456503319883249e-09" iyz="4.8251731695129717068e-38" izz="3.5303647444715322361e-09"/>      
    </inertial>    
  </link>  

  <joint name="right_knee_front_rev_2" type="revolute">    
    <origin xyz="-0.0057402514854763405858 -0.013858192987669298857 -0.02619999999999997678" rpy="-6.2776058347430638833e-15 -3.649417008249174908e-17 3.1358007158038927464"/>    
    <parent link="right_calf_link"/>    
    <child link="bearing_683"/>    
    <axis xyz="0 0 1"/>    
    <limit effort="1" velocity="20" lower="-6.283185307179586232" upper="6.283185307179586232"/>    
    <joint_properties friction="0.0"/>    
  </joint>  

  <link name="bearing_683_2">    
    <visual>      
      <origin xyz="0 0 0" rpy="0 -0 0"/>      
      <geometry>        
        <mesh filename="package:///meshes/right_bearing_683_2_visual.stl"/>        
      </geometry>      
      <material name="bearing_683_2_material">        
        <color rgba="0.64705882352941179736 0.64705882352941179736 0.64705882352941179736 1.0"/>        
      </material>      
    </visual>    
    <collision>      
      <origin xyz="0 0 0" rpy="0 -0 0"/>      
      <geometry>        
        <mesh filename="package:///meshes/right_bearing_683_2_collision.stl"/>        
      </geometry>      
    </collision>    
    <inertial>      
      <origin xyz="1.0732094295242468195e-19 2.7997443358460577788e-17 -0.0015499999999999977771" rpy="0 0 0"/>      
      <mass value="0.00048694686130641793437"/>      
      <inertia ixx="2.1551456503319879113e-09" ixy="-2.4982999913736959872e-27" ixz="1.1943003538897581327e-37" iyy="2.1551456503319883249e-09" iyz="8.2447751888914575401e-38" izz="3.5303647444715322361e-09"/>      
    </inertial>    
  </link>  

  <joint name="right_knee_back_rev_2" type="revolute">    
    <origin xyz="0.0057402514854764047705 0.013858192987669326612 -0.026199999999999966371" rpy="-6.6378328094146457949e-15 -3.5392027487744668907e-17 3.1357969761588506685"/>    
    <parent link="right_calf_link"/>    
    <child link="bearing_683_2"/>    
    <axis xyz="0 0 1"/>    
    <limit effort="1" velocity="20" lower="-6.283185307179586232" upper="6.283185307179586232"/>    
    <joint_properties friction="0.0"/>    
  </joint>  

  <link name="ank_pitch_link">    
    <visual>      
      <origin xyz="0 0 0" rpy="0 -0 0"/>      
      <geometry>        
        <mesh filename="package:///meshes/right_ank_pitch_link_visual.stl"/>        
      </geometry>      
      <material name="ank_pitch_link_material">        
        <color rgba="0.63189161126160264814 0.7266866879354088038 0.78356373393969258601 1.0"/>        
      </material>      
    </visual>    
    <collision>      
      <origin xyz="0 0 0" rpy="0 -0 0"/>      
      <geometry>        
        <mesh filename="package:///meshes/right_ank_pitch_link_collision.stl"/>        
      </geometry>      
    </collision>    
    <inertial>      
      <origin xyz="0.00059528282565905657042 -4.026968257827852565e-08 7.7616094189678438892e-08" rpy="0 0 0"/>      
      <mass value="0.0042238381753791614387"/>      
      <inertia ixx="3.9782741364675321991e-07" ixy="-1.6834347643884432913e-13" ixz="2.0919192028159930918e-14" iyy="4.3705254067418641311e-07" iyz="-1.6428822141780859485e-12" izz="8.8858574534600124764e-08"/>      
    </inertial>    
  </link>  

  <link name="ank_roll_link">    
    <visual>      
      <origin xyz="0 0 0" rpy="0 -0 0"/>      
      <geometry>        
        <mesh filename="package:///meshes/right_ank_roll_link_visual.stl"/>        
      </geometry>      
      <material name="ank_roll_link_material">        
        <color rgba="0.61568627450980395466 0.81176470588235294379 0.92941176470588227065 1.0"/>        
      </material>      
    </visual>    
    <collision>      
      <origin xyz="0 0 0" rpy="0 -0 0"/>      
      <geometry>        
        <mesh filename="package:///meshes/right_ank_roll_link_collision.stl"/>        
      </geometry>      
    </collision>    
    <inertial>      
      <origin xyz="-3.3748977754987916802e-09 0.016071733707723686452 -0.0096236810250137777567" rpy="0 0 0"/>      
      <mass value="0.010900000000000003436"/>      
      <inertia ixx="2.6058536057764963368e-06" ixy="-5.4054321087398513321e-13" ixz="6.069254909621619699e-13" iyy="2.5928781338360468952e-06" iyz="3.9359839679282456802e-07" izz="1.6179884211196010928e-06"/>      
    </inertial>    
  </link>  

  <link name="ank_rr_link">    
    <visual>      
      <origin xyz="0 0 0" rpy="0 -0 0"/>      
      <geometry>        
        <mesh filename="package:///meshes/right_ank_rr_link_visual.stl"/>        
      </geometry>      
      <material name="ank_rr_link_material">        
        <color rgba="0.61568627450980395466 0.81176470588235294379 0.92941176470588238168 1.0"/>        
      </material>      
    </visual>    
    <collision>      
      <origin xyz="0 0 0" rpy="0 -0 0"/>      
      <geometry>        
        <mesh filename="package:///meshes/right_ank_rr_link_collision.stl"/>        
      </geometry>      
    </collision>    
    <inertial>      
      <origin xyz="-4.5249610960606040573e-05 -0.0063096429836315137685 2.0541493629114029303e-19" rpy="0 0 0"/>      
      <mass value="0.0014499999999999996832"/>      
      <inertia ixx="2.9739579267716143416e-08" ixy="-2.4213146797977953366e-10" ixz="-3.5523394884456569378e-14" iyy="2.7430027724071957055e-08" iyz="9.0746301005749663886e-32" izz="4.2921949116163665819e-08"/>      
    </inertial>    
  </link>  

  <link name="ank_motor_rod_long">    
    <visual>      
      <origin xyz="0 0 0" rpy="0 -0 0"/>      
      <geometry>        
        <mesh filename="package:///meshes/right_ank_motor_rod_long_visual.stl"/>        
      </geometry>      
      <material name="ank_motor_rod_long_material">        
        <color rgba="0.63549975559783222767 0.7077439301702044272 0.75109043491362770251 1.0"/>        
      </material>      
    </visual>    
    <collision>      
      <origin xyz="0 0 0" rpy="0 -0 0"/>      
      <geometry>        
        <mesh filename="package:///meshes/right_ank_motor_rod_long_collision.stl"/>        
      </geometry>      
    </collision>    
    <inertial>      
      <origin xyz="2.4855088520493177138e-10 0.034559019974062285541 0.0009385170487845899065" rpy="0 0 0"/>      
      <mass value="0.0021712857268636710437"/>      
      <inertia ixx="8.5350290058000464345e-07" ixy="1.4884244180834259739e-14" ixz="4.5749525025600497579e-11" iyy="1.3237321792739588955e-08" iyz="-4.3668910960878901781e-09" izz="8.5812217519451811101e-07"/>      
    </inertial>    
  </link>  

  <joint name="right_ank_long_rev_2" type="revolute">    
    <origin xyz="-3.4694469519536141888e-18 -0.010000000000000008882 0" rpy="-1.570796326794896558 -1.3320366994106180858 -1.5707963267948950037"/>    
    <parent link="ank_rr_link"/>    
    <child link="ank_motor_rod_long"/>    
    <axis xyz="0 0 1"/>    
    <limit effort="1" velocity="20" lower="-1.570796326794896558" upper="1.570796326794896558"/>    
    <joint_properties friction="0.0"/>    
  </joint>  

  <joint name="right_ank_long_rev_1" type="revolute">    
    <origin xyz="0.017999999999999995171 0.015999999999999986455 -0.020600000000000007194" rpy="-2.0731393629286849282e-16 7.494126450902431242e-16 0.018223085043010137096"/>    
    <parent link="ank_roll_link"/>    
    <child link="ank_rr_link"/>    
    <axis xyz="0 0 1"/>    
    <limit effort="1" velocity="20" lower="-1.570796326794896558" upper="1.570796326794896558"/>    
    <joint_properties friction="0.0"/>    
  </joint>  

  <link name="ank_rr_link_2">    
    <visual>      
      <origin xyz="0 0 0" rpy="0 -0 0"/>      
      <geometry>        
        <mesh filename="package:///meshes/right_ank_rr_link_2_visual.stl"/>        
      </geometry>      
      <material name="ank_rr_link_2_material">        
        <color rgba="0.61568627450980395466 0.81176470588235294379 0.92941176470588238168 1.0"/>        
      </material>      
    </visual>    
    <collision>      
      <origin xyz="0 0 0" rpy="0 -0 0"/>      
      <geometry>        
        <mesh filename="package:///meshes/right_ank_rr_link_2_collision.stl"/>        
      </geometry>      
    </collision>    
    <inertial>      
      <origin xyz="-4.5249610960602571126e-05 0.0063096429836314027462 -2.0541493629100097608e-19" rpy="0 0 0"/>      
      <mass value="0.0014499999999999996832"/>      
      <inertia ixx="2.9739579267716143416e-08" ixy="2.4213146797977953366e-10" ixz="3.5523394884456569378e-14" iyy="2.7430027724071957055e-08" iyz="8.3643788813932377547e-32" izz="4.2921949116163665819e-08"/>      
    </inertial>    
  </link>  

  <link name="ank_motor_rod_short">    
    <visual>      
      <origin xyz="0 0 0" rpy="0 -0 0"/>      
      <geometry>        
        <mesh filename="package:///meshes/right_ank_motor_rod_short_visual.stl"/>        
      </geometry>      
      <material name="ank_motor_rod_short_material">        
        <color rgba="0.41222606689734719865 0.58339100346020766885 0.8110726643598615837 1.0"/>        
      </material>      
    </visual>    
    <collision>      
      <origin xyz="0 0 0" rpy="0 -0 0"/>      
      <geometry>        
        <mesh filename="package:///meshes/right_ank_motor_rod_short_collision.stl"/>        
      </geometry>      
    </collision>    
    <inertial>      
      <origin xyz="2.6038940490746279194e-10 0.023830465465870923764 0.0009040350635962171328" rpy="0 0 0"/>      
      <mass value="0.001700000000000000339"/>      
      <inertia ixx="3.3153416252670103599e-07" ixy="8.741976963456311881e-15" ixz="4.5749941567748262401e-11" iyy="1.0947363610305739478e-08" iyz="-3.5863098646405146614e-09" izz="3.3621340447865252573e-07"/>      
    </inertial>    
  </link>  

  <joint name="right_ank_short_rev_2" type="revolute">    
    <origin xyz="-6.9388939039072283776e-18 0.010000000000000008882 6.9388939039072283776e-18" rpy="-1.5707963267948854558 1.2119133862908557653 -1.5707963267949027752"/>    
    <parent link="ank_rr_link_2"/>    
    <child link="ank_motor_rod_short"/>    
    <axis xyz="0 0 1"/>    
    <limit effort="1" velocity="20" lower="-1.570796326794896558" upper="1.570796326794896558"/>    
    <joint_properties friction="0.0"/>    
  </joint>  

  <joint name="right_ank_short_rev_1" type="revolute">    
    <origin xyz="-0.018000000000000009048 0.015999999999999986455 -0.020599999999999996786" rpy="1.2085562754084012184e-16 -4.4422865000044981723e-16 3.115474105082512768"/>    
    <parent link="ank_roll_link"/>    
    <child link="ank_rr_link_2"/>    
    <axis xyz="0 0 1"/>    
    <limit effort="1" velocity="20" lower="-1.570796326794896558" upper="1.570796326794896558"/>    
    <joint_properties friction="0.0"/>    
  </joint>  

  <link name="right_sole_link">    
    <visual>      
      <origin xyz="0 0 0" rpy="0 -0 0"/>      
      <geometry>        
        <mesh filename="package:///meshes/right_sole_link_visual.stl"/>        
      </geometry>      
      <material name="right_sole_link_material">        
        <color rgba="0.61568627450980395466 0.81176470588235305481 0.92941176470588238168 1.0"/>        
      </material>      
    </visual>    
    <collision>      
      <origin xyz="0 0 0" rpy="0 -0 0"/>      
      <geometry>        
        <mesh filename="package:///meshes/right_sole_link_collision.stl"/>        
      </geometry>      
    </collision>    
    <inertial>      
      <origin xyz="-0.028269220649489175401 -7.4209810882689804793e-08 -0.010206288127739998259" rpy="0 0 0"/>      
      <mass value="0.013900000000000007835"/>      
      <inertia ixx="1.3160690708871243068e-06" ixy="-1.0226444191974891076e-10" ixz="-2.3744136049829838944e-07" iyy="1.3575381226152454021e-05" iyz="-7.1602330638764630989e-13" izz="1.4673427099197175005e-05"/>      
    </inertial>    
  </link>  

  <joint name="right_sole" type="fixed">    
    <origin xyz="-9.2157184661267876891e-18 0.024999999999999938938 -0.022599999999999998562" rpy="1.5707963267949021091 1.5707963267948905628 0"/>    
    <parent link="ank_roll_link"/>    
    <child link="right_sole_link"/>    
    <axis xyz="0 0 1"/>    
    <limit effort="1" velocity="20"/>    
    <joint_properties friction="0.0"/>    
  </joint>  

  <joint name="right_ank_roll" type="revolute">    
    <origin xyz="0.0015000000000000004649 0 -9.7578195523695399061e-19" rpy="-3.141592653589793116 -1.5707963267948956698 0"/>    
    <parent link="ank_pitch_link"/>    
    <child link="ank_roll_link"/>    
    <axis xyz="0 0 1"/>    
    <limit effort="1" velocity="20" lower="-0.785398163397448279" upper="0.785398163397448279"/>    
    <joint_properties friction="0.0"/>    
  </joint>  

  <joint name="right_ank_pitch" type="revolute">    
    <origin xyz="4.3837881646777831769e-17 0.10000000000000000555 -0.010399999999999944011" rpy="2.2204460560390508438e-16 3.5527136779803609004e-15 3.1415926535897873428"/>    
    <parent link="right_calf_link"/>    
    <child link="ank_pitch_link"/>    
    <axis xyz="0 0 1"/>    
    <limit effort="1" velocity="20" lower="-0.785398163397448279" upper="0.95993108859688125456"/>    
    <joint_properties friction="0.0"/>    
  </joint>  

  <link name="ank_motor_arm">    
    <visual>      
      <origin xyz="0 0 0" rpy="0 -0 0"/>      
      <geometry>        
        <mesh filename="package:///meshes/right_ank_motor_arm_visual.stl"/>        
      </geometry>      
      <material name="ank_motor_arm_material">        
        <color rgba="0.62517751827980905244 0.70593642422614044651 0.75978993426662766453 1.0"/>        
      </material>      
    </visual>    
    <collision>      
      <origin xyz="0 0 0" rpy="0 -0 0"/>      
      <geometry>        
        <mesh filename="package:///meshes/right_ank_motor_arm_collision.stl"/>        
      </geometry>      
    </collision>    
    <inertial>      
      <origin xyz="0.014511489101591695805 -2.8371214923197373628e-17 0.0040925443765950624692" rpy="0 0 0"/>      
      <mass value="0.0020595846677894939954"/>      
      <inertia ixx="2.75918367565218459e-08" ixy="-1.6758595368887842784e-23" ixz="-3.0270788206594894824e-08" iyy="1.6138599216238459113e-07" iyz="-3.3435412526956429362e-23" izz="1.6437836765016314004e-07"/>      
    </inertial>    
  </link>  

  <joint name="right_ank_act_1" type="revolute">    
    <origin xyz="0.01349999999999646795 0.044500000000006922907 0.0040000000000042796461" rpy="-3.078520668360990726e-13 -4.5496150843455205025e-14 0.21173394130153330717"/>    
    <parent link="right_calf_link"/>    
    <child link="ank_motor_arm"/>    
    <axis xyz="0 0 1"/>    
    <limit effort="1" velocity="20" lower="-1.3089969389957472057" upper="1.3089969389957472057"/>    
    <joint_properties friction="0.0"/>    
  </joint>  

  <link name="ank_motor_arm_2">    
    <visual>      
      <origin xyz="0 0 0" rpy="0 -0 0"/>      
      <geometry>        
        <mesh filename="package:///meshes/right_ank_motor_arm_2_visual.stl"/>        
      </geometry>      
      <material name="ank_motor_arm_2_material">        
        <color rgba="0.62517751827980905244 0.70593642422614044651 0.75978993426662766453 1.0"/>        
      </material>      
    </visual>    
    <collision>      
      <origin xyz="0 0 0" rpy="0 -0 0"/>      
      <geometry>        
        <mesh filename="package:///meshes/right_ank_motor_arm_2_collision.stl"/>        
      </geometry>      
    </collision>    
    <inertial>      
      <origin xyz="0.014511489101591685397 5.5448015589825106898e-19 0.0040925443765950642039" rpy="0 0 0"/>      
      <mass value="0.0020595846677894939954"/>      
      <inertia ixx="2.7591836756521965014e-08" ixy="-2.786136438945596108e-23" ixz="-3.027078820659482865e-08" iyy="1.6138599216238437937e-07" iyz="-3.6560728613848348131e-24" izz="1.6437836765016284887e-07"/>      
    </inertial>    
  </link>  

  <joint name="right_ank_act_2" type="revolute">    
    <origin xyz="0.013500000000004360942 0.064500000000008050893 -0.024800000000002021816" rpy="-3.1415926535895257743 -2.0958441553975745862e-13 0.22995607267268677876"/>    
    <parent link="right_calf_link"/>    
    <child link="ank_motor_arm_2"/>    
    <axis xyz="0 0 1"/>    
    <limit effort="1" velocity="20" lower="-1.3089969389957472057" upper="1.3089969389957472057"/>    
    <joint_properties friction="0.0"/>    
  </joint>  

  <joint name="right_knee_pitch" type="revolute">    
    <origin xyz="1.1564389868401171602e-17 -0.096000000000000029754 -0.0092000000000000067835" rpy="-6.0024085179096384259e-15 1.3010426071629226535e-16 3.1415926535897913396"/>    
    <parent link="right_hip_pitch_link_xm430"/>    
    <child link="right_calf_link"/>    
    <axis xyz="0 0 1"/>    
    <limit effort="1" velocity="20" lower="-1.9198621771937625091" upper="0"/>    
    <joint_properties friction="0.0"/>    
  </joint>  

  <link name="xm430_plate">    
    <visual>      
      <origin xyz="0 0 0" rpy="0 -0 0"/>      
      <geometry>        
        <mesh filename="package:///meshes/right_xm430_plate_visual.stl"/>        
      </geometry>      
      <material name="xm430_plate_material">        
        <color rgba="0.61568627450980395466 0.81176470588235294379 0.9294117647058824927 1.0"/>        
      </material>      
    </visual>    
    <collision>      
      <origin xyz="0 0 0" rpy="0 -0 0"/>      
      <geometry>        
        <mesh filename="package:///meshes/right_xm430_plate_collision.stl"/>        
      </geometry>      
    </collision>    
    <inertial>      
      <origin xyz="3.9034269558608525572e-19 4.0403155142548792296e-18 -0.0024039046431217989813" rpy="0 0 0"/>      
      <mass value="0.0026999999999999992756"/>      
      <inertia ixx="2.6720434385876693618e-07" ixy="-6.8936588702566374239e-08" ixz="5.2034483092649082032e-36" iyy="1.2933116645363405536e-07" iyz="1.1219688235926719214e-35" izz="3.8533537562751439267e-07"/>      
    </inertial>    
  </link>  

  <link name="knee_rod">    
    <visual>      
      <origin xyz="0 0 0" rpy="0 -0 0"/>      
      <geometry>        
        <mesh filename="package:///meshes/right_knee_rod_visual.stl"/>        
      </geometry>      
      <material name="knee_rod_material">        
        <color rgba="0.62051618944235198416 0.78640765248647581664 0.88594253031295022716 1.0"/>        
      </material>      
    </visual>    
    <collision>      
      <origin xyz="0 0 0" rpy="0 -0 0"/>      
      <geometry>        
        <mesh filename="package:///meshes/right_knee_rod_collision.stl"/>        
      </geometry>      
    </collision>    
    <inertial>      
      <origin xyz="0.014594546907469960195 4.2152786375369788398e-05 -0.0015996227373185887589" rpy="0 0 0"/>      
      <mass value="0.0031629468613064179276"/>      
      <inertia ixx="2.5896145569812783873e-08" ixy="-3.5408233594415055965e-10" ixz="4.1682973432396374719e-10" iyy="6.0153250390525877384e-07" iyz="1.2039109459404085995e-12" izz="6.2266858519717461123e-07"/>      
    </inertial>    
  </link>  

  <joint name="right_knee_front_rev_1" type="revolute">    
    <origin xyz="-0.0057402514854763475247 -0.013858192987669298857 -0.0050000000000000009714" rpy="-7.6843565403024876539e-16 -7.2468500696722411095e-16 1.5650043890089964105"/>    
    <parent link="xm430_plate"/>    
    <child link="knee_rod"/>    
    <axis xyz="0 0 1"/>    
    <limit effort="1" velocity="20" lower="-6.283185307179586232" upper="6.283185307179586232"/>    
    <joint_properties friction="0.0"/>    
  </joint>  

  <link name="knee_rod_2">    
    <visual>      
      <origin xyz="0 0 0" rpy="0 -0 0"/>      
      <geometry>        
        <mesh filename="package:///meshes/right_knee_rod_2_visual.stl"/>        
      </geometry>      
      <material name="knee_rod_2_material">        
        <color rgba="0.62051618944235198416 0.78640765248647581664 0.88594253031295022716 1.0"/>        
      </material>      
    </visual>    
    <collision>      
      <origin xyz="0 0 0" rpy="0 -0 0"/>      
      <geometry>        
        <mesh filename="package:///meshes/right_knee_rod_2_collision.stl"/>        
      </geometry>      
    </collision>    
    <inertial>      
      <origin xyz="0.014594546749629417476 4.2261942307114621806e-05 -0.0015996227373187431493" rpy="0 0 0"/>      
      <mass value="0.0031629468613064179276"/>      
      <inertia ixx="2.5896150873195108889e-08" ixy="-3.5499923916223384349e-10" ixz="4.1682972981661921117e-10" iyy="6.0153250125354727592e-07" iyz="1.2070285090916656039e-12" izz="6.2266858784884725151e-07"/>      
    </inertial>    
  </link>  

  <joint name="right_knee_back_rev_1" type="revolute">    
    <origin xyz="0.0057402514854763509941 0.013858192987669284979 -0.0050000000000000009714" rpy="1.4780745018405688374e-15 -6.0371120429764004227e-16 1.5650006493639538885"/>    
    <parent link="xm430_plate"/>    
    <child link="knee_rod_2"/>    
    <axis xyz="0 0 1"/>    
    <limit effort="1" velocity="20" lower="-6.283185307179586232" upper="6.283185307179586232"/>    
    <joint_properties friction="0.0"/>    
  </joint>  

  <joint name="right_knee_act" type="revolute">    
    <origin xyz="0.00014999999999998383225 -0.061500000000000006051 -0.030400000000000024225" rpy="-3.3306690735930707292e-16 -2.9976021666231129079e-15 3.1415926535897913396"/>    
    <parent link="right_hip_pitch_link_xm430"/>    
    <child link="xm430_plate"/>    
    <axis xyz="0 0 1"/>    
    <limit effort="1" velocity="20" lower="-1.9198621771937625091" upper="0"/>    
    <joint_properties friction="0.0"/>    
  </joint>  

  <joint name="right_hip_pitch" type="revolute">    
    <origin xyz="-0.024000000716143048141 -0.019000000152443574652 -0.019000000152453545843" rpy="1.5707963267951119413 1.5707963267947440134 0"/>    
    <parent link="hip_roll_link"/>    
    <child link="right_hip_pitch_link_xm430"/>    
    <axis xyz="0 0 1"/>    
    <limit effort="1" velocity="20" lower="-1.570796326794896558" upper="1.570796326794896558"/>    
    <joint_properties friction="0.0"/>    
  </joint>  

  <joint name="right_hip_roll" type="revolute">    
    <origin xyz="-0.019000000000000096673 2.0909656639487276466e-16 -0.025999999999999905131" rpy="-2.4415165121040963179e-28 -1.5707963267948938935 0"/>    
    <parent link="hip_yaw_link"/>    
    <child link="hip_roll_link"/>    
    <axis xyz="0 0 1"/>    
    <limit effort="1" velocity="20" lower="-0.785398163397448279" upper="1.570796326794896558"/>    
    <joint_properties friction="0.0"/>    
  </joint>  


</robot>