<?xml version="1.0" ?><robot name="right_leg_XM430">  
  <link name="hip_yaw_link">    
    <visual>      
      <origin xyz="0 0 0" rpy="0 -0 0"/>      
      <geometry>        
        <mesh filename="package:///meshes/right_hip_yaw_link_visual.stl"/>        
      </geometry>      
      <material name="hip_yaw_link_material">        
        <color rgba="0.61568627450980395466 0.81176470588235294379 0.92941176470588238168 1.0"/>        
      </material>      
    </visual>    
    <collision>      
      <origin xyz="0 0 0" rpy="0 -0 0"/>      
      <geometry>        
        <mesh filename="package:///meshes/right_hip_yaw_link_collision.stl"/>        
      </geometry>      
    </collision>    
    <inertial>      
      <origin xyz="-6.7015689604249926662e-20 4.3918015011849180404e-19 -0.0098390489054829104176" rpy="0 0 0"/>      
      <mass value="0.017999999999999995171"/>      
      <inertia ixx="2.638503389144253662e-06" ixy="0" ixz="0" iyy="7.6596731957046890345e-06" iyz="0" izz="7.7220708070894769837e-06"/>      
    </inertial>    
  </link>  

  <link name="hip_roll_link">    
    <visual>      
      <origin xyz="0 0 0" rpy="0 -0 0"/>      
      <geometry>        
        <mesh filename="package:///meshes/right_hip_roll_link_visual.stl"/>        
      </geometry>      
      <material name="hip_roll_link_material">        
        <color rgba="0.51698661238356036218 0.50347815951093466413 0.49050589017722012741 1.0"/>        
      </material>      
    </visual>    
    <collision>      
      <origin xyz="0 0 0" rpy="0 -0 0"/>      
      <geometry>        
        <mesh filename="package:///meshes/right_hip_roll_link_collision.stl"/>        
      </geometry>      
    </collision>    
    <inertial>      
      <origin xyz="-0.011999849582182768939 -0.00049598090794319320881 -0.018504111838597472883" rpy="0 0 0"/>      
      <mass value="0.10699970659110669136"/>      
      <inertia ixx="2.2075996228675266026e-05" ixy="-4.50058018289495008e-08" ixz="-4.5362214342475956034e-08" iyy="2.9866686933523323838e-05" iyz="-5.5606319466522003496e-07" izz="2.9866720157735093328e-05"/>      
    </inertial>    
  </link>  

  <link name="right_hip_pitch_link_xm430">    
    <visual>      
      <origin xyz="0 0 0" rpy="0 -0 0"/>      
      <geometry>        
        <mesh filename="package:///meshes/right_hip_pitch_link_xm430_visual.stl"/>        
      </geometry>      
      <material name="right_hip_pitch_link_xm430_material">        
        <color rgba="0.57975821272406502516 0.77143728959223789587 0.90851483081009554166 1.0"/>        
      </material>      
    </visual>    
    <collision>      
      <origin xyz="0 0 0" rpy="0 -0 0"/>      
      <geometry>        
        <mesh filename="package:///meshes/right_hip_pitch_link_xm430_collision.stl"/>        
      </geometry>      
    </collision>    
    <inertial>      
      <origin xyz="0.0025369940892301435544 -0.053177222976062685222 -0.015212667045966776422" rpy="0 0 0"/>      
      <mass value="0.029200901345856088154"/>      
      <inertia ixx="4.1359210165692305292e-05" ixy="2.8846904860009788469e-07" ixz="3.5209134634345168732e-09" iyy="9.0572095101179097984e-06" iyz="1.6889923798545578151e-06" izz="4.074145340165466261e-05"/>      
    </inertial>    
  </link>  

  <link name="right_calf_link">    
    <visual>      
      <origin xyz="0 0 0" rpy="0 -0 0"/>      
      <geometry>        
        <mesh filename="package:///meshes/right_calf_link_visual.stl"/>        
      </geometry>      
      <material name="right_calf_link_material">        
        <color rgba="0.61177930930733637194 0.71653254923097875473 0.74989274724786592063 1.0"/>        
      </material>      
    </visual>    
    <collision>      
      <origin xyz="0 0 0" rpy="0 -0 0"/>      
      <geometry>        
        <mesh filename="package:///meshes/right_calf_link_collision.stl"/>        
      </geometry>      
    </collision>    
    <inertial>      
      <origin xyz="0.0011880884108858465187 0.049643066575010608155 -0.0098634853265740091155" rpy="0 0 0"/>      
      <mass value="0.079607494529051442411"/>      
      <inertia ixx="4.8056790185738505847e-05" ixy="-3.5190664140523731458e-06" ixz="3.9918569370880469757e-07" iyy="1.4293033414473552055e-05" iyz="-4.8654596308570628042e-07" izz="5.1185953583038329819e-05"/>      
    </inertial>    
  </link>  

  <link name="bearing_683">    
    <visual>      
      <origin xyz="0 0 0" rpy="0 -0 0"/>      
      <geometry>        
        <mesh filename="package:///meshes/right_bearing_683_visual.stl"/>        
      </geometry>      
      <material name="bearing_683_material">        
        <color rgba="0.64705882352941179736 0.64705882352941179736 0.64705882352941179736 1.0"/>        
      </material>      
    </visual>    
    <collision>      
      <origin xyz="0 0 0" rpy="0 -0 0"/>      
      <geometry>        
        <mesh filename="package:///meshes/right_bearing_683_collision.stl"/>        
      </geometry>      
    </collision>    
    <inertial>      
      <origin xyz="1.0732094295238763188e-19 2.4186774283159686951e-19 -0.0015499999999999982108" rpy="0 0 0"/>      
      <mass value="0.00048694686130641793437"/>      
      <inertia ixx="2.1551456503319887385e-09" ixy="-2.9294495027892568051e-27" ixz="9.2988683363002032047e-39" iyy="2.1551456503319891521e-09" iyz="-6.9734227591432482265e-38" izz="3.5303647444715305817e-09"/>      
    </inertial>    
  </link>  

  <joint name="right_knee_front_rev_2" type="revolute">    
    <origin xyz="-0.0057402514854763431879 -0.013858192987669298857 -0.026199999999999994127" rpy="-5.4477346283033895825e-15 1.0965747154702311575e-14 3.1358007158040965834"/>    
    <parent link="right_calf_link"/>    
    <child link="bearing_683"/>    
    <axis xyz="0 0 1"/>    
    <limit effort="1" velocity="20" lower="-6.283185307179586232" upper="6.283185307179586232"/>    
    <joint_properties friction="0.0"/>    
  </joint>  

  <link name="bearing_683_2">    
    <visual>      
      <origin xyz="0 0 0" rpy="0 -0 0"/>      
      <geometry>        
        <mesh filename="package:///meshes/right_bearing_683_2_visual.stl"/>        
      </geometry>      
      <material name="bearing_683_2_material">        
        <color rgba="0.64705882352941179736 0.64705882352941179736 0.64705882352941179736 1.0"/>        
      </material>      
    </visual>    
    <collision>      
      <origin xyz="0 0 0" rpy="0 -0 0"/>      
      <geometry>        
        <mesh filename="package:///meshes/right_bearing_683_2_collision.stl"/>        
      </geometry>      
    </collision>    
    <inertial>      
      <origin xyz="9.7468268094080836801e-19 2.4186774283165874001e-19 -0.0015499999999999977771" rpy="0 0 0"/>      
      <mass value="0.00048694686130641793437"/>      
      <inertia ixx="2.1551456503319887385e-09" ixy="-1.2055502399488045527e-29" ixz="6.0530663080618900365e-38" iyy="2.1551456503319891521e-09" iyz="6.329646417650877137e-38" izz="3.5303647444715322361e-09"/>      
    </inertial>    
  </link>  

  <joint name="right_knee_back_rev_2" type="revolute">    
    <origin xyz="0.0057402514854763726782 0.013858192987669298857 -0.026200000000000001066" rpy="-1.8771482682971376925e-15 -9.8530873122510239724e-18 3.1357969761587902724"/>    
    <parent link="right_calf_link"/>    
    <child link="bearing_683_2"/>    
    <axis xyz="0 0 1"/>    
    <limit effort="1" velocity="20" lower="-6.283185307179586232" upper="6.283185307179586232"/>    
    <joint_properties friction="0.0"/>    
  </joint>  

  <link name="ank_pitch_link">    
    <visual>      
      <origin xyz="0 0 0" rpy="0 -0 0"/>      
      <geometry>        
        <mesh filename="package:///meshes/right_ank_pitch_link_visual.stl"/>        
      </geometry>      
      <material name="ank_pitch_link_material">        
        <color rgba="0.63189161126160264814 0.7266866879354088038 0.78356373393969258601 1.0"/>        
      </material>      
    </visual>    
    <collision>      
      <origin xyz="0 0 0" rpy="0 -0 0"/>      
      <geometry>        
        <mesh filename="package:///meshes/right_ank_pitch_link_collision.stl"/>        
      </geometry>      
    </collision>    
    <inertial>      
      <origin xyz="0.00059528282565905667884 -4.0269682589415725122e-08 7.7616094188425227177e-08" rpy="0 0 0"/>      
      <mass value="0.0042238381753791614387"/>      
      <inertia ixx="3.9782741364675321991e-07" ixy="-1.6834347649910148831e-13" ixz="2.0919192021941485552e-14" iyy="4.3705254067418651898e-07" iyz="-1.6428822141780806979e-12" izz="8.8858574534600111529e-08"/>      
    </inertial>    
  </link>  

  <link name="ank_roll_link">    
    <visual>      
      <origin xyz="0 0 0" rpy="0 -0 0"/>      
      <geometry>        
        <mesh filename="package:///meshes/right_ank_roll_link_visual.stl"/>        
      </geometry>      
      <material name="ank_roll_link_material">        
        <color rgba="0.61568627450980395466 0.81176470588235294379 0.92941176470588238168 1.0"/>        
      </material>      
    </visual>    
    <collision>      
      <origin xyz="0 0 0" rpy="0 -0 0"/>      
      <geometry>        
        <mesh filename="package:///meshes/right_ank_roll_link_collision.stl"/>        
      </geometry>      
    </collision>    
    <inertial>      
      <origin xyz="-3.374897775305092037e-09 0.016071733707723714207 -0.0096236810250137777567" rpy="0 0 0"/>      
      <mass value="0.010900000000000006906"/>      
      <inertia ixx="2.6058536057764959133e-06" ixy="-5.4054321086197607014e-13" ixz="6.0692549095841946231e-13" iyy="2.5928781338360460482e-06" iyz="3.9359839679282425038e-07" izz="1.6179884211196010928e-06"/>      
    </inertial>    
  </link>  

  <link name="ank_rr_link">    
    <visual>      
      <origin xyz="0 0 0" rpy="0 -0 0"/>      
      <geometry>        
        <mesh filename="package:///meshes/right_ank_rr_link_visual.stl"/>        
      </geometry>      
      <material name="ank_rr_link_material">        
        <color rgba="0.61568627450980395466 0.81176470588235294379 0.92941176470588238168 1.0"/>        
      </material>      
    </visual>    
    <collision>      
      <origin xyz="0 0 0" rpy="0 -0 0"/>      
      <geometry>        
        <mesh filename="package:///meshes/right_ank_rr_link_collision.stl"/>        
      </geometry>      
    </collision>    
    <inertial>      
      <origin xyz="-4.5249610960602422048e-05 -0.0063096429836314027462 1.9359077708117763666e-19" rpy="0 0 0"/>      
      <mass value="0.0014499999999999999001"/>      
      <inertia ixx="2.9739579267716163268e-08" ixy="-2.4213146797978005064e-10" ixz="-3.5523394884482601788e-14" iyy="2.7430027724071950438e-08" iyz="-9.2286660723348399955e-32" izz="4.2921949116163665819e-08"/>      
    </inertial>    
  </link>  

  <link name="ank_motor_rod_long">    
    <visual>      
      <origin xyz="0 0 0" rpy="0 -0 0"/>      
      <geometry>        
        <mesh filename="package:///meshes/right_ank_motor_rod_long_visual.stl"/>        
      </geometry>      
      <material name="ank_motor_rod_long_material">        
        <color rgba="0.63549975559783222767 0.7077439301702044272 0.75109043491362781353 1.0"/>        
      </material>      
    </visual>    
    <collision>      
      <origin xyz="0 0 0" rpy="0 -0 0"/>      
      <geometry>        
        <mesh filename="package:///meshes/right_ank_motor_rod_long_collision.stl"/>        
      </geometry>      
    </collision>    
    <inertial>      
      <origin xyz="2.4855086429196933828e-10 0.034559019974062202274 0.00093851704878448538941" rpy="0 0 0"/>      
      <mass value="0.0021712857268636714773"/>      
      <inertia ixx="8.5350290057999892598e-07" ixy="1.4884244311377931608e-14" ixz="4.5749525025513695314e-11" iyy="1.3237321792739358999e-08" iyz="-4.3668910960836045554e-09" izz="8.5812217519451249942e-07"/>      
    </inertial>    
  </link>  

  <joint name="right_ank_long_rev_2" type="revolute">    
    <origin xyz="3.4694469519536141888e-18 -0.0099999999999998423483 1.0408340855860842566e-17" rpy="-1.570796326794896558 -1.3320366994106278558 -1.5707963267948821251"/>    
    <parent link="ank_rr_link"/>    
    <child link="ank_motor_rod_long"/>    
    <axis xyz="0 0 1"/>    
    <limit effort="1" velocity="20" lower="-1.570796326794896558" upper="1.570796326794896558"/>    
    <joint_properties friction="0.0"/>    
  </joint>  

  <joint name="right_ank_long_rev_1" type="revolute">    
    <origin xyz="0.017999999999999988232 0.016000000000000014211 -0.020600000000000014133" rpy="-6.5592393894058373872e-17 4.425192650031777037e-16 0.01822308504299342824"/>    
    <parent link="ank_roll_link"/>    
    <child link="ank_rr_link"/>    
    <axis xyz="0 0 1"/>    
    <limit effort="1" velocity="20" lower="-1.570796326794896558" upper="1.570796326794896558"/>    
    <joint_properties friction="0.0"/>    
  </joint>  

  <link name="ank_rr_link_2">    
    <visual>      
      <origin xyz="0 0 0" rpy="0 -0 0"/>      
      <geometry>        
        <mesh filename="package:///meshes/right_ank_rr_link_2_visual.stl"/>        
      </geometry>      
      <material name="ank_rr_link_2_material">        
        <color rgba="0.61568627450980395466 0.81176470588235294379 0.92941176470588238168 1.0"/>        
      </material>      
    </visual>    
    <collision>      
      <origin xyz="0 0 0" rpy="0 -0 0"/>      
      <geometry>        
        <mesh filename="package:///meshes/right_ank_rr_link_2_collision.stl"/>        
      </geometry>      
    </collision>    
    <inertial>      
      <origin xyz="-4.524961096060238139e-05 0.0063096429836314027462 -1.9359077708145472983e-19" rpy="0 0 0"/>      
      <mass value="0.0014499999999999999001"/>      
      <inertia ixx="2.9739579267716150033e-08" ixy="2.4213146797978025744e-10" ixz="3.5523394884482595477e-14" iyy="2.7430027724071950438e-08" iyz="5.6282437144470795625e-32" izz="4.2921949116163665819e-08"/>      
    </inertial>    
  </link>  

  <link name="ank_motor_rod_short">    
    <visual>      
      <origin xyz="0 0 0" rpy="0 -0 0"/>      
      <geometry>        
        <mesh filename="package:///meshes/right_ank_motor_rod_short_visual.stl"/>        
      </geometry>      
      <material name="ank_motor_rod_short_material">        
        <color rgba="0.41222606689734714314 0.58339100346020755783 0.8110726643598615837 1.0"/>        
      </material>      
    </visual>    
    <collision>      
      <origin xyz="0 0 0" rpy="0 -0 0"/>      
      <geometry>        
        <mesh filename="package:///meshes/right_ank_motor_rod_short_collision.stl"/>        
      </geometry>      
    </collision>    
    <inertial>      
      <origin xyz="2.6038939217395135539e-10 0.023830465465871003561 0.0009040350635961763668" rpy="0 0 0"/>      
      <mass value="0.0017000000000000005558"/>      
      <inertia ixx="3.3153416252670696522e-07" ixy="8.7419773793873309686e-15" ixz="4.5749941567750892577e-11" iyy="1.0947363610305942965e-08" iyz="-3.5863098646396907895e-09" izz="3.3621340447865776674e-07"/>      
    </inertial>    
  </link>  

  <joint name="right_ank_short_rev_2" type="revolute">    
    <origin xyz="3.4694469519536141888e-18 0.010000000000000008882 -6.9388939039072283776e-18" rpy="-1.570796326794896558 1.211913386290874195 -1.5707963267949693886"/>    
    <parent link="ank_rr_link_2"/>    
    <child link="ank_motor_rod_short"/>    
    <axis xyz="0 0 1"/>    
    <limit effort="1" velocity="20" lower="-1.570796326794896558" upper="1.570796326794896558"/>    
    <joint_properties friction="0.0"/>    
  </joint>  

  <joint name="right_ank_short_rev_1" type="revolute">    
    <origin xyz="-0.018000000000000015987 0.016000000000000069722 -0.020599999999999996786" rpy="-5.1243183935211302546e-15 2.3393195508611717606e-14 3.115474105082493228"/>    
    <parent link="ank_roll_link"/>    
    <child link="ank_rr_link_2"/>    
    <axis xyz="0 0 1"/>    
    <limit effort="1" velocity="20" lower="-1.570796326794896558" upper="1.570796326794896558"/>    
    <joint_properties friction="0.0"/>    
  </joint>  

  <link name="right_sole_link">    
    <visual>      
      <origin xyz="0 0 0" rpy="0 -0 0"/>      
      <geometry>        
        <mesh filename="package:///meshes/right_sole_link_visual.stl"/>        
      </geometry>      
      <material name="right_sole_link_material">        
        <color rgba="0.61568627450980395466 0.81176470588235294379 0.92941176470588238168 1.0"/>        
      </material>      
    </visual>    
    <collision>      
      <origin xyz="0 0 0" rpy="0 -0 0"/>      
      <geometry>        
        <mesh filename="package:///meshes/right_sole_link_collision.stl"/>        
      </geometry>      
    </collision>    
    <inertial>      
      <origin xyz="-0.02826922064948917887 -7.4209810882872538916e-08 -0.010206288127740055505" rpy="0 0 0"/>      
      <mass value="0.013900000000000004366"/>      
      <inertia ixx="1.316069070887124095e-06" ixy="-1.0226444191973209573e-10" ixz="-2.3744136049829838944e-07" iyy="1.3575381226152454021e-05" iyz="-7.1602330637823177879e-13" izz="1.4673427099197175005e-05"/>      
    </inertial>    
  </link>  

  <joint name="right_sole" type="fixed">    
    <origin xyz="-8.9988780316296868023e-18 0.025000000000000022204 -0.022600000000000002032" rpy="1.5707963267948985564 1.5707963267948945596 0"/>    
    <parent link="ank_roll_link"/>    
    <child link="right_sole_link"/>    
    <axis xyz="0 0 1"/>    
    <limit effort="1" velocity="20"/>    
    <joint_properties friction="0.0"/>    
  </joint>  

  <joint name="right_ank_roll" type="revolute">    
    <origin xyz="0.0014999999999999998144 2.7755575615628913511e-17 -1.4419888894057208972e-17" rpy="-3.141592653589793116 -1.5707963267948947816 0"/>    
    <parent link="ank_pitch_link"/>    
    <child link="ank_roll_link"/>    
    <axis xyz="0 0 1"/>    
    <limit effort="1" velocity="20" lower="-0.785398163397448279" upper="0.785398163397448279"/>    
    <joint_properties friction="0.0"/>    
  </joint>  

  <joint name="right_ank_pitch" type="revolute">    
    <origin xyz="2.5458137454050591327e-17 0.10000000000000003331 -0.010400000000000018605" rpy="1.5825612599836936462e-15 -6.6613381503165742443e-16 -3.1415926535897873428"/>    
    <parent link="right_calf_link"/>    
    <child link="ank_pitch_link"/>    
    <axis xyz="0 0 1"/>    
    <limit effort="1" velocity="20" lower="-0.785398163397448279" upper="0.95993108859688125456"/>    
    <joint_properties friction="0.0"/>    
  </joint>  

  <link name="ank_motor_arm">    
    <visual>      
      <origin xyz="0 0 0" rpy="0 -0 0"/>      
      <geometry>        
        <mesh filename="package:///meshes/right_ank_motor_arm_visual.stl"/>        
      </geometry>      
      <material name="ank_motor_arm_material">        
        <color rgba="0.62517751827980905244 0.70593642422614044651 0.75978993426662777555 1.0"/>        
      </material>      
    </visual>    
    <collision>      
      <origin xyz="0 0 0" rpy="0 -0 0"/>      
      <geometry>        
        <mesh filename="package:///meshes/right_ank_motor_arm_collision.stl"/>        
      </geometry>      
    </collision>    
    <inertial>      
      <origin xyz="0.014511489101591685397 -1.2304772143439285592e-18 0.0040925443765950624692" rpy="0 0 0"/>      
      <mass value="0.0020595846677894939954"/>      
      <inertia ixx="2.7591836756521888913e-08" ixy="-5.9964751007237139186e-24" ixz="-3.0270788206594808798e-08" iyy="1.6138599216238429997e-07" iyz="-1.0580171637286161896e-23" izz="1.6437836765016284887e-07"/>      
    </inertial>    
  </link>  

  <joint name="right_ank_act_1" type="revolute">    
    <origin xyz="0.013499999999996532135 0.044500000000006922907 0.0040000000000042501558" rpy="-3.1437427131281823257e-13 -4.4003633570199104585e-14 0.21173394130151781956"/>    
    <parent link="right_calf_link"/>    
    <child link="ank_motor_arm"/>    
    <axis xyz="0 0 1"/>    
    <limit effort="1" velocity="20" lower="-1.3089969389957472057" upper="1.3089969389957472057"/>    
    <joint_properties friction="0.0"/>    
  </joint>  

  <link name="ank_motor_arm_2">    
    <visual>      
      <origin xyz="0 0 0" rpy="0 -0 0"/>      
      <geometry>        
        <mesh filename="package:///meshes/right_ank_motor_arm_2_visual.stl"/>        
      </geometry>      
      <material name="ank_motor_arm_2_material">        
        <color rgba="0.62517751827980905244 0.70593642422614044651 0.75978993426662777555 1.0"/>        
      </material>      
    </visual>    
    <collision>      
      <origin xyz="0 0 0" rpy="0 -0 0"/>      
      <geometry>        
        <mesh filename="package:///meshes/right_ank_motor_arm_2_collision.stl"/>        
      </geometry>      
    </collision>    
    <inertial>      
      <origin xyz="0.014511489101591685397 4.5584079062740652548e-19 0.0040925443765950642039" rpy="0 0 0"/>      
      <mass value="0.0020595846677894939954"/>      
      <inertia ixx="2.7591836756521965014e-08" ixy="-3.0026020760096009728e-23" ixz="-3.0270788206594841885e-08" iyy="1.613859921623843529e-07" iyz="-6.8768720166424008923e-24" izz="1.6437836765016284887e-07"/>      
    </inertial>    
  </link>  

  <joint name="right_ank_act_2" type="revolute">    
    <origin xyz="0.013500000000004223899 0.06450000000000813416 -0.024800000000001803241" rpy="-3.1415926535895222216 -2.1045472835494036236e-13 0.22995607267266512941"/>    
    <parent link="right_calf_link"/>    
    <child link="ank_motor_arm_2"/>    
    <axis xyz="0 0 1"/>    
    <limit effort="1" velocity="20" lower="-1.3089969389957472057" upper="1.3089969389957472057"/>    
    <joint_properties friction="0.0"/>    
  </joint>  

  <joint name="right_knee_pitch" type="revolute">    
    <origin xyz="-3.0242154156037831921e-17 -0.096000000000000015876 -0.0091999999999999963751" rpy="1.9802508686334247224e-15 -1.2115308756231608563e-14 3.1415926535897615857"/>    
    <parent link="right_hip_pitch_link_xm430"/>    
    <child link="right_calf_link"/>    
    <axis xyz="0 0 1"/>    
    <limit effort="1" velocity="20" lower="-1.9198621771937625091" upper="0"/>    
    <joint_properties friction="0.0"/>    
  </joint>  

  <link name="xm430_plate">    
    <visual>      
      <origin xyz="0 0 0" rpy="0 -0 0"/>      
      <geometry>        
        <mesh filename="package:///meshes/right_xm430_plate_visual.stl"/>        
      </geometry>      
      <material name="xm430_plate_material">        
        <color rgba="0.61568627450980395466 0.81176470588235294379 0.92941176470588227065 1.0"/>        
      </material>      
    </visual>    
    <collision>      
      <origin xyz="0 0 0" rpy="0 -0 0"/>      
      <geometry>        
        <mesh filename="package:///meshes/right_xm430_plate_collision.stl"/>        
      </geometry>      
    </collision>    
    <inertial>      
      <origin xyz="9.1975985740996841453e-19 1.783860014833551564e-17 -0.0024039046431217955119" rpy="0 0 0"/>      
      <mass value="0.0027000000000000001429"/>      
      <inertia ixx="2.6720434385876688324e-07" ixy="-6.8936588702566387474e-08" ixz="-3.4845808582805296013e-36" iyy="1.2933116645363405536e-07" iyz="-1.1011162650770204514e-36" izz="3.8533537562751439267e-07"/>      
    </inertial>    
  </link>  

  <link name="knee_rod">    
    <visual>      
      <origin xyz="0 0 0" rpy="0 -0 0"/>      
      <geometry>        
        <mesh filename="package:///meshes/right_knee_rod_visual.stl"/>        
      </geometry>      
      <material name="knee_rod_material">        
        <color rgba="0.62711287994822195735 0.75177502733065859619 0.8265723157601205795 1.0"/>        
      </material>      
    </visual>    
    <collision>      
      <origin xyz="0 0 0" rpy="0 -0 0"/>      
      <geometry>        
        <mesh filename="package:///meshes/right_knee_rod_collision.stl"/>        
      </geometry>      
    </collision>    
    <inertial>      
      <origin xyz="0.010967336860938672188 3.1676475513803476272e-05 -0.0015872899055782941843" rpy="0 0 0"/>      
      <mass value="0.0013369468613064179954"/>      
      <inertia ixx="9.6972542174599785294e-09" ixy="-2.6608159054156034333e-10" ixz="3.1323426064377209516e-10" iyy="2.4572580704828929624e-07" iyz="9.0470070491434320118e-13" izz="2.533776609675739859e-07"/>      
    </inertial>    
  </link>  

  <joint name="right_knee_front_rev_1" type="revolute">    
    <origin xyz="-0.005740251485476348392 -0.013858192987669284979 -0.0050000000000000044409" rpy="-1.2384470314426580757e-14 -1.7414957345394515419e-15 1.5650043890091922538"/>    
    <parent link="xm430_plate"/>    
    <child link="knee_rod"/>    
    <axis xyz="0 0 1"/>    
    <limit effort="1" velocity="20" lower="-6.283185307179586232" upper="6.283185307179586232"/>    
    <joint_properties friction="0.0"/>    
  </joint>  

  <link name="knee_rod_2">    
    <visual>      
      <origin xyz="0 0 0" rpy="0 -0 0"/>      
      <geometry>        
        <mesh filename="package:///meshes/right_knee_rod_2_visual.stl"/>        
      </geometry>      
      <material name="knee_rod_2_material">        
        <color rgba="0.62711287994822195735 0.75177502733065859619 0.8265723157601205795 1.0"/>        
      </material>      
    </visual>    
    <collision>      
      <origin xyz="0 0 0" rpy="0 -0 0"/>      
      <geometry>        
        <mesh filename="package:///meshes/right_knee_rod_2_collision.stl"/>        
      </geometry>      
    </collision>    
    <inertial>      
      <origin xyz="0.010967336742326699514 3.1758502723681846197e-05 -0.0015872899055780393968" rpy="0 0 0"/>      
      <mass value="0.0013369468613064179954"/>      
      <inertia ixx="9.6972582027827120085e-09" ixy="-2.6677061413968154947e-10" ixz="3.1323425725317939212e-10" iyy="2.4572580505561670632e-07" iyz="9.0704345416446645418e-13" izz="2.5337766296022052957e-07"/>      
    </inertial>    
  </link>  

  <joint name="right_knee_back_rev_1" type="revolute">    
    <origin xyz="0.0057402514854763509941 0.013858192987669298857 -0.0050000000000000009714" rpy="4.9254694032746774356e-16 3.0156850660129127871e-15 1.5650006493638755067"/>    
    <parent link="xm430_plate"/>    
    <child link="knee_rod_2"/>    
    <axis xyz="0 0 1"/>    
    <limit effort="1" velocity="20" lower="-6.283185307179586232" upper="6.283185307179586232"/>    
    <joint_properties friction="0.0"/>    
  </joint>  

  <joint name="right_knee_act" type="revolute">    
    <origin xyz="0.00014999999999999350875 -0.06150000000000001299 -0.030400000000000010347" rpy="1.3560136669320073081e-26 -9.9920072221372949076e-16 3.1415926535897598093"/>    
    <parent link="right_hip_pitch_link_xm430"/>    
    <child link="xm430_plate"/>    
    <axis xyz="0 0 1"/>    
    <limit effort="1" velocity="20" lower="-1.9198621771937625091" upper="0"/>    
    <joint_properties friction="0.0"/>    
  </joint>  

  <joint name="right_hip_pitch" type="revolute">    
    <origin xyz="-0.024000000716143048141 -0.019000000152443574652 -0.019000000152453549312" rpy="1.5707963267951119413 1.5707963267946947195 0"/>    
    <parent link="hip_roll_link"/>    
    <child link="right_hip_pitch_link_xm430"/>    
    <axis xyz="0 0 1"/>    
    <limit effort="1" velocity="20" lower="-1.570796326794896558" upper="1.570796326794896558"/>    
    <joint_properties friction="0.0"/>    
  </joint>  

  <joint name="right_hip_roll" type="revolute">    
    <origin xyz="-0.018999999999999999528 3.350043889036771243e-18 -0.026000000000000002276" rpy="2.5210948034330457424e-32 -1.5707963267948741315 0"/>    
    <parent link="hip_yaw_link"/>    
    <child link="hip_roll_link"/>    
    <axis xyz="0 0 1"/>    
    <limit effort="1" velocity="20" lower="-0.785398163397448279" upper="1.570796326794896558"/>    
    <joint_properties friction="0.0"/>    
  </joint>  


</robot>