<mujoco model="sysID_XM430">
  <compiler angle="radian" autolimits="true" />

  <asset>
    <mesh name="xm430_visual" file="../assemblies/sysID_XM430/meshes/xm430_visual.stl" />
    <mesh name="arm_430_visual" file="../assemblies/sysID_XM430/meshes/arm_430_visual.stl" />
  </asset>

  <worldbody>
    <geom type="mesh" rgba="0.91426 0.700008 0.130248 1" mesh="xm430_visual" class="visual" />
    <body name="arm_430" pos="0.093 0.0326999 0.0055694" quat="0.5 -0.5 0.5 -0.5">
      <inertial pos="-0.0722306 0 -0.019" quat="0.707107 0 0 0.707107" mass="0.2345" diaginertia="0.000369018 0.00023539 0.000184483" />
      <joint name="joint_0" pos="0 0 0" axis="0 0 1" range="-1.5708 1.5708" damping="0.195" armature="0.002" frictionloss="0.0" />
      <geom type="mesh" rgba="0.629995 0.655186 0.678154 1" mesh="arm_430_visual" class="visual" />
    </body>
  </worldbody>
  <option>
    <flag eulerdamp="disable" />
  </option>
  <actuator>
    <position name="joint_0" joint="joint_0" kp="21.09375" ctrlrange="-1.5708 1.5708" class="XM430" />
  </actuator>
  <equality />
  <default>
    <geom type="mesh" solref="0.004 1" />
    <default class="XM430">
      <position forcerange="-3 3" />
    </default>
    <default class="XC430">
      <position forcerange="-2 2" />
    </default>
    <default class="2XC430">
      <position forcerange="-2 2" />
    </default>
    <default class="XL430">
      <position forcerange="-2 2" />
    </default>
    <default class="2XL430">
      <position forcerange="-2 2" />
    </default>
    <default class="XC330">
      <position forcerange="-1 1" />
    </default>
    <default class="visual">
      <geom type="mesh" contype="0" conaffinity="0" group="2" />
    </default>
    <default class="collision">
      <geom group="3" />
    </default>
  </default>
  <contact />
</mujoco>