<mujoco model="sysID_XM430">
  <compiler angle="radian" autolimits="true" />
  <asset>
    <mesh name="xm430_visual" file="../assemblies/sysID_XM430/meshes/xm430_visual.stl" />
    <mesh name="arm_430_visual" file="../assemblies/sysID_XM430/meshes/arm_430_visual.stl" />
  </asset>
  <worldbody>
    <geom rgba="0.647059 0.647059 0.647059 1" mesh="xm430_visual" class="visual" />
    <body name="arm_430" pos="0.093 0.0326999 0.0055694" quat="0.5 -0.5 0.5 -0.5">
      <inertial pos="-0.0700005 0 -0.019" quat="0.707107 0 0 0.707107" mass="0.0945" diaginertia="0.000176057 9.76865e-05 9.75621e-05" />
      <joint name="joint_0" pos="0 0 0" axis="0 0 1" limited="true" range="-1.5708 1.5708" damping="0.352" armature="0.003" frictionloss="0.0" />
      <geom rgba="0.604714 0.667227 0.72422 1" mesh="arm_430_visual" class="visual" />
    </body>
  </worldbody>
  <actuator>
    <position name="joint_0" joint="joint_0" kp="18.75" ctrlrange="-1.5708 1.5708" class="XM430" />
  </actuator>
  <default>
    <default class="XM430">
      <position forcerange="-3 3" />
    </default>
    <default class="XC430">
      <position forcerange="-2 2" />
    </default>
    <default class="2XC430">
      <position forcerange="-2 2" />
    </default>
    <default class="XL430">
      <position forcerange="-2 2" />
    </default>
    <default class="2XL430">
      <position forcerange="-2 2" />
    </default>
    <default class="XC330">
      <position forcerange="-1 1" />
    </default>
    <geom type="mesh" solref=".004 1" />
    <default class="visual">
      <geom contype="0" conaffinity="0" group="2" />
    </default>
    <default class="collision">
      <geom group="3" />
    </default>
  </default>
  <contact />
</mujoco>