<?xml version="1.0" ?><robot name="sysID_XC430">  
  <link name="xc430">    
    <visual>      
      <origin xyz="0 0 0" rpy="0 -0 0"/>      
      <geometry>        
        <mesh filename="package:///meshes/xc430_visual.stl"/>        
      </geometry>      
      <material name="xc430_material">        
        <color rgba="0.44786462886842598463 0.5373344895746794414 0.69800988116095852298 1.0"/>        
      </material>      
    </visual>    
    <collision>      
      <origin xyz="0 0 0" rpy="0 -0 0"/>      
      <geometry>        
        <mesh filename="package:///meshes/xc430_collision.stl"/>        
      </geometry>      
    </collision>    
    <inertial>      
      <origin xyz="0.0709224439626469777 0.016712412139443657416 0.005543011911192575851" rpy="0 0 0"/>      
      <mass value="0.086449999993020207323"/>      
      <inertia ixx="2.7835937895289607013e-05" ixy="-5.7442278246997958779e-06" ixz="-3.9581376465514811914e-08" iyy="2.9061697096171238287e-05" iyz="-5.0973493978072786503e-08" izz="4.3242134177797572506e-05"/>      
    </inertial>    
  </link>  

  <link name="arm_430">    
    <visual>      
      <origin xyz="0 0 0" rpy="0 -0 0"/>      
      <geometry>        
        <mesh filename="package:///meshes/arm_430_visual.stl"/>        
      </geometry>      
      <material name="arm_430_material">        
        <color rgba="0.62999456499017503219 0.65518625360592019913 0.6781537689702749061 1.0"/>        
      </material>      
    </visual>    
    <collision>      
      <origin xyz="0 0 0" rpy="0 -0 0"/>      
      <geometry>        
        <mesh filename="package:///meshes/arm_430_collision.stl"/>        
      </geometry>      
    </collision>    
    <inertial>      
      <origin xyz="-0.072230555077122740593 -1.7460798580073727076e-17 -0.0190000000000000481" rpy="0 0 0"/>      
      <mass value="0.23449999999999993072"/>      
      <inertia ixx="0.00023538980795506243815" ixy="-2.5358048858425616401e-20" ixz="-5.3151317440207346277e-20" iyy="0.00036901840263902106537" iyz="1.4658762773094762347e-16" izz="0.00018448272046932707438"/>      
    </inertial>    
  </link>  

  <joint name="joint_0" type="revolute">    
    <origin xyz="0.054999999999999681088 0.032699857927858962114 0.0055693959459660142761" rpy="1.57079632679489678 -5.5511151231258061214e-17 -1.5707963267948972241"/>    
    <parent link="xc430"/>    
    <child link="arm_430"/>    
    <axis xyz="0 0 1"/>    
    <limit effort="1" velocity="20" lower="-1.570796326794896558" upper="1.570796326794896558"/>    
    <joint_properties friction="0.0"/>    
  </joint>  


</robot>