<?xml version="1.0" ?><robot name="right_arm_gripper">  
  <link name="sho_pitch_link">    
    <visual>      
      <origin xyz="0 0 0" rpy="0 -0 0"/>      
      <geometry>        
        <mesh filename="package:///meshes/right_sho_pitch_link_visual.stl"/>        
      </geometry>      
      <material name="sho_pitch_link_material">        
        <color rgba="0.61568627450980395466 0.81176470588235294379 0.92941176470588227065 1.0"/>        
      </material>      
    </visual>    
    <collision>      
      <origin xyz="0 0 0" rpy="0 -0 0"/>      
      <geometry>        
        <mesh filename="package:///meshes/right_sho_pitch_link_collision.stl"/>        
      </geometry>      
    </collision>    
    <inertial>      
      <origin xyz="5.8254246964215295881e-11 -5.1264642561120952189e-05 0.008244078812709491888" rpy="0 0 0"/>      
      <mass value="0.0085999999999999982708"/>      
      <inertia ixx="1.2272887040545796108e-06" ixy="-2.1429944197535315064e-14" ixz="-8.5847198170025356625e-15" iyy="2.9107306060364620088e-06" iyz="7.4623841398182868942e-09" izz="3.0803135950773491928e-06"/>      
    </inertial>    
  </link>  

  <link name="2xl430_gears">    
    <visual>      
      <origin xyz="0 0 0" rpy="0 -0 0"/>      
      <geometry>        
        <mesh filename="package:///meshes/right_2xl430_gears_visual.stl"/>        
      </geometry>      
      <material name="2xl430_gears_material">        
        <color rgba="0.75605985687944088358 0.8580469596269301169 0.91320266199377464478 1.0"/>        
      </material>      
    </visual>    
    <collision>      
      <origin xyz="0 0 0" rpy="0 -0 0"/>      
      <geometry>        
        <mesh filename="package:///meshes/right_2xl430_gears_collision.stl"/>        
      </geometry>      
    </collision>    
    <inertial>      
      <origin xyz="-0.011593155021923642542 -0.0024238821558115221377 -0.01855109552380418067" rpy="0 0 0"/>      
      <mass value="0.11800003674524907338"/>      
      <inertia ixx="2.7511554932656560375e-05" ixy="8.9994756795124576377e-07" ixz="-2.3362914880511697392e-08" iyy="3.2796647067986007455e-05" iyz="-6.5715261571553837593e-07" izz="3.5775886684226159849e-05"/>      
    </inertial>    
  </link>  

  <link name="spur_1m_24t_drive">    
    <visual>      
      <origin xyz="0 0 0" rpy="0 -0 0"/>      
      <geometry>        
        <mesh filename="package:///meshes/right_spur_1m_24t_drive_visual.stl"/>        
      </geometry>      
      <material name="spur_1m_24t_drive_material">        
        <color rgba="0.61568627450980406568 0.81176470588235294379 0.92941176470588238168 1.0"/>        
      </material>      
    </visual>    
    <collision>      
      <origin xyz="0 0 0" rpy="0 -0 0"/>      
      <geometry>        
        <mesh filename="package:///meshes/right_spur_1m_24t_drive_collision.stl"/>        
      </geometry>      
    </collision>    
    <inertial>      
      <origin xyz="-7.751924474065288114e-15 -1.211430957726248335e-16 0.0047949116178401416863" rpy="0 0 0"/>      
      <mass value="0.0032000000000000001533"/>      
      <inertia ixx="1.4019331346159890349e-07" ixy="1.6002410021513630837e-15" ixz="3.3976222871599421455e-36" iyy="1.4019331260388786185e-07" iyz="-3.6968693489158643946e-37" izz="2.3838919844264060647e-07"/>      
    </inertial>    
  </link>  

  <joint name="right_sho_yaw_drive" type="revolute">    
    <origin xyz="-0.024000000716137899481 -0.019000000152449094543 -0.019000000152446464702" rpy="1.5707963267947575581 -1.6021123593593761996e-14 3.9927856220238265396e-14"/>    
    <parent link="2xl430_gears"/>    
    <child link="spur_1m_24t_drive"/>    
    <axis xyz="0 0 1"/>    
    <limit effort="1" velocity="20" lower="-2.6179938779914944114" upper="2.6179938779914944114"/>    
    <joint_properties friction="0.0"/>    
  </joint>  

  <link name="spur_1m_24t_driven">    
    <visual>      
      <origin xyz="0 0 0" rpy="0 -0 0"/>      
      <geometry>        
        <mesh filename="package:///meshes/right_spur_1m_24t_driven_visual.stl"/>        
      </geometry>      
      <material name="spur_1m_24t_driven_material">        
        <color rgba="0.23137254901960788156 0.38039215686274502337 0.7058823529411765163 1.0"/>        
      </material>      
    </visual>    
    <collision>      
      <origin xyz="0 0 0" rpy="0 -0 0"/>      
      <geometry>        
        <mesh filename="package:///meshes/right_spur_1m_24t_driven_collision.stl"/>        
      </geometry>      
    </collision>    
    <inertial>      
      <origin xyz="2.2397001460351634776e-18 -5.804960647391017135e-15 -0.00097054817521927832808" rpy="0 0 0"/>      
      <mass value="0.0026999999999999997093"/>      
      <inertia ixx="1.2036234079571065709e-07" ixy="-4.8068006864718580788e-37" ixz="-3.7548680678340956839e-36" iyy="1.203623407957104718e-07" iyz="2.7377938088300361412e-37" izz="2.2847261745924535316e-07"/>      
    </inertial>    
  </link>  

  <link name="sho_yaw_link">    
    <visual>      
      <origin xyz="0 0 0" rpy="0 -0 0"/>      
      <geometry>        
        <mesh filename="package:///meshes/right_sho_yaw_link_visual.stl"/>        
      </geometry>      
      <material name="sho_yaw_link_material">        
        <color rgba="0.61568627450980395466 0.81176470588235294379 0.92941176470588238168 1.0"/>        
      </material>      
    </visual>    
    <collision>      
      <origin xyz="0 0 0" rpy="0 -0 0"/>      
      <geometry>        
        <mesh filename="package:///meshes/right_sho_yaw_link_collision.stl"/>        
      </geometry>      
    </collision>    
    <inertial>      
      <origin xyz="-1.2817564279967688722e-18 4.0208771290521817504e-18 -0.024303257848520158635" rpy="0 0 0"/>      
      <mass value="0.014500000000000012879"/>      
      <inertia ixx="9.0846670053041365841e-06" ixy="3.6224092806453171386e-13" ixz="1.4255068536486918059e-34" iyy="5.6910950712097533498e-06" iyz="1.5897088116575402094e-35" izz="4.48196098455489844e-06"/>      
    </inertial>    
  </link>  

  <link name="2xl430_gears_2">    
    <visual>      
      <origin xyz="0 0 0" rpy="0 -0 0"/>      
      <geometry>        
        <mesh filename="package:///meshes/right_2xl430_gears_2_visual.stl"/>        
      </geometry>      
      <material name="2xl430_gears_2_material">        
        <color rgba="0.75605985687944088358 0.8580469596269301169 0.91320266199377464478 1.0"/>        
      </material>      
    </visual>    
    <collision>      
      <origin xyz="0 0 0" rpy="0 -0 0"/>      
      <geometry>        
        <mesh filename="package:///meshes/right_2xl430_gears_2_collision.stl"/>        
      </geometry>      
    </collision>    
    <inertial>      
      <origin xyz="-0.011593155021931275325 -0.002423882155810542019 -0.018551095523808777688" rpy="0 0 0"/>      
      <mass value="0.11800003674524907338"/>      
      <inertia ixx="2.7511554932660216169e-05" ixy="8.9994756794983164226e-07" ixz="-2.336291487988372834e-08" iyy="3.2796647067987294945e-05" iyz="-6.5715261571663126019e-07" izz="3.57758866842291143e-05"/>      
    </inertial>    
  </link>  

  <link name="spur_1m_24t_drive_2">    
    <visual>      
      <origin xyz="0 0 0" rpy="0 -0 0"/>      
      <geometry>        
        <mesh filename="package:///meshes/right_spur_1m_24t_drive_2_visual.stl"/>        
      </geometry>      
      <material name="spur_1m_24t_drive_2_material">        
        <color rgba="0.61568627450980406568 0.81176470588235294379 0.92941176470588238168 1.0"/>        
      </material>      
    </visual>    
    <collision>      
      <origin xyz="0 0 0" rpy="0 -0 0"/>      
      <geometry>        
        <mesh filename="package:///meshes/right_spur_1m_24t_drive_2_collision.stl"/>        
      </geometry>      
    </collision>    
    <inertial>      
      <origin xyz="-7.751924474065288114e-15 -1.2114309579847422764e-16 0.0047949116178401382168" rpy="0 0 0"/>      
      <mass value="0.0032000000000000001533"/>      
      <inertia ixx="1.4019331346159890349e-07" ixy="1.6002410021513630837e-15" ixz="-1.0876898409367052523e-36" iyy="1.4019331260388786185e-07" iyz="2.8326589331473283833e-37" izz="2.3838919844264060647e-07"/>      
    </inertial>    
  </link>  

  <joint name="right_elbow_yaw_drive" type="revolute">    
    <origin xyz="-0.024000000716148744973 -0.01900000015245331686 -0.01900000015245205745" rpy="1.5707963267949269781 1.6255101888762571504e-13 -7.7038633886878518967e-14"/>    
    <parent link="2xl430_gears_2"/>    
    <child link="spur_1m_24t_drive_2"/>    
    <axis xyz="0 0 1"/>    
    <limit effort="1" velocity="20" lower="-2.6179938779914944114" upper="2.6179938779914944114"/>    
    <joint_properties friction="0.0"/>    
  </joint>  

  <link name="spur_1m_24t_driven_2">    
    <visual>      
      <origin xyz="0 0 0" rpy="0 -0 0"/>      
      <geometry>        
        <mesh filename="package:///meshes/right_spur_1m_24t_driven_2_visual.stl"/>        
      </geometry>      
      <material name="spur_1m_24t_driven_2_material">        
        <color rgba="0.23137254901960788156 0.38039215686274502337 0.7058823529411765163 1.0"/>        
      </material>      
    </visual>    
    <collision>      
      <origin xyz="0 0 0" rpy="0 -0 0"/>      
      <geometry>        
        <mesh filename="package:///meshes/right_spur_1m_24t_driven_2_collision.stl"/>        
      </geometry>      
    </collision>    
    <inertial>      
      <origin xyz="5.7091470979890261114e-18 -5.8049606473910155572e-15 -0.00097054817521928168911" rpy="0 0 0"/>      
      <mass value="0.0026999999999999997093"/>      
      <inertia ixx="1.2036234079571065709e-07" ixy="-7.4179684800806379779e-38" ixz="6.4659171650319086526e-37" iyy="1.203623407957104718e-07" iyz="-1.7823790256373093551e-36" izz="2.2847261745924545904e-07"/>      
    </inertial>    
  </link>  

  <link name="elb_yaw_link">    
    <visual>      
      <origin xyz="0 0 0" rpy="0 -0 0"/>      
      <geometry>        
        <mesh filename="package:///meshes/right_elb_yaw_link_visual.stl"/>        
      </geometry>      
      <material name="elb_yaw_link_material">        
        <color rgba="0.61568627450980395466 0.81176470588235294379 0.92941176470588227065 1.0"/>        
      </material>      
    </visual>    
    <collision>      
      <origin xyz="0 0 0" rpy="0 -0 0"/>      
      <geometry>        
        <mesh filename="package:///meshes/right_elb_yaw_link_collision.stl"/>        
      </geometry>      
    </collision>    
    <inertial>      
      <origin xyz="5.3127688027384996195e-08 0.0019833638641961665906 -0.023416643551549952418" rpy="0 0 0"/>      
      <mass value="0.017500000000000001665"/>      
      <inertia ixx="1.4134344903109199776e-05" ixy="1.6945783921921615402e-12" ixz="-1.1286398721829634941e-11" iyy="6.6435900776211365815e-06" iyz="1.0545227077253059697e-06" izz="8.9925290757998976773e-06"/>      
    </inertial>    
  </link>  

  <link name="spur_1m_24t_driven_3">    
    <visual>      
      <origin xyz="0 0 0" rpy="0 -0 0"/>      
      <geometry>        
        <mesh filename="package:///meshes/right_spur_1m_24t_driven_3_visual.stl"/>        
      </geometry>      
      <material name="spur_1m_24t_driven_3_material">        
        <color rgba="0.23137254901960788156 0.38039215686274502337 0.7058823529411765163 1.0"/>        
      </material>      
    </visual>    
    <collision>      
      <origin xyz="0 0 0" rpy="0 -0 0"/>      
      <geometry>        
        <mesh filename="package:///meshes/right_spur_1m_24t_driven_3_collision.stl"/>        
      </geometry>      
    </collision>    
    <inertial>      
      <origin xyz="2.9995275761664531893e-17 -5.8049606473910179238e-15 -0.0025705481752192754774" rpy="0 0 0"/>      
      <mass value="0.0026999999999999997093"/>      
      <inertia ixx="1.2036234079571065709e-07" ixy="-1.3806367110425286735e-36" ixz="9.070298151083200235e-37" iyy="1.203623407957104718e-07" iyz="3.0378272403323605098e-37" izz="2.2847261745924545904e-07"/>      
    </inertial>    
  </link>  

  <link name="2xl430_gears_3">    
    <visual>      
      <origin xyz="0 0 0" rpy="0 -0 0"/>      
      <geometry>        
        <mesh filename="package:///meshes/right_2xl430_gears_3_visual.stl"/>        
      </geometry>      
      <material name="2xl430_gears_3_material">        
        <color rgba="0.75605985687944088358 0.8580469596269301169 0.91320266199377464478 1.0"/>        
      </material>      
    </visual>    
    <collision>      
      <origin xyz="0 0 0" rpy="0 -0 0"/>      
      <geometry>        
        <mesh filename="package:///meshes/right_2xl430_gears_3_collision.stl"/>        
      </geometry>      
    </collision>    
    <inertial>      
      <origin xyz="0.00044890447619669565215 0.011593154663860445394 -0.024576117996643907782" rpy="0 0 0"/>      
      <mass value="0.11800003674524907338"/>      
      <inertia ixx="3.5775886684226132744e-05" ixy="2.3362914880833387932e-08" ixz="6.5715261571618688553e-07" iyy="2.7511554932656353699e-05" iyz="8.9994756795086396367e-07" izz="3.2796647067986874817e-05"/>      
    </inertial>    
  </link>  

  <link name="spur_1m_24t_drive_3">    
    <visual>      
      <origin xyz="0 0 0" rpy="0 -0 0"/>      
      <geometry>        
        <mesh filename="package:///meshes/right_spur_1m_24t_drive_3_visual.stl"/>        
      </geometry>      
      <material name="spur_1m_24t_drive_3_material">        
        <color rgba="0.61568627450980406568 0.81176470588235294379 0.92941176470588238168 1.0"/>        
      </material>      
    </visual>    
    <collision>      
      <origin xyz="0 0 0" rpy="0 -0 0"/>      
      <geometry>        
        <mesh filename="package:///meshes/right_spur_1m_24t_drive_3_collision.stl"/>        
      </geometry>      
    </collision>    
    <inertial>      
      <origin xyz="-7.7241688984496576227e-15 -1.2114309577262443907e-16 0.004794911617840143421" rpy="0 0 0"/>      
      <mass value="0.0032000000000000001533"/>      
      <inertia ixx="1.4019331346159885055e-07" ixy="1.6002410021513630837e-15" ixz="-1.29365709829275547e-36" iyy="1.4019331260388786185e-07" iyz="-1.8076585423776766936e-37" izz="2.3838919844264060647e-07"/>      
    </inertial>    
  </link>  

  <joint name="right_wrist_pitch_drive" type="revolute">    
    <origin xyz="-1.5244753931023469169e-10 0.024000000358074063955 -0.0080000000000028659297" rpy="2.0921450023946095227e-14 5.319128891731015468e-14 -1.5707963267948152897"/>    
    <parent link="2xl430_gears_3"/>    
    <child link="spur_1m_24t_drive_3"/>    
    <axis xyz="0 0 1"/>    
    <limit effort="1" velocity="20" lower="-1.3962634015954635824" upper="1.9198621771937625091"/>    
    <joint_properties friction="0.0"/>    
  </joint>  

  <link name="gripper_connector">    
    <visual>      
      <origin xyz="0 0 0" rpy="0 -0 0"/>      
      <geometry>        
        <mesh filename="package:///meshes/right_gripper_connector_visual.stl"/>        
      </geometry>      
      <material name="gripper_connector_material">        
        <color rgba="0.61568627450980395466 0.81176470588235294379 0.92941176470588227065 1.0"/>        
      </material>      
    </visual>    
    <collision>      
      <origin xyz="0 0 0" rpy="0 -0 0"/>      
      <geometry>        
        <mesh filename="package:///meshes/right_gripper_connector_collision.stl"/>        
      </geometry>      
    </collision>    
    <inertial>      
      <origin xyz="-0.00020216391502726472869 0.024011997737921234736 -0.029290084989921687242" rpy="0 0 0"/>      
      <mass value="0.0099999999999999880651"/>      
      <inertia ixx="5.3138306577478889962e-06" ixy="2.3224171675565346272e-08" ixz="4.7690345371182966176e-08" iyy="3.8402250096486075095e-06" iyz="8.1160112886319393595e-09" izz="2.257315404231779922e-06"/>      
    </inertial>    
  </link>  

  <link name="right_rail_guide">    
    <visual>      
      <origin xyz="0 0 0" rpy="0 -0 0"/>      
      <geometry>        
        <mesh filename="package:///meshes/right_rail_guide_visual.stl"/>        
      </geometry>      
      <material name="right_rail_guide_material">        
        <color rgba="0.6201144836561668372 0.81392203854340150482 0.93009302765147672254 1.0"/>        
      </material>      
    </visual>    
    <collision>      
      <origin xyz="0 0 0" rpy="0 -0 0"/>      
      <geometry>        
        <mesh filename="package:///meshes/right_rail_guide_collision.stl"/>        
      </geometry>      
    </collision>    
    <inertial>      
      <origin xyz="0.010819769137967559167 -0.002111301198521865069 -7.7620928513503963803e-05" rpy="0 0 0"/>      
      <mass value="0.031084136786219580817"/>      
      <inertia ixx="7.843066623607029627e-06" ixy="-2.064451767957414831e-06" ixz="4.0045882799668551793e-06" iyy="2.7294704119451739579e-05" iyz="8.89490755300507747e-07" izz="3.0492488744516627947e-05"/>      
    </inertial>    
  </link>  

  <link name="rail">    
    <visual>      
      <origin xyz="0 0 0" rpy="0 -0 0"/>      
      <geometry>        
        <mesh filename="package:///meshes/right_rail_visual.stl"/>        
      </geometry>      
      <material name="rail_material">        
        <color rgba="0.64705882352941179736 0.64705882352941179736 0.64705882352941179736 1.0"/>        
      </material>      
    </visual>    
    <collision>      
      <origin xyz="0 0 0" rpy="0 -0 0"/>      
      <geometry>        
        <mesh filename="package:///meshes/right_rail_collision.stl"/>        
      </geometry>      
    </collision>    
    <inertial>      
      <origin xyz="0.029554714214719193105 -0.015933051259988690457 -0.010638774525132295434" rpy="0 0 0"/>      
      <mass value="0.017100000000000000616"/>      
      <inertia ixx="3.6591938331681695171e-06" ixy="2.1013138412446668144e-08" ixz="-1.1335092663308587465e-07" iyy="4.7380338190523256316e-06" iyz="3.1225833654311333417e-08" izz="6.0956112819844617947e-06"/>      
    </inertial>    
  </link>  

  <joint name="right_gripper_pinion" type="prismatic">    
    <origin xyz="-0.028872600000000556847 -0.015974999999999992678 -0.00535000000000218634" rpy="3.141592653589793116 1.570796326794896558 0"/>    
    <parent link="right_rail_guide"/>    
    <child link="rail"/>    
    <axis xyz="0 0 1"/>    
    <limit effort="1" velocity="20" lower="-0.025000000000000001388" upper="0"/>    
    <joint_properties friction="0.0"/>    
  </joint>  

  <link name="rail_2">    
    <visual>      
      <origin xyz="0 0 0" rpy="0 -0 0"/>      
      <geometry>        
        <mesh filename="package:///meshes/right_rail_2_visual.stl"/>        
      </geometry>      
      <material name="rail_2_material">        
        <color rgba="0.64705882352941179736 0.64705882352941179736 0.64705882352941179736 1.0"/>        
      </material>      
    </visual>    
    <collision>      
      <origin xyz="0 0 0" rpy="0 -0 0"/>      
      <geometry>        
        <mesh filename="package:///meshes/right_rail_2_collision.stl"/>        
      </geometry>      
    </collision>    
    <inertial>      
      <origin xyz="0.029554714214719193105 -0.015933051259988686987 -0.010638774525132295434" rpy="0 0 0"/>      
      <mass value="0.017100000000000000616"/>      
      <inertia ixx="3.6591938331681695171e-06" ixy="2.1013138412446668144e-08" ixz="-1.1335092663308587465e-07" iyy="4.7380338190523256316e-06" iyz="3.1225833654311333417e-08" izz="6.0956112819844617947e-06"/>      
    </inertial>    
  </link>  

  <joint name="right_gripper_pinion_mirror" type="prismatic">    
    <origin xyz="0.062872599999997391684 0.015974999999999996148 -0.0053500000000021585844" rpy="-5.1375487870838840353e-26 1.5707963267948901187 0"/>    
    <parent link="right_rail_guide"/>    
    <child link="rail_2"/>    
    <axis xyz="0 0 1"/>    
    <limit effort="1" velocity="20" lower="-0.025000000000000001388" upper="0"/>    
    <joint_properties friction="0.0"/>    
  </joint>  

  <link name="xc330">    
    <visual>      
      <origin xyz="0 0 0" rpy="0 -0 0"/>      
      <geometry>        
        <mesh filename="package:///meshes/right_xc330_visual.stl"/>        
      </geometry>      
      <material name="xc330_material">        
        <color rgba="0.66932535752643773641 0.72911795671409962427 0.67547870389434394589 1.0"/>        
      </material>      
    </visual>    
    <collision>      
      <origin xyz="0 0 0" rpy="0 -0 0"/>      
      <geometry>        
        <mesh filename="package:///meshes/right_xc330_collision.stl"/>        
      </geometry>      
    </collision>    
    <inertial>      
      <origin xyz="0.0080045171539636986169 -0.015558009851631672549 -0.011717805512818120842" rpy="0 0 0"/>      
      <mass value="0.026599999993091753836"/>      
      <inertia ixx="3.868341066651400925e-06" ixy="-7.7688424002223831296e-10" ixz="5.7969695832979731151e-10" iyy="2.1626767907494457945e-06" iyz="8.3590274792900736609e-09" izz="3.3158761130056259384e-06"/>      
    </inertial>    
  </link>  

  <link name="spur_gear_(18_teeth)">    
    <visual>      
      <origin xyz="0 0 0" rpy="0 -0 0"/>      
      <geometry>        
        <mesh filename="package:///meshes/right_spur_gear_(18_teeth)_visual.stl"/>        
      </geometry>      
      <material name="spur_gear_(18_teeth)_material">        
        <color rgba="0.9176470588235294823 0.9176470588235294823 0.9176470588235294823 1.0"/>        
      </material>      
    </visual>    
    <collision>      
      <origin xyz="0 0 0" rpy="0 -0 0"/>      
      <geometry>        
        <mesh filename="package:///meshes/right_spur_gear_(18_teeth)_collision.stl"/>        
      </geometry>      
    </collision>    
    <inertial>      
      <origin xyz="5.7245874707234634116e-17 -3.4694469519536141888e-17 -0.0025000000000000078583" rpy="0 0 0"/>      
      <mass value="0.0012999999999999997235"/>      
      <inertia ixx="3.3282842836137718203e-08" ixy="-1.6483175047912543603e-22" ixz="2.0134892040511168155e-37" iyy="3.3282842836137453506e-08" iyz="-1.4284978873565059479e-37" izz="6.1149428795799502273e-08"/>      
    </inertial>    
  </link>  

  <joint name="right_gripper_rack" type="revolute">    
    <origin xyz="0.0079999999999993201549 -0.022499999999994794997 -0.025999999999999606759" rpy="2.4369395390407848563e-14 1.8923581380997412337e-14 3.1415926535897598093"/>    
    <parent link="xc330"/>    
    <child link="spur_gear_(18_teeth)"/>    
    <axis xyz="0 0 1"/>    
    <limit effort="1" velocity="20" lower="0" upper="2.7052603405912107881"/>    
    <joint_properties friction="0.0"/>    
  </joint>  

  <joint name="right_gripper_motor" type="fixed">    
    <origin xyz="-0.0059500000000000108358 -0.022599999999999998562 0.023299999999999959632" rpy="-1.0436096431306391491e-14 4.584660564324367864e-30 -3.141592653589793116"/>    
    <parent link="right_rail_guide"/>    
    <child link="xc330"/>    
    <axis xyz="0 0 1"/>    
    <limit effort="1" velocity="20"/>    
    <joint_properties friction="0.0"/>    
  </joint>  

  <joint name="right_gripper_fixed" type="fixed">    
    <origin xyz="3.4694469519536141888e-18 0.037000000000000032863 -0.0019999999999999983069" rpy="1.570796326794891673 1.570796326794896558 0"/>    
    <parent link="gripper_connector"/>    
    <child link="right_rail_guide"/>    
    <axis xyz="0 0 1"/>    
    <limit effort="1" velocity="20"/>    
    <joint_properties friction="0.0"/>    
  </joint>  

  <joint name="right_wrist_roll" type="revolute">    
    <origin xyz="0.019000000000002639777 -3.5806405063176782733e-10 -0.027000000152454364799" rpy="-3.1415926535897558125 -1.5707963267947788744 0"/>    
    <parent link="2xl430_gears_3"/>    
    <child link="gripper_connector"/>    
    <axis xyz="0 0 1"/>    
    <limit effort="1" velocity="20" lower="-1.3962634015954635824" upper="1.9198621771937625091"/>    
    <joint_properties friction="0.0"/>    
  </joint>  

  <link name="wrist_bearing_plate">    
    <visual>      
      <origin xyz="0 0 0" rpy="0 -0 0"/>      
      <geometry>        
        <mesh filename="package:///meshes/right_wrist_bearing_plate_visual.stl"/>        
      </geometry>      
      <material name="wrist_bearing_plate_material">        
        <color rgba="0.64496316278892629192 0.69011804996940528945 0.71706771073555886087 1.0"/>        
      </material>      
    </visual>    
    <collision>      
      <origin xyz="0 0 0" rpy="0 -0 0"/>      
      <geometry>        
        <mesh filename="package:///meshes/right_wrist_bearing_plate_collision.stl"/>        
      </geometry>      
    </collision>    
    <inertial>      
      <origin xyz="-0.0075835583121500096254 -0.015499999999999982542 -0.0018386323705903342279" rpy="0 0 0"/>      
      <mass value="0.0049000367468305539714"/>      
      <inertia ixx="4.970743010915013972e-07" ixy="6.835022250017547813e-23" ixz="1.8100904820814078261e-08" iyy="7.1268523603538605999e-07" iyz="1.3148545519931043656e-23" izz="1.1919657811600117705e-06"/>      
    </inertial>    
  </link>  

  <joint name="right_wrist_pitch_fixed" type="fixed">    
    <origin xyz="0.01550000000000212666 9.7144514654701197287e-15 -0.045000000000006409873" rpy="1.7541523788970447002e-14 1.2040368702059279945e-13 -1.5707963267947835373"/>    
    <parent link="2xl430_gears_3"/>    
    <child link="wrist_bearing_plate"/>    
    <axis xyz="0 0 1"/>    
    <limit effort="1" velocity="20"/>    
    <joint_properties friction="0.0"/>    
  </joint>  

  <joint name="right_wrist_pitch_driven" type="revolute">    
    <origin xyz="2.7755575615628913511e-17 3.9443045261050590271e-31 -0.0015999999999999966072" rpy="1.3582904646488232485e-14 2.0737500615824777463e-14 1.570796326794896558"/>    
    <parent link="spur_1m_24t_driven_3"/>    
    <child link="2xl430_gears_3"/>    
    <axis xyz="0 0 1"/>    
    <limit effort="1" velocity="20" lower="-1.9198621771937625091" upper="1.3962634015954635824"/>    
    <joint_properties friction="0.0"/>    
  </joint>  

  <joint name="right_wrist_roll_fixed" type="fixed">    
    <origin xyz="1.0846837446788912324e-30 -0.025300000000000006511 -0.051999999999999976796" rpy="1.5707963267948952257 1.5707963267948956698 0"/>    
    <parent link="elb_yaw_link"/>    
    <child link="spur_1m_24t_driven_3"/>    
    <axis xyz="0 0 1"/>    
    <limit effort="1" velocity="20"/>    
    <joint_properties friction="0.0"/>    
  </joint>  

  <joint name="right_elbow_yaw_fixed" type="fixed">    
    <origin xyz="0 6.9025329206838532974e-31 0.0016000000000000041966" rpy="3.1415926535897904515 9.8876398673015319607e-16 -1.5707963267948961139"/>    
    <parent link="spur_1m_24t_driven_2"/>    
    <child link="elb_yaw_link"/>    
    <axis xyz="0 0 1"/>    
    <limit effort="1" velocity="20"/>    
    <joint_properties friction="0.0"/>    
  </joint>  

  <joint name="right_elbow_yaw_driven" type="revolute">    
    <origin xyz="-3.5807057666148445207e-10 -0.027000000152458084046 -0.019000000000001945888" rpy="1.5707963267949378583 3.9751140894689616291e-14 -4.8122446750143955108e-14"/>    
    <parent link="2xl430_gears_2"/>    
    <child link="spur_1m_24t_driven_2"/>    
    <axis xyz="0 0 1"/>    
    <limit effort="1" velocity="20" lower="-2.6179938779914944114" upper="2.6179938779914944114"/>    
    <joint_properties friction="0.0"/>    
  </joint>  

  <joint name="right_elbow_roll" type="revolute">    
    <origin xyz="-6.2450045135165055399e-17 -0.019000000000000055039 -0.058999999999999983014" rpy="1.5707963267948976682 -6.0447453237754791364e-15 3.4446905417540585232e-15"/>    
    <parent link="sho_yaw_link"/>    
    <child link="2xl430_gears_2"/>    
    <axis xyz="0 0 1"/>    
    <limit effort="1" velocity="20" lower="-1.9198621771937625091" upper="2.4434609527920612138"/>    
    <joint_properties friction="0.0"/>    
  </joint>  

  <joint name="right_sho_yaw_fixed" type="fixed">    
    <origin xyz="5.5511151231257827021e-17 -5.5955222556880518216e-17 0.0015999999999998862354" rpy="3.141592653589793116 1.024631402903628403e-29 3.0929606673668622441e-31"/>    
    <parent link="spur_1m_24t_driven"/>    
    <child link="sho_yaw_link"/>    
    <axis xyz="0 0 1"/>    
    <limit effort="1" velocity="20"/>    
    <joint_properties friction="0.0"/>    
  </joint>  

  <joint name="right_sho_yaw_driven" type="revolute">    
    <origin xyz="-3.5806703782559345939e-10 -0.027000000152449448593 -0.018999999999999434008" rpy="1.5707963267947753216 -5.6469601652704289819e-14 2.3773531644080762555e-14"/>    
    <parent link="2xl430_gears"/>    
    <child link="spur_1m_24t_driven"/>    
    <axis xyz="0 0 1"/>    
    <limit effort="1" velocity="20" lower="-2.6179938779914944114" upper="2.6179938779914944114"/>    
    <joint_properties friction="0.0"/>    
  </joint>  

  <joint name="right_sho_roll" type="revolute">    
    <origin xyz="-0.018999999999999912792 0.00099999999999999286508 0.027000000000000079492" rpy="3.141592653589793116 1.5707963267947739894 0"/>    
    <parent link="sho_pitch_link"/>    
    <child link="2xl430_gears"/>    
    <axis xyz="0 0 1"/>    
    <limit effort="1" velocity="20" lower="-1.570796326794896558" upper="0.34906585039886589561"/>    
    <joint_properties friction="0.0"/>    
  </joint>  


</robot>