<?xml version="1.0" ?><robot name="4R_body">  
  <link name="body_link">    
    <visual>      
      <origin xyz="0 0 0" rpy="0 -0 0"/>      
      <geometry>        
        <mesh filename="package:///meshes/body_link_visual.stl"/>        
      </geometry>      
      <material name="body_link_material">        
        <color rgba="0.59240232552230254193 0.77493742445477609149 0.89675162167089739196 1.0"/>        
      </material>      
    </visual>    
    <collision>      
      <origin xyz="0 0 0" rpy="0 -0 0"/>      
      <geometry>        
        <mesh filename="package:///meshes/body_link_collision.stl"/>        
      </geometry>      
    </collision>    
    <inertial>      
      <origin xyz="-0.011392539113329219411 1.8329806416124711958e-07 0.37864501400110928131" rpy="0 0 0"/>      
      <mass value="1.3010345634555096073"/>      
      <inertia ixx="0.0047624725171278572619" ixy="1.2254736467186099066e-09" ixz="2.5710312085007243653e-05" iyy="0.0036676689183223294341" iyz="7.2555792615153116409e-09" izz="0.003205257716390452153"/>      
    </inertial>    
  </link>  

  <link name="neck_link">    
    <visual>      
      <origin xyz="0 0 0" rpy="0 -0 0"/>      
      <geometry>        
        <mesh filename="package:///meshes/neck_link_visual.stl"/>        
      </geometry>      
      <material name="neck_link_material">        
        <color rgba="0.61568627450980395466 0.81176470588235294379 0.92941176470588238168 1.0"/>        
      </material>      
    </visual>    
    <collision>      
      <origin xyz="0 0 0" rpy="0 -0 0"/>      
      <geometry>        
        <mesh filename="package:///meshes/neck_link_collision.stl"/>        
      </geometry>      
    </collision>    
    <inertial>      
      <origin xyz="3.067903593042405049e-19 -5.1123361372111250322e-20 -0.020000000000000000416" rpy="0 0 0"/>      
      <mass value="0.018378317023500286703"/>      
      <inertia ixx="3.4842226023719301187e-06" ixy="2.6492046803872183431e-38" ixz="-4.2946359314041097936e-38" iyy="3.4842226023719301187e-06" iyz="-3.2653968785718786279e-70" izz="2.06756066514378241e-06"/>      
    </inertial>    
  </link>  

  <link name="head_link">    
    <visual>      
      <origin xyz="0 0 0" rpy="0 -0 0"/>      
      <geometry>        
        <mesh filename="package:///meshes/head_link_visual.stl"/>        
      </geometry>      
      <material name="head_link_material">        
        <color rgba="0.79607843137254907795 0.82352941176470584317 0.93725490196078442562 1.0"/>        
      </material>      
    </visual>    
    <collision>      
      <origin xyz="0 0 0" rpy="0 -0 0"/>      
      <geometry>        
        <mesh filename="package:///meshes/head_link_collision.stl"/>        
      </geometry>      
    </collision>    
    <inertial>      
      <origin xyz="0.0011121374382810683603 0.002300308913386693143 -0.012472157860955830275" rpy="0 0 0"/>      
      <mass value="0.075015538754887006734"/>      
      <inertia ixx="6.8018019107715040579e-06" ixy="6.7244456377383520563e-07" ixz="2.3059386910262087019e-09" iyy="4.5222250439264427752e-05" iyz="-1.2119065455131472216e-08" izz="4.5708811148256761484e-05"/>      
    </inertial>    
  </link>  

  <joint name="head" type="fixed">    
    <origin xyz="0 -6.505213034913026604e-19 -0.039999999999999980016" rpy="-3.6199375412562401434e-16 -2.4218742848029192401e-16 -5.5511151231257722251e-17"/>    
    <parent link="neck_link"/>    
    <child link="head_link"/>    
    <axis xyz="0 0 1"/>    
    <limit effort="1" velocity="20"/>    
    <joint_properties friction="0.0"/>    
  </joint>  

  <joint name="neck" type="fixed">    
    <origin xyz="-0.00089999999999998414602 -4.4507968385753129991e-18 0.44079999999999996962" rpy="-3.141592653589793116 8.5053965662326763145e-17 1.57079632679489678"/>    
    <parent link="body_link"/>    
    <child link="neck_link"/>    
    <axis xyz="0 0 1"/>    
    <limit effort="1" velocity="20"/>    
    <joint_properties friction="0.0"/>    
  </joint>  

  <link name="left_3r+rh5_leg">    
    <visual>      
      <origin xyz="0 0 0" rpy="0 -0 0"/>      
      <geometry>        
        <mesh filename="package:///meshes/left_3r+rh5_leg_visual.stl"/>        
      </geometry>      
      <material name="left_3r+rh5_leg_material">        
        <color rgba="0.71718891381070037916 0.7145153391356499073 0.54776150702613102261 1.0"/>        
      </material>      
    </visual>    
    <collision>      
      <origin xyz="0 0 0" rpy="0 -0 0"/>      
      <geometry>        
        <mesh filename="package:///meshes/left_3r+rh5_leg_collision.stl"/>        
      </geometry>      
    </collision>    
    <inertial>      
      <origin xyz="-0.0057949354331666511758 0.0012805658729350311194 -0.12292888404780155653" rpy="0 0 0"/>      
      <mass value="0.33263980481353833119"/>      
      <inertia ixx="0.0020722263032183605054" ixy="-2.4160213398511650298e-06" ixz="-0.00016841678767884915601" iyy="0.0020895101464939946044" iyz="-1.496827777764726835e-05" izz="0.00012793993533713593209"/>      
    </inertial>    
  </link>  

  <joint name="left_hip_yaw" type="revolute">    
    <origin xyz="-0.0064000000000000714304 0.033999999999999967748 0.28550000000000003153" rpy="-2.2204460492518612204e-16 2.2204460492555594989e-16 -1.1840637646123850812e-13"/>    
    <parent link="body_link"/>    
    <child link="left_3r+rh5_leg"/>    
    <axis xyz="0 0 1"/>    
    <limit effort="1" velocity="20" lower="-0.785398163397448279" upper="0.785398163397448279"/>    
    <joint_properties friction="0.0"/>    
  </joint>  

  <link name="right_3r+rh5_leg">    
    <visual>      
      <origin xyz="0 0 0" rpy="0 -0 0"/>      
      <geometry>        
        <mesh filename="package:///meshes/right_3r+rh5_leg_visual.stl"/>        
      </geometry>      
      <material name="right_3r+rh5_leg_material">        
        <color rgba="0.71718890946276314668 0.71451534271328898118 0.54776152214714135535 1.0"/>        
      </material>      
    </visual>    
    <collision>      
      <origin xyz="0 0 0" rpy="0 -0 0"/>      
      <geometry>        
        <mesh filename="package:///meshes/right_3r+rh5_leg_collision.stl"/>        
      </geometry>      
    </collision>    
    <inertial>      
      <origin xyz="-0.0061805519919522966185 -0.0013688630484464121406 -0.12292888475263911985" rpy="0 0 0"/>      
      <mass value="0.33263981813604837079"/>      
      <inertia ixx="0.0020721484552876077469" ixy="3.0759664920856137109e-06" ixz="-0.00015980266136794189715" iyy="0.0020879739869916771021" iyz="1.2495840772183636696e-05" izz="0.00012632601919162841247"/>      
    </inertial>    
  </link>  

  <joint name="right_hip_yaw" type="revolute">    
    <origin xyz="-0.0064000000000002613826 -0.033999999999999974687 0.28549999999999997602" rpy="-2.2204460492504235214e-16 2.2204460492504629644e-16 1.4018091897720291992e-15"/>    
    <parent link="body_link"/>    
    <child link="right_3r+rh5_leg"/>    
    <axis xyz="0 0 1"/>    
    <limit effort="1" velocity="20" lower="-0.785398163397448279" upper="0.785398163397448279"/>    
    <joint_properties friction="0.0"/>    
  </joint>  

  <link name="left_op3_arm">    
    <visual>      
      <origin xyz="0 0 0" rpy="0 -0 0"/>      
      <geometry>        
        <mesh filename="package:///meshes/left_op3_arm_visual.stl"/>        
      </geometry>      
      <material name="left_op3_arm_material">        
        <color rgba="0.43679090525622338292 0.55632699296835241842 0.73866672762452756373 1.0"/>        
      </material>      
    </visual>    
    <collision>      
      <origin xyz="0 0 0" rpy="0 -0 0"/>      
      <geometry>        
        <mesh filename="package:///meshes/left_op3_arm_collision.stl"/>        
      </geometry>      
    </collision>    
    <inertial>      
      <origin xyz="-0.00020428504385901121712 0.0084974083799592651373 -0.077500874070941985772" rpy="0 0 0"/>      
      <mass value="0.15851190405198536948"/>      
      <inertia ixx="0.00031790513312416251784" ixy="1.6282384685203494143e-08" ixz="1.7003539351512554503e-07" iyy="0.00032542543411612402529" iyz="-2.1568541493911628421e-06" izz="3.1121013419237742175e-05"/>      
    </inertial>    
  </link>  

  <joint name="left_sho_pitch" type="revolute">    
    <origin xyz="-0.00090000000000018190449 0.058000000000000113964 0.42079999999999984084" rpy="-1.570796326794871911 3.5360603334311235812e-14 -3.1415926535897371608"/>    
    <parent link="body_link"/>    
    <child link="left_op3_arm"/>    
    <axis xyz="0 0 1"/>    
    <limit effort="1" velocity="20" lower="-1.570796326794896558" upper="1.570796326794896558"/>    
    <joint_properties friction="0.0"/>    
  </joint>  

  <link name="right_op3_arm">    
    <visual>      
      <origin xyz="0 0 0" rpy="0 -0 0"/>      
      <geometry>        
        <mesh filename="package:///meshes/right_op3_arm_visual.stl"/>        
      </geometry>      
      <material name="right_op3_arm_material">        
        <color rgba="0.4367909052562232719 0.55632699296835219638 0.73866672762452734169 1.0"/>        
      </material>      
    </visual>    
    <collision>      
      <origin xyz="0 0 0" rpy="0 -0 0"/>      
      <geometry>        
        <mesh filename="package:///meshes/right_op3_arm_collision.stl"/>        
      </geometry>      
    </collision>    
    <inertial>      
      <origin xyz="0.0002042847840719565016 0.0084974123651775437804 -0.077500874070941902505" rpy="0 0 0"/>      
      <mass value="0.15851190405198542499"/>      
      <inertia ixx="0.00031790513375913511535" ixy="-1.6266918505923425318e-08" ixz="-1.7003398641181844695e-07" iyy="0.00032542543413294493411" iyz="-2.2241497042743640359e-06" izz="3.11210140710387837e-05"/>      
    </inertial>    
  </link>  

  <joint name="right_sho_pitch" type="revolute">    
    <origin xyz="-0.00090000000000000062589 -0.057999999999999982125 0.42079999999999995186" rpy="-1.5707963267948972241 1.3877787807856806753e-15 6.3545304591998415249e-17"/>    
    <parent link="body_link"/>    
    <child link="right_op3_arm"/>    
    <axis xyz="0 0 1"/>    
    <limit effort="1" velocity="20" lower="-1.570796326794896558" upper="1.570796326794896558"/>    
    <joint_properties friction="0.0"/>    
  </joint>  


</robot>