<?xml version="1.0" ?><robot name="4R_body">  
  <link name="body_link">    
    <visual>      
      <origin xyz="0 0 0" rpy="0 -0 0"/>      
      <geometry>        
        <mesh filename="package:///meshes/body_link_visual.stl"/>        
      </geometry>      
      <material name="body_link_material">        
        <color rgba="0.59240232552230254193 0.77493742445477598046 0.89675162167089728094 1.0"/>        
      </material>      
    </visual>    
    <collision>      
      <origin xyz="0 0 0" rpy="0 -0 0"/>      
      <geometry>        
        <mesh filename="package:///meshes/body_link_collision.stl"/>        
      </geometry>      
    </collision>    
    <inertial>      
      <origin xyz="-0.011392539113329219411 1.8329806415983037757e-07 0.37864501400110933682" rpy="0 0 0"/>      
      <mass value="1.3010345634555100514"/>      
      <inertia ixx="0.004762472517127859864" ixy="1.2254736467186099066e-09" ixz="2.5710312085007240265e-05" iyy="0.0036676689183223290004" iyz="7.2555792614915947183e-09" izz="0.0032052577163904517193"/>      
    </inertial>    
  </link>  

  <link name="neck_link">    
    <visual>      
      <origin xyz="0 0 0" rpy="0 -0 0"/>      
      <geometry>        
        <mesh filename="package:///meshes/neck_link_visual.stl"/>        
      </geometry>      
      <material name="neck_link_material">        
        <color rgba="0.61568627450980395466 0.81176470588235294379 0.92941176470588238168 1.0"/>        
      </material>      
    </visual>    
    <collision>      
      <origin xyz="0 0 0" rpy="0 -0 0"/>      
      <geometry>        
        <mesh filename="package:///meshes/neck_link_collision.stl"/>        
      </geometry>      
    </collision>    
    <inertial>      
      <origin xyz="3.067903593042405049e-19 -5.1123361372111250322e-20 -0.020000000000000000416" rpy="0 0 0"/>      
      <mass value="0.018378317023500286703"/>      
      <inertia ixx="3.4842226023719301187e-06" ixy="2.6492046803872183431e-38" ixz="-4.2946359314041097936e-38" iyy="3.4842226023719301187e-06" iyz="-3.2653968785718786279e-70" izz="2.06756066514378241e-06"/>      
    </inertial>    
  </link>  

  <link name="head_link">    
    <visual>      
      <origin xyz="0 0 0" rpy="0 -0 0"/>      
      <geometry>        
        <mesh filename="package:///meshes/head_link_visual.stl"/>        
      </geometry>      
      <material name="head_link_material">        
        <color rgba="0.79607843137254896693 0.82352941176470584317 0.93725490196078442562 1.0"/>        
      </material>      
    </visual>    
    <collision>      
      <origin xyz="0 0 0" rpy="0 -0 0"/>      
      <geometry>        
        <mesh filename="package:///meshes/head_link_collision.stl"/>        
      </geometry>      
    </collision>    
    <inertial>      
      <origin xyz="0.0011121374382810690108 0.0023003089133866896736 -0.012472157860955830275" rpy="0 0 0"/>      
      <mass value="0.075015538754886992856"/>      
      <inertia ixx="6.8018019107715040579e-06" ixy="6.7244456377383520563e-07" ixz="2.3059386910262827346e-09" iyy="4.5222250439264427752e-05" iyz="-1.2119065455131516884e-08" izz="4.5708811148256761484e-05"/>      
    </inertial>    
  </link>  

  <joint name="head" type="fixed">    
    <origin xyz="0 -6.505213034913026604e-19 -0.039999999999999980016" rpy="-3.6199375412562401434e-16 -2.4218742848029192401e-16 -5.5511151231257722251e-17"/>    
    <parent link="neck_link"/>    
    <child link="head_link"/>    
    <axis xyz="0 0 1"/>    
    <limit effort="1" velocity="20"/>    
    <joint_properties friction="0.0"/>    
  </joint>  

  <joint name="neck" type="fixed">    
    <origin xyz="-0.00089999999999998414602 -4.4507968385753129991e-18 0.44079999999999996962" rpy="-3.141592653589793116 8.5053965662326763145e-17 1.57079632679489678"/>    
    <parent link="body_link"/>    
    <child link="neck_link"/>    
    <axis xyz="0 0 1"/>    
    <limit effort="1" velocity="20"/>    
    <joint_properties friction="0.0"/>    
  </joint>  

  <link name="left_3r+rh5_leg">    
    <visual>      
      <origin xyz="0 0 0" rpy="0 -0 0"/>      
      <geometry>        
        <mesh filename="package:///meshes/left_3r+rh5_leg_visual.stl"/>        
      </geometry>      
      <material name="left_3r+rh5_leg_material">        
        <color rgba="0.71712717993919605775 0.71457448616025487365 0.54799362657198125159 1.0"/>        
      </material>      
    </visual>    
    <collision>      
      <origin xyz="0 0 0" rpy="0 -0 0"/>      
      <geometry>        
        <mesh filename="package:///meshes/left_3r+rh5_leg_collision.stl"/>        
      </geometry>      
    </collision>    
    <inertial>      
      <origin xyz="-0.0058058945689643641497 0.0012819461612545224923 -0.12293655421554991469" rpy="0 0 0"/>      
      <mass value="0.33284223931512424421"/>      
      <inertia ixx="0.0020723404158643214841" ixy="-2.5006724028867826048e-06" ixz="-0.00016838020890165854206" iyy="0.0020895913239501293264" iyz="-1.4913270975287094475e-05" izz="0.00012793227628371946171"/>      
    </inertial>    
  </link>  

  <joint name="left_hip_yaw" type="revolute">    
    <origin xyz="-0.006400000000000070563 0.033999999999999967748 0.28550000000000003153" rpy="-1.0062408617649953783e-14 -1.7373496713084857328e-15 -1.0702550091647256269e-13"/>    
    <parent link="body_link"/>    
    <child link="left_3r+rh5_leg"/>    
    <axis xyz="0 0 1"/>    
    <limit effort="1" velocity="20" lower="-1.570796326794896558" upper="1.570796326794896558"/>    
    <joint_properties friction="0.0"/>    
  </joint>  

  <link name="right_3r+rh5_leg">    
    <visual>      
      <origin xyz="0 0 0" rpy="0 -0 0"/>      
      <geometry>        
        <mesh filename="package:///meshes/right_3r+rh5_leg_visual.stl"/>        
      </geometry>      
      <material name="right_3r+rh5_leg_material">        
        <color rgba="0.71712718175007705845 0.71457448383750632459 0.54799361853656014532 1.0"/>        
      </material>      
    </visual>    
    <collision>      
      <origin xyz="0 0 0" rpy="0 -0 0"/>      
      <geometry>        
        <mesh filename="package:///meshes/right_3r+rh5_leg_collision.stl"/>        
      </geometry>      
    </collision>    
    <inertial>      
      <origin xyz="-0.0061633136198055403498 -0.0013701892908356114089 -0.12293655515520661436" rpy="0 0 0"/>      
      <mass value="0.33284223244644678408"/>      
      <inertia ixx="0.0020722624883763550441" ixy="2.9935021834292540521e-06" ixz="-0.00015980824900195924124" iyy="0.002088167369264168436" iyz="1.2441059842190334235e-05" izz="0.00012643048500212105941"/>      
    </inertial>    
  </link>  

  <joint name="right_hip_yaw" type="revolute">    
    <origin xyz="-0.0064000000000002613826 -0.033999999999999974687 0.28549999999999997602" rpy="-2.4175737836120826254e-16 2.1811947592303793928e-16 -1.3443908046660001512e-14"/>    
    <parent link="body_link"/>    
    <child link="right_3r+rh5_leg"/>    
    <axis xyz="0 0 1"/>    
    <limit effort="1" velocity="20" lower="-1.570796326794896558" upper="1.570796326794896558"/>    
    <joint_properties friction="0.0"/>    
  </joint>  

  <link name="left_op3_arm">    
    <visual>      
      <origin xyz="0 0 0" rpy="0 -0 0"/>      
      <geometry>        
        <mesh filename="package:///meshes/left_op3_arm_visual.stl"/>        
      </geometry>      
      <material name="left_op3_arm_material">        
        <color rgba="0.43679090525622349395 0.55632699296835252945 0.73866672762452778578 1.0"/>        
      </material>      
    </visual>    
    <collision>      
      <origin xyz="0 0 0" rpy="0 -0 0"/>      
      <geometry>        
        <mesh filename="package:///meshes/left_op3_arm_collision.stl"/>        
      </geometry>      
    </collision>    
    <inertial>      
      <origin xyz="-0.00020428504385901186764 0.0084974083799592651373 -0.07750087407094199965" rpy="0 0 0"/>      
      <mass value="0.15851190405198534172"/>      
      <inertia ixx="0.00031790513312416246363" ixy="1.6282384685203375029e-08" ixz="1.7003539351512639206e-07" iyy="0.00032542543411612391687" iyz="-2.1568541493911607245e-06" izz="3.1121013419237748951e-05"/>      
    </inertial>    
  </link>  

  <joint name="left_sho_pitch" type="revolute">    
    <origin xyz="-0.00090000000000018190449 0.058000000000000113964 0.42079999999999984084" rpy="-1.570796326794871911 3.5360603334311235812e-14 -3.1415926535897371608"/>    
    <parent link="body_link"/>    
    <child link="left_op3_arm"/>    
    <axis xyz="0 0 1"/>    
    <limit effort="1" velocity="20" lower="-1.570796326794896558" upper="1.570796326794896558"/>    
    <joint_properties friction="0.0"/>    
  </joint>  

  <link name="right_op3_arm">    
    <visual>      
      <origin xyz="0 0 0" rpy="0 -0 0"/>      
      <geometry>        
        <mesh filename="package:///meshes/right_op3_arm_visual.stl"/>        
      </geometry>      
      <material name="right_op3_arm_material">        
        <color rgba="0.4367909052562232719 0.55632699296835219638 0.73866672762452734169 1.0"/>        
      </material>      
    </visual>    
    <collision>      
      <origin xyz="0 0 0" rpy="0 -0 0"/>      
      <geometry>        
        <mesh filename="package:///meshes/right_op3_arm_collision.stl"/>        
      </geometry>      
    </collision>    
    <inertial>      
      <origin xyz="0.0002042847840719570708 0.0084974123651775437804 -0.077500874070941902505" rpy="0 0 0"/>      
      <mass value="0.15851190405198542499"/>      
      <inertia ixx="0.00031790513375913511535" ixy="-1.6266918505923392231e-08" ixz="-1.70033986411818844e-07" iyy="0.0003254254341329448799" iyz="-2.2241497042743636124e-06" izz="3.1121014071038790476e-05"/>      
    </inertial>    
  </link>  

  <joint name="right_sho_pitch" type="revolute">    
    <origin xyz="-0.00090000000000000062589 -0.057999999999999982125 0.42079999999999995186" rpy="-1.5707963267948972241 1.3877787807856806753e-15 6.3545304591998415249e-17"/>    
    <parent link="body_link"/>    
    <child link="right_op3_arm"/>    
    <axis xyz="0 0 1"/>    
    <limit effort="1" velocity="20" lower="-1.570796326794896558" upper="1.570796326794896558"/>    
    <joint_properties friction="0.0"/>    
  </joint>  


</robot>