<?xml version="1.0" ?><robot name="4R_body">  
  <link name="base_link"/>  
  <joint name="base_link_to_base" type="fixed">    
    <parent link="base_link"/>    
    <child link="body_link"/>    
    <origin rpy="0.0 0 0" xyz="0 0 0"/>    
  </joint>  
  <link name="body_link">    
    <visual>      
      <origin xyz="0 0 0" rpy="0 -0 0"/>      
      <geometry>        
        <mesh filename="package:///meshes/body_link_visual.stl"/>        
      </geometry>      
      <material name="body_link_material">        
        <color rgba="0.55996023298811625768 0.73378146029516932991 0.87169628976554447419 1.0"/>        
      </material>      
    </visual>    
    <collision>      
      <origin xyz="0 0 0" rpy="0 -0 0"/>      
      <geometry>        
        <mesh filename="package:///meshes/body_link_collision.stl"/>        
      </geometry>      
    </collision>    
    <inertial>      
      <origin xyz="-0.015921871165220459476 3.0739283045681201247e-07 0.38102616953748202899" rpy="0 0 0"/>      
      <mass value="0.67608257475273103587"/>      
      <inertia ixx="0.0031022286229082205074" ixy="-4.7652709113595442803e-09" ixz="6.3573332153048944153e-05" iyy="0.0024203844758186893876" iyz="8.1740734972655720511e-10" izz="0.0017849397724631682269"/>      
    </inertial>    
  </link>  

  <link name="neck_link">    
    <visual>      
      <origin xyz="0 0 0" rpy="0 -0 0"/>      
      <geometry>        
        <mesh filename="package:///meshes/neck_link_visual.stl"/>        
      </geometry>      
      <material name="neck_link_material">        
        <color rgba="0.61568627450980395466 0.81176470588235294379 0.92941176470588238168 1.0"/>        
      </material>      
    </visual>    
    <collision>      
      <origin xyz="0 0 0" rpy="0 -0 0"/>      
      <geometry>        
        <mesh filename="package:///meshes/neck_link_collision.stl"/>        
      </geometry>      
    </collision>    
    <inertial>      
      <origin xyz="3.067903593042405049e-19 -5.1123361372111250322e-20 -0.020000000000000000416" rpy="0 0 0"/>      
      <mass value="0.017530087007031042168"/>      
      <inertia ixx="3.3234123284163027768e-06" ixy="-1.0338857654327673847e-106" ixz="0" iyy="3.3234123284163027768e-06" iyz="0" izz="1.9721347882909923679e-06"/>      
    </inertial>    
  </link>  

  <link name="head_link">    
    <visual>      
      <origin xyz="0 0 0" rpy="0 -0 0"/>      
      <geometry>        
        <mesh filename="package:///meshes/head_link_visual.stl"/>        
      </geometry>      
      <material name="head_link_material">        
        <color rgba="0.79607843137254896693 0.82352941176470584317 0.93725490196078442562 1.0"/>        
      </material>      
    </visual>    
    <collision>      
      <origin xyz="0 0 0" rpy="0 -0 0"/>      
      <geometry>        
        <mesh filename="package:///meshes/head_link_collision.stl"/>        
      </geometry>      
    </collision>    
    <inertial>      
      <origin xyz="0.0011121374382810679266 0.0023003089133866896736 -0.012472157860955830275" rpy="0 0 0"/>      
      <mass value="0.075015538754886992856"/>      
      <inertia ixx="6.8018019107715040579e-06" ixy="6.7244456377383520563e-07" ixz="2.3059386910262455114e-09" iyy="4.5222250439264427752e-05" iyz="-1.2119065455131493722e-08" izz="4.5708811148256761484e-05"/>      
    </inertial>    
  </link>  

  <joint name="head" type="fixed">    
    <origin xyz="0 8.6736173798840354721e-19 -0.039999999999999980016" rpy="0 -1.0509729472670562853e-99 -4.1486002514987779604e-69"/>    
    <parent link="neck_link"/>    
    <child link="head_link"/>    
    <axis xyz="0 0 1"/>    
    <limit effort="1" velocity="20"/>    
    <joint_properties friction="0.0"/>    
  </joint>  

  <joint name="neck" type="fixed">    
    <origin xyz="-0.0063999999999999925004 -7.4035645855646046943e-18 0.44990000000000002212" rpy="-3.141592653589793116 2.5403140807248779693e-85 1.570796326794896558"/>    
    <parent link="body_link"/>    
    <child link="neck_link"/>    
    <axis xyz="0 0 1"/>    
    <limit effort="1" velocity="20"/>    
    <joint_properties friction="0.0"/>    
  </joint>  

  <link name="left_3r+rh5_leg">    
    <visual>      
      <origin xyz="0 0 0" rpy="0 -0 0"/>      
      <geometry>        
        <mesh filename="package:///meshes/left_3r+rh5_leg_visual.stl"/>        
      </geometry>      
      <material name="left_3r+rh5_leg_material">        
        <color rgba="0.72627467525282640715 0.71260494176763444774 0.53290000167478146498 1.0"/>        
      </material>      
    </visual>    
    <collision>      
      <origin xyz="0 0 0" rpy="0 -0 0"/>      
      <geometry>        
        <mesh filename="package:///meshes/left_3r+rh5_leg_collision.stl"/>        
      </geometry>      
    </collision>    
    <inertial>      
      <origin xyz="0.010946649733723525649 -0.0030169602527998738706 -0.13165264429371414945" rpy="0 0 0"/>      
      <mass value="0.3199783344694824283"/>      
      <inertia ixx="0.0021620048167114258413" ixy="2.22307729498773714e-07" ixz="0.00025465922356352323295" iyy="0.0022249617284479101913" iyz="-2.3208519914293467099e-05" izz="0.00015772039955936958673"/>      
    </inertial>    
  </link>  

  <joint name="left_hip_yaw" type="revolute">    
    <origin xyz="-0.0064000000000000063782 0.034999999999999989453 0.29849999999999998757" rpy="3.2485353740361531821e-29 -6.1232339957386420457e-17 3.1415926535897265026"/>    
    <parent link="body_link"/>    
    <child link="left_3r+rh5_leg"/>    
    <axis xyz="0 0 1"/>    
    <limit effort="1" velocity="20" lower="-1.570796326794896558" upper="1.570796326794896558"/>    
    <joint_properties friction="0.0"/>    
  </joint>  

  <link name="right_3r+rh5_leg">    
    <visual>      
      <origin xyz="0 0 0" rpy="0 -0 0"/>      
      <geometry>        
        <mesh filename="package:///meshes/right_3r+rh5_leg_visual.stl"/>        
      </geometry>      
      <material name="right_3r+rh5_leg_material">        
        <color rgba="0.72627467545840551644 0.71260494158330056624 0.53290000093768263856 1.0"/>        
      </material>      
    </visual>    
    <collision>      
      <origin xyz="0 0 0" rpy="0 -0 0"/>      
      <geometry>        
        <mesh filename="package:///meshes/right_3r+rh5_leg_collision.stl"/>        
      </geometry>      
    </collision>    
    <inertial>      
      <origin xyz="0.010574861262559361041 0.0031310788441783793563 -0.13165302797936576096" rpy="0 0 0"/>      
      <mass value="0.31997833387465624"/>      
      <inertia ixx="0.0021620114344515157026" ixy="-1.5565555797502680755e-07" ixz="0.00026390790259678747814" iyy="0.0022275419836603597458" iyz="2.6264662037550822675e-05" izz="0.00016026731146034475426"/>      
    </inertial>    
  </link>  

  <joint name="right_hip_yaw" type="revolute">    
    <origin xyz="-0.0064000000000000063782 -0.035000000000000003331 0.29849999999999998757" rpy="2.7148356055467616192e-15 4.7934048230446615859e-16 3.1415926535897602534"/>    
    <parent link="body_link"/>    
    <child link="right_3r+rh5_leg"/>    
    <axis xyz="0 0 1"/>    
    <limit effort="1" velocity="20" lower="-1.570796326794896558" upper="1.570796326794896558"/>    
    <joint_properties friction="0.0"/>    
  </joint>  

  <link name="left_op3_arm">    
    <visual>      
      <origin xyz="0 0 0" rpy="0 -0 0"/>      
      <geometry>        
        <mesh filename="package:///meshes/left_op3_arm_visual.stl"/>        
      </geometry>      
      <material name="left_op3_arm_material">        
        <color rgba="0.43523473395306988554 0.55451173083354099447 0.73762059152478276491 1.0"/>        
      </material>      
    </visual>    
    <collision>      
      <origin xyz="0 0 0" rpy="0 -0 0"/>      
      <geometry>        
        <mesh filename="package:///meshes/left_op3_arm_collision.stl"/>        
      </geometry>      
    </collision>    
    <inertial>      
      <origin xyz="-0.00020870187266119704077 0.0085165979821906247216 -0.077300388864323499316" rpy="0 0 0"/>      
      <mass value="0.1571979940418067323"/>      
      <inertia ixx="0.00031144888768403394862" ixy="1.5866524066531853438e-08" ixz="1.6569417508438020539e-07" iyy="0.00031881972937998232648" iyz="-2.0709890631882568646e-06" izz="3.0672546414051314796e-05"/>      
    </inertial>    
  </link>  

  <joint name="left_sho_pitch" type="revolute">    
    <origin xyz="-0.0064000000000001572992 0.060499999999999103106 0.42989999999999989333" rpy="-1.5707963267948708008 3.5465916442993729594e-14 -3.1415926535897371608"/>    
    <parent link="body_link"/>    
    <child link="left_op3_arm"/>    
    <axis xyz="0 0 1"/>    
    <limit effort="1" velocity="20" lower="-1.570796326794896558" upper="1.570796326794896558"/>    
    <joint_properties friction="0.0"/>    
  </joint>  

  <link name="right_op3_arm">    
    <visual>      
      <origin xyz="0 0 0" rpy="0 -0 0"/>      
      <geometry>        
        <mesh filename="package:///meshes/right_op3_arm_visual.stl"/>        
      </geometry>      
      <material name="right_op3_arm_material">        
        <color rgba="0.43523473395306977451 0.55451173083354088345 0.73762059152478265389 1.0"/>        
      </material>      
    </visual>    
    <collision>      
      <origin xyz="0 0 0" rpy="0 -0 0"/>      
      <geometry>        
        <mesh filename="package:///meshes/right_op3_arm_collision.stl"/>        
      </geometry>      
    </collision>    
    <inertial>      
      <origin xyz="0.00020870162279267500879 0.0085166018152483986825 -0.077300388864323263394" rpy="0 0 0"/>      
      <mass value="0.15719799404180676006"/>      
      <inertia ixx="0.00031144888826657490854" ixy="-1.5851769803179352734e-08" ixz="-1.6569284080204546777e-07" iyy="0.00031881972939637399965" iyz="-2.1382841643537578816e-06" izz="3.0672547012990940989e-05"/>      
    </inertial>    
  </link>  

  <joint name="right_sho_pitch" type="revolute">    
    <origin xyz="-0.0064000000000000063782 -0.06050000000000008149 0.42989999999999994884" rpy="-1.570796326794896336 6.9606380272961593273e-16 1.3836137928249486855e-31"/>    
    <parent link="body_link"/>    
    <child link="right_op3_arm"/>    
    <axis xyz="0 0 1"/>    
    <limit effort="1" velocity="20" lower="-1.570796326794896558" upper="1.570796326794896558"/>    
    <joint_properties friction="0.0"/>    
  </joint>  


</robot>