<?xml version="1.0" ?><robot name="4R_body">  
  <link name="base_link"/>  
  <joint name="base_link_to_base" type="fixed">    
    <parent link="base_link"/>    
    <child link="body_link"/>    
    <origin rpy="0.0 0 0" xyz="0 0 0"/>    
  </joint>  
  <link name="body_link">    
    <visual>      
      <origin xyz="0 0 0" rpy="0 -0 0"/>      
      <geometry>        
        <mesh filename="package:///meshes/body_link_visual.stl"/>        
      </geometry>      
      <material name="body_link_material">        
        <color rgba="0.5924023255223024309 0.77493742445477598046 0.89675162167089705889 1.0"/>        
      </material>      
    </visual>    
    <collision>      
      <origin xyz="0 0 0" rpy="0 -0 0"/>      
      <geometry>        
        <mesh filename="package:///meshes/body_link_collision.stl"/>        
      </geometry>      
    </collision>    
    <inertial>      
      <origin xyz="-0.016892539113329191336 1.8329806416258032297e-07 0.37034501400110925173" rpy="0 0 0"/>      
      <mass value="1.3010345634555104954"/>      
      <inertia ixx="0.0047624725171278572619" ixy="1.225473646717127599e-09" ixz="2.5710312085007236876e-05" iyy="0.003667668918322326832" iyz="7.2555792615186997727e-09" izz="0.003205257716390450852"/>      
    </inertial>    
  </link>  

  <link name="neck_link">    
    <visual>      
      <origin xyz="0 0 0" rpy="0 -0 0"/>      
      <geometry>        
        <mesh filename="package:///meshes/neck_link_visual.stl"/>        
      </geometry>      
      <material name="neck_link_material">        
        <color rgba="0.61568627450980395466 0.81176470588235294379 0.92941176470588238168 1.0"/>        
      </material>      
    </visual>    
    <collision>      
      <origin xyz="0 0 0" rpy="0 -0 0"/>      
      <geometry>        
        <mesh filename="package:///meshes/neck_link_collision.stl"/>        
      </geometry>      
    </collision>    
    <inertial>      
      <origin xyz="3.067903593042405049e-19 -5.1123361372111250322e-20 -0.020000000000000000416" rpy="0 0 0"/>      
      <mass value="0.018378317023500286703"/>      
      <inertia ixx="3.4842226023719301187e-06" ixy="2.6492046803872183431e-38" ixz="-4.2946359314041097936e-38" iyy="3.4842226023719301187e-06" iyz="-3.2653968785718786279e-70" izz="2.06756066514378241e-06"/>      
    </inertial>    
  </link>  

  <link name="head_link">    
    <visual>      
      <origin xyz="0 0 0" rpy="0 -0 0"/>      
      <geometry>        
        <mesh filename="package:///meshes/head_link_visual.stl"/>        
      </geometry>      
      <material name="head_link_material">        
        <color rgba="0.79607843137254907795 0.82352941176470584317 0.93725490196078442562 1.0"/>        
      </material>      
    </visual>    
    <collision>      
      <origin xyz="0 0 0" rpy="0 -0 0"/>      
      <geometry>        
        <mesh filename="package:///meshes/head_link_collision.stl"/>        
      </geometry>      
    </collision>    
    <inertial>      
      <origin xyz="0.0011121374382810683603 0.002300308913386693143 -0.012472157860955830275" rpy="0 0 0"/>      
      <mass value="0.075015538754887006734"/>      
      <inertia ixx="6.8018019107715040579e-06" ixy="6.7244456377383520563e-07" ixz="2.3059386910262087019e-09" iyy="4.5222250439264427752e-05" iyz="-1.2119065455131472216e-08" izz="4.5708811148256761484e-05"/>      
    </inertial>    
  </link>  

  <joint name="head" type="fixed">    
    <origin xyz="-4.1826855620466421722e-19 -2.6020852139652106416e-18 -0.039999999999999980016" rpy="-3.6199375412562401434e-16 -2.4218742848029192401e-16 -5.5511151231257722251e-17"/>    
    <parent link="neck_link"/>    
    <child link="head_link"/>    
    <axis xyz="0 0 1"/>    
    <limit effort="1" velocity="20"/>    
    <joint_properties friction="0.0"/>    
  </joint>  

  <joint name="neck" type="fixed">    
    <origin xyz="-0.0063999999999999838268 -5.2372852656669075105e-18 0.43249999999999999556" rpy="-3.141592653589793116 8.5053965662326763145e-17 1.57079632679489678"/>    
    <parent link="body_link"/>    
    <child link="neck_link"/>    
    <axis xyz="0 0 1"/>    
    <limit effort="1" velocity="20"/>    
    <joint_properties friction="0.0"/>    
  </joint>  

  <link name="left_3r+rh5_leg">    
    <visual>      
      <origin xyz="0 0 0" rpy="0 -0 0"/>      
      <geometry>        
        <mesh filename="package:///meshes/left_3r+rh5_leg_visual.stl"/>        
      </geometry>      
      <material name="left_3r+rh5_leg_material">        
        <color rgba="0.7171271799475166242 0.71457448616022800625 0.54799362655478534023 1.0"/>        
      </material>      
    </visual>    
    <collision>      
      <origin xyz="0 0 0" rpy="0 -0 0"/>      
      <geometry>        
        <mesh filename="package:///meshes/left_3r+rh5_leg_collision.stl"/>        
      </geometry>      
    </collision>    
    <inertial>      
      <origin xyz="-0.0058058945690210505761 0.0012819461613717780899 -0.1229365542183281923" rpy="0 0 0"/>      
      <mass value="0.33284223932564410697"/>      
      <inertia ixx="0.002072340415949308623" ixy="-2.5006724026681892356e-06" ixz="-0.00016838020890331192327" iyy="0.0020895913240315368634" iyz="-1.4913270971738864989e-05" izz="0.00012793227628743334204"/>      
    </inertial>    
  </link>  

  <joint name="left_hip_yaw" type="revolute">    
    <origin xyz="-0.011900000000000070244 0.033999999999999974687 0.27720000000000011298" rpy="-2.2204460494577687078e-16 2.2204460491536837829e-16 -1.0069344447037764778e-13"/>    
    <parent link="body_link"/>    
    <child link="left_3r+rh5_leg"/>    
    <axis xyz="0 0 1"/>    
    <limit effort="1" velocity="20" lower="-1.570796326794896558" upper="1.570796326794896558"/>    
    <joint_properties friction="0.0"/>    
  </joint>  

  <link name="right_3r+rh5_leg">    
    <visual>      
      <origin xyz="0 0 0" rpy="0 -0 0"/>      
      <geometry>        
        <mesh filename="package:///meshes/right_3r+rh5_leg_visual.stl"/>        
      </geometry>      
      <material name="right_3r+rh5_leg_material">        
        <color rgba="0.71712718175839773593 0.71457448383747956822 0.54799361851936401191 1.0"/>        
      </material>      
    </visual>    
    <collision>      
      <origin xyz="0 0 0" rpy="0 -0 0"/>      
      <geometry>        
        <mesh filename="package:///meshes/right_3r+rh5_leg_collision.stl"/>        
      </geometry>      
    </collision>    
    <inertial>      
      <origin xyz="-0.0061633136198482188842 -0.0013701892906334306888 -0.12293655515798564137" rpy="0 0 0"/>      
      <mass value="0.33284223245696664684"/>      
      <inertia ixx="0.0020722624884616522647" ixy="2.993502183672930608e-06" ixz="-0.00015980824900316650036" iyy="0.0020881673693455633962" iyz="1.2441059848202831592e-05" izz="0.00012643048500608186678"/>      
    </inertial>    
  </link>  

  <joint name="right_hip_yaw" type="revolute">    
    <origin xyz="-0.011900000000000259329 -0.033999999999999981626 0.27720000000000000195" rpy="-2.2204460717259335277e-16 2.2204461793479381443e-16 -6.6849266279598662255e-15"/>    
    <parent link="body_link"/>    
    <child link="right_3r+rh5_leg"/>    
    <axis xyz="0 0 1"/>    
    <limit effort="1" velocity="20" lower="-1.570796326794896558" upper="1.570796326794896558"/>    
    <joint_properties friction="0.0"/>    
  </joint>  

  <link name="left_op3_arm">    
    <visual>      
      <origin xyz="0 0 0" rpy="0 -0 0"/>      
      <geometry>        
        <mesh filename="package:///meshes/left_op3_arm_visual.stl"/>        
      </geometry>      
      <material name="left_op3_arm_material">        
        <color rgba="0.43679090525622338292 0.55632699296835241842 0.73866672762452756373 1.0"/>        
      </material>      
    </visual>    
    <collision>      
      <origin xyz="0 0 0" rpy="0 -0 0"/>      
      <geometry>        
        <mesh filename="package:///meshes/left_op3_arm_collision.stl"/>        
      </geometry>      
    </collision>    
    <inertial>      
      <origin xyz="-0.00020428504385891849073 0.0084974083799593830985 -0.077500874070942013527" rpy="0 0 0"/>      
      <mass value="0.15851190405198536948"/>      
      <inertia ixx="0.00031790513312416240942" ixy="1.6282384685201555232e-08" ixz="1.7003539351515688525e-07" iyy="0.00032542543411612386266" iyz="-2.1568541493910739036e-06" izz="3.1121013419237755727e-05"/>      
    </inertial>    
  </link>  

  <joint name="left_sho_pitch" type="revolute">    
    <origin xyz="-0.0064000000000001278089 0.057999999999999600486 0.41249999999999986677" rpy="-1.570796326794871911 3.5360603334311235812e-14 -3.1415926535897371608"/>    
    <parent link="body_link"/>    
    <child link="left_op3_arm"/>    
    <axis xyz="0 0 1"/>    
    <limit effort="1" velocity="20" lower="-1.570796326794896558" upper="1.570796326794896558"/>    
    <joint_properties friction="0.0"/>    
  </joint>  

  <link name="right_op3_arm">    
    <visual>      
      <origin xyz="0 0 0" rpy="0 -0 0"/>      
      <geometry>        
        <mesh filename="package:///meshes/right_op3_arm_visual.stl"/>        
      </geometry>      
      <material name="right_op3_arm_material">        
        <color rgba="0.4367909052562232719 0.55632699296835219638 0.73866672762452734169 1.0"/>        
      </material>      
    </visual>    
    <collision>      
      <origin xyz="0 0 0" rpy="0 -0 0"/>      
      <geometry>        
        <mesh filename="package:///meshes/right_op3_arm_collision.stl"/>        
      </geometry>      
    </collision>    
    <inertial>      
      <origin xyz="0.00020428478407195433319 0.008497412365177571536 -0.077500874070941902505" rpy="0 0 0"/>      
      <mass value="0.15851190405198542499"/>      
      <inertia ixx="0.00031790513375913500693" ixy="-1.6266918505923094446e-08" ixz="-1.7003398641181908223e-07" iyy="0.00032542543413294482569" iyz="-2.2241497042744703386e-06" izz="3.11210140710387837e-05"/>      
    </inertial>    
  </link>  

  <joint name="right_sho_pitch" type="revolute">    
    <origin xyz="-0.0063999999999999916331 -0.057999999999999989064 0.4124999999999999778" rpy="-1.5707963267948972241 1.3877787807856806753e-15 6.3545304591998415249e-17"/>    
    <parent link="body_link"/>    
    <child link="right_op3_arm"/>    
    <axis xyz="0 0 1"/>    
    <limit effort="1" velocity="20" lower="-1.570796326794896558" upper="1.570796326794896558"/>    
    <joint_properties friction="0.0"/>    
  </joint>  


</robot>