<?xml version="1.0" ?><robot name="4R_body">  
  <link name="base_link"/>  
  <joint name="base_link_to_base" type="fixed">    
    <parent link="base_link"/>    
    <child link="body_link"/>    
    <origin rpy="0.0 0 0" xyz="0 0 0"/>    
  </joint>  
  <link name="body_link">    
    <visual>      
      <origin xyz="0 0 0" rpy="0 -0 0"/>      
      <geometry>        
        <mesh filename="package:///meshes/body_link_visual.stl"/>        
      </geometry>      
      <material name="body_link_material">        
        <color rgba="0.5599602329881163687 0.73378146029516944093 0.87169628976554425215 1.0"/>        
      </material>      
    </visual>    
    <collision>      
      <origin xyz="0 0 0" rpy="0 -0 0"/>      
      <geometry>        
        <mesh filename="package:///meshes/body_link_collision.stl"/>        
      </geometry>      
    </collision>    
    <inertial>      
      <origin xyz="-0.015921871165220462946 3.0739283047348972063e-07 0.38112616953748185145" rpy="0 0 0"/>      
      <mass value="0.67608257475273170201"/>      
      <inertia ixx="0.0031022286229082192063" ixy="-4.7652709113387919731e-09" ixz="6.3573332153048917048e-05" iyy="0.002420384475818691556" iyz="8.1740734978754357731e-10" izz="0.0017849397724631669258"/>      
    </inertial>    
  </link>  

  <link name="neck_link">    
    <visual>      
      <origin xyz="0 0 0" rpy="0 -0 0"/>      
      <geometry>        
        <mesh filename="package:///meshes/neck_link_visual.stl"/>        
      </geometry>      
      <material name="neck_link_material">        
        <color rgba="0.61568627450980395466 0.81176470588235294379 0.92941176470588238168 1.0"/>        
      </material>      
    </visual>    
    <collision>      
      <origin xyz="0 0 0" rpy="0 -0 0"/>      
      <geometry>        
        <mesh filename="package:///meshes/neck_link_collision.stl"/>        
      </geometry>      
    </collision>    
    <inertial>      
      <origin xyz="3.067903593042405049e-19 -5.1123361372111057729e-20 -0.020000000000000000416" rpy="0 0 0"/>      
      <mass value="0.017530087007031042168"/>      
      <inertia ixx="3.3234123284163032003e-06" ixy="-1.0338857654327673847e-106" ixz="0" iyy="3.3234123284163027768e-06" iyz="0" izz="1.9721347882909923679e-06"/>      
    </inertial>    
  </link>  

  <link name="head_link">    
    <visual>      
      <origin xyz="0 0 0" rpy="0 -0 0"/>      
      <geometry>        
        <mesh filename="package:///meshes/head_link_visual.stl"/>        
      </geometry>      
      <material name="head_link_material">        
        <color rgba="0.79607843137254896693 0.82352941176470584317 0.93725490196078442562 1.0"/>        
      </material>      
    </visual>    
    <collision>      
      <origin xyz="0 0 0" rpy="0 -0 0"/>      
      <geometry>        
        <mesh filename="package:///meshes/head_link_collision.stl"/>        
      </geometry>      
    </collision>    
    <inertial>      
      <origin xyz="0.0011121374382810677098 0.0023003089133866896736 -0.012472157860955830275" rpy="0 0 0"/>      
      <mass value="0.075015538754886992856"/>      
      <inertia ixx="6.8018019107715040579e-06" ixy="6.7244456377383499387e-07" ixz="2.305938691026195467e-09" iyy="4.5222250439264427752e-05" iyz="-1.2119065455131485451e-08" izz="4.5708811148256761484e-05"/>      
    </inertial>    
  </link>  

  <joint name="head" type="fixed">    
    <origin xyz="0 8.6736173798840354721e-19 -0.039999999999999980016" rpy="0 -1.0509729472670562853e-99 -4.1486002514987779604e-69"/>    
    <parent link="neck_link"/>    
    <child link="head_link"/>    
    <axis xyz="0 0 1"/>    
    <limit effort="1" velocity="20"/>    
    <joint_properties friction="0.0"/>    
  </joint>  

  <joint name="neck" type="fixed">    
    <origin xyz="-0.0063999999999999925004 -7.4035645855646046943e-18 0.4500000000000000111" rpy="-3.141592653589793116 2.5403140807248779693e-85 1.570796326794896558"/>    
    <parent link="body_link"/>    
    <child link="neck_link"/>    
    <axis xyz="0 0 1"/>    
    <limit effort="1" velocity="20"/>    
    <joint_properties friction="0.0"/>    
  </joint>  

  <link name="left_3r+rh5_leg">    
    <visual>      
      <origin xyz="0 0 0" rpy="0 -0 0"/>      
      <geometry>        
        <mesh filename="package:///meshes/left_3r+rh5_leg_visual.stl"/>        
      </geometry>      
      <material name="left_3r+rh5_leg_material">        
        <color rgba="0.72627467525282651817 0.71260494176763444774 0.53290000167478146498 1.0"/>        
      </material>      
    </visual>    
    <collision>      
      <origin xyz="0 0 0" rpy="0 -0 0"/>      
      <geometry>        
        <mesh filename="package:///meshes/left_3r+rh5_leg_collision.stl"/>        
      </geometry>      
    </collision>    
    <inertial>      
      <origin xyz="0.01094664973371831454 -0.0030169602527908728241 -0.13165264429371340005" rpy="0 0 0"/>      
      <mass value="0.3199783344694824283"/>      
      <inertia ixx="0.0021620048167113521155" ixy="2.2230772947951472587e-07" ixz="0.00025465922356342565475" iyy="0.0022249617284478234551" iyz="-2.3208519914077067122e-05" izz="0.00015772039955934296957"/>      
    </inertial>    
  </link>  

  <joint name="left_hip_yaw" type="revolute">    
    <origin xyz="-0.0064000000000000055109 0.034999999999999982514 0.29859999999999997655" rpy="2.5294987785272742576e-29 -6.1232339957503159545e-17 3.1415926535897900074"/>    
    <parent link="body_link"/>    
    <child link="left_3r+rh5_leg"/>    
    <axis xyz="0 0 1"/>    
    <limit effort="1" velocity="20" lower="-1.570796326794896558" upper="1.570796326794896558"/>    
    <joint_properties friction="0.0"/>    
  </joint>  

  <link name="right_3r+rh5_leg">    
    <visual>      
      <origin xyz="0 0 0" rpy="0 -0 0"/>      
      <geometry>        
        <mesh filename="package:///meshes/right_3r+rh5_leg_visual.stl"/>        
      </geometry>      
      <material name="right_3r+rh5_leg_material">        
        <color rgba="0.72627467545840551644 0.71260494158330045522 0.53290000093768263856 1.0"/>        
      </material>      
    </visual>    
    <collision>      
      <origin xyz="0 0 0" rpy="0 -0 0"/>      
      <geometry>        
        <mesh filename="package:///meshes/right_3r+rh5_leg_collision.stl"/>        
      </geometry>      
    </collision>    
    <inertial>      
      <origin xyz="0.01087870825337156587 0.0034348696165698751337 -0.13165302797936612178" rpy="0 0 0"/>      
      <mass value="0.31997833387465629551"/>      
      <inertia ixx="0.0021613731824519730879" ixy="1.2062419211943558528e-06" ixz="0.00025486592924638340691" iyy="0.002225456169987340832" iyz="1.7389919802971502515e-05" izz="0.00015754324578742413799"/>      
    </inertial>    
  </link>  

  <joint name="right_hip_yaw" type="revolute">    
    <origin xyz="-0.0064000000000000063782 -0.034999999999999996392 0.29859999999999997655" rpy="-4.0795765885139752246e-16 -1.4246408104590497614e-16 -3.1415926535897877869"/>    
    <parent link="body_link"/>    
    <child link="right_3r+rh5_leg"/>    
    <axis xyz="0 0 1"/>    
    <limit effort="1" velocity="20" lower="-1.570796326794896558" upper="1.570796326794896558"/>    
    <joint_properties friction="0.0"/>    
  </joint>  

  <link name="left_op3_arm">    
    <visual>      
      <origin xyz="0 0 0" rpy="0 -0 0"/>      
      <geometry>        
        <mesh filename="package:///meshes/left_op3_arm_visual.stl"/>        
      </geometry>      
      <material name="left_op3_arm_material">        
        <color rgba="0.43523473395306988554 0.55451173083354088345 0.73762059152478276491 1.0"/>        
      </material>      
    </visual>    
    <collision>      
      <origin xyz="0 0 0" rpy="0 -0 0"/>      
      <geometry>        
        <mesh filename="package:///meshes/left_op3_arm_collision.stl"/>        
      </geometry>      
    </collision>    
    <inertial>      
      <origin xyz="-0.00020870187266119733893 0.0085165979821906247216 -0.077300388864323457683" rpy="0 0 0"/>      
      <mass value="0.1571979940418067323"/>      
      <inertia ixx="0.00031144888768403367757" ixy="1.5866524066531985787e-08" ixz="1.6569417508437933189e-07" iyy="0.00031881972937998200122" iyz="-2.0709890631882577117e-06" izz="3.0672546414051321572e-05"/>      
    </inertial>    
  </link>  

  <joint name="left_sho_pitch" type="revolute">    
    <origin xyz="-0.0064000000000001572992 0.060499999999999110045 0.42999999999999988232" rpy="-1.5707963267948708008 3.5465916442993729594e-14 -3.1415926535897371608"/>    
    <parent link="body_link"/>    
    <child link="left_op3_arm"/>    
    <axis xyz="0 0 1"/>    
    <limit effort="1" velocity="20" lower="-1.570796326794896558" upper="1.570796326794896558"/>    
    <joint_properties friction="0.0"/>    
  </joint>  

  <link name="right_op3_arm">    
    <visual>      
      <origin xyz="0 0 0" rpy="0 -0 0"/>      
      <geometry>        
        <mesh filename="package:///meshes/right_op3_arm_visual.stl"/>        
      </geometry>      
      <material name="right_op3_arm_material">        
        <color rgba="0.43523473395306977451 0.55451173083354088345 0.73762059152478265389 1.0"/>        
      </material>      
    </visual>    
    <collision>      
      <origin xyz="0 0 0" rpy="0 -0 0"/>      
      <geometry>        
        <mesh filename="package:///meshes/right_op3_arm_collision.stl"/>        
      </geometry>      
    </collision>    
    <inertial>      
      <origin xyz="0.00020870162279267546958 0.0085166018152483986825 -0.077300388864323263394" rpy="0 0 0"/>      
      <mass value="0.15719799404180676006"/>      
      <inertia ixx="0.00031144888826657485432" ixy="-1.5851769803179399056e-08" ixz="-1.6569284080204345607e-07" iyy="0.00031881972939637389123" iyz="-2.1382841643537604227e-06" izz="3.0672547012990934213e-05"/>      
    </inertial>    
  </link>  

  <joint name="right_sho_pitch" type="revolute">    
    <origin xyz="-0.0064000000000000063782 -0.06050000000000008149 0.42999999999999993783" rpy="-1.570796326794896336 6.9606380272961593273e-16 1.3836137928249486855e-31"/>    
    <parent link="body_link"/>    
    <child link="right_op3_arm"/>    
    <axis xyz="0 0 1"/>    
    <limit effort="1" velocity="20" lower="-1.570796326794896558" upper="1.570796326794896558"/>    
    <joint_properties friction="0.0"/>    
  </joint>  


</robot>