<?xml version="1.0" ?>
<robot name="toddlerbot_2xm">
  <mujoco>
    <compiler strippath="false" balanceinertia="true" discardvisual="false"/>
  </mujoco>
  <link name="torso">
    <visual>
      <origin xyz="0 0 0" rpy="0 -0 0"/>
      <geometry>
        <mesh filename="../assemblies/toddlerbot_2xm/meshes/torso_visual.stl"/>
      </geometry>
      <material name="torso_material">
        <color rgba="0.58430211183841918032 0.75033614665161918467 0.87206890730692354641 1.0"/>
      </material>
    </visual>
    <collision name="torso_collision">
      <origin xyz="-0.02850000374019146 -5.000084638595581e-05 0.07071307324804366" rpy="0 0 0"/>
      <geometry>
        <box size="0.14100000634789467 0.13759998977184296 0.14554688287898898"/>
      </geometry>
    </collision>
    <inertial>
      <origin xyz="-0.0089771536282007430296 0.0025954798665039067497 0.069461396698008895378" rpy="0 0 0"/>
      <mass value="0.76506596310120122961"/>
      <inertia ixx="0.0024739587695634499172" ixy="-3.13158365810029389e-05" ixz="-5.2926440215534802406e-05" iyy="0.0019649143544098156278" iyz="6.5538214354498366011e-05" izz="0.0018703366390322023749"/>
    </inertial>
  </link>
  <link name="spur_1m_20t">
    <visual>
      <origin xyz="0 0 0" rpy="0 -0 0"/>
      <geometry>
        <mesh filename="../assemblies/toddlerbot_2xm/meshes/spur_1m_20t_visual.stl"/>
      </geometry>
      <material name="spur_1m_20t_material">
        <color rgba="0.64705882352941179736 0.64705882352941179736 0.64705882352941179736 1.0"/>
      </material>
    </visual>
    <inertial>
      <origin xyz="-3.9958123139678099615e-19 -8.3531856098436992621e-18 0.003384232105434467619" rpy="0 0 0"/>
      <mass value="0.0015778025963745997712"/>
      <inertia ixx="4.5874424196602078292e-08" ixy="3.1019108513555356752e-24" ixz="-7.1097175513400442172e-39" iyy="4.5874424196602058439e-08" iyz="7.8419015231486113446e-38" izz="8.1737050837173876176e-08"/>
    </inertial>
  </link>
  <joint name="neck_yaw_drive" type="revolute">
    <origin xyz="-0.0049999999999995221878 3.1860588521011854095e-18 0.12148651076281755112" rpy="1.1607298201443905188e-14 1.6509758832059179101e-15 -5.3832337592600790636e-15"/>
    <parent link="torso"/>
    <child link="spur_1m_20t"/>
    <axis xyz="0 0 1"/>
    <limit effort="1" velocity="20" lower="-2.8797932657906435416" upper="2.8797932657906435416"/>
    <joint_properties friction="0.0"/>
  </joint>
  <link name="neck_yaw_link_v2">
    <visual>
      <origin xyz="0 0 0" rpy="0 -0 0"/>
      <geometry>
        <mesh filename="../assemblies/toddlerbot_2xm/meshes/neck_yaw_link_v2_visual.stl"/>
      </geometry>
      <material name="neck_yaw_link_v2_material">
        <color rgba="0.2313725490196078538 0.38039215686274513439 0.7058823529411765163 1.0"/>
      </material>
    </visual>
    <inertial>
      <origin xyz="-1.1403990894995030566e-06 -1.1841855613142649787e-10 0.0082571849701004434302" rpy="0 0 0"/>
      <mass value="0.0067298837334394071702"/>
      <inertia ixx="5.2266067624765407703e-07" ixy="-6.3046400790024473369e-15" ixz="1.1949403084472483455e-09" iyy="6.121851997955396235e-07" iyz="-2.6012808712432690235e-15" izz="2.8062851709981659854e-07"/>
    </inertial>
  </link>
  <link name="head">
    <visual>
      <origin xyz="0 0 0" rpy="0 -0 0"/>
      <geometry>
        <mesh filename="../assemblies/toddlerbot_2xm/meshes/head_visual.stl"/>
      </geometry>
      <material name="head_material">
        <color rgba="0.62873939703496795062 0.7936429130509347063 0.87330110949792505437 1.0"/>
      </material>
    </visual>
    <inertial>
      <origin xyz="-0.045316002313821109049 -0.011276855645191815464 -0.0010251236602533209466" rpy="0 0 0"/>
      <mass value="0.13722101760550831084"/>
      <inertia ixx="0.00011880807294044645305" ixy="1.1390016804756297269e-06" ixz="1.8378816154938832318e-06" iyy="0.00010489076115432944571" iyz="-9.2536559812163028915e-06" izz="9.1894624061611060711e-05"/>
    </inertial>
  </link>
  <link name="motor_plate">
    <visual>
      <origin xyz="0 0 0" rpy="0 -0 0"/>
      <geometry>
        <mesh filename="../assemblies/toddlerbot_2xm/meshes/motor_plate_visual.stl"/>
      </geometry>
      <material name="motor_plate_material">
        <color rgba="0.64705882352941179736 0.64705882352941179736 0.64705882352941179736 1.0"/>
      </material>
    </visual>
    <inertial>
      <origin xyz="-1.3877787807814456755e-17 1.0408340855860841026e-17 -0.0028281768943845485807" rpy="0 0 0"/>
      <mass value="0.0016999999999999996884"/>
      <inertia ixx="4.805029073310371698e-08" ixy="1.0773753257370470989e-09" ixz="2.5688599579652610276e-36" iyy="5.1782428339099010347e-08" iyz="-7.2816377740330205339e-37" izz="9.2194729037862196389e-08"/>
    </inertial>
  </link>
  <link name="bearing_683">
    <visual>
      <origin xyz="0 0 0" rpy="0 -0 0"/>
      <geometry>
        <mesh filename="../assemblies/toddlerbot_2xm/meshes/bearing_683_visual.stl"/>
      </geometry>
      <material name="bearing_683_material">
        <color rgba="0.64705882352941179736 0.64705882352941179736 0.64705882352941179736 1.0"/>
      </material>
    </visual>
    <inertial>
      <origin xyz="-1.377046686486211029e-17 2.4186774283164342887e-19 -0.0015499999999999999455" rpy="0 0 0"/>
      <mass value="0.00048694686130641793437"/>
      <inertia ixx="2.1551456503319879113e-09" ixy="2.5851915512476533313e-25" ixz="-6.9415003913512529706e-38" iyy="2.1551456503319883249e-09" iyz="2.0853062969768179496e-37" izz="3.5303647444715305817e-09"/>
    </inertial>
  </link>
  <joint name="neck_pitch_front_rev_2" type="revolute">
    <origin xyz="-0.0019411428382688222793 -0.0072444436971680035986 -0.0054999999999999805989" rpy="-5.1957590769503590071e-16 7.0973975406608356491e-16 0.90975198639595111771"/>
    <parent link="motor_plate"/>
    <child link="bearing_683"/>
    <axis xyz="0 0 1"/>
    <limit effort="1" velocity="20" lower="-6.283185307179586232" upper="6.283185307179586232"/>
    <joint_properties friction="0.0"/>
  </joint>
  <link name="bearing_683_2">
    <visual>
      <origin xyz="0 0 0" rpy="0 -0 0"/>
      <geometry>
        <mesh filename="../assemblies/toddlerbot_2xm/meshes/bearing_683_2_visual.stl"/>
      </geometry>
      <material name="bearing_683_2_material">
        <color rgba="0.64705882352941179736 0.64705882352941179736 0.64705882352941179736 1.0"/>
      </material>
    </visual>
    <inertial>
      <origin xyz="1.0732094295237626889e-19 2.4186774283160216582e-19 -0.0015499999999999995118" rpy="0 0 0"/>
      <mass value="0.00048694686130641793437"/>
      <inertia ixx="2.1551456503319887385e-09" ixy="1.8251488745200396765e-26" ixz="-1.5490026867967484146e-39" iyy="2.1551456503319883249e-09" iyz="3.6026043115100660851e-40" izz="3.5303647444715322361e-09"/>
    </inertial>
  </link>
  <joint name="neck_pitch_back_rev_2" type="revolute">
    <origin xyz="0.0019411428382689610572 0.0072444436971680226806 -0.005499999999999985803" rpy="-1.8767779702219551721e-13 -1.1288623462566221499e-13 0.91260750869648277206"/>
    <parent link="motor_plate"/>
    <child link="bearing_683_2"/>
    <axis xyz="0 0 1"/>
    <limit effort="1" velocity="20" lower="-6.283185307179586232" upper="6.283185307179586232"/>
    <joint_properties friction="0.0"/>
  </joint>
  <joint name="neck_pitch_act" type="revolute">
    <origin xyz="-0.032615697718561015295 -0.026999999999999690914 0.0024999999999997845126" rpy="-3.1415926535897686911 -2.172400990893164017e-13 -3.1097313972849995878"/>
    <parent link="head"/>
    <child link="motor_plate"/>
    <axis xyz="0 0 1"/>
    <limit effort="1" velocity="20" lower="-1.3962634015954635824" upper="0.61086523819801530344"/>
    <joint_properties friction="0.0"/>
  </joint>
  <joint name="neck_pitch" type="revolute">
    <origin xyz="5.2041704279304212832e-17 0.0039999999999999775319 0.0194000000000001116" rpy="-1.5707963267949143216 1.5425174793626117431 -3.141592653589773132"/>
    <parent link="neck_yaw_link_v2"/>
    <child link="head"/>
    <axis xyz="0 0 1"/>
    <limit effort="1" velocity="20" lower="-1.3962634015954635824" upper="0.61086523819801530344"/>
    <joint_properties friction="0.0"/>
  </joint>
  <link name="neck_rod">
    <visual>
      <origin xyz="0 0 0" rpy="0 -0 0"/>
      <geometry>
        <mesh filename="../assemblies/toddlerbot_2xm/meshes/neck_rod_visual.stl"/>
      </geometry>
      <material name="neck_rod_material">
        <color rgba="0.62051618944235198416 0.78640765248647581664 0.88594253031295022716 1.0"/>
      </material>
    </visual>
    <inertial>
      <origin xyz="0.017901071965598931712 4.2302323074261959665e-05 -0.0016023848482647042382" rpy="0 0 0"/>
      <mass value="0.0031629468613064179276"/>
      <inertia ixx="1.6183187611802097473e-08" ixy="-4.3584354036308681235e-10" ixz="5.3972444229564912739e-10" iyy="7.9343818053891974154e-07" iyz="1.2754318721146128966e-12" izz="8.0487503406250116168e-07"/>
    </inertial>
  </link>
  <joint name="neck_pitch_front_rev_1" type="revolute">
    <origin xyz="-0.0072444436971680417625 -0.0040000000000000599312 0.017458857161731150542" rpy="1.5707963267945426189 -0.90616957752344262644 -3.1415926535894937999"/>
    <parent link="neck_yaw_link_v2"/>
    <child link="neck_rod"/>
    <axis xyz="0 0 1"/>
    <limit effort="1" velocity="20" lower="-6.283185307179586232" upper="6.283185307179586232"/>
    <joint_properties friction="0.0"/>
  </joint>
  <link name="neck_rod_2">
    <visual>
      <origin xyz="0 0 0" rpy="0 -0 0"/>
      <geometry>
        <mesh filename="../assemblies/toddlerbot_2xm/meshes/neck_rod_2_visual.stl"/>
      </geometry>
      <material name="neck_rod_2_material">
        <color rgba="0.62051618944235198416 0.78640765248647581664 0.88594253031295022716 1.0"/>
      </material>
    </visual>
    <inertial>
      <origin xyz="0.017942953356015384908 -4.2302323074262413675e-05 -0.0016023848482718246276" rpy="0 0 0"/>
      <mass value="0.0031629468613064179276"/>
      <inertia ixx="1.6183187611802580547e-08" ixy="4.3686324094345629304e-10" ixz="5.4098718295409539865e-10" iyy="7.9430220338142222792e-07" iyz="-1.2754318724161339624e-12" izz="8.0573905690500205987e-07"/>
    </inertial>
  </link>
  <joint name="neck_pitch_back_rev_1" type="revolute">
    <origin xyz="0.0072444436971680417625 -0.0040000000000000339104 0.021341142838269072657" rpy="1.5707963267948958919 -0.9090250998239748359 3.1415926535897904515"/>
    <parent link="neck_yaw_link_v2"/>
    <child link="neck_rod_2"/>
    <axis xyz="0 0 1"/>
    <limit effort="1" velocity="20" lower="-6.283185307179586232" upper="6.283185307179586232"/>
    <joint_properties friction="0.0"/>
  </joint>
  <joint name="neck_yaw_driven" type="revolute">
    <origin xyz="0.016000000000000624834 3.2103613134323069307e-17 0.12248651076281735772" rpy="-1.2490009034196296056e-15 7.5678714822898148914e-15 -8.6007558735577479982e-16"/>
    <parent link="torso"/>
    <child link="neck_yaw_link_v2"/>
    <axis xyz="0 0 1"/>
    <limit effort="1" velocity="20" lower="-2.6179938779914944114" upper="2.6179938779914944114"/>
    <joint_properties friction="0.0"/>
  </joint>
  <link name="waist_gears">
    <visual>
      <origin xyz="0 0 0" rpy="0 -0 0"/>
      <geometry>
        <mesh filename="../assemblies/toddlerbot_2xm/meshes/waist_gears_visual.stl"/>
      </geometry>
      <material name="waist_gears_material">
        <color rgba="0.29673072126509869584 0.50090014891145351328 0.633160425035579566 1.0"/>
      </material>
    </visual>
    <inertial>
      <origin xyz="-2.9089024311039519452e-07 5.5035553748503828604e-08 -0.012592985430860507978" rpy="0 0 0"/>
      <mass value="0.026337180140419177987"/>
      <inertia ixx="1.5367047941033410526e-06" ixy="1.8828487082747051516e-11" ixz="4.0600521957525664523e-10" iyy="7.3024712275450647349e-06" iyz="3.2911737857335293121e-12" izz="6.9859065635059603986e-06"/>
    </inertial>
  </link>
  <link name="pelvis_link">
    <visual>
      <origin xyz="0 0 0" rpy="0 -0 0"/>
      <geometry>
        <mesh filename="../assemblies/toddlerbot_2xm/meshes/pelvis_link_visual.stl"/>
      </geometry>
      <material name="pelvis_link_material">
        <color rgba="0.64205964988973107666 0.7711287811580390672 0.80455743168009175026 1.0"/>
      </material>
    </visual>
    <collision name="pelvis_link_collision">
      <origin xyz="0.0 -0.02584999892860651 -0.022750000469386578" rpy="0 0 0"/>
      <geometry>
        <box size="0.11999999731779099 0.06549999676644802 0.07000000216066837"/>
      </geometry>
    </collision>
    <inertial>
      <origin xyz="-6.1578321615923423822e-17 -0.026032561888413158213 -0.02319724977571635538" rpy="0 0 0"/>
      <mass value="0.10819999998618366754"/>
      <inertia ixx="4.7071238246534341499e-05" ixy="-9.0595715818951526549e-20" ixz="-5.6250773233159001356e-09" iyy="9.6814924554186260262e-05" iyz="5.2104858833105037041e-07" izz="7.2108884823996998174e-05"/>
    </inertial>
  </link>
  <link name="spiral_bevel_1m_14t_30deg">
    <visual>
      <origin xyz="0 0 0" rpy="0 -0 0"/>
      <geometry>
        <mesh filename="../assemblies/toddlerbot_2xm/meshes/spiral_bevel_1m_14t_30deg_visual.stl"/>
      </geometry>
      <material name="spiral_bevel_1m_14t_30deg_material">
        <color rgba="0.64705882352941179736 0.64705882352941179736 0.64705882352941179736 1.0"/>
      </material>
    </visual>
    <inertial>
      <origin xyz="7.4971447279470481499e-10 7.1802237506385358719e-10 0.006686895501897913846" rpy="0 0 0"/>
      <mass value="0.00073261524436595492574"/>
      <inertia ixx="1.3495056019478196665e-08" ixy="4.0596681291792787018e-17" ixz="8.599255015702218872e-16" iyy="1.3495056150237195634e-08" iyz="-6.7913008245448690494e-16" izz="1.43559865498164051e-08"/>
    </inertial>
  </link>
  <joint name="waist_act_1" type="revolute">
    <origin xyz="3.7125771266094977152e-17 -0.019600000000000020184 -0.012750000000000000916" rpy="1.570796326794896558 2.7529416277864663811e-15 -3.1415926535897913396"/>
    <parent link="pelvis_link"/>
    <child link="spiral_bevel_1m_14t_30deg"/>
    <axis xyz="0 0 1"/>
    <limit effort="1" velocity="20" lower="-4.6774823953448034786" upper="4.6774823953448034786"/>
    <joint_properties friction="0.0"/>
  </joint>
  <link name="spiral_bevel_1m_14t_30deg_2">
    <visual>
      <origin xyz="0 0 0" rpy="0 -0 0"/>
      <geometry>
        <mesh filename="../assemblies/toddlerbot_2xm/meshes/spiral_bevel_1m_14t_30deg_2_visual.stl"/>
      </geometry>
      <material name="spiral_bevel_1m_14t_30deg_2_material">
        <color rgba="0.64705882352941179736 0.64705882352941179736 0.64705882352941179736 1.0"/>
      </material>
    </visual>
    <inertial>
      <origin xyz="3.6393116818744802484e-10 -9.7220472297654403349e-10 -0.0066868955018979207849" rpy="0 0 0"/>
      <mass value="0.00073261524436595492574"/>
      <inertia ixx="1.3495056012354477525e-08" ixy="2.5804136222378210375e-17" ixz="-1.0694296051663920415e-15" iyy="1.3495056157360908156e-08" iyz="-2.3876736954310903269e-16" izz="1.43559865498164051e-08"/>
    </inertial>
  </link>
  <joint name="waist_act_2" type="revolute">
    <origin xyz="8.2006622604210144818e-18 -0.019599999999999999367 -0.032750000000000001332" rpy="-1.570796326794896558 -5.4984382998055662717e-16 -3.1415926535897922278"/>
    <parent link="pelvis_link"/>
    <child link="spiral_bevel_1m_14t_30deg_2"/>
    <axis xyz="0 0 1"/>
    <limit effort="1" velocity="20" lower="-4.6774823953448034786" upper="4.6774823953448034786"/>
    <joint_properties friction="0.0"/>
  </joint>
  <joint name="left_hip_pitch" type="revolute">
    <origin xyz="0.018000000000000015987 -0.048100000000000003864 -0.022750000000000006328" rpy="-1.570796326794896558 1.6504994128029653493e-13 1.570796326794901443"/>
    <parent link="pelvis_link"/>
    <child link="left_hip_pitch_link"/>
    <axis xyz="0 0 1"/>
    <limit effort="1" velocity="20" lower="-0.785398163397448279" upper="2.356194490192344837"/>
    <joint_properties friction="0.0"/>
  </joint>
  <joint name="right_hip_pitch" type="revolute">
    <origin xyz="-0.018000000000000012518 -0.048100000000000017741 -0.022750000000000002859" rpy="1.570796326794896558 1.5655006806055883195e-13 1.570796326794896336"/>
    <parent link="pelvis_link"/>
    <child link="right_hip_pitch_link"/>
    <axis xyz="0 0 1"/>
    <limit effort="1" velocity="20" lower="-2.356194490192344837" upper="0.785398163397448279"/>
    <joint_properties friction="0.0"/>
  </joint>
  <joint name="waist_roll" type="revolute">
    <origin xyz="-0.022707865260687083719 -1.1505205732202515009e-18 -0.014000000000000000291" rpy="1.5707963267948970021 -3.0586650082910413294e-14 -1.57079632679489678"/>
    <parent link="waist_gears"/>
    <child link="pelvis_link"/>
    <axis xyz="0 0 1"/>
    <limit effort="1" velocity="20" lower="-0.52359877559829881566" upper="0.52359877559829881566"/>
    <joint_properties friction="0.0"/>
  </joint>
  <joint name="waist_yaw" type="revolute">
    <origin xyz="-2.7755575615628913511e-17 -1.0995740381784306341e-19 1.4125540584113742641e-29" rpy="-2.4607930332406853109e-24 -4.0763901438054436429e-15 3.1415926535897922278"/>
    <parent link="torso"/>
    <child link="waist_gears"/>
    <axis xyz="0 0 1"/>
    <limit effort="1" velocity="20" lower="-1.570796326794896558" upper="1.570796326794896558"/>
    <joint_properties friction="0.0"/>
  </joint>
  <joint name="left_sho_pitch" type="revolute">
    <origin xyz="-0.003500000000000471484 0.067000000000001072586 0.10423651076281729988" rpy="-1.5707963267949092145 -4.1300296516055854858e-14 3.4824310043944882416e-14"/>
    <parent link="torso"/>
    <child link="sho_pitch_link"/>
    <axis xyz="0 0 1"/>
    <limit effort="1" velocity="20" lower="-3.141592653589793116" upper="1.570796326794896558"/>
    <joint_properties friction="0.0"/>
  </joint>
  <joint name="right_sho_pitch" type="revolute">
    <origin xyz="-0.003499999999998689923 -0.067000000000001017075 0.10423651076281729988" rpy="-1.5707963267948874542 3.1641356201815939038e-14 -3.1415926535897420457"/>
    <parent link="torso"/>
    <child link="sho_pitch_link_2"/>
    <axis xyz="0 0 1"/>
    <limit effort="1" velocity="20" lower="-1.570796326794896558" upper="3.141592653589793116"/>
    <joint_properties friction="0.0"/>
  </joint>
  <link name="left_hip_pitch_link">
    <visual>
      <origin xyz="0 0 0" rpy="0 -0 0"/>
      <geometry>
        <mesh filename="../assemblies/left_leg_2xm/meshes/left_hip_pitch_link_visual.stl"/>
      </geometry>
      <material name="left_hip_pitch_link_material">
        <color rgba="0.92982090412552342862 0.72254076531321620447 0.12744144951766167573 1.0"/>
      </material>
    </visual>
    <inertial>
      <origin xyz="-0.011706350670177599962 0.019742757684791095024 -0.018852427217597104991" rpy="0 0 0"/>
      <mass value="0.19376376696210850792"/>
      <inertia ixx="0.00011804472850814715546" ixy="-1.5895078857706018834e-06" ixz="-3.4383747953545210347e-08" iyy="5.1588508581731065325e-05" iyz="7.4157570294140530861e-07" izz="0.00013525831069619408532"/>
    </inertial>
  </link>
  <link name="hip_yaw_link">
    <visual>
      <origin xyz="0 0 0" rpy="0 -0 0"/>
      <geometry>
        <mesh filename="../assemblies/left_leg_2xm/meshes/left_hip_yaw_link_visual.stl"/>
      </geometry>
      <material name="hip_yaw_link_material">
        <color rgba="0.61568627450980395466 0.81176470588235294379 0.92941176470588238168 1.0"/>
      </material>
    </visual>
    <inertial>
      <origin xyz="-1.1351340770169766513e-06 0.016382481946049850391 0.024904960957045248898" rpy="0 0 0"/>
      <mass value="0.013199999999999989519"/>
      <inertia ixx="6.2164630245752423339e-06" ixy="1.711222792995632811e-10" ixz="2.3737014581360032619e-10" iyy="5.5106440267526434637e-06" iyz="8.1727857918858932185e-08" izz="2.6855910648547497853e-06"/>
    </inertial>
  </link>
  <link name="spur_gear_21_teeth">
    <visual>
      <origin xyz="0 0 0" rpy="0 -0 0"/>
      <geometry>
        <mesh filename="../assemblies/left_leg_2xm/meshes/left_spur_gear_21_teeth_visual.stl"/>
      </geometry>
      <material name="spur_gear_21_teeth_material">
        <color rgba="0.61568627450980395466 0.81176470588235294379 0.9294117647058824927 1.0"/>
      </material>
    </visual>
    <inertial>
      <origin xyz="-4.5505288977337882293e-11 -1.6782163717306987843e-11 -0.00249241020062506086" rpy="0 0 0"/>
      <mass value="0.0021999999999999996989"/>
      <inertia ixx="7.0162310059594183647e-08" ixy="3.0428041711026148533e-41" ixz="-6.0897863866794247362e-39" iyy="7.016231005804743531e-08" iyz="8.2010274057603441653e-39" izz="1.3125544198538286659e-07"/>
    </inertial>
  </link>
  <link name="left_thigh_link">
    <visual>
      <origin xyz="0 0 0" rpy="0 -0 0"/>
      <geometry>
        <mesh filename="../assemblies/left_leg_2xm/meshes/left_thigh_link_visual.stl"/>
      </geometry>
      <material name="left_thigh_link_material">
        <color rgba="0.8077380222132878318 0.71541030077254164077 0.35058406659986918186 1.0"/>
      </material>
    </visual>
    <collision name="left_thigh_link_collision">
      <origin xyz="-0.005438103005193837 -0.004840145161154905 0.05247500166296959" rpy="0.0 0.0 0.0"/>
      <geometry>
        <capsule radius="0.03603217800708148" length="0.03288564731177622"/>
      </geometry>
    </collision>
    <inertial>
      <origin xyz="-0.009931074824787505459 -0.0055733268638735152314 0.039014117054800664941" rpy="0 0 0"/>
      <mass value="0.14895408167669121902"/>
      <inertia ixx="7.3955327919484757822e-05" ixy="-1.1805488631448604991e-06" ixz="-8.0603251552292583818e-06" iyy="8.899510291969826045e-05" iyz="1.1275669888580036226e-06" izz="4.2292269256454549447e-05"/>
    </inertial>
  </link>
  <link name="spur_gear_18_teeth">
    <visual>
      <origin xyz="0 0 0" rpy="0 -0 0"/>
      <geometry>
        <mesh filename="../assemblies/left_leg_2xm/meshes/left_spur_gear_18_teeth_visual.stl"/>
      </geometry>
      <material name="spur_gear_18_teeth_material">
        <color rgba="0.61568627450980395466 0.81176470588235294379 0.92941176470588238168 1.0"/>
      </material>
    </visual>
    <inertial>
      <origin xyz="2.6439001777770671405e-18 8.5434987333314918169e-18 0.0017500000000000108785" rpy="0 0 0"/>
      <mass value="0.0012000000000000001117"/>
      <inertia ixx="2.9545593202975793532e-08" ixy="1.2314171653707795068e-23" ixz="-9.4023651664732437708e-36" iyy="2.9545593202975863016e-08" iyz="1.5954477302672659434e-36" izz="5.6662838285388571446e-08"/>
    </inertial>
  </link>
  <joint name="left_hip_yaw_drive" type="revolute">
    <origin xyz="-0.019199999999993382083 0.00020000000000426967905 -3.438915818776422384e-14" rpy="-3.1415926535896581129 -4.9090714472496588269e-13 4.6739125815344266384e-13"/>
    <parent link="left_thigh_link"/>
    <child link="spur_gear_18_teeth"/>
    <axis xyz="0 0 1"/>
    <limit effort="1" velocity="20" lower="-1.8325957145940461324" upper="1.8325957145940461324"/>
    <joint_properties friction="0.0"/>
  </joint>
  <link name="left_calf_link">
    <visual>
      <origin xyz="0 0 0" rpy="0 -0 0"/>
      <geometry>
        <mesh filename="../assemblies/left_leg_2xm/meshes/left_calf_link_visual.stl"/>
      </geometry>
      <material name="left_calf_link_material">
        <color rgba="0.61568627450980395466 0.81176470588235283277 0.92941176470588238168 1.0"/>
      </material>
    </visual>
    <inertial>
      <origin xyz="-0.004345005439123867351 0.04075298216524993189 0.0087116093515531897035" rpy="0 0 0"/>
      <mass value="0.03099999999999998937"/>
      <inertia ixx="3.3069388685111919361e-05" ixy="-1.3783307153201250192e-06" ixz="-1.2742534026333974449e-07" iyy="7.7316525337312093391e-06" iyz="-7.3356500593832537363e-08" izz="2.8031377753986202908e-05"/>
    </inertial>
  </link>
  <link name="bearing_683_3">
    <visual>
      <origin xyz="0 0 0" rpy="0 -0 0"/>
      <geometry>
        <mesh filename="../assemblies/left_leg_2xm/meshes/left_bearing_683_visual.stl"/>
      </geometry>
      <material name="bearing_683_material">
        <color rgba="0.64705882352941179736 0.64705882352941179736 0.64705882352941179736 1.0"/>
      </material>
    </visual>
    <inertial>
      <origin xyz="1.0732094295237694297e-19 -2.4186774283160226211e-19 -0.0015500000000000003792" rpy="0 0 0"/>
      <mass value="0.00048694686130641793437"/>
      <inertia ixx="2.1551456503319879113e-09" ixy="-6.2799976202677632124e-28" ixz="5.1534174171568426072e-40" iyy="2.1551456503319883249e-09" iyz="-5.0160366256123927433e-41" izz="3.5303647444715305817e-09"/>
    </inertial>
  </link>
  <joint name="left_knee_front_rev_2" type="revolute">
    <origin xyz="-0.0057402514854763136976 -0.013858192987669076812 0.026199999999999178807" rpy="3.141592653589793116 -3.6846712218145297232e-15 -1.5696597423400153737"/>
    <parent link="left_calf_link"/>
    <child link="bearing_683_3"/>
    <axis xyz="0 0 1"/>
    <limit effort="1" velocity="20"/>
    <joint_properties friction="0.0"/>
  </joint>
  <link name="bearing_683_4">
    <visual>
      <origin xyz="0 0 0" rpy="0 -0 0"/>
      <geometry>
        <mesh filename="../assemblies/left_leg_2xm/meshes/left_bearing_683_2_visual.stl"/>
      </geometry>
      <material name="bearing_683_2_material">
        <color rgba="0.64705882352941179736 0.64705882352941179736 0.64705882352941179736 1.0"/>
      </material>
    </visual>
    <inertial>
      <origin xyz="1.0732094295237709945e-19 6.2549399515680022583e-19 -0.0015500000000000001624" rpy="0 0 0"/>
      <mass value="0.00048694686130641793437"/>
      <inertia ixx="2.1551456503319887385e-09" ixy="1.5334993719773141702e-28" ixz="-4.3380717671628368304e-42" iyy="2.1551456503319891521e-09" iyz="2.8653118878668096225e-39" izz="3.5303647444715305817e-09"/>
    </inertial>
  </link>
  <joint name="left_knee_back_rev_2" type="revolute">
    <origin xyz="0.0057402514854765652325 0.013858192987669493146 0.026199999999999244726" rpy="-3.1415926535897873428 -6.1642758581299746636e-16 -1.569659900865386204"/>
    <parent link="left_calf_link"/>
    <child link="bearing_683_4"/>
    <axis xyz="0 0 1"/>
    <limit effort="1" velocity="20"/>
    <joint_properties friction="0.0"/>
  </joint>
  <link name="left_ank_pitch_link">
    <visual>
      <origin xyz="0 0 0" rpy="0 -0 0"/>
      <geometry>
        <mesh filename="../assemblies/left_leg_2xm/meshes/left_ank_pitch_link_visual.stl"/>
      </geometry>
      <material name="left_ank_pitch_link_material">
        <color rgba="0.70321688500203327621 0.64514870846184446673 0.40484735422826279017 1.0"/>
      </material>
    </visual>
    <collision name="left_ank_pitch_link_collision">
      <origin xyz="0.01934999879449606 0.012000000104308128 0.016799999633803964" rpy="0 0 0"/>
      <geometry>
        <box size="0.084799999371171 0.04650000110268593 0.046639998117461806"/>
      </geometry>
    </collision>
    <inertial>
      <origin xyz="0.017770422751691619667 0.012417933919336193033 0.018813528244421732355" rpy="0 0 0"/>
      <mass value="0.17676376695067899658"/>
      <inertia ixx="4.7033214273546878508e-05" ixy="-5.8981911382268089093e-07" ixz="-5.5304655046867245964e-07" iyy="0.00010706748281469059521" iyz="-5.954368905048644969e-08" izz="0.00012159782211823027165"/>
    </inertial>
  </link>
  <link name="ank_roll_link">
    <visual>
      <origin xyz="0 0 0" rpy="0 -0 0"/>
      <geometry>
        <mesh filename="../assemblies/left_leg_2xm/meshes/left_ank_roll_link_visual.stl"/>
      </geometry>
      <material name="ank_roll_link_material">
        <color rgba="0.61568627450980395466 0.81176470588235294379 0.92941176470588238168 1.0"/>
      </material>
    </visual>
    <collision name="ank_roll_link_collision">
      <origin xyz="-0.014500000514090061 0.0 0.038999998942017555" rpy="0 0 0"/>
      <geometry>
        <box size="0.04900000058114529 0.041999999433755875 0.12000000104308128"/>
      </geometry>
    </collision>
    <inertial>
      <origin xyz="-0.026987231947660717674 5.653272469623604523e-13 0.033766671354451605058" rpy="0 0 0"/>
      <mass value="0.042599999999999998979"/>
      <inertia ixx="3.7149943594120509295e-05" ixy="1.94807275579421073e-17" ixz="2.3895918372294030898e-06" iyy="3.7472718057542804256e-05" iyz="7.8258680835538914296e-12" izz="1.0051685129153406552e-05"/>
    </inertial>
  </link>
  <joint name="left_ank_roll" type="revolute">
    <origin xyz="0.022749999999981843773 -7.882583474838611437e-15 0.01900000000000073852" rpy="-1.5707963267949500707 -9.3641111455497678285e-15 1.5707963267951978725"/>
    <parent link="left_ank_pitch_link"/>
    <child link="ank_roll_link"/>
    <axis xyz="0 0 1"/>
    <limit effort="1" velocity="20" lower="-1.570796326794896558" upper="1.570796326794896558"/>
    <joint_properties friction="0.0"/>
  </joint>
  <joint name="left_ank_pitch" type="revolute">
    <origin xyz="1.3731962615615156409e-15 0.099999999999997951639 0.02774999999999918851" rpy="3.141592653589793116 -4.9446121211182754037e-18 -2.0452759225209035521e-15"/>
    <parent link="left_calf_link"/>
    <child link="left_ank_pitch_link"/>
    <axis xyz="0 0 1"/>
    <limit effort="1" velocity="20" lower="-1.7453292519943295336" upper="0.785398163397448279"/>
    <joint_properties friction="0.0"/>
  </joint>
  <joint name="left_knee" type="revolute">
    <origin xyz="3.2303803729205604611e-16 -0.0087500000000000285882 0.085950000000000484346" rpy="1.5707963267948998887 9.1903399882501304125e-17 -3.1415926535897926719"/>
    <parent link="left_thigh_link"/>
    <child link="left_calf_link"/>
    <axis xyz="0 0 1"/>
    <limit effort="1" velocity="20" lower="-1.570796326794896558" upper="0"/>
    <joint_properties friction="0.0"/>
  </joint>
  <link name="xm430_plate">
    <visual>
      <origin xyz="0 0 0" rpy="0 -0 0"/>
      <geometry>
        <mesh filename="../assemblies/left_leg_2xm/meshes/left_xm430_plate_visual.stl"/>
      </geometry>
      <material name="xm430_plate_material">
        <color rgba="0.61568627450980395466 0.81176470588235294379 0.92941176470588227065 1.0"/>
      </material>
    </visual>
    <inertial>
      <origin xyz="1.2199949069473465797e-18 -2.5675705000662896147e-18 0.0025278513919583852493" rpy="0 0 0"/>
      <mass value="0.0026999999999999997093"/>
      <inertia ixx="1.2887178787151819394e-07" ixy="5.8739562556303553596e-08" ixz="8.8620754357183379589e-39" iyy="2.4635091298412528789e-07" iyz="4.4470047921031726444e-38" izz="3.646799841381030595e-07"/>
    </inertial>
  </link>
  <link name="knee_rod">
    <visual>
      <origin xyz="0 0 0" rpy="0 -0 0"/>
      <geometry>
        <mesh filename="../assemblies/left_leg_2xm/meshes/left_knee_rod_visual.stl"/>
      </geometry>
      <material name="knee_rod_material">
        <color rgba="0.62051618944235198416 0.78640765248647581664 0.88594253031295022716 1.0"/>
      </material>
    </visual>
    <inertial>
      <origin xyz="0.017534290263858352821 3.9858446391435727811e-05 -0.0015981336617514451531" rpy="0 0 0"/>
      <mass value="0.0031629468613064179276"/>
      <inertia ixx="2.7978945925001967021e-08" ixy="-4.0224987309131433355e-10" ixz="4.8576302098649207963e-10" iyy="8.7495154957252311209e-07" iyz="1.1042225844322773014e-12" izz="8.9816306921226656837e-07"/>
    </inertial>
  </link>
  <joint name="left_knee_front_rev_1" type="revolute">
    <origin xyz="0.013858192987669049057 -0.0057402514854763527288 0.0049999999999999914305" rpy="-3.1415926535897908956 3.4964474193337374653e-15 -3.1404560691349008295"/>
    <parent link="xm430_plate"/>
    <child link="knee_rod"/>
    <axis xyz="0 0 1"/>
    <limit effort="1" velocity="20"/>
    <joint_properties friction="0.0"/>
  </joint>
  <link name="knee_rod_2">
    <visual>
      <origin xyz="0 0 0" rpy="0 -0 0"/>
      <geometry>
        <mesh filename="../assemblies/left_leg_2xm/meshes/left_knee_rod_2_visual.stl"/>
      </geometry>
      <material name="knee_rod_2_material">
        <color rgba="0.62051618944235198416 0.78640765248647581664 0.88594253031295022716 1.0"/>
      </material>
    </visual>
    <inertial>
      <origin xyz="0.017534290270177187165 3.9852887128006895645e-05 -0.0015981336617513928946" rpy="0 0 0"/>
      <mass value="0.0031629468613064179276"/>
      <inertia ixx="2.7978945669952882124e-08" ixy="-4.0219376936919183332e-10" ixz="4.8576302116128196051e-10" iyy="8.7495154970007240378e-07" iyz="1.1040685742798436999e-12" izz="8.9816306908475899306e-07"/>
    </inertial>
  </link>
  <joint name="left_knee_back_rev_1" type="revolute">
    <origin xyz="-0.013858192987669118446 0.0057402514854763457899 0.0049999999999999888284" rpy="3.1415926535897873428 1.9452985330695691049e-16 -3.1404562276602714377"/>
    <parent link="xm430_plate"/>
    <child link="knee_rod_2"/>
    <axis xyz="0 0 1"/>
    <limit effort="1" velocity="20"/>
    <joint_properties friction="0.0"/>
  </joint>
  <joint name="left_knee_act" type="revolute">
    <origin xyz="1.4647571350279164903e-16 0.012449999999999985384 0.044500000000000053402" rpy="-1.57079632679489678 1.5707963267948930053 0"/>
    <parent link="left_thigh_link"/>
    <child link="xm430_plate"/>
    <axis xyz="0 0 1"/>
    <limit effort="1" velocity="20" lower="-1.570796326794896558" upper="0"/>
    <joint_properties friction="0.0"/>
  </joint>
  <joint name="left_hip_yaw_driven" type="revolute">
    <origin xyz="-1.5720931501039814293e-18 -3.4694469519536141888e-18 -0.0050000000000000044409" rpy="-3.1415926535897904515 -2.6731719319053922034e-15 1.0531803182873569707e-15"/>
    <parent link="spur_gear_21_teeth"/>
    <child link="left_thigh_link"/>
    <axis xyz="0 0 1"/>
    <limit effort="1" velocity="20" lower="-1.570796326794896558" upper="1.570796326794896558"/>
    <joint_properties friction="0.0"/>
  </joint>
  <joint name="left_hip_yaw_fixed" type="fixed">
    <origin xyz="0 0.027999999999999993644 0.02300000000000000655" rpy="1.570796326794896336 -1.5707963267948870101 0"/>
    <parent link="hip_yaw_link"/>
    <child link="spur_gear_21_teeth"/>
    <axis xyz="0 0 1"/>
    <limit effort="1" velocity="20"/>
    <joint_properties friction="0.0"/>
  </joint>
  <joint name="left_hip_roll" type="revolute">
    <origin xyz="-0.023749999999998987199 0.022750000000000013267 -0.019050000000000236883" rpy="1.5707963267948872321 -1.5707963267948945596 0"/>
    <parent link="left_hip_pitch_link"/>
    <child link="hip_yaw_link"/>
    <axis xyz="0 0 1"/>
    <limit effort="1" velocity="20" lower="-1.570796326794896558" upper="1.570796326794896558"/>
    <joint_properties friction="0.0"/>
  </joint>
  <link name="right_hip_pitch_link">
    <visual>
      <origin xyz="0 0 0" rpy="0 -0 0"/>
      <geometry>
        <mesh filename="../assemblies/right_leg_2xm/meshes/right_hip_pitch_link_visual.stl"/>
      </geometry>
      <material name="right_hip_pitch_link_material">
        <color rgba="0.92982090412552342862 0.72254076531321620447 0.12744144951766167573 1.0"/>
      </material>
    </visual>
    <inertial>
      <origin xyz="-0.01170635067017833375 -0.019742757686486544361 -0.018808249759672979878" rpy="0 0 0"/>
      <mass value="0.19376376696210850792"/>
      <inertia ixx="0.00011804182389326951623" ixy="1.5895078464523899925e-06" ixz="-3.0802177008483233797e-08" iyy="5.1585603979825105493e-05" iyz="-5.5648114095732285423e-07" izz="0.00013525831068322282606"/>
    </inertial>
  </link>
  <link name="hip_yaw_link_2">
    <visual>
      <origin xyz="0 0 0" rpy="0 -0 0"/>
      <geometry>
        <mesh filename="../assemblies/right_leg_2xm/meshes/right_hip_yaw_link_visual.stl"/>
      </geometry>
      <material name="hip_yaw_link_material">
        <color rgba="0.61568627450980395466 0.81176470588235294379 0.92941176470588238168 1.0"/>
      </material>
    </visual>
    <inertial>
      <origin xyz="-1.135134077016976863e-06 0.01638248194604985386 0.024904960957045241959" rpy="0 0 0"/>
      <mass value="0.013199999999999989519"/>
      <inertia ixx="6.216463024575245722e-06" ixy="1.711222792995633328e-10" ixz="2.3737014581360037789e-10" iyy="5.5106440267526434637e-06" iyz="8.1727857918858932185e-08" izz="2.6855910648547497853e-06"/>
    </inertial>
  </link>
  <link name="spur_gear_21_teeth_2">
    <visual>
      <origin xyz="0 0 0" rpy="0 -0 0"/>
      <geometry>
        <mesh filename="../assemblies/right_leg_2xm/meshes/right_spur_gear_21_teeth_visual.stl"/>
      </geometry>
      <material name="spur_gear_21_teeth_material">
        <color rgba="0.61568627450980395466 0.81176470588235294379 0.9294117647058824927 1.0"/>
      </material>
    </visual>
    <inertial>
      <origin xyz="-4.5505288977337882293e-11 -1.6782163717306987843e-11 -0.0024924102006250539211" rpy="0 0 0"/>
      <mass value="0.0021999999999999996989"/>
      <inertia ixx="7.0162310059594183647e-08" ixy="6.9185379282510963078e-39" ixz="5.5122342094673161746e-40" iyy="7.016231005804743531e-08" iyz="-1.9797591643880531248e-71" izz="1.3125544198538286659e-07"/>
    </inertial>
  </link>
  <link name="right_thigh_link">
    <visual>
      <origin xyz="0 0 0" rpy="0 -0 0"/>
      <geometry>
        <mesh filename="../assemblies/right_leg_2xm/meshes/right_thigh_link_visual.stl"/>
      </geometry>
      <material name="right_thigh_link_material">
        <color rgba="0.81231119922470296224 0.7131158892107314351 0.33680089849959454762 1.0"/>
      </material>
    </visual>
    <collision name="right_thigh_link_collision">
      <origin xyz="0.0060016458203471824 -0.004471145098522489 0.05247500166296959" rpy="0.0 0.0 0.0"/>
      <geometry>
        <capsule radius="0.0356642456589791" length="0.03362151200798098"/>
      </geometry>
    </collision>
    <inertial>
      <origin xyz="0.010187905578010832477 -0.0056188467228509399523 0.038815928333491692137" rpy="0 0 0"/>
      <mass value="0.14548965119785953193"/>
      <inertia ixx="7.0942049594865160683e-05" ixy="1.1158758975155788993e-06" ixz="7.6515558781285007971e-06" iyy="8.515739880291365064e-05" iyz="1.069933739907198978e-06" izz="4.0945306935232121995e-05"/>
    </inertial>
  </link>
  <link name="spur_gear_18_teeth_2">
    <visual>
      <origin xyz="0 0 0" rpy="0 -0 0"/>
      <geometry>
        <mesh filename="../assemblies/right_leg_2xm/meshes/right_spur_gear_18_teeth_visual.stl"/>
      </geometry>
      <material name="spur_gear_18_teeth_material">
        <color rgba="0.61568627450980395466 0.81176470588235294379 0.92941176470588238168 1.0"/>
      </material>
    </visual>
    <inertial>
      <origin xyz="1.1201704073225982176e-18 -1.2342259190192713513e-17 0.0017499999999999922302" rpy="0 0 0"/>
      <mass value="0.0012000000000000001117"/>
      <inertia ixx="2.9545593202975796841e-08" ixy="1.2382036808367865321e-38" ixz="4.6295946344312827085e-37" iyy="2.9545593202975872942e-08" iyz="-1.1444185360592795855e-38" izz="5.6662838285388571446e-08"/>
    </inertial>
  </link>
  <joint name="right_hip_yaw_drive" type="revolute">
    <origin xyz="0.019200000000000608941 0.00019999999999991205368 -3.986394547794702703e-14" rpy="-3.1415926535897487071 -3.3554531021644002431e-13 4.6155381424903106362e-13"/>
    <parent link="right_thigh_link"/>
    <child link="spur_gear_18_teeth_2"/>
    <axis xyz="0 0 1"/>
    <limit effort="1" velocity="20" lower="-1.8325957145940461324" upper="1.8325957145940461324"/>
    <joint_properties friction="0.0"/>
  </joint>
  <link name="right_calf_link">
    <visual>
      <origin xyz="0 0 0" rpy="0 -0 0"/>
      <geometry>
        <mesh filename="../assemblies/right_leg_2xm/meshes/right_calf_link_visual.stl"/>
      </geometry>
      <material name="right_calf_link_material">
        <color rgba="0.61568627450980395466 0.81176470588235294379 0.92941176470588238168 1.0"/>
      </material>
    </visual>
    <inertial>
      <origin xyz="-0.0043450054394401412677 -0.040752982164757395322 0.0087116093514751861276" rpy="0 0 0"/>
      <mass value="0.0309999999999999859"/>
      <inertia ixx="3.3069388685436868305e-05" ixy="1.3783307152005356137e-06" ixz="-1.2742534017148746522e-07" iyy="7.7316525337489631496e-06" iyz="7.3356500737981874876e-08" izz="2.8031377754211893143e-05"/>
    </inertial>
  </link>
  <link name="bearing_683_5">
    <visual>
      <origin xyz="0 0 0" rpy="0 -0 0"/>
      <geometry>
        <mesh filename="../assemblies/right_leg_2xm/meshes/right_bearing_683_visual.stl"/>
      </geometry>
      <material name="bearing_683_material">
        <color rgba="0.64705882352941179736 0.64705882352941179736 0.64705882352941179736 1.0"/>
      </material>
    </visual>
    <inertial>
      <origin xyz="-2.7648254672676539312e-17 6.2549399515680128509e-19 -0.0015500000000000003792" rpy="0 0 0"/>
      <mass value="0.00048694686130641793437"/>
      <inertia ixx="2.1551456503319887385e-09" ixy="5.938329734254552816e-29" ixz="4.2234669276366031341e-39" iyy="2.1551456503319883249e-09" iyz="-6.7335134926202872924e-41" izz="3.5303647444715305817e-09"/>
    </inertial>
  </link>
  <joint name="right_knee_front_rev_2" type="revolute">
    <origin xyz="0.0057402514854763718108 -0.013858192987669770702 0.026200000000000028821" rpy="3.141592653589793116 4.7532333134949093273e-16 1.5719104681400370982"/>
    <parent link="right_calf_link"/>
    <child link="bearing_683_5"/>
    <axis xyz="0 0 1"/>
    <limit effort="1" velocity="20"/>
    <joint_properties friction="0.0"/>
  </joint>
  <link name="bearing_683_6">
    <visual>
      <origin xyz="0 0 0" rpy="0 -0 0"/>
      <geometry>
        <mesh filename="../assemblies/right_leg_2xm/meshes/right_bearing_683_2_visual.stl"/>
      </geometry>
      <material name="bearing_683_2_material">
        <color rgba="0.64705882352941179736 0.64705882352941179736 0.64705882352941179736 1.0"/>
      </material>
    </visual>
    <inertial>
      <origin xyz="-2.7648254672676536231e-17 -2.4186774283160226211e-19 -0.0015500000000000003792" rpy="0 0 0"/>
      <mass value="0.00048694686130641793437"/>
      <inertia ixx="2.1551456503319887385e-09" ixy="-2.4504277341214625333e-28" ixz="3.3901768108754338424e-41" iyy="2.1551456503319883249e-09" iyz="5.4755107341247360049e-60" izz="3.5303647444715305817e-09"/>
    </inertial>
  </link>
  <joint name="right_knee_back_rev_2" type="revolute">
    <origin xyz="-0.0057402514854763934948 0.013858192987669021301 0.026199999999999980249" rpy="3.1415926535897922278 -1.6769178092422380047e-15 1.5719169850876628658"/>
    <parent link="right_calf_link"/>
    <child link="bearing_683_6"/>
    <axis xyz="0 0 1"/>
    <limit effort="1" velocity="20"/>
    <joint_properties friction="0.0"/>
  </joint>
  <link name="right_ank_pitch_link">
    <visual>
      <origin xyz="0 0 0" rpy="0 -0 0"/>
      <geometry>
        <mesh filename="../assemblies/right_leg_2xm/meshes/right_ank_pitch_link_visual.stl"/>
      </geometry>
      <material name="right_ank_pitch_link_material">
        <color rgba="0.70321688500203327621 0.64514870846184446673 0.40484735422826279017 1.0"/>
      </material>
    </visual>
    <collision name="right_ank_pitch_link_collision">
      <origin xyz="-0.01934999879449606 0.012000001966953278 0.016799999633803964" rpy="0 0 0"/>
      <geometry>
        <box size="0.084799999371171 0.04650000482797623 0.046639998117461806"/>
      </geometry>
    </collision>
    <inertial>
      <origin xyz="-0.01777042274983306816 0.012417933919336260687 0.018814514831173693304" rpy="0 0 0"/>
      <mass value="0.17676376695067899658"/>
      <inertia ixx="4.7033279140152881915e-05" ixy="5.8981907474083015582e-07" ixz="6.1533221595097461637e-07" iyy="0.00010706754769297033216" iyz="-5.2427772221904961753e-08" izz="0.00012159782212990462183"/>
    </inertial>
  </link>
  <link name="ank_roll_link_2">
    <visual>
      <origin xyz="0 0 0" rpy="0 -0 0"/>
      <geometry>
        <mesh filename="../assemblies/right_leg_2xm/meshes/right_ank_roll_link_visual.stl"/>
      </geometry>
      <material name="ank_roll_link_material">
        <color rgba="0.61568627450980395466 0.81176470588235294379 0.92941176470588238168 1.0"/>
      </material>
    </visual>
    <collision name="ank_roll_link_2_collision">
      <origin xyz="-0.014500000514090061 0.0 0.038999998942017555" rpy="0 0 0"/>
      <geometry>
        <box size="0.04900000058114529 0.041999999433755875 0.12000000104308128"/>
      </geometry>
    </collision>
    <inertial>
      <origin xyz="-0.026987231947660686449 5.6532512304029935813e-13 0.033766671354451605058" rpy="0 0 0"/>
      <mass value="0.042599999999999998979"/>
      <inertia ixx="3.7149943594118530626e-05" ixy="1.9666667662832936347e-17" ixz="2.3895918372292815406e-06" iyy="3.7472718057541049203e-05" iyz="7.8258680124225771449e-12" izz="1.0051685129153372671e-05"/>
    </inertial>
  </link>
  <joint name="right_ank_roll" type="revolute">
    <origin xyz="-0.022749999999990028199 -3.5249581031848720158e-15 0.018999999999999451356" rpy="1.5707963267948190644 2.082200812017336445e-14 1.5707963267948397146"/>
    <parent link="right_ank_pitch_link"/>
    <child link="ank_roll_link_2"/>
    <axis xyz="0 0 1"/>
    <limit effort="1" velocity="20" lower="-1.570796326794896558" upper="1.570796326794896558"/>
    <joint_properties friction="0.0"/>
  </joint>
  <joint name="right_ank_pitch" type="revolute">
    <origin xyz="3.5236570605778894105e-17 -0.09999999999999995004 0.027749999999999993422" rpy="-3.1415926535897917837 -7.8513249565814058339e-16 -3.1415926535897864547"/>
    <parent link="right_calf_link"/>
    <child link="right_ank_pitch_link"/>
    <axis xyz="0 0 1"/>
    <limit effort="1" velocity="20" lower="-0.785398163397448279" upper="1.7453292519943295336"/>
    <joint_properties friction="0.0"/>
  </joint>
  <joint name="right_knee" type="revolute">
    <origin xyz="9.915028867379938049e-17 -0.0087500000000001326717 0.085950000000000637002" rpy="-1.57079632679489678 -1.8596235662471439105e-15 -1.7091941954032421329e-15"/>
    <parent link="right_thigh_link"/>
    <child link="right_calf_link"/>
    <axis xyz="0 0 1"/>
    <limit effort="1" velocity="20" lower="0" upper="1.570796326794896558"/>
    <joint_properties friction="0.0"/>
  </joint>
  <link name="xm430_plate_2">
    <visual>
      <origin xyz="0 0 0" rpy="0 -0 0"/>
      <geometry>
        <mesh filename="../assemblies/right_leg_2xm/meshes/right_xm430_plate_visual.stl"/>
      </geometry>
      <material name="xm430_plate_material">
        <color rgba="0.61568627450980395466 0.81176470588235294379 0.92941176470588227065 1.0"/>
      </material>
    </visual>
    <inertial>
      <origin xyz="-1.0678768463071413547e-18 -2.7932101897381823422e-18 0.0025278513919583835146" rpy="0 0 0"/>
      <mass value="0.0026999999999999997093"/>
      <inertia ixx="2.4635091298412528789e-07" ixy="5.8739562556303540361e-08" ixz="-6.1340137510844996234e-39" iyy="1.2887178787151819394e-07" iyz="3.0966973396831916887e-38" izz="3.646799841381030595e-07"/>
    </inertial>
  </link>
  <link name="knee_rod_3">
    <visual>
      <origin xyz="0 0 0" rpy="0 -0 0"/>
      <geometry>
        <mesh filename="../assemblies/right_leg_2xm/meshes/right_knee_rod_visual.stl"/>
      </geometry>
      <material name="knee_rod_material">
        <color rgba="0.62051618944235198416 0.78640765248647581664 0.88594253031295022716 1.0"/>
      </material>
    </visual>
    <inertial>
      <origin xyz="0.017534291149574238872 3.9071397871386789554e-05 -0.0015981336617514770287" rpy="0 0 0"/>
      <mass value="0.0031629468613064179276"/>
      <inertia ixx="2.7978910170551288005e-08" ixy="-3.94307030303930001e-10" ixz="4.8576304552482821547e-10" iyy="8.7495156744971494086e-07" iyz="1.0824185061383664554e-12" izz="8.9816305133507018681e-07"/>
    </inertial>
  </link>
  <joint name="right_knee_front_rev_1" type="revolute">
    <origin xyz="0.0057402514854763813518 -0.013858192987669354368 0.0049999999999999922978" rpy="-3.141592653589793116 -2.2680076696535559301e-15 -1.5696821854497560178"/>
    <parent link="xm430_plate_2"/>
    <child link="knee_rod_3"/>
    <axis xyz="0 0 1"/>
    <limit effort="1" velocity="20"/>
    <joint_properties friction="0.0"/>
  </joint>
  <link name="knee_rod_4">
    <visual>
      <origin xyz="0 0 0" rpy="0 -0 0"/>
      <geometry>
        <mesh filename="../assemblies/right_leg_2xm/meshes/right_knee_rod_2_visual.stl"/>
      </geometry>
      <material name="knee_rod_2_material">
        <color rgba="0.62051618944235198416 0.78640765248647581664 0.88594253031295022716 1.0"/>
      </material>
    </visual>
    <inertial>
      <origin xyz="0.017534290894203184707 3.9299938126582091243e-05 -0.0015981336617514319259" rpy="0 0 0"/>
      <mass value="0.0031629468613064179276"/>
      <inertia ixx="2.7978920479332387554e-08" ixy="-3.9661344391086863808e-10" ixz="4.8576303845852543957e-10" iyy="8.7495156229529202847e-07" iyz="1.0887498949803466658e-12" izz="8.9816305648941188991e-07"/>
    </inertial>
  </link>
  <joint name="right_knee_back_rev_1" type="revolute">
    <origin xyz="-0.005740251485476307626 0.013858192987669243346 0.0050000000000000209208" rpy="-3.1415926535897926719 -7.2263408907627713374e-17 -1.5696756685021302502"/>
    <parent link="xm430_plate_2"/>
    <child link="knee_rod_4"/>
    <axis xyz="0 0 1"/>
    <limit effort="1" velocity="20"/>
    <joint_properties friction="0.0"/>
  </joint>
  <joint name="right_knee_act" type="revolute">
    <origin xyz="-3.4965520062657517997e-17 0.012449999999999900382 0.044500000000000414224" rpy="-1.5707963267948978903 -1.8873791418627653299e-15 -1.8392984561052994525e-15"/>
    <parent link="right_thigh_link"/>
    <child link="xm430_plate_2"/>
    <axis xyz="0 0 1"/>
    <limit effort="1" velocity="20" lower="0" upper="1.570796326794896558"/>
    <joint_properties friction="0.0"/>
  </joint>
  <joint name="right_hip_yaw_driven" type="revolute">
    <origin xyz="-5.1120132432691534063e-17 -1.1449174941446926823e-16 -0.0050000000000000044409" rpy="3.141592653589793116 1.1586097708402311315e-16 -1.9261630240694359833e-15"/>
    <parent link="spur_gear_21_teeth_2"/>
    <child link="right_thigh_link"/>
    <axis xyz="0 0 1"/>
    <limit effort="1" velocity="20" lower="-1.570796326794896558" upper="1.570796326794896558"/>
    <joint_properties friction="0.0"/>
  </joint>
  <joint name="right_hip_yaw_fixed" type="fixed">
    <origin xyz="1.1449174941446926823e-16 0.027999999999999990175 0.022999999999999951039" rpy="1.57079632679489678 1.570796326794896336 0"/>
    <parent link="hip_yaw_link_2"/>
    <child link="spur_gear_21_teeth_2"/>
    <axis xyz="0 0 1"/>
    <limit effort="1" velocity="20"/>
    <joint_properties friction="0.0"/>
  </joint>
  <joint name="right_hip_roll" type="revolute">
    <origin xyz="-0.023750000000001200706 -0.022749999999999999389 -0.018950000000000081363" rpy="-1.570796326794896558 1.5707963267948952257 0"/>
    <parent link="right_hip_pitch_link"/>
    <child link="hip_yaw_link_2"/>
    <axis xyz="0 0 1"/>
    <limit effort="1" velocity="20" lower="-1.570796326794896558" upper="1.570796326794896558"/>
    <joint_properties friction="0.0"/>
  </joint>
  <link name="sho_pitch_link">
    <visual>
      <origin xyz="0 0 0" rpy="0 -0 0"/>
      <geometry>
        <mesh filename="../assemblies/left_arm_umi/meshes/left_sho_pitch_link_visual.stl"/>
      </geometry>
      <material name="sho_pitch_link_material">
        <color rgba="0.61568627450980395466 0.81176470588235294379 0.92941176470588227065 1.0"/>
      </material>
    </visual>
    <inertial>
      <origin xyz="-1.025903438159899119e-18 -2.1966078074444220184e-18 0.012913250798677602602" rpy="0 0 0"/>
      <mass value="0.0085999999999999982708"/>
      <inertia ixx="1.8365636406635814379e-06" ixy="0" ixz="0" iyy="4.0110869076839152165e-06" iyz="0" izz="3.5160516450492493809e-06"/>
    </inertial>
  </link>
  <link name="2xl430_gears">
    <visual>
      <origin xyz="0 0 0" rpy="0 -0 0"/>
      <geometry>
        <mesh filename="../assemblies/left_arm_umi/meshes/left_2xl430_gears_visual.stl"/>
      </geometry>
      <material name="2xl430_gears_material">
        <color rgba="0.75914767920569214965 0.85560384745670925444 0.90519468321360607721 1.0"/>
      </material>
    </visual>
    <collision name="2xl430_gears_collision">
      <origin xyz="-0.011708511453562324 -0.002663695648909637 -0.019869671274007784" rpy="0 0 0"/>
      <geometry>
        <sphere radius="0.031174628050041002"/>
      </geometry>
    </collision>
    <inertial>
      <origin xyz="-0.011592905737980642444 -0.0024238553642583816373 -0.018551095523802015735" rpy="0 0 0"/>
      <mass value="0.11800003674524911501"/>
      <inertia ixx="2.7511021050428206944e-05" ixy="9.0043904315036704004e-07" ixz="-2.3349710124172453411e-08" iyy="3.2796197843345624423e-05" iyz="-6.5715119654599577247e-07" izz="3.5775739835744996948e-05"/>
    </inertial>
  </link>
  <link name="spur_1m_24t_drive">
    <visual>
      <origin xyz="0 0 0" rpy="0 -0 0"/>
      <geometry>
        <mesh filename="../assemblies/left_arm_umi/meshes/left_spur_1m_24t_drive_visual.stl"/>
      </geometry>
      <material name="spur_1m_24t_drive_material">
        <color rgba="0.61568627450980395466 0.81176470588235294379 0.92941176470588238168 1.0"/>
      </material>
    </visual>
    <inertial>
      <origin xyz="3.0395421551447426547e-15 -3.3912620813973872492e-16 0.0048096451474093065287" rpy="0 0 0"/>
      <mass value="0.0031999999999999997197"/>
      <inertia ixx="1.4097598887016953379e-07" ixy="1.5562823114943523235e-15" ixz="7.4273784759770902112e-37" iyy="1.4097598803635996198e-07" iyz="7.8038995636436382948e-37" izz="2.4107776386988835496e-07"/>
    </inertial>
  </link>
  <joint name="left_sho_yaw_drive" type="revolute">
    <origin xyz="-0.024000000716142534662 -0.019000000152456227726 -0.019000000152442717699" rpy="1.5707963267945506125 -5.5729871745090160275e-14 6.2805146429461445464e-14"/>
    <parent link="2xl430_gears"/>
    <child link="spur_1m_24t_drive"/>
    <axis xyz="0 0 1"/>
    <limit effort="1" velocity="20" lower="-2.6179938779914944114" upper="2.6179938779914944114"/>
    <joint_properties friction="0.0"/>
  </joint>
  <link name="spur_1m_24t_driven">
    <visual>
      <origin xyz="0 0 0" rpy="0 -0 0"/>
      <geometry>
        <mesh filename="../assemblies/left_arm_umi/meshes/left_spur_1m_24t_driven_visual.stl"/>
      </geometry>
      <material name="spur_1m_24t_driven_material">
        <color rgba="0.23137254901960788156 0.38039215686274502337 0.7058823529411765163 1.0"/>
      </material>
    </visual>
    <inertial>
      <origin xyz="-2.6903043908340867984e-18 -1.688384205958136519e-15 -0.00097237500038395777158" rpy="0 0 0"/>
      <mass value="0.0026999999999999997093"/>
      <inertia ixx="1.2202334915684080498e-07" ixy="1.3837295890494949211e-37" ixz="-1.0447421496749939075e-36" iyy="1.2202334915684064616e-07" iyz="3.3220397498769138301e-37" izz="2.3180293204341252239e-07"/>
    </inertial>
  </link>
  <link name="sho_yaw_link">
    <visual>
      <origin xyz="0 0 0" rpy="0 -0 0"/>
      <geometry>
        <mesh filename="../assemblies/left_arm_umi/meshes/left_sho_yaw_link_visual.stl"/>
      </geometry>
      <material name="sho_yaw_link_material">
        <color rgba="0.61568627450980395466 0.81176470588235294379 0.92941176470588238168 1.0"/>
      </material>
    </visual>
    <inertial>
      <origin xyz="-4.7730210054629770351e-18 2.6069328434163573568e-18 -0.024649285094360089132" rpy="0 0 0"/>
      <mass value="0.014500000000000007674"/>
      <inertia ixx="9.2365904614004439553e-06" ixy="3.5862833440690451918e-13" ixz="-8.2397007242855601464e-43" iyy="5.8163826335078791714e-06" iyz="-5.4352775587714288989e-35" izz="4.5074356741562122031e-06"/>
    </inertial>
  </link>
  <link name="2xl430_gears_2">
    <visual>
      <origin xyz="0 0 0" rpy="0 -0 0"/>
      <geometry>
        <mesh filename="../assemblies/left_arm_umi/meshes/left_2xl430_gears_2_visual.stl"/>
      </geometry>
      <material name="2xl430_gears_2_material">
        <color rgba="0.75914767920569214965 0.85560384745670925444 0.90519468321360607721 1.0"/>
      </material>
    </visual>
    <collision name="2xl430_gears_2_collision">
      <origin xyz="-0.011708511453562392 -0.002663695648909657 -0.019869671274007874" rpy="0 0 0"/>
      <geometry>
        <sphere radius="0.031174628050041016"/>
      </geometry>
    </collision>
    <inertial>
      <origin xyz="-0.011592905737981091738 -0.0024238553642542742458 -0.018551095523813909" rpy="0 0 0"/>
      <mass value="0.11800003674524911501"/>
      <inertia ixx="2.751102105042832214e-05" ixy="9.0043904315329650349e-07" ixz="-2.3349710125436329138e-08" iyy="3.2796197843348145193e-05" iyz="-6.5715119655126410565e-07" izz="3.5775739835745051158e-05"/>
    </inertial>
  </link>
  <link name="spur_1m_24t_drive_2">
    <visual>
      <origin xyz="0 0 0" rpy="0 -0 0"/>
      <geometry>
        <mesh filename="../assemblies/left_arm_umi/meshes/left_spur_1m_24t_drive_2_visual.stl"/>
      </geometry>
      <material name="spur_1m_24t_drive_2_material">
        <color rgba="0.61568627450980395466 0.81176470588235294379 0.92941176470588238168 1.0"/>
      </material>
    </visual>
    <inertial>
      <origin xyz="3.0395421551447426547e-15 -3.3912620811388947869e-16 0.0048096451474092995898" rpy="0 0 0"/>
      <mass value="0.0031999999999999997197"/>
      <inertia ixx="1.4097598887016953379e-07" ixy="1.5562823102285579479e-15" ixz="2.9661020669666376683e-36" iyy="1.4097598803635998845e-07" iyz="9.1368612700525381613e-36" izz="2.4107776386988835496e-07"/>
    </inertial>
  </link>
  <joint name="left_elbow_yaw_drive" type="revolute">
    <origin xyz="-0.024000000716140806878 -0.019000000152450138846 -0.01900000015246447807" rpy="1.5707963267949478503 -2.5802640142449200815e-13 5.2180482157376444099e-14"/>
    <parent link="2xl430_gears_2"/>
    <child link="spur_1m_24t_drive_2"/>
    <axis xyz="0 0 1"/>
    <limit effort="1" velocity="20" lower="-2.6179938779914944114" upper="2.6179938779914944114"/>
    <joint_properties friction="0.0"/>
  </joint>
  <link name="spur_1m_24t_driven_2">
    <visual>
      <origin xyz="0 0 0" rpy="0 -0 0"/>
      <geometry>
        <mesh filename="../assemblies/left_arm_umi/meshes/left_spur_1m_24t_driven_2_visual.stl"/>
      </geometry>
      <material name="spur_1m_24t_driven_2_material">
        <color rgba="0.23137254901960788156 0.38039215686274502337 0.7058823529411765163 1.0"/>
      </material>
    </visual>
    <inertial>
      <origin xyz="-2.6903043908350131707e-18 -1.685153565132015999e-15 -0.00097237500038395083268" rpy="0 0 0"/>
      <mass value="0.0026999999999999997093"/>
      <inertia ixx="1.2202334915684080498e-07" ixy="-5.3426136268858280334e-65" ixz="-2.7609150325300431337e-36" iyy="1.2202334915684064616e-07" iyz="5.8515286657488347587e-36" izz="2.3180293204341252239e-07"/>
    </inertial>
  </link>
  <link name="elb_yaw_link">
    <visual>
      <origin xyz="0 0 0" rpy="0 -0 0"/>
      <geometry>
        <mesh filename="../assemblies/left_arm_umi/meshes/left_elb_yaw_link_visual.stl"/>
      </geometry>
      <material name="elb_yaw_link_material">
        <color rgba="0.61568627450980395466 0.81176470588235294379 0.92941176470588227065 1.0"/>
      </material>
    </visual>
    <inertial>
      <origin xyz="5.3127688027774929136e-08 0.0019833638641961618201 -0.023416643551549959357" rpy="0 0 0"/>
      <mass value="0.017500000000000005135"/>
      <inertia ixx="1.4134344903109199776e-05" ixy="1.6945783922006120707e-12" ixz="-1.1286398721833143996e-11" iyy="6.6435900776211374285e-06" iyz="1.0545227077253055462e-06" izz="8.9925290757999027595e-06"/>
    </inertial>
  </link>
  <link name="spur_1m_24t_driven_3">
    <visual>
      <origin xyz="0 0 0" rpy="0 -0 0"/>
      <geometry>
        <mesh filename="../assemblies/left_arm_umi/meshes/left_spur_1m_24t_driven_3_visual.stl"/>
      </geometry>
      <material name="spur_1m_24t_driven_3_material">
        <color rgba="0.23137254901960788156 0.38039215686274502337 0.7058823529411765163 1.0"/>
      </material>
    </visual>
    <inertial>
      <origin xyz="-2.6903043908334539378e-18 -1.6883842059581396744e-15 -0.0025723750003839550293" rpy="0 0 0"/>
      <mass value="0.0026999999999999997093"/>
      <inertia ixx="1.2202334915684080498e-07" ixy="1.650838217124924475e-37" ixz="5.8515286657488347587e-36" iyy="1.2202334915684064616e-07" iyz="0" izz="2.3180293204341252239e-07"/>
    </inertial>
  </link>
  <link name="2xl430_gears_3">
    <visual>
      <origin xyz="0 0 0" rpy="0 -0 0"/>
      <geometry>
        <mesh filename="../assemblies/left_arm_umi/meshes/left_2xl430_gears_3_visual.stl"/>
      </geometry>
      <material name="2xl430_gears_3_material">
        <color rgba="0.75914767920569214965 0.85560384745670925444 0.90519468321360607721 1.0"/>
      </material>
    </visual>
    <collision name="2xl430_gears_3_collision">
      <origin xyz="-0.0008536254376339707 0.011718714468016044 -0.02433707854457951" rpy="0 0 0"/>
      <geometry>
        <sphere radius="0.031160574725534955"/>
      </geometry>
    </collision>
    <inertial>
      <origin xyz="0.00044890447619909743101 0.011592905379898219356 -0.024576144788197168412" rpy="0 0 0"/>
      <mass value="0.11800003674524911501"/>
      <inertia ixx="3.5775739835742089931e-05" ixy="2.3349710123834755271e-08" ixz="6.5715119654965728415e-07" iyy="2.7511021050427807144e-05" iyz="9.0043904315220340747e-07" izz="3.2796197843345726067e-05"/>
    </inertial>
  </link>
  <link name="spur_1m_24t_drive_3">
    <visual>
      <origin xyz="0 0 0" rpy="0 -0 0"/>
      <geometry>
        <mesh filename="../assemblies/left_arm_umi/meshes/left_spur_1m_24t_drive_3_visual.stl"/>
      </geometry>
      <material name="spur_1m_24t_drive_3_material">
        <color rgba="0.61568627450980395466 0.81176470588235294379 0.92941176470588238168 1.0"/>
      </material>
    </visual>
    <inertial>
      <origin xyz="3.0326032612408350319e-15 -3.3912620811388928147e-16 0.0048096451474093030592" rpy="0 0 0"/>
      <mass value="0.0031999999999999997197"/>
      <inertia ixx="1.4097598887016953379e-07" ixy="1.5562823135372803981e-15" ixz="1.2722418906858421266e-35" iyy="1.4097598803635998845e-07" iyz="4.1397718535750480265e-37" izz="2.4107776386988835496e-07"/>
    </inertial>
  </link>
  <joint name="left_wrist_pitch_drive" type="revolute">
    <origin xyz="-1.5244492967147879128e-10 0.024000000358059658812 -0.0080000000000056449567" rpy="-3.0533404903795228175e-14 -1.7699329119283895979e-13 -1.5707963267949680564"/>
    <parent link="2xl430_gears_3"/>
    <child link="spur_1m_24t_drive_3"/>
    <axis xyz="0 0 1"/>
    <limit effort="1" velocity="20" lower="-1.9198621771937625091" upper="1.3962634015954635824"/>
    <joint_properties friction="0.0"/>
  </joint>
  <link name="hand">
    <visual>
      <origin xyz="0 0 0" rpy="0 -0 0"/>
      <geometry>
        <mesh filename="../assemblies/left_arm_umi/meshes/left_hand_visual.stl"/>
      </geometry>
      <material name="hand_material">
        <color rgba="0.6414991312980887761 0.67624720774385704836 0.69709605361131787848 1.0"/>
      </material>
    </visual>
    <collision name="hand_collision">
      <origin xyz="0.0044999998062849045 -0.023250000085681677 -0.019000000320374966" rpy="0 0 0"/>
      <geometry>
        <box size="0.05000000074505806 0.06749999988824129 0.07400000281631947"/>
      </geometry>
    </collision>
    <inertial>
      <origin xyz="0.0037132560743682414481 -0.042135580180293757957 -0.019513129422372377242" rpy="0 0 0"/>
      <mass value="0.039500000000000000389"/>
      <inertia ixx="2.4655505305535776886e-05" ixy="6.2292690516533964304e-07" ixz="1.3905202790272152079e-08" iyy="2.5499495709674505013e-05" iyz="-4.0482284361498457642e-08" izz="1.3476712281039049114e-05"/>
    </inertial>
  </link>
  <joint name="left_wrist_roll" type="revolute">
    <origin xyz="0.019000000000009276829 -3.5808436771311846769e-10 -0.027000000152447547336" rpy="1.2196020852255911422e-29 1.5707963267946087882 0"/>
    <parent link="2xl430_gears_3"/>
    <child link="hand"/>
    <axis xyz="0 0 1"/>
    <limit effort="1" velocity="20" lower="-1.9198621771937625091" upper="1.3962634015954635824"/>
    <joint_properties friction="0.0"/>
  </joint>
  <link name="wrist_bearing_plate">
    <visual>
      <origin xyz="0 0 0" rpy="0 -0 0"/>
      <geometry>
        <mesh filename="../assemblies/left_arm_umi/meshes/left_wrist_bearing_plate_visual.stl"/>
      </geometry>
      <material name="wrist_bearing_plate_material">
        <color rgba="0.71932243125689054875 0.63128434304969727187 0.52422389360984933404 1.0"/>
      </material>
    </visual>
    <inertial>
      <origin xyz="-0.0075835583121499931455 -0.015499999999999977338 -0.0018386323705903331437" rpy="0 0 0"/>
      <mass value="0.0049000367468305557062"/>
      <inertia ixx="4.970743010915013972e-07" ixy="1.1194558104431275937e-22" ixz="1.8100904820813988926e-08" iyy="7.1268523603538489532e-07" iyz="1.6072883979218723091e-23" izz="1.1919657811600100764e-06"/>
    </inertial>
  </link>
  <joint name="left_wrist_pitch_fixed" type="fixed">
    <origin xyz="0.015500000000005004566 -1.8207657603852567263e-14 -0.044999999999998596678" rpy="4.0494715863782802008e-14 -2.8209346585231002385e-13 -1.570796326794906328"/>
    <parent link="2xl430_gears_3"/>
    <child link="wrist_bearing_plate"/>
    <axis xyz="0 0 1"/>
    <limit effort="1" velocity="20"/>
    <joint_properties friction="0.0"/>
  </joint>
  <joint name="left_wrist_pitch_driven" type="revolute">
    <origin xyz="0 -3.9443045261050590271e-30 -0.0015999999999999972577" rpy="6.0387003530043805309e-16 -4.4981039962148287683e-16 -1.570796326794896558"/>
    <parent link="spur_1m_24t_driven_3"/>
    <child link="2xl430_gears_3"/>
    <axis xyz="0 0 1"/>
    <limit effort="1" velocity="20" lower="-1.3962634015954635824" upper="1.9198621771937625091"/>
    <joint_properties friction="0.0"/>
  </joint>
  <joint name="left_wrist_roll_fixed" type="fixed">
    <origin xyz="1.5777218104420236108e-30 -0.025300000000000006511 -0.05200000000000001843" rpy="1.5707963267949043296 -1.5707963267948885644 0"/>
    <parent link="elb_yaw_link"/>
    <child link="spur_1m_24t_driven_3"/>
    <axis xyz="0 0 1"/>
    <limit effort="1" velocity="20"/>
    <joint_properties friction="0.0"/>
  </joint>
  <joint name="left_elbow_yaw_fixed" type="fixed">
    <origin xyz="-1.5777218104420236108e-30 0 0.0016000000000000041966" rpy="-3.1415926535897873428 3.0591810185765374017e-29 0"/>
    <parent link="spur_1m_24t_driven_2"/>
    <child link="elb_yaw_link"/>
    <axis xyz="0 0 1"/>
    <limit effort="1" velocity="20"/>
    <joint_properties friction="0.0"/>
  </joint>
  <joint name="left_elbow_yaw_driven" type="revolute">
    <origin xyz="-3.5806251019732115992e-10 -0.027000000152458583647 -0.019000000000009956841" rpy="1.5707963267948450437 1.5707963267948292785 0"/>
    <parent link="2xl430_gears_2"/>
    <child link="spur_1m_24t_driven_2"/>
    <axis xyz="0 0 1"/>
    <limit effort="1" velocity="20" lower="-2.6179938779914944114" upper="2.6179938779914944114"/>
    <joint_properties friction="0.0"/>
  </joint>
  <joint name="left_elbow_roll" type="revolute">
    <origin xyz="-3.4694469519536141888e-18 -0.018999999999999999528 -0.059000000000000024647" rpy="1.570796326794896336 -5.3290705182069808708e-14 -2.456539448233997185e-14"/>
    <parent link="sho_yaw_link"/>
    <child link="2xl430_gears_2"/>
    <axis xyz="0 0 1"/>
    <limit effort="1" velocity="20" lower="-1.9198621771937625091" upper="2.4434609527920612138"/>
    <joint_properties friction="0.0"/>
  </joint>
  <joint name="left_sho_yaw_fixed" type="fixed">
    <origin xyz="3.4694469519536141888e-18 -9.8607613152626475676e-31 0.0015999999999999972577" rpy="3.141592653589793116 1.2621774483536197294e-29 4.7331654313260743357e-30"/>
    <parent link="spur_1m_24t_driven"/>
    <child link="sho_yaw_link"/>
    <axis xyz="0 0 1"/>
    <limit effort="1" velocity="20"/>
    <joint_properties friction="0.0"/>
  </joint>
  <joint name="left_sho_yaw_driven" type="revolute">
    <origin xyz="-3.5807158627054747058e-10 -0.02700000015245348009 -0.018999999999996589062" rpy="1.5707963267947120389 -1.3118271136488182808e-14 9.2981178312429448086e-14"/>
    <parent link="2xl430_gears"/>
    <child link="spur_1m_24t_driven"/>
    <axis xyz="0 0 1"/>
    <limit effort="1" velocity="20" lower="-2.6179938779914944114" upper="2.6179938779914944114"/>
    <joint_properties friction="0.0"/>
  </joint>
  <joint name="left_sho_roll" type="revolute">
    <origin xyz="-0.019000000000000016875 1.4231671397091401999e-17 0.027000000000000023981" rpy="-3.141592653589793116 1.5707963267948372721 0"/>
    <parent link="sho_pitch_link"/>
    <child link="2xl430_gears"/>
    <axis xyz="0 0 1"/>
    <limit effort="1" velocity="20" lower="-1.570796326794896558" upper="0.34906585039886589561"/>
    <joint_properties friction="0.0"/>
  </joint>
  <link name="sho_pitch_link_2">
    <visual>
      <origin xyz="0 0 0" rpy="0 -0 0"/>
      <geometry>
        <mesh filename="../assemblies/right_arm_umi/meshes/right_sho_pitch_link_visual.stl"/>
      </geometry>
      <material name="sho_pitch_link_material">
        <color rgba="0.61568627450980395466 0.81176470588235294379 0.92941176470588227065 1.0"/>
      </material>
    </visual>
    <inertial>
      <origin xyz="-1.025903438159899119e-18 -2.1966078074444289517e-18 0.012913250798677602602" rpy="0 0 0"/>
      <mass value="0.0085999999999999982708"/>
      <inertia ixx="1.8365636406635814379e-06" ixy="2.7052466620977967735e-97" ixz="-6.0867229013657688598e-136" iyy="4.0110869076839152165e-06" iyz="-1.6935833339184753197e-44" izz="3.5160516450492493809e-06"/>
    </inertial>
  </link>
  <link name="2xl430_gears_4">
    <visual>
      <origin xyz="0 0 0" rpy="0 -0 0"/>
      <geometry>
        <mesh filename="../assemblies/right_arm_umi/meshes/right_2xl430_gears_visual.stl"/>
      </geometry>
      <material name="2xl430_gears_material">
        <color rgba="0.75914767920569214965 0.85560384745670925444 0.90519468321360607721 1.0"/>
      </material>
    </visual>
    <collision name="2xl430_gears_4_collision">
      <origin xyz="-0.01170851145356234 -0.002663695648909648 -0.019869671274007784" rpy="0 0 0"/>
      <geometry>
        <sphere radius="0.031174628050041002"/>
      </geometry>
    </collision>
    <inertial>
      <origin xyz="-0.011592905737978696085 -0.0024238553642522840843 -0.018551095523803726173" rpy="0 0 0"/>
      <mass value="0.11800003674524911501"/>
      <inertia ixx="2.7511021050424646017e-05" ixy="9.0043904315135573925e-07" ixz="-2.3349710123960218718e-08" iyy="3.2796197843346207182e-05" iyz="-6.5715119654693386146e-07" izz="3.5775739835740998952e-05"/>
    </inertial>
  </link>
  <link name="spur_1m_24t_drive_4">
    <visual>
      <origin xyz="0 0 0" rpy="0 -0 0"/>
      <geometry>
        <mesh filename="../assemblies/right_arm_umi/meshes/right_spur_1m_24t_drive_visual.stl"/>
      </geometry>
      <material name="spur_1m_24t_drive_material">
        <color rgba="0.61568627450980395466 0.81176470588235294379 0.92941176470588238168 1.0"/>
      </material>
    </visual>
    <inertial>
      <origin xyz="3.0326032612408354263e-15 -3.3912620811388938008e-16 0.0048096451474093030592" rpy="0 0 0"/>
      <mass value="0.0031999999999999997197"/>
      <inertia ixx="1.4097598887016958673e-07" ixy="1.556282310200251252e-15" ixz="3.9554371954665940773e-37" iyy="1.4097598803635998845e-07" iyz="-1.3068306635892902166e-36" izz="2.4107776386988835496e-07"/>
    </inertial>
  </link>
  <joint name="right_sho_yaw_drive" type="revolute">
    <origin xyz="-0.024000000716138267243 -0.019000000152445337132 -0.019000000152448424939" rpy="1.5707963267949289765 -7.4062049324254792929e-14 1.9645226351351914911e-14"/>
    <parent link="2xl430_gears_4"/>
    <child link="spur_1m_24t_drive_4"/>
    <axis xyz="0 0 1"/>
    <limit effort="1" velocity="20" lower="-2.6179938779914944114" upper="2.6179938779914944114"/>
    <joint_properties friction="0.0"/>
  </joint>
  <link name="spur_1m_24t_driven_4">
    <visual>
      <origin xyz="0 0 0" rpy="0 -0 0"/>
      <geometry>
        <mesh filename="../assemblies/right_arm_umi/meshes/right_spur_1m_24t_driven_visual.stl"/>
      </geometry>
      <material name="spur_1m_24t_driven_material">
        <color rgba="0.23137254901960788156 0.38039215686274502337 0.7058823529411765163 1.0"/>
      </material>
    </visual>
    <inertial>
      <origin xyz="-2.690304390834019776e-18 -1.6883842059581361246e-15 -0.00097237500038395777158" rpy="0 0 0"/>
      <mass value="0.0026999999999999997093"/>
      <inertia ixx="1.2202334915684080498e-07" ixy="0" ixz="0" iyy="1.2202334915684064616e-07" iyz="-3.1611202962161956801e-37" izz="2.3180293204341252239e-07"/>
    </inertial>
  </link>
  <link name="sho_yaw_link_2">
    <visual>
      <origin xyz="0 0 0" rpy="0 -0 0"/>
      <geometry>
        <mesh filename="../assemblies/right_arm_umi/meshes/right_sho_yaw_link_visual.stl"/>
      </geometry>
      <material name="sho_yaw_link_material">
        <color rgba="0.61568627450980395466 0.81176470588235294379 0.92941176470588238168 1.0"/>
      </material>
    </visual>
    <inertial>
      <origin xyz="-1.3035740535093626537e-18 2.6069328434162263936e-18 -0.024649285094360089132" rpy="0 0 0"/>
      <mass value="0.014500000000000007674"/>
      <inertia ixx="9.2365904614004439553e-06" ixy="3.5862833440690451918e-13" ixz="3.9137616104652588598e-44" iyy="5.8163826335078791714e-06" iyz="-5.7710285861749289932e-36" izz="4.5074356741562122031e-06"/>
    </inertial>
  </link>
  <link name="2xl430_gears_5">
    <visual>
      <origin xyz="0 0 0" rpy="0 -0 0"/>
      <geometry>
        <mesh filename="../assemblies/right_arm_umi/meshes/right_2xl430_gears_2_visual.stl"/>
      </geometry>
      <material name="2xl430_gears_2_material">
        <color rgba="0.75914767920569214965 0.85560384745670925444 0.90519468321360607721 1.0"/>
      </material>
    </visual>
    <collision name="2xl430_gears_5_collision">
      <origin xyz="-0.011708886637741642 -0.002663752496014671 -0.019869324751325072" rpy="0 0 0"/>
      <geometry>
        <sphere radius="0.031174264351886416"/>
      </geometry>
    </collision>
    <inertial>
      <origin xyz="-0.011592905737984599349 -0.0024238553642520702797 -0.018551095523805894577" rpy="0 0 0"/>
      <mass value="0.11800003674524911501"/>
      <inertia ixx="2.7511021050426058868e-05" ixy="9.0043904315050701224e-07" ixz="-2.3349710123665345373e-08" iyy="3.2796197843347223622e-05" iyz="-6.5715119654724493431e-07" izz="3.5775739835742266114e-05"/>
    </inertial>
  </link>
  <link name="spur_1m_24t_drive_5">
    <visual>
      <origin xyz="0 0 0" rpy="0 -0 0"/>
      <geometry>
        <mesh filename="../assemblies/right_arm_umi/meshes/right_spur_1m_24t_drive_2_visual.stl"/>
      </geometry>
      <material name="spur_1m_24t_drive_2_material">
        <color rgba="0.61568627450980395466 0.81176470588235294379 0.92941176470588238168 1.0"/>
      </material>
    </visual>
    <inertial>
      <origin xyz="3.0326032612408362152e-15 -3.3912620813973872492e-16 0.0048096451474092995898" rpy="0 0 0"/>
      <mass value="0.0031999999999999997197"/>
      <inertia ixx="1.409759888701696132e-07" ixy="1.556282310200251252e-15" ixz="4.338399461542561307e-37" iyy="1.4097598803635998845e-07" iyz="-1.6678098941986840071e-37" izz="2.4107776386988835496e-07"/>
    </inertial>
  </link>
  <joint name="right_elbow_yaw_drive" type="revolute">
    <origin xyz="-0.024000000716147169844 -0.019000000152450874369 -0.019000000152450294971" rpy="1.5707963267949571762 3.0057922366849630622e-14 -3.9474149714292987702e-14"/>
    <parent link="2xl430_gears_5"/>
    <child link="spur_1m_24t_drive_5"/>
    <axis xyz="0 0 1"/>
    <limit effort="1" velocity="20" lower="-2.6179938779914944114" upper="2.6179938779914944114"/>
    <joint_properties friction="0.0"/>
  </joint>
  <link name="spur_1m_24t_driven_5">
    <visual>
      <origin xyz="0 0 0" rpy="0 -0 0"/>
      <geometry>
        <mesh filename="../assemblies/right_arm_umi/meshes/right_spur_1m_24t_driven_2_visual.stl"/>
      </geometry>
      <material name="spur_1m_24t_driven_2_material">
        <color rgba="0.23137254901960788156 0.38039215686274502337 0.7058823529411765163 1.0"/>
      </material>
    </visual>
    <inertial>
      <origin xyz="7.7914256111959441279e-19 -1.6883842059581375051e-15 -0.00097237500038395083268" rpy="0 0 0"/>
      <mass value="0.0026999999999999997093"/>
      <inertia ixx="1.2202334915684080498e-07" ixy="3.8503779869585959908e-37" ixz="-5.0252529353177568274e-67" iyy="1.2202334915684064616e-07" iyz="-1.5292377512497484237e-36" izz="2.3180293204341252239e-07"/>
    </inertial>
  </link>
  <link name="elb_yaw_link_2">
    <visual>
      <origin xyz="0 0 0" rpy="0 -0 0"/>
      <geometry>
        <mesh filename="../assemblies/right_arm_umi/meshes/right_elb_yaw_link_visual.stl"/>
      </geometry>
      <material name="elb_yaw_link_material">
        <color rgba="0.61568627450980395466 0.81176470588235294379 0.92941176470588227065 1.0"/>
      </material>
    </visual>
    <inertial>
      <origin xyz="5.3127688027774929136e-08 0.0019833638641961613865 -0.023416643551549952418" rpy="0 0 0"/>
      <mass value="0.017500000000000005135"/>
      <inertia ixx="1.4134344903109199776e-05" ixy="1.6945783922006116668e-12" ixz="-1.1286398721833140765e-11" iyy="6.6435900776211340404e-06" iyz="1.0545227077253051227e-06" izz="8.9925290757998993713e-06"/>
    </inertial>
  </link>
  <link name="spur_1m_24t_driven_6">
    <visual>
      <origin xyz="0 0 0" rpy="0 -0 0"/>
      <geometry>
        <mesh filename="../assemblies/right_arm_umi/meshes/right_spur_1m_24t_driven_3_visual.stl"/>
      </geometry>
      <material name="spur_1m_24t_driven_3_material">
        <color rgba="0.23137254901960788156 0.38039215686274502337 0.7058823529411765163 1.0"/>
      </material>
    </visual>
    <inertial>
      <origin xyz="2.5065271224794893349e-17 -1.6883842059581341524e-15 -0.0025723750003839550293" rpy="0 0 0"/>
      <mass value="0.0026999999999999997093"/>
      <inertia ixx="1.2202334915684080498e-07" ixy="1.2024235126300529745e-36" ixz="-1.9251889934793005011e-37" iyy="1.2202334915684064616e-07" iyz="-6.5691309546560350094e-67" izz="2.3180293204341252239e-07"/>
    </inertial>
  </link>
  <link name="2xl430_gears_6">
    <visual>
      <origin xyz="0 0 0" rpy="0 -0 0"/>
      <geometry>
        <mesh filename="../assemblies/right_arm_umi/meshes/right_2xl430_gears_3_visual.stl"/>
      </geometry>
      <material name="2xl430_gears_3_material">
        <color rgba="0.75914767920569214965 0.85560384745670925444 0.90519468321360607721 1.0"/>
      </material>
    </visual>
    <collision name="2xl430_gears_6_collision">
      <origin xyz="-0.0008536254376340004 0.01171871446801601 -0.024337078544579577" rpy="0 0 0"/>
      <geometry>
        <sphere radius="0.031160574725534955"/>
      </geometry>
    </collision>
    <inertial>
      <origin xyz="0.00044890447620015019132 0.011592905379911784894 -0.024576144788197196167" rpy="0 0 0"/>
      <mass value="0.11800003674524911501"/>
      <inertia ixx="3.5775739835742767557e-05" ixy="2.3349710123598476092e-08" ixz="6.5715119654677461927e-07" iyy="2.7511021050425875909e-05" iyz="9.0043904315183473638e-07" izz="3.2796197843346695073e-05"/>
    </inertial>
  </link>
  <link name="spur_1m_24t_drive_6">
    <visual>
      <origin xyz="0 0 0" rpy="0 -0 0"/>
      <geometry>
        <mesh filename="../assemblies/right_arm_umi/meshes/right_spur_1m_24t_drive_3_visual.stl"/>
      </geometry>
      <material name="spur_1m_24t_drive_3_material">
        <color rgba="0.61568627450980395466 0.81176470588235294379 0.92941176470588238168 1.0"/>
      </material>
    </visual>
    <inertial>
      <origin xyz="3.0326032612408354263e-15 -3.3912620813973872492e-16 0.0048096451474093030592" rpy="0 0 0"/>
      <mass value="0.0031999999999999997197"/>
      <inertia ixx="1.4097598887016958673e-07" ixy="1.556282310200251252e-15" ixz="2.126004267201905483e-36" iyy="1.4097598803635998845e-07" iyz="9.9024180490680084723e-38" izz="2.4107776386988835496e-07"/>
    </inertial>
  </link>
  <joint name="right_wrist_pitch_drive" type="revolute">
    <origin xyz="-1.5244312511681577095e-10 0.024000000358071760242 -0.0080000000000008727324" rpy="1.2483159056391235944e-14 7.3485321852726251993e-14 -1.5707963267948601427"/>
    <parent link="2xl430_gears_6"/>
    <child link="spur_1m_24t_drive_6"/>
    <axis xyz="0 0 1"/>
    <limit effort="1" velocity="20" lower="-1.3962634015954635824" upper="1.9198621771937625091"/>
    <joint_properties friction="0.0"/>
  </joint>
  <link name="hand_2">
    <visual>
      <origin xyz="0 0 0" rpy="0 -0 0"/>
      <geometry>
        <mesh filename="../assemblies/right_arm_umi/meshes/right_hand_visual.stl"/>
      </geometry>
      <material name="hand_material">
        <color rgba="0.64149913129808888712 0.67624720774385704836 0.69709605361131798951 1.0"/>
      </material>
    </visual>
    <collision name="hand_2_collision">
      <origin xyz="0.0044999998062849045 -0.023250000085681677 -0.019000000320374966" rpy="0 0 0"/>
      <geometry>
        <box size="0.05000000074505806 0.06749999988824129 0.07400000281631947"/>
      </geometry>
    </collision>
    <inertial>
      <origin xyz="0.0037132560777026289017 -0.042135580180293688568 -0.018486870577627653039" rpy="0 0 0"/>
      <mass value="0.039499999999999986511"/>
      <inertia ixx="2.4655505305535363534e-05" ixy="6.2292690365591920186e-07" ixz="-1.3905201231125071739e-08" iyy="2.5499495708696273439e-05" iyz="4.048228436147507821e-08" izz="1.3476712280060871749e-05"/>
    </inertial>
  </link>
  <joint name="right_wrist_roll" type="revolute">
    <origin xyz="0.019000000000002754269 -3.5806785314562716849e-10 -0.02700000015244990656" rpy="3.4259954561441936844e-30 1.5707963267948314989 0"/>
    <parent link="2xl430_gears_6"/>
    <child link="hand_2"/>
    <axis xyz="0 0 1"/>
    <limit effort="1" velocity="20" lower="-1.3962634015954635824" upper="1.9198621771937625091"/>
    <joint_properties friction="0.0"/>
  </joint>
  <link name="wrist_bearing_plate_2">
    <visual>
      <origin xyz="0 0 0" rpy="0 -0 0"/>
      <geometry>
        <mesh filename="../assemblies/right_arm_umi/meshes/right_wrist_bearing_plate_visual.stl"/>
      </geometry>
      <material name="wrist_bearing_plate_material">
        <color rgba="0.71932243125689054875 0.63128434304969727187 0.52422389360984933404 1.0"/>
      </material>
    </visual>
    <inertial>
      <origin xyz="-0.0075835583121499862067 -0.015499999999999977338 -0.0018386323705903283732" rpy="0 0 0"/>
      <mass value="0.0049000367468305557062"/>
      <inertia ixx="4.9707430109150118544e-07" ixy="8.4884857117213009255e-23" ixz="1.8100904820814061718e-08" iyy="7.1268523603538553059e-07" iyz="4.7142878042649513411e-24" izz="1.1919657811600107117e-06"/>
    </inertial>
  </link>
  <joint name="right_wrist_pitch_fixed" type="fixed">
    <origin xyz="0.015500000000003963732 4.5519144009631418157e-15 -0.04500000000000373146" rpy="-3.0531133177156822825e-15 1.2051470932306205513e-13 -1.570796326794896558"/>
    <parent link="2xl430_gears_6"/>
    <child link="wrist_bearing_plate_2"/>
    <axis xyz="0 0 1"/>
    <limit effort="1" velocity="20"/>
    <joint_properties friction="0.0"/>
  </joint>
  <joint name="right_wrist_pitch_driven" type="revolute">
    <origin xyz="2.7755575615628913511e-17 3.1554436208840472216e-30 -0.0015999999999999972577" rpy="-3.8285686988021856593e-16 -1.2621774483536197294e-29 1.570796326794896558"/>
    <parent link="spur_1m_24t_driven_6"/>
    <child link="2xl430_gears_6"/>
    <axis xyz="0 0 1"/>
    <limit effort="1" velocity="20" lower="-1.9198621771937625091" upper="1.3962634015954635824"/>
    <joint_properties friction="0.0"/>
  </joint>
  <joint name="right_wrist_roll_fixed" type="fixed">
    <origin xyz="3.9443045261050590271e-30 -0.025299999999999999573 -0.051999999999999976796" rpy="1.570796326794896558 1.570796326794896558 0"/>
    <parent link="elb_yaw_link_2"/>
    <child link="spur_1m_24t_driven_6"/>
    <axis xyz="0 0 1"/>
    <limit effort="1" velocity="20"/>
    <joint_properties friction="0.0"/>
  </joint>
  <joint name="right_elbow_yaw_fixed" type="fixed">
    <origin xyz="3.4694469519536141888e-18 0 0.0016000000000000180744" rpy="3.141592653589793116 5.5511151240344703462e-17 -1.57079632679489678"/>
    <parent link="spur_1m_24t_driven_5"/>
    <child link="elb_yaw_link_2"/>
    <axis xyz="0 0 1"/>
    <limit effort="1" velocity="20"/>
    <joint_properties friction="0.0"/>
  </joint>
  <joint name="right_elbow_yaw_driven" type="revolute">
    <origin xyz="-3.5807115952857238028e-10 -0.027000000152453032531 -0.01900000000000281325" rpy="1.5707963267949576203 3.0519690799675378401e-14 -4.0239863453830675462e-14"/>
    <parent link="2xl430_gears_5"/>
    <child link="spur_1m_24t_driven_5"/>
    <axis xyz="0 0 1"/>
    <limit effort="1" velocity="20" lower="-2.6179938779914944114" upper="2.6179938779914944114"/>
    <joint_properties friction="0.0"/>
  </joint>
  <joint name="right_elbow_roll" type="revolute">
    <origin xyz="0 -0.018999999999999999528 -0.059000000000000024647" rpy="1.5707963267948952257 -4.3465231414242792334e-14 -2.6978419498660684154e-14"/>
    <parent link="sho_yaw_link_2"/>
    <child link="2xl430_gears_5"/>
    <axis xyz="0 0 1"/>
    <limit effort="1" velocity="20" lower="-1.9198621771937625091" upper="2.4434609527920612138"/>
    <joint_properties friction="0.0"/>
  </joint>
  <joint name="right_sho_yaw_fixed" type="fixed">
    <origin xyz="0 3.9443045261050590271e-31 0.0015999999999999972577" rpy="3.141592653589793116 -5.0487097934144755546e-29 -1.8301573001127473886e-28"/>
    <parent link="spur_1m_24t_driven_4"/>
    <child link="sho_yaw_link_2"/>
    <axis xyz="0 0 1"/>
    <limit effort="1" velocity="20"/>
    <joint_properties friction="0.0"/>
  </joint>
  <joint name="right_sho_yaw_driven" type="revolute">
    <origin xyz="-3.5806816886529979627e-10 -0.027000000152446666096 -0.019000000000003354483" rpy="1.5707963267949260899 -2.2055090607973039157e-14 7.6050277186033683693e-15"/>
    <parent link="2xl430_gears_4"/>
    <child link="spur_1m_24t_driven_4"/>
    <axis xyz="0 0 1"/>
    <limit effort="1" velocity="20" lower="-2.6179938779914944114" upper="2.6179938779914944114"/>
    <joint_properties friction="0.0"/>
  </joint>
  <joint name="right_sho_roll" type="revolute">
    <origin xyz="-0.018999999999999999528 9.3241386833306442318e-18 0.027000000000000006634" rpy="3.141592653589793116 1.5707963267948952257 0"/>
    <parent link="sho_pitch_link_2"/>
    <child link="2xl430_gears_4"/>
    <axis xyz="0 0 1"/>
    <limit effort="1" velocity="20" lower="-1.570796326794896558" upper="0.34906585039886589561"/>
    <joint_properties friction="0.0"/>
  </joint>
</robot>