<?xml version="1.0" ?><robot name="right_leg_2xm">  
  <link name="right_hip_pitch_link">    
    <visual>      
      <origin xyz="0 0 0" rpy="0 -0 0"/>      
      <geometry>        
        <mesh filename="package:///meshes/right_hip_pitch_link_visual.stl"/>        
      </geometry>      
      <material name="right_hip_pitch_link_material">        
        <color rgba="0.92982090412552342862 0.72254076531321620447 0.12744144951766167573 1.0"/>        
      </material>      
    </visual>    
    <collision>      
      <origin xyz="0 0 0" rpy="0 -0 0"/>      
      <geometry>        
        <mesh filename="package:///meshes/right_hip_pitch_link_collision.stl"/>        
      </geometry>      
    </collision>    
    <inertial>      
      <origin xyz="-0.01170635067017833375 -0.019742757686486544361 -0.018808249759672979878" rpy="0 0 0"/>      
      <mass value="0.19376376696210850792"/>      
      <inertia ixx="0.00011804182389326951623" ixy="1.5895078464523899925e-06" ixz="-3.0802177008483233797e-08" iyy="5.1585603979825105493e-05" iyz="-5.5648114095732285423e-07" izz="0.00013525831068322282606"/>      
    </inertial>    
  </link>  

  <link name="hip_yaw_link">    
    <visual>      
      <origin xyz="0 0 0" rpy="0 -0 0"/>      
      <geometry>        
        <mesh filename="package:///meshes/right_hip_yaw_link_visual.stl"/>        
      </geometry>      
      <material name="hip_yaw_link_material">        
        <color rgba="0.61568627450980395466 0.81176470588235294379 0.92941176470588238168 1.0"/>        
      </material>      
    </visual>    
    <collision>      
      <origin xyz="0 0 0" rpy="0 -0 0"/>      
      <geometry>        
        <mesh filename="package:///meshes/right_hip_yaw_link_collision.stl"/>        
      </geometry>      
    </collision>    
    <inertial>      
      <origin xyz="-1.135134077016976863e-06 0.01638248194604985386 0.024904960957045241959" rpy="0 0 0"/>      
      <mass value="0.013199999999999989519"/>      
      <inertia ixx="6.216463024575245722e-06" ixy="1.711222792995633328e-10" ixz="2.3737014581360037789e-10" iyy="5.5106440267526434637e-06" iyz="8.1727857918858932185e-08" izz="2.6855910648547497853e-06"/>      
    </inertial>    
  </link>  

  <link name="spur_gear_21_teeth">    
    <visual>      
      <origin xyz="0 0 0" rpy="0 -0 0"/>      
      <geometry>        
        <mesh filename="package:///meshes/right_spur_gear_21_teeth_visual.stl"/>        
      </geometry>      
      <material name="spur_gear_21_teeth_material">        
        <color rgba="0.61568627450980395466 0.81176470588235294379 0.9294117647058824927 1.0"/>        
      </material>      
    </visual>    
    <collision>      
      <origin xyz="0 0 0" rpy="0 -0 0"/>      
      <geometry>        
        <mesh filename="package:///meshes/right_spur_gear_21_teeth_collision.stl"/>        
      </geometry>      
    </collision>    
    <inertial>      
      <origin xyz="-4.5505288977337882293e-11 -1.6782163717306987843e-11 -0.0024924102006250539211" rpy="0 0 0"/>      
      <mass value="0.0021999999999999996989"/>      
      <inertia ixx="7.0162310059594183647e-08" ixy="6.9185379282510963078e-39" ixz="5.5122342094673161746e-40" iyy="7.016231005804743531e-08" iyz="-1.9797591643880531248e-71" izz="1.3125544198538286659e-07"/>      
    </inertial>    
  </link>  

  <link name="right_thigh_link">    
    <visual>      
      <origin xyz="0 0 0" rpy="0 -0 0"/>      
      <geometry>        
        <mesh filename="package:///meshes/right_thigh_link_visual.stl"/>        
      </geometry>      
      <material name="right_thigh_link_material">        
        <color rgba="0.81231119922470296224 0.7131158892107314351 0.33680089849959454762 1.0"/>        
      </material>      
    </visual>    
    <collision>      
      <origin xyz="0 0 0" rpy="0 -0 0"/>      
      <geometry>        
        <mesh filename="package:///meshes/right_thigh_link_collision.stl"/>        
      </geometry>      
    </collision>    
    <inertial>      
      <origin xyz="0.010187905578010832477 -0.0056188467228509399523 0.038815928333491692137" rpy="0 0 0"/>      
      <mass value="0.14548965119785953193"/>      
      <inertia ixx="7.0942049594865160683e-05" ixy="1.1158758975155788993e-06" ixz="7.6515558781285007971e-06" iyy="8.515739880291365064e-05" iyz="1.069933739907198978e-06" izz="4.0945306935232121995e-05"/>      
    </inertial>    
  </link>  

  <link name="spur_gear_18_teeth">    
    <visual>      
      <origin xyz="0 0 0" rpy="0 -0 0"/>      
      <geometry>        
        <mesh filename="package:///meshes/right_spur_gear_18_teeth_visual.stl"/>        
      </geometry>      
      <material name="spur_gear_18_teeth_material">        
        <color rgba="0.61568627450980395466 0.81176470588235294379 0.92941176470588238168 1.0"/>        
      </material>      
    </visual>    
    <collision>      
      <origin xyz="0 0 0" rpy="0 -0 0"/>      
      <geometry>        
        <mesh filename="package:///meshes/right_spur_gear_18_teeth_collision.stl"/>        
      </geometry>      
    </collision>    
    <inertial>      
      <origin xyz="1.1201704073225982176e-18 -1.2342259190192713513e-17 0.0017499999999999922302" rpy="0 0 0"/>      
      <mass value="0.0012000000000000001117"/>      
      <inertia ixx="2.9545593202975796841e-08" ixy="1.2382036808367865321e-38" ixz="4.6295946344312827085e-37" iyy="2.9545593202975872942e-08" iyz="-1.1444185360592795855e-38" izz="5.6662838285388571446e-08"/>      
    </inertial>    
  </link>  

  <joint name="right_hip_yaw_drive" type="revolute">    
    <origin xyz="0.019200000000000608941 0.00019999999999991205368 -3.986394547794702703e-14" rpy="-3.1415926535897487071 -3.3554531021644002431e-13 4.6155381424903106362e-13"/>    
    <parent link="right_thigh_link"/>    
    <child link="spur_gear_18_teeth"/>    
    <axis xyz="0 0 1"/>    
    <limit effort="1" velocity="20" lower="-1.8325957145940461324" upper="1.8325957145940461324"/>    
    <joint_properties friction="0.0"/>    
  </joint>  

  <link name="right_calf_link">    
    <visual>      
      <origin xyz="0 0 0" rpy="0 -0 0"/>      
      <geometry>        
        <mesh filename="package:///meshes/right_calf_link_visual.stl"/>        
      </geometry>      
      <material name="right_calf_link_material">        
        <color rgba="0.61568627450980395466 0.81176470588235294379 0.92941176470588238168 1.0"/>        
      </material>      
    </visual>    
    <collision>      
      <origin xyz="0 0 0" rpy="0 -0 0"/>      
      <geometry>        
        <mesh filename="package:///meshes/right_calf_link_collision.stl"/>        
      </geometry>      
    </collision>    
    <inertial>      
      <origin xyz="-0.0043450054394401412677 -0.040752982164757395322 0.0087116093514751861276" rpy="0 0 0"/>      
      <mass value="0.0309999999999999859"/>      
      <inertia ixx="3.3069388685436868305e-05" ixy="1.3783307152005356137e-06" ixz="-1.2742534017148746522e-07" iyy="7.7316525337489631496e-06" iyz="7.3356500737981874876e-08" izz="2.8031377754211893143e-05"/>      
    </inertial>    
  </link>  

  <link name="bearing_683">    
    <visual>      
      <origin xyz="0 0 0" rpy="0 -0 0"/>      
      <geometry>        
        <mesh filename="package:///meshes/right_bearing_683_visual.stl"/>        
      </geometry>      
      <material name="bearing_683_material">        
        <color rgba="0.64705882352941179736 0.64705882352941179736 0.64705882352941179736 1.0"/>        
      </material>      
    </visual>    
    <collision>      
      <origin xyz="0 0 0" rpy="0 -0 0"/>      
      <geometry>        
        <mesh filename="package:///meshes/right_bearing_683_collision.stl"/>        
      </geometry>      
    </collision>    
    <inertial>      
      <origin xyz="-2.7648254672676539312e-17 6.2549399515680128509e-19 -0.0015500000000000003792" rpy="0 0 0"/>      
      <mass value="0.00048694686130641793437"/>      
      <inertia ixx="2.1551456503319887385e-09" ixy="5.938329734254552816e-29" ixz="4.2234669276366031341e-39" iyy="2.1551456503319883249e-09" iyz="-6.7335134926202872924e-41" izz="3.5303647444715305817e-09"/>      
    </inertial>    
  </link>  

  <joint name="right_knee_front_rev_2" type="revolute">    
    <origin xyz="0.0057402514854763718108 -0.013858192987669770702 0.026200000000000028821" rpy="3.141592653589793116 4.7532333134949093273e-16 1.5719104681400370982"/>    
    <parent link="right_calf_link"/>    
    <child link="bearing_683"/>    
    <axis xyz="0 0 1"/>    
    <limit effort="1" velocity="20"/>    
    <joint_properties friction="0.0"/>    
  </joint>  

  <link name="bearing_683_2">    
    <visual>      
      <origin xyz="0 0 0" rpy="0 -0 0"/>      
      <geometry>        
        <mesh filename="package:///meshes/right_bearing_683_2_visual.stl"/>        
      </geometry>      
      <material name="bearing_683_2_material">        
        <color rgba="0.64705882352941179736 0.64705882352941179736 0.64705882352941179736 1.0"/>        
      </material>      
    </visual>    
    <collision>      
      <origin xyz="0 0 0" rpy="0 -0 0"/>      
      <geometry>        
        <mesh filename="package:///meshes/right_bearing_683_2_collision.stl"/>        
      </geometry>      
    </collision>    
    <inertial>      
      <origin xyz="-2.7648254672676536231e-17 -2.4186774283160226211e-19 -0.0015500000000000003792" rpy="0 0 0"/>      
      <mass value="0.00048694686130641793437"/>      
      <inertia ixx="2.1551456503319887385e-09" ixy="-2.4504277341214625333e-28" ixz="3.3901768108754338424e-41" iyy="2.1551456503319883249e-09" iyz="5.4755107341247360049e-60" izz="3.5303647444715305817e-09"/>      
    </inertial>    
  </link>  

  <joint name="right_knee_back_rev_2" type="revolute">    
    <origin xyz="-0.0057402514854763934948 0.013858192987669021301 0.026199999999999980249" rpy="3.1415926535897922278 -1.6769178092422380047e-15 1.5719169850876628658"/>    
    <parent link="right_calf_link"/>    
    <child link="bearing_683_2"/>    
    <axis xyz="0 0 1"/>    
    <limit effort="1" velocity="20"/>    
    <joint_properties friction="0.0"/>    
  </joint>  

  <link name="right_ank_pitch_link">    
    <visual>      
      <origin xyz="0 0 0" rpy="0 -0 0"/>      
      <geometry>        
        <mesh filename="package:///meshes/right_ank_pitch_link_visual.stl"/>        
      </geometry>      
      <material name="right_ank_pitch_link_material">        
        <color rgba="0.70321688500203327621 0.64514870846184446673 0.40484735422826279017 1.0"/>        
      </material>      
    </visual>    
    <collision>      
      <origin xyz="0 0 0" rpy="0 -0 0"/>      
      <geometry>        
        <mesh filename="package:///meshes/right_ank_pitch_link_collision.stl"/>        
      </geometry>      
    </collision>    
    <inertial>      
      <origin xyz="-0.01777042274983306816 0.012417933919336260687 0.018814514831173693304" rpy="0 0 0"/>      
      <mass value="0.17676376695067899658"/>      
      <inertia ixx="4.7033279140152881915e-05" ixy="5.8981907474083015582e-07" ixz="6.1533221595097461637e-07" iyy="0.00010706754769297033216" iyz="-5.2427772221904961753e-08" izz="0.00012159782212990462183"/>      
    </inertial>    
  </link>  

  <link name="ank_roll_link">    
    <visual>      
      <origin xyz="0 0 0" rpy="0 -0 0"/>      
      <geometry>        
        <mesh filename="package:///meshes/right_ank_roll_link_visual.stl"/>        
      </geometry>      
      <material name="ank_roll_link_material">        
        <color rgba="0.61568627450980395466 0.81176470588235294379 0.92941176470588238168 1.0"/>        
      </material>      
    </visual>    
    <collision>      
      <origin xyz="0 0 0" rpy="0 -0 0"/>      
      <geometry>        
        <mesh filename="package:///meshes/right_ank_roll_link_collision.stl"/>        
      </geometry>      
    </collision>    
    <inertial>      
      <origin xyz="-0.026987231947660686449 5.6532512304029935813e-13 0.033766671354451605058" rpy="0 0 0"/>      
      <mass value="0.042599999999999998979"/>      
      <inertia ixx="3.7149943594118530626e-05" ixy="1.9666667662832936347e-17" ixz="2.3895918372292815406e-06" iyy="3.7472718057541049203e-05" iyz="7.8258680124225771449e-12" izz="1.0051685129153372671e-05"/>      
    </inertial>    
  </link>  

  <joint name="right_ank_roll" type="revolute">    
    <origin xyz="-0.022749999999990028199 -3.5249581031848720158e-15 0.018999999999999451356" rpy="1.5707963267948190644 2.082200812017336445e-14 1.5707963267948397146"/>    
    <parent link="right_ank_pitch_link"/>    
    <child link="ank_roll_link"/>    
    <axis xyz="0 0 1"/>    
    <limit effort="1" velocity="20" lower="-1.570796326794896558" upper="1.570796326794896558"/>    
    <joint_properties friction="0.0"/>    
  </joint>  

  <joint name="right_ank_pitch" type="revolute">    
    <origin xyz="3.5236570605778894105e-17 -0.09999999999999995004 0.027749999999999993422" rpy="-3.1415926535897917837 -7.8513249565814058339e-16 -3.1415926535897864547"/>    
    <parent link="right_calf_link"/>    
    <child link="right_ank_pitch_link"/>    
    <axis xyz="0 0 1"/>    
    <limit effort="1" velocity="20" lower="-0.785398163397448279" upper="1.7453292519943295336"/>    
    <joint_properties friction="0.0"/>    
  </joint>  

  <joint name="right_knee" type="revolute">    
    <origin xyz="9.915028867379938049e-17 -0.0087500000000001326717 0.085950000000000637002" rpy="-1.57079632679489678 -1.8596235662471439105e-15 -1.7091941954032421329e-15"/>    
    <parent link="right_thigh_link"/>    
    <child link="right_calf_link"/>    
    <axis xyz="0 0 1"/>    
    <limit effort="1" velocity="20" lower="0" upper="1.570796326794896558"/>    
    <joint_properties friction="0.0"/>    
  </joint>  

  <link name="xm430_plate">    
    <visual>      
      <origin xyz="0 0 0" rpy="0 -0 0"/>      
      <geometry>        
        <mesh filename="package:///meshes/right_xm430_plate_visual.stl"/>        
      </geometry>      
      <material name="xm430_plate_material">        
        <color rgba="0.61568627450980395466 0.81176470588235294379 0.92941176470588227065 1.0"/>        
      </material>      
    </visual>    
    <collision>      
      <origin xyz="0 0 0" rpy="0 -0 0"/>      
      <geometry>        
        <mesh filename="package:///meshes/right_xm430_plate_collision.stl"/>        
      </geometry>      
    </collision>    
    <inertial>      
      <origin xyz="-1.0678768463071413547e-18 -2.7932101897381823422e-18 0.0025278513919583835146" rpy="0 0 0"/>      
      <mass value="0.0026999999999999997093"/>      
      <inertia ixx="2.4635091298412528789e-07" ixy="5.8739562556303540361e-08" ixz="-6.1340137510844996234e-39" iyy="1.2887178787151819394e-07" iyz="3.0966973396831916887e-38" izz="3.646799841381030595e-07"/>      
    </inertial>    
  </link>  

  <link name="knee_rod">    
    <visual>      
      <origin xyz="0 0 0" rpy="0 -0 0"/>      
      <geometry>        
        <mesh filename="package:///meshes/right_knee_rod_visual.stl"/>        
      </geometry>      
      <material name="knee_rod_material">        
        <color rgba="0.62051618944235198416 0.78640765248647581664 0.88594253031295022716 1.0"/>        
      </material>      
    </visual>    
    <collision>      
      <origin xyz="0 0 0" rpy="0 -0 0"/>      
      <geometry>        
        <mesh filename="package:///meshes/right_knee_rod_collision.stl"/>        
      </geometry>      
    </collision>    
    <inertial>      
      <origin xyz="0.017534291149574238872 3.9071397871386789554e-05 -0.0015981336617514770287" rpy="0 0 0"/>      
      <mass value="0.0031629468613064179276"/>      
      <inertia ixx="2.7978910170551288005e-08" ixy="-3.94307030303930001e-10" ixz="4.8576304552482821547e-10" iyy="8.7495156744971494086e-07" iyz="1.0824185061383664554e-12" izz="8.9816305133507018681e-07"/>      
    </inertial>    
  </link>  

  <joint name="right_knee_front_rev_1" type="revolute">    
    <origin xyz="0.0057402514854763813518 -0.013858192987669354368 0.0049999999999999922978" rpy="-3.141592653589793116 -2.2680076696535559301e-15 -1.5696821854497560178"/>    
    <parent link="xm430_plate"/>    
    <child link="knee_rod"/>    
    <axis xyz="0 0 1"/>    
    <limit effort="1" velocity="20"/>    
    <joint_properties friction="0.0"/>    
  </joint>  

  <link name="knee_rod_2">    
    <visual>      
      <origin xyz="0 0 0" rpy="0 -0 0"/>      
      <geometry>        
        <mesh filename="package:///meshes/right_knee_rod_2_visual.stl"/>        
      </geometry>      
      <material name="knee_rod_2_material">        
        <color rgba="0.62051618944235198416 0.78640765248647581664 0.88594253031295022716 1.0"/>        
      </material>      
    </visual>    
    <collision>      
      <origin xyz="0 0 0" rpy="0 -0 0"/>      
      <geometry>        
        <mesh filename="package:///meshes/right_knee_rod_2_collision.stl"/>        
      </geometry>      
    </collision>    
    <inertial>      
      <origin xyz="0.017534290894203184707 3.9299938126582091243e-05 -0.0015981336617514319259" rpy="0 0 0"/>      
      <mass value="0.0031629468613064179276"/>      
      <inertia ixx="2.7978920479332387554e-08" ixy="-3.9661344391086863808e-10" ixz="4.8576303845852543957e-10" iyy="8.7495156229529202847e-07" iyz="1.0887498949803466658e-12" izz="8.9816305648941188991e-07"/>      
    </inertial>    
  </link>  

  <joint name="right_knee_back_rev_1" type="revolute">    
    <origin xyz="-0.005740251485476307626 0.013858192987669243346 0.0050000000000000209208" rpy="-3.1415926535897926719 -7.2263408907627713374e-17 -1.5696756685021302502"/>    
    <parent link="xm430_plate"/>    
    <child link="knee_rod_2"/>    
    <axis xyz="0 0 1"/>    
    <limit effort="1" velocity="20"/>    
    <joint_properties friction="0.0"/>    
  </joint>  

  <joint name="right_knee_act" type="revolute">    
    <origin xyz="-3.4965520062657517997e-17 0.012449999999999900382 0.044500000000000414224" rpy="-1.5707963267948978903 -1.8873791418627653299e-15 -1.8392984561052994525e-15"/>    
    <parent link="right_thigh_link"/>    
    <child link="xm430_plate"/>    
    <axis xyz="0 0 1"/>    
    <limit effort="1" velocity="20" lower="0" upper="1.570796326794896558"/>    
    <joint_properties friction="0.0"/>    
  </joint>  

  <joint name="right_hip_yaw_driven" type="revolute">    
    <origin xyz="-5.1120132432691534063e-17 -1.1449174941446926823e-16 -0.0050000000000000044409" rpy="3.141592653589793116 1.1586097708402311315e-16 -1.9261630240694359833e-15"/>    
    <parent link="spur_gear_21_teeth"/>    
    <child link="right_thigh_link"/>    
    <axis xyz="0 0 1"/>    
    <limit effort="1" velocity="20" lower="-1.570796326794896558" upper="1.570796326794896558"/>    
    <joint_properties friction="0.0"/>    
  </joint>  

  <joint name="right_hip_yaw_fixed" type="fixed">    
    <origin xyz="1.1449174941446926823e-16 0.027999999999999990175 0.022999999999999951039" rpy="1.57079632679489678 1.570796326794896336 0"/>    
    <parent link="hip_yaw_link"/>    
    <child link="spur_gear_21_teeth"/>    
    <axis xyz="0 0 1"/>    
    <limit effort="1" velocity="20"/>    
    <joint_properties friction="0.0"/>    
  </joint>  

  <joint name="right_hip_roll" type="revolute">    
    <origin xyz="-0.023750000000001200706 -0.022749999999999999389 -0.018950000000000081363" rpy="-1.570796326794896558 1.5707963267948952257 0"/>    
    <parent link="right_hip_pitch_link"/>    
    <child link="hip_yaw_link"/>    
    <axis xyz="0 0 1"/>    
    <limit effort="1" velocity="20" lower="-1.570796326794896558" upper="1.570796326794896558"/>    
    <joint_properties friction="0.0"/>    
  </joint>  


</robot>