<?xml version="1.0" ?><robot name="no_body">  
  <link name="body_link">    
    <visual>      
      <origin xyz="0 0 0" rpy="0 -0 0"/>      
      <geometry>        
        <mesh filename="package:///meshes/body_link_visual.stl"/>        
      </geometry>      
      <material name="body_link_material">        
        <color rgba="0.61397237829351869465 0.80332498114502748354 0.91540927344620071082 1.0"/>        
      </material>      
    </visual>    
    <collision>      
      <origin xyz="0 0 0" rpy="0 -0 0"/>      
      <geometry>        
        <mesh filename="package:///meshes/body_link_collision.stl"/>        
      </geometry>      
    </collision>    
    <inertial>      
      <origin xyz="-0.01499364327886279491 -0.00061666227763491530088 0.37865534467571948518" rpy="0 0 0"/>      
      <mass value="1.0086534506317459403"/>      
      <inertia ixx="0.0046858218276694544105" ixy="9.5066545070522087891e-06" ixz="-0.00033041186495409415264" iyy="0.0039734105446477419737" iyz="-2.4960818033478732468e-05" izz="0.0024171325638287608113"/>      
    </inertial>    
  </link>  

  <link name="left_3r+rh5_leg">    
    <visual>      
      <origin xyz="0 0 0" rpy="0 -0 0"/>      
      <geometry>        
        <mesh filename="package:///meshes/left_3r+rh5_leg_visual.stl"/>        
      </geometry>      
      <material name="left_3r+rh5_leg_material">        
        <color rgba="0.71739176220228562109 0.71434779139739223996 0.54703151743593081413 1.0"/>        
      </material>      
    </visual>    
    <collision>      
      <origin xyz="0 0 0" rpy="0 -0 0"/>      
      <geometry>        
        <mesh filename="package:///meshes/left_3r+rh5_leg_collision.stl"/>        
      </geometry>      
    </collision>    
    <inertial>      
      <origin xyz="-0.0038241616594010103235 0.0013115658691236348199 -0.12289928861698865004" rpy="0 0 0"/>      
      <mass value="0.33195598389228875291"/>      
      <inertia ixx="0.0020902078719060072053" ixy="-1.6071516345336311138e-06" ixz="-0.00010501190153826278628" iyy="0.0020817060999193046089" iyz="-1.5044687092366121846e-05" izz="0.00012532959137049671291"/>      
    </inertial>    
  </link>  

  <joint name="left_hip_yaw" type="revolute">    
    <origin xyz="-0.0093999999999961926511 0.033999999999999301614 0.28500000000000003109" rpy="9.5014891068790173158e-14 -1.7824800733959379972e-14 -7.7962407392327512346e-15"/>    
    <parent link="body_link"/>    
    <child link="left_3r+rh5_leg"/>    
    <axis xyz="0 0 1"/>    
    <limit effort="1" velocity="20" lower="-0.785398163397448279" upper="0.785398163397448279"/>    
    <joint_properties friction="0.0"/>    
  </joint>  

  <link name="right_3r+rh5_leg">    
    <visual>      
      <origin xyz="0 0 0" rpy="0 -0 0"/>      
      <geometry>        
        <mesh filename="package:///meshes/right_3r+rh5_leg_visual.stl"/>        
      </geometry>      
      <material name="right_3r+rh5_leg_material">        
        <color rgba="0.71739233455731554745 0.71434834594644691652 0.5470307114278246674 1.0"/>        
      </material>      
    </visual>    
    <collision>      
      <origin xyz="0 0 0" rpy="0 -0 0"/>      
      <geometry>        
        <mesh filename="package:///meshes/right_3r+rh5_leg_collision.stl"/>        
      </geometry>      
    </collision>    
    <inertial>      
      <origin xyz="-0.003889680852743220181 -0.001107195478697155103 -0.12289828084282115872" rpy="0 0 0"/>      
      <mass value="0.3319532758554966656"/>      
      <inertia ixx="0.0020903301182359445252" ixy="1.7017694071494316904e-06" ixz="-0.00010478221356105752436" iyy="0.0020814970798241337092" iyz="4.4542630918547628768e-06" izz="0.00012532536902788734656"/>      
    </inertial>    
  </link>  

  <joint name="right_hip_yaw" type="revolute">    
    <origin xyz="-0.009399999999996381736 -0.034000000000000807354 0.28499999999999969802" rpy="9.1462148145194911492e-14 -1.7824800733940560906e-14 -2.1356041234847096424e-13"/>    
    <parent link="body_link"/>    
    <child link="right_3r+rh5_leg"/>    
    <axis xyz="0 0 1"/>    
    <limit effort="1" velocity="20" lower="-0.785398163397448279" upper="0.785398163397448279"/>    
    <joint_properties friction="0.0"/>    
  </joint>  


</robot>