<?xml version="1.0" ?><robot name="no_body">  
  <link name="base_link"/>  
  <joint name="base_link_to_base" type="fixed">    
    <parent link="base_link"/>    
    <child link="hip_link"/>    
    <origin rpy="0.0 0 0" xyz="0 0 0"/>    
  </joint>  
  <link name="hip_link">    
    <visual>      
      <origin xyz="0 0 0" rpy="0 -0 0"/>      
      <geometry>        
        <mesh filename="package:///meshes/hip_link_visual.stl"/>        
      </geometry>      
      <material name="hip_link_material">        
        <color rgba="0.60265235106909242901 0.7475818661971369572 0.82292492068132760963 1.0"/>        
      </material>      
    </visual>    
    <collision>      
      <origin xyz="0 0 0" rpy="0 -0 0"/>      
      <geometry>        
        <mesh filename="package:///meshes/hip_link_collision.stl"/>        
      </geometry>      
    </collision>    
    <inertial>      
      <origin xyz="-0.014403523331510960717 -0.00023164401215090829741 0.31153288519557342795" rpy="0 0 0"/>      
      <mass value="0.1326329205818372603"/>      
      <inertia ixx="0.00012163093315384157793" ixy="1.4038303149150794108e-07" ixz="1.0872278951927060253e-05" iyy="8.4970137932106120315e-05" iyz="3.874082128923384354e-07" izz="0.00015647103471607424"/>      
    </inertial>    
  </link>  

  <link name="left_3r+rh5_leg">    
    <visual>      
      <origin xyz="0 0 0" rpy="0 -0 0"/>      
      <geometry>        
        <mesh filename="package:///meshes/left_3r+rh5_leg_visual.stl"/>        
      </geometry>      
      <material name="left_3r+rh5_leg_material">        
        <color rgba="0.71686042550810946672 0.7144790892559227391 0.54826554434056440357 1.0"/>        
      </material>      
    </visual>    
    <collision>      
      <origin xyz="0 0 0" rpy="0 -0 0"/>      
      <geometry>        
        <mesh filename="package:///meshes/left_3r+rh5_leg_collision.stl"/>        
      </geometry>      
    </collision>    
    <inertial>      
      <origin xyz="-0.0058110214490449665567 0.001279686124124864181 -0.12297433429408506644" rpy="0 0 0"/>      
      <mass value="0.33316789121369472237"/>      
      <inertia ixx="0.0020728504432678952589" ixy="-2.4992671449968986735e-06" ixz="-0.0001686395026840326061" iyy="0.0020902600990169461527" iyz="-1.4941040436112179677e-05" izz="0.00012810207417984580645"/>      
    </inertial>    
  </link>  

  <joint name="left_hip_yaw" type="revolute">    
    <origin xyz="-0.0063999999999966028508 0.033999999999999308553 0.28550000000000008704" rpy="1.2173498077216098975e-16 -2.7428229896967586736e-14 -8.3846071870935304412e-14"/>    
    <parent link="hip_link"/>    
    <child link="left_3r+rh5_leg"/>    
    <axis xyz="0 0 1"/>    
    <limit effort="1" velocity="20" lower="-1.570796326794896558" upper="1.570796326794896558"/>    
    <joint_properties friction="0.0"/>    
  </joint>  

  <link name="right_3r+rh5_leg">    
    <visual>      
      <origin xyz="0 0 0" rpy="0 -0 0"/>      
      <geometry>        
        <mesh filename="package:///meshes/right_3r+rh5_leg_visual.stl"/>        
      </geometry>      
      <material name="right_3r+rh5_leg_material">        
        <color rgba="0.71686042395258697812 0.71447909400773312871 0.54826555699525381105 1.0"/>        
      </material>      
    </visual>    
    <collision>      
      <origin xyz="0 0 0" rpy="0 -0 0"/>      
      <geometry>        
        <mesh filename="package:///meshes/right_3r+rh5_leg_collision.stl"/>        
      </geometry>      
    </collision>    
    <inertial>      
      <origin xyz="-0.0061680903068686634971 -0.0013678380978310038414 -0.12297433810277710875" rpy="0 0 0"/>      
      <mass value="0.33316790148107094938"/>      
      <inertia ixx="0.0020727726973481467448" ixy="2.9907688148734340892e-06" ixz="-0.00016006303496028572646" iyy="0.0020888350217583059182" iyz="1.246973674394419292e-05" izz="0.00012659923624478477402"/>      
    </inertial>    
  </link>  

  <joint name="right_hip_yaw" type="revolute">    
    <origin xyz="-0.006399999999996792803 -0.034000000000000661637 0.28549999999999997602" rpy="1.2173498094410956825e-16 -2.7428229798067236768e-14 -5.0714987764877150767e-13"/>    
    <parent link="hip_link"/>    
    <child link="right_3r+rh5_leg"/>    
    <axis xyz="0 0 1"/>    
    <limit effort="1" velocity="20" lower="-1.570796326794896558" upper="1.570796326794896558"/>    
    <joint_properties friction="0.0"/>    
  </joint>  


</robot>