<?xml version="1.0" ?><robot name="no_body">  
  <link name="body_link">    
    <visual>      
      <origin xyz="0 0 0" rpy="0 -0 0"/>      
      <geometry>        
        <mesh filename="package:///meshes/body_link_visual.stl"/>        
      </geometry>      
      <material name="body_link_material">        
        <color rgba="0.61191666591375948325 0.79320205394593001902 0.89861415227348584445 1.0"/>        
      </material>      
    </visual>    
    <collision>      
      <origin xyz="0 0 0" rpy="0 -0 0"/>      
      <geometry>        
        <mesh filename="package:///meshes/body_link_collision.stl"/>        
      </geometry>      
    </collision>    
    <inertial>      
      <origin xyz="-0.014920248342481507234 -0.000542212187899950189 0.36967388723580163479" rpy="0 0 0"/>      
      <mass value="0.4585959758251314522"/>      
      <inertia ixx="0.0021798234497381182781" ixy="3.7850609619240563318e-06" ixz="-0.00012930898049707379403" iyy="0.0018771552890593046301" iyz="-7.7403691175502276582e-06" izz="0.0010094302917501435379"/>      
    </inertial>    
  </link>  

  <link name="left_3r+rh5_leg">    
    <visual>      
      <origin xyz="0 0 0" rpy="0 -0 0"/>      
      <geometry>        
        <mesh filename="package:///meshes/left_3r+rh5_leg_visual.stl"/>        
      </geometry>      
      <material name="left_3r+rh5_leg_material">        
        <color rgba="0.71548646284892525316 0.71617275078144981837 0.5541948362930610994 1.0"/>        
      </material>      
    </visual>    
    <collision>      
      <origin xyz="0 0 0" rpy="0 -0 0"/>      
      <geometry>        
        <mesh filename="package:///meshes/left_3r+rh5_leg_collision.stl"/>        
      </geometry>      
    </collision>    
    <inertial>      
      <origin xyz="-0.0037039654286989075714 0.001713047861235082259 -0.1259121494527896401" rpy="0 0 0"/>      
      <mass value="0.33829340200722179954"/>      
      <inertia ixx="0.0022554973173798831959" ixy="-3.3382109269216464943e-06" ixz="-9.8559718003185365861e-05" iyy="0.0022471450996238619829" iyz="6.2836418004119886483e-06" izz="0.00013436261622447125651"/>      
    </inertial>    
  </link>  

  <joint name="left_hip_yaw" type="revolute">    
    <origin xyz="-0.0093999999999961978553 0.033999999999999419575 0.28500000000000003109" rpy="9.2483505067470270586e-14 -1.7702340883530983486e-14 -6.9407309914055112031e-15"/>    
    <parent link="body_link"/>    
    <child link="left_3r+rh5_leg"/>    
    <axis xyz="0 0 1"/>    
    <limit effort="1" velocity="20" lower="-0.785398163397448279" upper="0.785398163397448279"/>    
    <joint_properties friction="0.0"/>    
  </joint>  

  <link name="right_3r+rh5_leg">    
    <visual>      
      <origin xyz="0 0 0" rpy="0 -0 0"/>      
      <geometry>        
        <mesh filename="package:///meshes/right_3r+rh5_leg_visual.stl"/>        
      </geometry>      
      <material name="right_3r+rh5_leg_material">        
        <color rgba="0.7154870096471849239 0.71617330915073806885 0.55419410115732903321 1.0"/>        
      </material>      
    </visual>    
    <collision>      
      <origin xyz="0 0 0" rpy="0 -0 0"/>      
      <geometry>        
        <mesh filename="package:///meshes/right_3r+rh5_leg_collision.stl"/>        
      </geometry>      
    </collision>    
    <inertial>      
      <origin xyz="-0.0037682598395942586318 -0.0015125298822245625881 -0.12591118405751519638" rpy="0 0 0"/>      
      <mass value="0.33829069255504623515"/>      
      <inertia ixx="0.0022556762306764665052" ixy="3.4497589344622571066e-06" ixz="-9.8264651978343200457e-05" iyy="0.0022469432808350712875" iyz="-1.7079682513248730925e-05" izz="0.00013441834136167804623"/>      
    </inertial>    
  </link>  

  <joint name="right_hip_yaw" type="revolute">    
    <origin xyz="-0.009399999999996381736 -0.03400000000000077266 0.28499999999999969802" rpy="8.8930762143875021541e-14 -1.7702340883511041083e-14 -2.3118089975893051414e-13"/>    
    <parent link="body_link"/>    
    <child link="right_3r+rh5_leg"/>    
    <axis xyz="0 0 1"/>    
    <limit effort="1" velocity="20" lower="-0.785398163397448279" upper="0.785398163397448279"/>    
    <joint_properties friction="0.0"/>    
  </joint>  


</robot>