<?xml version="1.0" ?><robot name="no_body">  
  <link name="body_link">    
    <visual>      
      <origin xyz="0 0 0" rpy="0 -0 0"/>      
      <geometry>        
        <mesh filename="package:///meshes/body_link_visual.stl"/>        
      </geometry>      
      <material name="body_link_material">        
        <color rgba="0.60265235106909254004 0.74758186619713706822 0.82292492068132783167 1.0"/>        
      </material>      
    </visual>    
    <collision>      
      <origin xyz="0 0 0" rpy="0 -0 0"/>      
      <geometry>        
        <mesh filename="package:///meshes/body_link_collision.stl"/>        
      </geometry>      
    </collision>    
    <inertial>      
      <origin xyz="-0.014403523331510962452 -0.00023164401215091008635 0.31153288519557342795" rpy="0 0 0"/>      
      <mass value="0.1326329205818372603"/>      
      <inertia ixx="0.00012163093315384155082" ixy="1.4038303149150714698e-07" ixz="1.0872278951927058559e-05" iyy="8.497013793210614742e-05" iyz="3.8740821289234341171e-07" izz="0.00015647103471607424"/>      
    </inertial>    
  </link>  

  <link name="left_3r+rh5_leg">    
    <visual>      
      <origin xyz="0 0 0" rpy="0 -0 0"/>      
      <geometry>        
        <mesh filename="package:///meshes/left_3r+rh5_leg_visual.stl"/>        
      </geometry>      
      <material name="left_3r+rh5_leg_material">        
        <color rgba="0.7171271799391958357 0.71457448616025509569 0.54799362657198125159 1.0"/>        
      </material>      
    </visual>    
    <collision>      
      <origin xyz="0 0 0" rpy="0 -0 0"/>      
      <geometry>        
        <mesh filename="package:///meshes/left_3r+rh5_leg_collision.stl"/>        
      </geometry>      
    </collision>    
    <inertial>      
      <origin xyz="-0.0058324190712774320183 0.0012819453771138163492 -0.12293055910084987881" rpy="0 0 0"/>      
      <mass value="0.33284223931512413319"/>      
      <inertia ixx="0.0020720388461187961258" ixy="-2.5131091303277369554e-06" ixz="-0.00016921530472662103741" iyy="0.0020894468705220264372" iyz="-1.4910411596287402228e-05" izz="0.00012809377610829497597"/>      
    </inertial>    
  </link>  

  <joint name="left_hip_yaw" type="revolute">    
    <origin xyz="-0.0063999999999966045855 0.033999999999999447331 0.28550000000000008704" rpy="1.2173498077257119742e-16 -2.7439672175516685782e-14 -9.8815480994853422476e-14"/>    
    <parent link="body_link"/>    
    <child link="left_3r+rh5_leg"/>    
    <axis xyz="0 0 1"/>    
    <limit effort="1" velocity="20" lower="-1.570796326794896558" upper="1.570796326794896558"/>    
    <joint_properties friction="0.0"/>    
  </joint>  

  <link name="right_3r+rh5_leg">    
    <visual>      
      <origin xyz="0 0 0" rpy="0 -0 0"/>      
      <geometry>        
        <mesh filename="package:///meshes/right_3r+rh5_leg_visual.stl"/>        
      </geometry>      
      <material name="right_3r+rh5_leg_material">        
        <color rgba="0.71712718175007694743 0.71457448383750599152 0.54799361853656025634 1.0"/>        
      </material>      
    </visual>    
    <collision>      
      <origin xyz="0 0 0" rpy="0 -0 0"/>      
      <geometry>        
        <mesh filename="package:///meshes/right_3r+rh5_leg_collision.stl"/>        
      </geometry>      
    </collision>    
    <inertial>      
      <origin xyz="-0.0061898381239721784672 -0.0013701900749778120163 -0.12293056003991345571" rpy="0 0 0"/>      
      <mass value="0.33284223244644683959"/>      
      <inertia ixx="0.0020719609172381715616" ixy="3.0047926839012403494e-06" ixz="-0.00016064405800913261519" iyy="0.0020880166048914605356" iyz="1.2438642530825984729e-05" izz="0.00012658567250601915647"/>      
    </inertial>    
  </link>  

  <joint name="right_hip_yaw" type="revolute">    
    <origin xyz="-0.006399999999996792803 -0.034000000000000661637 0.28549999999999997602" rpy="1.2173498094410956825e-16 -2.7428229798067236768e-14 -5.0714987764877150767e-13"/>    
    <parent link="body_link"/>    
    <child link="right_3r+rh5_leg"/>    
    <axis xyz="0 0 1"/>    
    <limit effort="1" velocity="20" lower="-1.570796326794896558" upper="1.570796326794896558"/>    
    <joint_properties friction="0.0"/>    
  </joint>  


</robot>