<?xml version="1.0" ?><robot name="no_body">  
  <link name="body_link">    
    <visual>      
      <origin xyz="0 0 0" rpy="0 -0 0"/>      
      <geometry>        
        <mesh filename="package:///meshes/body_link_visual.stl"/>        
      </geometry>      
      <material name="body_link_material">        
        <color rgba="0.60265235106909254004 0.74758186619713706822 0.82292492068132760963 1.0"/>        
      </material>      
    </visual>    
    <collision>      
      <origin xyz="0 0 0" rpy="0 -0 0"/>      
      <geometry>        
        <mesh filename="package:///meshes/body_link_collision.stl"/>        
      </geometry>      
    </collision>    
    <inertial>      
      <origin xyz="-0.014403523331510958982 -0.00023164401215091008635 0.31153288519557337244" rpy="0 0 0"/>      
      <mass value="0.1326329205818372603"/>      
      <inertia ixx="0.00012163093315384152372" ixy="1.4038303149150653818e-07" ixz="1.0872278951927060253e-05" iyy="8.4970137932106160972e-05" iyz="3.8740821289234436463e-07" izz="0.00015647103471607424"/>      
    </inertial>    
  </link>  

  <link name="left_3r+rh5_leg">    
    <visual>      
      <origin xyz="0 0 0" rpy="0 -0 0"/>      
      <geometry>        
        <mesh filename="package:///meshes/left_3r+rh5_leg_visual.stl"/>        
      </geometry>      
      <material name="left_3r+rh5_leg_material">        
        <color rgba="0.7151006302578406526 0.71651611718153718211 0.55561346004080180982 1.0"/>        
      </material>      
    </visual>    
    <collision>      
      <origin xyz="0 0 0" rpy="0 -0 0"/>      
      <geometry>        
        <mesh filename="package:///meshes/left_3r+rh5_leg_collision.stl"/>        
      </geometry>      
    </collision>    
    <inertial>      
      <origin xyz="-0.005547235312513381679 0.0016952279099333045914 -0.12640401954186183953" rpy="0 0 0"/>      
      <mass value="0.33962718831922139584"/>      
      <inertia ixx="0.0022619510230785289974" ixy="-4.0359021620084531597e-06" ixz="-0.00015413503205377718144" iyy="0.0022810463114783783613" iyz="6.1345814808295563744e-06" izz="0.00013891036459460386673"/>      
    </inertial>    
  </link>  

  <joint name="left_hip_yaw" type="revolute">    
    <origin xyz="-0.0063999999999966063202 0.033999999999999308553 0.28550000000000003153" rpy="2.3275728331677864905e-16 1.1102230242191183694e-16 -1.1455751422015388711e-13"/>    
    <parent link="body_link"/>    
    <child link="left_3r+rh5_leg"/>    
    <axis xyz="0 0 1"/>    
    <limit effort="1" velocity="20" lower="-0.785398163397448279" upper="0.785398163397448279"/>    
    <joint_properties friction="0.0"/>    
  </joint>  

  <link name="right_3r+rh5_leg">    
    <visual>      
      <origin xyz="0 0 0" rpy="0 -0 0"/>      
      <geometry>        
        <mesh filename="package:///meshes/right_3r+rh5_leg_visual.stl"/>        
      </geometry>      
      <material name="right_3r+rh5_leg_material">        
        <color rgba="0.71510062610691527141 0.71651612058251878956 0.55561347444629649583 1.0"/>        
      </material>      
    </visual>    
    <collision>      
      <origin xyz="0 0 0" rpy="0 -0 0"/>      
      <geometry>        
        <mesh filename="package:///meshes/right_3r+rh5_leg_collision.stl"/>        
      </geometry>      
    </collision>    
    <inertial>      
      <origin xyz="-0.0058975150586949133882 -0.0017817086421426096051 -0.12640402004841491679" rpy="0 0 0"/>      
      <mass value="0.33962720155413217427"/>      
      <inertia ixx="0.0022618488656267424913" ixy="4.570093946423826001e-06" ixz="-0.0001451505612564215242" iyy="0.0022796847409983023516" iyz="-8.5049572830257439147e-06" izz="0.00013744673675701815792"/>      
    </inertial>    
  </link>  

  <joint name="right_hip_yaw" type="revolute">    
    <origin xyz="-0.0063999999999967980072 -0.034000000000000668576 0.28549999999999992051" rpy="1.2173498094825229595e-16 9.8900267199457111713e-23 -3.0336177719551955022e-13"/>    
    <parent link="body_link"/>    
    <child link="right_3r+rh5_leg"/>    
    <axis xyz="0 0 1"/>    
    <limit effort="1" velocity="20" lower="-0.785398163397448279" upper="0.785398163397448279"/>    
    <joint_properties friction="0.0"/>    
  </joint>  


</robot>