<?xml version="1.0" ?><robot name="no_body">  
  <link name="body_link">    
    <visual>      
      <origin xyz="0 0 0" rpy="0 -0 0"/>      
      <geometry>        
        <mesh filename="package:///meshes/body_link_visual.stl"/>        
      </geometry>      
      <material name="body_link_material">        
        <color rgba="0.61191666591375959428 0.79320205394593013004 0.8986141522734856224 1.0"/>        
      </material>      
    </visual>    
    <collision>      
      <origin xyz="0 0 0" rpy="0 -0 0"/>      
      <geometry>        
        <mesh filename="package:///meshes/body_link_collision.stl"/>        
      </geometry>      
    </collision>    
    <inertial>      
      <origin xyz="-0.014920248342481510703 -0.00054221218789995083952 0.3696738872358016903" rpy="0 0 0"/>      
      <mass value="0.45859597582513078606"/>      
      <inertia ixx="0.0021798234497381182781" ixy="3.7850609619239741696e-06" ixz="-0.00012930898049707392956" iyy="0.0018771552890593046301" iyz="-7.7403691175502191879e-06" izz="0.0010094302917501433211"/>      
    </inertial>    
  </link>  

  <link name="left_3r+rh5_leg">    
    <visual>      
      <origin xyz="0 0 0" rpy="0 -0 0"/>      
      <geometry>        
        <mesh filename="package:///meshes/left_3r+rh5_leg_visual.stl"/>        
      </geometry>      
      <material name="left_3r+rh5_leg_material">        
        <color rgba="0.71739176220228562109 0.71434779139739223996 0.54703151743593081413 1.0"/>        
      </material>      
    </visual>    
    <collision>      
      <origin xyz="0 0 0" rpy="0 -0 0"/>      
      <geometry>        
        <mesh filename="package:///meshes/left_3r+rh5_leg_collision.stl"/>        
      </geometry>      
    </collision>    
    <inertial>      
      <origin xyz="-0.0038241616594005913878 0.0013115658691236419756 -0.12289928861698871942" rpy="0 0 0"/>      
      <mass value="0.33195598389228875291"/>      
      <inertia ixx="0.0020902078719060085063" ixy="-1.6071516345335995618e-06" ixz="-0.00010501190153825374675" iyy="0.0020817060999193050426" iyz="-1.5044687092365859266e-05" izz="0.00012532959137049579134"/>      
    </inertial>    
  </link>  

  <joint name="left_hip_yaw" type="revolute">    
    <origin xyz="-0.0093999999999960781594 0.033999999999999308553 0.2850000000000000866" rpy="9.5014891068789895479e-14 -1.3383908635459135619e-14 -4.8061927846509854508e-15"/>    
    <parent link="body_link"/>    
    <child link="left_3r+rh5_leg"/>    
    <axis xyz="0 0 1"/>    
    <limit effort="1" velocity="20" lower="-0.785398163397448279" upper="0.785398163397448279"/>    
    <joint_properties friction="0.0"/>    
  </joint>  

  <link name="right_3r+rh5_leg">    
    <visual>      
      <origin xyz="0 0 0" rpy="0 -0 0"/>      
      <geometry>        
        <mesh filename="package:///meshes/right_3r+rh5_leg_visual.stl"/>        
      </geometry>      
      <material name="right_3r+rh5_leg_material">        
        <color rgba="0.71739233455731554745 0.71434834594644691652 0.5470307114278246674 1.0"/>        
      </material>      
    </visual>    
    <collision>      
      <origin xyz="0 0 0" rpy="0 -0 0"/>      
      <geometry>        
        <mesh filename="package:///meshes/right_3r+rh5_leg_collision.stl"/>        
      </geometry>      
    </collision>    
    <inertial>      
      <origin xyz="-0.0038896808527443763742 -0.0011071954786971787386 -0.12289828084282095055" rpy="0 0 0"/>      
      <mass value="0.3319532758554966656"/>      
      <inertia ixx="0.0020903301182359341169" ixy="1.7017694071499579097e-06" ixz="-0.00010478221356109979469" iyy="0.002081497079824127204" iyz="4.4542630918541843533e-06" izz="0.00012532536902789127679"/>      
    </inertial>    
  </link>  

  <joint name="right_hip_yaw" type="revolute">    
    <origin xyz="-0.0093999999999962672442 -0.034000000000000779599 0.28499999999999980904" rpy="9.1462148145193586205e-14 -1.3383908635439859014e-14 -2.1556636800468298824e-13"/>    
    <parent link="body_link"/>    
    <child link="right_3r+rh5_leg"/>    
    <axis xyz="0 0 1"/>    
    <limit effort="1" velocity="20" lower="-0.785398163397448279" upper="0.785398163397448279"/>    
    <joint_properties friction="0.0"/>    
  </joint>  


</robot>