<?xml version="1.0" ?><robot name="no_body">  
  <link name="body_link">    
    <visual>      
      <origin xyz="0 0 0" rpy="0 -0 0"/>      
      <geometry>        
        <mesh filename="package:///meshes/body_link_visual.stl"/>        
      </geometry>      
      <material name="body_link_material">        
        <color rgba="0.60265235106909254004 0.74758186619713706822 0.82292492068132760963 1.0"/>        
      </material>      
    </visual>    
    <collision>      
      <origin xyz="0 0 0" rpy="0 -0 0"/>      
      <geometry>        
        <mesh filename="package:///meshes/body_link_collision.stl"/>        
      </geometry>      
    </collision>    
    <inertial>      
      <origin xyz="-0.014403523331510958982 -0.00023164401215090967977 0.31153288519557337244" rpy="0 0 0"/>      
      <mass value="0.1326329205818372603"/>      
      <inertia ixx="0.00012163093315384152372" ixy="1.4038303149150823224e-07" ixz="1.0872278951927058559e-05" iyy="8.4970137932106160972e-05" iyz="3.8740821289234436463e-07" izz="0.00015647103471607424"/>      
    </inertial>    
  </link>  

  <link name="left_3r+rh5_leg">    
    <visual>      
      <origin xyz="0 0 0" rpy="0 -0 0"/>      
      <geometry>        
        <mesh filename="package:///meshes/left_3r+rh5_leg_visual.stl"/>        
      </geometry>      
      <material name="left_3r+rh5_leg_material">        
        <color rgba="0.71550788199074344398 0.71615223480390555189 0.55411430712654130559 1.0"/>        
      </material>      
    </visual>    
    <collision>      
      <origin xyz="0 0 0" rpy="0 -0 0"/>      
      <geometry>        
        <mesh filename="package:///meshes/left_3r+rh5_leg_collision.stl"/>        
      </geometry>      
    </collision>    
    <inertial>      
      <origin xyz="-0.007264489912447109031 0.0017025756332140617056 -0.12508545733467263394" rpy="0 0 0"/>      
      <mass value="0.33822081293183930972"/>      
      <inertia ixx="0.0022103069966566842551" ixy="-3.3503438217051409123e-06" ixz="-0.00021603212999043205477" iyy="0.0022209258303605488791" iyz="6.733008445795404371e-06" izz="0.00015317911107648086327"/>      
    </inertial>    
  </link>  

  <joint name="left_hip_yaw" type="revolute">    
    <origin xyz="-0.0063999999999966063202 0.033999999999999308553 0.28550000000000003153" rpy="2.3275728331677864905e-16 1.1102230242191363653e-16 -1.222458086656465435e-13"/>    
    <parent link="body_link"/>    
    <child link="left_3r+rh5_leg"/>    
    <axis xyz="0 0 1"/>    
    <limit effort="1" velocity="20" lower="-0.785398163397448279" upper="0.785398163397448279"/>    
    <joint_properties friction="0.0"/>    
  </joint>  

  <link name="right_3r+rh5_leg">    
    <visual>      
      <origin xyz="0 0 0" rpy="0 -0 0"/>      
      <geometry>        
        <mesh filename="package:///meshes/right_3r+rh5_leg_visual.stl"/>        
      </geometry>      
      <material name="right_3r+rh5_leg_material">        
        <color rgba="0.71550842907794598435 0.71615279312867885508 0.55411357118791604304 1.0"/>        
      </material>      
    </visual>    
    <collision>      
      <origin xyz="0 0 0" rpy="0 -0 0"/>      
      <geometry>        
        <mesh filename="package:///meshes/right_3r+rh5_leg_collision.stl"/>        
      </geometry>      
    </collision>    
    <inertial>      
      <origin xyz="-0.0060218735149276600427 -0.0017887432924778201484 -0.12552634492928660404" rpy="0 0 0"/>      
      <mass value="0.33821810347966374533"/>      
      <inertia ixx="0.0022349146461358190656" ixy="3.9264255357566598165e-06" ixz="-0.00015491053168490589282" iyy="0.0022337705813790117125" iyz="-8.8487516248507333663e-06" izz="0.0001411928456623556794"/>      
    </inertial>    
  </link>  

  <joint name="right_hip_yaw" type="revolute">    
    <origin xyz="-0.0063999999999967980072 -0.034000000000000668576 0.28549999999999992051" rpy="1.2173498094825229595e-16 9.8900267199457111713e-23 -3.0336177719551955022e-13"/>    
    <parent link="body_link"/>    
    <child link="right_3r+rh5_leg"/>    
    <axis xyz="0 0 1"/>    
    <limit effort="1" velocity="20" lower="-0.785398163397448279" upper="0.785398163397448279"/>    
    <joint_properties friction="0.0"/>    
  </joint>  


</robot>