<?xml version="1.0" ?><robot name="no_body">  
  <link name="body_link">    
    <visual>      
      <origin xyz="0 0 0" rpy="0 -0 0"/>      
      <geometry>        
        <mesh filename="package:///meshes/body_link_visual.stl"/>        
      </geometry>      
      <material name="body_link_material">        
        <color rgba="0.60265235106909265106 0.74758186619713717924 0.82292492068132783167 1.0"/>        
      </material>      
    </visual>    
    <collision>      
      <origin xyz="0 0 0" rpy="0 -0 0"/>      
      <geometry>        
        <mesh filename="package:///meshes/body_link_collision.stl"/>        
      </geometry>      
    </collision>    
    <inertial>      
      <origin xyz="-0.014403523331510962452 -0.00023164401215090967977 0.31153288519557342795" rpy="0 0 0"/>      
      <mass value="0.1326329205818372603"/>      
      <inertia ixx="0.00012163093315384155082" ixy="1.4038303149150714698e-07" ixz="1.0872278951927053477e-05" iyy="8.497013793210614742e-05" iyz="3.8740821289234341171e-07" izz="0.00015647103471607424"/>      
    </inertial>    
  </link>  

  <link name="left_3r+rh5_leg">    
    <visual>      
      <origin xyz="0 0 0" rpy="0 -0 0"/>      
      <geometry>        
        <mesh filename="package:///meshes/left_3r+rh5_leg_visual.stl"/>        
      </geometry>      
      <material name="left_3r+rh5_leg_material">        
        <color rgba="0.71718891380237659305 0.71451533913567544243 0.54776150704333026464 1.0"/>        
      </material>      
    </visual>    
    <collision>      
      <origin xyz="0 0 0" rpy="0 -0 0"/>      
      <geometry>        
        <mesh filename="package:///meshes/left_3r+rh5_leg_collision.stl"/>        
      </geometry>      
    </collision>    
    <inertial>      
      <origin xyz="-0.0058214760774321153147 0.0012805650882004118198 -0.12292288528187433894" rpy="0 0 0"/>      
      <mass value="0.3326398048030183574"/>      
      <inertia ixx="0.0020719247027692600481" ixy="-2.4284458845249828833e-06" ixz="-0.00016925192938209974482" iyy="0.0020893658557290164385" iyz="-1.4965421158452737197e-05" izz="0.0001281016285196669342"/>      
    </inertial>    
  </link>  

  <joint name="left_hip_yaw" type="revolute">    
    <origin xyz="-0.0063999999999966045855 0.03399999999999939182 0.28550000000000008704" rpy="2.327572832560927136e-16 4.9789962508008699149e-17 -1.0650377544034614197e-13"/>    
    <parent link="body_link"/>    
    <child link="left_3r+rh5_leg"/>    
    <axis xyz="0 0 1"/>    
    <limit effort="1" velocity="20" lower="-0.785398163397448279" upper="0.785398163397448279"/>    
    <joint_properties friction="0.0"/>    
  </joint>  

  <link name="right_3r+rh5_leg">    
    <visual>      
      <origin xyz="0 0 0" rpy="0 -0 0"/>      
      <geometry>        
        <mesh filename="package:///meshes/right_3r+rh5_leg_visual.stl"/>        
      </geometry>      
      <material name="right_3r+rh5_leg_material">        
        <color rgba="0.71718890945443924956 0.71451534271331362813 0.54776152216434048636 1.0"/>        
      </material>      
    </visual>    
    <collision>      
      <origin xyz="0 0 0" rpy="0 -0 0"/>      
      <geometry>        
        <mesh filename="package:///meshes/right_3r+rh5_leg_collision.stl"/>        
      </geometry>      
    </collision>    
    <inertial>      
      <origin xyz="-0.0062070926364563598285 -0.001368863833266003617 -0.12292288598647738151" rpy="0 0 0"/>      
      <mass value="0.33263981812552856354"/>      
      <inertia ixx="0.0020718468534475439902" ixy="3.0872452894728312851e-06" ixz="-0.00016063857251854125842" iyy="0.0020878228874006659992" iyz="1.2493426099018985835e-05" izz="0.00012648090217262802112"/>      
    </inertial>    
  </link>  

  <joint name="right_hip_yaw" type="revolute">    
    <origin xyz="-0.0063999999999967962724 -0.034000000000000661637 0.28549999999999992051" rpy="1.2173498094910643509e-16 -6.1232339957301087894e-17 -5.033057304260250785e-13"/>    
    <parent link="body_link"/>    
    <child link="right_3r+rh5_leg"/>    
    <axis xyz="0 0 1"/>    
    <limit effort="1" velocity="20" lower="-0.785398163397448279" upper="0.785398163397448279"/>    
    <joint_properties friction="0.0"/>    
  </joint>  


</robot>