<?xml version="1.0" ?><robot name="toddlerbot_arms">  
  <link name="torso">    
    <visual>      
      <origin xyz="0 0 0" rpy="0 -0 0"/>      
      <geometry>        
        <mesh filename="package:///meshes/torso_visual.stl"/>        
      </geometry>      
      <material name="torso_material">        
        <color rgba="0.5756764758149645056 0.73345309646743483967 0.85630877307465791404 1.0"/>        
      </material>      
    </visual>    
    <collision>      
      <origin xyz="0 0 0" rpy="0 -0 0"/>      
      <geometry>        
        <mesh filename="package:///meshes/torso_collision.stl"/>        
      </geometry>      
    </collision>    
    <inertial>      
      <origin xyz="-0.0091191073850786716348 0.0035999898782853481487 0.074714667450737570764" rpy="0 0 0"/>      
      <mass value="0.60012685450989189384"/>      
      <inertia ixx="0.0016758431902176411116" ixy="-3.7928818472167753404e-05" ixz="-8.334174503158488798e-05" iyy="0.0013162908560489874638" iyz="5.6004476213218945025e-05" izz="0.0012673959172651175307"/>      
    </inertial>    
  </link>  

  <link name="left_arm_hand">    
    <visual>      
      <origin xyz="0 0 0" rpy="0 -0 0"/>      
      <geometry>        
        <mesh filename="package:///meshes/left_arm_hand_visual.stl"/>        
      </geometry>      
      <material name="left_arm_hand_material">        
        <color rgba="0.61568627450980395466 0.81176470588235294379 0.92941176470588227065 1.0"/>        
      </material>      
    </visual>    
    <collision>      
      <origin xyz="0 0 0" rpy="0 -0 0"/>      
      <geometry>        
        <mesh filename="package:///meshes/left_arm_hand_collision.stl"/>        
      </geometry>      
    </collision>    
    <inertial>      
      <origin xyz="5.8254249521811582877e-11 -5.1264642561120958965e-05 0.008244078812709491888" rpy="0 0 0"/>      
      <mass value="0.0085999999999999965361"/>      
      <inertia ixx="1.2272887040545793991e-06" ixy="-2.1429944230882620695e-14" ixz="-8.5847199149485390626e-15" iyy="2.9107306060364624323e-06" iyz="7.4623841398183150184e-09" izz="3.0803135950773496163e-06"/>      
    </inertial>    
  </link>  

  <joint name="left_sho_pitch" type="revolute">    
    <origin xyz="-0.0030000000000002949654 0.062000000000001082023 0.10423651076281742478" rpy="-1.5707963267949081043 -4.0958527081001641839e-14 3.5234047634505718213e-14"/>    
    <parent link="torso"/>    
    <child link="left_arm_hand"/>    
    <axis xyz="0 0 1"/>    
    <limit effort="1" velocity="20" lower="-3.141592653589793116" upper="1.570796326794896558"/>    
    <joint_properties friction="0.0"/>    
  </joint>  

  <link name="right_arm_hand">    
    <visual>      
      <origin xyz="0 0 0" rpy="0 -0 0"/>      
      <geometry>        
        <mesh filename="package:///meshes/right_arm_hand_visual.stl"/>        
      </geometry>      
      <material name="right_arm_hand_material">        
        <color rgba="0.61568627450980395466 0.81176470588235294379 0.92941176470588227065 1.0"/>        
      </material>      
    </visual>    
    <collision>      
      <origin xyz="0 0 0" rpy="0 -0 0"/>      
      <geometry>        
        <mesh filename="package:///meshes/right_arm_hand_collision.stl"/>        
      </geometry>      
    </collision>    
    <inertial>      
      <origin xyz="5.8254249521811582877e-11 -5.1264642561120958965e-05 0.008244078812709491888" rpy="0 0 0"/>      
      <mass value="0.0085999999999999965361"/>      
      <inertia ixx="1.2272887040545793991e-06" ixy="-2.1429944230882620695e-14" ixz="-8.5847199149485390626e-15" iyy="2.9107306060364624323e-06" iyz="7.4623841398183150184e-09" izz="3.0803135950773496163e-06"/>      
    </inertial>    
  </link>  

  <joint name="right_sho_pitch" type="revolute">    
    <origin xyz="-0.0029999999999986998872 -0.06200000000000097794 0.10423651076281731376" rpy="-1.5707963267948885644 3.4812325502379109658e-14 -3.1415926535897562566"/>    
    <parent link="torso"/>    
    <child link="right_arm_hand"/>    
    <axis xyz="0 0 1"/>    
    <limit effort="1" velocity="20" lower="-1.570796326794896558" upper="3.141592653589793116"/>    
    <joint_properties friction="0.0"/>    
  </joint>  


</robot>