<robot name="toddlerbot">
  <mujoco>
    <compiler strippath="false" balanceinertia="true" discardvisual="false" />
  </mujoco>
  <link name="torso">
    <visual>
      <origin xyz="0 0 0" rpy="0 -0 0" />
      <geometry>
        <mesh filename="../assemblies/toddlerbot/meshes/torso_visual.stl" />
      </geometry>
      <material name="torso_material">
        <color rgba="0.6197852121554117133 0.80497509985632864637 0.91238666069265517145 1.0" />
      </material>
    </visual>
    <inertial>
      <origin xyz="-0.017582789998871049819 -0.0008892412850613319944 0.066328103881054256696" rpy="0 0 0" />
      <mass value="0.38210896478125000453" />
      <inertia ixx="0.00097913100143531372858" ixy="1.368754266574914548e-05" ixz="5.3060955780646044695e-05" iyy="0.00088767318813584431599" iyz="-1.8064914536012927244e-05" izz="0.00068582374333484930409" />
    </inertial>
  </link>

  <link name="spur_1m_20t">
    <visual>
      <origin xyz="0 0 0" rpy="0 -0 0" />
      <geometry>
        <mesh filename="../assemblies/toddlerbot/meshes/spur_1m_20t_visual.stl" />
      </geometry>
      <material name="spur_1m_20t_material">
        <color rgba="0.64705882352941179736 0.64705882352941179736 0.64705882352941179736 1.0" />
      </material>
    </visual>
    <inertial>
      <origin xyz="-5.0044775065590171545e-18 6.0502252725870090006e-18 -0.0033745971730663147647" rpy="0 0 0" />
      <mass value="0.0015534950290892286448" />
      <inertia ixx="4.4726508287871812856e-08" ixy="7.684011163414536344e-24" ixz="2.7597381312606821682e-39" iyy="4.4726508287871786386e-08" iyz="-4.880475641083095171e-38" izz="7.9558906764902006609e-08" />
    </inertial>
  </link>

  <joint name="neck_yaw_drive" type="revolute">
    <origin xyz="-0.004999999999999059884 -1.8020791195763170554e-16 0.12248651076281816263" rpy="-3.1415926535897913396 1.7995135580561967136e-15 9.6455933634066887197e-16" />
    <parent link="torso" />
    <child link="spur_1m_20t" />
    <axis xyz="0 0 1" />
    <limit effort="1" velocity="20" lower="-3.141592653589793116" upper="3.141592653589793116" />
    <joint_properties friction="0.0" />
  </joint>

  <link name="neck_yaw_link">
    <visual>
      <origin xyz="0 0 0" rpy="0 -0 0" />
      <geometry>
        <mesh filename="../assemblies/toddlerbot/meshes/neck_yaw_link_visual.stl" />
      </geometry>
      <material name="neck_yaw_link_material">
        <color rgba="0.33636252417476664167 0.48680769190259887136 0.74976123534949801197 1.0" />
      </material>
    </visual>
    <inertial>
      <origin xyz="2.7291286461356290677e-05 0.00019798992283539515501 -0.0115274120371948504" rpy="0 0 0" />
      <mass value="0.0085168305947458250449" />
      <inertia ixx="1.0407116999274388487e-06" ixy="-2.4210150464746039776e-11" ixz="4.7246803220671246024e-10" iyy="1.1240009954110499114e-06" iyz="3.0834841754646676679e-08" izz="3.1587565167292060697e-07" />
    </inertial>
  </link>

  <link name="neck_pitch_link">
    <visual>
      <origin xyz="0 0 0" rpy="0 -0 0" />
      <geometry>
        <mesh filename="../assemblies/toddlerbot/meshes/neck_pitch_link_visual.stl" />
      </geometry>
      <material name="neck_pitch_link_material">
        <color rgba="0.75175531149912766526 0.80237790269364195339 0.88100511756510224703 1.0" />
      </material>
    </visual>
    <inertial>
      <origin xyz="-0.0033208985050365335059 -0.033447827507434767236 -0.00017266927552015079862" rpy="0 0 0" />
      <mass value="0.10851928601941271402" />
      <inertia ixx="7.4643011916861726944e-05" ixy="1.9512994501134094261e-06" ixz="2.6631618432505370407e-06" iyy="6.1956827409922912795e-05" iyz="-1.1454163205103217525e-05" izz="2.701288336202765537e-05" />
    </inertial>
  </link>

  <link name="spur_gear_(13_teeth)">
    <visual>
      <origin xyz="0 0 0" rpy="0 -0 0" />
      <geometry>
        <mesh filename="../assemblies/toddlerbot/meshes/spur_gear_(13_teeth)_visual.stl" />
      </geometry>
      <material name="spur_gear_(13_teeth)_material">
        <color rgba="0.64705882352941179736 0.64705882352941179736 0.64705882352941179736 1.0" />
      </material>
    </visual>
    <inertial>
      <origin xyz="1.0399873342418501553e-09 2.3905206814663368286e-10 -0.0092751511485596373902" rpy="0 0 0" />
      <mass value="0.00081469437497230855032" />
      <inertia ixx="2.0244839552178295378e-08" ixy="-2.9046301764120405049e-15" ixz="8.297606606936787006e-15" iyy="2.0244841689973771385e-08" iyz="-1.31421177847285757e-15" izz="1.8905472907863310999e-08" />
    </inertial>
  </link>

  <joint name="neck_pitch_drive" type="revolute">
    <origin xyz="-1.4571677198205179593e-16 -0.015650000000000330314 0.0087999999999993777644" rpy="-2.1434555572207676319e-16 -1.5880065549567459396e-15 1.570796326794896558" />
    <parent link="neck_pitch_link" />
    <child link="spur_gear_(13_teeth)" />
    <axis xyz="0 0 1" />
    <limit effort="1" velocity="20" lower="-1.570796326794896558" upper="1.570796326794896558" />
    <joint_properties friction="0.0" />
  </joint>

  <joint name="neck_pitch_driven" type="revolute">
    <origin xyz="3.7500073185592341929e-10 0.0051500000614755261225 -0.027499999999999941158" rpy="1.57079632679489678 -1.7934420258902467287e-15 -3.1415926535897922278" />
    <parent link="neck_yaw_link" />
    <child link="neck_pitch_link" />
    <axis xyz="0 0 1" />
    <limit effort="1" velocity="20" lower="-1.570796326794896558" upper="1.570796326794896558" />
    <joint_properties friction="0.0" />
  </joint>

  <joint name="neck_yaw_driven" type="revolute">
    <origin xyz="0.016000000000001915468 1.4752314067929367773e-17 0.12348651076281796923" rpy="-3.141592653589793116 -0 -3.1415926535897922278" />
    <parent link="torso" />
    <child link="neck_yaw_link" />
    <axis xyz="0 0 1" />
    <limit effort="1" velocity="20" lower="-3.141592653589793116" upper="3.141592653589793116" />
    <joint_properties friction="0.0" />
  </joint>

  <link name="waist_gears">
    <visual>
      <origin xyz="0 0 0" rpy="0 -0 0" />
      <geometry>
        <mesh filename="../assemblies/toddlerbot/meshes/waist_gears_visual.stl" />
      </geometry>
      <material name="waist_gears_material">
        <color rgba="0.2705751638183052088 0.53648836590125015267 0.70305495274644791426 1.0" />
      </material>
    </visual>
    <inertial>
      <origin xyz="6.5469454462684754055e-08 -5.678589769108444202e-10 -0.012726165583898677025" rpy="0 0 0" />
      <mass value="0.023315805669179824611" />
      <inertia ixx="6.9043104388291928151e-06" ixy="-1.8428638769590440561e-11" ixz="9.9668712610669700131e-13" iyy="1.162409197167636598e-06" iyz="-3.3260430300288233958e-10" izz="6.8701920560919842564e-06" />
    </inertial>
  </link>

  <link name="waist_link">
    <visual>
      <origin xyz="0 0 0" rpy="0 -0 0" />
      <geometry>
        <mesh filename="../assemblies/toddlerbot/meshes/waist_link_visual.stl" />
      </geometry>
      <material name="waist_link_material">
        <color rgba="0.63066856640767587905 0.67759035867951045162 0.66849819411858002471 1.0" />
      </material>
    </visual>
    <inertial>
      <origin xyz="-7.8326157945763225844e-07 -0.026309055188168648659 0.029773273854826105139" rpy="0 0 0" />
      <mass value="0.15193452399186058166" />
      <inertia ixx="6.3853955317574355379e-05" ixy="6.7244006990957541522e-10" ixz="3.1782521385896526105e-06" iyy="0.00018554067350207199979" iyz="-3.2622478832003394146e-06" izz="0.00014578323476960398171" />
    </inertial>
  </link>

  <link name="spiral_bevel_1m_14t_30deg">
    <visual>
      <origin xyz="0 0 0" rpy="0 -0 0" />
      <geometry>
        <mesh filename="../assemblies/toddlerbot/meshes/spiral_bevel_1m_14t_30deg_visual.stl" />
      </geometry>
      <material name="spiral_bevel_1m_14t_30deg_material">
        <color rgba="0.64705882352941179736 0.64705882352941179736 0.64705882352941179736 1.0" />
      </material>
    </visual>
    <inertial>
      <origin xyz="8.2641075233036431769e-10 3.4055789828804639008e-10 0.0068612577407481684794" rpy="0 0 0" />
      <mass value="0.00067997563436136235649" />
      <inertia ixx="1.2174575798018975493e-08" ixy="3.8216070047630807068e-18" ixz="4.7204547823421934484e-16" iyy="1.2174575801813732727e-08" iyz="-2.6184097732597935737e-16" izz="1.3178653206314311711e-08" />
    </inertial>
  </link>

  <joint name="waist_act_1" type="revolute">
    <origin xyz="4.8392086706372466624e-17 -0.019600000000000009776 0.012750000000000042549" rpy="-1.5707963267948961139 -1.5707963267948215069 0" />
    <parent link="waist_link" />
    <child link="spiral_bevel_1m_14t_30deg" />
    <axis xyz="0 0 1" />
    <limit effort="1" velocity="20" lower="-2.7925268031909271649" upper="2.7925268031909271649" />
    <joint_properties friction="0.0" />
  </joint>

  <link name="spiral_bevel_1m_14t_30deg_2">
    <visual>
      <origin xyz="0 0 0" rpy="0 -0 0" />
      <geometry>
        <mesh filename="../assemblies/toddlerbot/meshes/spiral_bevel_1m_14t_30deg_2_visual.stl" />
      </geometry>
      <material name="spiral_bevel_1m_14t_30deg_2_material">
        <color rgba="0.64705882352941179736 0.64705882352941179736 0.64705882352941179736 1.0" />
      </material>
    </visual>
    <inertial>
      <origin xyz="7.2990964661290291815e-10 5.1591309341166232978e-10 0.0068612577407481702141" rpy="0 0 0" />
      <mass value="0.00067997563436136235649" />
      <inertia ixx="1.2174575796548751289e-08" ixy="2.6199053407227811934e-18" ixz="5.1847541137723511287e-16" iyy="1.2174575803283978437e-08" iyz="-1.502360766603294444e-16" izz="1.3178653206314315019e-08" />
    </inertial>
  </link>

  <joint name="waist_act_2" type="revolute">
    <origin xyz="-6.321225856846266752e-16 -0.019600000000000079164 0.032750000000000834" rpy="-1.5707963267948976682 -1.3463968515393018865 1.5503953316521244903e-14" />
    <parent link="waist_link" />
    <child link="spiral_bevel_1m_14t_30deg_2" />
    <axis xyz="0 0 1" />
    <limit effort="1" velocity="20" lower="-2.7925268031909271649" upper="2.7925268031909271649" />
    <joint_properties friction="0.0" />
  </joint>

  <link name="spur_gear_19_teeth">
    <visual>
      <origin xyz="0 0 0" rpy="0 -0 0" />
      <geometry>
        <mesh filename="../assemblies/toddlerbot/meshes/spur_gear_19_teeth_visual.stl" />
      </geometry>
      <material name="spur_gear_19_teeth_material">
        <color rgba="0.61568627450980395466 0.81176470588235294379 0.92941176470588238168 1.0" />
      </material>
    </visual>
    <inertial>
      <origin xyz="-4.9156135348702214374e-09 9.0060874048927839393e-10 -0.0045295192537419945097" rpy="0 0 0" />
      <mass value="0.0010993711450650535313" />
      <inertia ixx="2.9215018435433082044e-08" ixy="2.5903313772733109345e-16" ixz="-8.424261245563750688e-15" iyy="2.9215021540034058468e-08" iyz="1.5226232384526170773e-15" izz="4.5709977027671368266e-08" />
    </inertial>
  </link>

  <joint name="left_hip_yaw_drive" type="revolute">
    <origin xyz="-0.036999999999999179379 -0.037100000000004823564 0.039500000000000423661" rpy="-1.5707963267950579844 5.71102443800098102e-13 2.6906455702027046663e-13" />
    <parent link="waist_link" />
    <child link="spur_gear_19_teeth" />
    <axis xyz="0 0 1" />
    <limit effort="1" velocity="20" lower="-1.570796326794896558" upper="1.570796326794896558" />
    <joint_properties friction="0.0" />
  </joint>

  <link name="spur_gear_21_teeth">
    <visual>
      <origin xyz="0 0 0" rpy="0 -0 0" />
      <geometry>
        <mesh filename="../assemblies/toddlerbot/meshes/spur_gear_21_teeth_visual.stl" />
      </geometry>
      <material name="spur_gear_21_teeth_material">
        <color rgba="0.61568627450980395466 0.81176470588235294379 0.92941176470588238168 1.0" />
      </material>
    </visual>
    <inertial>
      <origin xyz="-4.7814841733033882526e-10 1.2610017463689733481e-12 -0.0024944618616143366362" rpy="0 0 0" />
      <mass value="0.0010063046528317972673" />
      <inertia ixx="3.1842855421068488283e-08" ixy="2.1452075797961618719e-37" ixz="-1.1964366566353525762e-38" iyy="3.1842855426953779079e-08" iyz="1.1823805759556976152e-38" izz="5.9529380586728028132e-08" />
    </inertial>
  </link>

  <joint name="left_leg_fixed" type="fixed">
    <origin xyz="3.0357660829594124152e-18 -1.3877787807814456755e-17 -0.0049999999999999697464" rpy="-1.0439449364097525548e-14 1.9685459861175557675e-31 1.834678230847674038e-29" />
    <parent link="spur_gear_21_teeth" />
    <child link="hip_yaw_link" />
    <axis xyz="0 0 1" />
    <limit effort="1" velocity="20" />
    <joint_properties friction="0.0" />
  </joint>

  <joint name="left_hip_yaw_driven" type="revolute">
    <origin xyz="-0.037000000000000005107 -0.041100000000000108669 0.019500000000000006911" rpy="-1.5707963267948841235 1.5707963267948932273 0" />
    <parent link="waist_link" />
    <child link="spur_gear_21_teeth" />
    <axis xyz="0 0 1" />
    <limit effort="1" velocity="20" lower="-1.570796326794896558" upper="1.570796326794896558" />
    <joint_properties friction="0.0" />
  </joint>

  <link name="spur_gear_19_teeth_2">
    <visual>
      <origin xyz="0 0 0" rpy="0 -0 0" />
      <geometry>
        <mesh filename="../assemblies/toddlerbot/meshes/spur_gear_19_teeth_2_visual.stl" />
      </geometry>
      <material name="spur_gear_19_teeth_2_material">
        <color rgba="0.61568627450980395466 0.81176470588235294379 0.92941176470588238168 1.0" />
      </material>
    </visual>
    <inertial>
      <origin xyz="-4.9156135418091161685e-09 9.0060873701983133858e-10 -0.0045295192537419875708" rpy="0 0 0" />
      <mass value="0.0010993711450650535313" />
      <inertia ixx="2.9215018435433095279e-08" ixy="2.5903313731232818381e-16" ixz="-8.4242612455637522657e-15" iyy="2.9215021540034058468e-08" iyz="1.5226232384526170773e-15" izz="4.5709977027671368266e-08" />
    </inertial>
  </link>

  <joint name="right_hip_yaw_drive" type="revolute">
    <origin xyz="0.037000000000000358991 -0.037100000000003852119 0.039500000000000062839" rpy="-1.5707963267949709429 3.0764921674346154011e-13 2.7727445053553844104e-13" />
    <parent link="waist_link" />
    <child link="spur_gear_19_teeth_2" />
    <axis xyz="0 0 1" />
    <limit effort="1" velocity="20" lower="-1.570796326794896558" upper="1.570796326794896558" />
    <joint_properties friction="0.0" />
  </joint>

  <link name="spur_gear_21_teeth_2">
    <visual>
      <origin xyz="0 0 0" rpy="0 -0 0" />
      <geometry>
        <mesh filename="../assemblies/toddlerbot/meshes/spur_gear_21_teeth_2_visual.stl" />
      </geometry>
      <material name="spur_gear_21_teeth_2_material">
        <color rgba="0.61568627450980395466 0.81176470588235294379 0.92941176470588238168 1.0" />
      </material>
    </visual>
    <inertial>
      <origin xyz="-4.7814841733033882526e-10 -1.2610156241567811626e-12 -0.0025055381383856678047" rpy="0 0 0" />
      <mass value="0.0010063046528317972673" />
      <inertia ixx="3.1842855421068488283e-08" ixy="1.560614116831242474e-38" ixz="2.021036725007793052e-39" iyy="3.1842855426953779079e-08" iyz="5.2356557841516804612e-39" izz="5.9529380586728028132e-08" />
    </inertial>
  </link>

  <joint name="right_leg_fixed" type="fixed">
    <origin xyz="0 0 -0.004999999999999997502" rpy="1.0732181508787092545e-15 5.1822669723995480778e-16 -1.6653345369374924824e-16" />
    <parent link="spur_gear_21_teeth_2" />
    <child link="hip_yaw_link_2" />
    <axis xyz="0 0 1" />
    <limit effort="1" velocity="20" />
    <joint_properties friction="0.0" />
  </joint>

  <joint name="right_hip_yaw_driven" type="revolute">
    <origin xyz="0.037000000000000005107 -0.041100000000000011524 0.019500000000000010381" rpy="-1.5707963267948983344 1.5707963267948950037 0" />
    <parent link="waist_link" />
    <child link="spur_gear_21_teeth_2" />
    <axis xyz="0 0 1" />
    <limit effort="1" velocity="20" lower="-1.570796326794896558" upper="1.570796326794896558" />
    <joint_properties friction="0.0" />
  </joint>

  <joint name="waist_roll" type="revolute">
    <origin xyz="-6.2255683191263486807e-20 0.022707865260692461362 -0.013000000000000004607" rpy="1.5707963267948952257 1.2017992026080351615e-15 4.2181022606678868535e-16" />
    <parent link="waist_gears" />
    <child link="waist_link" />
    <axis xyz="0 0 1" />
    <limit effort="1" velocity="20" lower="-0.52359877559829881566" upper="0.52359877559829881566" />
    <joint_properties friction="0.0" />
  </joint>

  <joint name="waist_yaw" type="revolute">
    <origin xyz="-1.7347234759768070944e-18 -1.9721522630525295135e-31 0" rpy="2.0946901476030943553e-15 7.1861600448343401911e-16 -1.5707963267948228392" />
    <parent link="torso" />
    <child link="waist_gears" />
    <axis xyz="0 0 1" />
    <limit effort="1" velocity="20" lower="-1.570796326794896558" upper="1.570796326794896558" />
    <joint_properties friction="0.0" />
  </joint>

  <joint name="left_arm_fixed" type="fixed">
    <origin xyz="0.0010000000000009051128 0.049000000000000341893 0.11948651076281792405" rpy="-5.9230088976703815107e-16 1.7322096859285544219e-15 1.6762794059802379347e-29" />
    <parent link="torso" />
    <child link="xc430" />
    <axis xyz="0 0 1" />
    <limit effort="1" velocity="20" />
    <joint_properties friction="0.0" />
  </joint>

  <joint name="right_arm_fixed" type="fixed">
    <origin xyz="0.0010000000000010308802 -0.049000000000000321076 0.11948651076281791017" rpy="-5.9230088976591895466e-16 1.732209685967738918e-15 1.6762794059934078982e-29" />
    <parent link="torso" />
    <child link="xc430_2" />
    <axis xyz="0 0 1" />
    <limit effort="1" velocity="20" />
    <joint_properties friction="0.0" />
  </joint>


  <link name="hip_yaw_link">
    <visual>
      <origin xyz="0 0 0" rpy="0 -0 0" />
      <geometry>
        <mesh filename="../assemblies/left_leg_XM430/meshes/left_hip_yaw_link_visual.stl" />
      </geometry>
      <material name="hip_yaw_link_material">
        <color rgba="0.61568627450980395466 0.81176470588235294379 0.92941176470588238168 1.0" />
      </material>
    </visual>
    <inertial>
      <origin xyz="5.0634076589877702038e-19 -2.7164092610786665035e-19 -0.0098390489054829121524" rpy="0 0 0" />
      <mass value="0.01799999999999999864" />
      <inertia ixx="2.638503389144253662e-06" ixy="0" ixz="0" iyy="7.6596731957046873405e-06" iyz="0" izz="7.7220708070894752896e-06" />
    </inertial>
  </link>

  <link name="hip_roll_link">
    <visual>
      <origin xyz="0 0 0" rpy="0 -0 0" />
      <geometry>
        <mesh filename="../assemblies/left_leg_XM430/meshes/left_hip_roll_link_visual.stl" />
      </geometry>
      <material name="hip_roll_link_material">
        <color rgba="0.51698661238356036218 0.50347815951093466413 0.49050589017722012741 1.0" />
      </material>
    </visual>
    <inertial>
      <origin xyz="-0.01199984958218530337 -0.0004959809079404651393 -0.018504111838597576967" rpy="0 0 0" />
      <mass value="0.10699970659110669136" />
      <inertia ixx="2.2075996228675282966e-05" ixy="-4.5005801828807040447e-08" ixz="-4.5362214344039340626e-08" iyy="2.9866686933523838834e-05" iyz="-5.5606319466519229463e-07" izz="2.9866720157736157201e-05" />
    </inertial>
  </link>

  <link name="left_hip_pitch_link_xm430">
    <visual>
      <origin xyz="0 0 0" rpy="0 -0 0" />
      <geometry>
        <mesh filename="../assemblies/left_leg_XM430/meshes/left_hip_pitch_link_xm430_visual.stl" />
      </geometry>
      <material name="left_hip_pitch_link_xm430_material">
        <color rgba="0.58789271125196740364 0.76961381353217661605 0.89677560122075017368 1.0" />
      </material>
    </visual>
    <inertial>
      <origin xyz="-0.0021034922210874298226 -0.056433529773950774633 -0.01878212058974302115" rpy="0 0 0" />
      <mass value="0.035548688791081778371" />
      <inertia ixx="4.7516856109358680967e-05" ixy="3.1522442711494380493e-07" ixz="2.5035892596237987366e-07" iyy="1.1480134512562668991e-05" iyz="-3.2345708465544645217e-07" izz="4.5084071722891830574e-05" />
    </inertial>
  </link>

  <link name="left_calf_link">
    <visual>
      <origin xyz="0 0 0" rpy="0 -0 0" />
      <geometry>
        <mesh filename="../assemblies/left_leg_XM430/meshes/left_calf_link_visual.stl" />
      </geometry>
      <material name="left_calf_link_material">
        <color rgba="0.61177930930733659398 0.71653254923097897677 0.74989274724786592063 1.0" />
      </material>
    </visual>
    <inertial>
      <origin xyz="0.0011880880234995086671 -0.049643068417602145836 -0.0098634853143295432576" rpy="0 0 0" />
      <mass value="0.079607494529051442411" />
      <inertia ixx="4.8048473174225995465e-05" ixy="3.5190650833675639945e-06" ixz="3.9918574956050711346e-07" iyy="1.4293033116537751201e-05" iyz="4.8859952267608235656e-07" izz="5.1177637188996114167e-05" />
    </inertial>
  </link>

  <link name="ank_pitch_link">
    <visual>
      <origin xyz="0 0 0" rpy="0 -0 0" />
      <geometry>
        <mesh filename="../assemblies/left_leg_XM430/meshes/left_ank_pitch_link_visual.stl" />
      </geometry>
      <material name="ank_pitch_link_material">
        <color rgba="0.63189161126160264814 0.7266866879354088038 0.78356373393969258601 1.0" />
      </material>
    </visual>
    <inertial>
      <origin xyz="0.00059528282565925356995 -4.0269680598773380526e-08 7.7616089895315615493e-08" rpy="0 0 0" />
      <mass value="0.0042238381753791614387" />
      <inertia ixx="3.9782741364683718205e-07" ixy="-1.6834347673011815484e-13" ixz="2.0919187769527529349e-14" iyy="4.3705254067427603978e-07" iyz="-1.6428821984567374725e-12" izz="8.8858574534605604009e-08" />
    </inertial>
  </link>

  <link name="ank_roll_link">
    <visual>
      <origin xyz="0 0 0" rpy="0 -0 0" />
      <geometry>
        <mesh filename="../assemblies/left_leg_XM430/meshes/left_ank_roll_link_visual.stl" />
      </geometry>
      <material name="ank_roll_link_material">
        <color rgba="0.61568627450980395466 0.81176470588235294379 0.92941176470588215963 1.0" />
      </material>
    </visual>
    <inertial>
      <origin xyz="-1.326857245972531542e-07 0.026796353429500447546 -0.0010526854006037489938" rpy="0 0 0" />
      <mass value="0.024800000000000002598" />
      <inertia ixx="1.9846878556458577087e-05" ixy="3.3200060665790483864e-11" ixz="1.9151591849009576669e-11" iyy="1.8695132008820605535e-05" iyz="-1.6314461615565737141e-06" izz="5.1708394998630578918e-06" />
    </inertial>
  </link>

  <link name="ank_rr_link">
    <visual>
      <origin xyz="0 0 0" rpy="0 -0 0" />
      <geometry>
        <mesh filename="../assemblies/left_leg_XM430/meshes/left_ank_rr_link_visual.stl" />
      </geometry>
      <material name="ank_rr_link_material">
        <color rgba="0.61568627450980395466 0.81176470588235294379 0.92941176470588238168 1.0" />
      </material>
    </visual>
    <inertial>
      <origin xyz="-4.5249610960602408495e-05 0.00630964298363145739 -3.6748618882445427259e-18" rpy="0 0 0" />
      <mass value="0.0014499999999999999001" />
      <inertia ixx="2.9739579267716143416e-08" ixy="2.4213146797978030914e-10" ixz="3.5523394884496750797e-14" iyy="2.7430027724071957055e-08" iyz="-4.2623487632672813461e-32" izz="4.2921949116163672436e-08" />
    </inertial>
  </link>

  <link name="ank_motor_rod_long">
    <visual>
      <origin xyz="0 0 0" rpy="0 -0 0" />
      <geometry>
        <mesh filename="../assemblies/left_leg_XM430/meshes/left_ank_motor_rod_long_visual.stl" />
      </geometry>
      <material name="ank_motor_rod_long_material">
        <color rgba="0.63549975559783222767 0.70774393017020453822 0.75109043491362792455 1.0" />
      </material>
    </visual>
    <inertial>
      <origin xyz="2.4855089041408689308e-10 0.03455901997406223003 0.0009385170487845105429" rpy="0 0 0" />
      <mass value="0.0021712857268636710437" />
      <inertia ixx="8.5350290058000506697e-07" ixy="1.4884244339179740713e-14" ixz="4.5749525025637242493e-11" iyy="1.3237321792739610462e-08" iyz="-4.3668910960846004808e-09" izz="8.5812217519451853453e-07" />
    </inertial>
  </link>

  <joint name="left_ank_L_rev_2" type="revolute">
    <origin xyz="-1.4571677198205179593e-16 0.0099999999999997868372 4.8572257327350598644e-17" rpy="-1.5707963267948941155 1.3320366994106946912 -1.5707963267949134334" />
    <parent link="ank_rr_link" />
    <child link="ank_motor_rod_long" />
    <axis xyz="0 0 1" />
    <limit effort="1" velocity="20" lower="-1.570796326794896558" upper="1.570796326794896558" />
    <joint_properties friction="0.0" />
  </joint>

  <joint name="left_ank_L_rev_1" type="revolute">
    <origin xyz="-0.018000000000000012518 0.016000000000000125233 -0.020600000000000000255" rpy="-8.4059225450220432022e-16 5.2239277705698694431e-16 3.1233695685467259828" />
    <parent link="ank_roll_link" />
    <child link="ank_rr_link" />
    <axis xyz="0 0 1" />
    <limit effort="1" velocity="20" lower="-1.570796326794896558" upper="1.570796326794896558" />
    <joint_properties friction="0.0" />
  </joint>

  <link name="ank_rr_link_2">
    <visual>
      <origin xyz="0 0 0" rpy="0 -0 0" />
      <geometry>
        <mesh filename="../assemblies/left_leg_XM430/meshes/left_ank_rr_link_2_visual.stl" />
      </geometry>
      <material name="ank_rr_link_2_material">
        <color rgba="0.61568627450980395466 0.81176470588235294379 0.92941176470588238168 1.0" />
      </material>
    </visual>
    <inertial>
      <origin xyz="-4.5249610960605891495e-05 -0.00630964298363145739 2.0541493629143806588e-19" rpy="0 0 0" />
      <mass value="0.0014499999999999999001" />
      <inertia ixx="2.9739579267716163268e-08" ixy="-2.4213146797978056763e-10" ixz="-3.5523394884496763419e-14" iyy="2.7430027724071957055e-08" iyz="9.9853089481997372062e-32" izz="4.2921949116163672436e-08" />
    </inertial>
  </link>

  <link name="ank_motor_rod_short">
    <visual>
      <origin xyz="0 0 0" rpy="0 -0 0" />
      <geometry>
        <mesh filename="../assemblies/left_leg_XM430/meshes/left_ank_motor_rod_short_visual.stl" />
      </geometry>
      <material name="ank_motor_rod_short_material">
        <color rgba="0.41222606689734719865 0.58339100346020766885 0.8110726643598615837 1.0" />
      </material>
    </visual>
    <inertial>
      <origin xyz="2.6038938586306682781e-10 0.023830465465870892539 0.00090403506359618016151" rpy="0 0 0" />
      <mass value="0.0017000000000000001221" />
      <inertia ixx="3.3153416252670167126e-07" ixy="8.7419771574814541053e-15" ixz="4.5749941567649142899e-11" iyy="1.0947363610305767602e-08" iyz="-3.5863098646400448228e-09" izz="3.3621340447865331982e-07" />
    </inertial>
  </link>

  <joint name="left_ank_S_rev_2" type="revolute">
    <origin xyz="-6.2450045135165055399e-17 -0.0099999999999998423483 -4.1633363423443370266e-17" rpy="-1.5707963267948958919 -1.2119133862911237731 -1.5707963267948858999" />
    <parent link="ank_rr_link_2" />
    <child link="ank_motor_rod_short" />
    <axis xyz="0 0 1" />
    <limit effort="1" velocity="20" lower="-1.570796326794896558" upper="1.570796326794896558" />
    <joint_properties friction="0.0" />
  </joint>

  <joint name="left_ank_S_rev_1" type="revolute">
    <origin xyz="0.017999999999999995171 0.016000000000000125233 -0.020600000000000007194" rpy="2.3133772225631454961e-16 4.5369818524477751182e-16 0.026118548507388435198" />
    <parent link="ank_roll_link" />
    <child link="ank_rr_link_2" />
    <axis xyz="0 0 1" />
    <limit effort="1" velocity="20" lower="-1.570796326794896558" upper="1.570796326794896558" />
    <joint_properties friction="0.0" />
  </joint>

  <joint name="left_ank_roll" type="revolute">
    <origin xyz="0.0014999999999999969955 -5.5511151231257827021e-17 -1.116728237660069567e-17" rpy="5.4670424773813653591e-26 1.570796326794896558 0" />
    <parent link="ank_pitch_link" />
    <child link="ank_roll_link" />
    <axis xyz="0 0 1" />
    <limit effort="1" velocity="20" lower="-0.785398163397448279" upper="0.785398163397448279" />
    <joint_properties friction="0.0" />
  </joint>

  <joint name="left_ank_pitch" type="revolute">
    <origin xyz="1.7782265719353869385e-16 -0.099999999999999367173 -0.01040000000000083219" rpy="-1.1833532294864106881e-14 4.9479686682726630759e-20 -3.141592653589793116" />
    <parent link="left_calf_link" />
    <child link="ank_pitch_link" />
    <axis xyz="0 0 1" />
    <limit effort="1" velocity="20" lower="-0.785398163397448279" upper="0.95993108859688125456" />
    <joint_properties friction="0.0" />
  </joint>

  <link name="ank_motor_arm">
    <visual>
      <origin xyz="0 0 0" rpy="0 -0 0" />
      <geometry>
        <mesh filename="../assemblies/left_leg_XM430/meshes/left_ank_motor_arm_visual.stl" />
      </geometry>
      <material name="ank_motor_arm_material">
        <color rgba="0.62517751827980905244 0.70593642422614044651 0.75978993426662777555 1.0" />
      </material>
    </visual>
    <inertial>
      <origin xyz="0.014511489101591673254 1.6149252322944875367e-17 0.0040925443765950589997" rpy="0 0 0" />
      <mass value="0.0020595846677894939954" />
      <inertia ixx="2.7591836756521862443e-08" ixy="-2.122037364747248789e-22" ixz="-3.0270788206594736006e-08" iyy="1.6138599216238408821e-07" iyz="-3.965998194135607124e-23" izz="1.643783676501625577e-07" />
    </inertial>
  </link>

  <joint name="left_ank_act_1" type="revolute">
    <origin xyz="0.013499999999996521727 -0.044499999999990991206 0.004000000000004368117" rpy="-4.1933768254600954213e-13 -2.2608993309587937077e-13 -0.21173394130242484401" />
    <parent link="left_calf_link" />
    <child link="ank_motor_arm" />
    <axis xyz="0 0 1" />
    <limit effort="1" velocity="20" lower="-1.3089969389957472057" upper="1.3089969389957472057" />
    <joint_properties friction="0.0" />
  </joint>

  <link name="ank_motor_arm_2">
    <visual>
      <origin xyz="0 0 0" rpy="0 -0 0" />
      <geometry>
        <mesh filename="../assemblies/left_leg_XM430/meshes/left_ank_motor_arm_2_visual.stl" />
      </geometry>
      <material name="ank_motor_arm_2_material">
        <color rgba="0.62517751827980905244 0.70593642422614044651 0.75978993426662777555 1.0" />
      </material>
    </visual>
    <inertial>
      <origin xyz="0.014511489101591607334 -1.6909149467570922096e-17 0.0040925443765950589997" rpy="0 0 0" />
      <mass value="0.0020595846677894939954" />
      <inertia ixx="2.7591836756521849208e-08" ixy="1.7248964524221960755e-22" ixz="-3.0270788206594504395e-08" iyy="1.6138599216238257943e-07" iyz="2.1742002146829879954e-23" izz="1.6437836765016112833e-07" />
    </inertial>
  </link>

  <joint name="left_ank_act_2" type="revolute">
    <origin xyz="0.013499999999999821171 -0.064499999999989482413 -0.024800000000000977513" rpy="-3.141592653589404982 8.5681358223374411603e-14 -0.22995607267358961212" />
    <parent link="left_calf_link" />
    <child link="ank_motor_arm_2" />
    <axis xyz="0 0 1" />
    <limit effort="1" velocity="20" lower="-1.3089969389957472057" upper="1.3089969389957472057" />
    <joint_properties friction="0.0" />
  </joint>

  <joint name="left_knee" type="revolute">
    <origin xyz="1.71083466609787999e-16 -0.095999999999999086064 -0.0092000000000000258654" rpy="-1.1991266448696223104e-14 1.4169663141522339643e-15 2.5724847819777364634e-18" />
    <parent link="left_hip_pitch_link_xm430" />
    <child link="left_calf_link" />
    <axis xyz="0 0 1" />
    <limit effort="1" velocity="20" lower="0" upper="1.9198621771937625091" />
    <joint_properties friction="0.0" />
  </joint>

  <joint name="left_hip_pitch" type="revolute">
    <origin xyz="-0.024000000716151929925 -0.01900000015243963683 -0.019000000152454777497" rpy="1.5707963267952702591 1.5707963267945455055 0" />
    <parent link="hip_roll_link" />
    <child link="left_hip_pitch_link_xm430" />
    <axis xyz="0 0 1" />
    <limit effort="1" velocity="20" lower="-1.570796326794896558" upper="1.570796326794896558" />
    <joint_properties friction="0.0" />
  </joint>

  <joint name="left_hip_roll" type="revolute">
    <origin xyz="0.018999999999999999528 -2.8647205520269057584e-18 -0.026000000000000002276" rpy="3.141592653589793116 -1.570796326794896558 0" />
    <parent link="hip_yaw_link" />
    <child link="hip_roll_link" />
    <axis xyz="0 0 1" />
    <limit effort="1" velocity="20" lower="-0.785398163397448279" upper="1.570796326794896558" />
    <joint_properties friction="0.0" />
  </joint>


  <link name="hip_yaw_link_2">
    <visual>
      <origin xyz="0 0 0" rpy="0 -0 0" />
      <geometry>
        <mesh filename="../assemblies/right_leg_XM430/meshes/right_hip_yaw_link_visual.stl" />
      </geometry>
      <material name="hip_yaw_link_material">
        <color rgba="0.61568627450980395466 0.81176470588235294379 0.92941176470588238168 1.0" />
      </material>
    </visual>
    <inertial>
      <origin xyz="-5.0634076589877702038e-19 2.7164092610786665035e-19 -0.0098390489054829121524" rpy="0 0 0" />
      <mass value="0.01799999999999999864" />
      <inertia ixx="2.638503389144253662e-06" ixy="0" ixz="0" iyy="7.6596731957046873405e-06" iyz="0" izz="7.7220708070894752896e-06" />
    </inertial>
  </link>

  <link name="hip_roll_link_2">
    <visual>
      <origin xyz="0 0 0" rpy="0 -0 0" />
      <geometry>
        <mesh filename="../assemblies/right_leg_XM430/meshes/right_hip_roll_link_visual.stl" />
      </geometry>
      <material name="hip_roll_link_material">
        <color rgba="0.51698661238356036218 0.50347815951093466413 0.49050589017722012741 1.0" />
      </material>
    </visual>
    <inertial>
      <origin xyz="-0.011999849582183100272 -0.00049598090794401839508 -0.018504111838595651424" rpy="0 0 0" />
      <mass value="0.10699970659110669136" />
      <inertia ixx="2.2075996228674994975e-05" ixy="-4.5005801829288313979e-08" ixz="-4.5362214342477828771e-08" iyy="2.9866686933523046012e-05" iyz="-5.5606319466522384661e-07" izz="2.9866720157734995072e-05" />
    </inertial>
  </link>

  <link name="right_hip_pitch_link_xm430">
    <visual>
      <origin xyz="0 0 0" rpy="0 -0 0" />
      <geometry>
        <mesh filename="../assemblies/right_leg_XM430/meshes/right_hip_pitch_link_xm430_visual.stl" />
      </geometry>
      <material name="right_hip_pitch_link_xm430_material">
        <color rgba="0.58789271125196773671 0.76961381353217694912 0.89677560122075017368 1.0" />
      </material>
    </visual>
    <inertial>
      <origin xyz="0.0021006649942336111554 -0.056435111435693005588 -0.01878211574616768173" rpy="0 0 0" />
      <mass value="0.035548688791081764493" />
      <inertia ixx="4.7524489027106042293e-05" ixy="-3.118356473346120052e-07" ixz="-2.5180919440227332812e-07" iyy="1.1474508196147079308e-05" iyz="-3.24481121151267744e-07" izz="4.5086069259999308047e-05" />
    </inertial>
  </link>

  <link name="right_calf_link">
    <visual>
      <origin xyz="0 0 0" rpy="0 -0 0" />
      <geometry>
        <mesh filename="../assemblies/right_leg_XM430/meshes/right_calf_link_visual.stl" />
      </geometry>
      <material name="right_calf_link_material">
        <color rgba="0.61177930930733637194 0.71653254923097875473 0.74989274724786569859 1.0" />
      </material>
    </visual>
    <inertial>
      <origin xyz="0.001188088410885886851 0.04964306657501051101 -0.0098634853265742155476" rpy="0 0 0" />
      <mass value="0.079607494529051442411" />
      <inertia ixx="4.8056790185738451637e-05" ixy="-3.5190664140524625078e-06" ixz="3.9918569370893101136e-07" iyy="1.4293033414473587631e-05" iyz="-4.8654596308584805256e-07" izz="5.1185953583038370476e-05" />
    </inertial>
  </link>

  <link name="ank_pitch_link_2">
    <visual>
      <origin xyz="0 0 0" rpy="0 -0 0" />
      <geometry>
        <mesh filename="../assemblies/right_leg_XM430/meshes/right_ank_pitch_link_visual.stl" />
      </geometry>
      <material name="ank_pitch_link_material">
        <color rgba="0.63189161126160264814 0.7266866879354088038 0.78356373393969258601 1.0" />
      </material>
    </visual>
    <inertial>
      <origin xyz="0.00059528282565907803762 -4.0269682332179541599e-08 7.7616094724284792329e-08" rpy="0 0 0" />
      <mass value="0.0042238381753791614387" />
      <inertia ixx="3.9782741364674310846e-07" ixy="-1.6834347588868364615e-13" ixz="2.0919192129833751745e-14" iyy="4.3705254067416634901e-07" iyz="-1.6428822125575282589e-12" izz="8.8858574534590013309e-08" />
    </inertial>
  </link>

  <link name="ank_roll_link_2">
    <visual>
      <origin xyz="0 0 0" rpy="0 -0 0" />
      <geometry>
        <mesh filename="../assemblies/right_leg_XM430/meshes/right_ank_roll_link_visual.stl" />
      </geometry>
      <material name="ank_roll_link_material">
        <color rgba="0.61568627450980406568 0.81176470588235305481 0.9294117647058824927 1.0" />
      </material>
    </visual>
    <inertial>
      <origin xyz="-4.3076724073976496513e-08 0.026796342838297407957 -0.0010522562961590997428" rpy="0 0 0" />
      <mass value="0.024800000000000009537" />
      <inertia ixx="1.9846823873608352578e-05" ixy="8.455956721996400947e-12" ixz="1.0948936918465161116e-10" iyy="1.869509854898196972e-05" iyz="-1.6315562466569507807e-06" izz="5.1708532177991941474e-06" />
    </inertial>
  </link>

  <link name="ank_rr_link_3">
    <visual>
      <origin xyz="0 0 0" rpy="0 -0 0" />
      <geometry>
        <mesh filename="../assemblies/right_leg_XM430/meshes/right_ank_rr_link_visual.stl" />
      </geometry>
      <material name="ank_rr_link_material">
        <color rgba="0.61568627450980395466 0.81176470588235294379 0.92941176470588238168 1.0" />
      </material>
    </visual>
    <inertial>
      <origin xyz="-4.5249610960598959377e-05 -0.0063096429836314027462 2.0541493629099765385e-19" rpy="0 0 0" />
      <mass value="0.0014499999999999999001" />
      <inertia ixx="2.9739579267716150033e-08" ixy="-2.4213146797978030914e-10" ixz="-3.5523394884496757108e-14" iyy="2.7430027724071957055e-08" iyz="-3.8436473465939445106e-32" izz="4.2921949116163672436e-08" />
    </inertial>
  </link>

  <link name="ank_motor_rod_long_2">
    <visual>
      <origin xyz="0 0 0" rpy="0 -0 0" />
      <geometry>
        <mesh filename="../assemblies/right_leg_XM430/meshes/right_ank_motor_rod_long_visual.stl" />
      </geometry>
      <material name="ank_motor_rod_long_material">
        <color rgba="0.63549975559783222767 0.70774393017020453822 0.75109043491362792455 1.0" />
      </material>
    </visual>
    <inertial>
      <origin xyz="2.4855088453923733882e-10 0.034559019974062271663 0.00093851704878454621315" rpy="0 0 0" />
      <mass value="0.0021712857268636710437" />
      <inertia ixx="8.5350290058000326702e-07" ixy="1.4884244285071130669e-14" ixz="4.5749525025569116415e-11" iyy="1.3237321792739554213e-08" iyz="-4.3668910960860596274e-09" izz="8.5812217519451684046e-07" />
    </inertial>
  </link>

  <joint name="right_ank_L_rev_2" type="revolute">
    <origin xyz="-6.9388939039072283776e-18 -0.0099999999999996203037 3.1225022567582527699e-17" rpy="-1.5707963267948887864 -1.3320366994106427327 -1.5707963267948827912" />
    <parent link="ank_rr_link_3" />
    <child link="ank_motor_rod_long_2" />
    <axis xyz="0 0 1" />
    <limit effort="1" velocity="20" lower="-1.570796326794896558" upper="1.570796326794896558" />
    <joint_properties friction="0.0" />
  </joint>

  <joint name="right_ank_L_rev_1" type="revolute">
    <origin xyz="0.017999999999999981293 0.015999999999999847677 -0.020600000000000014133" rpy="6.2884229534673233247e-16 3.939086273962429945e-15 0.018223085042996144817" />
    <parent link="ank_roll_link_2" />
    <child link="ank_rr_link_3" />
    <axis xyz="0 0 1" />
    <limit effort="1" velocity="20" lower="-1.570796326794896558" upper="1.570796326794896558" />
    <joint_properties friction="0.0" />
  </joint>

  <link name="ank_rr_link_4">
    <visual>
      <origin xyz="0 0 0" rpy="0 -0 0" />
      <geometry>
        <mesh filename="../assemblies/right_leg_XM430/meshes/right_ank_rr_link_2_visual.stl" />
      </geometry>
      <material name="ank_rr_link_2_material">
        <color rgba="0.61568627450980395466 0.81176470588235294379 0.92941176470588238168 1.0" />
      </material>
    </visual>
    <inertial>
      <origin xyz="-4.5249610960602408495e-05 0.0063096429836315146358 3.2640320156625727923e-18" rpy="0 0 0" />
      <mass value="0.0014499999999999999001" />
      <inertia ixx="2.9739579267716150033e-08" ixy="2.4213146797978046423e-10" ixz="3.5523394884496757108e-14" iyy="2.7430027724071963673e-08" iyz="1.2033448591711135213e-32" izz="4.2921949116163672436e-08" />
    </inertial>
  </link>

  <link name="ank_motor_rod_short_2">
    <visual>
      <origin xyz="0 0 0" rpy="0 -0 0" />
      <geometry>
        <mesh filename="../assemblies/right_leg_XM430/meshes/right_ank_motor_rod_short_visual.stl" />
      </geometry>
      <material name="ank_motor_rod_short_material">
        <color rgba="0.41222606689734719865 0.58339100346020766885 0.8110726643598615837 1.0" />
      </material>
    </visual>
    <inertial>
      <origin xyz="2.6038940666329829529e-10 0.023830465465870916825 0.00090403506359621962647" rpy="0 0 0" />
      <mass value="0.0017000000000000001221" />
      <inertia ixx="3.315341625266997125e-07" ixy="8.7419770976385825866e-15" ixz="4.5749941567737612451e-11" iyy="1.0947363610305722935e-08" iyz="-3.5863098646405680146e-09" izz="3.3621340447865173163e-07" />
    </inertial>
  </link>

  <joint name="right_ank_S_rev_2" type="revolute">
    <origin xyz="-2.7755575615628913511e-16 0.010000000000000563993 -1.561251128379126385e-16" rpy="-1.5707963267949354158 1.2119133862908570975 -1.5707963267949336394" />
    <parent link="ank_rr_link_4" />
    <child link="ank_motor_rod_short_2" />
    <axis xyz="0 0 1" />
    <limit effort="1" velocity="20" lower="-1.570796326794896558" upper="1.570796326794896558" />
    <joint_properties friction="0.0" />
  </joint>

  <joint name="right_ank_S_rev_1" type="revolute">
    <origin xyz="-0.018000000000000026396 0.016000000000000735856 -0.02059999999999996903" rpy="-4.338977813478965687e-16 1.6392354569195739132e-16 3.1154741050825114357" />
    <parent link="ank_roll_link_2" />
    <child link="ank_rr_link_4" />
    <axis xyz="0 0 1" />
    <limit effort="1" velocity="20" lower="-1.570796326794896558" upper="1.570796326794896558" />
    <joint_properties friction="0.0" />
  </joint>

  <joint name="right_ank_roll" type="revolute">
    <origin xyz="0.0014999999999999924418 2.7755575615628913511e-17 -1.3877787807814456755e-17" rpy="3.141592653589793116 -1.570796326794896336 0" />
    <parent link="ank_pitch_link_2" />
    <child link="ank_roll_link_2" />
    <axis xyz="0 0 1" />
    <limit effort="1" velocity="20" lower="-0.785398163397448279" upper="0.785398163397448279" />
    <joint_properties friction="0.0" />
  </joint>

  <joint name="right_ank_pitch" type="revolute">
    <origin xyz="-4.0265291502142843319e-17 0.10000000000000000555 -0.010399999999999947481" rpy="-5.6239133145192868052e-16 -1.1344214119702528777e-16 3.141592653589793116" />
    <parent link="right_calf_link" />
    <child link="ank_pitch_link_2" />
    <axis xyz="0 0 1" />
    <limit effort="1" velocity="20" lower="-0.785398163397448279" upper="0.95993108859688125456" />
    <joint_properties friction="0.0" />
  </joint>

  <link name="ank_motor_arm_3">
    <visual>
      <origin xyz="0 0 0" rpy="0 -0 0" />
      <geometry>
        <mesh filename="../assemblies/right_leg_XM430/meshes/right_ank_motor_arm_visual.stl" />
      </geometry>
      <material name="ank_motor_arm_material">
        <color rgba="0.62517751827980905244 0.70593642422614044651 0.75978993426662777555 1.0" />
      </material>
    </visual>
    <inertial>
      <origin xyz="0.014511489101591681927 -1.1579941253344586694e-17 0.0040925443765950555303" rpy="0 0 0" />
      <mass value="0.0020595846677894939954" />
      <inertia ixx="2.7591836756521941853e-08" ixy="-2.02835504715638112e-22" ixz="-3.0270788206594762476e-08" iyy="1.6138599216238445878e-07" iyz="-1.011038189621288701e-22" izz="1.6437836765016292828e-07" />
    </inertial>
  </link>

  <joint name="right_ank_act_1" type="revolute">
    <origin xyz="0.013499999999995838246 0.044500000000006201262 0.0040000000000029352354" rpy="-2.9762431821176080221e-13 -7.5970722241046912715e-14 0.21173394130155420712" />
    <parent link="right_calf_link" />
    <child link="ank_motor_arm_3" />
    <axis xyz="0 0 1" />
    <limit effort="1" velocity="20" lower="-1.3089969389957472057" upper="1.3089969389957472057" />
    <joint_properties friction="0.0" />
  </joint>

  <link name="ank_motor_arm_4">
    <visual>
      <origin xyz="0 0 0" rpy="0 -0 0" />
      <geometry>
        <mesh filename="../assemblies/right_leg_XM430/meshes/right_ank_motor_arm_2_visual.stl" />
      </geometry>
      <material name="ank_motor_arm_2_material">
        <color rgba="0.62517751827980905244 0.70593642422614044651 0.75978993426662777555 1.0" />
      </material>
    </visual>
    <inertial>
      <origin xyz="0.014511489101591688866 -1.3683386509673053894e-19 0.004092544376595107572" rpy="0 0 0" />
      <mass value="0.0020595846677894939954" />
      <inertia ixx="2.7591836756522421617e-08" ixy="-1.3606445664121134143e-22" ixz="-3.0270788206595338193e-08" iyy="1.6138599216238422056e-07" iyz="-3.3298011122761505662e-22" izz="1.6437836765016327238e-07" />
    </inertial>
  </link>

  <joint name="right_ank_act_2" type="revolute">
    <origin xyz="0.013500000000004725234 0.064500000000008106404 -0.024800000000001404254" rpy="-3.1415926535894733718 -2.3305959971649736532e-13 0.22995607267265857909" />
    <parent link="right_calf_link" />
    <child link="ank_motor_arm_4" />
    <axis xyz="0 0 1" />
    <limit effort="1" velocity="20" lower="-1.3089969389957472057" upper="1.3089969389957472057" />
    <joint_properties friction="0.0" />
  </joint>

  <joint name="right_knee" type="revolute">
    <origin xyz="-2.9922268808255885729e-17 -0.096000000000000029754 -0.0091999999999999235167" rpy="1.2825226684517786044e-14 1.3611434254495038701e-14 -3.1415926535897926719" />
    <parent link="right_hip_pitch_link_xm430" />
    <child link="right_calf_link" />
    <axis xyz="0 0 1" />
    <limit effort="1" velocity="20" lower="-1.9198621771937625091" upper="0" />
    <joint_properties friction="0.0" />
  </joint>

  <joint name="right_hip_pitch" type="revolute">
    <origin xyz="-0.024000000716142638746 -0.019000000152444462831 -0.019000000152450562119" rpy="1.5707963267951012831 1.5707963267947298025 0" />
    <parent link="hip_roll_link_2" />
    <child link="right_hip_pitch_link_xm430" />
    <axis xyz="0 0 1" />
    <limit effort="1" velocity="20" lower="-1.570796326794896558" upper="1.570796326794896558" />
    <joint_properties friction="0.0" />
  </joint>

  <joint name="right_hip_roll" type="revolute">
    <origin xyz="-0.018999999999999999528 3.3500438890367473614e-18 -0.026000000000000002276" rpy="1.737531809691582777e-30 -1.570796326794896558 0" />
    <parent link="hip_yaw_link_2" />
    <child link="hip_roll_link_2" />
    <axis xyz="0 0 1" />
    <limit effort="1" velocity="20" lower="-0.785398163397448279" upper="1.570796326794896558" />
    <joint_properties friction="0.0" />
  </joint>


  <link name="xc430">
    <visual>
      <origin xyz="0 0 0" rpy="0 -0 0" />
      <geometry>
        <mesh filename="../assemblies/left_arm_hand/meshes/left_xc430_visual.stl" />
      </geometry>
      <material name="xc430_material">
        <color rgba="0.3960334863748344314 0.50878377002232877402 0.71126755432153676573 1.0" />
      </material>
    </visual>
    <inertial>
      <origin xyz="0.007649938948420367639 -0.0056800345415021161882 -0.014255781343936730146" rpy="0 0 0" />
      <mass value="0.065021926915724281848" />
      <inertia ixx="1.0685477757330408185e-05" ixy="2.4991048730003782262e-08" ixz="-4.3793050176056826951e-09" iyy="1.6030858372951694338e-05" iyz="-9.5846760480288827968e-09" izz="1.8186829094811185627e-05" />
    </inertial>
  </link>

  <link name="sho_pitch_link">
    <visual>
      <origin xyz="0 0 0" rpy="0 -0 0" />
      <geometry>
        <mesh filename="../assemblies/left_arm_hand/meshes/left_sho_pitch_link_visual.stl" />
      </geometry>
      <material name="sho_pitch_link_material">
        <color rgba="0.61568627450980395466 0.81176470588235294379 0.92941176470588238168 1.0" />
      </material>
    </visual>
    <inertial>
      <origin xyz="5.825424752983753426e-11 -5.1264642561121013175e-05 0.0082440788127094953575" rpy="0 0 0" />
      <mass value="0.008600000000000003475" />
      <inertia ixx="1.2272887040545802461e-06" ixy="-2.142994420191543053e-14" ixz="-8.5847198540427074509e-15" iyy="2.9107306060364645499e-06" iyz="7.4623841398183117097e-09" izz="3.0803135950773496163e-06" />
    </inertial>
  </link>

  <link name="2xl430_gears">
    <visual>
      <origin xyz="0 0 0" rpy="0 -0 0" />
      <geometry>
        <mesh filename="../assemblies/left_arm_hand/meshes/left_2xl430_gears_visual.stl" />
      </geometry>
      <material name="2xl430_gears_material">
        <color rgba="0.91900666046079226845 0.7025956886054134376 0.12479235365575504224 1.0" />
      </material>
    </visual>
    <inertial>
      <origin xyz="-0.011545549214475146413 -0.0025776045975616475661 -0.018554883443549097938" rpy="0 0 0" />
      <mass value="0.10921242823035924585" />
      <inertia ixx="2.5633987199176192553e-05" ixy="9.2332485824732311751e-07" ixz="-1.9126365492206487289e-08" iyy="3.0316164317563576338e-05" iyz="-6.1055425070402846345e-07" izz="3.3278157643470436923e-05" />
    </inertial>
  </link>

  <link name="spur_1m_24t_drive">
    <visual>
      <origin xyz="0 0 0" rpy="0 -0 0" />
      <geometry>
        <mesh filename="../assemblies/left_arm_hand/meshes/left_spur_1m_24t_drive_visual.stl" />
      </geometry>
      <material name="spur_1m_24t_drive_material">
        <color rgba="0.61568627450980406568 0.81176470588235294379 0.92941176470588238168 1.0" />
      </material>
    </visual>
    <inertial>
      <origin xyz="-7.7521101396039417664e-15 -1.2144011607250416242e-16 0.0047949116178401460231" rpy="0 0 0" />
      <mass value="0.0032000000000000001533" />
      <inertia ixx="1.4019331346159892996e-07" ixy="1.6002410053751656435e-15" ixz="-8.7717508276537448259e-37" iyy="1.4019331260388786185e-07" iyz="1.1548227992196316113e-37" izz="2.3838919844264060647e-07" />
    </inertial>
  </link>

  <joint name="left_sho_yaw_drive" type="revolute">
    <origin xyz="-0.024000000716149078039 -0.019000000152453292573 -0.019000000152451651525" rpy="1.5707963267948956698 -4.5091784937906777239e-14 2.4545027507744066908e-14" />
    <parent link="2xl430_gears" />
    <child link="spur_1m_24t_drive" />
    <axis xyz="0 0 1" />
    <limit effort="1" velocity="20" lower="-3.141592653589793116" upper="3.141592653589793116" />
    <joint_properties friction="0.0" />
  </joint>

  <link name="spur_1m_24t_driven">
    <visual>
      <origin xyz="0 0 0" rpy="0 -0 0" />
      <geometry>
        <mesh filename="../assemblies/left_arm_hand/meshes/left_spur_1m_24t_driven_visual.stl" />
      </geometry>
      <material name="spur_1m_24t_driven_material">
        <color rgba="0.23137254901960788156 0.38039215686274502337 0.7058823529411765163 1.0" />
      </material>
    </visual>
    <inertial>
      <origin xyz="2.5339767539064915348e-18 -5.7992099762712231414e-15 -0.00096866348640038332785" rpy="0 0 0" />
      <mass value="0.0026999999999999997093" />
      <inertia ixx="1.2026541119643502094e-07" ixy="-2.1120706372726556366e-36" ixz="0" iyy="1.2026541119643483565e-07" iyz="0" izz="2.2827257365099366486e-07" />
    </inertial>
  </link>

  <link name="sho_yaw_link">
    <visual>
      <origin xyz="0 0 0" rpy="0 -0 0" />
      <geometry>
        <mesh filename="../assemblies/left_arm_hand/meshes/left_sho_yaw_link_visual.stl" />
      </geometry>
      <material name="sho_yaw_link_material">
        <color rgba="0.61568627450980395466 0.81176470588235294379 0.92941176470588238168 1.0" />
      </material>
    </visual>
    <inertial>
      <origin xyz="5.7814996523352891568e-18 3.8649239170559342289e-18 -0.024214576156328389278" rpy="0 0 0" />
      <mass value="0.014499999999999986858" />
      <inertia ixx="9.0490855102914890835e-06" ixy="3.5997729401745807688e-13" ixz="0" iyy="5.6767199180624668202e-06" iyz="0" izz="4.4590603637468091569e-06" />
    </inertial>
  </link>

  <link name="2xl430_gears_2">
    <visual>
      <origin xyz="0 0 0" rpy="0 -0 0" />
      <geometry>
        <mesh filename="../assemblies/left_arm_hand/meshes/left_2xl430_gears_2_visual.stl" />
      </geometry>
      <material name="2xl430_gears_2_material">
        <color rgba="0.91900666046079226845 0.7025956886054134376 0.12479235365575504224 1.0" />
      </material>
    </visual>
    <inertial>
      <origin xyz="-0.01154554921447331281 -0.0025776045975613760819 -0.018554883443544802762" rpy="0 0 0" />
      <mass value="0.10921242823035924585" />
      <inertia ixx="2.5633987199174796643e-05" ixy="9.2332485824667196093e-07" ixz="-1.9126365492400034317e-08" iyy="3.0316164317562424373e-05" iyz="-6.1055425070424720971e-07" izz="3.327815764346942726e-05" />
    </inertial>
  </link>

  <link name="spur_1m_24t_drive_2">
    <visual>
      <origin xyz="0 0 0" rpy="0 -0 0" />
      <geometry>
        <mesh filename="../assemblies/left_arm_hand/meshes/left_spur_1m_24t_drive_2_visual.stl" />
      </geometry>
      <material name="spur_1m_24t_drive_2_material">
        <color rgba="0.61568627450980406568 0.81176470588235294379 0.92941176470588238168 1.0" />
      </material>
    </visual>
    <inertial>
      <origin xyz="-7.7521101396039417664e-15 -1.2144011607250455685e-16 0.0047949116178401512273" rpy="0 0 0" />
      <mass value="0.0032000000000000001533" />
      <inertia ixx="1.4019331346159892996e-07" ixy="1.6002410086838880937e-15" ixz="3.3868739208338279975e-37" iyy="1.4019331260388786185e-07" iyz="2.3470577016292310921e-36" izz="2.3838919844264071235e-07" />
    </inertial>
  </link>

  <joint name="left_elbow_yaw_drive" type="revolute">
    <origin xyz="-0.024000000716143922441 -0.019000000152449375568 -0.019000000152448702495" rpy="1.5707963267948812369 -8.0032142329674811068e-15 1.2365412156371141215e-13" />
    <parent link="2xl430_gears_2" />
    <child link="spur_1m_24t_drive_2" />
    <axis xyz="0 0 1" />
    <limit effort="1" velocity="20" lower="-3.141592653589793116" upper="3.141592653589793116" />
    <joint_properties friction="0.0" />
  </joint>

  <link name="spur_1m_24t_driven_2">
    <visual>
      <origin xyz="0 0 0" rpy="0 -0 0" />
      <geometry>
        <mesh filename="../assemblies/left_arm_hand/meshes/left_spur_1m_24t_driven_2_visual.stl" />
      </geometry>
      <material name="spur_1m_24t_driven_2_material">
        <color rgba="0.23137254901960788156 0.38039215686274502337 0.7058823529411765163 1.0" />
      </material>
    </visual>
    <inertial>
      <origin xyz="2.5339767539064915348e-18 -5.7992099762712231414e-15 -0.00096866348640037638895" rpy="0 0 0" />
      <mass value="0.0026999999999999997093" />
      <inertia ixx="1.2026541119643502094e-07" ixy="-6.5732337140722133283e-38" ixz="0" iyy="1.2026541119643483565e-07" iyz="0" izz="2.2827257365099366486e-07" />
    </inertial>
  </link>

  <link name="elb_yaw_link">
    <visual>
      <origin xyz="0 0 0" rpy="0 -0 0" />
      <geometry>
        <mesh filename="../assemblies/left_arm_hand/meshes/left_elb_yaw_link_visual.stl" />
      </geometry>
      <material name="elb_yaw_link_material">
        <color rgba="0.61568627450980395466 0.81176470588235294379 0.92941176470588227065 1.0" />
      </material>
    </visual>
    <inertial>
      <origin xyz="5.287088917269459775e-08 0.0019873558182742479504 -0.023365661199828729327" rpy="0 0 0" />
      <mass value="0.017500000000000001665" />
      <inertia ixx="1.4097804991252558057e-05" ixy="1.6900809684051191583e-12" ixz="-1.1184673662158690996e-11" iyy="6.6367696417680293553e-06" iyz="1.0579908722588339983e-06" izz="8.9601142768980697473e-06" />
    </inertial>
  </link>

  <link name="spur_1m_24t_driven_3">
    <visual>
      <origin xyz="0 0 0" rpy="0 -0 0" />
      <geometry>
        <mesh filename="../assemblies/left_arm_hand/meshes/left_spur_1m_24t_driven_3_visual.stl" />
      </geometry>
      <material name="spur_1m_24t_driven_3_material">
        <color rgba="0.23137254901960788156 0.38039215686274502337 0.7058823529411765163 1.0" />
      </material>
    </visual>
    <inertial>
      <origin xyz="-2.522159886172245202e-17 -5.7992099762712231414e-15 -0.0025686634864003805856" rpy="0 0 0" />
      <mass value="0.0026999999999999997093" />
      <inertia ixx="1.2026541119643502094e-07" ixy="-2.9625477072638547111e-36" ixz="-1.5730367353383820857e-37" iyy="1.2026541119643483565e-07" iyz="1.1070062413737891266e-37" izz="2.2827257365099366486e-07" />
    </inertial>
  </link>

  <link name="2xl430_gears_3">
    <visual>
      <origin xyz="0 0 0" rpy="0 -0 0" />
      <geometry>
        <mesh filename="../assemblies/left_arm_hand/meshes/left_2xl430_gears_3_visual.stl" />
      </geometry>
      <material name="2xl430_gears_3_material">
        <color rgba="0.91900666046079226845 0.7025956886054134376 0.12479235365575504224 1.0" />
      </material>
    </visual>
    <inertial>
      <origin xyz="0.00044511655645805596948 0.011545548856396192772 -0.024422395554887000452" rpy="0 0 0" />
      <mass value="0.10921242823035924585" />
      <inertia ixx="3.3278157643469847388e-05" ixy="1.9126365494095211942e-08" ixz="6.1055425070499323398e-07" iyy="2.5633987199175328579e-05" iyz="9.2332485824892242159e-07" izz="3.0316164317561428263e-05" />
    </inertial>
  </link>

  <link name="spur_1m_24t_drive_3">
    <visual>
      <origin xyz="0 0 0" rpy="0 -0 0" />
      <geometry>
        <mesh filename="../assemblies/left_arm_hand/meshes/left_spur_1m_24t_drive_3_visual.stl" />
      </geometry>
      <material name="spur_1m_24t_drive_3_material">
        <color rgba="0.61568627450980406568 0.81176470588235294379 0.92941176470588238168 1.0" />
      </material>
    </visual>
    <inertial>
      <origin xyz="-7.7243545639883128529e-15 -1.2837900997641198244e-16 0.0047949116178401399516" rpy="0 0 0" />
      <mass value="0.0032000000000000001533" />
      <inertia ixx="1.4019331346159892996e-07" ixy="1.6002410041546426147e-15" ixz="-6.4318290562543542602e-36" iyy="1.4019331260388791479e-07" iyz="-3.5497739011481716373e-36" izz="2.3838919844264060647e-07" />
    </inertial>
  </link>

  <joint name="left_wrist_pitch_drive" type="revolute">
    <origin xyz="-1.5244678436276970501e-10 0.024000000358067485884 -0.0080000000000028173575" rpy="-6.0688227754444846318e-17 9.0954925662261794972e-16 -1.5707963267950935116" />
    <parent link="2xl430_gears_3" />
    <child link="spur_1m_24t_drive_3" />
    <axis xyz="0 0 1" />
    <limit effort="1" velocity="20" lower="-1.570796326794896558" upper="1.570796326794896558" />
    <joint_properties friction="0.0" />
  </joint>

  <link name="wrist_bearing_plate">
    <visual>
      <origin xyz="0 0 0" rpy="0 -0 0" />
      <geometry>
        <mesh filename="../assemblies/left_arm_hand/meshes/left_wrist_bearing_plate_visual.stl" />
      </geometry>
      <material name="wrist_bearing_plate_material">
        <color rgba="0.64496316278892629192 0.69011804996940528945 0.71706771073555874985 1.0" />
      </material>
    </visual>
    <inertial>
      <origin xyz="-0.0075896393545961445687 -0.015499999999999991215 -0.0018386110045718407138" rpy="0 0 0" />
      <mass value="0.0049000367468305539714" />
      <inertia ixx="4.9747313520140109893e-07" ixy="1.9458462399620376262e-22" ixz="1.8097509420524938529e-08" iyy="7.1295025627582449075e-07" iyz="2.3459445642475020808e-23" izz="1.192629795229191449e-06" />
    </inertial>
  </link>

  <joint name="left_wrist_roll_fixed" type="fixed">
    <origin xyz="0.015500000000005648149 -4.3853809472693683347e-15 -0.044999999999999262812" rpy="-1.5598633495994326207e-14 -1.730560139634137368e-13 -1.5707963267946343233" />
    <parent link="2xl430_gears_3" />
    <child link="wrist_bearing_plate" />
    <axis xyz="0 0 1" />
    <limit effort="1" velocity="20" />
    <joint_properties friction="0.0" />
  </joint>

  <link name="hand">
    <visual>
      <origin xyz="0 0 0" rpy="0 -0 0" />
      <geometry>
        <mesh filename="../assemblies/left_arm_hand/meshes/left_hand_visual.stl" />
      </geometry>
      <material name="hand_material">
        <color rgba="0.61568627450980395466 0.81176470588235294379 0.92941176470588238168 1.0" />
      </material>
    </visual>
    <inertial>
      <origin xyz="-4.3038382213741598201e-08 -0.049723778585225204829 -0.017933572005385655518" rpy="0 0 0" />
      <mass value="0.017000000000000004691" />
      <inertia ixx="9.4921414617707115536e-06" ixy="-1.554921589734161308e-11" ixz="-1.0809694196434974908e-11" iyy="4.0745028295219354634e-06" iyz="2.4719408559887990214e-07" izz="6.6623859522963546108e-06" />
    </inertial>
  </link>

  <joint name="left_wrist_roll" type="revolute">
    <origin xyz="0.019000000000001057709 -3.5807262710463305666e-10 -0.027000000152450100849" rpy="1.2848055952475997313e-13 1.5707963267946998265 0" />
    <parent link="2xl430_gears_3" />
    <child link="hand" />
    <axis xyz="0 0 1" />
    <limit effort="1" velocity="20" lower="-1.570796326794896558" upper="1.570796326794896558" />
    <joint_properties friction="0.0" />
  </joint>

  <joint name="left_wrist_pitch_driven" type="revolute">
    <origin xyz="-8.3266726846886740532e-17 5.4817261840867104183e-16 -0.0016000000000001152189" rpy="-5.7142471032373773212e-16 5.5511151217739912712e-17 -1.570796326794896336" />
    <parent link="spur_1m_24t_driven_3" />
    <child link="2xl430_gears_3" />
    <axis xyz="0 0 1" />
    <limit effort="1" velocity="20" lower="-1.570796326794896558" upper="1.570796326794896558" />
    <joint_properties friction="0.0" />
  </joint>

  <joint name="left_wrist_pitch_fixed" type="fixed">
    <origin xyz="2.0816681711721685133e-17 -0.025299999999999989164 -0.051999999999999990674" rpy="1.5707963267948958919 -1.570796326794896336 0" />
    <parent link="elb_yaw_link" />
    <child link="spur_1m_24t_driven_3" />
    <axis xyz="0 0 1" />
    <limit effort="1" velocity="20" />
    <joint_properties friction="0.0" />
  </joint>

  <joint name="left_elbow_yaw_fixed" type="fixed">
    <origin xyz="1.3097162243624893563e-16 6.2450045135165055399e-17 0.0015999999999997960298" rpy="-3.141592653589793116 -5.5511151231207524813e-17 -1.570796326794896336" />
    <parent link="spur_1m_24t_driven_2" />
    <child link="elb_yaw_link" />
    <axis xyz="0 0 1" />
    <limit effort="1" velocity="20" />
    <joint_properties friction="0.0" />
  </joint>

  <joint name="left_elbow_yaw_driven" type="revolute">
    <origin xyz="-3.5807262710463305666e-10 -0.027000000152449854518 -0.01900000000000161629" rpy="1.570796326794891673 1.5707963267948441555 0" />
    <parent link="2xl430_gears_2" />
    <child link="spur_1m_24t_driven_2" />
    <axis xyz="0 0 1" />
    <limit effort="1" velocity="20" lower="-3.141592653589793116" upper="3.141592653589793116" />
    <joint_properties friction="0.0" />
  </joint>

  <joint name="left_elbow_roll" type="revolute">
    <origin xyz="7.6327832942979512154e-17 -0.018999999999999992589 -0.059000000000000031586" rpy="1.570796326794896558 -7.0029629609134176679e-16 7.044195017682708143e-15" />
    <parent link="sho_yaw_link" />
    <child link="2xl430_gears_2" />
    <axis xyz="0 0 1" />
    <limit effort="1" velocity="20" lower="-1.570796326794896558" upper="1.570796326794896558" />
    <joint_properties friction="0.0" />
  </joint>

  <joint name="left_sho_yaw_fixed" type="fixed">
    <origin xyz="0 1.561251128379126385e-17 0.0015999999999999903189" rpy="-3.1415926535897922278 1.4418079614154122748e-16 -6.106226635437282205e-16" />
    <parent link="spur_1m_24t_driven" />
    <child link="sho_yaw_link" />
    <axis xyz="0 0 1" />
    <limit effort="1" velocity="20" />
    <joint_properties friction="0.0" />
  </joint>

  <joint name="left_sho_yaw_driven" type="revolute">
    <origin xyz="-3.5807536102883119611e-10 -0.027000000152448761642 -0.019000000000006084938" rpy="1.5707963267949398567 1.8984813721086286179e-14 -7.1310113557521486963e-14" />
    <parent link="2xl430_gears" />
    <child link="spur_1m_24t_driven" />
    <axis xyz="0 0 1" />
    <limit effort="1" velocity="20" lower="-3.141592653589793116" upper="3.141592653589793116" />
    <joint_properties friction="0.0" />
  </joint>

  <joint name="left_sho_roll" type="revolute">
    <origin xyz="-0.018999999999999992589 0.00099999999999997833677 0.026999999999999996225" rpy="-3.141592653589793116 1.5707963267948954478 0" />
    <parent link="sho_pitch_link" />
    <child link="2xl430_gears" />
    <axis xyz="0 0 1" />
    <limit effort="1" velocity="20" lower="-1.570796326794896558" upper="1.570796326794896558" />
    <joint_properties friction="0.0" />
  </joint>

  <joint name="left_sho_pitch" type="revolute">
    <origin xyz="-0.0039999999999985160273 0.012999999999999725317 -0.01424999999999848263" rpy="-1.5707963267948332753 -5.5178084323870191707e-14 -1.1649761152065636686e-13" />
    <parent link="xc430" />
    <child link="sho_pitch_link" />
    <axis xyz="0 0 1" />
    <limit effort="1" velocity="20" lower="-1.570796326794896558" upper="1.570796326794896558" />
    <joint_properties friction="0.0" />
  </joint>


  <link name="xc430_2">
    <visual>
      <origin xyz="0 0 0" rpy="0 -0 0" />
      <geometry>
        <mesh filename="../assemblies/right_arm_hand/meshes/right_xc430_visual.stl" />
      </geometry>
      <material name="xc430_material">
        <color rgba="0.3960334863748344314 0.50878377002232877402 0.71126755432153676573 1.0" />
      </material>
    </visual>
    <inertial>
      <origin xyz="0.0076499389484204942738 0.0056800345415021630258 -0.01424421865606324486" rpy="0 0 0" />
      <mass value="0.065021926915724281848" />
      <inertia ixx="1.0685477757330491194e-05" ixy="-2.499104872988050919e-08" ixz="4.3793050176100287021e-09" iyy="1.6030858372951945059e-05" iyz="-9.5846760479532371298e-09" izz="1.8186829094811067043e-05" />
    </inertial>
  </link>

  <link name="sho_pitch_link_2">
    <visual>
      <origin xyz="0 0 0" rpy="0 -0 0" />
      <geometry>
        <mesh filename="../assemblies/right_arm_hand/meshes/right_sho_pitch_link_visual.stl" />
      </geometry>
      <material name="sho_pitch_link_material">
        <color rgba="0.61568627450980395466 0.81176470588235294379 0.92941176470588238168 1.0" />
      </material>
    </visual>
    <inertial>
      <origin xyz="5.825424752983753426e-11 -5.1264642561120999623e-05 0.0082440788127094953575" rpy="0 0 0" />
      <mass value="0.008600000000000003475" />
      <inertia ixx="1.2272887040545802461e-06" ixy="-2.1429944201915424219e-14" ixz="-8.5847198540427074509e-15" iyy="2.9107306060364628558e-06" iyz="7.4623841398183100553e-09" izz="3.0803135950773496163e-06" />
    </inertial>
  </link>

  <link name="2xl430_gears_4">
    <visual>
      <origin xyz="0 0 0" rpy="0 -0 0" />
      <geometry>
        <mesh filename="../assemblies/right_arm_hand/meshes/right_2xl430_gears_visual.stl" />
      </geometry>
      <material name="2xl430_gears_material">
        <color rgba="0.91900666046079226845 0.7025956886054134376 0.12479235365575504224 1.0" />
      </material>
    </visual>
    <inertial>
      <origin xyz="-0.011545549214474582628 -0.0025776045975625170963 -0.01855488344354406377" rpy="0 0 0" />
      <mass value="0.10921242823035924585" />
      <inertia ixx="2.5633987199174718716e-05" ixy="9.2332485824708510125e-07" ixz="-1.9126365491687785487e-08" iyy="3.0316164317562065231e-05" iyz="-6.1055425070399691147e-07" izz="3.327815764346926463e-05" />
    </inertial>
  </link>

  <link name="spur_1m_24t_drive_4">
    <visual>
      <origin xyz="0 0 0" rpy="0 -0 0" />
      <geometry>
        <mesh filename="../assemblies/right_arm_hand/meshes/right_spur_1m_24t_drive_visual.stl" />
      </geometry>
      <material name="spur_1m_24t_drive_material">
        <color rgba="0.61568627450980406568 0.81176470588235294379 0.92941176470588238168 1.0" />
      </material>
    </visual>
    <inertial>
      <origin xyz="-7.7521101396039417664e-15 -1.2057275433451556166e-16 0.0047949116178401512273" rpy="0 0 0" />
      <mass value="0.0032000000000000001533" />
      <inertia ixx="1.4019331346159887702e-07" ixy="1.6002410000914703581e-15" ixz="-5.4090992845575242873e-36" iyy="1.4019331260388783538e-07" iyz="-6.8087356421599067805e-36" izz="2.3838919844264071235e-07" />
    </inertial>
  </link>

  <joint name="right_sho_yaw_drive" type="revolute">
    <origin xyz="-0.024000000716145303281 -0.01900000015244998619 -0.01900000015244465365" rpy="1.5707963267947440134 8.8389520895546782802e-14 1.3333206406916649652e-13" />
    <parent link="2xl430_gears_4" />
    <child link="spur_1m_24t_drive_4" />
    <axis xyz="0 0 1" />
    <limit effort="1" velocity="20" lower="-3.141592653589793116" upper="3.141592653589793116" />
    <joint_properties friction="0.0" />
  </joint>

  <link name="spur_1m_24t_driven_4">
    <visual>
      <origin xyz="0 0 0" rpy="0 -0 0" />
      <geometry>
        <mesh filename="../assemblies/right_arm_hand/meshes/right_spur_1m_24t_driven_visual.stl" />
      </geometry>
      <material name="spur_1m_24t_driven_material">
        <color rgba="0.23137254901960788156 0.38039215686274502337 0.7058823529411765163 1.0" />
      </material>
    </visual>
    <inertial>
      <origin xyz="2.5339767539064826755e-18 -5.7992099762712231414e-15 -0.00096866348640038332785" rpy="0 0 0" />
      <mass value="0.0026999999999999997093" />
      <inertia ixx="1.2026541119643502094e-07" ixy="3.0132909596002639219e-36" ixz="-9.0037654543726475118e-38" iyy="1.2026541119643483565e-07" iyz="0" izz="2.2827257365099366486e-07" />
    </inertial>
  </link>

  <link name="sho_yaw_link_2">
    <visual>
      <origin xyz="0 0 0" rpy="0 -0 0" />
      <geometry>
        <mesh filename="../assemblies/right_arm_hand/meshes/right_sho_yaw_link_visual.stl" />
      </geometry>
      <material name="sho_yaw_link_material">
        <color rgba="0.61568627450980395466 0.81176470588235294379 0.92941176470588238168 1.0" />
      </material>
    </visual>
    <inertial>
      <origin xyz="-1.1573942515719257393e-18 3.8649239170559342289e-18 -0.024214576156328385809" rpy="0 0 0" />
      <mass value="0.014499999999999986858" />
      <inertia ixx="9.0490855102914890835e-06" ixy="3.5997729401745807688e-13" ixz="1.7587891974902210219e-36" iyy="5.6767199180624668202e-06" iyz="0" izz="4.4590603637468091569e-06" />
    </inertial>
  </link>

  <link name="2xl430_gears_5">
    <visual>
      <origin xyz="0 0 0" rpy="0 -0 0" />
      <geometry>
        <mesh filename="../assemblies/right_arm_hand/meshes/right_2xl430_gears_2_visual.stl" />
      </geometry>
      <material name="2xl430_gears_2_material">
        <color rgba="0.91900666046079226845 0.7025956886054134376 0.12479235365575504224 1.0" />
      </material>
    </visual>
    <inertial>
      <origin xyz="-0.011545549214473463731 -0.0025776045975580215604 -0.018554883443548501193" rpy="0 0 0" />
      <mass value="0.10921242823035924585" />
      <inertia ixx="2.5633987199173058531e-05" ixy="9.2332485824729887119e-07" ixz="-1.9126365492406122366e-08" iyy="3.0316164317562349835e-05" iyz="-6.1055425070545116116e-07" izz="3.3278157643466920043e-05" />
    </inertial>
  </link>

  <link name="spur_1m_24t_drive_5">
    <visual>
      <origin xyz="0 0 0" rpy="0 -0 0" />
      <geometry>
        <mesh filename="../assemblies/right_arm_hand/meshes/right_spur_1m_24t_drive_2_visual.stl" />
      </geometry>
      <material name="spur_1m_24t_drive_2_material">
        <color rgba="0.61568627450980406568 0.81176470588235294379 0.92941176470588238168 1.0" />
      </material>
    </visual>
    <inertial>
      <origin xyz="-7.7659879274117562231e-15 -1.2057275433451595609e-16 0.0047949116178401382168" rpy="0 0 0" />
      <mass value="0.0032000000000000001533" />
      <inertia ixx="1.4019331346159887702e-07" ixy="1.6002410041546426147e-15" ixz="-3.624182631715073592e-36" iyy="1.4019331260388791479e-07" iyz="-4.1524596034726495678e-37" izz="2.3838919844264060647e-07" />
    </inertial>
  </link>

  <joint name="right_elbow_yaw_drive" type="revolute">
    <origin xyz="-0.024000000716140640344 -0.019000000152444435075 -0.019000000152454357694" rpy="1.5707963267949622832 8.194034361146178641e-14 -1.7317067989020890092e-13" />
    <parent link="2xl430_gears_5" />
    <child link="spur_1m_24t_drive_5" />
    <axis xyz="0 0 1" />
    <limit effort="1" velocity="20" lower="-3.141592653589793116" upper="3.141592653589793116" />
    <joint_properties friction="0.0" />
  </joint>

  <link name="spur_1m_24t_driven_5">
    <visual>
      <origin xyz="0 0 0" rpy="0 -0 0" />
      <geometry>
        <mesh filename="../assemblies/right_arm_hand/meshes/right_spur_1m_24t_driven_2_visual.stl" />
      </geometry>
      <material name="spur_1m_24t_driven_2_material">
        <color rgba="0.23137254901960788156 0.38039215686274502337 0.7058823529411765163 1.0" />
      </material>
    </visual>
    <inertial>
      <origin xyz="2.5339767539064915348e-18 -5.7992099762712231414e-15 -0.00096866348640037638895" rpy="0 0 0" />
      <mass value="0.0026999999999999997093" />
      <inertia ixx="1.2026541119643502094e-07" ixy="-2.2321759283396738301e-36" ixz="0" iyy="1.2026541119643483565e-07" iyz="0" izz="2.2827257365099366486e-07" />
    </inertial>
  </link>

  <link name="elb_yaw_link_2">
    <visual>
      <origin xyz="0 0 0" rpy="0 -0 0" />
      <geometry>
        <mesh filename="../assemblies/right_arm_hand/meshes/right_elb_yaw_link_visual.stl" />
      </geometry>
      <material name="elb_yaw_link_material">
        <color rgba="0.61568627450980395466 0.81176470588235294379 0.92941176470588227065 1.0" />
      </material>
    </visual>
    <inertial>
      <origin xyz="5.287088917269459775e-08 0.0019873558182742479504 -0.023365661199828736266" rpy="0 0 0" />
      <mass value="0.017500000000000001665" />
      <inertia ixx="1.4097804991252558057e-05" ixy="1.6900809684051191583e-12" ixz="-1.1184673662158687765e-11" iyy="6.6367696417680293553e-06" iyz="1.0579908722588337865e-06" izz="8.9601142768980663591e-06" />
    </inertial>
  </link>

  <link name="spur_1m_24t_driven_6">
    <visual>
      <origin xyz="0 0 0" rpy="0 -0 0" />
      <geometry>
        <mesh filename="../assemblies/right_arm_hand/meshes/right_spur_1m_24t_driven_3_visual.stl" />
      </geometry>
      <material name="spur_1m_24t_driven_3_material">
        <color rgba="0.23137254901960788156 0.38039215686274502337 0.7058823529411765163 1.0" />
      </material>
    </visual>
    <inertial>
      <origin xyz="2.5339767539064672681e-18 -5.8061488701751303698e-15 -0.0025686634864003771161" rpy="0 0 0" />
      <mass value="0.0026999999999999997093" />
      <inertia ixx="1.2026541119643502094e-07" ixy="-8.8943138390222300706e-38" ixz="-3.4871107238620772993e-37" iyy="1.2026541119643483565e-07" iyz="3.5770621358774076477e-36" izz="2.2827257365099366486e-07" />
    </inertial>
  </link>

  <link name="2xl430_gears_6">
    <visual>
      <origin xyz="0 0 0" rpy="0 -0 0" />
      <geometry>
        <mesh filename="../assemblies/right_arm_hand/meshes/right_2xl430_gears_3_visual.stl" />
      </geometry>
      <material name="2xl430_gears_3_material">
        <color rgba="0.91900666046079226845 0.7025956886054134376 0.12479235365575504224 1.0" />
      </material>
    </visual>
    <inertial>
      <origin xyz="0.00044511655645500768086 0.011545548856405010371 -0.024422395554887468827" rpy="0 0 0" />
      <mass value="0.10921242823035924585" />
      <inertia ixx="3.3278157643468370163e-05" ixy="1.9126365492366470636e-08" ixz="6.1055425070389431461e-07" iyy="2.5633987199173590468e-05" iyz="9.2332485824554837172e-07" izz="3.0316164317561851779e-05" />
    </inertial>
  </link>

  <link name="spur_1m_24t_drive_6">
    <visual>
      <origin xyz="0 0 0" rpy="0 -0 0" />
      <geometry>
        <mesh filename="../assemblies/right_arm_hand/meshes/right_spur_1m_24t_drive_3_visual.stl" />
      </geometry>
      <material name="spur_1m_24t_drive_3_material">
        <color rgba="0.61568627450980406568 0.81176470588235294379 0.92941176470588238168 1.0" />
      </material>
    </visual>
    <inertial>
      <origin xyz="-7.7798657152195722576e-15 -1.2837900997641119358e-16 0.0047949116178401416863" rpy="0 0 0" />
      <mass value="0.0032000000000000001533" />
      <inertia ixx="1.4019331346159892996e-07" ixy="1.6002410033435796138e-15" ixz="1.8689311580061739594e-36" iyy="1.4019331260388783538e-07" iyz="1.2273789032714357933e-37" izz="2.3838919844264060647e-07" />
    </inertial>
  </link>

  <joint name="right_wrist_pitch_drive" type="revolute">
    <origin xyz="-1.5244812356929315911e-10 0.024000000358072565154 -0.0079999999999997069983" rpy="3.0683701463333139415e-15 3.000158893453974941e-16 -1.5707963267949427433" />
    <parent link="2xl430_gears_6" />
    <child link="spur_1m_24t_drive_6" />
    <axis xyz="0 0 1" />
    <limit effort="1" velocity="20" lower="-1.570796326794896558" upper="1.570796326794896558" />
    <joint_properties friction="0.0" />
  </joint>

  <link name="wrist_bearing_plate_2">
    <visual>
      <origin xyz="0 0 0" rpy="0 -0 0" />
      <geometry>
        <mesh filename="../assemblies/right_arm_hand/meshes/right_wrist_bearing_plate_visual.stl" />
      </geometry>
      <material name="wrist_bearing_plate_material">
        <color rgba="0.64496316278892629192 0.69011804996940528945 0.71706771073555874985 1.0" />
      </material>
    </visual>
    <inertial>
      <origin xyz="-0.0075896393545961402319 -0.015499999999999991215 -0.0018386110045718361602" rpy="0 0 0" />
      <mass value="0.0049000367468305539714" />
      <inertia ixx="4.9747313520140120481e-07" ixy="1.4311016266183815911e-23" ixz="1.8097509420524783019e-08" iyy="7.129502562758232202e-07" iyz="1.3422300279367577938e-23" izz="1.192629795229189755e-06" />
    </inertial>
  </link>

  <joint name="right_wrist_roll_fixed" type="fixed">
    <origin xyz="0.015499999999999309469 5.6343818499726694426e-15 -0.045000000000002496336" rpy="-3.8857806018810176234e-16 1.2034817586933650002e-13 -1.5707963267948996666" />
    <parent link="2xl430_gears_6" />
    <child link="wrist_bearing_plate_2" />
    <axis xyz="0 0 1" />
    <limit effort="1" velocity="20" />
    <joint_properties friction="0.0" />
  </joint>

  <link name="hand_2">
    <visual>
      <origin xyz="0 0 0" rpy="0 -0 0" />
      <geometry>
        <mesh filename="../assemblies/right_arm_hand/meshes/right_hand_visual.stl" />
      </geometry>
      <material name="hand_material">
        <color rgba="0.61568627450980395466 0.81176470588235294379 0.92941176470588238168 1.0" />
      </material>
    </visual>
    <inertial>
      <origin xyz="-4.3038382212874236463e-08 0.049723778585225232585 -0.020066427994614347008" rpy="0 0 0" />
      <mass value="0.017000000000000004691" />
      <inertia ixx="9.4921414617707115536e-06" ixy="1.554921589734161308e-11" ixz="1.0809694196434976524e-11" iyy="4.0745028295219354634e-06" iyz="2.4719408559887995508e-07" izz="6.6623859522963579989e-06" />
    </inertial>
  </link>

  <joint name="right_wrist_roll" type="revolute">
    <origin xyz="0.018999999999997782552 -3.5806707598950993088e-10 -0.027000000152450402691" rpy="-3.1415926535897886751 -1.5707963267947642194 0" />
    <parent link="2xl430_gears_6" />
    <child link="hand_2" />
    <axis xyz="0 0 1" />
    <limit effort="1" velocity="20" lower="-1.570796326794896558" upper="1.570796326794896558" />
    <joint_properties friction="0.0" />
  </joint>

  <joint name="right_wrist_pitch_driven" type="revolute">
    <origin xyz="-2.7755575615628913511e-17 6.9388939039072283776e-18 -0.0016000000000002227718" rpy="-4.5800957231150559108e-15 -6.2172489379009776006e-15 1.570796326794896558" />
    <parent link="spur_1m_24t_driven_6" />
    <child link="2xl430_gears_6" />
    <axis xyz="0 0 1" />
    <limit effort="1" velocity="20" lower="-1.570796326794896558" upper="1.570796326794896558" />
    <joint_properties friction="0.0" />
  </joint>

  <joint name="right_wrist_pitch_fixed" type="fixed">
    <origin xyz="0 -0.025299999999999996103 -0.052000000000000046185" rpy="1.5707963267948905628 1.5707963267948905628 0" />
    <parent link="elb_yaw_link_2" />
    <child link="spur_1m_24t_driven_6" />
    <axis xyz="0 0 1" />
    <limit effort="1" velocity="20" />
    <joint_properties friction="0.0" />
  </joint>

  <joint name="right_elbow_yaw_fixed" type="fixed">
    <origin xyz="-6.9388939039072283776e-18 0 0.0015999999999999903189" rpy="-3.141592653589793116 -2.2204460328203446248e-16 -3.141592653589793116" />
    <parent link="spur_1m_24t_driven_5" />
    <child link="elb_yaw_link_2" />
    <axis xyz="0 0 1" />
    <limit effort="1" velocity="20" />
    <joint_properties friction="0.0" />
  </joint>

  <joint name="right_elbow_yaw_driven" type="revolute">
    <origin xyz="-3.5806981685260197423e-10 -0.027000000152445247092 -0.019000000000004103884" rpy="-1.5707963267950058039 5.9602610059045593461e-15 3.1415926535897913396" />
    <parent link="2xl430_gears_5" />
    <child link="spur_1m_24t_driven_5" />
    <axis xyz="0 0 1" />
    <limit effort="1" velocity="20" lower="-3.141592653589793116" upper="3.141592653589793116" />
    <joint_properties friction="0.0" />
  </joint>

  <joint name="right_elbow_roll" type="revolute">
    <origin xyz="1.3183898417423733918e-16 -0.018999999999999933609 -0.059000000000000038525" rpy="1.570796326794896558 -2.6733818545004476465e-15 -6.1232339957031568635e-17" />
    <parent link="sho_yaw_link_2" />
    <child link="2xl430_gears_5" />
    <axis xyz="0 0 1" />
    <limit effort="1" velocity="20" lower="-1.570796326794896558" upper="1.570796326794896558" />
    <joint_properties friction="0.0" />
  </joint>

  <joint name="right_sho_yaw_fixed" type="fixed">
    <origin xyz="-6.9388939039072283776e-18 -8.6736173798840354721e-19 0.0016000000000000041966" rpy="-3.141592653589793116 -3.0292258760486853328e-28 -8.5559900487112566884e-29" />
    <parent link="spur_1m_24t_driven_4" />
    <child link="sho_yaw_link_2" />
    <axis xyz="0 0 1" />
    <limit effort="1" velocity="20" />
    <joint_properties friction="0.0" />
  </joint>

  <joint name="right_sho_yaw_driven" type="revolute">
    <origin xyz="-3.5807402876120164592e-10 -0.027000000152449625535 -0.019000000000000287492" rpy="1.5707963267948759079 -1.13931263975872123e-27 -4.4614134174147354846e-14" />
    <parent link="2xl430_gears_4" />
    <child link="spur_1m_24t_driven_4" />
    <axis xyz="0 0 1" />
    <limit effort="1" velocity="20" lower="-3.141592653589793116" upper="3.141592653589793116" />
    <joint_properties friction="0.0" />
  </joint>

  <joint name="right_sho_roll" type="revolute">
    <origin xyz="-0.018999999999999999528 0.0010000000000000251743 0.026999999999999996225" rpy="3.141592653589793116 1.570796326794896558 0" />
    <parent link="sho_pitch_link_2" />
    <child link="2xl430_gears_4" />
    <axis xyz="0 0 1" />
    <limit effort="1" velocity="20" lower="-1.570796326794896558" upper="1.570796326794896558" />
    <joint_properties friction="0.0" />
  </joint>

  <joint name="right_sho_pitch" type="revolute">
    <origin xyz="-0.0039999999999983789842 -0.012999999999999045305 -0.014250000000000390826" rpy="-1.5707963267949442976 1.6903145549952781317e-14 -3.1415926535895994931" />
    <parent link="xc430_2" />
    <child link="sho_pitch_link_2" />
    <axis xyz="0 0 1" />
    <limit effort="1" velocity="20" lower="-1.570796326794896558" upper="1.570796326794896558" />
    <joint_properties friction="0.0" />
  </joint>


</robot>