<robot name="toddlerbot">  
  <mujoco><compiler strippath="false" balanceinertia="true" discardvisual="false" /></mujoco><link name="torso">    
    <visual>      
      <origin xyz="0 0 0" rpy="0 -0 0" />      
      <geometry>        
        <mesh filename="../assemblies/toddlerbot/meshes/torso_visual.stl" />        
      </geometry>      
      <material name="torso_material">        
        <color rgba="0.58602628355191022091 0.73205173766587616768 0.84624015779321404285 1.0" />        
      </material>      
    </visual>    
    <collision>      
      <origin xyz="0 0 0" rpy="0 -0 0" />      
      <geometry>        
        <mesh filename="collisions/torso_collision.stl" />        
      </geometry>      
    </collision>    
    <inertial>      
      <origin xyz="-0.0074328354797873856519 0.0025059801105640597436 0.073401015491149065872" rpy="0 0 0" />      
      <mass value="0.58490521749923585215" />      
      <inertia ixx="0.0016168191047346508818" ixy="-1.4736281865313545779e-05" ixz="3.2221053182213641741e-07" iyy="0.0013101565794344577007" iyz="2.4169833425786332702e-05" izz="0.0011896913602930953707" />      
    </inertial>    
  </link>  

  <link name="spur_1m_20t">    
    <visual>      
      <origin xyz="0 0 0" rpy="0 -0 0" />      
      <geometry>        
        <mesh filename="../assemblies/toddlerbot/meshes/spur_1m_20t_visual.stl" />        
      </geometry>      
      <material name="spur_1m_20t_material">        
        <color rgba="0.64705882352941179736 0.64705882352941179736 0.64705882352941179736 1.0" />        
      </material>      
    </visual>    
    <inertial>      
      <origin xyz="-5.3115843702594968093e-18 6.267656612818368267e-18 -0.0033745971730663147647" rpy="0 0 0" />      
      <mass value="0.0015534950290892286448" />      
      <inertia ixx="4.4726508287871799621e-08" ixy="5.2024693257554525847e-24" ixz="2.7597381312606821682e-39" iyy="4.4726508287871786386e-08" iyz="-4.880475641083095171e-38" izz="7.9558906764902006609e-08" />      
    </inertial>    
  </link>  

  <joint name="neck_yaw_drive" type="revolute">    
    <origin xyz="-0.004999999999999059884 -1.8020791195763170554e-16 0.12248651076281816263" rpy="-3.1415926535897913396 1.7995135580561967136e-15 9.6455933634066887197e-16" />    
    <parent link="torso" />    
    <child link="spur_1m_20t" />    
    <axis xyz="0 0 1" />    
    <limit effort="1" velocity="20" lower="-3.141592653589793116" upper="3.141592653589793116" />    
    <joint_properties friction="0.0" />    
  </joint>  

  <link name="neck_yaw_link">    
    <visual>      
      <origin xyz="0 0 0" rpy="0 -0 0" />      
      <geometry>        
        <mesh filename="../assemblies/toddlerbot/meshes/neck_yaw_link_visual.stl" />        
      </geometry>      
      <material name="neck_yaw_link_material">        
        <color rgba="0.33636252417476653065 0.48680769190259864931 0.74976123534949778993 1.0" />        
      </material>      
    </visual>    
    <inertial>      
      <origin xyz="2.729128646113388693e-05 0.00019798992283532641659 -0.011527412037194836522" rpy="0 0 0" />      
      <mass value="0.0085168305947458285143" />      
      <inertia ixx="1.0407116999274144965e-06" ixy="-2.4210150466633400977e-11" ixz="4.724680321864392974e-10" iyy="1.1240009954110278886e-06" iyz="3.0834841754638120323e-08" izz="3.158756516729191776e-07" />      
    </inertial>    
  </link>  

  <link name="neck_pitch_link">    
    <visual>      
      <origin xyz="0 0 0" rpy="0 -0 0" />      
      <geometry>        
        <mesh filename="../assemblies/toddlerbot/meshes/neck_pitch_link_visual.stl" />        
      </geometry>      
      <material name="neck_pitch_link_material">        
        <color rgba="0.74911126277760053949 0.80002799398726853752 0.87441258869524285391 1.0" />        
      </material>      
    </visual>    
    <collision>      
      <origin xyz="0 0 0" rpy="0 -0 0" />      
      <geometry>        
        <mesh filename="collisions/neck_pitch_link_collision.stl" />        
      </geometry>      
    </collision>    
    <inertial>      
      <origin xyz="-0.0034370497615718049317 -0.032876793988991424855 0.00036476492134716474638" rpy="0 0 0" />      
      <mass value="0.11211553874797880459" />      
      <inertia ixx="7.7015755459849957677e-05" ixy="2.1757968319820864549e-06" ixz="2.8732209413521026174e-06" iyy="6.3502636688155217164e-05" iyz="-1.2492352737635673663e-05" izz="2.8610002383974706596e-05" />      
    </inertial>    
  </link>  

  <link name="spur_gear_(13_teeth)">    
    <visual>      
      <origin xyz="0 0 0" rpy="0 -0 0" />      
      <geometry>        
        <mesh filename="../assemblies/toddlerbot/meshes/spur_gear_(13_teeth)_visual.stl" />        
      </geometry>      
      <material name="spur_gear_(13_teeth)_material">        
        <color rgba="0.64705882352941179736 0.64705882352941179736 0.64705882352941179736 1.0" />        
      </material>      
    </visual>    
    <inertial>      
      <origin xyz="1.0399873341738908573e-09 2.3905206819408639796e-10 -0.0092751511485596373902" rpy="0 0 0" />      
      <mass value="0.00081469437497230865874" />      
      <inertia ixx="2.0244839552178295378e-08" ixy="-2.9046301764120405049e-15" ixz="8.2976066066373874712e-15" iyy="2.0244841689973771385e-08" iyz="-1.3142117784254373661e-15" izz="1.8905472907863310999e-08" />      
    </inertial>    
  </link>  

  <joint name="neck_pitch_drive" type="revolute">    
    <origin xyz="-1.4571677198205179593e-16 -0.015650000000000330314 0.0087999999999993777644" rpy="-2.1434555572207676319e-16 -1.5880065549567459396e-15 1.570796326794896558" />    
    <parent link="neck_pitch_link" />    
    <child link="spur_gear_(13_teeth)" />    
    <axis xyz="0 0 1" />    
    <limit effort="1" velocity="20" lower="-1.570796326794896558" upper="1.570796326794896558" />    
    <joint_properties friction="0.0" />    
  </joint>  

  <joint name="neck_pitch_driven" type="revolute">    
    <origin xyz="3.7500073185592341929e-10 0.0051500000614755261225 -0.027499999999999941158" rpy="1.57079632679489678 -1.7934420258902467287e-15 -3.1415926535897922278" />    
    <parent link="neck_yaw_link" />    
    <child link="neck_pitch_link" />    
    <axis xyz="0 0 1" />    
    <limit effort="1" velocity="20" lower="-1.570796326794896558" upper="1.570796326794896558" />    
    <joint_properties friction="0.0" />    
  </joint>  

  <joint name="neck_yaw_driven" type="revolute">    
    <origin xyz="0.016000000000001915468 1.4752314067929367773e-17 0.12348651076281796923" rpy="-3.141592653589793116 -0 -3.1415926535897922278" />    
    <parent link="torso" />    
    <child link="neck_yaw_link" />    
    <axis xyz="0 0 1" />    
    <limit effort="1" velocity="20" lower="-3.141592653589793116" upper="3.141592653589793116" />    
    <joint_properties friction="0.0" />    
  </joint>  

  <link name="waist_gears">    
    <visual>      
      <origin xyz="0 0 0" rpy="0 -0 0" />      
      <geometry>        
        <mesh filename="../assemblies/toddlerbot/meshes/waist_gears_visual.stl" />        
      </geometry>      
      <material name="waist_gears_material">        
        <color rgba="0.27057516381830515328 0.53648836590125015267 0.70305495274644802528 1.0" />        
      </material>      
    </visual>    
    <inertial>      
      <origin xyz="6.5469454462562728371e-08 -5.6785897865462200837e-10 -0.012726165583898677025" rpy="0 0 0" />      
      <mass value="0.02331580566917982808" />      
      <inertia ixx="6.9043104388291945091e-06" ixy="-1.8428638769651587303e-11" ixz="9.9668712610592374092e-13" iyy="1.1624091971676370215e-06" iyz="-3.3260430300241911844e-10" izz="6.8701920560919859505e-06" />      
    </inertial>    
  </link>  

  <link name="waist_link">    
    <visual>      
      <origin xyz="0 0 0" rpy="0 -0 0" />      
      <geometry>        
        <mesh filename="../assemblies/toddlerbot/meshes/waist_link_visual.stl" />        
      </geometry>      
      <material name="waist_link_material">        
        <color rgba="0.63401200025306059249 0.68204699127249923674 0.66910193985036237052 1.0" />        
      </material>      
    </visual>    
    <collision>      
      <origin xyz="0 0 0" rpy="0 -0 0" />      
      <geometry>        
        <mesh filename="collisions/waist_link_collision.stl" />        
      </geometry>      
    </collision>    
    <inertial>      
      <origin xyz="-9.1086191324708718293e-07 -0.02620448375530855592 0.030190392008842433652" rpy="0 0 0" />      
      <mass value="0.1663195349061246664" />      
      <inertia ixx="6.8622997376113035605e-05" ixy="6.1328048221653534174e-10" ixz="3.6786792027264541809e-06" iyy="0.00020057117429216707164" iyz="-3.7255079147351952329e-06" izz="0.00015770127977213045721" />      
    </inertial>    
  </link>  

  <link name="spiral_bevel_1m_14t_30deg">    
    <visual>      
      <origin xyz="0 0 0" rpy="0 -0 0" />      
      <geometry>        
        <mesh filename="../assemblies/toddlerbot/meshes/spiral_bevel_1m_14t_30deg_visual.stl" />        
      </geometry>      
      <material name="spiral_bevel_1m_14t_30deg_material">        
        <color rgba="0.64705882352941179736 0.64705882352941179736 0.64705882352941179736 1.0" />        
      </material>      
    </visual>    
    <inertial>      
      <origin xyz="8.2641075233036431769e-10 3.4055789742068465209e-10 0.0068612577407481641426" rpy="0 0 0" />      
      <mass value="0.00067997563436136246491" />      
      <inertia ixx="1.2174575798018973838e-08" ixy="3.8216070434470129766e-18" ixz="4.7204547854141617805e-16" iyy="1.2174575801813732727e-08" iyz="-2.6184097762970973854e-16" izz="1.3178653206314311711e-08" />      
    </inertial>    
  </link>  

  <joint name="waist_act_1" type="revolute">    
    <origin xyz="-4.3158571269690260163e-16 -0.019600000000000134676 0.012750000000000493577" rpy="-1.5707963267948961139 -1.5707963267948088504 0" />    
    <parent link="waist_link" />    
    <child link="spiral_bevel_1m_14t_30deg" />    
    <axis xyz="0 0 1" />    
    <limit effort="1" velocity="20" lower="-2.7925268031909271649" upper="2.7925268031909271649" />    
    <joint_properties friction="0.0" />    
  </joint>  

  <link name="spiral_bevel_1m_14t_30deg_2">    
    <visual>      
      <origin xyz="0 0 0" rpy="0 -0 0" />      
      <geometry>        
        <mesh filename="../assemblies/toddlerbot/meshes/spiral_bevel_1m_14t_30deg_2_visual.stl" />        
      </geometry>      
      <material name="spiral_bevel_1m_14t_30deg_2_material">        
        <color rgba="0.64705882352941179736 0.64705882352941179736 0.64705882352941179736 1.0" />        
      </material>      
    </visual>    
    <inertial>      
      <origin xyz="7.299096500823498701e-10 5.1591309282916804967e-10 0.0068612577407481632752" rpy="0 0 0" />      
      <mass value="0.00067997563436136246491" />      
      <inertia ixx="1.2174575796548749635e-08" ixy="2.6199054052568876071e-18" ixz="5.1847541181367891679e-16" iyy="1.2174575803283978437e-08" iyz="-1.5023607688884004006e-16" izz="1.3178653206314315019e-08" />      
    </inertial>    
  </link>  

  <joint name="waist_act_2" type="revolute">    
    <origin xyz="-5.8109383000701193055e-16 -0.019600000000000120798 0.03275000000000045236" rpy="-1.5707963267948927832 -1.3463968515393145431 1.0161280646543158659e-14" />    
    <parent link="waist_link" />    
    <child link="spiral_bevel_1m_14t_30deg_2" />    
    <axis xyz="0 0 1" />    
    <limit effort="1" velocity="20" lower="-2.7925268031909271649" upper="2.7925268031909271649" />    
    <joint_properties friction="0.0" />    
  </joint>  

  <link name="spur_gear_19_teeth">    
    <visual>      
      <origin xyz="0 0 0" rpy="0 -0 0" />      
      <geometry>        
        <mesh filename="../assemblies/toddlerbot/meshes/spur_gear_19_teeth_visual.stl" />        
      </geometry>      
      <material name="spur_gear_19_teeth_material">        
        <color rgba="0.61568627450980395466 0.81176470588235294379 0.92941176470588238168 1.0" />        
      </material>      
    </visual>    
    <inertial>      
      <origin xyz="-4.9156135350749387128e-09 9.0060874060975807733e-10 -0.0045295192537419875708" rpy="0 0 0" />      
      <mass value="0.0010993711450650535313" />      
      <inertia ixx="2.9215018435433075427e-08" ixy="2.5903313814092139973e-16" ixz="-8.4242612454600564997e-15" iyy="2.9215021540034058468e-08" iyz="1.522623238362820646e-15" izz="4.5709977027671355031e-08" />      
    </inertial>    
  </link>  

  <joint name="left_hip_yaw_drive" type="revolute">    
    <origin xyz="-0.036999999999999207134 -0.037100000000004823564 0.039500000000000437539" rpy="-1.5707963267950579844 5.7109166702824404977e-13 2.6938840543896956895e-13" />    
    <parent link="waist_link" />    
    <child link="spur_gear_19_teeth" />    
    <axis xyz="0 0 1" />    
    <limit effort="1" velocity="20" lower="-1.570796326794896558" upper="1.570796326794896558" />    
    <joint_properties friction="0.0" />    
  </joint>  

  <link name="spur_gear_21_teeth">    
    <visual>      
      <origin xyz="0 0 0" rpy="0 -0 0" />      
      <geometry>        
        <mesh filename="../assemblies/toddlerbot/meshes/spur_gear_21_teeth_visual.stl" />        
      </geometry>      
      <material name="spur_gear_21_teeth_material">        
        <color rgba="0.61568627450980395466 0.81176470588235294379 0.92941176470588238168 1.0" />        
      </material>      
    </visual>    
    <inertial>      
      <origin xyz="-4.7814841776401959085e-10 1.2610226465348769291e-12 -0.0024944618616143370698" rpy="0 0 0" />      
      <mass value="0.0010063046528317974842" />      
      <inertia ixx="3.1842855421068481665e-08" ixy="-5.9730587676548820251e-38" ixz="5.4199104819300928604e-39" iyy="3.1842855426953785697e-08" iyz="-3.7144429244050308014e-38" izz="5.9529380586728028132e-08" />      
    </inertial>    
  </link>  

  <joint name="left_leg_fixed" type="fixed">    
    <origin xyz="-4.336808689942017736e-19 6.9388939039072283776e-18 -0.0050000000000000044409" rpy="-1.0439449364097535015e-14 3.7110850528220658615e-31 -4.3084061976207498209e-30" />    
    <parent link="spur_gear_21_teeth" />    
    <child link="hip_yaw_link" />    
    <axis xyz="0 0 1" />    
    <limit effort="1" velocity="20" />    
    <joint_properties friction="0.0" />    
  </joint>  

  <joint name="left_hip_yaw_driven" type="revolute">    
    <origin xyz="-0.036999999999999998168 -0.041100000000000067035 0.019500000000000006911" rpy="-1.5707963267948841235 1.5707963267948956698 0" />    
    <parent link="waist_link" />    
    <child link="spur_gear_21_teeth" />    
    <axis xyz="0 0 1" />    
    <limit effort="1" velocity="20" lower="-1.570796326794896558" upper="1.570796326794896558" />    
    <joint_properties friction="0.0" />    
  </joint>  

  <link name="spur_gear_19_teeth_2">    
    <visual>      
      <origin xyz="0 0 0" rpy="0 -0 0" />      
      <geometry>        
        <mesh filename="../assemblies/toddlerbot/meshes/spur_gear_19_teeth_2_visual.stl" />        
      </geometry>      
      <material name="spur_gear_19_teeth_2_material">        
        <color rgba="0.61568627450980395466 0.81176470588235294379 0.92941176470588238168 1.0" />        
      </material>      
    </visual>    
    <inertial>      
      <origin xyz="-4.91561353507493954e-09 9.0060873714031122877e-10 -0.0045295192537419875708" rpy="0 0 0" />      
      <mass value="0.0010993711450650535313" />      
      <inertia ixx="2.9215018435433088662e-08" ixy="2.5903313826161381487e-16" ixz="-8.4242612454600580774e-15" iyy="2.9215021540034071703e-08" iyz="1.5226232383628210404e-15" izz="4.5709977027671355031e-08" />      
    </inertial>    
  </link>  

  <joint name="right_hip_yaw_drive" type="revolute">    
    <origin xyz="0.037000000000000352052 -0.037100000000003852119 0.039500000000000062839" rpy="-1.5707963267949709429 3.0763843997160748787e-13 2.7733309074151655565e-13" />    
    <parent link="waist_link" />    
    <child link="spur_gear_19_teeth_2" />    
    <axis xyz="0 0 1" />    
    <limit effort="1" velocity="20" lower="-1.570796326794896558" upper="1.570796326794896558" />    
    <joint_properties friction="0.0" />    
  </joint>  

  <link name="spur_gear_21_teeth_2">    
    <visual>      
      <origin xyz="0 0 0" rpy="0 -0 0" />      
      <geometry>        
        <mesh filename="../assemblies/toddlerbot/meshes/spur_gear_21_teeth_2_visual.stl" />        
      </geometry>      
      <material name="spur_gear_21_teeth_2_material">        
        <color rgba="0.61568627450980395466 0.81176470588235294379 0.92941176470588238168 1.0" />        
      </material>      
    </visual>    
    <inertial>      
      <origin xyz="-4.7814841733033872186e-10 -1.2610157076409730219e-12 -0.002505538138385667371" rpy="0 0 0" />      
      <mass value="0.0010063046528317974842" />      
      <inertia ixx="3.1842855421068481665e-08" ixy="-5.6450446515323895372e-38" ixz="-1.2410298257532391259e-39" iyy="3.1842855426953785697e-08" iyz="3.0480208504147716512e-38" izz="5.9529380586728028132e-08" />      
    </inertial>    
  </link>  

  <joint name="right_leg_fixed" type="fixed">    
    <origin xyz="0 -6.9388939039072283776e-18 -0.004999999999999997502" rpy="1.60982722631807463e-15 -3.5340660733628542786e-32 -3.0121122483794329866e-31" />    
    <parent link="spur_gear_21_teeth_2" />    
    <child link="hip_yaw_link_2" />    
    <axis xyz="0 0 1" />    
    <limit effort="1" velocity="20" />    
    <joint_properties friction="0.0" />    
  </joint>  

  <joint name="right_hip_yaw_driven" type="revolute">    
    <origin xyz="0.036999999999999991229 -0.041099999999999997646 0.019500000000000006911" rpy="-1.5707963267948983344 1.5707963267948956698 0" />    
    <parent link="waist_link" />    
    <child link="spur_gear_21_teeth_2" />    
    <axis xyz="0 0 1" />    
    <limit effort="1" velocity="20" lower="-1.570796326794896558" upper="1.570796326794896558" />    
    <joint_properties friction="0.0" />    
  </joint>  

  <joint name="waist_roll" type="revolute">    
    <origin xyz="-1.2306064131348466017e-19 0.022707865260692457893 -0.013000000000000011546" rpy="1.5707963267948952257 -4.14087346736882539e-15 4.2181022606674638269e-16" />    
    <parent link="waist_gears" />    
    <child link="waist_link" />    
    <axis xyz="0 0 1" />    
    <limit effort="1" velocity="20" lower="-0.52359877559829881566" upper="0.52359877559829881566" />    
    <joint_properties friction="0.0" />    
  </joint>  

  <joint name="waist_yaw" type="revolute">    
    <origin xyz="0 -3.9443045261050590271e-31 0" rpy="2.0946901476026454934e-15 7.1861600448342810266e-16 -1.5707963267948101826" />    
    <parent link="torso" />    
    <child link="waist_gears" />    
    <axis xyz="0 0 1" />    
    <limit effort="1" velocity="20" lower="-1.570796326794896558" upper="1.570796326794896558" />    
    <joint_properties friction="0.0" />    
  </joint>  

  <joint name="left_sho_pitch" type="revolute">    
    <origin xyz="-0.0029999999999997389866 0.062000000000000464462 0.10523651076281793915" rpy="-1.5707963267948983344 -3.4972025276127318207e-15 -2.4598039012687864683e-16" />    
    <parent link="torso" />    
    <child link="sho_pitch_link" />    
    <axis xyz="0 0 1" />    
    <limit effort="1" velocity="20" lower="-1.570796326794896558" upper="1.570796326794896558" />    
    <joint_properties friction="0.0" />    
  </joint>  

  <joint name="right_sho_pitch" type="revolute">    
    <origin xyz="-0.0030000000000001136868 -0.061999999999999992617 0.10523651076281731465" rpy="-1.570796326794896558 -3.3306690742370509197e-16 3.141592653589793116" />    
    <parent link="torso" />    
    <child link="sho_pitch_link_2" />    
    <axis xyz="0 0 1" />    
    <limit effort="1" velocity="20" lower="-1.570796326794896558" upper="1.570796326794896558" />    
    <joint_properties friction="0.0" />    
  </joint>  


<link name="hip_yaw_link">    
    <visual>      
      <origin xyz="0 0 0" rpy="0 -0 0" />      
      <geometry>        
        <mesh filename="../assemblies/left_leg_XM430/meshes/left_hip_yaw_link_visual.stl" />        
      </geometry>      
      <material name="hip_yaw_link_material">        
        <color rgba="0.61568627450980395466 0.81176470588235294379 0.92941176470588238168 1.0" />        
      </material>      
    </visual>    
    <inertial>      
      <origin xyz="6.9994164697772127436e-19 -3.8999545121627272677e-19 -0.0098390489054829138871" rpy="0 0 0" />      
      <mass value="0.017999999999999995171" />      
      <inertia ixx="2.6385033891442540855e-06" ixy="0" ixz="0" iyy="7.6596731957046890345e-06" iyz="0" izz="7.7220708070894769837e-06" />      
    </inertial>    
  </link>  

  <link name="hip_roll_link">    
    <visual>      
      <origin xyz="0 0 0" rpy="0 -0 0" />      
      <geometry>        
        <mesh filename="../assemblies/left_leg_XM430/meshes/left_hip_roll_link_visual.stl" />        
      </geometry>      
      <material name="hip_roll_link_material">        
        <color rgba="0.51698661238356047321 0.50347815951093488618 0.49050589017722012741 1.0" />        
      </material>      
    </visual>    
    <collision>      
      <origin xyz="0 0 0" rpy="0 -0 0" />      
      <geometry>        
        <mesh filename="collisions/left_hip_roll_link_collision.stl" />        
      </geometry>      
    </collision>    
    <inertial>      
      <origin xyz="-0.011999849582185678071 -0.00049598090794010681048 -0.018504111838598649026" rpy="0 0 0" />      
      <mass value="0.11059999999836234164" />      
      <inertia ixx="2.2818802599018682756e-05" ixy="-4.6520143286691176809e-08" ixz="-4.6888548260742845694e-08" iyy="3.087163208233903455e-05" iyz="-5.7477343899716666035e-07" izz="3.0871666424469295785e-05" />      
    </inertial>    
  </link>  

  <link name="left_hip_pitch_link_xm430">    
    <visual>      
      <origin xyz="0 0 0" rpy="0 -0 0" />      
      <geometry>        
        <mesh filename="../assemblies/left_leg_XM430/meshes/left_hip_pitch_link_xm430_visual.stl" />        
      </geometry>      
      <material name="left_hip_pitch_link_xm430_material">        
        <color rgba="0.87072221357329560032 0.72641010956094287376 0.24785169615220703498 1.0" />        
      </material>      
    </visual>    
    <collision>      
      <origin xyz="0 0 0" rpy="0 -0 0" />      
      <geometry>        
        <mesh filename="collisions/left_hip_pitch_link_xm430_collision.stl" />        
      </geometry>      
    </collision>    
    <inertial>      
      <origin xyz="-0.00075729214155295329104 -0.050714785675264786868 -0.012656155119960033756" rpy="0 0 0" />      
      <mass value="0.1148009013503056841" />      
      <inertia ixx="6.6072773889429780268e-05" ixy="-4.6080149277698338478e-07" ixz="-1.8170739115316130752e-07" iyy="2.3633638685370093061e-05" iyz="1.412525392534511906e-06" izz="6.2221728804334047735e-05" />      
    </inertial>    
  </link>  

  <link name="left_calf_link">    
    <visual>      
      <origin xyz="0 0 0" rpy="0 -0 0" />      
      <geometry>        
        <mesh filename="../assemblies/left_leg_XM430/meshes/left_calf_link_visual.stl" />        
      </geometry>      
      <material name="left_calf_link_material">        
        <color rgba="0.616547745550632742 0.7175754134247219751 0.74372657889541438081 1.0" />        
      </material>      
    </visual>    
    <collision>      
      <origin xyz="0 0 0" rpy="0 -0 0" />      
      <geometry>        
        <mesh filename="collisions/left_calf_link_collision.stl" />        
      </geometry>      
    </collision>    
    <inertial>      
      <origin xyz="0.001633055673954363898 -0.050045528174708892033 -0.0099079425125457917106" rpy="0 0 0" />      
      <mass value="0.086799999986183581924" />      
      <inertia ixx="4.9509459873200504219e-05" ixy="3.6911110041724544372e-06" ixz="4.1819058040000167512e-07" iyy="1.553122903796312626e-05" iyz="4.6309763568465605115e-07" izz="5.3138661991211913937e-05" />      
    </inertial>    
  </link>  

  <link name="bearing_683">    
    <visual>      
      <origin xyz="0 0 0" rpy="0 -0 0" />      
      <geometry>        
        <mesh filename="../assemblies/left_leg_XM430/meshes/left_bearing_683_visual.stl" />        
      </geometry>      
      <material name="bearing_683_material">        
        <color rgba="0.64705882352941179736 0.64705882352941179736 0.64705882352941179736 1.0" />        
      </material>      
    </visual>    
    <inertial>      
      <origin xyz="1.0732094295235117161e-19 6.2549399515679974435e-19 -0.0015500000000000003792" rpy="0 0 0" />      
      <mass value="0.00048694686130641793437" />      
      <inertia ixx="2.1551456503319879113e-09" ixy="2.3860364254964754589e-27" ixz="1.1214000884108555107e-37" iyy="2.1551456503319883249e-09" iyz="-2.5890704815542465569e-38" izz="3.5303647444715305817e-09" />      
    </inertial>    
  </link>  

  <joint name="left_knee_front_rev_2" type="revolute">    
    <origin xyz="-0.0057402514854763735455 0.013858192987669520901 -0.026199999999998880434" rpy="-2.0198851465398702307e-14 -3.8607515872534395329e-14 1.5737070550412859404" />    
    <parent link="left_calf_link" />    
    <child link="bearing_683" />    
    <axis xyz="0 0 1" />    
    <limit effort="1" velocity="20" lower="-6.283185307179586232" upper="6.283185307179586232" />    
    <joint_properties friction="0.0" />    
  </joint>  

  <link name="bearing_683_2">    
    <visual>      
      <origin xyz="0 0 0" rpy="0 -0 0" />      
      <geometry>        
        <mesh filename="../assemblies/left_leg_XM430/meshes/left_bearing_683_2_visual.stl" />        
      </geometry>      
      <material name="bearing_683_2_material">        
        <color rgba="0.64705882352941179736 0.64705882352941179736 0.64705882352941179736 1.0" />        
      </material>      
    </visual>    
    <inertial>      
      <origin xyz="1.0732094295233481325e-19 -1.1092294808199973352e-18 -0.0015500000000000003792" rpy="0 0 0" />      
      <mass value="0.00048694686130641793437" />      
      <inertia ixx="2.1551456503319887385e-09" ixy="1.3912489984452133502e-28" ixz="7.9233709950009322277e-38" iyy="2.1551456503319874977e-09" iyz="-4.6239177088477271353e-38" izz="3.5303647444715305817e-09" />      
    </inertial>    
  </link>  

  <joint name="left_knee_back_rev_2" type="revolute">    
    <origin xyz="0.0057402514854763839539 -0.01385819298766921559 -0.026199999999999640243" rpy="-3.4995571909695562261e-16 -2.90815686857019016e-14 1.5739207094624192429" />    
    <parent link="left_calf_link" />    
    <child link="bearing_683_2" />    
    <axis xyz="0 0 1" />    
    <limit effort="1" velocity="20" lower="-6.283185307179586232" upper="6.283185307179586232" />    
    <joint_properties friction="0.0" />    
  </joint>  

  <link name="ank_pitch_link">    
    <visual>      
      <origin xyz="0 0 0" rpy="0 -0 0" />      
      <geometry>        
        <mesh filename="../assemblies/left_leg_XM430/meshes/left_ank_pitch_link_visual.stl" />        
      </geometry>      
      <material name="ank_pitch_link_material">        
        <color rgba="0.63189161126160264814 0.7266866879354088038 0.78356373393969258601 1.0" />        
      </material>      
    </visual>    
    <inertial>      
      <origin xyz="0.0005952828256592173576 -4.0269683181568689667e-08 7.7616092716332508893e-08" rpy="0 0 0" />      
      <mass value="0.0042238381753791614387" />      
      <inertia ixx="3.9782741364678456013e-07" ixy="-1.6834347828603229053e-13" ixz="2.0919188855107369529e-14" iyy="4.3705254067423072352e-07" iyz="-1.6428822181660838267e-12" izz="8.8858574534612975842e-08" />      
    </inertial>    
  </link>  

  <link name="ank_roll_link">    
    <visual>      
      <origin xyz="0 0 0" rpy="0 -0 0" />      
      <geometry>        
        <mesh filename="../assemblies/left_leg_XM430/meshes/left_ank_roll_link_visual.stl" />        
      </geometry>      
      <material name="ank_roll_link_material">        
        <color rgba="0.61568627450980395466 0.81176470588235294379 0.92941176470588227065 1.0" />        
      </material>      
    </visual>    
    <inertial>      
      <origin xyz="-3.3748977754987916802e-09 0.016071733707723686452 -0.0096236810250137777567" rpy="0 0 0" />      
      <mass value="0.010900000000000003436" />      
      <inertia ixx="2.6058536057764963368e-06" ixy="-5.4054321087398513321e-13" ixz="6.069254909621619699e-13" iyy="2.5928781338360468952e-06" iyz="3.9359839679282456802e-07" izz="1.6179884211196010928e-06" />      
    </inertial>    
  </link>  

  <link name="ank_rr_link">    
    <visual>      
      <origin xyz="0 0 0" rpy="0 -0 0" />      
      <geometry>        
        <mesh filename="../assemblies/left_leg_XM430/meshes/left_ank_rr_link_visual.stl" />        
      </geometry>      
      <material name="ank_rr_link_material">        
        <color rgba="0.61568627450980395466 0.81176470588235294379 0.92941176470588238168 1.0" />        
      </material>      
    </visual>    
    <inertial>      
      <origin xyz="-4.5249610960602584678e-05 0.0063096429836314582573 -2.0541493629085886652e-19" rpy="0 0 0" />      
      <mass value="0.0014499999999999996832" />      
      <inertia ixx="2.9739579267716143416e-08" ixy="2.4213146797977948196e-10" ixz="3.5523394884456569378e-14" iyy="2.7430027724071957055e-08" iyz="6.0453569845698011573e-32" izz="4.2921949116163665819e-08" />      
    </inertial>    
  </link>  

  <link name="ank_motor_rod_long">    
    <visual>      
      <origin xyz="0 0 0" rpy="0 -0 0" />      
      <geometry>        
        <mesh filename="../assemblies/left_leg_XM430/meshes/left_ank_motor_rod_long_visual.stl" />        
      </geometry>      
      <material name="ank_motor_rod_long_material">        
        <color rgba="0.63549975559783222767 0.7077439301702044272 0.75109043491362770251 1.0" />        
      </material>      
    </visual>    
    <inertial>      
      <origin xyz="2.4855088813549552477e-10 0.034559019974062146763 0.00093851704878456236776" rpy="0 0 0" />      
      <mass value="0.0021712857268636710437" />      
      <inertia ixx="8.5350290057999892598e-07" ixy="1.488424486145758595e-14" ixz="4.5749525025198726908e-11" iyy="1.3237321792739390432e-08" iyz="-4.3668910960866295549e-09" izz="8.5812217519451080535e-07" />      
    </inertial>    
  </link>  

  <joint name="left_ank_long_rev_2" type="revolute">    
    <origin xyz="-2.1579960041151480254e-15 0.0099999999999990651922 -8.08381139805192106e-16" rpy="-1.5707963267948954478 1.3320366994106502823 -1.5707963267948126251" />    
    <parent link="ank_rr_link" />    
    <child link="ank_motor_rod_long" />    
    <axis xyz="0 0 1" />    
    <limit effort="1" velocity="20" lower="-1.570796326794896558" upper="1.570796326794896558" />    
    <joint_properties friction="0.0" />    
  </joint>  

  <joint name="left_ank_long_rev_1" type="revolute">    
    <origin xyz="-0.018000000000002184392 0.015999999999998931743 -0.020599999999999191874" rpy="5.6928860135513275759e-16 -8.1605439123400921334e-16 3.1233695685467459668" />    
    <parent link="ank_roll_link" />    
    <child link="ank_rr_link" />    
    <axis xyz="0 0 1" />    
    <limit effort="1" velocity="20" lower="-1.570796326794896558" upper="1.570796326794896558" />    
    <joint_properties friction="0.0" />    
  </joint>  

  <link name="ank_rr_link_2">    
    <visual>      
      <origin xyz="0 0 0" rpy="0 -0 0" />      
      <geometry>        
        <mesh filename="../assemblies/left_leg_XM430/meshes/left_ank_rr_link_2_visual.stl" />        
      </geometry>      
      <material name="ank_rr_link_2_material">        
        <color rgba="0.61568627450980395466 0.81176470588235294379 0.92941176470588238168 1.0" />        
      </material>      
    </visual>    
    <inertial>      
      <origin xyz="-4.5249610960599115231e-05 -0.0063096429836315120337 2.0541493629107726698e-19" rpy="0 0 0" />      
      <mass value="0.0014499999999999996832" />      
      <inertia ixx="2.9739579267716143416e-08" ixy="-2.4213146797977943026e-10" ixz="-3.5523394884456569378e-14" iyy="2.7430027724071950438e-08" iyz="1.9531260171098395433e-32" izz="4.2921949116163665819e-08" />      
    </inertial>    
  </link>  

  <link name="ank_motor_rod_short">    
    <visual>      
      <origin xyz="0 0 0" rpy="0 -0 0" />      
      <geometry>        
        <mesh filename="../assemblies/left_leg_XM430/meshes/left_ank_motor_rod_short_visual.stl" />        
      </geometry>      
      <material name="ank_motor_rod_short_material">        
        <color rgba="0.41222606689734719865 0.58339100346020766885 0.8110726643598615837 1.0" />        
      </material>      
    </visual>    
    <inertial>      
      <origin xyz="2.6038941132517273255e-10 0.023830465465870746822 0.00090403506359631655414" rpy="0 0 0" />      
      <mass value="0.001700000000000000339" />      
      <inertia ixx="3.31534162526694895e-07" ixy="8.7419769213848246822e-15" ixz="4.5749941567520897592e-11" iyy="1.0947363610305454928e-08" iyz="-3.5863098646425486986e-09" izz="3.362134044786455377e-07" />      
    </inertial>    
  </link>  

  <joint name="left_ank_short_rev_2" type="revolute">    
    <origin xyz="-3.4694469519536141888e-18 -0.010000000000000064393 -6.9388939039072283776e-18" rpy="-1.570796326794896558 -1.2119133862910156374 -1.570796326794871467" />    
    <parent link="ank_rr_link_2" />    
    <child link="ank_motor_rod_short" />    
    <axis xyz="0 0 1" />    
    <limit effort="1" velocity="20" lower="-1.570796326794896558" upper="1.570796326794896558" />    
    <joint_properties friction="0.0" />    
  </joint>  

  <joint name="left_ank_short_rev_1" type="revolute">    
    <origin xyz="0.017999999999999995171 0.015999999999999986455 -0.020600000000000000255" rpy="-3.244504776895705127e-16 1.1087098867936222379e-15 0.026118548507359652666" />    
    <parent link="ank_roll_link" />    
    <child link="ank_rr_link_2" />    
    <axis xyz="0 0 1" />    
    <limit effort="1" velocity="20" lower="-1.570796326794896558" upper="1.570796326794896558" />    
    <joint_properties friction="0.0" />    
  </joint>  

  <link name="left_sole_link">    
    <visual>      
      <origin xyz="0 0 0" rpy="0 -0 0" />      
      <geometry>        
        <mesh filename="../assemblies/left_leg_XM430/meshes/left_sole_link_visual.stl" />        
      </geometry>      
      <material name="left_sole_link_material">        
        <color rgba="0.61568627450980395466 0.81176470588235283277 0.92941176470588238168 1.0" />        
      </material>      
    </visual>    
    <collision>      
      <origin xyz="0 0 0" rpy="0 -0 0" />      
      <geometry>        
        <mesh filename="../assemblies/left_leg_XM430/meshes/left_sole_link_collision.stl" />        
      </geometry>      
    </collision>    
    <inertial>      
      <origin xyz="-0.028268455053070309924 -2.3408773987406203758e-07 -0.010206307024274944434" rpy="0 0 0" />      
      <mass value="0.013899999999999999162" />      
      <inertia ixx="1.3160509347109561336e-06" ixy="3.0094161237480981899e-12" ixz="-2.3741900688425293673e-07" iyy="1.3575574544571530477e-05" iyz="-6.7706521654991170568e-12" izz="1.4673603612256135535e-05" />      
    </inertial>    
  </link>  

  <joint name="left_sole" type="fixed">    
    <origin xyz="-9.1072982488782372457e-18 0.024999999999999994449 -0.022600000000000002032" rpy="1.570796326794896558 1.570796326794896336 0" />    
    <parent link="ank_roll_link" />    
    <child link="left_sole_link" />    
    <axis xyz="0 0 1" />    
    <limit effort="1" velocity="20" />    
    <joint_properties friction="0.0" />    
  </joint>  

  <joint name="left_ank_roll" type="revolute">    
    <origin xyz="0.0014999999999999241371 -2.7755575615628913511e-17 1.5796825653113799603e-16" rpy="2.1953071957139364813e-17 1.5707963267948659158 0" />    
    <parent link="ank_pitch_link" />    
    <child link="ank_roll_link" />    
    <axis xyz="0 0 1" />    
    <limit effort="1" velocity="20" lower="-0.785398163397448279" upper="0.785398163397448279" />    
    <joint_properties friction="0.0" />    
  </joint>  

  <joint name="left_ank_pitch" type="revolute">    
    <origin xyz="-5.8754783795495723237e-17 -0.10000000000000036637 -0.01040000000000218007" rpy="-6.6613494777492792143e-16 5.5008909826911396159e-25 3.141592653589793116" />    
    <parent link="left_calf_link" />    
    <child link="ank_pitch_link" />    
    <axis xyz="0 0 1" />    
    <limit effort="1" velocity="20" lower="-0.785398163397448279" upper="0.95993108859688125456" />    
    <joint_properties friction="0.0" />    
  </joint>  

  <link name="ank_motor_arm">    
    <visual>      
      <origin xyz="0 0 0" rpy="0 -0 0" />      
      <geometry>        
        <mesh filename="../assemblies/left_leg_XM430/meshes/left_ank_motor_arm_visual.stl" />        
      </geometry>      
      <material name="ank_motor_arm_material">        
        <color rgba="0.62517751827980905244 0.70593642422614044651 0.75978993426662766453 1.0" />        
      </material>      
    </visual>    
    <inertial>      
      <origin xyz="0.014511489101591688866 -1.3661063433491998512e-18 0.0040925443765950720101" rpy="0 0 0" />      
      <mass value="0.0020595846677894939954" />      
      <inertia ixx="2.759183675652207751e-08" ixy="1.3728927743830823072e-23" ixz="-3.027078820659488159e-08" iyy="1.6138599216238440584e-07" iyz="-1.5005615352829754492e-23" izz="1.643783676501628224e-07" />      
    </inertial>    
  </link>  

  <joint name="left_ank_act_1" type="revolute">    
    <origin xyz="0.013499999999998150632 -0.044499999999994099831 0.004000000000003878925" rpy="-4.199339249962906148e-13 -1.7566169631614281426e-13 -0.21173394130241762756" />    
    <parent link="left_calf_link" />    
    <child link="ank_motor_arm" />    
    <axis xyz="0 0 1" />    
    <limit effort="1" velocity="20" lower="-1.3089969389957472057" upper="1.3089969389957472057" />    
    <joint_properties friction="0.0" />    
  </joint>  

  <link name="ank_motor_arm_2">    
    <visual>      
      <origin xyz="0 0 0" rpy="0 -0 0" />      
      <geometry>        
        <mesh filename="../assemblies/left_leg_XM430/meshes/left_ank_motor_arm_2_visual.stl" />        
      </geometry>      
      <material name="ank_motor_arm_2_material">        
        <color rgba="0.62517751827980905244 0.70593642422614044651 0.75978993426662766453 1.0" />        
      </material>      
    </visual>    
    <inertial>      
      <origin xyz="0.014511489101591685397 1.2132948235844081638e-17 0.0040925443765950659386" rpy="0 0 0" />      
      <mass value="0.0020595846677894939954" />      
      <inertia ixx="2.759183675652200141e-08" ixy="1.4447443099816966568e-22" ixz="-3.0270788206594848502e-08" iyy="1.6138599216238443231e-07" iyz="5.8537400859049381353e-23" izz="1.6437836765016287534e-07" />      
    </inertial>    
  </link>  

  <joint name="left_ank_act_2" type="revolute">    
    <origin xyz="0.013500000000004789419 -0.064499999999987761568 -0.024800000000002139777" rpy="-3.1415926535893099469 1.5472440156112037689e-14 -0.22995607267390710815" />    
    <parent link="left_calf_link" />    
    <child link="ank_motor_arm_2" />    
    <axis xyz="0 0 1" />    
    <limit effort="1" velocity="20" lower="-1.3089969389957472057" upper="1.3089969389957472057" />    
    <joint_properties friction="0.0" />    
  </joint>  

  <joint name="left_knee_pitch" type="revolute">    
    <origin xyz="1.9837028473669800546e-17 -0.096000000000000015876 -0.0091999999999999738237" rpy="-2.9366522548798717986e-14 3.5724636926721053889e-16 4.1927868643308625526e-16" />    
    <parent link="left_hip_pitch_link_xm430" />    
    <child link="left_calf_link" />    
    <axis xyz="0 0 1" />    
    <limit effort="1" velocity="20" lower="0" upper="1.9198621771937625091" />    
    <joint_properties friction="0.0" />    
  </joint>  

  <link name="xm430_plate">    
    <visual>      
      <origin xyz="0 0 0" rpy="0 -0 0" />      
      <geometry>        
        <mesh filename="../assemblies/left_leg_XM430/meshes/left_xm430_plate_visual.stl" />        
      </geometry>      
      <material name="xm430_plate_material">        
        <color rgba="0.61568627450980395466 0.81176470588235294379 0.9294117647058824927 1.0" />        
      </material>      
    </visual>    
    <inertial>      
      <origin xyz="-1.0744839342516173804e-17 2.3911851510422750402e-18 -0.0024039046431217955119" rpy="0 0 0" />      
      <mass value="0.0026999999999999992756" />      
      <inertia ixx="1.2933116645363416124e-07" ixy="-6.8936588702566453648e-08" ixz="-1.8408351292855479299e-35" iyy="2.672043438587668303e-07" iyz="1.2415852302568489052e-35" izz="3.8533537562751439267e-07" />      
    </inertial>    
  </link>  

  <link name="knee_rod">    
    <visual>      
      <origin xyz="0 0 0" rpy="0 -0 0" />      
      <geometry>        
        <mesh filename="../assemblies/left_leg_XM430/meshes/left_knee_rod_visual.stl" />        
      </geometry>      
      <material name="knee_rod_material">        
        <color rgba="0.62051618944235198416 0.78640765248647581664 0.88594253031295022716 1.0" />        
      </material>      
    </visual>    
    <inertial>      
      <origin xyz="0.014594547204704258134 4.1946460598583926106e-05 -0.0015996227373173928839" rpy="0 0 0" />      
      <mass value="0.0031629468613064179276" />      
      <inertia ixx="2.5896135582861323238e-08" ixy="-3.523492118218595344e-10" ixz="4.1682974279785014807e-10" iyy="6.0153250889878618971e-07" iyz="1.1980181501036628568e-12" izz="6.2266858020374725112e-07" />      
    </inertial>    
  </link>  

  <joint name="left_knee_front_rev_1" type="revolute">    
    <origin xyz="0.013858192987669312735 0.0057402514854763440552 -0.0050000000000000009714" rpy="-8.8273423888544989682e-15 5.9762404835944504039e-15 -3.1386819253434037336" />    
    <parent link="xm430_plate" />    
    <child link="knee_rod" />    
    <axis xyz="0 0 1" />    
    <limit effort="1" velocity="20" lower="-6.283185307179586232" upper="6.283185307179586232" />    
    <joint_properties friction="0.0" />    
  </joint>  

  <link name="knee_rod_2">    
    <visual>      
      <origin xyz="0 0 0" rpy="0 -0 0" />      
      <geometry>        
        <mesh filename="../assemblies/left_leg_XM430/meshes/left_knee_rod_2_visual.stl" />        
      </geometry>      
      <material name="knee_rod_2_material">        
        <color rgba="0.62051618944235198416 0.78640765248647581664 0.88594253031295022716 1.0" />        
      </material>      
    </visual>    
    <inertial>      
      <origin xyz="0.014594555500542014462 3.5710133123464131357e-05 -0.0015996227373176105917" rpy="0 0 0" />      
      <mass value="0.0031629468613064179276" />      
      <inertia ixx="2.5895856845870582634e-08" ixy="-2.9996438872428646949e-10" ixz="4.1682997973827996187e-10" iyy="6.0153264826847845892e-07" iyz="1.0199045846546678738e-12" izz="6.226684408364528263e-07" />      
    </inertial>    
  </link>  

  <joint name="left_knee_back_rev_1" type="revolute">    
    <origin xyz="-0.013858192987669298857 -0.0057402514854763440552 -0.0050000000000000009714" rpy="-2.9668697207277861891e-16 -3.5495245422933824495e-15 -3.1384682709222704311" />    
    <parent link="xm430_plate" />    
    <child link="knee_rod_2" />    
    <axis xyz="0 0 1" />    
    <limit effort="1" velocity="20" lower="-6.283185307179586232" upper="6.283185307179586232" />    
    <joint_properties friction="0.0" />    
  </joint>  

  <joint name="left_knee_act" type="revolute">    
    <origin xyz="-0.00015000000000003010057 -0.061500000000000082379 -0.030400000000000440559" rpy="-3.9687967765302122778e-16 -3.2670861344266613268e-15 1.570796326794896558" />    
    <parent link="left_hip_pitch_link_xm430" />    
    <child link="xm430_plate" />    
    <axis xyz="0 0 1" />    
    <limit effort="1" velocity="20" lower="0" upper="1.9198621771937625091" />    
    <joint_properties friction="0.0" />    
  </joint>  

  <joint name="left_hip_pitch" type="revolute">    
    <origin xyz="-0.024000000716151263791 -0.019000000152441045426 -0.019000000152457018759" rpy="1.5707963267952340658 1.5707963267945517227 0" />    
    <parent link="hip_roll_link" />    
    <child link="left_hip_pitch_link_xm430" />    
    <axis xyz="0 0 1" />    
    <limit effort="1" velocity="20" lower="-1.570796326794896558" upper="1.570796326794896558" />    
    <joint_properties friction="0.0" />    
  </joint>  

  <joint name="left_hip_roll" type="revolute">    
    <origin xyz="0.018999999999999194616 -8.636160306239192055e-16 -0.026000000000000224321" rpy="-3.141592653589793116 -1.5707963267948843455 0" />    
    <parent link="hip_yaw_link" />    
    <child link="hip_roll_link" />    
    <axis xyz="0 0 1" />    
    <limit effort="1" velocity="20" lower="-0.785398163397448279" upper="1.570796326794896558" />    
    <joint_properties friction="0.0" />    
  </joint>  


<link name="hip_yaw_link_2">    
    <visual>      
      <origin xyz="0 0 0" rpy="0 -0 0" />      
      <geometry>        
        <mesh filename="../assemblies/right_leg_XM430/meshes/right_hip_yaw_link_visual.stl" />        
      </geometry>      
      <material name="hip_yaw_link_material">        
        <color rgba="0.61568627450980395466 0.81176470588235294379 0.92941176470588238168 1.0" />        
      </material>      
    </visual>    
    <inertial>      
      <origin xyz="-6.9994164697772127436e-19 3.8999545121627272677e-19 -0.0098390489054829138871" rpy="0 0 0" />      
      <mass value="0.017999999999999995171" />      
      <inertia ixx="2.6385033891442540855e-06" ixy="0" ixz="0" iyy="7.6596731957046890345e-06" iyz="0" izz="7.7220708070894769837e-06" />      
    </inertial>    
  </link>  

  <link name="hip_roll_link_2">    
    <visual>      
      <origin xyz="0 0 0" rpy="0 -0 0" />      
      <geometry>        
        <mesh filename="../assemblies/right_leg_XM430/meshes/right_hip_roll_link_visual.stl" />        
      </geometry>      
      <material name="hip_roll_link_material">        
        <color rgba="0.51698661238356047321 0.50347815951093488618 0.49050589017722012741 1.0" />        
      </material>      
    </visual>    
    <collision>      
      <origin xyz="0 0 0" rpy="0 -0 0" />      
      <geometry>        
        <mesh filename="collisions/right_hip_roll_link_collision.stl" />        
      </geometry>      
    </collision>    
    <inertial>      
      <origin xyz="-0.011999849582182770674 -0.00049598090794319277513 -0.018504111838597465944" rpy="0 0 0" />      
      <mass value="0.11059999999836234164" />      
      <inertia ixx="2.2818802599018211805e-05" ixy="-4.6520143286279624676e-08" ixz="-4.6888548259070842361e-08" iyy="3.0871632082338072321e-05" iyz="-5.7477343899720911788e-07" izz="3.0871666424467954085e-05" />      
    </inertial>    
  </link>  

  <link name="right_hip_pitch_link_xm430">    
    <visual>      
      <origin xyz="0 0 0" rpy="0 -0 0" />      
      <geometry>        
        <mesh filename="../assemblies/right_leg_XM430/meshes/right_hip_pitch_link_xm430_visual.stl" />        
      </geometry>      
      <material name="right_hip_pitch_link_xm430_material">        
        <color rgba="0.87072221357329571134 0.72641010956094276274 0.24785169615220697947 1.0" />        
      </material>      
    </visual>    
    <collision>      
      <origin xyz="0 0 0" rpy="0 -0 0" />      
      <geometry>        
        <mesh filename="collisions/right_hip_pitch_link_xm430_collision.stl" />        
      </geometry>      
    </collision>    
    <inertial>      
      <origin xyz="0.00075715881371275360785 -0.050714784778880674099 -0.012656153620121986594" rpy="0 0 0" />      
      <mass value="0.11480090135030567022" />      
      <inertia ixx="6.6072786489385133975e-05" ixy="4.6010682906023012432e-07" ixz="1.8171597853316402541e-07" iyy="2.3633665181581899978e-05" iyz="1.4125296519934367832e-06" izz="6.2221763055417950421e-05" />      
    </inertial>    
  </link>  

  <link name="right_calf_link">    
    <visual>      
      <origin xyz="0 0 0" rpy="0 -0 0" />      
      <geometry>        
        <mesh filename="../assemblies/right_leg_XM430/meshes/right_calf_link_visual.stl" />        
      </geometry>      
      <material name="right_calf_link_material">        
        <color rgba="0.616547745550632742 0.71757541342472208612 0.74372657889541449183 1.0" />        
      </material>      
    </visual>    
    <collision>      
      <origin xyz="0 0 0" rpy="0 -0 0" />      
      <geometry>        
        <mesh filename="collisions/right_calf_link_collision.stl" />        
      </geometry>      
    </collision>    
    <inertial>      
      <origin xyz="0.0016330560292397253586 0.050045526484800359479 -0.0099079425237751303501" rpy="0 0 0" />      
      <mass value="0.086799999986183568046" />      
      <inertia ixx="4.9519076588877538128e-05" ixy="-3.6911123877149621398e-06" ixz="4.1819052274329280094e-07" iyy="1.5531229308366383744e-05" iyz="-4.6072292079373447431e-07" izz="5.3148278062060573122e-05" />      
    </inertial>    
  </link>  

  <link name="bearing_683_3">    
    <visual>      
      <origin xyz="0 0 0" rpy="0 -0 0" />      
      <geometry>        
        <mesh filename="../assemblies/right_leg_XM430/meshes/right_bearing_683_visual.stl" />        
      </geometry>      
      <material name="bearing_683_material">        
        <color rgba="0.64705882352941179736 0.64705882352941179736 0.64705882352941179736 1.0" />        
      </material>      
    </visual>    
    <inertial>      
      <origin xyz="1.0732094295240964766e-19 2.4186774283163086217e-19 -0.0015499999999999977771" rpy="0 0 0" />      
      <mass value="0.00048694686130641793437" />      
      <inertia ixx="2.1551456503319879113e-09" ixy="-3.3628103926129874696e-28" ixz="7.6066353359661959036e-38" iyy="2.1551456503319883249e-09" iyz="4.8251731695129717068e-38" izz="3.5303647444715322361e-09" />      
    </inertial>    
  </link>  

  <joint name="right_knee_front_rev_2" type="revolute">    
    <origin xyz="-0.0057402514854763405858 -0.013858192987669298857 -0.02619999999999997678" rpy="-6.2776058347430638833e-15 -3.649417008249174908e-17 3.1358007158038927464" />    
    <parent link="right_calf_link" />    
    <child link="bearing_683_3" />    
    <axis xyz="0 0 1" />    
    <limit effort="1" velocity="20" lower="-6.283185307179586232" upper="6.283185307179586232" />    
    <joint_properties friction="0.0" />    
  </joint>  

  <link name="bearing_683_4">    
    <visual>      
      <origin xyz="0 0 0" rpy="0 -0 0" />      
      <geometry>        
        <mesh filename="../assemblies/right_leg_XM430/meshes/right_bearing_683_2_visual.stl" />        
      </geometry>      
      <material name="bearing_683_2_material">        
        <color rgba="0.64705882352941179736 0.64705882352941179736 0.64705882352941179736 1.0" />        
      </material>      
    </visual>    
    <inertial>      
      <origin xyz="1.0732094295242468195e-19 2.7997443358460577788e-17 -0.0015499999999999977771" rpy="0 0 0" />      
      <mass value="0.00048694686130641793437" />      
      <inertia ixx="2.1551456503319879113e-09" ixy="-2.4982999913736959872e-27" ixz="1.1943003538897581327e-37" iyy="2.1551456503319883249e-09" iyz="8.2447751888914575401e-38" izz="3.5303647444715322361e-09" />      
    </inertial>    
  </link>  

  <joint name="right_knee_back_rev_2" type="revolute">    
    <origin xyz="0.0057402514854764047705 0.013858192987669326612 -0.026199999999999966371" rpy="-6.6378328094146457949e-15 -3.5392027487744668907e-17 3.1357969761588506685" />    
    <parent link="right_calf_link" />    
    <child link="bearing_683_4" />    
    <axis xyz="0 0 1" />    
    <limit effort="1" velocity="20" lower="-6.283185307179586232" upper="6.283185307179586232" />    
    <joint_properties friction="0.0" />    
  </joint>  

  <link name="ank_pitch_link_2">    
    <visual>      
      <origin xyz="0 0 0" rpy="0 -0 0" />      
      <geometry>        
        <mesh filename="../assemblies/right_leg_XM430/meshes/right_ank_pitch_link_visual.stl" />        
      </geometry>      
      <material name="ank_pitch_link_material">        
        <color rgba="0.63189161126160264814 0.7266866879354088038 0.78356373393969258601 1.0" />        
      </material>      
    </visual>    
    <inertial>      
      <origin xyz="0.00059528282565905657042 -4.026968257827852565e-08 7.7616094189678438892e-08" rpy="0 0 0" />      
      <mass value="0.0042238381753791614387" />      
      <inertia ixx="3.9782741364675321991e-07" ixy="-1.6834347643884432913e-13" ixz="2.0919192028159930918e-14" iyy="4.3705254067418641311e-07" iyz="-1.6428822141780859485e-12" izz="8.8858574534600124764e-08" />      
    </inertial>    
  </link>  

  <link name="ank_roll_link_2">    
    <visual>      
      <origin xyz="0 0 0" rpy="0 -0 0" />      
      <geometry>        
        <mesh filename="../assemblies/right_leg_XM430/meshes/right_ank_roll_link_visual.stl" />        
      </geometry>      
      <material name="ank_roll_link_material">        
        <color rgba="0.61568627450980395466 0.81176470588235294379 0.92941176470588227065 1.0" />        
      </material>      
    </visual>    
    <inertial>      
      <origin xyz="-3.3748977754987916802e-09 0.016071733707723686452 -0.0096236810250137777567" rpy="0 0 0" />      
      <mass value="0.010900000000000003436" />      
      <inertia ixx="2.6058536057764963368e-06" ixy="-5.4054321087398513321e-13" ixz="6.069254909621619699e-13" iyy="2.5928781338360468952e-06" iyz="3.9359839679282456802e-07" izz="1.6179884211196010928e-06" />      
    </inertial>    
  </link>  

  <link name="ank_rr_link_3">    
    <visual>      
      <origin xyz="0 0 0" rpy="0 -0 0" />      
      <geometry>        
        <mesh filename="../assemblies/right_leg_XM430/meshes/right_ank_rr_link_visual.stl" />        
      </geometry>      
      <material name="ank_rr_link_material">        
        <color rgba="0.61568627450980395466 0.81176470588235294379 0.92941176470588238168 1.0" />        
      </material>      
    </visual>    
    <inertial>      
      <origin xyz="-4.5249610960606040573e-05 -0.0063096429836315137685 2.0541493629114029303e-19" rpy="0 0 0" />      
      <mass value="0.0014499999999999996832" />      
      <inertia ixx="2.9739579267716143416e-08" ixy="-2.4213146797977953366e-10" ixz="-3.5523394884456569378e-14" iyy="2.7430027724071957055e-08" iyz="9.0746301005749663886e-32" izz="4.2921949116163665819e-08" />      
    </inertial>    
  </link>  

  <link name="ank_motor_rod_long_2">    
    <visual>      
      <origin xyz="0 0 0" rpy="0 -0 0" />      
      <geometry>        
        <mesh filename="../assemblies/right_leg_XM430/meshes/right_ank_motor_rod_long_visual.stl" />        
      </geometry>      
      <material name="ank_motor_rod_long_material">        
        <color rgba="0.63549975559783222767 0.7077439301702044272 0.75109043491362770251 1.0" />        
      </material>      
    </visual>    
    <inertial>      
      <origin xyz="2.4855088520493177138e-10 0.034559019974062285541 0.0009385170487845899065" rpy="0 0 0" />      
      <mass value="0.0021712857268636710437" />      
      <inertia ixx="8.5350290058000464345e-07" ixy="1.4884244180834259739e-14" ixz="4.5749525025600497579e-11" iyy="1.3237321792739588955e-08" iyz="-4.3668910960878901781e-09" izz="8.5812217519451811101e-07" />      
    </inertial>    
  </link>  

  <joint name="right_ank_long_rev_2" type="revolute">    
    <origin xyz="-3.4694469519536141888e-18 -0.010000000000000008882 0" rpy="-1.570796326794896558 -1.3320366994106180858 -1.5707963267948950037" />    
    <parent link="ank_rr_link_3" />    
    <child link="ank_motor_rod_long_2" />    
    <axis xyz="0 0 1" />    
    <limit effort="1" velocity="20" lower="-1.570796326794896558" upper="1.570796326794896558" />    
    <joint_properties friction="0.0" />    
  </joint>  

  <joint name="right_ank_long_rev_1" type="revolute">    
    <origin xyz="0.017999999999999995171 0.015999999999999986455 -0.020600000000000007194" rpy="-2.0731393629286849282e-16 7.494126450902431242e-16 0.018223085043010137096" />    
    <parent link="ank_roll_link_2" />    
    <child link="ank_rr_link_3" />    
    <axis xyz="0 0 1" />    
    <limit effort="1" velocity="20" lower="-1.570796326794896558" upper="1.570796326794896558" />    
    <joint_properties friction="0.0" />    
  </joint>  

  <link name="ank_rr_link_4">    
    <visual>      
      <origin xyz="0 0 0" rpy="0 -0 0" />      
      <geometry>        
        <mesh filename="../assemblies/right_leg_XM430/meshes/right_ank_rr_link_2_visual.stl" />        
      </geometry>      
      <material name="ank_rr_link_2_material">        
        <color rgba="0.61568627450980395466 0.81176470588235294379 0.92941176470588238168 1.0" />        
      </material>      
    </visual>    
    <inertial>      
      <origin xyz="-4.5249610960602571126e-05 0.0063096429836314027462 -2.0541493629100097608e-19" rpy="0 0 0" />      
      <mass value="0.0014499999999999996832" />      
      <inertia ixx="2.9739579267716143416e-08" ixy="2.4213146797977953366e-10" ixz="3.5523394884456569378e-14" iyy="2.7430027724071957055e-08" iyz="8.3643788813932377547e-32" izz="4.2921949116163665819e-08" />      
    </inertial>    
  </link>  

  <link name="ank_motor_rod_short_2">    
    <visual>      
      <origin xyz="0 0 0" rpy="0 -0 0" />      
      <geometry>        
        <mesh filename="../assemblies/right_leg_XM430/meshes/right_ank_motor_rod_short_visual.stl" />        
      </geometry>      
      <material name="ank_motor_rod_short_material">        
        <color rgba="0.41222606689734719865 0.58339100346020766885 0.8110726643598615837 1.0" />        
      </material>      
    </visual>    
    <inertial>      
      <origin xyz="2.6038940490746279194e-10 0.023830465465870923764 0.0009040350635962171328" rpy="0 0 0" />      
      <mass value="0.001700000000000000339" />      
      <inertia ixx="3.3153416252670103599e-07" ixy="8.741976963456311881e-15" ixz="4.5749941567748262401e-11" iyy="1.0947363610305739478e-08" iyz="-3.5863098646405146614e-09" izz="3.3621340447865252573e-07" />      
    </inertial>    
  </link>  

  <joint name="right_ank_short_rev_2" type="revolute">    
    <origin xyz="-6.9388939039072283776e-18 0.010000000000000008882 6.9388939039072283776e-18" rpy="-1.5707963267948854558 1.2119133862908557653 -1.5707963267949027752" />    
    <parent link="ank_rr_link_4" />    
    <child link="ank_motor_rod_short_2" />    
    <axis xyz="0 0 1" />    
    <limit effort="1" velocity="20" lower="-1.570796326794896558" upper="1.570796326794896558" />    
    <joint_properties friction="0.0" />    
  </joint>  

  <joint name="right_ank_short_rev_1" type="revolute">    
    <origin xyz="-0.018000000000000009048 0.015999999999999986455 -0.020599999999999996786" rpy="1.2085562754084012184e-16 -4.4422865000044981723e-16 3.115474105082512768" />    
    <parent link="ank_roll_link_2" />    
    <child link="ank_rr_link_4" />    
    <axis xyz="0 0 1" />    
    <limit effort="1" velocity="20" lower="-1.570796326794896558" upper="1.570796326794896558" />    
    <joint_properties friction="0.0" />    
  </joint>  

  <link name="right_sole_link">    
    <visual>      
      <origin xyz="0 0 0" rpy="0 -0 0" />      
      <geometry>        
        <mesh filename="../assemblies/right_leg_XM430/meshes/right_sole_link_visual.stl" />        
      </geometry>      
      <material name="right_sole_link_material">        
        <color rgba="0.61568627450980395466 0.81176470588235305481 0.92941176470588238168 1.0" />        
      </material>      
    </visual>    
    <collision>      
      <origin xyz="0 0 0" rpy="0 -0 0" />      
      <geometry>        
        <mesh filename="../assemblies/right_leg_XM430/meshes/right_sole_link_collision.stl" />        
      </geometry>      
    </collision>    
    <inertial>      
      <origin xyz="-0.028269220649489175401 -7.4209810882689804793e-08 -0.010206288127739998259" rpy="0 0 0" />      
      <mass value="0.013900000000000007835" />      
      <inertia ixx="1.3160690708871243068e-06" ixy="-1.0226444191974891076e-10" ixz="-2.3744136049829838944e-07" iyy="1.3575381226152454021e-05" iyz="-7.1602330638764630989e-13" izz="1.4673427099197175005e-05" />      
    </inertial>    
  </link>  

  <joint name="right_sole" type="fixed">    
    <origin xyz="-9.2157184661267876891e-18 0.024999999999999938938 -0.022599999999999998562" rpy="1.5707963267949021091 1.5707963267948905628 0" />    
    <parent link="ank_roll_link_2" />    
    <child link="right_sole_link" />    
    <axis xyz="0 0 1" />    
    <limit effort="1" velocity="20" />    
    <joint_properties friction="0.0" />    
  </joint>  

  <joint name="right_ank_roll" type="revolute">    
    <origin xyz="0.0015000000000000004649 0 -9.7578195523695399061e-19" rpy="-3.141592653589793116 -1.5707963267948956698 0" />    
    <parent link="ank_pitch_link_2" />    
    <child link="ank_roll_link_2" />    
    <axis xyz="0 0 1" />    
    <limit effort="1" velocity="20" lower="-0.785398163397448279" upper="0.785398163397448279" />    
    <joint_properties friction="0.0" />    
  </joint>  

  <joint name="right_ank_pitch" type="revolute">    
    <origin xyz="4.3837881646777831769e-17 0.10000000000000000555 -0.010399999999999944011" rpy="2.2204460560390508438e-16 3.5527136779803609004e-15 3.1415926535897873428" />    
    <parent link="right_calf_link" />    
    <child link="ank_pitch_link_2" />    
    <axis xyz="0 0 1" />    
    <limit effort="1" velocity="20" lower="-0.785398163397448279" upper="0.95993108859688125456" />    
    <joint_properties friction="0.0" />    
  </joint>  

  <link name="ank_motor_arm_3">    
    <visual>      
      <origin xyz="0 0 0" rpy="0 -0 0" />      
      <geometry>        
        <mesh filename="../assemblies/right_leg_XM430/meshes/right_ank_motor_arm_visual.stl" />        
      </geometry>      
      <material name="ank_motor_arm_material">        
        <color rgba="0.62517751827980905244 0.70593642422614044651 0.75978993426662766453 1.0" />        
      </material>      
    </visual>    
    <inertial>      
      <origin xyz="0.014511489101591695805 -2.8371214923197373628e-17 0.0040925443765950624692" rpy="0 0 0" />      
      <mass value="0.0020595846677894939954" />      
      <inertia ixx="2.75918367565218459e-08" ixy="-1.6758595368887842784e-23" ixz="-3.0270788206594894824e-08" iyy="1.6138599216238459113e-07" iyz="-3.3435412526956429362e-23" izz="1.6437836765016314004e-07" />      
    </inertial>    
  </link>  

  <joint name="right_ank_act_1" type="revolute">    
    <origin xyz="0.01349999999999646795 0.044500000000006922907 0.0040000000000042796461" rpy="-3.078520668360990726e-13 -4.5496150843455205025e-14 0.21173394130153330717" />    
    <parent link="right_calf_link" />    
    <child link="ank_motor_arm_3" />    
    <axis xyz="0 0 1" />    
    <limit effort="1" velocity="20" lower="-1.3089969389957472057" upper="1.3089969389957472057" />    
    <joint_properties friction="0.0" />    
  </joint>  

  <link name="ank_motor_arm_4">    
    <visual>      
      <origin xyz="0 0 0" rpy="0 -0 0" />      
      <geometry>        
        <mesh filename="../assemblies/right_leg_XM430/meshes/right_ank_motor_arm_2_visual.stl" />        
      </geometry>      
      <material name="ank_motor_arm_2_material">        
        <color rgba="0.62517751827980905244 0.70593642422614044651 0.75978993426662766453 1.0" />        
      </material>      
    </visual>    
    <inertial>      
      <origin xyz="0.014511489101591685397 5.5448015589825106898e-19 0.0040925443765950642039" rpy="0 0 0" />      
      <mass value="0.0020595846677894939954" />      
      <inertia ixx="2.7591836756521965014e-08" ixy="-2.786136438945596108e-23" ixz="-3.027078820659482865e-08" iyy="1.6138599216238437937e-07" iyz="-3.6560728613848348131e-24" izz="1.6437836765016284887e-07" />      
    </inertial>    
  </link>  

  <joint name="right_ank_act_2" type="revolute">    
    <origin xyz="0.013500000000004360942 0.064500000000008050893 -0.024800000000002021816" rpy="-3.1415926535895257743 -2.0958441553975745862e-13 0.22995607267268677876" />    
    <parent link="right_calf_link" />    
    <child link="ank_motor_arm_4" />    
    <axis xyz="0 0 1" />    
    <limit effort="1" velocity="20" lower="-1.3089969389957472057" upper="1.3089969389957472057" />    
    <joint_properties friction="0.0" />    
  </joint>  

  <joint name="right_knee_pitch" type="revolute">    
    <origin xyz="1.1564389868401171602e-17 -0.096000000000000029754 -0.0092000000000000067835" rpy="-6.0024085179096384259e-15 1.3010426071629226535e-16 3.1415926535897913396" />    
    <parent link="right_hip_pitch_link_xm430" />    
    <child link="right_calf_link" />    
    <axis xyz="0 0 1" />    
    <limit effort="1" velocity="20" lower="-1.9198621771937625091" upper="0" />    
    <joint_properties friction="0.0" />    
  </joint>  

  <link name="xm430_plate_2">    
    <visual>      
      <origin xyz="0 0 0" rpy="0 -0 0" />      
      <geometry>        
        <mesh filename="../assemblies/right_leg_XM430/meshes/right_xm430_plate_visual.stl" />        
      </geometry>      
      <material name="xm430_plate_material">        
        <color rgba="0.61568627450980395466 0.81176470588235294379 0.9294117647058824927 1.0" />        
      </material>      
    </visual>    
    <inertial>      
      <origin xyz="3.9034269558608525572e-19 4.0403155142548792296e-18 -0.0024039046431217989813" rpy="0 0 0" />      
      <mass value="0.0026999999999999992756" />      
      <inertia ixx="2.6720434385876693618e-07" ixy="-6.8936588702566374239e-08" ixz="5.2034483092649082032e-36" iyy="1.2933116645363405536e-07" iyz="1.1219688235926719214e-35" izz="3.8533537562751439267e-07" />      
    </inertial>    
  </link>  

  <link name="knee_rod_3">    
    <visual>      
      <origin xyz="0 0 0" rpy="0 -0 0" />      
      <geometry>        
        <mesh filename="../assemblies/right_leg_XM430/meshes/right_knee_rod_visual.stl" />        
      </geometry>      
      <material name="knee_rod_material">        
        <color rgba="0.62051618944235198416 0.78640765248647581664 0.88594253031295022716 1.0" />        
      </material>      
    </visual>    
    <inertial>      
      <origin xyz="0.014594546907469960195 4.2152786375369788398e-05 -0.0015996227373185887589" rpy="0 0 0" />      
      <mass value="0.0031629468613064179276" />      
      <inertia ixx="2.5896145569812783873e-08" ixy="-3.5408233594415055965e-10" ixz="4.1682973432396374719e-10" iyy="6.0153250390525877384e-07" iyz="1.2039109459404085995e-12" izz="6.2266858519717461123e-07" />      
    </inertial>    
  </link>  

  <joint name="right_knee_front_rev_1" type="revolute">    
    <origin xyz="-0.0057402514854763475247 -0.013858192987669298857 -0.0050000000000000009714" rpy="-7.6843565403024876539e-16 -7.2468500696722411095e-16 1.5650043890089964105" />    
    <parent link="xm430_plate_2" />    
    <child link="knee_rod_3" />    
    <axis xyz="0 0 1" />    
    <limit effort="1" velocity="20" lower="-6.283185307179586232" upper="6.283185307179586232" />    
    <joint_properties friction="0.0" />    
  </joint>  

  <link name="knee_rod_4">    
    <visual>      
      <origin xyz="0 0 0" rpy="0 -0 0" />      
      <geometry>        
        <mesh filename="../assemblies/right_leg_XM430/meshes/right_knee_rod_2_visual.stl" />        
      </geometry>      
      <material name="knee_rod_2_material">        
        <color rgba="0.62051618944235198416 0.78640765248647581664 0.88594253031295022716 1.0" />        
      </material>      
    </visual>    
    <inertial>      
      <origin xyz="0.014594546749629417476 4.2261942307114621806e-05 -0.0015996227373187431493" rpy="0 0 0" />      
      <mass value="0.0031629468613064179276" />      
      <inertia ixx="2.5896150873195108889e-08" ixy="-3.5499923916223384349e-10" ixz="4.1682972981661921117e-10" iyy="6.0153250125354727592e-07" iyz="1.2070285090916656039e-12" izz="6.2266858784884725151e-07" />      
    </inertial>    
  </link>  

  <joint name="right_knee_back_rev_1" type="revolute">    
    <origin xyz="0.0057402514854763509941 0.013858192987669284979 -0.0050000000000000009714" rpy="1.4780745018405688374e-15 -6.0371120429764004227e-16 1.5650006493639538885" />    
    <parent link="xm430_plate_2" />    
    <child link="knee_rod_4" />    
    <axis xyz="0 0 1" />    
    <limit effort="1" velocity="20" lower="-6.283185307179586232" upper="6.283185307179586232" />    
    <joint_properties friction="0.0" />    
  </joint>  

  <joint name="right_knee_act" type="revolute">    
    <origin xyz="0.00014999999999998383225 -0.061500000000000006051 -0.030400000000000024225" rpy="-3.3306690735930707292e-16 -2.9976021666231129079e-15 3.1415926535897913396" />    
    <parent link="right_hip_pitch_link_xm430" />    
    <child link="xm430_plate_2" />    
    <axis xyz="0 0 1" />    
    <limit effort="1" velocity="20" lower="-1.9198621771937625091" upper="0" />    
    <joint_properties friction="0.0" />    
  </joint>  

  <joint name="right_hip_pitch" type="revolute">    
    <origin xyz="-0.024000000716143048141 -0.019000000152443574652 -0.019000000152453545843" rpy="1.5707963267951119413 1.5707963267947440134 0" />    
    <parent link="hip_roll_link_2" />    
    <child link="right_hip_pitch_link_xm430" />    
    <axis xyz="0 0 1" />    
    <limit effort="1" velocity="20" lower="-1.570796326794896558" upper="1.570796326794896558" />    
    <joint_properties friction="0.0" />    
  </joint>  

  <joint name="right_hip_roll" type="revolute">    
    <origin xyz="-0.019000000000000096673 2.0909656639487276466e-16 -0.025999999999999905131" rpy="-2.4415165121040963179e-28 -1.5707963267948938935 0" />    
    <parent link="hip_yaw_link_2" />    
    <child link="hip_roll_link_2" />    
    <axis xyz="0 0 1" />    
    <limit effort="1" velocity="20" lower="-0.785398163397448279" upper="1.570796326794896558" />    
    <joint_properties friction="0.0" />    
  </joint>  


<link name="sho_pitch_link">    
    <visual>      
      <origin xyz="0 0 0" rpy="0 -0 0" />      
      <geometry>        
        <mesh filename="../assemblies/left_arm_hand/meshes/left_sho_pitch_link_visual.stl" />        
      </geometry>      
      <material name="sho_pitch_link_material">        
        <color rgba="0.61568627450980395466 0.81176470588235294379 0.9294117647058824927 1.0" />        
      </material>      
    </visual>    
    <inertial>      
      <origin xyz="5.8254248476640018068e-11 -5.1264642561121738235e-05 0.0082440788127094901533" rpy="0 0 0" />      
      <mass value="0.0085999999999999930667" />      
      <inertia ixx="1.2272887040545789755e-06" ixy="-2.1429944205637421431e-14" ixz="-8.5847198694572451764e-15" iyy="2.9107306060364607382e-06" iyz="7.4623841398183265989e-09" izz="3.0803135950773479222e-06" />      
    </inertial>    
  </link>  

  <link name="2xl430_gears">    
    <visual>      
      <origin xyz="0 0 0" rpy="0 -0 0" />      
      <geometry>        
        <mesh filename="../assemblies/left_arm_hand/meshes/left_2xl430_gears_visual.stl" />        
      </geometry>      
      <material name="2xl430_gears_material">        
        <color rgba="0.7560598568794409946 0.85804695962693022793 0.91320266199377464478 1.0" />        
      </material>      
    </visual>    
    <collision>      
      <origin xyz="0 0 0" rpy="0 -0 0" />      
      <geometry>        
        <mesh filename="collisions/left_2xl430_gears_collision.stl" />        
      </geometry>      
    </collision>    
    <inertial>      
      <origin xyz="-0.011579403981036557811 -0.00242257661414001799 -0.018551095523803538823" rpy="0 0 0" />      
      <mass value="0.1180000367452490595" />      
      <inertia ixx="2.7482298083236081848e-05" ixy="9.2729623432982064947e-07" ixz="-2.2634512003761326374e-08" iyy="3.2770742486672784378e-05" iyz="-6.5708346020130337141e-07" izz="3.5767957544054292845e-05" />      
    </inertial>    
  </link>  

  <link name="spur_1m_24t_drive">    
    <visual>      
      <origin xyz="0 0 0" rpy="0 -0 0" />      
      <geometry>        
        <mesh filename="../assemblies/left_arm_hand/meshes/left_spur_1m_24t_drive_visual.stl" />        
      </geometry>      
      <material name="spur_1m_24t_drive_material">        
        <color rgba="0.61568627450980406568 0.81176470588235294379 0.92941176470588238168 1.0" />        
      </material>      
    </visual>    
    <inertial>      
      <origin xyz="-7.7449938932320867273e-15 -1.2129782962544905429e-16 0.0047949116178401416863" rpy="0 0 0" />      
      <mass value="0.0032000000000000001533" />      
      <inertia ixx="1.4019331346159890349e-07" ixy="1.6002409988426406335e-15" ixz="-2.7590023788381681633e-36" iyy="1.4019331260388786185e-07" iyz="1.44478866539024023e-37" izz="2.3838919844264060647e-07" />      
    </inertial>    
  </link>  

  <joint name="left_sho_yaw_drive" type="revolute">    
    <origin xyz="-0.024000000716141271784 -0.019000000152448497798 -0.019000000152447297369" rpy="1.570796326794886788 -1.6649913824689159326e-15 2.951073631457867516e-14" />    
    <parent link="2xl430_gears" />    
    <child link="spur_1m_24t_drive" />    
    <axis xyz="0 0 1" />    
    <limit effort="1" velocity="20" lower="-1.570796326794896558" upper="1.570796326794896558" />    
    <joint_properties friction="0.0" />    
  </joint>  

  <link name="spur_1m_24t_driven">    
    <visual>      
      <origin xyz="0 0 0" rpy="0 -0 0" />      
      <geometry>        
        <mesh filename="../assemblies/left_arm_hand/meshes/left_spur_1m_24t_driven_visual.stl" />        
      </geometry>      
      <material name="spur_1m_24t_driven_material">        
        <color rgba="0.23137254901960788156 0.38039215686274502337 0.7058823529411765163 1.0" />        
      </material>      
    </visual>    
    <inertial>      
      <origin xyz="2.5336458747541433782e-18 -5.7987576959439556938e-15 -0.00096866348640038332785" rpy="0 0 0" />      
      <mass value="0.0026999999999999997093" />      
      <inertia ixx="1.2026541119643504741e-07" ixy="-4.4954231945806923146e-48" ixz="1.2986909681771952643e-36" iyy="1.2026541119643483565e-07" iyz="1.1676358468802655893e-37" izz="2.2827257365099366486e-07" />      
    </inertial>    
  </link>  

  <link name="sho_yaw_link">    
    <visual>      
      <origin xyz="0 0 0" rpy="0 -0 0" />      
      <geometry>        
        <mesh filename="../assemblies/left_arm_hand/meshes/left_sho_yaw_link_visual.stl" />        
      </geometry>      
      <material name="sho_yaw_link_material">        
        <color rgba="0.61568627450980395466 0.81176470588235294379 0.92941176470588238168 1.0" />        
      </material>      
    </visual>    
    <inertial>      
      <origin xyz="-1.3040543109243650501e-18 3.7205074538886824605e-18 -0.024214576156328410095" rpy="0 0 0" />      
      <mass value="0.014500000000000007674" />      
      <inertia ixx="9.0490855102914992479e-06" ixy="3.5997729401434988918e-13" ixz="-1.9687833522128379057e-35" iyy="5.6767199180624744435e-06" iyz="2.0673322214327146524e-36" izz="4.4590603637468133921e-06" />      
    </inertial>    
  </link>  

  <link name="2xl430_gears_2">    
    <visual>      
      <origin xyz="0 0 0" rpy="0 -0 0" />      
      <geometry>        
        <mesh filename="../assemblies/left_arm_hand/meshes/left_2xl430_gears_2_visual.stl" />        
      </geometry>      
      <material name="2xl430_gears_2_material">        
        <color rgba="0.7560598568794409946 0.85804695962693022793 0.91320266199377464478 1.0" />        
      </material>      
    </visual>    
    <collision>      
      <origin xyz="0 0 0" rpy="0 -0 0" />      
      <geometry>        
        <mesh filename="collisions/left_2xl430_gears_2_collision.stl" />        
      </geometry>      
    </collision>    
    <inertial>      
      <origin xyz="-0.011579403981034347773 -0.0024225766141400461792 -0.018551095523803212695" rpy="0 0 0" />      
      <mass value="0.1180000367452490595" />      
      <inertia ixx="2.7482298083235241591e-05" ixy="9.2729623433064015385e-07" ixz="-2.2634512003851505604e-08" iyy="3.2770742486672987666e-05" iyz="-6.5708346020124767899e-07" izz="3.5767957544053737191e-05" />      
    </inertial>    
  </link>  

  <link name="spur_1m_24t_drive_2">    
    <visual>      
      <origin xyz="0 0 0" rpy="0 -0 0" />      
      <geometry>        
        <mesh filename="../assemblies/left_arm_hand/meshes/left_spur_1m_24t_drive_2_visual.stl" />        
      </geometry>      
      <material name="spur_1m_24t_drive_2_material">        
        <color rgba="0.61568627450980406568 0.81176470588235294379 0.92941176470588238168 1.0" />        
      </material>      
    </visual>    
    <inertial>      
      <origin xyz="-7.7449938932320867273e-15 -1.2129782962544925151e-16 0.0047949116178401382168" rpy="0 0 0" />      
      <mass value="0.0032000000000000001533" />      
      <inertia ixx="1.4019331346159892996e-07" ixy="1.6002410041546426147e-15" ixz="3.0907108770750589246e-37" iyy="1.4019331260388791479e-07" iyz="-9.9147138716248503567e-38" izz="2.3838919844264060647e-07" />      
    </inertial>    
  </link>  

  <joint name="left_elbow_yaw_drive" type="revolute">    
    <origin xyz="-0.024000000716138836232 -0.019000000152446974711 -0.01900000015244691226" rpy="1.5707963267948983344 5.4262918776078815822e-15 5.0024824484551637689e-15" />    
    <parent link="2xl430_gears_2" />    
    <child link="spur_1m_24t_drive_2" />    
    <axis xyz="0 0 1" />    
    <limit effort="1" velocity="20" lower="-1.570796326794896558" upper="1.570796326794896558" />    
    <joint_properties friction="0.0" />    
  </joint>  

  <link name="spur_1m_24t_driven_2">    
    <visual>      
      <origin xyz="0 0 0" rpy="0 -0 0" />      
      <geometry>        
        <mesh filename="../assemblies/left_arm_hand/meshes/left_spur_1m_24t_driven_2_visual.stl" />        
      </geometry>      
      <material name="spur_1m_24t_driven_2_material">        
        <color rgba="0.23137254901960788156 0.38039215686274502337 0.7058823529411765163 1.0" />        
      </material>      
    </visual>    
    <inertial>      
      <origin xyz="2.5336458747546475867e-18 -5.7989934404527921162e-15 -0.00096866348640037638895" rpy="0 0 0" />      
      <mass value="0.0026999999999999997093" />      
      <inertia ixx="1.2026541119643504741e-07" ixy="0" ixz="-2.3174394451652826373e-37" iyy="1.2026541119643483565e-07" iyz="0" izz="2.2827257365099366486e-07" />      
    </inertial>    
  </link>  

  <link name="elb_yaw_link">    
    <visual>      
      <origin xyz="0 0 0" rpy="0 -0 0" />      
      <geometry>        
        <mesh filename="../assemblies/left_arm_hand/meshes/left_elb_yaw_link_visual.stl" />        
      </geometry>      
      <material name="elb_yaw_link_material">        
        <color rgba="0.61568627450980395466 0.81176470588235294379 0.92941176470588227065 1.0" />        
      </material>      
    </visual>    
    <inertial>      
      <origin xyz="5.2870889173026998625e-08 0.0019873558182742449146 -0.023365661199828736266" rpy="0 0 0" />      
      <mass value="0.017500000000000001665" />      
      <inertia ixx="1.4097804991252561445e-05" ixy="1.6900809684031188595e-12" ixz="-1.1184673662111207274e-11" iyy="6.6367696417680310494e-06" iyz="1.0579908722588335747e-06" izz="8.9601142768980680532e-06" />      
    </inertial>    
  </link>  

  <link name="spur_1m_24t_driven_3">    
    <visual>      
      <origin xyz="0 0 0" rpy="0 -0 0" />      
      <geometry>        
        <mesh filename="../assemblies/left_arm_hand/meshes/left_spur_1m_24t_driven_3_visual.stl" />        
      </geometry>      
      <material name="spur_1m_24t_driven_3_material">        
        <color rgba="0.23137254901960788156 0.38039215686274502337 0.7058823529411765163 1.0" />        
      </material>      
    </visual>    
    <inertial>      
      <origin xyz="-2.522192974087503514e-17 -5.795523993500838502e-15 -0.0025686634864003771161" rpy="0 0 0" />      
      <mass value="0.0026999999999999997093" />      
      <inertia ixx="1.2026541119643504741e-07" ixy="0" ixz="1.8719165699834955332e-37" iyy="1.2026541119643483565e-07" iyz="0" izz="2.2827257365099366486e-07" />      
    </inertial>    
  </link>  

  <link name="2xl430_gears_3">    
    <visual>      
      <origin xyz="0 0 0" rpy="0 -0 0" />      
      <geometry>        
        <mesh filename="../assemblies/left_arm_hand/meshes/left_2xl430_gears_3_visual.stl" />        
      </geometry>      
      <material name="2xl430_gears_3_material">        
        <color rgba="0.7560598568794409946 0.85804695962693022793 0.91320266199377464478 1.0" />        
      </material>      
    </visual>    
    <collision>      
      <origin xyz="0 0 0" rpy="0 -0 0" />      
      <geometry>        
        <mesh filename="collisions/left_2xl430_gears_3_collision.stl" />        
      </geometry>      
    </collision>    
    <inertial>      
      <origin xyz="0.00044890447620181688111 0.011579403622954375849 -0.02457742353831019258" rpy="0 0 0" />      
      <mass value="0.1180000367452490595" />      
      <inertia ixx="3.5767957544054143767e-05" ixy="2.2634512003808356555e-08" ixz="6.5708346020219709704e-07" iyy="2.7482298083236979703e-05" iyz="9.2729623433153303245e-07" izz="3.2770742486671795043e-05" />      
    </inertial>    
  </link>  

  <link name="spur_1m_24t_drive_3">    
    <visual>      
      <origin xyz="0 0 0" rpy="0 -0 0" />      
      <geometry>        
        <mesh filename="../assemblies/left_arm_hand/meshes/left_spur_1m_24t_drive_3_visual.stl" />        
      </geometry>      
      <material name="spur_1m_24t_drive_3_material">        
        <color rgba="0.61568627450980406568 0.81176470588235294379 0.92941176470588238168 1.0" />        
      </material>      
    </visual>    
    <inertial>      
      <origin xyz="-7.7796883627516228692e-15 -1.180803229146237919e-16 0.0047949116178401460231" rpy="0 0 0" />      
      <mass value="0.0032000000000000001533" />      
      <inertia ixx="1.4019331346159890349e-07" ixy="1.6002409988426406335e-15" ixz="7.8896159369094263749e-37" iyy="1.4019331260388786185e-07" iyz="-7.1504782971518037505e-37" izz="2.3838919844264060647e-07" />      
    </inertial>    
  </link>  

  <joint name="left_wrist_pitch_drive" type="revolute">    
    <origin xyz="-1.5244092446686785536e-10 0.024000000358059436767 -0.0080000000000068592632" rpy="7.9382516163035126435e-16 -8.221371570986757145e-15 -1.5707963267949174302" />    
    <parent link="2xl430_gears_3" />    
    <child link="spur_1m_24t_drive_3" />    
    <axis xyz="0 0 1" />    
    <limit effort="1" velocity="20" lower="-1.570796326794896558" upper="1.570796326794896558" />    
    <joint_properties friction="0.0" />    
  </joint>  

  <link name="wrist_bearing_plate">    
    <visual>      
      <origin xyz="0 0 0" rpy="0 -0 0" />      
      <geometry>        
        <mesh filename="../assemblies/left_arm_hand/meshes/left_wrist_bearing_plate_visual.stl" />        
      </geometry>      
      <material name="wrist_bearing_plate_material">        
        <color rgba="0.64496316278892629192 0.69011804996940528945 0.71706771073555886087 1.0" />        
      </material>      
    </visual>    
    <inertial>      
      <origin xyz="-0.0075896393545961402319 -0.015499999999999972133 -0.0018386110045718368107" rpy="0 0 0" />      
      <mass value="0.0049000367468305548388" />      
      <inertia ixx="4.9747313520140099305e-07" ixy="1.1209637001029811002e-22" ixz="1.8097509420524786327e-08" iyy="7.1295025627582300844e-07" iyz="1.3782490438152935122e-23" izz="1.1926297952291895432e-06" />      
    </inertial>    
  </link>  

  <joint name="left_wrist_roll_fixed" type="fixed">    
    <origin xyz="0.01550000000000526304 -1.7097434579227410723e-14 -0.04500000000000015099" rpy="-4.0578651550049919625e-14 -2.8349544933803382357e-13 -1.5707963267949061059" />    
    <parent link="2xl430_gears_3" />    
    <child link="wrist_bearing_plate" />    
    <axis xyz="0 0 1" />    
    <limit effort="1" velocity="20" />    
    <joint_properties friction="0.0" />    
  </joint>  

  <link name="hand">    
    <visual>      
      <origin xyz="0 0 0" rpy="0 -0 0" />      
      <geometry>        
        <mesh filename="../assemblies/left_arm_hand/meshes/left_hand_visual.stl" />        
      </geometry>      
      <material name="hand_material">        
        <color rgba="0.61568627450980395466 0.81176470588235294379 0.92941176470588238168 1.0" />        
      </material>      
    </visual>    
    <collision>      
      <origin xyz="0 0 0" rpy="0 -0 0" />      
      <geometry>        
        <mesh filename="../assemblies/left_arm_hand/meshes/left_hand_collision.stl" />        
      </geometry>      
    </collision>    
    <inertial>      
      <origin xyz="-4.3038382212799598302e-08 -0.049723778585231907801 -0.017933572005390342741" rpy="0 0 0" />      
      <mass value="0.017000000000001441042" />      
      <inertia ixx="9.492141461772624154e-06" ixy="-1.5549215897336582142e-11" ixz="-1.0809694196517789905e-11" iyy="4.0745028295199771232e-06" iyz="2.4719408559837110004e-07" izz="6.6623859523002763733e-06" />      
    </inertial>    
  </link>  

  <joint name="left_wrist_roll" type="revolute">    
    <origin xyz="0.019000000000005953099 -3.5808089826616651408e-10 -0.027000000152448959401" rpy="3.3651291228740167001e-14 1.5707963267946079 0" />    
    <parent link="2xl430_gears_3" />    
    <child link="hand" />    
    <axis xyz="0 0 1" />    
    <limit effort="1" velocity="20" lower="-1.570796326794896558" upper="1.570796326794896558" />    
    <joint_properties friction="0.0" />    
  </joint>  

  <joint name="left_wrist_pitch_driven" type="revolute">    
    <origin xyz="0 0 -0.0015999999999999972577" rpy="2.6611337865898239456e-16 -4.9789962509675426656e-17 -1.57079632679489678" />    
    <parent link="spur_1m_24t_driven_3" />    
    <child link="2xl430_gears_3" />    
    <axis xyz="0 0 1" />    
    <limit effort="1" velocity="20" lower="-1.570796326794896558" upper="1.570796326794896558" />    
    <joint_properties friction="0.0" />    
  </joint>  

  <joint name="left_wrist_pitch_fixed" type="fixed">    
    <origin xyz="3.4694469519536141888e-18 -0.025300000000000003042 -0.05200000000000001843" rpy="1.570796326794896558 -1.570796326794896558 0" />    
    <parent link="elb_yaw_link" />    
    <child link="spur_1m_24t_driven_3" />    
    <axis xyz="0 0 1" />    
    <limit effort="1" velocity="20" />    
    <joint_properties friction="0.0" />    
  </joint>  

  <joint name="left_elbow_yaw_fixed" type="fixed">    
    <origin xyz="1.5777218104420236108e-30 0 0.0015999999999999903189" rpy="3.141592653589793116 -0 -1.570796326794896558" />    
    <parent link="spur_1m_24t_driven_2" />    
    <child link="elb_yaw_link" />    
    <axis xyz="0 0 1" />    
    <limit effort="1" velocity="20" />    
    <joint_properties friction="0.0" />    
  </joint>  

  <joint name="left_elbow_yaw_driven" type="revolute">    
    <origin xyz="-3.5806829723483701855e-10 -0.027000000152447967139 -0.019000000000002889577" rpy="1.5707963267948912289 1.5707963267948952257 0" />    
    <parent link="2xl430_gears_2" />    
    <child link="spur_1m_24t_driven_2" />    
    <axis xyz="0 0 1" />    
    <limit effort="1" velocity="20" lower="-1.570796326794896558" upper="1.570796326794896558" />    
    <joint_properties friction="0.0" />    
  </joint>  

  <joint name="left_elbow_roll" type="revolute">    
    <origin xyz="0 -0.019000000000000002998 -0.059000000000000010769" rpy="1.570796326794896558 7.8238344481275579773e-14 -2.6785925512137038591e-14" />    
    <parent link="sho_yaw_link" />    
    <child link="2xl430_gears_2" />    
    <axis xyz="0 0 1" />    
    <limit effort="1" velocity="20" lower="-1.570796326794896558" upper="1.570796326794896558" />    
    <joint_properties friction="0.0" />    
  </joint>  

  <joint name="left_sho_yaw_fixed" type="fixed">    
    <origin xyz="-6.9388939039072283776e-18 -3.9443045261050590271e-31 0.0015999999999999972577" rpy="-3.141592653589793116 -2.947294251859628371e-29 -3.8176863193325490556e-30" />    
    <parent link="spur_1m_24t_driven" />    
    <child link="sho_yaw_link" />    
    <axis xyz="0 0 1" />    
    <limit effort="1" velocity="20" />    
    <joint_properties friction="0.0" />    
  </joint>  

  <joint name="left_sho_yaw_driven" type="revolute">    
    <origin xyz="-3.5807099299511868651e-10 -0.027000000152450111257 -0.019000000000003024886" rpy="1.5707963267949034414 2.5500465800399188824e-14 -4.889500977014397436e-15" />    
    <parent link="2xl430_gears" />    
    <child link="spur_1m_24t_driven" />    
    <axis xyz="0 0 1" />    
    <limit effort="1" velocity="20" lower="-1.570796326794896558" upper="1.570796326794896558" />    
    <joint_properties friction="0.0" />    
  </joint>  

  <joint name="left_sho_roll" type="revolute">    
    <origin xyz="-0.018999999999999999528 0.0010000000000000076102 0.027000000000000003164" rpy="-3.141592653589793116 1.5707963267947588903 0" />    
    <parent link="sho_pitch_link" />    
    <child link="2xl430_gears" />    
    <axis xyz="0 0 1" />    
    <limit effort="1" velocity="20" lower="-1.570796326794896558" upper="1.570796326794896558" />    
    <joint_properties friction="0.0" />    
  </joint>  


<link name="sho_pitch_link_2">    
    <visual>      
      <origin xyz="0 0 0" rpy="0 -0 0" />      
      <geometry>        
        <mesh filename="../assemblies/right_arm_hand/meshes/right_sho_pitch_link_visual.stl" />        
      </geometry>      
      <material name="sho_pitch_link_material">        
        <color rgba="0.61568627450980395466 0.81176470588235294379 0.9294117647058824927 1.0" />        
      </material>      
    </visual>    
    <inertial>      
      <origin xyz="5.8254248476640018068e-11 -5.1264642561121738235e-05 0.0082440788127094901533" rpy="0 0 0" />      
      <mass value="0.0085999999999999930667" />      
      <inertia ixx="1.2272887040545789755e-06" ixy="-2.1429944205637421431e-14" ixz="-8.5847198694572451764e-15" iyy="2.9107306060364607382e-06" iyz="7.4623841398183265989e-09" izz="3.0803135950773479222e-06" />      
    </inertial>    
  </link>  

  <link name="2xl430_gears_4">    
    <visual>      
      <origin xyz="0 0 0" rpy="0 -0 0" />      
      <geometry>        
        <mesh filename="../assemblies/right_arm_hand/meshes/right_2xl430_gears_visual.stl" />        
      </geometry>      
      <material name="2xl430_gears_material">        
        <color rgba="0.7560598568794409946 0.85804695962693022793 0.91320266199377464478 1.0" />        
      </material>      
    </visual>    
    <collision>      
      <origin xyz="0 0 0" rpy="0 -0 0" />      
      <geometry>        
        <mesh filename="collisions/right_2xl430_gears_collision.stl" />        
      </geometry>      
    </collision>    
    <inertial>      
      <origin xyz="-0.011579403981034821353 -0.0024225766141402647544 -0.018551095523804388837" rpy="0 0 0" />      
      <mass value="0.1180000367452490595" />      
      <inertia ixx="2.7482298083236305464e-05" ixy="9.2729623432947548355e-07" ixz="-2.263451200412418073e-08" iyy="3.2770742486672947008e-05" iyz="-6.5708346020133862915e-07" izz="3.5767957544054530014e-05" />      
    </inertial>    
  </link>  

  <link name="spur_1m_24t_drive_4">    
    <visual>      
      <origin xyz="0 0 0" rpy="0 -0 0" />      
      <geometry>        
        <mesh filename="../assemblies/right_arm_hand/meshes/right_spur_1m_24t_drive_visual.stl" />        
      </geometry>      
      <material name="spur_1m_24t_drive_material">        
        <color rgba="0.61568627450980406568 0.81176470588235294379 0.92941176470588238168 1.0" />        
      </material>      
    </visual>    
    <inertial>      
      <origin xyz="-7.7449938932320851496e-15 -1.2129782965129864565e-16 0.0047949116178401442884" rpy="0 0 0" />      
      <mass value="0.0032000000000000001533" />      
      <inertia ixx="1.4019331346159885055e-07" ixy="1.600241000902533359e-15" ixz="-3.3725439700307396967e-36" iyy="1.4019331260388791479e-07" iyz="3.7162875711380697641e-37" izz="2.3838919844264071235e-07" />      
    </inertial>    
  </link>  

  <joint name="right_sho_yaw_drive" type="revolute">    
    <origin xyz="-0.024000000716138513573 -0.019000000152446919199 -0.019000000152449438018" rpy="1.5707963267949425212 -7.4825707768639476445e-14 5.2729872485629252068e-14" />    
    <parent link="2xl430_gears_4" />    
    <child link="spur_1m_24t_drive_4" />    
    <axis xyz="0 0 1" />    
    <limit effort="1" velocity="20" lower="-1.570796326794896558" upper="1.570796326794896558" />    
    <joint_properties friction="0.0" />    
  </joint>  

  <link name="spur_1m_24t_driven_4">    
    <visual>      
      <origin xyz="0 0 0" rpy="0 -0 0" />      
      <geometry>        
        <mesh filename="../assemblies/right_arm_hand/meshes/right_spur_1m_24t_driven_visual.stl" />        
      </geometry>      
      <material name="spur_1m_24t_driven_material">        
        <color rgba="0.23137254901960788156 0.38039215686274502337 0.7058823529411765163 1.0" />        
      </material>      
    </visual>    
    <inertial>      
      <origin xyz="2.533645874753873748e-18 -5.7987576959439556938e-15 -0.00096866348640038332785" rpy="0 0 0" />      
      <mass value="0.0026999999999999997093" />      
      <inertia ixx="1.2026541119643504741e-07" ixy="5.2847048168055754729e-37" ixz="1.9316027113092421355e-38" iyy="1.2026541119643483565e-07" iyz="-1.2918756583307677809e-36" izz="2.2827257365099366486e-07" />      
    </inertial>    
  </link>  

  <link name="sho_yaw_link_2">    
    <visual>      
      <origin xyz="0 0 0" rpy="0 -0 0" />      
      <geometry>        
        <mesh filename="../assemblies/right_arm_hand/meshes/right_sho_yaw_link_visual.stl" />        
      </geometry>      
      <material name="sho_yaw_link_material">        
        <color rgba="0.61568627450980395466 0.81176470588235294379 0.92941176470588238168 1.0" />        
      </material>      
    </visual>    
    <inertial>      
      <origin xyz="-1.3040543109245098801e-18 3.7205074538892864321e-18 -0.024214576156328410095" rpy="0 0 0" />      
      <mass value="0.014500000000000007674" />      
      <inertia ixx="9.0490855102914992479e-06" ixy="3.5997729401434988918e-13" ixz="-1.5560945723103439761e-36" iyy="5.6767199180624744435e-06" iyz="-2.9419992751368725319e-35" izz="4.4590603637468133921e-06" />      
    </inertial>    
  </link>  

  <link name="2xl430_gears_5">    
    <visual>      
      <origin xyz="0 0 0" rpy="0 -0 0" />      
      <geometry>        
        <mesh filename="../assemblies/right_arm_hand/meshes/right_2xl430_gears_2_visual.stl" />        
      </geometry>      
      <material name="2xl430_gears_2_material">        
        <color rgba="0.7560598568794409946 0.85804695962693022793 0.91320266199377464478 1.0" />        
      </material>      
    </visual>    
    <collision>      
      <origin xyz="0 0 0" rpy="0 -0 0" />      
      <geometry>        
        <mesh filename="collisions/right_2xl430_gears_2_collision.stl" />        
      </geometry>      
    </collision>    
    <inertial>      
      <origin xyz="-0.011579403981039057547 -0.0024225766141394637458 -0.018551095523804617821" rpy="0 0 0" />      
      <mass value="0.1180000367452490595" />      
      <inertia ixx="2.7482298083236664606e-05" ixy="9.2729623432884931444e-07" ixz="-2.2634512003316144386e-08" iyy="3.2770742486673401018e-05" iyz="-6.5708346020123095009e-07" izz="3.5767957544054685868e-05" />      
    </inertial>    
  </link>  

  <link name="spur_1m_24t_drive_5">    
    <visual>      
      <origin xyz="0 0 0" rpy="0 -0 0" />      
      <geometry>        
        <mesh filename="../assemblies/right_arm_hand/meshes/right_spur_1m_24t_drive_2_visual.stl" />        
      </geometry>      
      <material name="spur_1m_24t_drive_2_material">        
        <color rgba="0.61568627450980406568 0.81176470588235294379 0.92941176470588238168 1.0" />        
      </material>      
    </visual>    
    <inertial>      
      <origin xyz="-7.7449938932320851496e-15 -1.2129782959959985736e-16 0.0047949116178401382168" rpy="0 0 0" />      
      <mass value="0.0032000000000000001533" />      
      <inertia ixx="1.4019331346159885055e-07" ixy="1.6002410034284993069e-15" ixz="3.6740237543131420414e-36" iyy="1.4019331260388783538e-07" iyz="2.3145098935860352889e-36" izz="2.3838919844264060647e-07" />      
    </inertial>    
  </link>  

  <joint name="right_elbow_yaw_drive" type="revolute">    
    <origin xyz="-0.024000000716145237362 -0.019000000152448695556 -0.019000000152448712903" rpy="1.5707963267950246777 1.6760397103577610108e-15 -7.8984688976387225082e-14" />    
    <parent link="2xl430_gears_5" />    
    <child link="spur_1m_24t_drive_5" />    
    <axis xyz="0 0 1" />    
    <limit effort="1" velocity="20" lower="-1.570796326794896558" upper="1.570796326794896558" />    
    <joint_properties friction="0.0" />    
  </joint>  

  <link name="spur_1m_24t_driven_5">    
    <visual>      
      <origin xyz="0 0 0" rpy="0 -0 0" />      
      <geometry>        
        <mesh filename="../assemblies/right_arm_hand/meshes/right_spur_1m_24t_driven_2_visual.stl" />        
      </geometry>      
      <material name="spur_1m_24t_driven_2_material">        
        <color rgba="0.23137254901960788156 0.38039215686274502337 0.7058823529411765163 1.0" />        
      </material>      
    </visual>    
    <inertial>      
      <origin xyz="2.533645874753873748e-18 -5.7987576959439572715e-15 -0.00096866348640039037516" rpy="0 0 0" />      
      <mass value="0.0026999999999999997093" />      
      <inertia ixx="1.2026541119643504741e-07" ixy="0" ixz="0" iyy="1.2026541119643483565e-07" iyz="6.783026707528045418e-37" izz="2.2827257365099366486e-07" />      
    </inertial>    
  </link>  

  <link name="elb_yaw_link_2">    
    <visual>      
      <origin xyz="0 0 0" rpy="0 -0 0" />      
      <geometry>        
        <mesh filename="../assemblies/right_arm_hand/meshes/right_elb_yaw_link_visual.stl" />        
      </geometry>      
      <material name="elb_yaw_link_material">        
        <color rgba="0.61568627450980395466 0.81176470588235294379 0.92941176470588227065 1.0" />        
      </material>      
    </visual>    
    <inertial>      
      <origin xyz="5.2870889173026998625e-08 0.0019873558182742449146 -0.023365661199828743205" rpy="0 0 0" />      
      <mass value="0.017500000000000001665" />      
      <inertia ixx="1.4097804991252561445e-05" ixy="1.6900809684031188595e-12" ixz="-1.1184673662111210506e-11" iyy="6.6367696417680310494e-06" iyz="1.0579908722588337865e-06" izz="8.9601142768980714413e-06" />      
    </inertial>    
  </link>  

  <link name="spur_1m_24t_driven_6">    
    <visual>      
      <origin xyz="0 0 0" rpy="0 -0 0" />      
      <geometry>        
        <mesh filename="../assemblies/right_arm_hand/meshes/right_spur_1m_24t_driven_3_visual.stl" />        
      </geometry>      
      <material name="spur_1m_24t_driven_3_material">        
        <color rgba="0.23137254901960788156 0.38039215686274502337 0.7058823529411765163 1.0" />        
      </material>      
    </visual>    
    <inertial>      
      <origin xyz="2.5336458747537077329e-18 -5.8024628874047449415e-15 -0.0025686634864003771161" rpy="0 0 0" />      
      <mass value="0.0026999999999999997093" />      
      <inertia ixx="1.2026541119643504741e-07" ixy="2.8037466893945158888e-37" ixz="-2.8777189928702814774e-36" iyy="1.2026541119643483565e-07" iyz="3.635258721425244615e-37" izz="2.2827257365099366486e-07" />      
    </inertial>    
  </link>  

  <link name="2xl430_gears_6">    
    <visual>      
      <origin xyz="0 0 0" rpy="0 -0 0" />      
      <geometry>        
        <mesh filename="../assemblies/right_arm_hand/meshes/right_2xl430_gears_3_visual.stl" />        
      </geometry>      
      <material name="2xl430_gears_3_material">        
        <color rgba="0.7560598568794409946 0.85804695962693022793 0.91320266199377464478 1.0" />        
      </material>      
    </visual>    
    <collision>      
      <origin xyz="0 0 0" rpy="0 -0 0" />      
      <geometry>        
        <mesh filename="collisions/right_2xl430_gears_3_collision.stl" />        
      </geometry>      
    </collision>    
    <inertial>      
      <origin xyz="0.00044890447619843476664 0.01157940362297065276 -0.024577423538311955059" rpy="0 0 0" />      
      <mass value="0.1180000367452490595" />      
      <inertia ixx="3.576795754405587849e-05" ixy="2.2634512003787071543e-08" ixz="6.5708346020150612992e-07" iyy="2.7482298083237169438e-05" iyz="9.2729623433001282007e-07" izz="3.2770742486673529767e-05" />      
    </inertial>    
  </link>  

  <link name="spur_1m_24t_drive_6">    
    <visual>      
      <origin xyz="0 0 0" rpy="0 -0 0" />      
      <geometry>        
        <mesh filename="../assemblies/right_arm_hand/meshes/right_spur_1m_24t_drive_3_visual.stl" />        
      </geometry>      
      <material name="spur_1m_24t_drive_3_material">        
        <color rgba="0.61568627450980406568 0.81176470588235294379 0.92941176470588238168 1.0" />        
      </material>      
    </visual>    
    <inertial>      
      <origin xyz="-7.7796883627516228692e-15 -1.215497698665776033e-16 0.0047949116178401460231" rpy="0 0 0" />      
      <mass value="0.0032000000000000001533" />      
      <inertia ixx="1.4019331346159890349e-07" ixy="1.600241005431778838e-15" ixz="-1.1296774958367438425e-36" iyy="1.4019331260388786185e-07" iyz="-2.0315228471819926087e-37" izz="2.3838919844264060647e-07" />      
    </inertial>    
  </link>  

  <joint name="right_wrist_pitch_drive" type="revolute">    
    <origin xyz="-1.5244520229495961416e-10 0.0240000003580740362 -0.0080000000000021095903" rpy="-2.1390725319343247708e-14 -2.6312285683659644689e-14 -1.5707963267949076602" />    
    <parent link="2xl430_gears_6" />    
    <child link="spur_1m_24t_drive_6" />    
    <axis xyz="0 0 1" />    
    <limit effort="1" velocity="20" lower="-1.570796326794896558" upper="1.570796326794896558" />    
    <joint_properties friction="0.0" />    
  </joint>  

  <link name="wrist_bearing_plate_2">    
    <visual>      
      <origin xyz="0 0 0" rpy="0 -0 0" />      
      <geometry>        
        <mesh filename="../assemblies/right_arm_hand/meshes/right_wrist_bearing_plate_visual.stl" />        
      </geometry>      
      <material name="wrist_bearing_plate_material">        
        <color rgba="0.64496316278892629192 0.69011804996940528945 0.71706771073555886087 1.0" />        
      </material>      
    </visual>    
    <inertial>      
      <origin xyz="-0.0075896393545961532423 -0.015499999999999973868 -0.001838611004571847219" rpy="0 0 0" />      
      <mass value="0.0049000367468305548388" />      
      <inertia ixx="4.9747313520140056954e-07" ixy="-4.7294520745626485782e-23" ixz="1.8097509420524756549e-08" iyy="7.1295025627582216141e-07" iyz="1.6092186684708218823e-22" izz="1.1926297952291889079e-06" />      
    </inertial>    
  </link>  

  <joint name="right_wrist_roll_fixed" type="fixed">    
    <origin xyz="0.015500000000002378195 7.6882944455292090424e-15 -0.045000000000006055989" rpy="-4.8017145823115539524e-14 1.2051470932306250951e-13 -1.570796326794896558" />    
    <parent link="2xl430_gears_6" />    
    <child link="wrist_bearing_plate_2" />    
    <axis xyz="0 0 1" />    
    <limit effort="1" velocity="20" />    
    <joint_properties friction="0.0" />    
  </joint>  

  <link name="hand_2">    
    <visual>      
      <origin xyz="0 0 0" rpy="0 -0 0" />      
      <geometry>        
        <mesh filename="../assemblies/right_arm_hand/meshes/right_hand_visual.stl" />        
      </geometry>      
      <material name="hand_material">        
        <color rgba="0.61568627450980395466 0.81176470588235294379 0.92941176470588238168 1.0" />        
      </material>      
    </visual>    
    <collision>      
      <origin xyz="0 0 0" rpy="0 -0 0" />      
      <geometry>        
        <mesh filename="../assemblies/right_arm_hand/meshes/right_hand_collision.stl" />        
      </geometry>      
    </collision>    
    <inertial>      
      <origin xyz="-4.3038382212365917433e-08 0.049723778585231921678 -0.020066427994609656316" rpy="0 0 0" />      
      <mass value="0.017000000000001441042" />      
      <inertia ixx="9.492141461772624154e-06" ixy="1.5549215897336585373e-11" ixz="1.080969419651779152e-11" iyy="4.0745028295199788173e-06" iyz="2.4719408559837120591e-07" izz="6.6623859523002797615e-06" />      
    </inertial>    
  </link>  

  <joint name="right_wrist_roll" type="revolute">    
    <origin xyz="0.019000000000002986722 -3.580650775880656056e-10 -0.027000000152453820096" rpy="-3.1415926535897797933 -1.5707963267947695485 0" />    
    <parent link="2xl430_gears_6" />    
    <child link="hand_2" />    
    <axis xyz="0 0 1" />    
    <limit effort="1" velocity="20" lower="-1.570796326794896558" upper="1.570796326794896558" />    
    <joint_properties friction="0.0" />    
  </joint>  

  <joint name="right_wrist_pitch_driven" type="revolute">    
    <origin xyz="0 0 -0.0016000000000000007272" rpy="2.5486097626493842382e-14 -1.8651746813702645656e-14 1.570796326794896558" />    
    <parent link="spur_1m_24t_driven_6" />    
    <child link="2xl430_gears_6" />    
    <axis xyz="0 0 1" />    
    <limit effort="1" velocity="20" lower="-1.570796326794896558" upper="1.570796326794896558" />    
    <joint_properties friction="0.0" />    
  </joint>  

  <joint name="right_wrist_pitch_fixed" type="fixed">    
    <origin xyz="3.4694469519536141888e-18 -0.025299999999999999573 -0.052000000000000004552" rpy="1.5707963267949045516 1.570796326794896558 0" />    
    <parent link="elb_yaw_link_2" />    
    <child link="spur_1m_24t_driven_6" />    
    <axis xyz="0 0 1" />    
    <limit effort="1" velocity="20" />    
    <joint_properties friction="0.0" />    
  </joint>  

  <joint name="right_elbow_yaw_fixed" type="fixed">    
    <origin xyz="-3.4694469519536141888e-18 -2.3665827156630354162e-30 0.0015999999999999903189" rpy="-3.1415926535897917837 7.2632216806324781157e-16 -1.1934897514010108924e-15" />    
    <parent link="spur_1m_24t_driven_5" />    
    <child link="elb_yaw_link_2" />    
    <axis xyz="0 0 1" />    
    <limit effort="1" velocity="20" />    
    <joint_properties friction="0.0" />    
  </joint>  

  <joint name="right_elbow_yaw_driven" type="revolute">    
    <origin xyz="-3.5807088544226317595e-10 -0.027000000152451505975 -0.01900000000000293468" rpy="1.570796326794921427 8.4749116765166275158e-14 -2.9577354942701689238e-14" />    
    <parent link="2xl430_gears_5" />    
    <child link="spur_1m_24t_driven_5" />    
    <axis xyz="0 0 1" />    
    <limit effort="1" velocity="20" lower="-1.570796326794896558" upper="1.570796326794896558" />    
    <joint_properties friction="0.0" />    
  </joint>  

  <joint name="right_elbow_roll" type="revolute">    
    <origin xyz="0 -0.018999999999999950956 -0.058999999999999955258" rpy="1.570796326794896558 -2.9936014833487158253e-15 -1.8179902027461223811e-15" />    
    <parent link="sho_yaw_link_2" />    
    <child link="2xl430_gears_5" />    
    <axis xyz="0 0 1" />    
    <limit effort="1" velocity="20" lower="-1.570796326794896558" upper="1.570796326794896558" />    
    <joint_properties friction="0.0" />    
  </joint>  

  <joint name="right_sho_yaw_fixed" type="fixed">    
    <origin xyz="-5.898059818321144121e-17 1.201620916072157247e-16 0.0015999999999999972577" rpy="-3.141592653589793116 -5.4212913233780230364e-29 2.371286511247144379e-30" />    
    <parent link="spur_1m_24t_driven_4" />    
    <child link="sho_yaw_link_2" />    
    <axis xyz="0 0 1" />    
    <limit effort="1" velocity="20" />    
    <joint_properties friction="0.0" />    
  </joint>  

  <joint name="right_sho_yaw_driven" type="revolute">    
    <origin xyz="-3.5806683312822329412e-10 -0.027000000152447932444 -0.019000000000004180212" rpy="1.570796326794941189 -3.7231669281427893777e-14 -1.380172419158038954e-15" />    
    <parent link="2xl430_gears_4" />    
    <child link="spur_1m_24t_driven_4" />    
    <axis xyz="0 0 1" />    
    <limit effort="1" velocity="20" lower="-1.570796326794896558" upper="1.570796326794896558" />    
    <joint_properties friction="0.0" />    
  </joint>  

  <joint name="right_sho_roll" type="revolute">    
    <origin xyz="-0.01899999999999998565 0.0010000000000000112965 0.027000000000000013572" rpy="3.141592653589793116 1.570796326794896558 0" />    
    <parent link="sho_pitch_link_2" />    
    <child link="2xl430_gears_4" />    
    <axis xyz="0 0 1" />    
    <limit effort="1" velocity="20" lower="-1.570796326794896558" upper="1.570796326794896558" />    
    <joint_properties friction="0.0" />    
  </joint>  


</robot>