<robot name="toddlerbot">
  <mujoco>
    <compiler strippath="false" balanceinertia="true" discardvisual="false" />
  </mujoco>
  <link name="torso">
    <visual>
      <origin xyz="0 0 0" rpy="0 -0 0" />
      <geometry>
        <mesh filename="../assemblies/toddlerbot/meshes/torso_visual.stl" />
      </geometry>
      <material name="torso_material">
        <color rgba="0.6197852121554117133 0.80497509985632864637 0.91238666069265517145 1.0" />
      </material>
    </visual>
    <inertial>
      <origin xyz="-0.017582789998871049819 -0.0008892412850613319944 0.066328103881054256696" rpy="0 0 0" />
      <mass value="0.38210896478125000453" />
      <inertia ixx="0.00097913100143531372858" ixy="1.368754266574914548e-05" ixz="5.3060955780646044695e-05" iyy="0.00088767318813584431599" iyz="-1.8064914536012927244e-05" izz="0.00068582374333484930409" />
    </inertial>
  </link>

  <link name="spur_1m_20t">
    <visual>
      <origin xyz="0 0 0" rpy="0 -0 0" />
      <geometry>
        <mesh filename="../assemblies/toddlerbot/meshes/spur_1m_20t_visual.stl" />
      </geometry>
      <material name="spur_1m_20t_material">
        <color rgba="0.64705882352941179736 0.64705882352941179736 0.64705882352941179736 1.0" />
      </material>
    </visual>
    <inertial>
      <origin xyz="-5.0044775065590171545e-18 6.0502252725870090006e-18 -0.0033745971730663147647" rpy="0 0 0" />
      <mass value="0.0015534950290892286448" />
      <inertia ixx="4.4726508287871812856e-08" ixy="7.684011163414536344e-24" ixz="2.7597381312606821682e-39" iyy="4.4726508287871786386e-08" iyz="-4.880475641083095171e-38" izz="7.9558906764902006609e-08" />
    </inertial>
  </link>

  <joint name="neck_yaw_drive" type="revolute">
    <origin xyz="-0.004999999999999059884 -1.8020791195763170554e-16 0.12248651076281816263" rpy="-3.1415926535897913396 1.7995135580561967136e-15 9.6455933634066887197e-16" />
    <parent link="torso" />
    <child link="spur_1m_20t" />
    <axis xyz="0 0 1" />
    <limit effort="1" velocity="20" lower="-3.141592653589793116" upper="3.141592653589793116" />
    <joint_properties friction="0.0" />
  </joint>

  <link name="neck_yaw_link">
    <visual>
      <origin xyz="0 0 0" rpy="0 -0 0" />
      <geometry>
        <mesh filename="../assemblies/toddlerbot/meshes/neck_yaw_link_visual.stl" />
      </geometry>
      <material name="neck_yaw_link_material">
        <color rgba="0.33636252417476664167 0.48680769190259887136 0.74976123534949801197 1.0" />
      </material>
    </visual>
    <inertial>
      <origin xyz="2.7291286461356290677e-05 0.00019798992283539515501 -0.0115274120371948504" rpy="0 0 0" />
      <mass value="0.0085168305947458250449" />
      <inertia ixx="1.0407116999274388487e-06" ixy="-2.4210150464746039776e-11" ixz="4.7246803220671246024e-10" iyy="1.1240009954110499114e-06" iyz="3.0834841754646676679e-08" izz="3.1587565167292060697e-07" />
    </inertial>
  </link>

  <link name="neck_pitch_link">
    <visual>
      <origin xyz="0 0 0" rpy="0 -0 0" />
      <geometry>
        <mesh filename="../assemblies/toddlerbot/meshes/neck_pitch_link_visual.stl" />
      </geometry>
      <material name="neck_pitch_link_material">
        <color rgba="0.75175531149912766526 0.80237790269364195339 0.88100511756510224703 1.0" />
      </material>
    </visual>
    <inertial>
      <origin xyz="-0.0033208985050365335059 -0.033447827507434767236 -0.00017266927552015079862" rpy="0 0 0" />
      <mass value="0.10851928601941271402" />
      <inertia ixx="7.4643011916861726944e-05" ixy="1.9512994501134094261e-06" ixz="2.6631618432505370407e-06" iyy="6.1956827409922912795e-05" iyz="-1.1454163205103217525e-05" izz="2.701288336202765537e-05" />
    </inertial>
  </link>

  <link name="spur_gear_(13_teeth)">
    <visual>
      <origin xyz="0 0 0" rpy="0 -0 0" />
      <geometry>
        <mesh filename="../assemblies/toddlerbot/meshes/spur_gear_(13_teeth)_visual.stl" />
      </geometry>
      <material name="spur_gear_(13_teeth)_material">
        <color rgba="0.64705882352941179736 0.64705882352941179736 0.64705882352941179736 1.0" />
      </material>
    </visual>
    <inertial>
      <origin xyz="1.0399873342418501553e-09 2.3905206814663368286e-10 -0.0092751511485596373902" rpy="0 0 0" />
      <mass value="0.00081469437497230855032" />
      <inertia ixx="2.0244839552178295378e-08" ixy="-2.9046301764120405049e-15" ixz="8.297606606936787006e-15" iyy="2.0244841689973771385e-08" iyz="-1.31421177847285757e-15" izz="1.8905472907863310999e-08" />
    </inertial>
  </link>

  <joint name="neck_pitch_drive" type="revolute">
    <origin xyz="-1.4571677198205179593e-16 -0.015650000000000330314 0.0087999999999993777644" rpy="-2.1434555572207676319e-16 -1.5880065549567459396e-15 1.570796326794896558" />
    <parent link="neck_pitch_link" />
    <child link="spur_gear_(13_teeth)" />
    <axis xyz="0 0 1" />
    <limit effort="1" velocity="20" lower="-1.570796326794896558" upper="1.570796326794896558" />
    <joint_properties friction="0.0" />
  </joint>

  <joint name="neck_pitch_driven" type="revolute">
    <origin xyz="3.7500073185592341929e-10 0.0051500000614755261225 -0.027499999999999941158" rpy="1.57079632679489678 -1.7934420258902467287e-15 -3.1415926535897922278" />
    <parent link="neck_yaw_link" />
    <child link="neck_pitch_link" />
    <axis xyz="0 0 1" />
    <limit effort="1" velocity="20" lower="-1.570796326794896558" upper="1.570796326794896558" />
    <joint_properties friction="0.0" />
  </joint>

  <joint name="neck_yaw_driven" type="revolute">
    <origin xyz="0.016000000000001915468 1.4752314067929367773e-17 0.12348651076281796923" rpy="-3.141592653589793116 -0 -3.1415926535897922278" />
    <parent link="torso" />
    <child link="neck_yaw_link" />
    <axis xyz="0 0 1" />
    <limit effort="1" velocity="20" lower="-3.141592653589793116" upper="3.141592653589793116" />
    <joint_properties friction="0.0" />
  </joint>

  <link name="waist_gears">
    <visual>
      <origin xyz="0 0 0" rpy="0 -0 0" />
      <geometry>
        <mesh filename="../assemblies/toddlerbot/meshes/waist_gears_visual.stl" />
      </geometry>
      <material name="waist_gears_material">
        <color rgba="0.2705751638183052088 0.53648836590125015267 0.70305495274644791426 1.0" />
      </material>
    </visual>
    <inertial>
      <origin xyz="6.5469454462684754055e-08 -5.678589769108444202e-10 -0.012726165583898677025" rpy="0 0 0" />
      <mass value="0.023315805669179824611" />
      <inertia ixx="6.9043104388291928151e-06" ixy="-1.8428638769590440561e-11" ixz="9.9668712610669700131e-13" iyy="1.162409197167636598e-06" iyz="-3.3260430300288233958e-10" izz="6.8701920560919842564e-06" />
    </inertial>
  </link>

  <link name="waist_link">
    <visual>
      <origin xyz="0 0 0" rpy="0 -0 0" />
      <geometry>
        <mesh filename="../assemblies/toddlerbot/meshes/waist_link_visual.stl" />
      </geometry>
      <material name="waist_link_material">
        <color rgba="0.63066856640767587905 0.67759035867951045162 0.66849819411858002471 1.0" />
      </material>
    </visual>
    <inertial>
      <origin xyz="-7.8326157945763225844e-07 -0.026309055188168648659 0.029773273854826105139" rpy="0 0 0" />
      <mass value="0.15193452399186058166" />
      <inertia ixx="6.3853955317574355379e-05" ixy="6.7244006990957541522e-10" ixz="3.1782521385896526105e-06" iyy="0.00018554067350207199979" iyz="-3.2622478832003394146e-06" izz="0.00014578323476960398171" />
    </inertial>
  </link>

  <link name="spiral_bevel_1m_14t_30deg">
    <visual>
      <origin xyz="0 0 0" rpy="0 -0 0" />
      <geometry>
        <mesh filename="../assemblies/toddlerbot/meshes/spiral_bevel_1m_14t_30deg_visual.stl" />
      </geometry>
      <material name="spiral_bevel_1m_14t_30deg_material">
        <color rgba="0.64705882352941179736 0.64705882352941179736 0.64705882352941179736 1.0" />
      </material>
    </visual>
    <inertial>
      <origin xyz="8.2641075233036431769e-10 3.4055789828804639008e-10 0.0068612577407481684794" rpy="0 0 0" />
      <mass value="0.00067997563436136235649" />
      <inertia ixx="1.2174575798018975493e-08" ixy="3.8216070047630807068e-18" ixz="4.7204547823421934484e-16" iyy="1.2174575801813732727e-08" iyz="-2.6184097732597935737e-16" izz="1.3178653206314311711e-08" />
    </inertial>
  </link>

  <joint name="waist_act_1" type="revolute">
    <origin xyz="4.8392086706372466624e-17 -0.019600000000000009776 0.012750000000000042549" rpy="-1.5707963267948961139 -1.5707963267948215069 0" />
    <parent link="waist_link" />
    <child link="spiral_bevel_1m_14t_30deg" />
    <axis xyz="0 0 1" />
    <limit effort="1" velocity="20" lower="-2.7925268031909271649" upper="2.7925268031909271649" />
    <joint_properties friction="0.0" />
  </joint>

  <link name="spiral_bevel_1m_14t_30deg_2">
    <visual>
      <origin xyz="0 0 0" rpy="0 -0 0" />
      <geometry>
        <mesh filename="../assemblies/toddlerbot/meshes/spiral_bevel_1m_14t_30deg_2_visual.stl" />
      </geometry>
      <material name="spiral_bevel_1m_14t_30deg_2_material">
        <color rgba="0.64705882352941179736 0.64705882352941179736 0.64705882352941179736 1.0" />
      </material>
    </visual>
    <inertial>
      <origin xyz="7.2990964661290291815e-10 5.1591309341166232978e-10 0.0068612577407481702141" rpy="0 0 0" />
      <mass value="0.00067997563436136235649" />
      <inertia ixx="1.2174575796548751289e-08" ixy="2.6199053407227811934e-18" ixz="5.1847541137723511287e-16" iyy="1.2174575803283978437e-08" iyz="-1.502360766603294444e-16" izz="1.3178653206314315019e-08" />
    </inertial>
  </link>

  <joint name="waist_act_2" type="revolute">
    <origin xyz="-6.321225856846266752e-16 -0.019600000000000079164 0.032750000000000834" rpy="-1.5707963267948976682 -1.3463968515393018865 1.5503953316521244903e-14" />
    <parent link="waist_link" />
    <child link="spiral_bevel_1m_14t_30deg_2" />
    <axis xyz="0 0 1" />
    <limit effort="1" velocity="20" lower="-2.7925268031909271649" upper="2.7925268031909271649" />
    <joint_properties friction="0.0" />
  </joint>

  <link name="spur_gear_19_teeth">
    <visual>
      <origin xyz="0 0 0" rpy="0 -0 0" />
      <geometry>
        <mesh filename="../assemblies/toddlerbot/meshes/spur_gear_19_teeth_visual.stl" />
      </geometry>
      <material name="spur_gear_19_teeth_material">
        <color rgba="0.61568627450980395466 0.81176470588235294379 0.92941176470588238168 1.0" />
      </material>
    </visual>
    <inertial>
      <origin xyz="-4.9156135348702214374e-09 9.0060874048927839393e-10 -0.0045295192537419945097" rpy="0 0 0" />
      <mass value="0.0010993711450650535313" />
      <inertia ixx="2.9215018435433082044e-08" ixy="2.5903313772733109345e-16" ixz="-8.424261245563750688e-15" iyy="2.9215021540034058468e-08" iyz="1.5226232384526170773e-15" izz="4.5709977027671368266e-08" />
    </inertial>
  </link>

  <joint name="left_hip_yaw_drive" type="revolute">
    <origin xyz="-0.036999999999999179379 -0.037100000000004823564 0.039500000000000423661" rpy="-1.5707963267950579844 5.71102443800098102e-13 2.6906455702027046663e-13" />
    <parent link="waist_link" />
    <child link="spur_gear_19_teeth" />
    <axis xyz="0 0 1" />
    <limit effort="1" velocity="20" lower="-1.570796326794896558" upper="1.570796326794896558" />
    <joint_properties friction="0.0" />
  </joint>

  <link name="spur_gear_21_teeth">
    <visual>
      <origin xyz="0 0 0" rpy="0 -0 0" />
      <geometry>
        <mesh filename="../assemblies/toddlerbot/meshes/spur_gear_21_teeth_visual.stl" />
      </geometry>
      <material name="spur_gear_21_teeth_material">
        <color rgba="0.61568627450980395466 0.81176470588235294379 0.92941176470588238168 1.0" />
      </material>
    </visual>
    <inertial>
      <origin xyz="-4.7814841733033882526e-10 1.2610017463689733481e-12 -0.0024944618616143366362" rpy="0 0 0" />
      <mass value="0.0010063046528317972673" />
      <inertia ixx="3.1842855421068488283e-08" ixy="2.1452075797961618719e-37" ixz="-1.1964366566353525762e-38" iyy="3.1842855426953779079e-08" iyz="1.1823805759556976152e-38" izz="5.9529380586728028132e-08" />
    </inertial>
  </link>

  <joint name="left_leg_fixed" type="fixed">
    <origin xyz="3.0357660829594124152e-18 -1.3877787807814456755e-17 -0.0049999999999999697464" rpy="-1.0439449364097525548e-14 1.9685459861175557675e-31 1.834678230847674038e-29" />
    <parent link="spur_gear_21_teeth" />
    <child link="hip_yaw_link" />
    <axis xyz="0 0 1" />
    <limit effort="1" velocity="20" />
    <joint_properties friction="0.0" />
  </joint>

  <joint name="left_hip_yaw_driven" type="revolute">
    <origin xyz="-0.037000000000000005107 -0.041100000000000108669 0.019500000000000006911" rpy="-1.5707963267948841235 1.5707963267948932273 0" />
    <parent link="waist_link" />
    <child link="spur_gear_21_teeth" />
    <axis xyz="0 0 1" />
    <limit effort="1" velocity="20" lower="-1.570796326794896558" upper="1.570796326794896558" />
    <joint_properties friction="0.0" />
  </joint>

  <link name="spur_gear_19_teeth_2">
    <visual>
      <origin xyz="0 0 0" rpy="0 -0 0" />
      <geometry>
        <mesh filename="../assemblies/toddlerbot/meshes/spur_gear_19_teeth_2_visual.stl" />
      </geometry>
      <material name="spur_gear_19_teeth_2_material">
        <color rgba="0.61568627450980395466 0.81176470588235294379 0.92941176470588238168 1.0" />
      </material>
    </visual>
    <inertial>
      <origin xyz="-4.9156135418091161685e-09 9.0060873701983133858e-10 -0.0045295192537419875708" rpy="0 0 0" />
      <mass value="0.0010993711450650535313" />
      <inertia ixx="2.9215018435433095279e-08" ixy="2.5903313731232818381e-16" ixz="-8.4242612455637522657e-15" iyy="2.9215021540034058468e-08" iyz="1.5226232384526170773e-15" izz="4.5709977027671368266e-08" />
    </inertial>
  </link>

  <joint name="right_hip_yaw_drive" type="revolute">
    <origin xyz="0.037000000000000358991 -0.037100000000003852119 0.039500000000000062839" rpy="-1.5707963267949709429 3.0764921674346154011e-13 2.7727445053553844104e-13" />
    <parent link="waist_link" />
    <child link="spur_gear_19_teeth_2" />
    <axis xyz="0 0 1" />
    <limit effort="1" velocity="20" lower="-1.570796326794896558" upper="1.570796326794896558" />
    <joint_properties friction="0.0" />
  </joint>

  <link name="spur_gear_21_teeth_2">
    <visual>
      <origin xyz="0 0 0" rpy="0 -0 0" />
      <geometry>
        <mesh filename="../assemblies/toddlerbot/meshes/spur_gear_21_teeth_2_visual.stl" />
      </geometry>
      <material name="spur_gear_21_teeth_2_material">
        <color rgba="0.61568627450980395466 0.81176470588235294379 0.92941176470588238168 1.0" />
      </material>
    </visual>
    <inertial>
      <origin xyz="-4.7814841733033882526e-10 -1.2610156241567811626e-12 -0.0025055381383856678047" rpy="0 0 0" />
      <mass value="0.0010063046528317972673" />
      <inertia ixx="3.1842855421068488283e-08" ixy="1.560614116831242474e-38" ixz="2.021036725007793052e-39" iyy="3.1842855426953779079e-08" iyz="5.2356557841516804612e-39" izz="5.9529380586728028132e-08" />
    </inertial>
  </link>

  <joint name="right_leg_fixed" type="fixed">
    <origin xyz="0 0 -0.004999999999999997502" rpy="1.0732181508787092545e-15 5.1822669723995480778e-16 -1.6653345369374924824e-16" />
    <parent link="spur_gear_21_teeth_2" />
    <child link="hip_yaw_link_2" />
    <axis xyz="0 0 1" />
    <limit effort="1" velocity="20" />
    <joint_properties friction="0.0" />
  </joint>

  <joint name="right_hip_yaw_driven" type="revolute">
    <origin xyz="0.037000000000000005107 -0.041100000000000011524 0.019500000000000010381" rpy="-1.5707963267948983344 1.5707963267948950037 0" />
    <parent link="waist_link" />
    <child link="spur_gear_21_teeth_2" />
    <axis xyz="0 0 1" />
    <limit effort="1" velocity="20" lower="-1.570796326794896558" upper="1.570796326794896558" />
    <joint_properties friction="0.0" />
  </joint>

  <joint name="waist_roll" type="revolute">
    <origin xyz="-6.2255683191263486807e-20 0.022707865260692461362 -0.013000000000000004607" rpy="1.5707963267948952257 1.2017992026080351615e-15 4.2181022606678868535e-16" />
    <parent link="waist_gears" />
    <child link="waist_link" />
    <axis xyz="0 0 1" />
    <limit effort="1" velocity="20" lower="-0.52359877559829881566" upper="0.52359877559829881566" />
    <joint_properties friction="0.0" />
  </joint>

  <joint name="waist_yaw" type="revolute">
    <origin xyz="-1.7347234759768070944e-18 -1.9721522630525295135e-31 0" rpy="2.0946901476030943553e-15 7.1861600448343401911e-16 -1.5707963267948228392" />
    <parent link="torso" />
    <child link="waist_gears" />
    <axis xyz="0 0 1" />
    <limit effort="1" velocity="20" lower="-1.570796326794896558" upper="1.570796326794896558" />
    <joint_properties friction="0.0" />
  </joint>

  <joint name="left_arm_fixed" type="fixed">
    <origin xyz="0.0010000000000009051128 0.049000000000000341893 0.11948651076281792405" rpy="-5.9230088976703815107e-16 1.7322096859285544219e-15 1.6762794059802379347e-29" />
    <parent link="torso" />
    <child link="xc430" />
    <axis xyz="0 0 1" />
    <limit effort="1" velocity="20" />
    <joint_properties friction="0.0" />
  </joint>

  <joint name="right_arm_fixed" type="fixed">
    <origin xyz="0.0010000000000010308802 -0.049000000000000321076 0.11948651076281791017" rpy="-5.9230088976591895466e-16 1.732209685967738918e-15 1.6762794059934078982e-29" />
    <parent link="torso" />
    <child link="xc430_2" />
    <axis xyz="0 0 1" />
    <limit effort="1" velocity="20" />
    <joint_properties friction="0.0" />
  </joint>


  <link name="hip_yaw_link">
    <visual>
      <origin xyz="0 0 0" rpy="0 -0 0" />
      <geometry>
        <mesh filename="../assemblies/left_leg_XM430/meshes/left_hip_yaw_link_visual.stl" />
      </geometry>
      <material name="hip_yaw_link_material">
        <color rgba="0.61568627450980395466 0.81176470588235294379 0.92941176470588238168 1.0" />
      </material>
    </visual>
    <inertial>
      <origin xyz="6.7015689604249926662e-20 -4.3918015011849180404e-19 -0.0098390489054829104176" rpy="0 0 0" />
      <mass value="0.017999999999999995171" />
      <inertia ixx="2.638503389144253662e-06" ixy="0" ixz="0" iyy="7.6596731957046890345e-06" iyz="0" izz="7.7220708070894769837e-06" />
    </inertial>
  </link>

  <link name="hip_roll_link">
    <visual>
      <origin xyz="0 0 0" rpy="0 -0 0" />
      <geometry>
        <mesh filename="../assemblies/left_leg_XM430/meshes/left_hip_roll_link_visual.stl" />
      </geometry>
      <material name="hip_roll_link_material">
        <color rgba="0.51698661238356036218 0.50347815951093466413 0.49050589017722012741 1.0" />
      </material>
    </visual>
    <inertial>
      <origin xyz="-0.011999849582185674601 -0.0004959809079401069189 -0.018504111838598645556" rpy="0 0 0" />
      <mass value="0.10699970659110669136" />
      <inertia ixx="2.2075996228675713259e-05" ixy="-4.5005801829347553346e-08" ixz="-4.5362214344093656614e-08" iyy="2.9866686933524272515e-05" iyz="-5.560631946651787421e-07" izz="2.9866720157736384206e-05" />
    </inertial>
  </link>

  <link name="left_hip_pitch_link_xm430">
    <visual>
      <origin xyz="0 0 0" rpy="0 -0 0" />
      <geometry>
        <mesh filename="../assemblies/left_leg_XM430/meshes/left_hip_pitch_link_xm430_visual.stl" />
      </geometry>
      <material name="left_hip_pitch_link_xm430_material">
        <color rgba="0.57975821272406502516 0.77143728959223789587 0.90851483081009554166 1.0" />
      </material>
    </visual>
    <inertial>
      <origin xyz="-0.0025375182677326571165 -0.053177226500122250219 -0.015212672942454373223" rpy="0 0 0" />
      <mass value="0.029200901345856088154" />
      <inertia ixx="4.1359196178562864237e-05" ixy="-2.8912579823061075449e-07" ixz="-3.4728834573984853464e-09" iyy="9.0571276411052843605e-06" iyz="1.6889888074652840905e-06" izz="4.0741364151347275225e-05" />
    </inertial>
  </link>

  <link name="left_calf_link">
    <visual>
      <origin xyz="0 0 0" rpy="0 -0 0" />
      <geometry>
        <mesh filename="../assemblies/left_leg_XM430/meshes/left_calf_link_visual.stl" />
      </geometry>
      <material name="left_calf_link_material">
        <color rgba="0.61177930930733637194 0.71653254923097864371 0.74989274724786580961 1.0" />
      </material>
    </visual>
    <inertial>
      <origin xyz="0.0011880880235005835451 -0.049643068417602347064 -0.009863485314329628259" rpy="0 0 0" />
      <mass value="0.079607494529051470167" />
      <inertia ixx="4.8048473174226137767e-05" ixy="3.5190650833685130949e-06" ixz="3.9918574956074798845e-07" iyy="1.4293033116538981093e-05" iyz="4.8859952267606043958e-07" izz="5.1177637188996500414e-05" />
    </inertial>
  </link>

  <link name="bearing_683">
    <visual>
      <origin xyz="0 0 0" rpy="0 -0 0" />
      <geometry>
        <mesh filename="../assemblies/left_leg_XM430/meshes/left_bearing_683_visual.stl" />
      </geometry>
      <material name="bearing_683_material">
        <color rgba="0.64705882352941179736 0.64705882352941179736 0.64705882352941179736 1.0" />
      </material>
    </visual>
    <inertial>
      <origin xyz="1.0732094295242002361e-19 -2.4186774283162282142e-19 -0.0015500000000000003792" rpy="0 0 0" />
      <mass value="0.00048694686130641793437" />
      <inertia ixx="2.1551456503319879113e-09" ixy="2.3860364254964754589e-27" ixz="3.2226027709542401446e-38" iyy="2.1551456503319883249e-09" iyz="4.7329117499858264175e-38" izz="3.5303647444715305817e-09" />
    </inertial>
  </link>

  <joint name="left_knee_front_rev_2" type="revolute">
    <origin xyz="-0.0057402514854763518615 0.013858192987669382124 -0.026199999999999619427" rpy="-2.0062355525798721356e-14 -1.903658682771083387e-14 1.5737070550412661785" />
    <parent link="left_calf_link" />
    <child link="bearing_683" />
    <axis xyz="0 0 1" />
    <limit effort="1" velocity="20" lower="-6.283185307179586232" upper="6.283185307179586232" />
    <joint_properties friction="0.0" />
  </joint>

  <link name="bearing_683_2">
    <visual>
      <origin xyz="0 0 0" rpy="0 -0 0" />
      <geometry>
        <mesh filename="../assemblies/left_leg_XM430/meshes/left_bearing_683_2_visual.stl" />
      </geometry>
      <material name="bearing_683_2_material">
        <color rgba="0.64705882352941179736 0.64705882352941179736 0.64705882352941179736 1.0" />
      </material>
    </visual>
    <inertial>
      <origin xyz="1.0732094295233882159e-19 -1.1092294808199977204e-18 -0.0015500000000000003792" rpy="0 0 0" />
      <mass value="0.00048694686130641793437" />
      <inertia ixx="2.1551456503319879113e-09" ixy="1.1019900283537080477e-27" ixz="8.8307566613355357602e-38" iyy="2.1551456503319874977e-09" iyz="-3.6503814788283070297e-38" izz="3.5303647444715305817e-09" />
    </inertial>
  </link>

  <joint name="left_knee_back_rev_2" type="revolute">
    <origin xyz="0.0057402514854763683413 -0.013858192987669298857 -0.026199999999999869227" rpy="-3.4182534048236850093e-16 -2.9781674294251979449e-14 1.5739207094625164984" />
    <parent link="left_calf_link" />
    <child link="bearing_683_2" />
    <axis xyz="0 0 1" />
    <limit effort="1" velocity="20" lower="-6.283185307179586232" upper="6.283185307179586232" />
    <joint_properties friction="0.0" />
  </joint>

  <link name="ank_pitch_link">
    <visual>
      <origin xyz="0 0 0" rpy="0 -0 0" />
      <geometry>
        <mesh filename="../assemblies/left_leg_XM430/meshes/left_ank_pitch_link_visual.stl" />
      </geometry>
      <material name="ank_pitch_link_material">
        <color rgba="0.63189161126160264814 0.7266866879354088038 0.78356373393969258601 1.0" />
      </material>
    </visual>
    <inertial>
      <origin xyz="0.00059528282565921724918 -4.0269683161750494364e-08 7.7616092714039670114e-08" rpy="0 0 0" />
      <mass value="0.0042238381753791614387" />
      <inertia ixx="3.9782741364678456013e-07" ixy="-1.6834347827674826857e-13" ixz="2.0919188852949828642e-14" iyy="4.3705254067423072352e-07" iyz="-1.6428822181660775663e-12" izz="8.8858574534613002312e-08" />
    </inertial>
  </link>

  <link name="ank_roll_link">
    <visual>
      <origin xyz="0 0 0" rpy="0 -0 0" />
      <geometry>
        <mesh filename="../assemblies/left_leg_XM430/meshes/left_ank_roll_link_visual.stl" />
      </geometry>
      <material name="ank_roll_link_material">
        <color rgba="0.61568627450980395466 0.81176470588235294379 0.92941176470588238168 1.0" />
      </material>
    </visual>
    <inertial>
      <origin xyz="-3.3748977754135122542e-09 0.016071733707723686452 -0.0096236810250137777567" rpy="0 0 0" />
      <mass value="0.010900000000000006906" />
      <inertia ixx="2.6058536057764959133e-06" ixy="-5.4054321086197607014e-13" ixz="6.0692549095841946231e-13" iyy="2.5928781338360460482e-06" iyz="3.9359839679282425038e-07" izz="1.6179884211196010928e-06" />
    </inertial>
  </link>

  <link name="ank_rr_link">
    <visual>
      <origin xyz="0 0 0" rpy="0 -0 0" />
      <geometry>
        <mesh filename="../assemblies/left_leg_XM430/meshes/left_ank_rr_link_visual.stl" />
      </geometry>
      <material name="ank_rr_link_material">
        <color rgba="0.61568627450980395466 0.81176470588235294379 0.92941176470588238168 1.0" />
      </material>
    </visual>
    <inertial>
      <origin xyz="-4.5249610960605905047e-05 0.0063096429836314591247 -1.9359077708118618298e-19" rpy="0 0 0" />
      <mass value="0.0014499999999999999001" />
      <inertia ixx="2.9739579267716150033e-08" ixy="2.4213146797978005064e-10" ixz="3.5523394884482595477e-14" iyy="2.7430027724071957055e-08" iyz="9.162206139630780346e-32" izz="4.2921949116163665819e-08" />
    </inertial>
  </link>

  <link name="ank_motor_rod_long">
    <visual>
      <origin xyz="0 0 0" rpy="0 -0 0" />
      <geometry>
        <mesh filename="../assemblies/left_leg_XM430/meshes/left_ank_motor_rod_long_visual.stl" />
      </geometry>
      <material name="ank_motor_rod_long_material">
        <color rgba="0.63549975559783222767 0.7077439301702044272 0.75109043491362781353 1.0" />
      </material>
    </visual>
    <inertial>
      <origin xyz="2.4855086863516898073e-10 0.034559019974062264724 0.00093851704878454675525" rpy="0 0 0" />
      <mass value="0.0021712857268636714773" />
      <inertia ixx="8.5350290058000125532e-07" ixy="1.4884244251843848646e-14" ixz="4.5749525025437181107e-11" iyy="1.3237321792739489693e-08" iyz="-4.3668910960862267179e-09" izz="8.5812217519451419348e-07" />
    </inertial>
  </link>

  <joint name="left_ank_long_rev_2" type="revolute">
    <origin xyz="0 0.0099999999999998978595 0" rpy="-1.570796326794896558 1.3320366994106831449 -1.5707963267948692465" />
    <parent link="ank_rr_link" />
    <child link="ank_motor_rod_long" />
    <axis xyz="0 0 1" />
    <limit effort="1" velocity="20" lower="-1.570796326794896558" upper="1.570796326794896558" />
    <joint_properties friction="0.0" />
  </joint>

  <joint name="left_ank_long_rev_1" type="revolute">
    <origin xyz="-0.018000000000000009048 0.015999999999999986455 -0.020600000000000000255" rpy="2.8727848934883667062e-16 -5.525634831039645443e-16 3.123369568546756625" />
    <parent link="ank_roll_link" />
    <child link="ank_rr_link" />
    <axis xyz="0 0 1" />
    <limit effort="1" velocity="20" lower="-1.570796326794896558" upper="1.570796326794896558" />
    <joint_properties friction="0.0" />
  </joint>

  <link name="ank_rr_link_2">
    <visual>
      <origin xyz="0 0 0" rpy="0 -0 0" />
      <geometry>
        <mesh filename="../assemblies/left_leg_XM430/meshes/left_ank_rr_link_2_visual.stl" />
      </geometry>
      <material name="ank_rr_link_2_material">
        <color rgba="0.61568627450980395466 0.81176470588235294379 0.92941176470588238168 1.0" />
      </material>
    </visual>
    <inertial>
      <origin xyz="-4.5249610960602428824e-05 -0.0063096429836314591247 3.6630377290353359488e-18" rpy="0 0 0" />
      <mass value="0.0014499999999999999001" />
      <inertia ixx="2.9739579267716150033e-08" ixy="-2.4213146797978005064e-10" ixz="-3.5523394884482595477e-14" iyy="2.7430027724071957055e-08" iyz="-3.6789861909458584708e-33" izz="4.2921949116163665819e-08" />
    </inertial>
  </link>

  <link name="ank_motor_rod_short">
    <visual>
      <origin xyz="0 0 0" rpy="0 -0 0" />
      <geometry>
        <mesh filename="../assemblies/left_leg_XM430/meshes/left_ank_motor_rod_short_visual.stl" />
      </geometry>
      <material name="ank_motor_rod_short_material">
        <color rgba="0.41222606689734714314 0.58339100346020755783 0.8110726643598615837 1.0" />
      </material>
    </visual>
    <inertial>
      <origin xyz="2.6038941161397234857e-10 0.023830465465870833558 0.00090403506359625226095" rpy="0 0 0" />
      <mass value="0.0017000000000000005558" />
      <inertia ixx="3.3153416252670008308e-07" ixy="8.7419770413212724484e-15" ixz="4.5749941567653724704e-11" iyy="1.0947363610305691502e-08" iyz="-3.5863098646413951952e-09" izz="3.3621340447865130812e-07" />
    </inertial>
  </link>

  <joint name="left_ank_short_rev_2" type="revolute">
    <origin xyz="-3.4694469519536141888e-18 -0.010000000000000008882 6.9388939039072283776e-18" rpy="-1.570796326794896558 -1.2119133862910269617 -1.5707963267948883423" />
    <parent link="ank_rr_link_2" />
    <child link="ank_motor_rod_short" />
    <axis xyz="0 0 1" />
    <limit effort="1" velocity="20" lower="-1.570796326794896558" upper="1.570796326794896558" />
    <joint_properties friction="0.0" />
  </joint>

  <joint name="left_ank_short_rev_1" type="revolute">
    <origin xyz="0.017999999999999995171 0.015999999999999930944 -0.020600000000000003725" rpy="-1.0311645834080153765e-16 5.6225127493299344711e-16 0.026118548507380327101" />
    <parent link="ank_roll_link" />
    <child link="ank_rr_link_2" />
    <axis xyz="0 0 1" />
    <limit effort="1" velocity="20" lower="-1.570796326794896558" upper="1.570796326794896558" />
    <joint_properties friction="0.0" />
  </joint>

  <link name="left_sole_link">
    <visual>
      <origin xyz="0 0 0" rpy="0 -0 0" />
      <geometry>
        <mesh filename="../assemblies/left_leg_XM430/meshes/left_sole_link_visual.stl" />
      </geometry>
      <material name="left_sole_link_material">
        <color rgba="0.61568627450980395466 0.81176470588235283277 0.92941176470588238168 1.0" />
      </material>
    </visual>
    <inertial>
      <origin xyz="-0.028268455053070316862 -2.3408773987365633526e-07 -0.010206307024274999945" rpy="0 0 0" />
      <mass value="0.013899999999999999162" />
      <inertia ixx="1.3160509347109557101e-06" ixy="3.0094161237965149129e-12" ixz="-2.3741900688425285732e-07" iyy="1.3575574544571525394e-05" iyz="-6.7706521655058411305e-12" izz="1.4673603612256130453e-05" />
    </inertial>
  </link>

  <joint name="left_sole" type="fixed">
    <origin xyz="-9.2157184661267876891e-18 0.024999999999999994449 -0.022600000000000002032" rpy="1.570796326794896558 1.570796326794896336 0" />
    <parent link="ank_roll_link" />
    <child link="left_sole_link" />
    <axis xyz="0 0 1" />
    <limit effort="1" velocity="20" />
    <joint_properties friction="0.0" />
  </joint>

  <joint name="left_ank_roll" type="revolute">
    <origin xyz="0.0014999999999999985133 0 1.4961989980299961189e-17" rpy="-8.1315126453654400003e-20 1.5707963267948643615 0" />
    <parent link="ank_pitch_link" />
    <child link="ank_roll_link" />
    <axis xyz="0 0 1" />
    <limit effort="1" velocity="20" lower="-0.785398163397448279" upper="0.785398163397448279" />
    <joint_properties friction="0.0" />
  </joint>

  <joint name="left_ank_pitch" type="revolute">
    <origin xyz="1.883621368080212499e-17 -0.10000000000000011657 -0.010400000000000679534" rpy="-2.2204498262023812517e-16 1.8329922217212873636e-25 3.1415926535897735761" />
    <parent link="left_calf_link" />
    <child link="ank_pitch_link" />
    <axis xyz="0 0 1" />
    <limit effort="1" velocity="20" lower="-0.785398163397448279" upper="0.95993108859688125456" />
    <joint_properties friction="0.0" />
  </joint>

  <link name="ank_motor_arm">
    <visual>
      <origin xyz="0 0 0" rpy="0 -0 0" />
      <geometry>
        <mesh filename="../assemblies/left_leg_XM430/meshes/left_ank_motor_arm_visual.stl" />
      </geometry>
      <material name="ank_motor_arm_material">
        <color rgba="0.62517751827980905244 0.70593642422614044651 0.75978993426662777555 1.0" />
      </material>
    </visual>
    <inertial>
      <origin xyz="0.014511489101591688866 1.5458538573533088711e-17 0.0040925443765950676733" rpy="0 0 0" />
      <mass value="0.0020595846677894939954" />
      <inertia ixx="2.759183675652200141e-08" ixy="-1.9009878417117313037e-22" ixz="-3.0270788206594848502e-08" iyy="1.6138599216238432643e-07" iyz="-6.6015574537835669746e-23" izz="1.6437836765016276946e-07" />
    </inertial>
  </link>

  <joint name="left_ank_act_1" type="revolute">
    <origin xyz="0.013499999999997966751 -0.044499999999993017363 0.0040000000000045363852" rpy="-4.512918339157919121e-13 -1.8247036451598847972e-13 -0.21173394130250977607" />
    <parent link="left_calf_link" />
    <child link="ank_motor_arm" />
    <axis xyz="0 0 1" />
    <limit effort="1" velocity="20" lower="-1.3089969389957472057" upper="1.3089969389957472057" />
    <joint_properties friction="0.0" />
  </joint>

  <link name="ank_motor_arm_2">
    <visual>
      <origin xyz="0 0 0" rpy="0 -0 0" />
      <geometry>
        <mesh filename="../assemblies/left_leg_XM430/meshes/left_ank_motor_arm_2_visual.stl" />
      </geometry>
      <material name="ank_motor_arm_2_material">
        <color rgba="0.62517751827980905244 0.70593642422614044651 0.75978993426662777555 1.0" />
      </material>
    </visual>
    <inertial>
      <origin xyz="0.014511489101591676723 -1.112981947261650627e-19 0.0040925443765951119088" rpy="0 0 0" />
      <mass value="0.0020595846677894939954" />
      <inertia ixx="2.7591836756522302503e-08" ixy="1.1275965192317790989e-23" ixz="-3.0270788206595285254e-08" iyy="1.6138599216238480289e-07" iyz="2.0037669756401538607e-22" izz="1.6437836765016303416e-07" />
    </inertial>
  </link>

  <joint name="left_ank_act_2" type="revolute">
    <origin xyz="0.013500000000004746051 -0.064499999999987706056 -0.024800000000001584666" rpy="-3.1415926535893468063 1.0027652560385185679e-14 -0.22995607267388484818" />
    <parent link="left_calf_link" />
    <child link="ank_motor_arm_2" />
    <axis xyz="0 0 1" />
    <limit effort="1" velocity="20" lower="-1.3089969389957472057" upper="1.3089969389957472057" />
    <joint_properties friction="0.0" />
  </joint>

  <joint name="left_knee_pitch" type="revolute">
    <origin xyz="2.2117522176442097808e-17 -0.095999999999999974243 -0.0091999999999999824973" rpy="-9.7888408496123132916e-15 3.4506032502141251583e-16 2.567762240649299705e-15" />
    <parent link="left_hip_pitch_link_xm430" />
    <child link="left_calf_link" />
    <axis xyz="0 0 1" />
    <limit effort="1" velocity="20" lower="0" upper="1.9198621771937625091" />
    <joint_properties friction="0.0" />
  </joint>

  <link name="xm430_plate">
    <visual>
      <origin xyz="0 0 0" rpy="0 -0 0" />
      <geometry>
        <mesh filename="../assemblies/left_leg_XM430/meshes/left_xm430_plate_visual.stl" />
      </geometry>
      <material name="xm430_plate_material">
        <color rgba="0.61568627450980395466 0.81176470588235294379 0.92941176470588227065 1.0" />
      </material>
    </visual>
    <inertial>
      <origin xyz="-2.4285323750692823328e-17 1.9685523391706791778e-18 -0.0024039046431217972466" rpy="0 0 0" />
      <mass value="0.0027000000000000001429" />
      <inertia ixx="1.293311664536341083e-07" ixy="-6.8936588702566466883e-08" ixz="-1.0792300286928120643e-36" iyy="2.6720434385876688324e-07" iyz="-2.0174295513870425417e-36" izz="3.8533537562751439267e-07" />
    </inertial>
  </link>

  <link name="knee_rod">
    <visual>
      <origin xyz="0 0 0" rpy="0 -0 0" />
      <geometry>
        <mesh filename="../assemblies/left_leg_XM430/meshes/left_knee_rod_visual.stl" />
      </geometry>
      <material name="knee_rod_material">
        <color rgba="0.62711287994822195735 0.75177502733065859619 0.8265723157601205795 1.0" />
      </material>
    </visual>
    <inertial>
      <origin xyz="0.010967337084300846431 3.1521428272557010914e-05 -0.0015872899055776874648" rpy="0 0 0" />
      <mass value="0.0013369468613064179954" />
      <inertia ixx="9.6972467125837695887e-09" ixy="-2.6477920303729672181e-10" ixz="3.1323426701696586354e-10" iyy="2.4572581080075166109e-07" iyz="9.0027245620290024723e-13" izz="2.533776572151701722e-07" />
    </inertial>
  </link>

  <joint name="left_knee_front_rev_1" type="revolute">
    <origin xyz="0.013858192987669298857 0.0057402514854763466573 -0.0050000000000000027062" rpy="-8.6224438144716539469e-15 8.3081819011448317203e-15 -3.138681925343421053" />
    <parent link="xm430_plate" />
    <child link="knee_rod" />
    <axis xyz="0 0 1" />
    <limit effort="1" velocity="20" lower="-6.283185307179586232" upper="6.283185307179586232" />
    <joint_properties friction="0.0" />
  </joint>

  <link name="knee_rod_2">
    <visual>
      <origin xyz="0 0 0" rpy="0 -0 0" />
      <geometry>
        <mesh filename="../assemblies/left_leg_XM430/meshes/left_knee_rod_2_visual.stl" />
      </geometry>
      <material name="knee_rod_2_material">
        <color rgba="0.62711287994822195735 0.75177502733065859619 0.8265723157601205795 1.0" />
      </material>
    </visual>
    <inertial>
      <origin xyz="0.01096734331835830592 2.6835026929233934723e-05 -0.0015872899055774424351" rpy="0 0 0" />
      <mass value="0.0013369468613064179954" />
      <inertia ixx="9.6970372506189099743e-09" ixy="-2.2541367799788274447e-10" ixz="3.1323444506172159439e-10" iyy="2.4572591553263387398e-07" iyz="7.6642579330299712232e-13" izz="2.5337755248509198067e-07" />
    </inertial>
  </link>

  <joint name="left_knee_back_rev_1" type="revolute">
    <origin xyz="-0.013858192987669326612 -0.0057402514854763449226 -0.0049999999999999992367" rpy="-9.8678816935430688804e-17 1.9053378273586200235e-14 -3.1384682709221709551" />
    <parent link="xm430_plate" />
    <child link="knee_rod_2" />
    <axis xyz="0 0 1" />
    <limit effort="1" velocity="20" lower="-6.283185307179586232" upper="6.283185307179586232" />
    <joint_properties friction="0.0" />
  </joint>

  <joint name="left_knee_act" type="revolute">
    <origin xyz="-0.00015000000000000730522 -0.061500000000000019929 -0.030400000000000135247" rpy="-1.3229322588422224447e-16 -9.4099897484365535516e-16 1.570796326794896558" />
    <parent link="left_hip_pitch_link_xm430" />
    <child link="xm430_plate" />
    <axis xyz="0 0 1" />
    <limit effort="1" velocity="20" lower="0" upper="1.9198621771937625091" />
    <joint_properties friction="0.0" />
  </joint>

  <joint name="left_hip_pitch" type="revolute">
    <origin xyz="-0.024000000716151277669 -0.019000000152441035017 -0.019000000152457018759" rpy="1.5707963267952340658 1.5707963267945346253 0" />
    <parent link="hip_roll_link" />
    <child link="left_hip_pitch_link_xm430" />
    <axis xyz="0 0 1" />
    <limit effort="1" velocity="20" lower="-1.570796326794896558" upper="1.570796326794896558" />
    <joint_properties friction="0.0" />
  </joint>

  <joint name="left_hip_roll" type="revolute">
    <origin xyz="0.018999999999999996059 -3.3500438890367315688e-18 -0.026000000000000002276" rpy="-3.141592653589793116 -1.5707963267948934494 0" />
    <parent link="hip_yaw_link" />
    <child link="hip_roll_link" />
    <axis xyz="0 0 1" />
    <limit effort="1" velocity="20" lower="-0.785398163397448279" upper="1.570796326794896558" />
    <joint_properties friction="0.0" />
  </joint>


  <link name="hip_yaw_link_2">
    <visual>
      <origin xyz="0 0 0" rpy="0 -0 0" />
      <geometry>
        <mesh filename="../assemblies/right_leg_XM430/meshes/right_hip_yaw_link_visual.stl" />
      </geometry>
      <material name="hip_yaw_link_material">
        <color rgba="0.61568627450980395466 0.81176470588235294379 0.92941176470588238168 1.0" />
      </material>
    </visual>
    <inertial>
      <origin xyz="-6.7015689604249926662e-20 4.3918015011849180404e-19 -0.0098390489054829104176" rpy="0 0 0" />
      <mass value="0.017999999999999995171" />
      <inertia ixx="2.638503389144253662e-06" ixy="0" ixz="0" iyy="7.6596731957046890345e-06" iyz="0" izz="7.7220708070894769837e-06" />
    </inertial>
  </link>

  <link name="hip_roll_link_2">
    <visual>
      <origin xyz="0 0 0" rpy="0 -0 0" />
      <geometry>
        <mesh filename="../assemblies/right_leg_XM430/meshes/right_hip_roll_link_visual.stl" />
      </geometry>
      <material name="hip_roll_link_material">
        <color rgba="0.51698661238356036218 0.50347815951093466413 0.49050589017722012741 1.0" />
      </material>
    </visual>
    <inertial>
      <origin xyz="-0.011999849582182768939 -0.00049598090794319320881 -0.018504111838597472883" rpy="0 0 0" />
      <mass value="0.10699970659110669136" />
      <inertia ixx="2.2075996228675266026e-05" ixy="-4.50058018289495008e-08" ixz="-4.5362214342475956034e-08" iyy="2.9866686933523323838e-05" iyz="-5.5606319466522003496e-07" izz="2.9866720157735093328e-05" />
    </inertial>
  </link>

  <link name="right_hip_pitch_link_xm430">
    <visual>
      <origin xyz="0 0 0" rpy="0 -0 0" />
      <geometry>
        <mesh filename="../assemblies/right_leg_XM430/meshes/right_hip_pitch_link_xm430_visual.stl" />
      </geometry>
      <material name="right_hip_pitch_link_xm430_material">
        <color rgba="0.57975821272406502516 0.77143728959223789587 0.90851483081009554166 1.0" />
      </material>
    </visual>
    <inertial>
      <origin xyz="0.0025369940892301435544 -0.053177222976062685222 -0.015212667045966776422" rpy="0 0 0" />
      <mass value="0.029200901345856088154" />
      <inertia ixx="4.1359210165692305292e-05" ixy="2.8846904860009788469e-07" ixz="3.5209134634345168732e-09" iyy="9.0572095101179097984e-06" iyz="1.6889923798545578151e-06" izz="4.074145340165466261e-05" />
    </inertial>
  </link>

  <link name="right_calf_link">
    <visual>
      <origin xyz="0 0 0" rpy="0 -0 0" />
      <geometry>
        <mesh filename="../assemblies/right_leg_XM430/meshes/right_calf_link_visual.stl" />
      </geometry>
      <material name="right_calf_link_material">
        <color rgba="0.61177930930733637194 0.71653254923097875473 0.74989274724786592063 1.0" />
      </material>
    </visual>
    <inertial>
      <origin xyz="0.0011880884108858465187 0.049643066575010608155 -0.0098634853265740091155" rpy="0 0 0" />
      <mass value="0.079607494529051442411" />
      <inertia ixx="4.8056790185738505847e-05" ixy="-3.5190664140523731458e-06" ixz="3.9918569370880469757e-07" iyy="1.4293033414473552055e-05" iyz="-4.8654596308570628042e-07" izz="5.1185953583038329819e-05" />
    </inertial>
  </link>

  <link name="bearing_683_3">
    <visual>
      <origin xyz="0 0 0" rpy="0 -0 0" />
      <geometry>
        <mesh filename="../assemblies/right_leg_XM430/meshes/right_bearing_683_visual.stl" />
      </geometry>
      <material name="bearing_683_material">
        <color rgba="0.64705882352941179736 0.64705882352941179736 0.64705882352941179736 1.0" />
      </material>
    </visual>
    <inertial>
      <origin xyz="1.0732094295238763188e-19 2.4186774283159686951e-19 -0.0015499999999999982108" rpy="0 0 0" />
      <mass value="0.00048694686130641793437" />
      <inertia ixx="2.1551456503319887385e-09" ixy="-2.9294495027892568051e-27" ixz="9.2988683363002032047e-39" iyy="2.1551456503319891521e-09" iyz="-6.9734227591432482265e-38" izz="3.5303647444715305817e-09" />
    </inertial>
  </link>

  <joint name="right_knee_front_rev_2" type="revolute">
    <origin xyz="-0.0057402514854763431879 -0.013858192987669298857 -0.026199999999999994127" rpy="-5.4477346283033895825e-15 1.0965747154702311575e-14 3.1358007158040965834" />
    <parent link="right_calf_link" />
    <child link="bearing_683_3" />
    <axis xyz="0 0 1" />
    <limit effort="1" velocity="20" lower="-6.283185307179586232" upper="6.283185307179586232" />
    <joint_properties friction="0.0" />
  </joint>

  <link name="bearing_683_4">
    <visual>
      <origin xyz="0 0 0" rpy="0 -0 0" />
      <geometry>
        <mesh filename="../assemblies/right_leg_XM430/meshes/right_bearing_683_2_visual.stl" />
      </geometry>
      <material name="bearing_683_2_material">
        <color rgba="0.64705882352941179736 0.64705882352941179736 0.64705882352941179736 1.0" />
      </material>
    </visual>
    <inertial>
      <origin xyz="9.7468268094080836801e-19 2.4186774283165874001e-19 -0.0015499999999999977771" rpy="0 0 0" />
      <mass value="0.00048694686130641793437" />
      <inertia ixx="2.1551456503319887385e-09" ixy="-1.2055502399488045527e-29" ixz="6.0530663080618900365e-38" iyy="2.1551456503319891521e-09" iyz="6.329646417650877137e-38" izz="3.5303647444715322361e-09" />
    </inertial>
  </link>

  <joint name="right_knee_back_rev_2" type="revolute">
    <origin xyz="0.0057402514854763726782 0.013858192987669298857 -0.026200000000000001066" rpy="-1.8771482682971376925e-15 -9.8530873122510239724e-18 3.1357969761587902724" />
    <parent link="right_calf_link" />
    <child link="bearing_683_4" />
    <axis xyz="0 0 1" />
    <limit effort="1" velocity="20" lower="-6.283185307179586232" upper="6.283185307179586232" />
    <joint_properties friction="0.0" />
  </joint>

  <link name="ank_pitch_link_2">
    <visual>
      <origin xyz="0 0 0" rpy="0 -0 0" />
      <geometry>
        <mesh filename="../assemblies/right_leg_XM430/meshes/right_ank_pitch_link_visual.stl" />
      </geometry>
      <material name="ank_pitch_link_material">
        <color rgba="0.63189161126160264814 0.7266866879354088038 0.78356373393969258601 1.0" />
      </material>
    </visual>
    <inertial>
      <origin xyz="0.00059528282565905667884 -4.0269682589415725122e-08 7.7616094188425227177e-08" rpy="0 0 0" />
      <mass value="0.0042238381753791614387" />
      <inertia ixx="3.9782741364675321991e-07" ixy="-1.6834347649910148831e-13" ixz="2.0919192021941485552e-14" iyy="4.3705254067418651898e-07" iyz="-1.6428822141780806979e-12" izz="8.8858574534600111529e-08" />
    </inertial>
  </link>

  <link name="ank_roll_link_2">
    <visual>
      <origin xyz="0 0 0" rpy="0 -0 0" />
      <geometry>
        <mesh filename="../assemblies/right_leg_XM430/meshes/right_ank_roll_link_visual.stl" />
      </geometry>
      <material name="ank_roll_link_material">
        <color rgba="0.61568627450980395466 0.81176470588235294379 0.92941176470588238168 1.0" />
      </material>
    </visual>
    <inertial>
      <origin xyz="-3.374897775305092037e-09 0.016071733707723714207 -0.0096236810250137777567" rpy="0 0 0" />
      <mass value="0.010900000000000006906" />
      <inertia ixx="2.6058536057764959133e-06" ixy="-5.4054321086197607014e-13" ixz="6.0692549095841946231e-13" iyy="2.5928781338360460482e-06" iyz="3.9359839679282425038e-07" izz="1.6179884211196010928e-06" />
    </inertial>
  </link>

  <link name="ank_rr_link_3">
    <visual>
      <origin xyz="0 0 0" rpy="0 -0 0" />
      <geometry>
        <mesh filename="../assemblies/right_leg_XM430/meshes/right_ank_rr_link_visual.stl" />
      </geometry>
      <material name="ank_rr_link_material">
        <color rgba="0.61568627450980395466 0.81176470588235294379 0.92941176470588238168 1.0" />
      </material>
    </visual>
    <inertial>
      <origin xyz="-4.5249610960602422048e-05 -0.0063096429836314027462 1.9359077708117763666e-19" rpy="0 0 0" />
      <mass value="0.0014499999999999999001" />
      <inertia ixx="2.9739579267716163268e-08" ixy="-2.4213146797978005064e-10" ixz="-3.5523394884482601788e-14" iyy="2.7430027724071950438e-08" iyz="-9.2286660723348399955e-32" izz="4.2921949116163665819e-08" />
    </inertial>
  </link>

  <link name="ank_motor_rod_long_2">
    <visual>
      <origin xyz="0 0 0" rpy="0 -0 0" />
      <geometry>
        <mesh filename="../assemblies/right_leg_XM430/meshes/right_ank_motor_rod_long_visual.stl" />
      </geometry>
      <material name="ank_motor_rod_long_material">
        <color rgba="0.63549975559783222767 0.7077439301702044272 0.75109043491362781353 1.0" />
      </material>
    </visual>
    <inertial>
      <origin xyz="2.4855086429196933828e-10 0.034559019974062202274 0.00093851704878448538941" rpy="0 0 0" />
      <mass value="0.0021712857268636714773" />
      <inertia ixx="8.5350290057999892598e-07" ixy="1.4884244311377931608e-14" ixz="4.5749525025513695314e-11" iyy="1.3237321792739358999e-08" iyz="-4.3668910960836045554e-09" izz="8.5812217519451249942e-07" />
    </inertial>
  </link>

  <joint name="right_ank_long_rev_2" type="revolute">
    <origin xyz="3.4694469519536141888e-18 -0.0099999999999998423483 1.0408340855860842566e-17" rpy="-1.570796326794896558 -1.3320366994106278558 -1.5707963267948821251" />
    <parent link="ank_rr_link_3" />
    <child link="ank_motor_rod_long_2" />
    <axis xyz="0 0 1" />
    <limit effort="1" velocity="20" lower="-1.570796326794896558" upper="1.570796326794896558" />
    <joint_properties friction="0.0" />
  </joint>

  <joint name="right_ank_long_rev_1" type="revolute">
    <origin xyz="0.017999999999999988232 0.016000000000000014211 -0.020600000000000014133" rpy="-6.5592393894058373872e-17 4.425192650031777037e-16 0.01822308504299342824" />
    <parent link="ank_roll_link_2" />
    <child link="ank_rr_link_3" />
    <axis xyz="0 0 1" />
    <limit effort="1" velocity="20" lower="-1.570796326794896558" upper="1.570796326794896558" />
    <joint_properties friction="0.0" />
  </joint>

  <link name="ank_rr_link_4">
    <visual>
      <origin xyz="0 0 0" rpy="0 -0 0" />
      <geometry>
        <mesh filename="../assemblies/right_leg_XM430/meshes/right_ank_rr_link_2_visual.stl" />
      </geometry>
      <material name="ank_rr_link_2_material">
        <color rgba="0.61568627450980395466 0.81176470588235294379 0.92941176470588238168 1.0" />
      </material>
    </visual>
    <inertial>
      <origin xyz="-4.524961096060238139e-05 0.0063096429836314027462 -1.9359077708145472983e-19" rpy="0 0 0" />
      <mass value="0.0014499999999999999001" />
      <inertia ixx="2.9739579267716150033e-08" ixy="2.4213146797978025744e-10" ixz="3.5523394884482595477e-14" iyy="2.7430027724071950438e-08" iyz="5.6282437144470795625e-32" izz="4.2921949116163665819e-08" />
    </inertial>
  </link>

  <link name="ank_motor_rod_short_2">
    <visual>
      <origin xyz="0 0 0" rpy="0 -0 0" />
      <geometry>
        <mesh filename="../assemblies/right_leg_XM430/meshes/right_ank_motor_rod_short_visual.stl" />
      </geometry>
      <material name="ank_motor_rod_short_material">
        <color rgba="0.41222606689734714314 0.58339100346020755783 0.8110726643598615837 1.0" />
      </material>
    </visual>
    <inertial>
      <origin xyz="2.6038939217395135539e-10 0.023830465465871003561 0.0009040350635961763668" rpy="0 0 0" />
      <mass value="0.0017000000000000005558" />
      <inertia ixx="3.3153416252670696522e-07" ixy="8.7419773793873309686e-15" ixz="4.5749941567750892577e-11" iyy="1.0947363610305942965e-08" iyz="-3.5863098646396907895e-09" izz="3.3621340447865776674e-07" />
    </inertial>
  </link>

  <joint name="right_ank_short_rev_2" type="revolute">
    <origin xyz="3.4694469519536141888e-18 0.010000000000000008882 -6.9388939039072283776e-18" rpy="-1.570796326794896558 1.211913386290874195 -1.5707963267949693886" />
    <parent link="ank_rr_link_4" />
    <child link="ank_motor_rod_short_2" />
    <axis xyz="0 0 1" />
    <limit effort="1" velocity="20" lower="-1.570796326794896558" upper="1.570796326794896558" />
    <joint_properties friction="0.0" />
  </joint>

  <joint name="right_ank_short_rev_1" type="revolute">
    <origin xyz="-0.018000000000000015987 0.016000000000000069722 -0.020599999999999996786" rpy="-5.1243183935211302546e-15 2.3393195508611717606e-14 3.115474105082493228" />
    <parent link="ank_roll_link_2" />
    <child link="ank_rr_link_4" />
    <axis xyz="0 0 1" />
    <limit effort="1" velocity="20" lower="-1.570796326794896558" upper="1.570796326794896558" />
    <joint_properties friction="0.0" />
  </joint>

  <link name="right_sole_link">
    <visual>
      <origin xyz="0 0 0" rpy="0 -0 0" />
      <geometry>
        <mesh filename="../assemblies/right_leg_XM430/meshes/right_sole_link_visual.stl" />
      </geometry>
      <material name="right_sole_link_material">
        <color rgba="0.61568627450980395466 0.81176470588235294379 0.92941176470588238168 1.0" />
      </material>
    </visual>
    <inertial>
      <origin xyz="-0.02826922064948917887 -7.4209810882872538916e-08 -0.010206288127740055505" rpy="0 0 0" />
      <mass value="0.013900000000000004366" />
      <inertia ixx="1.316069070887124095e-06" ixy="-1.0226444191973209573e-10" ixz="-2.3744136049829838944e-07" iyy="1.3575381226152454021e-05" iyz="-7.1602330637823177879e-13" izz="1.4673427099197175005e-05" />
    </inertial>
  </link>

  <joint name="right_sole" type="fixed">
    <origin xyz="-8.9988780316296868023e-18 0.025000000000000022204 -0.022600000000000002032" rpy="1.5707963267948985564 1.5707963267948945596 0" />
    <parent link="ank_roll_link_2" />
    <child link="right_sole_link" />
    <axis xyz="0 0 1" />
    <limit effort="1" velocity="20" />
    <joint_properties friction="0.0" />
  </joint>

  <joint name="right_ank_roll" type="revolute">
    <origin xyz="0.0014999999999999998144 2.7755575615628913511e-17 -1.4419888894057208972e-17" rpy="-3.141592653589793116 -1.5707963267948947816 0" />
    <parent link="ank_pitch_link_2" />
    <child link="ank_roll_link_2" />
    <axis xyz="0 0 1" />
    <limit effort="1" velocity="20" lower="-0.785398163397448279" upper="0.785398163397448279" />
    <joint_properties friction="0.0" />
  </joint>

  <joint name="right_ank_pitch" type="revolute">
    <origin xyz="2.5458137454050591327e-17 0.10000000000000003331 -0.010400000000000018605" rpy="1.5825612599836936462e-15 -6.6613381503165742443e-16 -3.1415926535897873428" />
    <parent link="right_calf_link" />
    <child link="ank_pitch_link_2" />
    <axis xyz="0 0 1" />
    <limit effort="1" velocity="20" lower="-0.785398163397448279" upper="0.95993108859688125456" />
    <joint_properties friction="0.0" />
  </joint>

  <link name="ank_motor_arm_3">
    <visual>
      <origin xyz="0 0 0" rpy="0 -0 0" />
      <geometry>
        <mesh filename="../assemblies/right_leg_XM430/meshes/right_ank_motor_arm_visual.stl" />
      </geometry>
      <material name="ank_motor_arm_material">
        <color rgba="0.62517751827980905244 0.70593642422614044651 0.75978993426662777555 1.0" />
      </material>
    </visual>
    <inertial>
      <origin xyz="0.014511489101591685397 -1.2304772143439285592e-18 0.0040925443765950624692" rpy="0 0 0" />
      <mass value="0.0020595846677894939954" />
      <inertia ixx="2.7591836756521888913e-08" ixy="-5.9964751007237139186e-24" ixz="-3.0270788206594808798e-08" iyy="1.6138599216238429997e-07" iyz="-1.0580171637286161896e-23" izz="1.6437836765016284887e-07" />
    </inertial>
  </link>

  <joint name="right_ank_act_1" type="revolute">
    <origin xyz="0.013499999999996532135 0.044500000000006922907 0.0040000000000042501558" rpy="-3.1437427131281823257e-13 -4.4003633570199104585e-14 0.21173394130151781956" />
    <parent link="right_calf_link" />
    <child link="ank_motor_arm_3" />
    <axis xyz="0 0 1" />
    <limit effort="1" velocity="20" lower="-1.3089969389957472057" upper="1.3089969389957472057" />
    <joint_properties friction="0.0" />
  </joint>

  <link name="ank_motor_arm_4">
    <visual>
      <origin xyz="0 0 0" rpy="0 -0 0" />
      <geometry>
        <mesh filename="../assemblies/right_leg_XM430/meshes/right_ank_motor_arm_2_visual.stl" />
      </geometry>
      <material name="ank_motor_arm_2_material">
        <color rgba="0.62517751827980905244 0.70593642422614044651 0.75978993426662777555 1.0" />
      </material>
    </visual>
    <inertial>
      <origin xyz="0.014511489101591685397 4.5584079062740652548e-19 0.0040925443765950642039" rpy="0 0 0" />
      <mass value="0.0020595846677894939954" />
      <inertia ixx="2.7591836756521965014e-08" ixy="-3.0026020760096009728e-23" ixz="-3.0270788206594841885e-08" iyy="1.613859921623843529e-07" iyz="-6.8768720166424008923e-24" izz="1.6437836765016284887e-07" />
    </inertial>
  </link>

  <joint name="right_ank_act_2" type="revolute">
    <origin xyz="0.013500000000004223899 0.06450000000000813416 -0.024800000000001803241" rpy="-3.1415926535895222216 -2.1045472835494036236e-13 0.22995607267266512941" />
    <parent link="right_calf_link" />
    <child link="ank_motor_arm_4" />
    <axis xyz="0 0 1" />
    <limit effort="1" velocity="20" lower="-1.3089969389957472057" upper="1.3089969389957472057" />
    <joint_properties friction="0.0" />
  </joint>

  <joint name="right_knee_pitch" type="revolute">
    <origin xyz="-3.0242154156037831921e-17 -0.096000000000000015876 -0.0091999999999999963751" rpy="1.9802508686334247224e-15 -1.2115308756231608563e-14 3.1415926535897615857" />
    <parent link="right_hip_pitch_link_xm430" />
    <child link="right_calf_link" />
    <axis xyz="0 0 1" />
    <limit effort="1" velocity="20" lower="-1.9198621771937625091" upper="0" />
    <joint_properties friction="0.0" />
  </joint>

  <link name="xm430_plate_2">
    <visual>
      <origin xyz="0 0 0" rpy="0 -0 0" />
      <geometry>
        <mesh filename="../assemblies/right_leg_XM430/meshes/right_xm430_plate_visual.stl" />
      </geometry>
      <material name="xm430_plate_material">
        <color rgba="0.61568627450980395466 0.81176470588235294379 0.92941176470588227065 1.0" />
      </material>
    </visual>
    <inertial>
      <origin xyz="9.1975985740996841453e-19 1.783860014833551564e-17 -0.0024039046431217955119" rpy="0 0 0" />
      <mass value="0.0027000000000000001429" />
      <inertia ixx="2.6720434385876688324e-07" ixy="-6.8936588702566387474e-08" ixz="-3.4845808582805296013e-36" iyy="1.2933116645363405536e-07" iyz="-1.1011162650770204514e-36" izz="3.8533537562751439267e-07" />
    </inertial>
  </link>

  <link name="knee_rod_3">
    <visual>
      <origin xyz="0 0 0" rpy="0 -0 0" />
      <geometry>
        <mesh filename="../assemblies/right_leg_XM430/meshes/right_knee_rod_visual.stl" />
      </geometry>
      <material name="knee_rod_material">
        <color rgba="0.62711287994822195735 0.75177502733065859619 0.8265723157601205795 1.0" />
      </material>
    </visual>
    <inertial>
      <origin xyz="0.010967336860938672188 3.1676475513803476272e-05 -0.0015872899055782941843" rpy="0 0 0" />
      <mass value="0.0013369468613064179954" />
      <inertia ixx="9.6972542174599785294e-09" ixy="-2.6608159054156034333e-10" ixz="3.1323426064377209516e-10" iyy="2.4572580704828929624e-07" iyz="9.0470070491434320118e-13" izz="2.533776609675739859e-07" />
    </inertial>
  </link>

  <joint name="right_knee_front_rev_1" type="revolute">
    <origin xyz="-0.005740251485476348392 -0.013858192987669284979 -0.0050000000000000044409" rpy="-1.2384470314426580757e-14 -1.7414957345394515419e-15 1.5650043890091922538" />
    <parent link="xm430_plate_2" />
    <child link="knee_rod_3" />
    <axis xyz="0 0 1" />
    <limit effort="1" velocity="20" lower="-6.283185307179586232" upper="6.283185307179586232" />
    <joint_properties friction="0.0" />
  </joint>

  <link name="knee_rod_4">
    <visual>
      <origin xyz="0 0 0" rpy="0 -0 0" />
      <geometry>
        <mesh filename="../assemblies/right_leg_XM430/meshes/right_knee_rod_2_visual.stl" />
      </geometry>
      <material name="knee_rod_2_material">
        <color rgba="0.62711287994822195735 0.75177502733065859619 0.8265723157601205795 1.0" />
      </material>
    </visual>
    <inertial>
      <origin xyz="0.010967336742326699514 3.1758502723681846197e-05 -0.0015872899055780393968" rpy="0 0 0" />
      <mass value="0.0013369468613064179954" />
      <inertia ixx="9.6972582027827120085e-09" ixy="-2.6677061413968154947e-10" ixz="3.1323425725317939212e-10" iyy="2.4572580505561670632e-07" iyz="9.0704345416446645418e-13" izz="2.5337766296022052957e-07" />
    </inertial>
  </link>

  <joint name="right_knee_back_rev_1" type="revolute">
    <origin xyz="0.0057402514854763509941 0.013858192987669298857 -0.0050000000000000009714" rpy="4.9254694032746774356e-16 3.0156850660129127871e-15 1.5650006493638755067" />
    <parent link="xm430_plate_2" />
    <child link="knee_rod_4" />
    <axis xyz="0 0 1" />
    <limit effort="1" velocity="20" lower="-6.283185307179586232" upper="6.283185307179586232" />
    <joint_properties friction="0.0" />
  </joint>

  <joint name="right_knee_act" type="revolute">
    <origin xyz="0.00014999999999999350875 -0.06150000000000001299 -0.030400000000000010347" rpy="1.3560136669320073081e-26 -9.9920072221372949076e-16 3.1415926535897598093" />
    <parent link="right_hip_pitch_link_xm430" />
    <child link="xm430_plate_2" />
    <axis xyz="0 0 1" />
    <limit effort="1" velocity="20" lower="-1.9198621771937625091" upper="0" />
    <joint_properties friction="0.0" />
  </joint>

  <joint name="right_hip_pitch" type="revolute">
    <origin xyz="-0.024000000716143048141 -0.019000000152443574652 -0.019000000152453549312" rpy="1.5707963267951119413 1.5707963267946947195 0" />
    <parent link="hip_roll_link_2" />
    <child link="right_hip_pitch_link_xm430" />
    <axis xyz="0 0 1" />
    <limit effort="1" velocity="20" lower="-1.570796326794896558" upper="1.570796326794896558" />
    <joint_properties friction="0.0" />
  </joint>

  <joint name="right_hip_roll" type="revolute">
    <origin xyz="-0.018999999999999999528 3.350043889036771243e-18 -0.026000000000000002276" rpy="2.5210948034330457424e-32 -1.5707963267948741315 0" />
    <parent link="hip_yaw_link_2" />
    <child link="hip_roll_link_2" />
    <axis xyz="0 0 1" />
    <limit effort="1" velocity="20" lower="-0.785398163397448279" upper="1.570796326794896558" />
    <joint_properties friction="0.0" />
  </joint>


  <link name="xc430">
    <visual>
      <origin xyz="0 0 0" rpy="0 -0 0" />
      <geometry>
        <mesh filename="../assemblies/left_arm_hand/meshes/left_xc430_visual.stl" />
      </geometry>
      <material name="xc430_material">
        <color rgba="0.3960334863748344314 0.50878377002232877402 0.71126755432153676573 1.0" />
      </material>
    </visual>
    <inertial>
      <origin xyz="0.007649938948420367639 -0.0056800345415021161882 -0.014255781343936730146" rpy="0 0 0" />
      <mass value="0.065021926915724281848" />
      <inertia ixx="1.0685477757330408185e-05" ixy="2.4991048730003782262e-08" ixz="-4.3793050176056826951e-09" iyy="1.6030858372951694338e-05" iyz="-9.5846760480288827968e-09" izz="1.8186829094811185627e-05" />
    </inertial>
  </link>

  <link name="sho_pitch_link">
    <visual>
      <origin xyz="0 0 0" rpy="0 -0 0" />
      <geometry>
        <mesh filename="../assemblies/left_arm_hand/meshes/left_sho_pitch_link_visual.stl" />
      </geometry>
      <material name="sho_pitch_link_material">
        <color rgba="0.61568627450980395466 0.81176470588235294379 0.92941176470588238168 1.0" />
      </material>
    </visual>
    <inertial>
      <origin xyz="5.825424752983753426e-11 -5.1264642561121013175e-05 0.0082440788127094953575" rpy="0 0 0" />
      <mass value="0.008600000000000003475" />
      <inertia ixx="1.2272887040545802461e-06" ixy="-2.142994420191543053e-14" ixz="-8.5847198540427074509e-15" iyy="2.9107306060364645499e-06" iyz="7.4623841398183117097e-09" izz="3.0803135950773496163e-06" />
    </inertial>
  </link>

  <link name="2xl430_gears">
    <visual>
      <origin xyz="0 0 0" rpy="0 -0 0" />
      <geometry>
        <mesh filename="../assemblies/left_arm_hand/meshes/left_2xl430_gears_visual.stl" />
      </geometry>
      <material name="2xl430_gears_material">
        <color rgba="0.91900666046079226845 0.7025956886054134376 0.12479235365575504224 1.0" />
      </material>
    </visual>
    <inertial>
      <origin xyz="-0.011545549214475146413 -0.0025776045975616475661 -0.018554883443549097938" rpy="0 0 0" />
      <mass value="0.10921242823035924585" />
      <inertia ixx="2.5633987199176192553e-05" ixy="9.2332485824732311751e-07" ixz="-1.9126365492206487289e-08" iyy="3.0316164317563576338e-05" iyz="-6.1055425070402846345e-07" izz="3.3278157643470436923e-05" />
    </inertial>
  </link>

  <link name="spur_1m_24t_drive">
    <visual>
      <origin xyz="0 0 0" rpy="0 -0 0" />
      <geometry>
        <mesh filename="../assemblies/left_arm_hand/meshes/left_spur_1m_24t_drive_visual.stl" />
      </geometry>
      <material name="spur_1m_24t_drive_material">
        <color rgba="0.61568627450980406568 0.81176470588235294379 0.92941176470588238168 1.0" />
      </material>
    </visual>
    <inertial>
      <origin xyz="-7.7521101396039417664e-15 -1.2144011607250416242e-16 0.0047949116178401460231" rpy="0 0 0" />
      <mass value="0.0032000000000000001533" />
      <inertia ixx="1.4019331346159892996e-07" ixy="1.6002410053751656435e-15" ixz="-8.7717508276537448259e-37" iyy="1.4019331260388786185e-07" iyz="1.1548227992196316113e-37" izz="2.3838919844264060647e-07" />
    </inertial>
  </link>

  <joint name="left_sho_yaw_drive" type="revolute">
    <origin xyz="-0.024000000716149078039 -0.019000000152453292573 -0.019000000152451651525" rpy="1.5707963267948956698 -4.5091784937906777239e-14 2.4545027507744066908e-14" />
    <parent link="2xl430_gears" />
    <child link="spur_1m_24t_drive" />
    <axis xyz="0 0 1" />
    <limit effort="1" velocity="20" lower="-3.141592653589793116" upper="3.141592653589793116" />
    <joint_properties friction="0.0" />
  </joint>

  <link name="spur_1m_24t_driven">
    <visual>
      <origin xyz="0 0 0" rpy="0 -0 0" />
      <geometry>
        <mesh filename="../assemblies/left_arm_hand/meshes/left_spur_1m_24t_driven_visual.stl" />
      </geometry>
      <material name="spur_1m_24t_driven_material">
        <color rgba="0.23137254901960788156 0.38039215686274502337 0.7058823529411765163 1.0" />
      </material>
    </visual>
    <inertial>
      <origin xyz="2.5339767539064915348e-18 -5.7992099762712231414e-15 -0.00096866348640038332785" rpy="0 0 0" />
      <mass value="0.0026999999999999997093" />
      <inertia ixx="1.2026541119643502094e-07" ixy="-2.1120706372726556366e-36" ixz="0" iyy="1.2026541119643483565e-07" iyz="0" izz="2.2827257365099366486e-07" />
    </inertial>
  </link>

  <link name="sho_yaw_link">
    <visual>
      <origin xyz="0 0 0" rpy="0 -0 0" />
      <geometry>
        <mesh filename="../assemblies/left_arm_hand/meshes/left_sho_yaw_link_visual.stl" />
      </geometry>
      <material name="sho_yaw_link_material">
        <color rgba="0.61568627450980395466 0.81176470588235294379 0.92941176470588238168 1.0" />
      </material>
    </visual>
    <inertial>
      <origin xyz="5.7814996523352891568e-18 3.8649239170559342289e-18 -0.024214576156328389278" rpy="0 0 0" />
      <mass value="0.014499999999999986858" />
      <inertia ixx="9.0490855102914890835e-06" ixy="3.5997729401745807688e-13" ixz="0" iyy="5.6767199180624668202e-06" iyz="0" izz="4.4590603637468091569e-06" />
    </inertial>
  </link>

  <link name="2xl430_gears_2">
    <visual>
      <origin xyz="0 0 0" rpy="0 -0 0" />
      <geometry>
        <mesh filename="../assemblies/left_arm_hand/meshes/left_2xl430_gears_2_visual.stl" />
      </geometry>
      <material name="2xl430_gears_2_material">
        <color rgba="0.91900666046079226845 0.7025956886054134376 0.12479235365575504224 1.0" />
      </material>
    </visual>
    <inertial>
      <origin xyz="-0.01154554921447331281 -0.0025776045975613760819 -0.018554883443544802762" rpy="0 0 0" />
      <mass value="0.10921242823035924585" />
      <inertia ixx="2.5633987199174796643e-05" ixy="9.2332485824667196093e-07" ixz="-1.9126365492400034317e-08" iyy="3.0316164317562424373e-05" iyz="-6.1055425070424720971e-07" izz="3.327815764346942726e-05" />
    </inertial>
  </link>

  <link name="spur_1m_24t_drive_2">
    <visual>
      <origin xyz="0 0 0" rpy="0 -0 0" />
      <geometry>
        <mesh filename="../assemblies/left_arm_hand/meshes/left_spur_1m_24t_drive_2_visual.stl" />
      </geometry>
      <material name="spur_1m_24t_drive_2_material">
        <color rgba="0.61568627450980406568 0.81176470588235294379 0.92941176470588238168 1.0" />
      </material>
    </visual>
    <inertial>
      <origin xyz="-7.7521101396039417664e-15 -1.2144011607250455685e-16 0.0047949116178401512273" rpy="0 0 0" />
      <mass value="0.0032000000000000001533" />
      <inertia ixx="1.4019331346159892996e-07" ixy="1.6002410086838880937e-15" ixz="3.3868739208338279975e-37" iyy="1.4019331260388786185e-07" iyz="2.3470577016292310921e-36" izz="2.3838919844264071235e-07" />
    </inertial>
  </link>

  <joint name="left_elbow_yaw_drive" type="revolute">
    <origin xyz="-0.024000000716143922441 -0.019000000152449375568 -0.019000000152448702495" rpy="1.5707963267948812369 -8.0032142329674811068e-15 1.2365412156371141215e-13" />
    <parent link="2xl430_gears_2" />
    <child link="spur_1m_24t_drive_2" />
    <axis xyz="0 0 1" />
    <limit effort="1" velocity="20" lower="-3.141592653589793116" upper="3.141592653589793116" />
    <joint_properties friction="0.0" />
  </joint>

  <link name="spur_1m_24t_driven_2">
    <visual>
      <origin xyz="0 0 0" rpy="0 -0 0" />
      <geometry>
        <mesh filename="../assemblies/left_arm_hand/meshes/left_spur_1m_24t_driven_2_visual.stl" />
      </geometry>
      <material name="spur_1m_24t_driven_2_material">
        <color rgba="0.23137254901960788156 0.38039215686274502337 0.7058823529411765163 1.0" />
      </material>
    </visual>
    <inertial>
      <origin xyz="2.5339767539064915348e-18 -5.7992099762712231414e-15 -0.00096866348640037638895" rpy="0 0 0" />
      <mass value="0.0026999999999999997093" />
      <inertia ixx="1.2026541119643502094e-07" ixy="-6.5732337140722133283e-38" ixz="0" iyy="1.2026541119643483565e-07" iyz="0" izz="2.2827257365099366486e-07" />
    </inertial>
  </link>

  <link name="elb_yaw_link">
    <visual>
      <origin xyz="0 0 0" rpy="0 -0 0" />
      <geometry>
        <mesh filename="../assemblies/left_arm_hand/meshes/left_elb_yaw_link_visual.stl" />
      </geometry>
      <material name="elb_yaw_link_material">
        <color rgba="0.61568627450980395466 0.81176470588235294379 0.92941176470588227065 1.0" />
      </material>
    </visual>
    <inertial>
      <origin xyz="5.287088917269459775e-08 0.0019873558182742479504 -0.023365661199828729327" rpy="0 0 0" />
      <mass value="0.017500000000000001665" />
      <inertia ixx="1.4097804991252558057e-05" ixy="1.6900809684051191583e-12" ixz="-1.1184673662158690996e-11" iyy="6.6367696417680293553e-06" iyz="1.0579908722588339983e-06" izz="8.9601142768980697473e-06" />
    </inertial>
  </link>

  <link name="spur_1m_24t_driven_3">
    <visual>
      <origin xyz="0 0 0" rpy="0 -0 0" />
      <geometry>
        <mesh filename="../assemblies/left_arm_hand/meshes/left_spur_1m_24t_driven_3_visual.stl" />
      </geometry>
      <material name="spur_1m_24t_driven_3_material">
        <color rgba="0.23137254901960788156 0.38039215686274502337 0.7058823529411765163 1.0" />
      </material>
    </visual>
    <inertial>
      <origin xyz="-2.522159886172245202e-17 -5.7992099762712231414e-15 -0.0025686634864003805856" rpy="0 0 0" />
      <mass value="0.0026999999999999997093" />
      <inertia ixx="1.2026541119643502094e-07" ixy="-2.9625477072638547111e-36" ixz="-1.5730367353383820857e-37" iyy="1.2026541119643483565e-07" iyz="1.1070062413737891266e-37" izz="2.2827257365099366486e-07" />
    </inertial>
  </link>

  <link name="2xl430_gears_3">
    <visual>
      <origin xyz="0 0 0" rpy="0 -0 0" />
      <geometry>
        <mesh filename="../assemblies/left_arm_hand/meshes/left_2xl430_gears_3_visual.stl" />
      </geometry>
      <material name="2xl430_gears_3_material">
        <color rgba="0.91900666046079226845 0.7025956886054134376 0.12479235365575504224 1.0" />
      </material>
    </visual>
    <inertial>
      <origin xyz="0.00044511655645805596948 0.011545548856396192772 -0.024422395554887000452" rpy="0 0 0" />
      <mass value="0.10921242823035924585" />
      <inertia ixx="3.3278157643469847388e-05" ixy="1.9126365494095211942e-08" ixz="6.1055425070499323398e-07" iyy="2.5633987199175328579e-05" iyz="9.2332485824892242159e-07" izz="3.0316164317561428263e-05" />
    </inertial>
  </link>

  <link name="spur_1m_24t_drive_3">
    <visual>
      <origin xyz="0 0 0" rpy="0 -0 0" />
      <geometry>
        <mesh filename="../assemblies/left_arm_hand/meshes/left_spur_1m_24t_drive_3_visual.stl" />
      </geometry>
      <material name="spur_1m_24t_drive_3_material">
        <color rgba="0.61568627450980406568 0.81176470588235294379 0.92941176470588238168 1.0" />
      </material>
    </visual>
    <inertial>
      <origin xyz="-7.7243545639883128529e-15 -1.2837900997641198244e-16 0.0047949116178401399516" rpy="0 0 0" />
      <mass value="0.0032000000000000001533" />
      <inertia ixx="1.4019331346159892996e-07" ixy="1.6002410041546426147e-15" ixz="-6.4318290562543542602e-36" iyy="1.4019331260388791479e-07" iyz="-3.5497739011481716373e-36" izz="2.3838919844264060647e-07" />
    </inertial>
  </link>

  <joint name="left_wrist_pitch_drive" type="revolute">
    <origin xyz="-1.5244678436276970501e-10 0.024000000358067485884 -0.0080000000000028173575" rpy="-6.0688227754444846318e-17 9.0954925662261794972e-16 -1.5707963267950935116" />
    <parent link="2xl430_gears_3" />
    <child link="spur_1m_24t_drive_3" />
    <axis xyz="0 0 1" />
    <limit effort="1" velocity="20" lower="-1.570796326794896558" upper="1.570796326794896558" />
    <joint_properties friction="0.0" />
  </joint>

  <link name="wrist_bearing_plate">
    <visual>
      <origin xyz="0 0 0" rpy="0 -0 0" />
      <geometry>
        <mesh filename="../assemblies/left_arm_hand/meshes/left_wrist_bearing_plate_visual.stl" />
      </geometry>
      <material name="wrist_bearing_plate_material">
        <color rgba="0.64496316278892629192 0.69011804996940528945 0.71706771073555874985 1.0" />
      </material>
    </visual>
    <inertial>
      <origin xyz="-0.0075896393545961445687 -0.015499999999999991215 -0.0018386110045718407138" rpy="0 0 0" />
      <mass value="0.0049000367468305539714" />
      <inertia ixx="4.9747313520140109893e-07" ixy="1.9458462399620376262e-22" ixz="1.8097509420524938529e-08" iyy="7.1295025627582449075e-07" iyz="2.3459445642475020808e-23" izz="1.192629795229191449e-06" />
    </inertial>
  </link>

  <joint name="left_wrist_roll_fixed" type="fixed">
    <origin xyz="0.015500000000005648149 -4.3853809472693683347e-15 -0.044999999999999262812" rpy="-1.5598633495994326207e-14 -1.730560139634137368e-13 -1.5707963267946343233" />
    <parent link="2xl430_gears_3" />
    <child link="wrist_bearing_plate" />
    <axis xyz="0 0 1" />
    <limit effort="1" velocity="20" />
    <joint_properties friction="0.0" />
  </joint>

  <link name="hand">
    <visual>
      <origin xyz="0 0 0" rpy="0 -0 0" />
      <geometry>
        <mesh filename="../assemblies/left_arm_hand/meshes/left_hand_visual.stl" />
      </geometry>
      <material name="hand_material">
        <color rgba="0.61568627450980395466 0.81176470588235294379 0.92941176470588238168 1.0" />
      </material>
    </visual>
    <inertial>
      <origin xyz="-4.3038382213741598201e-08 -0.049723778585225204829 -0.017933572005385655518" rpy="0 0 0" />
      <mass value="0.017000000000000004691" />
      <inertia ixx="9.4921414617707115536e-06" ixy="-1.554921589734161308e-11" ixz="-1.0809694196434974908e-11" iyy="4.0745028295219354634e-06" iyz="2.4719408559887990214e-07" izz="6.6623859522963546108e-06" />
    </inertial>
  </link>

  <joint name="left_wrist_roll" type="revolute">
    <origin xyz="0.019000000000001057709 -3.5807262710463305666e-10 -0.027000000152450100849" rpy="1.2848055952475997313e-13 1.5707963267946998265 0" />
    <parent link="2xl430_gears_3" />
    <child link="hand" />
    <axis xyz="0 0 1" />
    <limit effort="1" velocity="20" lower="-1.570796326794896558" upper="1.570796326794896558" />
    <joint_properties friction="0.0" />
  </joint>

  <joint name="left_wrist_pitch_driven" type="revolute">
    <origin xyz="-8.3266726846886740532e-17 5.4817261840867104183e-16 -0.0016000000000001152189" rpy="-5.7142471032373773212e-16 5.5511151217739912712e-17 -1.570796326794896336" />
    <parent link="spur_1m_24t_driven_3" />
    <child link="2xl430_gears_3" />
    <axis xyz="0 0 1" />
    <limit effort="1" velocity="20" lower="-1.570796326794896558" upper="1.570796326794896558" />
    <joint_properties friction="0.0" />
  </joint>

  <joint name="left_wrist_pitch_fixed" type="fixed">
    <origin xyz="2.0816681711721685133e-17 -0.025299999999999989164 -0.051999999999999990674" rpy="1.5707963267948958919 -1.570796326794896336 0" />
    <parent link="elb_yaw_link" />
    <child link="spur_1m_24t_driven_3" />
    <axis xyz="0 0 1" />
    <limit effort="1" velocity="20" />
    <joint_properties friction="0.0" />
  </joint>

  <joint name="left_elbow_yaw_fixed" type="fixed">
    <origin xyz="1.3097162243624893563e-16 6.2450045135165055399e-17 0.0015999999999997960298" rpy="-3.141592653589793116 -5.5511151231207524813e-17 -1.570796326794896336" />
    <parent link="spur_1m_24t_driven_2" />
    <child link="elb_yaw_link" />
    <axis xyz="0 0 1" />
    <limit effort="1" velocity="20" />
    <joint_properties friction="0.0" />
  </joint>

  <joint name="left_elbow_yaw_driven" type="revolute">
    <origin xyz="-3.5807262710463305666e-10 -0.027000000152449854518 -0.01900000000000161629" rpy="1.570796326794891673 1.5707963267948441555 0" />
    <parent link="2xl430_gears_2" />
    <child link="spur_1m_24t_driven_2" />
    <axis xyz="0 0 1" />
    <limit effort="1" velocity="20" lower="-3.141592653589793116" upper="3.141592653589793116" />
    <joint_properties friction="0.0" />
  </joint>

  <joint name="left_elbow_roll" type="revolute">
    <origin xyz="7.6327832942979512154e-17 -0.018999999999999992589 -0.059000000000000031586" rpy="1.570796326794896558 -7.0029629609134176679e-16 7.044195017682708143e-15" />
    <parent link="sho_yaw_link" />
    <child link="2xl430_gears_2" />
    <axis xyz="0 0 1" />
    <limit effort="1" velocity="20" lower="-1.570796326794896558" upper="1.570796326794896558" />
    <joint_properties friction="0.0" />
  </joint>

  <joint name="left_sho_yaw_fixed" type="fixed">
    <origin xyz="0 1.561251128379126385e-17 0.0015999999999999903189" rpy="-3.1415926535897922278 1.4418079614154122748e-16 -6.106226635437282205e-16" />
    <parent link="spur_1m_24t_driven" />
    <child link="sho_yaw_link" />
    <axis xyz="0 0 1" />
    <limit effort="1" velocity="20" />
    <joint_properties friction="0.0" />
  </joint>

  <joint name="left_sho_yaw_driven" type="revolute">
    <origin xyz="-3.5807536102883119611e-10 -0.027000000152448761642 -0.019000000000006084938" rpy="1.5707963267949398567 1.8984813721086286179e-14 -7.1310113557521486963e-14" />
    <parent link="2xl430_gears" />
    <child link="spur_1m_24t_driven" />
    <axis xyz="0 0 1" />
    <limit effort="1" velocity="20" lower="-3.141592653589793116" upper="3.141592653589793116" />
    <joint_properties friction="0.0" />
  </joint>

  <joint name="left_sho_roll" type="revolute">
    <origin xyz="-0.018999999999999992589 0.00099999999999997833677 0.026999999999999996225" rpy="-3.141592653589793116 1.5707963267948954478 0" />
    <parent link="sho_pitch_link" />
    <child link="2xl430_gears" />
    <axis xyz="0 0 1" />
    <limit effort="1" velocity="20" lower="-1.570796326794896558" upper="1.570796326794896558" />
    <joint_properties friction="0.0" />
  </joint>

  <joint name="left_sho_pitch" type="revolute">
    <origin xyz="-0.0039999999999985160273 0.012999999999999725317 -0.01424999999999848263" rpy="-1.5707963267948332753 -5.5178084323870191707e-14 -1.1649761152065636686e-13" />
    <parent link="xc430" />
    <child link="sho_pitch_link" />
    <axis xyz="0 0 1" />
    <limit effort="1" velocity="20" lower="-1.570796326794896558" upper="1.570796326794896558" />
    <joint_properties friction="0.0" />
  </joint>


  <link name="xc430_2">
    <visual>
      <origin xyz="0 0 0" rpy="0 -0 0" />
      <geometry>
        <mesh filename="../assemblies/right_arm_hand/meshes/right_xc430_visual.stl" />
      </geometry>
      <material name="xc430_material">
        <color rgba="0.3960334863748344314 0.50878377002232877402 0.71126755432153676573 1.0" />
      </material>
    </visual>
    <inertial>
      <origin xyz="0.0076499389484204942738 0.0056800345415021630258 -0.01424421865606324486" rpy="0 0 0" />
      <mass value="0.065021926915724281848" />
      <inertia ixx="1.0685477757330491194e-05" ixy="-2.499104872988050919e-08" ixz="4.3793050176100287021e-09" iyy="1.6030858372951945059e-05" iyz="-9.5846760479532371298e-09" izz="1.8186829094811067043e-05" />
    </inertial>
  </link>

  <link name="sho_pitch_link_2">
    <visual>
      <origin xyz="0 0 0" rpy="0 -0 0" />
      <geometry>
        <mesh filename="../assemblies/right_arm_hand/meshes/right_sho_pitch_link_visual.stl" />
      </geometry>
      <material name="sho_pitch_link_material">
        <color rgba="0.61568627450980395466 0.81176470588235294379 0.92941176470588238168 1.0" />
      </material>
    </visual>
    <inertial>
      <origin xyz="5.825424752983753426e-11 -5.1264642561120999623e-05 0.0082440788127094953575" rpy="0 0 0" />
      <mass value="0.008600000000000003475" />
      <inertia ixx="1.2272887040545802461e-06" ixy="-2.1429944201915424219e-14" ixz="-8.5847198540427074509e-15" iyy="2.9107306060364628558e-06" iyz="7.4623841398183100553e-09" izz="3.0803135950773496163e-06" />
    </inertial>
  </link>

  <link name="2xl430_gears_4">
    <visual>
      <origin xyz="0 0 0" rpy="0 -0 0" />
      <geometry>
        <mesh filename="../assemblies/right_arm_hand/meshes/right_2xl430_gears_visual.stl" />
      </geometry>
      <material name="2xl430_gears_material">
        <color rgba="0.91900666046079226845 0.7025956886054134376 0.12479235365575504224 1.0" />
      </material>
    </visual>
    <inertial>
      <origin xyz="-0.011545549214474582628 -0.0025776045975625170963 -0.01855488344354406377" rpy="0 0 0" />
      <mass value="0.10921242823035924585" />
      <inertia ixx="2.5633987199174718716e-05" ixy="9.2332485824708510125e-07" ixz="-1.9126365491687785487e-08" iyy="3.0316164317562065231e-05" iyz="-6.1055425070399691147e-07" izz="3.327815764346926463e-05" />
    </inertial>
  </link>

  <link name="spur_1m_24t_drive_4">
    <visual>
      <origin xyz="0 0 0" rpy="0 -0 0" />
      <geometry>
        <mesh filename="../assemblies/right_arm_hand/meshes/right_spur_1m_24t_drive_visual.stl" />
      </geometry>
      <material name="spur_1m_24t_drive_material">
        <color rgba="0.61568627450980406568 0.81176470588235294379 0.92941176470588238168 1.0" />
      </material>
    </visual>
    <inertial>
      <origin xyz="-7.7521101396039417664e-15 -1.2057275433451556166e-16 0.0047949116178401512273" rpy="0 0 0" />
      <mass value="0.0032000000000000001533" />
      <inertia ixx="1.4019331346159887702e-07" ixy="1.6002410000914703581e-15" ixz="-5.4090992845575242873e-36" iyy="1.4019331260388783538e-07" iyz="-6.8087356421599067805e-36" izz="2.3838919844264071235e-07" />
    </inertial>
  </link>

  <joint name="right_sho_yaw_drive" type="revolute">
    <origin xyz="-0.024000000716145303281 -0.01900000015244998619 -0.01900000015244465365" rpy="1.5707963267947440134 8.8389520895546782802e-14 1.3333206406916649652e-13" />
    <parent link="2xl430_gears_4" />
    <child link="spur_1m_24t_drive_4" />
    <axis xyz="0 0 1" />
    <limit effort="1" velocity="20" lower="-3.141592653589793116" upper="3.141592653589793116" />
    <joint_properties friction="0.0" />
  </joint>

  <link name="spur_1m_24t_driven_4">
    <visual>
      <origin xyz="0 0 0" rpy="0 -0 0" />
      <geometry>
        <mesh filename="../assemblies/right_arm_hand/meshes/right_spur_1m_24t_driven_visual.stl" />
      </geometry>
      <material name="spur_1m_24t_driven_material">
        <color rgba="0.23137254901960788156 0.38039215686274502337 0.7058823529411765163 1.0" />
      </material>
    </visual>
    <inertial>
      <origin xyz="2.5339767539064826755e-18 -5.7992099762712231414e-15 -0.00096866348640038332785" rpy="0 0 0" />
      <mass value="0.0026999999999999997093" />
      <inertia ixx="1.2026541119643502094e-07" ixy="3.0132909596002639219e-36" ixz="-9.0037654543726475118e-38" iyy="1.2026541119643483565e-07" iyz="0" izz="2.2827257365099366486e-07" />
    </inertial>
  </link>

  <link name="sho_yaw_link_2">
    <visual>
      <origin xyz="0 0 0" rpy="0 -0 0" />
      <geometry>
        <mesh filename="../assemblies/right_arm_hand/meshes/right_sho_yaw_link_visual.stl" />
      </geometry>
      <material name="sho_yaw_link_material">
        <color rgba="0.61568627450980395466 0.81176470588235294379 0.92941176470588238168 1.0" />
      </material>
    </visual>
    <inertial>
      <origin xyz="-1.1573942515719257393e-18 3.8649239170559342289e-18 -0.024214576156328385809" rpy="0 0 0" />
      <mass value="0.014499999999999986858" />
      <inertia ixx="9.0490855102914890835e-06" ixy="3.5997729401745807688e-13" ixz="1.7587891974902210219e-36" iyy="5.6767199180624668202e-06" iyz="0" izz="4.4590603637468091569e-06" />
    </inertial>
  </link>

  <link name="2xl430_gears_5">
    <visual>
      <origin xyz="0 0 0" rpy="0 -0 0" />
      <geometry>
        <mesh filename="../assemblies/right_arm_hand/meshes/right_2xl430_gears_2_visual.stl" />
      </geometry>
      <material name="2xl430_gears_2_material">
        <color rgba="0.91900666046079226845 0.7025956886054134376 0.12479235365575504224 1.0" />
      </material>
    </visual>
    <inertial>
      <origin xyz="-0.011545549214473463731 -0.0025776045975580215604 -0.018554883443548501193" rpy="0 0 0" />
      <mass value="0.10921242823035924585" />
      <inertia ixx="2.5633987199173058531e-05" ixy="9.2332485824729887119e-07" ixz="-1.9126365492406122366e-08" iyy="3.0316164317562349835e-05" iyz="-6.1055425070545116116e-07" izz="3.3278157643466920043e-05" />
    </inertial>
  </link>

  <link name="spur_1m_24t_drive_5">
    <visual>
      <origin xyz="0 0 0" rpy="0 -0 0" />
      <geometry>
        <mesh filename="../assemblies/right_arm_hand/meshes/right_spur_1m_24t_drive_2_visual.stl" />
      </geometry>
      <material name="spur_1m_24t_drive_2_material">
        <color rgba="0.61568627450980406568 0.81176470588235294379 0.92941176470588238168 1.0" />
      </material>
    </visual>
    <inertial>
      <origin xyz="-7.7659879274117562231e-15 -1.2057275433451595609e-16 0.0047949116178401382168" rpy="0 0 0" />
      <mass value="0.0032000000000000001533" />
      <inertia ixx="1.4019331346159887702e-07" ixy="1.6002410041546426147e-15" ixz="-3.624182631715073592e-36" iyy="1.4019331260388791479e-07" iyz="-4.1524596034726495678e-37" izz="2.3838919844264060647e-07" />
    </inertial>
  </link>

  <joint name="right_elbow_yaw_drive" type="revolute">
    <origin xyz="-0.024000000716140640344 -0.019000000152444435075 -0.019000000152454357694" rpy="1.5707963267949622832 8.194034361146178641e-14 -1.7317067989020890092e-13" />
    <parent link="2xl430_gears_5" />
    <child link="spur_1m_24t_drive_5" />
    <axis xyz="0 0 1" />
    <limit effort="1" velocity="20" lower="-3.141592653589793116" upper="3.141592653589793116" />
    <joint_properties friction="0.0" />
  </joint>

  <link name="spur_1m_24t_driven_5">
    <visual>
      <origin xyz="0 0 0" rpy="0 -0 0" />
      <geometry>
        <mesh filename="../assemblies/right_arm_hand/meshes/right_spur_1m_24t_driven_2_visual.stl" />
      </geometry>
      <material name="spur_1m_24t_driven_2_material">
        <color rgba="0.23137254901960788156 0.38039215686274502337 0.7058823529411765163 1.0" />
      </material>
    </visual>
    <inertial>
      <origin xyz="2.5339767539064915348e-18 -5.7992099762712231414e-15 -0.00096866348640037638895" rpy="0 0 0" />
      <mass value="0.0026999999999999997093" />
      <inertia ixx="1.2026541119643502094e-07" ixy="-2.2321759283396738301e-36" ixz="0" iyy="1.2026541119643483565e-07" iyz="0" izz="2.2827257365099366486e-07" />
    </inertial>
  </link>

  <link name="elb_yaw_link_2">
    <visual>
      <origin xyz="0 0 0" rpy="0 -0 0" />
      <geometry>
        <mesh filename="../assemblies/right_arm_hand/meshes/right_elb_yaw_link_visual.stl" />
      </geometry>
      <material name="elb_yaw_link_material">
        <color rgba="0.61568627450980395466 0.81176470588235294379 0.92941176470588227065 1.0" />
      </material>
    </visual>
    <inertial>
      <origin xyz="5.287088917269459775e-08 0.0019873558182742479504 -0.023365661199828736266" rpy="0 0 0" />
      <mass value="0.017500000000000001665" />
      <inertia ixx="1.4097804991252558057e-05" ixy="1.6900809684051191583e-12" ixz="-1.1184673662158687765e-11" iyy="6.6367696417680293553e-06" iyz="1.0579908722588337865e-06" izz="8.9601142768980663591e-06" />
    </inertial>
  </link>

  <link name="spur_1m_24t_driven_6">
    <visual>
      <origin xyz="0 0 0" rpy="0 -0 0" />
      <geometry>
        <mesh filename="../assemblies/right_arm_hand/meshes/right_spur_1m_24t_driven_3_visual.stl" />
      </geometry>
      <material name="spur_1m_24t_driven_3_material">
        <color rgba="0.23137254901960788156 0.38039215686274502337 0.7058823529411765163 1.0" />
      </material>
    </visual>
    <inertial>
      <origin xyz="2.5339767539064672681e-18 -5.8061488701751303698e-15 -0.0025686634864003771161" rpy="0 0 0" />
      <mass value="0.0026999999999999997093" />
      <inertia ixx="1.2026541119643502094e-07" ixy="-8.8943138390222300706e-38" ixz="-3.4871107238620772993e-37" iyy="1.2026541119643483565e-07" iyz="3.5770621358774076477e-36" izz="2.2827257365099366486e-07" />
    </inertial>
  </link>

  <link name="2xl430_gears_6">
    <visual>
      <origin xyz="0 0 0" rpy="0 -0 0" />
      <geometry>
        <mesh filename="../assemblies/right_arm_hand/meshes/right_2xl430_gears_3_visual.stl" />
      </geometry>
      <material name="2xl430_gears_3_material">
        <color rgba="0.91900666046079226845 0.7025956886054134376 0.12479235365575504224 1.0" />
      </material>
    </visual>
    <inertial>
      <origin xyz="0.00044511655645500768086 0.011545548856405010371 -0.024422395554887468827" rpy="0 0 0" />
      <mass value="0.10921242823035924585" />
      <inertia ixx="3.3278157643468370163e-05" ixy="1.9126365492366470636e-08" ixz="6.1055425070389431461e-07" iyy="2.5633987199173590468e-05" iyz="9.2332485824554837172e-07" izz="3.0316164317561851779e-05" />
    </inertial>
  </link>

  <link name="spur_1m_24t_drive_6">
    <visual>
      <origin xyz="0 0 0" rpy="0 -0 0" />
      <geometry>
        <mesh filename="../assemblies/right_arm_hand/meshes/right_spur_1m_24t_drive_3_visual.stl" />
      </geometry>
      <material name="spur_1m_24t_drive_3_material">
        <color rgba="0.61568627450980406568 0.81176470588235294379 0.92941176470588238168 1.0" />
      </material>
    </visual>
    <inertial>
      <origin xyz="-7.7798657152195722576e-15 -1.2837900997641119358e-16 0.0047949116178401416863" rpy="0 0 0" />
      <mass value="0.0032000000000000001533" />
      <inertia ixx="1.4019331346159892996e-07" ixy="1.6002410033435796138e-15" ixz="1.8689311580061739594e-36" iyy="1.4019331260388783538e-07" iyz="1.2273789032714357933e-37" izz="2.3838919844264060647e-07" />
    </inertial>
  </link>

  <joint name="right_wrist_pitch_drive" type="revolute">
    <origin xyz="-1.5244812356929315911e-10 0.024000000358072565154 -0.0079999999999997069983" rpy="3.0683701463333139415e-15 3.000158893453974941e-16 -1.5707963267949427433" />
    <parent link="2xl430_gears_6" />
    <child link="spur_1m_24t_drive_6" />
    <axis xyz="0 0 1" />
    <limit effort="1" velocity="20" lower="-1.570796326794896558" upper="1.570796326794896558" />
    <joint_properties friction="0.0" />
  </joint>

  <link name="wrist_bearing_plate_2">
    <visual>
      <origin xyz="0 0 0" rpy="0 -0 0" />
      <geometry>
        <mesh filename="../assemblies/right_arm_hand/meshes/right_wrist_bearing_plate_visual.stl" />
      </geometry>
      <material name="wrist_bearing_plate_material">
        <color rgba="0.64496316278892629192 0.69011804996940528945 0.71706771073555874985 1.0" />
      </material>
    </visual>
    <inertial>
      <origin xyz="-0.0075896393545961402319 -0.015499999999999991215 -0.0018386110045718361602" rpy="0 0 0" />
      <mass value="0.0049000367468305539714" />
      <inertia ixx="4.9747313520140120481e-07" ixy="1.4311016266183815911e-23" ixz="1.8097509420524783019e-08" iyy="7.129502562758232202e-07" iyz="1.3422300279367577938e-23" izz="1.192629795229189755e-06" />
    </inertial>
  </link>

  <joint name="right_wrist_roll_fixed" type="fixed">
    <origin xyz="0.015499999999999309469 5.6343818499726694426e-15 -0.045000000000002496336" rpy="-3.8857806018810176234e-16 1.2034817586933650002e-13 -1.5707963267948996666" />
    <parent link="2xl430_gears_6" />
    <child link="wrist_bearing_plate_2" />
    <axis xyz="0 0 1" />
    <limit effort="1" velocity="20" />
    <joint_properties friction="0.0" />
  </joint>

  <link name="hand_2">
    <visual>
      <origin xyz="0 0 0" rpy="0 -0 0" />
      <geometry>
        <mesh filename="../assemblies/right_arm_hand/meshes/right_hand_visual.stl" />
      </geometry>
      <material name="hand_material">
        <color rgba="0.61568627450980395466 0.81176470588235294379 0.92941176470588238168 1.0" />
      </material>
    </visual>
    <inertial>
      <origin xyz="-4.3038382212874236463e-08 0.049723778585225232585 -0.020066427994614347008" rpy="0 0 0" />
      <mass value="0.017000000000000004691" />
      <inertia ixx="9.4921414617707115536e-06" ixy="1.554921589734161308e-11" ixz="1.0809694196434976524e-11" iyy="4.0745028295219354634e-06" iyz="2.4719408559887995508e-07" izz="6.6623859522963579989e-06" />
    </inertial>
  </link>

  <joint name="right_wrist_roll" type="revolute">
    <origin xyz="0.018999999999997782552 -3.5806707598950993088e-10 -0.027000000152450402691" rpy="-3.1415926535897886751 -1.5707963267947642194 0" />
    <parent link="2xl430_gears_6" />
    <child link="hand_2" />
    <axis xyz="0 0 1" />
    <limit effort="1" velocity="20" lower="-1.570796326794896558" upper="1.570796326794896558" />
    <joint_properties friction="0.0" />
  </joint>

  <joint name="right_wrist_pitch_driven" type="revolute">
    <origin xyz="-2.7755575615628913511e-17 6.9388939039072283776e-18 -0.0016000000000002227718" rpy="-4.5800957231150559108e-15 -6.2172489379009776006e-15 1.570796326794896558" />
    <parent link="spur_1m_24t_driven_6" />
    <child link="2xl430_gears_6" />
    <axis xyz="0 0 1" />
    <limit effort="1" velocity="20" lower="-1.570796326794896558" upper="1.570796326794896558" />
    <joint_properties friction="0.0" />
  </joint>

  <joint name="right_wrist_pitch_fixed" type="fixed">
    <origin xyz="0 -0.025299999999999996103 -0.052000000000000046185" rpy="1.5707963267948905628 1.5707963267948905628 0" />
    <parent link="elb_yaw_link_2" />
    <child link="spur_1m_24t_driven_6" />
    <axis xyz="0 0 1" />
    <limit effort="1" velocity="20" />
    <joint_properties friction="0.0" />
  </joint>

  <joint name="right_elbow_yaw_fixed" type="fixed">
    <origin xyz="-6.9388939039072283776e-18 0 0.0015999999999999903189" rpy="-3.141592653589793116 -2.2204460328203446248e-16 -3.141592653589793116" />
    <parent link="spur_1m_24t_driven_5" />
    <child link="elb_yaw_link_2" />
    <axis xyz="0 0 1" />
    <limit effort="1" velocity="20" />
    <joint_properties friction="0.0" />
  </joint>

  <joint name="right_elbow_yaw_driven" type="revolute">
    <origin xyz="-3.5806981685260197423e-10 -0.027000000152445247092 -0.019000000000004103884" rpy="-1.5707963267950058039 5.9602610059045593461e-15 3.1415926535897913396" />
    <parent link="2xl430_gears_5" />
    <child link="spur_1m_24t_driven_5" />
    <axis xyz="0 0 1" />
    <limit effort="1" velocity="20" lower="-3.141592653589793116" upper="3.141592653589793116" />
    <joint_properties friction="0.0" />
  </joint>

  <joint name="right_elbow_roll" type="revolute">
    <origin xyz="1.3183898417423733918e-16 -0.018999999999999933609 -0.059000000000000038525" rpy="1.570796326794896558 -2.6733818545004476465e-15 -6.1232339957031568635e-17" />
    <parent link="sho_yaw_link_2" />
    <child link="2xl430_gears_5" />
    <axis xyz="0 0 1" />
    <limit effort="1" velocity="20" lower="-1.570796326794896558" upper="1.570796326794896558" />
    <joint_properties friction="0.0" />
  </joint>

  <joint name="right_sho_yaw_fixed" type="fixed">
    <origin xyz="-6.9388939039072283776e-18 -8.6736173798840354721e-19 0.0016000000000000041966" rpy="-3.141592653589793116 -3.0292258760486853328e-28 -8.5559900487112566884e-29" />
    <parent link="spur_1m_24t_driven_4" />
    <child link="sho_yaw_link_2" />
    <axis xyz="0 0 1" />
    <limit effort="1" velocity="20" />
    <joint_properties friction="0.0" />
  </joint>

  <joint name="right_sho_yaw_driven" type="revolute">
    <origin xyz="-3.5807402876120164592e-10 -0.027000000152449625535 -0.019000000000000287492" rpy="1.5707963267948759079 -1.13931263975872123e-27 -4.4614134174147354846e-14" />
    <parent link="2xl430_gears_4" />
    <child link="spur_1m_24t_driven_4" />
    <axis xyz="0 0 1" />
    <limit effort="1" velocity="20" lower="-3.141592653589793116" upper="3.141592653589793116" />
    <joint_properties friction="0.0" />
  </joint>

  <joint name="right_sho_roll" type="revolute">
    <origin xyz="-0.018999999999999999528 0.0010000000000000251743 0.026999999999999996225" rpy="3.141592653589793116 1.570796326794896558 0" />
    <parent link="sho_pitch_link_2" />
    <child link="2xl430_gears_4" />
    <axis xyz="0 0 1" />
    <limit effort="1" velocity="20" lower="-1.570796326794896558" upper="1.570796326794896558" />
    <joint_properties friction="0.0" />
  </joint>

  <joint name="right_sho_pitch" type="revolute">
    <origin xyz="-0.0039999999999983789842 -0.012999999999999045305 -0.014250000000000390826" rpy="-1.5707963267949442976 1.6903145549952781317e-14 -3.1415926535895994931" />
    <parent link="xc430_2" />
    <child link="sho_pitch_link_2" />
    <axis xyz="0 0 1" />
    <limit effort="1" velocity="20" lower="-1.570796326794896558" upper="1.570796326794896558" />
    <joint_properties friction="0.0" />
  </joint>


</robot>