<robot name="toddlerbot">
  <mujoco>
    <compiler strippath="false" balanceinertia="true" discardvisual="false" />
  </mujoco>
  <link name="torso">
    <visual>
      <origin xyz="0 0 0" rpy="0 -0 0" />
      <geometry>
        <mesh filename="../assemblies/toddlerbot/meshes/torso_visual.stl" />
      </geometry>
      <material name="torso_material">
        <color rgba="0.58602628355191022091 0.73205173766587605666 0.84624015779321404285 1.0" />
      </material>
    </visual>
    <collision>
      <origin xyz="0 0 0" rpy="0 -0 0" />
      <geometry>
        <mesh filename="collisions/torso_collision.stl" />
      </geometry>
    </collision>
    <inertial>
      <origin xyz="-0.0074328354797873951929 0.0025059801105640597436 0.073401015491149051995" rpy="0 0 0" />
      <mass value="0.5849052174992360742" />
      <inertia ixx="0.001616819104734650665" ixy="-1.4736281865313569496e-05" ixz="3.2221053182212498246e-07" iyy="0.001310156579434457267" iyz="2.4169833425786298821e-05" izz="0.0011896913602930953707" />
    </inertial>
  </link>

  <link name="spur_1m_20t">
    <visual>
      <origin xyz="0 0 0" rpy="0 -0 0" />
      <geometry>
        <mesh filename="../assemblies/toddlerbot/meshes/spur_1m_20t_visual.stl" />
      </geometry>
      <material name="spur_1m_20t_material">
        <color rgba="0.64705882352941179736 0.64705882352941179736 0.64705882352941179736 1.0" />
      </material>
    </visual>
    <inertial>
      <origin xyz="-5.3890758640437683033e-18 5.8683689274605119589e-18 -0.0033745971730663147647" rpy="0 0 0" />
      <mass value="0.0015534950290892286448" />
      <inertia ixx="4.4726508287871799621e-08" ixy="5.2024693257554525847e-24" ixz="2.7597381312606821682e-39" iyy="4.4726508287871786386e-08" iyz="-4.880475641083095171e-38" izz="7.9558906764902006609e-08" />
    </inertial>
  </link>

  <joint name="neck_yaw_drive" type="revolute">
    <origin xyz="-0.004999999999999059884 -1.8020791195763170554e-16 0.12248651076281816263" rpy="-3.1415926535897913396 1.7995135580561967136e-15 9.6455933634066887197e-16" />
    <parent link="torso" />
    <child link="spur_1m_20t" />
    <axis xyz="0 0 1" />
    <limit effort="1" velocity="20" lower="-3.141592653589793116" upper="3.141592653589793116" />
    <joint_properties friction="0.0" />
  </joint>

  <link name="neck_yaw_link">
    <visual>
      <origin xyz="0 0 0" rpy="0 -0 0" />
      <geometry>
        <mesh filename="../assemblies/toddlerbot/meshes/neck_yaw_link_visual.stl" />
      </geometry>
      <material name="neck_yaw_link_material">
        <color rgba="0.33636252417476664167 0.48680769190259887136 0.74976123534949801197 1.0" />
      </material>
    </visual>
    <inertial>
      <origin xyz="2.7291286461155648901e-05 0.00019798992283532579318 -0.011527412037194841726" rpy="0 0 0" />
      <mass value="0.0085168305947458250449" />
      <inertia ixx="1.0407116999274142848e-06" ixy="-2.4210150466643223747e-11" ixz="4.7246803218799873965e-10" iyy="1.1240009954110278886e-06" iyz="3.0834841754638146793e-08" izz="3.1587565167291907172e-07" />
    </inertial>
  </link>

  <link name="neck_pitch_link">
    <visual>
      <origin xyz="0 0 0" rpy="0 -0 0" />
      <geometry>
        <mesh filename="../assemblies/toddlerbot/meshes/neck_pitch_link_visual.stl" />
      </geometry>
      <material name="neck_pitch_link_material">
        <color rgba="0.74911126277760042846 0.80002799398726853752 0.87441258869524285391 1.0" />
      </material>
    </visual>
    <collision>
      <origin xyz="0 0 0" rpy="0 -0 0" />
      <geometry>
        <mesh filename="collisions/neck_pitch_link_collision.stl" />
      </geometry>
    </collision>
    <inertial>
      <origin xyz="-0.003437049761571804498 -0.032876793988991417916 0.00036476492134716469217" rpy="0 0 0" />
      <mass value="0.11211553874797881847" />
      <inertia ixx="7.7015755459849957677e-05" ixy="2.1757968319820868784e-06" ixz="2.8732209413521026174e-06" iyy="6.3502636688155217164e-05" iyz="-1.2492352737635673663e-05" izz="2.8610002383974706596e-05" />
    </inertial>
  </link>

  <link name="spur_gear_(13_teeth)">
    <visual>
      <origin xyz="0 0 0" rpy="0 -0 0" />
      <geometry>
        <mesh filename="../assemblies/toddlerbot/meshes/spur_gear_(13_teeth)_visual.stl" />
      </geometry>
      <material name="spur_gear_(13_teeth)_material">
        <color rgba="0.64705882352941179736 0.64705882352941179736 0.64705882352941179736 1.0" />
      </material>
    </visual>
    <inertial>
      <origin xyz="1.0399873341600411655e-09 2.3905206815959089847e-10 -0.0092751511485596356554" rpy="0 0 0" />
      <mass value="0.00081469437497230855032" />
      <inertia ixx="2.0244839552178298687e-08" ixy="-2.9046301772392211175e-15" ixz="8.2976066069498047887e-15" iyy="2.0244841689973771385e-08" iyz="-1.3142117784749194552e-15" izz="1.8905472907863310999e-08" />
    </inertial>
  </link>

  <joint name="neck_pitch_drive" type="revolute">
    <origin xyz="-1.4571677198205179593e-16 -0.015650000000000330314 0.0087999999999993777644" rpy="-2.1434555572207676319e-16 -1.5880065549567459396e-15 1.570796326794896558" />
    <parent link="neck_pitch_link" />
    <child link="spur_gear_(13_teeth)" />
    <axis xyz="0 0 1" />
    <limit effort="1" velocity="20" lower="-1.570796326794896558" upper="1.570796326794896558" />
    <joint_properties friction="0.0" />
  </joint>

  <joint name="neck_pitch_driven" type="revolute">
    <origin xyz="3.7500078736707465055e-10 0.0051500000614755261225 -0.027499999999999941158" rpy="1.570796326794896558 7.3154045537456631165e-17 -3.141592653589793116" />
    <parent link="neck_yaw_link" />
    <child link="neck_pitch_link" />
    <axis xyz="0 0 1" />
    <limit effort="1" velocity="20" lower="-1.570796326794896558" upper="1.570796326794896558" />
    <joint_properties friction="0.0" />
  </joint>

  <joint name="neck_yaw_driven" type="revolute">
    <origin xyz="0.016000000000001915468 1.75992996990887874e-17 0.12348651076281796923" rpy="3.141592653589793116 -1.8665960714277032613e-15 -3.141592653589793116" />
    <parent link="torso" />
    <child link="neck_yaw_link" />
    <axis xyz="0 0 1" />
    <limit effort="1" velocity="20" lower="-3.141592653589793116" upper="3.141592653589793116" />
    <joint_properties friction="0.0" />
  </joint>

  <link name="waist_gears">
    <visual>
      <origin xyz="0 0 0" rpy="0 -0 0" />
      <geometry>
        <mesh filename="../assemblies/toddlerbot/meshes/waist_gears_visual.stl" />
      </geometry>
      <material name="waist_gears_material">
        <color rgba="0.2705751638183052088 0.53648836590125015267 0.70305495274644791426 1.0" />
      </material>
    </visual>
    <inertial>
      <origin xyz="6.5469454461777740587e-08 5.6785896935447445789e-10 0.012726165583898670086" rpy="0 0 0" />
      <mass value="0.023315805669179824611" />
      <inertia ixx="6.9043104388291792625e-06" ixy="1.8428638770370908087e-11" ixz="-9.9668712552151659918e-13" iyy="1.1624091971676391391e-06" iyz="-3.3260430299263522616e-10" izz="6.8701920560919723979e-06" />
    </inertial>
  </link>

  <link name="waist_link">
    <visual>
      <origin xyz="0 0 0" rpy="0 -0 0" />
      <geometry>
        <mesh filename="../assemblies/toddlerbot/meshes/waist_link_visual.stl" />
      </geometry>
      <material name="waist_link_material">
        <color rgba="0.63401200025306059249 0.68204699127249923674 0.6691019398503622595 1.0" />
      </material>
    </visual>
    <collision>
      <origin xyz="0 0 0" rpy="0 -0 0" />
      <geometry>
        <mesh filename="collisions/waist_link_collision.stl" />
      </geometry>
    </collision>
    <inertial>
      <origin xyz="-9.1086191307873980818e-07 0.026204483755308483062 -0.030190392008842579369" rpy="0 0 0" />
      <mass value="0.16631953490612461088" />
      <inertia ixx="6.8622997376114865196e-05" ixy="-6.1328048292105499562e-10" ixz="-3.678679202726610035e-06" iyy="0.00020057117429216598744" iyz="-3.7255079147360503126e-06" izz="0.00015770127977213013195" />
    </inertial>
  </link>

  <link name="spiral_bevel_1m_14t_30deg">
    <visual>
      <origin xyz="0 0 0" rpy="0 -0 0" />
      <geometry>
        <mesh filename="../assemblies/toddlerbot/meshes/spiral_bevel_1m_14t_30deg_visual.stl" />
      </geometry>
      <material name="spiral_bevel_1m_14t_30deg_material">
        <color rgba="0.64705882352941179736 0.64705882352941179736 0.64705882352941179736 1.0" />
      </material>
    </visual>
    <inertial>
      <origin xyz="8.2641075406508779366e-10 3.4055789742068460039e-10 0.0068612577407481598057" rpy="0 0 0" />
      <mass value="0.00067997563436136235649" />
      <inertia ixx="1.2174575798018973838e-08" ixy="3.8216074570373192531e-18" ixz="4.7204547840164412653e-16" iyy="1.2174575801813732727e-08" iyz="-2.6184097788467663355e-16" izz="1.3178653206314315019e-08" />
    </inertial>
  </link>

  <joint name="waist_act_1" type="revolute">
    <origin xyz="-6.2837407918937052528e-16 0.01959999999999966977 -0.012749999999999159575" rpy="1.570796326794896558 1.570796326794493103 0" />
    <parent link="waist_link" />
    <child link="spiral_bevel_1m_14t_30deg" />
    <axis xyz="0 0 1" />
    <limit effort="1" velocity="20" lower="-2.7925268031909271649" upper="2.7925268031909271649" />
    <joint_properties friction="0.0" />
  </joint>

  <link name="spiral_bevel_1m_14t_30deg_2">
    <visual>
      <origin xyz="0 0 0" rpy="0 -0 0" />
      <geometry>
        <mesh filename="../assemblies/toddlerbot/meshes/spiral_bevel_1m_14t_30deg_2_visual.stl" />
      </geometry>
      <material name="spiral_bevel_1m_14t_30deg_2_material">
        <color rgba="0.64705882352941179736 0.64705882352941179736 0.64705882352941179736 1.0" />
      </material>
    </visual>
    <inertial>
      <origin xyz="7.2990964834762639413e-10 5.159130923874479157e-10 0.0068612577407481667446" rpy="0 0 0" />
      <mass value="0.00067997563436136235649" />
      <inertia ixx="1.2174575796548746326e-08" ixy="2.6199065386911604042e-18" ixz="5.1847541165558655682e-16" iyy="1.2174575803283978437e-08" iyz="-1.5023607716950052919e-16" izz="1.3178653206314315019e-08" />
    </inertial>
  </link>

  <joint name="waist_act_2" type="revolute">
    <origin xyz="1.7857132216672699403e-18 0.019600000000000002837 -0.03275000000000001521" rpy="1.5707963267948883423 1.3463968515392001901 -8.4737581302220905773e-15" />
    <parent link="waist_link" />
    <child link="spiral_bevel_1m_14t_30deg_2" />
    <axis xyz="0 0 1" />
    <limit effort="1" velocity="20" lower="-2.7925268031909271649" upper="2.7925268031909271649" />
    <joint_properties friction="0.0" />
  </joint>

  <link name="spur_gear_19_teeth">
    <visual>
      <origin xyz="0 0 0" rpy="0 -0 0" />
      <geometry>
        <mesh filename="../assemblies/toddlerbot/meshes/spur_gear_19_teeth_visual.stl" />
      </geometry>
      <material name="spur_gear_19_teeth_material">
        <color rgba="0.61568627450980395466 0.81176470588235294379 0.92941176470588238168 1.0" />
      </material>
    </visual>
    <inertial>
      <origin xyz="-4.9156135418512965894e-09 9.0060873697348523604e-10 -0.0045295192537419875708" rpy="0 0 0" />
      <mass value="0.0010993711450650533144" />
      <inertia ixx="2.9215018435433095279e-08" ixy="2.590331374580708277e-16" ixz="-8.4242612452402814292e-15" iyy="2.921502154003405516e-08" iyz="1.5226232385810775537e-15" izz="4.5709977027671374883e-08" />
    </inertial>
  </link>

  <joint name="left_hip_yaw_drive" type="revolute">
    <origin xyz="-0.0369999999999981663 0.037100000000004268452 -0.039500000000001450617" rpy="1.5707963267947455677 -6.8515340787203273188e-13 -2.5801190558218208173e-13" />
    <parent link="waist_link" />
    <child link="spur_gear_19_teeth" />
    <axis xyz="0 0 1" />
    <limit effort="1" velocity="20" lower="-1.570796326794896558" upper="1.570796326794896558" />
    <joint_properties friction="0.0" />
  </joint>

  <link name="spur_gear_21_teeth">
    <visual>
      <origin xyz="0 0 0" rpy="0 -0 0" />
      <geometry>
        <mesh filename="../assemblies/toddlerbot/meshes/spur_gear_21_teeth_visual.stl" />
      </geometry>
      <material name="spur_gear_21_teeth_material">
        <color rgba="0.61568627450980395466 0.81176470588235294379 0.92941176470588238168 1.0" />
      </material>
    </visual>
    <inertial>
      <origin xyz="-4.7814841807291116546e-10 1.261015606518316409e-12 -0.0024944618616143296973" rpy="0 0 0" />
      <mass value="0.0010063046528317972673" />
      <inertia ixx="3.1842855421068488283e-08" ixy="2.3102497982291840404e-37" ixz="3.9865261597844170004e-39" iyy="3.1842855426953792314e-08" iyz="8.4454990525371346054e-39" izz="5.9529380586728047984e-08" />
    </inertial>
  </link>

  <joint name="left_leg_fixed" type="fixed">
    <origin xyz="-4.336808689942017736e-19 0 -0.004999999999999997502" rpy="3.9256239966020548641e-16 6.0371007920787862203e-16 5.9674487573614440696e-16" />
    <parent link="spur_gear_21_teeth" />
    <child link="hip_yaw_link" />
    <axis xyz="0 0 1" />
    <limit effort="1" velocity="20" />
    <joint_properties friction="0.0" />
  </joint>

  <joint name="left_hip_yaw_driven" type="revolute">
    <origin xyz="-0.03699999999999998429 0.041100000000000011524 -0.019499999999999999972" rpy="1.5707963267948956698 -1.5707963267948861219 0" />
    <parent link="waist_link" />
    <child link="spur_gear_21_teeth" />
    <axis xyz="0 0 1" />
    <limit effort="1" velocity="20" lower="-1.570796326794896558" upper="1.570796326794896558" />
    <joint_properties friction="0.0" />
  </joint>

  <link name="spur_gear_19_teeth_2">
    <visual>
      <origin xyz="0 0 0" rpy="0 -0 0" />
      <geometry>
        <mesh filename="../assemblies/toddlerbot/meshes/spur_gear_19_teeth_2_visual.stl" />
      </geometry>
      <material name="spur_gear_19_teeth_2_material">
        <color rgba="0.61568627450980395466 0.81176470588235294379 0.92941176470588238168 1.0" />
      </material>
    </visual>
    <inertial>
      <origin xyz="-4.9156135418512965894e-09 9.0060873697348523604e-10 -0.0045295192537419945097" rpy="0 0 0" />
      <mass value="0.0010993711450650533144" />
      <inertia ixx="2.9215018435433095279e-08" ixy="2.5903313731232818381e-16" ixz="-8.4242612452402814292e-15" iyy="2.9215021540034061777e-08" iyz="1.5226232385810777509e-15" izz="4.5709977027671374883e-08" />
    </inertial>
  </link>

  <joint name="right_hip_yaw_drive" type="revolute">
    <origin xyz="0.037000000000000601852 0.037100000000004115797 -0.039499999999999833855" rpy="1.5707963267948861219 -4.0933607639229270295e-13 -3.6944432958726287967e-13" />
    <parent link="waist_link" />
    <child link="spur_gear_19_teeth_2" />
    <axis xyz="0 0 1" />
    <limit effort="1" velocity="20" lower="-1.570796326794896558" upper="1.570796326794896558" />
    <joint_properties friction="0.0" />
  </joint>

  <link name="spur_gear_21_teeth_2">
    <visual>
      <origin xyz="0 0 0" rpy="0 -0 0" />
      <geometry>
        <mesh filename="../assemblies/toddlerbot/meshes/spur_gear_21_teeth_2_visual.stl" />
      </geometry>
      <material name="spur_gear_21_teeth_2_material">
        <color rgba="0.61568627450980395466 0.81176470588235294379 0.92941176470588238168 1.0" />
      </material>
    </visual>
    <inertial>
      <origin xyz="-4.7814841763923029646e-10 -1.2610156065183166109e-12 -0.0025055381383856678047" rpy="0 0 0" />
      <mass value="0.0010063046528317972673" />
      <inertia ixx="3.1842855421068488283e-08" ixy="2.8197916970140418123e-36" ixz="-5.1368559626832086278e-40" iyy="3.1842855426953805549e-08" iyz="-1.6564068439911513797e-37" izz="5.9529380586728047984e-08" />
    </inertial>
  </link>

  <joint name="right_leg_fixed" type="fixed">
    <origin xyz="4.336808689942017736e-19 -6.9388939039072283776e-18 -0.0050000000000000044409" rpy="-4.6198149465961399771e-14 1.8953383221571858275e-31 2.6475889041157274137e-29" />
    <parent link="spur_gear_21_teeth_2" />
    <child link="hip_yaw_link_2" />
    <axis xyz="0 0 1" />
    <limit effort="1" velocity="20" />
    <joint_properties friction="0.0" />
  </joint>

  <joint name="right_hip_yaw_driven" type="revolute">
    <origin xyz="0.036999999999999998168 0.041100000000000011524 -0.01950000000000001385" rpy="1.5707963267949343056 -1.5707963267948712449 0" />
    <parent link="waist_link" />
    <child link="spur_gear_21_teeth_2" />
    <axis xyz="0 0 1" />
    <limit effort="1" velocity="20" lower="-1.570796326794896558" upper="1.570796326794896558" />
    <joint_properties friction="0.0" />
  </joint>

  <joint name="waist_roll" type="revolute">
    <origin xyz="4.3613235720115761641e-19 -0.022707865260692444015 0.013000000000000013281" rpy="1.570796326794896558 -2.3897582906932224823e-15 2.1266135278953062992e-16" />
    <parent link="waist_gears" />
    <child link="waist_link" />
    <axis xyz="0 0 1" />
    <limit effort="1" velocity="20" lower="-0.52359877559829881566" upper="0.52359877559829881566" />
    <joint_properties friction="0.0" />
  </joint>

  <joint name="waist_yaw" type="revolute">
    <origin xyz="-7.6501305290577192864e-16 -3.9884543972351746136e-15 -7.771561172376095783e-16" rpy="-3.1415926535897922278 -2.0665189604238262613e-16 -1.5707963267945077579" />
    <parent link="torso" />
    <child link="waist_gears" />
    <axis xyz="0 0 1" />
    <limit effort="1" velocity="20" lower="-1.570796326794896558" upper="1.570796326794896558" />
    <joint_properties friction="0.0" />
  </joint>

  <joint name="left_sho_pitch" type="revolute">
    <origin xyz="-0.0029999999999997528644 0.062000000000000436706 0.10523651076281793915" rpy="-1.5707963267948983344 6.3108872417680944433e-30 -1.215300360748803713e-15" />
    <parent link="torso" />
    <child link="sho_pitch_link" />
    <axis xyz="0 0 1" />
    <limit effort="1" velocity="20" lower="-1.570796326794896558" upper="1.570796326794896558" />
    <joint_properties friction="0.0" />
  </joint>

  <joint name="right_sho_pitch" type="revolute">
    <origin xyz="-0.0030000000000001275646 -0.061999999999999985678 0.10523651076281731465" rpy="-1.570796326794896558 -9.4663308626521416649e-30 3.1415926535897922278" />
    <parent link="torso" />
    <child link="sho_pitch_link_2" />
    <axis xyz="0 0 1" />
    <limit effort="1" velocity="20" lower="-1.570796326794896558" upper="1.570796326794896558" />
    <joint_properties friction="0.0" />
  </joint>


  <link name="hip_yaw_link">
    <visual>
      <origin xyz="0 0 0" rpy="0 -0 0" />
      <geometry>
        <mesh filename="../assemblies/left_leg_XM430/meshes/left_hip_yaw_link_visual.stl" />
      </geometry>
      <material name="hip_yaw_link_material">
        <color rgba="0.61568627450980395466 0.81176470588235294379 0.92941176470588238168 1.0" />
      </material>
    </visual>
    <inertial>
      <origin xyz="1.936008810789442299e-19 -3.8705683598185288124e-19 -0.0098390489054829104176" rpy="0 0 0" />
      <mass value="0.017999999999999988232" />
      <inertia ixx="2.6385033891442519679e-06" ixy="0" ixz="0" iyy="7.6596731957046856464e-06" iyz="0" izz="7.7220708070894735956e-06" />
    </inertial>
  </link>

  <link name="hip_roll_link">
    <visual>
      <origin xyz="0 0 0" rpy="0 -0 0" />
      <geometry>
        <mesh filename="../assemblies/left_leg_XM430/meshes/left_hip_roll_link_visual.stl" />
      </geometry>
      <material name="hip_roll_link_material">
        <color rgba="0.51698661238356047321 0.50347815951093488618 0.49050589017722012741 1.0" />
      </material>
    </visual>
    <collision>
      <origin xyz="0 0 0" rpy="0 -0 0" />
      <geometry>
        <mesh filename="collisions/left_hip_roll_link_collision.stl" />
      </geometry>
    </collision>
    <inertial>
      <origin xyz="-0.011999849582185678071 -0.00049598090794010681048 -0.018504111838598649026" rpy="0 0 0" />
      <mass value="0.11059999999836234164" />
      <inertia ixx="2.2818802599018682756e-05" ixy="-4.6520143286691335628e-08" ixz="-4.6888548260742951573e-08" iyy="3.087163208233903455e-05" iyz="-5.7477343899716666035e-07" izz="3.0871666424469295785e-05" />
    </inertial>
  </link>

  <link name="left_hip_pitch_link_xm430">
    <visual>
      <origin xyz="0 0 0" rpy="0 -0 0" />
      <geometry>
        <mesh filename="../assemblies/left_leg_XM430/meshes/left_hip_pitch_link_xm430_visual.stl" />
      </geometry>
      <material name="left_hip_pitch_link_xm430_material">
        <color rgba="0.87072221357329560032 0.72641010956094287376 0.24785169615220706274 1.0" />
      </material>
    </visual>
    <collision>
      <origin xyz="0 0 0" rpy="0 -0 0" />
      <geometry>
        <mesh filename="collisions/left_hip_pitch_link_xm430_collision.stl" />
      </geometry>
    </collision>
    <inertial>
      <origin xyz="-0.00075729214155292174076 -0.050714785675264870135 -0.01265615511995994702" rpy="0 0 0" />
      <mass value="0.1148009013503056841" />
      <inertia ixx="6.6072773889430024214e-05" ixy="-4.6080149277697999665e-07" ixz="-1.8170739115315532535e-07" iyy="2.3633638685369744083e-05" iyz="1.412525392534493483e-06" izz="6.2221728804333370109e-05" />
    </inertial>
  </link>

  <link name="left_calf_link">
    <visual>
      <origin xyz="0 0 0" rpy="0 -0 0" />
      <geometry>
        <mesh filename="../assemblies/left_leg_XM430/meshes/left_calf_link_visual.stl" />
      </geometry>
      <material name="left_calf_link_material">
        <color rgba="0.616547745550632742 0.7175754134247219751 0.74372657889541438081 1.0" />
      </material>
    </visual>
    <collision>
      <origin xyz="0 0 0" rpy="0 -0 0" />
      <geometry>
        <mesh filename="collisions/left_calf_link_collision.stl" />
      </geometry>
    </collision>
    <inertial>
      <origin xyz="0.0016330556739544105187 -0.05004552817470941245 -0.00990794251254689326" rpy="0 0 0" />
      <mass value="0.086799999986183581924" />
      <inertia ixx="4.9509459873201005662e-05" ixy="3.6911110041726115618e-06" ixz="4.1819058040005260298e-07" iyy="1.5531229037963214352e-05" iyz="4.6309763568406281045e-07" izz="5.3138661991212117225e-05" />
    </inertial>
  </link>

  <link name="bearing_683">
    <visual>
      <origin xyz="0 0 0" rpy="0 -0 0" />
      <geometry>
        <mesh filename="../assemblies/left_leg_XM430/meshes/left_bearing_683_visual.stl" />
      </geometry>
      <material name="bearing_683_material">
        <color rgba="0.64705882352941179736 0.64705882352941179736 0.64705882352941179736 1.0" />
      </material>
    </visual>
    <inertial>
      <origin xyz="-2.7648254672676560882e-17 -2.4186774283160986954e-19 -0.0015500000000000003792" rpy="0 0 0" />
      <mass value="0.00048694686130641793437" />
      <inertia ixx="2.1551456503319879113e-09" ixy="-4.4250458487272837846e-28" ixz="1.4236606339070577909e-37" iyy="2.1551456503319883249e-09" iyz="2.6417696319569490619e-38" izz="3.5303647444715305817e-09" />
    </inertial>
  </link>

  <joint name="left_knee_front_rev_2" type="revolute">
    <origin xyz="-0.0057402514854764646185 0.013858192987669826213 -0.026199999999996635702" rpy="4.271508439620268736e-16 -1.1008548509280322482e-13 1.5737070550412617376" />
    <parent link="left_calf_link" />
    <child link="bearing_683" />
    <axis xyz="0 0 1" />
    <limit effort="1" velocity="20" lower="-6.283185307179586232" upper="6.283185307179586232" />
    <joint_properties friction="0.0" />
  </joint>

  <link name="bearing_683_2">
    <visual>
      <origin xyz="0 0 0" rpy="0 -0 0" />
      <geometry>
        <mesh filename="../assemblies/left_leg_XM430/meshes/left_bearing_683_2_visual.stl" />
      </geometry>
      <material name="bearing_683_2_material">
        <color rgba="0.64705882352941179736 0.64705882352941179736 0.64705882352941179736 1.0" />
      </material>
    </visual>
    <inertial>
      <origin xyz="2.7862896558581167531e-17 -2.4186774283159200654e-19 -0.0015500000000000003792" rpy="0 0 0" />
      <mass value="0.00048694686130641793437" />
      <inertia ixx="2.1551456503319879113e-09" ixy="-6.4275203259867930164e-28" ixz="2.9263918729646175688e-37" iyy="2.1551456503319883249e-09" iyz="-4.3446809261446184652e-39" izz="3.5303647444715305817e-09" />
    </inertial>
  </link>

  <joint name="left_knee_back_rev_2" type="revolute">
    <origin xyz="0.0057402514854764186483 -0.013858192987669104568 -0.026199999999998932476" rpy="6.9110111902347492695e-16 -8.195589825460743709e-14 1.5739207094623721694" />
    <parent link="left_calf_link" />
    <child link="bearing_683_2" />
    <axis xyz="0 0 1" />
    <limit effort="1" velocity="20" lower="-6.283185307179586232" upper="6.283185307179586232" />
    <joint_properties friction="0.0" />
  </joint>

  <link name="ank_pitch_link">
    <visual>
      <origin xyz="0 0 0" rpy="0 -0 0" />
      <geometry>
        <mesh filename="../assemblies/left_leg_XM430/meshes/left_ank_pitch_link_visual.stl" />
      </geometry>
      <material name="ank_pitch_link_material">
        <color rgba="0.63189161126160264814 0.7266866879354088038 0.78356373393969258601 1.0" />
      </material>
    </visual>
    <inertial>
      <origin xyz="0.00059528282565921692392 -4.0269683147413475732e-08 7.7616092721130685841e-08" rpy="0 0 0" />
      <mass value="0.0042238381753791614387" />
      <inertia ixx="3.9782741364678456013e-07" ixy="-1.6834347831048760968e-13" ixz="2.0919188855236162116e-14" iyy="4.3705254067423077646e-07" iyz="-1.642882218166082817e-12" izz="8.8858574534612962607e-08" />
    </inertial>
  </link>

  <link name="ank_roll_link">
    <visual>
      <origin xyz="0 0 0" rpy="0 -0 0" />
      <geometry>
        <mesh filename="../assemblies/left_leg_XM430/meshes/left_ank_roll_link_visual.stl" />
      </geometry>
      <material name="ank_roll_link_material">
        <color rgba="0.61568627450980395466 0.81176470588235294379 0.92941176470588227065 1.0" />
      </material>
    </visual>
    <inertial>
      <origin xyz="-3.3748977754703192964e-09 0.016071733707723682982 -0.0096236810250137777567" rpy="0 0 0" />
      <mass value="0.010900000000000005171" />
      <inertia ixx="2.6058536057764959133e-06" ixy="-5.4054321089151263802e-13" ixz="6.069254909533594434e-13" iyy="2.5928781338360464717e-06" iyz="3.9359839679282451508e-07" izz="1.6179884211196015163e-06" />
    </inertial>
  </link>

  <link name="ank_rr_link">
    <visual>
      <origin xyz="0 0 0" rpy="0 -0 0" />
      <geometry>
        <mesh filename="../assemblies/left_leg_XM430/meshes/left_ank_rr_link_visual.stl" />
      </geometry>
      <material name="ank_rr_link_material">
        <color rgba="0.61568627450980395466 0.81176470588235294379 0.92941176470588238168 1.0" />
      </material>
    </visual>
    <inertial>
      <origin xyz="-4.5249610960606060901e-05 0.0063096429836314036135 3.2687616793466314446e-18" rpy="0 0 0" />
      <mass value="0.0014499999999999999001" />
      <inertia ixx="2.9739579267716143416e-08" ixy="2.4213146797977948196e-10" ixz="3.5523394884449564293e-14" iyy="2.7430027724071963673e-08" iyz="-1.166695675233048238e-31" izz="4.2921949116163665819e-08" />
    </inertial>
  </link>

  <link name="ank_motor_rod_long">
    <visual>
      <origin xyz="0 0 0" rpy="0 -0 0" />
      <geometry>
        <mesh filename="../assemblies/left_leg_XM430/meshes/left_ank_motor_rod_long_visual.stl" />
      </geometry>
      <material name="ank_motor_rod_long_material">
        <color rgba="0.63549975559783222767 0.70774393017020453822 0.75109043491362792455 1.0" />
      </material>
    </visual>
    <inertial>
      <origin xyz="2.4855086533143567039e-10 0.034559019974062285541 0.00093851704878456453617" rpy="0 0 0" />
      <mass value="0.0021712857268636710437" />
      <inertia ixx="8.5350290058000210235e-07" ixy="1.4884244436311688568e-14" ixz="4.5749525025580115332e-11" iyy="1.3237321792739486385e-08" iyz="-4.36689109608721189e-09" izz="8.5812217519451556991e-07" />
    </inertial>
  </link>

  <joint name="left_ank_long_rev_2" type="revolute">
    <origin xyz="-6.9388939039072283776e-18 0.010000000000000008882 0" rpy="-1.570796326794896558 1.3320366994106418446 -1.5707963267948841235" />
    <parent link="ank_rr_link" />
    <child link="ank_motor_rod_long" />
    <axis xyz="0 0 1" />
    <limit effort="1" velocity="20" lower="-1.570796326794896558" upper="1.570796326794896558" />
    <joint_properties friction="0.0" />
  </joint>

  <joint name="left_ank_long_rev_1" type="revolute">
    <origin xyz="-0.018000000000000005579 0.016000000000000041966 -0.020599999999999996786" rpy="2.5433593855225719214e-15 -2.6604907481913981572e-15 3.123369568546706887" />
    <parent link="ank_roll_link" />
    <child link="ank_rr_link" />
    <axis xyz="0 0 1" />
    <limit effort="1" velocity="20" lower="-1.570796326794896558" upper="1.570796326794896558" />
    <joint_properties friction="0.0" />
  </joint>

  <link name="ank_rr_link_2">
    <visual>
      <origin xyz="0 0 0" rpy="0 -0 0" />
      <geometry>
        <mesh filename="../assemblies/left_leg_XM430/meshes/left_ank_rr_link_2_visual.stl" />
      </geometry>
      <material name="ank_rr_link_2_material">
        <color rgba="0.61568627450980395466 0.81176470588235294379 0.92941176470588238168 1.0" />
      </material>
    </visual>
    <inertial>
      <origin xyz="-4.5249610960599122007e-05 -0.0063096429836314591247 2.0068527260719917058e-19" rpy="0 0 0" />
      <mass value="0.0014499999999999999001" />
      <inertia ixx="2.9739579267716163268e-08" ixy="-2.4213146797977979215e-10" ixz="-3.5523394884449576915e-14" iyy="2.7430027724071963673e-08" iyz="7.4287544947805872756e-32" izz="4.2921949116163665819e-08" />
    </inertial>
  </link>

  <link name="ank_motor_rod_short">
    <visual>
      <origin xyz="0 0 0" rpy="0 -0 0" />
      <geometry>
        <mesh filename="../assemblies/left_leg_XM430/meshes/left_ank_motor_rod_short_visual.stl" />
      </geometry>
      <material name="ank_motor_rod_short_material">
        <color rgba="0.41222606689734719865 0.58339100346020766885 0.8110726643598615837 1.0" />
      </material>
    </visual>
    <inertial>
      <origin xyz="2.6038941369069990436e-10 0.023830465465870913355 0.0009040350635962251559" rpy="0 0 0" />
      <mass value="0.0017000000000000001221" />
      <inertia ixx="3.3153416252670061247e-07" ixy="8.7419771437823938146e-15" ixz="4.5749941567721385493e-11" iyy="1.0947363610305772565e-08" iyz="-3.5863098646406916781e-09" izz="3.3621340447865210221e-07" />
    </inertial>
  </link>

  <joint name="left_ank_short_rev_2" type="revolute">
    <origin xyz="3.4694469519536141888e-18 -0.010000000000000064393 -3.4694469519536141888e-18" rpy="-1.570796326794896558 -1.2119133862909994281 -1.5707963267948890085" />
    <parent link="ank_rr_link_2" />
    <child link="ank_motor_rod_short" />
    <axis xyz="0 0 1" />
    <limit effort="1" velocity="20" lower="-1.570796326794896558" upper="1.570796326794896558" />
    <joint_properties friction="0.0" />
  </joint>

  <joint name="left_ank_short_rev_1" type="revolute">
    <origin xyz="0.01799999999999999864 0.015999999999999986455 -0.020600000000000003725" rpy="-9.884525357415052455e-16 2.7480857223716701119e-15 0.026118548507321499158" />
    <parent link="ank_roll_link" />
    <child link="ank_rr_link_2" />
    <axis xyz="0 0 1" />
    <limit effort="1" velocity="20" lower="-1.570796326794896558" upper="1.570796326794896558" />
    <joint_properties friction="0.0" />
  </joint>

  <link name="left_sole_link">
    <visual>
      <origin xyz="0 0 0" rpy="0 -0 0" />
      <geometry>
        <mesh filename="../assemblies/left_leg_XM430/meshes/left_sole_link_visual.stl" />
      </geometry>
      <material name="left_sole_link_material">
        <color rgba="0.61568627450980395466 0.81176470588235283277 0.92941176470588238168 1.0" />
      </material>
    </visual>
    <collision>
      <origin xyz="0 0 0" rpy="0 -0 0" />
      <geometry>
        <mesh filename="../assemblies/left_leg_XM430/meshes/left_sole_link_collision.stl" />
      </geometry>
    </collision>
    <inertial>
      <origin xyz="-0.028268455053070316862 -2.3408773987391338329e-07 -0.010206307024274999945" rpy="0 0 0" />
      <mass value="0.013899999999999999162" />
      <inertia ixx="1.3160509347109559219e-06" ixy="3.009416123814671285e-12" ixz="-2.3741900688425285732e-07" iyy="1.3575574544571530477e-05" iyz="-6.7706521655058411305e-12" izz="1.4673603612256133841e-05" />
    </inertial>
  </link>

  <joint name="left_sole" type="fixed">
    <origin xyz="-9.1072982488782372457e-18 0.024999999999999994449 -0.022600000000000005501" rpy="1.570796326794896558 1.570796326794896336 0" />
    <parent link="ank_roll_link" />
    <child link="left_sole_link" />
    <axis xyz="0 0 1" />
    <limit effort="1" velocity="20" />
    <joint_properties friction="0.0" />
  </joint>

  <joint name="left_ank_roll" type="revolute">
    <origin xyz="0.0014999999999999601326 -3.3306690738754696213e-16 -2.7549577202856667668e-16" rpy="3.7524749012299854346e-16 1.5707963267948723551 0" />
    <parent link="ank_pitch_link" />
    <child link="ank_roll_link" />
    <axis xyz="0 0 1" />
    <limit effort="1" velocity="20" lower="-0.785398163397448279" upper="0.785398163397448279" />
    <joint_properties friction="0.0" />
  </joint>

  <joint name="left_ank_pitch" type="revolute">
    <origin xyz="-5.02528144577274134e-17 -0.10000000000000103251 -0.010400000000005618292" rpy="-1.9984048432388552166e-15 1.6503134118918274764e-24 3.1415926535897926719" />
    <parent link="left_calf_link" />
    <child link="ank_pitch_link" />
    <axis xyz="0 0 1" />
    <limit effort="1" velocity="20" lower="-0.785398163397448279" upper="0.95993108859688125456" />
    <joint_properties friction="0.0" />
  </joint>

  <link name="ank_motor_arm">
    <visual>
      <origin xyz="0 0 0" rpy="0 -0 0" />
      <geometry>
        <mesh filename="../assemblies/left_leg_XM430/meshes/left_ank_motor_arm_visual.stl" />
      </geometry>
      <material name="ank_motor_arm_material">
        <color rgba="0.62517751827980905244 0.70593642422614044651 0.75978993426662777555 1.0" />
      </material>
    </visual>
    <inertial>
      <origin xyz="0.014511489101591690601 -1.9139519629607821646e-18 0.0040925443765950954289" rpy="0 0 0" />
      <mass value="0.0020595846677894939954" />
      <inertia ixx="2.7591836756522385221e-08" ixy="6.6823408482601443028e-23" ixz="-3.0270788206595093348e-08" iyy="1.6138599216238480289e-07" iyz="-3.8538641125382110039e-23" izz="1.6437836765016306063e-07" />
    </inertial>
  </link>

  <joint name="left_ank_act_1" type="revolute">
    <origin xyz="0.013499999999998665845 -0.044499999999995792921 0.0040000000000033272829" rpy="-4.1712942586566064875e-13 -1.3694125076526491156e-13 -0.21173394130239187039" />
    <parent link="left_calf_link" />
    <child link="ank_motor_arm" />
    <axis xyz="0 0 1" />
    <limit effort="1" velocity="20" lower="-1.3089969389957472057" upper="1.3089969389957472057" />
    <joint_properties friction="0.0" />
  </joint>

  <link name="ank_motor_arm_2">
    <visual>
      <origin xyz="0 0 0" rpy="0 -0 0" />
      <geometry>
        <mesh filename="../assemblies/left_leg_XM430/meshes/left_ank_motor_arm_2_visual.stl" />
      </geometry>
      <material name="ank_motor_arm_2_material">
        <color rgba="0.62517751827980905244 0.70593642422614044651 0.75978993426662777555 1.0" />
      </material>
    </visual>
    <inertial>
      <origin xyz="0.014511489101591690601 1.7312959194653252834e-17 0.0040925443765950746122" rpy="0 0 0" />
      <mass value="0.0020595846677894939954" />
      <inertia ixx="2.7591836756522120524e-08" ixy="-2.5310552726340107976e-22" ixz="-3.027078820659488159e-08" iyy="1.6138599216238453819e-07" iyz="-4.1771713778084962819e-23" izz="1.6437836765016290181e-07" />
    </inertial>
  </link>

  <joint name="left_ank_act_2" type="revolute">
    <origin xyz="0.013500000000004905645 -0.064499999999988205657 -0.024800000000003801642" rpy="-3.1415926535893086147 1.5803801662501837498e-14 -0.22995607267385878569" />
    <parent link="left_calf_link" />
    <child link="ank_motor_arm_2" />
    <axis xyz="0 0 1" />
    <limit effort="1" velocity="20" lower="-1.3089969389957472057" upper="1.3089969389957472057" />
    <joint_properties friction="0.0" />
  </joint>

  <joint name="left_knee_pitch" type="revolute">
    <origin xyz="2.2567659777873647925e-17 -0.096000000000000001998 -0.0091999999999999321904" rpy="-8.2328001363584503113e-14 -1.0561188185116160038e-15 1.3586247681681341312e-15" />
    <parent link="left_hip_pitch_link_xm430" />
    <child link="left_calf_link" />
    <axis xyz="0 0 1" />
    <limit effort="1" velocity="20" lower="0" upper="1.9198621771937625091" />
    <joint_properties friction="0.0" />
  </joint>

  <link name="xm430_plate">
    <visual>
      <origin xyz="0 0 0" rpy="0 -0 0" />
      <geometry>
        <mesh filename="../assemblies/left_leg_XM430/meshes/left_xm430_plate_visual.stl" />
      </geometry>
      <material name="xm430_plate_material">
        <color rgba="0.61568627450980395466 0.81176470588235294379 0.92941176470588227065 1.0" />
      </material>
    </visual>
    <inertial>
      <origin xyz="3.526469098209085274e-18 2.0247695724436449953e-18 -0.0024039046431217955119" rpy="0 0 0" />
      <mass value="0.0026999999999999997093" />
      <inertia ixx="1.2933116645363413477e-07" ixy="-6.8936588702566480118e-08" ixz="-1.3749119573051436324e-35" iyy="2.6720434385876693618e-07" iyz="1.6081256606048751007e-35" izz="3.8533537562751439267e-07" />
    </inertial>
  </link>

  <link name="knee_rod">
    <visual>
      <origin xyz="0 0 0" rpy="0 -0 0" />
      <geometry>
        <mesh filename="../assemblies/left_leg_XM430/meshes/left_knee_rod_visual.stl" />
      </geometry>
      <material name="knee_rod_material">
        <color rgba="0.62051618944235198416 0.78640765248647581664 0.88594253031295022716 1.0" />
      </material>
    </visual>
    <inertial>
      <origin xyz="0.014594547204704525281 4.1946460599132681484e-05 -0.001599622737316051509" rpy="0 0 0" />
      <mass value="0.0031629468613064179276" />
      <inertia ixx="2.589613558286168058e-08" ixy="-3.5234921180517954075e-10" ixz="4.1682974277862750461e-10" iyy="6.0153250889879762465e-07" iyz="1.1980181584497357053e-12" izz="6.2266858020375222744e-07" />
    </inertial>
  </link>

  <joint name="left_knee_front_rev_1" type="revolute">
    <origin xyz="0.013858192987669284979 0.0057402514854763449226 -0.0050000000000000044409" rpy="-2.6482027166570673961e-14 1.7928721450783686478e-14 -3.1386819253434268262" />
    <parent link="xm430_plate" />
    <child link="knee_rod" />
    <axis xyz="0 0 1" />
    <limit effort="1" velocity="20" lower="-6.283185307179586232" upper="6.283185307179586232" />
    <joint_properties friction="0.0" />
  </joint>

  <link name="knee_rod_2">
    <visual>
      <origin xyz="0 0 0" rpy="0 -0 0" />
      <geometry>
        <mesh filename="../assemblies/left_leg_XM430/meshes/left_knee_rod_2_visual.stl" />
      </geometry>
      <material name="knee_rod_2_material">
        <color rgba="0.62051618944235198416 0.78640765248647581664 0.88594253031295022716 1.0" />
      </material>
    </visual>
    <inertial>
      <origin xyz="0.014594555500543209686 3.5710133124878954206e-05 -0.0015996227373166677695" rpy="0 0 0" />
      <mass value="0.0031629468613064179276" />
      <inertia ixx="2.5895856845870585942e-08" ixy="-2.9996438873621668867e-10" ixz="4.1682997973030594077e-10" iyy="6.0153264826849772892e-07" iyz="1.0199045846345435146e-12" izz="6.2266844083647283746e-07" />
    </inertial>
  </link>

  <joint name="left_knee_back_rev_1" type="revolute">
    <origin xyz="-0.013858192987669298857 -0.0057402514854763457899 -0.004999999999999997502" rpy="-8.90060916222688594e-16 -9.8269699236230981438e-15 -3.1384682709223161723" />
    <parent link="xm430_plate" />
    <child link="knee_rod_2" />
    <axis xyz="0 0 1" />
    <limit effort="1" velocity="20" lower="-6.283185307179586232" upper="6.283185307179586232" />
    <joint_properties friction="0.0" />
  </joint>

  <joint name="left_knee_act" type="revolute">
    <origin xyz="-0.00014999999999999462006 -0.061500000000000019929 -0.030400000000000017286" rpy="-1.4293624205725000014e-15 -9.8302390852442860967e-15 1.5707963267948961139" />
    <parent link="left_hip_pitch_link_xm430" />
    <child link="xm430_plate" />
    <axis xyz="0 0 1" />
    <limit effort="1" velocity="20" lower="0" upper="1.9198621771937625091" />
    <joint_properties friction="0.0" />
  </joint>

  <joint name="left_hip_pitch" type="revolute">
    <origin xyz="-0.024000000716151263791 -0.019000000152441052365 -0.019000000152457018759" rpy="1.5707963267952342878 1.5707963267945523889 0" />
    <parent link="hip_roll_link" />
    <child link="left_hip_pitch_link_xm430" />
    <axis xyz="0 0 1" />
    <limit effort="1" velocity="20" lower="-1.570796326794896558" upper="1.570796326794896558" />
    <joint_properties friction="0.0" />
  </joint>

  <joint name="left_hip_roll" type="revolute">
    <origin xyz="0.018999999999999999528 -3.3500438890369418804e-18 -0.026000000000000002276" rpy="-3.141592653589793116 -1.5707963267948679142 0" />
    <parent link="hip_yaw_link" />
    <child link="hip_roll_link" />
    <axis xyz="0 0 1" />
    <limit effort="1" velocity="20" lower="-0.785398163397448279" upper="1.570796326794896558" />
    <joint_properties friction="0.0" />
  </joint>


  <link name="hip_yaw_link_2">
    <visual>
      <origin xyz="0 0 0" rpy="0 -0 0" />
      <geometry>
        <mesh filename="../assemblies/right_leg_XM430/meshes/right_hip_yaw_link_visual.stl" />
      </geometry>
      <material name="hip_yaw_link_material">
        <color rgba="0.61568627450980395466 0.81176470588235294379 0.92941176470588238168 1.0" />
      </material>
    </visual>
    <inertial>
      <origin xyz="-1.936008810789442299e-19 3.8705683598185288124e-19 -0.0098390489054829104176" rpy="0 0 0" />
      <mass value="0.017999999999999988232" />
      <inertia ixx="2.6385033891442519679e-06" ixy="0" ixz="0" iyy="7.6596731957046856464e-06" iyz="0" izz="7.7220708070894735956e-06" />
    </inertial>
  </link>

  <link name="hip_roll_link_2">
    <visual>
      <origin xyz="0 0 0" rpy="0 -0 0" />
      <geometry>
        <mesh filename="../assemblies/right_leg_XM430/meshes/right_hip_roll_link_visual.stl" />
      </geometry>
      <material name="hip_roll_link_material">
        <color rgba="0.51698661238356047321 0.50347815951093488618 0.49050589017722012741 1.0" />
      </material>
    </visual>
    <collision>
      <origin xyz="0 0 0" rpy="0 -0 0" />
      <geometry>
        <mesh filename="collisions/right_hip_roll_link_collision.stl" />
      </geometry>
    </collision>
    <inertial>
      <origin xyz="-0.011999849582182770674 -0.00049598090794319277513 -0.018504111838597465944" rpy="0 0 0" />
      <mass value="0.11059999999836234164" />
      <inertia ixx="2.2818802599018211805e-05" ixy="-4.6520143286279624676e-08" ixz="-4.6888548259070657073e-08" iyy="3.0871632082338065545e-05" iyz="-5.7477343899720880024e-07" izz="3.0871666424467947309e-05" />
    </inertial>
  </link>

  <link name="right_hip_pitch_link_xm430">
    <visual>
      <origin xyz="0 0 0" rpy="0 -0 0" />
      <geometry>
        <mesh filename="../assemblies/right_leg_XM430/meshes/right_hip_pitch_link_xm430_visual.stl" />
      </geometry>
      <material name="right_hip_pitch_link_xm430_material">
        <color rgba="0.87072221357329560032 0.72641010956094287376 0.24785169615220706274 1.0" />
      </material>
    </visual>
    <collision>
      <origin xyz="0 0 0" rpy="0 -0 0" />
      <geometry>
        <mesh filename="collisions/right_hip_pitch_link_xm430_collision.stl" />
      </geometry>
    </collision>
    <inertial>
      <origin xyz="0.00075715881371275946254 -0.050714784778880715732 -0.012656153620121958839" rpy="0 0 0" />
      <mass value="0.1148009013503056841" />
      <inertia ixx="6.6072786489385201738e-05" ixy="4.6010682906024558268e-07" ixz="1.8171597853316566654e-07" iyy="2.3633665181581954188e-05" iyz="1.4125296519934134898e-06" izz="6.2221763055418004632e-05" />
    </inertial>
  </link>

  <link name="right_calf_link">
    <visual>
      <origin xyz="0 0 0" rpy="0 -0 0" />
      <geometry>
        <mesh filename="../assemblies/right_leg_XM430/meshes/right_calf_link_visual.stl" />
      </geometry>
      <material name="right_calf_link_material">
        <color rgba="0.616547745550632742 0.7175754134247219751 0.74372657889541426979 1.0" />
      </material>
    </visual>
    <collision>
      <origin xyz="0 0 0" rpy="0 -0 0" />
      <geometry>
        <mesh filename="collisions/right_calf_link_collision.stl" />
      </geometry>
    </collision>
    <inertial>
      <origin xyz="0.001633056029239726226 0.050045526484800345601 -0.0099079425237751286154" rpy="0 0 0" />
      <mass value="0.086799999986183568046" />
      <inertia ixx="4.9519076588877544904e-05" ixy="-3.6911123877149629868e-06" ixz="4.1819052274329295976e-07" iyy="1.5531229308366376968e-05" iyz="-4.607229207937335214e-07" izz="5.3148278062060566346e-05" />
    </inertial>
  </link>

  <link name="bearing_683_3">
    <visual>
      <origin xyz="0 0 0" rpy="0 -0 0" />
      <geometry>
        <mesh filename="../assemblies/right_leg_XM430/meshes/right_bearing_683_visual.stl" />
      </geometry>
      <material name="bearing_683_material">
        <color rgba="0.64705882352941179736 0.64705882352941179736 0.64705882352941179736 1.0" />
      </material>
    </visual>
    <inertial>
      <origin xyz="1.0732094295240964766e-19 2.4186774283163086217e-19 -0.0015499999999999977771" rpy="0 0 0" />
      <mass value="0.00048694686130641793437" />
      <inertia ixx="2.1551456503319879113e-09" ixy="-3.3628103926129874696e-28" ixz="7.6066353359661959036e-38" iyy="2.1551456503319883249e-09" iyz="4.8251731695129717068e-38" izz="3.5303647444715322361e-09" />
    </inertial>
  </link>

  <joint name="right_knee_front_rev_2" type="revolute">
    <origin xyz="-0.0057402514854763405858 -0.013858192987669298857 -0.02619999999999997678" rpy="-6.2776058347430638833e-15 -3.649417008249174908e-17 3.1358007158038927464" />
    <parent link="right_calf_link" />
    <child link="bearing_683_3" />
    <axis xyz="0 0 1" />
    <limit effort="1" velocity="20" lower="-6.283185307179586232" upper="6.283185307179586232" />
    <joint_properties friction="0.0" />
  </joint>

  <link name="bearing_683_4">
    <visual>
      <origin xyz="0 0 0" rpy="0 -0 0" />
      <geometry>
        <mesh filename="../assemblies/right_leg_XM430/meshes/right_bearing_683_2_visual.stl" />
      </geometry>
      <material name="bearing_683_2_material">
        <color rgba="0.64705882352941179736 0.64705882352941179736 0.64705882352941179736 1.0" />
      </material>
    </visual>
    <inertial>
      <origin xyz="1.0732094295242468195e-19 2.7997443358460577788e-17 -0.0015499999999999977771" rpy="0 0 0" />
      <mass value="0.00048694686130641793437" />
      <inertia ixx="2.1551456503319879113e-09" ixy="-2.4982999913736959872e-27" ixz="1.1943003538897581327e-37" iyy="2.1551456503319883249e-09" iyz="8.2447751888914575401e-38" izz="3.5303647444715322361e-09" />
    </inertial>
  </link>

  <joint name="right_knee_back_rev_2" type="revolute">
    <origin xyz="0.0057402514854764047705 0.013858192987669326612 -0.026199999999999966371" rpy="-6.6378328094146457949e-15 -3.5392027487744668907e-17 3.1357969761588506685" />
    <parent link="right_calf_link" />
    <child link="bearing_683_4" />
    <axis xyz="0 0 1" />
    <limit effort="1" velocity="20" lower="-6.283185307179586232" upper="6.283185307179586232" />
    <joint_properties friction="0.0" />
  </joint>

  <link name="ank_pitch_link_2">
    <visual>
      <origin xyz="0 0 0" rpy="0 -0 0" />
      <geometry>
        <mesh filename="../assemblies/right_leg_XM430/meshes/right_ank_pitch_link_visual.stl" />
      </geometry>
      <material name="ank_pitch_link_material">
        <color rgba="0.63189161126160264814 0.7266866879354088038 0.78356373393969258601 1.0" />
      </material>
    </visual>
    <inertial>
      <origin xyz="0.00059528282565905624515 -4.0269682599634482799e-08 7.7616094187774163243e-08" rpy="0 0 0" />
      <mass value="0.0042238381753791614387" />
      <inertia ixx="3.9782741364675316697e-07" ixy="-1.6834347646329972401e-13" ixz="2.0919192023102915997e-14" iyy="4.3705254067418641311e-07" iyz="-1.6428822141780835252e-12" izz="8.885857453460008506e-08" />
    </inertial>
  </link>

  <link name="ank_roll_link_2">
    <visual>
      <origin xyz="0 0 0" rpy="0 -0 0" />
      <geometry>
        <mesh filename="../assemblies/right_leg_XM430/meshes/right_ank_roll_link_visual.stl" />
      </geometry>
      <material name="ank_roll_link_material">
        <color rgba="0.61568627450980395466 0.81176470588235294379 0.92941176470588227065 1.0" />
      </material>
    </visual>
    <inertial>
      <origin xyz="-3.3748977754703192964e-09 0.016071733707723655227 -0.0096236810250137777567" rpy="0 0 0" />
      <mass value="0.010900000000000005171" />
      <inertia ixx="2.6058536057764959133e-06" ixy="-5.4054321089151263802e-13" ixz="6.069254909533594434e-13" iyy="2.5928781338360464717e-06" iyz="3.9359839679282451508e-07" izz="1.6179884211196015163e-06" />
    </inertial>
  </link>

  <link name="ank_rr_link_3">
    <visual>
      <origin xyz="0 0 0" rpy="0 -0 0" />
      <geometry>
        <mesh filename="../assemblies/right_leg_XM430/meshes/right_ank_rr_link_visual.stl" />
      </geometry>
      <material name="ank_rr_link_material">
        <color rgba="0.61568627450980395466 0.81176470588235294379 0.92941176470588238168 1.0" />
      </material>
    </visual>
    <inertial>
      <origin xyz="-4.5249610960606040573e-05 -0.0063096429836315146358 2.0068527260725287995e-19" rpy="0 0 0" />
      <mass value="0.0014499999999999999001" />
      <inertia ixx="2.9739579267716150033e-08" ixy="-2.4213146797977979215e-10" ixz="-3.5523394884449570604e-14" iyy="2.7430027724071963673e-08" iyz="9.0746301005731786383e-32" izz="4.2921949116163665819e-08" />
    </inertial>
  </link>

  <link name="ank_motor_rod_long_2">
    <visual>
      <origin xyz="0 0 0" rpy="0 -0 0" />
      <geometry>
        <mesh filename="../assemblies/right_leg_XM430/meshes/right_ank_motor_rod_long_visual.stl" />
      </geometry>
      <material name="ank_motor_rod_long_material">
        <color rgba="0.63549975559783222767 0.70774393017020453822 0.75109043491362792455 1.0" />
      </material>
    </visual>
    <inertial>
      <origin xyz="2.4855088301378626682e-10 0.034559019974062285541 0.00093851704878458773809" rpy="0 0 0" />
      <mass value="0.0021712857268636710437" />
      <inertia ixx="8.5350290058000485521e-07" ixy="1.4884244120414140831e-14" ixz="4.5749525025599638087e-11" iyy="1.3237321792739588955e-08" iyz="-4.3668910960879505623e-09" izz="8.5812217519451832277e-07" />
    </inertial>
  </link>

  <joint name="right_ank_long_rev_2" type="revolute">
    <origin xyz="-3.4694469519536141888e-18 -0.010000000000000008882 0" rpy="-1.570796326794896558 -1.3320366994106180858 -1.5707963267948950037" />
    <parent link="ank_rr_link_3" />
    <child link="ank_motor_rod_long_2" />
    <axis xyz="0 0 1" />
    <limit effort="1" velocity="20" lower="-1.570796326794896558" upper="1.570796326794896558" />
    <joint_properties friction="0.0" />
  </joint>

  <joint name="right_ank_long_rev_1" type="revolute">
    <origin xyz="0.01800000000000012354 0.015999999999999792166 -0.020600000000000121686" rpy="-6.0785451271832051227e-15 6.1863719170134657294e-15 0.018223085043009137896" />
    <parent link="ank_roll_link_2" />
    <child link="ank_rr_link_3" />
    <axis xyz="0 0 1" />
    <limit effort="1" velocity="20" lower="-1.570796326794896558" upper="1.570796326794896558" />
    <joint_properties friction="0.0" />
  </joint>

  <link name="ank_rr_link_4">
    <visual>
      <origin xyz="0 0 0" rpy="0 -0 0" />
      <geometry>
        <mesh filename="../assemblies/right_leg_XM430/meshes/right_ank_rr_link_2_visual.stl" />
      </geometry>
      <material name="ank_rr_link_2_material">
        <color rgba="0.61568627450980395466 0.81176470588235294379 0.92941176470588238168 1.0" />
      </material>
    </visual>
    <inertial>
      <origin xyz="-4.5249610960602577902e-05 0.0063096429836314036135 -2.0068527260711353892e-19" rpy="0 0 0" />
      <mass value="0.0014499999999999999001" />
      <inertia ixx="2.9739579267716150033e-08" ixy="2.4213146797977979215e-10" ixz="3.5523394884449570604e-14" iyy="2.7430027724071963673e-08" iyz="8.3643788813915890394e-32" izz="4.2921949116163665819e-08" />
    </inertial>
  </link>

  <link name="ank_motor_rod_short_2">
    <visual>
      <origin xyz="0 0 0" rpy="0 -0 0" />
      <geometry>
        <mesh filename="../assemblies/right_leg_XM430/meshes/right_ank_motor_rod_short_visual.stl" />
      </geometry>
      <material name="ank_motor_rod_short_material">
        <color rgba="0.41222606689734719865 0.58339100346020766885 0.8110726643598615837 1.0" />
      </material>
    </visual>
    <inertial>
      <origin xyz="2.6038940490746279194e-10 0.023830465465870927233 0.00090403506359621724122" rpy="0 0 0" />
      <mass value="0.0017000000000000001221" />
      <inertia ixx="3.3153416252670114187e-07" ixy="8.7419769634369248354e-15" ixz="4.5749941567748120229e-11" iyy="1.0947363610305762639e-08" iyz="-3.5863098646405146614e-09" izz="3.3621340447865257867e-07" />
    </inertial>
  </link>

  <joint name="right_ank_short_rev_2" type="revolute">
    <origin xyz="-6.9388939039072283776e-18 0.010000000000000008882 6.9388939039072283776e-18" rpy="-1.5707963267948854558 1.2119133862908557653 -1.5707963267949027752" />
    <parent link="ank_rr_link_4" />
    <child link="ank_motor_rod_short_2" />
    <axis xyz="0 0 1" />
    <limit effort="1" velocity="20" lower="-1.570796326794896558" upper="1.570796326794896558" />
    <joint_properties friction="0.0" />
  </joint>

  <joint name="right_ank_short_rev_1" type="revolute">
    <origin xyz="-0.017999999999999880679 0.015999999999999847677 -0.020599999999999920458" rpy="6.2273204751553159641e-15 -5.6155890983045670953e-15 3.1154741050825118798" />
    <parent link="ank_roll_link_2" />
    <child link="ank_rr_link_4" />
    <axis xyz="0 0 1" />
    <limit effort="1" velocity="20" lower="-1.570796326794896558" upper="1.570796326794896558" />
    <joint_properties friction="0.0" />
  </joint>

  <link name="right_sole_link">
    <visual>
      <origin xyz="0 0 0" rpy="0 -0 0" />
      <geometry>
        <mesh filename="../assemblies/right_leg_XM430/meshes/right_sole_link_visual.stl" />
      </geometry>
      <material name="right_sole_link_material">
        <color rgba="0.61568627450980395466 0.81176470588235294379 0.92941176470588238168 1.0" />
      </material>
    </visual>
    <collision>
      <origin xyz="0 0 0" rpy="0 -0 0" />
      <geometry>
        <mesh filename="../assemblies/right_leg_XM430/meshes/right_sole_link_collision.stl" />
      </geometry>
    </collision>
    <inertial>
      <origin xyz="-0.028269220649489175401 -7.4209810882764118699e-08 -0.010206288127739999994" rpy="0 0 0" />
      <mass value="0.013900000000000000897" />
      <inertia ixx="1.316069070887124095e-06" ixy="-1.022644419197535895e-10" ixz="-2.3744136049829838944e-07" iyy="1.3575381226152448939e-05" iyz="-7.1602330637823157685e-13" izz="1.4673427099197171617e-05" />
    </inertial>
  </link>

  <joint name="right_sole" type="fixed">
    <origin xyz="-8.9988780316296868023e-18 0.024999999999999966693 -0.022599999999999998562" rpy="1.5707963267949132113 1.5707963267948785724 0" />
    <parent link="ank_roll_link_2" />
    <child link="right_sole_link" />
    <axis xyz="0 0 1" />
    <limit effort="1" velocity="20" />
    <joint_properties friction="0.0" />
  </joint>

  <joint name="right_ank_roll" type="revolute">
    <origin xyz="0.0014999999999999933092 -2.7755575615628913511e-17 1.5634195327240973938e-16" rpy="3.1415926535897877869 -1.5707963267948930053 0" />
    <parent link="ank_pitch_link_2" />
    <child link="ank_roll_link_2" />
    <axis xyz="0 0 1" />
    <limit effort="1" velocity="20" lower="-0.785398163397448279" upper="0.785398163397448279" />
    <joint_properties friction="0.0" />
  </joint>

  <joint name="right_ank_pitch" type="revolute">
    <origin xyz="1.2797197023165297585e-16 0.10000000000000003331 -0.010400000000000304834" rpy="1.0436096434816955048e-14 1.5765166945884729896e-14 -3.1415926535897877869" />
    <parent link="right_calf_link" />
    <child link="ank_pitch_link_2" />
    <axis xyz="0 0 1" />
    <limit effort="1" velocity="20" lower="-0.785398163397448279" upper="0.95993108859688125456" />
    <joint_properties friction="0.0" />
  </joint>

  <link name="ank_motor_arm_3">
    <visual>
      <origin xyz="0 0 0" rpy="0 -0 0" />
      <geometry>
        <mesh filename="../assemblies/right_leg_XM430/meshes/right_ank_motor_arm_visual.stl" />
      </geometry>
      <material name="ank_motor_arm_material">
        <color rgba="0.62517751827980905244 0.70593642422614044651 0.75978993426662777555 1.0" />
      </material>
    </visual>
    <inertial>
      <origin xyz="0.014511489101591695805 -2.8372853113762291411e-17 0.0040925443765950624692" rpy="0 0 0" />
      <mass value="0.0020595846677894939954" />
      <inertia ixx="2.75918367565218459e-08" ixy="-1.6787019015554178031e-23" ixz="-3.0270788206594894824e-08" iyy="1.6138599216238459113e-07" iyz="-3.3444356793862933946e-23" izz="1.6437836765016314004e-07" />
    </inertial>
  </link>

  <joint name="right_ank_act_1" type="revolute">
    <origin xyz="0.01349999999999646795 0.044500000000006922907 0.0040000000000042796461" rpy="-3.078520668360990726e-13 -4.5496150843455205025e-14 0.21173394130153330717" />
    <parent link="right_calf_link" />
    <child link="ank_motor_arm_3" />
    <axis xyz="0 0 1" />
    <limit effort="1" velocity="20" lower="-1.3089969389957472057" upper="1.3089969389957472057" />
    <joint_properties friction="0.0" />
  </joint>

  <link name="ank_motor_arm_4">
    <visual>
      <origin xyz="0 0 0" rpy="0 -0 0" />
      <geometry>
        <mesh filename="../assemblies/right_leg_XM430/meshes/right_ank_motor_arm_2_visual.stl" />
      </geometry>
      <material name="ank_motor_arm_2_material">
        <color rgba="0.62517751827980905244 0.70593642422614044651 0.75978993426662777555 1.0" />
      </material>
    </visual>
    <inertial>
      <origin xyz="0.014511489101591685397 5.5284196533333376732e-19 0.0040925443765950642039" rpy="0 0 0" />
      <mass value="0.0020595846677894939954" />
      <inertia ixx="2.7591836756521968322e-08" ixy="-2.7889788036122287511e-23" ixz="-3.027078820659482865e-08" iyy="1.613859921623843529e-07" iyz="-3.6650171282913371929e-24" izz="1.6437836765016284887e-07" />
    </inertial>
  </link>

  <joint name="right_ank_act_2" type="revolute">
    <origin xyz="0.013500000000004360942 0.064500000000008050893 -0.024800000000002021816" rpy="-3.1415926535895257743 -2.0958441553975745862e-13 0.22995607267268677876" />
    <parent link="right_calf_link" />
    <child link="ank_motor_arm_4" />
    <axis xyz="0 0 1" />
    <limit effort="1" velocity="20" lower="-1.3089969389957472057" upper="1.3089969389957472057" />
    <joint_properties friction="0.0" />
  </joint>

  <joint name="right_knee_pitch" type="revolute">
    <origin xyz="8.4950131805016210509e-17 -0.095999999999999904854 -0.0091999999999998940264" rpy="-3.3306690739599518911e-15 1.3010426078690428966e-16 -3.141592653589793116" />
    <parent link="right_hip_pitch_link_xm430" />
    <child link="right_calf_link" />
    <axis xyz="0 0 1" />
    <limit effort="1" velocity="20" lower="-1.9198621771937625091" upper="0" />
    <joint_properties friction="0.0" />
  </joint>

  <link name="xm430_plate_2">
    <visual>
      <origin xyz="0 0 0" rpy="0 -0 0" />
      <geometry>
        <mesh filename="../assemblies/right_leg_XM430/meshes/right_xm430_plate_visual.stl" />
      </geometry>
      <material name="xm430_plate_material">
        <color rgba="0.61568627450980395466 0.81176470588235294379 0.92941176470588227065 1.0" />
      </material>
    </visual>
    <inertial>
      <origin xyz="9.4686491172211488466e-19 4.0403155142547559701e-18 -0.0024039046431217955119" rpy="0 0 0" />
      <mass value="0.0026999999999999997093" />
      <inertia ixx="2.6720434385876693618e-07" ixy="-6.8936588702566387474e-08" ixz="-1.5108176982532656742e-36" iyy="1.2933116645363402889e-07" iyz="-4.2274380883249519434e-36" izz="3.8533537562751439267e-07" />
    </inertial>
  </link>

  <link name="knee_rod_3">
    <visual>
      <origin xyz="0 0 0" rpy="0 -0 0" />
      <geometry>
        <mesh filename="../assemblies/right_leg_XM430/meshes/right_knee_rod_visual.stl" />
      </geometry>
      <material name="knee_rod_material">
        <color rgba="0.62051618944235198416 0.78640765248647581664 0.88594253031295022716 1.0" />
      </material>
    </visual>
    <inertial>
      <origin xyz="0.014594546907469960195 4.2152786375369768069e-05 -0.0015996227373185887589" rpy="0 0 0" />
      <mass value="0.0031629468613064179276" />
      <inertia ixx="2.5896145569812783873e-08" ixy="-3.5408233594415040455e-10" ixz="4.1682973432396374719e-10" iyy="6.0153250390525877384e-07" iyz="1.2039109459404079936e-12" izz="6.2266858519717439947e-07" />
    </inertial>
  </link>

  <joint name="right_knee_front_rev_1" type="revolute">
    <origin xyz="-0.0057402514854763535962 -0.013858192987669201712 -0.0050000000000000009714" rpy="2.2465197872961639694e-15 -3.7120791298133282167e-15 1.5650043890089946341" />
    <parent link="xm430_plate_2" />
    <child link="knee_rod_3" />
    <axis xyz="0 0 1" />
    <limit effort="1" velocity="20" lower="-6.283185307179586232" upper="6.283185307179586232" />
    <joint_properties friction="0.0" />
  </joint>

  <link name="knee_rod_4">
    <visual>
      <origin xyz="0 0 0" rpy="0 -0 0" />
      <geometry>
        <mesh filename="../assemblies/right_leg_XM430/meshes/right_knee_rod_2_visual.stl" />
      </geometry>
      <material name="knee_rod_2_material">
        <color rgba="0.62051618944235198416 0.78640765248647581664 0.88594253031295022716 1.0" />
      </material>
    </visual>
    <inertial>
      <origin xyz="0.014594546749629417476 4.2261942307114608254e-05 -0.0015996227373187431493" rpy="0 0 0" />
      <mass value="0.0031629468613064179276" />
      <inertia ixx="2.5896150873195108889e-08" ixy="-3.5499923916223374009e-10" ixz="4.1682972981661921117e-10" iyy="6.0153250125354727592e-07" iyz="1.2070285090916652e-12" izz="6.2266858784884714563e-07" />
    </inertial>
  </link>

  <joint name="right_knee_back_rev_1" type="revolute">
    <origin xyz="0.005740251485476348392 0.013858192987669160079 -0.0049999999999999489297" rpy="4.4930411149395298006e-15 -3.5910940522596879248e-15 1.5650006493639521121" />
    <parent link="xm430_plate_2" />
    <child link="knee_rod_4" />
    <axis xyz="0 0 1" />
    <limit effort="1" velocity="20" lower="-6.283185307179586232" upper="6.283185307179586232" />
    <joint_properties friction="0.0" />
  </joint>

  <joint name="right_knee_act" type="revolute">
    <origin xyz="0.00014999999999997578205 -0.061499999999999985234 -0.030400000000000010347" rpy="-6.661338147321435048e-16 -5.9952043331935243853e-15 -3.1415926535897913396" />
    <parent link="right_hip_pitch_link_xm430" />
    <child link="xm430_plate_2" />
    <axis xyz="0 0 1" />
    <limit effort="1" velocity="20" lower="-1.9198621771937625091" upper="0" />
    <joint_properties friction="0.0" />
  </joint>

  <joint name="right_hip_pitch" type="revolute">
    <origin xyz="-0.024000000716143055079 -0.019000000152443571183 -0.019000000152453538904" rpy="1.5707963267951119413 1.5707963267947451236 0" />
    <parent link="hip_roll_link_2" />
    <child link="right_hip_pitch_link_xm430" />
    <axis xyz="0 0 1" />
    <limit effort="1" velocity="20" lower="-1.570796326794896558" upper="1.570796326794896558" />
    <joint_properties friction="0.0" />
  </joint>

  <joint name="right_hip_roll" type="revolute">
    <origin xyz="-0.018999999999999992589 1.141437663717389789e-17 -0.025999999999999988398" rpy="-2.6923160331957161178e-28 -1.5707963267948961139 0" />
    <parent link="hip_yaw_link_2" />
    <child link="hip_roll_link_2" />
    <axis xyz="0 0 1" />
    <limit effort="1" velocity="20" lower="-0.785398163397448279" upper="1.570796326794896558" />
    <joint_properties friction="0.0" />
  </joint>


  <link name="sho_pitch_link">
    <visual>
      <origin xyz="0 0 0" rpy="0 -0 0" />
      <geometry>
        <mesh filename="../assemblies/left_arm_hand/meshes/left_sho_pitch_link_visual.stl" />
      </geometry>
      <material name="sho_pitch_link_material">
        <color rgba="0.61568627450980395466 0.81176470588235294379 0.92941176470588227065 1.0" />
      </material>
    </visual>
    <inertial>
      <origin xyz="5.8254247665095031947e-11 -5.1264642561120918308e-05 0.008244078812709491888" rpy="0 0 0" />
      <mass value="0.0085999999999999982708" />
      <inertia ixx="1.2272887040545796108e-06" ixy="-2.1429944209410366436e-14" ixz="-8.5847198183600595731e-15" iyy="2.9107306060364624323e-06" iyz="7.4623841398183100553e-09" izz="3.0803135950773496163e-06" />
    </inertial>
  </link>

  <link name="2xl430_gears">
    <visual>
      <origin xyz="0 0 0" rpy="0 -0 0" />
      <geometry>
        <mesh filename="../assemblies/left_arm_hand/meshes/left_2xl430_gears_visual.stl" />
      </geometry>
      <material name="2xl430_gears_material">
        <color rgba="0.7560598568794409946 0.8580469596269301169 0.91320266199377464478 1.0" />
      </material>
    </visual>
    <collision>
      <origin xyz="0 0 0" rpy="0 -0 0" />
      <geometry>
        <mesh filename="collisions/left_2xl430_gears_collision.stl" />
      </geometry>
    </collision>
    <inertial>
      <origin xyz="-0.011579403981036557811 -0.00242257661414001799 -0.018551095523803538823" rpy="0 0 0" />
      <mass value="0.1180000367452490595" />
      <inertia ixx="2.7482298083236085236e-05" ixy="9.2729623432982064947e-07" ixz="-2.2634512003761591072e-08" iyy="3.2770742486672784378e-05" iyz="-6.5708346020130210086e-07" izz="3.5767957544054292845e-05" />
    </inertial>
  </link>

  <link name="spur_1m_24t_drive">
    <visual>
      <origin xyz="0 0 0" rpy="0 -0 0" />
      <geometry>
        <mesh filename="../assemblies/left_arm_hand/meshes/left_spur_1m_24t_drive_visual.stl" />
      </geometry>
      <material name="spur_1m_24t_drive_material">
        <color rgba="0.61568627450980406568 0.81176470588235294379 0.92941176470588238168 1.0" />
      </material>
    </visual>
    <inertial>
      <origin xyz="-7.7451324365296108088e-15 -1.2123883496324656278e-16 0.0047949116178401416863" rpy="0 0 0" />
      <mass value="0.0032000000000000001533" />
      <inertia ixx="1.4019331346159890349e-07" ixy="1.6002409988426406335e-15" ixz="-2.7590023788381681633e-36" iyy="1.4019331260388786185e-07" iyz="1.4447886653902400212e-37" izz="2.3838919844264058e-07" />
    </inertial>
  </link>

  <joint name="left_sho_yaw_drive" type="revolute">
    <origin xyz="-0.024000000716141271784 -0.019000000152448497798 -0.019000000152447297369" rpy="1.570796326794886788 -1.6649913824689159326e-15 2.951073631457867516e-14" />
    <parent link="2xl430_gears" />
    <child link="spur_1m_24t_drive" />
    <axis xyz="0 0 1" />
    <limit effort="1" velocity="20" lower="-1.570796326794896558" upper="1.570796326794896558" />
    <joint_properties friction="0.0" />
  </joint>

  <link name="spur_1m_24t_driven">
    <visual>
      <origin xyz="0 0 0" rpy="0 -0 0" />
      <geometry>
        <mesh filename="../assemblies/left_arm_hand/meshes/left_spur_1m_24t_driven_visual.stl" />
      </geometry>
      <material name="spur_1m_24t_driven_material">
        <color rgba="0.2313725490196078538 0.38039215686274507888 0.7058823529411765163 1.0" />
      </material>
    </visual>
    <inertial>
      <origin xyz="2.3220762588065675388e-18 -5.798730325463341593e-15 -0.00096866348640038332785" rpy="0 0 0" />
      <mass value="0.0026999999999999992756" />
      <inertia ixx="1.2026541119643504741e-07" ixy="-4.4954231945806923146e-48" ixz="1.2986909681774403234e-36" iyy="1.2026541119643483565e-07" iyz="1.1676358468496116926e-37" izz="2.2827257365099366486e-07" />
    </inertial>
  </link>

  <link name="sho_yaw_link">
    <visual>
      <origin xyz="0 0 0" rpy="0 -0 0" />
      <geometry>
        <mesh filename="../assemblies/left_arm_hand/meshes/left_sho_yaw_link_visual.stl" />
      </geometry>
      <material name="sho_yaw_link_material">
        <color rgba="0.61568627450980395466 0.81176470588235294379 0.92941176470588238168 1.0" />
      </material>
    </visual>
    <inertial>
      <origin xyz="1.0511337010315895262e-18 4.8247714301903735524e-18 -0.024214576156328403156" rpy="0 0 0" />
      <mass value="0.014500000000000012879" />
      <inertia ixx="9.0490855102914924716e-06" ixy="3.599772940163048001e-13" ixz="-1.9687833522128349656e-35" iyy="5.6767199180624702083e-06" iyz="2.0673322214327139842e-36" izz="4.4590603637468125451e-06" />
    </inertial>
  </link>

  <link name="2xl430_gears_2">
    <visual>
      <origin xyz="0 0 0" rpy="0 -0 0" />
      <geometry>
        <mesh filename="../assemblies/left_arm_hand/meshes/left_2xl430_gears_2_visual.stl" />
      </geometry>
      <material name="2xl430_gears_2_material">
        <color rgba="0.7560598568794409946 0.8580469596269301169 0.91320266199377464478 1.0" />
      </material>
    </visual>
    <collision>
      <origin xyz="0 0 0" rpy="0 -0 0" />
      <geometry>
        <mesh filename="collisions/left_2xl430_gears_2_collision.stl" />
      </geometry>
    </collision>
    <inertial>
      <origin xyz="-0.011579403981034347773 -0.0024225766141400457455 -0.018551095523803212695" rpy="0 0 0" />
      <mass value="0.1180000367452490595" />
      <inertia ixx="2.7482298083235241591e-05" ixy="9.2729623433063994209e-07" ixz="-2.2634512003851717363e-08" iyy="3.2770742486672987666e-05" iyz="-6.5708346020124651432e-07" izz="3.5767957544053737191e-05" />
    </inertial>
  </link>

  <link name="spur_1m_24t_drive_2">
    <visual>
      <origin xyz="0 0 0" rpy="0 -0 0" />
      <geometry>
        <mesh filename="../assemblies/left_arm_hand/meshes/left_spur_1m_24t_drive_2_visual.stl" />
      </geometry>
      <material name="spur_1m_24t_drive_2_material">
        <color rgba="0.61568627450980406568 0.81176470588235294379 0.92941176470588238168 1.0" />
      </material>
    </visual>
    <inertial>
      <origin xyz="-7.7451324365296108088e-15 -1.2123883496324676e-16 0.0047949116178401382168" rpy="0 0 0" />
      <mass value="0.0032000000000000001533" />
      <inertia ixx="1.4019331346159892996e-07" ixy="1.6002410041546426147e-15" ixz="3.0907108770750589246e-37" iyy="1.4019331260388791479e-07" iyz="-9.9147138716248503567e-38" izz="2.3838919844264058e-07" />
    </inertial>
  </link>

  <joint name="left_elbow_yaw_drive" type="revolute">
    <origin xyz="-0.024000000716138836232 -0.019000000152446974711 -0.01900000015244691226" rpy="1.5707963267948983344 5.4262918776078815822e-15 5.0024824484551637689e-15" />
    <parent link="2xl430_gears_2" />
    <child link="spur_1m_24t_drive_2" />
    <axis xyz="0 0 1" />
    <limit effort="1" velocity="20" lower="-1.570796326794896558" upper="1.570796326794896558" />
    <joint_properties friction="0.0" />
  </joint>

  <link name="spur_1m_24t_driven_2">
    <visual>
      <origin xyz="0 0 0" rpy="0 -0 0" />
      <geometry>
        <mesh filename="../assemblies/left_arm_hand/meshes/left_spur_1m_24t_driven_2_visual.stl" />
      </geometry>
      <material name="spur_1m_24t_driven_2_material">
        <color rgba="0.2313725490196078538 0.38039215686274507888 0.7058823529411765163 1.0" />
      </material>
    </visual>
    <inertial>
      <origin xyz="2.3220762588070840732e-18 -5.8024355169241300519e-15 -0.00096866348640037638895" rpy="0 0 0" />
      <mass value="0.0026999999999999992756" />
      <inertia ixx="1.2026541119643504741e-07" ixy="0" ixz="-4.2376867976628461944e-38" iyy="1.2026541119643483565e-07" iyz="0" izz="2.2827257365099366486e-07" />
    </inertial>
  </link>

  <link name="elb_yaw_link">
    <visual>
      <origin xyz="0 0 0" rpy="0 -0 0" />
      <geometry>
        <mesh filename="../assemblies/left_arm_hand/meshes/left_elb_yaw_link_visual.stl" />
      </geometry>
      <material name="elb_yaw_link_material">
        <color rgba="0.61568627450980395466 0.81176470588235294379 0.9294117647058824927 1.0" />
      </material>
    </visual>
    <inertial>
      <origin xyz="5.2870889172999410497e-08 0.0019873558182742449146 -0.023365661199828729327" rpy="0 0 0" />
      <mass value="0.017499999999999998196" />
      <inertia ixx="1.4097804991252558057e-05" ixy="1.6900809684103730477e-12" ixz="-1.1184673662102780372e-11" iyy="6.6367696417680293553e-06" iyz="1.057990872258833363e-06" izz="8.9601142768980663591e-06" />
    </inertial>
  </link>

  <link name="spur_1m_24t_driven_3">
    <visual>
      <origin xyz="0 0 0" rpy="0 -0 0" />
      <geometry>
        <mesh filename="../assemblies/left_arm_hand/meshes/left_spur_1m_24t_driven_3_visual.stl" />
      </geometry>
      <material name="spur_1m_24t_driven_3_material">
        <color rgba="0.2313725490196078538 0.38039215686274507888 0.7058823529411765163 1.0" />
      </material>
    </visual>
    <inertial>
      <origin xyz="-2.5433499356822610595e-17 -5.7954966230202228235e-15 -0.0025686634864003771161" rpy="0 0 0" />
      <mass value="0.0026999999999999992756" />
      <inertia ixx="1.2026541119643504741e-07" ixy="0" ixz="1.8719165699834955332e-37" iyy="1.2026541119643483565e-07" iyz="0" izz="2.2827257365099366486e-07" />
    </inertial>
  </link>

  <link name="2xl430_gears_3">
    <visual>
      <origin xyz="0 0 0" rpy="0 -0 0" />
      <geometry>
        <mesh filename="../assemblies/left_arm_hand/meshes/left_2xl430_gears_3_visual.stl" />
      </geometry>
      <material name="2xl430_gears_3_material">
        <color rgba="0.7560598568794409946 0.8580469596269301169 0.91320266199377464478 1.0" />
      </material>
    </visual>
    <collision>
      <origin xyz="0 0 0" rpy="0 -0 0" />
      <geometry>
        <mesh filename="collisions/left_2xl430_gears_3_collision.stl" />
      </geometry>
    </collision>
    <inertial>
      <origin xyz="0.00044890447620181747742 0.011579403622954375849 -0.02457742353831019258" rpy="0 0 0" />
      <mass value="0.1180000367452490595" />
      <inertia ixx="3.5767957544054143767e-05" ixy="2.2634512003808637796e-08" ixz="6.5708346020219582649e-07" iyy="2.7482298083236979703e-05" iyz="9.2729623433153303245e-07" izz="3.2770742486671795043e-05" />
    </inertial>
  </link>

  <link name="spur_1m_24t_drive_3">
    <visual>
      <origin xyz="0 0 0" rpy="0 -0 0" />
      <geometry>
        <mesh filename="../assemblies/left_arm_hand/meshes/left_spur_1m_24t_drive_3_visual.stl" />
      </geometry>
      <material name="spur_1m_24t_drive_3_material">
        <color rgba="0.61568627450980406568 0.81176470588235294379 0.92941176470588238168 1.0" />
      </material>
    </visual>
    <inertial>
      <origin xyz="-7.7798269060491469507e-15 -1.1802132825242130039e-16 0.0047949116178401460231" rpy="0 0 0" />
      <mass value="0.0032000000000000001533" />
      <inertia ixx="1.4019331346159890349e-07" ixy="1.6002409988426406335e-15" ixz="7.8604389108627940054e-37" iyy="1.4019331260388786185e-07" iyz="-7.1848091828131645846e-37" izz="2.3838919844264058e-07" />
    </inertial>
  </link>

  <joint name="left_wrist_pitch_drive" type="revolute">
    <origin xyz="-1.5244092793631480731e-10 0.024000000358059436767 -0.0080000000000068592632" rpy="7.9382516163034810891e-16 -8.2213715709867981657e-15 -1.5707963267949174302" />
    <parent link="2xl430_gears_3" />
    <child link="spur_1m_24t_drive_3" />
    <axis xyz="0 0 1" />
    <limit effort="1" velocity="20" lower="-1.570796326794896558" upper="1.570796326794896558" />
    <joint_properties friction="0.0" />
  </joint>

  <link name="wrist_bearing_plate">
    <visual>
      <origin xyz="0 0 0" rpy="0 -0 0" />
      <geometry>
        <mesh filename="../assemblies/left_arm_hand/meshes/left_wrist_bearing_plate_visual.stl" />
      </geometry>
      <material name="wrist_bearing_plate_material">
        <color rgba="0.64496316278892629192 0.69011804996940528945 0.71706771073555886087 1.0" />
      </material>
    </visual>
    <inertial>
      <origin xyz="-0.0075896393545961402319 -0.015499999999999972133 -0.0018386110045718368107" rpy="0 0 0" />
      <mass value="0.0049000367468305548388" />
      <inertia ixx="4.9747313520140109893e-07" ixy="1.1209637001029811002e-22" ixz="1.8097509420524786327e-08" iyy="7.129502562758226908e-07" iyz="1.3782490438152935122e-23" izz="1.1926297952291895432e-06" />
    </inertial>
  </link>

  <joint name="left_wrist_roll_fixed" type="fixed">
    <origin xyz="0.01550000000000526304 -1.7097434579227410723e-14 -0.04500000000000015099" rpy="-4.0578651550049919625e-14 -2.8349544933803382357e-13 -1.5707963267949061059" />
    <parent link="2xl430_gears_3" />
    <child link="wrist_bearing_plate" />
    <axis xyz="0 0 1" />
    <limit effort="1" velocity="20" />
    <joint_properties friction="0.0" />
  </joint>

  <link name="hand">
    <visual>
      <origin xyz="0 0 0" rpy="0 -0 0" />
      <geometry>
        <mesh filename="../assemblies/left_arm_hand/meshes/left_hand_visual.stl" />
      </geometry>
      <material name="hand_material">
        <color rgba="0.61568627450980395466 0.81176470588235294379 0.92941176470588238168 1.0" />
      </material>
    </visual>
    <collision>
      <origin xyz="0 0 0" rpy="0 -0 0" />
      <geometry>
        <mesh filename="../assemblies/left_arm_hand/meshes/left_hand_collision.stl" />
      </geometry>
    </collision>
    <inertial>
      <origin xyz="-4.3038382212799598302e-08 -0.049723778585231907801 -0.017933572005390342741" rpy="0 0 0" />
      <mass value="0.017000000000001441042" />
      <inertia ixx="9.4921414617726207659e-06" ixy="-1.5549215897381269282e-11" ixz="-1.0809694196504873285e-11" iyy="4.0745028295199771232e-06" iyz="2.4719408559837088828e-07" izz="6.6623859523002746793e-06" />
    </inertial>
  </link>

  <joint name="left_wrist_roll" type="revolute">
    <origin xyz="0.019000000000005953099 -3.5808089826616651408e-10 -0.027000000152448959401" rpy="3.3651291228740167001e-14 1.5707963267946079 0" />
    <parent link="2xl430_gears_3" />
    <child link="hand" />
    <axis xyz="0 0 1" />
    <limit effort="1" velocity="20" lower="-1.570796326794896558" upper="1.570796326794896558" />
    <joint_properties friction="0.0" />
  </joint>

  <joint name="left_wrist_pitch_driven" type="revolute">
    <origin xyz="0 0 -0.0015999999999999972577" rpy="2.6611337865898239456e-16 -4.9789962509675426656e-17 -1.57079632679489678" />
    <parent link="spur_1m_24t_driven_3" />
    <child link="2xl430_gears_3" />
    <axis xyz="0 0 1" />
    <limit effort="1" velocity="20" lower="-1.570796326794896558" upper="1.570796326794896558" />
    <joint_properties friction="0.0" />
  </joint>

  <joint name="left_wrist_pitch_fixed" type="fixed">
    <origin xyz="3.4694469519536141888e-18 -0.025300000000000003042 -0.05200000000000001843" rpy="1.570796326794896558 -1.570796326794896558 0" />
    <parent link="elb_yaw_link" />
    <child link="spur_1m_24t_driven_3" />
    <axis xyz="0 0 1" />
    <limit effort="1" velocity="20" />
    <joint_properties friction="0.0" />
  </joint>

  <joint name="left_elbow_yaw_fixed" type="fixed">
    <origin xyz="-1.498879432863449632e-17 3.1225022567582527699e-17 0.0015999999999999903189" rpy="3.141592653589793116 6.1232339945831272199e-17 -1.57079632679489678" />
    <parent link="spur_1m_24t_driven_2" />
    <child link="elb_yaw_link" />
    <axis xyz="0 0 1" />
    <limit effort="1" velocity="20" />
    <joint_properties friction="0.0" />
  </joint>

  <joint name="left_elbow_yaw_driven" type="revolute">
    <origin xyz="-3.5806832845985958613e-10 -0.027000000152447967139 -0.019000000000002903455" rpy="1.5707963267948912289 1.5707963267948950037 0" />
    <parent link="2xl430_gears_2" />
    <child link="spur_1m_24t_driven_2" />
    <axis xyz="0 0 1" />
    <limit effort="1" velocity="20" lower="-1.570796326794896558" upper="1.570796326794896558" />
    <joint_properties friction="0.0" />
  </joint>

  <joint name="left_elbow_roll" type="revolute">
    <origin xyz="0 -0.019000000000000002998 -0.059000000000000010769" rpy="1.570796326794896558 7.8238344481275579773e-14 -2.6785925512137038591e-14" />
    <parent link="sho_yaw_link" />
    <child link="2xl430_gears_2" />
    <axis xyz="0 0 1" />
    <limit effort="1" velocity="20" lower="-1.570796326794896558" upper="1.570796326794896558" />
    <joint_properties friction="0.0" />
  </joint>

  <joint name="left_sho_yaw_fixed" type="fixed">
    <origin xyz="-6.9388939039072283776e-18 -3.9443045261050590271e-31 0.0015999999999999972577" rpy="-3.141592653589793116 3.4918029198749163057e-28 2.4932009224355828724e-30" />
    <parent link="spur_1m_24t_driven" />
    <child link="sho_yaw_link" />
    <axis xyz="0 0 1" />
    <limit effort="1" velocity="20" />
    <joint_properties friction="0.0" />
  </joint>

  <joint name="left_sho_yaw_driven" type="revolute">
    <origin xyz="-3.5807099299511868651e-10 -0.027000000152450111257 -0.019000000000003024886" rpy="1.5707963267949034414 2.5500465800399195135e-14 -4.8895009770147760892e-15" />
    <parent link="2xl430_gears" />
    <child link="spur_1m_24t_driven" />
    <axis xyz="0 0 1" />
    <limit effort="1" velocity="20" lower="-1.570796326794896558" upper="1.570796326794896558" />
    <joint_properties friction="0.0" />
  </joint>

  <joint name="left_sho_roll" type="revolute">
    <origin xyz="-0.018999999999999999528 0.0010000000000000076102 0.027000000000000003164" rpy="-3.141592653589793116 1.5707963267947588903 0" />
    <parent link="sho_pitch_link" />
    <child link="2xl430_gears" />
    <axis xyz="0 0 1" />
    <limit effort="1" velocity="20" lower="-1.570796326794896558" upper="0" />
    <joint_properties friction="0.0" />
  </joint>


  <link name="sho_pitch_link_2">
    <visual>
      <origin xyz="0 0 0" rpy="0 -0 0" />
      <geometry>
        <mesh filename="../assemblies/right_arm_hand/meshes/right_sho_pitch_link_visual.stl" />
      </geometry>
      <material name="sho_pitch_link_material">
        <color rgba="0.61568627450980395466 0.81176470588235294379 0.92941176470588227065 1.0" />
      </material>
    </visual>
    <inertial>
      <origin xyz="5.8254247665095031947e-11 -5.1264642561120918308e-05 0.008244078812709491888" rpy="0 0 0" />
      <mass value="0.0085999999999999982708" />
      <inertia ixx="1.2272887040545796108e-06" ixy="-2.1429944209410366436e-14" ixz="-8.5847198183600595731e-15" iyy="2.9107306060364624323e-06" iyz="7.4623841398183100553e-09" izz="3.0803135950773496163e-06" />
    </inertial>
  </link>

  <link name="2xl430_gears_4">
    <visual>
      <origin xyz="0 0 0" rpy="0 -0 0" />
      <geometry>
        <mesh filename="../assemblies/right_arm_hand/meshes/right_2xl430_gears_visual.stl" />
      </geometry>
      <material name="2xl430_gears_material">
        <color rgba="0.7560598568794409946 0.8580469596269301169 0.91320266199377464478 1.0" />
      </material>
    </visual>
    <collision>
      <origin xyz="0 0 0" rpy="0 -0 0" />
      <geometry>
        <mesh filename="collisions/right_2xl430_gears_collision.stl" />
      </geometry>
    </collision>
    <inertial>
      <origin xyz="-0.011579403981034821353 -0.002422576614140263887 -0.018551095523804388837" rpy="0 0 0" />
      <mass value="0.1180000367452490595" />
      <inertia ixx="2.7482298083236305464e-05" ixy="9.2729623432947537767e-07" ixz="-2.2634512004124445428e-08" iyy="3.2770742486672947008e-05" iyz="-6.570834602013373586e-07" izz="3.5767957544054530014e-05" />
    </inertial>
  </link>

  <link name="spur_1m_24t_drive_4">
    <visual>
      <origin xyz="0 0 0" rpy="0 -0 0" />
      <geometry>
        <mesh filename="../assemblies/right_arm_hand/meshes/right_spur_1m_24t_drive_visual.stl" />
      </geometry>
      <material name="spur_1m_24t_drive_material">
        <color rgba="0.61568627450980406568 0.81176470588235294379 0.92941176470588238168 1.0" />
      </material>
    </visual>
    <inertial>
      <origin xyz="-7.745132436529609231e-15 -1.2123883498909615414e-16 0.0047949116178401442884" rpy="0 0 0" />
      <mass value="0.0032000000000000001533" />
      <inertia ixx="1.4019331346159885055e-07" ixy="1.6002409976221174075e-15" ixz="-3.3725439700307396967e-36" iyy="1.4019331260388791479e-07" iyz="3.7162875711380680936e-37" izz="2.3838919844264068588e-07" />
    </inertial>
  </link>

  <joint name="right_sho_yaw_drive" type="revolute">
    <origin xyz="-0.024000000716138513573 -0.019000000152446919199 -0.019000000152449438018" rpy="1.5707963267949425212 -7.4825707768639476445e-14 5.2729872485629252068e-14" />
    <parent link="2xl430_gears_4" />
    <child link="spur_1m_24t_drive_4" />
    <axis xyz="0 0 1" />
    <limit effort="1" velocity="20" lower="-1.570796326794896558" upper="1.570796326794896558" />
    <joint_properties friction="0.0" />
  </joint>

  <link name="spur_1m_24t_driven_4">
    <visual>
      <origin xyz="0 0 0" rpy="0 -0 0" />
      <geometry>
        <mesh filename="../assemblies/right_arm_hand/meshes/right_spur_1m_24t_driven_visual.stl" />
      </geometry>
      <material name="spur_1m_24t_driven_material">
        <color rgba="0.2313725490196078538 0.38039215686274507888 0.7058823529411765163 1.0" />
      </material>
    </visual>
    <inertial>
      <origin xyz="2.3220762588062982937e-18 -5.7987303254633400153e-15 -0.00096866348640037638895" rpy="0 0 0" />
      <mass value="0.0026999999999999992756" />
      <inertia ixx="1.2026541119643504741e-07" ixy="5.2847048168055838253e-37" ixz="-1.2726338952314176975e-38" iyy="1.2026541119643483565e-07" iyz="-1.211356248268672151e-36" izz="2.2827257365099366486e-07" />
    </inertial>
  </link>

  <link name="sho_yaw_link_2">
    <visual>
      <origin xyz="0 0 0" rpy="0 -0 0" />
      <geometry>
        <mesh filename="../assemblies/right_arm_hand/meshes/right_sho_yaw_link_visual.stl" />
      </geometry>
      <material name="sho_yaw_link_material">
        <color rgba="0.61568627450980395466 0.81176470588235294379 0.92941176470588238168 1.0" />
      </material>
    </visual>
    <inertial>
      <origin xyz="1.0511337010314446962e-18 4.824771430190977524e-18 -0.024214576156328403156" rpy="0 0 0" />
      <mass value="0.014500000000000012879" />
      <inertia ixx="9.0490855102914924716e-06" ixy="3.599772940163048001e-13" ixz="-1.5560945723103426397e-36" iyy="5.6767199180624702083e-06" iyz="-2.9419992751368714628e-35" izz="4.4590603637468125451e-06" />
    </inertial>
  </link>

  <link name="2xl430_gears_5">
    <visual>
      <origin xyz="0 0 0" rpy="0 -0 0" />
      <geometry>
        <mesh filename="../assemblies/right_arm_hand/meshes/right_2xl430_gears_2_visual.stl" />
      </geometry>
      <material name="2xl430_gears_2_material">
        <color rgba="0.7560598568794409946 0.8580469596269301169 0.91320266199377464478 1.0" />
      </material>
    </visual>
    <collision>
      <origin xyz="0 0 0" rpy="0 -0 0" />
      <geometry>
        <mesh filename="collisions/right_2xl430_gears_2_collision.stl" />
      </geometry>
    </collision>
    <inertial>
      <origin xyz="-0.011579403981039061017 -0.0024225766141394633121 -0.018551095523804617821" rpy="0 0 0" />
      <mass value="0.1180000367452490595" />
      <inertia ixx="2.7482298083236664606e-05" ixy="9.272962343288495262e-07" ixz="-2.2634512003316203943e-08" iyy="3.2770742486673401018e-05" iyz="-6.5708346020122967954e-07" izz="3.5767957544054685868e-05" />
    </inertial>
  </link>

  <link name="spur_1m_24t_drive_5">
    <visual>
      <origin xyz="0 0 0" rpy="0 -0 0" />
      <geometry>
        <mesh filename="../assemblies/right_arm_hand/meshes/right_spur_1m_24t_drive_2_visual.stl" />
      </geometry>
      <material name="spur_1m_24t_drive_2_material">
        <color rgba="0.61568627450980406568 0.81176470588235294379 0.92941176470588238168 1.0" />
      </material>
    </visual>
    <inertial>
      <origin xyz="-7.7520713304335164594e-15 -1.2123883498909595692e-16 0.0047949116178401382168" rpy="0 0 0" />
      <mass value="0.0032000000000000001533" />
      <inertia ixx="1.4019331346159885055e-07" ixy="1.6002410034284993069e-15" ixz="3.9902666707235194198e-36" iyy="1.4019331260388783538e-07" iyz="3.4574783485106886014e-36" izz="2.3838919844264058e-07" />
    </inertial>
  </link>

  <joint name="right_elbow_yaw_drive" type="revolute">
    <origin xyz="-0.024000000716145213076 -0.019000000152448681678 -0.019000000152448712903" rpy="1.5707963267950251218 7.4561439664805901366e-16 -7.8480721140448757714e-14" />
    <parent link="2xl430_gears_5" />
    <child link="spur_1m_24t_drive_5" />
    <axis xyz="0 0 1" />
    <limit effort="1" velocity="20" lower="-1.570796326794896558" upper="1.570796326794896558" />
    <joint_properties friction="0.0" />
  </joint>

  <link name="spur_1m_24t_driven_5">
    <visual>
      <origin xyz="0 0 0" rpy="0 -0 0" />
      <geometry>
        <mesh filename="../assemblies/right_arm_hand/meshes/right_spur_1m_24t_driven_2_visual.stl" />
      </geometry>
      <material name="spur_1m_24t_driven_2_material">
        <color rgba="0.2313725490196078538 0.38039215686274507888 0.7058823529411765163 1.0" />
      </material>
    </visual>
    <inertial>
      <origin xyz="2.3220762588062979086e-18 -5.7987303254633400153e-15 -0.00096866348640037638895" rpy="0 0 0" />
      <mass value="0.0026999999999999992756" />
      <inertia ixx="1.2026541119643504741e-07" ixy="0" ixz="0" iyy="1.2026541119643483565e-07" iyz="-9.4918233967974254824e-37" izz="2.2827257365099366486e-07" />
    </inertial>
  </link>

  <link name="elb_yaw_link_2">
    <visual>
      <origin xyz="0 0 0" rpy="0 -0 0" />
      <geometry>
        <mesh filename="../assemblies/right_arm_hand/meshes/right_elb_yaw_link_visual.stl" />
      </geometry>
      <material name="elb_yaw_link_material">
        <color rgba="0.61568627450980395466 0.81176470588235294379 0.9294117647058824927 1.0" />
      </material>
    </visual>
    <inertial>
      <origin xyz="5.2870889172999410497e-08 0.0019873558182742449146 -0.023365661199828736266" rpy="0 0 0" />
      <mass value="0.017499999999999998196" />
      <inertia ixx="1.4097804991252558057e-05" ixy="1.6900809684103730477e-12" ixz="-1.1184673662102783603e-11" iyy="6.6367696417680293553e-06" iyz="1.0579908722588335747e-06" izz="8.9601142768980697473e-06" />
    </inertial>
  </link>

  <link name="spur_1m_24t_driven_6">
    <visual>
      <origin xyz="0 0 0" rpy="0 -0 0" />
      <geometry>
        <mesh filename="../assemblies/right_arm_hand/meshes/right_spur_1m_24t_driven_3_visual.stl" />
      </geometry>
      <material name="spur_1m_24t_driven_3_material">
        <color rgba="0.2313725490196078538 0.38039215686274507888 0.7058823529411765163 1.0" />
      </material>
    </visual>
    <inertial>
      <origin xyz="2.3220762588060598636e-18 -5.8024355169241300519e-15 -0.0025686634864003771161" rpy="0 0 0" />
      <mass value="0.0026999999999999992756" />
      <inertia ixx="1.2026541119643504741e-07" ixy="-4.7860678020607527085e-37" ixz="-2.8055496736001201518e-36" iyy="1.2026541119643483565e-07" iyz="3.6352587214270437197e-37" izz="2.2827257365099366486e-07" />
    </inertial>
  </link>

  <link name="2xl430_gears_6">
    <visual>
      <origin xyz="0 0 0" rpy="0 -0 0" />
      <geometry>
        <mesh filename="../assemblies/right_arm_hand/meshes/right_2xl430_gears_3_visual.stl" />
      </geometry>
      <material name="2xl430_gears_3_material">
        <color rgba="0.7560598568794409946 0.8580469596269301169 0.91320266199377464478 1.0" />
      </material>
    </visual>
    <collision>
      <origin xyz="0 0 0" rpy="0 -0 0" />
      <geometry>
        <mesh filename="collisions/right_2xl430_gears_3_collision.stl" />
      </geometry>
    </collision>
    <inertial>
      <origin xyz="0.00044890447619843536296 0.011579403622970654494 -0.024577423538311958529" rpy="0 0 0" />
      <mass value="0.1180000367452490595" />
      <inertia ixx="3.5767957544055871714e-05" ixy="2.2634512003787700201e-08" ixz="6.5708346020150464761e-07" iyy="2.7482298083237169438e-05" iyz="9.2729623433000720848e-07" izz="3.2770742486673536543e-05" />
    </inertial>
  </link>

  <link name="spur_1m_24t_drive_6">
    <visual>
      <origin xyz="0 0 0" rpy="0 -0 0" />
      <geometry>
        <mesh filename="../assemblies/right_arm_hand/meshes/right_spur_1m_24t_drive_3_visual.stl" />
      </geometry>
      <material name="spur_1m_24t_drive_3_material">
        <color rgba="0.61568627450980406568 0.81176470588235294379 0.92941176470588238168 1.0" />
      </material>
    </visual>
    <inertial>
      <origin xyz="-7.7520713304335180371e-15 -1.2149077520437491458e-16 0.0047949116178401460231" rpy="0 0 0" />
      <mass value="0.0032000000000000001533" />
      <inertia ixx="1.4019331346159890349e-07" ixy="1.6002409988426406335e-15" ixz="1.9140638633296153923e-36" iyy="1.4019331260388786185e-07" iyz="6.3223716998931470865e-37" izz="2.3838919844264058e-07" />
    </inertial>
  </link>

  <joint name="right_wrist_pitch_drive" type="revolute">
    <origin xyz="-1.5244519882551266221e-10 0.0240000003580740362 -0.0080000000000021130597" rpy="-2.1390725319341436483e-14 -2.6312285683659641534e-14 -1.5707963267949076602" />
    <parent link="2xl430_gears_6" />
    <child link="spur_1m_24t_drive_6" />
    <axis xyz="0 0 1" />
    <limit effort="1" velocity="20" lower="-1.570796326794896558" upper="1.570796326794896558" />
    <joint_properties friction="0.0" />
  </joint>

  <link name="wrist_bearing_plate_2">
    <visual>
      <origin xyz="0 0 0" rpy="0 -0 0" />
      <geometry>
        <mesh filename="../assemblies/right_arm_hand/meshes/right_wrist_bearing_plate_visual.stl" />
      </geometry>
      <material name="wrist_bearing_plate_material">
        <color rgba="0.64496316278892629192 0.69011804996940528945 0.71706771073555886087 1.0" />
      </material>
    </visual>
    <inertial>
      <origin xyz="-0.0075896393545961463034 -0.015499999999999977338 -0.0018386110045718420149" rpy="0 0 0" />
      <mass value="0.0049000367468305548388" />
      <inertia ixx="4.9747313520140067541e-07" ixy="-8.7414694312869159183e-23" ixz="1.8097509420524766475e-08" iyy="7.1295025627582205553e-07" iyz="1.5611689182720965776e-22" izz="1.1926297952291891197e-06" />
    </inertial>
  </link>

  <joint name="right_wrist_roll_fixed" type="fixed">
    <origin xyz="0.015500000000002378195 7.7160500211448379559e-15 -0.045000000000006055989" rpy="-4.8017145823115337576e-14 1.2051470932306253475e-13 -1.570796326794896558" />
    <parent link="2xl430_gears_6" />
    <child link="wrist_bearing_plate_2" />
    <axis xyz="0 0 1" />
    <limit effort="1" velocity="20" />
    <joint_properties friction="0.0" />
  </joint>

  <link name="hand_2">
    <visual>
      <origin xyz="0 0 0" rpy="0 -0 0" />
      <geometry>
        <mesh filename="../assemblies/right_arm_hand/meshes/right_hand_visual.stl" />
      </geometry>
      <material name="hand_material">
        <color rgba="0.61568627450980395466 0.81176470588235294379 0.92941176470588238168 1.0" />
      </material>
    </visual>
    <collision>
      <origin xyz="0 0 0" rpy="0 -0 0" />
      <geometry>
        <mesh filename="../assemblies/right_arm_hand/meshes/right_hand_collision.stl" />
      </geometry>
    </collision>
    <inertial>
      <origin xyz="-4.3038382212365917433e-08 0.049723778585231921678 -0.020066427994609656316" rpy="0 0 0" />
      <mass value="0.017000000000001441042" />
      <inertia ixx="9.4921414617726207659e-06" ixy="1.5549215897381272513e-11" ixz="1.0809694196504874901e-11" iyy="4.0745028295199788173e-06" iyz="2.4719408559837099416e-07" izz="6.6623859523002780674e-06" />
    </inertial>
  </link>

  <joint name="right_wrist_roll" type="revolute">
    <origin xyz="0.019000000000002986722 -3.5806504983248998997e-10 -0.027000000152453823565" rpy="-3.1415926535897797933 -1.5707963267947699926 0" />
    <parent link="2xl430_gears_6" />
    <child link="hand_2" />
    <axis xyz="0 0 1" />
    <limit effort="1" velocity="20" lower="-1.570796326794896558" upper="1.570796326794896558" />
    <joint_properties friction="0.0" />
  </joint>

  <joint name="right_wrist_pitch_driven" type="revolute">
    <origin xyz="0 -3.4694469519536141888e-18 -0.0015999999999999937883" rpy="2.5695941831520308968e-14 -1.8435423390073007778e-14 1.570796326794896336" />
    <parent link="spur_1m_24t_driven_6" />
    <child link="2xl430_gears_6" />
    <axis xyz="0 0 1" />
    <limit effort="1" velocity="20" lower="-1.570796326794896558" upper="1.570796326794896558" />
    <joint_properties friction="0.0" />
  </joint>

  <joint name="right_wrist_pitch_fixed" type="fixed">
    <origin xyz="0 -0.025300000000000003042 -0.052000000000000032307" rpy="1.5707963267949045516 1.570796326794896558 0" />
    <parent link="elb_yaw_link_2" />
    <child link="spur_1m_24t_driven_6" />
    <axis xyz="0 0 1" />
    <limit effort="1" velocity="20" />
    <joint_properties friction="0.0" />
  </joint>

  <joint name="right_elbow_yaw_fixed" type="fixed">
    <origin xyz="0 -7.8886090522101180541e-31 0.0015999999999999903189" rpy="-3.1415926535897917837 -3.113586376513707077e-30 -9.3975474487378148241e-30" />
    <parent link="spur_1m_24t_driven_5" />
    <child link="elb_yaw_link_2" />
    <axis xyz="0 0 1" />
    <limit effort="1" velocity="20" />
    <joint_properties friction="0.0" />
  </joint>

  <joint name="right_elbow_yaw_driven" type="revolute">
    <origin xyz="-3.5807097564788392674e-10 -0.027000000152451450464 -0.019000000000002660594" rpy="1.570796326794921427 8.594260651656727047e-14 -2.9577354942701670305e-14" />
    <parent link="2xl430_gears_5" />
    <child link="spur_1m_24t_driven_5" />
    <axis xyz="0 0 1" />
    <limit effort="1" velocity="20" lower="-1.570796326794896558" upper="1.570796326794896558" />
    <joint_properties friction="0.0" />
  </joint>

  <joint name="right_elbow_roll" type="revolute">
    <origin xyz="1.3634926521177703762e-15 -0.018999999999998080924 -0.058999999999999955258" rpy="1.570796326794896558 4.7458355760175941122e-14 -1.8179902027463432622e-15" />
    <parent link="sho_yaw_link_2" />
    <child link="2xl430_gears_5" />
    <axis xyz="0 0 1" />
    <limit effort="1" velocity="20" lower="-1.570796326794896558" upper="1.570796326794896558" />
    <joint_properties friction="0.0" />
  </joint>

  <joint name="right_sho_yaw_fixed" type="fixed">
    <origin xyz="-1.4641066137244251877e-15 2.0460946366117099189e-16 0.0015999999999999764411" rpy="-3.1415926535897917837 7.3983136435191466048e-16 1.4710455076273571868e-15" />
    <parent link="spur_1m_24t_driven_4" />
    <child link="sho_yaw_link_2" />
    <axis xyz="0 0 1" />
    <limit effort="1" velocity="20" />
    <joint_properties friction="0.0" />
  </joint>

  <joint name="right_sho_yaw_driven" type="revolute">
    <origin xyz="-3.5806542800220775291e-10 -0.027000000152447953261 -0.019000000000004266948" rpy="1.5707963267949396347 -3.5760623773800501683e-14 -2.120003783509950459e-15" />
    <parent link="2xl430_gears_4" />
    <child link="spur_1m_24t_driven_4" />
    <axis xyz="0 0 1" />
    <limit effort="1" velocity="20" lower="-1.570796326794896558" upper="1.570796326794896558" />
    <joint_properties friction="0.0" />
  </joint>

  <joint name="right_sho_roll" type="revolute">
    <origin xyz="-0.01899999999999998565 0.0010000000000000112965 0.027000000000000013572" rpy="3.141592653589793116 1.570796326794896558 0" />
    <parent link="sho_pitch_link_2" />
    <child link="2xl430_gears_4" />
    <axis xyz="0 0 1" />
    <limit effort="1" velocity="20" lower="-1.570796326794896558" upper="0" />
    <joint_properties friction="0.0" />
  </joint>


</robot>