<mujoco model="toddlerbot">
  <compiler angle="radian" autolimits="true" />
  <asset>
    <mesh name="torso_visual" file="../assemblies/toddlerbot/meshes/torso_visual.stl" />
    <mesh name="spur_1m_20t_visual" file="../assemblies/toddlerbot/meshes/spur_1m_20t_visual.stl" />
    <mesh name="neck_yaw_link_visual" file="../assemblies/toddlerbot/meshes/neck_yaw_link_visual.stl" />
    <mesh name="neck_pitch_link_visual" file="../assemblies/toddlerbot/meshes/neck_pitch_link_visual.stl" />
    <mesh name="spur_gear_(13_teeth)_visual" file="../assemblies/toddlerbot/meshes/spur_gear_(13_teeth)_visual.stl" />
    <mesh name="waist_gears_visual" file="../assemblies/toddlerbot/meshes/waist_gears_visual.stl" />
    <mesh name="waist_link_visual" file="../assemblies/toddlerbot/meshes/waist_link_visual.stl" />
    <mesh name="spiral_bevel_1m_14t_30deg_visual" file="../assemblies/toddlerbot/meshes/spiral_bevel_1m_14t_30deg_visual.stl" />
    <mesh name="spiral_bevel_1m_14t_30deg_2_visual" file="../assemblies/toddlerbot/meshes/spiral_bevel_1m_14t_30deg_2_visual.stl" />
    <mesh name="spur_gear_19_teeth_visual" file="../assemblies/toddlerbot/meshes/spur_gear_19_teeth_visual.stl" />
    <mesh name="spur_gear_21_teeth_visual" file="../assemblies/toddlerbot/meshes/spur_gear_21_teeth_visual.stl" />
    <mesh name="spur_gear_19_teeth_2_visual" file="../assemblies/toddlerbot/meshes/spur_gear_19_teeth_2_visual.stl" />
    <mesh name="spur_gear_21_teeth_2_visual" file="../assemblies/toddlerbot/meshes/spur_gear_21_teeth_2_visual.stl" />
    <mesh name="left_hip_yaw_link_visual" file="../assemblies/left_leg_XM430/meshes/left_hip_yaw_link_visual.stl" />
    <mesh name="left_hip_roll_link_visual" file="../assemblies/left_leg_XM430/meshes/left_hip_roll_link_visual.stl" />
    <mesh name="left_hip_pitch_link_xm430_visual" file="../assemblies/left_leg_XM430/meshes/left_hip_pitch_link_xm430_visual.stl" />
    <mesh name="left_calf_link_visual" file="../assemblies/left_leg_XM430/meshes/left_calf_link_visual.stl" />
    <mesh name="left_ank_pitch_link_visual" file="../assemblies/left_leg_XM430/meshes/left_ank_pitch_link_visual.stl" />
    <mesh name="left_ank_roll_link_visual" file="../assemblies/left_leg_XM430/meshes/left_ank_roll_link_visual.stl" />
    <mesh name="left_ank_rr_link_visual" file="../assemblies/left_leg_XM430/meshes/left_ank_rr_link_visual.stl" />
    <mesh name="left_ank_motor_rod_long_visual" file="../assemblies/left_leg_XM430/meshes/left_ank_motor_rod_long_visual.stl" />
    <mesh name="left_ank_rr_link_2_visual" file="../assemblies/left_leg_XM430/meshes/left_ank_rr_link_2_visual.stl" />
    <mesh name="left_ank_motor_rod_short_visual" file="../assemblies/left_leg_XM430/meshes/left_ank_motor_rod_short_visual.stl" />
    <mesh name="left_ank_motor_arm_visual" file="../assemblies/left_leg_XM430/meshes/left_ank_motor_arm_visual.stl" />
    <mesh name="left_ank_motor_arm_2_visual" file="../assemblies/left_leg_XM430/meshes/left_ank_motor_arm_2_visual.stl" />
    <mesh name="right_hip_yaw_link_visual" file="../assemblies/right_leg_XM430/meshes/right_hip_yaw_link_visual.stl" />
    <mesh name="right_hip_roll_link_visual" file="../assemblies/right_leg_XM430/meshes/right_hip_roll_link_visual.stl" />
    <mesh name="right_hip_pitch_link_xm430_visual" file="../assemblies/right_leg_XM430/meshes/right_hip_pitch_link_xm430_visual.stl" />
    <mesh name="right_calf_link_visual" file="../assemblies/right_leg_XM430/meshes/right_calf_link_visual.stl" />
    <mesh name="right_ank_pitch_link_visual" file="../assemblies/right_leg_XM430/meshes/right_ank_pitch_link_visual.stl" />
    <mesh name="right_ank_roll_link_visual" file="../assemblies/right_leg_XM430/meshes/right_ank_roll_link_visual.stl" />
    <mesh name="right_ank_rr_link_visual" file="../assemblies/right_leg_XM430/meshes/right_ank_rr_link_visual.stl" />
    <mesh name="right_ank_motor_rod_long_visual" file="../assemblies/right_leg_XM430/meshes/right_ank_motor_rod_long_visual.stl" />
    <mesh name="right_ank_rr_link_2_visual" file="../assemblies/right_leg_XM430/meshes/right_ank_rr_link_2_visual.stl" />
    <mesh name="right_ank_motor_rod_short_visual" file="../assemblies/right_leg_XM430/meshes/right_ank_motor_rod_short_visual.stl" />
    <mesh name="right_ank_motor_arm_visual" file="../assemblies/right_leg_XM430/meshes/right_ank_motor_arm_visual.stl" />
    <mesh name="right_ank_motor_arm_2_visual" file="../assemblies/right_leg_XM430/meshes/right_ank_motor_arm_2_visual.stl" />
    <mesh name="left_xc430_visual" file="../assemblies/left_arm_hand/meshes/left_xc430_visual.stl" />
    <mesh name="left_sho_pitch_link_visual" file="../assemblies/left_arm_hand/meshes/left_sho_pitch_link_visual.stl" />
    <mesh name="left_2xl430_gears_visual" file="../assemblies/left_arm_hand/meshes/left_2xl430_gears_visual.stl" />
    <mesh name="left_spur_1m_24t_drive_visual" file="../assemblies/left_arm_hand/meshes/left_spur_1m_24t_drive_visual.stl" />
    <mesh name="left_spur_1m_24t_driven_visual" file="../assemblies/left_arm_hand/meshes/left_spur_1m_24t_driven_visual.stl" />
    <mesh name="left_sho_yaw_link_visual" file="../assemblies/left_arm_hand/meshes/left_sho_yaw_link_visual.stl" />
    <mesh name="left_2xl430_gears_2_visual" file="../assemblies/left_arm_hand/meshes/left_2xl430_gears_2_visual.stl" />
    <mesh name="left_spur_1m_24t_drive_2_visual" file="../assemblies/left_arm_hand/meshes/left_spur_1m_24t_drive_2_visual.stl" />
    <mesh name="left_spur_1m_24t_driven_2_visual" file="../assemblies/left_arm_hand/meshes/left_spur_1m_24t_driven_2_visual.stl" />
    <mesh name="left_elb_yaw_link_visual" file="../assemblies/left_arm_hand/meshes/left_elb_yaw_link_visual.stl" />
    <mesh name="left_spur_1m_24t_driven_3_visual" file="../assemblies/left_arm_hand/meshes/left_spur_1m_24t_driven_3_visual.stl" />
    <mesh name="left_2xl430_gears_3_visual" file="../assemblies/left_arm_hand/meshes/left_2xl430_gears_3_visual.stl" />
    <mesh name="left_spur_1m_24t_drive_3_visual" file="../assemblies/left_arm_hand/meshes/left_spur_1m_24t_drive_3_visual.stl" />
    <mesh name="left_wrist_bearing_plate_visual" file="../assemblies/left_arm_hand/meshes/left_wrist_bearing_plate_visual.stl" />
    <mesh name="left_hand_visual" file="../assemblies/left_arm_hand/meshes/left_hand_visual.stl" />
    <mesh name="right_xc430_visual" file="../assemblies/right_arm_hand/meshes/right_xc430_visual.stl" />
    <mesh name="right_sho_pitch_link_visual" file="../assemblies/right_arm_hand/meshes/right_sho_pitch_link_visual.stl" />
    <mesh name="right_2xl430_gears_visual" file="../assemblies/right_arm_hand/meshes/right_2xl430_gears_visual.stl" />
    <mesh name="right_spur_1m_24t_drive_visual" file="../assemblies/right_arm_hand/meshes/right_spur_1m_24t_drive_visual.stl" />
    <mesh name="right_spur_1m_24t_driven_visual" file="../assemblies/right_arm_hand/meshes/right_spur_1m_24t_driven_visual.stl" />
    <mesh name="right_sho_yaw_link_visual" file="../assemblies/right_arm_hand/meshes/right_sho_yaw_link_visual.stl" />
    <mesh name="right_2xl430_gears_2_visual" file="../assemblies/right_arm_hand/meshes/right_2xl430_gears_2_visual.stl" />
    <mesh name="right_spur_1m_24t_drive_2_visual" file="../assemblies/right_arm_hand/meshes/right_spur_1m_24t_drive_2_visual.stl" />
    <mesh name="right_spur_1m_24t_driven_2_visual" file="../assemblies/right_arm_hand/meshes/right_spur_1m_24t_driven_2_visual.stl" />
    <mesh name="right_elb_yaw_link_visual" file="../assemblies/right_arm_hand/meshes/right_elb_yaw_link_visual.stl" />
    <mesh name="right_spur_1m_24t_driven_3_visual" file="../assemblies/right_arm_hand/meshes/right_spur_1m_24t_driven_3_visual.stl" />
    <mesh name="right_2xl430_gears_3_visual" file="../assemblies/right_arm_hand/meshes/right_2xl430_gears_3_visual.stl" />
    <mesh name="right_spur_1m_24t_drive_3_visual" file="../assemblies/right_arm_hand/meshes/right_spur_1m_24t_drive_3_visual.stl" />
    <mesh name="right_wrist_bearing_plate_visual" file="../assemblies/right_arm_hand/meshes/right_wrist_bearing_plate_visual.stl" />
    <mesh name="right_hand_visual" file="../assemblies/right_arm_hand/meshes/right_hand_visual.stl" />
  </asset>
  <worldbody>
    <body name="torso" pos="0 0 0" quat="1 0 0 0">
      <inertial pos="-0.017583 -0.000889 0.066328" quat="1.000000 0.000000 0.000000 0.000000" mass="0.38210896" diaginertia="9.79131e-04 8.87673e-04 6.85824e-04" />
      <freejoint />
      <site name="imu" size="0.01" pos="0.0 0 0.0" />
      <site name="torso" fromto="0.01 0 0.4 -0.01 0 0.4" type="cylinder" size="0.005 0.005 1" group="3" />
      <geom rgba="0.619785 0.804975 0.912387 1" mesh="torso_visual" class="visual" />
      <geom pos="0.001 0.049 0.119487" quat="1 0 0 0" rgba="0.396033 0.508784 0.711268 1" mesh="left_xc430_visual" class="visual" />
      <geom pos="0.001 -0.049 0.119487" quat="1 0 0 0" rgba="0.396033 0.508784 0.711268 1" mesh="right_xc430_visual" class="visual" />
      <body name="spur_1m_20t" pos="-0.005 0 0.122487" quat="0 -1 0 0">
        <inertial pos="0 0 -0.0033746" quat="0.5 0.5 -0.5 0.5" mass="0.0015535" diaginertia="7.95589e-08 4.47265e-08 4.47265e-08" />
        <joint name="neck_yaw_drive" pos="0 0 0" axis="0 0 1" limited="true" range="-3.14159 3.14159" damping="0.099" armature="0.002" frictionloss="0.239" />
        <geom rgba="0.647059 0.647059 0.647059 1" mesh="spur_1m_20t_visual" class="visual" />
      </body>
      <body name="neck_yaw_link" pos="0.016 0 0.123487" quat="0 0 1 0">
        <inertial pos="2.72913e-05 0.00019799 -0.0115274" quat="0.706957 0.0132325 -0.0136941 0.707" mass="0.00851683" diaginertia="1.12518e-06 1.04071e-06 3.14701e-07" />
        <joint name="neck_yaw_driven" pos="0 0 0" axis="0 0 1" limited="true" range="-3.14159 3.14159" damping="0.099" armature="0.002" frictionloss="0.239" />
        <geom rgba="0.336363 0.486808 0.749761 1" mesh="neck_yaw_link_visual" class="visual" />
        <body name="neck_pitch_link" pos="3.75001e-10 0.00515 -0.0275" quat="0 0 -0.707107 -0.707107">
          <inertial pos="-0.0033209 -0.0334478 -0.000172669" quat="0.987043 -0.146771 -0.0216186 0.061129" mass="0.108519" diaginertia="7.49594e-05 6.52492e-05 2.34042e-05" />
          <joint name="neck_pitch_driven" pos="0 0 0" axis="0 0 1" limited="true" range="-1.5708 1.5708" damping="0.099" armature="0.002" frictionloss="0.239" />
          <geom rgba="0.751755 0.802378 0.881005 1" mesh="neck_pitch_link_visual" class="visual" />
          <body name="spur_gear_(13_teeth)" pos="0 -0.01565 0.0088" quat="0.707107 0 0 0.707107">
            <inertial pos="1.03999e-09 2.39052e-10 -0.00927515" mass="0.000814694" diaginertia="2.02448e-08 2.02448e-08 1.89055e-08" />
            <joint name="neck_pitch_drive" pos="0 0 0" axis="0 0 1" limited="true" range="-1.5708 1.5708" damping="0.099" armature="0.002" frictionloss="0.239" />
            <geom rgba="0.647059 0.647059 0.647059 1" mesh="spur_gear_(13_teeth)_visual" class="visual" />
          </body>
        </body>
      </body>
      <body name="waist_gears" pos="0 0 0" quat="0.707107 0 0 -0.707107">
        <inertial pos="6.54695e-08 -5.67859e-10 -0.0127262" quat="0.707086 0.707127 -1.13468e-06 -1.13475e-06" mass="0.0233158" diaginertia="6.90431e-06 6.87019e-06 1.16241e-06" />
        <joint name="waist_yaw" pos="0 0 0" axis="0 0 1" limited="true" range="-1.5708 1.5708" damping="0.099" armature="0.002" frictionloss="0.239" />
        <geom rgba="0.270575 0.536488 0.703055 1" mesh="waist_gears_visual" class="visual" />
        <body name="waist_link" pos="0 0.0227079 -0.013" quat="0.707107 0.707107 0 0">
          <inertial pos="-7.83262e-07 -0.0263091 0.0297733" quat="0.51004 0.488673 0.529691 0.469559" mass="0.151935" diaginertia="0.000185807 0.00014564 6.37307e-05" />
          <joint name="waist_roll" pos="0 0 0" axis="0 0 1" limited="true" range="-0.523599 0.523599" damping="0.099" armature="0.002" frictionloss="0.239" />
          <geom rgba="0.630669 0.67759 0.668498 1" mesh="waist_link_visual" class="visual" />
          <body name="spiral_bevel_1m_14t_30deg" pos="0 -0.0196 0.01275" quat="0.5 -0.5 -0.5 -0.5">
            <inertial pos="8.26411e-10 3.40558e-10 0.00686126" quat="0.5 0.5 -0.5 0.5" mass="0.000679976" diaginertia="1.31787e-08 1.21746e-08 1.21746e-08" />
            <joint name="waist_act_1" pos="0 0 0" axis="0 0 1" limited="true" range="-6.28319 6.28319" damping="0.099" armature="0.002" frictionloss="0.239" />
            <geom rgba="0.647059 0.647059 0.647059 1" mesh="spiral_bevel_1m_14t_30deg_visual" class="visual" />
          </body>
          <body name="spiral_bevel_1m_14t_30deg_2" pos="0 -0.0196 0.03275" quat="0.552838 -0.552838 -0.440874 -0.440874">
            <inertial pos="7.2991e-10 5.15913e-10 0.00686126" quat="0.5 0.5 -0.5 0.5" mass="0.000679976" diaginertia="1.31787e-08 1.21746e-08 1.21746e-08" />
            <joint name="waist_act_2" pos="0 0 0" axis="0 0 1" limited="true" range="-6.28319 6.28319" damping="0.099" armature="0.002" frictionloss="0.239" />
            <geom rgba="0.647059 0.647059 0.647059 1" mesh="spiral_bevel_1m_14t_30deg_2_visual" class="visual" />
          </body>
          <body name="spur_gear_19_teeth" pos="-0.037 -0.0371 0.0395" quat="0.707107 -0.707107 0 0">
            <inertial pos="-4.91561e-09 9.00609e-10 -0.00452952" quat="0.5 0.5 -0.5 0.5" mass="0.00109937" diaginertia="4.571e-08 2.9215e-08 2.9215e-08" />
            <joint name="left_hip_yaw_drive" pos="0 0 0" axis="0 0 1" limited="true" range="-1.5708 1.5708" damping="0.099" armature="0.002" frictionloss="0.239" />
            <geom rgba="0.615686 0.811765 0.929412 1" mesh="spur_gear_19_teeth_visual" class="visual" />
          </body>
          <body name="spur_gear_21_teeth" pos="-0.037 -0.0411 0.0195" quat="0.5 -0.5 0.5 0.5">
            <inertial pos="-2.5316e-11 0 -0.0141855" quat="0.5 0.5 0.5 0.5" mass="0.0190063" diaginertia="7.83675e-06 7.7816e-06 2.81558e-06" />
            <joint name="left_hip_yaw_driven" pos="0 0 0" axis="0 0 1" limited="true" range="-1.5708 1.5708" damping="0.099" armature="0.002" frictionloss="0.239" />
            <geom rgba="0.615686 0.811765 0.929412 1" mesh="spur_gear_21_teeth_visual" class="visual" />
            <geom pos="0 0 -0.005" quat="1 0 0 0" rgba="0.615686 0.811765 0.929412 1" mesh="left_hip_yaw_link_visual" class="visual" />
            <body name="hip_roll_link" pos="0.019 0 -0.031" quat="0 0.707107 0 0.707107">
              <inertial pos="-0.0119998 -0.000495981 -0.0185041" quat="-0.273471 0.652073 -0.267709 0.654482" mass="0.107" diaginertia="3.04228e-05 2.93112e-05 2.20754e-05" />
              <joint name="left_hip_roll" pos="0 0 0" axis="0 0 1" limited="true" range="-0.785398 1.5708" damping="0.218" armature="0.002" frictionloss="0.494" />
              <geom rgba="0.516987 0.503478 0.490506 1" mesh="left_hip_roll_link_visual" class="visual" />
              <body name="left_hip_pitch_link_xm430" pos="-0.024 -0.019 -0.019" quat="0.5 0.5 0.5 -0.5">
                <inertial pos="-0.00210349 -0.0564335 -0.0187821" quat="0.702624 0.709779 -0.0325208 0.0384008" mass="0.0355487" diaginertia="4.75445e-05 4.50623e-05 1.14742e-05" />
                <joint name="left_hip_pitch" pos="0 0 0" axis="0 0 1" limited="true" range="-1.5708 1.5708" damping="0.218" armature="0.002" frictionloss="0.494" />
                <geom rgba="0.587893 0.769614 0.896776 1" mesh="left_hip_pitch_link_xm430_visual" class="visual" />
                <body name="left_calf_link" pos="0 -0.096 -0.0092" quat="1 0 0 0">
                  <inertial pos="0.00118809 -0.0496431 -0.00986349" quat="0.516238 0.556959 -0.428745 0.489359" mass="0.0796075" diaginertia="5.12533e-05 4.83411e-05 1.39247e-05" />
                  <joint name="left_knee" pos="0 0 0" axis="0 0 1" limited="true" range="0 1.91986" damping="1.084" armature="0.045" frictionloss="0.03" />
                  <geom rgba="0.611779 0.716533 0.749893 1" mesh="left_calf_link_visual" class="visual" />
                  <body name="ank_pitch_link" pos="0 -0.1 -0.0104" quat="0 0 0 -1">
                    <inertial pos="0.000595283 -4.02697e-08 7.76161e-08" quat="0.707107 -1.66816e-06 1.66816e-06 0.707107" mass="0.00422384" diaginertia="4.37053e-07 3.97827e-07 8.88586e-08" />
                    <joint name="left_ank_pitch" pos="0 0 0" axis="0 0 1" limited="true" range="-0.785398 0.959931" damping="0.099" armature="0.002" frictionloss="0.239" />
                    <geom rgba="0.631892 0.726687 0.783564 1" mesh="left_ank_pitch_link_visual" class="visual" />
                    <body name="ank_roll_link" pos="0.0015 0 0" quat="0.707107 0 0.707107 0">
                      <inertial pos="-1.32686e-07 0.0267964 -0.00105269" quat="0.998249 -0.0591498 1.78294e-07 1.60483e-05" mass="0.0248" diaginertia="1.98469e-05 1.88892e-05 4.97682e-06" />
                      <joint name="left_ank_roll" pos="0 0 0" axis="0 0 1" limited="true" range="-0.785398 0.785398" damping="0.099" armature="0.002" frictionloss="0.239" />
                      <geom rgba="0.615686 0.811765 0.929412 1" mesh="left_ank_roll_link_visual" class="visual" />
                      <body name="ank_rr_link" pos="-0.018 0.016 -0.0206" quat="0.00911142 0 0 0.999958">
                        <inertial pos="-4.52496e-05 0.00630964 0" quat="0.473509 0.525157 -0.473509 0.525157" mass="0.00145" diaginertia="4.29219e-08 2.97647e-08 2.74049e-08" />
                        <joint name="left_ank_L_rev_1" pos="0 0 0" axis="0 0 1" limited="true" range="-1.5708 1.5708" damping="0.0" armature="0.0" frictionloss="0.0" />
                        <geom rgba="0.615686 0.811765 0.929412 1" mesh="left_ank_rr_link_visual" class="visual" />
                        <body name="ank_motor_rod_long" pos="0 0.01 0" quat="0.702074 -0.0842139 0.702074 -0.0842139">
                          <inertial pos="2.48551e-10 0.034559 0.000938517" quat="0.501157 0.503754 -0.498814 0.496243" mass="0.00217129" diaginertia="8.58145e-07 8.53502e-07 1.32148e-08" />
                          <joint name="left_ank_L_rev_2" pos="0 0 0" axis="0 0 1" limited="true" range="-1.5708 1.5708" damping="0.0" armature="0.0" frictionloss="0.0" />
                          <geom rgba="0.6355 0.707744 0.75109 1" mesh="left_ank_motor_rod_long_visual" class="visual" />
                        </body>
                      </body>
                      <body name="ank_rr_link_2" pos="0.018 0.016 -0.0206" quat="0.999915 0 0 0.0130589">
                        <inertial pos="-4.52496e-05 -0.00630964 0" quat="0.525157 0.473509 -0.525157 0.473509" mass="0.00145" diaginertia="4.29219e-08 2.97647e-08 2.74049e-08" />
                        <joint name="left_ank_S_rev_1" pos="0 0 0" axis="0 0 1" limited="true" range="-1.5708 1.5708" damping="0.0" armature="0.0" frictionloss="0.0" />
                        <geom rgba="0.615686 0.811765 0.929412 1" mesh="left_ank_rr_link_2_visual" class="visual" />
                        <body name="ank_motor_rod_short" pos="0 -0.01 0" quat="0.126204 -0.695753 0.126204 -0.695753">
                          <inertial pos="2.60389e-10 0.0238305 0.000904035" quat="0.499641 0.505179 -0.500306 0.494821" mass="0.0017" diaginertia="3.36253e-07 3.31534e-07 1.09078e-08" />
                          <joint name="left_ank_S_rev_2" pos="0 0 0" axis="0 0 1" limited="true" range="-1.5708 1.5708" damping="0.0" armature="0.0" frictionloss="0.0" />
                          <geom rgba="0.412226 0.583391 0.811073 1" mesh="left_ank_motor_rod_short_visual" class="visual" />
                        </body>
                      </body>
                    </body>
                  </body>
                  <body name="ank_motor_arm" pos="0.0135 -0.0445 0.004" quat="0.994401 0 0 -0.105669">
                    <inertial pos="0.0145115 0 0.00409254" quat="0 0.629747 0 0.7768" mass="0.00205958" diaginertia="1.70778e-07 1.61386e-07 2.11923e-08" />
                    <joint name="left_ank_act_1" pos="0 0 0" axis="0 0 1" limited="true" range="-1.309 1.309" damping="0.099" armature="0.002" frictionloss="0.239" />
                    <geom rgba="0.625178 0.705936 0.75979 1" mesh="left_ank_motor_arm_visual" class="visual" />
                  </body>
                  <body name="ank_motor_arm_2" pos="0.0135 -0.0645 -0.0248" quat="0 -0.993397 0.114725 0">
                    <inertial pos="0.0145115 0 0.00409254" quat="0 0.629747 0 0.7768" mass="0.00205958" diaginertia="1.70778e-07 1.61386e-07 2.11923e-08" />
                    <joint name="left_ank_act_2" pos="0 0 0" axis="0 0 1" limited="true" range="-1.309 1.309" damping="0.099" armature="0.002" frictionloss="0.239" />
                    <geom rgba="0.625178 0.705936 0.75979 1" mesh="left_ank_motor_arm_2_visual" class="visual" />
                  </body>
                </body>
              </body>
            </body>
          </body>
          <body name="spur_gear_19_teeth_2" pos="0.037 -0.0371 0.0395" quat="0.707107 -0.707107 0 0">
            <inertial pos="-4.91561e-09 9.00609e-10 -0.00452952" quat="0.5 0.5 -0.5 0.5" mass="0.00109937" diaginertia="4.571e-08 2.9215e-08 2.9215e-08" />
            <joint name="right_hip_yaw_drive" pos="0 0 0" axis="0 0 1" limited="true" range="-1.5708 1.5708" damping="0.099" armature="0.002" frictionloss="0.239" />
            <geom rgba="0.615686 0.811765 0.929412 1" mesh="spur_gear_19_teeth_2_visual" class="visual" />
          </body>
          <body name="spur_gear_21_teeth_2" pos="0.037 -0.0411 0.0195" quat="0.5 -0.5 0.5 0.5">
            <inertial pos="-2.5316e-11 0 -0.014186" quat="0.5 0.5 0.5 0.5" mass="0.0190063" diaginertia="7.83649e-06 7.7816e-06 2.81532e-06" />
            <joint name="right_hip_yaw_driven" pos="0 0 0" axis="0 0 1" limited="true" range="-1.5708 1.5708" damping="0.099" armature="0.002" frictionloss="0.239" />
            <geom rgba="0.615686 0.811765 0.929412 1" mesh="spur_gear_21_teeth_2_visual" class="visual" />
            <geom pos="0 0 -0.005" quat="1 0 0 0" rgba="0.615686 0.811765 0.929412 1" mesh="right_hip_yaw_link_visual" class="visual" />
            <body name="hip_roll_link_2" pos="-0.019 0 -0.031" quat="0.707107 0 -0.707107 0">
              <inertial pos="-0.0119998 -0.000495981 -0.0185041" quat="-0.273471 0.652073 -0.267709 0.654482" mass="0.107" diaginertia="3.04228e-05 2.93112e-05 2.20754e-05" />
              <joint name="right_hip_roll" pos="0 0 0" axis="0 0 1" limited="true" range="-0.785398 1.5708" damping="0.218" armature="0.002" frictionloss="0.494" />
              <geom rgba="0.516987 0.503478 0.490506 1" mesh="right_hip_roll_link_visual" class="visual" />
              <body name="right_hip_pitch_link_xm430" pos="-0.024 -0.019 -0.019" quat="0.5 0.5 0.5 -0.5">
                <inertial pos="0.00210066 -0.0564351 -0.0187821" quat="0.702609 0.709782 0.0326824 -0.0384919" mass="0.0355487" diaginertia="4.75524e-05 4.50641e-05 1.14686e-05" />
                <joint name="right_hip_pitch" pos="0 0 0" axis="0 0 1" limited="true" range="-1.5708 1.5708" damping="0.218" armature="0.002" frictionloss="0.494" />
                <geom rgba="0.587893 0.769614 0.896776 1" mesh="right_hip_pitch_link_xm430_visual" class="visual" />
                <body name="right_calf_link" pos="0 -0.096 -0.0092" quat="0 0 0 -1">
                  <inertial pos="0.00118809 0.0496431 -0.00986349" quat="0.556954 0.516211 -0.489358 0.428785" mass="0.0796075" diaginertia="5.12615e-05 4.83494e-05 1.39249e-05" />
                  <joint name="right_knee" pos="0 0 0" axis="0 0 1" limited="true" range="-1.91986 0" damping="1.084" armature="0.045" frictionloss="0.03" />
                  <geom rgba="0.611779 0.716533 0.749893 1" mesh="right_calf_link_visual" class="visual" />
                  <body name="ank_pitch_link_2" pos="0 0.1 -0.0104" quat="0 0 0 1">
                    <inertial pos="0.000595283 -4.02697e-08 7.76161e-08" quat="0.707107 -1.66816e-06 1.66816e-06 0.707107" mass="0.00422384" diaginertia="4.37053e-07 3.97827e-07 8.88586e-08" />
                    <joint name="right_ank_pitch" pos="0 0 0" axis="0 0 1" limited="true" range="-0.785398 0.959931" damping="0.099" armature="0.002" frictionloss="0.239" />
                    <geom rgba="0.631892 0.726687 0.783564 1" mesh="right_ank_pitch_link_visual" class="visual" />
                    <body name="ank_roll_link_2" pos="0.0015 0 0" quat="0 0.707107 0 0.707107">
                      <inertial pos="-4.30767e-08 0.0267963 -0.00105226" quat="0.998249 -0.0591539 -3.82292e-06 -2.14477e-06" mass="0.0248" diaginertia="1.98468e-05 1.88891e-05 4.97681e-06" />
                      <joint name="right_ank_roll" pos="0 0 0" axis="0 0 1" limited="true" range="-0.785398 0.785398" damping="0.099" armature="0.002" frictionloss="0.239" />
                      <geom rgba="0.615686 0.811765 0.929412 1" mesh="right_ank_roll_link_visual" class="visual" />
                      <body name="ank_rr_link_3" pos="0.018 0.016 -0.0206" quat="0.999958 0 0 0.00911142">
                        <inertial pos="-4.52496e-05 -0.00630964 0" quat="0.525157 0.473509 -0.525157 0.473509" mass="0.00145" diaginertia="4.29219e-08 2.97647e-08 2.74049e-08" />
                        <joint name="right_ank_L_rev_1" pos="0 0 0" axis="0 0 1" limited="true" range="-1.5708 1.5708" damping="0.0" armature="0.0" frictionloss="0.0" />
                        <geom rgba="0.615686 0.811765 0.929412 1" mesh="right_ank_rr_link_visual" class="visual" />
                        <body name="ank_motor_rod_long_2" pos="0 -0.01 0" quat="0.0842139 -0.702074 0.0842139 -0.702074">
                          <inertial pos="2.48551e-10 0.034559 0.000938517" quat="0.501157 0.503754 -0.498814 0.496243" mass="0.00217129" diaginertia="8.58145e-07 8.53502e-07 1.32148e-08" />
                          <joint name="right_ank_L_rev_2" pos="0 0 0" axis="0 0 1" limited="true" range="-1.5708 1.5708" damping="0.0" armature="0.0" frictionloss="0.0" />
                          <geom rgba="0.6355 0.707744 0.75109 1" mesh="right_ank_motor_rod_long_visual" class="visual" />
                        </body>
                      </body>
                      <body name="ank_rr_link_4" pos="-0.018 0.016 -0.0206" quat="0.0130589 0 0 0.999915">
                        <inertial pos="-4.52496e-05 0.00630964 0" quat="0.473509 0.525157 -0.473509 0.525157" mass="0.00145" diaginertia="4.29219e-08 2.97647e-08 2.74049e-08" />
                        <joint name="right_ank_S_rev_1" pos="0 0 0" axis="0 0 1" limited="true" range="-1.5708 1.5708" damping="0.0" armature="0.0" frictionloss="0.0" />
                        <geom rgba="0.615686 0.811765 0.929412 1" mesh="right_ank_rr_link_2_visual" class="visual" />
                        <body name="ank_motor_rod_short_2" pos="0 0.01 0" quat="0.695753 -0.126204 0.695753 -0.126204">
                          <inertial pos="2.60389e-10 0.0238305 0.000904035" quat="0.499641 0.505179 -0.500306 0.494821" mass="0.0017" diaginertia="3.36253e-07 3.31534e-07 1.09078e-08" />
                          <joint name="right_ank_S_rev_2" pos="0 0 0" axis="0 0 1" limited="true" range="-1.5708 1.5708" damping="0.0" armature="0.0" frictionloss="0.0" />
                          <geom rgba="0.412226 0.583391 0.811073 1" mesh="right_ank_motor_rod_short_visual" class="visual" />
                        </body>
                      </body>
                    </body>
                  </body>
                  <body name="ank_motor_arm_3" pos="0.0135 0.0445 0.004" quat="0.994401 0 0 0.105669">
                    <inertial pos="0.0145115 0 0.00409254" quat="0 0.629747 0 0.7768" mass="0.00205958" diaginertia="1.70778e-07 1.61386e-07 2.11923e-08" />
                    <joint name="right_ank_act_1" pos="0 0 0" axis="0 0 1" limited="true" range="-1.309 1.309" damping="0.099" armature="0.002" frictionloss="0.239" />
                    <geom rgba="0.625178 0.705936 0.75979 1" mesh="right_ank_motor_arm_visual" class="visual" />
                  </body>
                  <body name="ank_motor_arm_4" pos="0.0135 0.0645 -0.0248" quat="0 -0.993397 -0.114725 0">
                    <inertial pos="0.0145115 0 0.00409254" quat="0 0.629747 0 0.7768" mass="0.00205958" diaginertia="1.70778e-07 1.61386e-07 2.11923e-08" />
                    <joint name="right_ank_act_2" pos="0 0 0" axis="0 0 1" limited="true" range="-1.309 1.309" damping="0.099" armature="0.002" frictionloss="0.239" />
                    <geom rgba="0.625178 0.705936 0.75979 1" mesh="right_ank_motor_arm_2_visual" class="visual" />
                  </body>
                </body>
              </body>
            </body>
          </body>
        </body>
      </body>
      <body name="sho_pitch_link" pos="-0.003 0.062 0.105237" quat="0.707107 -0.707107 0 0">
        <inertial pos="5.82542e-11 -5.12646e-05 0.00824408" quat="0.0155166 0.706937 0.0155166 0.706937" mass="0.0086" diaginertia="3.08064e-06 2.9104e-06 1.22729e-06" />
        <joint name="left_sho_pitch" pos="0 0 0" axis="0 0 1" limited="true" range="-1.5708 1.5708" damping="0.195" armature="0.002" frictionloss="0.516" />
        <geom rgba="0.615686 0.811765 0.929412 1" mesh="left_sho_pitch_link_visual" class="visual" />
        <body name="2xl430_gears" pos="-0.019 0.001 0.027" quat="0 -0.707107 0 0.707107">
          <inertial pos="-0.0115455 -0.0025776 -0.0185549" quat="-0.00524699 0.697709 -0.139091 0.702729" mass="0.109212" diaginertia="3.34043e-05 3.03667e-05 2.54573e-05" />
          <joint name="left_sho_roll" pos="0 0 0" axis="0 0 1" limited="true" range="-1.5708 1.5708" damping="0.153" armature="0.008" frictionloss="0.998" />
          <geom rgba="0.919007 0.702596 0.124792 1" mesh="left_2xl430_gears_visual" class="visual" />
          <body name="spur_1m_24t_drive" pos="-0.024 -0.019 -0.019" quat="0.707107 0.707107 0 0">
            <inertial pos="0 0 0.00479491" quat="0.5 0.5 -0.5 0.5" mass="0.0032" diaginertia="2.38389e-07 1.40193e-07 1.40193e-07" />
            <joint name="left_sho_yaw_drive" pos="0 0 0" axis="0 0 1" limited="true" range="-3.14159 3.14159" damping="0.153" armature="0.008" frictionloss="0.998" />
            <geom rgba="0.615686 0.811765 0.929412 1" mesh="left_spur_1m_24t_drive_visual" class="visual" />
          </body>
          <body name="spur_1m_24t_driven" pos="-3.58075e-10 -0.027 -0.019" quat="0.707107 0.707107 0 0">
            <inertial pos="0 0 0.0216102" mass="0.0172" diaginertia="1.08021e-05 7.42977e-06 4.68733e-06" />
            <joint name="left_sho_yaw_driven" pos="0 0 0" axis="0 0 1" limited="true" range="-3.14159 3.14159" damping="0.153" armature="0.008" frictionloss="0.998" />
            <geom rgba="0.231373 0.380392 0.705882 1" mesh="left_spur_1m_24t_driven_visual" class="visual" />
            <geom pos="0 0 0.0016" quat="0 -1 0 0" rgba="0.615686 0.811765 0.929412 1" mesh="left_sho_yaw_link_visual" class="visual" />
            <body name="2xl430_gears_2" pos="0 0.019 0.0606" quat="0.707107 -0.707107 0 0">
              <inertial pos="-0.0115455 -0.0025776 -0.0185549" quat="-0.00524699 0.697709 -0.139091 0.702729" mass="0.109212" diaginertia="3.34043e-05 3.03667e-05 2.54573e-05" />
              <joint name="left_elbow_roll" pos="0 0 0" axis="0 0 1" limited="true" range="-1.5708 1.5708" damping="0.153" armature="0.008" frictionloss="0.998" />
              <geom rgba="0.919007 0.702596 0.124792 1" mesh="left_2xl430_gears_2_visual" class="visual" />
              <body name="spur_1m_24t_drive_2" pos="-0.024 -0.019 -0.019" quat="0.707107 0.707107 0 0">
                <inertial pos="0 0 0.00479491" quat="0.5 0.5 -0.5 0.5" mass="0.0032" diaginertia="2.38389e-07 1.40193e-07 1.40193e-07" />
                <joint name="left_elbow_yaw_drive" pos="0 0 0" axis="0 0 1" limited="true" range="-3.14159 3.14159" damping="0.153" armature="0.008" frictionloss="0.998" />
                <geom rgba="0.615686 0.811765 0.929412 1" mesh="left_spur_1m_24t_drive_2_visual" class="visual" />
              </body>
              <body name="spur_1m_24t_driven_2" pos="-3.58073e-10 -0.027 -0.019" quat="0.5 0.5 0.5 -0.5">
                <inertial pos="0.00116139 -4.04035e-08 0.025284" quat="0.665601 0.238694 0.238694 0.665601" mass="0.0229" diaginertia="1.97992e-05 1.15815e-05 1.01733e-05" />
                <joint name="left_elbow_yaw_driven" pos="0 0 0" axis="0 0 1" limited="true" range="-3.14159 3.14159" damping="0.153" armature="0.008" frictionloss="0.998" />
                <geom rgba="0.231373 0.380392 0.705882 1" mesh="left_spur_1m_24t_driven_2_visual" class="visual" />
                <geom pos="0 0 0.0016" quat="0 -0.707107 0.707107 0" rgba="0.615686 0.811765 0.929412 1" mesh="left_elb_yaw_link_visual" class="visual" />
                <geom pos="0.0253 0 0.0536" quat="0.707107 0 0.707107 0" rgba="0.231373 0.380392 0.705882 1" mesh="left_spur_1m_24t_driven_3_visual" class="visual" />
                <body name="2xl430_gears_3" pos="0.0237 0 0.0536" quat="0.5 -0.5 0.5 -0.5">
                  <inertial pos="0.000426003 0.0113757 -0.025385" quat="0.758579 0.649015 -0.0410507 0.0406514" mass="0.114112" diaginertia="3.64864e-05 3.1594e-05 2.84126e-05" />
                  <joint name="left_wrist_pitch_driven" pos="0 0 0" axis="0 0 1" limited="true" range="-1.5708 1.5708" damping="0.153" armature="0.008" frictionloss="0.998" />
                  <geom rgba="0.919007 0.702596 0.124792 1" mesh="left_2xl430_gears_3_visual" class="visual" />
                  <geom pos="0.0155 0 -0.045" quat="0.707107 0 0 -0.707107" rgba="0.644963 0.690118 0.717068 1" mesh="left_wrist_bearing_plate_visual" class="visual" />
                  <body name="spur_1m_24t_drive_3" pos="-1.52447e-10 0.024 -0.008" quat="0.707107 0 0 -0.707107">
                    <inertial pos="0 0 0.00479491" quat="0.5 0.5 -0.5 0.5" mass="0.0032" diaginertia="2.38389e-07 1.40193e-07 1.40193e-07" />
                    <joint name="left_wrist_pitch_drive" pos="0 0 0" axis="0 0 1" limited="true" range="-1.5708 1.5708" damping="0.153" armature="0.008" frictionloss="0.998" />
                    <geom rgba="0.615686 0.811765 0.929412 1" mesh="left_spur_1m_24t_drive_3_visual" class="visual" />
                  </body>
                  <body name="hand" pos="0.019 -3.58073e-10 -0.027" quat="0.707107 0 0.707107 0">
                    <inertial pos="-4.30384e-08 -0.0497238 -0.0179336" quat="0.739676 0.672963 4.83075e-07 -2.50564e-06" mass="0.017" diaginertia="9.49214e-06 6.68579e-06 4.0511e-06" />
                    <joint name="left_wrist_roll" pos="0 0 0" axis="0 0 1" limited="true" range="-1.5708 1.5708" damping="0.153" armature="0.008" frictionloss="0.998" />
                    <geom rgba="0.615686 0.811765 0.929412 1" mesh="left_hand_visual" class="visual" />
                  </body>
                </body>
              </body>
            </body>
          </body>
        </body>
      </body>
      <body name="sho_pitch_link_2" pos="-0.003 -0.062 0.105237" quat="0 0 0.707107 -0.707107">
        <inertial pos="5.82542e-11 -5.12646e-05 0.00824408" quat="0.0155166 0.706937 0.0155166 0.706937" mass="0.0086" diaginertia="3.08064e-06 2.9104e-06 1.22729e-06" />
        <joint name="right_sho_pitch" pos="0 0 0" axis="0 0 1" limited="true" range="-1.5708 1.5708" damping="0.195" armature="0.002" frictionloss="0.516" />
        <geom rgba="0.615686 0.811765 0.929412 1" mesh="right_sho_pitch_link_visual" class="visual" />
        <body name="2xl430_gears_4" pos="-0.019 0.001 0.027" quat="0 0.707107 0 -0.707107">
          <inertial pos="-0.0115455 -0.0025776 -0.0185549" quat="-0.00524699 0.697709 -0.139091 0.702729" mass="0.109212" diaginertia="3.34043e-05 3.03667e-05 2.54573e-05" />
          <joint name="right_sho_roll" pos="0 0 0" axis="0 0 1" limited="true" range="-1.5708 1.5708" damping="0.153" armature="0.008" frictionloss="0.998" />
          <geom rgba="0.919007 0.702596 0.124792 1" mesh="right_2xl430_gears_visual" class="visual" />
          <body name="spur_1m_24t_drive_4" pos="-0.024 -0.019 -0.019" quat="0.707107 0.707107 0 0">
            <inertial pos="0 0 0.00479491" quat="0.5 0.5 -0.5 0.5" mass="0.0032" diaginertia="2.38389e-07 1.40193e-07 1.40193e-07" />
            <joint name="right_sho_yaw_drive" pos="0 0 0" axis="0 0 1" limited="true" range="-3.14159 3.14159" damping="0.153" armature="0.008" frictionloss="0.998" />
            <geom rgba="0.615686 0.811765 0.929412 1" mesh="right_spur_1m_24t_drive_visual" class="visual" />
          </body>
          <body name="spur_1m_24t_driven_4" pos="-3.58074e-10 -0.027 -0.019" quat="0.707107 0.707107 0 0">
            <inertial pos="0 0 0.0216102" mass="0.0172" diaginertia="1.08021e-05 7.42977e-06 4.68733e-06" />
            <joint name="right_sho_yaw_driven" pos="0 0 0" axis="0 0 1" limited="true" range="-3.14159 3.14159" damping="0.153" armature="0.008" frictionloss="0.998" />
            <geom rgba="0.231373 0.380392 0.705882 1" mesh="right_spur_1m_24t_driven_visual" class="visual" />
            <geom pos="0 0 0.0016" quat="0 -1 0 0" rgba="0.615686 0.811765 0.929412 1" mesh="right_sho_yaw_link_visual" class="visual" />
            <body name="2xl430_gears_5" pos="0 0.019 0.0606" quat="0.707107 -0.707107 0 0">
              <inertial pos="-0.0115455 -0.0025776 -0.0185549" quat="-0.00524699 0.697709 -0.139091 0.702729" mass="0.109212" diaginertia="3.34043e-05 3.03667e-05 2.54573e-05" />
              <joint name="right_elbow_roll" pos="0 0 0" axis="0 0 1" limited="true" range="-1.5708 1.5708" damping="0.153" armature="0.008" frictionloss="0.998" />
              <geom rgba="0.919007 0.702596 0.124792 1" mesh="right_2xl430_gears_2_visual" class="visual" />
              <body name="spur_1m_24t_drive_5" pos="-0.024 -0.019 -0.019" quat="0.707107 0.707107 0 0">
                <inertial pos="0 0 0.00479491" quat="0.5 0.5 -0.5 0.5" mass="0.0032" diaginertia="2.38389e-07 1.40193e-07 1.40193e-07" />
                <joint name="right_elbow_yaw_drive" pos="0 0 0" axis="0 0 1" limited="true" range="-3.14159 3.14159" damping="0.153" armature="0.008" frictionloss="0.998" />
                <geom rgba="0.615686 0.811765 0.929412 1" mesh="right_spur_1m_24t_drive_2_visual" class="visual" />
              </body>
              <body name="spur_1m_24t_driven_5" pos="-3.5807e-10 -0.027 -0.019" quat="0 0 -0.707107 0.707107">
                <inertial pos="-4.04035e-08 -0.00116139 0.025284" quat="0.941302 0.337564 0 0" mass="0.0229" diaginertia="1.97992e-05 1.15815e-05 1.01733e-05" />
                <joint name="right_elbow_yaw_driven" pos="0 0 0" axis="0 0 1" limited="true" range="-3.14159 3.14159" damping="0.153" armature="0.008" frictionloss="0.998" />
                <geom rgba="0.231373 0.380392 0.705882 1" mesh="right_spur_1m_24t_driven_2_visual" class="visual" />
                <geom pos="0 0 0.0016" quat="0 0 1 0" rgba="0.615686 0.811765 0.929412 1" mesh="right_elb_yaw_link_visual" class="visual" />
                <geom pos="0 -0.0253 0.0536" quat="-0.5 -0.5 0.5 -0.5" rgba="0.231373 0.380392 0.705882 1" mesh="right_spur_1m_24t_driven_3_visual" class="visual" />
                <body name="2xl430_gears_6" pos="0 -0.0237 0.0536" quat="0 0 0.707107 -0.707107">
                  <inertial pos="0.000426003 0.0113757 -0.025385" quat="0.758579 0.649015 -0.0410507 0.0406514" mass="0.114112" diaginertia="3.64864e-05 3.1594e-05 2.84126e-05" />
                  <joint name="right_wrist_pitch_driven" pos="0 0 0" axis="0 0 1" limited="true" range="-1.5708 1.5708" damping="0.153" armature="0.008" frictionloss="0.998" />
                  <geom rgba="0.919007 0.702596 0.124792 1" mesh="right_2xl430_gears_3_visual" class="visual" />
                  <geom pos="0.0155 0 -0.045" quat="0.707107 0 0 -0.707107" rgba="0.644963 0.690118 0.717068 1" mesh="right_wrist_bearing_plate_visual" class="visual" />
                  <body name="spur_1m_24t_drive_6" pos="-1.52448e-10 0.024 -0.008" quat="0.707107 0 0 -0.707107">
                    <inertial pos="0 0 0.00479491" quat="0.5 0.5 -0.5 0.5" mass="0.0032" diaginertia="2.38389e-07 1.40193e-07 1.40193e-07" />
                    <joint name="right_wrist_pitch_drive" pos="0 0 0" axis="0 0 1" limited="true" range="-1.5708 1.5708" damping="0.153" armature="0.008" frictionloss="0.998" />
                    <geom rgba="0.615686 0.811765 0.929412 1" mesh="right_spur_1m_24t_drive_3_visual" class="visual" />
                  </body>
                  <body name="hand_2" pos="0.019 -3.58067e-10 -0.027" quat="0 -0.707107 0 -0.707107">
                    <inertial pos="-4.30384e-08 0.0497238 -0.0200664" quat="0.739676 0.672963 -4.83075e-07 2.50564e-06" mass="0.017" diaginertia="9.49214e-06 6.68579e-06 4.0511e-06" />
                    <joint name="right_wrist_roll" pos="0 0 0" axis="0 0 1" limited="true" range="-1.5708 1.5708" damping="0.153" armature="0.008" frictionloss="0.998" />
                    <geom rgba="0.615686 0.811765 0.929412 1" mesh="right_hand_visual" class="visual" />
                  </body>
                </body>
              </body>
            </body>
          </body>
        </body>
      </body>
    </body>
  </worldbody>
  <sensor>
    <framequat name="orientation" objtype="site" noise="0.001" objname="imu" />
    <framepos name="position" objtype="site" noise="0.001" objname="imu" />
    <gyro name="angular_velocity" site="imu" noise="0.005" cutoff="34.9" />
    <velocimeter name="linear_velocity" site="imu" noise="0.001" cutoff="30" />
    <accelerometer name="linear_acceleration" site="imu" noise="0.005" cutoff="157" />
    <magnetometer name="magnetometer" site="imu" />
  </sensor>
  <actuator>
    <position name="neck_yaw_act" joint="neck_yaw_driven" kp="18.75" gear="1.3846153846153846" ctrlrange="-3.14159 3.14159" class="XC330" />
    <position name="neck_pitch_act" joint="neck_pitch_driven" kp="18.75" gear="1.1" ctrlrange="-1.5708 1.5708" class="XC330" />
    <position name="waist_act_1_act" joint="waist_act_1" kp="18.75" ctrlrange="-6.28319 6.28319" class="XC330" />
    <position name="waist_act_2_act" joint="waist_act_2" kp="18.75" ctrlrange="-6.28319 6.28319" class="XC330" />
    <position name="left_hip_yaw_act" joint="left_hip_yaw_driven" kp="18.75" gear="1.105263157894737" ctrlrange="-1.5708 1.5708" class="XC330" />
    <position name="left_hip_roll_act" joint="left_hip_roll" kp="18.75" ctrlrange="-0.785398 1.5708" class="2XC430" />
    <position name="left_hip_pitch_act" joint="left_hip_pitch" kp="18.75" ctrlrange="-1.5708 1.5708" class="2XC430" />
    <position name="left_knee_act" joint="left_knee" kp="18.75" ctrlrange="0 1.91986" class="XM430" />
    <position name="left_ank_act_1_act" joint="left_ank_act_1" kp="18.75" ctrlrange="-1.309 1.309" class="XC330" />
    <position name="left_ank_act_2_act" joint="left_ank_act_2" kp="18.75" ctrlrange="-1.309 1.309" class="XC330" />
    <position name="right_hip_yaw_act" joint="right_hip_yaw_driven" kp="18.75" gear="1.105263157894737" ctrlrange="-1.5708 1.5708" class="XC330" />
    <position name="right_hip_roll_act" joint="right_hip_roll" kp="18.75" ctrlrange="-0.785398 1.5708" class="2XC430" />
    <position name="right_hip_pitch_act" joint="right_hip_pitch" kp="18.75" ctrlrange="-1.5708 1.5708" class="2XC430" />
    <position name="right_knee_act" joint="right_knee" kp="18.75" ctrlrange="-1.91986 0" class="XM430" />
    <position name="right_ank_act_1_act" joint="right_ank_act_1" kp="18.75" ctrlrange="-1.309 1.309" class="XC330" />
    <position name="right_ank_act_2_act" joint="right_ank_act_2" kp="18.75" ctrlrange="-1.309 1.309" class="XC330" />
    <position name="left_sho_pitch_act" joint="left_sho_pitch" kp="18.75" ctrlrange="-1.5708 1.5708" class="XC430" />
    <position name="left_sho_roll_act" joint="left_sho_roll" kp="18.75" ctrlrange="-1.5708 1.5708" class="2XL430" />
    <position name="left_sho_yaw_act" joint="left_sho_yaw_driven" kp="18.75" gear="1.0" ctrlrange="-3.14159 3.14159" class="2XL430" />
    <position name="left_elbow_roll_act" joint="left_elbow_roll" kp="18.75" ctrlrange="-1.5708 1.5708" class="2XL430" />
    <position name="left_elbow_yaw_act" joint="left_elbow_yaw_driven" kp="18.75" gear="1.0" ctrlrange="-3.14159 3.14159" class="2XL430" />
    <position name="left_wrist_pitch_act" joint="left_wrist_pitch_driven" kp="18.75" gear="1.0" ctrlrange="-1.5708 1.5708" class="2XL430" />
    <position name="left_wrist_roll_act" joint="left_wrist_roll" kp="18.75" ctrlrange="-1.5708 1.5708" class="2XL430" />
    <position name="right_sho_pitch_act" joint="right_sho_pitch" kp="18.75" ctrlrange="-1.5708 1.5708" class="XC430" />
    <position name="right_sho_roll_act" joint="right_sho_roll" kp="18.75" ctrlrange="-1.5708 1.5708" class="2XL430" />
    <position name="right_sho_yaw_act" joint="right_sho_yaw_driven" kp="18.75" gear="1.0" ctrlrange="-3.14159 3.14159" class="2XL430" />
    <position name="right_elbow_roll_act" joint="right_elbow_roll" kp="18.75" ctrlrange="-1.5708 1.5708" class="2XL430" />
    <position name="right_elbow_yaw_act" joint="right_elbow_yaw_driven" kp="18.75" gear="1.0" ctrlrange="-3.14159 3.14159" class="2XL430" />
    <position name="right_wrist_pitch_act" joint="right_wrist_pitch_driven" kp="18.75" gear="1.0" ctrlrange="-1.5708 1.5708" class="2XL430" />
    <position name="right_wrist_roll_act" joint="right_wrist_roll" kp="18.75" ctrlrange="-1.5708 1.5708" class="2XL430" />
  </actuator>
  <equality>
    <connect body1="ank_motor_arm" body2="ank_motor_rod_long" solimp="0.9999 0.9999 0.001 0.5 2" solref="0.0001 1" anchor="0.02 0 0.00582666" />
    <connect body1="ank_motor_arm_2" body2="ank_motor_rod_short" solimp="0.9999 0.9999 0.001 0.5 2" solref="0.0001 1" anchor="0.02 0 0.00582666" />
    <connect body1="ank_motor_arm_3" body2="ank_motor_rod_long_2" solimp="0.9999 0.9999 0.001 0.5 2" solref="0.0001 1" anchor="0.02 0 0.00582666" />
    <connect body1="ank_motor_arm_4" body2="ank_motor_rod_short_2" solimp="0.9999 0.9999 0.001 0.5 2" solref="0.0001 1" anchor="0.02 0 0.00582666" />
  </equality>
  <default>
    <default class="XM430">
      <position forcerange="-5 5" />
    </default>
    <default class="XC430">
      <position forcerange="-2 2" />
    </default>
    <default class="2XC430">
      <position forcerange="-2 2" />
    </default>
    <default class="XL430">
      <position forcerange="-2 2" />
    </default>
    <default class="2XL430">
      <position forcerange="-2 2" />
    </default>
    <default class="XC330">
      <position forcerange="-1 1" />
    </default>
    <geom type="mesh" solref=".004 1" />
    <default class="visual">
      <geom contype="0" conaffinity="0" group="2" />
    </default>
    <default class="collision">
      <geom group="3" />
    </default>
  </default>
  <contact />
</mujoco>