<robot name="toddlerbot">
  <mujoco>
    <compiler strippath="false" balanceinertia="true" discardvisual="false" />
  </mujoco>
  <link name="torso">
    <visual>
      <origin xyz="0 0 0" rpy="0 -0 0" />
      <geometry>
        <mesh filename="../assemblies/toddlerbot/meshes/torso_visual.stl" />
      </geometry>
      <material name="torso_material">
        <color rgba="0.6197852121554117133 0.80497509985632864637 0.91238666069265517145 1.0" />
      </material>
    </visual>
    <inertial>
      <origin xyz="-0.017582789998871049819 -0.0008892412850613319944 0.066328103881054256696" rpy="0 0 0" />
      <mass value="0.38210896478125000453" />
      <inertia ixx="0.00097913100143531372858" ixy="1.368754266574914548e-05" ixz="5.3060955780646044695e-05" iyy="0.00088767318813584431599" iyz="-1.8064914536012927244e-05" izz="0.00068582374333484930409" />
    </inertial>
  </link>

  <link name="spur_1m_20t">
    <visual>
      <origin xyz="0 0 0" rpy="0 -0 0" />
      <geometry>
        <mesh filename="../assemblies/toddlerbot/meshes/spur_1m_20t_visual.stl" />
      </geometry>
      <material name="spur_1m_20t_material">
        <color rgba="0.64705882352941179736 0.64705882352941179736 0.64705882352941179736 1.0" />
      </material>
    </visual>
    <inertial>
      <origin xyz="-5.0044775065590171545e-18 6.0502252725870090006e-18 -0.0033745971730663147647" rpy="0 0 0" />
      <mass value="0.0015534950290892286448" />
      <inertia ixx="4.4726508287871812856e-08" ixy="7.684011163414536344e-24" ixz="2.7597381312606821682e-39" iyy="4.4726508287871786386e-08" iyz="-4.880475641083095171e-38" izz="7.9558906764902006609e-08" />
    </inertial>
  </link>

  <joint name="neck_yaw_drive" type="revolute">
    <origin xyz="-0.004999999999999059884 -1.8020791195763170554e-16 0.12248651076281816263" rpy="-3.1415926535897913396 1.7995135580561967136e-15 9.6455933634066887197e-16" />
    <parent link="torso" />
    <child link="spur_1m_20t" />
    <axis xyz="0 0 1" />
    <limit effort="1" velocity="20" lower="-3.141592653589793116" upper="3.141592653589793116" />
    <joint_properties friction="0.0" />
  </joint>

  <link name="neck_yaw_link">
    <visual>
      <origin xyz="0 0 0" rpy="0 -0 0" />
      <geometry>
        <mesh filename="../assemblies/toddlerbot/meshes/neck_yaw_link_visual.stl" />
      </geometry>
      <material name="neck_yaw_link_material">
        <color rgba="0.33636252417476664167 0.48680769190259887136 0.74976123534949801197 1.0" />
      </material>
    </visual>
    <inertial>
      <origin xyz="2.7291286461356290677e-05 0.00019798992283539515501 -0.0115274120371948504" rpy="0 0 0" />
      <mass value="0.0085168305947458250449" />
      <inertia ixx="1.0407116999274388487e-06" ixy="-2.4210150464746039776e-11" ixz="4.7246803220671246024e-10" iyy="1.1240009954110499114e-06" iyz="3.0834841754646676679e-08" izz="3.1587565167292060697e-07" />
    </inertial>
  </link>

  <link name="neck_pitch_link">
    <visual>
      <origin xyz="0 0 0" rpy="0 -0 0" />
      <geometry>
        <mesh filename="../assemblies/toddlerbot/meshes/neck_pitch_link_visual.stl" />
      </geometry>
      <material name="neck_pitch_link_material">
        <color rgba="0.75175531149912766526 0.80237790269364195339 0.88100511756510224703 1.0" />
      </material>
    </visual>
    <inertial>
      <origin xyz="-0.0033208985050365335059 -0.033447827507434767236 -0.00017266927552015079862" rpy="0 0 0" />
      <mass value="0.10851928601941271402" />
      <inertia ixx="7.4643011916861726944e-05" ixy="1.9512994501134094261e-06" ixz="2.6631618432505370407e-06" iyy="6.1956827409922912795e-05" iyz="-1.1454163205103217525e-05" izz="2.701288336202765537e-05" />
    </inertial>
  </link>

  <link name="spur_gear_(13_teeth)">
    <visual>
      <origin xyz="0 0 0" rpy="0 -0 0" />
      <geometry>
        <mesh filename="../assemblies/toddlerbot/meshes/spur_gear_(13_teeth)_visual.stl" />
      </geometry>
      <material name="spur_gear_(13_teeth)_material">
        <color rgba="0.64705882352941179736 0.64705882352941179736 0.64705882352941179736 1.0" />
      </material>
    </visual>
    <inertial>
      <origin xyz="1.0399873342418501553e-09 2.3905206814663368286e-10 -0.0092751511485596373902" rpy="0 0 0" />
      <mass value="0.00081469437497230855032" />
      <inertia ixx="2.0244839552178295378e-08" ixy="-2.9046301764120405049e-15" ixz="8.297606606936787006e-15" iyy="2.0244841689973771385e-08" iyz="-1.31421177847285757e-15" izz="1.8905472907863310999e-08" />
    </inertial>
  </link>

  <joint name="neck_pitch_drive" type="revolute">
    <origin xyz="-1.4571677198205179593e-16 -0.015650000000000330314 0.0087999999999993777644" rpy="-2.1434555572207676319e-16 -1.5880065549567459396e-15 1.570796326794896558" />
    <parent link="neck_pitch_link" />
    <child link="spur_gear_(13_teeth)" />
    <axis xyz="0 0 1" />
    <limit effort="1" velocity="20" lower="-1.570796326794896558" upper="1.570796326794896558" />
    <joint_properties friction="0.0" />
  </joint>

  <joint name="neck_pitch_driven" type="revolute">
    <origin xyz="3.7500073185592341929e-10 0.0051500000614755261225 -0.027499999999999941158" rpy="1.57079632679489678 -1.7934420258902467287e-15 -3.1415926535897922278" />
    <parent link="neck_yaw_link" />
    <child link="neck_pitch_link" />
    <axis xyz="0 0 1" />
    <limit effort="1" velocity="20" lower="-1.570796326794896558" upper="1.570796326794896558" />
    <joint_properties friction="0.0" />
  </joint>

  <joint name="neck_yaw_driven" type="revolute">
    <origin xyz="0.016000000000001915468 1.4752314067929367773e-17 0.12348651076281796923" rpy="-3.141592653589793116 -0 -3.1415926535897922278" />
    <parent link="torso" />
    <child link="neck_yaw_link" />
    <axis xyz="0 0 1" />
    <limit effort="1" velocity="20" lower="-3.141592653589793116" upper="3.141592653589793116" />
    <joint_properties friction="0.0" />
  </joint>

  <link name="waist_gears">
    <visual>
      <origin xyz="0 0 0" rpy="0 -0 0" />
      <geometry>
        <mesh filename="../assemblies/toddlerbot/meshes/waist_gears_visual.stl" />
      </geometry>
      <material name="waist_gears_material">
        <color rgba="0.2705751638183052088 0.53648836590125015267 0.70305495274644791426 1.0" />
      </material>
    </visual>
    <inertial>
      <origin xyz="6.5469454462684754055e-08 -5.678589769108444202e-10 -0.012726165583898677025" rpy="0 0 0" />
      <mass value="0.023315805669179824611" />
      <inertia ixx="6.9043104388291928151e-06" ixy="-1.8428638769590440561e-11" ixz="9.9668712610669700131e-13" iyy="1.162409197167636598e-06" iyz="-3.3260430300288233958e-10" izz="6.8701920560919842564e-06" />
    </inertial>
  </link>

  <link name="waist_link">
    <visual>
      <origin xyz="0 0 0" rpy="0 -0 0" />
      <geometry>
        <mesh filename="../assemblies/toddlerbot/meshes/waist_link_visual.stl" />
      </geometry>
      <material name="waist_link_material">
        <color rgba="0.63066856640767587905 0.67759035867951045162 0.66849819411858002471 1.0" />
      </material>
    </visual>
    <inertial>
      <origin xyz="-7.8326157945763225844e-07 -0.026309055188168648659 0.029773273854826105139" rpy="0 0 0" />
      <mass value="0.15193452399186058166" />
      <inertia ixx="6.3853955317574355379e-05" ixy="6.7244006990957541522e-10" ixz="3.1782521385896526105e-06" iyy="0.00018554067350207199979" iyz="-3.2622478832003394146e-06" izz="0.00014578323476960398171" />
    </inertial>
  </link>

  <link name="spiral_bevel_1m_14t_30deg">
    <visual>
      <origin xyz="0 0 0" rpy="0 -0 0" />
      <geometry>
        <mesh filename="../assemblies/toddlerbot/meshes/spiral_bevel_1m_14t_30deg_visual.stl" />
      </geometry>
      <material name="spiral_bevel_1m_14t_30deg_material">
        <color rgba="0.64705882352941179736 0.64705882352941179736 0.64705882352941179736 1.0" />
      </material>
    </visual>
    <inertial>
      <origin xyz="8.2641075233036431769e-10 3.4055789828804639008e-10 0.0068612577407481684794" rpy="0 0 0" />
      <mass value="0.00067997563436136235649" />
      <inertia ixx="1.2174575798018975493e-08" ixy="3.8216070047630807068e-18" ixz="4.7204547823421934484e-16" iyy="1.2174575801813732727e-08" iyz="-2.6184097732597935737e-16" izz="1.3178653206314311711e-08" />
    </inertial>
  </link>

  <joint name="waist_act_1" type="revolute">
    <origin xyz="4.8392086706372466624e-17 -0.019600000000000009776 0.012750000000000042549" rpy="-1.5707963267948961139 -1.5707963267948215069 0" />
    <parent link="waist_link" />
    <child link="spiral_bevel_1m_14t_30deg" />
    <axis xyz="0 0 1" />
    <limit effort="1" velocity="20" lower="-2.7925268031909271649" upper="2.7925268031909271649" />
    <joint_properties friction="0.0" />
  </joint>

  <link name="spiral_bevel_1m_14t_30deg_2">
    <visual>
      <origin xyz="0 0 0" rpy="0 -0 0" />
      <geometry>
        <mesh filename="../assemblies/toddlerbot/meshes/spiral_bevel_1m_14t_30deg_2_visual.stl" />
      </geometry>
      <material name="spiral_bevel_1m_14t_30deg_2_material">
        <color rgba="0.64705882352941179736 0.64705882352941179736 0.64705882352941179736 1.0" />
      </material>
    </visual>
    <inertial>
      <origin xyz="7.2990964661290291815e-10 5.1591309341166232978e-10 0.0068612577407481702141" rpy="0 0 0" />
      <mass value="0.00067997563436136235649" />
      <inertia ixx="1.2174575796548751289e-08" ixy="2.6199053407227811934e-18" ixz="5.1847541137723511287e-16" iyy="1.2174575803283978437e-08" iyz="-1.502360766603294444e-16" izz="1.3178653206314315019e-08" />
    </inertial>
  </link>

  <joint name="waist_act_2" type="revolute">
    <origin xyz="-6.321225856846266752e-16 -0.019600000000000079164 0.032750000000000834" rpy="-1.5707963267948976682 -1.3463968515393018865 1.5503953316521244903e-14" />
    <parent link="waist_link" />
    <child link="spiral_bevel_1m_14t_30deg_2" />
    <axis xyz="0 0 1" />
    <limit effort="1" velocity="20" lower="-2.7925268031909271649" upper="2.7925268031909271649" />
    <joint_properties friction="0.0" />
  </joint>

  <link name="spur_gear_19_teeth">
    <visual>
      <origin xyz="0 0 0" rpy="0 -0 0" />
      <geometry>
        <mesh filename="../assemblies/toddlerbot/meshes/spur_gear_19_teeth_visual.stl" />
      </geometry>
      <material name="spur_gear_19_teeth_material">
        <color rgba="0.61568627450980395466 0.81176470588235294379 0.92941176470588238168 1.0" />
      </material>
    </visual>
    <inertial>
      <origin xyz="-4.9156135348702214374e-09 9.0060874048927839393e-10 -0.0045295192537419945097" rpy="0 0 0" />
      <mass value="0.0010993711450650535313" />
      <inertia ixx="2.9215018435433082044e-08" ixy="2.5903313772733109345e-16" ixz="-8.424261245563750688e-15" iyy="2.9215021540034058468e-08" iyz="1.5226232384526170773e-15" izz="4.5709977027671368266e-08" />
    </inertial>
  </link>

  <joint name="left_hip_yaw_drive" type="revolute">
    <origin xyz="-0.036999999999999179379 -0.037100000000004823564 0.039500000000000423661" rpy="-1.5707963267950579844 5.71102443800098102e-13 2.6906455702027046663e-13" />
    <parent link="waist_link" />
    <child link="spur_gear_19_teeth" />
    <axis xyz="0 0 1" />
    <limit effort="1" velocity="20" lower="-1.570796326794896558" upper="1.570796326794896558" />
    <joint_properties friction="0.0" />
  </joint>

  <link name="spur_gear_21_teeth">
    <visual>
      <origin xyz="0 0 0" rpy="0 -0 0" />
      <geometry>
        <mesh filename="../assemblies/toddlerbot/meshes/spur_gear_21_teeth_visual.stl" />
      </geometry>
      <material name="spur_gear_21_teeth_material">
        <color rgba="0.61568627450980395466 0.81176470588235294379 0.92941176470588238168 1.0" />
      </material>
    </visual>
    <inertial>
      <origin xyz="-4.7814841733033882526e-10 1.2610017463689733481e-12 -0.0024944618616143366362" rpy="0 0 0" />
      <mass value="0.0010063046528317972673" />
      <inertia ixx="3.1842855421068488283e-08" ixy="2.1452075797961618719e-37" ixz="-1.1964366566353525762e-38" iyy="3.1842855426953779079e-08" iyz="1.1823805759556976152e-38" izz="5.9529380586728028132e-08" />
    </inertial>
  </link>

  <joint name="left_leg_fixed" type="fixed">
    <origin xyz="3.0357660829594124152e-18 -1.3877787807814456755e-17 -0.0049999999999999697464" rpy="-1.0439449364097525548e-14 1.9685459861175557675e-31 1.834678230847674038e-29" />
    <parent link="spur_gear_21_teeth" />
    <child link="hip_yaw_link" />
    <axis xyz="0 0 1" />
    <limit effort="1" velocity="20" />
    <joint_properties friction="0.0" />
  </joint>

  <joint name="left_hip_yaw_driven" type="revolute">
    <origin xyz="-0.037000000000000005107 -0.041100000000000108669 0.019500000000000006911" rpy="-1.5707963267948841235 1.5707963267948932273 0" />
    <parent link="waist_link" />
    <child link="spur_gear_21_teeth" />
    <axis xyz="0 0 1" />
    <limit effort="1" velocity="20" lower="-1.570796326794896558" upper="1.570796326794896558" />
    <joint_properties friction="0.0" />
  </joint>

  <link name="spur_gear_19_teeth_2">
    <visual>
      <origin xyz="0 0 0" rpy="0 -0 0" />
      <geometry>
        <mesh filename="../assemblies/toddlerbot/meshes/spur_gear_19_teeth_2_visual.stl" />
      </geometry>
      <material name="spur_gear_19_teeth_2_material">
        <color rgba="0.61568627450980395466 0.81176470588235294379 0.92941176470588238168 1.0" />
      </material>
    </visual>
    <inertial>
      <origin xyz="-4.9156135418091161685e-09 9.0060873701983133858e-10 -0.0045295192537419875708" rpy="0 0 0" />
      <mass value="0.0010993711450650535313" />
      <inertia ixx="2.9215018435433095279e-08" ixy="2.5903313731232818381e-16" ixz="-8.4242612455637522657e-15" iyy="2.9215021540034058468e-08" iyz="1.5226232384526170773e-15" izz="4.5709977027671368266e-08" />
    </inertial>
  </link>

  <joint name="right_hip_yaw_drive" type="revolute">
    <origin xyz="0.037000000000000358991 -0.037100000000003852119 0.039500000000000062839" rpy="-1.5707963267949709429 3.0764921674346154011e-13 2.7727445053553844104e-13" />
    <parent link="waist_link" />
    <child link="spur_gear_19_teeth_2" />
    <axis xyz="0 0 1" />
    <limit effort="1" velocity="20" lower="-1.570796326794896558" upper="1.570796326794896558" />
    <joint_properties friction="0.0" />
  </joint>

  <link name="spur_gear_21_teeth_2">
    <visual>
      <origin xyz="0 0 0" rpy="0 -0 0" />
      <geometry>
        <mesh filename="../assemblies/toddlerbot/meshes/spur_gear_21_teeth_2_visual.stl" />
      </geometry>
      <material name="spur_gear_21_teeth_2_material">
        <color rgba="0.61568627450980395466 0.81176470588235294379 0.92941176470588238168 1.0" />
      </material>
    </visual>
    <inertial>
      <origin xyz="-4.7814841733033882526e-10 -1.2610156241567811626e-12 -0.0025055381383856678047" rpy="0 0 0" />
      <mass value="0.0010063046528317972673" />
      <inertia ixx="3.1842855421068488283e-08" ixy="1.560614116831242474e-38" ixz="2.021036725007793052e-39" iyy="3.1842855426953779079e-08" iyz="5.2356557841516804612e-39" izz="5.9529380586728028132e-08" />
    </inertial>
  </link>

  <joint name="right_leg_fixed" type="fixed">
    <origin xyz="0 0 -0.004999999999999997502" rpy="1.0732181508787092545e-15 5.1822669723995480778e-16 -1.6653345369374924824e-16" />
    <parent link="spur_gear_21_teeth_2" />
    <child link="hip_yaw_link_2" />
    <axis xyz="0 0 1" />
    <limit effort="1" velocity="20" />
    <joint_properties friction="0.0" />
  </joint>

  <joint name="right_hip_yaw_driven" type="revolute">
    <origin xyz="0.037000000000000005107 -0.041100000000000011524 0.019500000000000010381" rpy="-1.5707963267948983344 1.5707963267948950037 0" />
    <parent link="waist_link" />
    <child link="spur_gear_21_teeth_2" />
    <axis xyz="0 0 1" />
    <limit effort="1" velocity="20" lower="-1.570796326794896558" upper="1.570796326794896558" />
    <joint_properties friction="0.0" />
  </joint>

  <joint name="waist_roll" type="revolute">
    <origin xyz="-6.2255683191263486807e-20 0.022707865260692461362 -0.013000000000000004607" rpy="1.5707963267948952257 1.2017992026080351615e-15 4.2181022606678868535e-16" />
    <parent link="waist_gears" />
    <child link="waist_link" />
    <axis xyz="0 0 1" />
    <limit effort="1" velocity="20" lower="-0.52359877559829881566" upper="0.52359877559829881566" />
    <joint_properties friction="0.0" />
  </joint>

  <joint name="waist_yaw" type="revolute">
    <origin xyz="-1.7347234759768070944e-18 -1.9721522630525295135e-31 0" rpy="2.0946901476030943553e-15 7.1861600448343401911e-16 -1.5707963267948228392" />
    <parent link="torso" />
    <child link="waist_gears" />
    <axis xyz="0 0 1" />
    <limit effort="1" velocity="20" lower="-1.570796326794896558" upper="1.570796326794896558" />
    <joint_properties friction="0.0" />
  </joint>

  <joint name="left_arm_fixed" type="fixed">
    <origin xyz="0.0010000000000009051128 0.049000000000000341893 0.11948651076281792405" rpy="-5.9230088976703815107e-16 1.7322096859285544219e-15 1.6762794059802379347e-29" />
    <parent link="torso" />
    <child link="xc430" />
    <axis xyz="0 0 1" />
    <limit effort="1" velocity="20" />
    <joint_properties friction="0.0" />
  </joint>

  <joint name="right_arm_fixed" type="fixed">
    <origin xyz="0.0010000000000010308802 -0.049000000000000321076 0.11948651076281791017" rpy="-5.9230088976591895466e-16 1.732209685967738918e-15 1.6762794059934078982e-29" />
    <parent link="torso" />
    <child link="xc430_2" />
    <axis xyz="0 0 1" />
    <limit effort="1" velocity="20" />
    <joint_properties friction="0.0" />
  </joint>


  <link name="hip_yaw_link">
    <visual>
      <origin xyz="0 0 0" rpy="0 -0 0" />
      <geometry>
        <mesh filename="../assemblies/left_leg_XM430/meshes/left_hip_yaw_link_visual.stl" />
      </geometry>
      <material name="hip_yaw_link_material">
        <color rgba="0.61568627450980395466 0.81176470588235294379 0.92941176470588238168 1.0" />
      </material>
    </visual>
    <inertial>
      <origin xyz="-2.2261122848985064994e-19 -2.288253466384850684e-19 -0.0098390489054829104176" rpy="0 0 0" />
      <mass value="0.017999999999999991701" />
      <inertia ixx="2.6385033891442532385e-06" ixy="0" ixz="0" iyy="7.6596731957046856464e-06" iyz="0" izz="7.7220708070894735956e-06" />
    </inertial>
  </link>

  <link name="hip_roll_link">
    <visual>
      <origin xyz="0 0 0" rpy="0 -0 0" />
      <geometry>
        <mesh filename="../assemblies/left_leg_XM430/meshes/left_hip_roll_link_visual.stl" />
      </geometry>
      <material name="hip_roll_link_material">
        <color rgba="0.51698661238356036218 0.50347815951093466413 0.49050589017722012741 1.0" />
      </material>
    </visual>
    <inertial>
      <origin xyz="-0.011999849582185674601 -0.0004959809079401069189 -0.018504111838598652495" rpy="0 0 0" />
      <mass value="0.10699970659110669136" />
      <inertia ixx="2.2075996228675713259e-05" ixy="-4.5005801829347712165e-08" ixz="-4.5362214344093405151e-08" iyy="2.9866686933524272515e-05" iyz="-5.560631946651787421e-07" izz="2.9866720157736384206e-05" />
    </inertial>
  </link>

  <link name="left_hip_pitch_link_xm430">
    <visual>
      <origin xyz="0 0 0" rpy="0 -0 0" />
      <geometry>
        <mesh filename="../assemblies/left_leg_XM430/meshes/left_hip_pitch_link_xm430_visual.stl" />
      </geometry>
      <material name="left_hip_pitch_link_xm430_material">
        <color rgba="0.57975821272406502516 0.7714372895922380069 0.90851483081009554166 1.0" />
      </material>
    </visual>
    <inertial>
      <origin xyz="-0.0025375182677326558155 -0.05317722650012224328 -0.015212672942454387101" rpy="0 0 0" />
      <mass value="0.029200901345856091623" />
      <inertia ixx="4.1359196178562864237e-05" ixy="-2.8912579823060953688e-07" ixz="-3.4728834573987417724e-09" iyy="9.0571276411052877486e-06" iyz="1.6889888074652855728e-06" izz="4.0741364151347275225e-05" />
    </inertial>
  </link>

  <link name="left_calf_link">
    <visual>
      <origin xyz="0 0 0" rpy="0 -0 0" />
      <geometry>
        <mesh filename="../assemblies/left_leg_XM430/meshes/left_calf_link_visual.stl" />
      </geometry>
      <material name="left_calf_link_material">
        <color rgba="0.61177930930733637194 0.71653254923097864371 0.74989274724786580961 1.0" />
      </material>
    </visual>
    <inertial>
      <origin xyz="0.0011880880235005657642 -0.049643068417602222164 -0.0098634853143294513173" rpy="0 0 0" />
      <mass value="0.079607494529051470167" />
      <inertia ixx="4.8048473174225778625e-05" ixy="3.5190650833684927661e-06" ixz="3.9918574956073125955e-07" iyy="1.4293033116538852344e-05" iyz="4.8859952267616621282e-07" izz="5.1177637188996256468e-05" />
    </inertial>
  </link>

  <link name="bearing_683">
    <visual>
      <origin xyz="0 0 0" rpy="0 -0 0" />
      <geometry>
        <mesh filename="../assemblies/left_leg_XM430/meshes/left_bearing_683_visual.stl" />
      </geometry>
      <material name="bearing_683_material">
        <color rgba="0.64705882352941179736 0.64705882352941179736 0.64705882352941179736 1.0" />
      </material>
    </visual>
    <inertial>
      <origin xyz="1.0732094295242872641e-19 -2.4186774283162219549e-19 -0.0015500000000000038487" rpy="0 0 0" />
      <mass value="0.00048694686130641793437" />
      <inertia ixx="2.1551456503319887385e-09" ixy="-5.2579508363931942185e-28" ixz="-1.5562214681222354289e-37" iyy="2.1551456503319883249e-09" iyz="4.8142195701833082741e-38" izz="3.5303647444715305817e-09" />
    </inertial>
  </link>

  <joint name="left_knee_front_rev_2" type="revolute">
    <origin xyz="-0.0057402514854764550775 0.013858192987669104568 -0.026199999999999393913" rpy="-1.5337469739246175927e-15 -1.4481776095066082806e-14 1.5765933876571727179" />
    <parent link="left_calf_link" />
    <child link="bearing_683" />
    <axis xyz="0 0 1" />
    <limit effort="1" velocity="20" lower="-6.283185307179586232" upper="6.283185307179586232" />
    <joint_properties friction="0.0" />
  </joint>

  <link name="bearing_683_2">
    <visual>
      <origin xyz="0 0 0" rpy="0 -0 0" />
      <geometry>
        <mesh filename="../assemblies/left_leg_XM430/meshes/left_bearing_683_2_visual.stl" />
      </geometry>
      <material name="bearing_683_2_material">
        <color rgba="0.64705882352941179736 0.64705882352941179736 0.64705882352941179736 1.0" />
      </material>
    </visual>
    <inertial>
      <origin xyz="1.0732094295233511417e-19 -2.4186774283159946952e-19 -0.0015500000000000003792" rpy="0 0 0" />
      <mass value="0.00048694686130641793437" />
      <inertia ixx="2.1551456503319887385e-09" ixy="-6.075146888311029187e-28" ixz="1.0905108511003815412e-37" iyy="2.1551456503319883249e-09" iyz="-6.0120096918532290094e-39" izz="3.5303647444715305817e-09" />
    </inertial>
  </link>

  <joint name="left_knee_back_rev_2" type="revolute">
    <origin xyz="0.0057402514854763397184 -0.013858192987669382124 -0.026199999999999508404" rpy="-6.0044740500748964117e-15 -1.2959392046781909549e-14 1.5749326172567148507" />
    <parent link="left_calf_link" />
    <child link="bearing_683_2" />
    <axis xyz="0 0 1" />
    <limit effort="1" velocity="20" lower="-6.283185307179586232" upper="6.283185307179586232" />
    <joint_properties friction="0.0" />
  </joint>

  <link name="ank_pitch_link">
    <visual>
      <origin xyz="0 0 0" rpy="0 -0 0" />
      <geometry>
        <mesh filename="../assemblies/left_leg_XM430/meshes/left_ank_pitch_link_visual.stl" />
      </geometry>
      <material name="ank_pitch_link_material">
        <color rgba="0.63189161126160264814 0.7266866879354088038 0.78356373393969258601 1.0" />
      </material>
    </visual>
    <inertial>
      <origin xyz="0.00059528282565922429649 -4.026968314421366319e-08 7.7616092726367440568e-08" rpy="0 0 0" />
      <mass value="0.0042238381753791614387" />
      <inertia ixx="3.9782741364678456013e-07" ixy="-1.6834347840448532165e-13" ixz="2.0919189028788893413e-14" iyy="4.3705254067423072352e-07" iyz="-1.642882218166082817e-12" izz="8.8858574534612962607e-08" />
    </inertial>
  </link>

  <link name="ank_roll_link">
    <visual>
      <origin xyz="0 0 0" rpy="0 -0 0" />
      <geometry>
        <mesh filename="../assemblies/left_leg_XM430/meshes/left_ank_roll_link_visual.stl" />
      </geometry>
      <material name="ank_roll_link_material">
        <color rgba="0.61568627450980395466 0.81176470588235294379 0.9294117647058824927 1.0" />
      </material>
    </visual>
    <inertial>
      <origin xyz="-1.3268572459727253008e-07 0.026796353429500402443 -0.0010526854006037437896" rpy="0 0 0" />
      <mass value="0.024799999999999995659" />
      <inertia ixx="1.9846878556458580475e-05" ixy="3.3200060665847481778e-11" ixz="1.9151591849004810687e-11" iyy="1.8695132008820608923e-05" iyz="-1.6314461615565737141e-06" izz="5.1708394998630545036e-06" />
    </inertial>
  </link>

  <link name="ank_rr_link">
    <visual>
      <origin xyz="0 0 0" rpy="0 -0 0" />
      <geometry>
        <mesh filename="../assemblies/left_leg_XM430/meshes/left_ank_rr_link_visual.stl" />
      </geometry>
      <material name="ank_rr_link_material">
        <color rgba="0.61568627450980395466 0.81176470588235305481 0.92941176470588238168 1.0" />
      </material>
    </visual>
    <inertial>
      <origin xyz="-4.5249610960602571126e-05 0.0063096429836314582573 -1.9713802484447536718e-19" rpy="0 0 0" />
      <mass value="0.0014500000000000003338" />
      <inertia ixx="2.9739579267716156651e-08" ixy="2.4213146797977958536e-10" ixz="3.5523394884456039264e-14" iyy="2.743002772407197029e-08" iyz="4.8484729386581670697e-32" izz="4.2921949116163685671e-08" />
    </inertial>
  </link>

  <link name="ank_motor_rod_long">
    <visual>
      <origin xyz="0 0 0" rpy="0 -0 0" />
      <geometry>
        <mesh filename="../assemblies/left_leg_XM430/meshes/left_ank_motor_rod_long_visual.stl" />
      </geometry>
      <material name="ank_motor_rod_long_material">
        <color rgba="0.63549975559783222767 0.7077439301702044272 0.75109043491362770251 1.0" />
      </material>
    </visual>
    <inertial>
      <origin xyz="2.4855088326425076603e-10 0.034559019974062264724 0.00093851704878452723961" rpy="0 0 0" />
      <mass value="0.0021712857268636710437" />
      <inertia ixx="8.5350290058000496109e-07" ixy="1.4884244518799269911e-14" ixz="4.5749525025585298136e-11" iyy="1.3237321792739536015e-08" iyz="-4.3668910960852531263e-09" izz="8.5812217519451853453e-07" />
    </inertial>
  </link>

  <joint name="left_ank_long_rev_2" type="revolute">
    <origin xyz="-8.7083118494035716139e-16 0.0099999999999995092814 -1.0408340855860842566e-16" rpy="-1.5707963267948947816 1.3320366994106509484 -1.570796326794906328" />
    <parent link="ank_rr_link" />
    <child link="ank_motor_rod_long" />
    <axis xyz="0 0 1" />
    <limit effort="1" velocity="20" lower="-1.570796326794896558" upper="1.570796326794896558" />
    <joint_properties friction="0.0" />
  </joint>

  <joint name="left_ank_long_rev_1" type="revolute">
    <origin xyz="-0.018000000000000009048 0.016000000000000014211 -0.020599999999999993316" rpy="-6.6713492090580732284e-15 1.1685759706219267798e-15 3.1233695685467375291" />
    <parent link="ank_roll_link" />
    <child link="ank_rr_link" />
    <axis xyz="0 0 1" />
    <limit effort="1" velocity="20" lower="-1.570796326794896558" upper="1.570796326794896558" />
    <joint_properties friction="0.0" />
  </joint>

  <link name="ank_rr_link_2">
    <visual>
      <origin xyz="0 0 0" rpy="0 -0 0" />
      <geometry>
        <mesh filename="../assemblies/left_leg_XM430/meshes/left_ank_rr_link_2_visual.stl" />
      </geometry>
      <material name="ank_rr_link_2_material">
        <color rgba="0.61568627450980395466 0.81176470588235305481 0.92941176470588238168 1.0" />
      </material>
    </visual>
    <inertial>
      <origin xyz="-4.5249610960602571126e-05 -0.0063096429836314582573 3.6665849767975475512e-18" rpy="0 0 0" />
      <mass value="0.0014500000000000003338" />
      <inertia ixx="2.9739579267716156651e-08" ixy="-2.4213146797977958536e-10" ixz="-3.5523394884456039264e-14" iyy="2.743002772407197029e-08" iyz="2.8959809774280283228e-32" izz="4.2921949116163685671e-08" />
    </inertial>
  </link>

  <link name="ank_motor_rod_short">
    <visual>
      <origin xyz="0 0 0" rpy="0 -0 0" />
      <geometry>
        <mesh filename="../assemblies/left_leg_XM430/meshes/left_ank_motor_rod_short_visual.stl" />
      </geometry>
      <material name="ank_motor_rod_short_material">
        <color rgba="0.41222606689734719865 0.58339100346020755783 0.8110726643598615837 1.0" />
      </material>
    </visual>
    <inertial>
      <origin xyz="2.6038940630921277735e-10 0.023830465465870909886 0.00090403506359621691596" rpy="0 0 0" />
      <mass value="0.0017000000000000005558" />
      <inertia ixx="3.3153416252670177714e-07" ixy="8.7419769929220905374e-15" ixz="4.5749941567716138066e-11" iyy="1.0947363610305772565e-08" iyz="-3.5863098646406631404e-09" izz="3.3621340447865321394e-07" />
    </inertial>
  </link>

  <joint name="left_ank_small_rev_2" type="revolute">
    <origin xyz="9.0899510141184691747e-16 -0.0099999999999995647926 -1.0755285551056203985e-16" rpy="-1.570796326794896558 -1.2119133862909823307 -1.5707963267948985564" />
    <parent link="ank_rr_link_2" />
    <child link="ank_motor_rod_short" />
    <axis xyz="0 0 1" />
    <limit effort="1" velocity="20" lower="-1.570796326794896558" upper="1.570796326794896558" />
    <joint_properties friction="0.0" />
  </joint>

  <joint name="left_ank_small_rev_1" type="revolute">
    <origin xyz="0.01799999999999999864 0.016000000000000014211 -0.020600000000000007194" rpy="-2.3610930013721657667e-14 1.8265926123726939121e-15 0.026118548507372812278" />
    <parent link="ank_roll_link" />
    <child link="ank_rr_link_2" />
    <axis xyz="0 0 1" />
    <limit effort="1" velocity="20" lower="-1.570796326794896558" upper="1.570796326794896558" />
    <joint_properties friction="0.0" />
  </joint>

  <joint name="left_ank_roll" type="revolute">
    <origin xyz="0.001500000000001442237 -2.7755575615628913511e-17 5.1608023410310011059e-16" rpy="2.1179511264814085754e-16 1.570796326794896336 0" />
    <parent link="ank_pitch_link" />
    <child link="ank_roll_link" />
    <axis xyz="0 0 1" />
    <limit effort="1" velocity="20" lower="-0.785398163397448279" upper="0.785398163397448279" />
    <joint_properties friction="0.0" />
  </joint>

  <joint name="left_ank_pitch" type="revolute">
    <origin xyz="1.3606094101523029521e-15 -0.099999999999999422684 -0.010399999999999753192" rpy="-2.7292527261128833795e-15 8.7089742034479944265e-27 -3.1415926535897842342" />
    <parent link="left_calf_link" />
    <child link="ank_pitch_link" />
    <axis xyz="0 0 1" />
    <limit effort="1" velocity="20" lower="-0.785398163397448279" upper="0.95993108859688125456" />
    <joint_properties friction="0.0" />
  </joint>

  <link name="ank_motor_arm">
    <visual>
      <origin xyz="0 0 0" rpy="0 -0 0" />
      <geometry>
        <mesh filename="../assemblies/left_leg_XM430/meshes/left_ank_motor_arm_visual.stl" />
      </geometry>
      <material name="ank_motor_arm_material">
        <color rgba="0.62517751827980905244 0.70593642422614044651 0.75978993426662766453 1.0" />
      </material>
    </visual>
    <inertial>
      <origin xyz="0.014511489101591676723 1.5533629953170513721e-17 0.0040925443765950893574" rpy="0 0 0" />
      <mass value="0.0020595846677894939954" />
      <inertia ixx="2.7591836756522176772e-08" ixy="-1.073888424077530379e-22" ixz="-3.0270788206595033791e-08" iyy="1.613859921623843529e-07" iyz="-1.1775555296848878142e-22" izz="1.643783676501628224e-07" />
    </inertial>
  </link>

  <joint name="left_ank_act_1" type="revolute">
    <origin xyz="0.013499999999998390024 -0.044499999999992517763 0.0040000000000047931242" rpy="-4.6624689386713196717e-13 -1.8602011869043692927e-13 -0.21173394130248007761" />
    <parent link="left_calf_link" />
    <child link="ank_motor_arm" />
    <axis xyz="0 0 1" />
    <limit effort="1" velocity="20" lower="-1.3089969389957472057" upper="1.3089969389957472057" />
    <joint_properties friction="0.0" />
  </joint>

  <link name="ank_motor_arm_2">
    <visual>
      <origin xyz="0 0 0" rpy="0 -0 0" />
      <geometry>
        <mesh filename="../assemblies/left_leg_XM430/meshes/left_ank_motor_arm_2_visual.stl" />
      </geometry>
      <material name="ank_motor_arm_2_material">
        <color rgba="0.62517751827980905244 0.70593642422614044651 0.75978993426662766453 1.0" />
      </material>
    </visual>
    <inertial>
      <origin xyz="0.014511489101590405171 3.024037044074247143e-16 0.0040925443765950034886" rpy="0 0 0" />
      <mass value="0.0020595846677894939954" />
      <inertia ixx="2.7591836756521448853e-08" ixy="-3.4000254017017856248e-21" ixz="-3.0270788206589680278e-08" iyy="1.6138599216235497145e-07" iyz="-1.1468234907993340816e-21" izz="1.6437836765013386446e-07" />
    </inertial>
  </link>

  <joint name="left_ank_act_2" type="revolute">
    <origin xyz="0.013500000000005686271 -0.064499999999986984411 -0.024800000000000939349" rpy="-3.1415926535893090588 1.5796958800869922317e-14 -0.22995607267388284978" />
    <parent link="left_calf_link" />
    <child link="ank_motor_arm_2" />
    <axis xyz="0 0 1" />
    <limit effort="1" velocity="20" lower="-1.3089969389957472057" upper="1.3089969389957472057" />
    <joint_properties friction="0.0" />
  </joint>

  <joint name="left_knee_pitch" type="revolute">
    <origin xyz="1.7789635663640724108e-15 -0.095999999999999974243 -0.0092000000000004491379" rpy="-2.7292527217646126502e-15 1.3010425524809599738e-16 1.3434393505081787056e-14" />
    <parent link="left_hip_pitch_link_xm430" />
    <child link="left_calf_link" />
    <axis xyz="0 0 1" />
    <limit effort="1" velocity="20" lower="0" upper="1.9198621771937625091" />
    <joint_properties friction="0.0" />
  </joint>

  <link name="xm430_plate">
    <visual>
      <origin xyz="0 0 0" rpy="0 -0 0" />
      <geometry>
        <mesh filename="../assemblies/left_leg_XM430/meshes/left_xm430_plate_visual.stl" />
      </geometry>
      <material name="xm430_plate_material">
        <color rgba="0.61568627450980395466 0.81176470588235294379 0.92941176470588227065 1.0" />
      </material>
    </visual>
    <inertial>
      <origin xyz="3.4421432482995806958e-18 1.9695559014950283276e-18 -0.0024039046431217972466" rpy="0 0 0" />
      <mass value="0.0026999999999999997093" />
      <inertia ixx="1.2933116645363413477e-07" ixy="-6.8936588702566440413e-08" ixz="-1.4636059883575842587e-35" iyy="2.6720434385876688324e-07" iyz="-3.6939392146302759423e-37" izz="3.8533537562751439267e-07" />
    </inertial>
  </link>

  <link name="knee_rod">
    <visual>
      <origin xyz="0 0 0" rpy="0 -0 0" />
      <geometry>
        <mesh filename="../assemblies/left_leg_XM430/meshes/left_knee_rod_visual.stl" />
      </geometry>
      <material name="knee_rod_material">
        <color rgba="0.62711287994822184633 0.75177502733065848517 0.82657231576012035745 1.0" />
      </material>
    </visual>
    <inertial>
      <origin xyz="0.010967336698370255127 -3.1788847580806275266e-05 -0.0015872899055778412047" rpy="0 0 0" />
      <mass value="0.0013369468613064179954" />
      <inertia ixx="9.6972596797105259658e-09" ixy="2.6702550909382721953e-10" ixz="3.1323425599718969419e-10" iyy="2.4572580431713632521e-07" iyz="-9.0791012388215101528e-13" izz="2.5337766369868264653e-07" />
    </inertial>
  </link>

  <joint name="left_knee_front_rev_1" type="revolute">
    <origin xyz="0.013858192987669243346 0.0057402514854761515009 -0.0049999999999995308614" rpy="2.700462081678478798e-15 1.0789304203485744068e-14 -3.135795592727541159" />
    <parent link="xm430_plate" />
    <child link="knee_rod" />
    <axis xyz="0 0 1" />
    <limit effort="1" velocity="20" lower="-6.283185307179586232" upper="6.283185307179586232" />
    <joint_properties friction="0.0" />
  </joint>

  <link name="knee_rod_2">
    <visual>
      <origin xyz="0 0 0" rpy="0 -0 0" />
      <geometry>
        <mesh filename="../assemblies/left_leg_XM430/meshes/left_knee_rod_2_visual.stl" />
      </geometry>
      <material name="knee_rod_2_material">
        <color rgba="0.62711287994822184633 0.75177502733065848517 0.82657231576012035745 1.0" />
      </material>
    </visual>
    <inertial>
      <origin xyz="0.010967359242933370778 4.6393297827742935983e-06 -0.0015872899055775712383" rpy="0 0 0" />
      <mass value="0.0013369468613064179954" />
      <inertia ixx="9.6965021906694614659e-09" ixy="-3.8970331984128795066e-11" ixz="3.1323489988265582075e-10" iyy="2.4572618306503650155e-07" iyz="1.3250227035804205208e-13" izz="2.5337728495754195192e-07" />
    </inertial>
  </link>

  <joint name="left_knee_back_rev_1" type="revolute">
    <origin xyz="-0.013858192987669298857 -0.0057402514854763692087 -0.0050000000000000061756" rpy="9.6510604012704973759e-16 9.5675773494330421551e-15 -3.1374563631279994702" />
    <parent link="xm430_plate" />
    <child link="knee_rod_2" />
    <axis xyz="0 0 1" />
    <limit effort="1" velocity="20" lower="-6.283185307179586232" upper="6.283185307179586232" />
    <joint_properties friction="0.0" />
  </joint>

  <joint name="left_knee_act" type="revolute">
    <origin xyz="-0.00014999999999896470931 -0.061499999999999964417 -0.030400000000000516887" rpy="2.3599861887888032906e-15 -6.5336749892428132544e-16 1.5707963267949343056" />
    <parent link="left_hip_pitch_link_xm430" />
    <child link="xm430_plate" />
    <axis xyz="0 0 1" />
    <limit effort="1" velocity="20" lower="0" upper="1.9198621771937625091" />
    <joint_properties friction="0.0" />
  </joint>

  <joint name="left_hip_pitch" type="revolute">
    <origin xyz="-0.024000000716151263791 -0.019000000152441041956 -0.019000000152457022229" rpy="1.5707963267952340658 1.5707963267945734831 0" />
    <parent link="hip_roll_link" />
    <child link="left_hip_pitch_link_xm430" />
    <axis xyz="0 0 1" />
    <limit effort="1" velocity="20" lower="-1.570796326794896558" upper="1.570796326794896558" />
    <joint_properties friction="0.0" />
  </joint>

  <joint name="left_hip_roll" type="revolute">
    <origin xyz="0.018999999999999999528 -4.8230661142633672945e-18 -0.026000000000000002276" rpy="-3.141592653589793116 -1.570796326794896558 0" />
    <parent link="hip_yaw_link" />
    <child link="hip_roll_link" />
    <axis xyz="0 0 1" />
    <limit effort="1" velocity="20" lower="-0.785398163397448279" upper="1.570796326794896558" />
    <joint_properties friction="0.0" />
  </joint>


  <link name="hip_yaw_link_2">
    <visual>
      <origin xyz="0 0 0" rpy="0 -0 0" />
      <geometry>
        <mesh filename="../assemblies/right_leg_XM430/meshes/right_hip_yaw_link_visual.stl" />
      </geometry>
      <material name="hip_yaw_link_material">
        <color rgba="0.61568627450980395466 0.81176470588235294379 0.92941176470588238168 1.0" />
      </material>
    </visual>
    <inertial>
      <origin xyz="2.2261122848985064994e-19 2.288253466384850684e-19 -0.0098390489054829104176" rpy="0 0 0" />
      <mass value="0.017999999999999991701" />
      <inertia ixx="2.6385033891442532385e-06" ixy="0" ixz="0" iyy="7.6596731957046856464e-06" iyz="0" izz="7.7220708070894735956e-06" />
    </inertial>
  </link>

  <link name="hip_roll_link_2">
    <visual>
      <origin xyz="0 0 0" rpy="0 -0 0" />
      <geometry>
        <mesh filename="../assemblies/right_leg_XM430/meshes/right_hip_roll_link_visual.stl" />
      </geometry>
      <material name="hip_roll_link_material">
        <color rgba="0.51698661238356036218 0.50347815951093466413 0.49050589017722012741 1.0" />
      </material>
    </visual>
    <inertial>
      <origin xyz="-0.011999849582183100272 -0.00049598090794401882876 -0.018504111838595651424" rpy="0 0 0" />
      <mass value="0.10699970659110669136" />
      <inertia ixx="2.2075996228674994975e-05" ixy="-4.5005801829291755051e-08" ixz="-4.5362214342478331696e-08" iyy="2.9866686933523046012e-05" iyz="-5.5606319466522395249e-07" izz="2.9866720157734995072e-05" />
    </inertial>
  </link>

  <link name="right_hip_pitch_link_xm430">
    <visual>
      <origin xyz="0 0 0" rpy="0 -0 0" />
      <geometry>
        <mesh filename="../assemblies/right_leg_XM430/meshes/right_hip_pitch_link_xm430_visual.stl" />
      </geometry>
      <material name="right_hip_pitch_link_xm430_material">
        <color rgba="0.57975821272406502516 0.7714372895922380069 0.90851483081009554166 1.0" />
      </material>
    </visual>
    <inertial>
      <origin xyz="0.0025369940892301448554 -0.053177222976062671345 -0.015212667045966779891" rpy="0 0 0" />
      <mass value="0.029200901345856091623" />
      <inertia ixx="4.1359210165692298516e-05" ixy="2.8846904860009830821e-07" ixz="3.5209134634345789117e-09" iyy="9.0572095101179148806e-06" iyz="1.6889923798545565445e-06" izz="4.074145340165466261e-05" />
    </inertial>
  </link>

  <link name="right_calf_link">
    <visual>
      <origin xyz="0 0 0" rpy="0 -0 0" />
      <geometry>
        <mesh filename="../assemblies/right_leg_XM430/meshes/right_calf_link_visual.stl" />
      </geometry>
      <material name="right_calf_link_material">
        <color rgba="0.61177930930733637194 0.71653254923097864371 0.74989274724786580961 1.0" />
      </material>
    </visual>
    <inertial>
      <origin xyz="0.0011880884108858634322 0.049643066575010524888 -0.009863485326573422779" rpy="0 0 0" />
      <mass value="0.079607494529051470167" />
      <inertia ixx="4.805679018573734033e-05" ixy="-3.51906641405246759e-06" ixz="3.9918569370885615482e-07" iyy="1.4293033414473497845e-05" iyz="-4.8654596308614493761e-07" izz="5.118595358303713042e-05" />
    </inertial>
  </link>

  <link name="bearing_683_3">
    <visual>
      <origin xyz="0 0 0" rpy="0 -0 0" />
      <geometry>
        <mesh filename="../assemblies/right_leg_XM430/meshes/right_bearing_683_visual.stl" />
      </geometry>
      <material name="bearing_683_material">
        <color rgba="0.64705882352941179736 0.64705882352941179736 0.64705882352941179736 1.0" />
      </material>
    </visual>
    <inertial>
      <origin xyz="-7.6004079503600922272e-19 2.4186774283161203621e-19 -0.0015500000000000016803" rpy="0 0 0" />
      <mass value="0.00048694686130641793437" />
      <inertia ixx="2.1551456503319887385e-09" ixy="9.419365354963680652e-30" ixz="-3.4903624922962751371e-39" iyy="2.1551456503319883249e-09" iyz="-3.356379210815639853e-38" izz="3.5303647444715305817e-09" />
    </inertial>
  </link>

  <joint name="right_knee_front_rev_2" type="revolute">
    <origin xyz="-0.0057402514854760396112 -0.013858192987670631124 -0.026200000000000334133" rpy="-2.6211415108180604669e-14 2.1401571334997732958e-15 3.1358007158040726026" />
    <parent link="right_calf_link" />
    <child link="bearing_683_3" />
    <axis xyz="0 0 1" />
    <limit effort="1" velocity="20" lower="-6.283185307179586232" upper="6.283185307179586232" />
    <joint_properties friction="0.0" />
  </joint>

  <link name="bearing_683_4">
    <visual>
      <origin xyz="0 0 0" rpy="0 -0 0" />
      <geometry>
        <mesh filename="../assemblies/right_leg_XM430/meshes/right_bearing_683_2_visual.stl" />
      </geometry>
      <material name="bearing_683_2_material">
        <color rgba="0.64705882352941179736 0.64705882352941179736 0.64705882352941179736 1.0" />
      </material>
    </visual>
    <inertial>
      <origin xyz="9.7468268094084534586e-19 2.4186774283158141392e-19 -0.0015499999999999977771" rpy="0 0 0" />
      <mass value="0.00048694686130641793437" />
      <inertia ixx="2.1551456503319879113e-09" ixy="-1.7281406775645525029e-27" ixz="1.2572702394626222976e-37" iyy="2.1551456503319883249e-09" iyz="-7.5550461566108832582e-38" izz="3.5303647444715322361e-09" />
    </inertial>
  </link>

  <joint name="right_knee_back_rev_2" type="revolute">
    <origin xyz="0.0057402514854763301774 0.013858192987669354368 -0.026199999999999879635" rpy="-2.3762645872631018006e-14 4.5147572622556449325e-15 3.1357969761587378699" />
    <parent link="right_calf_link" />
    <child link="bearing_683_4" />
    <axis xyz="0 0 1" />
    <limit effort="1" velocity="20" lower="-6.283185307179586232" upper="6.283185307179586232" />
    <joint_properties friction="0.0" />
  </joint>

  <link name="ank_pitch_link_2">
    <visual>
      <origin xyz="0 0 0" rpy="0 -0 0" />
      <geometry>
        <mesh filename="../assemblies/right_leg_XM430/meshes/right_ank_pitch_link_visual.stl" />
      </geometry>
      <material name="ank_pitch_link_material">
        <color rgba="0.63189161126160264814 0.7266866879354088038 0.78356373393969258601 1.0" />
      </material>
    </visual>
    <inertial>
      <origin xyz="0.00059528282565905722094 -4.0269682566397717277e-08 7.7616094186470963349e-08" rpy="0 0 0" />
      <mass value="0.0042238381753791614387" />
      <inertia ixx="3.9782741364675306109e-07" ixy="-1.6834347642027653766e-13" ixz="2.0919192022540514969e-14" iyy="4.3705254067418636017e-07" iyz="-1.642882214178072418e-12" izz="8.8858574534600111529e-08" />
    </inertial>
  </link>

  <link name="ank_roll_link_2">
    <visual>
      <origin xyz="0 0 0" rpy="0 -0 0" />
      <geometry>
        <mesh filename="../assemblies/right_leg_XM430/meshes/right_ank_roll_link_visual.stl" />
      </geometry>
      <material name="ank_roll_link_material">
        <color rgba="0.61568627450980395466 0.81176470588235305481 0.92941176470588238168 1.0" />
      </material>
    </visual>
    <inertial>
      <origin xyz="-4.3076724133029694684e-08 0.026796342838297314282 -0.0010522562961593588671" rpy="0 0 0" />
      <mass value="0.024800000000000006067" />
      <inertia ixx="1.9846823873608379683e-05" ixy="8.4559567382041455576e-12" ixz="1.094893692005225317e-10" iyy="1.8695098548981512322e-05" iyz="-1.6315562466570575069e-06" izz="5.1708532177991517958e-06" />
    </inertial>
  </link>

  <link name="ank_rr_link_3">
    <visual>
      <origin xyz="0 0 0" rpy="0 -0 0" />
      <geometry>
        <mesh filename="../assemblies/right_leg_XM430/meshes/right_ank_rr_link_visual.stl" />
      </geometry>
      <material name="ank_rr_link_material">
        <color rgba="0.61568627450980395466 0.81176470588235305481 0.92941176470588238168 1.0" />
      </material>
    </visual>
    <inertial>
      <origin xyz="-4.524961096060602702e-05 -0.0063096429836315146358 1.971380248442424741e-19" rpy="0 0 0" />
      <mass value="0.0014500000000000003338" />
      <inertia ixx="2.9739579267716156651e-08" ixy="-2.4213146797977974045e-10" ixz="-3.5523394884456039264e-14" iyy="2.743002772407197029e-08" iyz="1.1362860756035541147e-31" izz="4.2921949116163685671e-08" />
    </inertial>
  </link>

  <link name="ank_motor_rod_long_2">
    <visual>
      <origin xyz="0 0 0" rpy="0 -0 0" />
      <geometry>
        <mesh filename="../assemblies/right_leg_XM430/meshes/right_ank_motor_rod_long_visual.stl" />
      </geometry>
      <material name="ank_motor_rod_long_material">
        <color rgba="0.63549975559783222767 0.7077439301702044272 0.75109043491362770251 1.0" />
      </material>
    </visual>
    <inertial>
      <origin xyz="2.4855088090226780465e-10 0.034559019974062271663 0.00093851704878453797321" rpy="0 0 0" />
      <mass value="0.0021712857268636710437" />
      <inertia ixx="8.5350290058000316114e-07" ixy="1.4884244458420421049e-14" ixz="4.5749525025566188971e-11" iyy="1.3237321792739565794e-08" iyz="-4.3668910960855302318e-09" izz="8.5812217519451694634e-07" />
    </inertial>
  </link>

  <joint name="right_ank_L_rev_2" type="revolute">
    <origin xyz="0 -0.010000000000000619504 3.2265856653168611956e-16" rpy="-1.5707963267948976682 -1.3320366994106360714 -1.5707963267948898967" />
    <parent link="ank_rr_link_3" />
    <child link="ank_motor_rod_long_2" />
    <axis xyz="0 0 1" />
    <limit effort="1" velocity="20" lower="-1.570796326794896558" upper="1.570796326794896558" />
    <joint_properties friction="0.0" />
  </joint>

  <joint name="right_ank_L_rev_1" type="revolute">
    <origin xyz="0.018000000000000074968 0.0159999999999997089 -0.020600000000000378425" rpy="-5.2246648675592445302e-15 7.3924679944672393986e-16 0.018223085042994146415" />
    <parent link="ank_roll_link_2" />
    <child link="ank_rr_link_3" />
    <axis xyz="0 0 1" />
    <limit effort="1" velocity="20" lower="-1.570796326794896558" upper="1.570796326794896558" />
    <joint_properties friction="0.0" />
  </joint>

  <link name="ank_rr_link_4">
    <visual>
      <origin xyz="0 0 0" rpy="0 -0 0" />
      <geometry>
        <mesh filename="../assemblies/right_leg_XM430/meshes/right_ank_rr_link_2_visual.stl" />
      </geometry>
      <material name="ank_rr_link_2_material">
        <color rgba="0.61568627450980395466 0.81176470588235305481 0.92941176470588238168 1.0" />
      </material>
    </visual>
    <inertial>
      <origin xyz="-4.524961096060602702e-05 0.0063096429836314582573 -1.9713802484428686679e-19" rpy="0 0 0" />
      <mass value="0.0014500000000000003338" />
      <inertia ixx="2.9739579267716156651e-08" ixy="2.4213146797977968875e-10" ixz="3.5523394884456039264e-14" iyy="2.743002772407197029e-08" iyz="9.1738885996303588753e-32" izz="4.2921949116163685671e-08" />
    </inertial>
  </link>

  <link name="ank_motor_rod_short_2">
    <visual>
      <origin xyz="0 0 0" rpy="0 -0 0" />
      <geometry>
        <mesh filename="../assemblies/right_leg_XM430/meshes/right_ank_motor_rod_short_visual.stl" />
      </geometry>
      <material name="ank_motor_rod_short_material">
        <color rgba="0.41222606689734719865 0.58339100346020755783 0.8110726643598615837 1.0" />
      </material>
    </visual>
    <inertial>
      <origin xyz="2.6038940077933527863e-10 0.023830465465870854375 0.00090403506359621995173" rpy="0 0 0" />
      <mass value="0.0017000000000000005558" />
      <inertia ixx="3.3153416252669738316e-07" ixy="8.7419776437350604926e-15" ixz="4.5749941567703542949e-11" iyy="1.0947363610305534337e-08" iyz="-3.586309864640583731e-09" izz="3.3621340447864903172e-07" />
    </inertial>
  </link>

  <joint name="right_ank_S_rev_2" type="revolute">
    <origin xyz="-6.9388939039072283776e-18 0.010000000000000008882 0" rpy="-1.570796326794896558 1.2119133862908271215 -1.5707963267949023312" />
    <parent link="ank_rr_link_4" />
    <child link="ank_motor_rod_short_2" />
    <axis xyz="0 0 1" />
    <limit effort="1" velocity="20" lower="-1.570796326794896558" upper="1.570796326794896558" />
    <joint_properties friction="0.0" />
  </joint>

  <joint name="right_ank_S_rev_1" type="revolute">
    <origin xyz="-0.01799999999999993619 0.015999999999999042766 -0.020600000000000055767" rpy="-1.7258701733812934599e-15 2.598884774487275976e-15 3.1154741050825038862" />
    <parent link="ank_roll_link_2" />
    <child link="ank_rr_link_4" />
    <axis xyz="0 0 1" />
    <limit effort="1" velocity="20" lower="-1.570796326794896558" upper="1.570796326794896558" />
    <joint_properties friction="0.0" />
  </joint>

  <joint name="right_ank_roll" type="revolute">
    <origin xyz="0.0015000000000003571674 -1.4710455076283324161e-15 -7.6869934029222264371e-17" rpy="3.1415926535897922278 -1.5707963267948936714 0" />
    <parent link="ank_pitch_link_2" />
    <child link="ank_roll_link_2" />
    <axis xyz="0 0 1" />
    <limit effort="1" velocity="20" lower="-0.785398163397448279" upper="0.785398163397448279" />
    <joint_properties friction="0.0" />
  </joint>

  <joint name="right_ank_pitch" type="revolute">
    <origin xyz="-1.4869836122455719424e-16 0.10000000000000000555 -0.010399999999997862343" rpy="-2.681188604470794026e-14 -2.1107204178545346346e-15 -3.1415926535897873428" />
    <parent link="right_calf_link" />
    <child link="ank_pitch_link_2" />
    <axis xyz="0 0 1" />
    <limit effort="1" velocity="20" lower="-0.785398163397448279" upper="0.95993108859688125456" />
    <joint_properties friction="0.0" />
  </joint>

  <link name="ank_motor_arm_3">
    <visual>
      <origin xyz="0 0 0" rpy="0 -0 0" />
      <geometry>
        <mesh filename="../assemblies/right_leg_XM430/meshes/right_ank_motor_arm_visual.stl" />
      </geometry>
      <material name="ank_motor_arm_material">
        <color rgba="0.62517751827980905244 0.70593642422614044651 0.75978993426662766453 1.0" />
      </material>
    </visual>
    <inertial>
      <origin xyz="0.014511489101591685397 -3.4291162151967374102e-17 0.0040925443765950650712" rpy="0 0 0" />
      <mass value="0.0020595846677894939954" />
      <inertia ixx="2.7591836756521961705e-08" ixy="3.6774668841229710337e-22" ixz="-3.027078820659485512e-08" iyy="1.6138599216238437937e-07" iyz="1.147774120894066267e-22" izz="1.643783676501628224e-07" />
    </inertial>
  </link>

  <joint name="right_ank_act_1" type="revolute">
    <origin xyz="0.013499999999995892022 0.044500000000006756373 0.0040000000000032995273" rpy="-2.8438542481158199641e-13 -8.7103248833400898994e-14 0.21173394130149567061" />
    <parent link="right_calf_link" />
    <child link="ank_motor_arm_3" />
    <axis xyz="0 0 1" />
    <limit effort="1" velocity="20" lower="-1.3089969389957472057" upper="1.3089969389957472057" />
    <joint_properties friction="0.0" />
  </joint>

  <link name="ank_motor_arm_4">
    <visual>
      <origin xyz="0 0 0" rpy="0 -0 0" />
      <geometry>
        <mesh filename="../assemblies/right_leg_XM430/meshes/right_ank_motor_arm_2_visual.stl" />
      </geometry>
      <material name="ank_motor_arm_2_material">
        <color rgba="0.62517751827980905244 0.70593642422614044651 0.75978993426662766453 1.0" />
      </material>
    </visual>
    <inertial>
      <origin xyz="0.014511489101591680193 -7.0562260975285691822e-17 0.0040925443765950997657" rpy="0 0 0" />
      <mass value="0.0020595846677894939954" />
      <inertia ixx="2.7591836756522299195e-08" ixy="6.5140894647308504299e-22" ixz="-3.0270788206595285254e-08" iyy="1.6138599216238453819e-07" iyz="1.0144905279532861012e-22" izz="1.6437836765016295475e-07" />
    </inertial>
  </link>

  <joint name="right_ank_act_2" type="revolute">
    <origin xyz="0.013500000000004461556 0.064500000000007967627 -0.02480000000000005117" rpy="-3.1415926535894955762 -2.1645240671651661488e-13 0.22995607267264547846" />
    <parent link="right_calf_link" />
    <child link="ank_motor_arm_4" />
    <axis xyz="0 0 1" />
    <limit effort="1" velocity="20" lower="-1.3089969389957472057" upper="1.3089969389957472057" />
    <joint_properties friction="0.0" />
  </joint>

  <joint name="right_knee_pitch" type="revolute">
    <origin xyz="-1.0147615000199594353e-17 -0.095999999999999974243 -0.0091999999999999963751" rpy="-2.6534330288551032658e-14 1.1031692555244897755e-16 3.1415926535897837901" />
    <parent link="right_hip_pitch_link_xm430" />
    <child link="right_calf_link" />
    <axis xyz="0 0 1" />
    <limit effort="1" velocity="20" lower="-1.9198621771937625091" upper="0" />
    <joint_properties friction="0.0" />
  </joint>

  <link name="xm430_plate_2">
    <visual>
      <origin xyz="0 0 0" rpy="0 -0 0" />
      <geometry>
        <mesh filename="../assemblies/right_leg_XM430/meshes/right_xm430_plate_visual.stl" />
      </geometry>
      <material name="xm430_plate_material">
        <color rgba="0.61568627450980395466 0.81176470588235294379 0.92941176470588227065 1.0" />
      </material>
    </visual>
    <inertial>
      <origin xyz="9.0711332485526191223e-19 3.9608123405210927809e-18 -0.0024039046431217989813" rpy="0 0 0" />
      <mass value="0.0026999999999999997093" />
      <inertia ixx="2.6720434385876688324e-07" ixy="-6.8936588702566387474e-08" ixz="5.7088300791331750827e-37" iyy="1.2933116645363405536e-07" iyz="1.8945956925322497883e-36" izz="3.8533537562751439267e-07" />
    </inertial>
  </link>

  <link name="knee_rod_3">
    <visual>
      <origin xyz="0 0 0" rpy="0 -0 0" />
      <geometry>
        <mesh filename="../assemblies/right_leg_XM430/meshes/right_knee_rod_visual.stl" />
      </geometry>
      <material name="knee_rod_material">
        <color rgba="0.62711287994822184633 0.75177502733065848517 0.82657231576012035745 1.0" />
      </material>
    </visual>
    <inertial>
      <origin xyz="0.010967336860938788415 3.1676475513568678739e-05 -0.0015872899055784160487" rpy="0 0 0" />
      <mass value="0.0013369468613064179954" />
      <inertia ixx="9.6972542174596575833e-09" ixy="-2.6608159053866443571e-10" ixz="3.1323426064517783691e-10" iyy="2.4572580704828347289e-07" iyz="9.0470070477483523269e-13" izz="2.5337766096757530939e-07" />
    </inertial>
  </link>

  <joint name="right_knee_front_rev_1" type="revolute">
    <origin xyz="-0.0057402514854763501267 -0.013858192987669298857 -0.004999999999999997502" rpy="1.3724907179645707302e-14 8.5838369743180810428e-15 1.5650043890091744903" />
    <parent link="xm430_plate_2" />
    <child link="knee_rod_3" />
    <axis xyz="0 0 1" />
    <limit effort="1" velocity="20" lower="-6.283185307179586232" upper="6.283185307179586232" />
    <joint_properties friction="0.0" />
  </joint>

  <link name="knee_rod_4">
    <visual>
      <origin xyz="0 0 0" rpy="0 -0 0" />
      <geometry>
        <mesh filename="../assemblies/right_leg_XM430/meshes/right_knee_rod_2_visual.stl" />
      </geometry>
      <material name="knee_rod_2_material">
        <color rgba="0.62711287994822184633 0.75177502733065848517 0.82657231576012035745 1.0" />
      </material>
    </visual>
    <inertial>
      <origin xyz="0.010967336742326090626 3.175850272440280676e-05 -0.0015872899055788310813" rpy="0 0 0" />
      <mass value="0.0013369468613064179954" />
      <inertia ixx="9.6972582027826425253e-09" ixy="-2.6677061414380881884e-10" ixz="3.1323425726045413542e-10" iyy="2.4572580505559759514e-07" iyz="9.0704345484111099949e-13" izz="2.5337766296021105338e-07" />
    </inertial>
  </link>

  <joint name="right_knee_back_rev_1" type="revolute">
    <origin xyz="0.0057402514854763518615 0.013858192987669284979 -0.004999999999999997502" rpy="1.5753282257193089183e-14 1.0921500977742974577e-14 1.5650006493638364269" />
    <parent link="xm430_plate_2" />
    <child link="knee_rod_4" />
    <axis xyz="0 0 1" />
    <limit effort="1" velocity="20" lower="-6.283185307179586232" upper="6.283185307179586232" />
    <joint_properties friction="0.0" />
  </joint>

  <joint name="right_knee_act" type="revolute">
    <origin xyz="0.00015000000000002473377 -0.061500000000000235034 -0.030399999999999871569" rpy="8.8262730457708764429e-15 -1.5870629741237974938e-14 3.1415926535897829019" />
    <parent link="right_hip_pitch_link_xm430" />
    <child link="xm430_plate_2" />
    <axis xyz="0 0 1" />
    <limit effort="1" velocity="20" lower="-1.9198621771937625091" upper="0" />
    <joint_properties friction="0.0" />
  </joint>

  <joint name="right_hip_pitch" type="revolute">
    <origin xyz="-0.024000000716142645685 -0.01900000015244446977 -0.019000000152450565588" rpy="1.5707963267950877384 1.5707963267947149255 0" />
    <parent link="hip_roll_link_2" />
    <child link="right_hip_pitch_link_xm430" />
    <axis xyz="0 0 1" />
    <limit effort="1" velocity="20" lower="-1.570796326794896558" upper="1.570796326794896558" />
    <joint_properties friction="0.0" />
  </joint>

  <joint name="right_hip_roll" type="revolute">
    <origin xyz="-0.019000000000000509537 -6.4654958575016212571e-17 -0.026000000000000463712" rpy="-1.3163472222772945962e-16 -1.5707963267948941155 0" />
    <parent link="hip_yaw_link_2" />
    <child link="hip_roll_link_2" />
    <axis xyz="0 0 1" />
    <limit effort="1" velocity="20" lower="-0.785398163397448279" upper="1.570796326794896558" />
    <joint_properties friction="0.0" />
  </joint>


  <link name="xc430">
    <visual>
      <origin xyz="0 0 0" rpy="0 -0 0" />
      <geometry>
        <mesh filename="../assemblies/left_arm_hand/meshes/left_xc430_visual.stl" />
      </geometry>
      <material name="xc430_material">
        <color rgba="0.3960334863748344314 0.50878377002232877402 0.71126755432153676573 1.0" />
      </material>
    </visual>
    <inertial>
      <origin xyz="0.007649938948420367639 -0.0056800345415021161882 -0.014255781343936730146" rpy="0 0 0" />
      <mass value="0.065021926915724281848" />
      <inertia ixx="1.0685477757330408185e-05" ixy="2.4991048730003782262e-08" ixz="-4.3793050176056826951e-09" iyy="1.6030858372951694338e-05" iyz="-9.5846760480288827968e-09" izz="1.8186829094811185627e-05" />
    </inertial>
  </link>

  <link name="sho_pitch_link">
    <visual>
      <origin xyz="0 0 0" rpy="0 -0 0" />
      <geometry>
        <mesh filename="../assemblies/left_arm_hand/meshes/left_sho_pitch_link_visual.stl" />
      </geometry>
      <material name="sho_pitch_link_material">
        <color rgba="0.61568627450980395466 0.81176470588235294379 0.92941176470588238168 1.0" />
      </material>
    </visual>
    <inertial>
      <origin xyz="5.825424752983753426e-11 -5.1264642561121013175e-05 0.0082440788127094953575" rpy="0 0 0" />
      <mass value="0.008600000000000003475" />
      <inertia ixx="1.2272887040545802461e-06" ixy="-2.142994420191543053e-14" ixz="-8.5847198540427074509e-15" iyy="2.9107306060364645499e-06" iyz="7.4623841398183117097e-09" izz="3.0803135950773496163e-06" />
    </inertial>
  </link>

  <link name="2xl430_gears">
    <visual>
      <origin xyz="0 0 0" rpy="0 -0 0" />
      <geometry>
        <mesh filename="../assemblies/left_arm_hand/meshes/left_2xl430_gears_visual.stl" />
      </geometry>
      <material name="2xl430_gears_material">
        <color rgba="0.91900666046079226845 0.7025956886054134376 0.12479235365575504224 1.0" />
      </material>
    </visual>
    <inertial>
      <origin xyz="-0.011545549214475146413 -0.0025776045975616475661 -0.018554883443549097938" rpy="0 0 0" />
      <mass value="0.10921242823035924585" />
      <inertia ixx="2.5633987199176192553e-05" ixy="9.2332485824732311751e-07" ixz="-1.9126365492206487289e-08" iyy="3.0316164317563576338e-05" iyz="-6.1055425070402846345e-07" izz="3.3278157643470436923e-05" />
    </inertial>
  </link>

  <link name="spur_1m_24t_drive">
    <visual>
      <origin xyz="0 0 0" rpy="0 -0 0" />
      <geometry>
        <mesh filename="../assemblies/left_arm_hand/meshes/left_spur_1m_24t_drive_visual.stl" />
      </geometry>
      <material name="spur_1m_24t_drive_material">
        <color rgba="0.61568627450980406568 0.81176470588235294379 0.92941176470588238168 1.0" />
      </material>
    </visual>
    <inertial>
      <origin xyz="-7.7521101396039417664e-15 -1.2144011607250416242e-16 0.0047949116178401460231" rpy="0 0 0" />
      <mass value="0.0032000000000000001533" />
      <inertia ixx="1.4019331346159892996e-07" ixy="1.6002410053751656435e-15" ixz="-8.7717508276537448259e-37" iyy="1.4019331260388786185e-07" iyz="1.1548227992196316113e-37" izz="2.3838919844264060647e-07" />
    </inertial>
  </link>

  <joint name="left_sho_yaw_drive" type="revolute">
    <origin xyz="-0.024000000716149078039 -0.019000000152453292573 -0.019000000152451651525" rpy="1.5707963267948956698 -4.5091784937906777239e-14 2.4545027507744066908e-14" />
    <parent link="2xl430_gears" />
    <child link="spur_1m_24t_drive" />
    <axis xyz="0 0 1" />
    <limit effort="1" velocity="20" lower="-3.141592653589793116" upper="3.141592653589793116" />
    <joint_properties friction="0.0" />
  </joint>

  <link name="spur_1m_24t_driven">
    <visual>
      <origin xyz="0 0 0" rpy="0 -0 0" />
      <geometry>
        <mesh filename="../assemblies/left_arm_hand/meshes/left_spur_1m_24t_driven_visual.stl" />
      </geometry>
      <material name="spur_1m_24t_driven_material">
        <color rgba="0.23137254901960788156 0.38039215686274502337 0.7058823529411765163 1.0" />
      </material>
    </visual>
    <inertial>
      <origin xyz="2.5339767539064915348e-18 -5.7992099762712231414e-15 -0.00096866348640038332785" rpy="0 0 0" />
      <mass value="0.0026999999999999997093" />
      <inertia ixx="1.2026541119643502094e-07" ixy="-2.1120706372726556366e-36" ixz="0" iyy="1.2026541119643483565e-07" iyz="0" izz="2.2827257365099366486e-07" />
    </inertial>
  </link>

  <link name="sho_yaw_link">
    <visual>
      <origin xyz="0 0 0" rpy="0 -0 0" />
      <geometry>
        <mesh filename="../assemblies/left_arm_hand/meshes/left_sho_yaw_link_visual.stl" />
      </geometry>
      <material name="sho_yaw_link_material">
        <color rgba="0.61568627450980395466 0.81176470588235294379 0.92941176470588238168 1.0" />
      </material>
    </visual>
    <inertial>
      <origin xyz="5.7814996523352891568e-18 3.8649239170559342289e-18 -0.024214576156328389278" rpy="0 0 0" />
      <mass value="0.014499999999999986858" />
      <inertia ixx="9.0490855102914890835e-06" ixy="3.5997729401745807688e-13" ixz="0" iyy="5.6767199180624668202e-06" iyz="0" izz="4.4590603637468091569e-06" />
    </inertial>
  </link>

  <link name="2xl430_gears_2">
    <visual>
      <origin xyz="0 0 0" rpy="0 -0 0" />
      <geometry>
        <mesh filename="../assemblies/left_arm_hand/meshes/left_2xl430_gears_2_visual.stl" />
      </geometry>
      <material name="2xl430_gears_2_material">
        <color rgba="0.91900666046079226845 0.7025956886054134376 0.12479235365575504224 1.0" />
      </material>
    </visual>
    <inertial>
      <origin xyz="-0.01154554921447331281 -0.0025776045975613760819 -0.018554883443544802762" rpy="0 0 0" />
      <mass value="0.10921242823035924585" />
      <inertia ixx="2.5633987199174796643e-05" ixy="9.2332485824667196093e-07" ixz="-1.9126365492400034317e-08" iyy="3.0316164317562424373e-05" iyz="-6.1055425070424720971e-07" izz="3.327815764346942726e-05" />
    </inertial>
  </link>

  <link name="spur_1m_24t_drive_2">
    <visual>
      <origin xyz="0 0 0" rpy="0 -0 0" />
      <geometry>
        <mesh filename="../assemblies/left_arm_hand/meshes/left_spur_1m_24t_drive_2_visual.stl" />
      </geometry>
      <material name="spur_1m_24t_drive_2_material">
        <color rgba="0.61568627450980406568 0.81176470588235294379 0.92941176470588238168 1.0" />
      </material>
    </visual>
    <inertial>
      <origin xyz="-7.7521101396039417664e-15 -1.2144011607250455685e-16 0.0047949116178401512273" rpy="0 0 0" />
      <mass value="0.0032000000000000001533" />
      <inertia ixx="1.4019331346159892996e-07" ixy="1.6002410086838880937e-15" ixz="3.3868739208338279975e-37" iyy="1.4019331260388786185e-07" iyz="2.3470577016292310921e-36" izz="2.3838919844264071235e-07" />
    </inertial>
  </link>

  <joint name="left_elbow_yaw_drive" type="revolute">
    <origin xyz="-0.024000000716143922441 -0.019000000152449375568 -0.019000000152448702495" rpy="1.5707963267948812369 -8.0032142329674811068e-15 1.2365412156371141215e-13" />
    <parent link="2xl430_gears_2" />
    <child link="spur_1m_24t_drive_2" />
    <axis xyz="0 0 1" />
    <limit effort="1" velocity="20" lower="-3.141592653589793116" upper="3.141592653589793116" />
    <joint_properties friction="0.0" />
  </joint>

  <link name="spur_1m_24t_driven_2">
    <visual>
      <origin xyz="0 0 0" rpy="0 -0 0" />
      <geometry>
        <mesh filename="../assemblies/left_arm_hand/meshes/left_spur_1m_24t_driven_2_visual.stl" />
      </geometry>
      <material name="spur_1m_24t_driven_2_material">
        <color rgba="0.23137254901960788156 0.38039215686274502337 0.7058823529411765163 1.0" />
      </material>
    </visual>
    <inertial>
      <origin xyz="2.5339767539064915348e-18 -5.7992099762712231414e-15 -0.00096866348640037638895" rpy="0 0 0" />
      <mass value="0.0026999999999999997093" />
      <inertia ixx="1.2026541119643502094e-07" ixy="-6.5732337140722133283e-38" ixz="0" iyy="1.2026541119643483565e-07" iyz="0" izz="2.2827257365099366486e-07" />
    </inertial>
  </link>

  <link name="elb_yaw_link">
    <visual>
      <origin xyz="0 0 0" rpy="0 -0 0" />
      <geometry>
        <mesh filename="../assemblies/left_arm_hand/meshes/left_elb_yaw_link_visual.stl" />
      </geometry>
      <material name="elb_yaw_link_material">
        <color rgba="0.61568627450980395466 0.81176470588235294379 0.92941176470588227065 1.0" />
      </material>
    </visual>
    <inertial>
      <origin xyz="5.287088917269459775e-08 0.0019873558182742479504 -0.023365661199828729327" rpy="0 0 0" />
      <mass value="0.017500000000000001665" />
      <inertia ixx="1.4097804991252558057e-05" ixy="1.6900809684051191583e-12" ixz="-1.1184673662158690996e-11" iyy="6.6367696417680293553e-06" iyz="1.0579908722588339983e-06" izz="8.9601142768980697473e-06" />
    </inertial>
  </link>

  <link name="spur_1m_24t_driven_3">
    <visual>
      <origin xyz="0 0 0" rpy="0 -0 0" />
      <geometry>
        <mesh filename="../assemblies/left_arm_hand/meshes/left_spur_1m_24t_driven_3_visual.stl" />
      </geometry>
      <material name="spur_1m_24t_driven_3_material">
        <color rgba="0.23137254901960788156 0.38039215686274502337 0.7058823529411765163 1.0" />
      </material>
    </visual>
    <inertial>
      <origin xyz="-2.522159886172245202e-17 -5.7992099762712231414e-15 -0.0025686634864003805856" rpy="0 0 0" />
      <mass value="0.0026999999999999997093" />
      <inertia ixx="1.2026541119643502094e-07" ixy="-2.9625477072638547111e-36" ixz="-1.5730367353383820857e-37" iyy="1.2026541119643483565e-07" iyz="1.1070062413737891266e-37" izz="2.2827257365099366486e-07" />
    </inertial>
  </link>

  <link name="2xl430_gears_3">
    <visual>
      <origin xyz="0 0 0" rpy="0 -0 0" />
      <geometry>
        <mesh filename="../assemblies/left_arm_hand/meshes/left_2xl430_gears_3_visual.stl" />
      </geometry>
      <material name="2xl430_gears_3_material">
        <color rgba="0.91900666046079226845 0.7025956886054134376 0.12479235365575504224 1.0" />
      </material>
    </visual>
    <inertial>
      <origin xyz="0.00044511655645805596948 0.011545548856396192772 -0.024422395554887000452" rpy="0 0 0" />
      <mass value="0.10921242823035924585" />
      <inertia ixx="3.3278157643469847388e-05" ixy="1.9126365494095211942e-08" ixz="6.1055425070499323398e-07" iyy="2.5633987199175328579e-05" iyz="9.2332485824892242159e-07" izz="3.0316164317561428263e-05" />
    </inertial>
  </link>

  <link name="spur_1m_24t_drive_3">
    <visual>
      <origin xyz="0 0 0" rpy="0 -0 0" />
      <geometry>
        <mesh filename="../assemblies/left_arm_hand/meshes/left_spur_1m_24t_drive_3_visual.stl" />
      </geometry>
      <material name="spur_1m_24t_drive_3_material">
        <color rgba="0.61568627450980406568 0.81176470588235294379 0.92941176470588238168 1.0" />
      </material>
    </visual>
    <inertial>
      <origin xyz="-7.7243545639883128529e-15 -1.2837900997641198244e-16 0.0047949116178401399516" rpy="0 0 0" />
      <mass value="0.0032000000000000001533" />
      <inertia ixx="1.4019331346159892996e-07" ixy="1.6002410041546426147e-15" ixz="-6.4318290562543542602e-36" iyy="1.4019331260388791479e-07" iyz="-3.5497739011481716373e-36" izz="2.3838919844264060647e-07" />
    </inertial>
  </link>

  <joint name="left_wrist_pitch_drive" type="revolute">
    <origin xyz="-1.5244678436276970501e-10 0.024000000358067485884 -0.0080000000000028173575" rpy="-6.0688227754444846318e-17 9.0954925662261794972e-16 -1.5707963267950935116" />
    <parent link="2xl430_gears_3" />
    <child link="spur_1m_24t_drive_3" />
    <axis xyz="0 0 1" />
    <limit effort="1" velocity="20" lower="-1.570796326794896558" upper="1.570796326794896558" />
    <joint_properties friction="0.0" />
  </joint>

  <link name="wrist_bearing_plate">
    <visual>
      <origin xyz="0 0 0" rpy="0 -0 0" />
      <geometry>
        <mesh filename="../assemblies/left_arm_hand/meshes/left_wrist_bearing_plate_visual.stl" />
      </geometry>
      <material name="wrist_bearing_plate_material">
        <color rgba="0.64496316278892629192 0.69011804996940528945 0.71706771073555874985 1.0" />
      </material>
    </visual>
    <inertial>
      <origin xyz="-0.0075896393545961445687 -0.015499999999999991215 -0.0018386110045718407138" rpy="0 0 0" />
      <mass value="0.0049000367468305539714" />
      <inertia ixx="4.9747313520140109893e-07" ixy="1.9458462399620376262e-22" ixz="1.8097509420524938529e-08" iyy="7.1295025627582449075e-07" iyz="2.3459445642475020808e-23" izz="1.192629795229191449e-06" />
    </inertial>
  </link>

  <joint name="left_wrist_roll_fixed" type="fixed">
    <origin xyz="0.015500000000005648149 -4.3853809472693683347e-15 -0.044999999999999262812" rpy="-1.5598633495994326207e-14 -1.730560139634137368e-13 -1.5707963267946343233" />
    <parent link="2xl430_gears_3" />
    <child link="wrist_bearing_plate" />
    <axis xyz="0 0 1" />
    <limit effort="1" velocity="20" />
    <joint_properties friction="0.0" />
  </joint>

  <link name="hand">
    <visual>
      <origin xyz="0 0 0" rpy="0 -0 0" />
      <geometry>
        <mesh filename="../assemblies/left_arm_hand/meshes/left_hand_visual.stl" />
      </geometry>
      <material name="hand_material">
        <color rgba="0.61568627450980395466 0.81176470588235294379 0.92941176470588238168 1.0" />
      </material>
    </visual>
    <inertial>
      <origin xyz="-4.3038382213741598201e-08 -0.049723778585225204829 -0.017933572005385655518" rpy="0 0 0" />
      <mass value="0.017000000000000004691" />
      <inertia ixx="9.4921414617707115536e-06" ixy="-1.554921589734161308e-11" ixz="-1.0809694196434974908e-11" iyy="4.0745028295219354634e-06" iyz="2.4719408559887990214e-07" izz="6.6623859522963546108e-06" />
    </inertial>
  </link>

  <joint name="left_wrist_roll" type="revolute">
    <origin xyz="0.019000000000001057709 -3.5807262710463305666e-10 -0.027000000152450100849" rpy="1.2848055952475997313e-13 1.5707963267946998265 0" />
    <parent link="2xl430_gears_3" />
    <child link="hand" />
    <axis xyz="0 0 1" />
    <limit effort="1" velocity="20" lower="-1.570796326794896558" upper="1.570796326794896558" />
    <joint_properties friction="0.0" />
  </joint>

  <joint name="left_wrist_pitch_driven" type="revolute">
    <origin xyz="-8.3266726846886740532e-17 5.4817261840867104183e-16 -0.0016000000000001152189" rpy="-5.7142471032373773212e-16 5.5511151217739912712e-17 -1.570796326794896336" />
    <parent link="spur_1m_24t_driven_3" />
    <child link="2xl430_gears_3" />
    <axis xyz="0 0 1" />
    <limit effort="1" velocity="20" lower="-1.570796326794896558" upper="1.570796326794896558" />
    <joint_properties friction="0.0" />
  </joint>

  <joint name="left_wrist_pitch_fixed" type="fixed">
    <origin xyz="2.0816681711721685133e-17 -0.025299999999999989164 -0.051999999999999990674" rpy="1.5707963267948958919 -1.570796326794896336 0" />
    <parent link="elb_yaw_link" />
    <child link="spur_1m_24t_driven_3" />
    <axis xyz="0 0 1" />
    <limit effort="1" velocity="20" />
    <joint_properties friction="0.0" />
  </joint>

  <joint name="left_elbow_yaw_fixed" type="fixed">
    <origin xyz="1.3097162243624893563e-16 6.2450045135165055399e-17 0.0015999999999997960298" rpy="-3.141592653589793116 -5.5511151231207524813e-17 -1.570796326794896336" />
    <parent link="spur_1m_24t_driven_2" />
    <child link="elb_yaw_link" />
    <axis xyz="0 0 1" />
    <limit effort="1" velocity="20" />
    <joint_properties friction="0.0" />
  </joint>

  <joint name="left_elbow_yaw_driven" type="revolute">
    <origin xyz="-3.5807262710463305666e-10 -0.027000000152449854518 -0.01900000000000161629" rpy="1.570796326794891673 1.5707963267948441555 0" />
    <parent link="2xl430_gears_2" />
    <child link="spur_1m_24t_driven_2" />
    <axis xyz="0 0 1" />
    <limit effort="1" velocity="20" lower="-3.141592653589793116" upper="3.141592653589793116" />
    <joint_properties friction="0.0" />
  </joint>

  <joint name="left_elbow_roll" type="revolute">
    <origin xyz="7.6327832942979512154e-17 -0.018999999999999992589 -0.059000000000000031586" rpy="1.570796326794896558 -7.0029629609134176679e-16 7.044195017682708143e-15" />
    <parent link="sho_yaw_link" />
    <child link="2xl430_gears_2" />
    <axis xyz="0 0 1" />
    <limit effort="1" velocity="20" lower="-1.570796326794896558" upper="1.570796326794896558" />
    <joint_properties friction="0.0" />
  </joint>

  <joint name="left_sho_yaw_fixed" type="fixed">
    <origin xyz="0 1.561251128379126385e-17 0.0015999999999999903189" rpy="-3.1415926535897922278 1.4418079614154122748e-16 -6.106226635437282205e-16" />
    <parent link="spur_1m_24t_driven" />
    <child link="sho_yaw_link" />
    <axis xyz="0 0 1" />
    <limit effort="1" velocity="20" />
    <joint_properties friction="0.0" />
  </joint>

  <joint name="left_sho_yaw_driven" type="revolute">
    <origin xyz="-3.5807536102883119611e-10 -0.027000000152448761642 -0.019000000000006084938" rpy="1.5707963267949398567 1.8984813721086286179e-14 -7.1310113557521486963e-14" />
    <parent link="2xl430_gears" />
    <child link="spur_1m_24t_driven" />
    <axis xyz="0 0 1" />
    <limit effort="1" velocity="20" lower="-3.141592653589793116" upper="3.141592653589793116" />
    <joint_properties friction="0.0" />
  </joint>

  <joint name="left_sho_roll" type="revolute">
    <origin xyz="-0.018999999999999992589 0.00099999999999997833677 0.026999999999999996225" rpy="-3.141592653589793116 1.5707963267948954478 0" />
    <parent link="sho_pitch_link" />
    <child link="2xl430_gears" />
    <axis xyz="0 0 1" />
    <limit effort="1" velocity="20" lower="-1.570796326794896558" upper="1.570796326794896558" />
    <joint_properties friction="0.0" />
  </joint>

  <joint name="left_sho_pitch" type="revolute">
    <origin xyz="-0.0039999999999985160273 0.012999999999999725317 -0.01424999999999848263" rpy="-1.5707963267948332753 -5.5178084323870191707e-14 -1.1649761152065636686e-13" />
    <parent link="xc430" />
    <child link="sho_pitch_link" />
    <axis xyz="0 0 1" />
    <limit effort="1" velocity="20" lower="-1.570796326794896558" upper="1.570796326794896558" />
    <joint_properties friction="0.0" />
  </joint>


  <link name="xc430_2">
    <visual>
      <origin xyz="0 0 0" rpy="0 -0 0" />
      <geometry>
        <mesh filename="../assemblies/right_arm_hand/meshes/right_xc430_visual.stl" />
      </geometry>
      <material name="xc430_material">
        <color rgba="0.3960334863748344314 0.50878377002232877402 0.71126755432153676573 1.0" />
      </material>
    </visual>
    <inertial>
      <origin xyz="0.0076499389484204942738 0.0056800345415021630258 -0.01424421865606324486" rpy="0 0 0" />
      <mass value="0.065021926915724281848" />
      <inertia ixx="1.0685477757330491194e-05" ixy="-2.499104872988050919e-08" ixz="4.3793050176100287021e-09" iyy="1.6030858372951945059e-05" iyz="-9.5846760479532371298e-09" izz="1.8186829094811067043e-05" />
    </inertial>
  </link>

  <link name="sho_pitch_link_2">
    <visual>
      <origin xyz="0 0 0" rpy="0 -0 0" />
      <geometry>
        <mesh filename="../assemblies/right_arm_hand/meshes/right_sho_pitch_link_visual.stl" />
      </geometry>
      <material name="sho_pitch_link_material">
        <color rgba="0.61568627450980395466 0.81176470588235294379 0.92941176470588238168 1.0" />
      </material>
    </visual>
    <inertial>
      <origin xyz="5.825424752983753426e-11 -5.1264642561120999623e-05 0.0082440788127094953575" rpy="0 0 0" />
      <mass value="0.008600000000000003475" />
      <inertia ixx="1.2272887040545802461e-06" ixy="-2.1429944201915424219e-14" ixz="-8.5847198540427074509e-15" iyy="2.9107306060364628558e-06" iyz="7.4623841398183100553e-09" izz="3.0803135950773496163e-06" />
    </inertial>
  </link>

  <link name="2xl430_gears_4">
    <visual>
      <origin xyz="0 0 0" rpy="0 -0 0" />
      <geometry>
        <mesh filename="../assemblies/right_arm_hand/meshes/right_2xl430_gears_visual.stl" />
      </geometry>
      <material name="2xl430_gears_material">
        <color rgba="0.91900666046079226845 0.7025956886054134376 0.12479235365575504224 1.0" />
      </material>
    </visual>
    <inertial>
      <origin xyz="-0.011545549214474582628 -0.0025776045975625170963 -0.01855488344354406377" rpy="0 0 0" />
      <mass value="0.10921242823035924585" />
      <inertia ixx="2.5633987199174718716e-05" ixy="9.2332485824708510125e-07" ixz="-1.9126365491687785487e-08" iyy="3.0316164317562065231e-05" iyz="-6.1055425070399691147e-07" izz="3.327815764346926463e-05" />
    </inertial>
  </link>

  <link name="spur_1m_24t_drive_4">
    <visual>
      <origin xyz="0 0 0" rpy="0 -0 0" />
      <geometry>
        <mesh filename="../assemblies/right_arm_hand/meshes/right_spur_1m_24t_drive_visual.stl" />
      </geometry>
      <material name="spur_1m_24t_drive_material">
        <color rgba="0.61568627450980406568 0.81176470588235294379 0.92941176470588238168 1.0" />
      </material>
    </visual>
    <inertial>
      <origin xyz="-7.7521101396039417664e-15 -1.2057275433451556166e-16 0.0047949116178401512273" rpy="0 0 0" />
      <mass value="0.0032000000000000001533" />
      <inertia ixx="1.4019331346159887702e-07" ixy="1.6002410000914703581e-15" ixz="-5.4090992845575242873e-36" iyy="1.4019331260388783538e-07" iyz="-6.8087356421599067805e-36" izz="2.3838919844264071235e-07" />
    </inertial>
  </link>

  <joint name="right_sho_yaw_drive" type="revolute">
    <origin xyz="-0.024000000716145303281 -0.01900000015244998619 -0.01900000015244465365" rpy="1.5707963267947440134 8.8389520895546782802e-14 1.3333206406916649652e-13" />
    <parent link="2xl430_gears_4" />
    <child link="spur_1m_24t_drive_4" />
    <axis xyz="0 0 1" />
    <limit effort="1" velocity="20" lower="-3.141592653589793116" upper="3.141592653589793116" />
    <joint_properties friction="0.0" />
  </joint>

  <link name="spur_1m_24t_driven_4">
    <visual>
      <origin xyz="0 0 0" rpy="0 -0 0" />
      <geometry>
        <mesh filename="../assemblies/right_arm_hand/meshes/right_spur_1m_24t_driven_visual.stl" />
      </geometry>
      <material name="spur_1m_24t_driven_material">
        <color rgba="0.23137254901960788156 0.38039215686274502337 0.7058823529411765163 1.0" />
      </material>
    </visual>
    <inertial>
      <origin xyz="2.5339767539064826755e-18 -5.7992099762712231414e-15 -0.00096866348640038332785" rpy="0 0 0" />
      <mass value="0.0026999999999999997093" />
      <inertia ixx="1.2026541119643502094e-07" ixy="3.0132909596002639219e-36" ixz="-9.0037654543726475118e-38" iyy="1.2026541119643483565e-07" iyz="0" izz="2.2827257365099366486e-07" />
    </inertial>
  </link>

  <link name="sho_yaw_link_2">
    <visual>
      <origin xyz="0 0 0" rpy="0 -0 0" />
      <geometry>
        <mesh filename="../assemblies/right_arm_hand/meshes/right_sho_yaw_link_visual.stl" />
      </geometry>
      <material name="sho_yaw_link_material">
        <color rgba="0.61568627450980395466 0.81176470588235294379 0.92941176470588238168 1.0" />
      </material>
    </visual>
    <inertial>
      <origin xyz="-1.1573942515719257393e-18 3.8649239170559342289e-18 -0.024214576156328385809" rpy="0 0 0" />
      <mass value="0.014499999999999986858" />
      <inertia ixx="9.0490855102914890835e-06" ixy="3.5997729401745807688e-13" ixz="1.7587891974902210219e-36" iyy="5.6767199180624668202e-06" iyz="0" izz="4.4590603637468091569e-06" />
    </inertial>
  </link>

  <link name="2xl430_gears_5">
    <visual>
      <origin xyz="0 0 0" rpy="0 -0 0" />
      <geometry>
        <mesh filename="../assemblies/right_arm_hand/meshes/right_2xl430_gears_2_visual.stl" />
      </geometry>
      <material name="2xl430_gears_2_material">
        <color rgba="0.91900666046079226845 0.7025956886054134376 0.12479235365575504224 1.0" />
      </material>
    </visual>
    <inertial>
      <origin xyz="-0.011545549214473463731 -0.0025776045975580215604 -0.018554883443548501193" rpy="0 0 0" />
      <mass value="0.10921242823035924585" />
      <inertia ixx="2.5633987199173058531e-05" ixy="9.2332485824729887119e-07" ixz="-1.9126365492406122366e-08" iyy="3.0316164317562349835e-05" iyz="-6.1055425070545116116e-07" izz="3.3278157643466920043e-05" />
    </inertial>
  </link>

  <link name="spur_1m_24t_drive_5">
    <visual>
      <origin xyz="0 0 0" rpy="0 -0 0" />
      <geometry>
        <mesh filename="../assemblies/right_arm_hand/meshes/right_spur_1m_24t_drive_2_visual.stl" />
      </geometry>
      <material name="spur_1m_24t_drive_2_material">
        <color rgba="0.61568627450980406568 0.81176470588235294379 0.92941176470588238168 1.0" />
      </material>
    </visual>
    <inertial>
      <origin xyz="-7.7659879274117562231e-15 -1.2057275433451595609e-16 0.0047949116178401382168" rpy="0 0 0" />
      <mass value="0.0032000000000000001533" />
      <inertia ixx="1.4019331346159887702e-07" ixy="1.6002410041546426147e-15" ixz="-3.624182631715073592e-36" iyy="1.4019331260388791479e-07" iyz="-4.1524596034726495678e-37" izz="2.3838919844264060647e-07" />
    </inertial>
  </link>

  <joint name="right_elbow_yaw_drive" type="revolute">
    <origin xyz="-0.024000000716140640344 -0.019000000152444435075 -0.019000000152454357694" rpy="1.5707963267949622832 8.194034361146178641e-14 -1.7317067989020890092e-13" />
    <parent link="2xl430_gears_5" />
    <child link="spur_1m_24t_drive_5" />
    <axis xyz="0 0 1" />
    <limit effort="1" velocity="20" lower="-3.141592653589793116" upper="3.141592653589793116" />
    <joint_properties friction="0.0" />
  </joint>

  <link name="spur_1m_24t_driven_5">
    <visual>
      <origin xyz="0 0 0" rpy="0 -0 0" />
      <geometry>
        <mesh filename="../assemblies/right_arm_hand/meshes/right_spur_1m_24t_driven_2_visual.stl" />
      </geometry>
      <material name="spur_1m_24t_driven_2_material">
        <color rgba="0.23137254901960788156 0.38039215686274502337 0.7058823529411765163 1.0" />
      </material>
    </visual>
    <inertial>
      <origin xyz="2.5339767539064915348e-18 -5.7992099762712231414e-15 -0.00096866348640037638895" rpy="0 0 0" />
      <mass value="0.0026999999999999997093" />
      <inertia ixx="1.2026541119643502094e-07" ixy="-2.2321759283396738301e-36" ixz="0" iyy="1.2026541119643483565e-07" iyz="0" izz="2.2827257365099366486e-07" />
    </inertial>
  </link>

  <link name="elb_yaw_link_2">
    <visual>
      <origin xyz="0 0 0" rpy="0 -0 0" />
      <geometry>
        <mesh filename="../assemblies/right_arm_hand/meshes/right_elb_yaw_link_visual.stl" />
      </geometry>
      <material name="elb_yaw_link_material">
        <color rgba="0.61568627450980395466 0.81176470588235294379 0.92941176470588227065 1.0" />
      </material>
    </visual>
    <inertial>
      <origin xyz="5.287088917269459775e-08 0.0019873558182742479504 -0.023365661199828736266" rpy="0 0 0" />
      <mass value="0.017500000000000001665" />
      <inertia ixx="1.4097804991252558057e-05" ixy="1.6900809684051191583e-12" ixz="-1.1184673662158687765e-11" iyy="6.6367696417680293553e-06" iyz="1.0579908722588337865e-06" izz="8.9601142768980663591e-06" />
    </inertial>
  </link>

  <link name="spur_1m_24t_driven_6">
    <visual>
      <origin xyz="0 0 0" rpy="0 -0 0" />
      <geometry>
        <mesh filename="../assemblies/right_arm_hand/meshes/right_spur_1m_24t_driven_3_visual.stl" />
      </geometry>
      <material name="spur_1m_24t_driven_3_material">
        <color rgba="0.23137254901960788156 0.38039215686274502337 0.7058823529411765163 1.0" />
      </material>
    </visual>
    <inertial>
      <origin xyz="2.5339767539064672681e-18 -5.8061488701751303698e-15 -0.0025686634864003771161" rpy="0 0 0" />
      <mass value="0.0026999999999999997093" />
      <inertia ixx="1.2026541119643502094e-07" ixy="-8.8943138390222300706e-38" ixz="-3.4871107238620772993e-37" iyy="1.2026541119643483565e-07" iyz="3.5770621358774076477e-36" izz="2.2827257365099366486e-07" />
    </inertial>
  </link>

  <link name="2xl430_gears_6">
    <visual>
      <origin xyz="0 0 0" rpy="0 -0 0" />
      <geometry>
        <mesh filename="../assemblies/right_arm_hand/meshes/right_2xl430_gears_3_visual.stl" />
      </geometry>
      <material name="2xl430_gears_3_material">
        <color rgba="0.91900666046079226845 0.7025956886054134376 0.12479235365575504224 1.0" />
      </material>
    </visual>
    <inertial>
      <origin xyz="0.00044511655645500768086 0.011545548856405010371 -0.024422395554887468827" rpy="0 0 0" />
      <mass value="0.10921242823035924585" />
      <inertia ixx="3.3278157643468370163e-05" ixy="1.9126365492366470636e-08" ixz="6.1055425070389431461e-07" iyy="2.5633987199173590468e-05" iyz="9.2332485824554837172e-07" izz="3.0316164317561851779e-05" />
    </inertial>
  </link>

  <link name="spur_1m_24t_drive_6">
    <visual>
      <origin xyz="0 0 0" rpy="0 -0 0" />
      <geometry>
        <mesh filename="../assemblies/right_arm_hand/meshes/right_spur_1m_24t_drive_3_visual.stl" />
      </geometry>
      <material name="spur_1m_24t_drive_3_material">
        <color rgba="0.61568627450980406568 0.81176470588235294379 0.92941176470588238168 1.0" />
      </material>
    </visual>
    <inertial>
      <origin xyz="-7.7798657152195722576e-15 -1.2837900997641119358e-16 0.0047949116178401416863" rpy="0 0 0" />
      <mass value="0.0032000000000000001533" />
      <inertia ixx="1.4019331346159892996e-07" ixy="1.6002410033435796138e-15" ixz="1.8689311580061739594e-36" iyy="1.4019331260388783538e-07" iyz="1.2273789032714357933e-37" izz="2.3838919844264060647e-07" />
    </inertial>
  </link>

  <joint name="right_wrist_pitch_drive" type="revolute">
    <origin xyz="-1.5244812356929315911e-10 0.024000000358072565154 -0.0079999999999997069983" rpy="3.0683701463333139415e-15 3.000158893453974941e-16 -1.5707963267949427433" />
    <parent link="2xl430_gears_6" />
    <child link="spur_1m_24t_drive_6" />
    <axis xyz="0 0 1" />
    <limit effort="1" velocity="20" lower="-1.570796326794896558" upper="1.570796326794896558" />
    <joint_properties friction="0.0" />
  </joint>

  <link name="wrist_bearing_plate_2">
    <visual>
      <origin xyz="0 0 0" rpy="0 -0 0" />
      <geometry>
        <mesh filename="../assemblies/right_arm_hand/meshes/right_wrist_bearing_plate_visual.stl" />
      </geometry>
      <material name="wrist_bearing_plate_material">
        <color rgba="0.64496316278892629192 0.69011804996940528945 0.71706771073555874985 1.0" />
      </material>
    </visual>
    <inertial>
      <origin xyz="-0.0075896393545961402319 -0.015499999999999991215 -0.0018386110045718361602" rpy="0 0 0" />
      <mass value="0.0049000367468305539714" />
      <inertia ixx="4.9747313520140120481e-07" ixy="1.4311016266183815911e-23" ixz="1.8097509420524783019e-08" iyy="7.129502562758232202e-07" iyz="1.3422300279367577938e-23" izz="1.192629795229189755e-06" />
    </inertial>
  </link>

  <joint name="right_wrist_roll_fixed" type="fixed">
    <origin xyz="0.015499999999999309469 5.6343818499726694426e-15 -0.045000000000002496336" rpy="-3.8857806018810176234e-16 1.2034817586933650002e-13 -1.5707963267948996666" />
    <parent link="2xl430_gears_6" />
    <child link="wrist_bearing_plate_2" />
    <axis xyz="0 0 1" />
    <limit effort="1" velocity="20" />
    <joint_properties friction="0.0" />
  </joint>

  <link name="hand_2">
    <visual>
      <origin xyz="0 0 0" rpy="0 -0 0" />
      <geometry>
        <mesh filename="../assemblies/right_arm_hand/meshes/right_hand_visual.stl" />
      </geometry>
      <material name="hand_material">
        <color rgba="0.61568627450980395466 0.81176470588235294379 0.92941176470588238168 1.0" />
      </material>
    </visual>
    <inertial>
      <origin xyz="-4.3038382212874236463e-08 0.049723778585225232585 -0.020066427994614347008" rpy="0 0 0" />
      <mass value="0.017000000000000004691" />
      <inertia ixx="9.4921414617707115536e-06" ixy="1.554921589734161308e-11" ixz="1.0809694196434976524e-11" iyy="4.0745028295219354634e-06" iyz="2.4719408559887995508e-07" izz="6.6623859522963579989e-06" />
    </inertial>
  </link>

  <joint name="right_wrist_roll" type="revolute">
    <origin xyz="0.018999999999997782552 -3.5806707598950993088e-10 -0.027000000152450402691" rpy="-3.1415926535897886751 -1.5707963267947642194 0" />
    <parent link="2xl430_gears_6" />
    <child link="hand_2" />
    <axis xyz="0 0 1" />
    <limit effort="1" velocity="20" lower="-1.570796326794896558" upper="1.570796326794896558" />
    <joint_properties friction="0.0" />
  </joint>

  <joint name="right_wrist_pitch_driven" type="revolute">
    <origin xyz="-2.7755575615628913511e-17 6.9388939039072283776e-18 -0.0016000000000002227718" rpy="-4.5800957231150559108e-15 -6.2172489379009776006e-15 1.570796326794896558" />
    <parent link="spur_1m_24t_driven_6" />
    <child link="2xl430_gears_6" />
    <axis xyz="0 0 1" />
    <limit effort="1" velocity="20" lower="-1.570796326794896558" upper="1.570796326794896558" />
    <joint_properties friction="0.0" />
  </joint>

  <joint name="right_wrist_pitch_fixed" type="fixed">
    <origin xyz="0 -0.025299999999999996103 -0.052000000000000046185" rpy="1.5707963267948905628 1.5707963267948905628 0" />
    <parent link="elb_yaw_link_2" />
    <child link="spur_1m_24t_driven_6" />
    <axis xyz="0 0 1" />
    <limit effort="1" velocity="20" />
    <joint_properties friction="0.0" />
  </joint>

  <joint name="right_elbow_yaw_fixed" type="fixed">
    <origin xyz="-6.9388939039072283776e-18 0 0.0015999999999999903189" rpy="-3.141592653589793116 -2.2204460328203446248e-16 -3.141592653589793116" />
    <parent link="spur_1m_24t_driven_5" />
    <child link="elb_yaw_link_2" />
    <axis xyz="0 0 1" />
    <limit effort="1" velocity="20" />
    <joint_properties friction="0.0" />
  </joint>

  <joint name="right_elbow_yaw_driven" type="revolute">
    <origin xyz="-3.5806981685260197423e-10 -0.027000000152445247092 -0.019000000000004103884" rpy="-1.5707963267950058039 5.9602610059045593461e-15 3.1415926535897913396" />
    <parent link="2xl430_gears_5" />
    <child link="spur_1m_24t_driven_5" />
    <axis xyz="0 0 1" />
    <limit effort="1" velocity="20" lower="-3.141592653589793116" upper="3.141592653589793116" />
    <joint_properties friction="0.0" />
  </joint>

  <joint name="right_elbow_roll" type="revolute">
    <origin xyz="1.3183898417423733918e-16 -0.018999999999999933609 -0.059000000000000038525" rpy="1.570796326794896558 -2.6733818545004476465e-15 -6.1232339957031568635e-17" />
    <parent link="sho_yaw_link_2" />
    <child link="2xl430_gears_5" />
    <axis xyz="0 0 1" />
    <limit effort="1" velocity="20" lower="-1.570796326794896558" upper="1.570796326794896558" />
    <joint_properties friction="0.0" />
  </joint>

  <joint name="right_sho_yaw_fixed" type="fixed">
    <origin xyz="-6.9388939039072283776e-18 -8.6736173798840354721e-19 0.0016000000000000041966" rpy="-3.141592653589793116 -3.0292258760486853328e-28 -8.5559900487112566884e-29" />
    <parent link="spur_1m_24t_driven_4" />
    <child link="sho_yaw_link_2" />
    <axis xyz="0 0 1" />
    <limit effort="1" velocity="20" />
    <joint_properties friction="0.0" />
  </joint>

  <joint name="right_sho_yaw_driven" type="revolute">
    <origin xyz="-3.5807402876120164592e-10 -0.027000000152449625535 -0.019000000000000287492" rpy="1.5707963267948759079 -1.13931263975872123e-27 -4.4614134174147354846e-14" />
    <parent link="2xl430_gears_4" />
    <child link="spur_1m_24t_driven_4" />
    <axis xyz="0 0 1" />
    <limit effort="1" velocity="20" lower="-3.141592653589793116" upper="3.141592653589793116" />
    <joint_properties friction="0.0" />
  </joint>

  <joint name="right_sho_roll" type="revolute">
    <origin xyz="-0.018999999999999999528 0.0010000000000000251743 0.026999999999999996225" rpy="3.141592653589793116 1.570796326794896558 0" />
    <parent link="sho_pitch_link_2" />
    <child link="2xl430_gears_4" />
    <axis xyz="0 0 1" />
    <limit effort="1" velocity="20" lower="-1.570796326794896558" upper="1.570796326794896558" />
    <joint_properties friction="0.0" />
  </joint>

  <joint name="right_sho_pitch" type="revolute">
    <origin xyz="-0.0039999999999983789842 -0.012999999999999045305 -0.014250000000000390826" rpy="-1.5707963267949442976 1.6903145549952781317e-14 -3.1415926535895994931" />
    <parent link="xc430_2" />
    <child link="sho_pitch_link_2" />
    <axis xyz="0 0 1" />
    <limit effort="1" velocity="20" lower="-1.570796326794896558" upper="1.570796326794896558" />
    <joint_properties friction="0.0" />
  </joint>


</robot>