<robot name="toddlerbot">
  <mujoco>
    <compiler strippath="false" balanceinertia="true" discardvisual="false" />
  </mujoco>
  <link name="torso">
    <visual>
      <origin xyz="0 0 0" rpy="0 -0 0" />
      <geometry>
        <mesh filename="../assemblies/toddlerbot/meshes/torso_visual.stl" />
      </geometry>
      <material name="torso_material">
        <color rgba="0.58602628355191022091 0.73205173766587616768 0.84624015779321404285 1.0" />
      </material>
    </visual>
    <collision>
      <origin xyz="0 0 0" rpy="0 -0 0" />
      <geometry>
        <mesh filename="collisions/torso_collision.stl" />
      </geometry>
    </collision>
    <inertial>
      <origin xyz="-0.0074328354797873830498 0.0025059801105640623457 0.073401015491149065872" rpy="0 0 0" />
      <mass value="0.58490521749923585215" />
      <inertia ixx="0.0016168191047346513155" ixy="-1.4736281865313549167e-05" ixz="3.2221053182213636447e-07" iyy="0.0013101565794344581344" iyz="2.4169833425786339478e-05" izz="0.0011896913602930955876" />
    </inertial>
  </link>

  <link name="spur_1m_20t">
    <visual>
      <origin xyz="0 0 0" rpy="0 -0 0" />
      <geometry>
        <mesh filename="../assemblies/toddlerbot/meshes/spur_1m_20t_visual.stl" />
      </geometry>
      <material name="spur_1m_20t_material">
        <color rgba="0.64705882352941190838 0.64705882352941190838 0.64705882352941190838 1.0" />
      </material>
    </visual>
    <inertial>
      <origin xyz="-2.4334996767091156826e-18 -7.8538274165156240587e-18 0.0033745971730663251731" rpy="0 0 0" />
      <mass value="0.0015534950290892282111" />
      <inertia ixx="4.4726508287871799621e-08" ixy="2.6608965793107671434e-24" ixz="2.7597381312606834733e-39" iyy="4.4726508287871786386e-08" iyz="-1.7424300806353613314e-38" izz="7.9558906764902019844e-08" />
    </inertial>
  </link>

  <joint name="neck_yaw_drive" type="revolute">
    <origin xyz="-0.0049999999999990590166 -1.7787571338323640394e-16 0.12248651076281813488" rpy="1.900955487881492792e-15 1.6770488781412432481e-15 9.8514697225632145493e-16" />
    <parent link="torso" />
    <child link="spur_1m_20t" />
    <axis xyz="0 0 1" />
    <limit effort="1" velocity="20" lower="-2.2689280275926284602" upper="2.2689280275926284602" />
    <joint_properties friction="0.0" />
  </joint>

  <link name="neck_yaw_link">
    <visual>
      <origin xyz="0 0 0" rpy="0 -0 0" />
      <geometry>
        <mesh filename="../assemblies/toddlerbot/meshes/neck_yaw_link_visual.stl" />
      </geometry>
      <material name="neck_yaw_link_material">
        <color rgba="0.33636252417476653065 0.48680769190259864931 0.74976123534949778993 1.0" />
      </material>
    </visual>
    <inertial>
      <origin xyz="2.7291286460608435124e-05 -0.00019798992283530681964 0.011527412037194878155" rpy="0 0 0" />
      <mass value="0.0085168305947458285143" />
      <inertia ixx="1.0407116999274151318e-06" ixy="2.4210150466155122562e-11" ixz="-4.7246803216687554533e-10" iyy="1.1240009954110308532e-06" iyz="3.083484175463602921e-08" izz="3.1587565167291864821e-07" />
    </inertial>
  </link>

  <link name="neck_pitch_link">
    <visual>
      <origin xyz="0 0 0" rpy="0 -0 0" />
      <geometry>
        <mesh filename="../assemblies/toddlerbot/meshes/neck_pitch_link_visual.stl" />
      </geometry>
      <material name="neck_pitch_link_material">
        <color rgba="0.74911126277760042846 0.80002799398726853752 0.87441258869524285391 1.0" />
      </material>
    </visual>
    <collision>
      <origin xyz="0 0 0" rpy="0 -0 0" />
      <geometry>
        <mesh filename="collisions/neck_pitch_link_collision.stl" />
      </geometry>
    </collision>
    <inertial>
      <origin xyz="-0.0034370497615721063399 0.032876793988991494244 -0.0003647649213469508875" rpy="0 0 0" />
      <mass value="0.11211553874797881847" />
      <inertia ixx="7.7015755459850933459e-05" ixy="-2.1757968319823676698e-06" ixz="-2.8732209413522855765e-06" iyy="6.350263668815466151e-05" iyz="-1.2492352737635124786e-05" izz="2.861000238397491666e-05" />
    </inertial>
  </link>

  <link name="spur_gear_(13_teeth)">
    <visual>
      <origin xyz="0 0 0" rpy="0 -0 0" />
      <geometry>
        <mesh filename="../assemblies/toddlerbot/meshes/spur_gear_(13_teeth)_visual.stl" />
      </geometry>
      <material name="spur_gear_(13_teeth)_material">
        <color rgba="0.64705882352941168634 0.64705882352941168634 0.64705882352941168634 1.0" />
      </material>
    </visual>
    <inertial>
      <origin xyz="9.1521557941667763632e-10 -5.4872578397643168315e-10 0.0092751511485596356554" rpy="0 0 0" />
      <mass value="0.00081469437497230876716" />
      <inertia ixx="2.0244841463618394107e-08" ixy="2.9781775002671977054e-15" ixz="-8.2976066068196316953e-15" iyy="2.02448397785336892e-08" iyz="1.3142117784543017866e-15" izz="1.8905472907863310999e-08" />
    </inertial>
  </link>

  <joint name="neck_pitch_drive" type="revolute">
    <origin xyz="-1.1692036228083679816e-15 0.01565000000000066338 -0.0087999999999981218246" rpy="1.2246467991513517459e-16 -6.1232339957502284403e-17 -1.5707963267949054398" />
    <parent link="neck_pitch_link" />
    <child link="spur_gear_(13_teeth)" />
    <axis xyz="0 0 1" />
    <limit effort="1" velocity="20" lower="-1.4279966607226330932" upper="1.4279966607226330932" />
    <joint_properties friction="0.0" />
  </joint>

  <joint name="neck_pitch_driven" type="revolute">
    <origin xyz="3.7499999980261655708e-10 -0.0051500000614753986203 0.027500000000000010547" rpy="1.570796326794896558 8.661048429666698261e-16 3.1415926535897926719" />
    <parent link="neck_yaw_link" />
    <child link="neck_pitch_link" />
    <axis xyz="0 0 1" />
    <limit effort="1" velocity="20" lower="-1.570796326794896558" upper="1.570796326794896558" />
    <joint_properties friction="0.0" />
  </joint>

  <joint name="neck_yaw_driven" type="revolute">
    <origin xyz="0.016000000000001790568 1.3355656282555062267e-17 0.12348651076281798311" rpy="5.2022234352156643924e-17 -1.693050922709124266e-15 -3.1415926535897926719" />
    <parent link="torso" />
    <child link="neck_yaw_link" />
    <axis xyz="0 0 1" />
    <limit effort="1" velocity="20" lower="-3.141592653589793116" upper="3.141592653589793116" />
    <joint_properties friction="0.0" />
  </joint>

  <link name="waist_gears">
    <visual>
      <origin xyz="0 0 0" rpy="0 -0 0" />
      <geometry>
        <mesh filename="../assemblies/toddlerbot/meshes/waist_gears_visual.stl" />
      </geometry>
      <material name="waist_gears_material">
        <color rgba="0.2705751638183052088 0.53648836590125015267 0.70305495274644791426 1.0" />
      </material>
    </visual>
    <inertial>
      <origin xyz="6.546945447531986512e-08 5.678591623325374745e-10 0.012726165583898526104" rpy="0 0 0" />
      <mass value="0.023315805669179824611" />
      <inertia ixx="6.9043104388290759245e-06" ixy="1.8428638775971751246e-11" ixz="-9.9668712564048197337e-13" iyy="1.1624091971676541739e-06" iyz="-3.3260430305085550639e-10" izz="6.8701920560918665188e-06" />
    </inertial>
  </link>

  <link name="waist_link">
    <visual>
      <origin xyz="0 0 0" rpy="0 -0 0" />
      <geometry>
        <mesh filename="../assemblies/toddlerbot/meshes/waist_link_visual.stl" />
      </geometry>
      <material name="waist_link_material">
        <color rgba="0.63401200025306070351 0.68204699127249923674 0.66910193985036237052 1.0" />
      </material>
    </visual>
    <collision>
      <origin xyz="0 0 0" rpy="0 -0 0" />
      <geometry>
        <mesh filename="collisions/waist_link_collision.stl" />
      </geometry>
    </collision>
    <inertial>
      <origin xyz="-9.1086191341836857393e-07 0.026204483755308718984 -0.030190392008842527327" rpy="0 0 0" />
      <mass value="0.16631953490612463864" />
      <inertia ixx="6.8622997376114526383e-05" ixy="-6.1328048361138684763e-10" ixz="-3.6786792027265986e-06" iyy="0.00020057117429216650244" iyz="-3.7255079147357470748e-06" izz="0.00015770127977213151431" />
    </inertial>
  </link>

  <link name="spiral_bevel_1m_14t_30deg">
    <visual>
      <origin xyz="0 0 0" rpy="0 -0 0" />
      <geometry>
        <mesh filename="../assemblies/toddlerbot/meshes/spiral_bevel_1m_14t_30deg_visual.stl" />
      </geometry>
      <material name="spiral_bevel_1m_14t_30deg_material">
        <color rgba="0.64705882352941179736 0.64705882352941179736 0.64705882352941179736 1.0" />
      </material>
    </visual>
    <inertial>
      <origin xyz="8.2641075059564084171e-10 3.4055789828804644178e-10 0.0068612577407481710814" rpy="0 0 0" />
      <mass value="0.00067997563436136246491" />
      <inertia ixx="1.2174575798018978801e-08" ixy="3.8216067208892337065e-18" ixz="4.7204547843348541229e-16" iyy="1.2174575801813734381e-08" iyz="-2.6184097792419969889e-16" izz="1.3178653206314315019e-08" />
    </inertial>
  </link>

  <joint name="waist_act_1" type="revolute">
    <origin xyz="-5.4541005536440740413e-16 0.019599999999999950795 -0.012750000000000089387" rpy="1.5707963267948983344 1.5707963267948863439 0" />
    <parent link="waist_link" />
    <child link="spiral_bevel_1m_14t_30deg" />
    <axis xyz="0 0 1" />
    <limit effort="1" velocity="20" lower="-2.7825534678416246059" upper="2.7825534678416246059" />
    <joint_properties friction="0.0" />
  </joint>

  <link name="spiral_bevel_1m_14t_30deg_2">
    <visual>
      <origin xyz="0 0 0" rpy="0 -0 0" />
      <geometry>
        <mesh filename="../assemblies/toddlerbot/meshes/spiral_bevel_1m_14t_30deg_2_visual.stl" />
      </geometry>
      <material name="spiral_bevel_1m_14t_30deg_2_material">
        <color rgba="0.64705882352941179736 0.64705882352941179736 0.64705882352941179736 1.0" />
      </material>
    </visual>
    <inertial>
      <origin xyz="7.2990964661290291815e-10 5.1591309311023058013e-10 0.0068612577407481684794" rpy="0 0 0" />
      <mass value="0.00067997563436136246491" />
      <inertia ixx="1.2174575796548744672e-08" ixy="2.619906587730623466e-18" ixz="5.184754117236686056e-16" iyy="1.2174575803283975128e-08" iyz="-1.5023607718873399344e-16" izz="1.3178653206314321637e-08" />
    </inertial>
  </link>

  <joint name="waist_act_2" type="revolute">
    <origin xyz="-2.5130149897002749361e-16 0.019599999999999936917 -0.032749999999999550304" rpy="1.5707963267949001107 1.3463968515392203962 -1.4991504265429651005e-13" />
    <parent link="waist_link" />
    <child link="spiral_bevel_1m_14t_30deg_2" />
    <axis xyz="0 0 1" />
    <limit effort="1" velocity="20" lower="-2.7825534678416246059" upper="2.7825534678416246059" />
    <joint_properties friction="0.0" />
  </joint>

  <link name="spur_gear_19_teeth">
    <visual>
      <origin xyz="0 0 0" rpy="0 -0 0" />
      <geometry>
        <mesh filename="../assemblies/toddlerbot/meshes/spur_gear_19_teeth_visual.stl" />
      </geometry>
      <material name="spur_gear_19_teeth_material">
        <color rgba="0.61568627450980395466 0.81176470588235294379 0.92941176470588238168 1.0" />
      </material>
    </visual>
    <inertial>
      <origin xyz="-4.9968063063607437635e-09 -7.9242210755682841365e-11 0.0045295192537419875708" rpy="0 0 0" />
      <mass value="0.0010993711450650535313" />
      <inertia ixx="2.9215018435433075427e-08" ixy="2.5903313731374078717e-16" ixz="8.559980850070259655e-15" iyy="2.9215021540034058468e-08" iyz="1.152688137911182053e-16" izz="4.5709977027671368266e-08" />
    </inertial>
  </link>

  <joint name="left_hip_yaw_drive" type="revolute">
    <origin xyz="-0.036999999999998325895 0.03710000000000578807 -0.0395000000000009302" rpy="-1.5707963267950055819 -5.5860808452836958954e-13 -3.9012105568284431132e-13" />
    <parent link="waist_link" />
    <child link="spur_gear_19_teeth" />
    <axis xyz="0 0 1" />
    <limit effort="1" velocity="20" lower="-1.4211966766239538806" upper="1.4211966766239538806" />
    <joint_properties friction="0.0" />
  </joint>

  <link name="spur_gear_21_teeth">
    <visual>
      <origin xyz="0 0 0" rpy="0 -0 0" />
      <geometry>
        <mesh filename="../assemblies/toddlerbot/meshes/spur_gear_21_teeth_visual.stl" />
      </geometry>
      <material name="spur_gear_21_teeth_material">
        <color rgba="0.61568627450980395466 0.81176470588235294379 0.92941176470588238168 1.0" />
      </material>
    </visual>
    <inertial>
      <origin xyz="-4.7814841745556497441e-10 -1.2610225839217328832e-12 0.002494461861614330131" rpy="0 0 0" />
      <mass value="0.0010063046528317974842" />
      <inertia ixx="3.1842855421068488283e-08" ixy="2.8803584912472002524e-40" ixz="0" iyy="3.1842855426953785697e-08" iyz="0" izz="5.9529380586728034749e-08" />
    </inertial>
  </link>

  <joint name="left_leg_fixed" type="fixed">
    <origin xyz="-7.3725747729014301513e-18 -6.9388939039072283776e-18 0.004999999999999997502" rpy="-3.141592653589793116 1.9721522630525295135e-31 -1.1102230246249028723e-16" />
    <parent link="spur_gear_21_teeth" />
    <child link="hip_yaw_link" />
    <axis xyz="0 0 1" />
    <limit effort="1" velocity="20" />
    <joint_properties friction="0.0" />
  </joint>

  <joint name="left_hip_yaw_driven" type="revolute">
    <origin xyz="-0.03699999999999998429 0.041100000000000004585 -0.019499999999999979156" rpy="-1.5707963267948983344 -1.570796326794896558 0" />
    <parent link="waist_link" />
    <child link="spur_gear_21_teeth" />
    <axis xyz="0 0 1" />
    <limit effort="1" velocity="20" lower="-1.570796326794896558" upper="1.570796326794896558" />
    <joint_properties friction="0.0" />
  </joint>

  <link name="spur_gear_19_teeth_2">
    <visual>
      <origin xyz="0 0 0" rpy="0 -0 0" />
      <geometry>
        <mesh filename="../assemblies/toddlerbot/meshes/spur_gear_19_teeth_2_visual.stl" />
      </geometry>
      <material name="spur_gear_19_teeth_2_material">
        <color rgba="0.61568627450980395466 0.81176470588235294379 0.92941176470588238168 1.0" />
      </material>
    </visual>
    <inertial>
      <origin xyz="-4.9968063063607454179e-09 -7.9242210755682737967e-11 0.0045295192537419875708" rpy="0 0 0" />
      <mass value="0.0010993711450650535313" />
      <inertia ixx="2.9215018435433088662e-08" ixy="2.5903313716658553992e-16" ixz="8.5599808500702612327e-15" iyy="2.9215021540034065086e-08" iyz="1.152688137911182053e-16" izz="4.5709977027671368266e-08" />
    </inertial>
  </link>

  <joint name="right_hip_yaw_drive" type="revolute">
    <origin xyz="0.037000000000001108391 0.037100000000003796607 -0.039500000000000472233" rpy="-1.5707963267950055819 -5.5860638843048369188e-13 -3.8568016358434373564e-13" />
    <parent link="waist_link" />
    <child link="spur_gear_19_teeth_2" />
    <axis xyz="0 0 1" />
    <limit effort="1" velocity="20" lower="-1.4211966766239538806" upper="1.4211966766239538806" />
    <joint_properties friction="0.0" />
  </joint>

  <link name="spur_gear_21_teeth_2">
    <visual>
      <origin xyz="0 0 0" rpy="0 -0 0" />
      <geometry>
        <mesh filename="../assemblies/toddlerbot/meshes/spur_gear_21_teeth_2_visual.stl" />
      </geometry>
      <material name="spur_gear_21_teeth_2_material">
        <color rgba="0.61568627450980395466 0.81176470588235294379 0.92941176470588238168 1.0" />
      </material>
    </visual>
    <inertial>
      <origin xyz="-4.7814841745556497441e-10 1.2610156450278289759e-12 0.002505538138385667371" rpy="0 0 0" />
      <mass value="0.0010063046528317974842" />
      <inertia ixx="3.1842855421068488283e-08" ixy="-3.7656769811774246715e-39" ixz="9.0009329324296215955e-39" iyy="3.1842855426953785697e-08" iyz="-4.3959137544666170172e-38" izz="5.9529380586728034749e-08" />
    </inertial>
  </link>

  <joint name="right_leg_fixed" type="fixed">
    <origin xyz="6.9388939039072283776e-18 0 0.004999999999999997502" rpy="-3.1415926535897784611 1.8262365126862931582e-15 -3.6959871191238926143e-16" />
    <parent link="spur_gear_21_teeth_2" />
    <child link="hip_yaw_link_2" />
    <axis xyz="0 0 1" />
    <limit effort="1" velocity="20" />
    <joint_properties friction="0.0" />
  </joint>

  <joint name="right_hip_yaw_driven" type="revolute">
    <origin xyz="0.036999999999999998168 0.041100000000000011524 -0.019499999999999979156" rpy="-1.5707963267949129893 -1.570796326794896558 0" />
    <parent link="waist_link" />
    <child link="spur_gear_21_teeth_2" />
    <axis xyz="0 0 1" />
    <limit effort="1" velocity="20" lower="-1.570796326794896558" upper="1.570796326794896558" />
    <joint_properties friction="0.0" />
  </joint>

  <joint name="waist_roll" type="revolute">
    <origin xyz="-5.6460850897507995335e-16 -0.022707865260693318316 0.012999999999999227451" rpy="1.57079632679489678 9.8097267041675110992e-15 1.1042194747589474972e-14" />
    <parent link="waist_gears" />
    <child link="waist_link" />
    <axis xyz="0 0 1" />
    <limit effort="1" velocity="20" lower="-0.52359877559829881566" upper="0.52359877559829881566" />
    <joint_properties friction="0.0" />
  </joint>

  <joint name="waist_yaw" type="revolute">
    <origin xyz="3.7643499428696713949e-16 3.9043635660773690095e-17 -3.1571967262777889118e-16" rpy="3.1415926535897917837 -1.9359568790009725236e-16 -1.57079632679489678" />
    <parent link="torso" />
    <child link="waist_gears" />
    <axis xyz="0 0 1" />
    <limit effort="1" velocity="20" lower="-1.570796326794896558" upper="1.570796326794896558" />
    <joint_properties friction="0.0" />
  </joint>

  <joint name="left_sho_pitch" type="revolute">
    <origin xyz="-0.0029999999999997528644 0.062000000000000436706 0.10523651076281793915" rpy="-1.5707963267948983344 8.0214786879603172751e-16 1.532501625198463655e-15" />
    <parent link="torso" />
    <child link="sho_pitch_link" />
    <axis xyz="0 0 1" />
    <limit effort="1" velocity="20" lower="-1.570796326794896558" upper="1.570796326794896558" />
    <joint_properties friction="0.0" />
  </joint>

  <joint name="right_sho_pitch" type="revolute">
    <origin xyz="-0.0030000000000001275646 -0.061999999999999985678 0.10523651076281731465" rpy="-1.570796326794896558 -6.5632891966464542239e-16 -3.1415926535897917837" />
    <parent link="torso" />
    <child link="sho_pitch_link_2" />
    <axis xyz="0 0 1" />
    <limit effort="1" velocity="20" lower="-1.570796326794896558" upper="1.570796326794896558" />
    <joint_properties friction="0.0" />
  </joint>


  <link name="hip_yaw_link">
    <visual>
      <origin xyz="0 0 0" rpy="0 -0 0" />
      <geometry>
        <mesh filename="../assemblies/left_leg_XM430/meshes/left_hip_yaw_link_visual.stl" />
      </geometry>
      <material name="hip_yaw_link_material">
        <color rgba="0.61568627450980395466 0.81176470588235294379 0.92941176470588238168 1.0" />
      </material>
    </visual>
    <inertial>
      <origin xyz="5.8080264323683266564e-19 -4.9051898562264800195e-19 -0.0098390489054829086829" rpy="0 0 0" />
      <mass value="0.017999999999999995171" />
      <inertia ixx="2.638503389144253662e-06" ixy="0" ixz="0" iyy="7.6596731957046890345e-06" iyz="0" izz="7.7220708070894769837e-06" />
    </inertial>
  </link>

  <link name="hip_roll_link">
    <visual>
      <origin xyz="0 0 0" rpy="0 -0 0" />
      <geometry>
        <mesh filename="../assemblies/left_leg_XM430/meshes/left_hip_roll_link_visual.stl" />
      </geometry>
      <material name="hip_roll_link_material">
        <color rgba="0.51698661238356047321 0.50347815951093488618 0.49050589017722012741 1.0" />
      </material>
    </visual>
    <collision>
      <origin xyz="0 0 0" rpy="0 -0 0" />
      <geometry>
        <mesh filename="collisions/left_hip_roll_link_collision.stl" />
      </geometry>
    </collision>
    <inertial>
      <origin xyz="-0.011999849582186344205 -0.00049598090793799955514 -0.018504111838598794743" rpy="0 0 0" />
      <mass value="0.11059999999836234164" />
      <inertia ixx="2.2818802599019123213e-05" ixy="-4.6520143286798432356e-08" ixz="-4.6888548260596792068e-08" iyy="3.0871632082339373363e-05" iyz="-5.7477343899716644859e-07" izz="3.0871666424470007293e-05" />
    </inertial>
  </link>

  <link name="left_hip_pitch_link_xm430">
    <visual>
      <origin xyz="0 0 0" rpy="0 -0 0" />
      <geometry>
        <mesh filename="../assemblies/left_leg_XM430/meshes/left_hip_pitch_link_xm430_visual.stl" />
      </geometry>
      <material name="left_hip_pitch_link_xm430_material">
        <color rgba="0.87072221357329560032 0.72641010956094276274 0.24785169615220697947 1.0" />
      </material>
    </visual>
    <collision>
      <origin xyz="0 0 0" rpy="0 -0 0" />
      <geometry>
        <mesh filename="collisions/left_hip_pitch_link_xm430_collision.stl" />
      </geometry>
    </collision>
    <inertial>
      <origin xyz="-0.000757292141553150399 -0.050714785675264828502 -0.012656155119959908856" rpy="0 0 0" />
      <mass value="0.1148009013503056841" />
      <inertia ixx="6.6072773889429997109e-05" ixy="-4.6080149277727730521e-07" ixz="-1.8170739115308356578e-07" iyy="2.3633638685369523855e-05" iyz="1.4125253925343137003e-06" izz="6.2221728804333370109e-05" />
    </inertial>
  </link>

  <link name="left_calf_link">
    <visual>
      <origin xyz="0 0 0" rpy="0 -0 0" />
      <geometry>
        <mesh filename="../assemblies/left_leg_XM430/meshes/left_calf_link_visual.stl" />
      </geometry>
      <material name="left_calf_link_material">
        <color rgba="0.616547745550632742 0.7175754134247219751 0.74372657889541438081 1.0" />
      </material>
    </visual>
    <collision>
      <origin xyz="0 0 0" rpy="0 -0 0" />
      <geometry>
        <mesh filename="collisions/left_calf_link_collision.stl" />
      </geometry>
    </collision>
    <inertial>
      <origin xyz="0.0016330556739555524004 -0.050045528174708642233 -0.0099079425125447578154" rpy="0 0 0" />
      <mass value="0.086799999986183581924" />
      <inertia ixx="4.9509459873200328036e-05" ixy="3.6911110041724866245e-06" ixz="4.181905803998407918e-07" iyy="1.5531229037964085102e-05" iyz="4.6309763568422438199e-07" izz="5.3138661991212957482e-05" />
    </inertial>
  </link>

  <link name="bearing_683">
    <visual>
      <origin xyz="0 0 0" rpy="0 -0 0" />
      <geometry>
        <mesh filename="../assemblies/left_leg_XM430/meshes/left_bearing_683_visual.stl" />
      </geometry>
      <material name="bearing_683_material">
        <color rgba="0.64705882352941179736 0.64705882352941179736 0.64705882352941179736 1.0" />
      </material>
    </visual>
    <inertial>
      <origin xyz="1.0732094295242497084e-19 -2.4186774283160283989e-19 -0.0015500000000000003792" rpy="0 0 0" />
      <mass value="0.00048694686130641793437" />
      <inertia ixx="2.1551456503319879113e-09" ixy="2.3666528901256796113e-27" ixz="2.0889236366122119332e-38" iyy="2.1551456503319891521e-09" iyz="1.3744560845328921415e-38" izz="3.5303647444715305817e-09" />
    </inertial>
  </link>

  <joint name="left_knee_front_rev_2" type="revolute">
    <origin xyz="-0.0057402514854770240668 0.013858192987668910279 -0.026200000000000563116" rpy="2.0453876360821841634e-16 7.1068359470475064937e-16 1.5765314753541341819" />
    <parent link="left_calf_link" />
    <child link="bearing_683" />
    <axis xyz="0 0 1" />
    <limit effort="1" velocity="20" lower="-6.283185307179586232" upper="6.283185307179586232" />
    <joint_properties friction="0.0" />
  </joint>

  <link name="bearing_683_2">
    <visual>
      <origin xyz="0 0 0" rpy="0 -0 0" />
      <geometry>
        <mesh filename="../assemblies/left_leg_XM430/meshes/left_bearing_683_2_visual.stl" />
      </geometry>
      <material name="bearing_683_2_material">
        <color rgba="0.64705882352941179736 0.64705882352941179736 0.64705882352941179736 1.0" />
      </material>
    </visual>
    <inertial>
      <origin xyz="1.0732094295248846635e-19 -2.4186774283160375471e-19 -0.0015500000000000003792" rpy="0 0 0" />
      <mass value="0.00048694686130641793437" />
      <inertia ixx="2.1551456503319887385e-09" ixy="-1.3855900387721121507e-27" ixz="-1.9257410757015346214e-37" iyy="2.1551456503319874977e-09" iyz="-2.8124792185573659681e-39" izz="3.5303647444715305817e-09" />
    </inertial>
  </link>

  <joint name="left_knee_back_rev_2" type="revolute">
    <origin xyz="0.0057402514854760517543 -0.013858192987669437635 -0.026200000000000216172" rpy="2.8877467674261435159e-16 -6.2660216643685709814e-15 1.5765686202203079702" />
    <parent link="left_calf_link" />
    <child link="bearing_683_2" />
    <axis xyz="0 0 1" />
    <limit effort="1" velocity="20" lower="-6.283185307179586232" upper="6.283185307179586232" />
    <joint_properties friction="0.0" />
  </joint>

  <link name="ank_pitch_link">
    <visual>
      <origin xyz="0 0 0" rpy="0 -0 0" />
      <geometry>
        <mesh filename="../assemblies/left_leg_XM430/meshes/left_ank_pitch_link_visual.stl" />
      </geometry>
      <material name="ank_pitch_link_material">
        <color rgba="0.63189161126160264814 0.7266866879354088038 0.78356373393969258601 1.0" />
      </material>
    </visual>
    <inertial>
      <origin xyz="0.00059528282565903347691 -4.0269677046895822506e-08 7.7616091227946370715e-08" rpy="0 0 0" />
      <mass value="0.0042238381753791614387" />
      <inertia ixx="3.9782741364681224752e-07" ixy="-1.6834347544690341436e-13" ixz="2.09191870411591794e-14" iyy="4.3705254067426624596e-07" iyz="-1.6428821654626687343e-12" izz="8.8858574534620810897e-08" />
    </inertial>
  </link>

  <link name="ank_roll_link">
    <visual>
      <origin xyz="0 0 0" rpy="0 -0 0" />
      <geometry>
        <mesh filename="../assemblies/left_leg_XM430/meshes/left_ank_roll_link_visual.stl" />
      </geometry>
      <material name="ank_roll_link_material">
        <color rgba="0.61568627450980395466 0.81176470588235283277 0.9294117647058824927 1.0" />
      </material>
    </visual>
    <inertial>
      <origin xyz="-3.3748977756107212112e-09 0.016071733707723686452 -0.0096236810250137812262" rpy="0 0 0" />
      <mass value="0.010899999999999999967" />
      <inertia ixx="2.6058536057764963368e-06" ixy="-5.4054321088170026859e-13" ixz="6.0692549095964215885e-13" iyy="2.5928781338360456246e-06" iyz="3.935983967928241445e-07" izz="1.6179884211196010928e-06" />
    </inertial>
  </link>

  <link name="ank_rr_link">
    <visual>
      <origin xyz="0 0 0" rpy="0 -0 0" />
      <geometry>
        <mesh filename="../assemblies/left_leg_XM430/meshes/left_ank_rr_link_visual.stl" />
      </geometry>
      <material name="ank_rr_link_material">
        <color rgba="0.61568627450980395466 0.81176470588235294379 0.92941176470588238168 1.0" />
      </material>
    </visual>
    <inertial>
      <origin xyz="-4.524961096060613544e-05 0.00630964298363145739 -2.2196875918440557794e-19" rpy="0 0 0" />
      <mass value="0.0014499999999999999001" />
      <inertia ixx="2.9739579267716143416e-08" ixy="2.4213146797977906837e-10" ixz="3.5523394884450959e-14" iyy="2.7430027724071957055e-08" iyz="-9.899747119770708535e-32" izz="4.2921949116163665819e-08" />
    </inertial>
  </link>

  <link name="ank_motor_rod_long">
    <visual>
      <origin xyz="0 0 0" rpy="0 -0 0" />
      <geometry>
        <mesh filename="../assemblies/left_leg_XM430/meshes/left_ank_motor_rod_long_visual.stl" />
      </geometry>
      <material name="ank_motor_rod_long_material">
        <color rgba="0.63549975559783222767 0.70774393017020453822 0.75109043491362792455 1.0" />
      </material>
    </visual>
    <inertial>
      <origin xyz="2.4855088958918268157e-10 0.034559019974062257785 0.00093851704878453623849" rpy="0 0 0" />
      <mass value="0.0021712857268636710437" />
      <inertia ixx="8.5350290058000400818e-07" ixy="1.4884244671507143804e-14" ixz="4.5749525025589375877e-11" iyy="1.3237321792739536015e-08" iyz="-4.3668910960857659783e-09" izz="8.5812217519451779337e-07" />
    </inertial>
  </link>

  <joint name="left_ank_long_rev_2" type="revolute">
    <origin xyz="2.4286128663675299322e-17 0.0099999999999992872368 1.3947176746853529039e-15" rpy="-1.5707963267948974462 1.3320366994105963254 -1.5707963267949054398" />
    <parent link="ank_rr_link" />
    <child link="ank_motor_rod_long" />
    <axis xyz="0 0 1" />
    <limit effort="1" velocity="20" lower="-1.570796326794896558" upper="1.570796326794896558" />
    <joint_properties friction="0.0" />
  </joint>

  <joint name="left_ank_long_rev_1" type="revolute">
    <origin xyz="-0.018000000000000015987 0.01599999999999926481 -0.020600000000001391504" rpy="-2.876394309884160705e-16 1.6317439732762683578e-16 3.1233695685467286474" />
    <parent link="ank_roll_link" />
    <child link="ank_rr_link" />
    <axis xyz="0 0 1" />
    <limit effort="1" velocity="20" lower="-1.570796326794896558" upper="1.570796326794896558" />
    <joint_properties friction="0.0" />
  </joint>

  <link name="ank_rr_link_2">
    <visual>
      <origin xyz="0 0 0" rpy="0 -0 0" />
      <geometry>
        <mesh filename="../assemblies/left_leg_XM430/meshes/left_ank_rr_link_2_visual.stl" />
      </geometry>
      <material name="ank_rr_link_2_material">
        <color rgba="0.61568627450980395466 0.81176470588235294379 0.92941176470588238168 1.0" />
      </material>
    </visual>
    <inertial>
      <origin xyz="-4.5249610960599182994e-05 -0.0063096429836314027462 3.6914157111383635934e-18" rpy="0 0 0" />
      <mass value="0.0014499999999999999001" />
      <inertia ixx="2.9739579267716150033e-08" ixy="-2.4213146797977927516e-10" ixz="-3.552339488445096531e-14" iyy="2.7430027724071957055e-08" iyz="-6.0455732447571649016e-32" izz="4.2921949116163665819e-08" />
    </inertial>
  </link>

  <link name="ank_motor_rod_short">
    <visual>
      <origin xyz="0 0 0" rpy="0 -0 0" />
      <geometry>
        <mesh filename="../assemblies/left_leg_XM430/meshes/left_ank_motor_rod_short_visual.stl" />
      </geometry>
      <material name="ank_motor_rod_short_material">
        <color rgba="0.41222606689734719865 0.58339100346020755783 0.8110726643598615837 1.0" />
      </material>
    </visual>
    <inertial>
      <origin xyz="2.6038941310109512801e-10 0.023830465465870951519 0.00090403506359622634852" rpy="0 0 0" />
      <mass value="0.0017000000000000005558" />
      <inertia ixx="3.3153416252670235948e-07" ixy="8.7419768621883457893e-15" ixz="4.5749941567727763831e-11" iyy="1.0947363610305772565e-08" iyz="-3.5863098646405767e-09" izz="3.3621340447865384922e-07" />
    </inertial>
  </link>

  <joint name="left_ank_short_rev_2" type="revolute">
    <origin xyz="0 -0.0099999999999998978595 0" rpy="-1.570796326794896558 -1.2119133862909823307 -1.570796326794896336" />
    <parent link="ank_rr_link_2" />
    <child link="ank_motor_rod_short" />
    <axis xyz="0 0 1" />
    <limit effort="1" velocity="20" lower="-1.570796326794896558" upper="1.570796326794896558" />
    <joint_properties friction="0.0" />
  </joint>

  <joint name="left_ank_short_rev_1" type="revolute">
    <origin xyz="0.018000000000000002109 0.015999999999999986455 -0.020600000000000010664" rpy="4.2172831995673088897e-16 -4.4678623027074358005e-17 0.026118548507422217203" />
    <parent link="ank_roll_link" />
    <child link="ank_rr_link_2" />
    <axis xyz="0 0 1" />
    <limit effort="1" velocity="20" lower="-1.570796326794896558" upper="1.570796326794896558" />
    <joint_properties friction="0.0" />
  </joint>

  <link name="left_sole_link">
    <visual>
      <origin xyz="0 0 0" rpy="0 -0 0" />
      <geometry>
        <mesh filename="../assemblies/left_leg_XM430/meshes/left_sole_link_visual.stl" />
      </geometry>
      <material name="left_sole_link_material">
        <color rgba="0.61568627450980384364 0.81176470588235294379 0.92941176470588238168 1.0" />
      </material>
    </visual>
    <collision>
      <origin xyz="0 0 0" rpy="0 -0 0" />
      <geometry>
        <mesh filename="../assemblies/left_leg_XM430/meshes/left_sole_link_collision.stl" />
      </geometry>
    </collision>
    <inertial>
      <origin xyz="-0.028268455053070316862 -2.3408773987386383187e-07 -0.010206307024274944434" rpy="0 0 0" />
      <mass value="0.013899999999999997427" />
      <inertia ixx="1.3160509347109557101e-06" ixy="3.0094161238153437731e-12" ixz="-2.3741900688425285732e-07" iyy="1.3575574544571525394e-05" iyz="-6.7706521655071861067e-12" izz="1.4673603612256130453e-05" />
    </inertial>
  </link>

  <joint name="left_sole" type="fixed">
    <origin xyz="-9.1072982488782372457e-18 0.024999999999999994449 -0.022600000000000002032" rpy="1.570796326794896558 1.570796326794896336 0" />
    <parent link="ank_roll_link" />
    <child link="left_sole_link" />
    <axis xyz="0 0 1" />
    <limit effort="1" velocity="20" />
    <joint_properties friction="0.0" />
  </joint>

  <joint name="left_ank_roll" type="revolute">
    <origin xyz="0.0015000000000000002481 2.7755575615628913511e-17 3.2742905609062233907e-17" rpy="9.9573127520767875392e-16 1.570796326794891673 0" />
    <parent link="ank_pitch_link" />
    <child link="ank_roll_link" />
    <axis xyz="0 0 1" />
    <limit effort="1" velocity="20" lower="-0.785398163397448279" upper="0.785398163397448279" />
    <joint_properties friction="0.0" />
  </joint>

  <joint name="left_ank_pitch" type="revolute">
    <origin xyz="1.5349482163618395221e-15 -0.099999999999999339417 -0.01039999999999923451" rpy="1.0427422814103565708e-14 3.7115492970717391096e-15 3.1415926535897922278" />
    <parent link="left_calf_link" />
    <child link="ank_pitch_link" />
    <axis xyz="0 0 1" />
    <limit effort="1" velocity="20" lower="-1.0471975511965976313" upper="0.785398163397448279" />
    <joint_properties friction="0.0" />
  </joint>

  <link name="ank_motor_arm">
    <visual>
      <origin xyz="0 0 0" rpy="0 -0 0" />
      <geometry>
        <mesh filename="../assemblies/left_leg_XM430/meshes/left_ank_motor_arm_visual.stl" />
      </geometry>
      <material name="ank_motor_arm_material">
        <color rgba="0.62517751827980905244 0.70593642422614044651 0.75978993426662777555 1.0" />
      </material>
    </visual>
    <inertial>
      <origin xyz="0.014511489101591690601 -1.1545580663345018721e-17 0.0040925443765950624692" rpy="0 0 0" />
      <mass value="0.0020595846677894939954" />
      <inertia ixx="2.7591836756521931927e-08" ixy="-2.4230143640013837058e-22" ixz="-3.0270788206594868355e-08" iyy="1.6138599216238429997e-07" iyz="-4.6294410303784278107e-23" izz="1.643783676501628224e-07" />
    </inertial>
  </link>

  <joint name="left_ank_act_1" type="revolute">
    <origin xyz="0.013500000000001635692 -0.044499999999992628785 0.0040000000000077733792" rpy="-5.7683923736819409867e-13 -7.5455504046046331278e-14 -0.21173394130254355461" />
    <parent link="left_calf_link" />
    <child link="ank_motor_arm" />
    <axis xyz="0 0 1" />
    <limit effort="1" velocity="20" lower="-1.3089969389957472057" upper="1.3089969389957472057" />
    <joint_properties friction="0.0" />
  </joint>

  <link name="ank_motor_arm_2">
    <visual>
      <origin xyz="0 0 0" rpy="0 -0 0" />
      <geometry>
        <mesh filename="../assemblies/left_leg_XM430/meshes/left_ank_motor_arm_2_visual.stl" />
      </geometry>
      <material name="ank_motor_arm_2_material">
        <color rgba="0.62517751827980905244 0.70593642422614044651 0.75978993426662777555 1.0" />
      </material>
    </visual>
    <inertial>
      <origin xyz="0.014511489101591680193 5.7606878752486150639e-19 0.0040925443765950728775" rpy="0 0 0" />
      <mass value="0.0020595846677894939954" />
      <inertia ixx="2.7591836756521756564e-08" ixy="-4.9660689707783155375e-23" ixz="-3.0270788206594901442e-08" iyy="1.6138599216238395586e-07" iyz="7.8266102013053568785e-24" izz="1.643783676501628224e-07" />
    </inertial>
  </link>

  <joint name="left_ank_act_2" type="revolute">
    <origin xyz="0.013500000000005811171 -0.064499999999988344435 -0.024800000000003163264" rpy="-3.1415926535893312632 1.9218128864630526701e-14 -0.22995607267384915451" />
    <parent link="left_calf_link" />
    <child link="ank_motor_arm_2" />
    <axis xyz="0 0 1" />
    <limit effort="1" velocity="20" lower="-1.3089969389957472057" upper="1.3089969389957472057" />
    <joint_properties friction="0.0" />
  </joint>

  <joint name="left_knee_pitch" type="revolute">
    <origin xyz="3.1436708451941898537e-17 -0.096000000000000001998 -0.0092000000000000154571" rpy="5.2388648972145238601e-16 -5.3048676098335846568e-16 -5.5511151227572361317e-17" />
    <parent link="left_hip_pitch_link_xm430" />
    <child link="left_calf_link" />
    <axis xyz="0 0 1" />
    <limit effort="1" velocity="20" lower="0" upper="1.9198621771937625091" />
    <joint_properties friction="0.0" />
  </joint>

  <link name="xm430_plate">
    <visual>
      <origin xyz="0 0 0" rpy="0 -0 0" />
      <geometry>
        <mesh filename="../assemblies/left_leg_XM430/meshes/left_xm430_plate_visual.stl" />
      </geometry>
      <material name="xm430_plate_material">
        <color rgba="0.61568627450980395466 0.81176470588235294379 0.92941176470588227065 1.0" />
      </material>
    </visual>
    <inertial>
      <origin xyz="3.3016001651175991011e-18 1.6874661728058342978e-18 -0.0024039046431217955119" rpy="0 0 0" />
      <mass value="0.0026999999999999997093" />
      <inertia ixx="1.2933116645363405536e-07" ixy="-6.8936588702566387474e-08" ixz="5.4735536363229107292e-35" iyy="2.672043438587668303e-07" iyz="-6.5325103416929007063e-36" izz="3.8533537562751428679e-07" />
    </inertial>
  </link>

  <link name="knee_rod">
    <visual>
      <origin xyz="0 0 0" rpy="0 -0 0" />
      <geometry>
        <mesh filename="../assemblies/left_leg_XM430/meshes/left_knee_rod_visual.stl" />
      </geometry>
      <material name="knee_rod_material">
        <color rgba="0.62051618944235198416 0.78640765248647581664 0.88594253031295022716 1.0" />
      </material>
    </visual>
    <inertial>
      <origin xyz="0.014594549254227701454 -4.0495174182604799708e-05 -0.0015996227373190293787" rpy="0 0 0" />
      <mass value="0.0031629468613064179276" />
      <inertia ixx="2.5896066719679952409e-08" ixy="3.4015849028409630471e-10" ixz="4.1682980135095616913e-10" iyy="6.015325433306769779e-07" iyz="-1.1565684637535341676e-12" izz="6.2266854577246018566e-07" />
    </inertial>
  </link>

  <joint name="left_knee_front_rev_1" type="revolute">
    <origin xyz="0.013858192987669312735 0.0057402514854763336469 -0.0049999999999999836242" rpy="-9.4192987622433650731e-16 3.8593656109062736187e-16 -3.1358575050305752541" />
    <parent link="xm430_plate" />
    <child link="knee_rod" />
    <axis xyz="0 0 1" />
    <limit effort="1" velocity="20" lower="-6.283185307179586232" upper="6.283185307179586232" />
    <joint_properties friction="0.0" />
  </joint>

  <link name="knee_rod_2">
    <visual>
      <origin xyz="0 0 0" rpy="0 -0 0" />
      <geometry>
        <mesh filename="../assemblies/left_leg_XM430/meshes/left_knee_rod_2_visual.stl" />
      </geometry>
      <material name="knee_rod_2_material">
        <color rgba="0.62051618944235198416 0.78640765248647581664 0.88594253031295022716 1.0" />
      </material>
    </visual>
    <inertial>
      <origin xyz="0.014594547729902917002 -4.1579390108021769244e-05 -0.0015996227373185551487" rpy="0 0 0" />
      <mass value="0.0031629468613064179276" />
      <inertia ixx="2.5896117936396405481e-08" ixy="3.4926584154272069241e-10" ixz="4.1682975780794621276e-10" iyy="6.0153251772212437219e-07" iyz="-1.1875343734383760925e-12" izz="6.2266857138059499237e-07" />
    </inertial>
  </link>

  <joint name="left_knee_back_rev_1" type="revolute">
    <origin xyz="-0.013858192987669284979 -0.0057402514854763449226 -0.0050000000000000009714" rpy="-1.240696991414760872e-15 6.8873592505729608146e-15 -3.1358203601644016878" />
    <parent link="xm430_plate" />
    <child link="knee_rod_2" />
    <axis xyz="0 0 1" />
    <limit effort="1" velocity="20" lower="-6.283185307179586232" upper="6.283185307179586232" />
    <joint_properties friction="0.0" />
  </joint>

  <joint name="left_knee_act" type="revolute">
    <origin xyz="-0.00015000000000007682969 -0.061499999999999728495 -0.030399999999999843814" rpy="-1.3864621477766001324e-15 9.2520451941214004081e-17 1.5707963267949205388" />
    <parent link="left_hip_pitch_link_xm430" />
    <child link="xm430_plate" />
    <axis xyz="0 0 1" />
    <limit effort="1" velocity="20" lower="0" upper="1.9198621771937625091" />
    <joint_properties friction="0.0" />
  </joint>

  <joint name="left_hip_pitch" type="revolute">
    <origin xyz="-0.024000000716155701214 -0.019000000152439879691 -0.019000000152457872243" rpy="1.570796326795379283 1.5707963267945606045 0" />
    <parent link="hip_roll_link" />
    <child link="left_hip_pitch_link_xm430" />
    <axis xyz="0 0 1" />
    <limit effort="1" velocity="20" lower="-1.570796326794896558" upper="1.570796326794896558" />
    <joint_properties friction="0.0" />
  </joint>

  <joint name="left_hip_roll" type="revolute">
    <origin xyz="0.018999999999999999528 -3.3500438890366171686e-18 -0.026000000000000002276" rpy="3.141592653589793116 -1.5707963267948930053 0" />
    <parent link="hip_yaw_link" />
    <child link="hip_roll_link" />
    <axis xyz="0 0 1" />
    <limit effort="1" velocity="20" lower="-0.785398163397448279" upper="1.570796326794896558" />
    <joint_properties friction="0.0" />
  </joint>


  <link name="hip_yaw_link_2">
    <visual>
      <origin xyz="0 0 0" rpy="0 -0 0" />
      <geometry>
        <mesh filename="../assemblies/right_leg_XM430/meshes/right_hip_yaw_link_visual.stl" />
      </geometry>
      <material name="hip_yaw_link_material">
        <color rgba="0.61568627450980395466 0.81176470588235294379 0.92941176470588238168 1.0" />
      </material>
    </visual>
    <inertial>
      <origin xyz="-5.8080264323683266564e-19 4.9051898562264800195e-19 -0.0098390489054829086829" rpy="0 0 0" />
      <mass value="0.017999999999999995171" />
      <inertia ixx="2.638503389144253662e-06" ixy="0" ixz="0" iyy="7.6596731957046890345e-06" iyz="0" izz="7.7220708070894769837e-06" />
    </inertial>
  </link>

  <link name="hip_roll_link_2">
    <visual>
      <origin xyz="0 0 0" rpy="0 -0 0" />
      <geometry>
        <mesh filename="../assemblies/right_leg_XM430/meshes/right_hip_roll_link_visual.stl" />
      </geometry>
      <material name="hip_roll_link_material">
        <color rgba="0.51698661238356047321 0.50347815951093488618 0.49050589017722012741 1.0" />
      </material>
    </visual>
    <collision>
      <origin xyz="0 0 0" rpy="0 -0 0" />
      <geometry>
        <mesh filename="collisions/right_hip_roll_link_collision.stl" />
      </geometry>
    </collision>
    <inertial>
      <origin xyz="-0.011999849582182775878 -0.00049598090794319277513 -0.018504111838597465944" rpy="0 0 0" />
      <mass value="0.11059999999836234164" />
      <inertia ixx="2.2818802599018211805e-05" ixy="-4.6520143286279465858e-08" ixz="-4.6888548259070895301e-08" iyy="3.0871632082338065545e-05" iyz="-5.7477343899720890612e-07" izz="3.0871666424467947309e-05" />
    </inertial>
  </link>

  <link name="right_hip_pitch_link_xm430">
    <visual>
      <origin xyz="0 0 0" rpy="0 -0 0" />
      <geometry>
        <mesh filename="../assemblies/right_leg_XM430/meshes/right_hip_pitch_link_xm430_visual.stl" />
      </geometry>
      <material name="right_hip_pitch_link_xm430_material">
        <color rgba="0.87072221357329571134 0.72641010956094276274 0.24785169615220697947 1.0" />
      </material>
    </visual>
    <collision>
      <origin xyz="0 0 0" rpy="0 -0 0" />
      <geometry>
        <mesh filename="collisions/right_hip_pitch_link_xm430_collision.stl" />
      </geometry>
    </collision>
    <inertial>
      <origin xyz="0.00075715881371283015253 -0.050714784778880722671 -0.01265615362012198486" rpy="0 0 0" />
      <mass value="0.11480090135030567022" />
      <inertia ixx="6.607278648938489003e-05" ixy="4.6010682906021323661e-07" ixz="1.8171597853315161109e-07" iyy="2.3633665181581639092e-05" iyz="1.4125296519934719351e-06" izz="6.2221763055418004632e-05" />
    </inertial>
  </link>

  <link name="right_calf_link">
    <visual>
      <origin xyz="0 0 0" rpy="0 -0 0" />
      <geometry>
        <mesh filename="../assemblies/right_leg_XM430/meshes/right_calf_link_visual.stl" />
      </geometry>
      <material name="right_calf_link_material">
        <color rgba="0.616547745550632742 0.71757541342472208612 0.74372657889541449183 1.0" />
      </material>
    </visual>
    <collision>
      <origin xyz="0 0 0" rpy="0 -0 0" />
      <geometry>
        <mesh filename="collisions/right_calf_link_collision.stl" />
      </geometry>
    </collision>
    <inertial>
      <origin xyz="0.0016330560292394452008 0.050045526484800137434 -0.0099079425237753142308" rpy="0 0 0" />
      <mass value="0.086799999986183568046" />
      <inertia ixx="4.9519076588877084118e-05" ixy="-3.6911123877145746222e-06" ixz="4.1819052274331339443e-07" iyy="1.5531229308366346475e-05" iyz="-4.6072292079354209195e-07" izz="5.3148278062059841286e-05" />
    </inertial>
  </link>

  <link name="bearing_683_3">
    <visual>
      <origin xyz="0 0 0" rpy="0 -0 0" />
      <geometry>
        <mesh filename="../assemblies/right_leg_XM430/meshes/right_bearing_683_visual.stl" />
      </geometry>
      <material name="bearing_683_material">
        <color rgba="0.64705882352941179736 0.64705882352941179736 0.64705882352941179736 1.0" />
      </material>
    </visual>
    <inertial>
      <origin xyz="1.0732094295239739393e-19 2.4186774283161266214e-19 -0.0015500000000000016803" rpy="0 0 0" />
      <mass value="0.00048694686130641793437" />
      <inertia ixx="2.1551456503319895657e-09" ixy="2.3175595566406579266e-27" ixz="2.4896541890902438623e-38" iyy="2.1551456503319883249e-09" iyz="5.4460298433450471486e-38" izz="3.5303647444715305817e-09" />
    </inertial>
  </link>

  <joint name="right_knee_front_rev_2" type="revolute">
    <origin xyz="-0.0057402514854763431879 -0.013858192987669382124 -0.026199999999999987188" rpy="4.9452523641215521159e-15 -3.1674356695639584582e-16 3.1359672412492258786" />
    <parent link="right_calf_link" />
    <child link="bearing_683_3" />
    <axis xyz="0 0 1" />
    <limit effort="1" velocity="20" lower="-6.283185307179586232" upper="6.283185307179586232" />
    <joint_properties friction="0.0" />
  </joint>

  <link name="bearing_683_4">
    <visual>
      <origin xyz="0 0 0" rpy="0 -0 0" />
      <geometry>
        <mesh filename="../assemblies/right_leg_XM430/meshes/right_bearing_683_2_visual.stl" />
      </geometry>
      <material name="bearing_683_2_material">
        <color rgba="0.64705882352941179736 0.64705882352941179736 0.64705882352941179736 1.0" />
      </material>
    </visual>
    <inertial>
      <origin xyz="1.0732094295240485691e-19 2.418677428316700067e-19 -0.0015499999999999977771" rpy="0 0 0" />
      <mass value="0.00048694686130641793437" />
      <inertia ixx="2.1551456503319887385e-09" ixy="9.4016331328971133286e-28" ixz="6.4941734545542371767e-38" iyy="2.1551456503319874977e-09" iyz="1.5195108877220808957e-37" izz="3.5303647444715322361e-09" />
    </inertial>
  </link>

  <joint name="right_knee_back_rev_2" type="revolute">
    <origin xyz="0.0057402514854763692087 0.013858192987669243346 -0.026199999999999990657" rpy="-2.5000942521723397481e-14 5.2473395102998583317e-16 3.1360672427763174319" />
    <parent link="right_calf_link" />
    <child link="bearing_683_4" />
    <axis xyz="0 0 1" />
    <limit effort="1" velocity="20" lower="-6.283185307179586232" upper="6.283185307179586232" />
    <joint_properties friction="0.0" />
  </joint>

  <link name="ank_pitch_link_2">
    <visual>
      <origin xyz="0 0 0" rpy="0 -0 0" />
      <geometry>
        <mesh filename="../assemblies/right_leg_XM430/meshes/right_ank_pitch_link_visual.stl" />
      </geometry>
      <material name="ank_pitch_link_material">
        <color rgba="0.63189161126160264814 0.7266866879354088038 0.78356373393969258601 1.0" />
      </material>
    </visual>
    <inertial>
      <origin xyz="0.00059528282565814453955 4.0269684199612070023e-08 -7.7616092347959137447e-08" rpy="0 0 0" />
      <mass value="0.0042238381753791614387" />
      <inertia ixx="3.9782741364678847766e-07" ixy="1.6834347545013802175e-13" ixz="-2.0919187193369323082e-14" iyy="4.3705254067423273522e-07" iyz="-1.6428822295928359723e-12" izz="8.8858574534611122958e-08" />
    </inertial>
  </link>

  <link name="ank_roll_link_2">
    <visual>
      <origin xyz="0 0 0" rpy="0 -0 0" />
      <geometry>
        <mesh filename="../assemblies/right_leg_XM430/meshes/right_ank_roll_link_visual.stl" />
      </geometry>
      <material name="ank_roll_link_material">
        <color rgba="0.61568627450980395466 0.81176470588235283277 0.9294117647058824927 1.0" />
      </material>
    </visual>
    <inertial>
      <origin xyz="-3.3748977755022993396e-09 0.016071733707723714207 -0.0096236810250137812262" rpy="0 0 0" />
      <mass value="0.010899999999999999967" />
      <inertia ixx="2.6058536057764954897e-06" ixy="-5.4054321088170016762e-13" ixz="6.0692549095964205787e-13" iyy="2.5928781338360456246e-06" iyz="3.935983967928241445e-07" izz="1.6179884211196010928e-06" />
    </inertial>
  </link>

  <link name="ank_rr_link_3">
    <visual>
      <origin xyz="0 0 0" rpy="0 -0 0" />
      <geometry>
        <mesh filename="../assemblies/right_leg_XM430/meshes/right_ank_rr_link_visual.stl" />
      </geometry>
      <material name="ank_rr_link_material">
        <color rgba="0.61568627450980395466 0.81176470588235294379 0.92941176470588238168 1.0" />
      </material>
    </visual>
    <inertial>
      <origin xyz="-4.5249610960602665993e-05 -0.0063096429836314027462 2.2196875918475768608e-19" rpy="0 0 0" />
      <mass value="0.0014499999999999999001" />
      <inertia ixx="2.9739579267716163268e-08" ixy="-2.4213146797977932686e-10" ixz="-3.5523394884450971621e-14" iyy="2.7430027724071957055e-08" iyz="4.4497301223675069461e-32" izz="4.2921949116163665819e-08" />
    </inertial>
  </link>

  <link name="ank_motor_rod_long_2">
    <visual>
      <origin xyz="0 0 0" rpy="0 -0 0" />
      <geometry>
        <mesh filename="../assemblies/right_leg_XM430/meshes/right_ank_motor_rod_long_visual.stl" />
      </geometry>
      <material name="ank_motor_rod_long_material">
        <color rgba="0.63549975559783222767 0.70774393017020453822 0.75109043491362792455 1.0" />
      </material>
    </visual>
    <inertial>
      <origin xyz="2.4855090154543866352e-10 0.034559019974062320235 0.00093851704878454577947" rpy="0 0 0" />
      <mass value="0.0021712857268636710437" />
      <inertia ixx="8.5350290058000443169e-07" ixy="1.4884243995416656531e-14" ixz="4.5749525025468381326e-11" iyy="1.3237321792739560831e-08" iyz="-4.3668910960860323305e-09" izz="8.5812217519451789925e-07" />
    </inertial>
  </link>

  <joint name="right_ank_long_rev_2" type="revolute">
    <origin xyz="-3.4694469519536141888e-18 -0.0099999999999999533706 -6.9388939039072283776e-18" rpy="-1.570796326794896558 -1.3320366994106251912 -1.5707963267948779063" />
    <parent link="ank_rr_link_3" />
    <child link="ank_motor_rod_long_2" />
    <axis xyz="0 0 1" />
    <limit effort="1" velocity="20" lower="-1.570796326794896558" upper="1.570796326794896558" />
    <joint_properties friction="0.0" />
  </joint>

  <joint name="right_ank_long_rev_1" type="revolute">
    <origin xyz="0.017999999999999995171 0.016000000000000014211 -0.020600000000000007194" rpy="2.4036779374278231896e-16 5.7386734097817399387e-16 0.018223085043007757056" />
    <parent link="ank_roll_link_2" />
    <child link="ank_rr_link_3" />
    <axis xyz="0 0 1" />
    <limit effort="1" velocity="20" lower="-1.570796326794896558" upper="1.570796326794896558" />
    <joint_properties friction="0.0" />
  </joint>

  <link name="ank_rr_link_4">
    <visual>
      <origin xyz="0 0 0" rpy="0 -0 0" />
      <geometry>
        <mesh filename="../assemblies/right_leg_XM430/meshes/right_ank_rr_link_2_visual.stl" />
      </geometry>
      <material name="ank_rr_link_2_material">
        <color rgba="0.61568627450980395466 0.81176470588235294379 0.92941176470588238168 1.0" />
      </material>
    </visual>
    <inertial>
      <origin xyz="-4.5249610960599196546e-05 0.0063096429836314591247 -2.2196875918465233771e-19" rpy="0 0 0" />
      <mass value="0.0014499999999999999001" />
      <inertia ixx="2.9739579267716163268e-08" ixy="2.4213146797977937856e-10" ixz="3.5523394884450971621e-14" iyy="2.7430027724071963673e-08" iyz="7.1669291072412853164e-32" izz="4.2921949116163665819e-08" />
    </inertial>
  </link>

  <link name="ank_motor_rod_short_2">
    <visual>
      <origin xyz="0 0 0" rpy="0 -0 0" />
      <geometry>
        <mesh filename="../assemblies/right_leg_XM430/meshes/right_ank_motor_rod_short_visual.stl" />
      </geometry>
      <material name="ank_motor_rod_short_material">
        <color rgba="0.41222606689734719865 0.58339100346020755783 0.8110726643598615837 1.0" />
      </material>
    </visual>
    <inertial>
      <origin xyz="2.6038943231632555042e-10 0.023830465465870850905 0.00090403506359630245951" rpy="0 0 0" />
      <mass value="0.0017000000000000005558" />
      <inertia ixx="3.3153416252669976544e-07" ixy="8.7419768121118736222e-15" ixz="4.574994156767735105e-11" iyy="1.0947363610305713008e-08" iyz="-3.5863098646421429665e-09" izz="3.3621340447865204927e-07" />
    </inertial>
  </link>

  <joint name="right_ank_short_rev_2" type="revolute">
    <origin xyz="0 0.010000000000000008882 0" rpy="-1.570796326794896558 1.2119133862909121646 -1.5707963267948537034" />
    <parent link="ank_rr_link_4" />
    <child link="ank_motor_rod_short_2" />
    <axis xyz="0 0 1" />
    <limit effort="1" velocity="20" lower="-1.570796326794896558" upper="1.570796326794896558" />
    <joint_properties friction="0.0" />
  </joint>

  <joint name="right_ank_short_rev_1" type="revolute">
    <origin xyz="-0.018000000000000012518 0.016000000000000014211 -0.020599999999999993316" rpy="1.6033225897674528336e-14 -1.3300018467937457486e-14 3.1154741050824821258" />
    <parent link="ank_roll_link_2" />
    <child link="ank_rr_link_4" />
    <axis xyz="0 0 1" />
    <limit effort="1" velocity="20" lower="-1.570796326794896558" upper="1.570796326794896558" />
    <joint_properties friction="0.0" />
  </joint>

  <link name="right_sole_link">
    <visual>
      <origin xyz="0 0 0" rpy="0 -0 0" />
      <geometry>
        <mesh filename="../assemblies/right_leg_XM430/meshes/right_sole_link_visual.stl" />
      </geometry>
      <material name="right_sole_link_material">
        <color rgba="0.61568627450980395466 0.81176470588235305481 0.92941176470588238168 1.0" />
      </material>
    </visual>
    <collision>
      <origin xyz="0 0 0" rpy="0 -0 0" />
      <geometry>
        <mesh filename="../assemblies/right_leg_XM430/meshes/right_sole_link_collision.stl" />
      </geometry>
    </collision>
    <inertial>
      <origin xyz="-0.02826922064948918234 -7.4209810882640253365e-08 -0.010206288127739998259" rpy="0 0 0" />
      <mass value="0.013900000000000007835" />
      <inertia ixx="1.316069070887124095e-06" ixy="-1.0226444191977043038e-10" ixz="-2.3744136049829838944e-07" iyy="1.3575381226152454021e-05" iyz="-7.1602330638899128618e-13" izz="1.4673427099197175005e-05" />
    </inertial>
  </link>

  <joint name="right_sole" type="fixed">
    <origin xyz="-8.8904578143811363589e-18 0.024999999999999966693 -0.022599999999999995093" rpy="1.570796326794896558 1.570796326794896336 0" />
    <parent link="ank_roll_link_2" />
    <child link="right_sole_link" />
    <axis xyz="0 0 1" />
    <limit effort="1" velocity="20" />
    <joint_properties friction="0.0" />
  </joint>

  <joint name="right_ank_roll" type="revolute">
    <origin xyz="0.0015000000000000002481 2.7755575615628913511e-17 1.2143064331837649661e-17" rpy="-8.0803901893659494053e-15 1.5707963267948927832 0" />
    <parent link="ank_pitch_link_2" />
    <child link="ank_roll_link_2" />
    <axis xyz="0 0 1" />
    <limit effort="1" velocity="20" lower="-0.785398163397448279" upper="0.785398163397448279" />
    <joint_properties friction="0.0" />
  </joint>

  <joint name="right_ank_pitch" type="revolute">
    <origin xyz="3.4616201395293281188e-16 0.10000000000000006106 -0.010399999999999975236" rpy="-3.1415926535897922278 1.9667427410937738729e-16 -3.1415926535897926719" />
    <parent link="right_calf_link" />
    <child link="ank_pitch_link_2" />
    <axis xyz="0 0 1" />
    <limit effort="1" velocity="20" lower="-1.0471975511965976313" upper="0.785398163397448279" />
    <joint_properties friction="0.0" />
  </joint>

  <link name="ank_motor_arm_3">
    <visual>
      <origin xyz="0 0 0" rpy="0 -0 0" />
      <geometry>
        <mesh filename="../assemblies/right_leg_XM430/meshes/right_ank_motor_arm_visual.stl" />
      </geometry>
      <material name="ank_motor_arm_material">
        <color rgba="0.62517751827980905244 0.70593642422614044651 0.75978993426662777555 1.0" />
      </material>
    </visual>
    <inertial>
      <origin xyz="0.014511489101591659376 -6.0716842868426040004e-17 0.0040925443765950589997" rpy="0 0 0" />
      <mass value="0.0020595846677894939954" />
      <inertia ixx="2.7591836756521892222e-08" ixy="3.3900077369708175932e-22" ixz="-3.0270788206594683066e-08" iyy="1.6138599216238377057e-07" iyz="9.6975644016840729871e-23" izz="1.6437836765016231947e-07" />
    </inertial>
  </link>

  <joint name="right_ank_act_1" type="revolute">
    <origin xyz="0.013499999999996006514 0.04450000000000683964 0.0040000000000046075088" rpy="-3.1559662337880072911e-13 -4.3224762083389784551e-14 0.21173394130152450865" />
    <parent link="right_calf_link" />
    <child link="ank_motor_arm_3" />
    <axis xyz="0 0 1" />
    <limit effort="1" velocity="20" lower="-1.3089969389957472057" upper="1.3089969389957472057" />
    <joint_properties friction="0.0" />
  </joint>

  <link name="ank_motor_arm_4">
    <visual>
      <origin xyz="0 0 0" rpy="0 -0 0" />
      <geometry>
        <mesh filename="../assemblies/right_leg_XM430/meshes/right_ank_motor_arm_2_visual.stl" />
      </geometry>
      <material name="ank_motor_arm_2_material">
        <color rgba="0.62517751827980905244 0.70593642422614044651 0.75978993426662777555 1.0" />
      </material>
    </visual>
    <inertial>
      <origin xyz="0.014511489101591685397 1.0861780912561501982e-17 0.0040925443765950624692" rpy="0 0 0" />
      <mass value="0.0020595846677894939954" />
      <inertia ixx="2.7591836756521941853e-08" ixy="1.7030620969413430294e-22" ixz="-3.0270788206594822033e-08" iyy="1.613859921623843529e-07" iyz="5.5992083730404144549e-23" izz="1.6437836765016284887e-07" />
    </inertial>
  </link>

  <joint name="right_ank_act_2" type="revolute">
    <origin xyz="0.013500000000003113676 0.064500000000006912915 -0.024800000000002909994" rpy="-3.1415926535895573046 -1.7198897169567297797e-13 0.22995607267273157626" />
    <parent link="right_calf_link" />
    <child link="ank_motor_arm_4" />
    <axis xyz="0 0 1" />
    <limit effort="1" velocity="20" lower="-1.3089969389957472057" upper="1.3089969389957472057" />
    <joint_properties friction="0.0" />
  </joint>

  <joint name="right_knee_pitch" type="revolute">
    <origin xyz="-2.9733995392255427503e-17 -0.096000000000000001998 -0.0091999999999999963751" rpy="-2.1337098754749728925e-16 3.9898639968108458448e-17 3.1415926535897846783" />
    <parent link="right_hip_pitch_link_xm430" />
    <child link="right_calf_link" />
    <axis xyz="0 0 1" />
    <limit effort="1" velocity="20" lower="-1.9198621771937625091" upper="0" />
    <joint_properties friction="0.0" />
  </joint>

  <link name="xm430_plate_2">
    <visual>
      <origin xyz="0 0 0" rpy="0 -0 0" />
      <geometry>
        <mesh filename="../assemblies/right_leg_XM430/meshes/right_xm430_plate_visual.stl" />
      </geometry>
      <material name="xm430_plate_material">
        <color rgba="0.61568627450980395466 0.81176470588235294379 0.92941176470588227065 1.0" />
      </material>
    </visual>
    <inertial>
      <origin xyz="1.0263680854558699407e-18 3.642799645586145742e-18 -0.0024039046431217972466" rpy="0 0 0" />
      <mass value="0.0026999999999999997093" />
      <inertia ixx="2.672043438587668303e-07" ixy="-6.8936588702566387474e-08" ixz="2.5793754136946570897e-36" iyy="1.2933116645363405536e-07" iyz="-5.5772549530744015424e-36" izz="3.8533537562751428679e-07" />
    </inertial>
  </link>

  <link name="knee_rod_3">
    <visual>
      <origin xyz="0 0 0" rpy="0 -0 0" />
      <geometry>
        <mesh filename="../assemblies/right_leg_XM430/meshes/right_knee_rod_visual.stl" />
      </geometry>
      <material name="knee_rod_material">
        <color rgba="0.62051618944235198416 0.78640765248647581664 0.88594253031295022716 1.0" />
      </material>
    </visual>
    <inertial>
      <origin xyz="0.014594553522267956006 3.7292099839724583211e-05 -0.0015996227373186720257" rpy="0 0 0" />
      <mass value="0.0031629468613064179276" />
      <inertia ixx="2.589592331513038355e-08" ixy="-3.1325283435871741767e-10" ixz="4.1682992324833826779e-10" iyy="6.015326150335526925e-07" iyz="1.0650865822052022654e-12" izz="6.2266847407077550526e-07" />
    </inertial>
  </link>

  <joint name="right_knee_front_rev_1" type="revolute">
    <origin xyz="-0.005740251485476348392 -0.013858192987669298857 -0.0050000000000000027062" rpy="1.2660330546546102165e-14 -5.760640040579399853e-15 1.5651709144543408669" />
    <parent link="xm430_plate_2" />
    <child link="knee_rod_3" />
    <axis xyz="0 0 1" />
    <limit effort="1" velocity="20" lower="-6.283185307179586232" upper="6.283185307179586232" />
    <joint_properties friction="0.0" />
  </joint>

  <link name="knee_rod_4">
    <visual>
      <origin xyz="0 0 0" rpy="0 -0 0" />
      <geometry>
        <mesh filename="../assemblies/right_leg_XM430/meshes/right_knee_rod_2_visual.stl" />
      </geometry>
      <material name="knee_rod_2_material">
        <color rgba="0.62051618944235198416 0.78640765248647581664 0.88594253031295022716 1.0" />
      </material>
    </visual>
    <inertial>
      <origin xyz="0.014594557105585473714 3.4373169586153155656e-05 -0.0015996227373184820734" rpy="0 0 0" />
      <mass value="0.0031629468613064179276" />
      <inertia ixx="2.5895802916981982353e-08" ixy="-2.8873395407690152335e-10" ixz="4.1683002558550284414e-10" iyy="6.0153267523314944791e-07" iyz="9.8172003926880134242e-13" izz="6.2266841387223796456e-07" />
    </inertial>
  </link>

  <joint name="right_knee_back_rev_1" type="revolute">
    <origin xyz="0.0057402514854763509941 0.013858192987669298857 -0.0050000000000000061756" rpy="1.7600934488845652939e-14 7.4447456537463636708e-16 1.5652709159814237605" />
    <parent link="xm430_plate_2" />
    <child link="knee_rod_4" />
    <axis xyz="0 0 1" />
    <limit effort="1" velocity="20" lower="-6.283185307179586232" upper="6.283185307179586232" />
    <joint_properties friction="0.0" />
  </joint>

  <joint name="right_knee_act" type="revolute">
    <origin xyz="0.0001500000000000903009 -0.061499999999999978295 -0.030400000000000013817" rpy="-2.110221371875480467e-15 -1.2104358314278240034e-14 3.1415926535897811256" />
    <parent link="right_hip_pitch_link_xm430" />
    <child link="xm430_plate_2" />
    <axis xyz="0 0 1" />
    <limit effort="1" velocity="20" lower="-1.9198621771937625091" upper="0" />
    <joint_properties friction="0.0" />
  </joint>

  <joint name="right_hip_pitch" type="revolute">
    <origin xyz="-0.024000000716142756707 -0.019000000152441819112 -0.019000000152452952568" rpy="1.5707963267951126074 1.5707963267947429031 0" />
    <parent link="hip_roll_link_2" />
    <child link="right_hip_pitch_link_xm430" />
    <axis xyz="0 0 1" />
    <limit effort="1" velocity="20" lower="-1.570796326794896558" upper="1.570796326794896558" />
    <joint_properties friction="0.0" />
  </joint>

  <joint name="right_hip_roll" type="revolute">
    <origin xyz="-0.018999999999999999528 3.350043889036771243e-18 -0.026000000000000002276" rpy="-6.1629758220389864097e-33 -1.5707963267948785724 0" />
    <parent link="hip_yaw_link_2" />
    <child link="hip_roll_link_2" />
    <axis xyz="0 0 1" />
    <limit effort="1" velocity="20" lower="-0.785398163397448279" upper="1.570796326794896558" />
    <joint_properties friction="0.0" />
  </joint>


  <link name="sho_pitch_link">
    <visual>
      <origin xyz="0 0 0" rpy="0 -0 0" />
      <geometry>
        <mesh filename="../assemblies/left_arm_hand/meshes/left_sho_pitch_link_visual.stl" />
      </geometry>
      <material name="sho_pitch_link_material">
        <color rgba="0.61568627450980395466 0.81176470588235294379 0.92941176470588227065 1.0" />
      </material>
    </visual>
    <inertial>
      <origin xyz="5.8254249669365172068e-11 -5.1264642561120511732e-05 0.0082440788127094901533" rpy="0 0 0" />
      <mass value="0.0085999999999999948014" />
      <inertia ixx="1.227288704054578552e-06" ixy="-2.142994421442472607e-14" ixz="-8.5847199972402478199e-15" iyy="2.9107306060364603147e-06" iyz="7.4623841398182653875e-09" izz="3.0803135950773474987e-06" />
    </inertial>
  </link>

  <link name="2xl430_gears">
    <visual>
      <origin xyz="0 0 0" rpy="0 -0 0" />
      <geometry>
        <mesh filename="../assemblies/left_arm_hand/meshes/left_2xl430_gears_visual.stl" />
      </geometry>
      <material name="2xl430_gears_material">
        <color rgba="0.75605985687944088358 0.8580469596269301169 0.91320266199377453376 1.0" />
      </material>
    </visual>
    <collision>
      <origin xyz="0 0 0" rpy="0 -0 0" />
      <geometry>
        <mesh filename="collisions/left_2xl430_gears_collision.stl" />
      </geometry>
    </collision>
    <inertial>
      <origin xyz="-0.011579403981036556076 -0.00242257661414001799 -0.018551095523803531884" rpy="0 0 0" />
      <mass value="0.11800003674524907338" />
      <inertia ixx="2.7482298083236092012e-05" ixy="9.2729623432982075535e-07" ixz="-2.2634512003761296596e-08" iyy="3.2770742486672784378e-05" iyz="-6.5708346020130284201e-07" izz="3.5767957544054292845e-05" />
    </inertial>
  </link>

  <link name="spur_1m_24t_drive">
    <visual>
      <origin xyz="0 0 0" rpy="0 -0 0" />
      <geometry>
        <mesh filename="../assemblies/left_arm_hand/meshes/left_spur_1m_24t_drive_visual.stl" />
      </geometry>
      <material name="spur_1m_24t_drive_material">
        <color rgba="0.61568627450980406568 0.81176470588235294379 0.92941176470588238168 1.0" />
      </material>
    </visual>
    <inertial>
      <origin xyz="-7.7589517893534835836e-15 -1.211050839611185126e-16 0.0047949116178401460231" rpy="0 0 0" />
      <mass value="0.0032000000000000001533" />
      <inertia ixx="1.4019331346159890349e-07" ixy="1.6002409955622246819e-15" ixz="-8.0106568502533350833e-38" iyy="1.4019331260388783538e-07" iyz="3.5707617447061284037e-38" izz="2.3838919844264060647e-07" />
    </inertial>
  </link>

  <joint name="left_sho_yaw_drive" type="revolute">
    <origin xyz="-0.024000000716141278723 -0.019000000152448490859 -0.0190000001524472939" rpy="1.570796326794886566 -1.7772407460995643501e-15 2.9721983312145830671e-14" />
    <parent link="2xl430_gears" />
    <child link="spur_1m_24t_drive" />
    <axis xyz="0 0 1" />
    <limit effort="1" velocity="20" lower="-1.570796326794896558" upper="1.570796326794896558" />
    <joint_properties friction="0.0" />
  </joint>

  <link name="spur_1m_24t_driven">
    <visual>
      <origin xyz="0 0 0" rpy="0 -0 0" />
      <geometry>
        <mesh filename="../assemblies/left_arm_hand/meshes/left_spur_1m_24t_driven_visual.stl" />
      </geometry>
      <material name="spur_1m_24t_driven_material">
        <color rgba="0.23137254901960788156 0.38039215686274507888 0.7058823529411765163 1.0" />
      </material>
    </visual>
    <inertial>
      <origin xyz="2.4350898561930652746e-18 -5.798576291048762493e-15 -0.00096866348640038332785" rpy="0 0 0" />
      <mass value="0.0027000000000000001429" />
      <inertia ixx="1.2026541119643502094e-07" ixy="-4.0474500803410873683e-47" ixz="-1.0726060653955529023e-38" iyy="1.2026541119643483565e-07" iyz="5.980474480612833222e-38" izz="2.2827257365099366486e-07" />
    </inertial>
  </link>

  <link name="sho_yaw_link">
    <visual>
      <origin xyz="0 0 0" rpy="0 -0 0" />
      <geometry>
        <mesh filename="../assemblies/left_arm_hand/meshes/left_sho_yaw_link_visual.stl" />
      </geometry>
      <material name="sho_yaw_link_material">
        <color rgba="0.61568627450980395466 0.81176470588235294379 0.92941176470588238168 1.0" />
      </material>
    </visual>
    <inertial>
      <origin xyz="-1.1573942515719326726e-18 3.7205074538890822836e-18 -0.024214576156328417034" rpy="0 0 0" />
      <mass value="0.014500000000000014613" />
      <inertia ixx="9.0490855102914958597e-06" ixy="3.5997729401630495156e-13" ixz="8.4928747802388958028e-37" iyy="5.6767199180624702083e-06" iyz="1.6087043138114345405e-36" izz="4.4590603637468133921e-06" />
    </inertial>
  </link>

  <link name="2xl430_gears_2">
    <visual>
      <origin xyz="0 0 0" rpy="0 -0 0" />
      <geometry>
        <mesh filename="../assemblies/left_arm_hand/meshes/left_2xl430_gears_2_visual.stl" />
      </geometry>
      <material name="2xl430_gears_2_material">
        <color rgba="0.75605985687944088358 0.8580469596269301169 0.91320266199377453376 1.0" />
      </material>
    </visual>
    <collision>
      <origin xyz="0 0 0" rpy="0 -0 0" />
      <geometry>
        <mesh filename="collisions/left_2xl430_gears_2_collision.stl" />
      </geometry>
    </collision>
    <inertial>
      <origin xyz="-0.01157940398103590382 -0.0024225766141403098572 -0.018551095523804767007" rpy="0 0 0" />
      <mass value="0.11800003674524907338" />
      <inertia ixx="2.7482298083236647666e-05" ixy="9.2729623433076127956e-07" ixz="-2.2634512003935616638e-08" iyy="3.2770742486673184177e-05" iyz="-6.5708346020168263041e-07" izz="3.5767957544054916261e-05" />
    </inertial>
  </link>

  <link name="spur_1m_24t_drive_2">
    <visual>
      <origin xyz="0 0 0" rpy="0 -0 0" />
      <geometry>
        <mesh filename="../assemblies/left_arm_hand/meshes/left_spur_1m_24t_drive_2_visual.stl" />
      </geometry>
      <material name="spur_1m_24t_drive_2_material">
        <color rgba="0.61568627450980406568 0.81176470588235294379 0.92941176470588238168 1.0" />
      </material>
    </visual>
    <inertial>
      <origin xyz="-7.7520128954495763552e-15 -1.2110508396111870982e-16 0.0047949116178401382168" rpy="0 0 0" />
      <mass value="0.0032000000000000001533" />
      <inertia ixx="1.4019331346159890349e-07" ixy="1.6002409988709471321e-15" ixz="2.601989679508350391e-37" iyy="1.4019331260388783538e-07" iyz="-1.1857416576551865918e-36" izz="2.3838919844264060647e-07" />
    </inertial>
  </link>

  <joint name="left_elbow_yaw_drive" type="revolute">
    <origin xyz="-0.024000000716141011575 -0.019000000152448556778 -0.019000000152448452695" rpy="1.5707963267949249797 5.3833632274240703492e-15 -6.2781152873576405876e-14" />
    <parent link="2xl430_gears_2" />
    <child link="spur_1m_24t_drive_2" />
    <axis xyz="0 0 1" />
    <limit effort="1" velocity="20" lower="-1.570796326794896558" upper="1.570796326794896558" />
    <joint_properties friction="0.0" />
  </joint>

  <link name="spur_1m_24t_driven_2">
    <visual>
      <origin xyz="0 0 0" rpy="0 -0 0" />
      <geometry>
        <mesh filename="../assemblies/left_arm_hand/meshes/left_spur_1m_24t_driven_2_visual.stl" />
      </geometry>
      <material name="spur_1m_24t_driven_2_material">
        <color rgba="0.23137254901960788156 0.38039215686274507888 0.7058823529411765163 1.0" />
      </material>
    </visual>
    <inertial>
      <origin xyz="2.4350898561930425487e-18 -5.7988120355575981266e-15 -0.00096866348640039037516" rpy="0 0 0" />
      <mass value="0.0027000000000000001429" />
      <inertia ixx="1.2026541119643502094e-07" ixy="0" ixz="-3.9131793608196566436e-37" iyy="1.2026541119643483565e-07" iyz="0" izz="2.2827257365099366486e-07" />
    </inertial>
  </link>

  <link name="elb_yaw_link">
    <visual>
      <origin xyz="0 0 0" rpy="0 -0 0" />
      <geometry>
        <mesh filename="../assemblies/left_arm_hand/meshes/left_elb_yaw_link_visual.stl" />
      </geometry>
      <material name="elb_yaw_link_material">
        <color rgba="0.61568627450980395466 0.81176470588235294379 0.92941176470588227065 1.0" />
      </material>
    </visual>
    <inertial>
      <origin xyz="5.2870889172758376684e-08 0.0019873558182742436136 -0.02336566119982871545" rpy="0 0 0" />
      <mass value="0.017500000000000005135" />
      <inertia ixx="1.4097804991252561445e-05" ixy="1.6900809684077683173e-12" ixz="-1.1184673662168510534e-11" iyy="6.6367696417680327434e-06" iyz="1.057990872258833363e-06" izz="8.9601142768980646651e-06" />
    </inertial>
  </link>

  <link name="spur_1m_24t_driven_3">
    <visual>
      <origin xyz="0 0 0" rpy="0 -0 0" />
      <geometry>
        <mesh filename="../assemblies/left_arm_hand/meshes/left_spur_1m_24t_driven_3_visual.stl" />
      </geometry>
      <material name="spur_1m_24t_driven_3_material">
        <color rgba="0.23137254901960788156 0.38039215686274507888 0.7058823529411765163 1.0" />
      </material>
    </visual>
    <inertial>
      <origin xyz="-2.5320485759435755406e-17 -5.8022814825095517408e-15 -0.0025686634864003805856" rpy="0 0 0" />
      <mass value="0.0027000000000000001429" />
      <inertia ixx="1.2026541119643502094e-07" ixy="7.589814491455755124e-37" ixz="1.0368687130951098114e-36" iyy="1.2026541119643483565e-07" iyz="7.7514145192038011191e-67" izz="2.2827257365099366486e-07" />
    </inertial>
  </link>

  <link name="2xl430_gears_3">
    <visual>
      <origin xyz="0 0 0" rpy="0 -0 0" />
      <geometry>
        <mesh filename="../assemblies/left_arm_hand/meshes/left_2xl430_gears_3_visual.stl" />
      </geometry>
      <material name="2xl430_gears_3_material">
        <color rgba="0.75605985687944088358 0.8580469596269301169 0.91320266199377453376 1.0" />
      </material>
    </visual>
    <collision>
      <origin xyz="0 0 0" rpy="0 -0 0" />
      <geometry>
        <mesh filename="collisions/left_2xl430_gears_3_collision.stl" />
      </geometry>
    </collision>
    <inertial>
      <origin xyz="0.0004489044762018264763 0.01157940362295437238 -0.024577423538310185641" rpy="0 0 0" />
      <mass value="0.11800003674524907338" />
      <inertia ixx="3.5767957544054143767e-05" ixy="2.2634512003808455817e-08" ixz="6.5708346020219752056e-07" iyy="2.7482298083236972926e-05" iyz="9.2729623433153800877e-07" izz="3.277074248667180182e-05" />
    </inertial>
  </link>

  <link name="spur_1m_24t_drive_3">
    <visual>
      <origin xyz="0 0 0" rpy="0 -0 0" />
      <geometry>
        <mesh filename="../assemblies/left_arm_hand/meshes/left_spur_1m_24t_drive_3_visual.stl" />
      </geometry>
      <material name="spur_1m_24t_drive_3_material">
        <color rgba="0.61568627450980406568 0.81176470588235294379 0.92941176470588238168 1.0" />
      </material>
    </visual>
    <inertial>
      <origin xyz="-7.7797684710652052688e-15 -1.2135702417639747025e-16 0.0047949116178401460231" rpy="0 0 0" />
      <mass value="0.0032000000000000001533" />
      <inertia ixx="1.4019331346159890349e-07" ixy="1.6002409955622246819e-15" ixz="1.353024793676005448e-36" iyy="1.4019331260388783538e-07" iyz="-6.353552390351152457e-37" izz="2.3838919844264060647e-07" />
    </inertial>
  </link>

  <joint name="left_wrist_roll_drive" type="revolute">
    <origin xyz="-1.5244091752797395145e-10 0.024000000358059436767 -0.0080000000000068592632" rpy="1.9871762375367660116e-15 -2.337019466836035928e-14 -1.5707963267949176522" />
    <parent link="2xl430_gears_3" />
    <child link="spur_1m_24t_drive_3" />
    <axis xyz="0 0 1" />
    <limit effort="1" velocity="20" lower="-1.570796326794896558" upper="1.570796326794896558" />
    <joint_properties friction="0.0" />
  </joint>

  <link name="hand">
    <visual>
      <origin xyz="0 0 0" rpy="0 -0 0" />
      <geometry>
        <mesh filename="../assemblies/left_arm_hand/meshes/left_hand_visual.stl" />
      </geometry>
      <material name="hand_material">
        <color rgba="0.61568627450980395466 0.81176470588235294379 0.92941176470588238168 1.0" />
      </material>
    </visual>
    <collision>
      <origin xyz="0 0 0" rpy="0 -0 0" />
      <geometry>
        <mesh filename="../assemblies/left_arm_hand/meshes/left_hand_collision.stl" />
      </geometry>
    </collision>
    <inertial>
      <origin xyz="-4.3038382212369557027e-08 -0.049723778585225218707 -0.017933572005385645109" rpy="0 0 0" />
      <mass value="0.01700000000000000816" />
      <inertia ixx="9.4921414617707132477e-06" ixy="-1.5549215897341496758e-11" ixz="-1.0809694196525066509e-11" iyy="4.0745028295219371575e-06" iyz="2.4719408559888000802e-07" izz="6.6623859522963571519e-06" />
    </inertial>
  </link>

  <joint name="left_wrist_pitch" type="revolute">
    <origin xyz="0.019000000000005953099 -3.5808089826616651408e-10 -0.027000000152448959401" rpy="3.3651291228739927188e-14 1.5707963267946487562 0" />
    <parent link="2xl430_gears_3" />
    <child link="hand" />
    <axis xyz="0 0 1" />
    <limit effort="1" velocity="20" lower="-1.570796326794896558" upper="1.570796326794896558" />
    <joint_properties friction="0.0" />
  </joint>

  <link name="wrist_bearing_plate">
    <visual>
      <origin xyz="0 0 0" rpy="0 -0 0" />
      <geometry>
        <mesh filename="../assemblies/left_arm_hand/meshes/left_wrist_bearing_plate_visual.stl" />
      </geometry>
      <material name="wrist_bearing_plate_material">
        <color rgba="0.64496316278892629192 0.69011804996940528945 0.71706771073555886087 1.0" />
      </material>
    </visual>
    <inertial>
      <origin xyz="-0.0075896393545961350277 -0.015499999999999973868 -0.0018386110045718368107" rpy="0 0 0" />
      <mass value="0.0049000367468305548388" />
      <inertia ixx="4.9747313520140109893e-07" ixy="5.5640336275171808945e-23" ixz="1.8097509420524730079e-08" iyy="7.1295025627582332608e-07" iyz="1.0346027163095738089e-23" izz="1.1926297952291908138e-06" />
    </inertial>
  </link>

  <joint name="left_wrist_pitch_fixed" type="fixed">
    <origin xyz="0.015500000000005269979 -1.7125190154843039636e-14 -0.04500000000000015099" rpy="-4.057865155005087888e-14 -2.9093394360302217044e-13 -1.5707963267949061059" />
    <parent link="2xl430_gears_3" />
    <child link="wrist_bearing_plate" />
    <axis xyz="0 0 1" />
    <limit effort="1" velocity="20" />
    <joint_properties friction="0.0" />
  </joint>

  <joint name="left_wrist_roll_driven" type="revolute">
    <origin xyz="-2.7755575615628913511e-17 0 -0.0015999999999999937883" rpy="2.1632341616309662631e-16 -1.4384639448392080473e-27 -1.57079632679489678" />
    <parent link="spur_1m_24t_driven_3" />
    <child link="2xl430_gears_3" />
    <axis xyz="0 0 1" />
    <limit effort="1" velocity="20" lower="-1.570796326794896558" upper="1.570796326794896558" />
    <joint_properties friction="0.0" />
  </joint>

  <joint name="left_wrist_roll_fixed" type="fixed">
    <origin xyz="-3.4694469519536141888e-18 -0.025300000000000003042 -0.051999999999999976796" rpy="1.570796326794896558 -1.570796326794896558 0" />
    <parent link="elb_yaw_link" />
    <child link="spur_1m_24t_driven_3" />
    <axis xyz="0 0 1" />
    <limit effort="1" velocity="20" />
    <joint_properties friction="0.0" />
  </joint>

  <joint name="left_elbow_yaw_fixed" type="fixed">
    <origin xyz="7.8886090522101180541e-31 3.4694469519536141888e-18 0.0015999999999999625633" rpy="3.141592653589793116 6.123233994422830684e-17 -1.57079632679489678" />
    <parent link="spur_1m_24t_driven_2" />
    <child link="elb_yaw_link" />
    <axis xyz="0 0 1" />
    <limit effort="1" velocity="20" />
    <joint_properties friction="0.0" />
  </joint>

  <joint name="left_elbow_yaw_driven" type="revolute">
    <origin xyz="-3.5806929990500613314e-10 -0.027000000152451131274 -0.019000000000003351014" rpy="1.5707963267949591746 1.5707963267948683583 0" />
    <parent link="2xl430_gears_2" />
    <child link="spur_1m_24t_driven_2" />
    <axis xyz="0 0 1" />
    <limit effort="1" velocity="20" lower="-1.570796326794896558" upper="1.570796326794896558" />
    <joint_properties friction="0.0" />
  </joint>

  <joint name="left_elbow_roll" type="revolute">
    <origin xyz="2.185751579730776939e-16 -0.018999999999999329925 -0.058999999999999733213" rpy="1.570796326794896558 -1.3443939455351824662e-14 1.2212453270787430779e-15" />
    <parent link="sho_yaw_link" />
    <child link="2xl430_gears_2" />
    <axis xyz="0 0 1" />
    <limit effort="1" velocity="20" lower="-1.570796326794896558" upper="1.570796326794896558" />
    <joint_properties friction="0.0" />
  </joint>

  <joint name="left_sho_yaw_fixed" type="fixed">
    <origin xyz="1.7347234759768070944e-17 -1.6375789611241112762e-17 0.0015999999999999972577" rpy="-3.1415926535897926719 2.775557561593911827e-16 4.4408920984097454411e-16" />
    <parent link="spur_1m_24t_driven" />
    <child link="sho_yaw_link" />
    <axis xyz="0 0 1" />
    <limit effort="1" velocity="20" />
    <joint_properties friction="0.0" />
  </joint>

  <joint name="left_sho_yaw_driven" type="revolute">
    <origin xyz="-3.5807098258677783065e-10 -0.027000000152450111257 -0.019000000000003021416" rpy="1.5707963267949009989 2.5840015203544507292e-14 -4.9507333169721578628e-15" />
    <parent link="2xl430_gears" />
    <child link="spur_1m_24t_driven" />
    <axis xyz="0 0 1" />
    <limit effort="1" velocity="20" lower="-1.570796326794896558" upper="1.570796326794896558" />
    <joint_properties friction="0.0" />
  </joint>

  <joint name="left_sho_roll" type="revolute">
    <origin xyz="-0.018999999999999947486 0.0010000000000000076102 0.027000000000000003164" rpy="-3.141592653589793116 1.570796326794896558 0" />
    <parent link="sho_pitch_link" />
    <child link="2xl430_gears" />
    <axis xyz="0 0 1" />
    <limit effort="1" velocity="20" lower="-1.570796326794896558" upper="0" />
    <joint_properties friction="0.0" />
  </joint>


  <link name="sho_pitch_link_2">
    <visual>
      <origin xyz="0 0 0" rpy="0 -0 0" />
      <geometry>
        <mesh filename="../assemblies/right_arm_hand/meshes/right_sho_pitch_link_visual.stl" />
      </geometry>
      <material name="sho_pitch_link_material">
        <color rgba="0.61568627450980395466 0.81176470588235294379 0.92941176470588227065 1.0" />
      </material>
    </visual>
    <inertial>
      <origin xyz="5.8254249669365172068e-11 -5.1264642561120511732e-05 0.0082440788127094901533" rpy="0 0 0" />
      <mass value="0.0085999999999999948014" />
      <inertia ixx="1.227288704054578552e-06" ixy="-2.142994421442472607e-14" ixz="-8.5847199972402478199e-15" iyy="2.9107306060364603147e-06" iyz="7.4623841398182653875e-09" izz="3.0803135950773474987e-06" />
    </inertial>
  </link>

  <link name="2xl430_gears_4">
    <visual>
      <origin xyz="0 0 0" rpy="0 -0 0" />
      <geometry>
        <mesh filename="../assemblies/right_arm_hand/meshes/right_2xl430_gears_visual.stl" />
      </geometry>
      <material name="2xl430_gears_material">
        <color rgba="0.75605985687944088358 0.8580469596269301169 0.91320266199377453376 1.0" />
      </material>
    </visual>
    <collision>
      <origin xyz="0 0 0" rpy="0 -0 0" />
      <geometry>
        <mesh filename="collisions/right_2xl430_gears_collision.stl" />
      </geometry>
    </collision>
    <inertial>
      <origin xyz="-0.011579403981034819618 -0.0024225766141402647544 -0.018551095523804385368" rpy="0 0 0" />
      <mass value="0.11800003674524907338" />
      <inertia ixx="2.7482298083236308853e-05" ixy="9.2729623432947548355e-07" ixz="-2.2634512004124150952e-08" iyy="3.2770742486672953784e-05" iyz="-6.5708346020133852327e-07" izz="3.5767957544054530014e-05" />
    </inertial>
  </link>

  <link name="spur_1m_24t_drive_4">
    <visual>
      <origin xyz="0 0 0" rpy="0 -0 0" />
      <geometry>
        <mesh filename="../assemblies/right_arm_hand/meshes/right_spur_1m_24t_drive_visual.stl" />
      </geometry>
      <material name="spur_1m_24t_drive_material">
        <color rgba="0.61568627450980406568 0.81176470588235294379 0.92941176470588238168 1.0" />
      </material>
    </visual>
    <inertial>
      <origin xyz="-7.7450740015456675491e-15 -1.2110508396111870982e-16 0.0047949116178401442884" rpy="0 0 0" />
      <mass value="0.0032000000000000001533" />
      <inertia ixx="1.4019331346159885055e-07" ixy="1.6002409976221174075e-15" ixz="-3.3725439700307396967e-36" iyy="1.4019331260388788832e-07" iyz="3.7162875711380714346e-37" izz="2.3838919844264071235e-07" />
    </inertial>
  </link>

  <joint name="right_sho_yaw_drive" type="revolute">
    <origin xyz="-0.024000000716138513573 -0.019000000152446919199 -0.019000000152449438018" rpy="1.5707963267949425212 -7.4825707768639476445e-14 5.2729872485629252068e-14" />
    <parent link="2xl430_gears_4" />
    <child link="spur_1m_24t_drive_4" />
    <axis xyz="0 0 1" />
    <limit effort="1" velocity="20" lower="-1.570796326794896558" upper="1.570796326794896558" />
    <joint_properties friction="0.0" />
  </joint>

  <link name="spur_1m_24t_driven_4">
    <visual>
      <origin xyz="0 0 0" rpy="0 -0 0" />
      <geometry>
        <mesh filename="../assemblies/right_arm_hand/meshes/right_spur_1m_24t_driven_visual.stl" />
      </geometry>
      <material name="spur_1m_24t_driven_material">
        <color rgba="0.23137254901960788156 0.38039215686274507888 0.7058823529411765163 1.0" />
      </material>
    </visual>
    <inertial>
      <origin xyz="2.4350898561930675858e-18 -5.798576291048762493e-15 -0.00096866348640038332785" rpy="0 0 0" />
      <mass value="0.0027000000000000001429" />
      <inertia ixx="1.2026541119643502094e-07" ixy="-5.5663580889415808082e-37" ixz="6.6068929034903528962e-38" iyy="1.2026541119643483565e-07" iyz="-8.7912927549812511121e-37" izz="2.2827257365099366486e-07" />
    </inertial>
  </link>

  <link name="sho_yaw_link_2">
    <visual>
      <origin xyz="0 0 0" rpy="0 -0 0" />
      <geometry>
        <mesh filename="../assemblies/right_arm_hand/meshes/right_sho_yaw_link_visual.stl" />
      </geometry>
      <material name="sho_yaw_link_material">
        <color rgba="0.61568627450980395466 0.81176470588235294379 0.92941176470588238168 1.0" />
      </material>
    </visual>
    <inertial>
      <origin xyz="-1.1573942515719415319e-18 3.7205074538885707566e-18 -0.024214576156328423973" rpy="0 0 0" />
      <mass value="0.014500000000000014613" />
      <inertia ixx="9.0490855102914958597e-06" ixy="3.5997729401630495156e-13" ixz="7.6329854215856995025e-36" iyy="5.6767199180624702083e-06" iyz="-3.9168248734789190621e-35" izz="4.4590603637468133921e-06" />
    </inertial>
  </link>

  <link name="2xl430_gears_5">
    <visual>
      <origin xyz="0 0 0" rpy="0 -0 0" />
      <geometry>
        <mesh filename="../assemblies/right_arm_hand/meshes/right_2xl430_gears_2_visual.stl" />
      </geometry>
      <material name="2xl430_gears_2_material">
        <color rgba="0.75605985687944088358 0.8580469596269301169 0.91320266199377453376 1.0" />
      </material>
    </visual>
    <collision>
      <origin xyz="0 0 0" rpy="0 -0 0" />
      <geometry>
        <mesh filename="collisions/right_2xl430_gears_2_collision.stl" />
      </geometry>
    </collision>
    <inertial>
      <origin xyz="-0.011579403981039059282 -0.0024225766141394641795 -0.01855109552380462129" rpy="0 0 0" />
      <mass value="0.11800003674524907338" />
      <inertia ixx="2.7482298083236667994e-05" ixy="9.272962343288520673e-07" ixz="-2.2634512003315836675e-08" iyy="3.2770742486673394241e-05" iyz="-6.5708346020123179712e-07" izz="3.5767957544054685868e-05" />
    </inertial>
  </link>

  <link name="spur_1m_24t_drive_5">
    <visual>
      <origin xyz="0 0 0" rpy="0 -0 0" />
      <geometry>
        <mesh filename="../assemblies/right_arm_hand/meshes/right_spur_1m_24t_drive_2_visual.stl" />
      </geometry>
      <material name="spur_1m_24t_drive_2_material">
        <color rgba="0.61568627450980406568 0.81176470588235294379 0.92941176470588238168 1.0" />
      </material>
    </visual>
    <inertial>
      <origin xyz="-7.7520128954495747775e-15 -1.2110508393526911846e-16 0.0047949116178401382168" rpy="0 0 0" />
      <mass value="0.0032000000000000001533" />
      <inertia ixx="1.4019331346159885055e-07" ixy="1.6002410001480835526e-15" ixz="1.6629977555619597901e-37" iyy="1.4019331260388780891e-07" iyz="-5.9003905059354033441e-36" izz="2.3838919844264060647e-07" />
    </inertial>
  </link>

  <joint name="right_elbow_yaw_drive" type="revolute">
    <origin xyz="-0.024000000716145233892 -0.019000000152448695556 -0.019000000152448716373" rpy="1.5707963267950251218 -1.5597582698688193762e-15 -8.7866473173388565758e-14" />
    <parent link="2xl430_gears_5" />
    <child link="spur_1m_24t_drive_5" />
    <axis xyz="0 0 1" />
    <limit effort="1" velocity="20" lower="-1.570796326794896558" upper="1.570796326794896558" />
    <joint_properties friction="0.0" />
  </joint>

  <link name="spur_1m_24t_driven_5">
    <visual>
      <origin xyz="0 0 0" rpy="0 -0 0" />
      <geometry>
        <mesh filename="../assemblies/right_arm_hand/meshes/right_spur_1m_24t_driven_2_visual.stl" />
      </geometry>
      <material name="spur_1m_24t_driven_2_material">
        <color rgba="0.23137254901960788156 0.38039215686274507888 0.7058823529411765163 1.0" />
      </material>
    </visual>
    <inertial>
      <origin xyz="2.4350898561930675858e-18 -5.7985762910487648596e-15 -0.00096866348640039037516" rpy="0 0 0" />
      <mass value="0.0027000000000000001429" />
      <inertia ixx="1.2026541119643502094e-07" ixy="0" ixz="0" iyy="1.2026541119643483565e-07" iyz="-2.0904260807940484234e-37" izz="2.2827257365099366486e-07" />
    </inertial>
  </link>

  <link name="elb_yaw_link_2">
    <visual>
      <origin xyz="0 0 0" rpy="0 -0 0" />
      <geometry>
        <mesh filename="../assemblies/right_arm_hand/meshes/right_elb_yaw_link_visual.stl" />
      </geometry>
      <material name="elb_yaw_link_material">
        <color rgba="0.61568627450980395466 0.81176470588235294379 0.92941176470588227065 1.0" />
      </material>
    </visual>
    <inertial>
      <origin xyz="5.2870889176227823636e-08 0.0019873558182742436136 -0.023365661199828722389" rpy="0 0 0" />
      <mass value="0.017500000000000005135" />
      <inertia ixx="1.4097804991252561445e-05" ixy="1.6900809684077683173e-12" ixz="-1.1184673662168513766e-11" iyy="6.6367696417680327434e-06" iyz="1.0579908722588335747e-06" izz="8.9601142768980680532e-06" />
    </inertial>
  </link>

  <link name="spur_1m_24t_driven_6">
    <visual>
      <origin xyz="0 0 0" rpy="0 -0 0" />
      <geometry>
        <mesh filename="../assemblies/right_arm_hand/meshes/right_spur_1m_24t_driven_3_visual.stl" />
      </geometry>
      <material name="spur_1m_24t_driven_3_material">
        <color rgba="0.23137254901960788156 0.38039215686274507888 0.7058823529411765163 1.0" />
      </material>
    </visual>
    <inertial>
      <origin xyz="3.0190665471821948356e-17 -5.7988120355575981266e-15 -0.0025686634864003805856" rpy="0 0 0" />
      <mass value="0.0027000000000000001429" />
      <inertia ixx="1.2026541119643502094e-07" ixy="2.4642767301845862177e-37" ixz="-2.4880139536911267997e-37" iyy="1.2026541119643483565e-07" iyz="5.0195324597132952237e-37" izz="2.2827257365099366486e-07" />
    </inertial>
  </link>

  <link name="2xl430_gears_6">
    <visual>
      <origin xyz="0 0 0" rpy="0 -0 0" />
      <geometry>
        <mesh filename="../assemblies/right_arm_hand/meshes/right_2xl430_gears_3_visual.stl" />
      </geometry>
      <material name="2xl430_gears_3_material">
        <color rgba="0.75605985687944088358 0.8580469596269301169 0.91320266199377453376 1.0" />
      </material>
    </visual>
    <collision>
      <origin xyz="0 0 0" rpy="0 -0 0" />
      <geometry>
        <mesh filename="collisions/right_2xl430_gears_3_collision.stl" />
      </geometry>
    </collision>
    <inertial>
      <origin xyz="0.00044890447620021383399 0.011579403622967155557 -0.024577423538309637469" rpy="0 0 0" />
      <mass value="0.11800003674524907338" />
      <inertia ixx="3.5767957544056075002e-05" ixy="2.2634512003691899451e-08" ixz="6.5708346020097959306e-07" iyy="2.7482298083237132169e-05" iyz="9.2729623433063305995e-07" izz="3.2770742486673109638e-05" />
    </inertial>
  </link>

  <link name="spur_1m_24t_drive_6">
    <visual>
      <origin xyz="0 0 0" rpy="0 -0 0" />
      <geometry>
        <mesh filename="../assemblies/right_arm_hand/meshes/right_spur_1m_24t_drive_3_visual.stl" />
      </geometry>
      <material name="spur_1m_24t_drive_3_material">
        <color rgba="0.61568627450980406568 0.81176470588235294379 0.92941176470588238168 1.0" />
      </material>
    </visual>
    <inertial>
      <origin xyz="-7.724257319833945864e-15 -1.2135702417639766747e-16 0.0047949116178401460231" rpy="0 0 0" />
      <mass value="0.0032000000000000001533" />
      <inertia ixx="1.4019331346159885055e-07" ixy="1.6002410054600855339e-15" ixz="-1.9540791723013520655e-37" iyy="1.4019331260388783538e-07" iyz="7.8971612067142880027e-37" izz="2.3838919844264060647e-07" />
    </inertial>
  </link>

  <joint name="right_wrist_roll_drive" type="revolute">
    <origin xyz="-1.5244304429895549902e-10 0.024000000358071205131 -0.0080000000000011832479" rpy="-2.7654003188110425226e-15 2.9457521138105151042e-15 -1.5707963267949167641" />
    <parent link="2xl430_gears_6" />
    <child link="spur_1m_24t_drive_6" />
    <axis xyz="0 0 1" />
    <limit effort="1" velocity="20" lower="-1.570796326794896558" upper="1.570796326794896558" />
    <joint_properties friction="0.0" />
  </joint>

  <link name="hand_2">
    <visual>
      <origin xyz="0 0 0" rpy="0 -0 0" />
      <geometry>
        <mesh filename="../assemblies/right_arm_hand/meshes/right_hand_visual.stl" />
      </geometry>
      <material name="hand_material">
        <color rgba="0.61568627450980395466 0.81176470588235294379 0.92941176470588238168 1.0" />
      </material>
    </visual>
    <collision>
      <origin xyz="0 0 0" rpy="0 -0 0" />
      <geometry>
        <mesh filename="../assemblies/right_arm_hand/meshes/right_hand_collision.stl" />
      </geometry>
    </collision>
    <inertial>
      <origin xyz="-4.3038382212369557027e-08 0.049723778585225204829 -0.020066427994614350477" rpy="0 0 0" />
      <mass value="0.01700000000000000816" />
      <inertia ixx="9.4921414617707132477e-06" ixy="1.5549215897341499989e-11" ixz="1.0809694196525068125e-11" iyy="4.0745028295219388515e-06" iyz="2.471940855988801139e-07" izz="6.66238595229636054e-06" />
    </inertial>
  </link>

  <joint name="right_wrist_pitch" type="revolute">
    <origin xyz="0.019000000000001918132 -3.5806760334544662783e-10 -0.027000000152449927376" rpy="3.1415926535897029659 -1.5707963267947193664 0" />
    <parent link="2xl430_gears_6" />
    <child link="hand_2" />
    <axis xyz="0 0 1" />
    <limit effort="1" velocity="20" lower="-1.570796326794896558" upper="1.570796326794896558" />
    <joint_properties friction="0.0" />
  </joint>

  <link name="wrist_bearing_plate_2">
    <visual>
      <origin xyz="0 0 0" rpy="0 -0 0" />
      <geometry>
        <mesh filename="../assemblies/right_arm_hand/meshes/right_wrist_bearing_plate_visual.stl" />
      </geometry>
      <material name="wrist_bearing_plate_material">
        <color rgba="0.64496316278892629192 0.69011804996940528945 0.71706771073555886087 1.0" />
      </material>
    </visual>
    <inertial>
      <origin xyz="-0.0075896393545961402319 -0.015499999999999980807 -0.0018386110045718391959" rpy="0 0 0" />
      <mass value="0.0049000367468305548388" />
      <inertia ixx="4.9747313520140141657e-07" ixy="1.2906283815271413783e-22" ixz="1.8097509420524789636e-08" iyy="7.1295025627582205553e-07" iyz="-1.4302832275274936878e-22" izz="1.1926297952291895432e-06" />
    </inertial>
  </link>

  <joint name="right_wrist_pitch_fixed" type="fixed">
    <origin xyz="0.015500000000003956793 4.5519144009631418157e-15 -0.045000000000003870237" rpy="-3.552713678787178252e-15 1.2051470932306258524e-13 -1.570796326794896558" />
    <parent link="2xl430_gears_6" />
    <child link="wrist_bearing_plate_2" />
    <axis xyz="0 0 1" />
    <limit effort="1" velocity="20" />
    <joint_properties friction="0.0" />
  </joint>

  <joint name="right_wrist_roll_driven" type="revolute">
    <origin xyz="2.7755575615628913511e-17 0 -0.0015999999999999972577" rpy="-5.61028737291082927e-15 5.3290705182036772791e-15 1.57079632679489678" />
    <parent link="spur_1m_24t_driven_6" />
    <child link="2xl430_gears_6" />
    <axis xyz="0 0 1" />
    <limit effort="1" velocity="20" lower="-1.570796326794896558" upper="1.570796326794896558" />
    <joint_properties friction="0.0" />
  </joint>

  <joint name="right_wrist_roll_fixed" type="fixed">
    <origin xyz="3.4694469519536141888e-18 -0.025299999999999996103 -0.051999999999999990674" rpy="1.5707963267949205388 1.570796326794896558 0" />
    <parent link="elb_yaw_link_2" />
    <child link="spur_1m_24t_driven_6" />
    <axis xyz="0 0 1" />
    <limit effort="1" velocity="20" />
    <joint_properties friction="0.0" />
  </joint>

  <joint name="right_elbow_yaw_fixed" type="fixed">
    <origin xyz="-3.4694469519536141888e-18 -1.5777218104420236108e-30 0.0015999999999999764411" rpy="-3.1415926535897891192 -8.3149610451184695905e-31 2.7073084493379207714e-30" />
    <parent link="spur_1m_24t_driven_5" />
    <child link="elb_yaw_link_2" />
    <axis xyz="0 0 1" />
    <limit effort="1" velocity="20" />
    <joint_properties friction="0.0" />
  </joint>

  <joint name="right_elbow_yaw_driven" type="revolute">
    <origin xyz="-3.5807111442576200488e-10 -0.027000000152451464341 -0.019000000000003632039" rpy="1.570796326794921427 1.0192981807050532901e-13 -4.32129208184743122e-14" />
    <parent link="2xl430_gears_5" />
    <child link="spur_1m_24t_driven_5" />
    <axis xyz="0 0 1" />
    <limit effort="1" velocity="20" lower="-1.570796326794896558" upper="1.570796326794896558" />
    <joint_properties friction="0.0" />
  </joint>

  <joint name="right_elbow_roll" type="revolute">
    <origin xyz="-2.2898349882893853646e-16 -0.019000000000000173001 -0.058999999999999837297" rpy="1.57079632679489678 -1.1224323958578838097e-14 -5.9062164171655744588e-15" />
    <parent link="sho_yaw_link_2" />
    <child link="2xl430_gears_5" />
    <axis xyz="0 0 1" />
    <limit effort="1" velocity="20" lower="-1.570796326794896558" upper="1.570796326794896558" />
    <joint_properties friction="0.0" />
  </joint>

  <joint name="right_sho_yaw_fixed" type="fixed">
    <origin xyz="3.4694469519536141888e-18 0 0.0016000000000000076661" rpy="-3.1415926535897917837 7.3983136435179850071e-16 1.4710455076273652726e-15" />
    <parent link="spur_1m_24t_driven_4" />
    <child link="sho_yaw_link_2" />
    <axis xyz="0 0 1" />
    <limit effort="1" velocity="20" />
    <joint_properties friction="0.0" />
  </joint>

  <joint name="right_sho_yaw_driven" type="revolute">
    <origin xyz="-3.5806675333094339919e-10 -0.027000000152447987956 -0.019000000000004509809" rpy="1.5707963267949396347 -3.4289578266172945506e-14 -6.6930782579143983011e-15" />
    <parent link="2xl430_gears_4" />
    <child link="spur_1m_24t_driven_4" />
    <axis xyz="0 0 1" />
    <limit effort="1" velocity="20" lower="-1.570796326794896558" upper="1.570796326794896558" />
    <joint_properties friction="0.0" />
  </joint>

  <joint name="right_sho_roll" type="revolute">
    <origin xyz="-0.01899999999999998565 0.0010000000000000112965 0.027000000000000013572" rpy="3.141592653589793116 1.570796326794896558 0" />
    <parent link="sho_pitch_link_2" />
    <child link="2xl430_gears_4" />
    <axis xyz="0 0 1" />
    <limit effort="1" velocity="20" lower="-1.570796326794896558" upper="0" />
    <joint_properties friction="0.0" />
  </joint>


</robot>