<robot name="toddlerbot">
  <mujoco>
    <compiler strippath="false" balanceinertia="true" discardvisual="false" />
  </mujoco>
  <link name="torso">
    <visual>
      <origin xyz="0 0 0" rpy="0 -0 0" />
      <geometry>
        <mesh filename="../assemblies/toddlerbot/meshes/torso_visual.stl" />
      </geometry>
      <material name="torso_material">
        <color rgba="0.61978521215541182432 0.80497509985632864637 0.91238666069265506042 1.0" />
      </material>
    </visual>
    <inertial>
      <origin xyz="-0.017582789998871067166 -0.00088924128506133025968 0.066328103881054270574" rpy="0 0 0" />
      <mass value="0.38210896478124972697" />
      <inertia ixx="0.00097913100143531286122" ixy="1.3687542665749137009e-05" ixz="5.3060955780646105681e-05" iyy="0.00088767318813584355705" iyz="-1.8064914536012934021e-05" izz="0.00068582374333484887041" />
    </inertial>
  </link>

  <link name="spur_1m_20t">
    <visual>
      <origin xyz="0 0 0" rpy="0 -0 0" />
      <geometry>
        <mesh filename="../assemblies/toddlerbot/meshes/spur_1m_20t_visual.stl" />
      </geometry>
      <material name="spur_1m_20t_material">
        <color rgba="0.64705882352941190838 0.64705882352941190838 0.64705882352941190838 1.0" />
      </material>
    </visual>
    <inertial>
      <origin xyz="-5.0947794673102296609e-18 6.23162891085252905e-18 -0.0033745971730663112953" rpy="0 0 0" />
      <mass value="0.0015534950290892282111" />
      <inertia ixx="4.4726508287871806238e-08" ixy="6.0398339042765388102e-24" ixz="2.7597381312606824945e-39" iyy="4.4726508287871793003e-08" iyz="-4.880475641083096215e-38" izz="7.9558906764902019844e-08" />
    </inertial>
  </link>

  <joint name="neck_yaw_drive" type="revolute">
    <origin xyz="-0.004999999999999059884 -1.8020791195763170554e-16 0.12248651076281816263" rpy="-3.1415926535897913396 1.7995135580561967136e-15 9.6455933634066887197e-16" />
    <parent link="torso" />
    <child link="spur_1m_20t" />
    <axis xyz="0 0 1" />
    <limit effort="1" velocity="20" lower="-3.141592653589793116" upper="3.141592653589793116" />
    <joint_properties friction="0.0" />
  </joint>

  <link name="neck_yaw_link">
    <visual>
      <origin xyz="0 0 0" rpy="0 -0 0" />
      <geometry>
        <mesh filename="../assemblies/toddlerbot/meshes/neck_yaw_link_visual.stl" />
      </geometry>
      <material name="neck_yaw_link_material">
        <color rgba="0.33636252417476658616 0.48680769190259876034 0.74976123534949778993 1.0" />
      </material>
    </visual>
    <inertial>
      <origin xyz="2.7291286461380542924e-05 0.00019798992283539501949 -0.011527412037194843461" rpy="0 0 0" />
      <mass value="0.0085168305947458267796" />
      <inertia ixx="1.0407116999274384252e-06" ixy="-2.4210150464765691778e-11" ixz="4.7246803220845781133e-10" iyy="1.1240009954110494879e-06" iyz="3.0834841754646663444e-08" izz="3.1587565167292071285e-07" />
    </inertial>
  </link>

  <link name="neck_pitch_link">
    <visual>
      <origin xyz="0 0 0" rpy="0 -0 0" />
      <geometry>
        <mesh filename="../assemblies/toddlerbot/meshes/neck_pitch_link_visual.stl" />
      </geometry>
      <material name="neck_pitch_link_material">
        <color rgba="0.75175531149912755424 0.80237790269364173135 0.88100511756510224703 1.0" />
      </material>
    </visual>
    <inertial>
      <origin xyz="-0.0033208985050365326386 -0.033447827507434774175 -0.00017266927552015304834" rpy="0 0 0" />
      <mass value="0.10851928601941274177" />
      <inertia ixx="7.4643011916861726944e-05" ixy="1.9512994501134157789e-06" ixz="2.6631618432505425465e-06" iyy="6.1956827409922899243e-05" iyz="-1.1454163205103217525e-05" izz="2.7012883362027665534e-05" />
    </inertial>
  </link>

  <link name="spur_gear_(13_teeth)">
    <visual>
      <origin xyz="0 0 0" rpy="0 -0 0" />
      <geometry>
        <mesh filename="../assemblies/toddlerbot/meshes/spur_gear_(13_teeth)_visual.stl" />
      </geometry>
      <material name="spur_gear_(13_teeth)_material">
        <color rgba="0.64705882352941179736 0.64705882352941179736 0.64705882352941179736 1.0" />
      </material>
    </visual>
    <inertial>
      <origin xyz="1.039987334203130658e-09 2.390520682198548835e-10 -0.0092751511485596356554" rpy="0 0 0" />
      <mass value="0.00081469437497230855032" />
      <inertia ixx="2.0244839552178298687e-08" ixy="-2.9046301772392211175e-15" ixz="8.2976066069888565589e-15" iyy="2.0244841689973771385e-08" iyz="-1.3142117784811047164e-15" izz="1.8905472907863310999e-08" />
    </inertial>
  </link>

  <joint name="neck_pitch_drive" type="revolute">
    <origin xyz="-1.4571677198205179593e-16 -0.015650000000000330314 0.0087999999999993777644" rpy="-2.1434555572207676319e-16 -1.5880065549567459396e-15 1.570796326794896558" />
    <parent link="neck_pitch_link" />
    <child link="spur_gear_(13_teeth)" />
    <axis xyz="0 0 1" />
    <limit effort="1" velocity="20" lower="-1.570796326794896558" upper="1.570796326794896558" />
    <joint_properties friction="0.0" />
  </joint>

  <joint name="neck_pitch_driven" type="revolute">
    <origin xyz="3.7500079430596855445e-10 0.0051500000614755261225 -0.02749999999999992728" rpy="1.57079632679489678 4.0384474451367016523e-16 -3.141592653589793116" />
    <parent link="neck_yaw_link" />
    <child link="neck_pitch_link" />
    <axis xyz="0 0 1" />
    <limit effort="1" velocity="20" lower="-1.570796326794896558" upper="1.570796326794896558" />
    <joint_properties friction="0.0" />
  </joint>

  <joint name="neck_yaw_driven" type="revolute">
    <origin xyz="0.016000000000001915468 1.4752314067929373936e-17 0.12348651076281796923" rpy="-3.141592653589793116 -2.1972867704039169433e-15 -3.1415926535897926719" />
    <parent link="torso" />
    <child link="neck_yaw_link" />
    <axis xyz="0 0 1" />
    <limit effort="1" velocity="20" lower="-3.141592653589793116" upper="3.141592653589793116" />
    <joint_properties friction="0.0" />
  </joint>

  <link name="waist_gears">
    <visual>
      <origin xyz="0 0 0" rpy="0 -0 0" />
      <geometry>
        <mesh filename="../assemblies/toddlerbot/meshes/waist_gears_visual.stl" />
      </geometry>
      <material name="waist_gears_material">
        <color rgba="0.2705751638183052088 0.53648836590125015267 0.70305495274644791426 1.0" />
      </material>
    </visual>
    <inertial>
      <origin xyz="6.546945446268474082e-08 -5.678589769108444202e-10 -0.012726165583898677025" rpy="0 0 0" />
      <mass value="0.023315805669179824611" />
      <inertia ixx="6.9043104388291928151e-06" ixy="-1.8428638769603772386e-11" ixz="9.9668712610669700131e-13" iyy="1.162409197167636598e-06" iyz="-3.3260430300288233958e-10" izz="6.8701920560919842564e-06" />
    </inertial>
  </link>

  <link name="waist_link">
    <visual>
      <origin xyz="0 0 0" rpy="0 -0 0" />
      <geometry>
        <mesh filename="../assemblies/toddlerbot/meshes/waist_link_visual.stl" />
      </geometry>
      <material name="waist_link_material">
        <color rgba="0.63066856640767576803 0.67759035867951045162 0.66849819411858013574 1.0" />
      </material>
    </visual>
    <inertial>
      <origin xyz="-7.8326157945834567194e-07 -0.026309055188168655598 0.029773273854826105139" rpy="0 0 0" />
      <mass value="0.15193452399186060942" />
      <inertia ixx="6.3853955317574341826e-05" ixy="6.7244006991677519528e-10" ixz="3.1782521385896500694e-06" iyy="0.000185540673502072054" iyz="-3.2622478832003326383e-06" izz="0.00014578323476960403592" />
    </inertial>
  </link>

  <link name="spiral_bevel_1m_14t_30deg">
    <visual>
      <origin xyz="0 0 0" rpy="0 -0 0" />
      <geometry>
        <mesh filename="../assemblies/toddlerbot/meshes/spiral_bevel_1m_14t_30deg_visual.stl" />
      </geometry>
      <material name="spiral_bevel_1m_14t_30deg_material">
        <color rgba="0.64705882352941179736 0.64705882352941179736 0.64705882352941179736 1.0" />
      </material>
    </visual>
    <inertial>
      <origin xyz="8.2641075233036431769e-10 3.4055789872172725907e-10 0.0068612577407481719488" rpy="0 0 0" />
      <mass value="0.00067997563436136246491" />
      <inertia ixx="1.2174575798018973838e-08" ixy="3.8216073728371227098e-18" ixz="4.720454783863198132e-16" iyy="1.2174575801813731073e-08" iyz="-2.618409774997137937e-16" izz="1.3178653206314311711e-08" />
    </inertial>
  </link>

  <joint name="waist_act_1" type="revolute">
    <origin xyz="3.5815341505539062119e-17 -0.019600000000000016714 0.012750000000000042549" rpy="-1.570796326794896336 -1.5707963267948215069 0" />
    <parent link="waist_link" />
    <child link="spiral_bevel_1m_14t_30deg" />
    <axis xyz="0 0 1" />
    <limit effort="1" velocity="20" lower="-6.283185307179586232" upper="6.283185307179586232" />
    <joint_properties friction="0.0" />
  </joint>

  <link name="spiral_bevel_1m_14t_30deg_2">
    <visual>
      <origin xyz="0 0 0" rpy="0 -0 0" />
      <geometry>
        <mesh filename="../assemblies/toddlerbot/meshes/spiral_bevel_1m_14t_30deg_2_visual.stl" />
      </geometry>
      <material name="spiral_bevel_1m_14t_30deg_2_material">
        <color rgba="0.64705882352941179736 0.64705882352941179736 0.64705882352941179736 1.0" />
      </material>
    </visual>
    <inertial>
      <origin xyz="7.2990964661290291815e-10 5.1591309333227129234e-10 0.0068612577407481710814" rpy="0 0 0" />
      <mass value="0.00067997563436136246491" />
      <inertia ixx="1.2174575796548749635e-08" ixy="2.6199053431044343109e-18" ixz="5.1847541160688376365e-16" iyy="1.2174575803283976783e-08" iyz="-1.5023607679690313333e-16" izz="1.3178653206314315019e-08" />
    </inertial>
  </link>

  <joint name="waist_act_2" type="revolute">
    <origin xyz="-6.3212258568462825292e-16 -0.019600000000000079164 0.032750000000000834" rpy="-1.5707963267948976682 -1.3463968515393018865 1.5503953316521244903e-14" />
    <parent link="waist_link" />
    <child link="spiral_bevel_1m_14t_30deg_2" />
    <axis xyz="0 0 1" />
    <limit effort="1" velocity="20" lower="-6.283185307179586232" upper="6.283185307179586232" />
    <joint_properties friction="0.0" />
  </joint>

  <link name="spur_gear_19_teeth">
    <visual>
      <origin xyz="0 0 0" rpy="0 -0 0" />
      <geometry>
        <mesh filename="../assemblies/toddlerbot/meshes/spur_gear_19_teeth_visual.stl" />
      </geometry>
      <material name="spur_gear_19_teeth_material">
        <color rgba="0.61568627450980395466 0.81176470588235294379 0.92941176470588238168 1.0" />
      </material>
    </visual>
    <inertial>
      <origin xyz="-4.9156135350294024201e-09 9.006087406040677985e-10 -0.0045295192537419936424" rpy="0 0 0" />
      <mass value="0.0010993711450650535313" />
      <inertia ixx="2.9215018435433082044e-08" ixy="2.5903313772733109345e-16" ixz="-8.4242612451073836103e-15" iyy="2.9215021540034058468e-08" iyz="1.5226232382724447964e-15" izz="4.5709977027671368266e-08" />
    </inertial>
  </link>

  <joint name="left_hip_yaw_drive" type="revolute">
    <origin xyz="-0.036999999999999179379 -0.037100000000004823564 0.039500000000000423661" rpy="-1.5707963267950579844 5.71102443800098102e-13 2.6906455702027046663e-13" />
    <parent link="waist_link" />
    <child link="spur_gear_19_teeth" />
    <axis xyz="0 0 1" />
    <limit effort="1" velocity="20" lower="-1.570796326794896558" upper="1.570796326794896558" />
    <joint_properties friction="0.0" />
  </joint>

  <link name="spur_gear_21_teeth">
    <visual>
      <origin xyz="0 0 0" rpy="0 -0 0" />
      <geometry>
        <mesh filename="../assemblies/toddlerbot/meshes/spur_gear_21_teeth_visual.stl" />
      </geometry>
      <material name="spur_gear_21_teeth_material">
        <color rgba="0.61568627450980395466 0.81176470588235294379 0.92941176470588238168 1.0" />
      </material>
    </visual>
    <inertial>
      <origin xyz="-4.7814841746391350153e-10 1.2610016837558293022e-12 -0.0024944618616143366362" rpy="0 0 0" />
      <mass value="0.0010063046528317972673" />
      <inertia ixx="3.1842855421068481665e-08" ixy="2.1452075797961539371e-37" ixz="-1.1964366566353854637e-38" iyy="3.1842855426953785697e-08" iyz="1.1823805759568236218e-38" izz="5.9529380586728028132e-08" />
    </inertial>
  </link>

  <joint name="left_leg_fixed" type="fixed">
    <origin xyz="-4.336808689942017736e-19 -1.3877787807814456755e-17 -0.004999999999999997502" rpy="-1.0439449364097525548e-14 -1.9757585399875400437e-31 5.7250078249404190712e-30" />
    <parent link="spur_gear_21_teeth" />
    <child link="hip_yaw_link" />
    <axis xyz="0 0 1" />
    <limit effort="1" velocity="20" />
    <joint_properties friction="0.0" />
  </joint>

  <joint name="left_hip_yaw_driven" type="revolute">
    <origin xyz="-0.037000000000000005107 -0.041100000000000080913 0.019500000000000003442" rpy="-1.5707963267948841235 1.5707963267948932273 0" />
    <parent link="waist_link" />
    <child link="spur_gear_21_teeth" />
    <axis xyz="0 0 1" />
    <limit effort="1" velocity="20" lower="-1.570796326794896558" upper="1.570796326794896558" />
    <joint_properties friction="0.0" />
  </joint>

  <link name="spur_gear_19_teeth_2">
    <visual>
      <origin xyz="0 0 0" rpy="0 -0 0" />
      <geometry>
        <mesh filename="../assemblies/toddlerbot/meshes/spur_gear_19_teeth_2_visual.stl" />
      </geometry>
      <material name="spur_gear_19_teeth_2_material">
        <color rgba="0.61568627450980395466 0.81176470588235294379 0.92941176470588238168 1.0" />
      </material>
    </visual>
    <inertial>
      <origin xyz="-4.9156135419682971512e-09 9.0060874060406821209e-10 -0.0045295192537419867035" rpy="0 0 0" />
      <mass value="0.0010993711450650535313" />
      <inertia ixx="2.9215018435433095279e-08" ixy="2.5903313743443320232e-16" ixz="-8.424261245107385188e-15" iyy="2.9215021540034071703e-08" iyz="1.5226232382724451908e-15" izz="4.5709977027671368266e-08" />
    </inertial>
  </link>

  <joint name="right_hip_yaw_drive" type="revolute">
    <origin xyz="0.037000000000000358991 -0.037100000000003852119 0.039500000000000069778" rpy="-1.5707963267949709429 3.0776023904592405576e-13 2.7738547283800353153e-13" />
    <parent link="waist_link" />
    <child link="spur_gear_19_teeth_2" />
    <axis xyz="0 0 1" />
    <limit effort="1" velocity="20" lower="-1.570796326794896558" upper="1.570796326794896558" />
    <joint_properties friction="0.0" />
  </joint>

  <link name="spur_gear_21_teeth_2">
    <visual>
      <origin xyz="0 0 0" rpy="0 -0 0" />
      <geometry>
        <mesh filename="../assemblies/toddlerbot/meshes/spur_gear_21_teeth_2_visual.stl" />
      </geometry>
      <material name="spur_gear_21_teeth_2_material">
        <color rgba="0.61568627450980395466 0.81176470588235294379 0.92941176470588238168 1.0" />
      </material>
    </visual>
    <inertial>
      <origin xyz="-4.7814841746391350153e-10 -1.2610155615436371167e-12 -0.0025055381383856678047" rpy="0 0 0" />
      <mass value="0.0010063046528317972673" />
      <inertia ixx="3.1842855421068481665e-08" ixy="1.560614116831243518e-38" ixz="2.0210367250077923995e-39" iyy="3.1842855426953785697e-08" iyz="5.2356557841516804612e-39" izz="5.9529380586728028132e-08" />
    </inertial>
  </link>

  <joint name="right_leg_fixed" type="fixed">
    <origin xyz="0 0 -0.004999999999999997502" rpy="1.0732181508787092545e-15 5.1822669723995480778e-16 -1.6653345369374924824e-16" />
    <parent link="spur_gear_21_teeth_2" />
    <child link="hip_yaw_link_2" />
    <axis xyz="0 0 1" />
    <limit effort="1" velocity="20" />
    <joint_properties friction="0.0" />
  </joint>

  <joint name="right_hip_yaw_driven" type="revolute">
    <origin xyz="0.037000000000000005107 -0.041100000000000011524 0.019500000000000010381" rpy="-1.5707963267948983344 1.5707963267948950037 0" />
    <parent link="waist_link" />
    <child link="spur_gear_21_teeth_2" />
    <axis xyz="0 0 1" />
    <limit effort="1" velocity="20" lower="-1.570796326794896558" upper="1.570796326794896558" />
    <joint_properties friction="0.0" />
  </joint>

  <joint name="waist_roll" type="revolute">
    <origin xyz="-6.2255683189587157383e-20 0.022707865260692461362 -0.013000000000000004607" rpy="1.5707963267948952257 1.2017992026080351615e-15 4.2181022606678868535e-16" />
    <parent link="waist_gears" />
    <child link="waist_link" />
    <axis xyz="0 0 1" />
    <limit effort="1" velocity="20" lower="-0.52359877559829881566" upper="0.52359877559829881566" />
    <joint_properties friction="0.0" />
  </joint>

  <joint name="waist_yaw" type="revolute">
    <origin xyz="-1.7347234759768070944e-18 -9.8607613152626475676e-32 0" rpy="2.0946901476030943553e-15 7.1861600448343401911e-16 -1.5707963267948228392" />
    <parent link="torso" />
    <child link="waist_gears" />
    <axis xyz="0 0 1" />
    <limit effort="1" velocity="20" lower="-1.570796326794896558" upper="1.570796326794896558" />
    <joint_properties friction="0.0" />
  </joint>

  <joint name="left_arm_fixed" type="fixed">
    <origin xyz="0.0010000000000009051128 0.049000000000000341893 0.11948651076281792405" rpy="-5.9230088976703815107e-16 1.7322096859285544219e-15 1.6762794059802379347e-29" />
    <parent link="torso" />
    <child link="xc430" />
    <axis xyz="0 0 1" />
    <limit effort="1" velocity="20" />
    <joint_properties friction="0.0" />
  </joint>

  <joint name="right_arm_fixed" type="fixed">
    <origin xyz="0.0010000000000010308802 -0.049000000000000321076 0.11948651076281791017" rpy="-5.9230088976591895466e-16 1.732209685967738918e-15 1.6762794059934078982e-29" />
    <parent link="torso" />
    <child link="xc430_2" />
    <axis xyz="0 0 1" />
    <limit effort="1" velocity="20" />
    <joint_properties friction="0.0" />
  </joint>


  <link name="hip_yaw_link">
    <visual>
      <origin xyz="0 0 0" rpy="0 -0 0" />
      <geometry>
        <mesh filename="../assemblies/left_leg_XM430/meshes/left_hip_yaw_link_visual.stl" />
      </geometry>
      <material name="hip_yaw_link_material">
        <color rgba="0.61568627450980395466 0.81176470588235294379 0.92941176470588238168 1.0" />
      </material>
    </visual>
    <inertial>
      <origin xyz="-2.8295513388461080681e-19 -3.4237970957901977335e-19 -0.0098390489054829086829" rpy="0 0 0" />
      <mass value="0.017999999999999991701" />
      <inertia ixx="2.6385033891442532385e-06" ixy="0" ixz="0" iyy="7.6596731957046890345e-06" iyz="0" izz="7.7220708070894752896e-06" />
    </inertial>
  </link>

  <link name="hip_roll_link">
    <visual>
      <origin xyz="0 0 0" rpy="0 -0 0" />
      <geometry>
        <mesh filename="../assemblies/left_leg_XM430/meshes/left_hip_roll_link_visual.stl" />
      </geometry>
      <material name="hip_roll_link_material">
        <color rgba="0.51698661238356036218 0.50347815951093466413 0.49050589017722012741 1.0" />
      </material>
    </visual>
    <inertial>
      <origin xyz="-0.01199984958218530337 -0.00049598090794046492246 -0.018504111838597580436" rpy="0 0 0" />
      <mass value="0.10699970659110667748" />
      <inertia ixx="2.2075996228675286354e-05" ixy="-4.5005801828807199265e-08" ixz="-4.5362214344039572237e-08" iyy="2.9866686933523838834e-05" iyz="-5.5606319466519240051e-07" izz="2.9866720157736157201e-05" />
    </inertial>
  </link>

  <link name="left_hip_pitch_link_xm430">
    <visual>
      <origin xyz="0 0 0" rpy="0 -0 0" />
      <geometry>
        <mesh filename="../assemblies/left_leg_XM430/meshes/left_hip_pitch_link_xm430_visual.stl" />
      </geometry>
      <material name="left_hip_pitch_link_xm430_material">
        <color rgba="0.58789271125196740364 0.76961381353217661605 0.89677560122075017368 1.0" />
      </material>
    </visual>
    <inertial>
      <origin xyz="-0.0021034922210874298226 -0.056433529773950774633 -0.01878212058974302115" rpy="0 0 0" />
      <mass value="0.035548688791081778371" />
      <inertia ixx="4.7516856109358680967e-05" ixy="3.1522442711494422845e-07" ixz="2.5035892596237971484e-07" iyy="1.1480134512562668991e-05" iyz="-3.2345708465544602866e-07" izz="4.5084071722891830574e-05" />
    </inertial>
  </link>

  <link name="left_calf_link">
    <visual>
      <origin xyz="0 0 0" rpy="0 -0 0" />
      <geometry>
        <mesh filename="../assemblies/left_leg_XM430/meshes/left_calf_link_visual.stl" />
      </geometry>
      <material name="left_calf_link_material">
        <color rgba="0.61177930930733648296 0.71653254923097853268 0.74989274724786558757 1.0" />
      </material>
    </visual>
    <inertial>
      <origin xyz="0.0011880880234995069324 -0.04964306841760212502 -0.0098634853143295415229" rpy="0 0 0" />
      <mass value="0.079607494529051470167" />
      <inertia ixx="4.8048473174226002242e-05" ixy="3.5190650833675678061e-06" ixz="3.9918574956050822519e-07" iyy="1.4293033116537747813e-05" iyz="4.8859952267608034486e-07" izz="5.1177637188996120943e-05" />
    </inertial>
  </link>

  <link name="ank_pitch_link">
    <visual>
      <origin xyz="0 0 0" rpy="0 -0 0" />
      <geometry>
        <mesh filename="../assemblies/left_leg_XM430/meshes/left_ank_pitch_link_visual.stl" />
      </geometry>
      <material name="ank_pitch_link_material">
        <color rgba="0.63189161126160264814 0.7266866879354088038 0.78356373393969258601 1.0" />
      </material>
    </visual>
    <inertial>
      <origin xyz="0.00059528282565925356995 -4.0269680598773380526e-08 7.7616089895315615493e-08" rpy="0 0 0" />
      <mass value="0.0042238381753791614387" />
      <inertia ixx="3.9782741364683723499e-07" ixy="-1.6834347673011815484e-13" ixz="2.0919187769527529349e-14" iyy="4.3705254067427603978e-07" iyz="-1.6428821984567370687e-12" izz="8.8858574534605604009e-08" />
    </inertial>
  </link>

  <link name="ank_roll_link">
    <visual>
      <origin xyz="0 0 0" rpy="0 -0 0" />
      <geometry>
        <mesh filename="../assemblies/left_leg_XM430/meshes/left_ank_roll_link_visual.stl" />
      </geometry>
      <material name="ank_roll_link_material">
        <color rgba="0.61568627450980395466 0.81176470588235294379 0.92941176470588238168 1.0" />
      </material>
    </visual>
    <inertial>
      <origin xyz="-1.3268572459728960309e-07 0.026796353429500454485 -0.0010526854006037440065" rpy="0 0 0" />
      <mass value="0.024800000000000002598" />
      <inertia ixx="1.9846878556458577087e-05" ixy="3.3200060665895135136e-11" ixz="1.9151591849061369162e-11" iyy="1.8695132008820605535e-05" iyz="-1.6314461615565737141e-06" izz="5.1708394998630570447e-06" />
    </inertial>
  </link>

  <link name="ank_rr_link">
    <visual>
      <origin xyz="0 0 0" rpy="0 -0 0" />
      <geometry>
        <mesh filename="../assemblies/left_leg_XM430/meshes/left_ank_rr_link_visual.stl" />
      </geometry>
      <material name="ank_rr_link_material">
        <color rgba="0.61568627450980395466 0.81176470588235294379 0.92941176470588238168 1.0" />
      </material>
    </visual>
    <inertial>
      <origin xyz="-4.5249610960602496587e-05 0.0063096429836314582573 -3.6742706802840567721e-18" rpy="0 0 0" />
      <mass value="0.0014500000000000001169" />
      <inertia ixx="2.9739579267716150033e-08" ixy="2.4213146797978020574e-10" ixz="3.5523394884459888905e-14" iyy="2.7430027724071963673e-08" iyz="-4.2623487632628579504e-32" izz="4.2921949116163685671e-08" />
    </inertial>
  </link>

  <link name="ank_motor_rod_long">
    <visual>
      <origin xyz="0 0 0" rpy="0 -0 0" />
      <geometry>
        <mesh filename="../assemblies/left_leg_XM430/meshes/left_ank_motor_rod_long_visual.stl" />
      </geometry>
      <material name="ank_motor_rod_long_material">
        <color rgba="0.63549975559783222767 0.70774393017020453822 0.75109043491362792455 1.0" />
      </material>
    </visual>
    <inertial>
      <origin xyz="2.4855089041386722493e-10 0.03455901997406223003 0.0009385170487845105429" rpy="0 0 0" />
      <mass value="0.0021712857268636710437" />
      <inertia ixx="8.5350290058000506697e-07" ixy="1.4884244339274097944e-14" ixz="4.5749525025637216644e-11" iyy="1.3237321792739608807e-08" iyz="-4.3668910960845996537e-09" izz="8.5812217519451853453e-07" />
    </inertial>
  </link>

  <joint name="left_ank_L_rev_2" type="revolute">
    <origin xyz="-1.4571677198205179593e-16 0.0099999999999997868372 4.8572257327350598644e-17" rpy="-1.5707963267948941155 1.3320366994106946912 -1.5707963267949134334" />
    <parent link="ank_rr_link" />
    <child link="ank_motor_rod_long" />
    <axis xyz="0 0 1" />
    <limit effort="1" velocity="20" lower="-1.570796326794896558" upper="1.570796326794896558" />
    <joint_properties friction="0.0" />
  </joint>

  <joint name="left_ank_L_rev_1" type="revolute">
    <origin xyz="-0.018000000000000012518 0.016000000000000125233 -0.020600000000000000255" rpy="-8.4059225450220432022e-16 5.2239277705698694431e-16 3.1233695685467259828" />
    <parent link="ank_roll_link" />
    <child link="ank_rr_link" />
    <axis xyz="0 0 1" />
    <limit effort="1" velocity="20" lower="-1.570796326794896558" upper="1.570796326794896558" />
    <joint_properties friction="0.0" />
  </joint>

  <link name="ank_rr_link_2">
    <visual>
      <origin xyz="0 0 0" rpy="0 -0 0" />
      <geometry>
        <mesh filename="../assemblies/left_leg_XM430/meshes/left_ank_rr_link_2_visual.stl" />
      </geometry>
      <material name="ank_rr_link_2_material">
        <color rgba="0.61568627450980395466 0.81176470588235294379 0.92941176470588238168 1.0" />
      </material>
    </visual>
    <inertial>
      <origin xyz="-4.524961096060597281e-05 -0.0063096429836314582573 2.0482372833095216031e-19" rpy="0 0 0" />
      <mass value="0.0014500000000000001169" />
      <inertia ixx="2.9739579267716169886e-08" ixy="-2.4213146797978046423e-10" ixz="-3.5523394884459901527e-14" iyy="2.7430027724071963673e-08" iyz="9.9853089481893763557e-32" izz="4.2921949116163685671e-08" />
    </inertial>
  </link>

  <link name="ank_motor_rod_short">
    <visual>
      <origin xyz="0 0 0" rpy="0 -0 0" />
      <geometry>
        <mesh filename="../assemblies/left_leg_XM430/meshes/left_ank_motor_rod_short_visual.stl" />
      </geometry>
      <material name="ank_motor_rod_short_material">
        <color rgba="0.41222606689734719865 0.58339100346020766885 0.8110726643598615837 1.0" />
      </material>
    </visual>
    <inertial>
      <origin xyz="2.6038938586334744884e-10 0.023830465465870892539 0.00090403506359618016151" rpy="0 0 0" />
      <mass value="0.0017000000000000001221" />
      <inertia ixx="3.3153416252670167126e-07" ixy="8.7419771573783562959e-15" ixz="4.574994156764911705e-11" iyy="1.0947363610305765948e-08" iyz="-3.58630986464004565e-09" izz="3.3621340447865331982e-07" />
    </inertial>
  </link>

  <joint name="left_ank_S_rev_2" type="revolute">
    <origin xyz="-6.2450045135165055399e-17 -0.0099999999999998423483 -4.1633363423443370266e-17" rpy="-1.5707963267948958919 -1.2119133862911237731 -1.5707963267948858999" />
    <parent link="ank_rr_link_2" />
    <child link="ank_motor_rod_short" />
    <axis xyz="0 0 1" />
    <limit effort="1" velocity="20" lower="-1.570796326794896558" upper="1.570796326794896558" />
    <joint_properties friction="0.0" />
  </joint>

  <joint name="left_ank_S_rev_1" type="revolute">
    <origin xyz="0.017999999999999995171 0.016000000000000125233 -0.020600000000000007194" rpy="2.3133772225631454961e-16 4.5369818524477751182e-16 0.026118548507388435198" />
    <parent link="ank_roll_link" />
    <child link="ank_rr_link_2" />
    <axis xyz="0 0 1" />
    <limit effort="1" velocity="20" lower="-1.570796326794896558" upper="1.570796326794896558" />
    <joint_properties friction="0.0" />
  </joint>

  <joint name="left_ank_roll" type="revolute">
    <origin xyz="0.0014999999999999969955 -5.5511151231257827021e-17 -1.116728237660069567e-17" rpy="5.4670424773813653591e-26 1.570796326794896558 0" />
    <parent link="ank_pitch_link" />
    <child link="ank_roll_link" />
    <axis xyz="0 0 1" />
    <limit effort="1" velocity="20" lower="-0.785398163397448279" upper="0.785398163397448279" />
    <joint_properties friction="0.0" />
  </joint>

  <joint name="left_ank_pitch" type="revolute">
    <origin xyz="1.7782265719353869385e-16 -0.099999999999999367173 -0.01040000000000083219" rpy="-1.1833532294864106881e-14 4.9479686682726630759e-20 -3.141592653589793116" />
    <parent link="left_calf_link" />
    <child link="ank_pitch_link" />
    <axis xyz="0 0 1" />
    <limit effort="1" velocity="20" lower="-0.785398163397448279" upper="0.95993108859688125456" />
    <joint_properties friction="0.0" />
  </joint>

  <link name="ank_motor_arm">
    <visual>
      <origin xyz="0 0 0" rpy="0 -0 0" />
      <geometry>
        <mesh filename="../assemblies/left_leg_XM430/meshes/left_ank_motor_arm_visual.stl" />
      </geometry>
      <material name="ank_motor_arm_material">
        <color rgba="0.62517751827980905244 0.70593642422614044651 0.75978993426662777555 1.0" />
      </material>
    </visual>
    <inertial>
      <origin xyz="0.014511489101591673254 1.6148638001483031199e-17 0.0040925443765950589997" rpy="0 0 0" />
      <mass value="0.0020595846677894939954" />
      <inertia ixx="2.7591836756521862443e-08" ixy="-2.1221439534222470061e-22" ixz="-3.0270788206594736006e-08" iyy="1.6138599216238408821e-07" iyz="-3.9663336041446003847e-23" izz="1.643783676501625577e-07" />
    </inertial>
  </link>

  <joint name="left_ank_act_1" type="revolute">
    <origin xyz="0.013499999999996521727 -0.044499999999990991206 0.004000000000004368117" rpy="-4.1933768254600954213e-13 -2.2608993309587937077e-13 -0.21173394130242484401" />
    <parent link="left_calf_link" />
    <child link="ank_motor_arm" />
    <axis xyz="0 0 1" />
    <limit effort="1" velocity="20" lower="-1.3089969389957472057" upper="1.3089969389957472057" />
    <joint_properties friction="0.0" />
  </joint>

  <link name="ank_motor_arm_2">
    <visual>
      <origin xyz="0 0 0" rpy="0 -0 0" />
      <geometry>
        <mesh filename="../assemblies/left_leg_XM430/meshes/left_ank_motor_arm_2_visual.stl" />
      </geometry>
      <material name="ank_motor_arm_2_material">
        <color rgba="0.62517751827980905244 0.70593642422614044651 0.75978993426662777555 1.0" />
      </material>
    </visual>
    <inertial>
      <origin xyz="0.014511489101591607334 -1.6909763789032763183e-17 0.0040925443765950589997" rpy="0 0 0" />
      <mass value="0.0020595846677894939954" />
      <inertia ixx="2.7591836756521849208e-08" ixy="1.7247898637471973881e-22" ixz="-3.0270788206594504395e-08" iyy="1.6138599216238257943e-07" iyz="2.1738648046739944409e-23" izz="1.6437836765016112833e-07" />
    </inertial>
  </link>

  <joint name="left_ank_act_2" type="revolute">
    <origin xyz="0.013499999999999821171 -0.064499999999989482413 -0.024800000000000977513" rpy="-3.141592653589404982 8.5681358223374411603e-14 -0.22995607267358961212" />
    <parent link="left_calf_link" />
    <child link="ank_motor_arm_2" />
    <axis xyz="0 0 1" />
    <limit effort="1" velocity="20" lower="-1.3089969389957472057" upper="1.3089969389957472057" />
    <joint_properties friction="0.0" />
  </joint>

  <joint name="left_knee" type="revolute">
    <origin xyz="1.71083466609787999e-16 -0.095999999999999086064 -0.0092000000000000258654" rpy="-1.1991266448696223104e-14 1.4169663141522339643e-15 2.5724847819777364634e-18" />
    <parent link="left_hip_pitch_link_xm430" />
    <child link="left_calf_link" />
    <axis xyz="0 0 1" />
    <limit effort="1" velocity="20" lower="0" upper="1.9198621771937625091" />
    <joint_properties friction="0.0" />
  </joint>

  <joint name="left_hip_pitch" type="revolute">
    <origin xyz="-0.024000000716151929925 -0.01900000015243963683 -0.019000000152454777497" rpy="1.5707963267952702591 1.5707963267945455055 0" />
    <parent link="hip_roll_link" />
    <child link="left_hip_pitch_link_xm430" />
    <axis xyz="0 0 1" />
    <limit effort="1" velocity="20" lower="-1.570796326794896558" upper="1.570796326794896558" />
    <joint_properties friction="0.0" />
  </joint>

  <joint name="left_hip_roll" type="revolute">
    <origin xyz="0.018999999999999999528 -2.8647205520269057584e-18 -0.026000000000000002276" rpy="3.141592653589793116 -1.570796326794896558 0" />
    <parent link="hip_yaw_link" />
    <child link="hip_roll_link" />
    <axis xyz="0 0 1" />
    <limit effort="1" velocity="20" lower="-0.785398163397448279" upper="1.570796326794896558" />
    <joint_properties friction="0.0" />
  </joint>


  <link name="hip_yaw_link_2">
    <visual>
      <origin xyz="0 0 0" rpy="0 -0 0" />
      <geometry>
        <mesh filename="../assemblies/right_leg_XM430/meshes/right_hip_yaw_link_visual.stl" />
      </geometry>
      <material name="hip_yaw_link_material">
        <color rgba="0.61568627450980395466 0.81176470588235294379 0.92941176470588238168 1.0" />
      </material>
    </visual>
    <inertial>
      <origin xyz="-3.7230938669027726335e-20 9.1070873563082211326e-20 -0.0098390489054829121524" rpy="0 0 0" />
      <mass value="0.01799999999999999864" />
      <inertia ixx="2.638503389144253662e-06" ixy="0" ixz="0" iyy="7.6596731957046890345e-06" iyz="0" izz="7.7220708070894769837e-06" />
    </inertial>
  </link>

  <link name="hip_roll_link_2">
    <visual>
      <origin xyz="0 0 0" rpy="0 -0 0" />
      <geometry>
        <mesh filename="../assemblies/right_leg_XM430/meshes/right_hip_roll_link_visual.stl" />
      </geometry>
      <material name="hip_roll_link_material">
        <color rgba="0.51698661238356036218 0.50347815951093466413 0.49050589017722012741 1.0" />
      </material>
    </visual>
    <inertial>
      <origin xyz="-0.011999849582183098537 -0.00049598090794401839508 -0.018504111838595658363" rpy="0 0 0" />
      <mass value="0.10699970659110667748" />
      <inertia ixx="2.2075996228674994975e-05" ixy="-4.5005801829288525738e-08" ixz="-4.5362214342478033911e-08" iyy="2.9866686933523039235e-05" iyz="-5.5606319466522384661e-07" izz="2.9866720157734995072e-05" />
    </inertial>
  </link>

  <link name="right_hip_pitch_link_xm430">
    <visual>
      <origin xyz="0 0 0" rpy="0 -0 0" />
      <geometry>
        <mesh filename="../assemblies/right_leg_XM430/meshes/right_hip_pitch_link_xm430_visual.stl" />
      </geometry>
      <material name="right_hip_pitch_link_xm430_material">
        <color rgba="0.58789271125196762569 0.76961381353217683809 0.89677560122075017368 1.0" />
      </material>
    </visual>
    <inertial>
      <origin xyz="0.0021006649942336115891 -0.056435111435693005588 -0.018782115746167674791" rpy="0 0 0" />
      <mass value="0.035548688791081764493" />
      <inertia ixx="4.7524489027106042293e-05" ixy="-3.1183564733461195226e-07" ixz="-2.5180919440227327518e-07" iyy="1.1474508196147079308e-05" iyz="-3.2448112115126763812e-07" izz="4.5086069259999308047e-05" />
    </inertial>
  </link>

  <link name="right_calf_link">
    <visual>
      <origin xyz="0 0 0" rpy="0 -0 0" />
      <geometry>
        <mesh filename="../assemblies/right_leg_XM430/meshes/right_calf_link_visual.stl" />
      </geometry>
      <material name="right_calf_link_material">
        <color rgba="0.61177930930733637194 0.71653254923097875473 0.74989274724786569859 1.0" />
      </material>
    </visual>
    <inertial>
      <origin xyz="0.0011880884108858846826 0.04964306657501051101 -0.0098634853265742207518" rpy="0 0 0" />
      <mass value="0.079607494529051456289" />
      <inertia ixx="4.8056790185738458413e-05" ixy="-3.5190664140524663194e-06" ixz="3.99185693708931329e-07" iyy="1.4293033414473597795e-05" iyz="-4.8654596308584815844e-07" izz="5.1185953583038384029e-05" />
    </inertial>
  </link>

  <link name="ank_pitch_link_2">
    <visual>
      <origin xyz="0 0 0" rpy="0 -0 0" />
      <geometry>
        <mesh filename="../assemblies/right_leg_XM430/meshes/right_ank_pitch_link_visual.stl" />
      </geometry>
      <material name="ank_pitch_link_material">
        <color rgba="0.63189161126160264814 0.7266866879354088038 0.78356373393969258601 1.0" />
      </material>
    </visual>
    <inertial>
      <origin xyz="0.00059528282565907803762 -4.0269682332179541599e-08 7.7616094724284792329e-08" rpy="0 0 0" />
      <mass value="0.0042238381753791614387" />
      <inertia ixx="3.978274136467431614e-07" ixy="-1.6834347588868364615e-13" ixz="2.0919192129833751745e-14" iyy="4.3705254067416634901e-07" iyz="-1.642882212557527855e-12" izz="8.8858574534590013309e-08" />
    </inertial>
  </link>

  <link name="ank_roll_link_2">
    <visual>
      <origin xyz="0 0 0" rpy="0 -0 0" />
      <geometry>
        <mesh filename="../assemblies/right_leg_XM430/meshes/right_ank_roll_link_visual.stl" />
      </geometry>
      <material name="ank_roll_link_material">
        <color rgba="0.61568627450980395466 0.81176470588235294379 0.92941176470588238168 1.0" />
      </material>
    </visual>
    <inertial>
      <origin xyz="-4.3076724074159488717e-08 0.026796342838297404487 -0.0010522562961590999596" rpy="0 0 0" />
      <mass value="0.024800000000000016476" />
      <inertia ixx="1.9846823873608352578e-05" ixy="8.4559567220819753663e-12" ixz="1.0948936918468670171e-10" iyy="1.8695098548981966332e-05" iyz="-1.6315562466569512042e-06" izz="5.1708532177991958415e-06" />
    </inertial>
  </link>

  <link name="ank_rr_link_3">
    <visual>
      <origin xyz="0 0 0" rpy="0 -0 0" />
      <geometry>
        <mesh filename="../assemblies/right_leg_XM430/meshes/right_ank_rr_link_visual.stl" />
      </geometry>
      <material name="ank_rr_link_material">
        <color rgba="0.61568627450980395466 0.81176470588235294379 0.92941176470588238168 1.0" />
      </material>
    </visual>
    <inertial>
      <origin xyz="-4.524961096059918977e-05 -0.0063096429836314027462 1.9359077708127903688e-19" rpy="0 0 0" />
      <mass value="0.0014499999999999999001" />
      <inertia ixx="2.9739579267716146725e-08" ixy="-2.4213146797977979215e-10" ixz="-3.5523394884522776896e-14" iyy="2.7430027724071957055e-08" iyz="-3.8436473465967602447e-32" izz="4.2921949116163665819e-08" />
    </inertial>
  </link>

  <link name="ank_motor_rod_long_2">
    <visual>
      <origin xyz="0 0 0" rpy="0 -0 0" />
      <geometry>
        <mesh filename="../assemblies/right_leg_XM430/meshes/right_ank_motor_rod_long_visual.stl" />
      </geometry>
      <material name="ank_motor_rod_long_material">
        <color rgba="0.63549975559783222767 0.70774393017020453822 0.75109043491362792455 1.0" />
      </material>
    </visual>
    <inertial>
      <origin xyz="2.4855088453945705867e-10 0.034559019974062271663 0.00093851704878454621315" rpy="0 0 0" />
      <mass value="0.0021712857268636710437" />
      <inertia ixx="8.5350290058000316114e-07" ixy="1.4884244285151247382e-14" ixz="4.5749525025568541266e-11" iyy="1.3237321792739552559e-08" iyz="-4.3668910960860588003e-09" izz="8.581221751945166287e-07" />
    </inertial>
  </link>

  <joint name="right_ank_L_rev_2" type="revolute">
    <origin xyz="-6.9388939039072283776e-18 -0.0099999999999996203037 3.1225022567582527699e-17" rpy="-1.5707963267948887864 -1.3320366994106427327 -1.5707963267948827912" />
    <parent link="ank_rr_link_3" />
    <child link="ank_motor_rod_long_2" />
    <axis xyz="0 0 1" />
    <limit effort="1" velocity="20" lower="-1.570796326794896558" upper="1.570796326794896558" />
    <joint_properties friction="0.0" />
  </joint>

  <joint name="right_ank_L_rev_1" type="revolute">
    <origin xyz="0.017999999999999981293 0.015999999999999847677 -0.020600000000000014133" rpy="6.2884229534673233247e-16 3.939086273962429945e-15 0.018223085042996144817" />
    <parent link="ank_roll_link_2" />
    <child link="ank_rr_link_3" />
    <axis xyz="0 0 1" />
    <limit effort="1" velocity="20" lower="-1.570796326794896558" upper="1.570796326794896558" />
    <joint_properties friction="0.0" />
  </joint>

  <link name="ank_rr_link_4">
    <visual>
      <origin xyz="0 0 0" rpy="0 -0 0" />
      <geometry>
        <mesh filename="../assemblies/right_leg_XM430/meshes/right_ank_rr_link_2_visual.stl" />
      </geometry>
      <material name="ank_rr_link_2_material">
        <color rgba="0.61568627450980395466 0.81176470588235294379 0.92941176470588238168 1.0" />
      </material>
    </visual>
    <inertial>
      <origin xyz="-4.5249610960602638888e-05 0.0063096429836315146358 3.2758561748722918667e-18" rpy="0 0 0" />
      <mass value="0.0014499999999999999001" />
      <inertia ixx="2.9739579267716146725e-08" ixy="2.4213146797977994725e-10" ixz="3.5523394884522776896e-14" iyy="2.7430027724071963673e-08" iyz="1.2033448591719948067e-32" izz="4.2921949116163665819e-08" />
    </inertial>
  </link>

  <link name="ank_motor_rod_short_2">
    <visual>
      <origin xyz="0 0 0" rpy="0 -0 0" />
      <geometry>
        <mesh filename="../assemblies/right_leg_XM430/meshes/right_ank_motor_rod_short_visual.stl" />
      </geometry>
      <material name="ank_motor_rod_short_material">
        <color rgba="0.41222606689734719865 0.58339100346020755783 0.8110726643598615837 1.0" />
      </material>
    </visual>
    <inertial>
      <origin xyz="2.6038940666301772597e-10 0.023830465465870913355 0.00090403506359621951805" rpy="0 0 0" />
      <mass value="0.0017000000000000005558" />
      <inertia ixx="3.315341625266997125e-07" ixy="8.7419770976124397362e-15" ixz="4.5749941567737586601e-11" iyy="1.0947363610305722935e-08" iyz="-3.5863098646405692554e-09" izz="3.3621340447865173163e-07" />
    </inertial>
  </link>

  <joint name="right_ank_S_rev_2" type="revolute">
    <origin xyz="-2.7755575615628913511e-16 0.010000000000000563993 -1.561251128379126385e-16" rpy="-1.5707963267949354158 1.2119133862908570975 -1.5707963267949336394" />
    <parent link="ank_rr_link_4" />
    <child link="ank_motor_rod_short_2" />
    <axis xyz="0 0 1" />
    <limit effort="1" velocity="20" lower="-1.570796326794896558" upper="1.570796326794896558" />
    <joint_properties friction="0.0" />
  </joint>

  <joint name="right_ank_S_rev_1" type="revolute">
    <origin xyz="-0.018000000000000026396 0.016000000000000735856 -0.02059999999999996903" rpy="-4.338977813478965687e-16 1.6392354569195739132e-16 3.1154741050825114357" />
    <parent link="ank_roll_link_2" />
    <child link="ank_rr_link_4" />
    <axis xyz="0 0 1" />
    <limit effort="1" velocity="20" lower="-1.570796326794896558" upper="1.570796326794896558" />
    <joint_properties friction="0.0" />
  </joint>

  <joint name="right_ank_roll" type="revolute">
    <origin xyz="0.0014999999999999924418 2.7755575615628913511e-17 -1.3877787807814456755e-17" rpy="3.141592653589793116 -1.570796326794896336 0" />
    <parent link="ank_pitch_link_2" />
    <child link="ank_roll_link_2" />
    <axis xyz="0 0 1" />
    <limit effort="1" velocity="20" lower="-0.785398163397448279" upper="0.785398163397448279" />
    <joint_properties friction="0.0" />
  </joint>

  <joint name="right_ank_pitch" type="revolute">
    <origin xyz="-4.0265291502142843319e-17 0.10000000000000000555 -0.010399999999999947481" rpy="-5.6239133145192868052e-16 -1.1344214119702528777e-16 3.141592653589793116" />
    <parent link="right_calf_link" />
    <child link="ank_pitch_link_2" />
    <axis xyz="0 0 1" />
    <limit effort="1" velocity="20" lower="-0.785398163397448279" upper="0.95993108859688125456" />
    <joint_properties friction="0.0" />
  </joint>

  <link name="ank_motor_arm_3">
    <visual>
      <origin xyz="0 0 0" rpy="0 -0 0" />
      <geometry>
        <mesh filename="../assemblies/right_leg_XM430/meshes/right_ank_motor_arm_visual.stl" />
      </geometry>
      <material name="ank_motor_arm_material">
        <color rgba="0.62517751827980905244 0.70593642422614044651 0.75978993426662777555 1.0" />
      </material>
    </visual>
    <inertial>
      <origin xyz="0.014511489101591683662 -1.158116989626827349e-17 0.0040925443765950555303" rpy="0 0 0" />
      <mass value="0.0020595846677894939954" />
      <inertia ixx="2.7591836756521938544e-08" ixy="-2.0285682245063780246e-22" ixz="-3.0270788206594755858e-08" iyy="1.6138599216238443231e-07" iyz="-1.0111052716230874707e-22" izz="1.6437836765016290181e-07" />
    </inertial>
  </link>

  <joint name="right_ank_act_1" type="revolute">
    <origin xyz="0.013499999999995838246 0.044500000000006201262 0.0040000000000029352354" rpy="-2.9762431821176080221e-13 -7.5970722241046912715e-14 0.21173394130155420712" />
    <parent link="right_calf_link" />
    <child link="ank_motor_arm_3" />
    <axis xyz="0 0 1" />
    <limit effort="1" velocity="20" lower="-1.3089969389957472057" upper="1.3089969389957472057" />
    <joint_properties friction="0.0" />
  </joint>

  <link name="ank_motor_arm_4">
    <visual>
      <origin xyz="0 0 0" rpy="0 -0 0" />
      <geometry>
        <mesh filename="../assemblies/right_leg_XM430/meshes/right_ank_motor_arm_2_visual.stl" />
      </geometry>
      <material name="ank_motor_arm_2_material">
        <color rgba="0.62517751827980905244 0.70593642422614044651 0.75978993426662777555 1.0" />
      </material>
    </visual>
    <inertial>
      <origin xyz="0.014511489101591688866 -1.3806250802041865963e-19 0.004092544376595107572" rpy="0 0 0" />
      <mass value="0.0020595846677894939954" />
      <inertia ixx="2.7591836756522421617e-08" ixy="-1.3608577437621110242e-22" ixz="-3.0270788206595331576e-08" iyy="1.6138599216238422056e-07" iyz="-3.3298681942779494534e-22" izz="1.6437836765016324592e-07" />
    </inertial>
  </link>

  <joint name="right_ank_act_2" type="revolute">
    <origin xyz="0.013500000000004725234 0.064500000000008106404 -0.024800000000001404254" rpy="-3.1415926535894733718 -2.3305959971649736532e-13 0.22995607267265857909" />
    <parent link="right_calf_link" />
    <child link="ank_motor_arm_4" />
    <axis xyz="0 0 1" />
    <limit effort="1" velocity="20" lower="-1.3089969389957472057" upper="1.3089969389957472057" />
    <joint_properties friction="0.0" />
  </joint>

  <joint name="right_knee" type="revolute">
    <origin xyz="-2.9922268808255885729e-17 -0.096000000000000029754 -0.0091999999999999235167" rpy="1.2825226684517786044e-14 1.3611434254495038701e-14 -3.1415926535897926719" />
    <parent link="right_hip_pitch_link_xm430" />
    <child link="right_calf_link" />
    <axis xyz="0 0 1" />
    <limit effort="1" velocity="20" lower="-1.9198621771937625091" upper="0" />
    <joint_properties friction="0.0" />
  </joint>

  <joint name="right_hip_pitch" type="revolute">
    <origin xyz="-0.024000000716142638746 -0.019000000152444462831 -0.019000000152450562119" rpy="1.5707963267951012831 1.5707963267947298025 0" />
    <parent link="hip_roll_link_2" />
    <child link="right_hip_pitch_link_xm430" />
    <axis xyz="0 0 1" />
    <limit effort="1" velocity="20" lower="-1.570796326794896558" upper="1.570796326794896558" />
    <joint_properties friction="0.0" />
  </joint>

  <joint name="right_hip_roll" type="revolute">
    <origin xyz="-0.018999999999999999528 3.3500438890367473614e-18 -0.026000000000000002276" rpy="1.737531809691582777e-30 -1.570796326794896558 0" />
    <parent link="hip_yaw_link_2" />
    <child link="hip_roll_link_2" />
    <axis xyz="0 0 1" />
    <limit effort="1" velocity="20" lower="-0.785398163397448279" upper="1.570796326794896558" />
    <joint_properties friction="0.0" />
  </joint>


  <link name="xc430">
    <visual>
      <origin xyz="0 0 0" rpy="0 -0 0" />
      <geometry>
        <mesh filename="../assemblies/left_arm_hand/meshes/left_xc430_visual.stl" />
      </geometry>
      <material name="xc430_material">
        <color rgba="0.39603348637483432038 0.50878377002232877402 0.7112675543215366547 1.0" />
      </material>
    </visual>
    <inertial>
      <origin xyz="0.0076499389484203641695 -0.0056800345415021161882 -0.014255781343936728411" rpy="0 0 0" />
      <mass value="0.065021926915724281848" />
      <inertia ixx="1.0685477757330404797e-05" ixy="2.4991048730004099899e-08" ixz="-4.3793050176056603612e-09" iyy="1.6030858372951694338e-05" iyz="-9.5846760480290978638e-09" izz="1.8186829094811185627e-05" />
    </inertial>
  </link>

  <link name="sho_pitch_link">
    <visual>
      <origin xyz="0 0 0" rpy="0 -0 0" />
      <geometry>
        <mesh filename="../assemblies/left_arm_hand/meshes/left_sho_pitch_link_visual.stl" />
      </geometry>
      <material name="sho_pitch_link_material">
        <color rgba="0.61568627450980395466 0.81176470588235294379 0.9294117647058824927 1.0" />
      </material>
    </visual>
    <inertial>
      <origin xyz="5.8254246533850555188e-11 -5.1264642561120633705e-05 0.0082440788127094866838" rpy="0 0 0" />
      <mass value="0.0085999999999999930667" />
      <inertia ixx="1.2272887040545789755e-06" ixy="-2.1429944218825389786e-14" ixz="-8.5847197649333819161e-15" iyy="2.9107306060364620088e-06" iyz="7.4623841398182868942e-09" izz="3.0803135950773479222e-06" />
    </inertial>
  </link>

  <link name="2xl430_gears">
    <visual>
      <origin xyz="0 0 0" rpy="0 -0 0" />
      <geometry>
        <mesh filename="../assemblies/left_arm_hand/meshes/left_2xl430_gears_visual.stl" />
      </geometry>
      <material name="2xl430_gears_material">
        <color rgba="0.91900666046079215743 0.7025956886054134376 0.12479235365575502836 1.0" />
      </material>
    </visual>
    <inertial>
      <origin xyz="-0.011545549214475142943 -0.0025776045975616475661 -0.018554883443549097938" rpy="0 0 0" />
      <mass value="0.10921242823035924585" />
      <inertia ixx="2.5633987199176192553e-05" ixy="9.2332485824732332927e-07" ixz="-1.9126365492205904953e-08" iyy="3.0316164317563583114e-05" iyz="-6.1055425070402856933e-07" izz="3.3278157643470436923e-05" />
    </inertial>
  </link>

  <link name="spur_1m_24t_drive">
    <visual>
      <origin xyz="0 0 0" rpy="0 -0 0" />
      <geometry>
        <mesh filename="../assemblies/left_arm_hand/meshes/left_spur_1m_24t_drive_visual.stl" />
      </geometry>
      <material name="spur_1m_24t_drive_material">
        <color rgba="0.61568627450980406568 0.81176470588235294379 0.92941176470588238168 1.0" />
      </material>
    </visual>
    <inertial>
      <origin xyz="-7.7519472167040379473e-15 -1.2127696869027378682e-16 0.0047949116178401460231" rpy="0 0 0" />
      <mass value="0.0032000000000000001533" />
      <inertia ixx="1.4019331346159892996e-07" ixy="1.6002409988143339376e-15" ixz="-8.7717508276537448259e-37" iyy="1.4019331260388786185e-07" iyz="1.1548227992196320289e-37" izz="2.3838919844264060647e-07" />
    </inertial>
  </link>

  <joint name="left_sho_yaw_drive" type="revolute">
    <origin xyz="-0.024000000716149078039 -0.019000000152453292573 -0.019000000152451651525" rpy="1.5707963267948956698 -4.5091784937906777239e-14 2.4545027507744066908e-14" />
    <parent link="2xl430_gears" />
    <child link="spur_1m_24t_drive" />
    <axis xyz="0 0 1" />
    <limit effort="1" velocity="20" lower="-3.141592653589793116" upper="3.141592653589793116" />
    <joint_properties friction="0.0" />
  </joint>

  <link name="spur_1m_24t_driven">
    <visual>
      <origin xyz="0 0 0" rpy="0 -0 0" />
      <geometry>
        <mesh filename="../assemblies/left_arm_hand/meshes/left_spur_1m_24t_driven_visual.stl" />
      </geometry>
      <material name="spur_1m_24t_driven_material">
        <color rgba="0.23137254901960788156 0.38039215686274507888 0.7058823529411765163 1.0" />
      </material>
    </visual>
    <inertial>
      <origin xyz="2.2938228594596052967e-18 -5.7989635076863972055e-15 -0.00096866348640038332785" rpy="0 0 0" />
      <mass value="0.0027000000000000001429" />
      <inertia ixx="1.2026541119643507388e-07" ixy="-2.1120706372726563048e-36" ixz="0" iyy="1.2026541119643486212e-07" iyz="0" izz="2.2827257365099369132e-07" />
    </inertial>
  </link>

  <link name="sho_yaw_link">
    <visual>
      <origin xyz="0 0 0" rpy="0 -0 0" />
      <geometry>
        <mesh filename="../assemblies/left_arm_hand/meshes/left_sho_yaw_link_visual.stl" />
      </geometry>
      <material name="sho_yaw_link_material">
        <color rgba="0.61568627450980384364 0.81176470588235294379 0.92941176470588238168 1.0" />
      </material>
    </visual>
    <inertial>
      <origin xyz="5.7814996523352868457e-18 3.4508249259427939065e-18 -0.024214576156328403156" rpy="0 0 0" />
      <mass value="0.01450000000000000247" />
      <inertia ixx="9.0490855102914907775e-06" ixy="3.5997729401569193722e-13" ixz="0" iyy="5.6767199180624685142e-06" iyz="0" izz="4.459060363746810004e-06" />
    </inertial>
  </link>

  <link name="2xl430_gears_2">
    <visual>
      <origin xyz="0 0 0" rpy="0 -0 0" />
      <geometry>
        <mesh filename="../assemblies/left_arm_hand/meshes/left_2xl430_gears_2_visual.stl" />
      </geometry>
      <material name="2xl430_gears_2_material">
        <color rgba="0.91900666046079215743 0.7025956886054134376 0.12479235365575502836 1.0" />
      </material>
    </visual>
    <inertial>
      <origin xyz="-0.01154554921447331281 -0.0025776045975613760819 -0.018554883443544802762" rpy="0 0 0" />
      <mass value="0.10921242823035924585" />
      <inertia ixx="2.5633987199174789866e-05" ixy="9.2332485824667196093e-07" ixz="-1.9126365492399451982e-08" iyy="3.031616431756243115e-05" iyz="-6.1055425070424752735e-07" izz="3.327815764346942726e-05" />
    </inertial>
  </link>

  <link name="spur_1m_24t_drive_2">
    <visual>
      <origin xyz="0 0 0" rpy="0 -0 0" />
      <geometry>
        <mesh filename="../assemblies/left_arm_hand/meshes/left_spur_1m_24t_drive_2_visual.stl" />
      </geometry>
      <material name="spur_1m_24t_drive_2_material">
        <color rgba="0.61568627450980406568 0.81176470588235294379 0.92941176470588238168 1.0" />
      </material>
    </visual>
    <inertial>
      <origin xyz="-7.7519472167040379473e-15 -1.2127696869027398403e-16 0.0047949116178401512273" rpy="0 0 0" />
      <mass value="0.0032000000000000001533" />
      <inertia ixx="1.4019331346159892996e-07" ixy="1.6002410021230563878e-15" ixz="3.3868739208338279975e-37" iyy="1.4019331260388786185e-07" iyz="2.3470577016292310921e-36" izz="2.3838919844264071235e-07" />
    </inertial>
  </link>

  <joint name="left_elbow_yaw_drive" type="revolute">
    <origin xyz="-0.024000000716143922441 -0.019000000152449375568 -0.019000000152448702495" rpy="1.5707963267948812369 -8.0032142329674811068e-15 1.2365412156371141215e-13" />
    <parent link="2xl430_gears_2" />
    <child link="spur_1m_24t_drive_2" />
    <axis xyz="0 0 1" />
    <limit effort="1" velocity="20" lower="-3.141592653589793116" upper="3.141592653589793116" />
    <joint_properties friction="0.0" />
  </joint>

  <link name="spur_1m_24t_driven_2">
    <visual>
      <origin xyz="0 0 0" rpy="0 -0 0" />
      <geometry>
        <mesh filename="../assemblies/left_arm_hand/meshes/left_spur_1m_24t_driven_2_visual.stl" />
      </geometry>
      <material name="spur_1m_24t_driven_2_material">
        <color rgba="0.23137254901960788156 0.38039215686274507888 0.7058823529411765163 1.0" />
      </material>
    </visual>
    <inertial>
      <origin xyz="2.2938228594596052967e-18 -5.7989635076863972055e-15 -0.00096866348640037638895" rpy="0 0 0" />
      <mass value="0.0027000000000000001429" />
      <inertia ixx="1.2026541119643507388e-07" ixy="-6.5732337140722154164e-38" ixz="0" iyy="1.2026541119643486212e-07" iyz="0" izz="2.2827257365099369132e-07" />
    </inertial>
  </link>

  <link name="elb_yaw_link">
    <visual>
      <origin xyz="0 0 0" rpy="0 -0 0" />
      <geometry>
        <mesh filename="../assemblies/left_arm_hand/meshes/left_elb_yaw_link_visual.stl" />
      </geometry>
      <material name="elb_yaw_link_material">
        <color rgba="0.61568627450980395466 0.81176470588235294379 0.9294117647058824927 1.0" />
      </material>
    </visual>
    <inertial>
      <origin xyz="5.2870889172653179162e-08 0.001987355818274245782 -0.023365661199828722389" rpy="0 0 0" />
      <mass value="0.017499999999999998196" />
      <inertia ixx="1.4097804991252561445e-05" ixy="1.6900809684089973752e-12" ixz="-1.1184673662179512683e-11" iyy="6.6367696417680327434e-06" iyz="1.0579908722588339983e-06" izz="8.9601142768980714413e-06" />
    </inertial>
  </link>

  <link name="spur_1m_24t_driven_3">
    <visual>
      <origin xyz="0 0 0" rpy="0 -0 0" />
      <geometry>
        <mesh filename="../assemblies/left_arm_hand/meshes/left_spur_1m_24t_driven_3_visual.stl" />
      </geometry>
      <material name="spur_1m_24t_driven_3_material">
        <color rgba="0.23137254901960788156 0.38039215686274507888 0.7058823529411765163 1.0" />
      </material>
    </visual>
    <inertial>
      <origin xyz="-2.5461752756169335177e-17 -5.7989635076863972055e-15 -0.0025686634864003805856" rpy="0 0 0" />
      <mass value="0.0027000000000000001429" />
      <inertia ixx="1.2026541119643507388e-07" ixy="-2.9625477072638557134e-36" ixz="-1.5730367353383818768e-37" iyy="1.2026541119643486212e-07" iyz="1.1070062413737891266e-37" izz="2.2827257365099369132e-07" />
    </inertial>
  </link>

  <link name="2xl430_gears_3">
    <visual>
      <origin xyz="0 0 0" rpy="0 -0 0" />
      <geometry>
        <mesh filename="../assemblies/left_arm_hand/meshes/left_2xl430_gears_3_visual.stl" />
      </geometry>
      <material name="2xl430_gears_3_material">
        <color rgba="0.91900666046079215743 0.7025956886054134376 0.12479235365575502836 1.0" />
      </material>
    </visual>
    <inertial>
      <origin xyz="0.00044511655645805531896 0.011545548856396192772 -0.024422395554887000452" rpy="0 0 0" />
      <mass value="0.10921242823035924585" />
      <inertia ixx="3.3278157643469847388e-05" ixy="1.9126365494094470788e-08" ixz="6.1055425070499333986e-07" iyy="2.5633987199175325191e-05" iyz="9.2332485824892220983e-07" izz="3.0316164317561431651e-05" />
    </inertial>
  </link>

  <link name="spur_1m_24t_drive_3">
    <visual>
      <origin xyz="0 0 0" rpy="0 -0 0" />
      <geometry>
        <mesh filename="../assemblies/left_arm_hand/meshes/left_spur_1m_24t_drive_3_visual.stl" />
      </geometry>
      <material name="spur_1m_24t_drive_3_material">
        <color rgba="0.61568627450980406568 0.81176470588235294379 0.92941176470588238168 1.0" />
      </material>
    </visual>
    <inertial>
      <origin xyz="-7.7241916410884090338e-15 -1.2821586259418121241e-16 0.0047949116178401399516" rpy="0 0 0" />
      <mass value="0.0032000000000000001533" />
      <inertia ixx="1.4019331346159892996e-07" ixy="1.6002410008742266632e-15" ixz="-6.4318290562543542602e-36" iyy="1.4019331260388791479e-07" iyz="-3.5497739011481709691e-36" izz="2.3838919844264060647e-07" />
    </inertial>
  </link>

  <joint name="left_wrist_pitch_drive" type="revolute">
    <origin xyz="-1.5244678436276970501e-10 0.024000000358067485884 -0.0080000000000028173575" rpy="-6.0688227754444846318e-17 9.0954925662261794972e-16 -1.5707963267950935116" />
    <parent link="2xl430_gears_3" />
    <child link="spur_1m_24t_drive_3" />
    <axis xyz="0 0 1" />
    <limit effort="1" velocity="20" lower="-1.570796326794896558" upper="1.570796326794896558" />
    <joint_properties friction="0.0" />
  </joint>

  <link name="wrist_bearing_plate">
    <visual>
      <origin xyz="0 0 0" rpy="0 -0 0" />
      <geometry>
        <mesh filename="../assemblies/left_arm_hand/meshes/left_wrist_bearing_plate_visual.stl" />
      </geometry>
      <material name="wrist_bearing_plate_material">
        <color rgba="0.64496316278892629192 0.69011804996940528945 0.71706771073555886087 1.0" />
      </material>
    </visual>
    <inertial>
      <origin xyz="-0.0075896393545961445687 -0.015499999999999980807 -0.0018386110045718409307" rpy="0 0 0" />
      <mass value="0.0049000367468305548388" />
      <inertia ixx="4.9747313520140109893e-07" ixy="2.4215325079326760439e-22" ixz="1.8097509420524938529e-08" iyy="7.1295025627582438487e-07" iyz="3.0016154882842111316e-23" izz="1.192629795229191449e-06" />
    </inertial>
  </link>

  <joint name="left_wrist_roll_fixed" type="fixed">
    <origin xyz="0.015500000000005648149 -4.3853809472693683347e-15 -0.044999999999999262812" rpy="-1.5598633495994326207e-14 -1.730560139634137368e-13 -1.5707963267946343233" />
    <parent link="2xl430_gears_3" />
    <child link="wrist_bearing_plate" />
    <axis xyz="0 0 1" />
    <limit effort="1" velocity="20" />
    <joint_properties friction="0.0" />
  </joint>

  <link name="hand">
    <visual>
      <origin xyz="0 0 0" rpy="0 -0 0" />
      <geometry>
        <mesh filename="../assemblies/left_arm_hand/meshes/left_hand_visual.stl" />
      </geometry>
      <material name="hand_material">
        <color rgba="0.61568627450980395466 0.81176470588235294379 0.92941176470588238168 1.0" />
      </material>
    </visual>
    <inertial>
      <origin xyz="-4.3038382213233279171e-08 -0.049723778585231907801 -0.01793357200539034968" rpy="0 0 0" />
      <mass value="0.017000000000001441042" />
      <inertia ixx="9.492141461772624154e-06" ixy="-1.5549215897336582142e-11" ixz="-1.0809694196523374989e-11" iyy="4.0745028295199771232e-06" iyz="2.4719408559837120591e-07" izz="6.6623859523002763733e-06" />
    </inertial>
  </link>

  <joint name="left_wrist_roll" type="revolute">
    <origin xyz="0.019000000000001057709 -3.5807262710463305666e-10 -0.027000000152450100849" rpy="1.2848055952475997313e-13 1.5707963267946998265 0" />
    <parent link="2xl430_gears_3" />
    <child link="hand" />
    <axis xyz="0 0 1" />
    <limit effort="1" velocity="20" lower="-1.570796326794896558" upper="1.570796326794896558" />
    <joint_properties friction="0.0" />
  </joint>

  <joint name="left_wrist_pitch_driven" type="revolute">
    <origin xyz="-8.3266726846886740532e-17 5.4817261840867104183e-16 -0.0016000000000001152189" rpy="-5.7142471032373773212e-16 5.5511151217739912712e-17 -1.570796326794896336" />
    <parent link="spur_1m_24t_driven_3" />
    <child link="2xl430_gears_3" />
    <axis xyz="0 0 1" />
    <limit effort="1" velocity="20" lower="-1.570796326794896558" upper="1.570796326794896558" />
    <joint_properties friction="0.0" />
  </joint>

  <joint name="left_wrist_pitch_fixed" type="fixed">
    <origin xyz="2.0816681711721685133e-17 -0.025299999999999989164 -0.051999999999999990674" rpy="1.5707963267948958919 -1.570796326794896336 0" />
    <parent link="elb_yaw_link" />
    <child link="spur_1m_24t_driven_3" />
    <axis xyz="0 0 1" />
    <limit effort="1" velocity="20" />
    <joint_properties friction="0.0" />
  </joint>

  <joint name="left_elbow_yaw_fixed" type="fixed">
    <origin xyz="1.3097162243624893563e-16 6.2450045135165055399e-17 0.0015999999999997960298" rpy="-3.141592653589793116 -5.5511151231207524813e-17 -1.570796326794896336" />
    <parent link="spur_1m_24t_driven_2" />
    <child link="elb_yaw_link" />
    <axis xyz="0 0 1" />
    <limit effort="1" velocity="20" />
    <joint_properties friction="0.0" />
  </joint>

  <joint name="left_elbow_yaw_driven" type="revolute">
    <origin xyz="-3.5807262710463305666e-10 -0.027000000152449854518 -0.01900000000000161629" rpy="1.570796326794891673 1.5707963267948441555 0" />
    <parent link="2xl430_gears_2" />
    <child link="spur_1m_24t_driven_2" />
    <axis xyz="0 0 1" />
    <limit effort="1" velocity="20" lower="-3.141592653589793116" upper="3.141592653589793116" />
    <joint_properties friction="0.0" />
  </joint>

  <joint name="left_elbow_roll" type="revolute">
    <origin xyz="7.6327832942979512154e-17 -0.018999999999999992589 -0.059000000000000031586" rpy="1.570796326794896558 -7.0029629609134176679e-16 7.044195017682708143e-15" />
    <parent link="sho_yaw_link" />
    <child link="2xl430_gears_2" />
    <axis xyz="0 0 1" />
    <limit effort="1" velocity="20" lower="-1.570796326794896558" upper="1.570796326794896558" />
    <joint_properties friction="0.0" />
  </joint>

  <joint name="left_sho_yaw_fixed" type="fixed">
    <origin xyz="0 1.561251128379126385e-17 0.0015999999999999903189" rpy="-3.1415926535897922278 1.4418079614154122748e-16 -6.106226635437282205e-16" />
    <parent link="spur_1m_24t_driven" />
    <child link="sho_yaw_link" />
    <axis xyz="0 0 1" />
    <limit effort="1" velocity="20" />
    <joint_properties friction="0.0" />
  </joint>

  <joint name="left_sho_yaw_driven" type="revolute">
    <origin xyz="-3.5807536102883119611e-10 -0.027000000152448761642 -0.019000000000006084938" rpy="1.5707963267949398567 1.8984813721086286179e-14 -7.1310113557521486963e-14" />
    <parent link="2xl430_gears" />
    <child link="spur_1m_24t_driven" />
    <axis xyz="0 0 1" />
    <limit effort="1" velocity="20" lower="-3.141592653589793116" upper="3.141592653589793116" />
    <joint_properties friction="0.0" />
  </joint>

  <joint name="left_sho_roll" type="revolute">
    <origin xyz="-0.018999999999999992589 0.00099999999999997833677 0.026999999999999996225" rpy="-3.141592653589793116 1.5707963267948954478 0" />
    <parent link="sho_pitch_link" />
    <child link="2xl430_gears" />
    <axis xyz="0 0 1" />
    <limit effort="1" velocity="20" lower="-1.570796326794896558" upper="1.570796326794896558" />
    <joint_properties friction="0.0" />
  </joint>

  <joint name="left_sho_pitch" type="revolute">
    <origin xyz="-0.0039999999999985160273 0.012999999999999725317 -0.01424999999999848263" rpy="-1.5707963267948332753 -5.5178084323870191707e-14 -1.1649761152065636686e-13" />
    <parent link="xc430" />
    <child link="sho_pitch_link" />
    <axis xyz="0 0 1" />
    <limit effort="1" velocity="20" lower="-1.570796326794896558" upper="1.570796326794896558" />
    <joint_properties friction="0.0" />
  </joint>


  <link name="xc430_2">
    <visual>
      <origin xyz="0 0 0" rpy="0 -0 0" />
      <geometry>
        <mesh filename="../assemblies/right_arm_hand/meshes/right_xc430_visual.stl" />
      </geometry>
      <material name="xc430_material">
        <color rgba="0.39603348637483432038 0.50878377002232877402 0.7112675543215366547 1.0" />
      </material>
    </visual>
    <inertial>
      <origin xyz="0.0076499389484204908043 0.0056800345415021604237 -0.014244218656063243125" rpy="0 0 0" />
      <mass value="0.065021926915724281848" />
      <inertia ixx="1.0685477757330492888e-05" ixy="-2.4991048729880562129e-08" ixz="4.3793050176100617893e-09" iyy="1.6030858372951941671e-05" iyz="-9.5846760479536623006e-09" izz="1.8186829094811067043e-05" />
    </inertial>
  </link>

  <link name="sho_pitch_link_2">
    <visual>
      <origin xyz="0 0 0" rpy="0 -0 0" />
      <geometry>
        <mesh filename="../assemblies/right_arm_hand/meshes/right_sho_pitch_link_visual.stl" />
      </geometry>
      <material name="sho_pitch_link_material">
        <color rgba="0.61568627450980395466 0.81176470588235294379 0.9294117647058824927 1.0" />
      </material>
    </visual>
    <inertial>
      <origin xyz="5.8254246533850555188e-11 -5.1264642561120620152e-05 0.0082440788127094866838" rpy="0 0 0" />
      <mass value="0.0085999999999999930667" />
      <inertia ixx="1.2272887040545789755e-06" ixy="-2.1429944218825383475e-14" ixz="-8.5847197649333819161e-15" iyy="2.9107306060364603147e-06" iyz="7.4623841398182852399e-09" izz="3.0803135950773479222e-06" />
    </inertial>
  </link>

  <link name="2xl430_gears_4">
    <visual>
      <origin xyz="0 0 0" rpy="0 -0 0" />
      <geometry>
        <mesh filename="../assemblies/right_arm_hand/meshes/right_2xl430_gears_visual.stl" />
      </geometry>
      <material name="2xl430_gears_material">
        <color rgba="0.91900666046079215743 0.7025956886054134376 0.12479235365575502836 1.0" />
      </material>
    </visual>
    <inertial>
      <origin xyz="-0.011545549214474582628 -0.0025776045975625166626 -0.01855488344354406377" rpy="0 0 0" />
      <mass value="0.10921242823035924585" />
      <inertia ixx="2.5633987199174715327e-05" ixy="9.2332485824708510125e-07" ixz="-1.9126365491687150213e-08" iyy="3.031616431756206862e-05" iyz="-6.1055425070399722911e-07" izz="3.3278157643469271406e-05" />
    </inertial>
  </link>

  <link name="spur_1m_24t_drive_4">
    <visual>
      <origin xyz="0 0 0" rpy="0 -0 0" />
      <geometry>
        <mesh filename="../assemblies/right_arm_hand/meshes/right_spur_1m_24t_drive_visual.stl" />
      </geometry>
      <material name="spur_1m_24t_drive_material">
        <color rgba="0.61568627450980406568 0.81176470588235294379 0.92941176470588238168 1.0" />
      </material>
    </visual>
    <inertial>
      <origin xyz="-7.7519472167040363696e-15 -1.2040960695228518605e-16 0.0047949116178401512273" rpy="0 0 0" />
      <mass value="0.0032000000000000001533" />
      <inertia ixx="1.4019331346159887702e-07" ixy="1.6002409968110544065e-15" ixz="-5.4090992845575242873e-36" iyy="1.4019331260388783538e-07" iyz="-6.8087356421599067805e-36" izz="2.3838919844264071235e-07" />
    </inertial>
  </link>

  <joint name="right_sho_yaw_drive" type="revolute">
    <origin xyz="-0.024000000716145303281 -0.01900000015244998619 -0.01900000015244465365" rpy="1.5707963267947440134 8.8389520895546782802e-14 1.3333206406916649652e-13" />
    <parent link="2xl430_gears_4" />
    <child link="spur_1m_24t_drive_4" />
    <axis xyz="0 0 1" />
    <limit effort="1" velocity="20" lower="-3.141592653589793116" upper="3.141592653589793116" />
    <joint_properties friction="0.0" />
  </joint>

  <link name="spur_1m_24t_driven_4">
    <visual>
      <origin xyz="0 0 0" rpy="0 -0 0" />
      <geometry>
        <mesh filename="../assemblies/right_arm_hand/meshes/right_spur_1m_24t_driven_visual.stl" />
      </geometry>
      <material name="spur_1m_24t_driven_material">
        <color rgba="0.23137254901960788156 0.38039215686274507888 0.7058823529411765163 1.0" />
      </material>
    </visual>
    <inertial>
      <origin xyz="2.2938228594595964374e-18 -5.7989635076863972055e-15 -0.00096866348640038332785" rpy="0 0 0" />
      <mass value="0.0027000000000000001429" />
      <inertia ixx="1.2026541119643507388e-07" ixy="3.0132909596002652583e-36" ixz="-9.0037654543726485558e-38" iyy="1.2026541119643486212e-07" iyz="0" izz="2.2827257365099369132e-07" />
    </inertial>
  </link>

  <link name="sho_yaw_link_2">
    <visual>
      <origin xyz="0 0 0" rpy="0 -0 0" />
      <geometry>
        <mesh filename="../assemblies/right_arm_hand/meshes/right_sho_yaw_link_visual.stl" />
      </geometry>
      <material name="sho_yaw_link_material">
        <color rgba="0.61568627450980384364 0.81176470588235294379 0.92941176470588238168 1.0" />
      </material>
    </visual>
    <inertial>
      <origin xyz="-1.1573942515719288208e-18 3.4508249259427939065e-18 -0.024214576156328396217" rpy="0 0 0" />
      <mass value="0.01450000000000000247" />
      <inertia ixx="9.0490855102914907775e-06" ixy="3.5997729401569193722e-13" ixz="1.758789197490221356e-36" iyy="5.6767199180624685142e-06" iyz="0" izz="4.459060363746810004e-06" />
    </inertial>
  </link>

  <link name="2xl430_gears_5">
    <visual>
      <origin xyz="0 0 0" rpy="0 -0 0" />
      <geometry>
        <mesh filename="../assemblies/right_arm_hand/meshes/right_2xl430_gears_2_visual.stl" />
      </geometry>
      <material name="2xl430_gears_2_material">
        <color rgba="0.91900666046079215743 0.7025956886054134376 0.12479235365575502836 1.0" />
      </material>
    </visual>
    <inertial>
      <origin xyz="-0.011545549214473465466 -0.0025776045975580211267 -0.018554883443548501193" rpy="0 0 0" />
      <mass value="0.10921242823035924585" />
      <inertia ixx="2.5633987199173058531e-05" ixy="9.2332485824729887119e-07" ixz="-1.9126365492405592971e-08" iyy="3.0316164317562353223e-05" iyz="-6.105542507054514788e-07" izz="3.3278157643466920043e-05" />
    </inertial>
  </link>

  <link name="spur_1m_24t_drive_5">
    <visual>
      <origin xyz="0 0 0" rpy="0 -0 0" />
      <geometry>
        <mesh filename="../assemblies/right_arm_hand/meshes/right_spur_1m_24t_drive_2_visual.stl" />
      </geometry>
      <material name="spur_1m_24t_drive_2_material">
        <color rgba="0.61568627450980406568 0.81176470588235294379 0.92941176470588238168 1.0" />
      </material>
    </visual>
    <inertial>
      <origin xyz="-7.7658250045118508263e-15 -1.2040960695228538327e-16 0.0047949116178401382168" rpy="0 0 0" />
      <mass value="0.0032000000000000001533" />
      <inertia ixx="1.4019331346159887702e-07" ixy="1.6002410008742266632e-15" ixz="-3.624182631715073592e-36" iyy="1.4019331260388791479e-07" iyz="-4.1524596034726478973e-37" izz="2.3838919844264060647e-07" />
    </inertial>
  </link>

  <joint name="right_elbow_yaw_drive" type="revolute">
    <origin xyz="-0.024000000716140640344 -0.019000000152444435075 -0.019000000152454357694" rpy="1.5707963267949622832 8.194034361146178641e-14 -1.7317067989020890092e-13" />
    <parent link="2xl430_gears_5" />
    <child link="spur_1m_24t_drive_5" />
    <axis xyz="0 0 1" />
    <limit effort="1" velocity="20" lower="-3.141592653589793116" upper="3.141592653589793116" />
    <joint_properties friction="0.0" />
  </joint>

  <link name="spur_1m_24t_driven_5">
    <visual>
      <origin xyz="0 0 0" rpy="0 -0 0" />
      <geometry>
        <mesh filename="../assemblies/right_arm_hand/meshes/right_spur_1m_24t_driven_2_visual.stl" />
      </geometry>
      <material name="spur_1m_24t_driven_2_material">
        <color rgba="0.23137254901960788156 0.38039215686274507888 0.7058823529411765163 1.0" />
      </material>
    </visual>
    <inertial>
      <origin xyz="2.2938228594596052967e-18 -5.7989635076863972055e-15 -0.00096866348640037638895" rpy="0 0 0" />
      <mass value="0.0027000000000000001429" />
      <inertia ixx="1.2026541119643507388e-07" ixy="-2.2321759283396744983e-36" ixz="0" iyy="1.2026541119643486212e-07" iyz="0" izz="2.2827257365099369132e-07" />
    </inertial>
  </link>

  <link name="elb_yaw_link_2">
    <visual>
      <origin xyz="0 0 0" rpy="0 -0 0" />
      <geometry>
        <mesh filename="../assemblies/right_arm_hand/meshes/right_elb_yaw_link_visual.stl" />
      </geometry>
      <material name="elb_yaw_link_material">
        <color rgba="0.61568627450980395466 0.81176470588235294379 0.9294117647058824927 1.0" />
      </material>
    </visual>
    <inertial>
      <origin xyz="5.2870889172653179162e-08 0.001987355818274245782 -0.023365661199828729327" rpy="0 0 0" />
      <mass value="0.017499999999999998196" />
      <inertia ixx="1.4097804991252561445e-05" ixy="1.6900809684089973752e-12" ixz="-1.1184673662179509452e-11" iyy="6.6367696417680327434e-06" iyz="1.0579908722588337865e-06" izz="8.9601142768980680532e-06" />
    </inertial>
  </link>

  <link name="spur_1m_24t_driven_6">
    <visual>
      <origin xyz="0 0 0" rpy="0 -0 0" />
      <geometry>
        <mesh filename="../assemblies/right_arm_hand/meshes/right_spur_1m_24t_driven_3_visual.stl" />
      </geometry>
      <material name="spur_1m_24t_driven_3_material">
        <color rgba="0.23137254901960788156 0.38039215686274507888 0.7058823529411765163 1.0" />
      </material>
    </visual>
    <inertial>
      <origin xyz="2.29382285945958103e-18 -5.8059024015903044338e-15 -0.0025686634864003771161" rpy="0 0 0" />
      <mass value="0.0027000000000000001429" />
      <inertia ixx="1.2026541119643507388e-07" ixy="-8.8943138390222332027e-38" ixz="-3.4871107238620781346e-37" iyy="1.2026541119643486212e-07" iyz="3.5770621358774083159e-36" izz="2.2827257365099369132e-07" />
    </inertial>
  </link>

  <link name="2xl430_gears_6">
    <visual>
      <origin xyz="0 0 0" rpy="0 -0 0" />
      <geometry>
        <mesh filename="../assemblies/right_arm_hand/meshes/right_2xl430_gears_3_visual.stl" />
      </geometry>
      <material name="2xl430_gears_3_material">
        <color rgba="0.91900666046079215743 0.7025956886054134376 0.12479235365575502836 1.0" />
      </material>
    </visual>
    <inertial>
      <origin xyz="0.00044511655645500708455 0.011545548856405010371 -0.024422395554887468827" rpy="0 0 0" />
      <mass value="0.10921242823035924585" />
      <inertia ixx="3.3278157643468370163e-05" ixy="1.9126365492365835362e-08" ixz="6.1055425070389452637e-07" iyy="2.563398719917358708e-05" iyz="9.2332485824554837172e-07" izz="3.0316164317561855167e-05" />
    </inertial>
  </link>

  <link name="spur_1m_24t_drive_6">
    <visual>
      <origin xyz="0 0 0" rpy="0 -0 0" />
      <geometry>
        <mesh filename="../assemblies/right_arm_hand/meshes/right_spur_1m_24t_drive_3_visual.stl" />
      </geometry>
      <material name="spur_1m_24t_drive_3_material">
        <color rgba="0.61568627450980406568 0.81176470588235294379 0.92941176470588238168 1.0" />
      </material>
    </visual>
    <inertial>
      <origin xyz="-7.7797027923196668608e-15 -1.2821586259418081798e-16 0.0047949116178401416863" rpy="0 0 0" />
      <mass value="0.0032000000000000001533" />
      <inertia ixx="1.4019331346159892996e-07" ixy="1.6002409967827479079e-15" ixz="1.8689311580061742935e-36" iyy="1.4019331260388783538e-07" iyz="1.2273789032714357933e-37" izz="2.3838919844264060647e-07" />
    </inertial>
  </link>

  <joint name="right_wrist_pitch_drive" type="revolute">
    <origin xyz="-1.5244812356929315911e-10 0.024000000358072565154 -0.0079999999999997069983" rpy="3.0683701463333139415e-15 3.000158893453974941e-16 -1.5707963267949427433" />
    <parent link="2xl430_gears_6" />
    <child link="spur_1m_24t_drive_6" />
    <axis xyz="0 0 1" />
    <limit effort="1" velocity="20" lower="-1.570796326794896558" upper="1.570796326794896558" />
    <joint_properties friction="0.0" />
  </joint>

  <link name="wrist_bearing_plate_2">
    <visual>
      <origin xyz="0 0 0" rpy="0 -0 0" />
      <geometry>
        <mesh filename="../assemblies/right_arm_hand/meshes/right_wrist_bearing_plate_visual.stl" />
      </geometry>
      <material name="wrist_bearing_plate_material">
        <color rgba="0.64496316278892629192 0.69011804996940528945 0.71706771073555886087 1.0" />
      </material>
    </visual>
    <inertial>
      <origin xyz="-0.0075896393545961402319 -0.015499999999999980807 -0.0018386110045718361602" rpy="0 0 0" />
      <mass value="0.0049000367468305548388" />
      <inertia ixx="4.9747313520140120481e-07" ixy="6.187964306324674079e-23" ixz="1.8097509420524783019e-08" iyy="7.1295025627582311432e-07" iyz="1.9151828907181811219e-23" izz="1.192629795229189755e-06" />
    </inertial>
  </link>

  <joint name="right_wrist_roll_fixed" type="fixed">
    <origin xyz="0.015499999999999309469 5.6343818499726694426e-15 -0.045000000000002496336" rpy="-3.8857806018810176234e-16 1.2034817586933650002e-13 -1.5707963267948996666" />
    <parent link="2xl430_gears_6" />
    <child link="wrist_bearing_plate_2" />
    <axis xyz="0 0 1" />
    <limit effort="1" velocity="20" />
    <joint_properties friction="0.0" />
  </joint>

  <link name="hand_2">
    <visual>
      <origin xyz="0 0 0" rpy="0 -0 0" />
      <geometry>
        <mesh filename="../assemblies/right_arm_hand/meshes/right_hand_visual.stl" />
      </geometry>
      <material name="hand_material">
        <color rgba="0.61568627450980395466 0.81176470588235294379 0.92941176470588238168 1.0" />
      </material>
    </visual>
    <inertial>
      <origin xyz="-4.3038382212365917433e-08 0.049723778585231935556 -0.020066427994609652846" rpy="0 0 0" />
      <mass value="0.017000000000001441042" />
      <inertia ixx="9.492141461772624154e-06" ixy="1.5549215897336582142e-11" ixz="1.0809694196523376605e-11" iyy="4.0745028295199771232e-06" iyz="2.4719408559837125885e-07" izz="6.6623859523002797615e-06" />
    </inertial>
  </link>

  <joint name="right_wrist_roll" type="revolute">
    <origin xyz="0.018999999999997782552 -3.5806707598950993088e-10 -0.027000000152450402691" rpy="-3.1415926535897886751 -1.5707963267947642194 0" />
    <parent link="2xl430_gears_6" />
    <child link="hand_2" />
    <axis xyz="0 0 1" />
    <limit effort="1" velocity="20" lower="-1.570796326794896558" upper="1.570796326794896558" />
    <joint_properties friction="0.0" />
  </joint>

  <joint name="right_wrist_pitch_driven" type="revolute">
    <origin xyz="-2.7755575615628913511e-17 6.9388939039072283776e-18 -0.0016000000000002227718" rpy="-4.5800957231150559108e-15 -6.2172489379009776006e-15 1.570796326794896558" />
    <parent link="spur_1m_24t_driven_6" />
    <child link="2xl430_gears_6" />
    <axis xyz="0 0 1" />
    <limit effort="1" velocity="20" lower="-1.570796326794896558" upper="1.570796326794896558" />
    <joint_properties friction="0.0" />
  </joint>

  <joint name="right_wrist_pitch_fixed" type="fixed">
    <origin xyz="0 -0.025299999999999996103 -0.052000000000000046185" rpy="1.5707963267948905628 1.5707963267948905628 0" />
    <parent link="elb_yaw_link_2" />
    <child link="spur_1m_24t_driven_6" />
    <axis xyz="0 0 1" />
    <limit effort="1" velocity="20" />
    <joint_properties friction="0.0" />
  </joint>

  <joint name="right_elbow_yaw_fixed" type="fixed">
    <origin xyz="-6.9388939039072283776e-18 0 0.0015999999999999903189" rpy="-3.141592653589793116 -2.2204460328203446248e-16 -3.141592653589793116" />
    <parent link="spur_1m_24t_driven_5" />
    <child link="elb_yaw_link_2" />
    <axis xyz="0 0 1" />
    <limit effort="1" velocity="20" />
    <joint_properties friction="0.0" />
  </joint>

  <joint name="right_elbow_yaw_driven" type="revolute">
    <origin xyz="-3.5806981685260197423e-10 -0.027000000152445247092 -0.019000000000004103884" rpy="-1.5707963267950058039 5.9602610059045593461e-15 3.1415926535897913396" />
    <parent link="2xl430_gears_5" />
    <child link="spur_1m_24t_driven_5" />
    <axis xyz="0 0 1" />
    <limit effort="1" velocity="20" lower="-3.141592653589793116" upper="3.141592653589793116" />
    <joint_properties friction="0.0" />
  </joint>

  <joint name="right_elbow_roll" type="revolute">
    <origin xyz="1.3183898417423733918e-16 -0.018999999999999933609 -0.059000000000000038525" rpy="1.570796326794896558 -2.6733818545004476465e-15 -6.1232339957031568635e-17" />
    <parent link="sho_yaw_link_2" />
    <child link="2xl430_gears_5" />
    <axis xyz="0 0 1" />
    <limit effort="1" velocity="20" lower="-1.570796326794896558" upper="1.570796326794896558" />
    <joint_properties friction="0.0" />
  </joint>

  <joint name="right_sho_yaw_fixed" type="fixed">
    <origin xyz="-6.9388939039072283776e-18 -8.6736173798840354721e-19 0.0016000000000000041966" rpy="-3.141592653589793116 -3.0292258760486853328e-28 -8.5559900487112566884e-29" />
    <parent link="spur_1m_24t_driven_4" />
    <child link="sho_yaw_link_2" />
    <axis xyz="0 0 1" />
    <limit effort="1" velocity="20" />
    <joint_properties friction="0.0" />
  </joint>

  <joint name="right_sho_yaw_driven" type="revolute">
    <origin xyz="-3.5807402876120164592e-10 -0.027000000152449625535 -0.019000000000000287492" rpy="1.5707963267948759079 -1.13931263975872123e-27 -4.4614134174147354846e-14" />
    <parent link="2xl430_gears_4" />
    <child link="spur_1m_24t_driven_4" />
    <axis xyz="0 0 1" />
    <limit effort="1" velocity="20" lower="-3.141592653589793116" upper="3.141592653589793116" />
    <joint_properties friction="0.0" />
  </joint>

  <joint name="right_sho_roll" type="revolute">
    <origin xyz="-0.018999999999999999528 0.0010000000000000251743 0.026999999999999996225" rpy="3.141592653589793116 1.570796326794896558 0" />
    <parent link="sho_pitch_link_2" />
    <child link="2xl430_gears_4" />
    <axis xyz="0 0 1" />
    <limit effort="1" velocity="20" lower="-1.570796326794896558" upper="1.570796326794896558" />
    <joint_properties friction="0.0" />
  </joint>

  <joint name="right_sho_pitch" type="revolute">
    <origin xyz="-0.0039999999999983789842 -0.012999999999999045305 -0.014250000000000390826" rpy="-1.5707963267949442976 1.6903145549952781317e-14 -3.1415926535895994931" />
    <parent link="xc430_2" />
    <child link="sho_pitch_link_2" />
    <axis xyz="0 0 1" />
    <limit effort="1" velocity="20" lower="-1.570796326794896558" upper="1.570796326794896558" />
    <joint_properties friction="0.0" />
  </joint>


</robot>