<robot name="toddlerbot">
  <mujoco>
    <compiler strippath="false" balanceinertia="true" discardvisual="false" />
  </mujoco>
  <link name="torso">
    <visual>
      <origin xyz="0 0 0" rpy="0 -0 0" />
      <geometry>
        <mesh filename="../assemblies/toddlerbot/meshes/torso_visual.stl" />
      </geometry>
      <material name="torso_material">
        <color rgba="0.5756764758149645056 0.73345309646743483967 0.85630877307465791404 1.0" />
      </material>
    </visual>
    <inertial>
      <origin xyz="-0.0091211546187125406432 0.0036055430201103995727 0.074702081176469287138" rpy="0 0 0" />
      <mass value="0.60012685450989189384" />
      <inertia ixx="0.0016762683716637551828" ixy="-3.7956721963544869667e-05" ixz="-8.3172104272568887339e-05" iyy="0.0013163016250066178307" iyz="5.6371331396665507135e-05" izz="0.0012676048753457814025" />
    </inertial>
  </link>

  <link name="spur_1m_20t">
    <visual>
      <origin xyz="0 0 0" rpy="0 -0 0" />
      <geometry>
        <mesh filename="../assemblies/toddlerbot/meshes/spur_1m_20t_visual.stl" />
      </geometry>
      <material name="spur_1m_20t_material">
        <color rgba="0.64705882352941179736 0.64705882352941179736 0.64705882352941179736 1.0" />
      </material>
    </visual>
    <inertial>
      <origin xyz="-2.264600315585787176e-18 -7.587391431216789923e-18 0.0033745971730663147647" rpy="0 0 0" />
      <mass value="0.0015534950290892286448" />
      <inertia ixx="4.4726508287871812856e-08" ixy="2.6608965793107671434e-24" ixz="-4.0749910772758008994e-38" iyy="4.4726508287871779768e-08" iyz="-7.464720539392493928e-38" izz="7.9558906764902019844e-08" />
    </inertial>
  </link>

  <joint name="neck_yaw_drive" type="revolute">
    <origin xyz="-0.004999999999999517851 2.6555840535020396321e-18 0.121486510762817565" rpy="1.1318451824181020002e-14 2.6985403517595457696e-15 -5.3863140912757267331e-15" />
    <parent link="torso" />
    <child link="spur_1m_20t" />
    <axis xyz="0 0 1" />
    <limit effort="1" velocity="20" lower="-2.8797932657906435416" upper="2.8797932657906435416" />
    <joint_properties friction="0.0" />
  </joint>

  <link name="neck_yaw_link">
    <visual>
      <origin xyz="0 0 0" rpy="0 -0 0" />
      <geometry>
        <mesh filename="../assemblies/toddlerbot/meshes/neck_yaw_link_visual.stl" />
      </geometry>
      <material name="neck_yaw_link_material">
        <color rgba="0.33636252417476658616 0.48680769190259876034 0.74976123534949778993 1.0" />
      </material>
    </visual>
    <inertial>
      <origin xyz="2.7291286461005574991e-05 -0.00019798992283532067032 0.011527412037194510394" rpy="0 0 0" />
      <mass value="0.0085168305947458267796" />
      <inertia ixx="1.0407116999274246609e-06" ixy="2.4210150466101252425e-11" ixz="-4.7246803217895962011e-10" iyy="1.124000995411045041e-06" iyz="3.0834841754639543074e-08" izz="3.1587565167291430716e-07" />
    </inertial>
  </link>

  <link name="neck_pitch_link">
    <visual>
      <origin xyz="0 0 0" rpy="0 -0 0" />
      <geometry>
        <mesh filename="../assemblies/toddlerbot/meshes/neck_pitch_link_visual.stl" />
      </geometry>
      <material name="neck_pitch_link_material">
        <color rgba="0.74911126277760042846 0.80002799398726853752 0.87441258869524285391 1.0" />
      </material>
    </visual>
    <inertial>
      <origin xyz="-0.0034370497615720967989 0.032876793988991216688 -0.00036476492134677904145" rpy="0 0 0" />
      <mass value="0.11211553874797881847" />
      <inertia ixx="7.7015755459845837709e-05" ixy="-2.1757968319815265661e-06" ixz="-2.8732209413513131827e-06" iyy="6.3502636688153170732e-05" iyz="-1.2492352737634845265e-05" izz="2.8610002383974730313e-05" />
    </inertial>
  </link>

  <link name="spur_gear_(13_teeth)">
    <visual>
      <origin xyz="0 0 0" rpy="0 -0 0" />
      <geometry>
        <mesh filename="../assemblies/toddlerbot/meshes/spur_gear_(13_teeth)_visual.stl" />
      </geometry>
      <material name="spur_gear_(13_teeth)_material">
        <color rgba="0.64705882352941179736 0.64705882352941179736 0.64705882352941179736 1.0" />
      </material>
    </visual>
    <inertial>
      <origin xyz="9.1521555160253732313e-10 -5.4872578733911464024e-10 0.0092751511485596373902" rpy="0 0 0" />
      <mass value="0.00081469437497230865874" />
      <inertia ixx="2.0244841463618380872e-08" ixy="2.9781775007011560058e-15" ixz="-8.2976066071190312301e-15" iyy="2.0244839778533682582e-08" iyz="1.3142117785017221878e-15" izz="1.8905472907863310999e-08" />
    </inertial>
  </link>

  <joint name="neck_pitch_drive" type="revolute">
    <origin xyz="-6.9735883734267645195e-16 0.015649999999999053557 -0.0087999999999970532349" rpy="-1.1409718301987536487e-15 4.409645192886135633e-16 -1.5707963267948976682" />
    <parent link="neck_pitch_link" />
    <child link="spur_gear_(13_teeth)" />
    <axis xyz="0 0 1" />
    <limit effort="1" velocity="20" lower="-2.174948760177549012" upper="2.174948760177549012" />
    <joint_properties friction="0.0" />
  </joint>

  <joint name="neck_pitch_driven" type="revolute">
    <origin xyz="3.7499979510524639181e-10 -0.0051500000614751947903 0.027499999999999941158" rpy="1.5707963267948978903 -2.0825786444073518345e-16 3.141592653589793116" />
    <parent link="neck_yaw_link" />
    <child link="neck_pitch_link" />
    <axis xyz="0 0 1" />
    <limit effort="1" velocity="20" lower="-1.570796326794896558" upper="1.570796326794896558" />
    <joint_properties friction="0.0" />
  </joint>

  <joint name="neck_yaw_driven" type="revolute">
    <origin xyz="0.016000000000001235456 2.2310681558151314601e-17 0.12248651076281746874" rpy="-4.8668742840765556337e-16 -4.0649010562893427138e-15 3.141592653589793116" />
    <parent link="torso" />
    <child link="neck_yaw_link" />
    <axis xyz="0 0 1" />
    <limit effort="1" velocity="20" lower="-2.6179938779914944114" upper="2.6179938779914944114" />
    <joint_properties friction="0.0" />
  </joint>

  <link name="waist_gears">
    <visual>
      <origin xyz="0 0 0" rpy="0 -0 0" />
      <geometry>
        <mesh filename="../assemblies/toddlerbot/meshes/waist_gears_visual.stl" />
      </geometry>
      <material name="waist_gears_material">
        <color rgba="0.26285745258304310523 0.51761993404322359513 0.70089950218325269837 1.0" />
      </material>
    </visual>
    <inertial>
      <origin xyz="-2.9615196346148577302e-07 5.6324425198301108519e-08 -0.012591728437027502677" rpy="0 0 0" />
      <mass value="0.025874065810895640477" />
      <inertia ixx="1.5221462961926445333e-06" ixy="1.8766602079766916675e-11" ixz="4.0586927770605968901e-10" iyy="7.280142068668490794e-06" iyz="3.1229108550824058464e-12" izz="6.9639458993359299767e-06" />
    </inertial>
  </link>

  <link name="waist_link">
    <visual>
      <origin xyz="0 0 0" rpy="0 -0 0" />
      <geometry>
        <mesh filename="../assemblies/toddlerbot/meshes/waist_link_visual.stl" />
      </geometry>
      <material name="waist_link_material">
        <color rgba="0.63401200025306059249 0.68204699127249923674 0.6691019398503622595 1.0" />
      </material>
    </visual>
    <inertial>
      <origin xyz="-9.1086191337257426703e-07 0.026204483755308753679 -0.030190392008842579369" rpy="0 0 0" />
      <mass value="0.16631953490612461088" />
      <inertia ixx="6.8622997376114634803e-05" ixy="-6.1328048461882665927e-10" ixz="-3.6786792027265062734e-06" iyy="0.00020057117429216644823" iyz="-3.7255079147358398249e-06" izz="0.00015770127977213132457" />
    </inertial>
  </link>

  <link name="spiral_bevel_1m_14t_30deg">
    <visual>
      <origin xyz="0 0 0" rpy="0 -0 0" />
      <geometry>
        <mesh filename="../assemblies/toddlerbot/meshes/spiral_bevel_1m_14t_30deg_visual.stl" />
      </geometry>
      <material name="spiral_bevel_1m_14t_30deg_material">
        <color rgba="0.64705882352941179736 0.64705882352941179736 0.64705882352941179736 1.0" />
      </material>
    </visual>
    <inertial>
      <origin xyz="7.4971447279470481499e-10 7.1802237332913011122e-10 0.0066868955018979103766" rpy="0 0 0" />
      <mass value="0.00073261524436595492574" />
      <inertia ixx="1.3495056019478195011e-08" ixy="4.0596681656909248509e-17" ixz="8.599255017511676462e-16" iyy="1.3495056150237195634e-08" iyz="-6.7913008233741570648e-16" izz="1.4355986549816408408e-08" />
    </inertial>
  </link>

  <joint name="waist_act_1" type="revolute">
    <origin xyz="5.7457652915638341522e-17 0.019599999999999964673 -0.012750000000000025202" rpy="1.5707963267948954478 1.570796326794896336 0" />
    <parent link="waist_link" />
    <child link="spiral_bevel_1m_14t_30deg" />
    <axis xyz="0 0 1" />
    <limit effort="1" velocity="20" lower="-4.6774823953448034786" upper="4.6774823953448034786" />
    <joint_properties friction="0.0" />
  </joint>

  <link name="spiral_bevel_1m_14t_30deg_2">
    <visual>
      <origin xyz="0 0 0" rpy="0 -0 0" />
      <geometry>
        <mesh filename="../assemblies/toddlerbot/meshes/spiral_bevel_1m_14t_30deg_2_visual.stl" />
      </geometry>
      <material name="spiral_bevel_1m_14t_30deg_2_material">
        <color rgba="0.64705882352941179736 0.64705882352941179736 0.64705882352941179736 1.0" />
      </material>
    </visual>
    <inertial>
      <origin xyz="5.711425533905245544e-10 8.6684721906479195987e-10 0.0066868955018979190502" rpy="0 0 0" />
      <mass value="0.00073261524436595492574" />
      <inertia ixx="1.3495056008338566936e-08" ixy="8.2092443034011452773e-18" ixz="9.8948603423502891461e-16" iyy="1.3495056161376838597e-08" iyz="-4.7075144749766452119e-16" izz="1.43559865498164051e-08" />
    </inertial>
  </link>

  <joint name="waist_act_2" type="revolute">
    <origin xyz="4.2745485696894321379e-17 0.019600000000000013245 -0.032749999999999994393" rpy="1.5707963267948956698 1.3463968515392303882 6.7698458176426589005e-15" />
    <parent link="waist_link" />
    <child link="spiral_bevel_1m_14t_30deg_2" />
    <axis xyz="0 0 1" />
    <limit effort="1" velocity="20" lower="-4.6774823953448034786" upper="4.6774823953448034786" />
    <joint_properties friction="0.0" />
  </joint>

  <link name="spur_gear_19_teeth">
    <visual>
      <origin xyz="0 0 0" rpy="0 -0 0" />
      <geometry>
        <mesh filename="../assemblies/toddlerbot/meshes/spur_gear_19_teeth_visual.stl" />
      </geometry>
      <material name="spur_gear_19_teeth_material">
        <color rgba="0.61568627450980395466 0.81176470588235294379 0.92941176470588238168 1.0" />
      </material>
    </visual>
    <inertial>
      <origin xyz="-4.7403242595143773768e-08 1.5460070764038637399e-08 0.0045456071298370023803" rpy="0 0 0" />
      <mass value="0.0011084409433758843876" />
      <inertia ixx="2.9582691212226700665e-08" ixy="-2.8904821292895135249e-14" ixz="7.8892082291036886091e-14" iyy="2.9582612758414119977e-08" iyz="-2.5767358059768096423e-14" izz="4.6351510704080136144e-08" />
    </inertial>
  </link>

  <joint name="left_hip_yaw_drive" type="revolute">
    <origin xyz="-0.036999999999998457734 0.037100000000005961542 -0.03950000000000024325" rpy="-1.5707963267949545116 -4.8003070743589248247e-13 -3.5749181392930616155e-13" />
    <parent link="waist_link" />
    <child link="spur_gear_19_teeth" />
    <axis xyz="0 0 1" />
    <limit effort="1" velocity="20" lower="-1.7361433085627806516" upper="1.7361433085627806516" />
    <joint_properties friction="0.0" />
  </joint>

  <link name="spur_gear_21_teeth">
    <visual>
      <origin xyz="0 0 0" rpy="0 -0 0" />
      <geometry>
        <mesh filename="../assemblies/toddlerbot/meshes/spur_gear_21_teeth_visual.stl" />
      </geometry>
      <material name="spur_gear_21_teeth_material">
        <color rgba="0.61568627450980395466 0.81176470588235294379 0.92941176470588238168 1.0" />
      </material>
    </visual>
    <inertial>
      <origin xyz="-6.7030730388797144104e-12 1.7758939849553634854e-11 0.0024945285429905615648" rpy="0 0 0" />
      <mass value="0.0010185686142775147826" />
      <inertia ixx="3.2410681505051109819e-08" ixy="-5.0070048685720157271e-39" ixz="-1.6778767679075106483e-38" iyy="3.2410681506302329683e-08" iyz="-2.1489356052918171638e-38" izz="6.0614091765677406549e-08" />
    </inertial>
  </link>

  <joint name="left_leg_fixed" type="fixed">
    <origin xyz="0 0 0.004999999999999997502" rpy="3.1415926535897926719 -1.9428902930939016723e-16 -7.6327832942984196016e-16" />
    <parent link="spur_gear_21_teeth" />
    <child link="hip_yaw_link" />
    <axis xyz="0 0 1" />
    <limit effort="1" velocity="20" />
    <joint_properties friction="0.0" />
  </joint>

  <joint name="left_hip_yaw_driven" type="revolute">
    <origin xyz="-0.036999999999999998168 0.041100000000000011524 -0.019500000000000027728" rpy="-1.5707963267948947816 -1.570796326794896558 0" />
    <parent link="waist_link" />
    <child link="spur_gear_21_teeth" />
    <axis xyz="0 0 1" />
    <limit effort="1" velocity="20" lower="-1.570796326794896558" upper="1.570796326794896558" />
    <joint_properties friction="0.0" />
  </joint>

  <link name="spur_gear_19_teeth_2">
    <visual>
      <origin xyz="0 0 0" rpy="0 -0 0" />
      <geometry>
        <mesh filename="../assemblies/toddlerbot/meshes/spur_gear_19_teeth_2_visual.stl" />
      </geometry>
      <material name="spur_gear_19_teeth_2_material">
        <color rgba="0.61568627450980395466 0.81176470588235294379 0.92941176470588238168 1.0" />
      </material>
    </visual>
    <inertial>
      <origin xyz="-4.7403242595143773768e-08 1.5460070764038640708e-08 0.0045456071298370023803" rpy="0 0 0" />
      <mass value="0.0011084409433758843876" />
      <inertia ixx="2.9582691212226700665e-08" ixy="-2.8904821292766292175e-14" ixz="7.8892082291036886091e-14" iyy="2.9582612758414133212e-08" iyz="-2.5767358059768102734e-14" izz="4.6351510704080136144e-08" />
    </inertial>
  </link>

  <joint name="right_hip_yaw_drive" type="revolute">
    <origin xyz="0.037000000000001719014 0.03710000000000327619 -0.0394999999999998061" rpy="-1.5707963267949545116 -4.8002361403961149694e-13 -3.5216274341110541015e-13" />
    <parent link="waist_link" />
    <child link="spur_gear_19_teeth_2" />
    <axis xyz="0 0 1" />
    <limit effort="1" velocity="20" lower="-1.7361433085627806516" upper="1.7361433085627806516" />
    <joint_properties friction="0.0" />
  </joint>

  <link name="spur_gear_21_teeth_2">
    <visual>
      <origin xyz="0 0 0" rpy="0 -0 0" />
      <geometry>
        <mesh filename="../assemblies/toddlerbot/meshes/spur_gear_21_teeth_2_visual.stl" />
      </geometry>
      <material name="spur_gear_21_teeth_2_material">
        <color rgba="0.61568627450980395466 0.81176470588235294379 0.92941176470588238168 1.0" />
      </material>
    </visual>
    <inertial>
      <origin xyz="-6.7030730388797144104e-12 -1.7758939849553634854e-11 0.0025054714570094428761" rpy="0 0 0" />
      <mass value="0.0010185686142775147826" />
      <inertia ixx="3.2410681505051109819e-08" ixy="8.7148977985253644487e-40" ixz="1.7387576366417533163e-38" iyy="3.2410681506302329683e-08" iyz="2.053667615524067426e-38" izz="6.0614091765677406549e-08" />
    </inertial>
  </link>

  <joint name="right_leg_fixed" type="fixed">
    <origin xyz="0 -6.9388939039072283776e-18 0.0050000000000000044409" rpy="-3.1415926535897926719 1.8281169925220331315e-17 -3.5772536718062127375e-16" />
    <parent link="spur_gear_21_teeth_2" />
    <child link="hip_yaw_link_2" />
    <axis xyz="0 0 1" />
    <limit effort="1" velocity="20" />
    <joint_properties friction="0.0" />
  </joint>

  <joint name="right_hip_yaw_driven" type="revolute">
    <origin xyz="0.036999999999999991229 0.041100000000000011524 -0.019500000000000017319" rpy="-1.570796326794896558 -1.5707963267948961139 0" />
    <parent link="waist_link" />
    <child link="spur_gear_21_teeth_2" />
    <axis xyz="0 0 1" />
    <limit effort="1" velocity="20" lower="-1.570796326794896558" upper="1.570796326794896558" />
    <joint_properties friction="0.0" />
  </joint>

  <joint name="waist_roll" type="revolute">
    <origin xyz="-0.022707865260692617487 -2.4393502827093082036e-16 -0.013999999999999814676" rpy="-1.5707963267948974462 1.8675461532229772614e-15 1.5707963267948952257" />
    <parent link="waist_gears" />
    <child link="waist_link" />
    <axis xyz="0 0 1" />
    <limit effort="1" velocity="20" lower="-0.52359877559829881566" upper="0.52359877559829881566" />
    <joint_properties friction="0.0" />
  </joint>

  <joint name="waist_yaw" type="revolute">
    <origin xyz="0 -3.1104917983741196655e-18 -7.5188305028877687703e-30" rpy="-1.4111145075746007461e-16 -4.1376224834060906822e-15 3.1415926535897922278" />
    <parent link="torso" />
    <child link="waist_gears" />
    <axis xyz="0 0 1" />
    <limit effort="1" velocity="20" lower="-1.570796326794896558" upper="1.570796326794896558" />
    <joint_properties friction="0.0" />
  </joint>

  <joint name="left_sho_pitch" type="revolute">
    <origin xyz="-0.0030000000000002949654 0.062000000000001082023 0.10423651076281743866" rpy="-1.5707963267949081043 -4.127643409825574977e-14 3.4723733359249779961e-14" />
    <parent link="torso" />
    <child link="sho_pitch_link" />
    <axis xyz="0 0 1" />
    <limit effort="1" velocity="20" lower="-3.141592653589793116" upper="1.570796326794896558" />
    <joint_properties friction="0.0" />
  </joint>

  <joint name="right_sho_pitch" type="revolute">
    <origin xyz="-0.0029999999999986998872 -0.06200000000000097794 0.10423651076281731376" rpy="-1.5707963267948885644 3.4812325502379109658e-14 -3.1415926535897562566" />
    <parent link="torso" />
    <child link="sho_pitch_link_2" />
    <axis xyz="0 0 1" />
    <limit effort="1" velocity="20" lower="-1.570796326794896558" upper="3.141592653589793116" />
    <joint_properties friction="0.0" />
  </joint>


  <link name="hip_yaw_link">
    <visual>
      <origin xyz="0 0 0" rpy="0 -0 0" />
      <geometry>
        <mesh filename="../assemblies/left_leg_XM430/meshes/left_hip_yaw_link_visual.stl" />
      </geometry>
      <material name="hip_yaw_link_material">
        <color rgba="0.61568627450980395466 0.81176470588235294379 0.92941176470588238168 1.0" />
      </material>
    </visual>
    <inertial>
      <origin xyz="-2.6052892110043261802e-19 -4.5779561945300561906e-19 -0.0098390489054829104176" rpy="0 0 0" />
      <mass value="0.017999999999999988232" />
      <inertia ixx="2.6385033891442523914e-06" ixy="0" ixz="0" iyy="7.6596731957046873405e-06" iyz="0" izz="7.7220708070894735956e-06" />
    </inertial>
  </link>

  <link name="hip_roll_link">
    <visual>
      <origin xyz="0 0 0" rpy="0 -0 0" />
      <geometry>
        <mesh filename="../assemblies/left_leg_XM430/meshes/left_hip_roll_link_visual.stl" />
      </geometry>
      <material name="hip_roll_link_material">
        <color rgba="0.51698661238356047321 0.50347815951093488618 0.49050589017722012741 1.0" />
      </material>
    </visual>
    <inertial>
      <origin xyz="-0.011999849582186344205 -0.00049598090793799955514 -0.018504111838598794743" rpy="0 0 0" />
      <mass value="0.11059999999836234164" />
      <inertia ixx="2.2818802599019123213e-05" ixy="-4.6520143286798432356e-08" ixz="-4.6888548260596792068e-08" iyy="3.0871632082339373363e-05" iyz="-5.7477343899716644859e-07" izz="3.0871666424470007293e-05" />
    </inertial>
  </link>

  <link name="left_hip_pitch_link_xm430">
    <visual>
      <origin xyz="0 0 0" rpy="0 -0 0" />
      <geometry>
        <mesh filename="../assemblies/left_leg_XM430/meshes/left_hip_pitch_link_xm430_visual.stl" />
      </geometry>
      <material name="left_hip_pitch_link_xm430_material">
        <color rgba="0.87072221357329560032 0.72641010956094276274 0.24785169615220706274 1.0" />
      </material>
    </visual>
    <inertial>
      <origin xyz="-0.00075729214155315050742 -0.050714785675264821563 -0.012656155119959915795" rpy="0 0 0" />
      <mass value="0.11480090135030569798" />
      <inertia ixx="6.6072773889430024214e-05" ixy="-4.6080149277727762285e-07" ixz="-1.8170739115308462457e-07" iyy="2.3633638685369530631e-05" iyz="1.4125253925343164532e-06" izz="6.2221728804333383662e-05" />
    </inertial>
  </link>

  <link name="left_calf_link">
    <visual>
      <origin xyz="0 0 0" rpy="0 -0 0" />
      <geometry>
        <mesh filename="../assemblies/left_leg_XM430/meshes/left_calf_link_visual.stl" />
      </geometry>
      <material name="left_calf_link_material">
        <color rgba="0.616547745550632742 0.7175754134247219751 0.74372657889541438081 1.0" />
      </material>
    </visual>
    <inertial>
      <origin xyz="0.0016330556739555508825 -0.050045528174708635294 -0.0099079425125447578154" rpy="0 0 0" />
      <mass value="0.086799999986183581924" />
      <inertia ixx="4.950945987320032126e-05" ixy="3.6911110041724887421e-06" ixz="4.181905803998413212e-07" iyy="1.5531229037964085102e-05" iyz="4.6309763568422332319e-07" izz="5.3138661991212950706e-05" />
    </inertial>
  </link>

  <link name="bearing_683">
    <visual>
      <origin xyz="0 0 0" rpy="0 -0 0" />
      <geometry>
        <mesh filename="../assemblies/left_leg_XM430/meshes/left_bearing_683_visual.stl" />
      </geometry>
      <material name="bearing_683_material">
        <color rgba="0.64705882352941179736 0.64705882352941179736 0.64705882352941179736 1.0" />
      </material>
    </visual>
    <inertial>
      <origin xyz="1.0732094295242497084e-19 -2.4186774283160283989e-19 -0.0015500000000000003792" rpy="0 0 0" />
      <mass value="0.00048694686130641793437" />
      <inertia ixx="2.1551456503319879113e-09" ixy="2.3666528901256796113e-27" ixz="2.0889236366122119332e-38" iyy="2.1551456503319891521e-09" iyz="1.3744560845328921415e-38" izz="3.5303647444715305817e-09" />
    </inertial>
  </link>

  <joint name="left_knee_front_rev_2" type="revolute">
    <origin xyz="-0.0057402514854770240668 0.013858192987668910279 -0.026200000000000563116" rpy="2.0453876360821841634e-16 7.1068359470475064937e-16 1.5765314753541341819" />
    <parent link="left_calf_link" />
    <child link="bearing_683" />
    <axis xyz="0 0 1" />
    <limit effort="1" velocity="20" lower="-6.283185307179586232" upper="6.283185307179586232" />
    <joint_properties friction="0.0" />
  </joint>

  <link name="bearing_683_2">
    <visual>
      <origin xyz="0 0 0" rpy="0 -0 0" />
      <geometry>
        <mesh filename="../assemblies/left_leg_XM430/meshes/left_bearing_683_2_visual.stl" />
      </geometry>
      <material name="bearing_683_2_material">
        <color rgba="0.64705882352941179736 0.64705882352941179736 0.64705882352941179736 1.0" />
      </material>
    </visual>
    <inertial>
      <origin xyz="1.0732094295248846635e-19 -2.4186774283160375471e-19 -0.0015500000000000003792" rpy="0 0 0" />
      <mass value="0.00048694686130641793437" />
      <inertia ixx="2.1551456503319887385e-09" ixy="-1.3855900387721121507e-27" ixz="-1.9257410757015346214e-37" iyy="2.1551456503319874977e-09" iyz="-2.8124792185573659681e-39" izz="3.5303647444715305817e-09" />
    </inertial>
  </link>

  <joint name="left_knee_back_rev_2" type="revolute">
    <origin xyz="0.0057402514854760517543 -0.013858192987669437635 -0.026200000000000216172" rpy="2.8877467674261435159e-16 -6.2660216643685709814e-15 1.5765686202203079702" />
    <parent link="left_calf_link" />
    <child link="bearing_683_2" />
    <axis xyz="0 0 1" />
    <limit effort="1" velocity="20" lower="-6.283185307179586232" upper="6.283185307179586232" />
    <joint_properties friction="0.0" />
  </joint>

  <link name="ank_pitch_link">
    <visual>
      <origin xyz="0 0 0" rpy="0 -0 0" />
      <geometry>
        <mesh filename="../assemblies/left_leg_XM430/meshes/left_ank_pitch_link_visual.stl" />
      </geometry>
      <material name="ank_pitch_link_material">
        <color rgba="0.63189161126160264814 0.7266866879354088038 0.78356373393969258601 1.0" />
      </material>
    </visual>
    <inertial>
      <origin xyz="0.00059528282565903347691 -4.0269677046895822506e-08 7.7616091227946370715e-08" rpy="0 0 0" />
      <mass value="0.0042238381753791614387" />
      <inertia ixx="3.9782741364681224752e-07" ixy="-1.6834347544690341436e-13" ixz="2.09191870411591794e-14" iyy="4.3705254067426624596e-07" iyz="-1.6428821654626687343e-12" izz="8.8858574534620810897e-08" />
    </inertial>
  </link>

  <link name="ank_roll_link">
    <visual>
      <origin xyz="0 0 0" rpy="0 -0 0" />
      <geometry>
        <mesh filename="../assemblies/left_leg_XM430/meshes/left_ank_roll_link_visual.stl" />
      </geometry>
      <material name="ank_roll_link_material">
        <color rgba="0.61568627450980395466 0.81176470588235294379 0.92941176470588227065 1.0" />
      </material>
    </visual>
    <collision name="ank_roll_link_collision">
      <origin xyz="0.0 0.016499999444931746 0.008400000631809235" rpy="0 0 0" />
      <geometry>
        <box size="0.041999999433755875 0.04500000271946192 0.12000000476837158" />
      </geometry>
    </collision>
    <inertial>
      <origin xyz="-3.2206255610852245098e-10 0.030487683096149076345 0.0047792578419041014184" rpy="0 0 0" />
      <mass value="0.027200000000000008893" />
      <inertia ixx="2.2943463470325727e-05" ixy="-2.0167229481717782239e-13" ixz="4.0806229578615089115e-12" iyy="2.5276617323505065215e-05" iyz="-7.4169474455435566413e-07" izz="5.0976619075837788231e-06" />
    </inertial>
  </link>

  <link name="ank_rr_link">
    <visual>
      <origin xyz="0 0 0" rpy="0 -0 0" />
      <geometry>
        <mesh filename="../assemblies/left_leg_XM430/meshes/left_ank_rr_link_visual.stl" />
      </geometry>
      <material name="ank_rr_link_material">
        <color rgba="0.61568627450980395466 0.81176470588235294379 0.92941176470588238168 1.0" />
      </material>
    </visual>
    <inertial>
      <origin xyz="-4.5249610960606115111e-05 0.00630964298363145739 -2.0009406464642610885e-19" rpy="0 0 0" />
      <mass value="0.0014499999999999999001" />
      <inertia ixx="2.9739579267716143416e-08" ixy="2.4213146797977855138e-10" ixz="3.5523394884432783644e-14" iyy="2.7430027724071957055e-08" iyz="-9.8997471197656441548e-32" izz="4.2921949116163672436e-08" />
    </inertial>
  </link>

  <link name="ank_motor_rod_long">
    <visual>
      <origin xyz="0 0 0" rpy="0 -0 0" />
      <geometry>
        <mesh filename="../assemblies/left_leg_XM430/meshes/left_ank_motor_rod_long_visual.stl" />
      </geometry>
      <material name="ank_motor_rod_long_material">
        <color rgba="0.63549975559783222767 0.7077439301702044272 0.75109043491362770251 1.0" />
      </material>
    </visual>
    <inertial>
      <origin xyz="2.485508918145648815e-10 0.034559019974062257785 0.00093851704878453840689" rpy="0 0 0" />
      <mass value="0.0021712857268636710437" />
      <inertia ixx="8.535029005800039023e-07" ixy="1.4884244732590480163e-14" ixz="4.5749525025589543898e-11" iyy="1.3237321792739536015e-08" iyz="-4.3668910960857039398e-09" izz="8.5812217519451768749e-07" />
    </inertial>
  </link>

  <joint name="left_ank_long_rev_2" type="revolute">
    <origin xyz="2.4286128663675299322e-17 0.0099999999999992872368 1.3947176746853529039e-15" rpy="-1.5707963267948974462 1.3320366994105963254 -1.5707963267949054398" />
    <parent link="ank_rr_link" />
    <child link="ank_motor_rod_long" />
    <axis xyz="0 0 1" />
    <limit effort="1" velocity="20" lower="-1.570796326794896558" upper="1.570796326794896558" />
    <joint_properties friction="0.0" />
  </joint>

  <joint name="left_ank_long_rev_1" type="revolute">
    <origin xyz="-0.018000000000000064559 0.015999999999999292566 -0.020600000000001391504" rpy="-2.876394309884160705e-16 1.6317439732762683578e-16 3.1233695685467286474" />
    <parent link="ank_roll_link" />
    <child link="ank_rr_link" />
    <axis xyz="0 0 1" />
    <limit effort="1" velocity="20" lower="-1.570796326794896558" upper="1.570796326794896558" />
    <joint_properties friction="0.0" />
  </joint>

  <link name="ank_rr_link_2">
    <visual>
      <origin xyz="0 0 0" rpy="0 -0 0" />
      <geometry>
        <mesh filename="../assemblies/left_leg_XM430/meshes/left_ank_rr_link_2_visual.stl" />
      </geometry>
      <material name="ank_rr_link_2_material">
        <color rgba="0.61568627450980395466 0.81176470588235294379 0.92941176470588238168 1.0" />
      </material>
    </visual>
    <inertial>
      <origin xyz="-4.5249610960599155889e-05 -0.0063096429836314027462 3.6695410166003840762e-18" rpy="0 0 0" />
      <mass value="0.0014499999999999999001" />
      <inertia ixx="2.9739579267716150033e-08" ixy="-2.4213146797977875817e-10" ixz="-3.5523394884432789955e-14" iyy="2.7430027724071957055e-08" iyz="-6.0455732447540710973e-32" izz="4.2921949116163672436e-08" />
    </inertial>
  </link>

  <link name="ank_motor_rod_short">
    <visual>
      <origin xyz="0 0 0" rpy="0 -0 0" />
      <geometry>
        <mesh filename="../assemblies/left_leg_XM430/meshes/left_ank_motor_rod_short_visual.stl" />
      </geometry>
      <material name="ank_motor_rod_short_material">
        <color rgba="0.41222606689734719865 0.58339100346020766885 0.8110726643598615837 1.0" />
      </material>
    </visual>
    <inertial>
      <origin xyz="2.6038941310109507631e-10 0.023830465465870951519 0.00090403506359623014323" rpy="0 0 0" />
      <mass value="0.0017000000000000001221" />
      <inertia ixx="3.3153416252670235948e-07" ixy="8.7419768620623363038e-15" ixz="4.5749941567727589348e-11" iyy="1.0947363610305772565e-08" iyz="-3.5863098646405051489e-09" izz="3.3621340447865384922e-07" />
    </inertial>
  </link>

  <joint name="left_ank_short_rev_2" type="revolute">
    <origin xyz="0 -0.0099999999999998978595 0" rpy="-1.570796326794896558 -1.2119133862909823307 -1.570796326794896336" />
    <parent link="ank_rr_link_2" />
    <child link="ank_motor_rod_short" />
    <axis xyz="0 0 1" />
    <limit effort="1" velocity="20" lower="-1.570796326794896558" upper="1.570796326794896558" />
    <joint_properties friction="0.0" />
  </joint>

  <joint name="left_ank_short_rev_1" type="revolute">
    <origin xyz="0.017999999999999953537 0.016000000000000014211 -0.020600000000000010664" rpy="4.2172831995673088897e-16 -4.4678623027074358005e-17 0.026118548507422217203" />
    <parent link="ank_roll_link" />
    <child link="ank_rr_link_2" />
    <axis xyz="0 0 1" />
    <limit effort="1" velocity="20" lower="-1.570796326794896558" upper="1.570796326794896558" />
    <joint_properties friction="0.0" />
  </joint>

  <joint name="left_ank_roll" type="revolute">
    <origin xyz="0.0014999999999999995975 0 -1.5395670849294162963e-17" rpy="9.9573127520767875392e-16 1.570796326794891673 0" />
    <parent link="ank_pitch_link" />
    <child link="ank_roll_link" />
    <axis xyz="0 0 1" />
    <limit effort="1" velocity="20" lower="-0.785398163397448279" upper="0.785398163397448279" />
    <joint_properties friction="0.0" />
  </joint>

  <joint name="left_ank_pitch" type="revolute">
    <origin xyz="1.5349482163618395221e-15 -0.099999999999999339417 -0.01039999999999923451" rpy="1.0427422814103565708e-14 3.7115492970717391096e-15 3.1415926535897922278" />
    <parent link="left_calf_link" />
    <child link="ank_pitch_link" />
    <axis xyz="0 0 1" />
    <limit effort="1" velocity="20" lower="-1.0471975511965976313" upper="0.785398163397448279" />
    <joint_properties friction="0.0" />
  </joint>

  <link name="ank_motor_arm">
    <visual>
      <origin xyz="0 0 0" rpy="0 -0 0" />
      <geometry>
        <mesh filename="../assemblies/left_leg_XM430/meshes/left_ank_motor_arm_visual.stl" />
      </geometry>
      <material name="ank_motor_arm_material">
        <color rgba="0.62483822591633164656 0.70971956673896574586 0.76585356440212004614 1.0" />
      </material>
    </visual>
    <inertial>
      <origin xyz="0.014032842952293513375 -1.1875681051906339057e-09 0.0040383546575275958146" rpy="0 0 0" />
      <mass value="0.0021359401157891211472" />
      <inertia ixx="2.9209776528328194436e-08" ixy="-4.6752002052090677473e-14" ixz="-3.1659407525131264056e-08" iyy="1.7718014185775920105e-07" iyz="-2.5844348438515616861e-15" izz="1.8139327643022061737e-07" />
    </inertial>
  </link>

  <joint name="left_ank_act_1" type="revolute">
    <origin xyz="0.013500000000001635692 -0.044499999999992628785 0.0040000000000077733792" rpy="-5.7683923736819409867e-13 -7.5455504046046331278e-14 -0.21173394130254355461" />
    <parent link="left_calf_link" />
    <child link="ank_motor_arm" />
    <axis xyz="0 0 1" />
    <limit effort="1" velocity="20" lower="-1.3089969389957472057" upper="1.3089969389957472057" />
    <joint_properties friction="0.0" />
  </joint>

  <link name="ank_motor_arm_2">
    <visual>
      <origin xyz="0 0 0" rpy="0 -0 0" />
      <geometry>
        <mesh filename="../assemblies/left_leg_XM430/meshes/left_ank_motor_arm_2_visual.stl" />
      </geometry>
      <material name="ank_motor_arm_2_material">
        <color rgba="0.62483822591633164656 0.70971956673896574586 0.76585356440212004614 1.0" />
      </material>
    </visual>
    <inertial>
      <origin xyz="0.014032842952293501232 -1.1875680925106995778e-09 0.0040383546575276053556" rpy="0 0 0" />
      <mass value="0.0021359401157891211472" />
      <inertia ixx="2.9209776528328022382e-08" ixy="-4.6752001844237150679e-14" ixz="-3.165940752513130376e-08" iyy="1.7718014185775885694e-07" iyz="-2.5844347879891186066e-15" izz="1.8139327643022061737e-07" />
    </inertial>
  </link>

  <joint name="left_ank_act_2" type="revolute">
    <origin xyz="0.013500000000005811171 -0.064499999999988344435 -0.024800000000003163264" rpy="-3.1415926535893312632 1.9218128864630526701e-14 -0.22995607267384915451" />
    <parent link="left_calf_link" />
    <child link="ank_motor_arm_2" />
    <axis xyz="0 0 1" />
    <limit effort="1" velocity="20" lower="-1.3089969389957472057" upper="1.3089969389957472057" />
    <joint_properties friction="0.0" />
  </joint>

  <joint name="left_knee_pitch" type="revolute">
    <origin xyz="3.1436708451941898537e-17 -0.096000000000000001998 -0.0092000000000000154571" rpy="5.2388648972145238601e-16 -5.3048676098335846568e-16 -5.5511151227572361317e-17" />
    <parent link="left_hip_pitch_link_xm430" />
    <child link="left_calf_link" />
    <axis xyz="0 0 1" />
    <limit effort="1" velocity="20" lower="0" upper="1.9198621771937625091" />
    <joint_properties friction="0.0" />
  </joint>

  <link name="xm430_plate">
    <visual>
      <origin xyz="0 0 0" rpy="0 -0 0" />
      <geometry>
        <mesh filename="../assemblies/left_leg_XM430/meshes/left_xm430_plate_visual.stl" />
      </geometry>
      <material name="xm430_plate_material">
        <color rgba="0.61568627450980395466 0.81176470588235294379 0.9294117647058824927 1.0" />
      </material>
    </visual>
    <inertial>
      <origin xyz="3.3859260150270524496e-18 2.0528781890801290596e-18 -0.0024039046431217955119" rpy="0 0 0" />
      <mass value="0.0026999999999999992756" />
      <inertia ixx="1.293311664536341083e-07" ixy="-6.8936588702566413944e-08" ixz="5.4735536363229128674e-35" iyy="2.672043438587668303e-07" iyz="-6.5325103416928993699e-36" izz="3.8533537562751439267e-07" />
    </inertial>
  </link>

  <link name="knee_rod">
    <visual>
      <origin xyz="0 0 0" rpy="0 -0 0" />
      <geometry>
        <mesh filename="../assemblies/left_leg_XM430/meshes/left_knee_rod_visual.stl" />
      </geometry>
      <material name="knee_rod_material">
        <color rgba="0.62051618944235198416 0.78640765248647581664 0.88594253031295022716 1.0" />
      </material>
    </visual>
    <inertial>
      <origin xyz="0.014594549254227703189 -4.0495174182604799708e-05 -0.0015996227373190293787" rpy="0 0 0" />
      <mass value="0.0031629468613064179276" />
      <inertia ixx="2.5896066719679945792e-08" ixy="3.4015849028409630471e-10" ixz="4.1682980135095627253e-10" iyy="6.015325433306769779e-07" iyz="-1.1565684637535341676e-12" izz="6.2266854577246018566e-07" />
    </inertial>
  </link>

  <joint name="left_knee_front_rev_1" type="revolute">
    <origin xyz="0.013858192987669312735 0.0057402514854763336469 -0.0049999999999999836242" rpy="-9.4192987622433650731e-16 3.8593656109062736187e-16 -3.1358575050305752541" />
    <parent link="xm430_plate" />
    <child link="knee_rod" />
    <axis xyz="0 0 1" />
    <limit effort="1" velocity="20" lower="-6.283185307179586232" upper="6.283185307179586232" />
    <joint_properties friction="0.0" />
  </joint>

  <link name="knee_rod_2">
    <visual>
      <origin xyz="0 0 0" rpy="0 -0 0" />
      <geometry>
        <mesh filename="../assemblies/left_leg_XM430/meshes/left_knee_rod_2_visual.stl" />
      </geometry>
      <material name="knee_rod_2_material">
        <color rgba="0.62051618944235198416 0.78640765248647581664 0.88594253031295022716 1.0" />
      </material>
    </visual>
    <inertial>
      <origin xyz="0.014594547729902918737 -4.1579390108021769244e-05 -0.0015996227373185551487" rpy="0 0 0" />
      <mass value="0.0031629468613064179276" />
      <inertia ixx="2.5896117936396398863e-08" ixy="3.4926584154272074411e-10" ixz="4.1682975780794631615e-10" iyy="6.0153251772212437219e-07" iyz="-1.1875343734383760925e-12" izz="6.2266857138059509825e-07" />
    </inertial>
  </link>

  <joint name="left_knee_back_rev_1" type="revolute">
    <origin xyz="-0.013858192987669284979 -0.0057402514854763449226 -0.0050000000000000009714" rpy="-1.240696991414760872e-15 6.8873592505729608146e-15 -3.1358203601644016878" />
    <parent link="xm430_plate" />
    <child link="knee_rod_2" />
    <axis xyz="0 0 1" />
    <limit effort="1" velocity="20" lower="-6.283185307179586232" upper="6.283185307179586232" />
    <joint_properties friction="0.0" />
  </joint>

  <joint name="left_knee_act" type="revolute">
    <origin xyz="-0.00015000000000007682969 -0.061499999999999728495 -0.030399999999999843814" rpy="-1.3864621477766001324e-15 9.2520451941214004081e-17 1.5707963267949205388" />
    <parent link="left_hip_pitch_link_xm430" />
    <child link="xm430_plate" />
    <axis xyz="0 0 1" />
    <limit effort="1" velocity="20" lower="0" upper="1.9198621771937625091" />
    <joint_properties friction="0.0" />
  </joint>

  <joint name="left_hip_pitch" type="revolute">
    <origin xyz="-0.024000000716155701214 -0.019000000152439879691 -0.019000000152457872243" rpy="1.570796326795379283 1.5707963267945606045 0" />
    <parent link="hip_roll_link" />
    <child link="left_hip_pitch_link_xm430" />
    <axis xyz="0 0 1" />
    <limit effort="1" velocity="20" lower="-1.570796326794896558" upper="1.570796326794896558" />
    <joint_properties friction="0.0" />
  </joint>

  <joint name="left_hip_roll" type="revolute">
    <origin xyz="0.018999999999999999528 -3.3500438890366171686e-18 -0.026000000000000002276" rpy="3.141592653589793116 -1.5707963267948930053 0" />
    <parent link="hip_yaw_link" />
    <child link="hip_roll_link" />
    <axis xyz="0 0 1" />
    <limit effort="1" velocity="20" lower="-0.785398163397448279" upper="0.785398163397448279" />
    <joint_properties friction="0.0" />
  </joint>


  <link name="hip_yaw_link_2">
    <visual>
      <origin xyz="0 0 0" rpy="0 -0 0" />
      <geometry>
        <mesh filename="../assemblies/right_leg_XM430/meshes/right_hip_yaw_link_visual.stl" />
      </geometry>
      <material name="hip_yaw_link_material">
        <color rgba="0.61568627450980395466 0.81176470588235294379 0.92941176470588238168 1.0" />
      </material>
    </visual>
    <inertial>
      <origin xyz="2.6052892110043261802e-19 4.5779561945300561906e-19 -0.0098390489054829104176" rpy="0 0 0" />
      <mass value="0.017999999999999988232" />
      <inertia ixx="2.6385033891442523914e-06" ixy="0" ixz="0" iyy="7.6596731957046873405e-06" iyz="0" izz="7.7220708070894735956e-06" />
    </inertial>
  </link>

  <link name="hip_roll_link_2">
    <visual>
      <origin xyz="0 0 0" rpy="0 -0 0" />
      <geometry>
        <mesh filename="../assemblies/right_leg_XM430/meshes/right_hip_roll_link_visual.stl" />
      </geometry>
      <material name="hip_roll_link_material">
        <color rgba="0.51698661238356047321 0.50347815951093488618 0.49050589017722012741 1.0" />
      </material>
    </visual>
    <inertial>
      <origin xyz="-0.011999849582182775878 -0.00049598090794319277513 -0.018504111838597465944" rpy="0 0 0" />
      <mass value="0.11059999999836234164" />
      <inertia ixx="2.2818802599018211805e-05" ixy="-4.6520143286279465858e-08" ixz="-4.6888548259070895301e-08" iyy="3.0871632082338065545e-05" iyz="-5.7477343899720890612e-07" izz="3.0871666424467947309e-05" />
    </inertial>
  </link>

  <link name="right_hip_pitch_link_xm430">
    <visual>
      <origin xyz="0 0 0" rpy="0 -0 0" />
      <geometry>
        <mesh filename="../assemblies/right_leg_XM430/meshes/right_hip_pitch_link_xm430_visual.stl" />
      </geometry>
      <material name="right_hip_pitch_link_xm430_material">
        <color rgba="0.8707222135732954893 0.72641010956094265172 0.24785169615220692396 1.0" />
      </material>
    </visual>
    <inertial>
      <origin xyz="0.00075715881371283015253 -0.050714784778880722671 -0.012656153620121983125" rpy="0 0 0" />
      <mass value="0.11480090135030567022" />
      <inertia ixx="6.607278648938489003e-05" ixy="4.6010682906021260133e-07" ixz="1.8171597853315155815e-07" iyy="2.3633665181581639092e-05" iyz="1.4125296519934706645e-06" izz="6.2221763055418004632e-05" />
    </inertial>
  </link>

  <link name="right_calf_link">
    <visual>
      <origin xyz="0 0 0" rpy="0 -0 0" />
      <geometry>
        <mesh filename="../assemblies/right_leg_XM430/meshes/right_calf_link_visual.stl" />
      </geometry>
      <material name="right_calf_link_material">
        <color rgba="0.616547745550632742 0.71757541342472208612 0.74372657889541438081 1.0" />
      </material>
    </visual>
    <inertial>
      <origin xyz="0.0016330560292394454176 0.050045526484800137434 -0.0099079425237753124961" rpy="0 0 0" />
      <mass value="0.086799999986183554168" />
      <inertia ixx="4.9519076588877077342e-05" ixy="-3.6911123877145733517e-06" ixz="4.1819052274331339443e-07" iyy="1.5531229308366343087e-05" iyz="-4.6072292079354113904e-07" izz="5.314827806205983451e-05" />
    </inertial>
  </link>

  <link name="bearing_683_3">
    <visual>
      <origin xyz="0 0 0" rpy="0 -0 0" />
      <geometry>
        <mesh filename="../assemblies/right_leg_XM430/meshes/right_bearing_683_visual.stl" />
      </geometry>
      <material name="bearing_683_material">
        <color rgba="0.64705882352941179736 0.64705882352941179736 0.64705882352941179736 1.0" />
      </material>
    </visual>
    <inertial>
      <origin xyz="1.0732094295239739393e-19 2.4186774283161266214e-19 -0.0015500000000000016803" rpy="0 0 0" />
      <mass value="0.00048694686130641793437" />
      <inertia ixx="2.1551456503319895657e-09" ixy="2.3175595566406579266e-27" ixz="2.4896541890902438623e-38" iyy="2.1551456503319883249e-09" iyz="5.4460298433450471486e-38" izz="3.5303647444715305817e-09" />
    </inertial>
  </link>

  <joint name="right_knee_front_rev_2" type="revolute">
    <origin xyz="-0.0057402514854763431879 -0.013858192987669382124 -0.026199999999999987188" rpy="4.9452523641215521159e-15 -3.1674356695639584582e-16 3.1359672412492258786" />
    <parent link="right_calf_link" />
    <child link="bearing_683_3" />
    <axis xyz="0 0 1" />
    <limit effort="1" velocity="20" lower="-6.283185307179586232" upper="6.283185307179586232" />
    <joint_properties friction="0.0" />
  </joint>

  <link name="bearing_683_4">
    <visual>
      <origin xyz="0 0 0" rpy="0 -0 0" />
      <geometry>
        <mesh filename="../assemblies/right_leg_XM430/meshes/right_bearing_683_2_visual.stl" />
      </geometry>
      <material name="bearing_683_2_material">
        <color rgba="0.64705882352941179736 0.64705882352941179736 0.64705882352941179736 1.0" />
      </material>
    </visual>
    <inertial>
      <origin xyz="1.0732094295240485691e-19 2.418677428316700067e-19 -0.0015499999999999977771" rpy="0 0 0" />
      <mass value="0.00048694686130641793437" />
      <inertia ixx="2.1551456503319887385e-09" ixy="9.4016331328971133286e-28" ixz="6.4941734545542371767e-38" iyy="2.1551456503319874977e-09" iyz="1.5195108877220808957e-37" izz="3.5303647444715322361e-09" />
    </inertial>
  </link>

  <joint name="right_knee_back_rev_2" type="revolute">
    <origin xyz="0.0057402514854763692087 0.013858192987669243346 -0.026199999999999990657" rpy="-2.5000942521723397481e-14 5.2473395102998583317e-16 3.1360672427763174319" />
    <parent link="right_calf_link" />
    <child link="bearing_683_4" />
    <axis xyz="0 0 1" />
    <limit effort="1" velocity="20" lower="-6.283185307179586232" upper="6.283185307179586232" />
    <joint_properties friction="0.0" />
  </joint>

  <link name="ank_pitch_link_2">
    <visual>
      <origin xyz="0 0 0" rpy="0 -0 0" />
      <geometry>
        <mesh filename="../assemblies/right_leg_XM430/meshes/right_ank_pitch_link_visual.stl" />
      </geometry>
      <material name="ank_pitch_link_material">
        <color rgba="0.63189161126160264814 0.7266866879354088038 0.78356373393969258601 1.0" />
      </material>
    </visual>
    <inertial>
      <origin xyz="0.00059528282565814453955 4.0269684199612070023e-08 -7.7616092347959137447e-08" rpy="0 0 0" />
      <mass value="0.0042238381753791614387" />
      <inertia ixx="3.9782741364678847766e-07" ixy="1.6834347545013802175e-13" ixz="-2.0919187193369323082e-14" iyy="4.3705254067423273522e-07" iyz="-1.6428822295928359723e-12" izz="8.8858574534611122958e-08" />
    </inertial>
  </link>

  <link name="ank_roll_link_2">
    <visual>
      <origin xyz="0 0 0" rpy="0 -0 0" />
      <geometry>
        <mesh filename="../assemblies/right_leg_XM430/meshes/right_ank_roll_link_visual.stl" />
      </geometry>
      <material name="ank_roll_link_material">
        <color rgba="0.61568627450980395466 0.81176470588235294379 0.92941176470588227065 1.0" />
      </material>
    </visual>
    <collision name="ank_roll_link_2_collision">
      <origin xyz="0.0 0.016499999444931746 0.008400000631809235" rpy="0 0 0" />
      <geometry>
        <box size="0.041999999433755875 0.04500000271946192 0.12000000476837158" />
      </geometry>
    </collision>
    <inertial>
      <origin xyz="-3.2206255610852239928e-10 0.030487683096149048589 0.0047792578419041014184" rpy="0 0 0" />
      <mass value="0.027200000000000008893" />
      <inertia ixx="2.2943463470325713448e-05" ixy="-2.016722948171777719e-13" ixz="4.0806229578615081037e-12" iyy="2.5276617323505065215e-05" iyz="-7.4169474455435566413e-07" izz="5.0976619075837788231e-06" />
    </inertial>
  </link>

  <link name="ank_rr_link_3">
    <visual>
      <origin xyz="0 0 0" rpy="0 -0 0" />
      <geometry>
        <mesh filename="../assemblies/right_leg_XM430/meshes/right_ank_rr_link_visual.stl" />
      </geometry>
      <material name="ank_rr_link_material">
        <color rgba="0.61568627450980395466 0.81176470588235294379 0.92941176470588238168 1.0" />
      </material>
    </visual>
    <inertial>
      <origin xyz="-4.5249610960602645664e-05 -0.0063096429836314027462 2.0009406464677816885e-19" rpy="0 0 0" />
      <mass value="0.0014499999999999999001" />
      <inertia ixx="2.9739579267716163268e-08" ixy="-2.4213146797977880987e-10" ixz="-3.5523394884432796266e-14" iyy="2.7430027724071957055e-08" iyz="4.4497301223652303834e-32" izz="4.2921949116163672436e-08" />
    </inertial>
  </link>

  <link name="ank_motor_rod_long_2">
    <visual>
      <origin xyz="0 0 0" rpy="0 -0 0" />
      <geometry>
        <mesh filename="../assemblies/right_leg_XM430/meshes/right_ank_motor_rod_long_visual.stl" />
      </geometry>
      <material name="ank_motor_rod_long_material">
        <color rgba="0.63549975559783222767 0.7077439301702044272 0.75109043491362770251 1.0" />
      </material>
    </visual>
    <inertial>
      <origin xyz="2.4855090373658416808e-10 0.034559019974062320235 0.00093851704878454773103" rpy="0 0 0" />
      <mass value="0.0021712857268636710437" />
      <inertia ixx="8.5350290058000421993e-07" ixy="1.4884244055558907074e-14" ixz="4.5749525025468555809e-11" iyy="1.3237321792739598881e-08" iyz="-4.3668910960859711191e-09" izz="8.5812217519451768749e-07" />
    </inertial>
  </link>

  <joint name="right_ank_long_rev_2" type="revolute">
    <origin xyz="-3.4694469519536141888e-18 -0.0099999999999999533706 -6.9388939039072283776e-18" rpy="-1.570796326794896558 -1.3320366994106251912 -1.5707963267948779063" />
    <parent link="ank_rr_link_3" />
    <child link="ank_motor_rod_long_2" />
    <axis xyz="0 0 1" />
    <limit effort="1" velocity="20" lower="-1.570796326794896558" upper="1.570796326794896558" />
    <joint_properties friction="0.0" />
  </joint>

  <joint name="right_ank_long_rev_1" type="revolute">
    <origin xyz="0.01799999999999999864 0.015999999999999764411 -0.020600000000000132094" rpy="-7.8386807614170502355e-15 7.211088289180617976e-16 0.018223085043007757056" />
    <parent link="ank_roll_link_2" />
    <child link="ank_rr_link_3" />
    <axis xyz="0 0 1" />
    <limit effort="1" velocity="20" lower="-1.570796326794896558" upper="1.570796326794896558" />
    <joint_properties friction="0.0" />
  </joint>

  <link name="ank_rr_link_4">
    <visual>
      <origin xyz="0 0 0" rpy="0 -0 0" />
      <geometry>
        <mesh filename="../assemblies/right_leg_XM430/meshes/right_ank_rr_link_2_visual.stl" />
      </geometry>
      <material name="ank_rr_link_2_material">
        <color rgba="0.61568627450980395466 0.81176470588235294379 0.92941176470588238168 1.0" />
      </material>
    </visual>
    <inertial>
      <origin xyz="-4.5249610960599182994e-05 0.0063096429836314591247 -2.0009406464667284455e-19" rpy="0 0 0" />
      <mass value="0.0014499999999999999001" />
      <inertia ixx="2.9739579267716163268e-08" ixy="2.4213146797977886157e-10" ixz="3.5523394884432796266e-14" iyy="2.7430027724071963673e-08" iyz="7.1669291072376189503e-32" izz="4.2921949116163672436e-08" />
    </inertial>
  </link>

  <link name="ank_motor_rod_short_2">
    <visual>
      <origin xyz="0 0 0" rpy="0 -0 0" />
      <geometry>
        <mesh filename="../assemblies/right_leg_XM430/meshes/right_ank_motor_rod_short_visual.stl" />
      </geometry>
      <material name="ank_motor_rod_short_material">
        <color rgba="0.41222606689734719865 0.58339100346020766885 0.8110726643598615837 1.0" />
      </material>
    </visual>
    <inertial>
      <origin xyz="2.6038943231632549872e-10 0.023830465465870847436 0.00090403506359630625422" rpy="0 0 0" />
      <mass value="0.0017000000000000001221" />
      <inertia ixx="3.3153416252669976544e-07" ixy="8.7419768119858657143e-15" ixz="4.5749941567677183029e-11" iyy="1.0947363610305713008e-08" iyz="-3.5863098646420718289e-09" izz="3.3621340447865204927e-07" />
    </inertial>
  </link>

  <joint name="right_ank_short_rev_2" type="revolute">
    <origin xyz="0 0.010000000000000008882 0" rpy="-1.570796326794896558 1.2119133862909121646 -1.5707963267948537034" />
    <parent link="ank_rr_link_4" />
    <child link="ank_motor_rod_short_2" />
    <axis xyz="0 0 1" />
    <limit effort="1" velocity="20" lower="-1.570796326794896558" upper="1.570796326794896558" />
    <joint_properties friction="0.0" />
  </joint>

  <joint name="right_ank_short_rev_1" type="revolute">
    <origin xyz="-0.018000000000000009048 0.015999999999999764411 -0.020600000000000118217" rpy="2.411086010918130345e-14 -1.3088994399411267302e-14 3.1154741050824821258" />
    <parent link="ank_roll_link_2" />
    <child link="ank_rr_link_4" />
    <axis xyz="0 0 1" />
    <limit effort="1" velocity="20" lower="-1.570796326794896558" upper="1.570796326794896558" />
    <joint_properties friction="0.0" />
  </joint>

  <joint name="right_ank_roll" type="revolute">
    <origin xyz="0.001499999999999998947 8.3266726846886740532e-17 1.3660947373317355868e-17" rpy="6.1391486757704172424e-30 1.5707963267948927832 0" />
    <parent link="ank_pitch_link_2" />
    <child link="ank_roll_link_2" />
    <axis xyz="0 0 1" />
    <limit effort="1" velocity="20" lower="-0.785398163397448279" upper="0.785398163397448279" />
    <joint_properties friction="0.0" />
  </joint>

  <joint name="right_ank_pitch" type="revolute">
    <origin xyz="3.4616201395293281188e-16 0.10000000000000006106 -0.010399999999999975236" rpy="-3.1415926535897922278 1.9667427410937738729e-16 -3.1415926535897926719" />
    <parent link="right_calf_link" />
    <child link="ank_pitch_link_2" />
    <axis xyz="0 0 1" />
    <limit effort="1" velocity="20" lower="-1.0471975511965976313" upper="0.785398163397448279" />
    <joint_properties friction="0.0" />
  </joint>

  <link name="ank_motor_arm_3">
    <visual>
      <origin xyz="0 0 0" rpy="0 -0 0" />
      <geometry>
        <mesh filename="../assemblies/right_leg_XM430/meshes/right_ank_motor_arm_visual.stl" />
      </geometry>
      <material name="ank_motor_arm_material">
        <color rgba="0.62483822591633164656 0.70971956673896574586 0.76585356440212004614 1.0" />
      </material>
    </visual>
    <inertial>
      <origin xyz="0.014032842952293483885 -1.1875681526054779929e-09 0.0040383546575275923451" rpy="0 0 0" />
      <mass value="0.0021359401157891211472" />
      <inertia ixx="2.920977652832815804e-08" ixy="-4.6752001422563860023e-14" ixz="-3.1659407525131065532e-08" iyy="1.7718014185775859225e-07" iyz="-2.5844346951013690337e-15" izz="1.8139327643022011445e-07" />
    </inertial>
  </link>

  <joint name="right_ank_act_1" type="revolute">
    <origin xyz="0.013499999999996006514 0.04450000000000683964 0.0040000000000046075088" rpy="-3.1559662337880072911e-13 -4.3224762083389784551e-14 0.21173394130152450865" />
    <parent link="right_calf_link" />
    <child link="ank_motor_arm_3" />
    <axis xyz="0 0 1" />
    <limit effort="1" velocity="20" lower="-1.3089969389957472057" upper="1.3089969389957472057" />
    <joint_properties friction="0.0" />
  </joint>

  <link name="ank_motor_arm_4">
    <visual>
      <origin xyz="0 0 0" rpy="0 -0 0" />
      <geometry>
        <mesh filename="../assemblies/right_leg_XM430/meshes/right_ank_motor_arm_2_visual.stl" />
      </geometry>
      <material name="ank_motor_arm_2_material">
        <color rgba="0.62483822591633164656 0.70971956673896574586 0.76585356440212004614 1.0" />
      </material>
    </visual>
    <inertial>
      <origin xyz="0.014032842952293506436 -1.187568081600947684e-09 0.0040383546575275958146" rpy="0 0 0" />
      <mass value="0.0021359401157891211472" />
      <inertia ixx="2.9209776528328204362e-08" ixy="-4.6752001607133292608e-14" ixz="-3.1659407525131217734e-08" iyy="1.7718014185775922752e-07" iyz="-2.5844347378765580252e-15" izz="1.8139327643022061737e-07" />
    </inertial>
  </link>

  <joint name="right_ank_act_2" type="revolute">
    <origin xyz="0.013500000000003113676 0.064500000000006912915 -0.024800000000002909994" rpy="-3.1415926535895573046 -1.7198897169567297797e-13 0.22995607267273157626" />
    <parent link="right_calf_link" />
    <child link="ank_motor_arm_4" />
    <axis xyz="0 0 1" />
    <limit effort="1" velocity="20" lower="-1.3089969389957472057" upper="1.3089969389957472057" />
    <joint_properties friction="0.0" />
  </joint>

  <joint name="right_knee_pitch" type="revolute">
    <origin xyz="-2.9733995392255427503e-17 -0.096000000000000001998 -0.0091999999999999963751" rpy="-2.1337098754749728925e-16 3.9898639968108458448e-17 3.1415926535897846783" />
    <parent link="right_hip_pitch_link_xm430" />
    <child link="right_calf_link" />
    <axis xyz="0 0 1" />
    <limit effort="1" velocity="20" lower="-1.9198621771937625091" upper="0" />
    <joint_properties friction="0.0" />
  </joint>

  <link name="xm430_plate_2">
    <visual>
      <origin xyz="0 0 0" rpy="0 -0 0" />
      <geometry>
        <mesh filename="../assemblies/right_leg_XM430/meshes/right_xm430_plate_visual.stl" />
      </geometry>
      <material name="xm430_plate_material">
        <color rgba="0.61568627450980395466 0.81176470588235294379 0.9294117647058824927 1.0" />
      </material>
    </visual>
    <inertial>
      <origin xyz="8.2761015112156068591e-19 3.9608123405210419363e-18 -0.0024039046431217972466" rpy="0 0 0" />
      <mass value="0.0026999999999999992756" />
      <inertia ixx="2.6720434385876688324e-07" ixy="-6.8936588702566374239e-08" ixz="2.5793754136946577579e-36" iyy="1.2933116645363405536e-07" iyz="-5.5772549530744028788e-36" izz="3.8533537562751439267e-07" />
    </inertial>
  </link>

  <link name="knee_rod_3">
    <visual>
      <origin xyz="0 0 0" rpy="0 -0 0" />
      <geometry>
        <mesh filename="../assemblies/right_leg_XM430/meshes/right_knee_rod_visual.stl" />
      </geometry>
      <material name="knee_rod_material">
        <color rgba="0.62051618944235198416 0.78640765248647581664 0.88594253031295022716 1.0" />
      </material>
    </visual>
    <inertial>
      <origin xyz="0.014594553522267959475 3.7292099839724583211e-05 -0.0015996227373186720257" rpy="0 0 0" />
      <mass value="0.0031629468613064179276" />
      <inertia ixx="2.5895923315130376932e-08" ixy="-3.1325283435871752107e-10" ixz="4.1682992324833837119e-10" iyy="6.015326150335526925e-07" iyz="1.0650865822052022654e-12" izz="6.2266847407077561114e-07" />
    </inertial>
  </link>

  <joint name="right_knee_front_rev_1" type="revolute">
    <origin xyz="-0.005740251485476348392 -0.013858192987669298857 -0.0050000000000000027062" rpy="1.2660330546546102165e-14 -5.760640040579399853e-15 1.5651709144543408669" />
    <parent link="xm430_plate_2" />
    <child link="knee_rod_3" />
    <axis xyz="0 0 1" />
    <limit effort="1" velocity="20" lower="-6.283185307179586232" upper="6.283185307179586232" />
    <joint_properties friction="0.0" />
  </joint>

  <link name="knee_rod_4">
    <visual>
      <origin xyz="0 0 0" rpy="0 -0 0" />
      <geometry>
        <mesh filename="../assemblies/right_leg_XM430/meshes/right_knee_rod_2_visual.stl" />
      </geometry>
      <material name="knee_rod_2_material">
        <color rgba="0.62051618944235198416 0.78640765248647581664 0.88594253031295022716 1.0" />
      </material>
    </visual>
    <inertial>
      <origin xyz="0.014594557105585477183 3.4373169586153155656e-05 -0.0015996227373184820734" rpy="0 0 0" />
      <mass value="0.0031629468613064179276" />
      <inertia ixx="2.5895802916981975736e-08" ixy="-2.8873395407690157505e-10" ixz="4.1683002558550294754e-10" iyy="6.0153267523314955379e-07" iyz="9.8172003926880134242e-13" izz="6.2266841387223807044e-07" />
    </inertial>
  </link>

  <joint name="right_knee_back_rev_1" type="revolute">
    <origin xyz="0.0057402514854763509941 0.013858192987669298857 -0.0050000000000000061756" rpy="1.7600934488845652939e-14 7.4447456537463636708e-16 1.5652709159814237605" />
    <parent link="xm430_plate_2" />
    <child link="knee_rod_4" />
    <axis xyz="0 0 1" />
    <limit effort="1" velocity="20" lower="-6.283185307179586232" upper="6.283185307179586232" />
    <joint_properties friction="0.0" />
  </joint>

  <joint name="right_knee_act" type="revolute">
    <origin xyz="0.0001500000000000903009 -0.061499999999999978295 -0.030400000000000013817" rpy="-2.110221371875480467e-15 -1.2104358314278240034e-14 3.1415926535897811256" />
    <parent link="right_hip_pitch_link_xm430" />
    <child link="xm430_plate_2" />
    <axis xyz="0 0 1" />
    <limit effort="1" velocity="20" lower="-1.9198621771937625091" upper="0" />
    <joint_properties friction="0.0" />
  </joint>

  <joint name="right_hip_pitch" type="revolute">
    <origin xyz="-0.024000000716142756707 -0.019000000152441819112 -0.019000000152452952568" rpy="1.5707963267951126074 1.5707963267947429031 0" />
    <parent link="hip_roll_link_2" />
    <child link="right_hip_pitch_link_xm430" />
    <axis xyz="0 0 1" />
    <limit effort="1" velocity="20" lower="-1.570796326794896558" upper="1.570796326794896558" />
    <joint_properties friction="0.0" />
  </joint>

  <joint name="right_hip_roll" type="revolute">
    <origin xyz="-0.018999999999999999528 3.350043889036771243e-18 -0.026000000000000002276" rpy="-6.1629758220389864097e-33 -1.5707963267948785724 0" />
    <parent link="hip_yaw_link_2" />
    <child link="hip_roll_link_2" />
    <axis xyz="0 0 1" />
    <limit effort="1" velocity="20" lower="-0.785398163397448279" upper="0.785398163397448279" />
    <joint_properties friction="0.0" />
  </joint>


  <link name="sho_pitch_link">
    <visual>
      <origin xyz="0 0 0" rpy="0 -0 0" />
      <geometry>
        <mesh filename="../assemblies/left_arm_gripper/meshes/left_sho_pitch_link_visual.stl" />
      </geometry>
      <material name="sho_pitch_link_material">
        <color rgba="0.61568627450980395466 0.81176470588235294379 0.92941176470588227065 1.0" />
      </material>
    </visual>
    <inertial>
      <origin xyz="5.825424713136965347e-11 -5.1264642561120613376e-05 0.0082440788127094623977" rpy="0 0 0" />
      <mass value="0.0085999999999999948014" />
      <inertia ixx="1.2272887040545698699e-06" ixy="-2.1429936857790001706e-14" ixz="-8.5847197986376549961e-15" iyy="2.9107306060364399859e-06" iyz="7.4623841398182289916e-09" izz="3.0803135950773254758e-06" />
    </inertial>
  </link>

  <link name="2xl430_gears">
    <visual>
      <origin xyz="0 0 0" rpy="0 -0 0" />
      <geometry>
        <mesh filename="../assemblies/left_arm_gripper/meshes/left_2xl430_gears_visual.stl" />
      </geometry>
      <material name="2xl430_gears_material">
        <color rgba="0.75605985687944110563 0.85804695962693022793 0.91320266199377464478 1.0" />
      </material>
    </visual>
    <inertial>
      <origin xyz="-0.011579403981038464272 -0.002422576614141830776 -0.018551095523803202286" rpy="0 0 0" />
      <mass value="0.11800003674524908726" />
      <inertia ixx="2.7482298083237826736e-05" ixy="9.2729623432995268073e-07" ixz="-2.2634512003660714742e-08" iyy="3.2770742486673136743e-05" iyz="-6.570834602012557258e-07" izz="3.5767957544056393486e-05" />
    </inertial>
  </link>

  <link name="spur_1m_24t_drive">
    <visual>
      <origin xyz="0 0 0" rpy="0 -0 0" />
      <geometry>
        <mesh filename="../assemblies/left_arm_gripper/meshes/left_spur_1m_24t_drive_visual.stl" />
      </geometry>
      <material name="spur_1m_24t_drive_material">
        <color rgba="0.61568627450980406568 0.81176470588235294379 0.92941176470588238168 1.0" />
      </material>
    </visual>
    <inertial>
      <origin xyz="-7.7448063662474734586e-15 -1.2123861050677117534e-16 0.0047949116178401460231" rpy="0 0 0" />
      <mass value="0.0032000000000000001533" />
      <inertia ixx="1.4019331346159890349e-07" ixy="1.6002409975938109088e-15" ixz="2.8305938916428361434e-36" iyy="1.4019331260388791479e-07" iyz="-2.7756084137331137677e-37" izz="2.3838919844264060647e-07" />
    </inertial>
  </link>

  <joint name="left_sho_yaw_drive" type="revolute">
    <origin xyz="-0.024000000716142340373 -0.019000000152452619501 -0.019000000152446860219" rpy="1.5707963267949109909 9.9706267968386760623e-14 1.1369019472068143296e-13" />
    <parent link="2xl430_gears" />
    <child link="spur_1m_24t_drive" />
    <axis xyz="0 0 1" />
    <limit effort="1" velocity="20" lower="-1.570796326794896558" upper="1.570796326794896558" />
    <joint_properties friction="0.0" />
  </joint>

  <link name="spur_1m_24t_driven">
    <visual>
      <origin xyz="0 0 0" rpy="0 -0 0" />
      <geometry>
        <mesh filename="../assemblies/left_arm_gripper/meshes/left_spur_1m_24t_driven_visual.stl" />
      </geometry>
      <material name="spur_1m_24t_driven_material">
        <color rgba="0.23137254901960788156 0.38039215686274502337 0.7058823529411765163 1.0" />
      </material>
    </visual>
    <inertial>
      <origin xyz="2.4762432785984072638e-18 -5.8048491945228596449e-15 -0.00097054817521927832808" rpy="0 0 0" />
      <mass value="0.0026999999999999997093" />
      <inertia ixx="1.2036234079571063062e-07" ixy="5.3408894128739695801e-38" ixz="5.1968416708483298415e-37" iyy="1.203623407957104718e-07" iyz="2.9528026526682685694e-38" izz="2.2847261745924530022e-07" />
    </inertial>
  </link>

  <link name="sho_yaw_link">
    <visual>
      <origin xyz="0 0 0" rpy="0 -0 0" />
      <geometry>
        <mesh filename="../assemblies/left_arm_gripper/meshes/left_sho_yaw_link_visual.stl" />
      </geometry>
      <material name="sho_yaw_link_material">
        <color rgba="0.61568627450980395466 0.81176470588235294379 0.92941176470588238168 1.0" />
      </material>
    </visual>
    <inertial>
      <origin xyz="-1.2817564279972674955e-18 1.5206593873888553284e-18 -0.024303257848520158635" rpy="0 0 0" />
      <mass value="0.014500000000000009409" />
      <inertia ixx="9.0846670053041348901e-06" ixy="3.6224092806459835683e-13" ixz="-1.3956049305714063063e-36" iyy="5.6910950712097508087e-06" iyz="7.9431974261832515669e-37" izz="4.4819609845548975929e-06" />
    </inertial>
  </link>

  <link name="2xl430_gears_2">
    <visual>
      <origin xyz="0 0 0" rpy="0 -0 0" />
      <geometry>
        <mesh filename="../assemblies/left_arm_gripper/meshes/left_2xl430_gears_2_visual.stl" />
      </geometry>
      <material name="2xl430_gears_2_material">
        <color rgba="0.75605985687944110563 0.85804695962693022793 0.91320266199377464478 1.0" />
      </material>
    </visual>
    <inertial>
      <origin xyz="-0.011579403981032826421 -0.0024225766141465132283 -0.018551095523802692278" rpy="0 0 0" />
      <mass value="0.11800003674524908726" />
      <inertia ixx="2.748229808324030346e-05" ixy="9.2729623433146018762e-07" ixz="-2.263451200429400091e-08" iyy="3.277074248667314352e-05" iyz="-6.5708346020031763681e-07" izz="3.5767957544059822276e-05" />
    </inertial>
  </link>

  <link name="spur_1m_24t_drive_2">
    <visual>
      <origin xyz="0 0 0" rpy="0 -0 0" />
      <geometry>
        <mesh filename="../assemblies/left_arm_gripper/meshes/left_spur_1m_24t_drive_2_visual.stl" />
      </geometry>
      <material name="spur_1m_24t_drive_2_material">
        <color rgba="0.61568627450980406568 0.81176470588235294379 0.92941176470588238168 1.0" />
      </material>
    </visual>
    <inertial>
      <origin xyz="-7.751745260151380687e-15 -1.2123861048092158399e-16 0.0047949116178401520946" rpy="0 0 0" />
      <mass value="0.0032000000000000001533" />
      <inertia ixx="1.4019331346159885055e-07" ixy="1.6002409988709471321e-15" ixz="-3.502605987210856533e-36" iyy="1.4019331260388786185e-07" iyz="9.4026470327642496469e-37" izz="2.3838919844264060647e-07" />
    </inertial>
  </link>

  <joint name="left_elbow_yaw_drive" type="revolute">
    <origin xyz="-0.024000000716136535989 -0.019000000152454787905 -0.019000000152441284818" rpy="1.5707963267946079 -2.8216931162767297778e-14 6.7112934369983557895e-14" />
    <parent link="2xl430_gears_2" />
    <child link="spur_1m_24t_drive_2" />
    <axis xyz="0 0 1" />
    <limit effort="1" velocity="20" lower="-1.570796326794896558" upper="1.570796326794896558" />
    <joint_properties friction="0.0" />
  </joint>

  <link name="spur_1m_24t_driven_2">
    <visual>
      <origin xyz="0 0 0" rpy="0 -0 0" />
      <geometry>
        <mesh filename="../assemblies/left_arm_gripper/meshes/left_spur_1m_24t_driven_2_visual.stl" />
      </geometry>
      <material name="spur_1m_24t_driven_2_material">
        <color rgba="0.23137254901960788156 0.38039215686274502337 0.7058823529411765163 1.0" />
      </material>
    </visual>
    <inertial>
      <origin xyz="2.4762432785983259896e-18 -5.8048491945228580672e-15 -0.00097054817521927117235" rpy="0 0 0" />
      <mass value="0.0026999999999999997093" />
      <inertia ixx="1.2036234079571063062e-07" ixy="-5.9343215704243974963e-39" ixz="-5.7094682119075744182e-37" iyy="1.203623407957104718e-07" iyz="2.8781323114403286985e-36" izz="2.2847261745924530022e-07" />
    </inertial>
  </link>

  <link name="elb_yaw_link">
    <visual>
      <origin xyz="0 0 0" rpy="0 -0 0" />
      <geometry>
        <mesh filename="../assemblies/left_arm_gripper/meshes/left_elb_yaw_link_visual.stl" />
      </geometry>
      <material name="elb_yaw_link_material">
        <color rgba="0.61568627450980395466 0.81176470588235294379 0.92941176470588238168 1.0" />
      </material>
    </visual>
    <inertial>
      <origin xyz="5.3127688027570469941e-08 0.0019833638641961657233 -0.023416643551549931601" rpy="0 0 0" />
      <mass value="0.017500000000000012074" />
      <inertia ixx="1.4134344903109203164e-05" ixy="1.6945783921965302898e-12" ixz="-1.12863987218649646e-11" iyy="6.6435900776211348874e-06" iyz="1.0545227077253063932e-06" izz="8.9925290757999027595e-06" />
    </inertial>
  </link>

  <link name="spur_1m_24t_driven_3">
    <visual>
      <origin xyz="0 0 0" rpy="0 -0 0" />
      <geometry>
        <mesh filename="../assemblies/left_arm_gripper/meshes/left_spur_1m_24t_driven_3_visual.stl" />
      </geometry>
      <material name="spur_1m_24t_driven_3_material">
        <color rgba="0.23137254901960788156 0.38039215686274502337 0.7058823529411765163 1.0" />
      </material>
    </visual>
    <inertial>
      <origin xyz="2.4762432785984296046e-18 -5.8048491945228509674e-15 -0.0025705481752192754774" rpy="0 0 0" />
      <mass value="0.0026999999999999997093" />
      <inertia ixx="1.2036234079571063062e-07" ixy="2.9658603783104118495e-36" ixz="1.4418649266169135506e-36" iyy="1.203623407957104718e-07" iyz="0" izz="2.2847261745924530022e-07" />
    </inertial>
  </link>

  <link name="2xl430_gears_3">
    <visual>
      <origin xyz="0 0 0" rpy="0 -0 0" />
      <geometry>
        <mesh filename="../assemblies/left_arm_gripper/meshes/left_2xl430_gears_3_visual.stl" />
      </geometry>
      <material name="2xl430_gears_3_material">
        <color rgba="0.75605985687944110563 0.85804695962693022793 0.91320266199377464478 1.0" />
      </material>
    </visual>
    <inertial>
      <origin xyz="0.00044890447620223944891 0.011579403622960069212 -0.024577423538311701789" rpy="0 0 0" />
      <mass value="0.11800003674524908726" />
      <inertia ixx="3.576795754405341193e-05" ixy="2.2634512003722922033e-08" ixz="6.5708346020262643687e-07" iyy="2.748229808323645793e-05" iyz="9.2729623432839615181e-07" izz="3.2770742486672282934e-05" />
    </inertial>
  </link>

  <link name="spur_1m_24t_drive_3">
    <visual>
      <origin xyz="0 0 0" rpy="0 -0 0" />
      <geometry>
        <mesh filename="../assemblies/left_arm_gripper/meshes/left_spur_1m_24t_drive_3_visual.stl" />
      </geometry>
      <material name="spur_1m_24t_drive_3_material">
        <color rgba="0.61568627450980406568 0.81176470588235294379 0.92941176470588238168 1.0" />
      </material>
    </visual>
    <inertial>
      <origin xyz="-7.751745260151380687e-15 -1.2123861050677117534e-16 0.004794911617840143421" rpy="0 0 0" />
      <mass value="0.0032000000000000001533" />
      <inertia ixx="1.4019331346159890349e-07" ixy="1.6002410034001928083e-15" ixz="-8.7717508276537431555e-37" iyy="1.4019331260388783538e-07" iyz="1.1548227992196316113e-37" izz="2.3838919844264060647e-07" />
    </inertial>
  </link>

  <joint name="left_wrist_pitch_drive" type="revolute">
    <origin xyz="-1.5244182510102145428e-10 0.024000000358063572348 -0.0080000000000052026022" rpy="3.8158623046065463386e-14 2.7687786355305660007e-15 -1.5707963267948872321" />
    <parent link="2xl430_gears_3" />
    <child link="spur_1m_24t_drive_3" />
    <axis xyz="0 0 1" />
    <limit effort="1" velocity="20" lower="-1.570796326794896558" upper="1.570796326794896558" />
    <joint_properties friction="0.0" />
  </joint>

  <link name="gripper_connector">
    <visual>
      <origin xyz="0 0 0" rpy="0 -0 0" />
      <geometry>
        <mesh filename="../assemblies/left_arm_gripper/meshes/left_gripper_connector_visual.stl" />
      </geometry>
      <material name="gripper_connector_material">
        <color rgba="0.61568627450980395466 0.81176470588235294379 0.92941176470588238168 1.0" />
      </material>
    </visual>
    <inertial>
      <origin xyz="-0.00020299682521053750918 0.023971521766976106732 0.0085969861498480255185" rpy="0 0 0" />
      <mass value="0.0099999999999999967387" />
      <inertia ixx="5.3001475666257306027e-06" ixy="2.3401437868255138619e-08" ixz="4.811583299767818531e-08" iyy="3.8245954467071441652e-06" iyz="1.9316561248438263276e-08" izz="2.2623415168893606272e-06" />
    </inertial>
  </link>

  <link name="left_rail_guide">
    <visual>
      <origin xyz="0 0 0" rpy="0 -0 0" />
      <geometry>
        <mesh filename="../assemblies/left_arm_gripper/meshes/left_rail_guide_visual.stl" />
      </geometry>
      <material name="left_rail_guide_material">
        <color rgba="0.61996873695689813655 0.81385103374119360797 0.93007060508235828156 1.0" />
      </material>
    </visual>
    <inertial>
      <origin xyz="0.0092700665834928308584 0.0022613527845001648101 6.7965382068776956643e-05" rpy="0 0 0" />
      <mass value="0.032142035224833366558" />
      <inertia ixx="7.5992490868921725935e-06" ixy="2.166186217073429695e-06" ixz="4.0652418928980958842e-06" iyy="2.7370569943527405134e-05" iyz="-9.4757783140872249955e-07" izz="3.0022397080929709613e-05" />
    </inertial>
  </link>

  <link name="rail">
    <visual>
      <origin xyz="0 0 0" rpy="0 -0 0" />
      <geometry>
        <mesh filename="../assemblies/left_arm_gripper/meshes/left_rail_visual.stl" />
      </geometry>
      <material name="rail_material">
        <color rgba="0.64705882352941179736 0.64705882352941179736 0.64705882352941179736 1.0" />
      </material>
    </visual>
    <inertial>
      <origin xyz="0.022744777800883849567 -0.01423343940335741048 -0.0079907133176532266217" rpy="0 0 0" />
      <mass value="0.01189999999999999912" />
      <inertia ixx="2.9161025366903515529e-06" ixy="4.4570835808164656273e-09" ixz="-7.5225164550604629609e-07" iyy="3.6201306422454496648e-06" iyz="2.6765050785959795044e-08" izz="4.4681807873990699658e-06" />
    </inertial>
  </link>

  <joint name="left_gripper_pinion_1" type="prismatic">
    <origin xyz="-0.028872599999999967041 -0.014174999999999993161 -0.0053500000000000214051" rpy="3.141592653589793116 1.5707963267948954478 0" />
    <parent link="left_rail_guide" />
    <child link="rail" />
    <axis xyz="0 0 1" />
    <limit effort="1" velocity="20" lower="-0.036872599999999998432" upper="0" />
    <joint_properties friction="0.0" />
  </joint>

  <link name="rail_2">
    <visual>
      <origin xyz="0 0 0" rpy="0 -0 0" />
      <geometry>
        <mesh filename="../assemblies/left_arm_gripper/meshes/left_rail_2_visual.stl" />
      </geometry>
      <material name="rail_2_material">
        <color rgba="0.64705882352941179736 0.64705882352941179736 0.64705882352941179736 1.0" />
      </material>
    </visual>
    <inertial>
      <origin xyz="0.022744777800883849567 -0.01423343940335741048 -0.0079907133176532543772" rpy="0 0 0" />
      <mass value="0.01189999999999999912" />
      <inertia ixx="2.9161025366903515529e-06" ixy="4.4570835808164656273e-09" ixz="-7.5225164550604629609e-07" iyy="3.6201306422454496648e-06" iyz="2.6765050785959795044e-08" izz="4.4681807873990699658e-06" />
    </inertial>
  </link>

  <joint name="left_gripper_pinion_2" type="prismatic">
    <origin xyz="0.062872600000000083975 0.014174999999999993161 -0.0053499999999999936495" rpy="-1.1102230241485031157e-16 1.5707963267948956698 0" />
    <parent link="left_rail_guide" />
    <child link="rail_2" />
    <axis xyz="0 0 1" />
    <limit effort="1" velocity="20" lower="-0.036872599999999998432" upper="0" />
    <joint_properties friction="0.0" />
  </joint>

  <link name="xc330">
    <visual>
      <origin xyz="0 0 0" rpy="0 -0 0" />
      <geometry>
        <mesh filename="../assemblies/left_arm_gripper/meshes/left_xc330_visual.stl" />
      </geometry>
      <material name="xc330_material">
        <color rgba="0.66932535752643762539 0.72911795671409951325 0.67547870389434383487 1.0" />
      </material>
    </visual>
    <inertial>
      <origin xyz="0.0080045171539641236241 -0.015558009851636250484 -0.011717805512819029837" rpy="0 0 0" />
      <mass value="0.026599999993091760775" />
      <inertia ixx="3.8683410666515347562e-06" ixy="-7.7688424002015278384e-10" ixz="5.7969695836396948678e-10" iyy="2.1626767907496152011e-06" iyz="8.3590274789491991479e-09" izz="3.3158761130056310206e-06" />
    </inertial>
  </link>

  <link name="spur_gear_(14_teeth)">
    <visual>
      <origin xyz="0 0 0" rpy="0 -0 0" />
      <geometry>
        <mesh filename="../assemblies/left_arm_gripper/meshes/left_spur_gear_(14_teeth)_visual.stl" />
      </geometry>
      <material name="spur_gear_(14_teeth)_material">
        <color rgba="0.91764705882352926025 0.91764705882352926025 0.91764705882352926025 1.0" />
      </material>
    </visual>
    <inertial>
      <origin xyz="5.0520117100133488108e-09 -3.0586955572509122447e-09 -0.006903728708833461146" rpy="0 0 0" />
      <mass value="0.0013000000000000001572" />
      <inertia ixx="2.6445547365951358714e-08" ixy="2.5401821979637465349e-10" ixz="1.9678356781400301005e-14" iyy="2.6850679146645044261e-08" iyz="-1.1914086608124239553e-14" izz="3.4027434623053054292e-08" />
    </inertial>
  </link>

  <joint name="left_gripper_rack" type="revolute">
    <origin xyz="0.0079999999999998683275 -0.022500000000001255107 -0.020000000000000905942" rpy="6.855915668332168754e-16 -2.3037346225485797513e-16 -3.7700408238277826924e-17" />
    <parent link="xc330" />
    <child link="spur_gear_(14_teeth)" />
    <axis xyz="0 0 1" />
    <limit effort="1" velocity="20" lower="0" upper="5.2359877559829888227" />
    <joint_properties friction="0.0" />
  </joint>

  <joint name="left_gripper_motor" type="fixed">
    <origin xyz="-0.021950000000000007699 0.022600000000000002032 0.023299999999999987388" rpy="7.2164496600760899834e-16 -8.5692192681739838362e-31 9.3430423746336819555e-31" />
    <parent link="left_rail_guide" />
    <child link="xc330" />
    <axis xyz="0 0 1" />
    <limit effort="1" velocity="20" />
    <joint_properties friction="0.0" />
  </joint>

  <joint name="left_gripper_fixed" type="fixed">
    <origin xyz="3.4694469519536141888e-18 0.037000000000000005107 0.036000000000000004219" rpy="1.5707963267948954478 1.570796326794896558 0" />
    <parent link="gripper_connector" />
    <child link="left_rail_guide" />
    <axis xyz="0 0 1" />
    <limit effort="1" velocity="20" />
    <joint_properties friction="0.0" />
  </joint>

  <joint name="left_wrist_roll" type="revolute">
    <origin xyz="0.019000000000008565593 -3.5807690146327786351e-10 -0.027000000152451481689" rpy="3.1415926535897225058 1.5707963267948779063 0" />
    <parent link="2xl430_gears_3" />
    <child link="gripper_connector" />
    <axis xyz="0 0 1" />
    <limit effort="1" velocity="20" lower="-1.570796326794896558" upper="1.570796326794896558" />
    <joint_properties friction="0.0" />
  </joint>

  <link name="wrist_bearing_plate">
    <visual>
      <origin xyz="0 0 0" rpy="0 -0 0" />
      <geometry>
        <mesh filename="../assemblies/left_arm_gripper/meshes/left_wrist_bearing_plate_visual.stl" />
      </geometry>
      <material name="wrist_bearing_plate_material">
        <color rgba="0.64496316278892629192 0.69011804996940528945 0.71706771073555886087 1.0" />
      </material>
    </visual>
    <inertial>
      <origin xyz="-0.0075835583121499792678 -0.015499999999999982542 -0.0018386323705903483226" rpy="0 0 0" />
      <mass value="0.0049000367468305548388" />
      <inertia ixx="4.9707430109150065605e-07" ixy="-2.8714724666942291057e-22" ixz="1.8100904820814273476e-08" iyy="7.1268523603538563647e-07" iyz="7.8617990471106424172e-24" izz="1.1919657811600102881e-06" />
    </inertial>
  </link>

  <joint name="left_wrist_pitch_fixed" type="fixed">
    <origin xyz="0.01550000000000705154 -7.0499162063697440317e-15 -0.045000000000003488598" rpy="2.3314683517158803644e-14 -2.7339241981393896051e-14 -1.5707963267949085484" />
    <parent link="2xl430_gears_3" />
    <child link="wrist_bearing_plate" />
    <axis xyz="0 0 1" />
    <limit effort="1" velocity="20" />
    <joint_properties friction="0.0" />
  </joint>

  <joint name="left_wrist_pitch_driven" type="revolute">
    <origin xyz="-2.7755575615628913511e-17 0 -0.0015999999999999972577" rpy="2.4980018055243628788e-16 -1.6081226490223879062e-16 -1.570796326794896558" />
    <parent link="spur_1m_24t_driven_3" />
    <child link="2xl430_gears_3" />
    <axis xyz="0 0 1" />
    <limit effort="1" velocity="20" lower="-1.570796326794896558" upper="1.570796326794896558" />
    <joint_properties friction="0.0" />
  </joint>

  <joint name="left_wrist_roll_fixed" type="fixed">
    <origin xyz="-6.3108872417680944433e-30 -0.025299999999999996103 -0.051999999999999976796" rpy="1.570796326794896558 -1.5707963267948958919 0" />
    <parent link="elb_yaw_link" />
    <child link="spur_1m_24t_driven_3" />
    <axis xyz="0 0 1" />
    <limit effort="1" velocity="20" />
    <joint_properties friction="0.0" />
  </joint>

  <joint name="left_elbow_yaw_fixed" type="fixed">
    <origin xyz="0 6.3108872417680944433e-30 0.0015999999999999903189" rpy="3.1415926535897926719 3.0894028578356351099e-29 -1.570796326794896558" />
    <parent link="spur_1m_24t_driven_2" />
    <child link="elb_yaw_link" />
    <axis xyz="0 0 1" />
    <limit effort="1" velocity="20" />
    <joint_properties friction="0.0" />
  </joint>

  <joint name="left_elbow_yaw_driven" type="revolute">
    <origin xyz="-3.5806391879278365309e-10 -0.027000000152454087243 -0.01899999999999553088" rpy="1.5707963267946445374 -1.957357187373244284e-14 -5.6726675369617376296e-14" />
    <parent link="2xl430_gears_2" />
    <child link="spur_1m_24t_driven_2" />
    <axis xyz="0 0 1" />
    <limit effort="1" velocity="20" lower="-1.570796326794896558" upper="1.570796326794896558" />
    <joint_properties friction="0.0" />
  </joint>

  <joint name="left_elbow_roll" type="revolute">
    <origin xyz="0 -0.019000000000000002998 -0.058999999999999989952" rpy="1.570796326794896558 -5.9921797729386389252e-15 -1.6081226496441365173e-16" />
    <parent link="sho_yaw_link" />
    <child link="2xl430_gears_2" />
    <axis xyz="0 0 1" />
    <limit effort="1" velocity="20" lower="-1.570796326794896558" upper="1.570796326794896558" />
    <joint_properties friction="0.0" />
  </joint>

  <joint name="left_sho_yaw_fixed" type="fixed">
    <origin xyz="0 0 0.0016000000000000007272" rpy="-3.141592653589793116 4.050196108650232498e-16 6.2450045046961790355e-17" />
    <parent link="spur_1m_24t_driven" />
    <child link="sho_yaw_link" />
    <axis xyz="0 0 1" />
    <limit effort="1" velocity="20" />
    <joint_properties friction="0.0" />
  </joint>

  <joint name="left_sho_yaw_driven" type="revolute">
    <origin xyz="-3.5806818968198150799e-10 -0.027000000152451984758 -0.01900000000000318795" rpy="1.5707963267948918951 5.5868781814391237904e-14 7.1004483613505400622e-14" />
    <parent link="2xl430_gears" />
    <child link="spur_1m_24t_driven" />
    <axis xyz="0 0 1" />
    <limit effort="1" velocity="20" lower="-1.570796326794896558" upper="1.570796326794896558" />
    <joint_properties friction="0.0" />
  </joint>

  <joint name="left_sho_roll" type="revolute">
    <origin xyz="-0.018999999999999937078 0.00099999999999997031368 0.02699999999999990602" rpy="3.1415926535897913396 1.5707963267948676922 0" />
    <parent link="sho_pitch_link" />
    <child link="2xl430_gears" />
    <axis xyz="0 0 1" />
    <limit effort="1" velocity="20" lower="-1.570796326794896558" upper="0" />
    <joint_properties friction="0.0" />
  </joint>


  <link name="sho_pitch_link_2">
    <visual>
      <origin xyz="0 0 0" rpy="0 -0 0" />
      <geometry>
        <mesh filename="../assemblies/right_arm_gripper/meshes/right_sho_pitch_link_visual.stl" />
      </geometry>
      <material name="sho_pitch_link_material">
        <color rgba="0.61568627450980395466 0.81176470588235294379 0.92941176470588227065 1.0" />
      </material>
    </visual>
    <inertial>
      <origin xyz="5.8254247222434160976e-11 -5.1264642561120796335e-05 0.008244078812709491888" rpy="0 0 0" />
      <mass value="0.0085999999999999948014" />
      <inertia ixx="1.2272887040545787638e-06" ixy="-2.1429944208389056621e-14" ixz="-8.5847198118935726732e-15" iyy="2.9107306060364603147e-06" iyz="7.4623841398182819312e-09" izz="3.0803135950773474987e-06" />
    </inertial>
  </link>

  <link name="2xl430_gears_4">
    <visual>
      <origin xyz="0 0 0" rpy="0 -0 0" />
      <geometry>
        <mesh filename="../assemblies/right_arm_gripper/meshes/right_2xl430_gears_visual.stl" />
      </geometry>
      <material name="2xl430_gears_material">
        <color rgba="0.75605985687944110563 0.85804695962693022793 0.91320266199377464478 1.0" />
      </material>
    </visual>
    <inertial>
      <origin xyz="-0.011579403981033858581 -0.0024225766141437814725 -0.018551095523802619419" rpy="0 0 0" />
      <mass value="0.11800003674524908726" />
      <inertia ixx="2.7482298083236915328e-05" ixy="9.2729623433052167511e-07" ixz="-2.263451200438713483e-08" iyy="3.2770742486672533656e-05" iyz="-6.5708346020062267455e-07" izz="3.576795754405571586e-05" />
    </inertial>
  </link>

  <link name="spur_1m_24t_drive_4">
    <visual>
      <origin xyz="0 0 0" rpy="0 -0 0" />
      <geometry>
        <mesh filename="../assemblies/right_arm_gripper/meshes/right_spur_1m_24t_drive_visual.stl" />
      </geometry>
      <material name="spur_1m_24t_drive_material">
        <color rgba="0.61568627450980406568 0.81176470588235294379 0.92941176470588238168 1.0" />
      </material>
    </visual>
    <inertial>
      <origin xyz="-7.751745260151380687e-15 -1.2123861048092197842e-16 0.0047949116178401460231" rpy="0 0 0" />
      <mass value="0.0032000000000000001533" />
      <inertia ixx="1.4019331346159885055e-07" ixy="1.6002410021796695823e-15" ixz="1.3924985888997309856e-36" iyy="1.4019331260388786185e-07" iyz="-4.5951838781519388734e-36" izz="2.3838919844264060647e-07" />
    </inertial>
  </link>

  <joint name="right_sho_yaw_drive" type="revolute">
    <origin xyz="-0.024000000716137483148 -0.019000000152449965374 -0.019000000152444667528" rpy="1.570796326794722475 -4.3999245160326114002e-14 5.9488666369146786408e-14" />
    <parent link="2xl430_gears_4" />
    <child link="spur_1m_24t_drive_4" />
    <axis xyz="0 0 1" />
    <limit effort="1" velocity="20" lower="-1.570796326794896558" upper="1.570796326794896558" />
    <joint_properties friction="0.0" />
  </joint>

  <link name="spur_1m_24t_driven_4">
    <visual>
      <origin xyz="0 0 0" rpy="0 -0 0" />
      <geometry>
        <mesh filename="../assemblies/right_arm_gripper/meshes/right_spur_1m_24t_driven_visual.stl" />
      </geometry>
      <material name="spur_1m_24t_driven_material">
        <color rgba="0.23137254901960788156 0.38039215686274502337 0.7058823529411765163 1.0" />
      </material>
    </visual>
    <inertial>
      <origin xyz="2.4762432785981830856e-18 -5.8048491945228596449e-15 -0.00097054817521927832808" rpy="0 0 0" />
      <mass value="0.0026999999999999997093" />
      <inertia ixx="1.2036234079571063062e-07" ixy="1.587431019793314561e-37" ixz="-1.5461159006407193093e-36" iyy="1.203623407957104718e-07" iyz="-1.0082599683077304872e-36" izz="2.2847261745924530022e-07" />
    </inertial>
  </link>

  <link name="sho_yaw_link_2">
    <visual>
      <origin xyz="0 0 0" rpy="0 -0 0" />
      <geometry>
        <mesh filename="../assemblies/right_arm_gripper/meshes/right_sho_yaw_link_visual.stl" />
      </geometry>
      <material name="sho_yaw_link_material">
        <color rgba="0.61568627450980395466 0.81176470588235294379 0.92941176470588238168 1.0" />
      </material>
    </visual>
    <inertial>
      <origin xyz="-1.2817564279969886208e-18 1.5206593873907567991e-18 -0.024303257848520158635" rpy="0 0 0" />
      <mass value="0.014500000000000009409" />
      <inertia ixx="9.0846670053041348901e-06" ixy="3.6224092806459835683e-13" ixz="5.6772952765067195751e-35" iyy="5.6910950712097508087e-06" iyz="-3.5185142106800999806e-35" izz="4.4819609845548975929e-06" />
    </inertial>
  </link>

  <link name="2xl430_gears_5">
    <visual>
      <origin xyz="0 0 0" rpy="0 -0 0" />
      <geometry>
        <mesh filename="../assemblies/right_arm_gripper/meshes/right_2xl430_gears_2_visual.stl" />
      </geometry>
      <material name="2xl430_gears_2_material">
        <color rgba="0.75605985687944110563 0.85804695962693022793 0.91320266199377464478 1.0" />
      </material>
    </visual>
    <inertial>
      <origin xyz="-0.011579403981039852051 -0.0024225766141425793092 -0.018551095523806137438" rpy="0 0 0" />
      <mass value="0.11800003674524908726" />
      <inertia ixx="2.7482298083239744418e-05" ixy="9.2729623432915117581e-07" ixz="-2.2634512003323466589e-08" iyy="3.2770742486673658516e-05" iyz="-6.5708346020140956816e-07" izz="3.5767957544057823278e-05" />
    </inertial>
  </link>

  <link name="spur_1m_24t_drive_5">
    <visual>
      <origin xyz="0 0 0" rpy="0 -0 0" />
      <geometry>
        <mesh filename="../assemblies/right_arm_gripper/meshes/right_spur_1m_24t_drive_2_visual.stl" />
      </geometry>
      <material name="spur_1m_24t_drive_2_material">
        <color rgba="0.61568627450980406568 0.81176470588235294379 0.92941176470588238168 1.0" />
      </material>
    </visual>
    <inertial>
      <origin xyz="-7.751745260151380687e-15 -1.2123861048092138677e-16 0.0047949116178401520946" rpy="0 0 0" />
      <mass value="0.0032000000000000001533" />
      <inertia ixx="1.4019331346159885055e-07" ixy="1.6002409968393611024e-15" ixz="-3.9348876968074062678e-37" iyy="1.4019331260388783538e-07" iyz="-2.6377672644807350883e-36" izz="2.3838919844264060647e-07" />
    </inertial>
  </link>

  <joint name="right_elbow_yaw_drive" type="revolute">
    <origin xyz="-0.024000000716145945129 -0.019000000152452470314 -0.019000000152448241059" rpy="1.5707963267948983344 1.6899208920332882627e-13 -6.1373298874875490715e-14" />
    <parent link="2xl430_gears_5" />
    <child link="spur_1m_24t_drive_5" />
    <axis xyz="0 0 1" />
    <limit effort="1" velocity="20" lower="-1.570796326794896558" upper="1.570796326794896558" />
    <joint_properties friction="0.0" />
  </joint>

  <link name="spur_1m_24t_driven_5">
    <visual>
      <origin xyz="0 0 0" rpy="0 -0 0" />
      <geometry>
        <mesh filename="../assemblies/right_arm_gripper/meshes/right_spur_1m_24t_driven_2_visual.stl" />
      </geometry>
      <material name="spur_1m_24t_driven_2_material">
        <color rgba="0.23137254901960788156 0.38039215686274502337 0.7058823529411765163 1.0" />
      </material>
    </visual>
    <inertial>
      <origin xyz="5.9456902305522602679e-18 -5.8048491945228580672e-15 -0.00097054817521927117235" rpy="0 0 0" />
      <mass value="0.0026999999999999997093" />
      <inertia ixx="1.2036234079571063062e-07" ixy="-8.9014824086108095032e-38" ixz="3.2067963391906028065e-36" iyy="1.203623407957104718e-07" iyz="2.7069667191504325644e-36" izz="2.2847261745924530022e-07" />
    </inertial>
  </link>

  <link name="elb_yaw_link_2">
    <visual>
      <origin xyz="0 0 0" rpy="0 -0 0" />
      <geometry>
        <mesh filename="../assemblies/right_arm_gripper/meshes/right_elb_yaw_link_visual.stl" />
      </geometry>
      <material name="elb_yaw_link_material">
        <color rgba="0.61568627450980395466 0.81176470588235294379 0.92941176470588238168 1.0" />
      </material>
    </visual>
    <inertial>
      <origin xyz="5.3127688027570469941e-08 0.0019833638641961657233 -0.023416643551549945479" rpy="0 0 0" />
      <mass value="0.017500000000000012074" />
      <inertia ixx="1.4134344903109203164e-05" ixy="1.6945783921965302898e-12" ixz="-1.12863987218649646e-11" iyy="6.6435900776211348874e-06" iyz="1.0545227077253063932e-06" izz="8.9925290757999027595e-06" />
    </inertial>
  </link>

  <link name="spur_1m_24t_driven_6">
    <visual>
      <origin xyz="0 0 0" rpy="0 -0 0" />
      <geometry>
        <mesh filename="../assemblies/right_arm_gripper/meshes/right_spur_1m_24t_driven_3_visual.stl" />
      </geometry>
      <material name="spur_1m_24t_driven_3_material">
        <color rgba="0.23137254901960788156 0.38039215686274502337 0.7058823529411765163 1.0" />
      </material>
    </visual>
    <inertial>
      <origin xyz="2.476243278598654168e-18 -5.8048491945228628003e-15 -0.0025705481752192754774" rpy="0 0 0" />
      <mass value="0.0026999999999999997093" />
      <inertia ixx="1.2036234079571063062e-07" ixy="-2.9839012757031514303e-36" ixz="3.2821659039070559178e-36" iyy="1.203623407957104718e-07" iyz="4.6846362701733088034e-37" izz="2.2847261745924530022e-07" />
    </inertial>
  </link>

  <link name="2xl430_gears_6">
    <visual>
      <origin xyz="0 0 0" rpy="0 -0 0" />
      <geometry>
        <mesh filename="../assemblies/right_arm_gripper/meshes/right_2xl430_gears_3_visual.stl" />
      </geometry>
      <material name="2xl430_gears_3_material">
        <color rgba="0.75605985687944110563 0.85804695962693022793 0.91320266199377464478 1.0" />
      </material>
    </visual>
    <inertial>
      <origin xyz="0.00044890447619679480244 0.011579403622971209606 -0.024577423538311955059" rpy="0 0 0" />
      <mass value="0.11800003674524908726" />
      <inertia ixx="3.5767957544055776846e-05" ixy="2.2634512004663462785e-08" ixz="6.5708346020171238244e-07" iyy="2.7482298083237115228e-05" iyz="9.2729623432988004766e-07" izz="3.2770742486673848251e-05" />
    </inertial>
  </link>

  <link name="spur_1m_24t_drive_6">
    <visual>
      <origin xyz="0 0 0" rpy="0 -0 0" />
      <geometry>
        <mesh filename="../assemblies/right_arm_gripper/meshes/right_spur_1m_24t_drive_3_visual.stl" />
      </geometry>
      <material name="spur_1m_24t_drive_3_material">
        <color rgba="0.61568627450980406568 0.81176470588235294379 0.92941176470588238168 1.0" />
      </material>
    </visual>
    <inertial>
      <origin xyz="-7.751745260151380687e-15 -1.2123861048092158399e-16 0.0047949116178401416863" rpy="0 0 0" />
      <mass value="0.0032000000000000001533" />
      <inertia ixx="1.4019331346159885055e-07" ixy="1.6002409988709471321e-15" ixz="3.0142658632333987562e-37" iyy="1.4019331260388786185e-07" iyz="2.9847825549003112408e-37" izz="2.3838919844264060647e-07" />
    </inertial>
  </link>

  <joint name="right_wrist_pitch_drive" type="revolute">
    <origin xyz="-1.5244730108012700873e-10 0.024000000358075063156 -0.0080000000000021147945" rpy="-2.3760361364596328788e-14 9.1171344708605480535e-14 -1.5707963267948272801" />
    <parent link="2xl430_gears_6" />
    <child link="spur_1m_24t_drive_6" />
    <axis xyz="0 0 1" />
    <limit effort="1" velocity="20" lower="-1.3962634015954635824" upper="1.9198621771937625091" />
    <joint_properties friction="0.0" />
  </joint>

  <link name="gripper_connector_2">
    <visual>
      <origin xyz="0 0 0" rpy="0 -0 0" />
      <geometry>
        <mesh filename="../assemblies/right_arm_gripper/meshes/right_gripper_connector_visual.stl" />
      </geometry>
      <material name="gripper_connector_material">
        <color rgba="0.61568627450980395466 0.81176470588235294379 0.92941176470588238168 1.0" />
      </material>
    </visual>
    <inertial>
      <origin xyz="-0.00020299682521053742787 0.023971521766976099793 -0.029403013850151985681" rpy="0 0 0" />
      <mass value="0.0099999999999999967387" />
      <inertia ixx="5.3001475666257289086e-06" ixy="2.3401437868255125384e-08" ixz="4.8115832997678172075e-08" iyy="3.8245954467071424711e-06" iyz="1.9316561248438259967e-08" izz="2.2623415168893606272e-06" />
    </inertial>
  </link>

  <link name="right_rail_guide">
    <visual>
      <origin xyz="0 0 0" rpy="0 -0 0" />
      <geometry>
        <mesh filename="../assemblies/right_arm_gripper/meshes/right_rail_guide_visual.stl" />
      </geometry>
      <material name="right_rail_guide_material">
        <color rgba="0.62025753727489985057 0.81399173133201496722 0.93011503590051247681 1.0" />
      </material>
    </visual>
    <inertial>
      <origin xyz="0.0092741550667162012123 -0.0022368973911260619375 1.1465282798790105357e-05" rpy="0 0 0" />
      <mass value="0.030111386261699939898" />
      <inertia ixx="7.0587141071297657626e-06" ixy="-2.0076614642548881315e-06" ixz="3.7679719233345454809e-06" iyy="2.5402123601769120974e-05" iyz="8.8191782705952307384e-07" izz="2.7857260235898915346e-05" />
    </inertial>
  </link>

  <link name="rail_3">
    <visual>
      <origin xyz="0 0 0" rpy="0 -0 0" />
      <geometry>
        <mesh filename="../assemblies/right_arm_gripper/meshes/right_rail_visual.stl" />
      </geometry>
      <material name="rail_material">
        <color rgba="0.64705882352941179736 0.64705882352941179736 0.64705882352941179736 1.0" />
      </material>
    </visual>
    <inertial>
      <origin xyz="0.022744777800883849567 -0.014233439403357403541 -0.0079907133176532543772" rpy="0 0 0" />
      <mass value="0.01189999999999999912" />
      <inertia ixx="2.9161025366903515529e-06" ixy="4.4570835808164656273e-09" ixz="-7.5225164550604629609e-07" iyy="3.6201306422454496648e-06" iyz="2.6765050785959795044e-08" izz="4.4681807873990699658e-06" />
    </inertial>
  </link>

  <joint name="right_gripper_pinion_1" type="prismatic">
    <origin xyz="-0.028872599999999963571 -0.014174999999999993161 -0.0053499999999999381384" rpy="3.141592653589793116 1.5707963267948958919 0" />
    <parent link="right_rail_guide" />
    <child link="rail_3" />
    <axis xyz="0 0 1" />
    <limit effort="1" velocity="20" lower="-0.036872599999999998432" upper="0" />
    <joint_properties friction="0.0" />
  </joint>

  <link name="rail_4">
    <visual>
      <origin xyz="0 0 0" rpy="0 -0 0" />
      <geometry>
        <mesh filename="../assemblies/right_arm_gripper/meshes/right_rail_2_visual.stl" />
      </geometry>
      <material name="rail_2_material">
        <color rgba="0.64705882352941179736 0.64705882352941179736 0.64705882352941179736 1.0" />
      </material>
    </visual>
    <inertial>
      <origin xyz="0.022744777800883849567 -0.01423343940335741048 -0.0079907133176532266217" rpy="0 0 0" />
      <mass value="0.01189999999999999912" />
      <inertia ixx="2.9161025366903515529e-06" ixy="4.4570835808164656273e-09" ixz="-7.5225164550604629609e-07" iyy="3.6201306422454496648e-06" iyz="2.6765050785959795044e-08" izz="4.4681807873990699658e-06" />
    </inertial>
  </link>

  <joint name="right_gripper_pinion_2" type="prismatic">
    <origin xyz="0.062872600000000000708 0.0141750000000000001 -0.0053499999999999381384" rpy="-1.1235956670197897365e-25 1.5707963267948958919 0" />
    <parent link="right_rail_guide" />
    <child link="rail_4" />
    <axis xyz="0 0 1" />
    <limit effort="1" velocity="20" lower="-0.036872599999999998432" upper="0" />
    <joint_properties friction="0.0" />
  </joint>

  <link name="xc330_2">
    <visual>
      <origin xyz="0 0 0" rpy="0 -0 0" />
      <geometry>
        <mesh filename="../assemblies/right_arm_gripper/meshes/right_xc330_visual.stl" />
      </geometry>
      <material name="xc330_material">
        <color rgba="0.66932535752643762539 0.72911795671409951325 0.67547870389434383487 1.0" />
      </material>
    </visual>
    <inertial>
      <origin xyz="0.0080045171539637003516 -0.015558009851631669079 -0.011717805512818117372" rpy="0 0 0" />
      <mass value="0.026599999993091760775" />
      <inertia ixx="3.8683410666514000779e-06" ixy="-7.7688424002216035119e-10" ixz="5.7969695832974809426e-10" iyy="2.162676790749446218e-06" iyz="8.3590274792902258621e-09" izz="3.3158761130056246679e-06" />
    </inertial>
  </link>

  <link name="spur_gear_(14_teeth)_2">
    <visual>
      <origin xyz="0 0 0" rpy="0 -0 0" />
      <geometry>
        <mesh filename="../assemblies/right_arm_gripper/meshes/right_spur_gear_(14_teeth)_visual.stl" />
      </geometry>
      <material name="spur_gear_(14_teeth)_material">
        <color rgba="0.91764705882352926025 0.91764705882352926025 0.91764705882352926025 1.0" />
      </material>
    </visual>
    <inertial>
      <origin xyz="5.0520117117480722868e-09 -3.0586955537814652928e-09 -0.006903728708833461146" rpy="0 0 0" />
      <mass value="0.0013000000000000001572" />
      <inertia ixx="2.644554736595136864e-08" ixy="2.5401821979637413651e-10" ixz="1.9678356781400304161e-14" iyy="2.6850679146645050879e-08" iyz="-1.1914086608124237975e-14" izz="3.4027434623053041057e-08" />
    </inertial>
  </link>

  <joint name="right_gripper_rack" type="revolute">
    <origin xyz="0.0079999999999993375022 -0.022499999999995499295 -0.019999999999999656941" rpy="3.9513898910780635647e-26 -6.1232339957375240819e-17 -4.4058789844277850015e-17" />
    <parent link="xc330_2" />
    <child link="spur_gear_(14_teeth)_2" />
    <axis xyz="0 0 1" />
    <limit effort="1" velocity="20" lower="0" upper="5.2359877559829888227" />
    <joint_properties friction="0.0" />
  </joint>

  <joint name="right_gripper_motor" type="fixed">
    <origin xyz="-0.0059500000000000038969 -0.022599999999999981215 0.023300000000000042899" rpy="-1.4352268952473380085e-25 1.0940480200944162675e-30 3.141592653589793116" />
    <parent link="right_rail_guide" />
    <child link="xc330_2" />
    <axis xyz="0 0 1" />
    <limit effort="1" velocity="20" />
    <joint_properties friction="0.0" />
  </joint>

  <joint name="right_gripper_fixed" type="fixed">
    <origin xyz="3.4694469519536141888e-18 0.037000000000000005107 -0.001999999999999991368" rpy="1.5707963267949094366 1.5707963267948832353 0" />
    <parent link="gripper_connector_2" />
    <child link="right_rail_guide" />
    <axis xyz="0 0 1" />
    <limit effort="1" velocity="20" />
    <joint_properties friction="0.0" />
  </joint>

  <joint name="right_wrist_roll" type="revolute">
    <origin xyz="0.019000000000003156725 -3.5806391185388974918e-10 -0.027000000152454312757" rpy="-3.141592653589708739 -1.5707963267948066299 0" />
    <parent link="2xl430_gears_6" />
    <child link="gripper_connector_2" />
    <axis xyz="0 0 1" />
    <limit effort="1" velocity="20" lower="-1.3962634015954635824" upper="1.9198621771937625091" />
    <joint_properties friction="0.0" />
  </joint>

  <link name="wrist_bearing_plate_2">
    <visual>
      <origin xyz="0 0 0" rpy="0 -0 0" />
      <geometry>
        <mesh filename="../assemblies/right_arm_gripper/meshes/right_wrist_bearing_plate_visual.stl" />
      </geometry>
      <material name="wrist_bearing_plate_material">
        <color rgba="0.64496316278892629192 0.69011804996940528945 0.71706771073555886087 1.0" />
      </material>
    </visual>
    <inertial>
      <origin xyz="-0.0075835583121499801351 -0.015499999999999980807 -0.001838632370590335529" rpy="0 0 0" />
      <mass value="0.0049000367468305548388" />
      <inertia ixx="4.970743010915013972e-07" ixy="3.135435358762893339e-23" ixz="1.8100904820814058409e-08" iyy="7.1268523603538574235e-07" iyz="8.8804451676286627573e-24" izz="1.1919657811600111352e-06" />
    </inertial>
  </link>

  <joint name="right_wrist_pitch_fixed" type="fixed">
    <origin xyz="0.01550000000000218911 9.9364960703951510368e-15 -0.045000000000006000478" rpy="-1.2645101217445535558e-15 1.2057022047428705255e-13 -1.5707963267947835373" />
    <parent link="2xl430_gears_6" />
    <child link="wrist_bearing_plate_2" />
    <axis xyz="0 0 1" />
    <limit effort="1" velocity="20" />
    <joint_properties friction="0.0" />
  </joint>

  <joint name="right_wrist_pitch_driven" type="revolute">
    <origin xyz="2.7755575615628913511e-17 -6.3108872417680944433e-30 -0.0015999999999999966072" rpy="-1.5154544286135535634e-14 1.7943243846840832321e-15 1.570796326794896558" />
    <parent link="spur_1m_24t_driven_6" />
    <child link="2xl430_gears_6" />
    <axis xyz="0 0 1" />
    <limit effort="1" velocity="20" lower="-1.9198621771937625091" upper="1.3962634015954635824" />
    <joint_properties friction="0.0" />
  </joint>

  <joint name="right_wrist_roll_fixed" type="fixed">
    <origin xyz="0 -0.025299999999999999573 -0.051999999999999990674" rpy="1.570796326794896558 1.570796326794896558 0" />
    <parent link="elb_yaw_link_2" />
    <child link="spur_1m_24t_driven_6" />
    <axis xyz="0 0 1" />
    <limit effort="1" velocity="20" />
    <joint_properties friction="0.0" />
  </joint>

  <joint name="right_elbow_yaw_fixed" type="fixed">
    <origin xyz="0 3.1554436208840472216e-30 0.0016000000000000180744" rpy="-3.1415926535897873428 3.3907091715322312159e-31 -1.570796326794896558" />
    <parent link="spur_1m_24t_driven_5" />
    <child link="elb_yaw_link_2" />
    <axis xyz="0 0 1" />
    <limit effort="1" velocity="20" />
    <joint_properties friction="0.0" />
  </joint>

  <joint name="right_elbow_yaw_driven" type="revolute">
    <origin xyz="-3.5806995563048005238e-10 -0.0270000001524559885 -0.01900000000000036729" rpy="1.5707963267948485964 8.4311697099246135987e-14 3.6920636757530582299e-14" />
    <parent link="2xl430_gears_5" />
    <child link="spur_1m_24t_driven_5" />
    <axis xyz="0 0 1" />
    <limit effort="1" velocity="20" lower="-2.6179938779914944114" upper="2.6179938779914944114" />
    <joint_properties friction="0.0" />
  </joint>

  <joint name="right_elbow_roll" type="revolute">
    <origin xyz="-5.2041704279304212832e-17 -0.018999999999999964834 -0.059000000000000114853" rpy="1.5707963267948974462 5.0352015639126703846e-15 2.5592341453658362349e-15" />
    <parent link="sho_yaw_link_2" />
    <child link="2xl430_gears_5" />
    <axis xyz="0 0 1" />
    <limit effort="1" velocity="20" lower="-1.570796326794896558" upper="1.570796326794896558" />
    <joint_properties friction="0.0" />
  </joint>

  <joint name="right_sho_yaw_fixed" type="fixed">
    <origin xyz="5.2041704279304212832e-17 3.787910703300854279e-17 0.0015999999999998966438" rpy="3.141592653589793116 1.6554645777787879748e-29 8.3603448337486833053e-32" />
    <parent link="spur_1m_24t_driven_4" />
    <child link="sho_yaw_link_2" />
    <axis xyz="0 0 1" />
    <limit effort="1" velocity="20" />
    <joint_properties friction="0.0" />
  </joint>

  <joint name="right_sho_yaw_driven" type="revolute">
    <origin xyz="-3.5806750273148502117e-10 -0.027000000152448928176 -0.018999999999998070516" rpy="1.5707963267947655517 -4.3564811365927410262e-14 2.9648675946254039113e-14" />
    <parent link="2xl430_gears_4" />
    <child link="spur_1m_24t_driven_4" />
    <axis xyz="0 0 1" />
    <limit effort="1" velocity="20" lower="-1.570796326794896558" upper="1.570796326794896558" />
    <joint_properties friction="0.0" />
  </joint>

  <joint name="right_sho_roll" type="revolute">
    <origin xyz="-0.01899999999999992667 0.0010000000000000069597 0.026999999999999999695" rpy="3.1415926535897922278 1.5707963267948588104 0" />
    <parent link="sho_pitch_link_2" />
    <child link="2xl430_gears_4" />
    <axis xyz="0 0 1" />
    <limit effort="1" velocity="20" lower="-1.570796326794896558" upper="0" />
    <joint_properties friction="0.0" />
  </joint>


</robot>