<robot name="toddlerbot">
  <mujoco>
    <compiler strippath="false" balanceinertia="true" discardvisual="false" />
  </mujoco>
  <link name="torso">
    <visual>
      <origin xyz="0 0 0" rpy="0 -0 0" />
      <geometry>
        <mesh filename="../assemblies/toddlerbot/meshes/torso_visual.stl" />
      </geometry>
      <material name="torso_material">
        <color rgba="0.5756764758149645056 0.73345309646743483967 0.85630877307465791404 1.0" />
      </material>
    </visual>
    <inertial>
      <origin xyz="-0.0091211546187125406432 0.0036055430201103995727 0.074702081176469287138" rpy="0 0 0" />
      <mass value="0.60012685450989189384" />
      <inertia ixx="0.0016762683716637551828" ixy="-3.7956721963544869667e-05" ixz="-8.3172104272568887339e-05" iyy="0.0013163016250066178307" iyz="5.6371331396665507135e-05" izz="0.0012676048753457814025" />
    </inertial>
  <collision name="torso_collision"><origin xyz="-0.023500001057982445 -2.4996697902679443e-05 0.060213070595636964" rpy="0 0 0" /><geometry><box size="0.13100000098347664 0.10207999944686891 0.1245468775741756" /></geometry></collision></link>

  <link name="spur_1m_20t">
    <visual>
      <origin xyz="0 0 0" rpy="0 -0 0" />
      <geometry>
        <mesh filename="../assemblies/toddlerbot/meshes/spur_1m_20t_visual.stl" />
      </geometry>
      <material name="spur_1m_20t_material">
        <color rgba="0.64705882352941179736 0.64705882352941179736 0.64705882352941179736 1.0" />
      </material>
    </visual>
    <inertial>
      <origin xyz="-2.264600315585787176e-18 -7.587391431216789923e-18 0.0033745971730663147647" rpy="0 0 0" />
      <mass value="0.0015534950290892286448" />
      <inertia ixx="4.4726508287871812856e-08" ixy="2.6608965793107671434e-24" ixz="-4.0749910772758008994e-38" iyy="4.4726508287871779768e-08" iyz="-7.464720539392493928e-38" izz="7.9558906764902019844e-08" />
    </inertial>
  </link>

  <joint name="neck_yaw_drive" type="revolute">
    <origin xyz="-0.004999999999999517851 2.6555840535020396321e-18 0.121486510762817565" rpy="1.1318451824181020002e-14 2.6985403517595457696e-15 -5.3863140912757267331e-15" />
    <parent link="torso" />
    <child link="spur_1m_20t" />
    <axis xyz="0 0 1" />
    <limit effort="1" velocity="20" lower="-2.8797932657906435416" upper="2.8797932657906435416" />
    <joint_properties friction="0.0" />
  </joint>

  <link name="neck_yaw_link">
    <visual>
      <origin xyz="0 0 0" rpy="0 -0 0" />
      <geometry>
        <mesh filename="../assemblies/toddlerbot/meshes/neck_yaw_link_visual.stl" />
      </geometry>
      <material name="neck_yaw_link_material">
        <color rgba="0.33636252417476658616 0.48680769190259876034 0.74976123534949778993 1.0" />
      </material>
    </visual>
    <inertial>
      <origin xyz="2.7291286461005574991e-05 -0.00019798992283532067032 0.011527412037194510394" rpy="0 0 0" />
      <mass value="0.0085168305947458267796" />
      <inertia ixx="1.0407116999274246609e-06" ixy="2.4210150466101252425e-11" ixz="-4.7246803217895962011e-10" iyy="1.124000995411045041e-06" iyz="3.0834841754639543074e-08" izz="3.1587565167291430716e-07" />
    </inertial>
  </link>

  <link name="neck_pitch_link">
    <visual>
      <origin xyz="0 0 0" rpy="0 -0 0" />
      <geometry>
        <mesh filename="../assemblies/toddlerbot/meshes/neck_pitch_link_visual.stl" />
      </geometry>
      <material name="neck_pitch_link_material">
        <color rgba="0.74911126277760042846 0.80002799398726853752 0.87441258869524285391 1.0" />
      </material>
    </visual>
    <inertial>
      <origin xyz="-0.0034370497615720967989 0.032876793988991216688 -0.00036476492134677904145" rpy="0 0 0" />
      <mass value="0.11211553874797881847" />
      <inertia ixx="7.7015755459845837709e-05" ixy="-2.1757968319815265661e-06" ixz="-2.8732209413513131827e-06" iyy="6.3502636688153170732e-05" iyz="-1.2492352737634845265e-05" izz="2.8610002383974730313e-05" />
    </inertial>
  </link>

  <link name="spur_gear_(13_teeth)">
    <visual>
      <origin xyz="0 0 0" rpy="0 -0 0" />
      <geometry>
        <mesh filename="../assemblies/toddlerbot/meshes/spur_gear_(13_teeth)_visual.stl" />
      </geometry>
      <material name="spur_gear_(13_teeth)_material">
        <color rgba="0.64705882352941179736 0.64705882352941179736 0.64705882352941179736 1.0" />
      </material>
    </visual>
    <inertial>
      <origin xyz="9.1521555160253732313e-10 -5.4872578733911464024e-10 0.0092751511485596373902" rpy="0 0 0" />
      <mass value="0.00081469437497230865874" />
      <inertia ixx="2.0244841463618380872e-08" ixy="2.9781775007011560058e-15" ixz="-8.2976066071190312301e-15" iyy="2.0244839778533682582e-08" iyz="1.3142117785017221878e-15" izz="1.8905472907863310999e-08" />
    </inertial>
  </link>

  <joint name="neck_pitch_drive" type="revolute">
    <origin xyz="-6.9735883734267645195e-16 0.015649999999999053557 -0.0087999999999970532349" rpy="-1.1409718301987536487e-15 4.409645192886135633e-16 -1.5707963267948976682" />
    <parent link="neck_pitch_link" />
    <child link="spur_gear_(13_teeth)" />
    <axis xyz="0 0 1" />
    <limit effort="1" velocity="20" lower="-2.174948760177549012" upper="2.174948760177549012" />
    <joint_properties friction="0.0" />
  </joint>

  <joint name="neck_pitch_driven" type="revolute">
    <origin xyz="3.7499979510524639181e-10 -0.0051500000614751947903 0.027499999999999941158" rpy="1.5707963267948978903 -2.0825786444073518345e-16 3.141592653589793116" />
    <parent link="neck_yaw_link" />
    <child link="neck_pitch_link" />
    <axis xyz="0 0 1" />
    <limit effort="1" velocity="20" lower="-1.570796326794896558" upper="1.570796326794896558" />
    <joint_properties friction="0.0" />
  </joint>

  <joint name="neck_yaw_driven" type="revolute">
    <origin xyz="0.016000000000001235456 2.2310681558151314601e-17 0.12248651076281746874" rpy="-4.8668742840765556337e-16 -4.0649010562893427138e-15 3.141592653589793116" />
    <parent link="torso" />
    <child link="neck_yaw_link" />
    <axis xyz="0 0 1" />
    <limit effort="1" velocity="20" lower="-2.6179938779914944114" upper="2.6179938779914944114" />
    <joint_properties friction="0.0" />
  </joint>

  <link name="waist_gears">
    <visual>
      <origin xyz="0 0 0" rpy="0 -0 0" />
      <geometry>
        <mesh filename="../assemblies/toddlerbot/meshes/waist_gears_visual.stl" />
      </geometry>
      <material name="waist_gears_material">
        <color rgba="0.26285745258304310523 0.51761993404322359513 0.70089950218325269837 1.0" />
      </material>
    </visual>
    <inertial>
      <origin xyz="-2.9615196346148577302e-07 5.6324425198301108519e-08 -0.012591728437027502677" rpy="0 0 0" />
      <mass value="0.025874065810895640477" />
      <inertia ixx="1.5221462961926445333e-06" ixy="1.8766602079766916675e-11" ixz="4.0586927770605968901e-10" iyy="7.280142068668490794e-06" iyz="3.1229108550824058464e-12" izz="6.9639458993359299767e-06" />
    </inertial>
  </link>

  <link name="waist_link">
    <visual>
      <origin xyz="0 0 0" rpy="0 -0 0" />
      <geometry>
        <mesh filename="../assemblies/toddlerbot/meshes/waist_link_visual.stl" />
      </geometry>
      <material name="waist_link_material">
        <color rgba="0.63401200025306059249 0.68204699127249923674 0.6691019398503622595 1.0" />
      </material>
    </visual>
    <inertial>
      <origin xyz="-9.1086191337257426703e-07 0.026204483755308753679 -0.030190392008842579369" rpy="0 0 0" />
      <mass value="0.16631953490612461088" />
      <inertia ixx="6.8622997376114634803e-05" ixy="-6.1328048461882665927e-10" ixz="-3.6786792027265062734e-06" iyy="0.00020057117429216644823" iyz="-3.7255079147358398249e-06" izz="0.00015770127977213132457" />
    </inertial>
  </link>

  <link name="spiral_bevel_1m_14t_30deg">
    <visual>
      <origin xyz="0 0 0" rpy="0 -0 0" />
      <geometry>
        <mesh filename="../assemblies/toddlerbot/meshes/spiral_bevel_1m_14t_30deg_visual.stl" />
      </geometry>
      <material name="spiral_bevel_1m_14t_30deg_material">
        <color rgba="0.64705882352941179736 0.64705882352941179736 0.64705882352941179736 1.0" />
      </material>
    </visual>
    <inertial>
      <origin xyz="7.4971447279470481499e-10 7.1802237332913011122e-10 0.0066868955018979103766" rpy="0 0 0" />
      <mass value="0.00073261524436595492574" />
      <inertia ixx="1.3495056019478195011e-08" ixy="4.0596681656909248509e-17" ixz="8.599255017511676462e-16" iyy="1.3495056150237195634e-08" iyz="-6.7913008233741570648e-16" izz="1.4355986549816408408e-08" />
    </inertial>
  </link>

  <joint name="waist_act_1" type="revolute">
    <origin xyz="5.7457652915638341522e-17 0.019599999999999964673 -0.012750000000000025202" rpy="1.5707963267948954478 1.570796326794896336 0" />
    <parent link="waist_link" />
    <child link="spiral_bevel_1m_14t_30deg" />
    <axis xyz="0 0 1" />
    <limit effort="1" velocity="20" lower="-4.6774823953448034786" upper="4.6774823953448034786" />
    <joint_properties friction="0.0" />
  </joint>

  <link name="spiral_bevel_1m_14t_30deg_2">
    <visual>
      <origin xyz="0 0 0" rpy="0 -0 0" />
      <geometry>
        <mesh filename="../assemblies/toddlerbot/meshes/spiral_bevel_1m_14t_30deg_2_visual.stl" />
      </geometry>
      <material name="spiral_bevel_1m_14t_30deg_2_material">
        <color rgba="0.64705882352941179736 0.64705882352941179736 0.64705882352941179736 1.0" />
      </material>
    </visual>
    <inertial>
      <origin xyz="5.711425533905245544e-10 8.6684721906479195987e-10 0.0066868955018979190502" rpy="0 0 0" />
      <mass value="0.00073261524436595492574" />
      <inertia ixx="1.3495056008338566936e-08" ixy="8.2092443034011452773e-18" ixz="9.8948603423502891461e-16" iyy="1.3495056161376838597e-08" iyz="-4.7075144749766452119e-16" izz="1.43559865498164051e-08" />
    </inertial>
  </link>

  <joint name="waist_act_2" type="revolute">
    <origin xyz="4.2745485696894321379e-17 0.019600000000000013245 -0.032749999999999994393" rpy="1.5707963267948956698 1.3463968515392303882 6.7698458176426589005e-15" />
    <parent link="waist_link" />
    <child link="spiral_bevel_1m_14t_30deg_2" />
    <axis xyz="0 0 1" />
    <limit effort="1" velocity="20" lower="-4.6774823953448034786" upper="4.6774823953448034786" />
    <joint_properties friction="0.0" />
  </joint>

  <link name="spur_gear_19_teeth">
    <visual>
      <origin xyz="0 0 0" rpy="0 -0 0" />
      <geometry>
        <mesh filename="../assemblies/toddlerbot/meshes/spur_gear_19_teeth_visual.stl" />
      </geometry>
      <material name="spur_gear_19_teeth_material">
        <color rgba="0.61568627450980395466 0.81176470588235294379 0.92941176470588238168 1.0" />
      </material>
    </visual>
    <inertial>
      <origin xyz="-4.7403242595143773768e-08 1.5460070764038637399e-08 0.0045456071298370023803" rpy="0 0 0" />
      <mass value="0.0011084409433758843876" />
      <inertia ixx="2.9582691212226700665e-08" ixy="-2.8904821292895135249e-14" ixz="7.8892082291036886091e-14" iyy="2.9582612758414119977e-08" iyz="-2.5767358059768096423e-14" izz="4.6351510704080136144e-08" />
    </inertial>
  </link>

  <joint name="left_hip_yaw_drive" type="revolute">
    <origin xyz="-0.036999999999998457734 0.037100000000005961542 -0.03950000000000024325" rpy="-1.5707963267949545116 -4.8003070743589248247e-13 -3.5749181392930616155e-13" />
    <parent link="waist_link" />
    <child link="spur_gear_19_teeth" />
    <axis xyz="0 0 1" />
    <limit effort="1" velocity="20" lower="-1.7361433085627806516" upper="1.7361433085627806516" />
    <joint_properties friction="0.0" />
  </joint>

  <link name="spur_gear_21_teeth">
    <visual>
      <origin xyz="0 0 0" rpy="0 -0 0" />
      <geometry>
        <mesh filename="../assemblies/toddlerbot/meshes/spur_gear_21_teeth_visual.stl" />
      </geometry>
      <material name="spur_gear_21_teeth_material">
        <color rgba="0.61568627450980395466 0.81176470588235294379 0.92941176470588238168 1.0" />
      </material>
    </visual>
    <inertial>
      <origin xyz="-6.7030730388797144104e-12 1.7758939849553634854e-11 0.0024945285429905615648" rpy="0 0 0" />
      <mass value="0.0010185686142775147826" />
      <inertia ixx="3.2410681505051109819e-08" ixy="-5.0070048685720157271e-39" ixz="-1.6778767679075106483e-38" iyy="3.2410681506302329683e-08" iyz="-2.1489356052918171638e-38" izz="6.0614091765677406549e-08" />
    </inertial>
  </link>

  <joint name="left_leg_fixed" type="fixed">
    <origin xyz="0 0 0.004999999999999997502" rpy="3.1415926535897926719 -1.9428902930939016723e-16 -7.6327832942984196016e-16" />
    <parent link="spur_gear_21_teeth" />
    <child link="hip_yaw_link" />
    <axis xyz="0 0 1" />
    <limit effort="1" velocity="20" />
    <joint_properties friction="0.0" />
  </joint>

  <joint name="left_hip_yaw_driven" type="revolute">
    <origin xyz="-0.036999999999999998168 0.041100000000000011524 -0.019500000000000027728" rpy="-1.5707963267948947816 -1.570796326794896558 0" />
    <parent link="waist_link" />
    <child link="spur_gear_21_teeth" />
    <axis xyz="0 0 1" />
    <limit effort="1" velocity="20" lower="-1.570796326794896558" upper="1.570796326794896558" />
    <joint_properties friction="0.0" />
  </joint>

  <link name="spur_gear_19_teeth_2">
    <visual>
      <origin xyz="0 0 0" rpy="0 -0 0" />
      <geometry>
        <mesh filename="../assemblies/toddlerbot/meshes/spur_gear_19_teeth_2_visual.stl" />
      </geometry>
      <material name="spur_gear_19_teeth_2_material">
        <color rgba="0.61568627450980395466 0.81176470588235294379 0.92941176470588238168 1.0" />
      </material>
    </visual>
    <inertial>
      <origin xyz="-4.7403242595143773768e-08 1.5460070764038640708e-08 0.0045456071298370023803" rpy="0 0 0" />
      <mass value="0.0011084409433758843876" />
      <inertia ixx="2.9582691212226700665e-08" ixy="-2.8904821292766292175e-14" ixz="7.8892082291036886091e-14" iyy="2.9582612758414133212e-08" iyz="-2.5767358059768102734e-14" izz="4.6351510704080136144e-08" />
    </inertial>
  </link>

  <joint name="right_hip_yaw_drive" type="revolute">
    <origin xyz="0.037000000000001719014 0.03710000000000327619 -0.0394999999999998061" rpy="-1.5707963267949545116 -4.8002361403961149694e-13 -3.5216274341110541015e-13" />
    <parent link="waist_link" />
    <child link="spur_gear_19_teeth_2" />
    <axis xyz="0 0 1" />
    <limit effort="1" velocity="20" lower="-1.7361433085627806516" upper="1.7361433085627806516" />
    <joint_properties friction="0.0" />
  </joint>

  <link name="spur_gear_21_teeth_2">
    <visual>
      <origin xyz="0 0 0" rpy="0 -0 0" />
      <geometry>
        <mesh filename="../assemblies/toddlerbot/meshes/spur_gear_21_teeth_2_visual.stl" />
      </geometry>
      <material name="spur_gear_21_teeth_2_material">
        <color rgba="0.61568627450980395466 0.81176470588235294379 0.92941176470588238168 1.0" />
      </material>
    </visual>
    <inertial>
      <origin xyz="-6.7030730388797144104e-12 -1.7758939849553634854e-11 0.0025054714570094428761" rpy="0 0 0" />
      <mass value="0.0010185686142775147826" />
      <inertia ixx="3.2410681505051109819e-08" ixy="8.7148977985253644487e-40" ixz="1.7387576366417533163e-38" iyy="3.2410681506302329683e-08" iyz="2.053667615524067426e-38" izz="6.0614091765677406549e-08" />
    </inertial>
  </link>

  <joint name="right_leg_fixed" type="fixed">
    <origin xyz="0 -6.9388939039072283776e-18 0.0050000000000000044409" rpy="-3.1415926535897926719 1.8281169925220331315e-17 -3.5772536718062127375e-16" />
    <parent link="spur_gear_21_teeth_2" />
    <child link="hip_yaw_link_2" />
    <axis xyz="0 0 1" />
    <limit effort="1" velocity="20" />
    <joint_properties friction="0.0" />
  </joint>

  <joint name="right_hip_yaw_driven" type="revolute">
    <origin xyz="0.036999999999999991229 0.041100000000000011524 -0.019500000000000017319" rpy="-1.570796326794896558 -1.5707963267948961139 0" />
    <parent link="waist_link" />
    <child link="spur_gear_21_teeth_2" />
    <axis xyz="0 0 1" />
    <limit effort="1" velocity="20" lower="-1.570796326794896558" upper="1.570796326794896558" />
    <joint_properties friction="0.0" />
  </joint>

  <joint name="waist_roll" type="revolute">
    <origin xyz="-0.022707865260692617487 -2.4393502827093082036e-16 -0.013999999999999814676" rpy="-1.5707963267948974462 1.8675461532229772614e-15 1.5707963267948952257" />
    <parent link="waist_gears" />
    <child link="waist_link" />
    <axis xyz="0 0 1" />
    <limit effort="1" velocity="20" lower="-0.52359877559829881566" upper="0.52359877559829881566" />
    <joint_properties friction="0.0" />
  </joint>

  <joint name="waist_yaw" type="revolute">
    <origin xyz="0 -3.1104917983741196655e-18 -7.5188305028877687703e-30" rpy="-1.4111145075746007461e-16 -4.1376224834060906822e-15 3.1415926535897922278" />
    <parent link="torso" />
    <child link="waist_gears" />
    <axis xyz="0 0 1" />
    <limit effort="1" velocity="20" lower="-1.570796326794896558" upper="1.570796326794896558" />
    <joint_properties friction="0.0" />
  </joint>

  <joint name="left_sho_pitch" type="revolute">
    <origin xyz="-0.0030000000000002949654 0.062000000000001082023 0.10423651076281743866" rpy="-1.5707963267949081043 -4.127643409825574977e-14 3.4723733359249779961e-14" />
    <parent link="torso" />
    <child link="sho_pitch_link" />
    <axis xyz="0 0 1" />
    <limit effort="1" velocity="20" lower="-3.141592653589793116" upper="1.570796326794896558" />
    <joint_properties friction="0.0" />
  </joint>

  <joint name="right_sho_pitch" type="revolute">
    <origin xyz="-0.0029999999999986998872 -0.06200000000000097794 0.10423651076281731376" rpy="-1.5707963267948885644 3.4812325502379109658e-14 -3.1415926535897562566" />
    <parent link="torso" />
    <child link="sho_pitch_link_2" />
    <axis xyz="0 0 1" />
    <limit effort="1" velocity="20" lower="-1.570796326794896558" upper="3.141592653589793116" />
    <joint_properties friction="0.0" />
  </joint>


  <link name="hip_yaw_link">
    <visual>
      <origin xyz="0 0 0" rpy="0 -0 0" />
      <geometry>
        <mesh filename="../assemblies/left_leg_XM430/meshes/left_hip_yaw_link_visual.stl" />
      </geometry>
      <material name="hip_yaw_link_material">
        <color rgba="0.61568627450980395466 0.81176470588235294379 0.92941176470588238168 1.0" />
      </material>
    </visual>
    <inertial>
      <origin xyz="-2.6052892110043261802e-19 -4.5779561945300561906e-19 -0.0098390489054829104176" rpy="0 0 0" />
      <mass value="0.017999999999999988232" />
      <inertia ixx="2.6385033891442523914e-06" ixy="0" ixz="0" iyy="7.6596731957046873405e-06" iyz="0" izz="7.7220708070894735956e-06" />
    </inertial>
  </link>

  <link name="hip_roll_link">
    <visual>
      <origin xyz="0 0 0" rpy="0 -0 0" />
      <geometry>
        <mesh filename="../assemblies/left_leg_XM430/meshes/left_hip_roll_link_visual.stl" />
      </geometry>
      <material name="hip_roll_link_material">
        <color rgba="0.51698661238356047321 0.50347815951093488618 0.49050589017722012741 1.0" />
      </material>
    </visual>
    <inertial>
      <origin xyz="-0.011999849582186344205 -0.00049598090793799955514 -0.018504111838598794743" rpy="0 0 0" />
      <mass value="0.11059999999836234164" />
      <inertia ixx="2.2818802599019123213e-05" ixy="-4.6520143286798432356e-08" ixz="-4.6888548260596792068e-08" iyy="3.0871632082339373363e-05" iyz="-5.7477343899716644859e-07" izz="3.0871666424470007293e-05" />
    </inertial>
  </link>

  <link name="left_hip_pitch_link_xm430">
    <visual>
      <origin xyz="0 0 0" rpy="0 -0 0" />
      <geometry>
        <mesh filename="../assemblies/left_leg_XM430/meshes/left_hip_pitch_link_xm430_visual.stl" />
      </geometry>
      <material name="left_hip_pitch_link_xm430_material">
        <color rgba="0.87072221357329560032 0.72641010956094276274 0.24785169615220706274 1.0" />
      </material>
    </visual>
    <inertial>
      <origin xyz="-0.00075729214155315050742 -0.050714785675264821563 -0.012656155119959915795" rpy="0 0 0" />
      <mass value="0.11480090135030569798" />
      <inertia ixx="6.6072773889430024214e-05" ixy="-4.6080149277727762285e-07" ixz="-1.8170739115308462457e-07" iyy="2.3633638685369530631e-05" iyz="1.4125253925343164532e-06" izz="6.2221728804333383662e-05" />
    </inertial>
  <collision name="left_hip_pitch_link_xm430_collision"><origin xyz="0.0 -0.05550000141374767 -0.01720000198110938" rpy="0 0 0" /><geometry><box size="0.03999999910593033 0.1190000013448298 0.049600002355873585" /></geometry></collision></link>

  <link name="left_calf_link">
    <visual>
      <origin xyz="0 0 0" rpy="0 -0 0" />
      <geometry>
        <mesh filename="../assemblies/left_leg_XM430/meshes/left_calf_link_visual.stl" />
      </geometry>
      <material name="left_calf_link_material">
        <color rgba="0.616547745550632742 0.7175754134247219751 0.74372657889541438081 1.0" />
      </material>
    </visual>
    <inertial>
      <origin xyz="0.0016330556739555508825 -0.050045528174708635294 -0.0099079425125447578154" rpy="0 0 0" />
      <mass value="0.086799999986183581924" />
      <inertia ixx="4.950945987320032126e-05" ixy="3.6911110041724887421e-06" ixz="4.181905803998413212e-07" iyy="1.5531229037964085102e-05" iyz="4.6309763568422332319e-07" izz="5.3138661991212950706e-05" />
    </inertial>
  </link>

  <link name="bearing_683">
    <visual>
      <origin xyz="0 0 0" rpy="0 -0 0" />
      <geometry>
        <mesh filename="../assemblies/left_leg_XM430/meshes/left_bearing_683_visual.stl" />
      </geometry>
      <material name="bearing_683_material">
        <color rgba="0.64705882352941179736 0.64705882352941179736 0.64705882352941179736 1.0" />
      </material>
    </visual>
    <inertial>
      <origin xyz="1.0732094295242497084e-19 -2.4186774283160283989e-19 -0.0015500000000000003792" rpy="0 0 0" />
      <mass value="0.00048694686130641793437" />
      <inertia ixx="2.1551456503319879113e-09" ixy="2.3666528901256796113e-27" ixz="2.0889236366122119332e-38" iyy="2.1551456503319891521e-09" iyz="1.3744560845328921415e-38" izz="3.5303647444715305817e-09" />
    </inertial>
  </link>

  <joint name="left_knee_front_rev_2" type="revolute">
    <origin xyz="-0.0057402514854770240668 0.013858192987668910279 -0.026200000000000563116" rpy="2.0453876360821841634e-16 7.1068359470475064937e-16 1.5765314753541341819" />
    <parent link="left_calf_link" />
    <child link="bearing_683" />
    <axis xyz="0 0 1" />
    <limit effort="1" velocity="20" lower="-6.283185307179586232" upper="6.283185307179586232" />
    <joint_properties friction="0.0" />
  </joint>

  <link name="bearing_683_2">
    <visual>
      <origin xyz="0 0 0" rpy="0 -0 0" />
      <geometry>
        <mesh filename="../assemblies/left_leg_XM430/meshes/left_bearing_683_2_visual.stl" />
      </geometry>
      <material name="bearing_683_2_material">
        <color rgba="0.64705882352941179736 0.64705882352941179736 0.64705882352941179736 1.0" />
      </material>
    </visual>
    <inertial>
      <origin xyz="1.0732094295248846635e-19 -2.4186774283160375471e-19 -0.0015500000000000003792" rpy="0 0 0" />
      <mass value="0.00048694686130641793437" />
      <inertia ixx="2.1551456503319887385e-09" ixy="-1.3855900387721121507e-27" ixz="-1.9257410757015346214e-37" iyy="2.1551456503319874977e-09" iyz="-2.8124792185573659681e-39" izz="3.5303647444715305817e-09" />
    </inertial>
  </link>

  <joint name="left_knee_back_rev_2" type="revolute">
    <origin xyz="0.0057402514854760517543 -0.013858192987669437635 -0.026200000000000216172" rpy="2.8877467674261435159e-16 -6.2660216643685709814e-15 1.5765686202203079702" />
    <parent link="left_calf_link" />
    <child link="bearing_683_2" />
    <axis xyz="0 0 1" />
    <limit effort="1" velocity="20" lower="-6.283185307179586232" upper="6.283185307179586232" />
    <joint_properties friction="0.0" />
  </joint>

  <link name="ank_pitch_link">
    <visual>
      <origin xyz="0 0 0" rpy="0 -0 0" />
      <geometry>
        <mesh filename="../assemblies/left_leg_XM430/meshes/left_ank_pitch_link_visual.stl" />
      </geometry>
      <material name="ank_pitch_link_material">
        <color rgba="0.63189161126160264814 0.7266866879354088038 0.78356373393969258601 1.0" />
      </material>
    </visual>
    <inertial>
      <origin xyz="0.00059528282565903347691 -4.0269677046895822506e-08 7.7616091227946370715e-08" rpy="0 0 0" />
      <mass value="0.0042238381753791614387" />
      <inertia ixx="3.9782741364681224752e-07" ixy="-1.6834347544690341436e-13" ixz="2.09191870411591794e-14" iyy="4.3705254067426624596e-07" iyz="-1.6428821654626687343e-12" izz="8.8858574534620810897e-08" />
    </inertial>
  </link>

  <link name="ank_roll_link">
    <visual>
      <origin xyz="0 0 0" rpy="0 -0 0" />
      <geometry>
        <mesh filename="../assemblies/left_leg_XM430/meshes/left_ank_roll_link_visual.stl" />
      </geometry>
      <material name="ank_roll_link_material">
        <color rgba="0.61568627450980395466 0.81176470588235294379 0.92941176470588227065 1.0" />
      </material>
    </visual>
    <collision name="ank_roll_link_collision">
      <origin xyz="0.0 0.016499999444931746 0.008400000631809235" rpy="0 0 0" />
      <geometry><box size="0.041999999433755875 0.04500000271946192 0.12000000476837158" /></geometry></collision>
    <inertial>
      <origin xyz="-3.2206255610852245098e-10 0.030487683096149076345 0.0047792578419041014184" rpy="0 0 0" />
      <mass value="0.027200000000000008893" />
      <inertia ixx="2.2943463470325727e-05" ixy="-2.0167229481717782239e-13" ixz="4.0806229578615089115e-12" iyy="2.5276617323505065215e-05" iyz="-7.4169474455435566413e-07" izz="5.0976619075837788231e-06" />
    </inertial>
  </link>

  <link name="ank_rr_link">
    <visual>
      <origin xyz="0 0 0" rpy="0 -0 0" />
      <geometry>
        <mesh filename="../assemblies/left_leg_XM430/meshes/left_ank_rr_link_visual.stl" />
      </geometry>
      <material name="ank_rr_link_material">
        <color rgba="0.61568627450980395466 0.81176470588235294379 0.92941176470588238168 1.0" />
      </material>
    </visual>
    <inertial>
      <origin xyz="-4.5249610960606115111e-05 0.00630964298363145739 -2.0009406464642610885e-19" rpy="0 0 0" />
      <mass value="0.0014499999999999999001" />
      <inertia ixx="2.9739579267716143416e-08" ixy="2.4213146797977855138e-10" ixz="3.5523394884432783644e-14" iyy="2.7430027724071957055e-08" iyz="-9.8997471197656441548e-32" izz="4.2921949116163672436e-08" />
    </inertial>
  </link>

  <link name="ank_motor_rod_long">
    <visual>
      <origin xyz="0 0 0" rpy="0 -0 0" />
      <geometry>
        <mesh filename="../assemblies/left_leg_XM430/meshes/left_ank_motor_rod_long_visual.stl" />
      </geometry>
      <material name="ank_motor_rod_long_material">
        <color rgba="0.63549975559783222767 0.7077439301702044272 0.75109043491362770251 1.0" />
      </material>
    </visual>
    <inertial>
      <origin xyz="2.485508918145648815e-10 0.034559019974062257785 0.00093851704878453840689" rpy="0 0 0" />
      <mass value="0.0021712857268636710437" />
      <inertia ixx="8.535029005800039023e-07" ixy="1.4884244732590480163e-14" ixz="4.5749525025589543898e-11" iyy="1.3237321792739536015e-08" iyz="-4.3668910960857039398e-09" izz="8.5812217519451768749e-07" />
    </inertial>
  </link>

  <joint name="left_ank_long_rev_2" type="revolute">
    <origin xyz="2.4286128663675299322e-17 0.0099999999999992872368 1.3947176746853529039e-15" rpy="-1.5707963267948974462 1.3320366994105963254 -1.5707963267949054398" />
    <parent link="ank_rr_link" />
    <child link="ank_motor_rod_long" />
    <axis xyz="0 0 1" />
    <limit effort="1" velocity="20" lower="-1.570796326794896558" upper="1.570796326794896558" />
    <joint_properties friction="0.0" />
  </joint>

  <joint name="left_ank_long_rev_1" type="revolute">
    <origin xyz="-0.018000000000000064559 0.015999999999999292566 -0.020600000000001391504" rpy="-2.876394309884160705e-16 1.6317439732762683578e-16 3.1233695685467286474" />
    <parent link="ank_roll_link" />
    <child link="ank_rr_link" />
    <axis xyz="0 0 1" />
    <limit effort="1" velocity="20" lower="-1.570796326794896558" upper="1.570796326794896558" />
    <joint_properties friction="0.0" />
  </joint>

  <link name="ank_rr_link_2">
    <visual>
      <origin xyz="0 0 0" rpy="0 -0 0" />
      <geometry>
        <mesh filename="../assemblies/left_leg_XM430/meshes/left_ank_rr_link_2_visual.stl" />
      </geometry>
      <material name="ank_rr_link_2_material">
        <color rgba="0.61568627450980395466 0.81176470588235294379 0.92941176470588238168 1.0" />
      </material>
    </visual>
    <inertial>
      <origin xyz="-4.5249610960599155889e-05 -0.0063096429836314027462 3.6695410166003840762e-18" rpy="0 0 0" />
      <mass value="0.0014499999999999999001" />
      <inertia ixx="2.9739579267716150033e-08" ixy="-2.4213146797977875817e-10" ixz="-3.5523394884432789955e-14" iyy="2.7430027724071957055e-08" iyz="-6.0455732447540710973e-32" izz="4.2921949116163672436e-08" />
    </inertial>
  </link>

  <link name="ank_motor_rod_short">
    <visual>
      <origin xyz="0 0 0" rpy="0 -0 0" />
      <geometry>
        <mesh filename="../assemblies/left_leg_XM430/meshes/left_ank_motor_rod_short_visual.stl" />
      </geometry>
      <material name="ank_motor_rod_short_material">
        <color rgba="0.41222606689734719865 0.58339100346020766885 0.8110726643598615837 1.0" />
      </material>
    </visual>
    <inertial>
      <origin xyz="2.6038941310109507631e-10 0.023830465465870951519 0.00090403506359623014323" rpy="0 0 0" />
      <mass value="0.0017000000000000001221" />
      <inertia ixx="3.3153416252670235948e-07" ixy="8.7419768620623363038e-15" ixz="4.5749941567727589348e-11" iyy="1.0947363610305772565e-08" iyz="-3.5863098646405051489e-09" izz="3.3621340447865384922e-07" />
    </inertial>
  </link>

  <joint name="left_ank_short_rev_2" type="revolute">
    <origin xyz="0 -0.0099999999999998978595 0" rpy="-1.570796326794896558 -1.2119133862909823307 -1.570796326794896336" />
    <parent link="ank_rr_link_2" />
    <child link="ank_motor_rod_short" />
    <axis xyz="0 0 1" />
    <limit effort="1" velocity="20" lower="-1.570796326794896558" upper="1.570796326794896558" />
    <joint_properties friction="0.0" />
  </joint>

  <joint name="left_ank_short_rev_1" type="revolute">
    <origin xyz="0.017999999999999953537 0.016000000000000014211 -0.020600000000000010664" rpy="4.2172831995673088897e-16 -4.4678623027074358005e-17 0.026118548507422217203" />
    <parent link="ank_roll_link" />
    <child link="ank_rr_link_2" />
    <axis xyz="0 0 1" />
    <limit effort="1" velocity="20" lower="-1.570796326794896558" upper="1.570796326794896558" />
    <joint_properties friction="0.0" />
  </joint>

  <joint name="left_ank_roll" type="revolute">
    <origin xyz="0.0014999999999999995975 0 -1.5395670849294162963e-17" rpy="9.9573127520767875392e-16 1.570796326794891673 0" />
    <parent link="ank_pitch_link" />
    <child link="ank_roll_link" />
    <axis xyz="0 0 1" />
    <limit effort="1" velocity="20" lower="-0.785398163397448279" upper="0.785398163397448279" />
    <joint_properties friction="0.0" />
  </joint>

  <joint name="left_ank_pitch" type="revolute">
    <origin xyz="1.5349482163618395221e-15 -0.099999999999999339417 -0.01039999999999923451" rpy="1.0427422814103565708e-14 3.7115492970717391096e-15 3.1415926535897922278" />
    <parent link="left_calf_link" />
    <child link="ank_pitch_link" />
    <axis xyz="0 0 1" />
    <limit effort="1" velocity="20" lower="-1.0471975511965976313" upper="0.785398163397448279" />
    <joint_properties friction="0.0" />
  </joint>

  <link name="ank_motor_arm">
    <visual>
      <origin xyz="0 0 0" rpy="0 -0 0" />
      <geometry>
        <mesh filename="../assemblies/left_leg_XM430/meshes/left_ank_motor_arm_visual.stl" />
      </geometry>
      <material name="ank_motor_arm_material">
        <color rgba="0.62483822591633164656 0.70971956673896574586 0.76585356440212004614 1.0" />
      </material>
    </visual>
    <inertial>
      <origin xyz="0.014032842952293513375 -1.1875681051906339057e-09 0.0040383546575275958146" rpy="0 0 0" />
      <mass value="0.0021359401157891211472" />
      <inertia ixx="2.9209776528328194436e-08" ixy="-4.6752002052090677473e-14" ixz="-3.1659407525131264056e-08" iyy="1.7718014185775920105e-07" iyz="-2.5844348438515616861e-15" izz="1.8139327643022061737e-07" />
    </inertial>
  </link>

  <joint name="left_ank_act_1" type="revolute">
    <origin xyz="0.013500000000001635692 -0.044499999999992628785 0.0040000000000077733792" rpy="-5.7683923736819409867e-13 -7.5455504046046331278e-14 -0.21173394130254355461" />
    <parent link="left_calf_link" />
    <child link="ank_motor_arm" />
    <axis xyz="0 0 1" />
    <limit effort="1" velocity="20" lower="-1.3089969389957472057" upper="1.3089969389957472057" />
    <joint_properties friction="0.0" />
  </joint>

  <link name="ank_motor_arm_2">
    <visual>
      <origin xyz="0 0 0" rpy="0 -0 0" />
      <geometry>
        <mesh filename="../assemblies/left_leg_XM430/meshes/left_ank_motor_arm_2_visual.stl" />
      </geometry>
      <material name="ank_motor_arm_2_material">
        <color rgba="0.62483822591633164656 0.70971956673896574586 0.76585356440212004614 1.0" />
      </material>
    </visual>
    <inertial>
      <origin xyz="0.014032842952293501232 -1.1875680925106995778e-09 0.0040383546575276053556" rpy="0 0 0" />
      <mass value="0.0021359401157891211472" />
      <inertia ixx="2.9209776528328022382e-08" ixy="-4.6752001844237150679e-14" ixz="-3.165940752513130376e-08" iyy="1.7718014185775885694e-07" iyz="-2.5844347879891186066e-15" izz="1.8139327643022061737e-07" />
    </inertial>
  </link>

  <joint name="left_ank_act_2" type="revolute">
    <origin xyz="0.013500000000005811171 -0.064499999999988344435 -0.024800000000003163264" rpy="-3.1415926535893312632 1.9218128864630526701e-14 -0.22995607267384915451" />
    <parent link="left_calf_link" />
    <child link="ank_motor_arm_2" />
    <axis xyz="0 0 1" />
    <limit effort="1" velocity="20" lower="-1.3089969389957472057" upper="1.3089969389957472057" />
    <joint_properties friction="0.0" />
  </joint>

  <joint name="left_knee_pitch" type="revolute">
    <origin xyz="3.1436708451941898537e-17 -0.096000000000000001998 -0.0092000000000000154571" rpy="5.2388648972145238601e-16 -5.3048676098335846568e-16 -5.5511151227572361317e-17" />
    <parent link="left_hip_pitch_link_xm430" />
    <child link="left_calf_link" />
    <axis xyz="0 0 1" />
    <limit effort="1" velocity="20" lower="0" upper="1.9198621771937625091" />
    <joint_properties friction="0.0" />
  </joint>

  <link name="xm430_plate">
    <visual>
      <origin xyz="0 0 0" rpy="0 -0 0" />
      <geometry>
        <mesh filename="../assemblies/left_leg_XM430/meshes/left_xm430_plate_visual.stl" />
      </geometry>
      <material name="xm430_plate_material">
        <color rgba="0.61568627450980395466 0.81176470588235294379 0.9294117647058824927 1.0" />
      </material>
    </visual>
    <inertial>
      <origin xyz="3.3859260150270524496e-18 2.0528781890801290596e-18 -0.0024039046431217955119" rpy="0 0 0" />
      <mass value="0.0026999999999999992756" />
      <inertia ixx="1.293311664536341083e-07" ixy="-6.8936588702566413944e-08" ixz="5.4735536363229128674e-35" iyy="2.672043438587668303e-07" iyz="-6.5325103416928993699e-36" izz="3.8533537562751439267e-07" />
    </inertial>
  </link>

  <link name="knee_rod">
    <visual>
      <origin xyz="0 0 0" rpy="0 -0 0" />
      <geometry>
        <mesh filename="../assemblies/left_leg_XM430/meshes/left_knee_rod_visual.stl" />
      </geometry>
      <material name="knee_rod_material">
        <color rgba="0.62051618944235198416 0.78640765248647581664 0.88594253031295022716 1.0" />
      </material>
    </visual>
    <inertial>
      <origin xyz="0.014594549254227703189 -4.0495174182604799708e-05 -0.0015996227373190293787" rpy="0 0 0" />
      <mass value="0.0031629468613064179276" />
      <inertia ixx="2.5896066719679945792e-08" ixy="3.4015849028409630471e-10" ixz="4.1682980135095627253e-10" iyy="6.015325433306769779e-07" iyz="-1.1565684637535341676e-12" izz="6.2266854577246018566e-07" />
    </inertial>
  </link>

  <joint name="left_knee_front_rev_1" type="revolute">
    <origin xyz="0.013858192987669312735 0.0057402514854763336469 -0.0049999999999999836242" rpy="-9.4192987622433650731e-16 3.8593656109062736187e-16 -3.1358575050305752541" />
    <parent link="xm430_plate" />
    <child link="knee_rod" />
    <axis xyz="0 0 1" />
    <limit effort="1" velocity="20" lower="-6.283185307179586232" upper="6.283185307179586232" />
    <joint_properties friction="0.0" />
  </joint>

  <link name="knee_rod_2">
    <visual>
      <origin xyz="0 0 0" rpy="0 -0 0" />
      <geometry>
        <mesh filename="../assemblies/left_leg_XM430/meshes/left_knee_rod_2_visual.stl" />
      </geometry>
      <material name="knee_rod_2_material">
        <color rgba="0.62051618944235198416 0.78640765248647581664 0.88594253031295022716 1.0" />
      </material>
    </visual>
    <inertial>
      <origin xyz="0.014594547729902918737 -4.1579390108021769244e-05 -0.0015996227373185551487" rpy="0 0 0" />
      <mass value="0.0031629468613064179276" />
      <inertia ixx="2.5896117936396398863e-08" ixy="3.4926584154272074411e-10" ixz="4.1682975780794631615e-10" iyy="6.0153251772212437219e-07" iyz="-1.1875343734383760925e-12" izz="6.2266857138059509825e-07" />
    </inertial>
  </link>

  <joint name="left_knee_back_rev_1" type="revolute">
    <origin xyz="-0.013858192987669284979 -0.0057402514854763449226 -0.0050000000000000009714" rpy="-1.240696991414760872e-15 6.8873592505729608146e-15 -3.1358203601644016878" />
    <parent link="xm430_plate" />
    <child link="knee_rod_2" />
    <axis xyz="0 0 1" />
    <limit effort="1" velocity="20" lower="-6.283185307179586232" upper="6.283185307179586232" />
    <joint_properties friction="0.0" />
  </joint>

  <joint name="left_knee_act" type="revolute">
    <origin xyz="-0.00015000000000007682969 -0.061499999999999728495 -0.030399999999999843814" rpy="-1.3864621477766001324e-15 9.2520451941214004081e-17 1.5707963267949205388" />
    <parent link="left_hip_pitch_link_xm430" />
    <child link="xm430_plate" />
    <axis xyz="0 0 1" />
    <limit effort="1" velocity="20" lower="0" upper="1.9198621771937625091" />
    <joint_properties friction="0.0" />
  </joint>

  <joint name="left_hip_pitch" type="revolute">
    <origin xyz="-0.024000000716155701214 -0.019000000152439879691 -0.019000000152457872243" rpy="1.570796326795379283 1.5707963267945606045 0" />
    <parent link="hip_roll_link" />
    <child link="left_hip_pitch_link_xm430" />
    <axis xyz="0 0 1" />
    <limit effort="1" velocity="20" lower="-1.570796326794896558" upper="1.570796326794896558" />
    <joint_properties friction="0.0" />
  </joint>

  <joint name="left_hip_roll" type="revolute">
    <origin xyz="0.018999999999999999528 -3.3500438890366171686e-18 -0.026000000000000002276" rpy="3.141592653589793116 -1.5707963267948930053 0" />
    <parent link="hip_yaw_link" />
    <child link="hip_roll_link" />
    <axis xyz="0 0 1" />
    <limit effort="1" velocity="20" lower="-0.785398163397448279" upper="0.785398163397448279" />
    <joint_properties friction="0.0" />
  </joint>


  <link name="hip_yaw_link_2">
    <visual>
      <origin xyz="0 0 0" rpy="0 -0 0" />
      <geometry>
        <mesh filename="../assemblies/right_leg_XM430/meshes/right_hip_yaw_link_visual.stl" />
      </geometry>
      <material name="hip_yaw_link_material">
        <color rgba="0.61568627450980395466 0.81176470588235294379 0.92941176470588238168 1.0" />
      </material>
    </visual>
    <inertial>
      <origin xyz="2.6052892110043261802e-19 4.5779561945300561906e-19 -0.0098390489054829104176" rpy="0 0 0" />
      <mass value="0.017999999999999988232" />
      <inertia ixx="2.6385033891442523914e-06" ixy="0" ixz="0" iyy="7.6596731957046873405e-06" iyz="0" izz="7.7220708070894735956e-06" />
    </inertial>
  </link>

  <link name="hip_roll_link_2">
    <visual>
      <origin xyz="0 0 0" rpy="0 -0 0" />
      <geometry>
        <mesh filename="../assemblies/right_leg_XM430/meshes/right_hip_roll_link_visual.stl" />
      </geometry>
      <material name="hip_roll_link_material">
        <color rgba="0.51698661238356047321 0.50347815951093488618 0.49050589017722012741 1.0" />
      </material>
    </visual>
    <inertial>
      <origin xyz="-0.011999849582182775878 -0.00049598090794319277513 -0.018504111838597465944" rpy="0 0 0" />
      <mass value="0.11059999999836234164" />
      <inertia ixx="2.2818802599018211805e-05" ixy="-4.6520143286279465858e-08" ixz="-4.6888548259070895301e-08" iyy="3.0871632082338065545e-05" iyz="-5.7477343899720890612e-07" izz="3.0871666424467947309e-05" />
    </inertial>
  </link>

  <link name="right_hip_pitch_link_xm430">
    <visual>
      <origin xyz="0 0 0" rpy="0 -0 0" />
      <geometry>
        <mesh filename="../assemblies/right_leg_XM430/meshes/right_hip_pitch_link_xm430_visual.stl" />
      </geometry>
      <material name="right_hip_pitch_link_xm430_material">
        <color rgba="0.8707222135732954893 0.72641010956094265172 0.24785169615220692396 1.0" />
      </material>
    </visual>
    <inertial>
      <origin xyz="0.00075715881371283015253 -0.050714784778880722671 -0.012656153620121983125" rpy="0 0 0" />
      <mass value="0.11480090135030567022" />
      <inertia ixx="6.607278648938489003e-05" ixy="4.6010682906021260133e-07" ixz="1.8171597853315155815e-07" iyy="2.3633665181581639092e-05" iyz="1.4125296519934706645e-06" izz="6.2221763055418004632e-05" />
    </inertial>
  <collision name="right_hip_pitch_link_xm430_collision"><origin xyz="0.0 -0.05550000141374767 -0.01720000011846423" rpy="0 0 0" /><geometry><box size="0.03999999910593033 0.1190000013448298 0.049599998630583286" /></geometry></collision></link>

  <link name="right_calf_link">
    <visual>
      <origin xyz="0 0 0" rpy="0 -0 0" />
      <geometry>
        <mesh filename="../assemblies/right_leg_XM430/meshes/right_calf_link_visual.stl" />
      </geometry>
      <material name="right_calf_link_material">
        <color rgba="0.616547745550632742 0.71757541342472208612 0.74372657889541438081 1.0" />
      </material>
    </visual>
    <inertial>
      <origin xyz="0.0016330560292394454176 0.050045526484800137434 -0.0099079425237753124961" rpy="0 0 0" />
      <mass value="0.086799999986183554168" />
      <inertia ixx="4.9519076588877077342e-05" ixy="-3.6911123877145733517e-06" ixz="4.1819052274331339443e-07" iyy="1.5531229308366343087e-05" iyz="-4.6072292079354113904e-07" izz="5.314827806205983451e-05" />
    </inertial>
  </link>

  <link name="bearing_683_3">
    <visual>
      <origin xyz="0 0 0" rpy="0 -0 0" />
      <geometry>
        <mesh filename="../assemblies/right_leg_XM430/meshes/right_bearing_683_visual.stl" />
      </geometry>
      <material name="bearing_683_material">
        <color rgba="0.64705882352941179736 0.64705882352941179736 0.64705882352941179736 1.0" />
      </material>
    </visual>
    <inertial>
      <origin xyz="1.0732094295239739393e-19 2.4186774283161266214e-19 -0.0015500000000000016803" rpy="0 0 0" />
      <mass value="0.00048694686130641793437" />
      <inertia ixx="2.1551456503319895657e-09" ixy="2.3175595566406579266e-27" ixz="2.4896541890902438623e-38" iyy="2.1551456503319883249e-09" iyz="5.4460298433450471486e-38" izz="3.5303647444715305817e-09" />
    </inertial>
  </link>

  <joint name="right_knee_front_rev_2" type="revolute">
    <origin xyz="-0.0057402514854763431879 -0.013858192987669382124 -0.026199999999999987188" rpy="4.9452523641215521159e-15 -3.1674356695639584582e-16 3.1359672412492258786" />
    <parent link="right_calf_link" />
    <child link="bearing_683_3" />
    <axis xyz="0 0 1" />
    <limit effort="1" velocity="20" lower="-6.283185307179586232" upper="6.283185307179586232" />
    <joint_properties friction="0.0" />
  </joint>

  <link name="bearing_683_4">
    <visual>
      <origin xyz="0 0 0" rpy="0 -0 0" />
      <geometry>
        <mesh filename="../assemblies/right_leg_XM430/meshes/right_bearing_683_2_visual.stl" />
      </geometry>
      <material name="bearing_683_2_material">
        <color rgba="0.64705882352941179736 0.64705882352941179736 0.64705882352941179736 1.0" />
      </material>
    </visual>
    <inertial>
      <origin xyz="1.0732094295240485691e-19 2.418677428316700067e-19 -0.0015499999999999977771" rpy="0 0 0" />
      <mass value="0.00048694686130641793437" />
      <inertia ixx="2.1551456503319887385e-09" ixy="9.4016331328971133286e-28" ixz="6.4941734545542371767e-38" iyy="2.1551456503319874977e-09" iyz="1.5195108877220808957e-37" izz="3.5303647444715322361e-09" />
    </inertial>
  </link>

  <joint name="right_knee_back_rev_2" type="revolute">
    <origin xyz="0.0057402514854763692087 0.013858192987669243346 -0.026199999999999990657" rpy="-2.5000942521723397481e-14 5.2473395102998583317e-16 3.1360672427763174319" />
    <parent link="right_calf_link" />
    <child link="bearing_683_4" />
    <axis xyz="0 0 1" />
    <limit effort="1" velocity="20" lower="-6.283185307179586232" upper="6.283185307179586232" />
    <joint_properties friction="0.0" />
  </joint>

  <link name="ank_pitch_link_2">
    <visual>
      <origin xyz="0 0 0" rpy="0 -0 0" />
      <geometry>
        <mesh filename="../assemblies/right_leg_XM430/meshes/right_ank_pitch_link_visual.stl" />
      </geometry>
      <material name="ank_pitch_link_material">
        <color rgba="0.63189161126160264814 0.7266866879354088038 0.78356373393969258601 1.0" />
      </material>
    </visual>
    <inertial>
      <origin xyz="0.00059528282565814453955 4.0269684199612070023e-08 -7.7616092347959137447e-08" rpy="0 0 0" />
      <mass value="0.0042238381753791614387" />
      <inertia ixx="3.9782741364678847766e-07" ixy="1.6834347545013802175e-13" ixz="-2.0919187193369323082e-14" iyy="4.3705254067423273522e-07" iyz="-1.6428822295928359723e-12" izz="8.8858574534611122958e-08" />
    </inertial>
  </link>

  <link name="ank_roll_link_2">
    <visual>
      <origin xyz="0 0 0" rpy="0 -0 0" />
      <geometry>
        <mesh filename="../assemblies/right_leg_XM430/meshes/right_ank_roll_link_visual.stl" />
      </geometry>
      <material name="ank_roll_link_material">
        <color rgba="0.61568627450980395466 0.81176470588235294379 0.92941176470588227065 1.0" />
      </material>
    </visual>
    <collision name="ank_roll_link_2_collision">
      <origin xyz="0.0 0.016499999444931746 0.008400000631809235" rpy="0 0 0" />
      <geometry><box size="0.041999999433755875 0.04500000271946192 0.12000000476837158" /></geometry></collision>
    <inertial>
      <origin xyz="-3.2206255610852239928e-10 0.030487683096149048589 0.0047792578419041014184" rpy="0 0 0" />
      <mass value="0.027200000000000008893" />
      <inertia ixx="2.2943463470325713448e-05" ixy="-2.016722948171777719e-13" ixz="4.0806229578615081037e-12" iyy="2.5276617323505065215e-05" iyz="-7.4169474455435566413e-07" izz="5.0976619075837788231e-06" />
    </inertial>
  </link>

  <link name="ank_rr_link_3">
    <visual>
      <origin xyz="0 0 0" rpy="0 -0 0" />
      <geometry>
        <mesh filename="../assemblies/right_leg_XM430/meshes/right_ank_rr_link_visual.stl" />
      </geometry>
      <material name="ank_rr_link_material">
        <color rgba="0.61568627450980395466 0.81176470588235294379 0.92941176470588238168 1.0" />
      </material>
    </visual>
    <inertial>
      <origin xyz="-4.5249610960602645664e-05 -0.0063096429836314027462 2.0009406464677816885e-19" rpy="0 0 0" />
      <mass value="0.0014499999999999999001" />
      <inertia ixx="2.9739579267716163268e-08" ixy="-2.4213146797977880987e-10" ixz="-3.5523394884432796266e-14" iyy="2.7430027724071957055e-08" iyz="4.4497301223652303834e-32" izz="4.2921949116163672436e-08" />
    </inertial>
  </link>

  <link name="ank_motor_rod_long_2">
    <visual>
      <origin xyz="0 0 0" rpy="0 -0 0" />
      <geometry>
        <mesh filename="../assemblies/right_leg_XM430/meshes/right_ank_motor_rod_long_visual.stl" />
      </geometry>
      <material name="ank_motor_rod_long_material">
        <color rgba="0.63549975559783222767 0.7077439301702044272 0.75109043491362770251 1.0" />
      </material>
    </visual>
    <inertial>
      <origin xyz="2.4855090373658416808e-10 0.034559019974062320235 0.00093851704878454773103" rpy="0 0 0" />
      <mass value="0.0021712857268636710437" />
      <inertia ixx="8.5350290058000421993e-07" ixy="1.4884244055558907074e-14" ixz="4.5749525025468555809e-11" iyy="1.3237321792739598881e-08" iyz="-4.3668910960859711191e-09" izz="8.5812217519451768749e-07" />
    </inertial>
  </link>

  <joint name="right_ank_long_rev_2" type="revolute">
    <origin xyz="-3.4694469519536141888e-18 -0.0099999999999999533706 -6.9388939039072283776e-18" rpy="-1.570796326794896558 -1.3320366994106251912 -1.5707963267948779063" />
    <parent link="ank_rr_link_3" />
    <child link="ank_motor_rod_long_2" />
    <axis xyz="0 0 1" />
    <limit effort="1" velocity="20" lower="-1.570796326794896558" upper="1.570796326794896558" />
    <joint_properties friction="0.0" />
  </joint>

  <joint name="right_ank_long_rev_1" type="revolute">
    <origin xyz="0.01799999999999999864 0.015999999999999764411 -0.020600000000000132094" rpy="-7.8386807614170502355e-15 7.211088289180617976e-16 0.018223085043007757056" />
    <parent link="ank_roll_link_2" />
    <child link="ank_rr_link_3" />
    <axis xyz="0 0 1" />
    <limit effort="1" velocity="20" lower="-1.570796326794896558" upper="1.570796326794896558" />
    <joint_properties friction="0.0" />
  </joint>

  <link name="ank_rr_link_4">
    <visual>
      <origin xyz="0 0 0" rpy="0 -0 0" />
      <geometry>
        <mesh filename="../assemblies/right_leg_XM430/meshes/right_ank_rr_link_2_visual.stl" />
      </geometry>
      <material name="ank_rr_link_2_material">
        <color rgba="0.61568627450980395466 0.81176470588235294379 0.92941176470588238168 1.0" />
      </material>
    </visual>
    <inertial>
      <origin xyz="-4.5249610960599182994e-05 0.0063096429836314591247 -2.0009406464667284455e-19" rpy="0 0 0" />
      <mass value="0.0014499999999999999001" />
      <inertia ixx="2.9739579267716163268e-08" ixy="2.4213146797977886157e-10" ixz="3.5523394884432796266e-14" iyy="2.7430027724071963673e-08" iyz="7.1669291072376189503e-32" izz="4.2921949116163672436e-08" />
    </inertial>
  </link>

  <link name="ank_motor_rod_short_2">
    <visual>
      <origin xyz="0 0 0" rpy="0 -0 0" />
      <geometry>
        <mesh filename="../assemblies/right_leg_XM430/meshes/right_ank_motor_rod_short_visual.stl" />
      </geometry>
      <material name="ank_motor_rod_short_material">
        <color rgba="0.41222606689734719865 0.58339100346020766885 0.8110726643598615837 1.0" />
      </material>
    </visual>
    <inertial>
      <origin xyz="2.6038943231632549872e-10 0.023830465465870847436 0.00090403506359630625422" rpy="0 0 0" />
      <mass value="0.0017000000000000001221" />
      <inertia ixx="3.3153416252669976544e-07" ixy="8.7419768119858657143e-15" ixz="4.5749941567677183029e-11" iyy="1.0947363610305713008e-08" iyz="-3.5863098646420718289e-09" izz="3.3621340447865204927e-07" />
    </inertial>
  </link>

  <joint name="right_ank_short_rev_2" type="revolute">
    <origin xyz="0 0.010000000000000008882 0" rpy="-1.570796326794896558 1.2119133862909121646 -1.5707963267948537034" />
    <parent link="ank_rr_link_4" />
    <child link="ank_motor_rod_short_2" />
    <axis xyz="0 0 1" />
    <limit effort="1" velocity="20" lower="-1.570796326794896558" upper="1.570796326794896558" />
    <joint_properties friction="0.0" />
  </joint>

  <joint name="right_ank_short_rev_1" type="revolute">
    <origin xyz="-0.018000000000000009048 0.015999999999999764411 -0.020600000000000118217" rpy="2.411086010918130345e-14 -1.3088994399411267302e-14 3.1154741050824821258" />
    <parent link="ank_roll_link_2" />
    <child link="ank_rr_link_4" />
    <axis xyz="0 0 1" />
    <limit effort="1" velocity="20" lower="-1.570796326794896558" upper="1.570796326794896558" />
    <joint_properties friction="0.0" />
  </joint>

  <joint name="right_ank_roll" type="revolute">
    <origin xyz="0.001499999999999998947 8.3266726846886740532e-17 1.3660947373317355868e-17" rpy="6.1391486757704172424e-30 1.5707963267948927832 0" />
    <parent link="ank_pitch_link_2" />
    <child link="ank_roll_link_2" />
    <axis xyz="0 0 1" />
    <limit effort="1" velocity="20" lower="-0.785398163397448279" upper="0.785398163397448279" />
    <joint_properties friction="0.0" />
  </joint>

  <joint name="right_ank_pitch" type="revolute">
    <origin xyz="3.4616201395293281188e-16 0.10000000000000006106 -0.010399999999999975236" rpy="-3.1415926535897922278 1.9667427410937738729e-16 -3.1415926535897926719" />
    <parent link="right_calf_link" />
    <child link="ank_pitch_link_2" />
    <axis xyz="0 0 1" />
    <limit effort="1" velocity="20" lower="-1.0471975511965976313" upper="0.785398163397448279" />
    <joint_properties friction="0.0" />
  </joint>

  <link name="ank_motor_arm_3">
    <visual>
      <origin xyz="0 0 0" rpy="0 -0 0" />
      <geometry>
        <mesh filename="../assemblies/right_leg_XM430/meshes/right_ank_motor_arm_visual.stl" />
      </geometry>
      <material name="ank_motor_arm_material">
        <color rgba="0.62483822591633164656 0.70971956673896574586 0.76585356440212004614 1.0" />
      </material>
    </visual>
    <inertial>
      <origin xyz="0.014032842952293483885 -1.1875681526054779929e-09 0.0040383546575275923451" rpy="0 0 0" />
      <mass value="0.0021359401157891211472" />
      <inertia ixx="2.920977652832815804e-08" ixy="-4.6752001422563860023e-14" ixz="-3.1659407525131065532e-08" iyy="1.7718014185775859225e-07" iyz="-2.5844346951013690337e-15" izz="1.8139327643022011445e-07" />
    </inertial>
  </link>

  <joint name="right_ank_act_1" type="revolute">
    <origin xyz="0.013499999999996006514 0.04450000000000683964 0.0040000000000046075088" rpy="-3.1559662337880072911e-13 -4.3224762083389784551e-14 0.21173394130152450865" />
    <parent link="right_calf_link" />
    <child link="ank_motor_arm_3" />
    <axis xyz="0 0 1" />
    <limit effort="1" velocity="20" lower="-1.3089969389957472057" upper="1.3089969389957472057" />
    <joint_properties friction="0.0" />
  </joint>

  <link name="ank_motor_arm_4">
    <visual>
      <origin xyz="0 0 0" rpy="0 -0 0" />
      <geometry>
        <mesh filename="../assemblies/right_leg_XM430/meshes/right_ank_motor_arm_2_visual.stl" />
      </geometry>
      <material name="ank_motor_arm_2_material">
        <color rgba="0.62483822591633164656 0.70971956673896574586 0.76585356440212004614 1.0" />
      </material>
    </visual>
    <inertial>
      <origin xyz="0.014032842952293506436 -1.187568081600947684e-09 0.0040383546575275958146" rpy="0 0 0" />
      <mass value="0.0021359401157891211472" />
      <inertia ixx="2.9209776528328204362e-08" ixy="-4.6752001607133292608e-14" ixz="-3.1659407525131217734e-08" iyy="1.7718014185775922752e-07" iyz="-2.5844347378765580252e-15" izz="1.8139327643022061737e-07" />
    </inertial>
  </link>

  <joint name="right_ank_act_2" type="revolute">
    <origin xyz="0.013500000000003113676 0.064500000000006912915 -0.024800000000002909994" rpy="-3.1415926535895573046 -1.7198897169567297797e-13 0.22995607267273157626" />
    <parent link="right_calf_link" />
    <child link="ank_motor_arm_4" />
    <axis xyz="0 0 1" />
    <limit effort="1" velocity="20" lower="-1.3089969389957472057" upper="1.3089969389957472057" />
    <joint_properties friction="0.0" />
  </joint>

  <joint name="right_knee_pitch" type="revolute">
    <origin xyz="-2.9733995392255427503e-17 -0.096000000000000001998 -0.0091999999999999963751" rpy="-2.1337098754749728925e-16 3.9898639968108458448e-17 3.1415926535897846783" />
    <parent link="right_hip_pitch_link_xm430" />
    <child link="right_calf_link" />
    <axis xyz="0 0 1" />
    <limit effort="1" velocity="20" lower="-1.9198621771937625091" upper="0" />
    <joint_properties friction="0.0" />
  </joint>

  <link name="xm430_plate_2">
    <visual>
      <origin xyz="0 0 0" rpy="0 -0 0" />
      <geometry>
        <mesh filename="../assemblies/right_leg_XM430/meshes/right_xm430_plate_visual.stl" />
      </geometry>
      <material name="xm430_plate_material">
        <color rgba="0.61568627450980395466 0.81176470588235294379 0.9294117647058824927 1.0" />
      </material>
    </visual>
    <inertial>
      <origin xyz="8.2761015112156068591e-19 3.9608123405210419363e-18 -0.0024039046431217972466" rpy="0 0 0" />
      <mass value="0.0026999999999999992756" />
      <inertia ixx="2.6720434385876688324e-07" ixy="-6.8936588702566374239e-08" ixz="2.5793754136946577579e-36" iyy="1.2933116645363405536e-07" iyz="-5.5772549530744028788e-36" izz="3.8533537562751439267e-07" />
    </inertial>
  </link>

  <link name="knee_rod_3">
    <visual>
      <origin xyz="0 0 0" rpy="0 -0 0" />
      <geometry>
        <mesh filename="../assemblies/right_leg_XM430/meshes/right_knee_rod_visual.stl" />
      </geometry>
      <material name="knee_rod_material">
        <color rgba="0.62051618944235198416 0.78640765248647581664 0.88594253031295022716 1.0" />
      </material>
    </visual>
    <inertial>
      <origin xyz="0.014594553522267959475 3.7292099839724583211e-05 -0.0015996227373186720257" rpy="0 0 0" />
      <mass value="0.0031629468613064179276" />
      <inertia ixx="2.5895923315130376932e-08" ixy="-3.1325283435871752107e-10" ixz="4.1682992324833837119e-10" iyy="6.015326150335526925e-07" iyz="1.0650865822052022654e-12" izz="6.2266847407077561114e-07" />
    </inertial>
  </link>

  <joint name="right_knee_front_rev_1" type="revolute">
    <origin xyz="-0.005740251485476348392 -0.013858192987669298857 -0.0050000000000000027062" rpy="1.2660330546546102165e-14 -5.760640040579399853e-15 1.5651709144543408669" />
    <parent link="xm430_plate_2" />
    <child link="knee_rod_3" />
    <axis xyz="0 0 1" />
    <limit effort="1" velocity="20" lower="-6.283185307179586232" upper="6.283185307179586232" />
    <joint_properties friction="0.0" />
  </joint>

  <link name="knee_rod_4">
    <visual>
      <origin xyz="0 0 0" rpy="0 -0 0" />
      <geometry>
        <mesh filename="../assemblies/right_leg_XM430/meshes/right_knee_rod_2_visual.stl" />
      </geometry>
      <material name="knee_rod_2_material">
        <color rgba="0.62051618944235198416 0.78640765248647581664 0.88594253031295022716 1.0" />
      </material>
    </visual>
    <inertial>
      <origin xyz="0.014594557105585477183 3.4373169586153155656e-05 -0.0015996227373184820734" rpy="0 0 0" />
      <mass value="0.0031629468613064179276" />
      <inertia ixx="2.5895802916981975736e-08" ixy="-2.8873395407690157505e-10" ixz="4.1683002558550294754e-10" iyy="6.0153267523314955379e-07" iyz="9.8172003926880134242e-13" izz="6.2266841387223807044e-07" />
    </inertial>
  </link>

  <joint name="right_knee_back_rev_1" type="revolute">
    <origin xyz="0.0057402514854763509941 0.013858192987669298857 -0.0050000000000000061756" rpy="1.7600934488845652939e-14 7.4447456537463636708e-16 1.5652709159814237605" />
    <parent link="xm430_plate_2" />
    <child link="knee_rod_4" />
    <axis xyz="0 0 1" />
    <limit effort="1" velocity="20" lower="-6.283185307179586232" upper="6.283185307179586232" />
    <joint_properties friction="0.0" />
  </joint>

  <joint name="right_knee_act" type="revolute">
    <origin xyz="0.0001500000000000903009 -0.061499999999999978295 -0.030400000000000013817" rpy="-2.110221371875480467e-15 -1.2104358314278240034e-14 3.1415926535897811256" />
    <parent link="right_hip_pitch_link_xm430" />
    <child link="xm430_plate_2" />
    <axis xyz="0 0 1" />
    <limit effort="1" velocity="20" lower="-1.9198621771937625091" upper="0" />
    <joint_properties friction="0.0" />
  </joint>

  <joint name="right_hip_pitch" type="revolute">
    <origin xyz="-0.024000000716142756707 -0.019000000152441819112 -0.019000000152452952568" rpy="1.5707963267951126074 1.5707963267947429031 0" />
    <parent link="hip_roll_link_2" />
    <child link="right_hip_pitch_link_xm430" />
    <axis xyz="0 0 1" />
    <limit effort="1" velocity="20" lower="-1.570796326794896558" upper="1.570796326794896558" />
    <joint_properties friction="0.0" />
  </joint>

  <joint name="right_hip_roll" type="revolute">
    <origin xyz="-0.018999999999999999528 3.350043889036771243e-18 -0.026000000000000002276" rpy="-6.1629758220389864097e-33 -1.5707963267948785724 0" />
    <parent link="hip_yaw_link_2" />
    <child link="hip_roll_link_2" />
    <axis xyz="0 0 1" />
    <limit effort="1" velocity="20" lower="-0.785398163397448279" upper="0.785398163397448279" />
    <joint_properties friction="0.0" />
  </joint>


  <link name="sho_pitch_link">
    <visual>
      <origin xyz="0 0 0" rpy="0 -0 0" />
      <geometry>
        <mesh filename="../assemblies/left_arm_hand/meshes/left_sho_pitch_link_visual.stl" />
      </geometry>
      <material name="sho_pitch_link_material">
        <color rgba="0.61568627450980395466 0.81176470588235294379 0.92941176470588238168 1.0" />
      </material>
    </visual>
    <inertial>
      <origin xyz="5.8254247652798875819e-11 -5.1264642561121521395e-05 0.0082440788127094901533" rpy="0 0 0" />
      <mass value="0.0086000000000000000056" />
      <inertia ixx="1.2272887040545791873e-06" ixy="-2.1429944210231087856e-14" ixz="-8.584719860658140756e-15" iyy="2.9107306060364611617e-06" iyz="7.4623841398183299076e-09" izz="3.0803135950773487693e-06" />
    </inertial>
  </link>

  <link name="2xl430_gears">
    <visual>
      <origin xyz="0 0 0" rpy="0 -0 0" />
      <geometry>
        <mesh filename="../assemblies/left_arm_hand/meshes/left_2xl430_gears_visual.stl" />
      </geometry>
      <material name="2xl430_gears_material">
        <color rgba="0.7560598568794409946 0.85804695962693022793 0.91320266199377464478 1.0" />
      </material>
    </visual>
    <inertial>
      <origin xyz="-0.011579403981036554341 -0.0024225766141400158216 -0.018551095523803531884" rpy="0 0 0" />
      <mass value="0.11800003674524907338" />
      <inertia ixx="2.7482298083236092012e-05" ixy="9.2729623432982117887e-07" ixz="-2.2634512003762348769e-08" iyy="3.2770742486672784378e-05" iyz="-6.5708346020130146558e-07" izz="3.5767957544054292845e-05" />
    </inertial>
  </link>

  <link name="spur_1m_24t_drive">
    <visual>
      <origin xyz="0 0 0" rpy="0 -0 0" />
      <geometry>
        <mesh filename="../assemblies/left_arm_hand/meshes/left_spur_1m_24t_drive_visual.stl" />
      </geometry>
      <material name="spur_1m_24t_drive_material">
        <color rgba="0.61568627450980406568 0.81176470588235294379 0.92941176470588238168 1.0" />
      </material>
    </visual>
    <inertial>
      <origin xyz="-7.7588747702773419228e-15 -1.2113919729783031184e-16 0.0047949116178401460231" rpy="0 0 0" />
      <mass value="0.0032000000000000001533" />
      <inertia ixx="1.4019331346159887702e-07" ixy="1.6002410021513630837e-15" ixz="-8.0106568502533340392e-38" iyy="1.4019331260388786185e-07" iyz="3.5707617447061325799e-38" izz="2.3838919844264060647e-07" />
    </inertial>
  </link>

  <joint name="left_sho_yaw_drive" type="revolute">
    <origin xyz="-0.024000000716141278723 -0.019000000152448490859 -0.0190000001524472939" rpy="1.570796326794886566 -1.7772407460995643501e-15 2.9721983312145830671e-14" />
    <parent link="2xl430_gears" />
    <child link="spur_1m_24t_drive" />
    <axis xyz="0 0 1" />
    <limit effort="1" velocity="20" lower="-1.570796326794896558" upper="1.570796326794896558" />
    <joint_properties friction="0.0" />
  </joint>

  <link name="spur_1m_24t_driven">
    <visual>
      <origin xyz="0 0 0" rpy="0 -0 0" />
      <geometry>
        <mesh filename="../assemblies/left_arm_hand/meshes/left_spur_1m_24t_driven_visual.stl" />
      </geometry>
      <material name="spur_1m_24t_driven_material">
        <color rgba="0.23137254901960788156 0.38039215686274507888 0.7058823529411765163 1.0" />
      </material>
    </visual>
    <inertial>
      <origin xyz="2.3289816703110464291e-18 -5.7987576959439556938e-15 -0.00096866348640038332785" rpy="0 0 0" />
      <mass value="0.0027000000000000001429" />
      <inertia ixx="1.2026541119643502094e-07" ixy="-4.0474500803410873683e-47" ixz="-1.0726060653955529023e-38" iyy="1.2026541119643483565e-07" iyz="5.980474480612833222e-38" izz="2.2827257365099366486e-07" />
    </inertial>
  </link>

  <link name="sho_yaw_link">
    <visual>
      <origin xyz="0 0 0" rpy="0 -0 0" />
      <geometry>
        <mesh filename="../assemblies/left_arm_hand/meshes/left_sho_yaw_link_visual.stl" />
      </geometry>
      <material name="sho_yaw_link_material">
        <color rgba="0.61568627450980395466 0.81176470588235294379 0.92941176470588238168 1.0" />
      </material>
    </visual>
    <inertial>
      <origin xyz="-1.1573942515719324801e-18 3.9965734479645065973e-18 -0.024214576156328410095" rpy="0 0 0" />
      <mass value="0.014500000000000019817" />
      <inertia ixx="9.0490855102915009419e-06" ixy="3.5997729401550392327e-13" ixz="8.4928747802388991438e-37" iyy="5.6767199180624735964e-06" iyz="1.6087043138114355428e-36" izz="4.4590603637468159332e-06" />
    </inertial>
  </link>

  <link name="2xl430_gears_2">
    <visual>
      <origin xyz="0 0 0" rpy="0 -0 0" />
      <geometry>
        <mesh filename="../assemblies/left_arm_hand/meshes/left_2xl430_gears_2_visual.stl" />
      </geometry>
      <material name="2xl430_gears_2_material">
        <color rgba="0.7560598568794409946 0.85804695962693022793 0.91320266199377464478 1.0" />
      </material>
    </visual>
    <inertial>
      <origin xyz="-0.01157940398103590382 -0.0024225766141403085562 -0.018551095523804767007" rpy="0 0 0" />
      <mass value="0.11800003674524907338" />
      <inertia ixx="2.7482298083236647666e-05" ixy="9.2729623433076170308e-07" ixz="-2.263451200393656955e-08" iyy="3.2770742486673184177e-05" iyz="-6.5708346020168125398e-07" izz="3.5767957544054909485e-05" />
    </inertial>
  </link>

  <link name="spur_1m_24t_drive_2">
    <visual>
      <origin xyz="0 0 0" rpy="0 -0 0" />
      <geometry>
        <mesh filename="../assemblies/left_arm_hand/meshes/left_spur_1m_24t_drive_2_visual.stl" />
      </geometry>
      <material name="spur_1m_24t_drive_2_material">
        <color rgba="0.61568627450980406568 0.81176470588235294379 0.92941176470588238168 1.0" />
      </material>
    </visual>
    <inertial>
      <origin xyz="-7.7519358763734346945e-15 -1.2113919729783050906e-16 0.0047949116178401382168" rpy="0 0 0" />
      <mass value="0.0032000000000000001533" />
      <inertia ixx="1.4019331346159887702e-07" ixy="1.6002410054600855339e-15" ixz="2.601989679508350391e-37" iyy="1.4019331260388786185e-07" iyz="-1.1857416576551867588e-36" izz="2.3838919844264060647e-07" />
    </inertial>
  </link>

  <joint name="left_elbow_yaw_drive" type="revolute">
    <origin xyz="-0.024000000716141011575 -0.019000000152448556778 -0.019000000152448452695" rpy="1.5707963267949249797 5.3833632274240703492e-15 -6.2781152873576405876e-14" />
    <parent link="2xl430_gears_2" />
    <child link="spur_1m_24t_drive_2" />
    <axis xyz="0 0 1" />
    <limit effort="1" velocity="20" lower="-1.570796326794896558" upper="1.570796326794896558" />
    <joint_properties friction="0.0" />
  </joint>

  <link name="spur_1m_24t_driven_2">
    <visual>
      <origin xyz="0 0 0" rpy="0 -0 0" />
      <geometry>
        <mesh filename="../assemblies/left_arm_hand/meshes/left_spur_1m_24t_driven_2_visual.stl" />
      </geometry>
      <material name="spur_1m_24t_driven_2_material">
        <color rgba="0.23137254901960788156 0.38039215686274507888 0.7058823529411765163 1.0" />
      </material>
    </visual>
    <inertial>
      <origin xyz="2.3289816703110237031e-18 -5.7989934404527921162e-15 -0.00096866348640039037516" rpy="0 0 0" />
      <mass value="0.0027000000000000001429" />
      <inertia ixx="1.2026541119643502094e-07" ixy="0" ixz="-3.9131793608196566436e-37" iyy="1.2026541119643483565e-07" iyz="0" izz="2.2827257365099366486e-07" />
    </inertial>
  </link>

  <link name="elb_yaw_link">
    <visual>
      <origin xyz="0 0 0" rpy="0 -0 0" />
      <geometry>
        <mesh filename="../assemblies/left_arm_hand/meshes/left_elb_yaw_link_visual.stl" />
      </geometry>
      <material name="elb_yaw_link_material">
        <color rgba="0.61568627450980395466 0.81176470588235294379 0.92941176470588227065 1.0" />
      </material>
    </visual>
    <inertial>
      <origin xyz="5.2870889172778520186e-08 0.0019873558182742466494 -0.02336566119982871545" rpy="0 0 0" />
      <mass value="0.017500000000000001665" />
      <inertia ixx="1.4097804991252558057e-05" ixy="1.690080968406779376e-12" ixz="-1.118467366217378058e-11" iyy="6.6367696417680302023e-06" iyz="1.0579908722588331512e-06" izz="8.9601142768980663591e-06" />
    </inertial>
  </link>

  <link name="spur_1m_24t_driven_3">
    <visual>
      <origin xyz="0 0 0" rpy="0 -0 0" />
      <geometry>
        <mesh filename="../assemblies/left_arm_hand/meshes/left_spur_1m_24t_driven_3_visual.stl" />
      </geometry>
      <material name="spur_1m_24t_driven_3_material">
        <color rgba="0.23137254901960788156 0.38039215686274507888 0.7058823529411765163 1.0" />
      </material>
    </visual>
    <inertial>
      <origin xyz="-2.5426593945317773481e-17 -5.8024628874047457304e-15 -0.0025686634864003805856" rpy="0 0 0" />
      <mass value="0.0027000000000000001429" />
      <inertia ixx="1.2026541119643502094e-07" ixy="7.589814491455755124e-37" ixz="1.0368687130951098114e-36" iyy="1.2026541119643483565e-07" iyz="7.7514145192038011191e-67" izz="2.2827257365099366486e-07" />
    </inertial>
  </link>

  <link name="2xl430_gears_3">
    <visual>
      <origin xyz="0 0 0" rpy="0 -0 0" />
      <geometry>
        <mesh filename="../assemblies/left_arm_hand/meshes/left_2xl430_gears_3_visual.stl" />
      </geometry>
      <material name="2xl430_gears_3_material">
        <color rgba="0.7560598568794409946 0.85804695962693022793 0.91320266199377464478 1.0" />
      </material>
    </visual>
    <inertial>
      <origin xyz="0.00044890447620182772313 0.011579403622954374115 -0.024577423538310189111" rpy="0 0 0" />
      <mass value="0.11800003674524907338" />
      <inertia ixx="3.5767957544054136991e-05" ixy="2.2634512003809435198e-08" ixz="6.5708346020219646177e-07" iyy="2.7482298083236969538e-05" iyz="9.2729623433153832641e-07" izz="3.277074248667180182e-05" />
    </inertial>
  </link>

  <link name="spur_1m_24t_drive_3">
    <visual>
      <origin xyz="0 0 0" rpy="0 -0 0" />
      <geometry>
        <mesh filename="../assemblies/left_arm_hand/meshes/left_spur_1m_24t_drive_3_visual.stl" />
      </geometry>
      <material name="spur_1m_24t_drive_3_material">
        <color rgba="0.61568627450980406568 0.81176470588235294379 0.92941176470588238168 1.0" />
      </material>
    </visual>
    <inertial>
      <origin xyz="-7.779691451989063608e-15 -1.2139113751310926949e-16 0.0047949116178401460231" rpy="0 0 0" />
      <mass value="0.0032000000000000001533" />
      <inertia ixx="1.4019331346159887702e-07" ixy="1.6002410021513630837e-15" ixz="1.353024793676005615e-36" iyy="1.4019331260388786185e-07" iyz="-6.353552390351152457e-37" izz="2.3838919844264060647e-07" />
    </inertial>
  </link>

  <joint name="left_wrist_roll_drive" type="revolute">
    <origin xyz="-1.5244091752797395145e-10 0.024000000358059436767 -0.0080000000000068592632" rpy="1.9871762375367660116e-15 -2.337019466836035928e-14 -1.5707963267949176522" />
    <parent link="2xl430_gears_3" />
    <child link="spur_1m_24t_drive_3" />
    <axis xyz="0 0 1" />
    <limit effort="1" velocity="20" lower="-1.570796326794896558" upper="1.570796326794896558" />
    <joint_properties friction="0.0" />
  </joint>

  <link name="hand">
    <visual>
      <origin xyz="0 0 0" rpy="0 -0 0" />
      <geometry>
        <mesh filename="../assemblies/left_arm_hand/meshes/left_hand_visual.stl" />
      </geometry>
      <material name="hand_material">
        <color rgba="0.61568627450980395466 0.81176470588235294379 0.92941176470588238168 1.0" />
      </material>
    </visual>
    <inertial>
      <origin xyz="-4.3038382212365917433e-08 -0.049723778585231935556 -0.017933572005390339271" rpy="0 0 0" />
      <mass value="0.017000000000001441042" />
      <inertia ixx="9.492141461772624154e-06" ixy="-1.5549215897336582142e-11" ixz="-1.0809694196523374989e-11" iyy="4.0745028295199771232e-06" iyz="2.4719408559837110004e-07" izz="6.6623859523002763733e-06" />
    </inertial>
  <collision name="hand_collision"><origin xyz="0.0 -0.03788831038400531 -0.017851115437224507" rpy="0 0 0" /><geometry><box size="0.020999999716877937 0.09677662048488855 0.04629777139052749" /></geometry></collision></link>

  <joint name="left_wrist_pitch" type="revolute">
    <origin xyz="0.019000000000005953099 -3.5808089826616651408e-10 -0.027000000152448959401" rpy="3.3651291228739927188e-14 1.5707963267946487562 0" />
    <parent link="2xl430_gears_3" />
    <child link="hand" />
    <axis xyz="0 0 1" />
    <limit effort="1" velocity="20" lower="-1.570796326794896558" upper="1.570796326794896558" />
    <joint_properties friction="0.0" />
  </joint>

  <link name="wrist_bearing_plate">
    <visual>
      <origin xyz="0 0 0" rpy="0 -0 0" />
      <geometry>
        <mesh filename="../assemblies/left_arm_hand/meshes/left_wrist_bearing_plate_visual.stl" />
      </geometry>
      <material name="wrist_bearing_plate_material">
        <color rgba="0.64496316278892629192 0.69011804996940528945 0.71706771073555886087 1.0" />
      </material>
    </visual>
    <inertial>
      <origin xyz="-0.0075896393545961393645 -0.015499999999999982542 -0.001838611004571836377" rpy="0 0 0" />
      <mass value="0.0049000367468305539714" />
      <inertia ixx="4.9747313520140109893e-07" ixy="3.1440518711942401996e-23" ixz="1.8097509420524730079e-08" iyy="7.1295025627582343196e-07" iyz="7.639371504633119733e-24" izz="1.192629795229190602e-06" />
    </inertial>
  </link>

  <joint name="left_wrist_pitch_fixed" type="fixed">
    <origin xyz="0.015500000000005269979 -1.7125190154843039636e-14 -0.04500000000000015099" rpy="-4.057865155005087888e-14 -2.9093394360302217044e-13 -1.5707963267949061059" />
    <parent link="2xl430_gears_3" />
    <child link="wrist_bearing_plate" />
    <axis xyz="0 0 1" />
    <limit effort="1" velocity="20" />
    <joint_properties friction="0.0" />
  </joint>

  <joint name="left_wrist_roll_driven" type="revolute">
    <origin xyz="-2.7755575615628913511e-17 0 -0.0015999999999999937883" rpy="2.1632341616309662631e-16 -1.4384639448392080473e-27 -1.57079632679489678" />
    <parent link="spur_1m_24t_driven_3" />
    <child link="2xl430_gears_3" />
    <axis xyz="0 0 1" />
    <limit effort="1" velocity="20" lower="-1.570796326794896558" upper="1.570796326794896558" />
    <joint_properties friction="0.0" />
  </joint>

  <joint name="left_wrist_roll_fixed" type="fixed">
    <origin xyz="-3.4694469519536141888e-18 -0.025300000000000003042 -0.051999999999999976796" rpy="1.570796326794896558 -1.570796326794896558 0" />
    <parent link="elb_yaw_link" />
    <child link="spur_1m_24t_driven_3" />
    <axis xyz="0 0 1" />
    <limit effort="1" velocity="20" />
    <joint_properties friction="0.0" />
  </joint>

  <joint name="left_elbow_yaw_fixed" type="fixed">
    <origin xyz="7.8886090522101180541e-31 3.4694469519536141888e-18 0.0015999999999999625633" rpy="3.141592653589793116 6.123233994422830684e-17 -1.57079632679489678" />
    <parent link="spur_1m_24t_driven_2" />
    <child link="elb_yaw_link" />
    <axis xyz="0 0 1" />
    <limit effort="1" velocity="20" />
    <joint_properties friction="0.0" />
  </joint>

  <joint name="left_elbow_yaw_driven" type="revolute">
    <origin xyz="-3.5806929990500613314e-10 -0.027000000152451131274 -0.019000000000003351014" rpy="1.5707963267949591746 1.5707963267948683583 0" />
    <parent link="2xl430_gears_2" />
    <child link="spur_1m_24t_driven_2" />
    <axis xyz="0 0 1" />
    <limit effort="1" velocity="20" lower="-1.570796326794896558" upper="1.570796326794896558" />
    <joint_properties friction="0.0" />
  </joint>

  <joint name="left_elbow_roll" type="revolute">
    <origin xyz="2.185751579730776939e-16 -0.018999999999999329925 -0.058999999999999733213" rpy="1.570796326794896558 -1.3443939455351824662e-14 1.2212453270787430779e-15" />
    <parent link="sho_yaw_link" />
    <child link="2xl430_gears_2" />
    <axis xyz="0 0 1" />
    <limit effort="1" velocity="20" lower="-1.570796326794896558" upper="1.570796326794896558" />
    <joint_properties friction="0.0" />
  </joint>

  <joint name="left_sho_yaw_fixed" type="fixed">
    <origin xyz="1.7347234759768070944e-17 -1.6375789611241112762e-17 0.0015999999999999972577" rpy="-3.1415926535897926719 2.775557561593911827e-16 4.4408920984097454411e-16" />
    <parent link="spur_1m_24t_driven" />
    <child link="sho_yaw_link" />
    <axis xyz="0 0 1" />
    <limit effort="1" velocity="20" />
    <joint_properties friction="0.0" />
  </joint>

  <joint name="left_sho_yaw_driven" type="revolute">
    <origin xyz="-3.5807098258677783065e-10 -0.027000000152450111257 -0.019000000000003021416" rpy="1.5707963267949009989 2.5840015203544507292e-14 -4.9507333169721578628e-15" />
    <parent link="2xl430_gears" />
    <child link="spur_1m_24t_driven" />
    <axis xyz="0 0 1" />
    <limit effort="1" velocity="20" lower="-1.570796326794896558" upper="1.570796326794896558" />
    <joint_properties friction="0.0" />
  </joint>

  <joint name="left_sho_roll" type="revolute">
    <origin xyz="-0.018999999999999947486 0.0010000000000000076102 0.027000000000000003164" rpy="-3.141592653589793116 1.570796326794896558 0" />
    <parent link="sho_pitch_link" />
    <child link="2xl430_gears" />
    <axis xyz="0 0 1" />
    <limit effort="1" velocity="20" lower="-1.570796326794896558" upper="0" />
    <joint_properties friction="0.0" />
  </joint>


  <link name="sho_pitch_link_2">
    <visual>
      <origin xyz="0 0 0" rpy="0 -0 0" />
      <geometry>
        <mesh filename="../assemblies/right_arm_hand/meshes/right_sho_pitch_link_visual.stl" />
      </geometry>
      <material name="sho_pitch_link_material">
        <color rgba="0.61568627450980395466 0.81176470588235294379 0.92941176470588238168 1.0" />
      </material>
    </visual>
    <inertial>
      <origin xyz="5.8254247652798875819e-11 -5.1264642561121521395e-05 0.0082440788127094901533" rpy="0 0 0" />
      <mass value="0.0086000000000000000056" />
      <inertia ixx="1.2272887040545791873e-06" ixy="-2.1429944210231087856e-14" ixz="-8.584719860658140756e-15" iyy="2.9107306060364611617e-06" iyz="7.4623841398183299076e-09" izz="3.0803135950773487693e-06" />
    </inertial>
  </link>

  <link name="2xl430_gears_4">
    <visual>
      <origin xyz="0 0 0" rpy="0 -0 0" />
      <geometry>
        <mesh filename="../assemblies/right_arm_hand/meshes/right_2xl430_gears_visual.stl" />
      </geometry>
      <material name="2xl430_gears_material">
        <color rgba="0.7560598568794409946 0.85804695962693022793 0.91320266199377464478 1.0" />
      </material>
    </visual>
    <inertial>
      <origin xyz="-0.011579403981034819618 -0.002422576614140262586 -0.018551095523804385368" rpy="0 0 0" />
      <mass value="0.11800003674524907338" />
      <inertia ixx="2.7482298083236305464e-05" ixy="9.2729623432947590706e-07" ixz="-2.2634512004125047616e-08" iyy="3.2770742486672947008e-05" iyz="-6.5708346020133704096e-07" izz="3.5767957544054523238e-05" />
    </inertial>
  </link>

  <link name="spur_1m_24t_drive_4">
    <visual>
      <origin xyz="0 0 0" rpy="0 -0 0" />
      <geometry>
        <mesh filename="../assemblies/right_arm_hand/meshes/right_spur_1m_24t_drive_visual.stl" />
      </geometry>
      <material name="spur_1m_24t_drive_material">
        <color rgba="0.61568627450980406568 0.81176470588235294379 0.92941176470588238168 1.0" />
      </material>
    </visual>
    <inertial>
      <origin xyz="-7.7449969824695274661e-15 -1.2113919729783050906e-16 0.0047949116178401442884" rpy="0 0 0" />
      <mass value="0.0032000000000000001533" />
      <inertia ixx="1.4019331346159882408e-07" ixy="1.6002410042112558093e-15" ixz="-3.3725439700307390285e-36" iyy="1.4019331260388791479e-07" iyz="3.7162875711380697641e-37" izz="2.3838919844264071235e-07" />
    </inertial>
  </link>

  <joint name="right_sho_yaw_drive" type="revolute">
    <origin xyz="-0.024000000716138513573 -0.019000000152446919199 -0.019000000152449438018" rpy="1.5707963267949425212 -7.4825707768639476445e-14 5.2729872485629252068e-14" />
    <parent link="2xl430_gears_4" />
    <child link="spur_1m_24t_drive_4" />
    <axis xyz="0 0 1" />
    <limit effort="1" velocity="20" lower="-1.570796326794896558" upper="1.570796326794896558" />
    <joint_properties friction="0.0" />
  </joint>

  <link name="spur_1m_24t_driven_4">
    <visual>
      <origin xyz="0 0 0" rpy="0 -0 0" />
      <geometry>
        <mesh filename="../assemblies/right_arm_hand/meshes/right_spur_1m_24t_driven_visual.stl" />
      </geometry>
      <material name="spur_1m_24t_driven_material">
        <color rgba="0.23137254901960788156 0.38039215686274507888 0.7058823529411765163 1.0" />
      </material>
    </visual>
    <inertial>
      <origin xyz="2.3289816703110487402e-18 -5.7987576959439572715e-15 -0.00096866348640038332785" rpy="0 0 0" />
      <mass value="0.0027000000000000001429" />
      <inertia ixx="1.2026541119643502094e-07" ixy="-5.5663580889415808082e-37" ixz="6.6068929034903528962e-38" iyy="1.2026541119643483565e-07" iyz="-8.7912927549812511121e-37" izz="2.2827257365099366486e-07" />
    </inertial>
  </link>

  <link name="sho_yaw_link_2">
    <visual>
      <origin xyz="0 0 0" rpy="0 -0 0" />
      <geometry>
        <mesh filename="../assemblies/right_arm_hand/meshes/right_sho_yaw_link_visual.stl" />
      </geometry>
      <material name="sho_yaw_link_material">
        <color rgba="0.61568627450980395466 0.81176470588235294379 0.92941176470588238168 1.0" />
      </material>
    </visual>
    <inertial>
      <origin xyz="-1.1573942515719413393e-18 3.9965734479639950703e-18 -0.024214576156328420503" rpy="0 0 0" />
      <mass value="0.014500000000000019817" />
      <inertia ixx="9.0490855102915009419e-06" ixy="3.5997729401550392327e-13" ixz="7.6329854215857035117e-36" iyy="5.6767199180624735964e-06" iyz="-3.9168248734789212003e-35" izz="4.4590603637468159332e-06" />
    </inertial>
  </link>

  <link name="2xl430_gears_5">
    <visual>
      <origin xyz="0 0 0" rpy="0 -0 0" />
      <geometry>
        <mesh filename="../assemblies/right_arm_hand/meshes/right_2xl430_gears_2_visual.stl" />
      </geometry>
      <material name="2xl430_gears_2_material">
        <color rgba="0.7560598568794409946 0.85804695962693022793 0.91320266199377464478 1.0" />
      </material>
    </visual>
    <inertial>
      <origin xyz="-0.011579403981039061017 -0.0024225766141394624448 -0.01855109552380462129" rpy="0 0 0" />
      <mass value="0.11800003674524907338" />
      <inertia ixx="2.7482298083236664606e-05" ixy="9.272962343288520673e-07" ixz="-2.263451200331673003e-08" iyy="3.2770742486673394241e-05" iyz="-6.5708346020123031481e-07" izz="3.5767957544054679092e-05" />
    </inertial>
  </link>

  <link name="spur_1m_24t_drive_5">
    <visual>
      <origin xyz="0 0 0" rpy="0 -0 0" />
      <geometry>
        <mesh filename="../assemblies/right_arm_hand/meshes/right_spur_1m_24t_drive_2_visual.stl" />
      </geometry>
      <material name="spur_1m_24t_drive_2_material">
        <color rgba="0.61568627450980406568 0.81176470588235294379 0.92941176470588238168 1.0" />
      </material>
    </visual>
    <inertial>
      <origin xyz="-7.7519358763734346945e-15 -1.2113919727198111491e-16 0.0047949116178401382168" rpy="0 0 0" />
      <mass value="0.0032000000000000001533" />
      <inertia ixx="1.4019331346159882408e-07" ixy="1.6002410067372217571e-15" ixz="1.6629977555619572844e-37" iyy="1.4019331260388783538e-07" iyz="-5.9003905059354040123e-36" izz="2.3838919844264060647e-07" />
    </inertial>
  </link>

  <joint name="right_elbow_yaw_drive" type="revolute">
    <origin xyz="-0.024000000716145233892 -0.019000000152448695556 -0.019000000152448716373" rpy="1.5707963267950251218 -1.5597582698688193762e-15 -8.7866473173388565758e-14" />
    <parent link="2xl430_gears_5" />
    <child link="spur_1m_24t_drive_5" />
    <axis xyz="0 0 1" />
    <limit effort="1" velocity="20" lower="-1.570796326794896558" upper="1.570796326794896558" />
    <joint_properties friction="0.0" />
  </joint>

  <link name="spur_1m_24t_driven_5">
    <visual>
      <origin xyz="0 0 0" rpy="0 -0 0" />
      <geometry>
        <mesh filename="../assemblies/right_arm_hand/meshes/right_spur_1m_24t_driven_2_visual.stl" />
      </geometry>
      <material name="spur_1m_24t_driven_2_material">
        <color rgba="0.23137254901960788156 0.38039215686274507888 0.7058823529411765163 1.0" />
      </material>
    </visual>
    <inertial>
      <origin xyz="2.3289816703110487402e-18 -5.7987576959439580604e-15 -0.00096866348640039037516" rpy="0 0 0" />
      <mass value="0.0027000000000000001429" />
      <inertia ixx="1.2026541119643502094e-07" ixy="0" ixz="0" iyy="1.2026541119643483565e-07" iyz="-2.0904260807940459177e-37" izz="2.2827257365099366486e-07" />
    </inertial>
  </link>

  <link name="elb_yaw_link_2">
    <visual>
      <origin xyz="0 0 0" rpy="0 -0 0" />
      <geometry>
        <mesh filename="../assemblies/right_arm_hand/meshes/right_elb_yaw_link_visual.stl" />
      </geometry>
      <material name="elb_yaw_link_material">
        <color rgba="0.61568627450980395466 0.81176470588235294379 0.92941176470588227065 1.0" />
      </material>
    </visual>
    <inertial>
      <origin xyz="5.2870889176247967138e-08 0.0019873558182742466494 -0.023365661199828722389" rpy="0 0 0" />
      <mass value="0.017500000000000001665" />
      <inertia ixx="1.4097804991252558057e-05" ixy="1.690080968406779376e-12" ixz="-1.1184673662173783811e-11" iyy="6.6367696417680302023e-06" iyz="1.057990872258833363e-06" izz="8.9601142768980697473e-06" />
    </inertial>
  </link>

  <link name="spur_1m_24t_driven_6">
    <visual>
      <origin xyz="0 0 0" rpy="0 -0 0" />
      <geometry>
        <mesh filename="../assemblies/right_arm_hand/meshes/right_spur_1m_24t_driven_3_visual.stl" />
      </geometry>
      <material name="spur_1m_24t_driven_3_material">
        <color rgba="0.23137254901960788156 0.38039215686274507888 0.7058823529411765163 1.0" />
      </material>
    </visual>
    <inertial>
      <origin xyz="3.008455728593993028e-17 -5.7989934404527921162e-15 -0.0025686634864003805856" rpy="0 0 0" />
      <mass value="0.0027000000000000001429" />
      <inertia ixx="1.2026541119643502094e-07" ixy="2.4642767301845862177e-37" ixz="-2.4880139536911267997e-37" iyy="1.2026541119643483565e-07" iyz="5.0195324597132952237e-37" izz="2.2827257365099366486e-07" />
    </inertial>
  </link>

  <link name="2xl430_gears_6">
    <visual>
      <origin xyz="0 0 0" rpy="0 -0 0" />
      <geometry>
        <mesh filename="../assemblies/right_arm_hand/meshes/right_2xl430_gears_3_visual.stl" />
      </geometry>
      <material name="2xl430_gears_3_material">
        <color rgba="0.7560598568794409946 0.85804695962693022793 0.91320266199377464478 1.0" />
      </material>
    </visual>
    <inertial>
      <origin xyz="0.00044890447620021529766 0.011579403622967155557 -0.024577423538309637469" rpy="0 0 0" />
      <mass value="0.11800003674524907338" />
      <inertia ixx="3.5767957544056075002e-05" ixy="2.2634512003692829202e-08" ixz="6.5708346020097832251e-07" iyy="2.7482298083237132169e-05" iyz="9.2729623433063327171e-07" izz="3.2770742486673109638e-05" />
    </inertial>
  </link>

  <link name="spur_1m_24t_drive_6">
    <visual>
      <origin xyz="0 0 0" rpy="0 -0 0" />
      <geometry>
        <mesh filename="../assemblies/right_arm_hand/meshes/right_spur_1m_24t_drive_3_visual.stl" />
      </geometry>
      <material name="spur_1m_24t_drive_3_material">
        <color rgba="0.61568627450980406568 0.81176470588235294379 0.92941176470588238168 1.0" />
      </material>
    </visual>
    <inertial>
      <origin xyz="-7.724180300757805781e-15 -1.2139113751310946671e-16 0.0047949116178401460231" rpy="0 0 0" />
      <mass value="0.0032000000000000001533" />
      <inertia ixx="1.4019331346159882408e-07" ixy="1.6002410120492237384e-15" ixz="-1.9540791723013512303e-37" iyy="1.4019331260388786185e-07" iyz="7.8971612067142880027e-37" izz="2.3838919844264060647e-07" />
    </inertial>
  </link>

  <joint name="right_wrist_roll_drive" type="revolute">
    <origin xyz="-1.5244304429895549902e-10 0.024000000358071205131 -0.0080000000000011832479" rpy="-2.7654003188110425226e-15 2.9457521138105151042e-15 -1.5707963267949167641" />
    <parent link="2xl430_gears_6" />
    <child link="spur_1m_24t_drive_6" />
    <axis xyz="0 0 1" />
    <limit effort="1" velocity="20" lower="-1.570796326794896558" upper="1.570796326794896558" />
    <joint_properties friction="0.0" />
  </joint>

  <link name="hand_2">
    <visual>
      <origin xyz="0 0 0" rpy="0 -0 0" />
      <geometry>
        <mesh filename="../assemblies/right_arm_hand/meshes/right_hand_visual.stl" />
      </geometry>
      <material name="hand_material">
        <color rgba="0.61568627450980395466 0.81176470588235294379 0.92941176470588238168 1.0" />
      </material>
    </visual>
    <inertial>
      <origin xyz="-4.3038382212365917433e-08 0.049723778585231921678 -0.020066427994609656316" rpy="0 0 0" />
      <mass value="0.017000000000001441042" />
      <inertia ixx="9.492141461772624154e-06" ixy="1.5549215897336585373e-11" ixz="1.0809694196523376605e-11" iyy="4.0745028295199788173e-06" iyz="2.4719408559837120591e-07" izz="6.6623859523002797615e-06" />
    </inertial>
  <collision name="hand_2_collision"><origin xyz="0.0 0.03788831038400531 -0.020148885785602033" rpy="0 0 0" /><geometry><box size="0.020999999716877937 0.09677662048488855 0.04629777115769684" /></geometry></collision></link>

  <joint name="right_wrist_pitch" type="revolute">
    <origin xyz="0.019000000000001918132 -3.5806760334544662783e-10 -0.027000000152449927376" rpy="3.1415926535897029659 -1.5707963267947193664 0" />
    <parent link="2xl430_gears_6" />
    <child link="hand_2" />
    <axis xyz="0 0 1" />
    <limit effort="1" velocity="20" lower="-1.570796326794896558" upper="1.570796326794896558" />
    <joint_properties friction="0.0" />
  </joint>

  <link name="wrist_bearing_plate_2">
    <visual>
      <origin xyz="0 0 0" rpy="0 -0 0" />
      <geometry>
        <mesh filename="../assemblies/right_arm_hand/meshes/right_wrist_bearing_plate_visual.stl" />
      </geometry>
      <material name="wrist_bearing_plate_material">
        <color rgba="0.64496316278892629192 0.69011804996940528945 0.71706771073555886087 1.0" />
      </material>
    </visual>
    <inertial>
      <origin xyz="-0.0075896393545961445687 -0.015499999999999986011 -0.0018386110045718389791" rpy="0 0 0" />
      <mass value="0.0049000367468305539714" />
      <inertia ixx="4.9747313520140131069e-07" ixy="1.0858724720439498592e-22" ixz="1.8097509420524789636e-08" iyy="7.1295025627582205553e-07" iyz="-1.4672026767920951309e-22" izz="1.1926297952291895432e-06" />
    </inertial>
  </link>

  <joint name="right_wrist_pitch_fixed" type="fixed">
    <origin xyz="0.015500000000003956793 4.5519144009631418157e-15 -0.045000000000003870237" rpy="-3.552713678787178252e-15 1.2051470932306258524e-13 -1.570796326794896558" />
    <parent link="2xl430_gears_6" />
    <child link="wrist_bearing_plate_2" />
    <axis xyz="0 0 1" />
    <limit effort="1" velocity="20" />
    <joint_properties friction="0.0" />
  </joint>

  <joint name="right_wrist_roll_driven" type="revolute">
    <origin xyz="2.7755575615628913511e-17 0 -0.0015999999999999972577" rpy="-5.61028737291082927e-15 5.3290705182036772791e-15 1.57079632679489678" />
    <parent link="spur_1m_24t_driven_6" />
    <child link="2xl430_gears_6" />
    <axis xyz="0 0 1" />
    <limit effort="1" velocity="20" lower="-1.570796326794896558" upper="1.570796326794896558" />
    <joint_properties friction="0.0" />
  </joint>

  <joint name="right_wrist_roll_fixed" type="fixed">
    <origin xyz="3.4694469519536141888e-18 -0.025299999999999996103 -0.051999999999999990674" rpy="1.5707963267949205388 1.570796326794896558 0" />
    <parent link="elb_yaw_link_2" />
    <child link="spur_1m_24t_driven_6" />
    <axis xyz="0 0 1" />
    <limit effort="1" velocity="20" />
    <joint_properties friction="0.0" />
  </joint>

  <joint name="right_elbow_yaw_fixed" type="fixed">
    <origin xyz="-3.4694469519536141888e-18 -1.5777218104420236108e-30 0.0015999999999999764411" rpy="-3.1415926535897891192 -8.3149610451184695905e-31 2.7073084493379207714e-30" />
    <parent link="spur_1m_24t_driven_5" />
    <child link="elb_yaw_link_2" />
    <axis xyz="0 0 1" />
    <limit effort="1" velocity="20" />
    <joint_properties friction="0.0" />
  </joint>

  <joint name="right_elbow_yaw_driven" type="revolute">
    <origin xyz="-3.5807111442576200488e-10 -0.027000000152451464341 -0.019000000000003632039" rpy="1.570796326794921427 1.0192981807050532901e-13 -4.32129208184743122e-14" />
    <parent link="2xl430_gears_5" />
    <child link="spur_1m_24t_driven_5" />
    <axis xyz="0 0 1" />
    <limit effort="1" velocity="20" lower="-1.570796326794896558" upper="1.570796326794896558" />
    <joint_properties friction="0.0" />
  </joint>

  <joint name="right_elbow_roll" type="revolute">
    <origin xyz="-2.2898349882893853646e-16 -0.019000000000000173001 -0.058999999999999837297" rpy="1.57079632679489678 -1.1224323958578838097e-14 -5.9062164171655744588e-15" />
    <parent link="sho_yaw_link_2" />
    <child link="2xl430_gears_5" />
    <axis xyz="0 0 1" />
    <limit effort="1" velocity="20" lower="-1.570796326794896558" upper="1.570796326794896558" />
    <joint_properties friction="0.0" />
  </joint>

  <joint name="right_sho_yaw_fixed" type="fixed">
    <origin xyz="3.4694469519536141888e-18 0 0.0016000000000000076661" rpy="-3.1415926535897917837 7.3983136435179850071e-16 1.4710455076273652726e-15" />
    <parent link="spur_1m_24t_driven_4" />
    <child link="sho_yaw_link_2" />
    <axis xyz="0 0 1" />
    <limit effort="1" velocity="20" />
    <joint_properties friction="0.0" />
  </joint>

  <joint name="right_sho_yaw_driven" type="revolute">
    <origin xyz="-3.5806675333094339919e-10 -0.027000000152447987956 -0.019000000000004509809" rpy="1.5707963267949396347 -3.4289578266172945506e-14 -6.6930782579143983011e-15" />
    <parent link="2xl430_gears_4" />
    <child link="spur_1m_24t_driven_4" />
    <axis xyz="0 0 1" />
    <limit effort="1" velocity="20" lower="-1.570796326794896558" upper="1.570796326794896558" />
    <joint_properties friction="0.0" />
  </joint>

  <joint name="right_sho_roll" type="revolute">
    <origin xyz="-0.01899999999999998565 0.0010000000000000112965 0.027000000000000013572" rpy="3.141592653589793116 1.570796326794896558 0" />
    <parent link="sho_pitch_link_2" />
    <child link="2xl430_gears_4" />
    <axis xyz="0 0 1" />
    <limit effort="1" velocity="20" lower="-1.570796326794896558" upper="0" />
    <joint_properties friction="0.0" />
  </joint>


</robot>