<robot name="base_legs">  
  <mujoco><compiler strippath="false" balanceinertia="true" discardvisual="false" /></mujoco><link name="base_link" />  
  <joint name="base_link_to_base" type="fixed">    
    <parent link="base_link" />    
    <child link="hip_link" />    
    <origin rpy="0.0 0 0" xyz="0 0 0" />    
  </joint>  
  <link name="hip_link">    
    <visual>      
      <origin xyz="0 0 0" rpy="0 -0 0" />      
      <geometry>        
        <mesh filename="../assemblies/no_body/meshes/hip_link_visual.stl" />        
      </geometry>      
      <material name="hip_link_material">        
        <color rgba="0.60265235106909242901 0.7475818661971369572 0.82292492068132760963 1.0" />        
      </material>      
    </visual>    
    <collision>      
      <origin xyz="0 0 0" rpy="0 -0 0" />      
      <geometry>        
        <mesh filename="../assemblies/no_body/meshes/hip_link_collision.stl" />        
      </geometry>      
    </collision>    
    <inertial>      
      <origin xyz="-0.014403523331510960717 -0.00023164401215090829741 0.31153288519557342795" rpy="0 0 0" />      
      <mass value="0.1326329205818372603" />      
      <inertia ixx="0.00012163093315384157793" ixy="1.4038303149150794108e-07" ixz="1.0872278951927060253e-05" iyy="8.4970137932106120315e-05" iyz="3.874082128923384354e-07" izz="0.00015647103471607424" />      
    </inertial>    
  </link>  

  <joint name="left_hip_yaw" type="revolute">    
    <origin xyz="-0.0063999999999966028508 0.033999999999999308553 0.28550000000000008704" rpy="1.2173498077216098975e-16 -2.7428229896967586736e-14 -8.3846071870935304412e-14" />    
    <parent link="hip_link" />    
    <child link="hip_yaw_link" />    
    <axis xyz="0 0 1" />    
    <limit effort="1" velocity="20" lower="-1.570796326794896558" upper="1.570796326794896558" />    
    <joint_properties friction="0.0" />    
  </joint>  

  <joint name="right_hip_yaw" type="revolute">    
    <origin xyz="-0.006399999999996792803 -0.034000000000000661637 0.28549999999999997602" rpy="1.2173498094410956825e-16 -2.7428229798067236768e-14 -5.0714987764877150767e-13" />    
    <parent link="hip_link" />    
    <child link="hip_yaw_link_2" />    
    <axis xyz="0 0 1" />    
    <limit effort="1" velocity="20" lower="-1.570796326794896558" upper="1.570796326794896558" />    
    <joint_properties friction="0.0" />    
  </joint>  


<link name="hip_yaw_link">    
    <visual>      
      <origin xyz="0 0 0" rpy="0 -0 0" />      
      <geometry>        
        <mesh filename="../assemblies/left_3R+RH5_leg/meshes/left_hip_yaw_link_visual.stl" />        
      </geometry>      
      <material name="hip_yaw_link_material">        
        <color rgba="0.61568627450980395466 0.81176470588235294379 0.9294117647058824927 1.0" />        
      </material>      
    </visual>    
    <collision>      
      <origin xyz="0 0 0" rpy="0 -0 0" />      
      <geometry>        
        <mesh filename="../assemblies/left_3R+RH5_leg/meshes/left_hip_yaw_link_collision.stl" />        
      </geometry>      
    </collision>    
    <inertial>      
      <origin xyz="2.1765780897682922701e-19 -3.0328722397683591057e-19 -0.0098390489054830127663" rpy="0 0 0" />      
      <mass value="0.009025883737097921064" />      
      <inertia ixx="1.3230458239086469384e-06" ixy="-3.3592249637948231893e-24" ixz="-1.1251788840973428727e-52" iyy="3.8408510960331422723e-06" iyz="2.3044956050358332095e-34" izz="3.8721396285793916291e-06" />      
    </inertial>    
  </link>  

  <link name="hip_roll_link">    
    <visual>      
      <origin xyz="0 0 0" rpy="0 -0 0" />      
      <geometry>        
        <mesh filename="../assemblies/left_3R+RH5_leg/meshes/left_hip_roll_link_visual.stl" />        
      </geometry>      
      <material name="hip_roll_link_material">        
        <color rgba="0.95018735644455865064 0.70678927200428420807 0.061612079402596699185 1.0" />        
      </material>      
    </visual>    
    <collision>      
      <origin xyz="0 0 0" rpy="0 -0 0" />      
      <geometry>        
        <mesh filename="../assemblies/left_3R+RH5_leg/meshes/left_hip_roll_link_collision.stl" />        
      </geometry>      
    </collision>    
    <inertial>      
      <origin xyz="-0.012000151133960529001 -0.00049588831385038078994 -0.018504019244504718578" rpy="0 0 0" />      
      <mass value="0.098012391483528679692" />      
      <inertia ixx="2.0221748766306297228e-05" ixy="-4.155206824409763275e-08" ixz="-4.1225592188059826934e-08" iyy="2.7358099958307017163e-05" iyz="-5.0935731752381958541e-07" izz="2.7358069524722873844e-05" />      
    </inertial>    
  </link>  

  <link name="left_hip_pitch_link">    
    <visual>      
      <origin xyz="0 0 0" rpy="0 -0 0" />      
      <geometry>        
        <mesh filename="../assemblies/left_3R+RH5_leg/meshes/left_hip_pitch_link_visual.stl" />        
      </geometry>      
      <material name="left_hip_pitch_link_material">        
        <color rgba="0.61653630588246988165 0.80730204117585691037 0.92176148235188926083 1.0" />        
      </material>      
    </visual>    
    <collision>      
      <origin xyz="0 0 0" rpy="0 -0 0" />      
      <geometry>        
        <mesh filename="../assemblies/left_3R+RH5_leg/meshes/left_hip_pitch_link_collision.stl" />        
      </geometry>      
    </collision>    
    <inertial>      
      <origin xyz="-0.00021632240618343800596 0.05298669563382005232 0.014788126099014510528" rpy="0 0 0" />      
      <mass value="0.094084588454108858402" />      
      <inertia ixx="6.3099190805816147737e-05" ixy="4.2254461504123312299e-07" ixz="-1.522356827537095822e-07" iyy="2.175478276519306561e-05" iyz="-1.4708367336520509537e-06" izz="6.2817482611037618514e-05" />      
    </inertial>    
  </link>  

  <link name="left_calf_link">    
    <visual>      
      <origin xyz="0 0 0" rpy="0 -0 0" />      
      <geometry>        
        <mesh filename="../assemblies/left_3R+RH5_leg/meshes/left_calf_link_visual.stl" />        
      </geometry>      
      <material name="left_calf_link_material">        
        <color rgba="0.55182138457441176627 0.7293668709690939167 0.87615813098181827279 1.0" />        
      </material>      
    </visual>    
    <collision>      
      <origin xyz="0 0 0" rpy="0 -0 0" />      
      <geometry>        
        <mesh filename="../assemblies/left_3R+RH5_leg/meshes/left_calf_link_collision.stl" />        
      </geometry>      
    </collision>    
    <inertial>      
      <origin xyz="-0.0038784319950641772158 -0.043110203474640479415 0.0081688997794044371226" rpy="0 0 0" />      
      <mass value="0.016616268752102307527" />      
      <inertia ixx="1.5958212392253871874e-05" ixy="-2.2918088445891357882e-07" ixz="5.9921361723211755557e-09" iyy="2.0657945480054530971e-06" iyz="2.8475122223882442474e-08" izz="1.5100754419726929867e-05" />      
    </inertial>    
  </link>  

  <link name="ank_pitch_link">    
    <visual>      
      <origin xyz="0 0 0" rpy="0 -0 0" />      
      <geometry>        
        <mesh filename="../assemblies/left_3R+RH5_leg/meshes/left_ank_pitch_link_visual.stl" />        
      </geometry>      
      <material name="ank_pitch_link_material">        
        <color rgba="0.63189161126160275916 0.72668668793540891482 0.78356373393969258601 1.0" />        
      </material>      
    </visual>    
    <collision>      
      <origin xyz="0 0 0" rpy="0 -0 0" />      
      <geometry>        
        <mesh filename="../assemblies/left_3R+RH5_leg/meshes/left_ank_pitch_link_collision.stl" />        
      </geometry>      
    </collision>    
    <inertial>      
      <origin xyz="4.0269684929069584861e-08 0.00059528282566768985547 -0.014599922383890568192" rpy="0 0 0" />      
      <mass value="0.0042238381753791605713" />      
      <inertia ixx="4.3705254067379640737e-07" ixy="1.6834346505531153752e-13" ixz="1.6428822287382073422e-12" iyy="3.9782741364642028303e-07" iyz="2.0919268318526515044e-14" izz="8.8858574534542963275e-08" />      
    </inertial>    
  </link>  

  <link name="ank_roll_link">    
    <visual>      
      <origin xyz="0 0 0" rpy="0 -0 0" />      
      <geometry>        
        <mesh filename="../assemblies/left_3R+RH5_leg/meshes/left_ank_roll_link_visual.stl" />        
      </geometry>      
      <material name="ank_roll_link_material">        
        <color rgba="0.61568627450980384364 0.81176470588235294379 0.92941176470588227065 1.0" />        
      </material>      
    </visual>    
    <collision>      
      <origin xyz="0 0 0" rpy="0 -0 0" />      
      <geometry>        
        <mesh filename="../assemblies/left_3R+RH5_leg/meshes/left_ank_roll_link_collision.stl" />        
      </geometry>      
    </collision>    
    <inertial>      
      <origin xyz="-6.3661537535998279249e-10 0.027240102316353730083 0.0019830147448535394815" rpy="0 0 0" />      
      <mass value="0.013844478784760253648" />      
      <inertia ixx="1.0150902309234944378e-05" ixy="6.8603302689878896666e-14" ixz="-3.2605547316567735187e-13" iyy="8.6636116663431534963e-06" iyz="-7.815177892654500666e-07" izz="2.8991570356470414996e-06" />      
    </inertial>    
  </link>  

  <link name="ank_rr_link">    
    <visual>      
      <origin xyz="0 0 0" rpy="0 -0 0" />      
      <geometry>        
        <mesh filename="../assemblies/left_3R+RH5_leg/meshes/left_ank_rr_link_visual.stl" />        
      </geometry>      
      <material name="ank_rr_link_material">        
        <color rgba="0.61568627450980395466 0.81176470588235294379 0.92941176470588238168 1.0" />        
      </material>      
    </visual>    
    <collision>      
      <origin xyz="0 0 0" rpy="0 -0 0" />      
      <geometry>        
        <mesh filename="../assemblies/left_3R+RH5_leg/meshes/left_ank_rr_link_collision.stl" />        
      </geometry>      
    </collision>    
    <inertial>      
      <origin xyz="3.4593503690060755664e-05 0.0062999445222072132655 -0.0018999999999999991288" rpy="0 0 0" />      
      <mass value="0.00044289790445047673732" />      
      <inertia ixx="9.0894755004835256766e-09" ixy="-5.6689994077039475986e-11" ixz="1.0879024115038849694e-14" iyy="8.3785129146959922129e-09" iyz="5.7549739868033255497e-29" izz="1.3107013728801484857e-08" />      
    </inertial>    
  </link>  

  <link name="12lf_rod_end">    
    <visual>      
      <origin xyz="0 0 0" rpy="0 -0 0" />      
      <geometry>        
        <mesh filename="../assemblies/left_3R+RH5_leg/meshes/left_12lf_rod_end_visual.stl" />        
      </geometry>      
      <material name="12lf_rod_end_material">        
        <color rgba="0.92771758928836534075 0.61049283053223002415 0.2184765849058516729 1.0" />        
      </material>      
    </visual>    
    <collision>      
      <origin xyz="0 0 0" rpy="0 -0 0" />      
      <geometry>        
        <mesh filename="../assemblies/left_3R+RH5_leg/meshes/left_12lf_rod_end_collision.stl" />        
      </geometry>      
    </collision>    
    <inertial>      
      <origin xyz="-4.4735198444399687738e-11 0.0038422185938245725229 -0.0020064384187209456482" rpy="0 0 0" />      
      <mass value="0.00085420491177815905965" />      
      <inertia ixx="1.1840985264406780776e-08" ixy="-2.0225978076946872923e-16" ixz="9.2606420200687332253e-16" iyy="3.3549621576797160603e-09" iyz="7.4535631381834222285e-12" izz="1.270352225441995511e-08" />      
    </inertial>    
  </link>  

  <joint name="left_ank_R21" type="revolute">    
    <origin xyz="0.0021000000000000115796 0.010000000000000064393 -0.0018999999999999919731" rpy="-1.570796326794896558 1.4273561685593663118 -1.5707963267949194286" />    
    <parent link="ank_rr_link" />    
    <child link="12lf_rod_end" />    
    <axis xyz="0 0 1" />    
    <limit effort="1" velocity="20" lower="-1.570796326794896558" upper="1.570796326794896558" />    
    <joint_properties friction="0.0" />    
  </joint>  

  <joint name="left_ank_R11" type="revolute">    
    <origin xyz="-0.010000000000000000208 0.012499999999999955591 -0.028000000000000004052" rpy="3.1415926535897775729 -1.1742161333363301013e-15 -0.10225158937860563679" />    
    <parent link="ank_roll_link" />    
    <child link="ank_rr_link" />    
    <axis xyz="0 0 1" />    
    <limit effort="1" velocity="20" lower="-1.570796326794896558" upper="1.570796326794896558" />    
    <joint_properties friction="0.0" />    
  </joint>  

  <link name="ank_rr_link_2">    
    <visual>      
      <origin xyz="0 0 0" rpy="0 -0 0" />      
      <geometry>        
        <mesh filename="../assemblies/left_3R+RH5_leg/meshes/left_ank_rr_link_2_visual.stl" />        
      </geometry>      
      <material name="ank_rr_link_2_material">        
        <color rgba="0.61568627450980395466 0.81176470588235294379 0.92941176470588238168 1.0" />        
      </material>      
    </visual>    
    <collision>      
      <origin xyz="0 0 0" rpy="0 -0 0" />      
      <geometry>        
        <mesh filename="../assemblies/left_3R+RH5_leg/meshes/left_ank_rr_link_2_collision.stl" />        
      </geometry>      
    </collision>    
    <inertial>      
      <origin xyz="3.4593503690053823546e-05 -0.0062999445222071577544 -0.0018999999999999986951" rpy="0 0 0" />      
      <mass value="0.00044289790445047673732" />      
      <inertia ixx="9.0894755004835256766e-09" ixy="5.6689994077039411362e-11" ixz="-1.0879024115038856004e-14" iyy="8.3785129146959922129e-09" iyz="2.4982057073096613675e-28" izz="1.3107013728801484857e-08" />      
    </inertial>    
  </link>  

  <link name="12lf_rod_end_2">    
    <visual>      
      <origin xyz="0 0 0" rpy="0 -0 0" />      
      <geometry>        
        <mesh filename="../assemblies/left_3R+RH5_leg/meshes/left_12lf_rod_end_2_visual.stl" />        
      </geometry>      
      <material name="12lf_rod_end_2_material">        
        <color rgba="0.92771758928836534075 0.61049283053223002415 0.2184765849058516729 1.0" />        
      </material>      
    </visual>    
    <collision>      
      <origin xyz="0 0 0" rpy="0 -0 0" />      
      <geometry>        
        <mesh filename="../assemblies/left_3R+RH5_leg/meshes/left_12lf_rod_end_2_collision.stl" />        
      </geometry>      
    </collision>    
    <inertial>      
      <origin xyz="-4.4735192961477846129e-11 0.003842218593824546502 -0.0020064384187209404441" rpy="0 0 0" />      
      <mass value="0.00085420491177815905965" />      
      <inertia ixx="1.1840985264406790703e-08" ixy="-2.0225977795415407403e-16" ixz="9.260641996031530076e-16" iyy="3.3549621576797297088e-09" iyz="7.4535631381853431616e-12" izz="1.2703522254419979925e-08" />      
    </inertial>    
  </link>  

  <joint name="left_ank_R22" type="revolute">    
    <origin xyz="0.0021000000000000115796 -0.010000000000000092149 -0.001899999999999929523" rpy="-1.5707963267948974462 -1.4273357206756709381 -1.5707963267949238695" />    
    <parent link="ank_rr_link_2" />    
    <child link="12lf_rod_end_2" />    
    <axis xyz="0 0 1" />    
    <limit effort="1" velocity="20" lower="-1.570796326794896558" upper="1.570796326794896558" />    
    <joint_properties friction="0.0" />    
  </joint>  

  <joint name="left_ank_R12" type="revolute">    
    <origin xyz="0.010000000000000001943 0.01249999999999990008 -0.027999999999999948541" rpy="3.1415926535897895633 4.4319359555376638558e-15 -3.0396078498296592585" />    
    <parent link="ank_roll_link" />    
    <child link="ank_rr_link_2" />    
    <axis xyz="0 0 1" />    
    <limit effort="1" velocity="20" lower="-1.570796326794896558" upper="1.570796326794896558" />    
    <joint_properties friction="0.0" />    
  </joint>  

  <joint name="left_ank_roll" type="revolute">    
    <origin xyz="3.3306690738754696213e-16 -0.0060999999999999726316 -0.014599999999999384304" rpy="-1.5707963257530275225 -1.5707136234809810915 -1.1504969698363094907e-09" />    
    <parent link="ank_pitch_link" />    
    <child link="ank_roll_link" />    
    <axis xyz="0 0 1" />    
    <limit effort="1" velocity="20" lower="-1.570796326794896558" upper="1.570796326794896558" />    
    <joint_properties friction="0.0" />    
  </joint>  

  <joint name="left_ank_pitch" type="revolute">    
    <origin xyz="1.6466858937503582328e-18 -0.099999999999999922284 -0.0062000000000000058537" rpy="-3.1415926535897842342 8.6597368124280298137e-15 -1.5709041950953850364" />    
    <parent link="left_calf_link" />    
    <child link="ank_pitch_link" />    
    <axis xyz="0 0 1" />    
    <limit effort="1" velocity="20" lower="-1.570796326794896558" upper="1.570796326794896558" />    
    <joint_properties friction="0.0" />    
  </joint>  

  <link name="ball_joint_container">    
    <visual>      
      <origin xyz="0 0 0" rpy="0 -0 0" />      
      <geometry>        
        <mesh filename="../assemblies/left_3R+RH5_leg/meshes/left_ball_joint_container_visual.stl" />        
      </geometry>      
      <material name="ball_joint_container_material">        
        <color rgba="0.61568627450980395466 0.81176470588235294379 0.92941176470588238168 1.0" />        
      </material>      
    </visual>    
    <collision>      
      <origin xyz="0 0 0" rpy="0 -0 0" />      
      <geometry>        
        <mesh filename="../assemblies/left_3R+RH5_leg/meshes/left_ball_joint_container_collision.stl" />        
      </geometry>      
    </collision>    
    <inertial>      
      <origin xyz="4.7221442975711842021e-19 -2.7877151006475838412e-17 -0.0097125341669083431473" rpy="0 0 0" />      
      <mass value="4.803735642533054869e-05" />      
      <inertia ixx="7.1865480628741666366e-10" ixy="-6.0207057396674474217e-27" ixz="-3.6117886961646768703e-40" iyy="8.475420427718555978e-10" iyz="1.5456803177358075357e-40" izz="1.8625314111651911712e-10" />      
    </inertial>    
  </link>  

  <link name="ball_joint_ball">    
    <visual>      
      <origin xyz="0 0 0" rpy="0 -0 0" />      
      <geometry>        
        <mesh filename="../assemblies/left_3R+RH5_leg/meshes/left_ball_joint_ball_visual.stl" />        
      </geometry>      
      <material name="ball_joint_ball_material">        
        <color rgba="0.3291302810242056065 0.44310466418644928188 0.69204871161977121741 1.0" />        
      </material>      
    </visual>    
    <collision>      
      <origin xyz="0 0 0" rpy="0 -0 0" />      
      <geometry>        
        <mesh filename="../assemblies/left_3R+RH5_leg/meshes/left_ball_joint_ball_collision.stl" />        
      </geometry>      
    </collision>    
    <inertial>      
      <origin xyz="-3.5973432739897649026e-17 -0.001030866981001612049 6.9901040024660753426e-18" rpy="0 0 0" />      
      <mass value="4.4053796295264630609e-05" />      
      <inertia ixx="3.1285011349692515165e-10" ixy="1.3601915226098823077e-25" ixz="1.2288975035430886355e-24" iyy="6.2569568612794299732e-11" iyz="-1.4378762277075310265e-24" izz="3.1285321460375278775e-10" />      
    </inertial>    
  </link>  

  <link name="12lf">    
    <visual>      
      <origin xyz="0 0 0" rpy="0 -0 0" />      
      <geometry>        
        <mesh filename="../assemblies/left_3R+RH5_leg/meshes/left_12lf_visual.stl" />        
      </geometry>      
      <material name="12lf_material">        
        <color rgba="0.62004392100736027693 0.58836684613512635345 0.49897069021535678246 1.0" />        
      </material>      
    </visual>    
    <collision>      
      <origin xyz="0 0 0" rpy="0 -0 0" />      
      <geometry>        
        <mesh filename="../assemblies/left_3R+RH5_leg/meshes/left_12lf_collision.stl" />        
      </geometry>      
    </collision>    
    <inertial>      
      <origin xyz="0.004908420724374793799 -0.00013802439943545955349 -0.029947003577161294269" rpy="0 0 0" />      
      <mass value="0.044782197696050352054" />      
      <inertia ixx="1.5260128421323230618e-05" ixy="2.2955773687024549985e-08" ixz="-8.1364204003969909788e-08" iyy="1.8188469778964206258e-05" iyz="-5.5542240843072458484e-08" izz="5.1496273901760196315e-06" />      
    </inertial>    
  </link>  

  <link name="12lf_rod">    
    <visual>      
      <origin xyz="0 0 0" rpy="0 -0 0" />      
      <geometry>        
        <mesh filename="../assemblies/left_3R+RH5_leg/meshes/left_12lf_rod_visual.stl" />        
      </geometry>      
      <material name="12lf_rod_material">        
        <color rgba="0.80250260812861884396 0.89340612183512713163 0.94491811293548189088 1.0" />        
      </material>      
    </visual>    
    <collision>      
      <origin xyz="0 0 0" rpy="0 -0 0" />      
      <geometry>        
        <mesh filename="../assemblies/left_3R+RH5_leg/meshes/left_12lf_rod_collision.stl" />        
      </geometry>      
    </collision>    
    <inertial>      
      <origin xyz="-6.3222084039961718332e-07 4.6933255300422815462e-07 -0.012893387334328536287" rpy="0 0 0" />      
      <mass value="0.0025088292483592140175" />      
      <inertia ixx="2.6944521128622790391e-07" ixy="7.1389570481770876814e-15" ixz="1.3562243134290258889e-11" iyy="2.6944520001679345975e-07" iyz="-1.0089988419986836156e-11" izz="1.7809843599861032107e-08" />      
    </inertial>    
  </link>  

  <joint name="left_ank_act1" type="prismatic">    
    <origin xyz="2.272209354975407436e-06 9.4368957093138305936e-16 -0.072676675805820711851" rpy="-3.1415926535896590011 9.257153768608790258e-14 -2.2021168238262611716" />    
    <parent link="12lf" />    
    <child link="12lf_rod" />    
    <axis xyz="0 0 1" />    
    <limit effort="1" velocity="20" lower="0" upper="0.040000000000000000833" />    
    <joint_properties friction="0.0" />    
  </joint>  

  <joint name="left_ank_B31" type="revolute">    
    <origin xyz="-1.4831885719601700657e-16 -0.0064387505004003253717 -6.9388939039072283776e-18" rpy="-1.570796326794896558 0.16912328473440299548 -4.2800865129067981483e-15" />    
    <parent link="ball_joint_ball" />    
    <child link="12lf" />    
    <axis xyz="0 0 1" />    
    <limit effort="1" velocity="20" lower="-0.785398163397448279" upper="0.785398163397448279" />    
    <joint_properties friction="0.0" />    
  </joint>  

  <joint name="left_ank_B21" type="revolute">    
    <origin xyz="6.9388939039072283776e-18 -2.7755575615628913511e-17 -0.011499999999999994602" rpy="1.57079632679489678 -1.4274634743672511838 1.570796326794916542" />    
    <parent link="ball_joint_container" />    
    <child link="ball_joint_ball" />    
    <axis xyz="0 0 1" />    
    <limit effort="1" velocity="20" lower="-0.785398163397448279" upper="0.785398163397448279" />    
    <joint_properties friction="0.0" />    
  </joint>  

  <joint name="left_ank_B11" type="revolute">    
    <origin xyz="0.0079999999999999966971 -0.015000000000000179856 0.028300000000000005707" rpy="-1.570796326794896558 1.4686290291020840382 1.5707963267948819031" />    
    <parent link="left_calf_link" />    
    <child link="ball_joint_container" />    
    <axis xyz="0 0 1" />    
    <limit effort="1" velocity="20" lower="-0.785398163397448279" upper="0.785398163397448279" />    
    <joint_properties friction="0.0" />    
  </joint>  

  <link name="ball_joint_container_2">    
    <visual>      
      <origin xyz="0 0 0" rpy="0 -0 0" />      
      <geometry>        
        <mesh filename="../assemblies/left_3R+RH5_leg/meshes/left_ball_joint_container_2_visual.stl" />        
      </geometry>      
      <material name="ball_joint_container_2_material">        
        <color rgba="0.61568627450980395466 0.81176470588235294379 0.92941176470588238168 1.0" />        
      </material>      
    </visual>    
    <collision>      
      <origin xyz="0 0 0" rpy="0 -0 0" />      
      <geometry>        
        <mesh filename="../assemblies/left_3R+RH5_leg/meshes/left_ball_joint_container_2_collision.stl" />        
      </geometry>      
    </collision>    
    <inertial>      
      <origin xyz="-6.4666794741501425057e-18 2.7634000224781994773e-17 -0.0097125341669083396778" rpy="0 0 0" />      
      <mass value="4.803735642533054869e-05" />      
      <inertia ixx="7.1865480628741666366e-10" ixy="7.1873734671859270535e-27" ixz="-7.401630654583883802e-39" iyy="8.475420427718555978e-10" iyz="4.6127798413306209879e-39" izz="1.8625314111651911712e-10" />      
    </inertial>    
  </link>  

  <link name="ball_joint_ball_2">    
    <visual>      
      <origin xyz="0 0 0" rpy="0 -0 0" />      
      <geometry>        
        <mesh filename="../assemblies/left_3R+RH5_leg/meshes/left_ball_joint_ball_2_visual.stl" />        
      </geometry>      
      <material name="ball_joint_ball_2_material">        
        <color rgba="0.3291302810242056065 0.44310466418644928188 0.69204871161977121741 1.0" />        
      </material>      
    </visual>    
    <collision>      
      <origin xyz="0 0 0" rpy="0 -0 0" />      
      <geometry>        
        <mesh filename="../assemblies/left_3R+RH5_leg/meshes/left_ball_joint_ball_2_collision.stl" />        
      </geometry>      
    </collision>    
    <inertial>      
      <origin xyz="-3.0448107095876113925e-18 -0.0010308669810015864618 2.0487703651502786928e-20" rpy="0 0 0" />      
      <mass value="4.4053796295264630609e-05" />      
      <inertia ixx="3.1285011349692101574e-10" ixy="3.5720905595371722737e-26" ixz="-5.5052111336016936798e-26" iyy="6.2569568612794868418e-11" iyz="3.2028151965658579899e-25" izz="3.1285321460376007728e-10" />      
    </inertial>    
  </link>  

  <link name="12lf_2">    
    <visual>      
      <origin xyz="0 0 0" rpy="0 -0 0" />      
      <geometry>        
        <mesh filename="../assemblies/left_3R+RH5_leg/meshes/left_12lf_2_visual.stl" />        
      </geometry>      
      <material name="12lf_2_material">        
        <color rgba="0.62004392100736005489 0.58836684613512635345 0.49897069021535678246 1.0" />        
      </material>      
    </visual>    
    <collision>      
      <origin xyz="0 0 0" rpy="0 -0 0" />      
      <geometry>        
        <mesh filename="../assemblies/left_3R+RH5_leg/meshes/left_12lf_2_collision.stl" />        
      </geometry>      
    </collision>    
    <inertial>      
      <origin xyz="0.0049084207243678019961 -0.0001380243994376417001 -0.029947003577159750365" rpy="0 0 0" />      
      <mass value="0.044782197696050352054" />      
      <inertia ixx="1.5260128421322251448e-05" ixy="2.2955773686925572862e-08" ixz="-8.1364204006926332707e-08" iyy="1.8188469778964612834e-05" iyz="-5.5542240844197318238e-08" izz="5.1496273901774528112e-06" />      
    </inertial>    
  </link>  

  <link name="12lf_rod_2">    
    <visual>      
      <origin xyz="0 0 0" rpy="0 -0 0" />      
      <geometry>        
        <mesh filename="../assemblies/left_3R+RH5_leg/meshes/left_12lf_rod_2_visual.stl" />        
      </geometry>      
      <material name="12lf_rod_2_material">        
        <color rgba="0.80250260812861884396 0.89340612183512713163 0.94491811293548189088 1.0" />        
      </material>      
    </visual>    
    <collision>      
      <origin xyz="0 0 0" rpy="0 -0 0" />      
      <geometry>        
        <mesh filename="../assemblies/left_3R+RH5_leg/meshes/left_12lf_rod_2_collision.stl" />        
      </geometry>      
    </collision>    
    <inertial>      
      <origin xyz="-6.3222083694362979666e-07 4.6933255239607247453e-07 -0.012893387334329486915" rpy="0 0 0" />      
      <mass value="0.0025088292483592140175" />      
      <inertia ixx="2.6944521128617687018e-07" ixy="7.1389570166472134457e-15" ixz="1.3562243032819284517e-11" iyy="2.6944520001674232014e-07" iyz="-1.008998840238269435e-11" izz="1.7809843599861002329e-08" />      
    </inertial>    
  </link>  

  <joint name="left_ank_act2" type="prismatic">    
    <origin xyz="2.2722093495249062745e-06 -6.7446048745978259831e-15 -0.072678522047017385388" rpy="-3.1415926535895004612 6.2111251208581937571e-14 -2.2021168238262802674" />    
    <parent link="12lf_2" />    
    <child link="12lf_rod_2" />    
    <axis xyz="0 0 1" />    
    <limit effort="1" velocity="20" lower="0" upper="0.040000000000000000833" />    
    <joint_properties friction="0.0" />    
  </joint>  

  <joint name="left_ank_B32" type="revolute">    
    <origin xyz="1.7347234759768070944e-17 -0.0064387505004004641496 1.3877787807814456755e-17" rpy="-1.5707963267948836794 -0.17992034540981183266 -3.9922693705457534994e-15" />    
    <parent link="ball_joint_ball_2" />    
    <child link="12lf_2" />    
    <axis xyz="0 0 1" />    
    <limit effort="1" velocity="20" lower="-0.785398163397448279" upper="0.785398163397448279" />    
    <joint_properties friction="0.0" />    
  </joint>  

  <joint name="left_ank_B22" type="revolute">    
    <origin xyz="-1.3877787807814456755e-17 8.3266726846886740532e-17 -0.011500000000000011949" rpy="1.570796326794896558 -1.4274430275990750427 -1.570796326794906328" />    
    <parent link="ball_joint_container_2" />    
    <child link="ball_joint_ball_2" />    
    <axis xyz="0 0 1" />    
    <limit effort="1" velocity="20" lower="-0.785398163397448279" upper="0.785398163397448279" />    
    <joint_properties friction="0.0" />    
  </joint>  

  <joint name="left_ank_B12" type="revolute">    
    <origin xyz="0.008000000000000003636 -0.015000000000000124345 -0.01149999999999918622" rpy="-1.570796326794896558 -1.4687304067506412597 1.5707963267949098807" />    
    <parent link="left_calf_link" />    
    <child link="ball_joint_container_2" />    
    <axis xyz="0 0 1" />    
    <limit effort="1" velocity="20" lower="-0.785398163397448279" upper="0.785398163397448279" />    
    <joint_properties friction="0.0" />    
  </joint>  

  <joint name="left_knee" type="revolute">    
    <origin xyz="-3.1366467205128203278e-15 0.095999999999999752198 0.027400000000000007683" rpy="-3.1415926535897926719 -2.5420496490693392505e-17 -8.4866560936749634e-15" />    
    <parent link="left_hip_pitch_link" />    
    <child link="left_calf_link" />    
    <axis xyz="0 0 1" />    
    <limit effort="1" velocity="20" lower="-1.570796326794896558" upper="2.2689280275926284602" />    
    <joint_properties friction="0.0" />    
  </joint>  

  <joint name="left_hip_pitch" type="revolute">    
    <origin xyz="-0.024000000716150875213 -0.01900000015244158319 -0.019000000152448091872" rpy="-1.5707963267945472818 1.5707963267948001906 0" />    
    <parent link="hip_roll_link" />    
    <child link="left_hip_pitch_link" />    
    <axis xyz="0 0 1" />    
    <limit effort="1" velocity="20" lower="-1.570796326794896558" upper="1.570796326794896558" />    
    <joint_properties friction="0.0" />    
  </joint>  

  <joint name="left_hip_roll" type="revolute">    
    <origin xyz="0.019000000000000304839 -3.3605706708588417072e-18 -0.026000000000000279832" rpy="1.5707963267908973126 -1.5707806634981131833 1.5707963268130720191" />    
    <parent link="hip_yaw_link" />    
    <child link="hip_roll_link" />    
    <axis xyz="0 0 1" />    
    <limit effort="1" velocity="20" lower="-1.570796326794896558" upper="1.570796326794896558" />    
    <joint_properties friction="0.0" />    
  </joint>  


<link name="hip_yaw_link_2">    
    <visual>      
      <origin xyz="0 0 0" rpy="0 -0 0" />      
      <geometry>        
        <mesh filename="../assemblies/right_3R+RH5_leg/meshes/right_hip_yaw_link_visual.stl" />        
      </geometry>      
      <material name="hip_yaw_link_material">        
        <color rgba="0.61568627450980395466 0.81176470588235294379 0.9294117647058824927 1.0" />        
      </material>      
    </visual>    
    <collision>      
      <origin xyz="0 0 0" rpy="0 -0 0" />      
      <geometry>        
        <mesh filename="../assemblies/right_3R+RH5_leg/meshes/right_hip_yaw_link_collision.stl" />        
      </geometry>      
    </collision>    
    <inertial>      
      <origin xyz="2.1765780897354368682e-19 -3.0328722395806411214e-19 -0.0098390489054829086829" rpy="0 0 0" />      
      <mass value="0.009025883737097921064" />      
      <inertia ixx="1.3230458239085880696e-06" ixy="-6.4778545919079861077e-49" ixz="1.7322911775161989053e-33" iyy="3.8408510960330541809e-06" iyz="-1.4482241779965781819e-32" izz="3.8721396285793086199e-06" />      
    </inertial>    
  </link>  

  <link name="hip_roll_link_2">    
    <visual>      
      <origin xyz="0 0 0" rpy="0 -0 0" />      
      <geometry>        
        <mesh filename="../assemblies/right_3R+RH5_leg/meshes/right_hip_roll_link_visual.stl" />        
      </geometry>      
      <material name="hip_roll_link_material">        
        <color rgba="0.95018735644455853961 0.70678927200428420807 0.061612079402596685307 1.0" />        
      </material>      
    </visual>    
    <collision>      
      <origin xyz="0 0 0" rpy="0 -0 0" />      
      <geometry>        
        <mesh filename="../assemblies/right_3R+RH5_leg/meshes/right_hip_roll_link_collision.stl" />        
      </geometry>      
    </collision>    
    <inertial>      
      <origin xyz="-0.012000151133960917579 -0.00049588831385676847546 -0.018504019244507459441" rpy="0 0 0" />      
      <mass value="0.09801239148352869357" />      
      <inertia ixx="2.0221748766307408535e-05" ixy="-4.1552068245398642269e-08" ixz="-4.1225592188036493823e-08" iyy="2.7358099958307688013e-05" iyz="-5.0935731752404839018e-07" izz="2.7358069524724229097e-05" />      
    </inertial>    
  </link>  

  <link name="right_hip_pitch_link">    
    <visual>      
      <origin xyz="0 0 0" rpy="0 -0 0" />      
      <geometry>        
        <mesh filename="../assemblies/right_3R+RH5_leg/meshes/right_hip_pitch_link_visual.stl" />        
      </geometry>      
      <material name="right_hip_pitch_link_material">        
        <color rgba="0.6165363060683557439 0.80730204019995621678 0.92176148067891616744 1.0" />        
      </material>      
    </visual>    
    <collision>      
      <origin xyz="0 0 0" rpy="0 -0 0" />      
      <geometry>        
        <mesh filename="../assemblies/right_3R+RH5_leg/meshes/right_hip_pitch_link_collision.stl" />        
      </geometry>      
    </collision>    
    <inertial>      
      <origin xyz="-1.4741268609426623978e-05 0.052986690876698237795 0.014788127171305245899" rpy="0 0 0" />      
      <mass value="0.094084567879581956773" />      
      <inertia ixx="6.3099182122443713016e-05" ixy="-2.2045192591942831085e-07" ixz="-1.2728889936268710697e-08" iyy="2.1759163818497920495e-05" iyz="-1.4708395298810234192e-06" izz="6.2821853547821832043e-05" />      
    </inertial>    
  </link>  

  <link name="right_calf_link">    
    <visual>      
      <origin xyz="0 0 0" rpy="0 -0 0" />      
      <geometry>        
        <mesh filename="../assemblies/right_3R+RH5_leg/meshes/right_calf_link_visual.stl" />        
      </geometry>      
      <material name="right_calf_link_material">        
        <color rgba="0.55182153444277581844 0.72936705907288057471 0.87615824804808439819 1.0" />        
      </material>      
    </visual>    
    <collision>      
      <origin xyz="0 0 0" rpy="0 -0 0" />      
      <geometry>        
        <mesh filename="../assemblies/right_3R+RH5_leg/meshes/right_calf_link_collision.stl" />        
      </geometry>      
    </collision>    
    <inertial>      
      <origin xyz="-0.0038784271883378156585 0.043110179744828905357 0.0081688793093392352007" rpy="0 0 0" />      
      <mass value="0.016616299594005391055" />      
      <inertia ixx="1.5958223723938048889e-05" ixy="2.2918216583122531074e-07" ixz="5.9933409326354686853e-09" iyy="2.0657984790181373815e-06" iyz="-2.8480740343859627724e-08" izz="1.5100763145605012705e-05" />      
    </inertial>    
  </link>  

  <link name="ank_pitch_link_2">    
    <visual>      
      <origin xyz="0 0 0" rpy="0 -0 0" />      
      <geometry>        
        <mesh filename="../assemblies/right_3R+RH5_leg/meshes/right_ank_pitch_link_visual.stl" />        
      </geometry>      
      <material name="ank_pitch_link_material">        
        <color rgba="0.63189161126160275916 0.72668668793540891482 0.78356373393969258601 1.0" />        
      </material>      
    </visual>    
    <collision>      
      <origin xyz="0 0 0" rpy="0 -0 0" />      
      <geometry>        
        <mesh filename="../assemblies/right_3R+RH5_leg/meshes/right_ank_pitch_link_collision.stl" />        
      </geometry>      
    </collision>    
    <inertial>      
      <origin xyz="4.026968783825126577e-08 0.00059528282566478777152 -0.014599922383890177879" rpy="0 0 0" />      
      <mass value="0.0042238381753791605713" />      
      <inertia ixx="4.3705254067388915748e-07" ixy="1.6834346644559477147e-13" ixz="1.6428822746950188149e-12" iyy="3.9782741364654717915e-07" iyz="2.0919211860378376185e-14" izz="8.8858574534509015783e-08" />      
    </inertial>    
  </link>  

  <link name="ank_roll_link_2">    
    <visual>      
      <origin xyz="0 0 0" rpy="0 -0 0" />      
      <geometry>        
        <mesh filename="../assemblies/right_3R+RH5_leg/meshes/right_ank_roll_link_visual.stl" />        
      </geometry>      
      <material name="ank_roll_link_material">        
        <color rgba="0.61568627450980384364 0.81176470588235294379 0.92941176470588227065 1.0" />        
      </material>      
    </visual>    
    <collision>      
      <origin xyz="0 0 0" rpy="0 -0 0" />      
      <geometry>        
        <mesh filename="../assemblies/right_3R+RH5_leg/meshes/right_ank_roll_link_collision.stl" />        
      </geometry>      
    </collision>    
    <inertial>      
      <origin xyz="-6.3661537446033702237e-10 0.027240102316353740491 0.0019830147448535390478" rpy="0 0 0" />      
      <mass value="0.013844478784760253648" />      
      <inertia ixx="1.0150902309234951154e-05" ixy="6.8603302689735109411e-14" ixz="-3.2605547316574369192e-13" iyy="8.6636116663431484141e-06" iyz="-7.8151778926545186654e-07" izz="2.8991570356470512405e-06" />      
    </inertial>    
  </link>  

  <link name="ank_rr_link_3">    
    <visual>      
      <origin xyz="0 0 0" rpy="0 -0 0" />      
      <geometry>        
        <mesh filename="../assemblies/right_3R+RH5_leg/meshes/right_ank_rr_link_visual.stl" />        
      </geometry>      
      <material name="ank_rr_link_material">        
        <color rgba="0.61568627450980395466 0.81176470588235294379 0.92941176470588238168 1.0" />        
      </material>      
    </visual>    
    <collision>      
      <origin xyz="0 0 0" rpy="0 -0 0" />      
      <geometry>        
        <mesh filename="../assemblies/right_3R+RH5_leg/meshes/right_ank_rr_link_collision.stl" />        
      </geometry>      
    </collision>    
    <inertial>      
      <origin xyz="3.4593503690053864204e-05 0.0062999445222072132655 -0.0018999999999999921899" rpy="0 0 0" />      
      <mass value="0.00044289790445047673732" />      
      <inertia ixx="9.0894755004835256766e-09" ixy="-5.6689994077039463061e-11" ixz="1.0879024115038818139e-14" iyy="8.3785129146959922129e-09" iyz="-6.7148521063699618988e-32" izz="1.3107013728801488166e-08" />      
    </inertial>    
  </link>  

  <link name="12lf_rod_end_3">    
    <visual>      
      <origin xyz="0 0 0" rpy="0 -0 0" />      
      <geometry>        
        <mesh filename="../assemblies/right_3R+RH5_leg/meshes/right_12lf_rod_end_visual.stl" />        
      </geometry>      
      <material name="12lf_rod_end_material">        
        <color rgba="0.92771758928836534075 0.61049283053223002415 0.2184765849058516729 1.0" />        
      </material>      
    </visual>    
    <collision>      
      <origin xyz="0 0 0" rpy="0 -0 0" />      
      <geometry>        
        <mesh filename="../assemblies/right_3R+RH5_leg/meshes/right_12lf_rod_end_collision.stl" />        
      </geometry>      
    </collision>    
    <inertial>      
      <origin xyz="-4.4735201141172343971e-11 0.0038422185938245959416 -0.002006438418720947383" rpy="0 0 0" />      
      <mass value="0.00085420491177815905965" />      
      <inertia ixx="1.1840985264406777468e-08" ixy="-2.0225977980941024108e-16" ixz="9.2606419959974177583e-16" iyy="3.3549621576797280544e-09" iyz="7.4535631381848423295e-12" izz="1.2703522254419960073e-08" />      
    </inertial>    
  </link>  

  <joint name="right_ank_R21" type="revolute">    
    <origin xyz="0.0021000000000000254574 0.010000000000000092149 -0.0018999999999999919731" rpy="-1.57079632679489678 1.4274562579811747032 -1.570796326794901665" />    
    <parent link="ank_rr_link_3" />    
    <child link="12lf_rod_end_3" />    
    <axis xyz="0 0 1" />    
    <limit effort="1" velocity="20" lower="-1.570796326794896558" upper="1.570796326794896558" />    
    <joint_properties friction="0.0" />    
  </joint>  

  <joint name="right_ank_R11" type="revolute">    
    <origin xyz="-0.0099999999999999932693 0.012500000000000038858 -0.02800000000000008038" rpy="-3.1415926535897926719 -7.9041717877712374794e-16 -0.10218566393336031561" />    
    <parent link="ank_roll_link_2" />    
    <child link="ank_rr_link_3" />    
    <axis xyz="0 0 1" />    
    <limit effort="1" velocity="20" lower="-1.570796326794896558" upper="1.570796326794896558" />    
    <joint_properties friction="0.0" />    
  </joint>  

  <link name="ank_rr_link_4">    
    <visual>      
      <origin xyz="0 0 0" rpy="0 -0 0" />      
      <geometry>        
        <mesh filename="../assemblies/right_3R+RH5_leg/meshes/right_ank_rr_link_2_visual.stl" />        
      </geometry>      
      <material name="ank_rr_link_2_material">        
        <color rgba="0.61568627450980395466 0.81176470588235294379 0.92941176470588238168 1.0" />        
      </material>      
    </visual>    
    <collision>      
      <origin xyz="0 0 0" rpy="0 -0 0" />      
      <geometry>        
        <mesh filename="../assemblies/right_3R+RH5_leg/meshes/right_ank_rr_link_2_collision.stl" />        
      </geometry>      
    </collision>    
    <inertial>      
      <origin xyz="3.4593503690053864204e-05 -0.0062999445222071577544 -0.0018999999999999986951" rpy="0 0 0" />      
      <mass value="0.00044289790445047673732" />      
      <inertia ixx="9.0894755004835223679e-09" ixy="5.6689994077039430749e-11" ixz="-1.0879024115038816561e-14" iyy="8.3785129146959922129e-09" iyz="-5.6146655472116469382e-32" izz="1.3107013728801488166e-08" />      
    </inertial>    
  </link>  

  <link name="12lf_rod_end_4">    
    <visual>      
      <origin xyz="0 0 0" rpy="0 -0 0" />      
      <geometry>        
        <mesh filename="../assemblies/right_3R+RH5_leg/meshes/right_12lf_rod_end_2_visual.stl" />        
      </geometry>      
      <material name="12lf_rod_end_2_material">        
        <color rgba="0.92771758928836534075 0.61049283053223013518 0.2184765849058516729 1.0" />        
      </material>      
    </visual>    
    <collision>      
      <origin xyz="0 0 0" rpy="0 -0 0" />      
      <geometry>        
        <mesh filename="../assemblies/right_3R+RH5_leg/meshes/right_12lf_rod_end_2_collision.stl" />        
      </geometry>      
    </collision>    
    <inertial>      
      <origin xyz="-4.4735188340877362683e-11 0.0038422185938245798954 -0.0020064384187209456482" rpy="0 0 0" />      
      <mass value="0.00085420491177815905965" />      
      <inertia ixx="1.1840985264406800629e-08" ixy="-2.0225978056313929985e-16" ixz="9.2606419976476418024e-16" iyy="3.3549621576797251593e-09" iyz="7.4535631381830506434e-12" izz="1.2703522254419991506e-08" />      
    </inertial>    
  </link>  

  <joint name="right_ank_R22" type="revolute">    
    <origin xyz="0.0021000000000000185185 -0.010000000000000203171 -0.0019000000000000336065" rpy="-1.5707963267948961139 -1.4274330297240631626 -1.5707963267948974462" />    
    <parent link="ank_rr_link_4" />    
    <child link="12lf_rod_end_4" />    
    <axis xyz="0 0 1" />    
    <limit effort="1" velocity="20" lower="-1.570796326794896558" upper="1.570796326794896558" />    
    <joint_properties friction="0.0" />    
  </joint>  

  <joint name="right_ank_R12" type="revolute">    
    <origin xyz="0.0099999999999999967387 0.012499999999999761302 -0.02800000000000008038" rpy="-3.141592653589793116 2.6793361964555018776e-16 -3.0395375511005577884" />    
    <parent link="ank_roll_link_2" />    
    <child link="ank_rr_link_4" />    
    <axis xyz="0 0 1" />    
    <limit effort="1" velocity="20" lower="-1.570796326794896558" upper="1.570796326794896558" />    
    <joint_properties friction="0.0" />    
  </joint>  

  <joint name="right_ank_roll" type="revolute">    
    <origin xyz="1.7763568394002504647e-15 -0.0061000000000006751946 -0.014600000000001986389" rpy="1.5707963281806591738 1.5707907166914047981 -3.1415926522336965476" />    
    <parent link="ank_pitch_link_2" />    
    <child link="ank_roll_link_2" />    
    <axis xyz="0 0 1" />    
    <limit effort="1" velocity="20" lower="-1.570796326794896558" upper="1.570796326794896558" />    
    <joint_properties friction="0.0" />    
  </joint>  

  <joint name="right_ank_pitch" type="revolute">    
    <origin xyz="1.1774009739933720541e-18 0.099999999999999922284 -0.0061999999999999937106" rpy="-3.141592653589793116 3.885801455584734555e-16 -1.5707963267948825692" />    
    <parent link="right_calf_link" />    
    <child link="ank_pitch_link_2" />    
    <axis xyz="0 0 1" />    
    <limit effort="1" velocity="20" lower="-1.570796326794896558" upper="1.570796326794896558" />    
    <joint_properties friction="0.0" />    
  </joint>  

  <link name="ball_joint_container_3">    
    <visual>      
      <origin xyz="0 0 0" rpy="0 -0 0" />      
      <geometry>        
        <mesh filename="../assemblies/right_3R+RH5_leg/meshes/right_ball_joint_container_visual.stl" />        
      </geometry>      
      <material name="ball_joint_container_material">        
        <color rgba="0.61568627450980395466 0.81176470588235294379 0.92941176470588238168 1.0" />        
      </material>      
    </visual>    
    <collision>      
      <origin xyz="0 0 0" rpy="0 -0 0" />      
      <geometry>        
        <mesh filename="../assemblies/right_3R+RH5_leg/meshes/right_ball_joint_container_collision.stl" />        
      </geometry>      
    </collision>    
    <inertial>      
      <origin xyz="4.7221442975708442754e-19 -1.2157539084691741387e-19 -0.0097125341669083396778" rpy="0 0 0" />      
      <mass value="4.803735642533054869e-05" />      
      <inertia ixx="7.1865480628741666366e-10" ixy="1.1825814236451355974e-26" ixz="-5.9322125038070853293e-39" iyy="8.4754204277185539101e-10" iyz="-1.7674753249233014464e-39" izz="1.8625314111651911712e-10" />      
    </inertial>    
  </link>  

  <link name="ball_joint_ball_3">    
    <visual>      
      <origin xyz="0 0 0" rpy="0 -0 0" />      
      <geometry>        
        <mesh filename="../assemblies/right_3R+RH5_leg/meshes/right_ball_joint_ball_visual.stl" />        
      </geometry>      
      <material name="ball_joint_ball_material">        
        <color rgba="0.3291302810242056065 0.44310466418644928188 0.69204871161977121741 1.0" />        
      </material>      
    </visual>    
    <collision>      
      <origin xyz="0 0 0" rpy="0 -0 0" />      
      <geometry>        
        <mesh filename="../assemblies/right_3R+RH5_leg/meshes/right_ball_joint_ball_collision.stl" />        
      </geometry>      
    </collision>    
    <inertial>      
      <origin xyz="-4.1125153491071802599e-18 -0.0010308669810016226741 -1.8495092015533564433e-18" rpy="0 0 0" />      
      <mass value="4.4053796295264630609e-05" />      
      <inertia ixx="3.1285011349692525504e-10" ixy="4.808384477806169279e-26" ixz="-2.1466154830118600303e-27" iyy="6.2569568612795566352e-11" iyz="6.1358688430553467103e-26" izz="3.1285321460376379959e-10" />      
    </inertial>    
  </link>  

  <link name="12lf_3">    
    <visual>      
      <origin xyz="0 0 0" rpy="0 -0 0" />      
      <geometry>        
        <mesh filename="../assemblies/right_3R+RH5_leg/meshes/right_12lf_visual.stl" />        
      </geometry>      
      <material name="12lf_material">        
        <color rgba="0.62004392100736016591 0.58836684613512635345 0.49897069021535672695 1.0" />        
      </material>      
    </visual>    
    <collision>      
      <origin xyz="0 0 0" rpy="0 -0 0" />      
      <geometry>        
        <mesh filename="../assemblies/right_3R+RH5_leg/meshes/right_12lf_collision.stl" />        
      </geometry>      
    </collision>    
    <inertial>      
      <origin xyz="0.0049084207243671454032 -0.00013802439943487300011 -0.02994700357714817629" rpy="0 0 0" />      
      <mass value="0.044782197696050352054" />      
      <inertia ixx="1.5260128421313289839e-05" ixy="2.2955773686477098695e-08" ixz="-8.1364204007546704932e-08" iyy="1.8188469778952530756e-05" iyz="-5.5542240842734075439e-08" izz="5.14962739017425865e-06" />      
    </inertial>    
  </link>  

  <link name="12lf_rod_3">    
    <visual>      
      <origin xyz="0 0 0" rpy="0 -0 0" />      
      <geometry>        
        <mesh filename="../assemblies/right_3R+RH5_leg/meshes/right_12lf_rod_visual.stl" />        
      </geometry>      
      <material name="12lf_rod_material">        
        <color rgba="0.80250260812861884396 0.89340612183512713163 0.94491811293548189088 1.0" />        
      </material>      
    </visual>    
    <collision>      
      <origin xyz="0 0 0" rpy="0 -0 0" />      
      <geometry>        
        <mesh filename="../assemblies/right_3R+RH5_leg/meshes/right_12lf_rod_collision.stl" />        
      </geometry>      
    </collision>    
    <inertial>      
      <origin xyz="-6.3222084032511767099e-07 4.6933255135565751144e-07 -0.012893387334331114086" rpy="0 0 0" />      
      <mass value="0.0025088292483592140175" />      
      <inertia ixx="2.6944521128608337892e-07" ixy="7.1389570387314549512e-15" ixz="1.3562243131326297886e-11" iyy="2.6944520001664893476e-07" iyz="-1.0089988374153191392e-11" izz="1.7809843599861015564e-08" />      
    </inertial>    
  </link>  

  <joint name="right_ank_act1" type="prismatic">    
    <origin xyz="2.2722093427785666764e-06 1.2698175844150227931e-15 -0.072674150483189009497" rpy="-3.1415926535897811256 9.814572829871540247e-15 -2.2021168238260906413" />    
    <parent link="12lf_3" />    
    <child link="12lf_rod_3" />    
    <axis xyz="0 0 1" />    
    <limit effort="1" velocity="20" lower="0" upper="0.040000000000000000833" />    
    <joint_properties friction="0.0" />    
  </joint>  

  <joint name="right_ank_B31" type="revolute">    
    <origin xyz="-1.3010426069826053208e-18 -0.0064387505004002698605 6.9388939039072283776e-18" rpy="-1.570796326794896558 0.16913440034154619829 2.2885625266571218396e-16" />    
    <parent link="ball_joint_ball_3" />    
    <child link="12lf_3" />    
    <axis xyz="0 0 1" />    
    <limit effort="1" velocity="20" lower="-0.785398163397448279" upper="0.785398163397448279" />    
    <joint_properties friction="0.0" />    
  </joint>  

  <joint name="right_ank_B21" type="revolute">    
    <origin xyz="-2.0816681711721685133e-17 1.1102230246251565404e-16 -0.011499999999999998071" rpy="1.570796326794896558 -1.4274562579810237128 1.5707963267948950037" />    
    <parent link="ball_joint_container_3" />    
    <child link="ball_joint_ball_3" />    
    <axis xyz="0 0 1" />    
    <limit effort="1" velocity="20" lower="-0.785398163397448279" upper="0.785398163397448279" />    
    <joint_properties friction="0.0" />    
  </joint>  

  <joint name="right_ank_B11" type="revolute">    
    <origin xyz="0.007999999999999972411 0.014999999999999957812 -0.011500000000000010214" rpy="1.5707963267948978903 -1.4686162729650020786 -1.5707963267948970021" />    
    <parent link="right_calf_link" />    
    <child link="ball_joint_container_3" />    
    <axis xyz="0 0 1" />    
    <limit effort="1" velocity="20" lower="-0.785398163397448279" upper="0.785398163397448279" />    
    <joint_properties friction="0.0" />    
  </joint>  

  <link name="ball_joint_container_4">    
    <visual>      
      <origin xyz="0 0 0" rpy="0 -0 0" />      
      <geometry>        
        <mesh filename="../assemblies/right_3R+RH5_leg/meshes/right_ball_joint_container_2_visual.stl" />        
      </geometry>      
      <material name="ball_joint_container_2_material">        
        <color rgba="0.61568627450980395466 0.81176470588235294379 0.92941176470588238168 1.0" />        
      </material>      
    </visual>    
    <collision>      
      <origin xyz="0 0 0" rpy="0 -0 0" />      
      <geometry>        
        <mesh filename="../assemblies/right_3R+RH5_leg/meshes/right_ball_joint_container_2_collision.stl" />        
      </geometry>      
    </collision>    
    <inertial>      
      <origin xyz="-6.4666794741501532909e-18 -2.7877151006475826086e-17 -0.0097125341669083431473" rpy="0 0 0" />      
      <mass value="4.803735642533054869e-05" />      
      <inertia ixx="7.1865480628741707725e-10" ixy="-7.6356461259815175018e-27" ixz="-5.5405074936934095688e-39" iyy="8.475420427718555978e-10" iyz="-1.6847421608208367339e-39" izz="1.8625314111651911712e-10" />      
    </inertial>    
  </link>  

  <link name="ball_joint_ball_4">    
    <visual>      
      <origin xyz="0 0 0" rpy="0 -0 0" />      
      <geometry>        
        <mesh filename="../assemblies/right_3R+RH5_leg/meshes/right_ball_joint_ball_2_visual.stl" />        
      </geometry>      
      <material name="ball_joint_ball_2_material">        
        <color rgba="0.3291302810242056065 0.44310466418644928188 0.69204871161977121741 1.0" />        
      </material>      
    </visual>    
    <collision>      
      <origin xyz="0 0 0" rpy="0 -0 0" />      
      <geometry>        
        <mesh filename="../assemblies/right_3R+RH5_leg/meshes/right_ball_joint_ball_2_collision.stl" />        
      </geometry>      
    </collision>    
    <inertial>      
      <origin xyz="-3.1503615901221646949e-18 -0.0010308669810016504297 2.1306171358979874201e-18" rpy="0 0 0" />      
      <mass value="4.4053796295264630609e-05" />      
      <inertia ixx="3.1285011349692535844e-10" ixy="5.5990895141001096842e-26" ixz="-2.8128653674633218659e-27" iyy="6.2569568612795579277e-11" iyz="-1.4031925621215802366e-26" izz="3.1285321460376441998e-10" />      
    </inertial>    
  </link>  

  <link name="12lf_4">    
    <visual>      
      <origin xyz="0 0 0" rpy="0 -0 0" />      
      <geometry>        
        <mesh filename="../assemblies/right_3R+RH5_leg/meshes/right_12lf_2_visual.stl" />        
      </geometry>      
      <material name="12lf_2_material">        
        <color rgba="0.62004392100736027693 0.58836684613512624242 0.49897069021535683797 1.0" />        
      </material>      
    </visual>    
    <collision>      
      <origin xyz="0 0 0" rpy="0 -0 0" />      
      <geometry>        
        <mesh filename="../assemblies/right_3R+RH5_leg/meshes/right_12lf_2_collision.stl" />        
      </geometry>      
    </collision>    
    <inertial>      
      <origin xyz="0.0049084207243654436395 -0.00013802439943709924664 -0.029947003577146625447" rpy="0 0 0" />      
      <mass value="0.044782197696050358993" />      
      <inertia ixx="1.5260128421312164979e-05" ixy="2.2955773686777500915e-08" ixz="-8.136420400830112012e-08" iyy="1.8188469778949572917e-05" iyz="-5.5542240843715674128e-08" izz="5.1496273901724036478e-06" />      
    </inertial>    
  </link>  

  <link name="12lf_rod_4">    
    <visual>      
      <origin xyz="0 0 0" rpy="0 -0 0" />      
      <geometry>        
        <mesh filename="../assemblies/right_3R+RH5_leg/meshes/right_12lf_rod_2_visual.stl" />        
      </geometry>      
      <material name="12lf_rod_2_material">        
        <color rgba="0.80250260812861884396 0.89340612183512713163 0.94491811293548189088 1.0" />        
      </material>      
    </visual>    
    <collision>      
      <origin xyz="0 0 0" rpy="0 -0 0" />      
      <geometry>        
        <mesh filename="../assemblies/right_3R+RH5_leg/meshes/right_12lf_rod_2_collision.stl" />        
      </geometry>      
    </collision>    
    <inertial>      
      <origin xyz="-6.3222084132226656172e-07 4.6933255081341041789e-07 -0.012893387334332461966" rpy="0 0 0" />      
      <mass value="0.0025088292483592140175" />      
      <inertia ixx="2.6944521128601032232e-07" ixy="7.1389570449845313104e-15" ixz="1.3562243158147916823e-11" iyy="2.6944520001657577229e-07" iyz="-1.0089988358384868711e-11" izz="1.7809843599861015564e-08" />      
    </inertial>    
  </link>  

  <joint name="right_ank_act2" type="prismatic">    
    <origin xyz="2.2722093417776312307e-06 -2.3800406090401793335e-15 -0.072674285805652133474" rpy="3.141592653589793116 -4.1997988128928857096e-16 -2.2021168238262838202" />    
    <parent link="12lf_4" />    
    <child link="12lf_rod_4" />    
    <axis xyz="0 0 1" />    
    <limit effort="1" velocity="20" lower="0" upper="0.040000000000000000833" />    
    <joint_properties friction="0.0" />    
  </joint>  

  <joint name="right_ank_B32" type="revolute">    
    <origin xyz="-1.5178830414797062076e-17 -0.006438750500400436394 1.3877787807814456755e-17" rpy="-1.5707963267948854558 -0.17993145005756266963 -2.2505490007573420062e-15" />    
    <parent link="ball_joint_ball_4" />    
    <child link="12lf_4" />    
    <axis xyz="0 0 1" />    
    <limit effort="1" velocity="20" lower="-0.785398163397448279" upper="0.785398163397448279" />    
    <joint_properties friction="0.0" />    
  </joint>  

  <joint name="right_ank_B22" type="revolute">    
    <origin xyz="-1.3877787807814456755e-17 -8.3266726846886740532e-17 -0.011499999999999991132" rpy="1.57079632679489678 -1.4274330297239778975 1.5707963267949012209" />    
    <parent link="ball_joint_container_4" />    
    <child link="ball_joint_ball_4" />    
    <axis xyz="0 0 1" />    
    <limit effort="1" velocity="20" lower="-0.785398163397448279" upper="0.785398163397448279" />    
    <joint_properties friction="0.0" />    
  </joint>  

  <joint name="right_ank_B12" type="revolute">    
    <origin xyz="0.0079999999999997000594 0.015000000000000290878 0.02830000000000029714" rpy="-1.5707963267948978903 -1.468735614201923223 1.5707963267949029973" />    
    <parent link="right_calf_link" />    
    <child link="ball_joint_container_4" />    
    <axis xyz="0 0 1" />    
    <limit effort="1" velocity="20" lower="-0.785398163397448279" upper="0.785398163397448279" />    
    <joint_properties friction="0.0" />    
  </joint>  

  <joint name="right_knee" type="revolute">    
    <origin xyz="-2.4109230505694711738e-15 0.095999999999999821587 0.027399999999999948702" rpy="3.141592653589793116 -1.6870185802395130185e-16 3.1415926535897922278" />    
    <parent link="right_hip_pitch_link" />    
    <child link="right_calf_link" />    
    <axis xyz="0 0 1" />    
    <limit effort="1" velocity="20" lower="-1.570796326794896558" upper="1.570796326794896558" />    
    <joint_properties friction="0.0" />    
  </joint>  

  <joint name="right_hip_pitch" type="revolute">    
    <origin xyz="-0.024000000716145986762 -0.019000000152457990205 -0.019000000152453774827" rpy="-1.5707963267951818853 1.5707963267947633312 0" />    
    <parent link="hip_roll_link_2" />    
    <child link="right_hip_pitch_link" />    
    <axis xyz="0 0 1" />    
    <limit effort="1" velocity="20" lower="-1.570796326794896558" upper="1.570796326794896558" />    
    <joint_properties friction="0.0" />    
  </joint>  

  <joint name="right_hip_roll" type="revolute">    
    <origin xyz="-0.018999999999999885036 -3.3499987806511678644e-18 -0.026000000000000002276" rpy="-1.5707963266839728433 -1.5707907166912637997 1.5707963266641831179" />    
    <parent link="hip_yaw_link_2" />    
    <child link="hip_roll_link_2" />    
    <axis xyz="0 0 1" />    
    <limit effort="1" velocity="20" lower="-1.570796326794896558" upper="1.570796326794896558" />    
    <joint_properties friction="0.0" />    
  </joint>  


</robot>