<robot name="base_legs">  
  <mujoco><compiler strippath="false" balanceinertia="true" discardvisual="false" /></mujoco><link name="base_link" />  
  <joint name="base_link_to_base" type="fixed">    
    <parent link="base_link" />    
    <child link="hip_link" />    
    <origin rpy="0.0 0 0" xyz="0 0 0" />    
  </joint>  
  <link name="hip_link">    
    <visual>      
      <origin xyz="0 0 0" rpy="0 -0 0" />      
      <geometry>        
        <mesh filename="../assemblies/no_body/meshes/hip_link_visual.stl" />        
      </geometry>      
      <material name="hip_link_material">        
        <color rgba="0.60265235106909242901 0.7475818661971369572 0.82292492068132760963 1.0" />        
      </material>      
    </visual>    
    <collision>      
      <origin xyz="0 0 0" rpy="0 -0 0" />      
      <geometry>        
        <mesh filename="../assemblies/no_body/meshes/hip_link_collision.stl" />        
      </geometry>      
    </collision>    
    <inertial>      
      <origin xyz="-0.01440352333151279085 -0.00023164401215059715849 0.31153288519557342795" rpy="0 0 0" />      
      <mass value="0.1326329205818372603" />      
      <inertia ixx="0.00012163093315383989741" ixy="1.4038303149257438203e-07" ixz="1.0872278951925664343e-05" iyy="8.4970137932102799945e-05" iyz="3.874082128926956186e-07" izz="0.00015647103471607302027" />      
    </inertial>    
  </link>  

  <joint name="left_hip_yaw" type="revolute">    
    <origin xyz="-0.0063999999999997730579 0.033999999999999780398 0.28550000000000019806" rpy="1.2173498077223837207e-16 -0 1.3877787807345010561e-17" />    
    <parent link="hip_link" />    
    <child link="hip_yaw_link" />    
    <axis xyz="0 0 1" />    
    <limit effort="1" velocity="20" lower="-1.570796326794896558" upper="1.570796326794896558" />    
    <joint_properties friction="0.0" />    
  </joint>  

  <joint name="right_hip_yaw" type="revolute">    
    <origin xyz="-0.0063999999999996715766 -0.034000000000000092648 0.28550000000000014255" rpy="1.2173498077030393722e-16 -4.683327753701002654e-30 2.5887568767631957634e-14" />    
    <parent link="hip_link" />    
    <child link="hip_yaw_link_2" />    
    <axis xyz="0 0 1" />    
    <limit effort="1" velocity="20" lower="-1.570796326794896558" upper="1.570796326794896558" />    
    <joint_properties friction="0.0" />    
  </joint>  


<link name="hip_yaw_link">    
    <visual>      
      <origin xyz="0 0 0" rpy="0 -0 0" />      
      <geometry>        
        <mesh filename="../assemblies/left_3R+RH5_leg/meshes/left_hip_yaw_link_visual.stl" />        
      </geometry>      
      <material name="hip_yaw_link_material">        
        <color rgba="0.61568627450980395466 0.81176470588235294379 0.92941176470588238168 1.0" />        
      </material>      
    </visual>    
    <collision>      
      <origin xyz="0 0 0" rpy="0 -0 0" />      
      <geometry>        
        <mesh filename="../assemblies/left_3R+RH5_leg/meshes/left_hip_yaw_link_collision.stl" />        
      </geometry>      
    </collision>    
    <inertial>      
      <origin xyz="-5.5101789230161932459e-19 -4.987496519892330868e-19 -0.0098390489054830127663" rpy="0 0 0" />      
      <mass value="0.0090258837370979175946" />      
      <inertia ixx="1.3230458239086465149e-06" ixy="-3.3592249637948231893e-24" ixz="-1.1251788840973426872e-52" iyy="3.8408510960331422723e-06" iyz="2.3044956050358332095e-34" izz="3.8721396285793907821e-06" />      
    </inertial>    
  </link>  

  <link name="hip_roll_link">    
    <visual>      
      <origin xyz="0 0 0" rpy="0 -0 0" />      
      <geometry>        
        <mesh filename="../assemblies/left_3R+RH5_leg/meshes/left_hip_roll_link_visual.stl" />        
      </geometry>      
      <material name="hip_roll_link_material">        
        <color rgba="0.95018735644455865064 0.70678927200428420807 0.061612079402596699185 1.0" />        
      </material>      
    </visual>    
    <collision>      
      <origin xyz="0 0 0" rpy="0 -0 0" />      
      <geometry>        
        <mesh filename="../assemblies/left_3R+RH5_leg/meshes/left_hip_roll_link_collision.stl" />        
      </geometry>      
    </collision>    
    <inertial>      
      <origin xyz="-0.012000151133960529001 -0.00049588831385038068152 -0.018504019244504718578" rpy="0 0 0" />      
      <mass value="0.098012391483528679692" />      
      <inertia ixx="2.0221748766306297228e-05" ixy="-4.1552068244097566575e-08" ixz="-4.1225592188060038692e-08" iyy="2.7358099958307017163e-05" iyz="-5.0935731752381958541e-07" izz="2.7358069524722873844e-05" />      
    </inertial>    
  </link>  

  <link name="left_hip_pitch_link">    
    <visual>      
      <origin xyz="0 0 0" rpy="0 -0 0" />      
      <geometry>        
        <mesh filename="../assemblies/left_3R+RH5_leg/meshes/left_hip_pitch_link_visual.stl" />        
      </geometry>      
      <material name="left_hip_pitch_link_material">        
        <color rgba="0.61653602481865321661 0.80730351676089540103 0.92176401192624057845 1.0" />        
      </material>      
    </visual>    
    <collision>      
      <origin xyz="0 0 0" rpy="0 -0 0" />      
      <geometry>        
        <mesh filename="../assemblies/left_3R+RH5_leg/meshes/left_hip_pitch_link_collision.stl" />        
      </geometry>      
    </collision>    
    <inertial>      
      <origin xyz="-0.00021625089587036150818 0.053000240769318827938 0.014794279324098446454" rpy="0 0 0" />      
      <mass value="0.094115707917386950965" />      
      <inertia ixx="6.316384435944080993e-05" ixy="4.2226893167611225534e-07" ixz="-1.5236088146924364196e-07" iyy="2.1766716876463621921e-05" iyz="-1.4946539861164846195e-06" izz="6.2872441725695250685e-05" />      
    </inertial>    
  </link>  

  <link name="left_calf_link">    
    <visual>      
      <origin xyz="0 0 0" rpy="0 -0 0" />      
      <geometry>        
        <mesh filename="../assemblies/left_3R+RH5_leg/meshes/left_calf_link_visual.stl" />        
      </geometry>      
      <material name="left_calf_link_material">        
        <color rgba="0.55182138457441176627 0.7293668709690939167 0.87615813098181816176 1.0" />        
      </material>      
    </visual>    
    <collision>      
      <origin xyz="0 0 0" rpy="0 -0 0" />      
      <geometry>        
        <mesh filename="../assemblies/left_3R+RH5_leg/meshes/left_calf_link_collision.stl" />        
      </geometry>      
    </collision>    
    <inertial>      
      <origin xyz="-0.0038784319950641780832 -0.043110203474640458599 0.008168899779404440592" rpy="0 0 0" />      
      <mass value="0.016616268752102307527" />      
      <inertia ixx="1.5958212392253868486e-05" ixy="-2.2918088445891347294e-07" ixz="5.9921361723212020254e-09" iyy="2.0657945480054530971e-06" iyz="2.8475122223882865991e-08" izz="1.5100754419726926479e-05" />      
    </inertial>    
  </link>  

  <link name="ank_pitch_link">    
    <visual>      
      <origin xyz="0 0 0" rpy="0 -0 0" />      
      <geometry>        
        <mesh filename="../assemblies/left_3R+RH5_leg/meshes/left_ank_pitch_link_visual.stl" />        
      </geometry>      
      <material name="ank_pitch_link_material">        
        <color rgba="0.63189161126160275916 0.72668668793540891482 0.78356373393969258601 1.0" />        
      </material>      
    </visual>    
    <collision>      
      <origin xyz="0 0 0" rpy="0 -0 0" />      
      <geometry>        
        <mesh filename="../assemblies/left_3R+RH5_leg/meshes/left_ank_pitch_link_collision.stl" />        
      </geometry>      
    </collision>    
    <inertial>      
      <origin xyz="4.0269684924332414137e-08 0.00059528282566768985547 -0.014599922383890571662" rpy="0 0 0" />      
      <mass value="0.0042238381753791605713" />      
      <inertia ixx="4.3705254067379651325e-07" ixy="1.6834346513414585352e-13" ixz="1.6428822287382144103e-12" iyy="3.9782741364642033597e-07" iyz="2.0919268320923642454e-14" izz="8.8858574534542989745e-08" />      
    </inertial>    
  </link>  

  <link name="ank_roll_link">    
    <visual>      
      <origin xyz="0 0 0" rpy="0 -0 0" />      
      <geometry>        
        <mesh filename="../assemblies/left_3R+RH5_leg/meshes/left_ank_roll_link_visual.stl" />        
      </geometry>      
      <material name="ank_roll_link_material">        
        <color rgba="0.61568627450980395466 0.81176470588235294379 0.92941176470588238168 1.0" />        
      </material>      
    </visual>    
    <collision>      
      <origin xyz="0 0 0" rpy="0 -0 0" />      
      <geometry>        
        <mesh filename="../assemblies/left_3R+RH5_leg/meshes/left_ank_roll_link_collision.stl" />        
      </geometry>      
    </collision>    
    <inertial>      
      <origin xyz="-6.3661537538722950148e-10 0.027240102316353702328 0.0019830147448535399152" rpy="0 0 0" />      
      <mass value="0.013844478784760248444" />      
      <inertia ixx="1.0150902309234930825e-05" ixy="6.8603302694880716568e-14" ixz="-3.2605547317656671208e-13" iyy="8.66361166634314672e-06" iyz="-7.8151778926544794902e-07" izz="2.8991570356470334528e-06" />      
    </inertial>    
  </link>  

  <link name="ank_rr_link">    
    <visual>      
      <origin xyz="0 0 0" rpy="0 -0 0" />      
      <geometry>        
        <mesh filename="../assemblies/left_3R+RH5_leg/meshes/left_ank_rr_link_visual.stl" />        
      </geometry>      
      <material name="ank_rr_link_material">        
        <color rgba="0.61568627450980395466 0.81176470588235294379 0.92941176470588238168 1.0" />        
      </material>      
    </visual>    
    <collision>      
      <origin xyz="0 0 0" rpy="0 -0 0" />      
      <geometry>        
        <mesh filename="../assemblies/left_3R+RH5_leg/meshes/left_ank_rr_link_collision.stl" />        
      </geometry>      
    </collision>    
    <inertial>      
      <origin xyz="3.4593503690053823546e-05 0.0062999445222072123982 -0.0019000000000000060677" rpy="0 0 0" />      
      <mass value="0.00044289790445047673732" />      
      <inertia ixx="9.0894755004835240223e-09" ixy="-5.6689994077039805565e-11" ixz="1.0879024115046993894e-14" iyy="8.3785129146959889042e-09" iyz="9.5636730547090625513e-32" izz="1.3107013728801491474e-08" />      
    </inertial>    
  </link>  

  <link name="12lf_rod_end">    
    <visual>      
      <origin xyz="0 0 0" rpy="0 -0 0" />      
      <geometry>        
        <mesh filename="../assemblies/left_3R+RH5_leg/meshes/left_12lf_rod_end_visual.stl" />        
      </geometry>      
      <material name="12lf_rod_end_material">        
        <color rgba="0.92771758928836534075 0.61049283053223002415 0.2184765849058516729 1.0" />        
      </material>      
    </visual>    
    <collision>      
      <origin xyz="0 0 0" rpy="0 -0 0" />      
      <geometry>        
        <mesh filename="../assemblies/left_3R+RH5_leg/meshes/left_12lf_rod_end_collision.stl" />        
      </geometry>      
    </collision>    
    <inertial>      
      <origin xyz="-4.4735199263164480729e-11 0.0038422185938245998447 -0.0020064384187209387093" rpy="0 0 0" />      
      <mass value="0.00085420491177815905965" />      
      <inertia ixx="1.1840985264406780776e-08" ixy="-2.0225978109188480936e-16" ixz="9.2606420203077699125e-16" iyy="3.354962157679717301e-09" iyz="7.4535631381837453459e-12" izz="1.270352225441995511e-08" />      
    </inertial>    
  </link>  

  <joint name="left_ank_R21" type="revolute">    
    <origin xyz="0.0020999999999999977018 0.0099999999999998978595 -0.0018999999999999919731" rpy="-1.570796326794896558 1.427444247264781696 -1.5707963267949185404" />    
    <parent link="ank_rr_link" />    
    <child link="12lf_rod_end" />    
    <axis xyz="0 0 1" />    
    <limit effort="1" velocity="20" lower="-1.570796326794896558" upper="1.570796326794896558" />    
    <joint_properties friction="0.0" />    
  </joint>  

  <joint name="left_ank_R11" type="revolute">    
    <origin xyz="-0.010000000000000000208 0.01249999999999990008 -0.028000000000000010991" rpy="3.1415926535897775729 -1.2028245921984228645e-15 -0.10217761180348046424" />    
    <parent link="ank_roll_link" />    
    <child link="ank_rr_link" />    
    <axis xyz="0 0 1" />    
    <limit effort="1" velocity="20" lower="-1.570796326794896558" upper="1.570796326794896558" />    
    <joint_properties friction="0.0" />    
  </joint>  

  <link name="ank_rr_link_2">    
    <visual>      
      <origin xyz="0 0 0" rpy="0 -0 0" />      
      <geometry>        
        <mesh filename="../assemblies/left_3R+RH5_leg/meshes/left_ank_rr_link_2_visual.stl" />        
      </geometry>      
      <material name="ank_rr_link_2_material">        
        <color rgba="0.61568627450980395466 0.81176470588235294379 0.92941176470588238168 1.0" />        
      </material>      
    </visual>    
    <collision>      
      <origin xyz="0 0 0" rpy="0 -0 0" />      
      <geometry>        
        <mesh filename="../assemblies/left_3R+RH5_leg/meshes/left_ank_rr_link_2_collision.stl" />        
      </geometry>      
    </collision>    
    <inertial>      
      <origin xyz="3.4593503690046918534e-05 -0.0062999445222072132655 -0.0018999999999999986951" rpy="0 0 0" />      
      <mass value="0.00044289790445047673732" />      
      <inertia ixx="9.089475500483527331e-09" ixy="5.6689994077039857264e-11" ixz="-1.0879024115046995471e-14" iyy="8.3785129146959922129e-09" iyz="2.9873436245068874165e-33" izz="1.3107013728801491474e-08" />      
    </inertial>    
  </link>  

  <link name="12lf_rod_end_2">    
    <visual>      
      <origin xyz="0 0 0" rpy="0 -0 0" />      
      <geometry>        
        <mesh filename="../assemblies/left_3R+RH5_leg/meshes/left_12lf_rod_end_2_visual.stl" />        
      </geometry>      
      <material name="12lf_rod_end_2_material">        
        <color rgba="0.92771758928836534075 0.61049283053223002415 0.2184765849058516729 1.0" />        
      </material>      
    </visual>    
    <collision>      
      <origin xyz="0 0 0" rpy="0 -0 0" />      
      <geometry>        
        <mesh filename="../assemblies/left_3R+RH5_leg/meshes/left_12lf_rod_end_2_collision.stl" />        
      </geometry>      
    </collision>    
    <inertial>      
      <origin xyz="-4.4735203354349371173e-11 0.003842218593824546502 -0.0020064384187209456482" rpy="0 0 0" />      
      <mass value="0.00085420491177815905965" />      
      <inertia ixx="1.1840985264406787394e-08" ixy="-2.0225978433757152935e-16" ixz="9.2606419955770456148e-16" iyy="3.3549621576797272272e-09" iyz="7.453563138182895547e-12" izz="1.2703522254419979925e-08" />      
    </inertial>    
  </link>  

  <joint name="left_ank_R22" type="revolute">    
    <origin xyz="0.0020999999999999977018 -0.0099999999999999811262 -0.0018999999999999919731" rpy="-1.570796326794896558 -1.4274442651028091955 -1.5707963267949247577" />    
    <parent link="ank_rr_link_2" />    
    <child link="12lf_rod_end_2" />    
    <axis xyz="0 0 1" />    
    <limit effort="1" velocity="20" lower="-1.570796326794896558" upper="1.570796326794896558" />    
    <joint_properties friction="0.0" />    
  </joint>  

  <joint name="left_ank_R12" type="revolute">    
    <origin xyz="0.010000000000000001943 0.012499999999999955591 -0.028000000000000004052" rpy="3.1415926535897895633 4.4869794467973275651e-15 -3.0395375511758455644" />    
    <parent link="ank_roll_link" />    
    <child link="ank_rr_link_2" />    
    <axis xyz="0 0 1" />    
    <limit effort="1" velocity="20" lower="-1.570796326794896558" upper="1.570796326794896558" />    
    <joint_properties friction="0.0" />    
  </joint>  

  <joint name="left_ank_roll" type="revolute">    
    <origin xyz="3.8857805861880478915e-16 -0.0060999999999999795705 -0.014599999999999386038" rpy="-1.5707963267948443775 -1.5707963267947531172 0" />    
    <parent link="ank_pitch_link" />    
    <child link="ank_roll_link" />    
    <axis xyz="0 0 1" />    
    <limit effort="1" velocity="20" lower="-1.570796326794896558" upper="1.570796326794896558" />    
    <joint_properties friction="0.0" />    
  </joint>  

  <joint name="left_ank_pitch" type="revolute">    
    <origin xyz="1.423878333410664658e-18 -0.10000000000000000555 -0.0061999999999999989148" rpy="-3.1415926535897842342 8.6597395925459892621e-15 -1.5707963267949183184" />    
    <parent link="left_calf_link" />    
    <child link="ank_pitch_link" />    
    <axis xyz="0 0 1" />    
    <limit effort="1" velocity="20" lower="-1.570796326794896558" upper="1.570796326794896558" />    
    <joint_properties friction="0.0" />    
  </joint>  

  <link name="ball_joint_container">    
    <visual>      
      <origin xyz="0 0 0" rpy="0 -0 0" />      
      <geometry>        
        <mesh filename="../assemblies/left_3R+RH5_leg/meshes/left_ball_joint_container_visual.stl" />        
      </geometry>      
      <material name="ball_joint_container_material">        
        <color rgba="0.61568627450980395466 0.81176470588235294379 0.92941176470588238168 1.0" />        
      </material>      
    </visual>    
    <collision>      
      <origin xyz="0 0 0" rpy="0 -0 0" />      
      <geometry>        
        <mesh filename="../assemblies/left_3R+RH5_leg/meshes/left_ball_joint_container_collision.stl" />        
      </geometry>      
    </collision>    
    <inertial>      
      <origin xyz="4.7221442975711524242e-19 2.7634000224781994773e-17 -0.0097125341669083431473" rpy="0 0 0" />      
      <mass value="4.803735642533054869e-05" />      
      <inertia ixx="7.1865480628741666366e-10" ixy="2.2082883359209331434e-26" ixz="-6.7686126584238005107e-39" iyy="8.475420427718555978e-10" iyz="4.0476499960716035532e-39" izz="1.8625314111651911712e-10" />      
    </inertial>    
  </link>  

  <link name="ball_joint_ball">    
    <visual>      
      <origin xyz="0 0 0" rpy="0 -0 0" />      
      <geometry>        
        <mesh filename="../assemblies/left_3R+RH5_leg/meshes/left_ball_joint_ball_visual.stl" />        
      </geometry>      
      <material name="ball_joint_ball_material">        
        <color rgba="0.3291302810242056065 0.44310466418644928188 0.69204871161977121741 1.0" />        
      </material>      
    </visual>    
    <collision>      
      <origin xyz="0 0 0" rpy="0 -0 0" />      
      <geometry>        
        <mesh filename="../assemblies/left_3R+RH5_leg/meshes/left_ball_joint_ball_collision.stl" />        
      </geometry>      
    </collision>    
    <inertial>      
      <origin xyz="-3.5282352022158340034e-17 -0.0010308669810015907986 3.4484745656648436569e-20" rpy="0 0 0" />      
      <mass value="4.4053796295264630609e-05" />      
      <inertia ixx="3.1285011349692468636e-10" ixy="1.1835109023980632545e-25" ixz="1.2294513601043791409e-24" iyy="6.2569568612794312656e-11" iyz="-1.4479264606251061365e-24" izz="3.1285321460375216736e-10" />      
    </inertial>    
  </link>  

  <link name="12lf">    
    <visual>      
      <origin xyz="0 0 0" rpy="0 -0 0" />      
      <geometry>        
        <mesh filename="../assemblies/left_3R+RH5_leg/meshes/left_12lf_visual.stl" />        
      </geometry>      
      <material name="12lf_material">        
        <color rgba="0.62004392100736027693 0.58836684613512635345 0.49897069021535678246 1.0" />        
      </material>      
    </visual>    
    <collision>      
      <origin xyz="0 0 0" rpy="0 -0 0" />      
      <geometry>        
        <mesh filename="../assemblies/left_3R+RH5_leg/meshes/left_12lf_collision.stl" />        
      </geometry>      
    </collision>    
    <inertial>      
      <origin xyz="0.0049084207243747877275 -0.00013802439943545668035 -0.02994700357716128386" rpy="0 0 0" />      
      <mass value="0.044782197696050352054" />      
      <inertia ixx="1.5260128421323247559e-05" ixy="2.2955773687025559146e-08" ixz="-8.1364204003970836231e-08" iyy="1.8188469778964219811e-05" iyz="-5.5542240843071426163e-08" izz="5.1496273901760187844e-06" />      
    </inertial>    
  </link>  

  <link name="12lf_rod">    
    <visual>      
      <origin xyz="0 0 0" rpy="0 -0 0" />      
      <geometry>        
        <mesh filename="../assemblies/left_3R+RH5_leg/meshes/left_12lf_rod_visual.stl" />        
      </geometry>      
      <material name="12lf_rod_material">        
        <color rgba="0.80250260812861884396 0.89340612183512713163 0.94491811293548189088 1.0" />        
      </material>      
    </visual>    
    <collision>      
      <origin xyz="0 0 0" rpy="0 -0 0" />      
      <geometry>        
        <mesh filename="../assemblies/left_3R+RH5_leg/meshes/left_12lf_rod_collision.stl" />        
      </geometry>      
    </collision>    
    <inertial>      
      <origin xyz="-6.3222084040519468352e-07 4.6933255299399133793e-07 -0.012893387334328583124" rpy="0 0 0" />      
      <mass value="0.0025088292483592140175" />      
      <inertia ixx="2.6944521128622689806e-07" ixy="7.1389570311739639531e-15" ixz="1.3562243134246940151e-11" iyy="2.694452000167924539e-07" iyz="-1.0089988419950412744e-11" izz="1.7809843599861032107e-08" />      
    </inertial>    
  </link>  

  <joint name="left_ank_act1" type="prismatic">    
    <origin xyz="2.2722093549316056682e-06 9.9920072216264088638e-16 -0.072674213012071053885" rpy="-3.1415926535896594451 9.2998178113314070509e-14 -2.2021168238262620598" />    
    <parent link="12lf" />    
    <child link="12lf_rod" />    
    <axis xyz="0 0 1" />    
    <limit effort="1" velocity="20" lower="0" upper="0.040000000000000000833" />    
    <joint_properties friction="0.0" />    
  </joint>  

  <joint name="left_ank_B31" type="revolute">    
    <origin xyz="-8.0794745893619790422e-16 -0.0064387505004003531273 0" rpy="-1.5707963267948918951 -0.0053985248584601302699 -5.6469137085305582343e-15" />    
    <parent link="ball_joint_ball" />    
    <child link="12lf" />    
    <axis xyz="0 0 1" />    
    <limit effort="1" velocity="20" lower="-0.785398163397448279" upper="0.785398163397448279" />    
    <joint_properties friction="0.0" />    
  </joint>  

  <joint name="left_ank_B21" type="revolute">    
    <origin xyz="0 2.7755575615628913511e-17 -0.01150000000000000154" rpy="1.570796326794896558 -1.4274442472644790492 1.5707963267949169861" />    
    <parent link="ball_joint_container" />    
    <child link="ball_joint_ball" />    
    <axis xyz="0 0 1" />    
    <limit effort="1" velocity="20" lower="-0.785398163397448279" upper="0.785398163397448279" />    
    <joint_properties friction="0.0" />    
  </joint>  

  <joint name="left_ank_B11" type="revolute">    
    <origin xyz="0.0079999999999999966971 -0.015000000000000068834 0.028299999999999995298" rpy="-1.5707963267948998887 1.4686187149912932615 1.5707963267948792385" />    
    <parent link="left_calf_link" />    
    <child link="ball_joint_container" />    
    <axis xyz="0 0 1" />    
    <limit effort="1" velocity="20" lower="-0.785398163397448279" upper="0.785398163397448279" />    
    <joint_properties friction="0.0" />    
  </joint>  

  <link name="ball_joint_container_2">    
    <visual>      
      <origin xyz="0 0 0" rpy="0 -0 0" />      
      <geometry>        
        <mesh filename="../assemblies/left_3R+RH5_leg/meshes/left_ball_joint_container_2_visual.stl" />        
      </geometry>      
      <material name="ball_joint_container_2_material">        
        <color rgba="0.61568627450980395466 0.81176470588235294379 0.92941176470588238168 1.0" />        
      </material>      
    </visual>    
    <collision>      
      <origin xyz="0 0 0" rpy="0 -0 0" />      
      <geometry>        
        <mesh filename="../assemblies/left_3R+RH5_leg/meshes/left_ball_joint_container_2_collision.stl" />        
      </geometry>      
    </collision>    
    <inertial>      
      <origin xyz="7.4111083336642996126e-18 -1.2157539084692978797e-19 -0.0097125341669083414126" rpy="0 0 0" />      
      <mass value="4.803735642533054869e-05" />      
      <inertia ixx="7.1865480628741666366e-10" ixy="1.7106140620783207512e-26" ixz="-2.370982448080810868e-39" iyy="8.475420427718555978e-10" iyz="-2.1088730165263217349e-39" izz="1.8625314111651911712e-10" />      
    </inertial>    
  </link>  

  <link name="ball_joint_ball_2">    
    <visual>      
      <origin xyz="0 0 0" rpy="0 -0 0" />      
      <geometry>        
        <mesh filename="../assemblies/left_3R+RH5_leg/meshes/left_ball_joint_ball_2_visual.stl" />        
      </geometry>      
      <material name="ball_joint_ball_2_material">        
        <color rgba="0.3291302810242056065 0.44310466418644928188 0.69204871161977121741 1.0" />        
      </material>      
    </visual>    
    <collision>      
      <origin xyz="0 0 0" rpy="0 -0 0" />      
      <geometry>        
        <mesh filename="../assemblies/left_3R+RH5_leg/meshes/left_ball_joint_ball_2_collision.stl" />        
      </geometry>      
    </collision>    
    <inertial>      
      <origin xyz="-3.8652799292757674415e-18 -0.0010308669810016077122 3.2017676601678189468e-20" rpy="0 0 0" />      
      <mass value="4.4053796295264630609e-05" />      
      <inertia ixx="3.1285011349692153273e-10" ixy="-5.4813875806817626912e-27" ixz="-5.586774544550461194e-26" iyy="6.2569568612794881343e-11" iyz="3.2615028123775678149e-25" izz="3.1285321460376069766e-10" />      
    </inertial>    
  </link>  

  <link name="12lf_2">    
    <visual>      
      <origin xyz="0 0 0" rpy="0 -0 0" />      
      <geometry>        
        <mesh filename="../assemblies/left_3R+RH5_leg/meshes/left_12lf_2_visual.stl" />        
      </geometry>      
      <material name="12lf_2_material">        
        <color rgba="0.62004392100736005489 0.58836684613512635345 0.49897069021535678246 1.0" />        
      </material>      
    </visual>    
    <collision>      
      <origin xyz="0 0 0" rpy="0 -0 0" />      
      <geometry>        
        <mesh filename="../assemblies/left_3R+RH5_leg/meshes/left_12lf_2_collision.stl" />        
      </geometry>      
    </collision>    
    <inertial>      
      <origin xyz="0.0049084207243677924551 -0.00013802439943763140017 -0.029947003577159750365" rpy="0 0 0" />      
      <mass value="0.044782197696050352054" />      
      <inertia ixx="1.5260128421322254836e-05" ixy="2.2955773686926383499e-08" ixz="-8.1364204006927047391e-08" iyy="1.8188469778964612834e-05" iyz="-5.5542240844196491057e-08" izz="5.1496273901774545053e-06" />      
    </inertial>    
  </link>  

  <link name="12lf_rod_2">    
    <visual>      
      <origin xyz="0 0 0" rpy="0 -0 0" />      
      <geometry>        
        <mesh filename="../assemblies/left_3R+RH5_leg/meshes/left_12lf_rod_2_visual.stl" />        
      </geometry>      
      <material name="12lf_rod_2_material">        
        <color rgba="0.80250260812861884396 0.89340612183512713163 0.94491811293548189088 1.0" />        
      </material>      
    </visual>    
    <collision>      
      <origin xyz="0 0 0" rpy="0 -0 0" />      
      <geometry>        
        <mesh filename="../assemblies/left_3R+RH5_leg/meshes/left_12lf_rod_2_collision.stl" />        
      </geometry>      
    </collision>    
    <inertial>      
      <origin xyz="-6.3222083693631249078e-07 4.6933255239442584248e-07 -0.012893387334329466098" rpy="0 0 0" />      
      <mass value="0.0025088292483592140175" />      
      <inertia ixx="2.694452112861764996e-07" ixy="7.1389570082051159166e-15" ixz="1.3562243032822788726e-11" iyy="2.6944520001674194956e-07" iyz="-1.0089988402347216056e-11" izz="1.7809843599861002329e-08" />      
    </inertial>    
  </link>  

  <joint name="left_ank_act2" type="prismatic">    
    <origin xyz="2.2722093494268943981e-06 -6.6960326172704753844e-15 -0.072674224000365938991" rpy="-3.1415926535895000171 6.1912461081019981423e-14 -2.2021168238262793793" />    
    <parent link="12lf_2" />    
    <child link="12lf_rod_2" />    
    <axis xyz="0 0 1" />    
    <limit effort="1" velocity="20" lower="0" upper="0.040000000000000000833" />    
    <joint_properties friction="0.0" />    
  </joint>  

  <joint name="left_ank_B32" type="revolute">    
    <origin xyz="-1.8214596497756474491e-17 -0.0064387505004002976161 0" rpy="-1.570796326794896558 -0.0053985248584149493969 -1.0409444774216770496e-15" />    
    <parent link="ball_joint_ball_2" />    
    <child link="12lf_2" />    
    <axis xyz="0 0 1" />    
    <limit effort="1" velocity="20" lower="-0.785398163397448279" upper="0.785398163397448279" />    
    <joint_properties friction="0.0" />    
  </joint>  

  <joint name="left_ank_B22" type="revolute">    
    <origin xyz="6.9388939039072283776e-18 0 -0.011500000000000003275" rpy="1.570796326794896558 -1.4274442651030925244 -1.5707963267949058839" />    
    <parent link="ball_joint_container_2" />    
    <child link="ball_joint_ball_2" />    
    <axis xyz="0 0 1" />    
    <limit effort="1" velocity="20" lower="-0.785398163397448279" upper="0.785398163397448279" />    
    <joint_properties friction="0.0" />    
  </joint>  

  <joint name="left_ank_B12" type="revolute">    
    <origin xyz="0.0080000000000000019013 -0.015000000000000013323 -0.011499999999999996336" rpy="-1.570796326794896558 -1.4687412243796080791 1.5707963267949098807" />    
    <parent link="left_calf_link" />    
    <child link="ball_joint_container_2" />    
    <axis xyz="0 0 1" />    
    <limit effort="1" velocity="20" lower="-0.785398163397448279" upper="0.785398163397448279" />    
    <joint_properties friction="0.0" />    
  </joint>  

  <joint name="left_knee" type="revolute">    
    <origin xyz="-3.1353220349901300315e-15 0.095999999999999724443 0.027399999999999993805" rpy="-3.1415926535897926719 -2.5420496495350503733e-17 4.2811095712787448488e-16" />    
    <parent link="left_hip_pitch_link" />    
    <child link="left_calf_link" />    
    <axis xyz="0 0 1" />    
    <limit effort="1" velocity="20" lower="-1.570796326794896558" upper="2.2689280275926284602" />    
    <joint_properties friction="0.0" />    
  </joint>  

  <joint name="left_hip_pitch" type="revolute">    
    <origin xyz="-0.024000000716150882152 -0.019000000152441572782 -0.019000000152448091872" rpy="-1.5707963267945472818 1.5707963267948001906 0" />    
    <parent link="hip_roll_link" />    
    <child link="left_hip_pitch_link" />    
    <axis xyz="0 0 1" />    
    <limit effort="1" velocity="20" lower="-1.570796326794896558" upper="1.570796326794896558" />    
    <joint_properties friction="0.0" />    
  </joint>  

  <joint name="left_hip_roll" type="revolute">    
    <origin xyz="0.019000000000000304839 -3.3624037938353715663e-18 -0.026000000000000279832" rpy="3.141592653589793116 -1.5707963267948512609 0" />    
    <parent link="hip_yaw_link" />    
    <child link="hip_roll_link" />    
    <axis xyz="0 0 1" />    
    <limit effort="1" velocity="20" lower="-1.570796326794896558" upper="1.570796326794896558" />    
    <joint_properties friction="0.0" />    
  </joint>  


<link name="hip_yaw_link_2">    
    <visual>      
      <origin xyz="0 0 0" rpy="0 -0 0" />      
      <geometry>        
        <mesh filename="../assemblies/right_3R+RH5_leg/meshes/right_hip_yaw_link_visual.stl" />        
      </geometry>      
      <material name="hip_yaw_link_material">        
        <color rgba="0.61568627450980395466 0.81176470588235294379 0.92941176470588238168 1.0" />        
      </material>      
    </visual>    
    <collision>      
      <origin xyz="0 0 0" rpy="0 -0 0" />      
      <geometry>        
        <mesh filename="../assemblies/right_3R+RH5_leg/meshes/right_hip_yaw_link_collision.stl" />        
      </geometry>      
    </collision>    
    <inertial>      
      <origin xyz="-5.510178923048878203e-19 -4.987496519704591217e-19 -0.0098390489054829086829" rpy="0 0 0" />      
      <mass value="0.0090258837370979175946" />      
      <inertia ixx="1.3230458239085876461e-06" ixy="-6.4778545919079861077e-49" ixz="1.7322911775161985632e-33" iyy="3.8408510960330541809e-06" iyz="-1.4482241779965781819e-32" izz="3.8721396285793077728e-06" />      
    </inertial>    
  </link>  

  <link name="hip_roll_link_2">    
    <visual>      
      <origin xyz="0 0 0" rpy="0 -0 0" />      
      <geometry>        
        <mesh filename="../assemblies/right_3R+RH5_leg/meshes/right_hip_roll_link_visual.stl" />        
      </geometry>      
      <material name="hip_roll_link_material">        
        <color rgba="0.95018735644455853961 0.70678927200428420807 0.061612079402596685307 1.0" />        
      </material>      
    </visual>    
    <collision>      
      <origin xyz="0 0 0" rpy="0 -0 0" />      
      <geometry>        
        <mesh filename="../assemblies/right_3R+RH5_leg/meshes/right_hip_roll_link_collision.stl" />        
      </geometry>      
    </collision>    
    <inertial>      
      <origin xyz="-0.012000151133960919314 -0.00049588831385676847546 -0.018504019244507452502" rpy="0 0 0" />      
      <mass value="0.09801239148352869357" />      
      <inertia ixx="2.0221748766307408535e-05" ixy="-4.1552068245398715061e-08" ixz="-4.1225592188036487205e-08" iyy="2.7358099958307688013e-05" iyz="-5.0935731752404828431e-07" izz="2.7358069524724229097e-05" />      
    </inertial>    
  </link>  

  <link name="right_hip_pitch_link">    
    <visual>      
      <origin xyz="0 0 0" rpy="0 -0 0" />      
      <geometry>        
        <mesh filename="../assemblies/right_3R+RH5_leg/meshes/right_hip_pitch_link_visual.stl" />        
      </geometry>      
      <material name="right_hip_pitch_link_material">        
        <color rgba="0.61653602500441606615 0.80730351578563952497 0.92176401025437348924 1.0" />        
      </material>      
    </visual>    
    <collision>      
      <origin xyz="0 0 0" rpy="0 -0 0" />      
      <geometry>        
        <mesh filename="../assemblies/right_3R+RH5_leg/meshes/right_hip_pitch_link_collision.stl" />        
      </geometry>      
    </collision>    
    <inertial>      
      <origin xyz="-1.4736411322153065889e-05 0.053000236016731046285 0.014794280397379757502" rpy="0 0 0" />      
      <mass value="0.094115687342860077091" />      
      <inertia ixx="6.3163835686947151387e-05" ixy="-2.2047071660339153482e-07" ixz="-1.2737388563441184458e-08" iyy="2.1771096480162823193e-05" iyz="-1.4946567837312502088e-06" izz="6.287681122623721224e-05" />      
    </inertial>    
  </link>  

  <link name="right_calf_link">    
    <visual>      
      <origin xyz="0 0 0" rpy="0 -0 0" />      
      <geometry>        
        <mesh filename="../assemblies/right_3R+RH5_leg/meshes/right_calf_link_visual.stl" />        
      </geometry>      
      <material name="right_calf_link_material">        
        <color rgba="0.55182153444277581844 0.72936705907288057471 0.87615824804808439819 1.0" />        
      </material>      
    </visual>    
    <collision>      
      <origin xyz="0 0 0" rpy="0 -0 0" />      
      <geometry>        
        <mesh filename="../assemblies/right_3R+RH5_leg/meshes/right_calf_link_collision.stl" />        
      </geometry>      
    </collision>    
    <inertial>      
      <origin xyz="-0.0038784271883378156585 0.043110179744828905357 0.0081688793093392352007" rpy="0 0 0" />      
      <mass value="0.016616299594005391055" />      
      <inertia ixx="1.5958223723938059054e-05" ixy="2.2918216583122541662e-07" ixz="5.9933409326354422155e-09" iyy="2.0657984790181373815e-06" iyz="-2.8480740343858780691e-08" izz="1.5100763145605022869e-05" />      
    </inertial>    
  </link>  

  <link name="ank_pitch_link_2">    
    <visual>      
      <origin xyz="0 0 0" rpy="0 -0 0" />      
      <geometry>        
        <mesh filename="../assemblies/right_3R+RH5_leg/meshes/right_ank_pitch_link_visual.stl" />        
      </geometry>      
      <material name="ank_pitch_link_material">        
        <color rgba="0.63189161126160275916 0.72668668793540891482 0.78356373393969258601 1.0" />        
      </material>      
    </visual>    
    <collision>      
      <origin xyz="0 0 0" rpy="0 -0 0" />      
      <geometry>        
        <mesh filename="../assemblies/right_3R+RH5_leg/meshes/right_ank_pitch_link_collision.stl" />        
      </geometry>      
    </collision>    
    <inertial>      
      <origin xyz="4.0269687825142352267e-08 0.00059528282566478787994 -0.014599922383890177879" rpy="0 0 0" />      
      <mass value="0.0042238381753791605713" />      
      <inertia ixx="4.370525406738890516e-07" ixy="1.6834346645318040744e-13" ixz="1.6428822743379449777e-12" iyy="3.9782741364654707327e-07" iyz="2.0919211866995821085e-14" izz="8.8858574534508976078e-08" />      
    </inertial>    
  </link>  

  <link name="ank_roll_link_2">    
    <visual>      
      <origin xyz="0 0 0" rpy="0 -0 0" />      
      <geometry>        
        <mesh filename="../assemblies/right_3R+RH5_leg/meshes/right_ank_roll_link_visual.stl" />        
      </geometry>      
      <material name="ank_roll_link_material">        
        <color rgba="0.61568627450980395466 0.81176470588235294379 0.92941176470588238168 1.0" />        
      </material>      
    </visual>    
    <collision>      
      <origin xyz="0 0 0" rpy="0 -0 0" />      
      <geometry>        
        <mesh filename="../assemblies/right_3R+RH5_leg/meshes/right_ank_roll_link_collision.stl" />        
      </geometry>      
    </collision>    
    <inertial>      
      <origin xyz="-6.3661537448889067673e-10 0.027240102316353712736 0.0019830147448535412162" rpy="0 0 0" />      
      <mass value="0.013844478784760248444" />      
      <inertia ixx="1.0150902309234939295e-05" ixy="6.8603302694880868029e-14" ixz="-3.2605547317656671208e-13" iyy="8.66361166634314672e-06" iyz="-7.8151778926544996072e-07" izz="2.8991570356470419231e-06" />      
    </inertial>    
  </link>  

  <link name="ank_rr_link_3">    
    <visual>      
      <origin xyz="0 0 0" rpy="0 -0 0" />      
      <geometry>        
        <mesh filename="../assemblies/right_3R+RH5_leg/meshes/right_ank_rr_link_visual.stl" />        
      </geometry>      
      <material name="ank_rr_link_material">        
        <color rgba="0.61568627450980395466 0.81176470588235294379 0.92941176470588238168 1.0" />        
      </material>      
    </visual>    
    <collision>      
      <origin xyz="0 0 0" rpy="0 -0 0" />      
      <geometry>        
        <mesh filename="../assemblies/right_3R+RH5_leg/meshes/right_ank_rr_link_collision.stl" />        
      </geometry>      
    </collision>    
    <inertial>      
      <origin xyz="3.4593503690053721902e-05 0.0062999445222072123982 -0.0018999999999999991288" rpy="0 0 0" />      
      <mass value="0.00044289790445047673732" />      
      <inertia ixx="9.0894755004835306397e-09" ixy="-5.6689994077040238543e-11" ixz="1.0879024115046998627e-14" iyy="8.3785129146959889042e-09" iyz="-2.2791699818292878737e-31" izz="1.3107013728801491474e-08" />      
    </inertial>    
  </link>  

  <link name="12lf_rod_end_3">    
    <visual>      
      <origin xyz="0 0 0" rpy="0 -0 0" />      
      <geometry>        
        <mesh filename="../assemblies/right_3R+RH5_leg/meshes/right_12lf_rod_end_visual.stl" />        
      </geometry>      
      <material name="12lf_rod_end_material">        
        <color rgba="0.92771758928836534075 0.61049283053223002415 0.2184765849058516729 1.0" />        
      </material>      
    </visual>    
    <collision>      
      <origin xyz="0 0 0" rpy="0 -0 0" />      
      <geometry>        
        <mesh filename="../assemblies/right_3R+RH5_leg/meshes/right_12lf_rod_end_collision.stl" />        
      </geometry>      
    </collision>    
    <inertial>      
      <origin xyz="-4.4735193531056495841e-11 0.0038422185938246015795 -0.0020064384187209387093" rpy="0 0 0" />      
      <mass value="0.00085420491177815905965" />      
      <inertia ixx="1.1840985264406790703e-08" ixy="-2.0225977890592725469e-16" ixz="9.2606419958118382304e-16" iyy="3.3549621576797276408e-09" iyz="7.4535631381827210636e-12" izz="1.2703522254419981579e-08" />      
    </inertial>    
  </link>  

  <joint name="right_ank_R21" type="revolute">    
    <origin xyz="0.0020999999999992344235 0.010000000000000036637 -0.0019000000000000127898" rpy="-1.570796326794896558 1.4274442472646977631 -1.570796326794901665" />    
    <parent link="ank_rr_link_3" />    
    <child link="12lf_rod_end_3" />    
    <axis xyz="0 0 1" />    
    <limit effort="1" velocity="20" lower="-1.570796326794896558" upper="1.570796326794896558" />    
    <joint_properties friction="0.0" />    
  </joint>  

  <joint name="right_ank_R11" type="revolute">    
    <origin xyz="-0.010000000000000165007 0.012500000000000260902 -0.027999999999999313632" rpy="-3.1415926535897926719 -6.3673174173468030794e-17 -0.102177611803432003" />    
    <parent link="ank_roll_link_2" />    
    <child link="ank_rr_link_3" />    
    <axis xyz="0 0 1" />    
    <limit effort="1" velocity="20" lower="-1.570796326794896558" upper="1.570796326794896558" />    
    <joint_properties friction="0.0" />    
  </joint>  

  <link name="ank_rr_link_4">    
    <visual>      
      <origin xyz="0 0 0" rpy="0 -0 0" />      
      <geometry>        
        <mesh filename="../assemblies/right_3R+RH5_leg/meshes/right_ank_rr_link_2_visual.stl" />        
      </geometry>      
      <material name="ank_rr_link_2_material">        
        <color rgba="0.61568627450980395466 0.81176470588235294379 0.92941176470588238168 1.0" />        
      </material>      
    </visual>    
    <collision>      
      <origin xyz="0 0 0" rpy="0 -0 0" />      
      <geometry>        
        <mesh filename="../assemblies/right_3R+RH5_leg/meshes/right_ank_rr_link_2_collision.stl" />        
      </geometry>      
    </collision>    
    <inertial>      
      <origin xyz="3.4593503690053843875e-05 -0.006299944522207156887 -0.0018999999999999986951" rpy="0 0 0" />      
      <mass value="0.00044289790445047673732" />      
      <inertia ixx="9.089475500483527331e-09" ixy="5.6689994077039947737e-11" ixz="-1.0879024115046995471e-14" iyy="8.3785129146959889042e-09" iyz="-8.3643934089884858692e-32" izz="1.3107013728801491474e-08" />      
    </inertial>    
  </link>  

  <link name="12lf_rod_end_4">    
    <visual>      
      <origin xyz="0 0 0" rpy="0 -0 0" />      
      <geometry>        
        <mesh filename="../assemblies/right_3R+RH5_leg/meshes/right_12lf_rod_end_2_visual.stl" />        
      </geometry>      
      <material name="12lf_rod_end_2_material">        
        <color rgba="0.92771758928836534075 0.61049283053223013518 0.2184765849058516729 1.0" />        
      </material>      
    </visual>    
    <collision>      
      <origin xyz="0 0 0" rpy="0 -0 0" />      
      <geometry>        
        <mesh filename="../assemblies/right_3R+RH5_leg/meshes/right_12lf_rod_end_2_collision.stl" />        
      </geometry>      
    </collision>    
    <inertial>      
      <origin xyz="-4.4735191827234303275e-11 0.0038422185938245738239 -0.0020064384187209456482" rpy="0 0 0" />      
      <mass value="0.00085420491177815905965" />      
      <inertia ixx="1.1840985264406785739e-08" ixy="-2.022597816344526657e-16" ixz="9.2606419971116108173e-16" iyy="3.3549621576797264e-09" iyz="7.4535631381825174997e-12" izz="1.2703522254419979925e-08" />      
    </inertial>    
  </link>  

  <joint name="right_ank_R22" type="revolute">    
    <origin xyz="0.0021000000000000115796 -0.010000000000000008882 -0.001899999999999998912" rpy="-1.57079632679489678 -1.4274442651030334606 -1.5707963267948972241" />    
    <parent link="ank_rr_link_4" />    
    <child link="12lf_rod_end_4" />    
    <axis xyz="0 0 1" />    
    <limit effort="1" velocity="20" lower="-1.570796326794896558" upper="1.570796326794896558" />    
    <joint_properties friction="0.0" />    
  </joint>  

  <joint name="right_ank_R12" type="revolute">    
    <origin xyz="0.010000000000000003678 0.012499999999999983347 -0.028000000000000014461" rpy="3.141592653589793116 1.4948154307943495876e-16 -3.0395375511749724851" />    
    <parent link="ank_roll_link_2" />    
    <child link="ank_rr_link_4" />    
    <axis xyz="0 0 1" />    
    <limit effort="1" velocity="20" lower="-1.570796326794896558" upper="1.570796326794896558" />    
    <joint_properties friction="0.0" />    
  </joint>  

  <joint name="right_ank_roll" type="revolute">    
    <origin xyz="1.7763568394002504647e-15 -0.0061000000000006751946 -0.014600000000001986389" rpy="-1.5707963267949152097 1.5707963267947568919 0" />    
    <parent link="ank_pitch_link_2" />    
    <child link="ank_roll_link_2" />    
    <axis xyz="0 0 1" />    
    <limit effort="1" velocity="20" lower="-1.570796326794896558" upper="1.570796326794896558" />    
    <joint_properties friction="0.0" />    
  </joint>  

  <joint name="right_ank_pitch" type="revolute">    
    <origin xyz="6.9626594985130732316e-16 0.099999999999999644729 -0.006199999999999853198" rpy="-3.1415926535897891192 -1.0660034804367828672e-14 -1.5707963267948825692" />    
    <parent link="right_calf_link" />    
    <child link="ank_pitch_link_2" />    
    <axis xyz="0 0 1" />    
    <limit effort="1" velocity="20" lower="-1.570796326794896558" upper="1.570796326794896558" />    
    <joint_properties friction="0.0" />    
  </joint>  

  <link name="ball_joint_container_3">    
    <visual>      
      <origin xyz="0 0 0" rpy="0 -0 0" />      
      <geometry>        
        <mesh filename="../assemblies/right_3R+RH5_leg/meshes/right_ball_joint_container_visual.stl" />        
      </geometry>      
      <material name="ball_joint_container_material">        
        <color rgba="0.61568627450980395466 0.81176470588235294379 0.92941176470588238168 1.0" />        
      </material>      
    </visual>    
    <collision>      
      <origin xyz="0 0 0" rpy="0 -0 0" />      
      <geometry>        
        <mesh filename="../assemblies/right_3R+RH5_leg/meshes/right_ball_joint_container_collision.stl" />        
      </geometry>      
    </collision>    
    <inertial>      
      <origin xyz="4.7221442975713479061e-19 -1.2157539084691849721e-19 -0.0097125341669083414126" rpy="0 0 0" />      
      <mass value="4.803735642533054869e-05" />      
      <inertia ixx="7.1865480628741666366e-10" ixy="8.7468747923266868859e-27" ixz="-1.0147356603452870718e-38" iyy="8.475420427718555978e-10" iyz="5.4451688879992596442e-39" izz="1.8625314111651911712e-10" />      
    </inertial>    
  </link>  

  <link name="ball_joint_ball_3">    
    <visual>      
      <origin xyz="0 0 0" rpy="0 -0 0" />      
      <geometry>        
        <mesh filename="../assemblies/right_3R+RH5_leg/meshes/right_ball_joint_ball_visual.stl" />        
      </geometry>      
      <material name="ball_joint_ball_material">        
        <color rgba="0.3291302810242056065 0.44310466418644928188 0.69204871161977121741 1.0" />        
      </material>      
    </visual>    
    <collision>      
      <origin xyz="0 0 0" rpy="0 -0 0" />      
      <geometry>        
        <mesh filename="../assemblies/right_3R+RH5_leg/meshes/right_ball_joint_ball_collision.stl" />        
      </geometry>      
    </collision>    
    <inertial>      
      <origin xyz="2.2663090322936730893e-18 -0.0010308669810016072785 -1.2451330920679759834e-17" rpy="0 0 0" />      
      <mass value="4.4053796295264630609e-05" />      
      <inertia ixx="3.1285011349692391087e-10" ixy="9.0806338731792162566e-26" ixz="-1.4814569422744550504e-27" iyy="6.2569568612795540503e-11" iyz="-9.0725496754301873347e-26" izz="3.1285321460376255882e-10" />      
    </inertial>    
  </link>  

  <link name="12lf_3">    
    <visual>      
      <origin xyz="0 0 0" rpy="0 -0 0" />      
      <geometry>        
        <mesh filename="../assemblies/right_3R+RH5_leg/meshes/right_12lf_visual.stl" />        
      </geometry>      
      <material name="12lf_material">        
        <color rgba="0.62004392100736016591 0.58836684613512635345 0.49897069021535672695 1.0" />        
      </material>      
    </visual>    
    <collision>      
      <origin xyz="0 0 0" rpy="0 -0 0" />      
      <geometry>        
        <mesh filename="../assemblies/right_3R+RH5_leg/meshes/right_12lf_collision.stl" />        
      </geometry>      
    </collision>    
    <inertial>      
      <origin xyz="0.0049084207243671419338 -0.00013802439943487768929 -0.029947003577148141595" rpy="0 0 0" />      
      <mass value="0.044782197696050352054" />      
      <inertia ixx="1.5260128421313266122e-05" ixy="2.2955773686476771131e-08" ixz="-8.1364204007546559348e-08" iyy="1.8188469778952507039e-05" iyz="-5.5542240842735795975e-08" izz="5.14962739017425865e-06" />      
    </inertial>    
  </link>  

  <link name="12lf_rod_3">    
    <visual>      
      <origin xyz="0 0 0" rpy="0 -0 0" />      
      <geometry>        
        <mesh filename="../assemblies/right_3R+RH5_leg/meshes/right_12lf_rod_visual.stl" />        
      </geometry>      
      <material name="12lf_rod_material">        
        <color rgba="0.80250260812861884396 0.89340612183512713163 0.94491811293548189088 1.0" />        
      </material>      
    </visual>    
    <collision>      
      <origin xyz="0 0 0" rpy="0 -0 0" />      
      <geometry>        
        <mesh filename="../assemblies/right_3R+RH5_leg/meshes/right_12lf_rod_collision.stl" />        
      </geometry>      
    </collision>    
    <inertial>      
      <origin xyz="-6.3222084033089920026e-07 4.6933255135528111117e-07 -0.01289338733433115225" rpy="0 0 0" />      
      <mass value="0.0025088292483592140175" />      
      <inertia ixx="2.6944521128608443771e-07" ixy="7.1389570292485185665e-15" ixz="1.3562243131395616268e-11" iyy="2.6944520001664999355e-07" iyz="-1.0089988374103258441e-11" izz="1.7809843599861015564e-08" />      
    </inertial>    
  </link>  

  <joint name="right_ank_act1" type="prismatic">    
    <origin xyz="2.2722093427881076555e-06 1.3183898417423733918e-15 -0.072674213012081267937" rpy="-3.1415926535897806815 9.5856772270727916853e-15 -2.2021168238260924177" />    
    <parent link="12lf_3" />    
    <child link="12lf_rod_3" />    
    <axis xyz="0 0 1" />    
    <limit effort="1" velocity="20" lower="0" upper="0.040000000000000000833" />    
    <joint_properties friction="0.0" />    
  </joint>  

  <joint name="right_ank_B31" type="revolute">    
    <origin xyz="8.2399365108898336985e-18 -0.006438750500400436394 2.5673907444456744997e-16" rpy="-1.570796326794896558 -0.0053985248578861414967 1.6676878818581557235e-16" />    
    <parent link="ball_joint_ball_3" />    
    <child link="12lf_3" />    
    <axis xyz="0 0 1" />    
    <limit effort="1" velocity="20" lower="-0.785398163397448279" upper="0.785398163397448279" />    
    <joint_properties friction="0.0" />    
  </joint>  

  <joint name="right_ank_B21" type="revolute">    
    <origin xyz="0 0 -0.011499999999999996336" rpy="1.570796326794896558 -1.4274442472645434421 1.5707963267948954478" />    
    <parent link="ball_joint_container_3" />    
    <child link="ball_joint_ball_3" />    
    <axis xyz="0 0 1" />    
    <limit effort="1" velocity="20" lower="-0.785398163397448279" upper="0.785398163397448279" />    
    <joint_properties friction="0.0" />    
  </joint>  

  <joint name="right_ank_B11" type="revolute">    
    <origin xyz="0.008000000000000003636 0.015000000000000013323 -0.01150000000000000501" rpy="1.57079632679489678 -1.4686187149913361161 -1.5707963267948945596" />    
    <parent link="right_calf_link" />    
    <child link="ball_joint_container_3" />    
    <axis xyz="0 0 1" />    
    <limit effort="1" velocity="20" lower="-0.785398163397448279" upper="0.785398163397448279" />    
    <joint_properties friction="0.0" />    
  </joint>  

  <link name="ball_joint_container_4">    
    <visual>      
      <origin xyz="0 0 0" rpy="0 -0 0" />      
      <geometry>        
        <mesh filename="../assemblies/right_3R+RH5_leg/meshes/right_ball_joint_container_2_visual.stl" />        
      </geometry>      
      <material name="ball_joint_container_2_material">        
        <color rgba="0.61568627450980395466 0.81176470588235294379 0.92941176470588238168 1.0" />        
      </material>      
    </visual>    
    <collision>      
      <origin xyz="0 0 0" rpy="0 -0 0" />      
      <geometry>        
        <mesh filename="../assemblies/right_3R+RH5_leg/meshes/right_ball_joint_container_2_collision.stl" />        
      </geometry>      
    </collision>    
    <inertial>      
      <origin xyz="4.7221442975711206464e-19 2.7634000224782004017e-17 -0.0097125341669083431473" rpy="0 0 0" />      
      <mass value="4.803735642533054869e-05" />      
      <inertia ixx="7.1865480628741666366e-10" ixy="1.0252266721523252213e-26" ixz="-1.0860167223587451485e-38" iyy="8.475420427718555978e-10" iyz="-4.8393596154155851099e-39" izz="1.8625314111651911712e-10" />      
    </inertial>    
  </link>  

  <link name="ball_joint_ball_4">    
    <visual>      
      <origin xyz="0 0 0" rpy="0 -0 0" />      
      <geometry>        
        <mesh filename="../assemblies/right_3R+RH5_leg/meshes/right_ball_joint_ball_2_visual.stl" />        
      </geometry>      
      <material name="ball_joint_ball_2_material">        
        <color rgba="0.3291302810242056065 0.44310466418644928188 0.69204871161977121741 1.0" />        
      </material>      
    </visual>    
    <collision>      
      <origin xyz="0 0 0" rpy="0 -0 0" />      
      <geometry>        
        <mesh filename="../assemblies/right_3R+RH5_leg/meshes/right_ball_joint_ball_2_collision.stl" />        
      </geometry>      
    </collision>    
    <inertial>      
      <origin xyz="5.0941697801840291577e-18 -0.0010308669810016504297 -6.4729600917583919283e-18" rpy="0 0 0" />      
      <mass value="4.4053796295264630609e-05" />      
      <inertia ixx="3.1285011349692525504e-10" ixy="1.1319973206775294355e-25" ixz="-1.7080104132990967035e-27" iyy="6.2569568612795566352e-11" iyz="6.0489020233327418607e-26" izz="3.1285321460376421318e-10" />      
    </inertial>    
  </link>  

  <link name="12lf_4">    
    <visual>      
      <origin xyz="0 0 0" rpy="0 -0 0" />      
      <geometry>        
        <mesh filename="../assemblies/right_3R+RH5_leg/meshes/right_12lf_2_visual.stl" />        
      </geometry>      
      <material name="12lf_2_material">        
        <color rgba="0.62004392100736027693 0.58836684613512624242 0.49897069021535683797 1.0" />        
      </material>      
    </visual>    
    <collision>      
      <origin xyz="0 0 0" rpy="0 -0 0" />      
      <geometry>        
        <mesh filename="../assemblies/right_3R+RH5_leg/meshes/right_12lf_2_collision.stl" />        
      </geometry>      
    </collision>    
    <inertial>      
      <origin xyz="0.0049084207243654453742 -0.00013802439943710122531 -0.029947003577146649733" rpy="0 0 0" />      
      <mass value="0.044782197696050358993" />      
      <inertia ixx="1.5260128421312148039e-05" ixy="2.2955773686778089867e-08" ixz="-8.1364204008300008389e-08" iyy="1.8188469778949555977e-05" iyz="-5.5542240843716263081e-08" izz="5.1496273901724028008e-06" />      
    </inertial>    
  </link>  

  <link name="12lf_rod_4">    
    <visual>      
      <origin xyz="0 0 0" rpy="0 -0 0" />      
      <geometry>        
        <mesh filename="../assemblies/right_3R+RH5_leg/meshes/right_12lf_rod_2_visual.stl" />        
      </geometry>      
      <material name="12lf_rod_2_material">        
        <color rgba="0.80250260812861884396 0.89340612183512713163 0.94491811293548189088 1.0" />        
      </material>      
    </visual>    
    <collision>      
      <origin xyz="0 0 0" rpy="0 -0 0" />      
      <geometry>        
        <mesh filename="../assemblies/right_3R+RH5_leg/meshes/right_12lf_rod_2_collision.stl" />        
      </geometry>      
    </collision>    
    <inertial>      
      <origin xyz="-6.3222084084173862976e-07 4.6933255090074846154e-07 -0.012893387334333228714" rpy="0 0 0" />      
      <mass value="0.0025088292483592140175" />      
      <inertia ixx="2.6944521128596934711e-07" ixy="7.1389570314206959784e-15" ixz="1.3562243144867532088e-11" iyy="2.6944520001653485001e-07" iyz="-1.008998836117697971e-11" izz="1.7809843599861015564e-08" />      
    </inertial>    
  </link>  

  <joint name="right_ank_act2" type="prismatic">    
    <origin xyz="2.2722093417481409316e-06 -2.4008572907519010187e-15 -0.072674224000375264865" rpy="3.1415926535897922278 -4.7750794099672222252e-16 -2.2021168238262847083" />    
    <parent link="12lf_4" />    
    <child link="12lf_rod_4" />    
    <axis xyz="0 0 1" />    
    <limit effort="1" velocity="20" lower="0" upper="0.040000000000000000833" />    
    <joint_properties friction="0.0" />    
  </joint>  

  <joint name="right_ank_B32" type="revolute">    
    <origin xyz="1.0408340855860842566e-17 -0.006438750500400436394 0" rpy="-1.57079632679489678 -0.0053985248581224047626 2.4993140229822924443e-16" />    
    <parent link="ball_joint_ball_4" />    
    <child link="12lf_4" />    
    <axis xyz="0 0 1" />    
    <limit effort="1" velocity="20" lower="-0.785398163397448279" upper="0.785398163397448279" />    
    <joint_properties friction="0.0" />    
  </joint>  

  <joint name="right_ank_B22" type="revolute">    
    <origin xyz="-9.0205620750793968909e-17 -5.5511151231257827021e-16 -0.011500000000000809922" rpy="1.5707963267949021091 -1.4274442651029393136 1.5707963267948958919" />    
    <parent link="ball_joint_container_4" />    
    <child link="ball_joint_ball_4" />    
    <axis xyz="0 0 1" />    
    <limit effort="1" velocity="20" lower="-0.785398163397448279" upper="0.785398163397448279" />    
    <joint_properties friction="0.0" />    
  </joint>  

  <joint name="right_ank_B12" type="revolute">    
    <origin xyz="0.0079999999999990304561 0.015000000000000374145 0.028300000000000304079" rpy="-1.570796326794896558 -1.4687412243800435085 1.5707963267949029973" />    
    <parent link="right_calf_link" />    
    <child link="ball_joint_container_4" />    
    <axis xyz="0 0 1" />    
    <limit effort="1" velocity="20" lower="-0.785398163397448279" upper="0.785398163397448279" />    
    <joint_properties friction="0.0" />    
  </joint>  

  <joint name="right_knee" type="revolute">    
    <origin xyz="-2.4092426568589641265e-15 0.095999999999999835465 0.027399999999999306854" rpy="3.1415926535897913396 -1.687018580240030462e-16 3.1415926535897922278" />    
    <parent link="right_hip_pitch_link" />    
    <child link="right_calf_link" />    
    <axis xyz="0 0 1" />    
    <limit effort="1" velocity="20" lower="-1.570796326794896558" upper="1.570796326794896558" />    
    <joint_properties friction="0.0" />    
  </joint>  

  <joint name="right_hip_pitch" type="revolute">    
    <origin xyz="-0.024000000716145983293 -0.019000000152457983266 -0.019000000152453771357" rpy="-1.5707963267951818853 1.5707963267947633312 0" />    
    <parent link="hip_roll_link_2" />    
    <child link="right_hip_pitch_link" />    
    <axis xyz="0 0 1" />    
    <limit effort="1" velocity="20" lower="-1.570796326794896558" upper="1.570796326794896558" />    
    <joint_properties friction="0.0" />    
  </joint>  

  <joint name="right_hip_roll" type="revolute">    
    <origin xyz="-0.018999999999999881567 -3.3500438889881561489e-18 -0.026000000000000002276" rpy="-4.6567077935502810538e-31 -1.5707963267948825692 0" />    
    <parent link="hip_yaw_link_2" />    
    <child link="hip_roll_link_2" />    
    <axis xyz="0 0 1" />    
    <limit effort="1" velocity="20" lower="-1.570796326794896558" upper="1.570796326794896558" />    
    <joint_properties friction="0.0" />    
  </joint>  


</robot>