<?xml version="1.0" ?><robot name="left_leg_OP3">  
  <link name="hip_yaw_link">    
    <visual>      
      <origin xyz="0 0 0" rpy="0 -0 0"/>      
      <geometry>        
        <mesh filename="package:///meshes/left_hip_yaw_link_visual.stl"/>        
      </geometry>      
      <material name="hip_yaw_link_material">        
        <color rgba="0.61568627450980395466 0.81176470588235294379 0.92941176470588238168 1.0"/>        
      </material>      
    </visual>    
    <collision>      
      <origin xyz="0 0 0" rpy="0 -0 0"/>      
      <geometry>        
        <mesh filename="package:///meshes/left_hip_yaw_link_collision.stl"/>        
      </geometry>      
    </collision>    
    <inertial>      
      <origin xyz="6.2152911665081054125e-19 -2.7363625088509876237e-19 -0.0098919667346054462181" rpy="0 0 0"/>      
      <mass value="0.017999999999999995171"/>      
      <inertia ixx="2.6483505271519536081e-06" ixy="0" ixz="0" iyy="7.7055357996008251511e-06" iyz="0" izz="7.7736682806805358371e-06"/>      
    </inertial>    
  </link>  

  <link name="hip_roll_link">    
    <visual>      
      <origin xyz="0 0 0" rpy="0 -0 0"/>      
      <geometry>        
        <mesh filename="package:///meshes/left_hip_roll_link_visual.stl"/>        
      </geometry>      
      <material name="hip_roll_link_material">        
        <color rgba="0.51698661238356047321 0.50347815951093488618 0.49050589017722012741 1.0"/>        
      </material>      
    </visual>    
    <collision>      
      <origin xyz="0 0 0" rpy="0 -0 0"/>      
      <geometry>        
        <mesh filename="package:///meshes/left_hip_roll_link_collision.stl"/>        
      </geometry>      
    </collision>    
    <inertial>      
      <origin xyz="-0.011999849582186038893 -0.00049598090793989018689 -0.018504111838600234563" rpy="0 0 0"/>      
      <mass value="0.11059999999836234164"/>      
      <inertia ixx="2.2818802599018831834e-05" ixy="-4.6520143286969321254e-08" ixz="-4.6888548260590009187e-08" iyy="3.0871632082339766387e-05" iyz="-5.7477343899715744887e-07" izz="3.0871666424470047951e-05"/>      
    </inertial>    
  </link>  

  <link name="left_hip_pitch_link_xm430">    
    <visual>      
      <origin xyz="0 0 0" rpy="0 -0 0"/>      
      <geometry>        
        <mesh filename="package:///meshes/left_hip_pitch_link_xm430_visual.stl"/>        
      </geometry>      
      <material name="left_hip_pitch_link_xm430_material">        
        <color rgba="0.87072221357329560032 0.72641010956094276274 0.24785169615220689621 1.0"/>        
      </material>      
    </visual>    
    <collision>      
      <origin xyz="0 0 0" rpy="0 -0 0"/>      
      <geometry>        
        <mesh filename="package:///meshes/left_hip_pitch_link_xm430_collision.stl"/>        
      </geometry>      
    </collision>    
    <inertial>      
      <origin xyz="-0.00075729214155304295456 -0.050714785675264779929 -0.012656155119959889774" rpy="0 0 0"/>      
      <mass value="0.11480090135030573961"/>      
      <inertia ixx="6.6072773889430173292e-05" ixy="-4.6080149277702520703e-07" ixz="-1.817073911531254145e-07" iyy="2.3633638685369896549e-05" iyz="1.4125253925343981918e-06" izz="6.2221728804333600502e-05"/>      
    </inertial>    
  </link>  

  <link name="left_calf_link">    
    <visual>      
      <origin xyz="0 0 0" rpy="0 -0 0"/>      
      <geometry>        
        <mesh filename="package:///meshes/left_calf_link_visual.stl"/>        
      </geometry>      
      <material name="left_calf_link_material">        
        <color rgba="0.522707147375079062 0.70740037950664136357 0.87533206831119547697 1.0"/>        
      </material>      
    </visual>    
    <collision>      
      <origin xyz="0 0 0" rpy="0 -0 0"/>      
      <geometry>        
        <mesh filename="package:///meshes/left_calf_link_collision.stl"/>        
      </geometry>      
    </collision>    
    <inertial>      
      <origin xyz="-0.0044523204300165267894 -0.040710500523439427378 -0.0093961650094223081453" rpy="0 0 0"/>      
      <mass value="0.030999999999999996309"/>      
      <inertia ixx="3.2664188400786654766e-05" ixy="1.5241815987951976083e-06" ixz="1.9691083269457300706e-07" iyy="7.7419254139683942511e-06" iyz="-6.3917470175186686833e-07" izz="2.7619943894570778039e-05"/>      
    </inertial>    
  </link>  

  <link name="bearing_683">    
    <visual>      
      <origin xyz="0 0 0" rpy="0 -0 0"/>      
      <geometry>        
        <mesh filename="package:///meshes/left_bearing_683_visual.stl"/>        
      </geometry>      
      <material name="bearing_683_material">        
        <color rgba="0.64705882352941179736 0.64705882352941179736 0.64705882352941179736 1.0"/>        
      </material>      
    </visual>    
    <collision>      
      <origin xyz="0 0 0" rpy="0 -0 0"/>      
      <geometry>        
        <mesh filename="package:///meshes/left_bearing_683_collision.stl"/>        
      </geometry>      
    </collision>    
    <inertial>      
      <origin xyz="-2.7648254672676582453e-17 -2.4186774283159735099e-19 -0.0015500000000000003792" rpy="0 0 0"/>      
      <mass value="0.00048694686130641793437"/>      
      <inertia ixx="2.1551456503319887385e-09" ixy="-1.3739799432863871443e-27" ixz="1.0787741748414364856e-37" iyy="2.1551456503319883249e-09" iyz="-6.6197326148846058524e-38" izz="3.5303647444715305817e-09"/>      
    </inertial>    
  </link>  

  <joint name="left_knee_front_rev_2" type="revolute">    
    <origin xyz="-0.0057402514854763319122 0.013858192987668660479 -0.026199999999999112887" rpy="8.8484216442970563213e-16 3.3685549164292615233e-15 1.576593387657243106"/>    
    <parent link="left_calf_link"/>    
    <child link="bearing_683"/>    
    <axis xyz="0 0 1"/>    
    <limit effort="1" velocity="20" lower="-6.283185307179586232" upper="6.283185307179586232"/>    
    <joint_properties friction="0.0"/>    
  </joint>  

  <link name="bearing_683_2">    
    <visual>      
      <origin xyz="0 0 0" rpy="0 -0 0"/>      
      <geometry>        
        <mesh filename="package:///meshes/left_bearing_683_2_visual.stl"/>        
      </geometry>      
      <material name="bearing_683_2_material">        
        <color rgba="0.64705882352941179736 0.64705882352941179736 0.64705882352941179736 1.0"/>        
      </material>      
    </visual>    
    <collision>      
      <origin xyz="0 0 0" rpy="0 -0 0"/>      
      <geometry>        
        <mesh filename="package:///meshes/left_bearing_683_2_collision.stl"/>        
      </geometry>      
    </collision>    
    <inertial>      
      <origin xyz="1.073209429524896219e-19 -2.4186774283161039917e-19 -0.0015500000000000003792" rpy="0 0 0"/>      
      <mass value="0.00048694686130641793437"/>      
      <inertia ixx="2.1551456503319887385e-09" ixy="-3.9266657504818319607e-28" ixz="-1.0998392839148126578e-37" iyy="2.1551456503319883249e-09" iyz="6.9164853041617154958e-38" izz="3.5303647444715305817e-09"/>      
    </inertial>    
  </link>  

  <joint name="left_knee_back_rev_2" type="revolute">    
    <origin xyz="0.0057402514854764195157 -0.013858192987669493146 -0.026199999999999154521" rpy="5.4450106890480900015e-16 3.294464518329961217e-15 1.5736949077299704491"/>    
    <parent link="left_calf_link"/>    
    <child link="bearing_683_2"/>    
    <axis xyz="0 0 1"/>    
    <limit effort="1" velocity="20" lower="-6.283185307179586232" upper="6.283185307179586232"/>    
    <joint_properties friction="0.0"/>    
  </joint>  

  <link name="ank_pitch_link">    
    <visual>      
      <origin xyz="0 0 0" rpy="0 -0 0"/>      
      <geometry>        
        <mesh filename="package:///meshes/left_ank_pitch_link_visual.stl"/>        
      </geometry>      
      <material name="ank_pitch_link_material">        
        <color rgba="0.70321688500203338723 0.64514870846184446673 0.40484735422826262363 1.0"/>        
      </material>      
    </visual>    
    <collision>      
      <origin xyz="0 0 0" rpy="0 -0 0"/>      
      <geometry>        
        <mesh filename="package:///meshes/left_ank_pitch_link_collision.stl"/>        
      </geometry>      
    </collision>    
    <inertial>      
      <origin xyz="0.017776203107322322006 0.01230030041746682512 0.018831974532189481308" rpy="0 0 0"/>      
      <mass value="0.17676376695067905209"/>      
      <inertia ixx="4.7297542278277774448e-05" ixy="-1.3315543916092891447e-06" ixz="-4.3254173313679960006e-07" iyy="0.00010699536914578303441" iyz="-1.2605067163766108607e-08" izz="0.00012178084959463849994"/>      
    </inertial>    
  </link>  

  <link name="ank_roll_link">    
    <visual>      
      <origin xyz="0 0 0" rpy="0 -0 0"/>      
      <geometry>        
        <mesh filename="package:///meshes/left_ank_roll_link_visual.stl"/>        
      </geometry>      
      <material name="ank_roll_link_material">        
        <color rgba="0.61568627450980395466 0.81176470588235294379 0.92941176470588238168 1.0"/>        
      </material>      
    </visual>    
    <collision>      
      <origin xyz="0 0 0" rpy="0 -0 0"/>      
      <geometry>        
        <mesh filename="package:///meshes/left_ank_roll_link_collision.stl"/>        
      </geometry>      
    </collision>    
    <inertial>      
      <origin xyz="-0.027036578607872979729 2.0295365777351691212e-12 -0.033620165726269600481" rpy="0 0 0"/>      
      <mass value="0.042600000000000005917"/>      
      <inertia ixx="3.7520823109402963056e-05" ixy="5.6542629400100989605e-16" ixz="-2.4055359385054290212e-06" iyy="3.785433237087349991e-05" iyz="5.1539486127278945924e-12" izz="1.0182523770086914855e-05"/>      
    </inertial>    
  </link>  

  <joint name="left_ank_roll" type="revolute">    
    <origin xyz="0.022749999999994167249 -8.3266726846886740532e-17 0.019000000000001897316" rpy="1.5707963267950513231 1.4301315653119179755e-13 1.5707963267948481523"/>    
    <parent link="ank_pitch_link"/>    
    <child link="ank_roll_link"/>    
    <axis xyz="0 0 1"/>    
    <limit effort="1" velocity="20" lower="-1.570796326794896558" upper="1.570796326794896558"/>    
    <joint_properties friction="0.0"/>    
  </joint>  

  <joint name="left_ank_pitch" type="revolute">    
    <origin xyz="0.00050000000000032288582 -0.099999999999996785904 -0.029400000000000661715" rpy="-3.7313901977116486581e-15 1.1636199395949206391e-16 -5.2669342108558058169e-15"/>    
    <parent link="left_calf_link"/>    
    <child link="ank_pitch_link"/>    
    <axis xyz="0 0 1"/>    
    <limit effort="1" velocity="20" lower="-1.7453292519943295336" upper="0.785398163397448279"/>    
    <joint_properties friction="0.0"/>    
  </joint>  

  <joint name="left_knee" type="revolute">    
    <origin xyz="2.990790261972040031e-17 -0.09600000000000055711 -0.0092000000000000276001" rpy="2.5205532109825094148e-15 5.7598642354355467767e-16 3.8634704751188379083e-16"/>    
    <parent link="left_hip_pitch_link_xm430"/>    
    <child link="left_calf_link"/>    
    <axis xyz="0 0 1"/>    
    <limit effort="1" velocity="20" lower="0" upper="2.0943951023931952626"/>    
    <joint_properties friction="0.0"/>    
  </joint>  

  <link name="xm430_plate">    
    <visual>      
      <origin xyz="0 0 0" rpy="0 -0 0"/>      
      <geometry>        
        <mesh filename="package:///meshes/left_xm430_plate_visual.stl"/>        
      </geometry>      
      <material name="xm430_plate_material">        
        <color rgba="0.61568627450980395466 0.81176470588235294379 0.9294117647058824927 1.0"/>        
      </material>      
    </visual>    
    <collision>      
      <origin xyz="0 0 0" rpy="0 -0 0"/>      
      <geometry>        
        <mesh filename="package:///meshes/left_xm430_plate_collision.stl"/>        
      </geometry>      
    </collision>    
    <inertial>      
      <origin xyz="-1.0576187642697415789e-17 1.9123351058976605899e-18 -0.0024039046431217920424" rpy="0 0 0"/>      
      <mass value="0.0026999999999999992756"/>      
      <inertia ixx="1.293311664536341083e-07" ixy="-6.8936588702566453648e-08" ixz="-3.6412025580228755743e-35" iyy="2.672043438587668303e-07" iyz="1.0673130497341053755e-36" izz="3.8533537562751439267e-07"/>      
    </inertial>    
  </link>  

  <link name="knee_rod">    
    <visual>      
      <origin xyz="0 0 0" rpy="0 -0 0"/>      
      <geometry>        
        <mesh filename="package:///meshes/left_knee_rod_visual.stl"/>        
      </geometry>      
      <material name="knee_rod_material">        
        <color rgba="0.62051618944235187314 0.78640765248647570562 0.88594253031295011613 1.0"/>        
      </material>      
    </visual>    
    <collision>      
      <origin xyz="0 0 0" rpy="0 -0 0"/>      
      <geometry>        
        <mesh filename="package:///meshes/left_knee_rod_collision.stl"/>        
      </geometry>      
    </collision>    
    <inertial>      
      <origin xyz="0.014594546691135943522 -4.2302323076251755255e-05 -0.0015996227373174989189" rpy="0 0 0"/>      
      <mass value="0.0031629468613064174939"/>      
      <inertia ixx="2.5896152838585538517e-08" ixy="3.5533843517251011193e-10" ixz="4.1682972813445851362e-10" iyy="6.0153250027086253156e-07" iyz="-1.2081818090464721153e-12" izz="6.2266858883154988944e-07"/>      
    </inertial>    
  </link>  

  <joint name="left_knee_front_rev_1" type="revolute">    
    <origin xyz="0.013858192987669298857 0.0057402514854763440552 -0.004999999999999997502" rpy="-2.1480523090933430766e-15 2.7897458296366629566e-14 -3.1357955927274452357"/>    
    <parent link="xm430_plate"/>    
    <child link="knee_rod"/>    
    <axis xyz="0 0 1"/>    
    <limit effort="1" velocity="20" lower="-6.283185307179586232" upper="6.283185307179586232"/>    
    <joint_properties friction="0.0"/>    
  </joint>  

  <link name="knee_rod_2">    
    <visual>      
      <origin xyz="0 0 0" rpy="0 -0 0"/>      
      <geometry>        
        <mesh filename="package:///meshes/left_knee_rod_2_visual.stl"/>        
      </geometry>      
      <material name="knee_rod_2_material">        
        <color rgba="0.62051618944235187314 0.78640765248647570562 0.88594253031295011613 1.0"/>        
      </material>      
    </visual>    
    <collision>      
      <origin xyz="0 0 0" rpy="0 -0 0"/>      
      <geometry>        
        <mesh filename="package:///meshes/left_knee_rod_2_collision.stl"/>        
      </geometry>      
    </collision>    
    <inertial>      
      <origin xyz="0.014594546693014234448 4.2301026627223579099e-05 -0.0015996227373183534871" rpy="0 0 0"/>      
      <mass value="0.0031629468613064174939"/>      
      <inertia ixx="2.5896152775456920729e-08" ixy="-3.5532754506598649849e-10" ixz="4.1682972818342982893e-10" iyy="6.0153250030243166126e-07" iyz="1.2081447937374144554e-12" izz="6.2266858879993067891e-07"/>      
    </inertial>    
  </link>  

  <joint name="left_knee_back_rev_1" type="revolute">    
    <origin xyz="-0.013858192987669298857 -0.0057402514854763449226 -0.004999999999999997502" rpy="-2.3102540588711712824e-15 2.7442875060730908856e-14 -3.1386940726547187808"/>    
    <parent link="xm430_plate"/>    
    <child link="knee_rod_2"/>    
    <axis xyz="0 0 1"/>    
    <limit effort="1" velocity="20" lower="-6.283185307179586232" upper="6.283185307179586232"/>    
    <joint_properties friction="0.0"/>    
  </joint>  

  <joint name="left_knee_act" type="revolute">    
    <origin xyz="-0.00015000000000009954372 -0.06150000000000001299 -0.030399999999999812589" rpy="-1.8754556207585452854e-15 2.8209809769508020585e-14 1.5707963267948990005"/>    
    <parent link="left_hip_pitch_link_xm430"/>    
    <child link="xm430_plate"/>    
    <axis xyz="0 0 1"/>    
    <limit effort="1" velocity="20" lower="0" upper="2.0943951023931952626"/>    
    <joint_properties friction="0.0"/>    
  </joint>  

  <joint name="left_hip_pitch" type="revolute">    
    <origin xyz="-0.024000000716156828784 -0.019000000152440157247 -0.019000000152458548786" rpy="1.5707963267953657382 1.5707963267943103602 0"/>    
    <parent link="hip_roll_link"/>    
    <child link="left_hip_pitch_link_xm430"/>    
    <axis xyz="0 0 1"/>    
    <limit effort="1" velocity="20" lower="-1.570796326794896558" upper="1.570796326794896558"/>    
    <joint_properties friction="0.0"/>    
  </joint>  

  <joint name="left_hip_roll" type="revolute">    
    <origin xyz="0.018999999999999905853 4.4904419342659082281e-16 -0.025999999999999946765" rpy="-3.141592653589793116 -1.5707963267948918951 0"/>    
    <parent link="hip_yaw_link"/>    
    <child link="hip_roll_link"/>    
    <axis xyz="0 0 1"/>    
    <limit effort="1" velocity="20" lower="-0.785398163397448279" upper="0.785398163397448279"/>    
    <joint_properties friction="0.0"/>    
  </joint>  


</robot>