<?xml version="1.0" ?><robot name="sysID_XM430">  
  <link name="xm430">    
    <visual>      
      <origin xyz="0 0 0" rpy="0 -0 0"/>      
      <geometry>        
        <mesh filename="package:///meshes/xm430_visual.stl"/>        
      </geometry>      
      <material name="xm430_material">        
        <color rgba="0.91426034379578879907 0.70000842084638215113 0.13024790887542941897 1.0"/>        
      </material>      
    </visual>    
    <collision>      
      <origin xyz="0 0 0" rpy="0 -0 0"/>      
      <geometry>        
        <mesh filename="package:///meshes/xm430_collision.stl"/>        
      </geometry>      
    </collision>    
    <inertial>      
      <origin xyz="0.071958135955560109664 0.017445641259993493327 0.0055435138757473530202" rpy="0 0 0"/>      
      <mass value="0.10345000000444962152"/>      
      <inertia ixx="3.2324316568160280452e-05" ixy="-6.1940121394904638384e-06" ixz="-3.1148674256868357982e-08" iyy="3.2377737272393003519e-05" iyz="-4.6596185424280932665e-08" izz="4.8950379202494915772e-05"/>      
    </inertial>    
  </link>  

  <link name="arm_430">    
    <visual>      
      <origin xyz="0 0 0" rpy="0 -0 0"/>      
      <geometry>        
        <mesh filename="package:///meshes/arm_430_visual.stl"/>        
      </geometry>      
      <material name="arm_430_material">        
        <color rgba="0.62999456499017514322 0.65518625360592031015 0.6781537689702749061 1.0"/>        
      </material>      
    </visual>    
    <collision>      
      <origin xyz="0 0 0" rpy="0 -0 0"/>      
      <geometry>        
        <mesh filename="package:///meshes/arm_430_collision.stl"/>        
      </geometry>      
    </collision>    
    <inertial>      
      <origin xyz="-0.072230555077123254071 -2.7271210028869799149e-17 -0.019000000000000252798" rpy="0 0 0"/>      
      <mass value="0.23449999999999998623"/>      
      <inertia ixx="0.00023538980795506769654" ixy="-5.2643097671854766073e-19" ixz="-5.0334932890586797649e-19" iyy="0.00036901840263902870899" iyz="1.4664649652078179734e-16" izz="0.00018448272046932702017"/>      
    </inertial>    
  </link>  

  <joint name="joint_0" type="revolute">    
    <origin xyz="0.093000000000000013212 0.032699857927858892725 0.0055693959459662215755" rpy="-1.570796326794896558 2.7547408798512016148e-15 -1.5707963267948912289"/>    
    <parent link="xm430"/>    
    <child link="arm_430"/>    
    <axis xyz="0 0 1"/>    
    <limit effort="1" velocity="20" lower="-1.570796326794896558" upper="1.570796326794896558"/>    
    <joint_properties friction="0.0"/>    
  </joint>  


</robot>