<?xml version="1.0" ?><robot name="toddlerbot">  
  <link name="torso">    
    <visual>      
      <origin xyz="0 0 0" rpy="0 -0 0"/>      
      <geometry>        
        <mesh filename="package:///meshes/torso_visual.stl"/>        
      </geometry>      
      <material name="torso_material">        
        <color rgba="0.63516273151698243726 0.78981928681973512241 0.89663049964256791302 1.0"/>        
      </material>      
    </visual>    
    <collision>      
      <origin xyz="0 0 0" rpy="0 -0 0"/>      
      <geometry>        
        <mesh filename="package:///meshes/torso_collision.stl"/>        
      </geometry>      
    </collision>    
    <inertial>      
      <origin xyz="-0.0048722525217245026691 -0.003034303452353634932 0.065731716369313880621" rpy="0 0 0"/>      
      <mass value="1.1229659631011945642"/>      
      <inertia ixx="0.0029864200494844057691" ixy="7.6544013873600596316e-05" ixz="1.6162160592159903103e-05" iyy="0.0024009089586494794522" iyz="-2.6100607927069047675e-05" izz="0.0025052134874968133744"/>      
    </inertial>    
  </link>  

  <link name="spur_1m_20t">    
    <visual>      
      <origin xyz="0 0 0" rpy="0 -0 0"/>      
      <geometry>        
        <mesh filename="package:///meshes/spur_1m_20t_visual.stl"/>        
      </geometry>      
      <material name="spur_1m_20t_material">        
        <color rgba="0.64705882352941179736 0.64705882352941179736 0.64705882352941179736 1.0"/>        
      </material>      
    </visual>    
    <collision>      
      <origin xyz="0 0 0" rpy="0 -0 0"/>      
      <geometry>        
        <mesh filename="package:///meshes/spur_1m_20t_collision.stl"/>        
      </geometry>      
    </collision>    
    <inertial>      
      <origin xyz="-1.7411803694581147988e-19 -8.1718749464796366429e-18 0.003384232105434467619" rpy="0 0 0"/>      
      <mass value="0.0015778025963745997712"/>      
      <inertia ixx="4.5874424196602078292e-08" ixy="3.9189074979405055341e-24" ixz="-7.1097175513400442172e-39" iyy="4.5874424196602051822e-08" iyz="7.8419015231486103005e-38" izz="8.1737050837173862941e-08"/>      
    </inertial>    
  </link>  

  <joint name="neck_yaw_drive" type="revolute">    
    <origin xyz="-0.0049999999999995221878 3.1860588521011854095e-18 0.12148651076281755112" rpy="1.1607298201443905188e-14 1.6509758832059179101e-15 -5.3832337592600790636e-15"/>    
    <parent link="torso"/>    
    <child link="spur_1m_20t"/>    
    <axis xyz="0 0 1"/>    
    <limit effort="1" velocity="20" lower="-2.8797932657906435416" upper="2.8797932657906435416"/>    
    <joint_properties friction="0.0"/>    
  </joint>  

  <link name="neck_yaw_link_v2">    
    <visual>      
      <origin xyz="0 0 0" rpy="0 -0 0"/>      
      <geometry>        
        <mesh filename="package:///meshes/neck_yaw_link_v2_visual.stl"/>        
      </geometry>      
      <material name="neck_yaw_link_v2_material">        
        <color rgba="0.2313725490196078538 0.38039215686274507888 0.70588235294117662733 1.0"/>        
      </material>      
    </visual>    
    <collision>      
      <origin xyz="0 0 0" rpy="0 -0 0"/>      
      <geometry>        
        <mesh filename="package:///meshes/neck_yaw_link_v2_collision.stl"/>        
      </geometry>      
    </collision>    
    <inertial>      
      <origin xyz="-1.1403990894989882723e-06 -1.1841855022748836188e-10 0.008257184970100570065" rpy="0 0 0"/>      
      <mass value="0.0067298837334394089049"/>      
      <inertia ixx="5.2266067624768509962e-07" ixy="-6.3046404852550345303e-15" ixz="1.194940308445471148e-09" iyy="6.121851997955700108e-07" iyz="-2.6012874340399422568e-15" izz="2.8062851709981919258e-07"/>      
    </inertial>    
  </link>  

  <link name="head">    
    <visual>      
      <origin xyz="0 0 0" rpy="0 -0 0"/>      
      <geometry>        
        <mesh filename="package:///meshes/head_visual.stl"/>        
      </geometry>      
      <material name="head_material">        
        <color rgba="0.6268574946787414115 0.79455216272759310314 0.87652603342635482253 1.0"/>        
      </material>      
    </visual>    
    <collision>      
      <origin xyz="0 0 0" rpy="0 -0 0"/>      
      <geometry>        
        <mesh filename="package:///meshes/head_collision.stl"/>        
      </geometry>      
    </collision>    
    <inertial>      
      <origin xyz="-0.043832613261137853833 -0.010490240883705313421 -0.00040226032898233550147" rpy="0 0 0"/>      
      <mass value="0.12772101760550844118"/>      
      <inertia ixx="0.0001150834912572321143" ixy="3.2199498087100703889e-06" ixz="3.6551948020729733223e-06" iyy="9.8737573554260360293e-05" iyz="-8.3059614999120791101e-06" izz="8.6247396675247271986e-05"/>      
    </inertial>    
  </link>  

  <link name="motor_plate">    
    <visual>      
      <origin xyz="0 0 0" rpy="0 -0 0"/>      
      <geometry>        
        <mesh filename="package:///meshes/motor_plate_visual.stl"/>        
      </geometry>      
      <material name="motor_plate_material">        
        <color rgba="0.64705882352941179736 0.64705882352941179736 0.64705882352941179736 1.0"/>        
      </material>      
    </visual>    
    <collision>      
      <origin xyz="0 0 0" rpy="0 -0 0"/>      
      <geometry>        
        <mesh filename="package:///meshes/motor_plate_collision.stl"/>        
      </geometry>      
    </collision>    
    <inertial>      
      <origin xyz="-1.3877787807814456755e-17 1.0408340855860841026e-17 -0.0028281768943845485807" rpy="0 0 0"/>      
      <mass value="0.0016999999999999996884"/>      
      <inertia ixx="4.805029073310371698e-08" ixy="1.0773753257370470989e-09" ixz="8.6222375027022660753e-36" iyy="5.1782428339099016964e-08" iyz="8.5565076078426530076e-37" izz="9.2194729037862183155e-08"/>      
    </inertial>    
  </link>  

  <link name="bearing_683">    
    <visual>      
      <origin xyz="0 0 0" rpy="0 -0 0"/>      
      <geometry>        
        <mesh filename="package:///meshes/bearing_683_visual.stl"/>        
      </geometry>      
      <material name="bearing_683_material">        
        <color rgba="0.64705882352941179736 0.64705882352941179736 0.64705882352941179736 1.0"/>        
      </material>      
    </visual>    
    <collision>      
      <origin xyz="0 0 0" rpy="0 -0 0"/>      
      <geometry>        
        <mesh filename="package:///meshes/bearing_683_collision.stl"/>        
      </geometry>      
    </collision>    
    <inertial>      
      <origin xyz="2.7862896558581346257e-17 -2.7513707872797354004e-17 -0.0015499999999999999455" rpy="0 0 0"/>      
      <mass value="0.00048694686130641793437"/>      
      <inertia ixx="2.1551456503319895657e-09" ixy="-2.2349065165105563807e-25" ixz="1.5117363048316738963e-37" iyy="2.1551456503319883249e-09" iyz="-1.4991787593073694529e-37" izz="3.5303647444715305817e-09"/>      
    </inertial>    
  </link>  

  <joint name="neck_pitch_front_rev_2" type="revolute">    
    <origin xyz="-0.0019411428382688777905 -0.0072444436971680140069 -0.0055000000000000014155" rpy="-6.4149072816529488098e-15 7.6581010280206250727e-15 0.88076594287809084616"/>    
    <parent link="motor_plate"/>    
    <child link="bearing_683"/>    
    <axis xyz="0 0 1"/>    
    <limit effort="1" velocity="20" lower="-6.283185307179586232" upper="6.283185307179586232"/>    
    <joint_properties friction="0.0"/>    
  </joint>  

  <link name="bearing_683_2">    
    <visual>      
      <origin xyz="0 0 0" rpy="0 -0 0"/>      
      <geometry>        
        <mesh filename="package:///meshes/bearing_683_2_visual.stl"/>        
      </geometry>      
      <material name="bearing_683_2_material">        
        <color rgba="0.64705882352941179736 0.64705882352941179736 0.64705882352941179736 1.0"/>        
      </material>      
    </visual>    
    <collision>      
      <origin xyz="0 0 0" rpy="0 -0 0"/>      
      <geometry>        
        <mesh filename="package:///meshes/bearing_683_2_collision.stl"/>        
      </geometry>      
    </collision>    
    <inertial>      
      <origin xyz="1.0732094295237683463e-19 2.4186774283160240656e-19 -0.0015499999999999999455" rpy="0 0 0"/>      
      <mass value="0.00048694686130641793437"/>      
      <inertia ixx="2.1551456503319887385e-09" ixy="9.7578640621250777055e-26" ixz="-6.152730879482004974e-40" iyy="2.1551456503319874977e-09" iyz="4.3097633785012721201e-40" izz="3.5303647444715305817e-09"/>      
    </inertial>    
  </link>  

  <joint name="neck_pitch_back_rev_2" type="revolute">    
    <origin xyz="0.0019411428382689055461 0.0072444436971680157417 -0.0055000000000000014155" rpy="-2.6894721862809934635e-13 -1.70427982545233833e-13 0.87787101658577615382"/>    
    <parent link="motor_plate"/>    
    <child link="bearing_683_2"/>    
    <axis xyz="0 0 1"/>    
    <limit effort="1" velocity="20" lower="-6.283185307179586232" upper="6.283185307179586232"/>    
    <joint_properties friction="0.0"/>    
  </joint>  

  <joint name="neck_pitch_act" type="revolute">    
    <origin xyz="-0.032615697718559516494 -0.026999999999999642342 0.0024999999999980927236" rpy="-3.1415926535897824579 -3.0391096960732561898e-13 -3.1415926535894773686"/>    
    <parent link="head"/>    
    <child link="motor_plate"/>    
    <axis xyz="0 0 1"/>    
    <limit effort="1" velocity="20" lower="-1.3962634015954635824" upper="0.61086523819801530344"/>    
    <joint_properties friction="0.0"/>    
  </joint>  

  <joint name="neck_pitch" type="revolute">    
    <origin xyz="-1.0061396160665481148e-16 0.0040000000000000607986 0.019400000000000028333" rpy="-1.570796326790486086 1.567169222346451507 3.1415926535866449676"/>    
    <parent link="neck_yaw_link_v2"/>    
    <child link="head"/>    
    <axis xyz="0 0 1"/>    
    <limit effort="1" velocity="20" lower="-1.3962634015954635824" upper="0.61086523819801530344"/>    
    <joint_properties friction="0.0"/>    
  </joint>  

  <link name="neck_rod">    
    <visual>      
      <origin xyz="0 0 0" rpy="0 -0 0"/>      
      <geometry>        
        <mesh filename="package:///meshes/neck_rod_visual.stl"/>        
      </geometry>      
      <material name="neck_rod_material">        
        <color rgba="0.62051618944235198416 0.78640765248647581664 0.88594253031295000511 1.0"/>        
      </material>      
    </visual>    
    <collision>      
      <origin xyz="0 0 0" rpy="0 -0 0"/>      
      <geometry>        
        <mesh filename="package:///meshes/neck_rod_collision.stl"/>        
      </geometry>      
    </collision>    
    <inertial>      
      <origin xyz="0.017942953356020419076 -4.2302323073851487499e-05 -0.0016023848482616159968" rpy="0 0 0"/>      
      <mass value="0.0031629468613064183613"/>      
      <inertia ixx="1.6183187611801733514e-08" ixy="4.3686324093919476193e-10" ixz="5.4098718285286100278e-10" iyy="7.9430220338151571918e-07" iyz="-1.2754318247154742971e-12" izz="8.0573905690510645668e-07"/>      
    </inertial>    
  </link>  

  <joint name="neck_pitch_front_rev_1" type="revolute">    
    <origin xyz="-0.0072444436971683887072 -0.0040000000000001223813 0.01745885716173128932" rpy="1.5707963267944309305 -0.8843930473262051617 -3.1415926535893787808"/>    
    <parent link="neck_yaw_link_v2"/>    
    <child link="neck_rod"/>    
    <axis xyz="0 0 1"/>    
    <limit effort="1" velocity="20" lower="-6.283185307179586232" upper="6.283185307179586232"/>    
    <joint_properties friction="0.0"/>    
  </joint>  

  <link name="neck_rod_2">    
    <visual>      
      <origin xyz="0 0 0" rpy="0 -0 0"/>      
      <geometry>        
        <mesh filename="package:///meshes/neck_rod_2_visual.stl"/>        
      </geometry>      
      <material name="neck_rod_2_material">        
        <color rgba="0.62051618944235198416 0.78640765248647581664 0.88594253031295000511 1.0"/>        
      </material>      
    </visual>    
    <collision>      
      <origin xyz="0 0 0" rpy="0 -0 0"/>      
      <geometry>        
        <mesh filename="package:///meshes/neck_rod_2_collision.stl"/>        
      </geometry>      
    </collision>    
    <inertial>      
      <origin xyz="0.017901072327983016258 4.2302323075204747993e-05 -0.0016023848482717385419" rpy="0 0 0"/>      
      <mass value="0.0031629468613064183613"/>      
      <inertia ixx="1.6183187611802643413e-08" ixy="-4.3584354919634348471e-10" ixz="5.3972445329632657527e-10" iyy="7.9343818800625886651e-07" iyz="1.2754318729384124892e-12" izz="8.0487504152983531034e-07"/>      
    </inertial>    
  </link>  

  <joint name="neck_pitch_back_rev_1" type="revolute">    
    <origin xyz="0.007244443697168208296 -0.0040000000000001215139 0.021341142838269100412" rpy="1.570796326794926312 -0.88149812103389046936 3.1415926535897855665"/>    
    <parent link="neck_yaw_link_v2"/>    
    <child link="neck_rod_2"/>    
    <axis xyz="0 0 1"/>    
    <limit effort="1" velocity="20" lower="-6.283185307179586232" upper="6.283185307179586232"/>    
    <joint_properties friction="0.0"/>    
  </joint>  

  <joint name="neck_yaw_driven" type="revolute">    
    <origin xyz="0.016000000000000621364 3.9122381713629107253e-19 0.12248651076281739936" rpy="1.5470695466536949876e-14 -3.0902695541116811913e-15 -8.6007558735577539147e-16"/>    
    <parent link="torso"/>    
    <child link="neck_yaw_link_v2"/>    
    <axis xyz="0 0 1"/>    
    <limit effort="1" velocity="20" lower="-2.6179938779914944114" upper="2.6179938779914944114"/>    
    <joint_properties friction="0.0"/>    
  </joint>  

  <link name="waist_gears">    
    <visual>      
      <origin xyz="0 0 0" rpy="0 -0 0"/>      
      <geometry>        
        <mesh filename="package:///meshes/waist_gears_visual.stl"/>        
      </geometry>      
      <material name="waist_gears_material">        
        <color rgba="0.26906161272592882261 0.52279219083255490386 0.70491767355474521661 1.0"/>        
      </material>      
    </visual>    
    <collision>      
      <origin xyz="0 0 0" rpy="0 -0 0"/>      
      <geometry>        
        <mesh filename="package:///meshes/waist_gears_collision.stl"/>        
      </geometry>      
    </collision>    
    <inertial>      
      <origin xyz="-2.9089024310344835968e-07 5.5035553745212688705e-08 -0.012592985430860511448" rpy="0 0 0"/>      
      <mass value="0.026337180140419174518"/>      
      <inertia ixx="1.5367047941032976421e-06" ixy="1.8828487098075703468e-11" ixz="4.0600521958548964489e-10" iyy="7.3024712275448216365e-06" iyz="3.291173783196110374e-12" izz="6.9859065635057444052e-06"/>      
    </inertial>    
  </link>  

  <link name="waist_link">    
    <visual>      
      <origin xyz="0 0 0" rpy="0 -0 0"/>      
      <geometry>        
        <mesh filename="package:///meshes/waist_link_visual.stl"/>        
      </geometry>      
      <material name="waist_link_material">        
        <color rgba="0.63430343020834178969 0.68126545235342628182 0.66860955758476403599 1.0"/>        
      </material>      
    </visual>    
    <collision>      
      <origin xyz="0 0 0" rpy="0 -0 0"/>      
      <geometry>        
        <mesh filename="package:///meshes/waist_link_collision.stl"/>        
      </geometry>      
    </collision>    
    <inertial>      
      <origin xyz="-7.9740521616280326004e-06 0.026228931551963423352 -0.02998428051279712972" rpy="0 0 0"/>      
      <mass value="0.1701195349061245532"/>      
      <inertia ixx="7.0275024401906955045e-05" ixy="6.4268611259925317636e-09" ixz="-3.6642841622762010822e-06" iyy="0.00020583820676506133407" iyz="-3.5576438610758414332e-06" izz="0.00016218669765393208351"/>      
    </inertial>    
  </link>  

  <link name="spiral_bevel_1m_14t_30deg">    
    <visual>      
      <origin xyz="0 0 0" rpy="0 -0 0"/>      
      <geometry>        
        <mesh filename="package:///meshes/spiral_bevel_1m_14t_30deg_visual.stl"/>        
      </geometry>      
      <material name="spiral_bevel_1m_14t_30deg_material">        
        <color rgba="0.64705882352941179736 0.64705882352941179736 0.64705882352941179736 1.0"/>        
      </material>      
    </visual>    
    <collision>      
      <origin xyz="0 0 0" rpy="0 -0 0"/>      
      <geometry>        
        <mesh filename="package:///meshes/spiral_bevel_1m_14t_30deg_collision.stl"/>        
      </geometry>      
    </collision>    
    <inertial>      
      <origin xyz="7.4971447279470471159e-10 7.1802237332913031801e-10 0.0066868955018979155808" rpy="0 0 0"/>      
      <mass value="0.00073261524436595481732"/>      
      <inertia ixx="1.3495056019478193356e-08" ixy="4.0596681197802678729e-17" ixz="8.5992550167062356727e-16" iyy="1.3495056150237190671e-08" iyz="-6.7913008216864562113e-16" izz="1.4355986549816400137e-08"/>      
    </inertial>    
  </link>  

  <joint name="waist_act_1" type="revolute">    
    <origin xyz="-2.3414432044644055064e-17 0.019600000000000124267 -0.01275000000000019347" rpy="1.5707963267948936714 1.5707963267948950037 0"/>    
    <parent link="waist_link"/>    
    <child link="spiral_bevel_1m_14t_30deg"/>    
    <axis xyz="0 0 1"/>    
    <limit effort="1" velocity="20" lower="-4.6774823953448034786" upper="4.6774823953448034786"/>    
    <joint_properties friction="0.0"/>    
  </joint>  

  <link name="spiral_bevel_1m_14t_30deg_2">    
    <visual>      
      <origin xyz="0 0 0" rpy="0 -0 0"/>      
      <geometry>        
        <mesh filename="package:///meshes/spiral_bevel_1m_14t_30deg_2_visual.stl"/>        
      </geometry>      
      <material name="spiral_bevel_1m_14t_30deg_2_material">        
        <color rgba="0.64705882352941179736 0.64705882352941179736 0.64705882352941179736 1.0"/>        
      </material>      
    </visual>    
    <collision>      
      <origin xyz="0 0 0" rpy="0 -0 0"/>      
      <geometry>        
        <mesh filename="package:///meshes/spiral_bevel_1m_14t_30deg_2_collision.stl"/>        
      </geometry>      
    </collision>    
    <inertial>      
      <origin xyz="5.7114255512524803038e-10 8.6684721775822544076e-10 0.0066868955018979155808" rpy="0 0 0"/>      
      <mass value="0.00073261524436595481732"/>      
      <inertia ixx="1.3495056008338566936e-08" ixy="8.2092430901240935917e-18" ixz="9.8948603407504713417e-16" iyy="1.3495056161376833634e-08" iyz="-4.707514473443887487e-16" izz="1.4355986549816406754e-08"/>      
    </inertial>    
  </link>  

  <joint name="waist_act_2" type="revolute">    
    <origin xyz="-1.4470390030684367241e-17 0.019600000000000561418 -0.032750000000000556444" rpy="1.5707963267948972241 1.3463968515392352732 -2.5409194566005071493e-16"/>    
    <parent link="waist_link"/>    
    <child link="spiral_bevel_1m_14t_30deg_2"/>    
    <axis xyz="0 0 1"/>    
    <limit effort="1" velocity="20" lower="-4.6774823953448034786" upper="4.6774823953448034786"/>    
    <joint_properties friction="0.0"/>    
  </joint>  

  <link name="spur_gear_19_teeth">    
    <visual>      
      <origin xyz="0 0 0" rpy="0 -0 0"/>      
      <geometry>        
        <mesh filename="package:///meshes/spur_gear_19_teeth_visual.stl"/>        
      </geometry>      
      <material name="spur_gear_19_teeth_material">        
        <color rgba="0.61568627450980395466 0.81176470588235294379 0.92941176470588238168 1.0"/>        
      </material>      
    </visual>    
    <collision>      
      <origin xyz="0 0 0" rpy="0 -0 0"/>      
      <geometry>        
        <mesh filename="package:///meshes/spur_gear_19_teeth_collision.stl"/>        
      </geometry>      
    </collision>    
    <inertial>      
      <origin xyz="3.982620680117638602e-10 -1.6001614920402937169e-10 0.010108515802794645205" rpy="0 0 0"/>      
      <mass value="0.0010324984452316548957"/>      
      <inertia ixx="3.3238560252068683086e-08" ixy="-2.6893322161694212647e-16" ixz="-1.3807194537611751814e-15" iyy="3.3238560155295367385e-08" iyz="1.5293509724853463311e-16" izz="4.0687617484182906052e-08"/>      
    </inertial>    
  </link>  

  <joint name="left_hip_yaw_drive" type="revolute">    
    <origin xyz="-0.03700000000000004674 0.03110000000000001652 -0.039199999999999998734" rpy="1.570796326794896558 -6.0440960687789003209e-17 3.141592653589793116"/>    
    <parent link="waist_link"/>    
    <child link="spur_gear_19_teeth"/>    
    <axis xyz="0 0 1"/>    
    <limit effort="1" velocity="20" lower="-1.7361433085627806516" upper="1.7361433085627806516"/>    
    <joint_properties friction="0.0"/>    
  </joint>  

  <link name="spur_gear_21_teeth">    
    <visual>      
      <origin xyz="0 0 0" rpy="0 -0 0"/>      
      <geometry>        
        <mesh filename="package:///meshes/spur_gear_21_teeth_visual.stl"/>        
      </geometry>      
      <material name="spur_gear_21_teeth_material">        
        <color rgba="0.61568627450980395466 0.81176470588235294379 0.92941176470588238168 1.0"/>        
      </material>      
    </visual>    
    <collision>      
      <origin xyz="0 0 0" rpy="0 -0 0"/>      
      <geometry>        
        <mesh filename="package:///meshes/spur_gear_21_teeth_collision.stl"/>        
      </geometry>      
    </collision>    
    <inertial>      
      <origin xyz="-4.3729139591556703921e-11 1.6127119597199833502e-11 0.002494565097368564837" rpy="0 0 0"/>      
      <mass value="0.0010254193609188259288"/>      
      <inertia ixx="3.2524278733440935307e-08" ixy="-1.4914712189193835363e-38" ixz="2.2080265684851786227e-38" iyy="3.2524278732748135148e-08" iyz="4.3384451924501422335e-37" izz="6.0814076151188752603e-08"/>      
    </inertial>    
  </link>  

  <link name="left_leg_xm430">    
    <visual>      
      <origin xyz="0 0 0" rpy="0 -0 0"/>      
      <geometry>        
        <mesh filename="package:///meshes/left_leg_xm430_visual.stl"/>        
      </geometry>      
      <material name="left_leg_xm430_material">        
        <color rgba="0.61568627450980395466 0.81176470588235294379 0.92941176470588238168 1.0"/>        
      </material>      
    </visual>    
    <collision>      
      <origin xyz="0 0 0" rpy="0 -0 0"/>      
      <geometry>        
        <mesh filename="package:///meshes/left_leg_xm430_collision.stl"/>        
      </geometry>      
    </collision>    
    <inertial>      
      <origin xyz="-7.651932752129559327e-20 -5.6834239798556453859e-19 -0.0098919667346054358098" rpy="0 0 0"/>      
      <mass value="0.017999999999999991701"/>      
      <inertia ixx="2.6483505271519523376e-06" ixy="-6.4092479739512348525e-41" ixz="-2.8702262763642955687e-36" iyy="7.705535799600823457e-06" iyz="2.5331536859936605928e-37" izz="7.7736682806805358371e-06"/>      
    </inertial>    
  </link>  

  <joint name="left_leg_fixed" type="fixed">    
    <origin xyz="2.168404344971008868e-18 -1.3877787807814456755e-17 0.0049999999999999905631" rpy="-3.1415926535897704674 -7.7860248023657121854e-31 -1.137084089218072634e-30"/>    
    <parent link="spur_gear_21_teeth"/>    
    <child link="left_leg_xm430"/>    
    <axis xyz="0 0 1"/>    
    <limit effort="1" velocity="20"/>    
    <joint_properties friction="0.0"/>    
  </joint>  

  <joint name="left_hip_yaw_driven" type="revolute">    
    <origin xyz="-0.037000000000000012046 0.04109999999999997683 -0.019500000000000017319" rpy="-1.5707963267949192065 -1.5707963267948790165 0"/>    
    <parent link="waist_link"/>    
    <child link="spur_gear_21_teeth"/>    
    <axis xyz="0 0 1"/>    
    <limit effort="1" velocity="20" lower="-1.570796326794896558" upper="1.570796326794896558"/>    
    <joint_properties friction="0.0"/>    
  </joint>  

  <link name="spur_gear_19_teeth_2">    
    <visual>      
      <origin xyz="0 0 0" rpy="0 -0 0"/>      
      <geometry>        
        <mesh filename="package:///meshes/spur_gear_19_teeth_2_visual.stl"/>        
      </geometry>      
      <material name="spur_gear_19_teeth_2_material">        
        <color rgba="0.61568627450980395466 0.81176470588235294379 0.92941176470588238168 1.0"/>        
      </material>      
    </visual>    
    <collision>      
      <origin xyz="0 0 0" rpy="0 -0 0"/>      
      <geometry>        
        <mesh filename="package:///meshes/spur_gear_19_teeth_2_collision.stl"/>        
      </geometry>      
    </collision>    
    <inertial>      
      <origin xyz="3.9826206801176391189e-10 -1.6001614920402937169e-10 0.010108515802794638266" rpy="0 0 0"/>      
      <mass value="0.0010324984452316548957"/>      
      <inertia ixx="3.3238560252068689703e-08" ixy="-2.6893322161694212647e-16" ixz="-1.3807194537611753786e-15" iyy="3.3238560155295367385e-08" iyz="1.5293509724853463311e-16" izz="4.0687617484182906052e-08"/>      
    </inertial>    
  </link>  

  <joint name="right_hip_yaw_drive" type="revolute">    
    <origin xyz="0.036999999999999942657 0.031100000000000009581 -0.039200000000000005673" rpy="1.57079632679489678 3.044498544160610484e-18 3.141592653589793116"/>    
    <parent link="waist_link"/>    
    <child link="spur_gear_19_teeth_2"/>    
    <axis xyz="0 0 1"/>    
    <limit effort="1" velocity="20" lower="-1.7361433085627806516" upper="1.7361433085627806516"/>    
    <joint_properties friction="0.0"/>    
  </joint>  

  <link name="spur_gear_21_teeth_2">    
    <visual>      
      <origin xyz="0 0 0" rpy="0 -0 0"/>      
      <geometry>        
        <mesh filename="package:///meshes/spur_gear_21_teeth_2_visual.stl"/>        
      </geometry>      
      <material name="spur_gear_21_teeth_2_material">        
        <color rgba="0.61568627450980395466 0.81176470588235294379 0.92941176470588238168 1.0"/>        
      </material>      
    </visual>    
    <collision>      
      <origin xyz="0 0 0" rpy="0 -0 0"/>      
      <geometry>        
        <mesh filename="package:///meshes/spur_gear_21_teeth_2_collision.stl"/>        
      </geometry>      
    </collision>    
    <inertial>      
      <origin xyz="-4.3729139591556703921e-11 -1.6127126536093737409e-11 0.0025054349026314465428" rpy="0 0 0"/>      
      <mass value="0.0010254193609188259288"/>      
      <inertia ixx="3.2524278733440935307e-08" ixy="9.6694257117435395665e-39" ixz="-2.1402570621690166588e-39" iyy="3.2524278732748135148e-08" iyz="-1.7530161696327481842e-38" izz="6.0814076151188752603e-08"/>      
    </inertial>    
  </link>  

  <link name="right_leg_xm430">    
    <visual>      
      <origin xyz="0 0 0" rpy="0 -0 0"/>      
      <geometry>        
        <mesh filename="package:///meshes/right_leg_xm430_visual.stl"/>        
      </geometry>      
      <material name="right_leg_xm430_material">        
        <color rgba="0.61568627450980395466 0.81176470588235294379 0.92941176470588238168 1.0"/>        
      </material>      
    </visual>    
    <collision>      
      <origin xyz="0 0 0" rpy="0 -0 0"/>      
      <geometry>        
        <mesh filename="package:///meshes/right_leg_xm430_collision.stl"/>        
      </geometry>      
    </collision>    
    <inertial>      
      <origin xyz="-7.6519327521300781244e-20 -5.6834239798552775333e-19 -0.0098919667346054427487" rpy="0 0 0"/>      
      <mass value="0.017999999999999991701"/>      
      <inertia ixx="2.6483505271519523376e-06" ixy="-1.5390984606506839002e-36" ixz="0" iyy="7.705535799600823457e-06" iyz="0" izz="7.7736682806805358371e-06"/>      
    </inertial>    
  </link>  

  <joint name="right_leg_fixed" type="fixed">    
    <origin xyz="-4.336808689942017736e-19 -6.9388939039072283776e-18 0.0050000000000000113798" rpy="-3.141592653589793116 9.3906761299382808154e-30 1.9103766403509957361e-30"/>    
    <parent link="spur_gear_21_teeth_2"/>    
    <child link="right_leg_xm430"/>    
    <axis xyz="0 0 1"/>    
    <limit effort="1" velocity="20"/>    
    <joint_properties friction="0.0"/>    
  </joint>  

  <joint name="right_hip_yaw_driven" type="revolute">    
    <origin xyz="0.03699999999999998429 0.041099999999999969891 -0.019500000000000017319" rpy="-1.570796326794896558 -1.570796326794896558 0"/>    
    <parent link="waist_link"/>    
    <child link="spur_gear_21_teeth_2"/>    
    <axis xyz="0 0 1"/>    
    <limit effort="1" velocity="20" lower="-1.570796326794896558" upper="1.570796326794896558"/>    
    <joint_properties friction="0.0"/>    
  </joint>  

  <joint name="waist_roll" type="revolute">    
    <origin xyz="-0.022707865260692055437 -1.3063957582126781116e-17 -0.013999999999999981209" rpy="-1.5707963267948956698 -5.9937357430034153564e-14 1.5707963267948785724"/>    
    <parent link="waist_gears"/>    
    <child link="waist_link"/>    
    <axis xyz="0 0 1"/>    
    <limit effort="1" velocity="20" lower="-0.52359877559829881566" upper="0.52359877559829881566"/>    
    <joint_properties friction="0.0"/>    
  </joint>  

  <joint name="waist_yaw" type="revolute">    
    <origin xyz="0 3.6977854932234928379e-32 -2.4651903288156618919e-32" rpy="-3.0322117681687121616e-16 -4.1243331367303576527e-15 3.1415926535897904515"/>    
    <parent link="torso"/>    
    <child link="waist_gears"/>    
    <axis xyz="0 0 1"/>    
    <limit effort="1" velocity="20" lower="-1.570796326794896558" upper="1.570796326794896558"/>    
    <joint_properties friction="0.0"/>    
  </joint>  

  <link name="left_arm_hand">    
    <visual>      
      <origin xyz="0 0 0" rpy="0 -0 0"/>      
      <geometry>        
        <mesh filename="package:///meshes/left_arm_hand_visual.stl"/>        
      </geometry>      
      <material name="left_arm_hand_material">        
        <color rgba="0.61568627450980395466 0.81176470588235294379 0.9294117647058824927 1.0"/>        
      </material>      
    </visual>    
    <collision>      
      <origin xyz="0 0 0" rpy="0 -0 0"/>      
      <geometry>        
        <mesh filename="package:///meshes/left_arm_hand_collision.stl"/>        
      </geometry>      
    </collision>    
    <inertial>      
      <origin xyz="5.8254247517541416907e-11 -5.126464256112098607e-05 0.0082440788127094901533" rpy="0 0 0"/>      
      <mass value="0.0085999999999999895972"/>      
      <inertia ixx="1.2272887040545787638e-06" ixy="-2.1429944215128323733e-14" ixz="-8.5847198376843733829e-15" iyy="2.9107306060364603147e-06" iyz="7.4623841398183067466e-09" izz="3.0803135950773470752e-06"/>      
    </inertial>    
  </link>  

  <joint name="left_sho_pitch" type="revolute">    
    <origin xyz="-0.0035000000000004693156 0.067000000000001086464 0.104236510762817286" rpy="-1.5707963267949081043 -4.127643409825574977e-14 3.4723733359249779961e-14"/>    
    <parent link="torso"/>    
    <child link="left_arm_hand"/>    
    <axis xyz="0 0 1"/>    
    <limit effort="1" velocity="20" lower="-3.141592653589793116" upper="1.570796326794896558"/>    
    <joint_properties friction="0.0"/>    
  </joint>  

  <link name="right_arm_hand">    
    <visual>      
      <origin xyz="0 0 0" rpy="0 -0 0"/>      
      <geometry>        
        <mesh filename="package:///meshes/right_arm_hand_visual.stl"/>        
      </geometry>      
      <material name="right_arm_hand_material">        
        <color rgba="0.61568627450980395466 0.81176470588235294379 0.9294117647058824927 1.0"/>        
      </material>      
    </visual>    
    <collision>      
      <origin xyz="0 0 0" rpy="0 -0 0"/>      
      <geometry>        
        <mesh filename="package:///meshes/right_arm_hand_collision.stl"/>        
      </geometry>      
    </collision>    
    <inertial>      
      <origin xyz="5.8254247517541416907e-11 -5.126464256112098607e-05 0.0082440788127094901533" rpy="0 0 0"/>      
      <mass value="0.0085999999999999895972"/>      
      <inertia ixx="1.2272887040545787638e-06" ixy="-2.1429944215128323733e-14" ixz="-8.5847198376843733829e-15" iyy="2.9107306060364603147e-06" iyz="7.4623841398183067466e-09" izz="3.0803135950773470752e-06"/>      
    </inertial>    
  </link>  

  <joint name="right_sho_pitch" type="revolute">    
    <origin xyz="-0.003499999999998689923 -0.067000000000001030953 0.10423651076281729988" rpy="-1.5707963267948885644 3.4812325502379109658e-14 -3.1415926535897562566"/>    
    <parent link="torso"/>    
    <child link="right_arm_hand"/>    
    <axis xyz="0 0 1"/>    
    <limit effort="1" velocity="20" lower="-1.570796326794896558" upper="3.141592653589793116"/>    
    <joint_properties friction="0.0"/>    
  </joint>  


</robot>