<?xml version="1.0" ?><robot name="toddlerbot">  
  <link name="torso">    
    <visual>      
      <origin xyz="0 0 0" rpy="0 -0 0"/>      
      <geometry>        
        <mesh filename="package:///meshes/torso_visual.stl"/>        
      </geometry>      
      <material name="torso_material">        
        <color rgba="0.63761324738265701129 0.79140018897832331568 0.89744804913511844191 1.0"/>        
      </material>      
    </visual>    
    <collision>      
      <origin xyz="0 0 0" rpy="0 -0 0"/>      
      <geometry>        
        <mesh filename="package:///meshes/torso_collision.stl"/>        
      </geometry>      
    </collision>    
    <inertial>      
      <origin xyz="-0.0045319089141771795592 -0.0033046849194456094992 0.065594108502291123552" rpy="0 0 0"/>      
      <mass value="1.1369659631011950207"/>      
      <inertia ixx="0.0029825917743578336458" ixy="8.173061428844131341e-05" ixz="2.1951370741855520289e-05" iyy="0.002396950639998903388" iyz="-2.9575017351929247349e-05" izz="0.002512635652390854922"/>      
    </inertial>    
  </link>  

  <link name="spur_1m_20t">    
    <visual>      
      <origin xyz="0 0 0" rpy="0 -0 0"/>      
      <geometry>        
        <mesh filename="package:///meshes/spur_1m_20t_visual.stl"/>        
      </geometry>      
      <material name="spur_1m_20t_material">        
        <color rgba="0.64705882352941179736 0.64705882352941179736 0.64705882352941179736 1.0"/>        
      </material>      
    </visual>    
    <collision>      
      <origin xyz="0 0 0" rpy="0 -0 0"/>      
      <geometry>        
        <mesh filename="package:///meshes/spur_1m_20t_collision.stl"/>        
      </geometry>      
    </collision>    
    <inertial>      
      <origin xyz="-8.5753164114088250402e-20 -7.9823296359483900623e-18 0.003384232105434467619" rpy="0 0 0"/>      
      <mass value="0.0015778025963745997712"/>      
      <inertia ixx="4.5874424196602091527e-08" ixy="6.4004493355995885587e-24" ixz="-7.1097175513400442172e-39" iyy="4.5874424196602051822e-08" iyz="7.8419015231486103005e-38" izz="8.1737050837173876176e-08"/>      
    </inertial>    
  </link>  

  <joint name="neck_yaw_drive" type="revolute">    
    <origin xyz="-0.0049999999999995221878 3.1860588521011854095e-18 0.12148651076281755112" rpy="1.1607298201443905188e-14 1.6509758832059179101e-15 -5.3832337592600790636e-15"/>    
    <parent link="torso"/>    
    <child link="spur_1m_20t"/>    
    <axis xyz="0 0 1"/>    
    <limit effort="1" velocity="20" lower="-2.8797932657906435416" upper="2.8797932657906435416"/>    
    <joint_properties friction="0.0"/>    
  </joint>  

  <link name="neck_yaw_link_v2">    
    <visual>      
      <origin xyz="0 0 0" rpy="0 -0 0"/>      
      <geometry>        
        <mesh filename="package:///meshes/neck_yaw_link_v2_visual.stl"/>        
      </geometry>      
      <material name="neck_yaw_link_v2_material">        
        <color rgba="0.2313725490196078538 0.38039215686274513439 0.70588235294117662733 1.0"/>        
      </material>      
    </visual>    
    <collision>      
      <origin xyz="0 0 0" rpy="0 -0 0"/>      
      <geometry>        
        <mesh filename="package:///meshes/neck_yaw_link_v2_collision.stl"/>        
      </geometry>      
    </collision>    
    <inertial>      
      <origin xyz="-1.1403990895369016788e-06 -1.1841855615507243796e-10 0.0082571849701004972066" rpy="0 0 0"/>      
      <mass value="0.0067298837334394089049"/>      
      <inertia ixx="5.2266067624768086445e-07" ixy="-6.304640333713484386e-15" ixz="1.194940308446679452e-09" iyy="6.1218519979556588152e-07" iyz="-2.6012872022712980049e-15" izz="2.8062851709981924551e-07"/>      
    </inertial>    
  </link>  

  <link name="head">    
    <visual>      
      <origin xyz="0 0 0" rpy="0 -0 0"/>      
      <geometry>        
        <mesh filename="package:///meshes/head_visual.stl"/>        
      </geometry>      
      <material name="head_material">        
        <color rgba="0.6268574946787414115 0.79455216272759310314 0.87652603342635460049 1.0"/>        
      </material>      
    </visual>    
    <collision>      
      <origin xyz="0 0 0" rpy="0 -0 0"/>      
      <geometry>        
        <mesh filename="package:///meshes/head_collision.stl"/>        
      </geometry>      
    </collision>    
    <inertial>      
      <origin xyz="-0.043832613261137839955 -0.010490240883705334238 -0.00040226032898233875408" rpy="0 0 0"/>      
      <mass value="0.12772101760550838567"/>      
      <inertia ixx="0.00011508349125723207364" ixy="3.2199498087100644597e-06" ixz="3.6551948020729792515e-06" iyy="9.8737573554260306082e-05" iyz="-8.3059614999120740279e-06" izz="8.6247396675247217776e-05"/>      
    </inertial>    
  </link>  

  <link name="motor_plate">    
    <visual>      
      <origin xyz="0 0 0" rpy="0 -0 0"/>      
      <geometry>        
        <mesh filename="package:///meshes/motor_plate_visual.stl"/>        
      </geometry>      
      <material name="motor_plate_material">        
        <color rgba="0.64705882352941179736 0.64705882352941179736 0.64705882352941179736 1.0"/>        
      </material>      
    </visual>    
    <collision>      
      <origin xyz="0 0 0" rpy="0 -0 0"/>      
      <geometry>        
        <mesh filename="package:///meshes/motor_plate_collision.stl"/>        
      </geometry>      
    </collision>    
    <inertial>      
      <origin xyz="2.0816681711721682051e-17 -3.4694469519536141888e-18 -0.0028281768943845485807" rpy="0 0 0"/>      
      <mass value="0.0016999999999999996884"/>      
      <inertia ixx="4.8050290733103697128e-08" ixy="1.0773753257370404815e-09" ixz="-7.7581517390052640125e-36" iyy="5.1782428339099010347e-08" iyz="-3.489439624544232414e-37" izz="9.2194729037862183155e-08"/>      
    </inertial>    
  </link>  

  <link name="bearing_683">    
    <visual>      
      <origin xyz="0 0 0" rpy="0 -0 0"/>      
      <geometry>        
        <mesh filename="package:///meshes/bearing_683_visual.stl"/>        
      </geometry>      
      <material name="bearing_683_material">        
        <color rgba="0.64705882352941179736 0.64705882352941179736 0.64705882352941179736 1.0"/>        
      </material>      
    </visual>    
    <collision>      
      <origin xyz="0 0 0" rpy="0 -0 0"/>      
      <geometry>        
        <mesh filename="package:///meshes/bearing_683_collision.stl"/>        
      </geometry>      
    </collision>    
    <inertial>      
      <origin xyz="1.0732094295236813184e-19 2.4186774283162407327e-19 -0.0015499999999999999455" rpy="0 0 0"/>      
      <mass value="0.00048694686130641793437"/>      
      <inertia ixx="2.1551456503319879113e-09" ixy="8.8695722220542739607e-27" ixz="-3.990276490501307198e-38" iyy="2.1551456503319883249e-09" iyz="3.2614313712998011813e-38" izz="3.5303647444715305817e-09"/>      
    </inertial>    
  </link>  

  <joint name="neck_pitch_front_rev_2" type="revolute">    
    <origin xyz="-0.0019411428382688777905 -0.0072444436971680140069 -0.0054999999999999996808" rpy="-7.8470437385325782231e-15 7.0575798498253499623e-15 0.88076594287801956984"/>    
    <parent link="motor_plate"/>    
    <child link="bearing_683"/>    
    <axis xyz="0 0 1"/>    
    <limit effort="1" velocity="20" lower="-6.283185307179586232" upper="6.283185307179586232"/>    
    <joint_properties friction="0.0"/>    
  </joint>  

  <link name="bearing_683_2">    
    <visual>      
      <origin xyz="0 0 0" rpy="0 -0 0"/>      
      <geometry>        
        <mesh filename="package:///meshes/bearing_683_2_visual.stl"/>        
      </geometry>      
      <material name="bearing_683_2_material">        
        <color rgba="0.64705882352941179736 0.64705882352941179736 0.64705882352941179736 1.0"/>        
      </material>      
    </visual>    
    <collision>      
      <origin xyz="0 0 0" rpy="0 -0 0"/>      
      <geometry>        
        <mesh filename="package:///meshes/bearing_683_2_collision.stl"/>        
      </geometry>      
    </collision>    
    <inertial>      
      <origin xyz="1.0732094295237642537e-19 2.4186774283160221397e-19 -0.0015499999999999999455" rpy="0 0 0"/>      
      <mass value="0.00048694686130641793437"/>      
      <inertia ixx="2.1551456503319887385e-09" ixy="1.0355000413046178976e-25" ixz="-1.5012828586696551818e-39" iyy="2.1551456503319883249e-09" iyz="1.0909476690756370037e-40" izz="3.5303647444715305817e-09"/>      
    </inertial>    
  </link>  

  <joint name="neck_pitch_back_rev_2" type="revolute">    
    <origin xyz="0.0019411428382689333016 0.007244443697168007068 -0.0054999999999999996808" rpy="-2.4312653183549898777e-13 -1.5948647674331375607e-13 0.87787101658573418739"/>    
    <parent link="motor_plate"/>    
    <child link="bearing_683_2"/>    
    <axis xyz="0 0 1"/>    
    <limit effort="1" velocity="20" lower="-6.283185307179586232" upper="6.283185307179586232"/>    
    <joint_properties friction="0.0"/>    
  </joint>  

  <joint name="neck_pitch_act" type="revolute">    
    <origin xyz="-0.032615697718559488738 -0.026999999999999642342 0.0024999999999980862184" rpy="-3.1415926535897824579 -3.0391096960732582093e-13 -3.1415926535895213334"/>    
    <parent link="head"/>    
    <child link="motor_plate"/>    
    <axis xyz="0 0 1"/>    
    <limit effort="1" velocity="20" lower="-1.3962634015954635824" upper="0.61086523819801530344"/>    
    <joint_properties friction="0.0"/>    
  </joint>  

  <joint name="neck_pitch" type="revolute">    
    <origin xyz="-1.1449174941446926823e-16 0.0040000000000001215139 0.019400000000000056088" rpy="-1.5707963267830740151 1.5671692223464293026 -3.1415926535855391855"/>    
    <parent link="neck_yaw_link_v2"/>    
    <child link="head"/>    
    <axis xyz="0 0 1"/>    
    <limit effort="1" velocity="20" lower="-1.3962634015954635824" upper="0.61086523819801530344"/>    
    <joint_properties friction="0.0"/>    
  </joint>  

  <link name="neck_rod">    
    <visual>      
      <origin xyz="0 0 0" rpy="0 -0 0"/>      
      <geometry>        
        <mesh filename="package:///meshes/neck_rod_visual.stl"/>        
      </geometry>      
      <material name="neck_rod_material">        
        <color rgba="0.62051618944235198416 0.78640765248647581664 0.88594253031295000511 1.0"/>        
      </material>      
    </visual>    
    <collision>      
      <origin xyz="0 0 0" rpy="0 -0 0"/>      
      <geometry>        
        <mesh filename="package:///meshes/neck_rod_collision.stl"/>        
      </geometry>      
    </collision>    
    <inertial>      
      <origin xyz="0.017942953356021015821 -4.2302323072829437216e-05 -0.0016023848482615999506" rpy="0 0 0"/>      
      <mass value="0.0031629468613064183613"/>      
      <inertia ixx="1.6183187611801680574e-08" ixy="4.3686324092854543192e-10" ixz="5.4098718285268760504e-10" iyy="7.9430220338152821291e-07" iyz="-1.2754318230195799618e-12" izz="8.0573905690511895042e-07"/>      
    </inertial>    
  </link>  

  <joint name="neck_pitch_front_rev_1" type="revolute">    
    <origin xyz="-0.0072444436971684077892 -0.0040000000000001085035 0.01745885716173128932" rpy="1.5707963267946412067 -0.88439304732620005467 -3.1415926535894236338"/>    
    <parent link="neck_yaw_link_v2"/>    
    <child link="neck_rod"/>    
    <axis xyz="0 0 1"/>    
    <limit effort="1" velocity="20" lower="-6.283185307179586232" upper="6.283185307179586232"/>    
    <joint_properties friction="0.0"/>    
  </joint>  

  <link name="neck_rod_2">    
    <visual>      
      <origin xyz="0 0 0" rpy="0 -0 0"/>      
      <geometry>        
        <mesh filename="package:///meshes/neck_rod_2_visual.stl"/>        
      </geometry>      
      <material name="neck_rod_2_material">        
        <color rgba="0.62051618944235198416 0.78640765248647581664 0.88594253031295000511 1.0"/>        
      </material>      
    </visual>    
    <collision>      
      <origin xyz="0 0 0" rpy="0 -0 0"/>      
      <geometry>        
        <mesh filename="package:///meshes/neck_rod_2_collision.stl"/>        
      </geometry>      
    </collision>    
    <inertial>      
      <origin xyz="0.017901072327982776866 4.2302323075069154959e-05 -0.0016023848482707595074" rpy="0 0 0"/>      
      <mass value="0.0031629468613064183613"/>      
      <inertia ixx="1.618318761180254746e-08" ixy="-4.3584354919588693271e-10" ixz="5.3972445328623424802e-10" iyy="7.9343818800625431371e-07" iyz="1.275431872910489489e-12" izz="8.0487504152983107517e-07"/>      
    </inertial>    
  </link>  

  <joint name="neck_pitch_back_rev_1" type="revolute">    
    <origin xyz="0.0072444436971681805404 -0.004000000000000133657 0.021341142838269128168" rpy="1.570796326794926312 -0.88149812103391333995 3.1415926535897837901"/>    
    <parent link="neck_yaw_link_v2"/>    
    <child link="neck_rod_2"/>    
    <axis xyz="0 0 1"/>    
    <limit effort="1" velocity="20" lower="-6.283185307179586232" upper="6.283185307179586232"/>    
    <joint_properties friction="0.0"/>    
  </joint>  

  <joint name="neck_yaw_driven" type="revolute">    
    <origin xyz="0.016000000000000621364 3.9122381713629107253e-19 0.12248651076281739936" rpy="1.5470695466536949876e-14 -3.0902695541116811913e-15 -8.6007558735577539147e-16"/>    
    <parent link="torso"/>    
    <child link="neck_yaw_link_v2"/>    
    <axis xyz="0 0 1"/>    
    <limit effort="1" velocity="20" lower="-2.6179938779914944114" upper="2.6179938779914944114"/>    
    <joint_properties friction="0.0"/>    
  </joint>  

  <link name="waist_gears">    
    <visual>      
      <origin xyz="0 0 0" rpy="0 -0 0"/>      
      <geometry>        
        <mesh filename="package:///meshes/waist_gears_visual.stl"/>        
      </geometry>      
      <material name="waist_gears_material">        
        <color rgba="0.26906161272592887812 0.5227921908325551259 0.70491767355474543866 1.0"/>        
      </material>      
    </visual>    
    <collision>      
      <origin xyz="0 0 0" rpy="0 -0 0"/>      
      <geometry>        
        <mesh filename="package:///meshes/waist_gears_collision.stl"/>        
      </geometry>      
    </collision>    
    <inertial>      
      <origin xyz="-2.908902431013901755e-07 5.503555374520705726e-08 -0.012592985430860513182" rpy="0 0 0"/>      
      <mass value="0.026337180140419171048"/>      
      <inertia ixx="1.5367047941032976421e-06" ixy="1.8828487098179149512e-11" ixz="4.0600521958570796887e-10" iyy="7.3024712275448224835e-06" iyz="3.2911737831925686031e-12" izz="6.9859065635057444052e-06"/>      
    </inertial>    
  </link>  

  <link name="waist_link">    
    <visual>      
      <origin xyz="0 0 0" rpy="0 -0 0"/>      
      <geometry>        
        <mesh filename="package:///meshes/waist_link_visual.stl"/>        
      </geometry>      
      <material name="waist_link_material">        
        <color rgba="0.64045710103832809157 0.77359797797318041734 0.8121440665002769288 1.0"/>        
      </material>      
    </visual>    
    <collision>      
      <origin xyz="0 0 0" rpy="0 -0 0"/>      
      <geometry>        
        <mesh filename="package:///meshes/waist_link_collision.stl"/>        
      </geometry>      
    </collision>    
    <inertial>      
      <origin xyz="-7.9462186464867303482e-18 -0.02366029304019734783 -0.02276276478536513187" rpy="0 0 0"/>      
      <mass value="0.11519999998618361825"/>      
      <inertia ixx="4.8136551023262806311e-05" ixy="-1.2581830707237827449e-20" ixz="-5.6250849574754699444e-09" iyy="0.00011032090752778278228" iyz="5.9362613986426644063e-08" izz="8.0980504503691129632e-05"/>      
    </inertial>    
  </link>  

  <link name="spiral_bevel_1m_14t_30deg">    
    <visual>      
      <origin xyz="0 0 0" rpy="0 -0 0"/>      
      <geometry>        
        <mesh filename="package:///meshes/spiral_bevel_1m_14t_30deg_visual.stl"/>        
      </geometry>      
      <material name="spiral_bevel_1m_14t_30deg_material">        
        <color rgba="0.64705882352941179736 0.64705882352941179736 0.64705882352941179736 1.0"/>        
      </material>      
    </visual>    
    <collision>      
      <origin xyz="0 0 0" rpy="0 -0 0"/>      
      <geometry>        
        <mesh filename="package:///meshes/spiral_bevel_1m_14t_30deg_collision.stl"/>        
      </geometry>      
    </collision>    
    <inertial>      
      <origin xyz="7.4971447279470481499e-10 7.1802237332913011122e-10 0.0066868955018979155808" rpy="0 0 0"/>      
      <mass value="0.00073261524436595492574"/>      
      <inertia ixx="1.3495056019478193356e-08" ixy="4.0596681708340680739e-17" ixz="8.5992550148967780827e-16" iyy="1.3495056150237198942e-08" iyz="-6.791300820279719016e-16" izz="1.4355986549816401791e-08"/>      
    </inertial>    
  </link>  

  <joint name="waist_act_1" type="revolute">    
    <origin xyz="-2.4504607866288808614e-16 -0.019600000000000054878 -0.012750000000000320105" rpy="-1.5707963267948259478 1.5358897417550183562 6.0735050737511900929e-14"/>    
    <parent link="waist_link"/>    
    <child link="spiral_bevel_1m_14t_30deg"/>    
    <axis xyz="0 0 1"/>    
    <limit effort="1" velocity="20" lower="-4.6774823953448034786" upper="4.6774823953448034786"/>    
    <joint_properties friction="0.0"/>    
  </joint>  

  <link name="spiral_bevel_1m_14t_30deg_2">    
    <visual>      
      <origin xyz="0 0 0" rpy="0 -0 0"/>      
      <geometry>        
        <mesh filename="package:///meshes/spiral_bevel_1m_14t_30deg_2_visual.stl"/>        
      </geometry>      
      <material name="spiral_bevel_1m_14t_30deg_2_material">        
        <color rgba="0.64705882352941179736 0.64705882352941179736 0.64705882352941179736 1.0"/>        
      </material>      
    </visual>    
    <collision>      
      <origin xyz="0 0 0" rpy="0 -0 0"/>      
      <geometry>        
        <mesh filename="package:///meshes/spiral_bevel_1m_14t_30deg_2_collision.stl"/>        
      </geometry>      
    </collision>    
    <inertial>      
      <origin xyz="3.6393116992217144912e-10 -9.7220472557862924745e-10 -0.0066868955018979069072" rpy="0 0 0"/>      
      <mass value="0.00073261524436595492574"/>      
      <inertia ixx="1.349505601235447918e-08" ixy="2.5804135905735602914e-17" ixz="-1.0694296048242906771e-15" iyy="1.3495056157360913119e-08" iyz="-2.3876736921528802276e-16" izz="1.43559865498164051e-08"/>      
    </inertial>    
  </link>  

  <joint name="waist_act_2" type="revolute">    
    <origin xyz="1.9472970659157160941e-16 -0.019600000000000117328 -0.032749999999999668265" rpy="-1.57079632679489678 3.8965962276001972074e-16 3.1415926535897926719"/>    
    <parent link="waist_link"/>    
    <child link="spiral_bevel_1m_14t_30deg_2"/>    
    <axis xyz="0 0 1"/>    
    <limit effort="1" velocity="20" lower="-4.6774823953448034786" upper="4.6774823953448034786"/>    
    <joint_properties friction="0.0"/>    
  </joint>  

  <link name="left_leg_reorder">    
    <visual>      
      <origin xyz="0 0 0" rpy="0 -0 0"/>      
      <geometry>        
        <mesh filename="package:///meshes/left_leg_reorder_visual.stl"/>        
      </geometry>      
      <material name="left_leg_reorder_material">        
        <color rgba="0.67125174564315504 0.66259123591943502873 0.50873452868464419385 1.0"/>        
      </material>      
    </visual>    
    <collision>      
      <origin xyz="0 0 0" rpy="0 -0 0"/>      
      <geometry>        
        <mesh filename="package:///meshes/left_leg_reorder_collision.stl"/>        
      </geometry>      
    </collision>    
    <inertial>      
      <origin xyz="-0.14004310032214337123 0.0076779156245802828926 0.018403852067420584798" rpy="0 0 0"/>      
      <mass value="0.54605320559212666698"/>      
      <inertia ixx="0.00028121199318280234569" ixy="0.00014488591912408514293" ixz="7.9487341781585258522e-05" iyy="0.0047253643687760428158" iyz="1.5628077712350429777e-06" izz="0.0048807249094106599716"/>      
    </inertial>    
  </link>  

  <joint name="left_hip_pitch" type="revolute">    
    <origin xyz="0.056000000000000008105 -0.040100000000000003697 -0.022750000000000002859" rpy="-1.57079632679489678 7.6559821685211629859e-14 1.5707963267948958919"/>    
    <parent link="waist_link"/>    
    <child link="left_leg_reorder"/>    
    <axis xyz="0 0 1"/>    
    <limit effort="1" velocity="20" lower="-1.570796326794896558" upper="1.570796326794896558"/>    
    <joint_properties friction="0.0"/>    
  </joint>  

  <link name="right_leg_reorder">    
    <visual>      
      <origin xyz="0 0 0" rpy="0 -0 0"/>      
      <geometry>        
        <mesh filename="package:///meshes/right_leg_reorder_visual.stl"/>        
      </geometry>      
      <material name="right_leg_reorder_material">        
        <color rgba="0.67260686576466521824 0.65895322176029724748 0.49847513241630836411 1.0"/>        
      </material>      
    </visual>    
    <collision>      
      <origin xyz="0 0 0" rpy="0 -0 0"/>      
      <geometry>        
        <mesh filename="package:///meshes/right_leg_reorder_collision.stl"/>        
      </geometry>      
    </collision>    
    <inertial>      
      <origin xyz="-0.14091393089739767674 -0.0076819471052545678161 0.018478287565424186129" rpy="0 0 0"/>      
      <mass value="0.53305320559212665543"/>      
      <inertia ixx="0.00027837916779686167719" ixy="-0.0001551428337168543831" ixz="7.8439788384465511601e-05" iyy="0.0046979239296804772494" iyz="-3.1677341835336004591e-06" izz="0.004852566967991571445"/>      
    </inertial>    
  </link>  

  <joint name="right_hip_pitch" type="revolute">    
    <origin xyz="-0.056000000000000028921 -0.040100000000000003697 -0.022750000000000002859" rpy="1.5707963267948974462 -3.2312277008054088096e-16 1.57079632679489678"/>    
    <parent link="waist_link"/>    
    <child link="right_leg_reorder"/>    
    <axis xyz="0 0 1"/>    
    <limit effort="1" velocity="20" lower="-1.570796326794896558" upper="1.570796326794896558"/>    
    <joint_properties friction="0.0"/>    
  </joint>  

  <joint name="waist_roll" type="revolute">    
    <origin xyz="-0.022707865260692041559 -1.3173316226474365908e-17 -0.013999999999999970801" rpy="1.5707963267948956698 -1.6844078265464242354e-15 -1.5707963267949138775"/>    
    <parent link="waist_gears"/>    
    <child link="waist_link"/>    
    <axis xyz="0 0 1"/>    
    <limit effort="1" velocity="20" lower="-0.52359877559829881566" upper="0.52359877559829881566"/>    
    <joint_properties friction="0.0"/>    
  </joint>  

  <joint name="waist_yaw" type="revolute">    
    <origin xyz="0 -9.8607613152626475676e-32 -2.4651903288156618919e-32" rpy="-4.2812126708735032307e-16 -4.1243331367303584415e-15 3.141592653589773132"/>    
    <parent link="torso"/>    
    <child link="waist_gears"/>    
    <axis xyz="0 0 1"/>    
    <limit effort="1" velocity="20" lower="-1.570796326794896558" upper="1.570796326794896558"/>    
    <joint_properties friction="0.0"/>    
  </joint>  

  <link name="left_arm_gripper">    
    <visual>      
      <origin xyz="0 0 0" rpy="0 -0 0"/>      
      <geometry>        
        <mesh filename="package:///meshes/left_arm_gripper_visual.stl"/>        
      </geometry>      
      <material name="left_arm_gripper_material">        
        <color rgba="0.71128714652107449812 0.82073262204819508181 0.88138467549144106084 1.0"/>        
      </material>      
    </visual>    
    <collision>      
      <origin xyz="0 0 0" rpy="0 -0 0"/>      
      <geometry>        
        <mesh filename="package:///meshes/left_arm_gripper_collision.stl"/>        
      </geometry>      
    </collision>    
    <inertial>      
      <origin xyz="-0.001932659044316142969 0.11061885803461765643 0.03361881734102539071" rpy="0 0 0"/>      
      <mass value="0.52042116458808618251"/>      
      <inertia ixx="0.0032154498414414924359" ixy="6.8537467457095992379e-05" ixz="5.2232701625316415041e-06" iyy="0.00025119280335963745663" iyz="0.00010182485268993281497" izz="0.0032566528820161585317"/>      
    </inertial>    
  </link>  

  <joint name="left_sho_pitch" type="revolute">    
    <origin xyz="-0.0035000000000004762545 0.067000000000001072586 0.10423651076281729988" rpy="-1.5707963267949092145 2.5785047081963992394e-15 3.4723733359249287712e-14"/>    
    <parent link="torso"/>    
    <child link="left_arm_gripper"/>    
    <axis xyz="0 0 1"/>    
    <limit effort="1" velocity="20" lower="-3.141592653589793116" upper="1.570796326794896558"/>    
    <joint_properties friction="0.0"/>    
  </joint>  

  <link name="right_arm_gripper">    
    <visual>      
      <origin xyz="0 0 0" rpy="0 -0 0"/>      
      <geometry>        
        <mesh filename="package:///meshes/right_arm_gripper_visual.stl"/>        
      </geometry>      
      <material name="right_arm_gripper_material">        
        <color rgba="0.71129392197386009933 0.82073325762495596969 0.88138127170161628676 1.0"/>        
      </material>      
    </visual>    
    <collision>      
      <origin xyz="0 0 0" rpy="0 -0 0"/>      
      <geometry>        
        <mesh filename="package:///meshes/right_arm_gripper_collision.stl"/>        
      </geometry>      
    </collision>    
    <inertial>      
      <origin xyz="0.0017292252317782591618 0.11061212328512395886 0.033626654209001502482" rpy="0 0 0"/>      
      <mass value="0.52038428376188905489"/>      
      <inertia ixx="0.0032150796908002412557" ixy="-8.9633430834409517115e-05" ixz="-4.9915017369121383674e-06" iyy="0.00025152691215897537719" iyz="0.00010143998239745082555" izz="0.0032566851159774577208"/>      
    </inertial>    
  </link>  

  <joint name="right_sho_pitch" type="revolute">    
    <origin xyz="-0.003499999999998689923 -0.067000000000001017075 0.10423651076281729988" rpy="-1.5707963267948874542 -6.5632891966464542239e-16 -3.1415926535897562566"/>    
    <parent link="torso"/>    
    <child link="right_arm_gripper"/>    
    <axis xyz="0 0 1"/>    
    <limit effort="1" velocity="20" lower="-1.570796326794896558" upper="3.141592653589793116"/>    
    <joint_properties friction="0.0"/>    
  </joint>  


</robot>