<?xml version="1.0" ?>
<robot name="base">
  <mujoco>
    <compiler meshdir="./meshes/" balanceinertia="true" discardvisual="false"/>
  </mujoco>
  <link name="base_link"/>
  <joint name="base_link_to_base" type="fixed">
    <parent link="base_link"/>
    <child link="body_link"/>
    <origin rpy="0.0 0 0" xyz="0 0 0"/>
  </joint>
  <link name="body_link">
    <visual>
      <origin xyz="0 0 0" rpy="0 -0 0"/>
      <geometry>
        <mesh filename="package:///meshes/body_link_visual.stl"/>
      </geometry>
      <material name="body_link_material">
        <color rgba="0.53580639039093391762 0.69998047627233739298 0.84668014903378230329 1.0"/>
      </material>
    </visual>
    <collision>
      <origin xyz="0 0 0" rpy="0 -0 0"/>
      <geometry>
        <mesh filename="package:///meshes/body_link_collision.stl"/>
      </geometry>
    </collision>
    <inertial>
      <origin xyz="4.4062888745527807323e-07 -0.031200877436958440042 0.38395009077148650745" rpy="0 0 0"/>
      <mass value="0.4716507296967951679"/>
      <inertia ixx="0.0016502701144258742801" ixy="4.6150671745821693558e-09" ixz="1.3865307172731644418e-09" iyy="0.0023122151204157948001" iyz="-3.2514009219666046983e-05" izz="0.0011726853930432577962"/>
    </inertial>
  </link>

  <link name="neck_link">
    <visual>
      <origin xyz="0 0 0" rpy="0 -0 0"/>
      <geometry>
        <mesh filename="package:///meshes/neck_link_visual.stl"/>
      </geometry>
      <material name="neck_link_material">
        <color rgba="0.61568627450980395466 0.81176470588235294379 0.92941176470588238168 1.0"/>
      </material>
    </visual>
    <collision>
      <origin xyz="0 0 0" rpy="0 -0 0"/>
      <geometry>
        <mesh filename="package:///meshes/neck_link_collision.stl"/>
      </geometry>
    </collision>
    <inertial>
      <origin xyz="3.067903593042405049e-19 -9.1848509936051460494e-19 -0.020000000000000000416" rpy="0 0 0"/>
      <mass value="0.017530087007031042168"/>
      <inertia ixx="3.3234123284163032003e-06" ixy="1.8465957235571471562e-127" ixz="0" iyy="3.3234123284163027768e-06" iyz="0" izz="1.9721347882909923679e-06"/>
    </inertial>
  </link>

  <link name="head_link">
    <visual>
      <origin xyz="0 0 0" rpy="0 -0 0"/>
      <geometry>
        <mesh filename="package:///meshes/head_link_visual.stl"/>
      </geometry>
      <material name="head_link_material">
        <color rgba="0.8244834257167694691 0.81414666111596944997 0.81414666111596944997 1.0"/>
      </material>
    </visual>
    <collision>
      <origin xyz="0 0 0" rpy="0 -0 0"/>
      <geometry>
        <mesh filename="package:///meshes/head_link_collision.stl"/>
      </geometry>
    </collision>
    <inertial>
      <origin xyz="2.2358691188927194157e-06 0.0031409810842001660916 -0.015821710746315161694" rpy="0 0 0"/>
      <mass value="0.15100469056885920671"/>
      <inertia ixx="2.7899919689649162722e-05" ixy="-3.0790264907023376999e-09" ixz="4.6506397695285924459e-11" iyy="0.00011117941329446043687" iyz="1.8351221308312761573e-07" izz="0.00011573305954401320492"/>
    </inertial>
  </link>

  <joint name="head" type="fixed">
    <origin xyz="4.6467068165737631661e-19 0 -0.040000000000000035527" rpy="-1.232595164407830946e-32 2.9519052500171698995e-47 3.141592653589793116"/>
    <parent link="neck_link"/>
    <child link="head_link"/>
    <axis xyz="0 0 1"/>
    <limit effort="1" velocity="20"/>
    <joint_properties friction="0.0"/>
  </joint>

  <joint name="neck" type="fixed">
    <origin xyz="-1.0873011537518218883e-17 -0.040000000000000007772 0.45008542000000001382" rpy="-3.141592653589793116 7.7518614875493756421e-90 -1.2659750538598650252e-73"/>
    <parent link="body_link"/>
    <child link="neck_link"/>
    <axis xyz="0 0 1"/>
    <limit effort="1" velocity="20"/>
    <joint_properties friction="0.0"/>
  </joint>

  <link name="hip_yaw_link">
    <visual>
      <origin xyz="0 0 0" rpy="0 -0 0"/>
      <geometry>
        <mesh filename="package:///meshes/hip_yaw_link_visual.stl"/>
      </geometry>
      <material name="hip_yaw_link_material">
        <color rgba="0.61568627450980395466 0.81176470588235283277 0.92941176470588238168 1.0"/>
      </material>
    </visual>
    <collision>
      <origin xyz="0 0 0" rpy="0 -0 0"/>
      <geometry>
        <mesh filename="package:///meshes/hip_yaw_link_collision.stl"/>
      </geometry>
    </collision>
    <inertial>
      <origin xyz="-1.1681991270985256196e-17 -1.1139107640297753075e-18 -0.0084531286823173752004" rpy="0 0 0"/>
      <mass value="0.0052740645607467504311"/>
      <inertia ixx="7.614358849964589485e-07" ixy="7.0320919219684271592e-15" ixz="-6.0306382408684683927e-39" iyy="1.7966487931922594855e-06" iyz="3.7663539899376740174e-47" izz="1.8873281741438429697e-06"/>
    </inertial>
  </link>

  <link name="hip_roll_link">
    <visual>
      <origin xyz="0 0 0" rpy="0 -0 0"/>
      <geometry>
        <mesh filename="package:///meshes/hip_roll_link_visual.stl"/>
      </geometry>
      <material name="hip_roll_link_material">
        <color rgba="0.95018735644455853961 0.70678927200428420807 0.061612079402596657551 1.0"/>
      </material>
    </visual>
    <collision>
      <origin xyz="0 0 0" rpy="0 -0 0"/>
      <geometry>
        <mesh filename="package:///meshes/hip_roll_link_collision.stl"/>
      </geometry>
    </collision>
    <inertial>
      <origin xyz="-0.012000151133956809754 -0.00049588831385685228428 -0.018504019244503906727" rpy="0 0 0"/>
      <mass value="0.098012391483528735203"/>
      <inertia ixx="2.0221748766305799172e-05" ixy="-4.1552068247043917743e-08" ixz="-4.1225592187927114076e-08" iyy="2.7358099958306302267e-05" iyz="-5.0935731752408608315e-07" izz="2.7358069524722362237e-05"/>
    </inertial>
  </link>

  <link name="hip_pitch_link">
    <visual>
      <origin xyz="0 0 0" rpy="0 -0 0"/>
      <geometry>
        <mesh filename="package:///meshes/hip_pitch_link_visual.stl"/>
      </geometry>
      <material name="hip_pitch_link_material">
        <color rgba="0.61568627450980395466 0.81176470588235294379 0.92941176470588227065 1.0"/>
      </material>
    </visual>
    <collision>
      <origin xyz="0 0 0" rpy="0 -0 0"/>
      <geometry>
        <mesh filename="package:///meshes/hip_pitch_link_collision.stl"/>
      </geometry>
    </collision>
    <inertial>
      <origin xyz="-0.00014465123710724137399 0.055851948309978166618 0.027156881267530071783" rpy="0 0 0"/>
      <mass value="0.075144662701080278122"/>
      <inertia ixx="4.0191529808885790849e-05" ixy="1.6238444184410847836e-07" ixz="-1.4752139614485871613e-08" iyy="1.4356178520875670162e-05" iyz="-2.3026600051062387554e-06" izz="4.2265078109541244435e-05"/>
    </inertial>
  </link>

  <link name="knee_link">
    <visual>
      <origin xyz="0 0 0" rpy="0 -0 0"/>
      <geometry>
        <mesh filename="package:///meshes/knee_link_visual.stl"/>
      </geometry>
      <material name="knee_link_material">
        <color rgba="0.62989867807310029324 0.73714958717504697194 0.80150013263621500137 1.0"/>
      </material>
    </visual>
    <collision>
      <origin xyz="0 0 0" rpy="0 -0 0"/>
      <geometry>
        <mesh filename="package:///meshes/knee_link_collision.stl"/>
      </geometry>
    </collision>
    <inertial>
      <origin xyz="-1.3520703212394527225e-16 -5.2401712082168067093e-17 -0.0032457853126644543862" rpy="0 0 0"/>
      <mass value="0.0043868974356887722316"/>
      <inertia ixx="4.1908664095027489833e-07" ixy="-2.2987123577109412168e-21" ixz="-8.7610206646853655963e-21" iyy="4.1908664095026505157e-07" iyz="2.6293821239081367941e-21" izz="8.0521341717894291241e-07"/>
    </inertial>
  </link>

  <link name="left_ank_base_link">
    <visual>
      <origin xyz="0 0 0" rpy="0 -0 0"/>
      <geometry>
        <mesh filename="package:///meshes/left_ank_base_link_visual.stl"/>
      </geometry>
      <material name="left_ank_base_link_material">
        <color rgba="0.54555368846635599045 0.72113944167448473799 0.8707199484021568292 1.0"/>
      </material>
    </visual>
    <collision>
      <origin xyz="0 0 0" rpy="0 -0 0"/>
      <geometry>
        <mesh filename="package:///meshes/left_ank_base_link_collision.stl"/>
      </geometry>
    </collision>
    <inertial>
      <origin xyz="-0.0022434246051615362727 0.043104146371691250128 0.0063175709427246463934" rpy="0 0 0"/>
      <mass value="0.014262086197619733285"/>
      <inertia ixx="1.5262993546706292821e-05" ixy="9.1266662056319813633e-07" ixz="6.040493364465579793e-08" iyy="1.9634197931225637931e-06" iyz="-7.3113325087215847891e-08" izz="1.5076214983324559731e-05"/>
    </inertial>
  </link>

  <link name="ank_pitch_link">
    <visual>
      <origin xyz="0 0 0" rpy="0 -0 0"/>
      <geometry>
        <mesh filename="package:///meshes/ank_pitch_link_visual.stl"/>
      </geometry>
      <material name="ank_pitch_link_material">
        <color rgba="0.63157201649708316626 0.72836456044913711061 0.78644008682036958824 1.0"/>
      </material>
    </visual>
    <collision>
      <origin xyz="0 0 0" rpy="0 -0 0"/>
      <geometry>
        <mesh filename="package:///meshes/ank_pitch_link_collision.stl"/>
      </geometry>
    </collision>
    <inertial>
      <origin xyz="3.9220459207133841126e-08 0.00058467997205909787769 -0.014599924406174018265" rpy="0 0 0"/>
      <mass value="0.0041366725921694333726"/>
      <inertia ixx="4.3252419788339129617e-07" ixy="1.5885354050182112289e-13" ixz="1.5670565586567116992e-12" iyy="3.952240811177501216e-07" iyz="1.6638141700383117302e-14" izz="8.5883658455742298844e-08"/>
    </inertial>
  </link>

  <link name="ank_roll_link">
    <visual>
      <origin xyz="0 0 0" rpy="0 -0 0"/>
      <geometry>
        <mesh filename="package:///meshes/ank_roll_link_visual.stl"/>
      </geometry>
      <material name="ank_roll_link_material">
        <color rgba="0.61568627450980395466 0.81176470588235283277 0.92941176470588238168 1.0"/>
      </material>
    </visual>
    <collision>
      <origin xyz="0 0 0" rpy="0 -0 0"/>
      <geometry>
        <mesh filename="package:///meshes/ank_roll_link_collision.stl"/>
      </geometry>
    </collision>
    <inertial>
      <origin xyz="-1.490127190476588998e-10 -0.013684967917931582446 0.014389602633949047372" rpy="0 0 0"/>
      <mass value="0.0054237955467263104098"/>
      <inertia ixx="2.3215873123896830813e-06" ixy="-5.738920933986654138e-15" ixz="-9.0715784846414911742e-15" iyy="2.1054587922310816195e-06" iyz="3.6308271258505771065e-07" izz="5.6387331373110588065e-07"/>
    </inertial>
  </link>

  <link name="ank_rigid_foot_link">
    <visual>
      <origin xyz="0 0 0" rpy="0 -0 0"/>
      <geometry>
        <mesh filename="package:///meshes/ank_rigid_foot_link_visual.stl"/>
      </geometry>
      <material name="ank_rigid_foot_link_material">
        <color rgba="0.61568627450980395466 0.81176470588235294379 0.92941176470588238168 1.0"/>
      </material>
    </visual>
    <collision>
      <origin xyz="0 0 0" rpy="0 -0 0"/>
      <geometry>
        <mesh filename="package:///meshes/ank_rigid_foot_link_collision.stl"/>
      </geometry>
    </collision>
    <inertial>
      <origin xyz="-0.023731999094105324377 -9.4396649073929792118e-10 -0.013306321578886224841" rpy="0 0 0"/>
      <mass value="0.0082157357687249205763"/>
      <inertia ixx="6.5404454512568340557e-07" ixy="3.432055610231370444e-13" ixz="-3.2926756768140883475e-07" iyy="5.8836130895435074023e-06" iyz="-3.0207161987707742574e-15" izz="6.2852473690143518829e-06"/>
    </inertial>
  </link>

  <joint name="left_ank_foot" type="fixed">
    <origin xyz="0 -0.022500000000000006106 0.025599999999999990818" rpy="-1.570796326794896558 -1.570796326794896558 0"/>
    <parent link="ank_roll_link"/>
    <child link="ank_rigid_foot_link"/>
    <axis xyz="0 0 1"/>
    <limit effort="1" velocity="20"/>
    <joint_properties friction="0.0"/>
  </joint>

  <link name="ank_rr_link">
    <visual>
      <origin xyz="0 0 0" rpy="0 -0 0"/>
      <geometry>
        <mesh filename="package:///meshes/ank_rr_link_visual.stl"/>
      </geometry>
      <material name="ank_rr_link_material">
        <color rgba="0.61568627450980395466 0.81176470588235294379 0.92941176470588238168 1.0"/>
      </material>
    </visual>
    <collision>
      <origin xyz="0 0 0" rpy="0 -0 0"/>
      <geometry>
        <mesh filename="package:///meshes/ank_rr_link_collision.stl"/>
      </geometry>
    </collision>
    <inertial>
      <origin xyz="2.9962725549972257138e-05 -0.0069241283254153065604 -0.0018999999999999997793" rpy="0 0 0"/>
      <mass value="0.0004758513732428606177"/>
      <inertia ixx="1.1040705352249966614e-08" ixy="4.3855175770053759351e-11" ixz="-6.7102857729383692117e-15" iyy="9.5635364996381547659e-09" iyz="-1.6997728993677950709e-26" izz="1.4744115584475849801e-08"/>
    </inertial>
  </link>

  <link name="ank_act_rod_head">
    <visual>
      <origin xyz="0 0 0" rpy="0 -0 0"/>
      <geometry>
        <mesh filename="package:///meshes/ank_act_rod_head_visual.stl"/>
      </geometry>
      <material name="ank_act_rod_head_material">
        <color rgba="0.97254901960784312376 0.52941176470588235947 0.0039215686274509803377 1.0"/>
      </material>
    </visual>
    <collision>
      <origin xyz="0 0 0" rpy="0 -0 0"/>
      <geometry>
        <mesh filename="package:///meshes/ank_act_rod_head_collision.stl"/>
      </geometry>
    </collision>
    <inertial>
      <origin xyz="-5.7828416694377681847e-11 0.0033987031118029092588 -0.0020055782443104655695" rpy="0 0 0"/>
      <mass value="0.00066080012085386230676"/>
      <inertia ixx="1.0675794104648557829e-08" ixy="-1.8531171293784165066e-16" ixz="9.2603132968165965753e-16" iyy="2.3773718249661060612e-09" iyz="6.3401399719235198854e-12" izz="1.1538333246010974441e-08"/>
    </inertial>
  </link>

  <joint name="left_ank_R21" type="revolute">
    <origin xyz="0.0020000000000000087153 -0.010000000000000001943 -0.0019000000000000004299" rpy="-1.5707963267948961139 -1.553434520486503656 -1.5707963267948825692"/>
    <parent link="ank_rr_link"/>
    <child link="ank_act_rod_head"/>
    <axis xyz="0 0 1"/>
    <limit effort="1" velocity="20" lower="-1.570796326794896558" upper="1.570796326794896558"/>
    <joint_properties friction="0.0"/>
  </joint>

  <joint name="left_ank_R11" type="revolute">
    <origin xyz="0.010000000000000001943 -0.012500000000000007633 0.040599999999999990263" rpy="5.5133286511563240655e-17 -1.424248725567722883e-16 3.0761399207850415038"/>
    <parent link="ank_roll_link"/>
    <child link="ank_rr_link"/>
    <axis xyz="0 0 1"/>
    <limit effort="1" velocity="20" lower="-1.570796326794896558" upper="1.570796326794896558"/>
    <joint_properties friction="0.0"/>
  </joint>

  <link name="ank_rr_link_2">
    <visual>
      <origin xyz="0 0 0" rpy="0 -0 0"/>
      <geometry>
        <mesh filename="package:///meshes/ank_rr_link_2_visual.stl"/>
      </geometry>
      <material name="ank_rr_link_2_material">
        <color rgba="0.61568627450980395466 0.81176470588235294379 0.92941176470588238168 1.0"/>
      </material>
    </visual>
    <collision>
      <origin xyz="0 0 0" rpy="0 -0 0"/>
      <geometry>
        <mesh filename="package:///meshes/ank_rr_link_2_collision.stl"/>
      </geometry>
    </collision>
    <inertial>
      <origin xyz="2.9962725549968913051e-05 0.0069241283254153161014 -0.001900000000000000213" rpy="0 0 0"/>
      <mass value="0.0004758513732428606177"/>
      <inertia ixx="1.1040705352249966614e-08" ixy="-4.3855175770053132503e-11" ixz="6.710285772940114172e-15" iyy="9.5635364996381613833e-09" iyz="-1.098017434635281399e-26" izz="1.4744115584475846492e-08"/>
    </inertial>
  </link>

  <link name="ank_act_rod_head_2">
    <visual>
      <origin xyz="0 0 0" rpy="0 -0 0"/>
      <geometry>
        <mesh filename="package:///meshes/ank_act_rod_head_2_visual.stl"/>
      </geometry>
      <material name="ank_act_rod_head_2_material">
        <color rgba="0.97254901960784312376 0.52941176470588235947 0.0039215686274509803377 1.0"/>
      </material>
    </visual>
    <collision>
      <origin xyz="0 0 0" rpy="0 -0 0"/>
      <geometry>
        <mesh filename="package:///meshes/ank_act_rod_head_2_collision.stl"/>
      </geometry>
    </collision>
    <inertial>
      <origin xyz="-5.7828415828288651704e-11 0.0033987031118029092588 -0.0020055782443104551611" rpy="0 0 0"/>
      <mass value="0.00066080012085386230676"/>
      <inertia ixx="1.067579410464855452e-08" ixy="-1.8531171292855439122e-16" ixz="9.2603132968162731423e-16" iyy="2.3773718249661060612e-09" iyz="6.340139971923948016e-12" izz="1.1538333246010974441e-08"/>
    </inertial>
  </link>

  <joint name="left_ank_R22" type="revolute">
    <origin xyz="0.0020000000000000017764 0.010000000000000001943 -0.0018999999999999995625" rpy="-1.5707963267949007768 1.5676670403457919623 -1.5707963267947144814"/>
    <parent link="ank_rr_link_2"/>
    <child link="ank_act_rod_head_2"/>
    <axis xyz="0 0 1"/>
    <limit effort="1" velocity="20" lower="-1.570796326794896558" upper="1.570796326794896558"/>
    <joint_properties friction="0.0"/>
  </joint>

  <joint name="left_ank_R12" type="revolute">
    <origin xyz="-0.010000000000000008882 -0.012500000000000000694 0.040599999999999997202" rpy="-1.0021582319192169566e-15 1.9109166915830268034e-16 0.075580800785917862106"/>
    <parent link="ank_roll_link"/>
    <child link="ank_rr_link_2"/>
    <axis xyz="0 0 1"/>
    <limit effort="1" velocity="20" lower="-1.570796326794896558" upper="1.570796326794896558"/>
    <joint_properties friction="0.0"/>
  </joint>

  <joint name="left_ank_roll" type="revolute">
    <origin xyz="0 0.0014999999999999943934 -0.014599999999999994926" rpy="1.5707963267948952257 -1.5707963267948858999 0"/>
    <parent link="ank_pitch_link"/>
    <child link="ank_roll_link"/>
    <axis xyz="0 0 1"/>
    <limit effort="1" velocity="20" lower="-1.570796326794896558" upper="1.570796326794896558"/>
    <joint_properties friction="0.0"/>
  </joint>

  <joint name="left_ank_pitch" type="revolute">
    <origin xyz="0 0.10000000000000003331 0.020899999999999988032" rpy="7.807247938257453967e-15 5.4959122264044313487e-15 1.5707963267949247577"/>
    <parent link="left_ank_base_link"/>
    <child link="ank_pitch_link"/>
    <axis xyz="0 0 1"/>
    <limit effort="1" velocity="20" lower="-1.570796326794896558" upper="1.570796326794896558"/>
    <joint_properties friction="0.0"/>
  </joint>

  <link name="ank_b_link">
    <visual>
      <origin xyz="0 0 0" rpy="0 -0 0"/>
      <geometry>
        <mesh filename="package:///meshes/ank_b_link_visual.stl"/>
      </geometry>
      <material name="ank_b_link_material">
        <color rgba="0.61568627450980406568 0.81176470588235294379 0.92941176470588238168 1.0"/>
      </material>
    </visual>
    <collision>
      <origin xyz="0 0 0" rpy="0 -0 0"/>
      <geometry>
        <mesh filename="package:///meshes/ank_b_link_collision.stl"/>
      </geometry>
    </collision>
    <inertial>
      <origin xyz="-4.9409968174917390889e-09 -5.9508723608339456203e-09 -0.0087165888679858073013" rpy="0 0 0"/>
      <mass value="0.00089583742203429468642"/>
      <inertia ixx="3.3822537554673509423e-08" ixy="3.9003059563514540252e-15" ixz="1.5176340834792994863e-14" iyy="4.5803979388252428374e-08" iyz="5.2207519907226496779e-14" izz="2.594683440225980531e-08"/>
    </inertial>
  </link>

  <link name="ank_act_link_head">
    <visual>
      <origin xyz="0 0 0" rpy="0 -0 0"/>
      <geometry>
        <mesh filename="package:///meshes/ank_act_link_head_visual.stl"/>
      </geometry>
      <material name="ank_act_link_head_material">
        <color rgba="0.8805660089056220885 0.88861789403065327697 0.90620490627743233158 1.0"/>
      </material>
    </visual>
    <collision>
      <origin xyz="0 0 0" rpy="0 -0 0"/>
      <geometry>
        <mesh filename="package:///meshes/ank_act_link_head_collision.stl"/>
      </geometry>
    </collision>
    <inertial>
      <origin xyz="8.5302207312373262101e-09 -0.0023472231756390153287 -0.0043000180232788580773" rpy="0 0 0"/>
      <mass value="0.0030517714925792842166"/>
      <inertia ixx="5.2970409371069197923e-08" ixy="-5.7058840887309489613e-14" ixz="1.0325254833995590953e-14" iyy="5.6254659413317869681e-08" iyz="1.1646556511412900509e-13" izz="6.2451084839898899757e-08"/>
    </inertial>
  </link>

  <link name="ank_act_link">
    <visual>
      <origin xyz="0 0 0" rpy="0 -0 0"/>
      <geometry>
        <mesh filename="package:///meshes/ank_act_link_visual.stl"/>
      </geometry>
      <material name="ank_act_link_material">
        <color rgba="0.62004392100736016591 0.58836684613512635345 0.49897069021535694899 1.0"/>
      </material>
    </visual>
    <collision>
      <origin xyz="0 0 0" rpy="0 -0 0"/>
      <geometry>
        <mesh filename="package:///meshes/ank_act_link_collision.stl"/>
      </geometry>
    </collision>
    <inertial>
      <origin xyz="0.004908420724366375186 -0.00013802439943784450011 -0.029947003577140057784" rpy="0 0 0"/>
      <mass value="0.044782197696050352054"/>
      <inertia ixx="1.5260128421306930316e-05" ixy="2.2955773687012661745e-08" ixz="-8.1364204007747517915e-08" iyy="1.8188469778944165459e-05" iyz="-5.5542240843933083663e-08" izz="5.1496273901721851133e-06"/>
    </inertial>
  </link>

  <link name="ank_act_rod">
    <visual>
      <origin xyz="0 0 0" rpy="0 -0 0"/>
      <geometry>
        <mesh filename="package:///meshes/ank_act_rod_visual.stl"/>
      </geometry>
      <material name="ank_act_rod_material">
        <color rgba="0.80016770676329840306 0.8929145636529542962 0.94547111589042631685 1.0"/>
      </material>
    </visual>
    <collision>
      <origin xyz="0 0 0" rpy="0 -0 0"/>
      <geometry>
        <mesh filename="package:///meshes/ank_act_rod_collision.stl"/>
      </geometry>
    </collision>
    <inertial>
      <origin xyz="-2.7254954593108692827e-06 -1.2667795959805515127e-05 0.0060054807227727970143" rpy="0 0 0"/>
      <mass value="0.0026945559868381376359"/>
      <inertia ixx="3.2231832056348304084e-07" ixy="-9.9380293173453290022e-13" ixz="1.0490654904665966313e-10" iyy="3.2231218697769351762e-07" iyz="5.6317539914555571603e-10" izz="1.8746557075763206192e-08"/>
    </inertial>
  </link>

  <joint name="left_ank_act1" type="prismatic">
    <origin xyz="2.2722093435375081971e-06 -2.3071822230491534356e-15 -0.059207313423202775904" rpy="3.141592653589793116 4.2775187765792706995e-15 -0.63671356442004245491"/>
    <parent link="ank_act_link"/>
    <child link="ank_act_rod"/>
    <axis xyz="0 0 1"/>
    <limit effort="1" velocity="20" lower="-0.017000000000000001221" upper="0.017000000000000001221"/>
    <joint_properties friction="0.0"/>
  </joint>

  <joint name="left_ank_B31" type="revolute">
    <origin xyz="-8.6736173798840354721e-19 -0.0060500000000000275779 -0.0043000000000000121458" rpy="1.570796326794896558 5.4574690878165813072e-06 3.1415926535897908956"/>
    <parent link="ank_act_link_head"/>
    <child link="ank_act_link"/>
    <axis xyz="0 0 1"/>
    <limit effort="1" velocity="20" lower="-1.570796326794896558" upper="1.570796326794896558"/>
    <joint_properties friction="0.0"/>
  </joint>

  <joint name="left_ank_B21" type="revolute">
    <origin xyz="-0.0045000000000000074662 0 -0.016999999999999997752" rpy="1.570796326794896336 1.5534345204864428158 -1.570796326794806852"/>
    <parent link="ank_b_link"/>
    <child link="ank_act_link_head"/>
    <axis xyz="0 0 1"/>
    <limit effort="1" velocity="20" lower="-1.570796326794896558" upper="1.570796326794896558"/>
    <joint_properties friction="0.0"/>
  </joint>

  <joint name="left_ank_B11" type="revolute">
    <origin xyz="0.018680019623525546263 0.010000000000000064393 0.02340000000000000413" rpy="-1.570796326794896558 -1.5053435939903097029 1.5707963267948918951"/>
    <parent link="left_ank_base_link"/>
    <child link="ank_b_link"/>
    <axis xyz="0 0 1"/>
    <limit effort="1" velocity="20" lower="-1.570796326794896558" upper="1.570796326794896558"/>
    <joint_properties friction="0.0"/>
  </joint>

  <link name="ank_b_link_2">
    <visual>
      <origin xyz="0 0 0" rpy="0 -0 0"/>
      <geometry>
        <mesh filename="package:///meshes/ank_b_link_2_visual.stl"/>
      </geometry>
      <material name="ank_b_link_2_material">
        <color rgba="0.61568627450980406568 0.81176470588235294379 0.92941176470588238168 1.0"/>
      </material>
    </visual>
    <collision>
      <origin xyz="0 0 0" rpy="0 -0 0"/>
      <geometry>
        <mesh filename="package:///meshes/ank_b_link_2_collision.stl"/>
      </geometry>
    </collision>
    <inertial>
      <origin xyz="-4.9409968105519146069e-09 5.9508723330967855267e-09 0.0087165888679858073013" rpy="0 0 0"/>
      <mass value="0.00089583742203429468642"/>
      <inertia ixx="3.3822537554673522657e-08" ixy="-3.9003059553415645495e-15" ixz="-1.517634083479588525e-14" iyy="4.5803979388252454843e-08" iyz="5.2207519907266482561e-14" izz="2.594683440225980531e-08"/>
    </inertial>
  </link>

  <link name="ank_act_link_head_2">
    <visual>
      <origin xyz="0 0 0" rpy="0 -0 0"/>
      <geometry>
        <mesh filename="package:///meshes/ank_act_link_head_2_visual.stl"/>
      </geometry>
      <material name="ank_act_link_head_2_material">
        <color rgba="0.8805660089056220885 0.88861789403065327697 0.90620490627743233158 1.0"/>
      </material>
    </visual>
    <collision>
      <origin xyz="0 0 0" rpy="0 -0 0"/>
      <geometry>
        <mesh filename="package:///meshes/ank_act_link_head_2_collision.stl"/>
      </geometry>
    </collision>
    <inertial>
      <origin xyz="8.530220741948524358e-09 0.0023472231756390227013 -0.0042999819767212330013" rpy="0 0 0"/>
      <mass value="0.0030517714925792842166"/>
      <inertia ixx="5.2970409371068833963e-08" ixy="5.7058840790942721059e-14" ixz="-1.0325254833610978663e-14" iyy="5.6254659413317882916e-08" iyz="1.1646556603205649062e-13" izz="6.2451084839898568884e-08"/>
    </inertial>
  </link>

  <link name="ank_act_link_2">
    <visual>
      <origin xyz="0 0 0" rpy="0 -0 0"/>
      <geometry>
        <mesh filename="package:///meshes/ank_act_link_2_visual.stl"/>
      </geometry>
      <material name="ank_act_link_2_material">
        <color rgba="0.62004392100736016591 0.58836684613512624242 0.4989706902153570045 1.0"/>
      </material>
    </visual>
    <collision>
      <origin xyz="0 0 0" rpy="0 -0 0"/>
      <geometry>
        <mesh filename="package:///meshes/ank_act_link_2_collision.stl"/>
      </geometry>
    </collision>
    <inertial>
      <origin xyz="0.0049084207243662511533 -0.00013802439943664125254 -0.029947003577138222447" rpy="0 0 0"/>
      <mass value="0.044782197696050358993"/>
      <inertia ixx="1.5260128421305517465e-05" ixy="2.2955773687102387681e-08" ixz="-8.1364204007729796397e-08" iyy="1.8188469778942888133e-05" iyz="-5.5542240843467744938e-08" izz="5.1496273901723545199e-06"/>
    </inertial>
  </link>

  <link name="ank_act_rod_2">
    <visual>
      <origin xyz="0 0 0" rpy="0 -0 0"/>
      <geometry>
        <mesh filename="package:///meshes/ank_act_rod_2_visual.stl"/>
      </geometry>
      <material name="ank_act_rod_2_material">
        <color rgba="0.80016770676329840306 0.8929145636529542962 0.94547111589042631685 1.0"/>
      </material>
    </visual>
    <collision>
      <origin xyz="0 0 0" rpy="0 -0 0"/>
      <geometry>
        <mesh filename="package:///meshes/ank_act_rod_2_collision.stl"/>
      </geometry>
    </collision>
    <inertial>
      <origin xyz="-2.725495458492131471e-06 -1.2667795960106567577e-05 0.006005480722770245236" rpy="0 0 0"/>
      <mass value="0.0026945559868381376359"/>
      <inertia ixx="3.2231832056332374571e-07" ixy="-9.9380293164140015846e-13" ixz="1.049065490212628531e-10" iyy="3.2231218697753416955e-07" iyz="5.6317539915542377394e-10" izz="1.8746557075763196266e-08"/>
    </inertial>
  </link>

  <joint name="left_ank_act2" type="prismatic">
    <origin xyz="2.2722093432694934201e-06 -4.024558464266192459e-16 -0.059246516530146259294" rpy="-3.141592653589793116 -1.9929871652631197461e-17 -0.63671356442003623766"/>
    <parent link="ank_act_link_2"/>
    <child link="ank_act_rod_2"/>
    <axis xyz="0 0 1"/>
    <limit effort="1" velocity="20" lower="-0.017000000000000001221" upper="0.017000000000000001221"/>
    <joint_properties friction="0.0"/>
  </joint>

  <joint name="left_ank_B32" type="revolute">
    <origin xyz="-8.6736173798840354721e-19 0.0060500000000000553335 -0.0042999999999999913292" rpy="-1.570796326794896558 -5.4574693029296022226e-06 -3.141592653589793116"/>
    <parent link="ank_act_link_head_2"/>
    <child link="ank_act_link_2"/>
    <axis xyz="0 0 1"/>
    <limit effort="1" velocity="20" lower="-1.570796326794896558" upper="1.570796326794896558"/>
    <joint_properties friction="0.0"/>
  </joint>

  <joint name="left_ank_B22" type="revolute">
    <origin xyz="-0.0044999999999999970579 -2.7755575615628913511e-17 0.016999999999999997752" rpy="1.570796326794896558 -1.5676670403455679192 -1.5707963267926954298"/>
    <parent link="ank_b_link_2"/>
    <child link="ank_act_link_head_2"/>
    <axis xyz="0 0 1"/>
    <limit effort="1" velocity="20" lower="-1.570796326794896558" upper="1.570796326794896558"/>
    <joint_properties friction="0.0"/>
  </joint>

  <joint name="left_ank_B12" type="revolute">
    <origin xyz="0.020000000000000007355 0.0099999999999999811262 -0.011500000000000003275" rpy="1.570796326794896558 1.4952155260088222377 1.5707963267949036634"/>
    <parent link="left_ank_base_link"/>
    <child link="ank_b_link_2"/>
    <axis xyz="0 0 1"/>
    <limit effort="1" velocity="20" lower="-1.570796326794896558" upper="1.570796326794896558"/>
    <joint_properties friction="0.0"/>
  </joint>

  <joint name="left_ank_base" type="fixed">
    <origin xyz="-2.6367796834847467835e-16 -9.7144514654701197287e-17 -0.0065000000000002416956" rpy="-3.3438186186406859098e-14 -6.9220172543623322901e-15 -2.0891591146372241461"/>
    <parent link="knee_link"/>
    <child link="left_ank_base_link"/>
    <axis xyz="0 0 1"/>
    <limit effort="1" velocity="20"/>
    <joint_properties friction="0.0"/>
  </joint>

  <joint name="left_knee" type="revolute">
    <origin xyz="-4.1633363423443370266e-17 0.10750000000000001221 0.02149999999999999481" rpy="3.1415926535897895633 2.6314965551403718944e-14 1.047197551196626053"/>
    <parent link="hip_pitch_link"/>
    <child link="knee_link"/>
    <axis xyz="0 0 1"/>
    <limit effort="1" velocity="20" lower="-1.0471975511965976313" upper="2.0943951023931952626"/>
    <joint_properties friction="0.0"/>
  </joint>

  <joint name="left_hip_pitch" type="revolute">
    <origin xyz="-0.024000000716140224011 -0.019000000152450662733 -0.019000000152448726781" rpy="-1.5707963267948796826 1.5707963267948239494 0"/>
    <parent link="hip_roll_link"/>
    <child link="hip_pitch_link"/>
    <axis xyz="0 0 1"/>
    <limit effort="1" velocity="20" lower="-1.570796326794896558" upper="1.570796326794896558"/>
    <joint_properties friction="0.0"/>
  </joint>

  <joint name="left_hip_roll" type="revolute">
    <origin xyz="0.018999999999999992589 -6.9388939039072283776e-18 -0.027499999999999968914" rpy="3.141592653589793116 -1.5707963267948794606 0"/>
    <parent link="hip_yaw_link"/>
    <child link="hip_roll_link"/>
    <axis xyz="0 0 1"/>
    <limit effort="1" velocity="20" lower="-1.570796326794896558" upper="1.570796326794896558"/>
    <joint_properties friction="0.0"/>
  </joint>

  <joint name="left_hip_yaw" type="revolute">
    <origin xyz="0.034999999999999989453 -0.039999999999999993894 0.29868541999999997927" rpy="4.1258627841574100087e-29 -6.1232339957431151336e-17 1.5707963267949682784"/>
    <parent link="body_link"/>
    <child link="hip_yaw_link"/>
    <axis xyz="0 0 1"/>
    <limit effort="1" velocity="20" lower="-1.570796326794896558" upper="1.570796326794896558"/>
    <joint_properties friction="0.0"/>
  </joint>

  <link name="hip_yaw_link_2">
    <visual>
      <origin xyz="0 0 0" rpy="0 -0 0"/>
      <geometry>
        <mesh filename="package:///meshes/hip_yaw_link_2_visual.stl"/>
      </geometry>
      <material name="hip_yaw_link_2_material">
        <color rgba="0.61568627450980395466 0.81176470588235283277 0.92941176470588238168 1.0"/>
      </material>
    </visual>
    <collision>
      <origin xyz="0 0 0" rpy="0 -0 0"/>
      <geometry>
        <mesh filename="package:///meshes/hip_yaw_link_2_collision.stl"/>
      </geometry>
    </collision>
    <inertial>
      <origin xyz="-4.7430973670780293593e-18 -1.1139107640297753075e-18 -0.0084531286823174307116" rpy="0 0 0"/>
      <mass value="0.0052740645607467504311"/>
      <inertia ixx="7.614358849964589485e-07" ixy="7.0320919219684271592e-15" ixz="0" iyy="1.7966487931922594855e-06" iyz="0" izz="1.8873281741438429697e-06"/>
    </inertial>
  </link>

  <link name="hip_roll_link_2">
    <visual>
      <origin xyz="0 0 0" rpy="0 -0 0"/>
      <geometry>
        <mesh filename="package:///meshes/hip_roll_link_2_visual.stl"/>
      </geometry>
      <material name="hip_roll_link_2_material">
        <color rgba="0.95018735644455831757 0.70678927200428420807 0.061612079402596671429 1.0"/>
      </material>
    </visual>
    <collision>
      <origin xyz="0 0 0" rpy="0 -0 0"/>
      <geometry>
        <mesh filename="package:///meshes/hip_roll_link_2_collision.stl"/>
      </geometry>
    </collision>
    <inertial>
      <origin xyz="-0.01200015113395831029 -0.00049588831385787273537 -0.01850401924450633187" rpy="0 0 0"/>
      <mass value="0.098012391483528735203"/>
      <inertia ixx="2.0221748766306612324e-05" ixy="-4.1552068246646480619e-08" ixz="-4.1225592188257595892e-08" iyy="2.7358099958306996834e-05" iyz="-5.0935731752411551755e-07" izz="2.7358069524723168612e-05"/>
    </inertial>
  </link>

  <link name="hip_pitch_link_2">
    <visual>
      <origin xyz="0 0 0" rpy="0 -0 0"/>
      <geometry>
        <mesh filename="package:///meshes/hip_pitch_link_2_visual.stl"/>
      </geometry>
      <material name="hip_pitch_link_2_material">
        <color rgba="0.61568627450980395466 0.81176470588235294379 0.92941176470588227065 1.0"/>
      </material>
    </visual>
    <collision>
      <origin xyz="0 0 0" rpy="0 -0 0"/>
      <geometry>
        <mesh filename="package:///meshes/hip_pitch_link_2_collision.stl"/>
      </geometry>
    </collision>
    <inertial>
      <origin xyz="-0.00014465123710724137399 -0.055851948309978104168 0.010843118732469946355" rpy="0 0 0"/>
      <mass value="0.075144662701080278122"/>
      <inertia ixx="4.019152980888577052e-05" ixy="-1.6238444184424675649e-07" ixz="1.4752139614346968136e-08" iyy="1.4356178520875580377e-05" iyz="-2.3026600051060799368e-06" izz="4.2265078109541224106e-05"/>
    </inertial>
  </link>

  <link name="knee_link_2">
    <visual>
      <origin xyz="0 0 0" rpy="0 -0 0"/>
      <geometry>
        <mesh filename="package:///meshes/knee_link_2_visual.stl"/>
      </geometry>
      <material name="knee_link_2_material">
        <color rgba="0.62989867807310029324 0.73714958717504697194 0.80150013263621500137 1.0"/>
      </material>
    </visual>
    <collision>
      <origin xyz="0 0 0" rpy="0 -0 0"/>
      <geometry>
        <mesh filename="package:///meshes/knee_link_2_collision.stl"/>
      </geometry>
    </collision>
    <inertial>
      <origin xyz="1.3474843285168849936e-17 3.6617563060250645358e-19 -0.0032457853126643277514" rpy="0 0 0"/>
      <mass value="0.0043868974356887722316"/>
      <inertia ixx="4.1908664095027246311e-07" ixy="2.0774760947716004696e-22" ixz="1.2387881013846626109e-22" iyy="4.1908664095027283369e-07" iyz="1.1580214084498681999e-22" izz="8.052134171789363479e-07"/>
    </inertial>
  </link>

  <link name="right_ank_base_link">
    <visual>
      <origin xyz="0 0 0" rpy="0 -0 0"/>
      <geometry>
        <mesh filename="package:///meshes/right_ank_base_link_visual.stl"/>
      </geometry>
      <material name="right_ank_base_link_material">
        <color rgba="0.5455536855413490871 0.7211394378947934003 0.87071994595430790564 1.0"/>
      </material>
    </visual>
    <collision>
      <origin xyz="0 0 0" rpy="0 -0 0"/>
      <geometry>
        <mesh filename="package:///meshes/right_ank_base_link_collision.stl"/>
      </geometry>
    </collision>
    <inertial>
      <origin xyz="-0.0022434246825545570841 -0.043104144816367782889 0.0063175704226240449179" rpy="0 0 0"/>
      <mass value="0.014262085602793541511"/>
      <inertia ixx="1.5262992632425661772e-05" ixy="-9.126666437101549421e-07" ixz="6.0404946505410351883e-08" iyy="1.9634196913479027744e-06" iyz="7.311305965850864211e-08" izz="1.5076214172992284614e-05"/>
    </inertial>
  </link>

  <link name="ank_pitch_link_2">
    <visual>
      <origin xyz="0 0 0" rpy="0 -0 0"/>
      <geometry>
        <mesh filename="package:///meshes/ank_pitch_link_2_visual.stl"/>
      </geometry>
      <material name="ank_pitch_link_2_material">
        <color rgba="0.63157201649708305524 0.72836456044913699959 0.78644008682036936619 1.0"/>
      </material>
    </visual>
    <collision>
      <origin xyz="0 0 0" rpy="0 -0 0"/>
      <geometry>
        <mesh filename="package:///meshes/ank_pitch_link_2_collision.stl"/>
      </geometry>
    </collision>
    <inertial>
      <origin xyz="3.9220459202245925007e-08 0.0005846799720591016724 -0.014599924406174028674" rpy="0 0 0"/>
      <mass value="0.0041366725921694342399"/>
      <inertia ixx="4.325241978833921432e-07" ixy="1.5885354046326463107e-13" ixz="1.5670565585478508128e-12" iyy="3.9522408111775075688e-07" iyz="1.6638141821151486735e-14" izz="8.5883658455742484132e-08"/>
    </inertial>
  </link>

  <link name="ank_roll_link_2">
    <visual>
      <origin xyz="0 0 0" rpy="0 -0 0"/>
      <geometry>
        <mesh filename="package:///meshes/ank_roll_link_2_visual.stl"/>
      </geometry>
      <material name="ank_roll_link_2_material">
        <color rgba="0.61568627450980395466 0.81176470588235283277 0.92941176470588238168 1.0"/>
      </material>
    </visual>
    <collision>
      <origin xyz="0 0 0" rpy="0 -0 0"/>
      <geometry>
        <mesh filename="package:///meshes/ank_roll_link_2_collision.stl"/>
      </geometry>
    </collision>
    <inertial>
      <origin xyz="-1.4901271210876499589e-10 -0.013684967917931578976 0.014389602633949056046" rpy="0 0 0"/>
      <mass value="0.0054237955467263104098"/>
      <inertia ixx="2.3215873123896830813e-06" ixy="-5.738920933986654138e-15" ixz="-9.0715784846414911742e-15" iyy="2.1054587922310816195e-06" iyz="3.6308271258505771065e-07" izz="5.6387331373110588065e-07"/>
    </inertial>
  </link>

  <link name="ank_rigid_foot_link_2">
    <visual>
      <origin xyz="0 0 0" rpy="0 -0 0"/>
      <geometry>
        <mesh filename="package:///meshes/ank_rigid_foot_link_2_visual.stl"/>
      </geometry>
      <material name="ank_rigid_foot_link_2_material">
        <color rgba="0.61568627450980395466 0.81176470588235294379 0.92941176470588238168 1.0"/>
      </material>
    </visual>
    <collision>
      <origin xyz="0 0 0" rpy="0 -0 0"/>
      <geometry>
        <mesh filename="package:///meshes/ank_rigid_foot_link_2_collision.stl"/>
      </geometry>
    </collision>
    <inertial>
      <origin xyz="-0.023731999094105331316 -9.4396648380040401727e-10 -0.013306321578886224841" rpy="0 0 0"/>
      <mass value="0.0082157357687249205763"/>
      <inertia ixx="6.5404454512568361732e-07" ixy="3.4320556102313714538e-13" ixz="-3.2926756768140883475e-07" iyy="5.8836130895435074023e-06" iyz="-3.020716198770773863e-15" izz="6.2852473690143501888e-06"/>
    </inertial>
  </link>

  <joint name="right_ank_foot" type="fixed">
    <origin xyz="6.9388939039072283776e-18 -0.022499999999999999167 0.025600000000000018574" rpy="-1.5707963267949041075 -1.570796326794896558 0"/>
    <parent link="ank_roll_link_2"/>
    <child link="ank_rigid_foot_link_2"/>
    <axis xyz="0 0 1"/>
    <limit effort="1" velocity="20"/>
    <joint_properties friction="0.0"/>
  </joint>

  <link name="ank_rr_link_3">
    <visual>
      <origin xyz="0 0 0" rpy="0 -0 0"/>
      <geometry>
        <mesh filename="package:///meshes/ank_rr_link_3_visual.stl"/>
      </geometry>
      <material name="ank_rr_link_3_material">
        <color rgba="0.61568627450980395466 0.81176470588235294379 0.92941176470588238168 1.0"/>
      </material>
    </visual>
    <collision>
      <origin xyz="0 0 0" rpy="0 -0 0"/>
      <geometry>
        <mesh filename="package:///meshes/ank_rr_link_3_collision.stl"/>
      </geometry>
    </collision>
    <inertial>
      <origin xyz="2.9962725549962011427e-05 -0.0069241283254153143667 -0.0018999999999999999962" rpy="0 0 0"/>
      <mass value="0.0004758513732428606177"/>
      <inertia ixx="1.1040705352249966614e-08" ixy="4.3855175770053423309e-11" ixz="-6.7102857729409661418e-15" iyy="9.5635364996381580746e-09" iyz="-5.9318350334710539236e-27" izz="1.4744115584475849801e-08"/>
    </inertial>
  </link>

  <link name="ank_act_rod_head_3">
    <visual>
      <origin xyz="0 0 0" rpy="0 -0 0"/>
      <geometry>
        <mesh filename="package:///meshes/ank_act_rod_head_3_visual.stl"/>
      </geometry>
      <material name="ank_act_rod_head_3_material">
        <color rgba="0.97254901960784312376 0.52941176470588235947 0.0039215686274509803377 1.0"/>
      </material>
    </visual>
    <collision>
      <origin xyz="0 0 0" rpy="0 -0 0"/>
      <geometry>
        <mesh filename="package:///meshes/ank_act_rod_head_3_collision.stl"/>
      </geometry>
    </collision>
    <inertial>
      <origin xyz="-5.78284158276621981e-11 0.0033987031118029161977 -0.0020055782443104621" rpy="0 0 0"/>
      <mass value="0.00066080012085386230676"/>
      <inertia ixx="1.067579410464855452e-08" ixy="-1.8531171293152625212e-16" ixz="9.2603132968057852366e-16" iyy="2.3773718249661060612e-09" iyz="6.3401399719238123066e-12" izz="1.1538333246010974441e-08"/>
    </inertial>
  </link>

  <joint name="right_ank_R21" type="revolute">
    <origin xyz="0.0019999999999999948375 -0.009999999999999995004 -0.001900000000000000213" rpy="-1.5707963267948972241 -1.5676670168132933458 -1.570796326795488973"/>
    <parent link="ank_rr_link_3"/>
    <child link="ank_act_rod_head_3"/>
    <axis xyz="0 0 1"/>
    <limit effort="1" velocity="20" lower="-1.570796326794896558" upper="1.570796326794896558"/>
    <joint_properties friction="0.0"/>
  </joint>

  <joint name="right_ank_R11" type="revolute">
    <origin xyz="0.0099999999999999880651 -0.012499999999999993755 0.040600000000000004141" rpy="1.838132558719167337e-14 -1.968550043761323508e-15 3.0693447373542399603"/>
    <parent link="ank_roll_link_2"/>
    <child link="ank_rr_link_3"/>
    <axis xyz="0 0 1"/>
    <limit effort="1" velocity="20" lower="-1.570796326794896558" upper="1.570796326794896558"/>
    <joint_properties friction="0.0"/>
  </joint>

  <link name="ank_rr_link_4">
    <visual>
      <origin xyz="0 0 0" rpy="0 -0 0"/>
      <geometry>
        <mesh filename="package:///meshes/ank_rr_link_4_visual.stl"/>
      </geometry>
      <material name="ank_rr_link_4_material">
        <color rgba="0.61568627450980395466 0.81176470588235294379 0.92941176470588238168 1.0"/>
      </material>
    </visual>
    <collision>
      <origin xyz="0 0 0" rpy="0 -0 0"/>
      <geometry>
        <mesh filename="package:///meshes/ank_rr_link_4_collision.stl"/>
      </geometry>
    </collision>
    <inertial>
      <origin xyz="2.9962725549972314736e-05 0.0069241283254153178361 -0.0018999999999999999962" rpy="0 0 0"/>
      <mass value="0.0004758513732428606177"/>
      <inertia ixx="1.1040705352249966614e-08" ixy="-4.3855175770053268212e-11" ixz="6.7102857729409827078e-15" iyy="9.5635364996381580746e-09" iyz="-2.3073285478781435036e-29" izz="1.4744115584475846492e-08"/>
    </inertial>
  </link>

  <link name="ank_act_rod_head_4">
    <visual>
      <origin xyz="0 0 0" rpy="0 -0 0"/>
      <geometry>
        <mesh filename="package:///meshes/ank_act_rod_head_4_visual.stl"/>
      </geometry>
      <material name="ank_act_rod_head_4_material">
        <color rgba="0.97254901960784312376 0.52941176470588235947 0.0039215686274509803377 1.0"/>
      </material>
    </visual>
    <collision>
      <origin xyz="0 0 0" rpy="0 -0 0"/>
      <geometry>
        <mesh filename="package:///meshes/ank_act_rod_head_4_collision.stl"/>
      </geometry>
    </collision>
    <inertial>
      <origin xyz="-5.7828415611869510633e-11 0.0033987031118029161977 -0.0020055782443104586306" rpy="0 0 0"/>
      <mass value="0.00066080012085386230676"/>
      <inertia ixx="1.0675794104648551211e-08" ixy="-1.8531171296390058598e-16" ixz="9.2603132967465891142e-16" iyy="2.377371824966105234e-09" iyz="6.340139971923939938e-12" izz="1.1538333246010974441e-08"/>
    </inertial>
  </link>

  <joint name="right_ank_R22" type="revolute">
    <origin xyz="0.0020000000000000052458 0.0099999999999999984734 -0.0019000000000000006467" rpy="-1.57079632679489678 1.5534346511596015539 -1.5707963267942353092"/>
    <parent link="ank_rr_link_4"/>
    <child link="ank_act_rod_head_4"/>
    <axis xyz="0 0 1"/>
    <limit effort="1" velocity="20" lower="-1.570796326794896558" upper="1.570796326794896558"/>
    <joint_properties friction="0.0"/>
  </joint>

  <joint name="right_ank_R12" type="revolute">
    <origin xyz="-0.010000000000000005412 -0.012499999999999993755 0.040600000000000004141" rpy="-5.4208100503948111158e-17 1.2515168021403654183e-16 0.068787263405284487794"/>
    <parent link="ank_roll_link_2"/>
    <child link="ank_rr_link_4"/>
    <axis xyz="0 0 1"/>
    <limit effort="1" velocity="20" lower="-1.570796326794896558" upper="1.570796326794896558"/>
    <joint_properties friction="0.0"/>
  </joint>

  <joint name="right_ank_roll" type="revolute">
    <origin xyz="-1.3877787807814456755e-17 0.0015000000000000013323 -0.014600000000000012274" rpy="1.570796326794896558 1.570796326794707154 0"/>
    <parent link="ank_pitch_link_2"/>
    <child link="ank_roll_link_2"/>
    <axis xyz="0 0 1"/>
    <limit effort="1" velocity="20" lower="-1.570796326794896558" upper="1.570796326794896558"/>
    <joint_properties friction="0.0"/>
  </joint>

  <joint name="right_ank_pitch" type="revolute">
    <origin xyz="1.0408340855860842566e-16 -0.10000000000000013045 0.020900000000000147626" rpy="-7.5018482240547858138e-15 2.5176249968740924777e-16 1.5707963267948918951"/>
    <parent link="right_ank_base_link"/>
    <child link="ank_pitch_link_2"/>
    <axis xyz="0 0 1"/>
    <limit effort="1" velocity="20" lower="-1.570796326794896558" upper="1.570796326794896558"/>
    <joint_properties friction="0.0"/>
  </joint>

  <link name="ank_b_link_3">
    <visual>
      <origin xyz="0 0 0" rpy="0 -0 0"/>
      <geometry>
        <mesh filename="package:///meshes/ank_b_link_3_visual.stl"/>
      </geometry>
      <material name="ank_b_link_3_material">
        <color rgba="0.61568627450980406568 0.81176470588235294379 0.92941176470588238168 1.0"/>
      </material>
    </visual>
    <collision>
      <origin xyz="0 0 0" rpy="0 -0 0"/>
      <geometry>
        <mesh filename="package:///meshes/ank_b_link_3_collision.stl"/>
      </geometry>
    </collision>
    <inertial>
      <origin xyz="-4.9409968313694177089e-09 -5.9508723608456336824e-09 -0.0087165888679858107707" rpy="0 0 0"/>
      <mass value="0.00089583742203429468642"/>
      <inertia ixx="3.3822537554673496188e-08" ixy="3.9003059560646825758e-15" ixz="1.517634083479436117e-14" iyy="4.5803979388252454843e-08" iyz="5.2207519907246716862e-14" izz="2.594683440225980531e-08"/>
    </inertial>
  </link>

  <link name="ank_act_link_head_3">
    <visual>
      <origin xyz="0 0 0" rpy="0 -0 0"/>
      <geometry>
        <mesh filename="package:///meshes/ank_act_link_head_3_visual.stl"/>
      </geometry>
      <material name="ank_act_link_head_3_material">
        <color rgba="0.8805660089056220885 0.88861789403065327697 0.90620490627743233158 1.0"/>
      </material>
    </visual>
    <collision>
      <origin xyz="0 0 0" rpy="0 -0 0"/>
      <geometry>
        <mesh filename="package:///meshes/ank_act_link_head_3_collision.stl"/>
      </geometry>
    </collision>
    <inertial>
      <origin xyz="8.5302207527986474898e-09 0.0023472231756390586968 -0.0042999819767211878985" rpy="0 0 0"/>
      <mass value="0.0030517714925792842166"/>
      <inertia ixx="5.2970409371069442768e-08" ixy="5.7058840645604994743e-14" ixz="-1.0325254833911354808e-14" iyy="5.6254659413317882916e-08" iyz="1.1646556549554161193e-13" izz="6.2451084839899151219e-08"/>
    </inertial>
  </link>

  <link name="ank_act_link_3">
    <visual>
      <origin xyz="0 0 0" rpy="0 -0 0"/>
      <geometry>
        <mesh filename="package:///meshes/ank_act_link_3_visual.stl"/>
      </geometry>
      <material name="ank_act_link_3_material">
        <color rgba="0.62004392100736027693 0.58836684613512624242 0.49897069021535678246 1.0"/>
      </material>
    </visual>
    <collision>
      <origin xyz="0 0 0" rpy="0 -0 0"/>
      <geometry>
        <mesh filename="package:///meshes/ank_act_link_3_collision.stl"/>
      </geometry>
    </collision>
    <inertial>
      <origin xyz="0.0049084207243661427331 -0.00013802439943759711228 -0.029947003577139412467" rpy="0 0 0"/>
      <mass value="0.044782197696050358993"/>
      <inertia ixx="1.5260128421306449201e-05" ixy="2.2955773686561457882e-08" ixz="-8.136420400779311211e-08" iyy="1.8188469778944450062e-05" iyz="-5.5542240843819442282e-08" izz="5.1496273901729406667e-06"/>
    </inertial>
  </link>

  <link name="ank_act_rod_3">
    <visual>
      <origin xyz="0 0 0" rpy="0 -0 0"/>
      <geometry>
        <mesh filename="package:///meshes/ank_act_rod_3_visual.stl"/>
      </geometry>
      <material name="ank_act_rod_3_material">
        <color rgba="0.80016770676329840306 0.8929145636529542962 0.94547111589042631685 1.0"/>
      </material>
    </visual>
    <collision>
      <origin xyz="0 0 0" rpy="0 -0 0"/>
      <geometry>
        <mesh filename="package:///meshes/ank_act_rod_3_collision.stl"/>
      </geometry>
    </collision>
    <inertial>
      <origin xyz="-2.7254954596954391814e-06 -1.2667795960588505607e-05 0.0060054807227746271475" rpy="0 0 0"/>
      <mass value="0.0026945559868381376359"/>
      <inertia ixx="3.2231832056359897847e-07" ixy="-9.9380293184862384608e-13" ixz="1.0490654905895674984e-10" iyy="3.223121869778092435e-07" iyz="5.6317539917026432471e-10" izz="1.8746557075763401407e-08"/>
    </inertial>
  </link>

  <joint name="right_ank_act1" type="prismatic">
    <origin xyz="2.2722093422193351958e-06 -3.0045410603918298875e-15 -0.059245818700239413768" rpy="3.141592653589793116 2.3300461121301510461e-18 -0.63671356442004811704"/>
    <parent link="ank_act_link_3"/>
    <child link="ank_act_rod_3"/>
    <axis xyz="0 0 1"/>
    <limit effort="1" velocity="20" lower="-0.017000000000000001221" upper="0.017000000000000001221"/>
    <joint_properties friction="0.0"/>
  </joint>

  <joint name="right_ank_B31" type="revolute">
    <origin xyz="2.168404344971008868e-19 0.0060500000000000553335 -0.0043000000000000052069" rpy="1.570796326794896558 5.4574690704063518601e-06 1.7018354478117103418e-17"/>
    <parent link="ank_act_link_head_3"/>
    <child link="ank_act_link_3"/>
    <axis xyz="0 0 1"/>
    <limit effort="1" velocity="20" lower="-1.570796326794896558" upper="1.570796326794896558"/>
    <joint_properties friction="0.0"/>
  </joint>

  <joint name="right_ank_B21" type="revolute">
    <origin xyz="0.0044999999999999762412 2.7755575615628913511e-17 -0.017000000000000004691" rpy="-1.5707963267948961139 -1.5676670168131927596 -1.5707963267948830133"/>
    <parent link="ank_b_link_3"/>
    <child link="ank_act_link_head_3"/>
    <axis xyz="0 0 1"/>
    <limit effort="1" velocity="20" lower="-1.570796326794896558" upper="1.570796326794896558"/>
    <joint_properties friction="0.0"/>
  </joint>

  <joint name="right_ank_B11" type="revolute">
    <origin xyz="0.019999999999999996947 -0.0099999999999999811262 -0.011499999999999982458" rpy="-1.570796326794896558 -1.4985484105593833704 1.5707963267948970021"/>
    <parent link="right_ank_base_link"/>
    <child link="ank_b_link_3"/>
    <axis xyz="0 0 1"/>
    <limit effort="1" velocity="20" lower="-1.570796326794896558" upper="1.570796326794896558"/>
    <joint_properties friction="0.0"/>
  </joint>

  <link name="ank_b_link_4">
    <visual>
      <origin xyz="0 0 0" rpy="0 -0 0"/>
      <geometry>
        <mesh filename="package:///meshes/ank_b_link_4_visual.stl"/>
      </geometry>
      <material name="ank_b_link_4_material">
        <color rgba="0.61568627450980406568 0.81176470588235294379 0.92941176470588238168 1.0"/>
      </material>
    </visual>
    <collision>
      <origin xyz="0 0 0" rpy="0 -0 0"/>
      <geometry>
        <mesh filename="package:///meshes/ank_b_link_4_collision.stl"/>
      </geometry>
    </collision>
    <inertial>
      <origin xyz="-4.9409968209608510328e-09 5.950872333092591721e-09 0.0087165888679858107707" rpy="0 0 0"/>
      <mass value="0.00089583742203429468642"/>
      <inertia ixx="3.3822537554673509423e-08" ixy="-3.900305954727526265e-15" ixz="-1.5176340834795639125e-14" iyy="4.5803979388252428374e-08" iyz="5.2207519907268161257e-14" izz="2.594683440225980531e-08"/>
    </inertial>
  </link>

  <link name="ank_act_link_head_4">
    <visual>
      <origin xyz="0 0 0" rpy="0 -0 0"/>
      <geometry>
        <mesh filename="package:///meshes/ank_act_link_head_4_visual.stl"/>
      </geometry>
      <material name="ank_act_link_head_4_material">
        <color rgba="0.8805660089056220885 0.88861789403065327697 0.90620490627743233158 1.0"/>
      </material>
    </visual>
    <collision>
      <origin xyz="0 0 0" rpy="0 -0 0"/>
      <geometry>
        <mesh filename="package:///meshes/ank_act_link_head_4_collision.stl"/>
      </geometry>
    </collision>
    <inertial>
      <origin xyz="8.5302207529927586554e-09 -0.0023472231756390378801 -0.0043000180232787826168" rpy="0 0 0"/>
      <mass value="0.0030517714925792842166"/>
      <inertia ixx="5.2970409371069072191e-08" ixy="-5.7058840680726849292e-14" ixz="1.0325254833524928138e-14" iyy="5.6254659413317882916e-08" iyz="1.1646556585173371717e-13" izz="6.2451084839898807112e-08"/>
    </inertial>
  </link>

  <link name="ank_act_link_4">
    <visual>
      <origin xyz="0 0 0" rpy="0 -0 0"/>
      <geometry>
        <mesh filename="package:///meshes/ank_act_link_4_visual.stl"/>
      </geometry>
      <material name="ank_act_link_4_material">
        <color rgba="0.62004392100736005489 0.58836684613512624242 0.49897069021535672695 1.0"/>
      </material>
    </visual>
    <collision>
      <origin xyz="0 0 0" rpy="0 -0 0"/>
      <geometry>
        <mesh filename="package:///meshes/ank_act_link_4_collision.stl"/>
      </geometry>
    </collision>
    <inertial>
      <origin xyz="0.0049084207243675903598 -0.00013802439943487318985 -0.029947003577138319591" rpy="0 0 0"/>
      <mass value="0.044782197696050358993"/>
      <inertia ixx="1.5260128421305612333e-05" ixy="2.295577368678629219e-08" ixz="-8.1364204007233421855e-08" iyy="1.818846977894322017e-05" iyz="-5.5542240842725128654e-08" izz="5.1496273901725603489e-06"/>
    </inertial>
  </link>

  <link name="ank_act_rod_4">
    <visual>
      <origin xyz="0 0 0" rpy="0 -0 0"/>
      <geometry>
        <mesh filename="package:///meshes/ank_act_rod_4_visual.stl"/>
      </geometry>
      <material name="ank_act_rod_4_material">
        <color rgba="0.80016770676329840306 0.8929145636529542962 0.94547111589042631685 1.0"/>
      </material>
    </visual>
    <collision>
      <origin xyz="0 0 0" rpy="0 -0 0"/>
      <geometry>
        <mesh filename="package:///meshes/ank_act_rod_4_collision.stl"/>
      </geometry>
    </collision>
    <inertial>
      <origin xyz="-2.7254954593936193194e-06 -1.2667795959606265873e-05 0.0060054807227751224111" rpy="0 0 0"/>
      <mass value="0.0026945559868381376359"/>
      <inertia ixx="3.2231832056363000106e-07" ixy="-9.9380293177805580787e-13" ixz="1.049065490498257357e-10" iyy="3.2231218697784047784e-07" iyz="5.6317539913926976376e-10" izz="1.8746557075763173105e-08"/>
    </inertial>
  </link>

  <joint name="right_ank_act2" type="prismatic">
    <origin xyz="2.2722093449636677348e-06 1.7694179454963432363e-15 -0.059208011505606339409" rpy="-3.1415926535897860106 -1.9568267140524259683e-14 -0.636713564419863709"/>
    <parent link="ank_act_link_4"/>
    <child link="ank_act_rod_4"/>
    <axis xyz="0 0 1"/>
    <limit effort="1" velocity="20" lower="-0.017000000000000001221" upper="0.017000000000000001221"/>
    <joint_properties friction="0.0"/>
  </joint>

  <joint name="right_ank_B32" type="revolute">
    <origin xyz="2.8189256484623115284e-18 -0.0060500000000000275779 -0.0042999999999999947986" rpy="-1.570796326794896558 -5.4574694521280218192e-06 -1.2970245616443644851e-17"/>
    <parent link="ank_act_link_head_4"/>
    <child link="ank_act_link_4"/>
    <axis xyz="0 0 1"/>
    <limit effort="1" velocity="20" lower="-1.570796326794896558" upper="1.570796326794896558"/>
    <joint_properties friction="0.0"/>
  </joint>

  <joint name="right_ank_B22" type="revolute">
    <origin xyz="0.0044999999999999970579 0 0.017000000000000001221" rpy="-1.57079632679489678 1.55343465115961199 -1.5707963267948699126"/>
    <parent link="ank_b_link_4"/>
    <child link="ank_act_link_head_4"/>
    <axis xyz="0 0 1"/>
    <limit effort="1" velocity="20" lower="-1.570796326794896558" upper="1.570796326794896558"/>
    <joint_properties friction="0.0"/>
  </joint>

  <joint name="right_ank_B12" type="revolute">
    <origin xyz="0.01868001962352556708 -0.0099999999999999811262 0.023399999999999976374" rpy="1.57079632679490655 1.5020090633897773547 1.5707963267949058839"/>
    <parent link="right_ank_base_link"/>
    <child link="ank_b_link_4"/>
    <axis xyz="0 0 1"/>
    <limit effort="1" velocity="20" lower="-1.570796326794896558" upper="1.570796326794896558"/>
    <joint_properties friction="0.0"/>
  </joint>

  <joint name="right_ank_base" type="fixed">
    <origin xyz="0 2.0816681711721685133e-17 -0.0064999999999999918954" rpy="-2.3897681857549792405e-16 -1.6802318149906911049e-16 1.0524335389525802942"/>
    <parent link="knee_link_2"/>
    <child link="right_ank_base_link"/>
    <axis xyz="0 0 1"/>
    <limit effort="1" velocity="20"/>
    <joint_properties friction="0.0"/>
  </joint>

  <joint name="right_knee" type="revolute">
    <origin xyz="-4.1633363423443370266e-17 -0.10749999999999998446 0.016499999999999986899" rpy="-7.9136240096094387749e-16 -6.4063376207831640667e-16 -1.0471975511964932704"/>
    <parent link="hip_pitch_link_2"/>
    <child link="knee_link_2"/>
    <axis xyz="0 0 1"/>
    <limit effort="1" velocity="20" lower="-1.0471975511965976313" upper="2.0943951023931952626"/>
    <joint_properties friction="0.0"/>
  </joint>

  <joint name="right_hip_pitch" type="revolute">
    <origin xyz="-0.02400000071614186159 -0.019000000152455120972 -0.019000000152451717444" rpy="-1.5707963267946463137 -1.5707963267948112929 0"/>
    <parent link="hip_roll_link_2"/>
    <child link="hip_pitch_link_2"/>
    <axis xyz="0 0 1"/>
    <limit effort="1" velocity="20" lower="-1.570796326794896558" upper="1.570796326794896558"/>
    <joint_properties friction="0.0"/>
  </joint>

  <joint name="right_hip_roll" type="revolute">
    <origin xyz="0.018999999999999999528 -6.9388939039072283776e-18 -0.027499999999999913403" rpy="3.141592653589793116 -1.5707963267948641395 0"/>
    <parent link="hip_yaw_link_2"/>
    <child link="hip_roll_link_2"/>
    <axis xyz="0 0 1"/>
    <limit effort="1" velocity="20" lower="-1.570796326794896558" upper="1.570796326794896558"/>
    <joint_properties friction="0.0"/>
  </joint>

  <joint name="right_hip_yaw" type="revolute">
    <origin xyz="-0.035000000000000003331 -0.039999999999999993894 0.29868541999999997927" rpy="-6.3173742254660021089e-26 -6.1232339666714670147e-17 1.5707963267947904207"/>
    <parent link="body_link"/>
    <child link="hip_yaw_link_2"/>
    <axis xyz="0 0 1"/>
    <limit effort="1" velocity="20" lower="-1.570796326794896558" upper="1.570796326794896558"/>
    <joint_properties friction="0.0"/>
  </joint>

  <link name="sho_pitch_link">
    <visual>
      <origin xyz="0 0 0" rpy="0 -0 0"/>
      <geometry>
        <mesh filename="package:///meshes/sho_pitch_link_visual.stl"/>
      </geometry>
      <material name="sho_pitch_link_material">
        <color rgba="0.61568627450980395466 0.81176470588235283277 0.92941176470588238168 1.0"/>
      </material>
    </visual>
    <collision>
      <origin xyz="0 0 0" rpy="0 -0 0"/>
      <geometry>
        <mesh filename="package:///meshes/sho_pitch_link_collision.stl"/>
      </geometry>
    </collision>
    <inertial>
      <origin xyz="-3.0491385327507088341e-09 0.0021980515983192282746 -0.0084441034778716100168" rpy="0 0 0"/>
      <mass value="0.0050714799847967799787"/>
      <inertia ixx="7.6348105206556983548e-07" ixy="1.1155743805524236464e-13" ixz="9.7455166256395812642e-15" iyy="1.766118017982326709e-06" iyz="1.1100867450486896583e-07" izz="1.8650955603811183778e-06"/>
    </inertial>
  </link>

  <link name="sho_roll_link">
    <visual>
      <origin xyz="0 0 0" rpy="0 -0 0"/>
      <geometry>
        <mesh filename="package:///meshes/sho_roll_link_visual.stl"/>
      </geometry>
      <material name="sho_roll_link_material">
        <color rgba="0.41243716778099176468 0.5314104017449963191 0.72755857506443588623 1.0"/>
      </material>
    </visual>
    <collision>
      <origin xyz="0 0 0" rpy="0 -0 0"/>
      <geometry>
        <mesh filename="package:///meshes/sho_roll_link_collision.stl"/>
      </geometry>
    </collision>
    <inertial>
      <origin xyz="-0.044750001317537507761 -2.1437024770199389841e-09 -0.018766560050927118264" rpy="0 0 0"/>
      <mass value="0.14053933881247798743"/>
      <inertia ixx="2.5542860709012482238e-05" ixy="3.3646029028990590982e-08" ixz="-2.9382375566007110611e-12" iyy="0.00018283946647031836127" iyz="-7.6178891178974175739e-12" izz="0.00017786975360446964059"/>
    </inertial>
  </link>

  <link name="elb_link">
    <visual>
      <origin xyz="0 0 0" rpy="0 -0 0"/>
      <geometry>
        <mesh filename="package:///meshes/elb_link_visual.stl"/>
      </geometry>
      <material name="elb_link_material">
        <color rgba="0.63276333362436720797 0.72211014553089525325 0.77571823267481221365 1.0"/>
      </material>
    </visual>
    <collision>
      <origin xyz="0 0 0" rpy="0 -0 0"/>
      <geometry>
        <mesh filename="package:///meshes/elb_link_collision.stl"/>
      </geometry>
    </collision>
    <inertial>
      <origin xyz="0.0035809919318979662947 0.051692930824584849836 0.018999999639623971898" rpy="0 0 0"/>
      <mass value="0.011587175244532088927"/>
      <inertia ixx="9.8008364445092869215e-06" ixy="-7.9870408555378619063e-07" ixz="2.3421926571634329299e-13" iyy="2.9172843721889671859e-06" iyz="2.5739632383903377718e-14" izz="8.0566619883509232614e-06"/>
    </inertial>
  </link>

  <joint name="left_elb" type="revolute">
    <origin xyz="-0.089500000000000121125 0 5.5511151231257827021e-17" rpy="-3.141592653589793116 -8.8760630082751599313e-15 -1.570796326794896558"/>
    <parent link="sho_roll_link"/>
    <child link="elb_link"/>
    <axis xyz="0 0 1"/>
    <limit effort="1" velocity="20" lower="-1.570796326794896558" upper="1.570796326794896558"/>
    <joint_properties friction="0.0"/>
  </joint>

  <joint name="left_sho_roll" type="revolute">
    <origin xyz="-0.018999999999999996059 0.0090000000000000079936 -0.02749999999999998973" rpy="-0 -1.5707963267948894526 0"/>
    <parent link="sho_pitch_link"/>
    <child link="sho_roll_link"/>
    <axis xyz="0 0 1"/>
    <limit effort="1" velocity="20" lower="-1.570796326794896558" upper="1.570796326794896558"/>
    <joint_properties friction="0.0"/>
  </joint>

  <joint name="left_sho_pitch" type="revolute">
    <origin xyz="0.06049999999999895739 -0.044999999999999804046 0.43008541999999988503" rpy="-1.5707963267948705788 3.7242253603279489435e-14 1.5707963267949578423"/>
    <parent link="body_link"/>
    <child link="sho_pitch_link"/>
    <axis xyz="0 0 1"/>
    <limit effort="1" velocity="20" lower="-1.570796326794896558" upper="1.570796326794896558"/>
    <joint_properties friction="0.0"/>
  </joint>

  <link name="sho_pitch_link_2">
    <visual>
      <origin xyz="0 0 0" rpy="0 -0 0"/>
      <geometry>
        <mesh filename="package:///meshes/sho_pitch_link_2_visual.stl"/>
      </geometry>
      <material name="sho_pitch_link_2_material">
        <color rgba="0.61568627450980395466 0.81176470588235283277 0.92941176470588238168 1.0"/>
      </material>
    </visual>
    <collision>
      <origin xyz="0 0 0" rpy="0 -0 0"/>
      <geometry>
        <mesh filename="package:///meshes/sho_pitch_link_2_collision.stl"/>
      </geometry>
    </collision>
    <inertial>
      <origin xyz="-3.0491385327507088341e-09 0.0021980515983192282746 -0.0084441034778716100168" rpy="0 0 0"/>
      <mass value="0.0050714799847967799787"/>
      <inertia ixx="7.6348105206556983548e-07" ixy="1.1155743805524236464e-13" ixz="9.7455166256395812642e-15" iyy="1.766118017982326709e-06" iyz="1.1100867450486896583e-07" izz="1.8650955603811183778e-06"/>
    </inertial>
  </link>

  <link name="sho_roll_link_2">
    <visual>
      <origin xyz="0 0 0" rpy="0 -0 0"/>
      <geometry>
        <mesh filename="package:///meshes/sho_roll_link_2_visual.stl"/>
      </geometry>
      <material name="sho_roll_link_2_material">
        <color rgba="0.4124371677809913761 0.53141040174499643012 0.72755857506443588623 1.0"/>
      </material>
    </visual>
    <collision>
      <origin xyz="0 0 0" rpy="0 -0 0"/>
      <geometry>
        <mesh filename="package:///meshes/sho_roll_link_2_collision.stl"/>
      </geometry>
    </collision>
    <inertial>
      <origin xyz="-0.044750001317537445311 -2.1437023966870046351e-09 -0.018766560050927128672" rpy="0 0 0"/>
      <mass value="0.14053933881247798743"/>
      <inertia ixx="2.5542860709012448357e-05" ixy="3.3646029028883666307e-08" ixz="-2.9382375867497900274e-12" iyy="0.0001828394664703180089" iyz="-7.6178891160455637463e-12" izz="0.00017786975360446926112"/>
    </inertial>
  </link>

  <link name="elb_link_2">
    <visual>
      <origin xyz="0 0 0" rpy="0 -0 0"/>
      <geometry>
        <mesh filename="package:///meshes/elb_link_2_visual.stl"/>
      </geometry>
      <material name="elb_link_2_material">
        <color rgba="0.63276333362436720797 0.72211014553089525325 0.77571823267481221365 1.0"/>
      </material>
    </visual>
    <collision>
      <origin xyz="0 0 0" rpy="0 -0 0"/>
      <geometry>
        <mesh filename="package:///meshes/elb_link_2_collision.stl"/>
      </geometry>
    </collision>
    <inertial>
      <origin xyz="0.003580991931897914253 -0.051692930824584988614 0.019000000360375988995" rpy="0 0 0"/>
      <mass value="0.011587175244532088927"/>
      <inertia ixx="9.8008364445091429259e-06" ixy="7.9870408555377486157e-07" ixz="-2.3421924060587059155e-13" iyy="2.9172843721889760797e-06" iyz="2.5739618557225107819e-14" izz="8.0566619883509825537e-06"/>
    </inertial>
  </link>

  <joint name="right_elb" type="revolute">
    <origin xyz="-0.089500000000000065614 0 1.3877787807814456755e-17" rpy="-3.141592653589793116 -3.3306690738761288132e-16 1.5707963267948976682"/>
    <parent link="sho_roll_link_2"/>
    <child link="elb_link_2"/>
    <axis xyz="0 0 1"/>
    <limit effort="1" velocity="20" lower="-1.570796326794896558" upper="1.570796326794896558"/>
    <joint_properties friction="0.0"/>
  </joint>

  <joint name="right_sho_roll" type="revolute">
    <origin xyz="0.019000000000000002998 0.0090000000000000079936 -0.02749999999999998973" rpy="-3.141592653589793116 -1.570796326794896558 0"/>
    <parent link="sho_pitch_link_2"/>
    <child link="sho_roll_link_2"/>
    <axis xyz="0 0 1"/>
    <limit effort="1" velocity="20" lower="-1.570796326794896558" upper="1.570796326794896558"/>
    <joint_properties friction="0.0"/>
  </joint>

  <joint name="right_sho_pitch" type="revolute">
    <origin xyz="-0.060500000000000005163 -0.044999999999999977518 0.43008541999999994054" rpy="-1.570796326794896558 7.2736973397141567712e-16 -1.570796326794896558"/>
    <parent link="body_link"/>
    <child link="sho_pitch_link_2"/>
    <axis xyz="0 0 1"/>
    <limit effort="1" velocity="20" lower="-1.570796326794896558" upper="1.570796326794896558"/>
    <joint_properties friction="0.0"/>
  </joint>


</robot>