<?xml version="1.0" ?>
<robot name="base">
    <mujoco>
        <compiler meshdir="./meshes/" balanceinertia="true" discardvisual="false"/>
    </mujoco>
    <link name="hip_pitch_link">
        <visual>
            <origin xyz="0 0 0" rpy="0 -0 0"/>
            <geometry>
                <mesh filename="package:///meshes/hip_pitch_link_visual.stl"/>
            </geometry>
            <material name="hip_pitch_link_material">
                <color rgba="0.61568627450980395466 0.81176470588235294379 0.92941176470588238168 1.0"/>
            </material>
        </visual>
        <collision>
            <origin xyz="0 0 0" rpy="0 -0 0"/>
            <geometry>
                <mesh filename="package:///meshes/hip_pitch_link_collision.stl"/>
            </geometry>
        </collision>
        <inertial>
            <origin xyz="3.7543054200835739919e-17 -0.0024843438022173120784 0.25078691758720839111" rpy="0 0 0"/>
            <mass value="0.016043083203926743197"/>
            <inertia ixx="2.3157747787741469802e-05" ixy="-3.9012231212623463053e-20" ixz="-1.4021514466931437321e-21" iyy="2.5164537982758234389e-05" iyz="1.2756337173477869953e-08" izz="2.0733076186948872116e-06"/>
        </inertial>
    </link>

    <link name="knee_link">
        <visual>
            <origin xyz="0 0 0" rpy="0 -0 0"/>
            <geometry>
                <mesh filename="package:///meshes/knee_link_visual.stl"/>
            </geometry>
            <material name="knee_link_material">
                <color rgba="0.62989867807310040426 0.73714958717504708297 0.80150013263621511239 1.0"/>
            </material>
        </visual>
        <collision>
            <origin xyz="0 0 0" rpy="0 -0 0"/>
            <geometry>
                <mesh filename="package:///meshes/knee_link_collision.stl"/>
            </geometry>
        </collision>
        <inertial>
            <origin xyz="8.2465938779409896661e-17 1.3905884258201561576e-17 -0.0032457853126643576754" rpy="0 0 0"/>
            <mass value="0.0043868974356887704968"/>
            <inertia ixx="4.1908664095026595155e-07" ixy="1.0471082065059430591e-21" ixz="-2.2345108996484541591e-21" iyy="4.1908664095026843971e-07" iyz="3.8103281067105722432e-21" izz="8.0521341717892533647e-07"/>
        </inertial>
    </link>

    <link name="ank_base_link">
        <visual>
            <origin xyz="0 0 0" rpy="0 -0 0"/>
            <geometry>
                <mesh filename="package:///meshes/ank_base_link_visual.stl"/>
            </geometry>
            <material name="ank_base_link_material">
                <color rgba="0.54555368846635599045 0.72113944167448473799 0.87071994840215694023 1.0"/>
            </material>
        </visual>
        <collision>
            <origin xyz="0 0 0" rpy="0 -0 0"/>
            <geometry>
                <mesh filename="package:///meshes/ank_base_link_collision.stl"/>
            </geometry>
        </collision>
        <inertial>
            <origin xyz="-0.0022434246051615341043 0.0431041463716912987 0.0063175709427246299135" rpy="0 0 0"/>
            <mass value="0.014262086197619731551"/>
            <inertia ixx="1.526299354670616746e-05" ixy="9.1266662056319061891e-07" ixz="6.0404933644660297793e-08" iyy="1.9634197931225375351e-06" iyz="-7.3113325087223630006e-08" izz="1.5076214983324410653e-05"/>
        </inertial>
    </link>

    <link name="ank_pitch_link">
        <visual>
            <origin xyz="0 0 0" rpy="0 -0 0"/>
            <geometry>
                <mesh filename="package:///meshes/ank_pitch_link_visual.stl"/>
            </geometry>
            <material name="ank_pitch_link_material">
                <color rgba="0.63157201649708305524 0.72836456044913699959 0.78644008682036936619 1.0"/>
            </material>
        </visual>
        <collision>
            <origin xyz="0 0 0" rpy="0 -0 0"/>
            <geometry>
                <mesh filename="package:///meshes/ank_pitch_link_collision.stl"/>
            </geometry>
        </collision>
        <inertial>
            <origin xyz="3.92204592178660265e-08 0.0005846799720591032987 -0.014599924406174028674" rpy="0 0 0"/>
            <mass value="0.0041366725921694342399"/>
            <inertia ixx="4.325241978833924079e-07" ixy="1.5885354054752991993e-13" ixz="1.5670565584190556006e-12" iyy="3.9522408111775107452e-07" iyz="1.6638141796336068358e-14" izz="8.5883658455742484132e-08"/>
        </inertial>
    </link>

    <link name="ank_roll_link">
        <visual>
            <origin xyz="0 0 0" rpy="0 -0 0"/>
            <geometry>
                <mesh filename="package:///meshes/ank_roll_link_visual.stl"/>
            </geometry>
            <material name="ank_roll_link_material">
                <color rgba="0.61568627450980395466 0.81176470588235305481 0.92941176470588238168 1.0"/>
            </material>
        </visual>
        <collision>
            <origin xyz="0 0 0" rpy="0 -0 0"/>
            <geometry>
                <mesh filename="package:///meshes/ank_roll_link_collision.stl"/>
            </geometry>
        </collision>
        <inertial>
            <origin xyz="-1.4901271645037536589e-10 -0.013684967917931589385 0.014389602633949057781" rpy="0 0 0"/>
            <mass value="0.0054237955467263095424"/>
            <inertia ixx="2.3215873123896826578e-06" ixy="-5.7389209322760936731e-15" ixz="-9.0715784896318946803e-15" iyy="2.105458792231080349e-06" iyz="3.6308271258505771065e-07" izz="5.6387331373110566889e-07"/>
        </inertial>
    </link>

    <link name="ank_rigid_foot_link">
        <visual>
            <origin xyz="0 0 0" rpy="0 -0 0"/>
            <geometry>
                <mesh filename="package:///meshes/ank_rigid_foot_link_visual.stl"/>
            </geometry>
            <material name="ank_rigid_foot_link_material">
                <color rgba="0.61568627450980395466 0.81176470588235294379 0.92941176470588238168 1.0"/>
            </material>
        </visual>
        <collision>
            <origin xyz="0 0 0" rpy="0 -0 0"/>
            <geometry>
                <mesh filename="package:///meshes/ank_rigid_foot_link_collision.stl"/>
            </geometry>
        </collision>
        <inertial>
            <origin xyz="-0.023731999094105324377 -9.4396649341355981347e-10 -0.013306321578886210963" rpy="0 0 0"/>
            <mass value="0.0082157357687249205763"/>
            <inertia ixx="6.5404454512568351144e-07" ixy="3.4320556103715367643e-13" ixz="-3.2926756768140872887e-07" iyy="5.8836130895435082494e-06" iyz="-3.0207161976736071833e-15" izz="6.2852473690143510358e-06"/>
        </inertial>
    </link>

    <joint name="ank_foot" type="fixed">
        <origin xyz="-3.9898639947466563171e-17 -0.022500000000000131006 0.025600000000000136535" rpy="-1.5707963267948477082 -1.5707963267948954478 0"/>
        <parent link="ank_roll_link"/>
        <child link="ank_rigid_foot_link"/>
        <axis xyz="0 0 1"/>
        <limit effort="1" velocity="20"/>
        <joint_properties friction="0.0"/>
    </joint>

    <link name="ank_rr_link">
        <visual>
            <origin xyz="0 0 0" rpy="0 -0 0"/>
            <geometry>
                <mesh filename="package:///meshes/ank_rr_link_visual.stl"/>
            </geometry>
            <material name="ank_rr_link_material">
                <color rgba="0.61568627450980395466 0.81176470588235294379 0.92941176470588238168 1.0"/>
            </material>
        </visual>
        <collision>
            <origin xyz="0 0 0" rpy="0 -0 0"/>
            <geometry>
                <mesh filename="package:///meshes/ank_rr_link_collision.stl"/>
            </geometry>
        </collision>
        <inertial>
            <origin xyz="2.9962725549969058741e-05 -0.006924128325415312632 -0.001900000000000005634" rpy="0 0 0"/>
            <mass value="0.00047585137324286067191"/>
            <inertia ixx="1.1040705352249968268e-08" ixy="4.3855175770053752889e-11" ixz="-6.710285773002005832e-15" iyy="9.5635364996381564202e-09" iyz="-2.8640025491958382031e-26" izz="1.4744115584475854764e-08"/>
        </inertial>
    </link>

    <link name="ank_act_rod_head">
        <visual>
            <origin xyz="0 0 0" rpy="0 -0 0"/>
            <geometry>
                <mesh filename="package:///meshes/ank_act_rod_head_visual.stl"/>
            </geometry>
            <material name="ank_act_rod_head_material">
                <color rgba="0.97254901960784312376 0.52941176470588235947 0.0039215686274509803377 1.0"/>
            </material>
        </visual>
        <collision>
            <origin xyz="0 0 0" rpy="0 -0 0"/>
            <geometry>
                <mesh filename="package:///meshes/ank_act_rod_head_collision.stl"/>
            </geometry>
        </collision>
        <inertial>
            <origin xyz="-5.7828415394479770048e-11 0.0033987031118029101262 -0.0020055782443104603653" rpy="0 0 0"/>
            <mass value="0.00066080012085386230676"/>
            <inertia ixx="1.067579410464855452e-08" ixy="-1.8531171293777893622e-16" ixz="9.2603132967627035704e-16" iyy="2.3773718249661060612e-09" iyz="6.3401399719236047037e-12" izz="1.1538333246010974441e-08"/>
        </inertial>
    </link>

    <joint name="ank_R21" type="revolute">
        <origin xyz="0.001999999999999990067 -0.0099999999999999672484 -0.0019000000000000058509" rpy="-1.5707963267948636954 -1.5534345204865058765 -1.5707963267948001906"/>
        <parent link="ank_rr_link"/>
        <child link="ank_act_rod_head"/>
        <axis xyz="0 0 1"/>
        <limit effort="1" velocity="20" lower="-1.570796326794896558" upper="1.570796326794896558"/>
        <joint_properties friction="0.0"/>
    </joint>

    <joint name="ank_R11" type="revolute">
        <origin xyz="0.009999999999999995004 -0.01250000000000002498 0.040599999999999976386" rpy="4.5538414498539748188e-14 8.2432841012071876929e-15 3.0761399207850028681"/>
        <parent link="ank_roll_link"/>
        <child link="ank_rr_link"/>
        <axis xyz="0 0 1"/>
        <limit effort="1" velocity="20" lower="-1.570796326794896558" upper="1.570796326794896558"/>
        <joint_properties friction="0.0"/>
    </joint>

    <link name="ank_rr_link_2">
        <visual>
            <origin xyz="0 0 0" rpy="0 -0 0"/>
            <geometry>
                <mesh filename="package:///meshes/ank_rr_link_2_visual.stl"/>
            </geometry>
            <material name="ank_rr_link_2_material">
                <color rgba="0.61568627450980395466 0.81176470588235294379 0.92941176470588238168 1.0"/>
            </material>
        </visual>
        <collision>
            <origin xyz="0 0 0" rpy="0 -0 0"/>
            <geometry>
                <mesh filename="package:///meshes/ank_rr_link_2_collision.stl"/>
            </geometry>
        </collision>
        <inertial>
            <origin xyz="2.9962725549968909663e-05 0.0069241283254153134993 -0.0018999999999999991288" rpy="0 0 0"/>
            <mass value="0.00047585137324286067191"/>
            <inertia ixx="1.1040705352249964959e-08" ixy="-4.3855175770053513782e-11" ixz="6.7102857730014323301e-15" iyy="9.5635364996381597289e-09" iyz="-8.2466825498419285333e-27" izz="1.4744115584475854764e-08"/>
        </inertial>
    </link>

    <link name="ank_act_rod_head_2">
        <visual>
            <origin xyz="0 0 0" rpy="0 -0 0"/>
            <geometry>
                <mesh filename="package:///meshes/ank_act_rod_head_2_visual.stl"/>
            </geometry>
            <material name="ank_act_rod_head_2_material">
                <color rgba="0.97254901960784312376 0.52941176470588235947 0.0039215686274509803377 1.0"/>
            </material>
        </visual>
        <collision>
            <origin xyz="0 0 0" rpy="0 -0 0"/>
            <geometry>
                <mesh filename="package:///meshes/ank_act_rod_head_2_collision.stl"/>
            </geometry>
        </collision>
        <inertial>
            <origin xyz="-5.7828422333254456549e-11 0.0033987031118029101262 -0.002005578244310459498" rpy="0 0 0"/>
            <mass value="0.00066080012085386230676"/>
            <inertia ixx="1.067579410464855452e-08" ixy="-1.8531171293372308183e-16" ixz="9.2603132968216255635e-16" iyy="2.377371824966105234e-09" iyz="6.340139971923712948e-12" izz="1.1538333246010974441e-08"/>
        </inertial>
    </link>

    <joint name="ank_R22" type="revolute">
        <origin xyz="0.0020000000000000139194 0.010000000000000050515 -0.0019000000000000127898" rpy="-1.5707963267951321473 1.5676670190976929042 -1.5707963267984343947"/>
        <parent link="ank_rr_link_2"/>
        <child link="ank_act_rod_head_2"/>
        <axis xyz="0 0 1"/>
        <limit effort="1" velocity="20" lower="-1.570796326794896558" upper="1.570796326794896558"/>
        <joint_properties friction="0.0"/>
    </joint>

    <joint name="ank_R12" type="revolute">
        <origin xyz="-0.0099999999999999845957 -0.012500000000000052736 0.040599999999999969447" rpy="-4.7709545858758676013e-14 1.2384261596296442717e-14 0.079471996733595215434"/>
        <parent link="ank_roll_link"/>
        <child link="ank_rr_link_2"/>
        <axis xyz="0 0 1"/>
        <limit effort="1" velocity="20" lower="-1.570796326794896558" upper="1.570796326794896558"/>
        <joint_properties friction="0.0"/>
    </joint>

    <joint name="ank_roll" type="revolute">
        <origin xyz="-9.7144514654701197287e-17 0.0015000000000004699244 -0.014599999999999951558" rpy="1.5707963267949847097 -1.5707963267948685804 0"/>
        <parent link="ank_pitch_link"/>
        <child link="ank_roll_link"/>
        <axis xyz="0 0 1"/>
        <limit effort="1" velocity="20" lower="-1.570796326794896558" upper="1.570796326794896558"/>
        <joint_properties friction="0.0"/>
    </joint>

    <joint name="ank_pitch" type="revolute">
        <origin xyz="-9.6428941220860764361e-16 0.10000000000000054678 0.020899999999999852723" rpy="-1.7591152789461700036e-14 -1.17510393317422114e-14 1.5707963267948696906"/>
        <parent link="ank_base_link"/>
        <child link="ank_pitch_link"/>
        <axis xyz="0 0 1"/>
        <limit effort="1" velocity="20" lower="-1.570796326794896558" upper="1.570796326794896558"/>
        <joint_properties friction="0.0"/>
    </joint>

    <link name="ank_b_link">
        <visual>
            <origin xyz="0 0 0" rpy="0 -0 0"/>
            <geometry>
                <mesh filename="package:///meshes/ank_b_link_visual.stl"/>
            </geometry>
            <material name="ank_b_link_material">
                <color rgba="0.61568627450980406568 0.81176470588235294379 0.92941176470588238168 1.0"/>
            </material>
        </visual>
        <collision>
            <origin xyz="0 0 0" rpy="0 -0 0"/>
            <geometry>
                <mesh filename="package:///meshes/ank_b_link_collision.stl"/>
            </geometry>
        </collision>
        <inertial>
            <origin xyz="-4.9409968167220855793e-09 -5.9508723331034724548e-09 -0.0087165888679858055665" rpy="0 0 0"/>
            <mass value="0.00089583742203429468642"/>
            <inertia ixx="3.3822537554673522657e-08" ixy="3.9003059548184590504e-15" ixz="1.5176340834356906244e-14" iyy="4.5803979388252428374e-08" iyz="5.220751990722038784e-14" izz="2.5946834402259798692e-08"/>
        </inertial>
    </link>

    <link name="ank_act_link_head">
        <visual>
            <origin xyz="0 0 0" rpy="0 -0 0"/>
            <geometry>
                <mesh filename="package:///meshes/ank_act_link_head_visual.stl"/>
            </geometry>
            <material name="ank_act_link_head_material">
                <color rgba="0.8805660089056220885 0.88861789403065327697 0.90620490627743233158 1.0"/>
            </material>
        </visual>
        <collision>
            <origin xyz="0 0 0" rpy="0 -0 0"/>
            <geometry>
                <mesh filename="package:///meshes/ank_act_link_head_collision.stl"/>
            </geometry>
        </collision>
        <inertial>
            <origin xyz="8.530220729853497713e-09 -0.0023472231756389880068 -0.0043000180232788303217" rpy="0 0 0"/>
            <mass value="0.0030517714925792842166"/>
            <inertia ixx="5.2970409371069164836e-08" ixy="-5.7058840905277633198e-14" ixz="1.0325254833985761746e-14" iyy="5.6254659413317882916e-08" iyz="1.1646556536464767636e-13" izz="6.2451084839898912991e-08"/>
        </inertial>
    </link>

    <link name="ank_act_link">
        <visual>
            <origin xyz="0 0 0" rpy="0 -0 0"/>
            <geometry>
                <mesh filename="package:///meshes/ank_act_link_visual.stl"/>
            </geometry>
            <material name="ank_act_link_material">
                <color rgba="0.62004392100736005489 0.58836684613512624242 0.49897069021535672695 1.0"/>
            </material>
        </visual>
        <collision>
            <origin xyz="0 0 0" rpy="0 -0 0"/>
            <geometry>
                <mesh filename="package:///meshes/ank_act_link_collision.stl"/>
            </geometry>
        </collision>
        <inertial>
            <origin xyz="0.0049084207243666050369 -0.00013802439943765723129 -0.02994700357713776448" rpy="0 0 0"/>
            <mass value="0.044782197696050358993"/>
            <inertia ixx="1.5260128421305198981e-05" ixy="2.2955773687018753103e-08" ixz="-8.1364204007616836613e-08" iyy="1.8188469778941959785e-05" iyz="-5.5542240843862614492e-08" izz="5.1496273901717082338e-06"/>
        </inertial>
    </link>

    <link name="ank_act_rod">
        <visual>
            <origin xyz="0 0 0" rpy="0 -0 0"/>
            <geometry>
                <mesh filename="package:///meshes/ank_act_rod_visual.stl"/>
            </geometry>
            <material name="ank_act_rod_material">
                <color rgba="0.80016770676329840306 0.8929145636529542962 0.94547111589042631685 1.0"/>
            </material>
        </visual>
        <collision>
            <origin xyz="0 0 0" rpy="0 -0 0"/>
            <geometry>
                <mesh filename="package:///meshes/ank_act_rod_collision.stl"/>
            </geometry>
        </collision>
        <inertial>
            <origin xyz="-2.7254954597961353052e-06 -1.2667795960183578119e-05 0.0060054807227730442123" rpy="0 0 0"/>
            <mass value="0.0026945559868381376359"/>
            <inertia ixx="3.2231832056350035208e-07" ixy="-9.9380293181808096937e-13" ixz="1.0490654906252051533e-10" iyy="3.2231218697771067004e-07" iyz="5.631753991573282539e-10" izz="1.8746557075763305454e-08"/>
        </inertial>
    </link>

    <joint name="ank_act1" type="prismatic">
        <origin xyz="2.2722093444352275959e-06 -2.0041477158394549463e-15 -0.059207313423200264024" rpy="3.141592653589793116 -7.1063902759635634618e-15 -0.636713564420013034"/>
        <parent link="ank_act_link"/>
        <child link="ank_act_rod"/>
        <axis xyz="0 0 1"/>
        <limit effort="1" velocity="20" lower="-0.017000000000000001221" upper="0.017000000000000001221"/>
        <joint_properties friction="0.0"/>
    </joint>

    <joint name="ank_B31" type="revolute">
        <origin xyz="-6.9388939039072283776e-18 -0.0060499999999999998224 -0.0043000000000000104111" rpy="1.5707963267948956698 5.4574690063281408408e-06 -3.1415926535897900074"/>
        <parent link="ank_act_link_head"/>
        <child link="ank_act_link"/>
        <axis xyz="0 0 1"/>
        <limit effort="1" velocity="20" lower="-1.570796326794896558" upper="1.570796326794896558"/>
        <joint_properties friction="0.0"/>
    </joint>

    <joint name="ank_B21" type="revolute">
        <origin xyz="-0.0045000000000000126704 0 -0.016999999999999990813" rpy="1.570796326794891451 1.5534345204864312695 -1.5707963267939346608"/>
        <parent link="ank_b_link"/>
        <child link="ank_act_link_head"/>
        <axis xyz="0 0 1"/>
        <limit effort="1" velocity="20" lower="-1.570796326794896558" upper="1.570796326794896558"/>
        <joint_properties friction="0.0"/>
    </joint>

    <joint name="ank_B11" type="revolute">
        <origin xyz="0.018680019623524654615 0.010000000000000702771 0.023399999999999573919" rpy="-1.5707963267948796826 -1.5053435939903385687 1.5707963267951574604"/>
        <parent link="ank_base_link"/>
        <child link="ank_b_link"/>
        <axis xyz="0 0 1"/>
        <limit effort="1" velocity="20" lower="-3.141592653589793116" upper="0"/>
        <joint_properties friction="0.0"/>
    </joint>

    <link name="ank_b_link_2">
        <visual>
            <origin xyz="0 0 0" rpy="0 -0 0"/>
            <geometry>
                <mesh filename="package:///meshes/ank_b_link_2_visual.stl"/>
            </geometry>
            <material name="ank_b_link_2_material">
                <color rgba="0.61568627450980406568 0.81176470588235294379 0.92941176470588238168 1.0"/>
            </material>
        </visual>
        <collision>
            <origin xyz="0 0 0" rpy="0 -0 0"/>
            <geometry>
                <mesh filename="package:///meshes/ank_b_link_2_collision.stl"/>
            </geometry>
        </collision>
        <inertial>
            <origin xyz="-4.9409968176994209797e-09 5.9508723608193632533e-09 0.0087165888679858055665" rpy="0 0 0"/>
            <mass value="0.00089583742203429468642"/>
            <inertia ixx="3.3822537554673509423e-08" ixy="-3.9003059556952858351e-15" ixz="-1.5176340834354183096e-14" iyy="4.5803979388252415139e-08" iyz="5.2207519907262115427e-14" izz="2.5946834402259798692e-08"/>
        </inertial>
    </link>

    <link name="ank_act_link_head_2">
        <visual>
            <origin xyz="0 0 0" rpy="0 -0 0"/>
            <geometry>
                <mesh filename="package:///meshes/ank_act_link_head_2_visual.stl"/>
            </geometry>
            <material name="ank_act_link_head_2_material">
                <color rgba="0.8805660089056220885 0.88861789403065327697 0.90620490627743233158 1.0"/>
            </material>
        </visual>
        <collision>
            <origin xyz="0 0 0" rpy="0 -0 0"/>
            <geometry>
                <mesh filename="package:///meshes/ank_act_link_head_2_collision.stl"/>
            </geometry>
        </collision>
        <inertial>
            <origin xyz="8.5302207582773872871e-09 -0.0023472231756390300739 -0.00430001802327877828" rpy="0 0 0"/>
            <mass value="0.0030517714925792842166"/>
            <inertia ixx="5.2970409371068959695e-08" ixy="-5.7058840689868068488e-14" ixz="1.0325254833926262701e-14" iyy="5.6254659413317869681e-08" iyz="1.1646556597952345353e-13" izz="6.2451084839898687998e-08"/>
        </inertial>
    </link>

    <link name="ank_act_link_2">
        <visual>
            <origin xyz="0 0 0" rpy="0 -0 0"/>
            <geometry>
                <mesh filename="package:///meshes/ank_act_link_2_visual.stl"/>
            </geometry>
            <material name="ank_act_link_2_material">
                <color rgba="0.62004392100736016591 0.58836684613512635345 0.49897069021535678246 1.0"/>
            </material>
        </visual>
        <collision>
            <origin xyz="0 0 0" rpy="0 -0 0"/>
            <geometry>
                <mesh filename="package:///meshes/ank_act_link_2_collision.stl"/>
            </geometry>
        </collision>
        <inertial>
            <origin xyz="0.0049084207243669910128 -0.00013802439943706406428 -0.029947003577137368963" rpy="0 0 0"/>
            <mass value="0.044782197696050352054"/>
            <inertia ixx="1.5260128421304853391e-05" ixy="2.2955773687144914691e-08" ixz="-8.1364204007474508608e-08" iyy="1.8188469778941637913e-05" iyz="-5.5542240843629978217e-08" izz="5.149627390171740421e-06"/>
        </inertial>
    </link>

    <link name="ank_act_rod_2">
        <visual>
            <origin xyz="0 0 0" rpy="0 -0 0"/>
            <geometry>
                <mesh filename="package:///meshes/ank_act_rod_2_visual.stl"/>
            </geometry>
            <material name="ank_act_rod_2_material">
                <color rgba="0.80016770676329840306 0.8929145636529542962 0.94547111589042631685 1.0"/>
            </material>
        </visual>
        <collision>
            <origin xyz="0 0 0" rpy="0 -0 0"/>
            <geometry>
                <mesh filename="package:///meshes/ank_act_rod_2_collision.stl"/>
            </geometry>
        </collision>
        <inertial>
            <origin xyz="-2.7254954588209572845e-06 -1.266779595767124621e-05 0.0060054807227736635086" rpy="0 0 0"/>
            <mass value="0.0026945559868381376359"/>
            <inertia ixx="3.2231832056353560982e-07" ixy="-9.9380293164881449171e-13" ixz="1.0490654903159184449e-10" iyy="3.2231218697774656306e-07" iyz="5.6317539907799708367e-10" izz="1.8746557075762736354e-08"/>
        </inertial>
    </link>

    <joint name="ank_act2" type="prismatic">
        <origin xyz="2.2722093450874836229e-06 -8.5521867365656589755e-16 -0.059245886443141021482" rpy="-3.141592653589793116 7.4572825813947619791e-15 -0.63671356442005910825"/>
        <parent link="ank_act_link_2"/>
        <child link="ank_act_rod_2"/>
        <axis xyz="0 0 1"/>
        <limit effort="1" velocity="20" lower="-0.017000000000000001221" upper="0.017000000000000001221"/>
        <joint_properties friction="0.0"/>
    </joint>

    <joint name="ank_B32" type="revolute">
        <origin xyz="-4.1633363423443370266e-17 -0.0060499999999999720668 -0.0042999999999999635736" rpy="1.5707963267948958919 5.4574691649268270539e-06 3.1415926535897900074"/>
        <parent link="ank_act_link_head_2"/>
        <child link="ank_act_link_2"/>
        <axis xyz="0 0 1"/>
        <limit effort="1" velocity="20" lower="-1.570796326794896558" upper="1.570796326794896558"/>
        <joint_properties friction="0.0"/>
    </joint>

    <joint name="ank_B22" type="revolute">
        <origin xyz="0.0044999999999999987926 -5.5511151231257827021e-17 0.016999999999999983874" rpy="-1.5707963267945563857 -1.5676670190976655928 -1.5707963267937707919"/>
        <parent link="ank_b_link_2"/>
        <child link="ank_act_link_head_2"/>
        <axis xyz="0 0 1"/>
        <limit effort="1" velocity="20" lower="-1.570796326794896558" upper="1.570796326794896558"/>
        <joint_properties friction="0.0"/>
    </joint>

    <joint name="ank_B12" type="revolute">
        <origin xyz="0.019999999999999386324 0.010000000000000314193 -0.011499999999999789904" rpy="1.5707963267948996666 1.4913243300613441278 1.5707963267949569541"/>
        <parent link="ank_base_link"/>
        <child link="ank_b_link_2"/>
        <axis xyz="0 0 1"/>
        <limit effort="1" velocity="20" lower="-1.570796326794896558" upper="1.570796326794896558"/>
        <joint_properties friction="0.0"/>
    </joint>

    <joint name="ank_base" type="fixed">
        <origin xyz="1.3877787807814456755e-16 0 -0.0064999999999999979669" rpy="-1.0312433704806125148e-14 1.2877894632628875911e-29 -2.0891591146372148202"/>
        <parent link="knee_link"/>
        <child link="ank_base_link"/>
        <axis xyz="0 0 1"/>
        <limit effort="1" velocity="20"/>
        <joint_properties friction="0.0"/>
    </joint>

    <joint name="knee" type="revolute">
        <origin xyz="1.873501354054951662e-16 -0.0050000000000002681189 0.19999999999999881761" rpy="1.5707963267948996666 1.0471975511965994077 3.1415926535897864547"/>
        <parent link="hip_pitch_link"/>
        <child link="knee_link"/>
        <axis xyz="0 0 1"/>
        <limit effort="1" velocity="20" lower="-1.0471975511965976313" upper="2.0943951023931952626"/>
        <joint_properties friction="0.0"/>
    </joint>


</robot>