<?xml version="1.0" ?>
<robot name="base">
<link name="hip_pitch_link">
<visual>
<origin xyz="0 0 0" rpy="0 -0 0" />
<geometry>
<mesh filename="package:///meshes/hip_pitch_link_visual.stl" />
</geometry>
<material name="hip_pitch_link_material">
<color rgba="0.61568627450980395466 0.81176470588235294379 0.92941176470588238168 1.0" />
</material>
</visual>
<collision>
<origin xyz="0 0 0" rpy="0 -0 0" />
<geometry>
<mesh filename="package:///meshes/hip_pitch_link_collision.stl" />
</geometry>
</collision>
<inertial>
<origin xyz="3.7608987471067194983e-17 -0.0024843438022173125121 0.25078691758720839111" rpy="0 0 0" />
<mass value="0.032344925814368437333" />
<inertia ixx="4.6689007636575548602e-05" ixy="-7.8653691960934419469e-20" ixz="-2.8269182393006934845e-21" iyy="5.0734955610399661626e-05" iyz="2.5718421720721515737e-08" izz="4.1800556828525945358e-06" />
</inertial>
</link>

<link name="knee_link">
<visual>
<origin xyz="0 0 0" rpy="0 -0 0" />
<geometry>
<mesh filename="package:///meshes/knee_link_visual.stl" />
</geometry>
<material name="knee_link_material">
<color rgba="0.62989867807310029324 0.73714958717504708297 0.80150013263621500137 1.0" />
</material>
</visual>
<collision>
<origin xyz="0 0 0" rpy="0 -0 0" />
<geometry>
<mesh filename="package:///meshes/knee_link_collision.stl" />
</geometry>
</collision>
<inertial>
<origin xyz="7.9169926254768554316e-17 1.4205562357824675974e-17 -0.0032457853126643576754" rpy="0 0 0" />
<mass value="0.0088445512816305894843" />
<inertia ixx="8.4493274385134268438e-07" ixy="2.1898451133721049949e-21" ixz="-4.4851299685095161539e-21" iyy="8.4493274385134776658e-07" iyz="7.6847401179354407912e-21" izz="1.6234141475381564121e-06" />
</inertial>
</link>

<link name="ank_base_link">
<visual>
<origin xyz="0 0 0" rpy="0 -0 0" />
<geometry>
<mesh filename="package:///meshes/ank_base_link_visual.stl" />
</geometry>
<material name="ank_base_link_material">
<color rgba="0.54555368846635610147 0.72113944167448473799 0.8707199484021568292 1.0" />
</material>
</visual>
<collision>
<origin xyz="0 0 0" rpy="0 -0 0" />
<geometry>
<mesh filename="package:///meshes/ank_base_link_collision.stl" />
</geometry>
</collision>
<inertial>
<origin xyz="-0.0022434246051615354053 0.0431041463716912987 0.0063175709427246290462" rpy="0 0 0" />
<mass value="0.028754206043588168701" />
<inertia ixx="3.0772164408681787376e-05" ixy="1.8400536704903033683e-06" ixz="1.2178414041262135893e-07" iyy="3.9585076474244700035e-06" iyz="-1.4740589735327421522e-07" izz="3.039559472444437372e-05" />
</inertial>
</link>

<link name="ank_pitch_link">
<visual>
<origin xyz="0 0 0" rpy="0 -0 0" />
<geometry>
<mesh filename="package:///meshes/ank_pitch_link_visual.stl" />
</geometry>
<material name="ank_pitch_link_material">
<color rgba="0.64184024980098741686 0.67445633560364026682 0.69402598708523177695 1.0" />
</material>
</visual>
<collision>
<origin xyz="0 0 0" rpy="0 -0 0" />
<geometry>
<mesh filename="package:///meshes/ank_pitch_link_collision.stl" />
</geometry>
</collision>
<inertial>
<origin xyz="1.065812785497239684e-07 0.00077531428866852054871 -0.014599794574393471294" rpy="0 0 0" />
<mass value="0.0030690306166371106658" />
<inertia ixx="2.0283928099407155777e-07" ixy="3.8262594985623510174e-13" ixz="3.1594306911978458925e-12" iyy="1.8551421794440896239e-07" iyz="1.5373147078928599918e-13" izz="5.947907120448394324e-08" />
</inertial>
</link>

<link name="ank_roll_link">
<visual>
<origin xyz="0 0 0" rpy="0 -0 0" />
<geometry>
<mesh filename="package:///meshes/ank_roll_link_visual.stl" />
</geometry>
<material name="ank_roll_link_material">
<color rgba="0.61568627450980395466 0.81176470588235305481 0.92941176470588238168 1.0" />
</material>
</visual>
<collision>
<origin xyz="0 0 0" rpy="0 -0 0" />
<geometry>
<mesh filename="package:///meshes/ank_roll_link_collision.stl" />
</geometry>
</collision>
<inertial>
<origin xyz="-1.4901271647678447696e-10 -0.013684967917931589385 0.014389602633949057781" rpy="0 0 0" />
<mass value="0.01093507166678692015" />
<inertia ixx="4.680619581430812295e-06" ixy="-1.1570405110499575645e-14" ixz="-1.8289472765046280558e-14" iyy="4.2448765972400816698e-06" iyz="7.3202159795374515811e-07" izz="1.1368413583288420761e-06" />
</inertial>
</link>

<link name="ank_rigid_foot_link">
<visual>
<origin xyz="0 0 0" rpy="0 -0 0" />
<geometry>
<mesh filename="package:///meshes/ank_rigid_foot_link_visual.stl" />
</geometry>
<material name="ank_rigid_foot_link_material">
<color rgba="0.61568627450980395466 0.81176470588235294379 0.92941176470588238168 1.0" />
</material>
</visual>
<collision>
<origin xyz="0 0 0" rpy="0 -0 0" />
<geometry>
<mesh filename="package:///meshes/ank_rigid_foot_link_collision.stl" />
</geometry>
</collision>
<inertial>
<origin xyz="-0.023731999094105324377 -9.4396649339015101572e-10 -0.013306321578886210963" rpy="0 0 0" />
<mass value="0.016563983404687340067" />
<inertia ixx="1.3186381958179099672e-06" ixy="6.9194669561983259093e-13" ixz="-6.6384590258348549074e-07" iyy="1.1862123164402234838e-05" iyz="-6.0901536277201698027e-15" izz="1.2671869695593449532e-05" />
</inertial>
</link>

<joint name="ank_foot" type="fixed">
<origin xyz="-3.9898639947466563171e-17 -0.022500000000000131006 0.025600000000000136535" rpy="-1.5707963267948477082 -1.5707963267948954478 0" />
<parent link="ank_roll_link" />
<child link="ank_rigid_foot_link" />
<axis xyz="0 0 1" />
<limit effort="1" velocity="20" />
<joint_properties friction="0.0" />
</joint>

<link name="ank_rr_link">
<visual>
<origin xyz="0 0 0" rpy="0 -0 0" />
<geometry>
<mesh filename="package:///meshes/ank_rr_link_visual.stl" />
</geometry>
<material name="ank_rr_link_material">
<color rgba="0.61568627450980395466 0.81176470588235294379 0.92941176470588238168 1.0" />
</material>
</visual>
<collision>
<origin xyz="0 0 0" rpy="0 -0 0" />
<geometry>
<mesh filename="package:///meshes/ank_rr_link_collision.stl" />
</geometry>
</collision>
<inertial>
<origin xyz="2.9962725549968997755e-05 -0.0069241283254153134993 -0.001900000000000005634" rpy="0 0 0" />
<mass value="0.00095937776863479966132" />
<inertia ixx="2.2259486597278172718e-08" ixy="8.8417693084785078546e-11" ixz="-1.3528801961571404317e-14" iyy="1.9281323587980155461e-08" iyz="-5.7741986878948337353e-26" izz="2.9726039484830349946e-08" />
</inertial>
</link>

<link name="ank_act_rod_head">
<visual>
<origin xyz="0 0 0" rpy="0 -0 0" />
<geometry>
<mesh filename="package:///meshes/ank_act_rod_head_visual.stl" />
</geometry>
<material name="ank_act_rod_head_material">
<color rgba="0.97254901960784312376 0.52941176470588235947 0.0039215686274509803377 1.0" />
</material>
</visual>
<collision>
<origin xyz="0 0 0" rpy="0 -0 0" />
<geometry>
<mesh filename="package:///meshes/ank_act_rod_head_collision.stl" />
</geometry>
</collision>
<inertial>
<origin xyz="-5.7828415394479757123e-11 0.0033987031118029096925 -0.0020055782443104603653" rpy="0 0 0" />
<mass value="0.00021950575367189157174" />
<inertia ixx="3.5463041803908300749e-09" ixy="-3.4252092716065174019e-27" ixz="3.0761072604181171894e-16" iyy="7.8971958044316566211e-10" iyz="2.106078917062050951e-12" izz="3.8328239589459786145e-09" />
</inertial>
</link>

<link name="closing_ank_act1_2">
<inertial>
<origin xyz="0 0 0" rpy="0 0 0" />
<mass value="1e-9" />
<inertia ixx="0" ixy="0" ixz="0" iyy="0" iyz="0" izz="0" />
</inertial>
</link>
<joint name="closing_ank_act1_2_frame" type="fixed">
<origin xyz="0 0.0040999999999999925393 -0.0020093773498181892977" rpy="1.570796326794896558 -1.570796326794896558 0" />
<parent link="ank_act_rod_head" />
<child link="closing_ank_act1_2" />
<axis xyz="0 0 0" />
</joint>

<joint name="ank_R21_passive" type="revolute">
<origin xyz="0.001999999999999990067 -0.0099999999999999672484 -0.0019000000000000058509" rpy="-1.5707963267948636954 -1.5534345204865058765 -1.5707963267948001906" />
<parent link="ank_rr_link" />
<child link="ank_act_rod_head" />
<axis xyz="0 0 1" />
<limit effort="1" velocity="20" lower="-1.570796326794896558" upper="1.570796326794896558" />
<joint_properties friction="0.0" />
</joint>

<joint name="ank_R11_passive" type="revolute">
<origin xyz="0.009999999999999995004 -0.01250000000000002498 0.040599999999999976386" rpy="4.5538414498539748188e-14 8.2432841012071876929e-15 3.0761399207850028681" />
<parent link="ank_roll_link" />
<child link="ank_rr_link" />
<axis xyz="0 0 1" />
<limit effort="1" velocity="20" lower="-1.570796326794896558" upper="1.570796326794896558" />
<joint_properties friction="0.0" />
</joint>

<link name="ank_rr_link_2">
<visual>
<origin xyz="0 0 0" rpy="0 -0 0" />
<geometry>
<mesh filename="package:///meshes/ank_rr_link_2_visual.stl" />
</geometry>
<material name="ank_rr_link_2_material">
<color rgba="0.61568627450980395466 0.81176470588235294379 0.92941176470588238168 1.0" />
</material>
</visual>
<collision>
<origin xyz="0 0 0" rpy="0 -0 0" />
<geometry>
<mesh filename="package:///meshes/ank_rr_link_2_collision.stl" />
</geometry>
</collision>
<inertial>
<origin xyz="2.9962725549968848677e-05 0.0069241283254153143667 -0.0018999999999999991288" rpy="0 0 0" />
<mass value="0.00095937776863479966132" />
<inertia ixx="2.22594865972781661e-08" ixy="-8.8417693084784600332e-11" ixz="1.3528801961570247847e-14" iyy="1.9281323587980162078e-08" iyz="-1.6626376108552277629e-26" izz="2.9726039484830349946e-08" />
</inertial>
</link>

<link name="ank_act_rod_head_2">
<visual>
<origin xyz="0 0 0" rpy="0 -0 0" />
<geometry>
<mesh filename="package:///meshes/ank_act_rod_head_2_visual.stl" />
</geometry>
<material name="ank_act_rod_head_2_material">
<color rgba="0.97254901960784312376 0.52941176470588235947 0.0039215686274509803377 1.0" />
</material>
</visual>
<collision>
<origin xyz="0 0 0" rpy="0 -0 0" />
<geometry>
<mesh filename="package:///meshes/ank_act_rod_head_2_collision.stl" />
</geometry>
</collision>
<inertial>
<origin xyz="-5.7828422333254443625e-11 0.0033987031118029101262 -0.002005578244310459498" rpy="0 0 0" />
<mass value="0.00021950575367189157174" />
<inertia ixx="3.5463041803908300749e-09" ixy="-2.0779273637994239933e-27" ixz="3.0761072604376908006e-16" iyy="7.8971958044316545532e-10" iyz="2.1060789170620873017e-12" izz="3.8328239589459786145e-09" />
</inertial>
</link>

<link name="closing_ank_act2_2">
<inertial>
<origin xyz="0 0 0" rpy="0 0 0" />
<mass value="1e-9" />
<inertia ixx="0" ixy="0" ixz="0" iyy="0" iyz="0" izz="0" />
</inertial>
</link>
<joint name="closing_ank_act2_2_frame" type="fixed">
<origin xyz="-6.9388939039072283776e-18 0.0040999999999999925393 -0.0020093773498181905987" rpy="1.570796326794896558 1.570796326794896558 0" />
<parent link="ank_act_rod_head_2" />
<child link="closing_ank_act2_2" />
<axis xyz="0 0 0" />
</joint>

<joint name="ank_R22_passive" type="revolute">
<origin xyz="0.0020000000000000139194 0.010000000000000050515 -0.0019000000000000127898" rpy="-1.5707963267951321473 1.5676670190976929042 -1.5707963267984343947" />
<parent link="ank_rr_link_2" />
<child link="ank_act_rod_head_2" />
<axis xyz="0 0 1" />
<limit effort="1" velocity="20" lower="-1.570796326794896558" upper="1.570796326794896558" />
<joint_properties friction="0.0" />
</joint>

<joint name="ank_R12_passive" type="revolute">
<origin xyz="-0.0099999999999999845957 -0.012500000000000052736 0.040599999999999969447" rpy="-4.7709545858758676013e-14 1.2384261596296442717e-14 0.079471996733595215434" />
<parent link="ank_roll_link" />
<child link="ank_rr_link_2" />
<axis xyz="0 0 1" />
<limit effort="1" velocity="20" lower="-1.570796326794896558" upper="1.570796326794896558" />
<joint_properties friction="0.0" />
</joint>

<joint name="ank_roll" type="revolute">
<origin xyz="-9.7144514654701197287e-17 0.0015000000000004699244 -0.014599999999999951558" rpy="1.5707963267949847097 -1.5707963267948685804 0" />
<parent link="ank_pitch_link" />
<child link="ank_roll_link" />
<axis xyz="0 0 1" />
<limit effort="1" velocity="20" lower="-1.570796326794896558" upper="1.570796326794896558" />
<joint_properties friction="0.0" />
</joint>

<joint name="ank_pitch" type="revolute">
<origin xyz="-9.6428941220860764361e-16 0.10000000000000054678 0.020899999999999852723" rpy="-1.7591152789461700036e-14 -1.17510393317422114e-14 1.5707963267948696906" />
<parent link="ank_base_link" />
<child link="ank_pitch_link" />
<axis xyz="0 0 1" />
<limit effort="1" velocity="20" lower="-1.570796326794896558" upper="1.570796326794896558" />
<joint_properties friction="0.0" />
</joint>

<link name="ank_b_link">
<visual>
<origin xyz="0 0 0" rpy="0 -0 0" />
<geometry>
<mesh filename="package:///meshes/ank_b_link_visual.stl" />
</geometry>
<material name="ank_b_link_material">
<color rgba="0.61568627450980395466 0.81176470588235294379 0.92941176470588238168 1.0" />
</material>
</visual>
<collision>
<origin xyz="0 0 0" rpy="0 -0 0" />
<geometry>
<mesh filename="package:///meshes/ank_b_link_collision.stl" />
</geometry>
</collision>
<inertial>
<origin xyz="-4.9409968167220864065e-09 -5.9508723331034708004e-09 -0.0087165888679858055665" rpy="0 0 0" />
<mass value="0.0018061238347465617769" />
<inertia ixx="6.8190599908615980891e-08" ixy="7.8635200701985070024e-15" ixz="3.0597461358580794824e-14" iyy="9.2346732637605712292e-08" iyz="1.0525709658713786578e-13" izz="5.2312166133588304563e-08" />
</inertial>
</link>

<link name="ank_act_link_head">
<visual>
<origin xyz="0 0 0" rpy="0 -0 0" />
<geometry>
<mesh filename="package:///meshes/ank_act_link_head_visual.stl" />
</geometry>
<material name="ank_act_link_head_material">
<color rgba="0.88056600890562186645 0.88861789403065327697 0.90620490627743222056 1.0" />
</material>
</visual>
<collision>
<origin xyz="0 0 0" rpy="0 -0 0" />
<geometry>
<mesh filename="package:///meshes/ank_act_link_head_collision.stl" />
</geometry>
</collision>
<inertial>
<origin xyz="8.5302207298544936385e-09 -0.0023472231756389875731 -0.0043000180232788303217" rpy="0 0 0" />
<mass value="0.001013742855626921513" />
<inertia ixx="1.7595804335327252452e-08" ixy="-1.8953906758198917907e-14" ixz="3.4298614250654216388e-15" iyy="1.8686772327038895467e-08" iyz="3.8687737630955502088e-14" izz="2.0745111892073785711e-08" />
</inertial>
</link>

<link name="ank_act_link">
<visual>
<origin xyz="0 0 0" rpy="0 -0 0" />
<geometry>
<mesh filename="package:///meshes/ank_act_link_visual.stl" />
</geometry>
<material name="ank_act_link_material">
<color rgba="0.62004392100736016591 0.58836684613512624242 0.49897069021535678246 1.0" />
</material>
</visual>
<collision>
<origin xyz="0 0 0" rpy="0 -0 0" />
<geometry>
<mesh filename="package:///meshes/ank_act_link_collision.stl" />
</geometry>
</collision>
<inertial>
<origin xyz="0.0049084207243666067716 -0.00013802439943765696024 -0.029947003577137778357" rpy="0 0 0" />
<mass value="0.014875829689094588817" />
<inertia ixx="5.0691364673482598494e-06" ixy="7.6254895319620944106e-09" ixz="-2.7027705290864318783e-08" iyy="6.0418780822953625318e-06" iyz="-1.8450119865752929257e-08" izz="1.7106123406097888202e-06" />
</inertial>
</link>

<link name="ank_act_rod">
<visual>
<origin xyz="0 0 0" rpy="0 -0 0" />
<geometry>
<mesh filename="package:///meshes/ank_act_rod_visual.stl" />
</geometry>
<material name="ank_act_rod_material">
<color rgba="0.80016770676329818102 0.8929145636529542962 0.94547111589042609481 1.0" />
</material>
</visual>
<collision>
<origin xyz="0 0 0" rpy="0 -0 0" />
<geometry>
<mesh filename="package:///meshes/ank_act_rod_collision.stl" />
</geometry>
</collision>
<inertial>
<origin xyz="-2.7254954597961323406e-06 -1.2667795960183581507e-05 0.0060054807227730442123" rpy="0 0 0" />
<mass value="0.00089508237670679559241" />
<inertia ixx="1.0706827018452707019e-07" ixy="-3.3012321678791319928e-13" ixz="3.4848043137961870114e-11" iyy="1.0706623271914387143e-07" iyz="1.8707660083621046869e-10" izz="6.2272645082923549957e-09" />
</inertial>
</link>

<link name="closing_ank_act1_1">
<inertial>
<origin xyz="0 0 0" rpy="0 0 0" />
<mass value="1e-9" />
<inertia ixx="0" ixy="0" ixz="0" iyy="0" iyz="0" izz="0" />
</inertial>
</link>
<joint name="closing_ank_act1_1_frame" type="fixed">
<origin xyz="-3.1001814916432196556e-05 -0.00019012642426191952993 0.023400000000002821321" rpy="-7.7012090744259865156e-14 2.3601491602027366924e-13 -2.2075153486839074191" />
<parent link="ank_act_rod" />
<child link="closing_ank_act1_1" />
<axis xyz="0 0 0" />
</joint>

<joint name="ank_act1_passive" type="prismatic">
<origin xyz="2.2722093444352275959e-06 -2.0041477158394549463e-15 -0.059207313423200264024" rpy="3.141592653589793116 -7.1063902759635634618e-15 -0.636713564420013034" />
<parent link="ank_act_link" />
<child link="ank_act_rod" />
<axis xyz="0 0 1" />
<limit effort="1" velocity="20" lower="-0.017000000000000001221" upper="0.017000000000000001221" />
<joint_properties friction="0.0" />
</joint>

<joint name="ank_B31_passive" type="revolute">
<origin xyz="-6.9388939039072283776e-18 -0.0060499999999999998224 -0.0043000000000000104111" rpy="1.5707963267948956698 5.4574690063281408408e-06 -3.1415926535897900074" />
<parent link="ank_act_link_head" />
<child link="ank_act_link" />
<axis xyz="0 0 1" />
<limit effort="1" velocity="20" lower="-1.570796326794896558" upper="1.570796326794896558" />
<joint_properties friction="0.0" />
</joint>

<joint name="ank_B21_passive" type="revolute">
<origin xyz="-0.0045000000000000126704 0 -0.016999999999999990813" rpy="1.570796326794891451 1.5534345204864312695 -1.5707963267939346608" />
<parent link="ank_b_link" />
<child link="ank_act_link_head" />
<axis xyz="0 0 1" />
<limit effort="1" velocity="20" lower="-1.570796326794896558" upper="1.570796326794896558" />
<joint_properties friction="0.0" />
</joint>

<joint name="ank_B11_passive" type="revolute">
<origin xyz="0.018680019623524654615 0.010000000000000702771 0.023399999999999573919" rpy="-1.5707963267948796826 -1.5053435939903385687 1.5707963267951574604" />
<parent link="ank_base_link" />
<child link="ank_b_link" />
<axis xyz="0 0 1" />
<limit effort="1" velocity="20" lower="-3.141592653589793116" upper="0" />
<joint_properties friction="0.0" />
</joint>

<link name="ank_b_link_2">
<visual>
<origin xyz="0 0 0" rpy="0 -0 0" />
<geometry>
<mesh filename="package:///meshes/ank_b_link_2_visual.stl" />
</geometry>
<material name="ank_b_link_2_material">
<color rgba="0.61568627450980395466 0.81176470588235294379 0.92941176470588238168 1.0" />
</material>
</visual>
<collision>
<origin xyz="0 0 0" rpy="0 -0 0" />
<geometry>
<mesh filename="package:///meshes/ank_b_link_2_collision.stl" />
</geometry>
</collision>
<inertial>
<origin xyz="-4.9409968176994226341e-09 5.9508723608193624261e-09 0.0087165888679858055665" rpy="0 0 0" />
<mass value="0.0018061238347465617769" />
<inertia ixx="6.8190599908615954421e-08" ixy="-7.8635200719663032703e-15" ixz="-3.0597461358575310663e-14" iyy="9.2346732637605685823e-08" iyz="1.0525709658722201515e-13" izz="5.2312166133588304563e-08" />
</inertial>
</link>

<link name="ank_act_link_head_2">
<visual>
<origin xyz="0 0 0" rpy="0 -0 0" />
<geometry>
<mesh filename="package:///meshes/ank_act_link_head_2_visual.stl" />
</geometry>
<material name="ank_act_link_head_2_material">
<color rgba="0.88056600890562186645 0.88861789403065327697 0.90620490627743222056 1.0" />
</material>
</visual>
<collision>
<origin xyz="0 0 0" rpy="0 -0 0" />
<geometry>
<mesh filename="package:///meshes/ank_act_link_head_2_collision.stl" />
</geometry>
</collision>
<inertial>
<origin xyz="8.5302207582783832126e-09 -0.0023472231756390296402 -0.00430001802327877828" rpy="0 0 0" />
<mass value="0.001013742855626921513" />
<inertia ixx="1.7595804335327186277e-08" ixy="-1.8953906686643784353e-14" ixz="3.4298614250456551511e-15" iyy="1.8686772327038888849e-08" iyz="3.8687737835206036071e-14" izz="2.0745111892073712919e-08" />
</inertial>
</link>

<link name="ank_act_link_2">
<visual>
<origin xyz="0 0 0" rpy="0 -0 0" />
<geometry>
<mesh filename="package:///meshes/ank_act_link_2_visual.stl" />
</geometry>
<material name="ank_act_link_2_material">
<color rgba="0.62004392100736027693 0.58836684613512646447 0.49897069021535678246 1.0" />
</material>
</visual>
<collision>
<origin xyz="0 0 0" rpy="0 -0 0" />
<geometry>
<mesh filename="package:///meshes/ank_act_link_2_collision.stl" />
</geometry>
</collision>
<inertial>
<origin xyz="0.0049084207243669875434 -0.00013802439943706379323 -0.029947003577137368963" rpy="0 0 0" />
<mass value="0.014875829689094592287" />
<inertia ixx="5.0691364673481446529e-06" ixy="7.6254895320040010348e-09" ixz="-2.7027705290816765824e-08" iyy="6.0418780822952549586e-06" iyz="-1.8450119865675657353e-08" izz="1.7106123406097994081e-06" />
</inertial>
</link>

<link name="ank_act_rod_2">
<visual>
<origin xyz="0 0 0" rpy="0 -0 0" />
<geometry>
<mesh filename="package:///meshes/ank_act_rod_2_visual.stl" />
</geometry>
<material name="ank_act_rod_2_material">
<color rgba="0.80016770676329818102 0.8929145636529542962 0.94547111589042609481 1.0" />
</material>
</visual>
<collision>
<origin xyz="0 0 0" rpy="0 -0 0" />
<geometry>
<mesh filename="package:///meshes/ank_act_rod_2_collision.stl" />
</geometry>
</collision>
<inertial>
<origin xyz="-2.7254954588209538963e-06 -1.2667795957671247904e-05 0.0060054807227736652434" rpy="0 0 0" />
<mass value="0.00089508237670679559241" />
<inertia ixx="1.0706827018453880954e-07" ixy="-3.3012321673174468724e-13" ixz="3.4848043127687931477e-11" iyy="1.0706623271915578283e-07" iyz="1.8707660080985820044e-10" izz="6.22726450829216888e-09" />
</inertial>
</link>

<link name="closing_ank_act2_1">
<inertial>
<origin xyz="0 0 0" rpy="0 0 0" />
<mass value="1e-9" />
<inertia ixx="0" ixy="0" ixz="0" iyy="0" iyz="0" izz="0" />
</inertial>
</link>
<joint name="closing_ank_act2_1_frame" type="fixed">
<origin xyz="-3.1001814911918446072e-05 -0.0001901264242515129238 0.023400000000005222178" rpy="-3.1112994060701347822e-14 -3.9361409747767986708e-14 -2.2075153486840899397" />
<parent link="ank_act_rod_2" />
<child link="closing_ank_act2_1" />
<axis xyz="0 0 0" />
</joint>

<joint name="ank_act2_passive" type="prismatic">
<origin xyz="2.2722093450874836229e-06 -8.5521867365656589755e-16 -0.059245886443141021482" rpy="-3.141592653589793116 7.4572825813947619791e-15 -0.63671356442005910825" />
<parent link="ank_act_link_2" />
<child link="ank_act_rod_2" />
<axis xyz="0 0 1" />
<limit effort="1" velocity="20" lower="-0.017000000000000001221" upper="0.017000000000000001221" />
<joint_properties friction="0.0" />
</joint>

<joint name="ank_B32_passive" type="revolute">
<origin xyz="-4.1633363423443370266e-17 -0.0060499999999999720668 -0.0042999999999999635736" rpy="1.5707963267948958919 5.4574691649268270539e-06 3.1415926535897900074" />
<parent link="ank_act_link_head_2" />
<child link="ank_act_link_2" />
<axis xyz="0 0 1" />
<limit effort="1" velocity="20" lower="-1.570796326794896558" upper="1.570796326794896558" />
<joint_properties friction="0.0" />
</joint>

<joint name="ank_B22_passive" type="revolute">
<origin xyz="0.0044999999999999987926 -5.5511151231257827021e-17 0.016999999999999983874" rpy="-1.5707963267945563857 -1.5676670190976655928 -1.5707963267937707919" />
<parent link="ank_b_link_2" />
<child link="ank_act_link_head_2" />
<axis xyz="0 0 1" />
<limit effort="1" velocity="20" lower="-1.570796326794896558" upper="1.570796326794896558" />
<joint_properties friction="0.0" />
</joint>

<joint name="ank_B12_passive" type="revolute">
<origin xyz="0.019999999999999386324 0.010000000000000314193 -0.011499999999999789904" rpy="1.5707963267948996666 1.4913243300613441278 1.5707963267949569541" />
<parent link="ank_base_link" />
<child link="ank_b_link_2" />
<axis xyz="0 0 1" />
<limit effort="1" velocity="20" lower="-1.570796326794896558" upper="1.570796326794896558" />
<joint_properties friction="0.0" />
</joint>

<joint name="ank_base" type="fixed">
<origin xyz="1.3877787807814456755e-16 0 -0.0064999999999999979669" rpy="-1.0312433704806125148e-14 1.2877894632628875911e-29 -2.0891591146372148202" />
<parent link="knee_link" />
<child link="ank_base_link" />
<axis xyz="0 0 1" />
<limit effort="1" velocity="20" />
<joint_properties friction="0.0" />
</joint>

<joint name="knee" type="revolute">
<origin xyz="1.873501354054951662e-16 -0.0050000000000002681189 0.19999999999999881761" rpy="1.5707963267948996666 1.0471975511965994077 3.1415926535897864547" />
<parent link="hip_pitch_link" />
<child link="knee_link" />
<axis xyz="0 0 1" />
<limit effort="1" velocity="20" lower="-1.0471975511965976313" upper="2.0943951023931952626" />
<joint_properties friction="0.0" />
</joint>


</robot>