<?xml version="1.0" ?><robot name="right_leg_OP3">  
  <link name="hip_yaw_link">    
    <visual>      
      <origin xyz="0 0 0" rpy="0 -0 0"/>      
      <geometry>        
        <mesh filename="package:///meshes/right_hip_yaw_link_visual.stl"/>        
      </geometry>      
      <material name="hip_yaw_link_material">        
        <color rgba="0.61568627450980395466 0.81176470588235294379 0.92941176470588238168 1.0"/>        
      </material>      
    </visual>    
    <collision>      
      <origin xyz="0 0 0" rpy="0 -0 0"/>      
      <geometry>        
        <mesh filename="package:///meshes/right_hip_yaw_link_collision.stl"/>        
      </geometry>      
    </collision>    
    <inertial>      
      <origin xyz="4.8161475668077511176e-19 -6.2050558167851175879e-21 -0.0098919667346054444834" rpy="0 0 0"/>      
      <mass value="0.017999999999999991701"/>      
      <inertia ixx="2.6483505271519536081e-06" ixy="0" ixz="0" iyy="7.7055357996008217629e-06" iyz="0" izz="7.773668280680532449e-06"/>      
    </inertial>    
  </link>  

  <link name="hip_roll_link">    
    <visual>      
      <origin xyz="0 0 0" rpy="0 -0 0"/>      
      <geometry>        
        <mesh filename="package:///meshes/right_hip_roll_link_visual.stl"/>        
      </geometry>      
      <material name="hip_roll_link_material">        
        <color rgba="0.51698661238356058423 0.5034781595109349972 0.49050589017722023844 1.0"/>        
      </material>      
    </visual>    
    <collision>      
      <origin xyz="0 0 0" rpy="0 -0 0"/>      
      <geometry>        
        <mesh filename="package:///meshes/right_hip_roll_link_collision.stl"/>        
      </geometry>      
    </collision>    
    <inertial>      
      <origin xyz="-0.011999849582182847002 -0.00049598090794352107154 -0.018504111838597715745" rpy="0 0 0"/>      
      <mass value="0.11059999999836231388"/>      
      <inertia ixx="2.2818802599018581112e-05" ixy="-4.6520143285862249191e-08" ixz="-4.688854825904277116e-08" iyy="3.087163208233820107e-05" iyz="-5.7477343899720075343e-07" izz="3.08716664244684352e-05"/>      
    </inertial>    
  </link>  

  <link name="right_hip_pitch_link_xm430">    
    <visual>      
      <origin xyz="0 0 0" rpy="0 -0 0"/>      
      <geometry>        
        <mesh filename="package:///meshes/right_hip_pitch_link_xm430_visual.stl"/>        
      </geometry>      
      <material name="right_hip_pitch_link_xm430_material">        
        <color rgba="0.87072221357329560032 0.72641010956094276274 0.24785169615220692396 1.0"/>        
      </material>      
    </visual>    
    <collision>      
      <origin xyz="0 0 0" rpy="0 -0 0"/>      
      <geometry>        
        <mesh filename="package:///meshes/right_hip_pitch_link_xm430_collision.stl"/>        
      </geometry>      
    </collision>    
    <inertial>      
      <origin xyz="0.00075715881371305002873 -0.050714784778880424299 -0.012656153620121844347" rpy="0 0 0"/>      
      <mass value="0.11480090135030571186"/>      
      <inertia ixx="6.6072786489385269501e-05" ixy="4.6010682906081563585e-07" ixz="1.8171597853303143829e-07" iyy="2.3633665181582133759e-05" iyz="1.4125296519926532777e-06" izz="6.2221763055416839114e-05"/>      
    </inertial>    
  </link>  

  <link name="right_calf_link">    
    <visual>      
      <origin xyz="0 0 0" rpy="0 -0 0"/>      
      <geometry>        
        <mesh filename="package:///meshes/right_calf_link_visual.stl"/>        
      </geometry>      
      <material name="right_calf_link_material">        
        <color rgba="0.522707147375079062 0.70740037950664136357 0.87533206831119536595 1.0"/>        
      </material>      
    </visual>    
    <collision>      
      <origin xyz="0 0 0" rpy="0 -0 0"/>      
      <geometry>        
        <mesh filename="package:///meshes/right_calf_link_collision.stl"/>        
      </geometry>      
    </collision>    
    <inertial>      
      <origin xyz="-0.0044698992063318841381 0.040537655000345604317 -0.0094043191617599383031" rpy="0 0 0"/>      
      <mass value="0.0309999999999999859"/>      
      <inertia ixx="3.2349006752264862681e-05" ixy="-1.4910956274418834536e-06" ixz="1.9651815973592531377e-07" iyy="7.7183393965099126091e-06" iyz="6.2686077155121789431e-07" izz="2.7323441483284231876e-05"/>      
    </inertial>    
  </link>  

  <link name="bearing_683">    
    <visual>      
      <origin xyz="0 0 0" rpy="0 -0 0"/>      
      <geometry>        
        <mesh filename="package:///meshes/right_bearing_683_visual.stl"/>        
      </geometry>      
      <material name="bearing_683_material">        
        <color rgba="0.64705882352941179736 0.64705882352941179736 0.64705882352941179736 1.0"/>        
      </material>      
    </visual>    
    <collision>      
      <origin xyz="0 0 0" rpy="0 -0 0"/>      
      <geometry>        
        <mesh filename="package:///meshes/right_bearing_683_collision.stl"/>        
      </geometry>      
    </collision>    
    <inertial>      
      <origin xyz="1.0732094295235738274e-19 2.4186774283158772134e-19 -0.0015500000000000053665" rpy="0 0 0"/>      
      <mass value="0.00048694686130641804279"/>      
      <inertia ixx="2.1551456503319891521e-09" ixy="-6.9957594434472426076e-28" ixz="-5.8827502853431130191e-38" iyy="2.1551456503319883249e-09" iyz="-4.6070882835329376461e-38" izz="3.5303647444715305817e-09"/>      
    </inertial>    
  </link>  

  <joint name="right_knee_front_rev_2" type="revolute">    
    <origin xyz="-0.0057402514854764750268 -0.013858192987669187834 -0.026200000000000837203" rpy="2.6700561543117312309e-15 -7.7788101235701736907e-15 3.1386680923234866469"/>    
    <parent link="right_calf_link"/>    
    <child link="bearing_683"/>    
    <axis xyz="0 0 1"/>    
    <limit effort="1" velocity="20" lower="-6.283185307179586232" upper="6.283185307179586232"/>    
    <joint_properties friction="0.0"/>    
  </joint>  

  <link name="bearing_683_2">    
    <visual>      
      <origin xyz="0 0 0" rpy="0 -0 0"/>      
      <geometry>        
        <mesh filename="package:///meshes/right_bearing_683_2_visual.stl"/>        
      </geometry>      
      <material name="bearing_683_2_material">        
        <color rgba="0.64705882352941179736 0.64705882352941179736 0.64705882352941179736 1.0"/>        
      </material>      
    </visual>    
    <collision>      
      <origin xyz="0 0 0" rpy="0 -0 0"/>      
      <geometry>        
        <mesh filename="package:///meshes/right_bearing_683_2_collision.stl"/>        
      </geometry>      
    </collision>    
    <inertial>      
      <origin xyz="1.0732094295240151061e-19 2.4186774283164829184e-19 -0.001549999999999997994" rpy="0 0 0"/>      
      <mass value="0.00048694686130641804279"/>      
      <inertia ixx="2.1551456503319883249e-09" ixy="-5.9919236713053523422e-28" ixz="6.6521184283211285355e-38" iyy="2.1551456503319874977e-09" iyz="1.2984630188935398657e-37" izz="3.5303647444715322361e-09"/>      
    </inertial>    
  </link>  

  <joint name="right_knee_back_rev_2" type="revolute">    
    <origin xyz="0.0057402514854764602817 0.01385819298766871599 -0.026199999999999792899" rpy="-2.1293173172291718105e-14 4.8029314978609855261e-14 3.1385914305327689"/>    
    <parent link="right_calf_link"/>    
    <child link="bearing_683_2"/>    
    <axis xyz="0 0 1"/>    
    <limit effort="1" velocity="20" lower="-6.283185307179586232" upper="6.283185307179586232"/>    
    <joint_properties friction="0.0"/>    
  </joint>  

  <link name="ank_pitch_link">    
    <visual>      
      <origin xyz="0 0 0" rpy="0 -0 0"/>      
      <geometry>        
        <mesh filename="package:///meshes/right_ank_pitch_link_visual.stl"/>        
      </geometry>      
      <material name="ank_pitch_link_material">        
        <color rgba="0.42838831031765539636 0.55128652208657225042 0.74128917770314906033 1.0"/>        
      </material>      
    </visual>    
    <collision>      
      <origin xyz="0 0 0" rpy="0 -0 0"/>      
      <geometry>        
        <mesh filename="package:///meshes/right_ank_pitch_link_collision.stl"/>        
      </geometry>      
    </collision>    
    <inertial>      
      <origin xyz="-0.012383885521091264614 -0.019663604311317139928 -0.018862066178909241837" rpy="0 0 0"/>      
      <mass value="0.15976376693924945749"/>      
      <inertia ixx="9.8184006245882954941e-05" ixy="-1.0738445982480605758e-06" ixz="-4.3555854012722139897e-08" iyy="4.2237181854197494908e-05" iyz="-4.1061630166171276171e-07" izz="0.00011168324060676464973"/>      
    </inertial>    
  </link>  

  <link name="ank_roll_link">    
    <visual>      
      <origin xyz="0 0 0" rpy="0 -0 0"/>      
      <geometry>        
        <mesh filename="package:///meshes/right_ank_roll_link_visual.stl"/>        
      </geometry>      
      <material name="ank_roll_link_material">        
        <color rgba="0.61568627450980395466 0.81176470588235283277 0.92941176470588227065 1.0"/>        
      </material>      
    </visual>    
    <collision>      
      <origin xyz="0 0 0" rpy="0 -0 0"/>      
      <geometry>        
        <mesh filename="package:///meshes/right_ank_roll_link_collision.stl"/>        
      </geometry>      
    </collision>    
    <inertial>      
      <origin xyz="-0.026981230777523994985 2.0010857558033887915e-12 -0.033733185742545780672" rpy="0 0 0"/>      
      <mass value="0.042600000000000012856"/>      
      <inertia ixx="3.7270477448018106545e-05" ixy="5.5392839593429372709e-16" ixz="-2.3925937758709918513e-06" iyy="3.7621548160200232573e-05" iyz="5.0816858838695054806e-12" izz="1.0126192914158552762e-05"/>      
    </inertial>    
  </link>  

  <joint name="right_ank_roll" type="revolute">    
    <origin xyz="-2.498001805406602216e-16 -0.022750000000001085326 -0.019000000000002174871" rpy="-1.5707963267948694686 1.175774048742249633e-14 -3.1415926535897815697"/>    
    <parent link="ank_pitch_link"/>    
    <child link="ank_roll_link"/>    
    <axis xyz="0 0 1"/>    
    <limit effort="1" velocity="20" lower="-1.570796326794896558" upper="1.570796326794896558"/>    
    <joint_properties friction="0.0"/>    
  </joint>  

  <joint name="right_ank_pitch" type="revolute">    
    <origin xyz="0.00050000000000010062437 0.099999999999999977796 0.0086000000000000208222" rpy="-7.4480623481441756806e-16 -2.1451753131548428425e-15 1.5707963267948934494"/>    
    <parent link="right_calf_link"/>    
    <child link="ank_pitch_link"/>    
    <axis xyz="0 0 1"/>    
    <limit effort="1" velocity="20" lower="-0.785398163397448279" upper="1.8325957145940461324"/>    
    <joint_properties friction="0.0"/>    
  </joint>  

  <joint name="right_knee_pitch" type="revolute">    
    <origin xyz="5.842070865544391856e-17 -0.095999999999999585665 -0.0092000000000001299488" rpy="-1.390597706429142792e-15 -1.7669519698394562425e-15 -3.1415926535897917837"/>    
    <parent link="right_hip_pitch_link_xm430"/>    
    <child link="right_calf_link"/>    
    <axis xyz="0 0 1"/>    
    <limit effort="1" velocity="20" lower="-1.9198621771937625091" upper="0"/>    
    <joint_properties friction="0.0"/>    
  </joint>  

  <link name="xm430_plate">    
    <visual>      
      <origin xyz="0 0 0" rpy="0 -0 0"/>      
      <geometry>        
        <mesh filename="package:///meshes/right_xm430_plate_visual.stl"/>        
      </geometry>      
      <material name="xm430_plate_material">        
        <color rgba="0.61568627450980395466 0.81176470588235294379 0.92941176470588227065 1.0"/>        
      </material>      
    </visual>    
    <collision>      
      <origin xyz="0 0 0" rpy="0 -0 0"/>      
      <geometry>        
        <mesh filename="package:///meshes/right_xm430_plate_collision.stl"/>        
      </geometry>      
    </collision>    
    <inertial>      
      <origin xyz="6.686038036541244332e-19 -1.0058407273929721429e-17 -0.0024039046431217955119" rpy="0 0 0"/>      
      <mass value="0.0026999999999999997093"/>      
      <inertia ixx="2.6720434385876693618e-07" ixy="-6.8936588702566387474e-08" ixz="7.6069107326939274577e-36" iyy="1.2933116645363405536e-07" iyz="-8.0362077709102010879e-37" izz="3.8533537562751439267e-07"/>      
    </inertial>    
  </link>  

  <link name="knee_rod">    
    <visual>      
      <origin xyz="0 0 0" rpy="0 -0 0"/>      
      <geometry>        
        <mesh filename="package:///meshes/right_knee_rod_visual.stl"/>        
      </geometry>      
      <material name="knee_rod_material">        
        <color rgba="0.62051618944235198416 0.78640765248647581664 0.88594253031295022716 1.0"/>        
      </material>      
    </visual>    
    <collision>      
      <origin xyz="0 0 0" rpy="0 -0 0"/>      
      <geometry>        
        <mesh filename="package:///meshes/right_knee_rod_collision.stl"/>        
      </geometry>      
    </collision>    
    <inertial>      
      <origin xyz="0.014594547782157756347 -4.1542690670228890951e-05 -0.001599622737319192009" rpy="0 0 0"/>      
      <mass value="0.0031629468613064179276"/>      
      <inertia ixx="2.5896116180643404295e-08" ixy="3.4895756841948530691e-10" ixz="4.1682975931088251416e-10" iyy="6.0153251859997407213e-07" iyz="-1.1864862127350796014e-12" izz="6.2266857050271903441e-07"/>      
    </inertial>    
  </link>  

  <joint name="right_knee_front_rev_1" type="revolute">    
    <origin xyz="-0.0057402514854764941088 -0.013858192987669354368 -0.004999999999999997502" rpy="2.2689194189169072921e-15 -9.1667614776401742833e-15 1.5678717655286389387"/>    
    <parent link="xm430_plate"/>    
    <child link="knee_rod"/>    
    <axis xyz="0 0 1"/>    
    <limit effort="1" velocity="20" lower="-6.283185307179586232" upper="6.283185307179586232"/>    
    <joint_properties friction="0.0"/>    
  </joint>  

  <link name="knee_rod_2">    
    <visual>      
      <origin xyz="0 0 0" rpy="0 -0 0"/>      
      <geometry>        
        <mesh filename="package:///meshes/right_knee_rod_2_visual.stl"/>        
      </geometry>      
      <material name="knee_rod_2_material">        
        <color rgba="0.62051618944235198416 0.78640765248647581664 0.88594253031295022716 1.0"/>        
      </material>      
    </visual>    
    <collision>      
      <origin xyz="0 0 0" rpy="0 -0 0"/>      
      <geometry>        
        <mesh filename="package:///meshes/right_knee_rod_2_collision.stl"/>        
      </geometry>      
    </collision>    
    <inertial>      
      <origin xyz="0.014594550881122903344 -3.9305021097373309819e-05 -0.0015996227373186859035" rpy="0 0 0"/>      
      <mass value="0.0031629468613064179276"/>      
      <inertia ixx="2.5896012056594757434e-08" ixy="3.3016126976555421201e-10" ixz="4.168298478138804972e-10" iyy="6.0153257066243701139e-07" iyz="-1.1225769174126416964e-12" izz="6.226685184411355271e-07"/>      
    </inertial>    
  </link>  

  <joint name="right_knee_back_rev_1" type="revolute">    
    <origin xyz="0.0057402514854763501267 0.013858192987669271101 -0.0050000000000000148492" rpy="-3.1552336572096932e-15 -3.3270436898146921635e-14 1.5677951037379203036"/>    
    <parent link="xm430_plate"/>    
    <child link="knee_rod_2"/>    
    <axis xyz="0 0 1"/>    
    <limit effort="1" velocity="20" lower="-6.283185307179586232" upper="6.283185307179586232"/>    
    <joint_properties friction="0.0"/>    
  </joint>  

  <joint name="right_knee_act" type="revolute">    
    <origin xyz="0.00014999999999998502487 -0.061499999999999561962 -0.030400000000000208106" rpy="-1.3157660724820988502e-14 2.289083756447533756e-16 3.1415926535897464866"/>    
    <parent link="right_hip_pitch_link_xm430"/>    
    <child link="xm430_plate"/>    
    <axis xyz="0 0 1"/>    
    <limit effort="1" velocity="20" lower="-1.9198621771937625091" upper="0"/>    
    <joint_properties friction="0.0"/>    
  </joint>  

  <joint name="right_hip_pitch" type="revolute">    
    <origin xyz="-0.02400000071614311753 -0.019000000152445541829 -0.019000000152453264818" rpy="1.5707963267950966202 1.5707963267947309127 0"/>    
    <parent link="hip_roll_link"/>    
    <child link="right_hip_pitch_link_xm430"/>    
    <axis xyz="0 0 1"/>    
    <limit effort="1" velocity="20" lower="-1.570796326794896558" upper="1.570796326794896558"/>    
    <joint_properties friction="0.0"/>    
  </joint>  

  <joint name="right_hip_roll" type="revolute">    
    <origin xyz="-0.018999999999999968303 3.4814450885713959653e-18 -0.025999999999999967581" rpy="7.693748353958839089e-20 -1.5707963267948961139 0"/>    
    <parent link="hip_yaw_link"/>    
    <child link="hip_roll_link"/>    
    <axis xyz="0 0 1"/>    
    <limit effort="1" velocity="20" lower="-0.785398163397448279" upper="0.785398163397448279"/>    
    <joint_properties friction="0.0"/>    
  </joint>  


</robot>