<?xml version="1.0" ?><robot name="right_leg">  
  <link name="hip_yaw_link">    
    <visual>      
      <origin xyz="0 0 0" rpy="0 -0 0"/>      
      <geometry>        
        <mesh filename="package:///meshes/right_hip_yaw_link_visual.stl"/>        
      </geometry>      
      <material name="hip_yaw_link_material">        
        <color rgba="0.61568627450980395466 0.81176470588235294379 0.92941176470588238168 1.0"/>        
      </material>      
    </visual>    
    <collision>      
      <origin xyz="0 0 0" rpy="0 -0 0"/>      
      <geometry>        
        <mesh filename="package:///meshes/right_hip_yaw_link_collision.stl"/>        
      </geometry>      
    </collision>    
    <inertial>      
      <origin xyz="5.5101789230161922829e-19 9.4009488797797037098e-20 -0.0098390489054830110316" rpy="0 0 0"/>      
      <mass value="0.014999999999999990771"/>      
      <inertia ixx="2.1987528242869480731e-06" ixy="-8.3046343399290497215e-24" ixz="4.3612943327265431314e-52" iyy="6.383060996420640264e-06" iyz="-3.8298115821567070173e-34" izz="6.4350590059080327294e-06"/>      
    </inertial>    
  </link>  

  <link name="hip_roll_link">    
    <visual>      
      <origin xyz="0 0 0" rpy="0 -0 0"/>      
      <geometry>        
        <mesh filename="package:///meshes/right_hip_roll_link_visual.stl"/>        
      </geometry>      
      <material name="hip_roll_link_material">        
        <color rgba="0.51698661238356036218 0.50347815951093466413 0.49050589017722012741 1.0"/>        
      </material>      
    </visual>    
    <collision>      
      <origin xyz="0 0 0" rpy="0 -0 0"/>      
      <geometry>        
        <mesh filename="package:///meshes/right_hip_roll_link_collision.stl"/>        
      </geometry>      
    </collision>    
    <inertial>      
      <origin xyz="-0.011999849582183100272 -0.00049598090794401882876 -0.018504111838595651424" rpy="0 0 0"/>      
      <mass value="0.1069997065911066636"/>      
      <inertia ixx="2.2075996228674991587e-05" ixy="-4.50058018292882081e-08" ixz="-4.5362214342478000824e-08" iyy="2.9866686933523039235e-05" iyz="-5.5606319466522384661e-07" izz="2.9866720157734995072e-05"/>      
    </inertial>    
  </link>  

  <link name="right_hip_pitch_link">    
    <visual>      
      <origin xyz="0 0 0" rpy="0 -0 0"/>      
      <geometry>        
        <mesh filename="package:///meshes/right_hip_pitch_link_visual.stl"/>        
      </geometry>      
      <material name="right_hip_pitch_link_material">        
        <color rgba="0.60761611741666032849 0.79846263680522922002 0.91833701394314359856 1.0"/>        
      </material>      
    </visual>    
    <collision>      
      <origin xyz="0 0 0" rpy="0 -0 0"/>      
      <geometry>        
        <mesh filename="package:///meshes/right_hip_pitch_link_collision.stl"/>        
      </geometry>      
    </collision>    
    <inertial>      
      <origin xyz="8.0773941032231556651e-05 -0.052581417673651403843 -0.011655813262989971058" rpy="0 0 0"/>      
      <mass value="0.12009145853012415106"/>      
      <inertia ixx="9.2247097907494272451e-05" ixy="5.9897190638720253149e-07" ixz="1.239566333530411569e-08" iyy="2.7434742286976261763e-05" iyz="-8.4141503550328761664e-07" izz="9.3303662120062470157e-05"/>      
    </inertial>    
  </link>  

  <link name="right_calf_link">    
    <visual>      
      <origin xyz="0 0 0" rpy="0 -0 0"/>      
      <geometry>        
        <mesh filename="package:///meshes/right_calf_link_visual.stl"/>        
      </geometry>      
      <material name="right_calf_link_material">        
        <color rgba="0.64161931050581799685 0.73230206884914084142 0.73021281586259856322 1.0"/>        
      </material>      
    </visual>    
    <collision>      
      <origin xyz="0 0 0" rpy="0 -0 0"/>      
      <geometry>        
        <mesh filename="package:///meshes/right_calf_link_collision.stl"/>        
      </geometry>      
    </collision>    
    <inertial>      
      <origin xyz="0.0030643812386838991703 0.051918375094622055965 -0.01085927475208015025" rpy="0 0 0"/>      
      <mass value="0.063407494529051477983"/>      
      <inertia ixx="2.8410482789501486137e-05" ixy="-1.7540677336711103632e-06" ixz="3.8446484462633270127e-08" iyy="1.1034151196211163356e-05" iyz="-9.0161138709108048692e-07" izz="3.1472137678069492554e-05"/>      
    </inertial>    
  </link>  

  <link name="ank_pitch_link">    
    <visual>      
      <origin xyz="0 0 0" rpy="0 -0 0"/>      
      <geometry>        
        <mesh filename="package:///meshes/right_ank_pitch_link_visual.stl"/>        
      </geometry>      
      <material name="ank_pitch_link_material">        
        <color rgba="0.63189161126160264814 0.7266866879354088038 0.78356373393969258601 1.0"/>        
      </material>      
    </visual>    
    <collision>      
      <origin xyz="0 0 0" rpy="0 -0 0"/>      
      <geometry>        
        <mesh filename="package:///meshes/right_ank_pitch_link_collision.stl"/>        
      </geometry>      
    </collision>    
    <inertial>      
      <origin xyz="0.00059528282565905440201 -4.026968237856073645e-08 7.7616094775413567145e-08" rpy="0 0 0"/>      
      <mass value="0.0042238381753791614387"/>      
      <inertia ixx="3.9782741364674252612e-07" ixy="-1.6834347683449874045e-13" ixz="2.0919191901307310826e-14" iyy="4.3705254067417497816e-07" iyz="-1.6428822125511820307e-12" izz="8.8858574534599238027e-08"/>      
    </inertial>    
  </link>  

  <link name="ank_roll_link">    
    <visual>      
      <origin xyz="0 0 0" rpy="0 -0 0"/>      
      <geometry>        
        <mesh filename="package:///meshes/right_ank_roll_link_visual.stl"/>        
      </geometry>      
      <material name="ank_roll_link_material">        
        <color rgba="0.61568627450980395466 0.81176470588235294379 0.92941176470588238168 1.0"/>        
      </material>      
    </visual>    
    <collision>      
      <origin xyz="0 0 0" rpy="0 -0 0"/>      
      <geometry>        
        <mesh filename="package:///meshes/right_ank_roll_link_collision.stl"/>        
      </geometry>      
    </collision>    
    <inertial>      
      <origin xyz="-4.9483915195213484015e-08 0.028527110080362932942 0.00033102406006746133401" rpy="0 0 0"/>      
      <mass value="0.016673175342021003681"/>      
      <inertia ixx="1.4264178920929491951e-05" ixy="5.4052969499822033549e-12" ixz="8.4276466932434609379e-11" iyy="1.3727539914375788723e-05" iyz="-1.0838221665159015586e-06" izz="3.2785781319932111571e-06"/>      
    </inertial>    
  </link>  

  <link name="ank_rr_link">    
    <visual>      
      <origin xyz="0 0 0" rpy="0 -0 0"/>      
      <geometry>        
        <mesh filename="package:///meshes/right_ank_rr_link_visual.stl"/>        
      </geometry>      
      <material name="ank_rr_link_material">        
        <color rgba="0.61568627450980395466 0.81176470588235294379 0.92941176470588238168 1.0"/>        
      </material>      
    </visual>    
    <collision>      
      <origin xyz="0 0 0" rpy="0 -0 0"/>      
      <geometry>        
        <mesh filename="package:///meshes/right_ank_rr_link_collision.stl"/>        
      </geometry>      
    </collision>    
    <inertial>      
      <origin xyz="-4.5249610960598952601e-05 -0.0063096429836314582573 2.0068527260713881675e-19" rpy="0 0 0"/>      
      <mass value="0.00044406186452863177783"/>      
      <inertia ixx="9.1077331171855727491e-09" ixy="-7.4152655953211051008e-11" ixz="-1.0879024115017615136e-14" iyy="8.4004339691196240407e-09" iyz="1.7002107092962467306e-32" izz="1.3144828106018414972e-08"/>      
    </inertial>    
  </link>  

  <link name="closing_right_ank_rev_L2_2">    
    <inertial>      
      <origin xyz="0 0 0" rpy="0 0 0"/>      
      <mass value="1e-9"/>      
      <inertia ixx="0" ixy="0" ixz="0" iyy="0" iyz="0" izz="0"/>      
    </inertial>    
  </link>  
  <joint name="closing_right_ank_rev_L2_2_frame" type="fixed">    
    <origin xyz="0 -0.010000000000000064393 0" rpy="3.141592653589793116 -1.570796326794896558 0"/>    
    <parent link="ank_rr_link"/>    
    <child link="closing_right_ank_rev_L2_2"/>    
    <axis xyz="0 0 0"/>    
  </joint>  

  <joint name="right_ank_rev_L1" type="revolute">    
    <origin xyz="0.017999999999999991701 0.016000000000000041966 -0.020600000000000010664" rpy="-4.4094442971808565918e-15 3.8693527039724707646e-15 0.018223085042986159748"/>    
    <parent link="ank_roll_link"/>    
    <child link="ank_rr_link"/>    
    <axis xyz="0 0 1"/>    
    <limit effort="1" velocity="20" lower="-1.570796326794896558" upper="1.570796326794896558"/>    
    <joint_properties friction="0.0"/>    
  </joint>  

  <link name="ank_rr_link_2">    
    <visual>      
      <origin xyz="0 0 0" rpy="0 -0 0"/>      
      <geometry>        
        <mesh filename="package:///meshes/right_ank_rr_link_2_visual.stl"/>        
      </geometry>      
      <material name="ank_rr_link_2_material">        
        <color rgba="0.61568627450980395466 0.81176470588235294379 0.92941176470588238168 1.0"/>        
      </material>      
    </visual>    
    <collision>      
      <origin xyz="0 0 0" rpy="0 -0 0"/>      
      <geometry>        
        <mesh filename="package:///meshes/right_ank_rr_link_2_collision.stl"/>        
      </geometry>      
    </collision>    
    <inertial>      
      <origin xyz="-4.5249610960602428824e-05 0.0063096429836314591247 -2.0068527260726479664e-19" rpy="0 0 0"/>      
      <mass value="0.00044406186452863177783"/>      
      <inertia ixx="9.1077331171855694404e-09" ixy="7.4152655953211051008e-11" ixz="1.087902411501761198e-14" iyy="8.4004339691196273494e-09" iyz="2.7884735617155562318e-32" izz="1.3144828106018414972e-08"/>      
    </inertial>    
  </link>  

  <link name="closing_right_ank_rev_S2_2">    
    <inertial>      
      <origin xyz="0 0 0" rpy="0 0 0"/>      
      <mass value="1e-9"/>      
      <inertia ixx="0" ixy="0" ixz="0" iyy="0" iyz="0" izz="0"/>      
    </inertial>    
  </link>  
  <joint name="closing_right_ank_rev_S2_2_frame" type="fixed">    
    <origin xyz="3.4694469519536141888e-18 0.0099999999999999533706 0" rpy="-2.5631746085143961934e-18 1.570796326794896558 0"/>    
    <parent link="ank_rr_link_2"/>    
    <child link="closing_right_ank_rev_S2_2"/>    
    <axis xyz="0 0 0"/>    
  </joint>  

  <joint name="right_ank_rev_S1" type="revolute">    
    <origin xyz="-0.018000000000000015987 0.016000000000000041966 -0.020600000000000000255" rpy="1.4371364039343547967e-14 2.2835971399963788062e-14 3.115474105082522982"/>    
    <parent link="ank_roll_link"/>    
    <child link="ank_rr_link_2"/>    
    <axis xyz="0 0 1"/>    
    <limit effort="1" velocity="20" lower="-1.570796326794896558" upper="1.570796326794896558"/>    
    <joint_properties friction="0.0"/>    
  </joint>  

  <joint name="right_ank_roll" type="revolute">    
    <origin xyz="0.001499999999999998947 2.7755575615628913511e-17 -4.9873299934333203964e-18" rpy="-3.141592653589793116 -1.5707963267948870101 0"/>    
    <parent link="ank_pitch_link"/>    
    <child link="ank_roll_link"/>    
    <axis xyz="0 0 1"/>    
    <limit effort="1" velocity="20" lower="-0.785398163397448279" upper="0.785398163397448279"/>    
    <joint_properties friction="0.0"/>    
  </joint>  

  <joint name="right_ank_pitch" type="revolute">    
    <origin xyz="3.0227701397881363998e-17 0.10000000000000000555 -0.010799999999999960673" rpy="-9.4739079309987039513e-16 -3.3792726492822699499e-27 3.1415926535897855665"/>    
    <parent link="right_calf_link"/>    
    <child link="ank_pitch_link"/>    
    <axis xyz="0 0 1"/>    
    <limit effort="1" velocity="20" lower="-0.785398163397448279" upper="0.95993108859688125456"/>    
    <joint_properties friction="0.0"/>    
  </joint>  

  <link name="ank_motor_arm">    
    <visual>      
      <origin xyz="0 0 0" rpy="0 -0 0"/>      
      <geometry>        
        <mesh filename="package:///meshes/right_ank_motor_arm_visual.stl"/>        
      </geometry>      
      <material name="ank_motor_arm_material">        
        <color rgba="0.61568627450980395466 0.81176470588235294379 0.92941176470588238168 1.0"/>        
      </material>      
    </visual>    
    <collision>      
      <origin xyz="0 0 0" rpy="0 -0 0"/>      
      <geometry>        
        <mesh filename="package:///meshes/right_ank_motor_arm_collision.stl"/>        
      </geometry>      
    </collision>    
    <inertial>      
      <origin xyz="0.0060871522238996099777 -1.8308909993408390959e-18 0.0014415996041339243158" rpy="0 0 0"/>      
      <mass value="0.00081249023041677498336"/>      
      <inertia ixx="1.258116822607804934e-08" ixy="-2.1432356807951258934e-25" ixz="-3.0436827602313046902e-10" iyy="5.1146616052620583155e-08" iyz="2.0005602337589400784e-27" izz="6.2546224268964395239e-08"/>      
    </inertial>    
  </link>  

  <link name="ball_joint_ball">    
    <visual>      
      <origin xyz="0 0 0" rpy="0 -0 0"/>      
      <geometry>        
        <mesh filename="package:///meshes/right_ball_joint_ball_visual.stl"/>        
      </geometry>      
      <material name="ball_joint_ball_material">        
        <color rgba="0.46677092258406521763 0.53140243424371769176 0.67257126234243258533 1.0"/>        
      </material>      
    </visual>    
    <collision>      
      <origin xyz="0 0 0" rpy="0 -0 0"/>      
      <geometry>        
        <mesh filename="package:///meshes/right_ball_joint_ball_collision.stl"/>        
      </geometry>      
    </collision>    
    <inertial>      
      <origin xyz="-6.6896809081545446615e-19 5.97689178889193649e-18 0.0027461895781546196739" rpy="0 0 0"/>      
      <mass value="0.00010858471987832157455"/>      
      <inertia ixx="6.6064515645817736705e-10" ixy="9.7187098782978794175e-26" ixz="9.1178909240945178245e-26" iyy="6.6066781021719541838e-10" iyz="2.9232164406625283156e-23" izz="4.0240894440645418758e-10"/>      
    </inertial>    
  </link>  

  <link name="ball_joint_container">    
    <visual>      
      <origin xyz="0 0 0" rpy="0 -0 0"/>      
      <geometry>        
        <mesh filename="package:///meshes/right_ball_joint_container_visual.stl"/>        
      </geometry>      
      <material name="ball_joint_container_material">        
        <color rgba="0.61568627450980395466 0.81176470588235294379 0.92941176470588238168 1.0"/>        
      </material>      
    </visual>    
    <collision>      
      <origin xyz="0 0 0" rpy="0 -0 0"/>      
      <geometry>        
        <mesh filename="package:///meshes/right_ball_joint_container_collision.stl"/>        
      </geometry>      
    </collision>    
    <inertial>      
      <origin xyz="-3.8796629846704810741e-18 -0.0027410199203514451494 -1.3308374583805715367e-17" rpy="0 0 0"/>      
      <mass value="0.00012018994143287794086"/>      
      <inertia ixx="3.7034315414442082721e-09" ixy="8.9294659341090581404e-27" ixz="-5.9074981957292945883e-16" iyy="9.0987209906188446842e-10" iyz="4.3431997068468714822e-26" izz="3.0460653612632305448e-09"/>      
    </inertial>    
  </link>  

  <link name="ank_motor_rod_long">    
    <visual>      
      <origin xyz="0 0 0" rpy="0 -0 0"/>      
      <geometry>        
        <mesh filename="package:///meshes/right_ank_motor_rod_long_visual.stl"/>        
      </geometry>      
      <material name="ank_motor_rod_long_material">        
        <color rgba="0.64705882352941179736 0.64705882352941179736 0.64705882352941179736 1.0"/>        
      </material>      
    </visual>    
    <collision>      
      <origin xyz="0 0 0" rpy="0 -0 0"/>      
      <geometry>        
        <mesh filename="package:///meshes/right_ank_motor_rod_long_collision.stl"/>        
      </geometry>      
    </collision>    
    <inertial>      
      <origin xyz="-9.7346416373003674671e-05 1.0182869582321401502e-06 -0.024100608682741296585" rpy="0 0 0"/>      
      <mass value="0.0013712857268636708969"/>      
      <inertia ixx="2.3699073636531186641e-07" ixy="-2.6102107799917087342e-12" ixz="-2.6767215486534995938e-09" iyy="2.3674128656418915843e-07" iyz="2.7996932450539675711e-11" izz="7.1763054928100996059e-09"/>      
    </inertial>    
  </link>  

  <link name="closing_right_ank_rev_L2_1">    
    <inertial>      
      <origin xyz="0 0 0" rpy="0 0 0"/>      
      <mass value="1e-9"/>      
      <inertia ixx="0" ixy="0" ixz="0" iyy="0" iyz="0" izz="0"/>      
    </inertial>    
  </link>  
  <joint name="closing_right_ank_rev_L2_1_frame" type="fixed">    
    <origin xyz="-0.00099994533629822746068 1.0455831645633795191e-05 -0.045999999999999985345" rpy="1.570796326794896558 -2.8188971864374840609e-17 1.5603403046269419541"/>    
    <parent link="ank_motor_rod_long"/>    
    <child link="closing_right_ank_rev_L2_1"/>    
    <axis xyz="0 0 0"/>    
  </joint>  

  <joint name="right_ank_ball_L3" type="revolute">    
    <origin xyz="-1.0408340855860842566e-17 -0.013000000000000011546 1.3877787807814456755e-17" rpy="-1.570796326794896558 0.0061458554436690055953 -4.8644952545361881732e-16"/>    
    <parent link="ball_joint_container"/>    
    <child link="ank_motor_rod_long"/>    
    <axis xyz="0 0 1"/>    
    <limit effort="1" velocity="20" lower="-1.570796326794896558" upper="1.570796326794896558"/>    
    <joint_properties friction="0.0"/>    
  </joint>  

  <joint name="right_ank_ball_L2" type="revolute">    
    <origin xyz="-2.7755575615628913511e-17 1.3877787807814456755e-17 0.0028266588050205147808" rpy="1.5707963267948927832 -1.553090247818769587 -2.4287402208590411845e-15"/>    
    <parent link="ball_joint_ball"/>    
    <child link="ball_joint_container"/>    
    <axis xyz="0 0 1"/>    
    <limit effort="1" velocity="20" lower="-0.785398163397448279" upper="0.785398163397448279"/>    
    <joint_properties friction="0.0"/>    
  </joint>  

  <joint name="right_ank_ball_L1" type="revolute">    
    <origin xyz="0.019999999999999990008 2.7755575615628913511e-17 0.0030000000000000009298" rpy="2.2437352798241120098e-17 -9.3184397210051753059e-16 1.5978601720098710715"/>    
    <parent link="ank_motor_arm"/>    
    <child link="ball_joint_ball"/>    
    <axis xyz="0 0 1"/>    
    <limit effort="1" velocity="20" lower="-1.570796326794896558" upper="1.570796326794896558"/>    
    <joint_properties friction="0.0"/>    
  </joint>  

  <joint name="right_ank_act_1" type="revolute">    
    <origin xyz="0.013499999999996349989 0.044500000000006978418 0.0036000000000021049884" rpy="-3.3664206006817568194e-13 -5.4090387307312932505e-14 0.21173394130150291481"/>    
    <parent link="right_calf_link"/>    
    <child link="ank_motor_arm"/>    
    <axis xyz="0 0 1"/>    
    <limit effort="1" velocity="20" lower="-1.570796326794896558" upper="1.570796326794896558"/>    
    <joint_properties friction="0.0"/>    
  </joint>  

  <link name="ank_motor_arm_2">    
    <visual>      
      <origin xyz="0 0 0" rpy="0 -0 0"/>      
      <geometry>        
        <mesh filename="package:///meshes/right_ank_motor_arm_2_visual.stl"/>        
      </geometry>      
      <material name="ank_motor_arm_2_material">        
        <color rgba="0.61568627450980395466 0.81176470588235294379 0.92941176470588238168 1.0"/>        
      </material>      
    </visual>    
    <collision>      
      <origin xyz="0 0 0" rpy="0 -0 0"/>      
      <geometry>        
        <mesh filename="package:///meshes/right_ank_motor_arm_2_collision.stl"/>        
      </geometry>      
    </collision>    
    <inertial>      
      <origin xyz="0.0060871522238996091103 -1.8465792797780258162e-18 0.0014415996041339243158" rpy="0 0 0"/>      
      <mass value="0.00081249023041677498336"/>      
      <inertia ixx="1.2581168226078046031e-08" ixy="-1.9242439983960606411e-25" ixz="-3.0436827602313041732e-10" iyy="5.114661605262056992e-08" iyz="2.7850017485702962572e-27" izz="6.2546224268964395239e-08"/>      
    </inertial>    
  </link>  

  <link name="ball_joint_ball_2">    
    <visual>      
      <origin xyz="0 0 0" rpy="0 -0 0"/>      
      <geometry>        
        <mesh filename="package:///meshes/right_ball_joint_ball_2_visual.stl"/>        
      </geometry>      
      <material name="ball_joint_ball_2_material">        
        <color rgba="0.46677092258406521763 0.53140243424371769176 0.67257126234243258533 1.0"/>        
      </material>      
    </visual>    
    <collision>      
      <origin xyz="0 0 0" rpy="0 -0 0"/>      
      <geometry>        
        <mesh filename="package:///meshes/right_ball_joint_ball_2_collision.stl"/>        
      </geometry>      
    </collision>    
    <inertial>      
      <origin xyz="-1.2560721515384612684e-17 -1.9941113688424229433e-17 0.0027461895781546214086" rpy="0 0 0"/>      
      <mass value="0.00010858471987832157455"/>      
      <inertia ixx="6.6064515645821076447e-10" ixy="-3.0176264260949983913e-25" ixz="-1.9399159043503863834e-25" iyy="6.6066781021722850561e-10" iyz="2.9219419132250446908e-25" izz="4.0240894440645403248e-10"/>      
    </inertial>    
  </link>  

  <link name="ball_joint_container_2">    
    <visual>      
      <origin xyz="0 0 0" rpy="0 -0 0"/>      
      <geometry>        
        <mesh filename="package:///meshes/right_ball_joint_container_2_visual.stl"/>        
      </geometry>      
      <material name="ball_joint_container_2_material">        
        <color rgba="0.61568627450980395466 0.81176470588235294379 0.92941176470588238168 1.0"/>        
      </material>      
    </visual>    
    <collision>      
      <origin xyz="0 0 0" rpy="0 -0 0"/>      
      <geometry>        
        <mesh filename="package:///meshes/right_ball_joint_container_2_collision.stl"/>        
      </geometry>      
    </collision>    
    <inertial>      
      <origin xyz="-4.0133440651590904688e-19 -0.0027410199203514729049 1.4416500497882479359e-17" rpy="0 0 0"/>      
      <mass value="0.00012018994143287794086"/>      
      <inertia ixx="3.7034315414442082721e-09" ixy="-1.5433838099016139987e-26" ixz="-5.9074981958037127679e-16" iyy="9.0987209906188446842e-10" iyz="8.8209636787008113388e-26" izz="3.0460653612632305448e-09"/>      
    </inertial>    
  </link>  

  <link name="ank_motor_rod_short">    
    <visual>      
      <origin xyz="0 0 0" rpy="0 -0 0"/>      
      <geometry>        
        <mesh filename="package:///meshes/right_ank_motor_rod_short_visual.stl"/>        
      </geometry>      
      <material name="ank_motor_rod_short_material">        
        <color rgba="0.2313725490196078538 0.38039215686274507888 0.70588235294117662733 1.0"/>        
      </material>      
    </visual>    
    <collision>      
      <origin xyz="0 0 0" rpy="0 -0 0"/>      
      <geometry>        
        <mesh filename="package:///meshes/right_ank_motor_rod_short_collision.stl"/>        
      </geometry>      
    </collision>    
    <inertial>      
      <origin xyz="-0.00018125718822256664531 1.8957901221527457458e-06 -0.014161547524153638919" rpy="0 0 0"/>      
      <mass value="0.00073646453671346689789"/>      
      <inertia ixx="4.8268216337600216335e-08" ixy="-2.7267361279487227202e-12" ixz="-1.4004321319276446064e-09" iyy="4.8007565255284155518e-08" iyz="1.4646474015460912981e-11" izz="3.9909990774867184227e-09"/>      
    </inertial>    
  </link>  

  <link name="closing_right_ank_rev_S2_1">    
    <inertial>      
      <origin xyz="0 0 0" rpy="0 0 0"/>      
      <mass value="1e-9"/>      
      <inertia ixx="0" ixy="0" ixz="0" iyy="0" iyz="0" izz="0"/>      
    </inertial>    
  </link>  
  <joint name="closing_right_ank_rev_S2_1_frame" type="fixed">    
    <origin xyz="-0.00099994533629824480792 1.0455831645606039615e-05 -0.026499999999999995781" rpy="1.570796326794896558 -2.3424437680691162737e-17 1.5603403046269499477"/>    
    <parent link="ank_motor_rod_short"/>    
    <child link="closing_right_ank_rev_S2_1"/>    
    <axis xyz="0 0 0"/>    
  </joint>  

  <joint name="right_ank_ball_S3" type="revolute">    
    <origin xyz="0 -0.013000000000000011546 1.3877787807814456755e-17" rpy="1.570796326794896558 -0.019631431462880346434 -3.141592653589793116"/>    
    <parent link="ball_joint_container_2"/>    
    <child link="ank_motor_rod_short"/>    
    <axis xyz="0 0 1"/>    
    <limit effort="1" velocity="20" lower="-1.570796326794896558" upper="1.570796326794896558"/>    
    <joint_properties friction="0.0"/>    
  </joint>  

  <joint name="right_ank_ball_S2" type="revolute">    
    <origin xyz="2.7755575615628913511e-17 0 0.0028266588050205147808" rpy="1.5707963267948981123 1.5463421405919186569 -3.1415926535897615857"/>    
    <parent link="ball_joint_ball_2"/>    
    <child link="ball_joint_container_2"/>    
    <axis xyz="0 0 1"/>    
    <limit effort="1" velocity="20" lower="-0.785398163397448279" upper="0.785398163397448279"/>    
    <joint_properties friction="0.0"/>    
  </joint>  

  <joint name="right_ank_ball_S1" type="revolute">    
    <origin xyz="0.019999999999999892863 -5.5511151231257827021e-17 0.0030000000000001050132" rpy="-4.1932123250748176672e-15 1.0094902775150862849e-14 -1.6998353895880471409"/>    
    <parent link="ank_motor_arm_2"/>    
    <child link="ball_joint_ball_2"/>    
    <axis xyz="0 0 1"/>    
    <limit effort="1" velocity="20" lower="-1.570796326794896558" upper="1.570796326794896558"/>    
    <joint_properties friction="0.0"/>    
  </joint>  

  <joint name="right_ank_act_2" type="revolute">    
    <origin xyz="0.013500000000003451947 0.064500000000007690071 -0.02520000000000061427" rpy="-3.1415926535895501992 -2.0043939315392612859e-13 0.22995607267269219109"/>    
    <parent link="right_calf_link"/>    
    <child link="ank_motor_arm_2"/>    
    <axis xyz="0 0 1"/>    
    <limit effort="1" velocity="20" lower="-1.570796326794896558" upper="1.570796326794896558"/>    
    <joint_properties friction="0.0"/>    
  </joint>  

  <joint name="right_knee" type="revolute">    
    <origin xyz="-7.3809043265734742862e-18 -0.095999999999999960365 -0.0092000000000004647505" rpy="-1.5931011152737801319e-16 2.6628384104697546258e-16 -3.1415926535897873428"/>    
    <parent link="right_hip_pitch_link"/>    
    <child link="right_calf_link"/>    
    <axis xyz="0 0 1"/>    
    <limit effort="1" velocity="20" lower="-1.9198621771937625091" upper="0"/>    
    <joint_properties friction="0.0"/>    
  </joint>  

  <joint name="right_hip_pitch" type="revolute">    
    <origin xyz="-0.024000000716142617929 -0.01900000015244446977 -0.019000000152450562119" rpy="1.5707963267950879604 1.5707963267947180341 0"/>    
    <parent link="hip_roll_link"/>    
    <child link="right_hip_pitch_link"/>    
    <axis xyz="0 0 1"/>    
    <limit effort="1" velocity="20" lower="-1.570796326794896558" upper="1.570796326794896558"/>    
    <joint_properties friction="0.0"/>    
  </joint>  

  <joint name="right_hip_roll" type="revolute">    
    <origin xyz="-0.019000000000000818318 3.4197469684896360212e-16 -0.026000000000000959843" rpy="-2.5681636235613216278e-28 -1.5707963267948938935 0"/>    
    <parent link="hip_yaw_link"/>    
    <child link="hip_roll_link"/>    
    <axis xyz="0 0 1"/>    
    <limit effort="1" velocity="20" lower="-0.785398163397448279" upper="1.570796326794896558"/>    
    <joint_properties friction="0.0"/>    
  </joint>  


</robot>