<?xml version="1.0" ?>
<robot name="toddlerbot">
  <mujoco>
    <compiler strippath="false" balanceinertia="true" discardvisual="false"/>
  </mujoco>
  <link name="torso">
    <visual>
      <origin xyz="0 0 0" rpy="0 -0 0"/>
      <geometry>
        <mesh filename="../assemblies/toddlerbot/meshes/torso_visual.stl"/>
      </geometry>
      <material name="torso_material">
        <color rgba="0.63761324738265878764 0.79140018897832431488 0.89744804913511877498 1.0"/>
      </material>
    </visual>
    <collision name="torso_collision">
      <origin xyz="-0.028500007465481758 -5.000084638595581e-05 0.07068824046291411" rpy="0 0 0"/>
      <geometry>
        <box size="0.14100001379847527 0.13759998977184296 0.1454972173087299"/>
      </geometry>
    </collision>
    <inertial>
      <origin xyz="-0.0045319089141771552731 -0.0033046849194455856467 0.065594108502290693341" rpy="0 0 0"/>
      <mass value="1.1369659631012025702"/>
      <inertia ixx="0.0029825917743578666055" ixy="8.1730614288441110122e-05" ixz="2.1951370741857685305e-05" iyy="0.0023969506399989372152" iyz="-2.9575017351927617657e-05" izz="0.0025126356523908575241"/>
    </inertial>
  </link>
  <link name="spur_1m_20t">
    <visual>
      <origin xyz="0 0 0" rpy="0 -0 0"/>
      <geometry>
        <mesh filename="../assemblies/toddlerbot/meshes/spur_1m_20t_visual.stl"/>
      </geometry>
      <material name="spur_1m_20t_material">
        <color rgba="0.64705882352941179736 0.64705882352941179736 0.64705882352941179736 1.0"/>
      </material>
    </visual>
    <inertial>
      <origin xyz="-2.9273600019542193503e-19 -8.407168954226882874e-18 0.003384232105434467619" rpy="0 0 0"/>
      <mass value="0.0015778025963745997712"/>
      <inertia ixx="4.5874424196602084909e-08" ixy="3.9290914639085633501e-24" ixz="-7.1097175513400442172e-39" iyy="4.5874424196602058439e-08" iyz="7.8419015231486113446e-38" izz="8.1737050837173876176e-08"/>
    </inertial>
  </link>
  <joint name="neck_yaw_drive" type="revolute">
    <origin xyz="-0.0049999999999995221878 3.1860588521011854095e-18 0.12148651076281755112" rpy="1.1607298201443905188e-14 1.6509758832059179101e-15 -5.3832337592600790636e-15"/>
    <parent link="torso"/>
    <child link="spur_1m_20t"/>
    <axis xyz="0 0 1"/>
    <limit effort="1" velocity="20" lower="-2.8797932657906435416" upper="2.8797932657906435416"/>
    <joint_properties friction="0.0"/>
  </joint>
  <link name="neck_yaw_link_v2">
    <visual>
      <origin xyz="0 0 0" rpy="0 -0 0"/>
      <geometry>
        <mesh filename="../assemblies/toddlerbot/meshes/neck_yaw_link_v2_visual.stl"/>
      </geometry>
      <material name="neck_yaw_link_v2_material">
        <color rgba="0.2313725490196078538 0.38039215686274507888 0.70588235294117662733 1.0"/>
      </material>
    </visual>
    <inertial>
      <origin xyz="-1.1403990895369493244e-06 -1.1841855614897924462e-10 0.0082571849701004972066" rpy="0 0 0"/>
      <mass value="0.0067298837334394089049"/>
      <inertia ixx="5.2266067624768086445e-07" ixy="-6.3046403327810586846e-15" ixz="1.1949403084466817268e-09" iyy="6.1218519979556588152e-07" iyz="-2.6012871962819705841e-15" izz="2.8062851709981924551e-07"/>
    </inertial>
  </link>
  <link name="head">
    <visual>
      <origin xyz="0 0 0" rpy="0 -0 0"/>
      <geometry>
        <mesh filename="../assemblies/toddlerbot/meshes/head_visual.stl"/>
      </geometry>
      <material name="head_material">
        <color rgba="0.62873939703496806164 0.79364291305093481732 0.87330110949792516539 1.0"/>
      </material>
    </visual>
    <inertial>
      <origin xyz="-0.045316002313821462932 -0.011276855645191824137 -0.0010251236602530945652" rpy="0 0 0"/>
      <mass value="0.13722101760550831084"/>
      <inertia ixx="0.000118808072940447212" ixy="1.1390016804751208719e-06" ixz="1.8378816154934639505e-06" iyy="0.00010489076115432989294" iyz="-9.2536559812160098181e-06" izz="9.1894624061612158465e-05"/>
    </inertial>
  </link>
  <link name="motor_plate">
    <visual>
      <origin xyz="0 0 0" rpy="0 -0 0"/>
      <geometry>
        <mesh filename="../assemblies/toddlerbot/meshes/motor_plate_visual.stl"/>
      </geometry>
      <material name="motor_plate_material">
        <color rgba="0.64705882352941179736 0.64705882352941179736 0.64705882352941179736 1.0"/>
      </material>
    </visual>
    <inertial>
      <origin xyz="-6.9388939039072283776e-18 -1.3877787807814456755e-17 -0.0028281768943845498818" rpy="0 0 0"/>
      <mass value="0.0017000000000000001221"/>
      <inertia ixx="4.805029073310371698e-08" ixy="1.0773753257370504076e-09" ixz="-3.1068233712543829119e-36" iyy="5.1782428339099010347e-08" iyz="8.7873943139860781386e-38" izz="9.2194729037862249329e-08"/>
    </inertial>
  </link>
  <link name="bearing_683">
    <visual>
      <origin xyz="0 0 0" rpy="0 -0 0"/>
      <geometry>
        <mesh filename="../assemblies/toddlerbot/meshes/bearing_683_visual.stl"/>
      </geometry>
      <material name="bearing_683_material">
        <color rgba="0.64705882352941179736 0.64705882352941179736 0.64705882352941179736 1.0"/>
      </material>
    </visual>
    <inertial>
      <origin xyz="1.3985108750766809383e-17 2.4186774283164997703e-19 -0.0015499999999999995118" rpy="0 0 0"/>
      <mass value="0.00048694686130641793437"/>
      <inertia ixx="2.1551456503319895657e-09" ixy="2.9047882901138312047e-26" ixz="-1.1228933808335255921e-37" iyy="2.1551456503319883249e-09" iyz="-1.3368752562953336429e-37" izz="3.5303647444715322361e-09"/>
    </inertial>
  </link>
  <joint name="neck_pitch_front_rev_2" type="revolute">
    <origin xyz="-0.0019411428382689055461 -0.0072444436971680192111 -0.0055000000000000005482" rpy="1.0718125710358602429e-14 -4.311384292830508141e-15 0.88076594287798393168"/>
    <parent link="motor_plate"/>
    <child link="bearing_683"/>
    <axis xyz="0 0 1"/>
    <limit effort="1" velocity="20" lower="-6.283185307179586232" upper="6.283185307179586232"/>
    <joint_properties friction="0.0"/>
  </joint>
  <link name="bearing_683_2">
    <visual>
      <origin xyz="0 0 0" rpy="0 -0 0"/>
      <geometry>
        <mesh filename="../assemblies/toddlerbot/meshes/bearing_683_2_visual.stl"/>
      </geometry>
      <material name="bearing_683_2_material">
        <color rgba="0.64705882352941179736 0.64705882352941179736 0.64705882352941179736 1.0"/>
      </material>
    </visual>
    <inertial>
      <origin xyz="1.3985108750766830954e-17 2.4186774283160303249e-19 -0.0015499999999999990782" rpy="0 0 0"/>
      <mass value="0.00048694686130641793437"/>
      <inertia ixx="2.1551456503319879113e-09" ixy="-2.1975945182776963045e-25" ixz="-2.7042340431588615727e-39" iyy="2.1551456503319883249e-09" iyz="2.2478231163415180367e-39" izz="3.5303647444715305817e-09"/>
    </inertial>
  </link>
  <joint name="neck_pitch_back_rev_2" type="revolute">
    <origin xyz="0.0019411428382688777905 0.007244443697168007068 -0.0055000000000000014155" rpy="-2.5111971789710972494e-13 -1.8026647498047445117e-13 0.87787101658584032471"/>
    <parent link="motor_plate"/>
    <child link="bearing_683_2"/>
    <axis xyz="0 0 1"/>
    <limit effort="1" velocity="20" lower="-6.283185307179586232" upper="6.283185307179586232"/>
    <joint_properties friction="0.0"/>
  </joint>
  <joint name="neck_pitch_act" type="revolute">
    <origin xyz="-0.032615697718560709983 -0.027000000000000058675 0.0024999999999998486974" rpy="-3.1415926535897655825 -3.1199051560142798919e-13 -3.141592653589449835"/>
    <parent link="head"/>
    <child link="motor_plate"/>
    <axis xyz="0 0 1"/>
    <limit effort="1" velocity="20" lower="-1.3962634015954635824" upper="0.61086523819801530344"/>
    <joint_properties friction="0.0"/>
  </joint>
  <joint name="neck_pitch" type="revolute">
    <origin xyz="-1.1796119636642288242e-16 0.0040000000000001215139 0.019400000000000056088" rpy="-1.5707963267904627713 1.5671692223466835436 -3.1415926535886637971"/>
    <parent link="neck_yaw_link_v2"/>
    <child link="head"/>
    <axis xyz="0 0 1"/>
    <limit effort="1" velocity="20" lower="-1.3962634015954635824" upper="0.61086523819801530344"/>
    <joint_properties friction="0.0"/>
  </joint>
  <link name="neck_rod">
    <visual>
      <origin xyz="0 0 0" rpy="0 -0 0"/>
      <geometry>
        <mesh filename="../assemblies/toddlerbot/meshes/neck_rod_visual.stl"/>
      </geometry>
      <material name="neck_rod_material">
        <color rgba="0.62051618944235187314 0.78640765248647570562 0.88594253031295011613 1.0"/>
      </material>
    </visual>
    <inertial>
      <origin xyz="0.017942953356019489264 -4.2302323070087306963e-05 -0.0016023848482628068844" rpy="0 0 0"/>
      <mass value="0.0031629468613064174939"/>
      <inertia ixx="1.6183187611801101548e-08" ixy="4.3686324090029618003e-10" ixz="5.4098718288322473511e-10" iyy="7.9430220338147421456e-07" iyz="-1.2754318974832872697e-12" izz="8.0573905690508686904e-07"/>
    </inertial>
  </link>
  <joint name="neck_pitch_front_rev_1" type="revolute">
    <origin xyz="-0.0072444436971684355447 -0.0040000000000001197792 0.017458857161731233809" rpy="1.5707963267946454256 -0.88439304732584833602 -3.1415926535894400651"/>
    <parent link="neck_yaw_link_v2"/>
    <child link="neck_rod"/>
    <axis xyz="0 0 1"/>
    <limit effort="1" velocity="20" lower="-6.283185307179586232" upper="6.283185307179586232"/>
    <joint_properties friction="0.0"/>
  </joint>
  <link name="neck_rod_2">
    <visual>
      <origin xyz="0 0 0" rpy="0 -0 0"/>
      <geometry>
        <mesh filename="../assemblies/toddlerbot/meshes/neck_rod_2_visual.stl"/>
      </geometry>
      <material name="neck_rod_2_material">
        <color rgba="0.62051618944235187314 0.78640765248647570562 0.88594253031295011613 1.0"/>
      </material>
    </visual>
    <inertial>
      <origin xyz="0.017901072327984525467 4.2302323074025779774e-05 -0.0016023848482717029801" rpy="0 0 0"/>
      <mass value="0.0031629468613064174939"/>
      <inertia ixx="1.6183187611802534225e-08" ixy="-4.3584354918256844597e-10" ixz="5.3972445329300678928e-10" iyy="7.9343818800628575981e-07" iyz="1.2754318717552505803e-12" izz="8.0487504152986580352e-07"/>
    </inertial>
  </link>
  <joint name="neck_pitch_back_rev_1" type="revolute">
    <origin xyz="0.0072444436971682013571 -0.0040000000000001362591 0.021341142838269100412" rpy="1.5707963267949220931 -0.8814981210337055062 3.1415926535897904515"/>
    <parent link="neck_yaw_link_v2"/>
    <child link="neck_rod_2"/>
    <axis xyz="0 0 1"/>
    <limit effort="1" velocity="20" lower="-6.283185307179586232" upper="6.283185307179586232"/>
    <joint_properties friction="0.0"/>
  </joint>
  <joint name="neck_yaw_driven" type="revolute">
    <origin xyz="0.016000000000000621364 3.9122381713629107253e-19 0.12248651076281739936" rpy="1.5470695466536949876e-14 -3.0902695541116811913e-15 -8.6007558735577539147e-16"/>
    <parent link="torso"/>
    <child link="neck_yaw_link_v2"/>
    <axis xyz="0 0 1"/>
    <limit effort="1" velocity="20" lower="-2.6179938779914944114" upper="2.6179938779914944114"/>
    <joint_properties friction="0.0"/>
  </joint>
  <link name="waist_gears">
    <visual>
      <origin xyz="0 0 0" rpy="0 -0 0"/>
      <geometry>
        <mesh filename="../assemblies/toddlerbot/meshes/waist_gears_visual.stl"/>
      </geometry>
      <material name="waist_gears_material">
        <color rgba="0.29673072126509869584 0.50090014891145351328 0.63316042503557934396 1.0"/>
      </material>
    </visual>
    <inertial>
      <origin xyz="-2.9089024309418600146e-07 5.5035553755051287407e-08 -0.012592985430860502774" rpy="0 0 0"/>
      <mass value="0.026337180140419174518"/>
      <inertia ixx="1.5367047941033374527e-06" ixy="1.8828487088222486339e-11" ixz="4.0600521957845183714e-10" iyy="7.302471227545066429e-06" iyz="3.2911737843456854381e-12" izz="6.9859065635059637868e-06"/>
    </inertial>
  </link>
  <link name="waist_link">
    <visual>
      <origin xyz="0 0 0" rpy="0 -0 0"/>
      <geometry>
        <mesh filename="../assemblies/toddlerbot/meshes/waist_link_visual.stl"/>
      </geometry>
      <material name="waist_link_material">
        <color rgba="0.64205964988973096563 0.77112878115803895618 0.80455743168009152821 1.0"/>
      </material>
    </visual>
    <collision name="waist_link_collision">
      <origin xyz="0.0 -0.021850000135600567 -0.022750000469386578" rpy="0 0 0"/>
      <geometry>
        <box size="0.11999999731779099 0.057499999180436134 0.07000000216066837"/>
      </geometry>
    </collision>
    <inertial>
      <origin xyz="-3.4876747961162537906e-18 -0.024647143936897920186 -0.024243097328499937232" rpy="0 0 0"/>
      <mass value="0.10819999998618363979"/>
      <inertia ixx="4.747970073566886237e-05" ixy="-9.3811587245404559892e-21" ixz="-5.6250747314438818848e-09" iyy="9.6352172992785340951e-05" iyz="1.5514215856083487346e-06" izz="6.7249246473027323736e-05"/>
    </inertial>
  </link>
  <link name="spiral_bevel_1m_14t_30deg">
    <visual>
      <origin xyz="0 0 0" rpy="0 -0 0"/>
      <geometry>
        <mesh filename="../assemblies/toddlerbot/meshes/spiral_bevel_1m_14t_30deg_visual.stl"/>
      </geometry>
      <material name="spiral_bevel_1m_14t_30deg_material">
        <color rgba="0.64705882352941179736 0.64705882352941179736 0.64705882352941179736 1.0"/>
      </material>
    </visual>
    <inertial>
      <origin xyz="7.4971447279470481499e-10 7.1802237593121532518e-10 0.006686895501897913846" rpy="0 0 0"/>
      <mass value="0.00073261524436595492574"/>
      <inertia ixx="1.3495056019478195011e-08" ixy="4.0596682073457136067e-17" ixz="8.5992550143797901999e-16" iyy="1.3495056150237195634e-08" iyz="-6.791300821815703182e-16" izz="1.4355986549816401791e-08"/>
    </inertial>
  </link>
  <joint name="waist_act_1" type="revolute">
    <origin xyz="-1.0950768566580540919e-18 -0.019600000000000002837 -0.012749999999999995712" rpy="1.570796326794896558 1.1603771602431690682e-14 -3.1415926535897926719"/>
    <parent link="waist_link"/>
    <child link="spiral_bevel_1m_14t_30deg"/>
    <axis xyz="0 0 1"/>
    <limit effort="1" velocity="20" lower="-4.6774823953448034786" upper="4.6774823953448034786"/>
    <joint_properties friction="0.0"/>
  </joint>
  <link name="spiral_bevel_1m_14t_30deg_2">
    <visual>
      <origin xyz="0 0 0" rpy="0 -0 0"/>
      <geometry>
        <mesh filename="../assemblies/toddlerbot/meshes/spiral_bevel_1m_14t_30deg_2_visual.stl"/>
      </geometry>
      <material name="spiral_bevel_1m_14t_30deg_2_material">
        <color rgba="0.64705882352941179736 0.64705882352941179736 0.64705882352941179736 1.0"/>
      </material>
    </visual>
    <inertial>
      <origin xyz="3.6393117165689492509e-10 -9.7220472384390577147e-10 -0.0066868955018979155808" rpy="0 0 0"/>
      <mass value="0.00073261524436595492574"/>
      <inertia ixx="1.3495056012354480834e-08" ixy="2.5804135905735602914e-17" ixz="-1.069429604882048706e-15" iyy="1.3495056157360909811e-08" iyz="-2.3876736936216327369e-16" izz="1.43559865498164051e-08"/>
    </inertial>
  </link>
  <joint name="waist_act_2" type="revolute">
    <origin xyz="1.3488415323837299524e-18 -0.019599999999999995898 -0.032750000000000001332" rpy="-1.570796326794896558 2.1438338568776302255e-14 -3.141592653589793116"/>
    <parent link="waist_link"/>
    <child link="spiral_bevel_1m_14t_30deg_2"/>
    <axis xyz="0 0 1"/>
    <limit effort="1" velocity="20" lower="-4.6774823953448034786" upper="4.6774823953448034786"/>
    <joint_properties friction="0.0"/>
  </joint>
  <joint name="left_hip_pitch" type="revolute">
    <origin xyz="0.056000000000000015044 -0.040099999999999996758 -0.022750000000000002859" rpy="-1.570796326794896558 -1.2750103475622600987e-14 1.5707963267948956698"/>
    <parent link="waist_link"/>
    <child link="2xc430"/>
    <axis xyz="0 0 1"/>
    <limit effort="1" velocity="20" lower="-1.570796326794896558" upper="2.356194490192344837"/>
    <joint_properties friction="0.0"/>
  </joint>
  <joint name="right_hip_pitch" type="revolute">
    <origin xyz="-0.056000000000000008105 -0.040100000000000010636 -0.022750000000000002859" rpy="1.570796326794896558 -4.6471944491513544759e-14 1.570796326794871689"/>
    <parent link="waist_link"/>
    <child link="2xc430_2"/>
    <axis xyz="0 0 1"/>
    <limit effort="1" velocity="20" lower="-2.356194490192344837" upper="1.570796326794896558"/>
    <joint_properties friction="0.0"/>
  </joint>
  <joint name="waist_roll" type="revolute">
    <origin xyz="-0.022707865260689970299 5.0992894772045551448e-17 -0.013999999999999354974" rpy="1.5707963267948972241 -1.2860661478503099299e-14 -1.570796326794896558"/>
    <parent link="waist_gears"/>
    <child link="waist_link"/>
    <axis xyz="0 0 1"/>
    <limit effort="1" velocity="20" lower="-0.52359877559829881566" upper="0.52359877559829881566"/>
    <joint_properties friction="0.0"/>
  </joint>
  <joint name="waist_yaw" type="revolute">
    <origin xyz="0 -5.3903211409646476972e-18 3.4694469519597032089e-18" rpy="-8.7262726250677497581e-16 -3.9724428353914665044e-15 -3.1415926535897766847"/>
    <parent link="torso"/>
    <child link="waist_gears"/>
    <axis xyz="0 0 1"/>
    <limit effort="1" velocity="20" lower="-1.570796326794896558" upper="1.570796326794896558"/>
    <joint_properties friction="0.0"/>
  </joint>
  <joint name="left_sho_pitch" type="revolute">
    <origin xyz="-0.0035000000000004437284 0.067000000000001058709 0.104236510762817286" rpy="-1.5707963267949092145 -4.1522341120980961897e-14 3.464089692039239269e-14"/>
    <parent link="torso"/>
    <child link="sho_pitch_link"/>
    <axis xyz="0 0 1"/>
    <limit effort="1" velocity="20" lower="-3.141592653589793116" upper="1.570796326794896558"/>
    <joint_properties friction="0.0"/>
  </joint>
  <joint name="right_sho_pitch" type="revolute">
    <origin xyz="-0.0034999999999986777799 -0.067000000000001072586 0.10423651076281732764" rpy="-1.5707963267948872321 3.624878175401132949e-14 -3.1415926535897562566"/>
    <parent link="torso"/>
    <child link="sho_pitch_link_2"/>
    <axis xyz="0 0 1"/>
    <limit effort="1" velocity="20" lower="-1.570796326794896558" upper="3.141592653589793116"/>
    <joint_properties friction="0.0"/>
  </joint>
  <link name="2xc430">
    <visual>
      <origin xyz="0 0 0" rpy="0 -0 0"/>
      <geometry>
        <mesh filename="../assemblies/left_leg_reorder/meshes/left_2xc430_visual.stl"/>
      </geometry>
      <material name="2xc430_material">
        <color rgba="0.51698661238356047321 0.50347815951093488618 0.49050589017722012741 1.0"/>
      </material>
    </visual>
    <inertial>
      <origin xyz="-0.012000151133967865147 0.00049588831386336226781 0.018504019244503618763" rpy="0 0 0"/>
      <mass value="0.11059999999836234164"/>
      <inertia ixx="2.2818802599021433919e-05" ixy="4.6888548259072258494e-08" ixz="4.6520143289445516196e-08" iyy="3.0871666424472358657e-05" iyz="-5.7477343899722563502e-07" izz="3.0871632082341921239e-05"/>
    </inertial>
  </link>
  <link name="hip_yaw_link">
    <visual>
      <origin xyz="0 0 0" rpy="0 -0 0"/>
      <geometry>
        <mesh filename="../assemblies/left_leg_reorder/meshes/left_hip_yaw_link_visual.stl"/>
      </geometry>
      <material name="hip_yaw_link_material">
        <color rgba="0.61568627450980395466 0.81176470588235283277 0.92941176470588238168 1.0"/>
      </material>
    </visual>
    <inertial>
      <origin xyz="-2.6529777091804280315e-18 -0.015800610849654266737 -0.019005670096647751116" rpy="0 0 0"/>
      <mass value="0.013199999999999994724"/>
      <inertia ixx="5.7894615975174157252e-06" ixy="-4.5096954887673693913e-35" ixz="-4.6860781276867837534e-35" iyy="5.0110144042848759377e-06" iyz="1.1826010760651800808e-09" izz="2.7344876354814335894e-06"/>
    </inertial>
  </link>
  <link name="spur_gear_21_teeth">
    <visual>
      <origin xyz="0 0 0" rpy="0 -0 0"/>
      <geometry>
        <mesh filename="../assemblies/left_leg_reorder/meshes/left_spur_gear_21_teeth_visual.stl"/>
      </geometry>
      <material name="spur_gear_21_teeth_material">
        <color rgba="0.61568627450980395466 0.81176470588235294379 0.9294117647058824927 1.0"/>
      </material>
    </visual>
    <inertial>
      <origin xyz="-4.5505289275732625397e-11 -1.6782160465261941845e-11 -0.00249241020062506086" rpy="0 0 0"/>
      <mass value="0.0022000000000000001325"/>
      <inertia ixx="7.0162310059594196881e-08" ixy="3.8801235249534522434e-48" ixz="2.812550158047784253e-36" iyy="7.016231005804746178e-08" iyz="3.6086829965958625889e-39" izz="1.3125544198538289306e-07"/>
    </inertial>
  </link>
  <link name="left_hip_pitch_link">
    <visual>
      <origin xyz="0 0 0" rpy="0 -0 0"/>
      <geometry>
        <mesh filename="../assemblies/left_leg_reorder/meshes/left_hip_pitch_link_visual.stl"/>
      </geometry>
      <material name="left_hip_pitch_link_material">
        <color rgba="0.79618318075804139777 0.72120748766550990538 0.38540937988910844991 1.0"/>
      </material>
    </visual>
    <collision name="left_hip_pitch_link_collision">
      <origin xyz="-0.005587761566049377 -0.004971450462434381 0.05247500166296959" rpy="0.0 0.0 0.0"/>
      <geometry>
        <capsule radius="0.035842919429443516" length="0.033264164467052146"/>
      </geometry>
    </collision>
    <inertial>
      <origin xyz="-0.0092773123251564133113 -0.0054583150498874076148 0.03951473811674113823" rpy="0 0 0"/>
      <mass value="0.15848965119785962674"/>
      <inertia ixx="8.2188788742760970928e-05" ixy="-1.3373705321924678437e-06" ixz="-9.0917451363903152822e-06" iyy="9.9396334685477745453e-05" iyz="1.298937899441436632e-06" izz="4.5892431466748451869e-05"/>
    </inertial>
  </link>
  <link name="spur_gear_18_teeth">
    <visual>
      <origin xyz="0 0 0" rpy="0 -0 0"/>
      <geometry>
        <mesh filename="../assemblies/left_leg_reorder/meshes/left_spur_gear_18_teeth_visual.stl"/>
      </geometry>
      <material name="spur_gear_18_teeth_material">
        <color rgba="0.61568627450980395466 0.81176470588235294379 0.92941176470588238168 1.0"/>
      </material>
    </visual>
    <inertial>
      <origin xyz="-7.7520300317166844125e-14 -3.6849386393036389205e-13 0.0017500000000010135486" rpy="0 0 0"/>
      <mass value="0.0011999999999999998949"/>
      <inertia ixx="2.9367899810799911435e-08" ixy="7.02382161729363821e-19" ixz="-3.9642189780159722141e-36" iyy="2.9367899814659476616e-08" iyz="7.4779432983140607212e-37" izz="5.6306346207859568346e-08"/>
    </inertial>
  </link>
  <joint name="left_hip_yaw_drive" type="revolute">
    <origin xyz="-0.019199999999993125344 0.00020000000000295475866 -3.3514857555871913064e-14" rpy="-3.1415926535896550043 -5.0131548558082056583e-13 4.8264233360682142308e-13"/>
    <parent link="left_hip_pitch_link"/>
    <child link="spur_gear_18_teeth"/>
    <axis xyz="0 0 1"/>
    <limit effort="1" velocity="20" lower="-1.8325957145940461324" upper="1.8325957145940461324"/>
    <joint_properties friction="0.0"/>
  </joint>
  <link name="left_calf_link">
    <visual>
      <origin xyz="0 0 0" rpy="0 -0 0"/>
      <geometry>
        <mesh filename="../assemblies/left_leg_reorder/meshes/left_calf_link_visual.stl"/>
      </geometry>
      <material name="left_calf_link_material">
        <color rgba="0.61568627450980395466 0.81176470588235283277 0.92941176470588238168 1.0"/>
      </material>
    </visual>
    <inertial>
      <origin xyz="-0.0043450054391248908378 0.040752982165250292712 0.0087116093515538506331" rpy="0 0 0"/>
      <mass value="0.030999999999999996309"/>
      <inertia ixx="3.3069388685110848712e-05" ixy="-1.3783307153200011406e-06" ixz="-1.2742534026335853803e-07" iyy="7.7316525337312940424e-06" iyz="-7.3356500593809455715e-08" izz="2.8031377753986189355e-05"/>
    </inertial>
  </link>
  <link name="bearing_683_3">
    <visual>
      <origin xyz="0 0 0" rpy="0 -0 0"/>
      <geometry>
        <mesh filename="../assemblies/left_leg_reorder/meshes/left_bearing_683_visual.stl"/>
      </geometry>
      <material name="bearing_683_material">
        <color rgba="0.64705882352941179736 0.64705882352941179736 0.64705882352941179736 1.0"/>
      </material>
    </visual>
    <inertial>
      <origin xyz="2.7862896558581284628e-17 -2.4186774283159373987e-19 -0.0015499999999999934403" rpy="0 0 0"/>
      <mass value="0.00048694686130641793437"/>
      <inertia ixx="2.1551456503319887385e-09" ixy="1.1914621380619801841e-28" ixz="1.5101308346925888839e-38" iyy="2.1551456503319891521e-09" iyz="1.9510753379696893624e-38" izz="3.5303647444715305817e-09"/>
    </inertial>
  </link>
  <joint name="left_knee_front_rev_2" type="revolute">
    <origin xyz="-0.0057402514854759043028 -0.013858192987668382923 0.026199999999997631434" rpy="-3.141592653589793116 5.8119982868751027369e-16 -1.5702375052298918057"/>
    <parent link="left_calf_link"/>
    <child link="bearing_683_3"/>
    <axis xyz="0 0 1"/>
    <limit effort="1" velocity="20"/>
    <joint_properties friction="0.0"/>
  </joint>
  <link name="bearing_683_4">
    <visual>
      <origin xyz="0 0 0" rpy="0 -0 0"/>
      <geometry>
        <mesh filename="../assemblies/left_leg_reorder/meshes/left_bearing_683_2_visual.stl"/>
      </geometry>
      <material name="bearing_683_2_material">
        <color rgba="0.64705882352941179736 0.64705882352941179736 0.64705882352941179736 1.0"/>
      </material>
    </visual>
    <inertial>
      <origin xyz="-2.7648254672676526986e-17 -2.4186774283159783248e-19 -0.0015500000000000003792" rpy="0 0 0"/>
      <mass value="0.00048694686130641793437"/>
      <inertia ixx="2.1551456503319887385e-09" ixy="-7.8866825289820444564e-28" ixz="-2.3651432074089930782e-38" iyy="2.1551456503319883249e-09" iyz="-6.4744944073117677257e-39" izz="3.5303647444715305817e-09"/>
    </inertial>
  </link>
  <joint name="left_knee_back_rev_2" type="revolute">
    <origin xyz="0.005740251485475959814 0.013858192987669604168 0.026199999999998637573" rpy="3.141592653589793116 1.5424497757392420363e-15 -1.5720025997049917876"/>
    <parent link="left_calf_link"/>
    <child link="bearing_683_4"/>
    <axis xyz="0 0 1"/>
    <limit effort="1" velocity="20"/>
    <joint_properties friction="0.0"/>
  </joint>
  <link name="left_ank_pitch_link">
    <visual>
      <origin xyz="0 0 0" rpy="0 -0 0"/>
      <geometry>
        <mesh filename="../assemblies/left_leg_reorder/meshes/left_ank_pitch_link_visual.stl"/>
      </geometry>
      <material name="left_ank_pitch_link_material">
        <color rgba="0.70321688500203327621 0.64514870846184446673 0.40484735422826279017 1.0"/>
      </material>
    </visual>
    <collision name="left_ank_pitch_link_collision">
      <origin xyz="0.01934999879449606 0.012000000104308128 0.016799999633803964" rpy="0 0 0"/>
      <geometry>
        <box size="0.084799999371171 0.04650000110268593 0.046639998117461806"/>
      </geometry>
    </collision>
    <inertial>
      <origin xyz="0.01777024189140121585 0.012301334508572171061 0.018813528244421770519" rpy="0 0 0"/>
      <mass value="0.17676376695067899658"/>
      <inertia ixx="4.7283316680251603133e-05" ixy="-1.3380598598440868841e-06" ixz="-5.5304058905135221963e-07" iyy="0.00010706456048089208876" iyz="-5.3225137839476522468e-08" izz="0.00012185522397136354139"/>
    </inertial>
  </link>
  <link name="ank_roll_link">
    <visual>
      <origin xyz="0 0 0" rpy="0 -0 0"/>
      <geometry>
        <mesh filename="../assemblies/left_leg_reorder/meshes/left_ank_roll_link_visual.stl"/>
      </geometry>
      <material name="ank_roll_link_material">
        <color rgba="0.61568627450980395466 0.81176470588235294379 0.92941176470588238168 1.0"/>
      </material>
    </visual>
    <collision name="ank_roll_link_collision">
      <origin xyz="-0.014500000514090061 0.0 0.038999998942017555" rpy="0 0 0"/>
      <geometry>
        <box size="0.04900000058114529 0.041999999433755875 0.12000000104308128"/>
      </geometry>
    </collision>
    <inertial>
      <origin xyz="-0.027003066516822105125 -2.005727129968961316e-12 0.033764011359896435593" rpy="0 0 0"/>
      <mass value="0.042599999999999998979"/>
      <inertia ixx="3.7284397827464328061e-05" ixy="-5.5173297572831528906e-16" ixz="2.3929183768080734033e-06" iyy="3.7589276943350436312e-05" iyz="5.093485532365750308e-12" izz="1.0090430906786797971e-05"/>
    </inertial>
  </link>
  <joint name="left_ank_roll" type="revolute">
    <origin xyz="0.022749999999985347915 -7.7438055967604668695e-15 0.019000000000000561579" rpy="-1.5707963267949487385 6.9598897929083939361e-14 1.5707963267951468023"/>
    <parent link="left_ank_pitch_link"/>
    <child link="ank_roll_link"/>
    <axis xyz="0 0 1"/>
    <limit effort="1" velocity="20" lower="-1.570796326794896558" upper="1.570796326794896558"/>
    <joint_properties friction="0.0"/>
  </joint>
  <joint name="left_ank_pitch" type="revolute">
    <origin xyz="-1.5860271119798389095e-15 0.099999999999998423483 0.027750000000001679573" rpy="-3.141592653589793116 2.6670249114811232296e-16 -3.8252904387067536217e-14"/>
    <parent link="left_calf_link"/>
    <child link="left_ank_pitch_link"/>
    <axis xyz="0 0 1"/>
    <limit effort="1" velocity="20" lower="-1.7453292519943295336" upper="0.785398163397448279"/>
    <joint_properties friction="0.0"/>
  </joint>
  <joint name="left_knee" type="revolute">
    <origin xyz="-9.150119726040088374e-16 -0.0087499999999997267464 0.085949999999997653277" rpy="1.5707963267948872321 4.8975632202997979707e-15 3.141592653589793116"/>
    <parent link="left_hip_pitch_link"/>
    <child link="left_calf_link"/>
    <axis xyz="0 0 1"/>
    <limit effort="1" velocity="20" lower="-2.0943951023931952626" upper="0"/>
    <joint_properties friction="0.0"/>
  </joint>
  <link name="xm430_plate">
    <visual>
      <origin xyz="0 0 0" rpy="0 -0 0"/>
      <geometry>
        <mesh filename="../assemblies/left_leg_reorder/meshes/left_xm430_plate_visual.stl"/>
      </geometry>
      <material name="xm430_plate_material">
        <color rgba="0.61568627450980395466 0.81176470588235294379 0.92941176470588227065 1.0"/>
      </material>
    </visual>
    <inertial>
      <origin xyz="1.2574180636021760909e-18 -2.454297176641402282e-18 0.002527851391958388285" rpy="0 0 0"/>
      <mass value="0.0027000000000000001429"/>
      <inertia ixx="1.2887178787151829982e-07" ixy="5.873956255630364624e-08" ixz="1.8999776467072272227e-37" iyy="2.4635091298412544671e-07" iyz="3.1227251026058173467e-36" izz="3.6467998413810321832e-07"/>
    </inertial>
  </link>
  <link name="knee_rod">
    <visual>
      <origin xyz="0 0 0" rpy="0 -0 0"/>
      <geometry>
        <mesh filename="../assemblies/left_leg_reorder/meshes/left_knee_rod_visual.stl"/>
      </geometry>
      <material name="knee_rod_material">
        <color rgba="0.62051618944235198416 0.78640765248647581664 0.88594253031295022716 1.0"/>
      </material>
    </visual>
    <inertial>
      <origin xyz="0.017534307439465060541 1.9597103348831170378e-05 -0.0015987301647619339435" rpy="0 0 0"/>
      <mass value="0.0031629468613064179276"/>
      <inertia ixx="2.4224450180623724587e-08" ixy="-1.9777338984408308296e-10" ixz="4.9178338762830809582e-10" iyy="8.1758888028360200094e-07" iyz="5.4963846751764537446e-13" izz="8.3704884992894945209e-07"/>
    </inertial>
  </link>
  <joint name="left_knee_front_rev_1" type="revolute">
    <origin xyz="0.013858192987669312735 -0.0057402514854763440552 0.004999999999999997502" rpy="-3.1415926535897784611 -7.4622057945515895608e-15 -3.1410338320247936927"/>
    <parent link="xm430_plate"/>
    <child link="knee_rod"/>
    <axis xyz="0 0 1"/>
    <limit effort="1" velocity="20"/>
    <joint_properties friction="0.0"/>
  </joint>
  <link name="knee_rod_2">
    <visual>
      <origin xyz="0 0 0" rpy="0 -0 0"/>
      <geometry>
        <mesh filename="../assemblies/left_leg_reorder/meshes/left_knee_rod_2_visual.stl"/>
      </geometry>
      <material name="knee_rod_2_material">
        <color rgba="0.62051618944235198416 0.78640765248647581664 0.88594253031295022716 1.0"/>
      </material>
    </visual>
    <inertial>
      <origin xyz="0.017534287401029989562 -4.2302323075187753124e-05 -0.0015987301647627436257" rpy="0 0 0"/>
      <mass value="0.0031629468613064179276"/>
      <inertia ixx="2.4225259089666954163e-08" ixy="4.2691331074777808525e-10" ixz="4.9178282561869325727e-10" iyy="8.1758847582921511072e-07" iyz="-1.1864500396169323768e-12" izz="8.370492543836071811e-07"/>
    </inertial>
  </link>
  <joint name="left_knee_back_rev_1" type="revolute">
    <origin xyz="-0.013858192987669298857 0.0057402514854763457899 0.0050000000000000044409" rpy="-3.1415926535897775729 -9.0463447639716938948e-15 3.1403863806796916691"/>
    <parent link="xm430_plate"/>
    <child link="knee_rod_2"/>
    <axis xyz="0 0 1"/>
    <limit effort="1" velocity="20"/>
    <joint_properties friction="0.0"/>
  </joint>
  <joint name="left_knee_act" type="revolute">
    <origin xyz="-7.4872906434390518473e-16 0.012449999999999808442 0.044499999999998832156" rpy="-1.5707963267948819031 1.5707963267948761299 0"/>
    <parent link="left_hip_pitch_link"/>
    <child link="xm430_plate"/>
    <axis xyz="0 0 1"/>
    <limit effort="1" velocity="20" lower="-2.0943951023931952626" upper="0"/>
    <joint_properties friction="0.0"/>
  </joint>
  <joint name="left_hip_yaw_driven" type="revolute">
    <origin xyz="6.1229146868660582384e-18 3.4694469519536141888e-18 -0.0050000000000000044409" rpy="3.1415926535897837901 1.1763977000879646623e-14 2.7749339408464486521e-29"/>
    <parent link="spur_gear_21_teeth"/>
    <child link="left_hip_pitch_link"/>
    <axis xyz="0 0 1"/>
    <limit effort="1" velocity="20" lower="-1.570796326794896558" upper="1.570796326794896558"/>
    <joint_properties friction="0.0"/>
  </joint>
  <joint name="left_hip_yaw_fixed" type="fixed">
    <origin xyz="-3.4694469519536141888e-18 -0.027999999999999986705 -0.018999999999999999528" rpy="-1.5707963267948950037 1.570796326794896336 0"/>
    <parent link="hip_yaw_link"/>
    <child link="spur_gear_21_teeth"/>
    <axis xyz="0 0 1"/>
    <limit effort="1" velocity="20"/>
    <joint_properties friction="0.0"/>
  </joint>
  <joint name="left_hip_roll" type="revolute">
    <origin xyz="-0.024000000716154074043 0.019000000152474230686 0.019000000152447748397" rpy="-1.5707963267952167463 -1.5707963267948206187 0"/>
    <parent link="2xc430"/>
    <child link="hip_yaw_link"/>
    <axis xyz="0 0 1"/>
    <limit effort="1" velocity="20" lower="-0.785398163397448279" upper="0.785398163397448279"/>
    <joint_properties friction="0.0"/>
  </joint>
  <link name="2xc430_2">
    <visual>
      <origin xyz="0 0 0" rpy="0 -0 0"/>
      <geometry>
        <mesh filename="../assemblies/right_leg_reorder/meshes/right_2xc430_visual.stl"/>
      </geometry>
      <material name="2xc430_material">
        <color rgba="0.51698661238356047321 0.50347815951093488618 0.49050589017722012741 1.0"/>
      </material>
    </visual>
    <inertial>
      <origin xyz="-0.012000151133958554886 0.00049588831385534079804 0.018504019244502921404" rpy="0 0 0"/>
      <mass value="0.11059999999836234164"/>
      <inertia ixx="2.2818802599017778125e-05" ixy="4.6888548258171730122e-08" ixz="4.6520143290256497303e-08" iyy="3.0871666424468414871e-05" iyz="-5.747734389970726397e-07" izz="3.087163208233809265e-05"/>
    </inertial>
  </link>
  <link name="hip_yaw_link_2">
    <visual>
      <origin xyz="0 0 0" rpy="0 -0 0"/>
      <geometry>
        <mesh filename="../assemblies/right_leg_reorder/meshes/right_hip_yaw_link_visual.stl"/>
      </geometry>
      <material name="hip_yaw_link_material">
        <color rgba="0.61568627450980395466 0.81176470588235283277 0.92941176470588238168 1.0"/>
      </material>
    </visual>
    <inertial>
      <origin xyz="-2.6529777091803952907e-18 -0.015800610849654270207 -0.019005670096647747647" rpy="0 0 0"/>
      <mass value="0.013199999999999994724"/>
      <inertia ixx="5.789461597517412337e-06" ixy="-3.2907588574144851931e-36" ixz="3.2286603810593676882e-35" iyy="5.0110144042848759377e-06" iyz="1.1826010760651800808e-09" izz="2.7344876354814335894e-06"/>
    </inertial>
  </link>
  <link name="spur_gear_21_teeth_2">
    <visual>
      <origin xyz="0 0 0" rpy="0 -0 0"/>
      <geometry>
        <mesh filename="../assemblies/right_leg_reorder/meshes/right_spur_gear_21_teeth_visual.stl"/>
      </geometry>
      <material name="spur_gear_21_teeth_material">
        <color rgba="0.61568627450980395466 0.81176470588235294379 0.9294117647058824927 1.0"/>
      </material>
    </visual>
    <inertial>
      <origin xyz="-4.5505289275732651246e-11 -1.6782167404155845752e-11 -0.00249241020062506086" rpy="0 0 0"/>
      <mass value="0.0022000000000000001325"/>
      <inertia ixx="7.0162310059594196881e-08" ixy="-5.4656449640042247183e-37" ixz="-4.3150666450744828066e-37" iyy="7.016231005804746178e-08" iyz="-6.9066436847920049312e-38" izz="1.3125544198538289306e-07"/>
    </inertial>
  </link>
  <link name="right_hip_pitch_link">
    <visual>
      <origin xyz="0 0 0" rpy="0 -0 0"/>
      <geometry>
        <mesh filename="../assemblies/right_leg_reorder/meshes/right_hip_pitch_link_visual.stl"/>
      </geometry>
      <material name="right_hip_pitch_link_material">
        <color rgba="0.81231119922470307326 0.71311588921073154612 0.33680089849959454762 1.0"/>
      </material>
    </visual>
    <collision name="right_hip_pitch_link_collision">
      <origin xyz="0.005910505318120873 -0.004269846160677242 0.05247500166296959" rpy="0.0 0.0 0.0"/>
      <geometry>
        <capsule radius="0.035830009896664204" length="0.03328998353261077"/>
      </geometry>
    </collision>
    <inertial>
      <origin xyz="0.010187905578010728394 -0.0056188467228508410731 0.038815928333491442337" rpy="0 0 0"/>
      <mass value="0.14548965119785950417"/>
      <inertia ixx="7.0942049594865431734e-05" ixy="1.1158758975156953663e-06" ixz="7.6515558781281230204e-06" iyy="8.5157398802913230511e-05" iyz="1.0699337399089805e-06" izz="4.0945306935231512132e-05"/>
    </inertial>
  </link>
  <link name="spur_gear_18_teeth_2">
    <visual>
      <origin xyz="0 0 0" rpy="0 -0 0"/>
      <geometry>
        <mesh filename="../assemblies/right_leg_reorder/meshes/right_spur_gear_18_teeth_visual.stl"/>
      </geometry>
      <material name="spur_gear_18_teeth_material">
        <color rgba="0.61568627450980395466 0.81176470588235294379 0.92941176470588238168 1.0"/>
      </material>
    </visual>
    <inertial>
      <origin xyz="-1.2350888076970198418e-14 -3.7635627055517647656e-13 0.0017500000000010135486" rpy="0 0 0"/>
      <mass value="0.0011999999999999998949"/>
      <inertia ixx="2.9367899810676062645e-08" ixy="-5.8641944654482965406e-38" ixz="5.3255683241419689376e-37" iyy="2.9367899814783318789e-08" iyz="1.3183913269072010735e-38" izz="5.6306346207859568346e-08"/>
    </inertial>
  </link>
  <joint name="right_hip_yaw_drive" type="revolute">
    <origin xyz="0.019199999999999432798 0.00020000000000077594597 -3.9572511933982923438e-14" rpy="-3.1415926535897544802 -2.6855722846812135811e-13 4.4780845698253311116e-13"/>
    <parent link="right_hip_pitch_link"/>
    <child link="spur_gear_18_teeth_2"/>
    <axis xyz="0 0 1"/>
    <limit effort="1" velocity="20" lower="-1.8325957145940461324" upper="1.8325957145940461324"/>
    <joint_properties friction="0.0"/>
  </joint>
  <link name="right_calf_link">
    <visual>
      <origin xyz="0 0 0" rpy="0 -0 0"/>
      <geometry>
        <mesh filename="../assemblies/right_leg_reorder/meshes/right_calf_link_visual.stl"/>
      </geometry>
      <material name="right_calf_link_material">
        <color rgba="0.61568627450980395466 0.81176470588235294379 0.9294117647058824927 1.0"/>
      </material>
    </visual>
    <inertial>
      <origin xyz="-0.0043450054394401473393 -0.040752982164757464711 0.0087116093514751895971" rpy="0 0 0"/>
      <mass value="0.030999999999999992839"/>
      <inertia ixx="3.306938868543694962e-05" ixy="1.3783307152005447193e-06" ixz="-1.274253401714876505e-07" iyy="7.7316525337490038072e-06" iyz="7.3356500737983568942e-08" izz="2.8031377754211947353e-05"/>
    </inertial>
  </link>
  <link name="bearing_683_5">
    <visual>
      <origin xyz="0 0 0" rpy="0 -0 0"/>
      <geometry>
        <mesh filename="../assemblies/right_leg_reorder/meshes/right_bearing_683_visual.stl"/>
      </geometry>
      <material name="bearing_683_material">
        <color rgba="0.64705882352941179736 0.64705882352941179736 0.64705882352941179736 1.0"/>
      </material>
    </visual>
    <inertial>
      <origin xyz="1.0732094295237755686e-19 -2.4186774283160312878e-19 -0.0015500000000000003792" rpy="0 0 0"/>
      <mass value="0.00048694686130641793437"/>
      <inertia ixx="2.1551456503319887385e-09" ixy="-1.7491155954423949016e-28" ixz="-1.4181088723102325815e-38" iyy="2.1551456503319883249e-09" iyz="2.7953863573959653405e-38" izz="3.5303647444715305817e-09"/>
    </inertial>
  </link>
  <joint name="right_knee_front_rev_2" type="revolute">
    <origin xyz="0.0057402514854763839539 -0.013858192987669326612 0.026200000000000188416" rpy="-3.1415926535897886751 -3.2616767361120603506e-15 1.5711344860216835961"/>
    <parent link="right_calf_link"/>
    <child link="bearing_683_5"/>
    <axis xyz="0 0 1"/>
    <limit effort="1" velocity="20"/>
    <joint_properties friction="0.0"/>
  </joint>
  <link name="bearing_683_6">
    <visual>
      <origin xyz="0 0 0" rpy="0 -0 0"/>
      <geometry>
        <mesh filename="../assemblies/right_leg_reorder/meshes/right_bearing_683_2_visual.stl"/>
      </geometry>
      <material name="bearing_683_2_material">
        <color rgba="0.64705882352941179736 0.64705882352941179736 0.64705882352941179736 1.0"/>
      </material>
    </visual>
    <inertial>
      <origin xyz="1.0732094295237708741e-19 -1.1092294808199861648e-18 -0.0015500000000000003792" rpy="0 0 0"/>
      <mass value="0.00048694686130641793437"/>
      <inertia ixx="2.1551456503319887385e-09" ixy="-5.2750838441507813886e-29" ixz="0" iyy="2.1551456503319883249e-09" iyz="-4.4559467649346522358e-38" izz="3.5303647444715305817e-09"/>
    </inertial>
  </link>
  <joint name="right_knee_back_rev_2" type="revolute">
    <origin xyz="-0.0057402514854757351673 0.013858192987668299656 0.026199999999999772082" rpy="-3.1415926535897873428 -1.7584330469580919838e-14 1.5695900556931792202"/>
    <parent link="right_calf_link"/>
    <child link="bearing_683_6"/>
    <axis xyz="0 0 1"/>
    <limit effort="1" velocity="20"/>
    <joint_properties friction="0.0"/>
  </joint>
  <link name="right_ank_pitch_link">
    <visual>
      <origin xyz="0 0 0" rpy="0 -0 0"/>
      <geometry>
        <mesh filename="../assemblies/right_leg_reorder/meshes/right_ank_pitch_link_visual.stl"/>
      </geometry>
      <material name="right_ank_pitch_link_material">
        <color rgba="0.70321688500203327621 0.64514870846184446673 0.40484735422826279017 1.0"/>
      </material>
    </visual>
    <collision name="right_ank_pitch_link_collision">
      <origin xyz="-0.01934999879449606 0.012000001966953278 0.016799999633803964" rpy="0 0 0"/>
      <geometry>
        <box size="0.084799999371171 0.04650000482797623 0.046639998117461806"/>
      </geometry>
    </collision>
    <inertial>
      <origin xyz="-0.017770241889542317398 0.012301334508572219634 0.018814514831173603099" rpy="0 0 0"/>
      <mass value="0.17676376695067899658"/>
      <inertia ixx="4.7283381546856786612e-05" ixy="1.3380598207240605858e-06" ixz="6.1532628607400666377e-07" iyy="0.0001070646253591693456" iyz="-5.1080086246266920656e-08" izz="0.00012185522398303507265"/>
    </inertial>
  </link>
  <link name="ank_roll_link_2">
    <visual>
      <origin xyz="0 0 0" rpy="0 -0 0"/>
      <geometry>
        <mesh filename="../assemblies/right_leg_reorder/meshes/right_ank_roll_link_visual.stl"/>
      </geometry>
      <material name="ank_roll_link_material">
        <color rgba="0.61568627450980395466 0.81176470588235294379 0.92941176470588238168 1.0"/>
      </material>
    </visual>
    <collision name="ank_roll_link_2_collision">
      <origin xyz="-0.014500000514090061 0.0 0.038999998942017555" rpy="0 0 0"/>
      <geometry>
        <box size="0.04900000058114529 0.041999999433755875 0.12000000104308128"/>
      </geometry>
    </collision>
    <inertial>
      <origin xyz="-0.027003066516822164106 -2.0057327605930640986e-12 0.033764011359896511921" rpy="0 0 0"/>
      <mass value="0.042599999999999998979"/>
      <inertia ixx="3.7284397827465391934e-05" ixy="-5.5176118208468573726e-16" ixz="2.3929183768081708121e-06" iyy="3.7589276943350449865e-05" iyz="5.0934855128918095395e-12" izz="1.0090430906787057163e-05"/>
    </inertial>
  </link>
  <joint name="right_ank_roll" type="revolute">
    <origin xyz="-0.022749999999988414906 -3.3306690738754696213e-15 0.01899999999999847991" rpy="1.5707963267948539254 5.2107940288300650017e-14 1.5707963267948161779"/>
    <parent link="right_ank_pitch_link"/>
    <child link="ank_roll_link_2"/>
    <axis xyz="0 0 1"/>
    <limit effort="1" velocity="20" lower="-1.570796326794896558" upper="1.570796326794896558"/>
    <joint_properties friction="0.0"/>
  </joint>
  <joint name="right_ank_pitch" type="revolute">
    <origin xyz="3.002118024832101527e-17 -0.10000000000000031086 0.027750000000000059341" rpy="-3.1415926535897926719 6.2448450038443343634e-16 -3.1415926535897926719"/>
    <parent link="right_calf_link"/>
    <child link="right_ank_pitch_link"/>
    <axis xyz="0 0 1"/>
    <limit effort="1" velocity="20" lower="-0.785398163397448279" upper="1.7453292519943295336"/>
    <joint_properties friction="0.0"/>
  </joint>
  <joint name="right_knee" type="revolute">
    <origin xyz="1.3574383152273289389e-16 -0.0087500000000006062512 0.085949999999999984746" rpy="-1.5707963267948805708 -3.7746952287071370984e-15 4.9902824220642934492e-15"/>
    <parent link="right_hip_pitch_link"/>
    <child link="right_calf_link"/>
    <axis xyz="0 0 1"/>
    <limit effort="1" velocity="20" lower="0" upper="2.0943951023931952626"/>
    <joint_properties friction="0.0"/>
  </joint>
  <link name="xm430_plate_2">
    <visual>
      <origin xyz="0 0 0" rpy="0 -0 0"/>
      <geometry>
        <mesh filename="../assemblies/right_leg_reorder/meshes/right_xm430_plate_visual.stl"/>
      </geometry>
      <material name="xm430_plate_material">
        <color rgba="0.61568627450980395466 0.81176470588235294379 0.92941176470588227065 1.0"/>
      </material>
    </visual>
    <inertial>
      <origin xyz="-9.7261304206861753998e-19 -2.7508707211877265003e-18 0.0025278513919583813462" rpy="0 0 0"/>
      <mass value="0.0027000000000000001429"/>
      <inertia ixx="2.4635091298412544671e-07" ixy="5.8739562556303566831e-08" ixz="3.1093856674988785691e-36" iyy="1.2887178787151822041e-07" iyz="7.4139751184723011127e-37" izz="3.6467998413810321832e-07"/>
    </inertial>
  </link>
  <link name="knee_rod_3">
    <visual>
      <origin xyz="0 0 0" rpy="0 -0 0"/>
      <geometry>
        <mesh filename="../assemblies/right_leg_reorder/meshes/right_knee_rod_visual.stl"/>
      </geometry>
      <material name="knee_rod_material">
        <color rgba="0.62051618944235198416 0.78640765248647581664 0.88594253031295022716 1.0"/>
      </material>
    </visual>
    <inertial>
      <origin xyz="0.017534310910028421543 1.185877916911817973e-05 -0.0015987301647647246799" rpy="0 0 0"/>
      <mass value="0.0031629468613064179276"/>
      <inertia ixx="2.4224310081263208001e-08" ixy="-1.196784738102416964e-10" ixz="4.9178348499397176204e-10" iyy="8.1758895033325342041e-07" iyz="3.3260227775621559853e-13" izz="8.3704877987923238757e-07"/>
    </inertial>
  </link>
  <joint name="right_knee_front_rev_1" type="revolute">
    <origin xyz="0.0057402514854763518615 -0.013858192987669257223 0.0050000000000000113798" rpy="3.141592653589793116 -1.111704857049913648e-15 -1.5704581675681130726"/>
    <parent link="xm430_plate_2"/>
    <child link="knee_rod_3"/>
    <axis xyz="0 0 1"/>
    <limit effort="1" velocity="20"/>
    <joint_properties friction="0.0"/>
  </joint>
  <link name="knee_rod_4">
    <visual>
      <origin xyz="0 0 0" rpy="0 -0 0"/>
      <geometry>
        <mesh filename="../assemblies/right_leg_reorder/meshes/right_knee_rod_2_visual.stl"/>
      </geometry>
      <material name="knee_rod_2_material">
        <color rgba="0.62051618944235198416 0.78640765248647581664 0.88594253031295022716 1.0"/>
      </material>
    </visual>
    <inertial>
      <origin xyz="0.017534287401106681686 -4.230225965767764535e-05 -0.0015987301647646889012" rpy="0 0 0"/>
      <mass value="0.0031629468613064179276"/>
      <inertia ixx="2.4225259086581160197e-08" ixy="4.269126707158853537e-10" ixz="4.9178282565450748946e-10" iyy="8.175884758307931331e-07" iyz="-1.186448257998784681e-12" izz="8.3704925438208728636e-07"/>
    </inertial>
  </link>
  <joint name="right_knee_back_rev_1" type="revolute">
    <origin xyz="-0.0057402514854763440552 0.013858192987669354368 0.0049999999999999905631" rpy="-3.141592653589793116 1.2542833298517128192e-14 -1.5720025978966174485"/>
    <parent link="xm430_plate_2"/>
    <child link="knee_rod_4"/>
    <axis xyz="0 0 1"/>
    <limit effort="1" velocity="20"/>
    <joint_properties friction="0.0"/>
  </joint>
  <joint name="right_knee_act" type="revolute">
    <origin xyz="3.9287971482105029401e-18 0.0124499999999997564 0.044500000000000400346" rpy="-1.5707963267948774622 -2.7749270113816245533e-16 5.4939032356427845754e-16"/>
    <parent link="right_hip_pitch_link"/>
    <child link="xm430_plate_2"/>
    <axis xyz="0 0 1"/>
    <limit effort="1" velocity="20" lower="0" upper="2.0943951023931952626"/>
    <joint_properties friction="0.0"/>
  </joint>
  <joint name="right_hip_yaw_driven" type="revolute">
    <origin xyz="-5.2457909251798218506e-18 -3.4694469519536141888e-18 -0.0050000000000000113798" rpy="3.1415926535897922278 -1.4272087055159576395e-14 -3.6758798213763643757e-30"/>
    <parent link="spur_gear_21_teeth_2"/>
    <child link="right_hip_pitch_link"/>
    <axis xyz="0 0 1"/>
    <limit effort="1" velocity="20" lower="-1.570796326794896558" upper="1.570796326794896558"/>
    <joint_properties friction="0.0"/>
  </joint>
  <joint name="right_hip_yaw_fixed" type="fixed">
    <origin xyz="6.9388939039072283776e-18 -0.027999999999999997113 -0.019000000000000002998" rpy="-1.5707963267948990005 1.5707963267948785724 0"/>
    <parent link="hip_yaw_link_2"/>
    <child link="spur_gear_21_teeth_2"/>
    <axis xyz="0 0 1"/>
    <limit effort="1" velocity="20"/>
    <joint_properties friction="0.0"/>
  </joint>
  <joint name="right_hip_roll" type="revolute">
    <origin xyz="-0.024000000716143506108 0.019000000152447637375 0.019000000152446804708" rpy="-1.5707963267948252817 -1.5707963267948190644 0"/>
    <parent link="2xc430_2"/>
    <child link="hip_yaw_link_2"/>
    <axis xyz="0 0 1"/>
    <limit effort="1" velocity="20" lower="-0.785398163397448279" upper="0.785398163397448279"/>
    <joint_properties friction="0.0"/>
  </joint>
  <link name="sho_pitch_link">
    <visual>
      <origin xyz="0 0 0" rpy="0 -0 0"/>
      <geometry>
        <mesh filename="../assemblies/left_arm_umi/meshes/left_sho_pitch_link_visual.stl"/>
      </geometry>
      <material name="sho_pitch_link_material">
        <color rgba="0.61568627450980395466 0.81176470588235294379 0.9294117647058824927 1.0"/>
      </material>
    </visual>
    <inertial>
      <origin xyz="-6.4657779715960017825e-19 -2.2052288447398826838e-18 0.012913250798677600867" rpy="0 0 0"/>
      <mass value="0.0085999999999999895972"/>
      <inertia ixx="1.8365636406635799556e-06" ixy="0" ixz="0" iyy="4.0110869076839109814e-06" iyz="0" izz="3.5160516450492455693e-06"/>
    </inertial>
  </link>
  <link name="2xl430_gears">
    <visual>
      <origin xyz="0 0 0" rpy="0 -0 0"/>
      <geometry>
        <mesh filename="../assemblies/left_arm_umi/meshes/left_2xl430_gears_visual.stl"/>
      </geometry>
      <material name="2xl430_gears_material">
        <color rgba="0.75914767920569226067 0.85560384745670925444 0.90519468321360618823 1.0"/>
      </material>
    </visual>
    <collision name="2xl430_gears_collision">
      <origin xyz="-0.011708624550579435 -0.00266315940464312 -0.01986897463774037" rpy="0 0 0"/>
      <geometry>
        <sphere radius="0.03117398374352779"/>
      </geometry>
    </collision>
    <inertial>
      <origin xyz="-0.011592905737981712769 -0.0024238553642539663324 -0.018551095523800652243" rpy="0 0 0"/>
      <mass value="0.11800003674524907338"/>
      <inertia ixx="2.7511021050425133908e-05" ixy="9.0043904315059457427e-07" ixz="-2.3349710123437291678e-08" iyy="3.2796197843345773501e-05" iyz="-6.5715119654595543253e-07" izz="3.577573983574187309e-05"/>
    </inertial>
  </link>
  <link name="spur_1m_24t_drive">
    <visual>
      <origin xyz="0 0 0" rpy="0 -0 0"/>
      <geometry>
        <mesh filename="../assemblies/left_arm_umi/meshes/left_spur_1m_24t_drive_visual.stl"/>
      </geometry>
      <material name="spur_1m_24t_drive_material">
        <color rgba="0.61568627450980406568 0.81176470588235294379 0.92941176470588238168 1.0"/>
      </material>
    </visual>
    <inertial>
      <origin xyz="3.0329768727181610639e-15 -3.3891425476220191508e-16 0.0048096451474093065287" rpy="0 0 0"/>
      <mass value="0.0032000000000000001533"/>
      <inertia ixx="1.4097598887016958673e-07" ixy="1.556282310200251252e-15" ixz="1.3007821291259216684e-36" iyy="1.4097598803635998845e-07" iyz="2.0801757662181522333e-36" izz="2.4107776386988830202e-07"/>
    </inertial>
  </link>
  <joint name="left_sho_yaw_drive" type="revolute">
    <origin xyz="-0.024000000716141004636 -0.019000000152450600283 -0.019000000152443286688" rpy="1.5707963267948328312 -1.2258104172924911424e-15 7.6362147953450801566e-14"/>
    <parent link="2xl430_gears"/>
    <child link="spur_1m_24t_drive"/>
    <axis xyz="0 0 1"/>
    <limit effort="1" velocity="20" lower="-2.6179938779914944114" upper="2.6179938779914944114"/>
    <joint_properties friction="0.0"/>
  </joint>
  <link name="spur_1m_24t_driven">
    <visual>
      <origin xyz="0 0 0" rpy="0 -0 0"/>
      <geometry>
        <mesh filename="../assemblies/left_arm_umi/meshes/left_spur_1m_24t_driven_visual.stl"/>
      </geometry>
      <material name="spur_1m_24t_driven_material">
        <color rgba="0.23137254901960788156 0.38039215686274502337 0.7058823529411765163 1.0"/>
      </material>
    </visual>
    <inertial>
      <origin xyz="-2.7696338792817279401e-18 -1.6888946739707568705e-15 -0.00097237500038395777158" rpy="0 0 0"/>
      <mass value="0.0026999999999999997093"/>
      <inertia ixx="1.2202334915684080498e-07" ixy="-5.4145940442873918866e-38" ixz="-1.29880804458499659e-37" iyy="1.2202334915684067263e-07" iyz="-1.7775256456003019676e-37" izz="2.3180293204341257533e-07"/>
    </inertial>
  </link>
  <link name="sho_yaw_link">
    <visual>
      <origin xyz="0 0 0" rpy="0 -0 0"/>
      <geometry>
        <mesh filename="../assemblies/left_arm_umi/meshes/left_sho_yaw_link_visual.stl"/>
      </geometry>
      <material name="sho_yaw_link_material">
        <color rgba="0.61568627450980384364 0.81176470588235294379 0.92941176470588238168 1.0"/>
      </material>
    </visual>
    <inertial>
      <origin xyz="-1.1660583139255996671e-18 3.5695430205023107659e-18 -0.024649285094360082193" rpy="0 0 0"/>
      <mass value="0.01450000000000000247"/>
      <inertia ixx="9.2365904614004439553e-06" ixy="3.5862833440698297613e-13" ixz="2.4228256401787986045e-43" iyy="5.8163826335078774773e-06" iyz="1.6375773286667063138e-35" izz="4.5074356741562122031e-06"/>
    </inertial>
  </link>
  <link name="2xl430_gears_2">
    <visual>
      <origin xyz="0 0 0" rpy="0 -0 0"/>
      <geometry>
        <mesh filename="../assemblies/left_arm_umi/meshes/left_2xl430_gears_2_visual.stl"/>
      </geometry>
      <material name="2xl430_gears_2_material">
        <color rgba="0.75914767920569226067 0.85560384745670925444 0.90519468321360618823 1.0"/>
      </material>
    </visual>
    <collision name="2xl430_gears_2_collision">
      <origin xyz="-0.01171064517292808 -0.0026638298343621657 -0.019868137531963884" rpy="0 0 0"/>
      <geometry>
        <sphere radius="0.03117267380501694"/>
      </geometry>
    </collision>
    <inertial>
      <origin xyz="-0.011592905737977807906 -0.0024238553642531254252 -0.018551095523810002402" rpy="0 0 0"/>
      <mass value="0.11800003674524907338"/>
      <inertia ixx="2.7511021050425465945e-05" ixy="9.0043904315422718094e-07" ixz="-2.3349710124856703831e-08" iyy="3.2796197843347501448e-05" iyz="-6.5715119654968068343e-07" izz="3.577573983574221868e-05"/>
    </inertial>
  </link>
  <link name="spur_1m_24t_drive_2">
    <visual>
      <origin xyz="0 0 0" rpy="0 -0 0"/>
      <geometry>
        <mesh filename="../assemblies/left_arm_umi/meshes/left_spur_1m_24t_drive_2_visual.stl"/>
      </geometry>
      <material name="spur_1m_24t_drive_2_material">
        <color rgba="0.61568627450980406568 0.81176470588235294379 0.92941176470588238168 1.0"/>
      </material>
    </visual>
    <inertial>
      <origin xyz="3.0399157666220686867e-15 -3.3891425476220186578e-16 0.0048096451474092995898" rpy="0 0 0"/>
      <mass value="0.0032000000000000001533"/>
      <inertia ixx="1.4097598887016958673e-07" ixy="1.5562823135089737022e-15" ixz="1.0580991581479530361e-37" iyy="1.4097598803635998845e-07" iyz="1.7893503109200296805e-36" izz="2.4107776386988830202e-07"/>
    </inertial>
  </link>
  <joint name="left_elbow_yaw_drive" type="revolute">
    <origin xyz="-0.024000000716137528251 -0.019000000152447529822 -0.019000000152459547986" rpy="1.570796326795050879 -2.4708842848455862195e-13 -6.0621939164177121919e-14"/>
    <parent link="2xl430_gears_2"/>
    <child link="spur_1m_24t_drive_2"/>
    <axis xyz="0 0 1"/>
    <limit effort="1" velocity="20" lower="-2.6179938779914944114" upper="2.6179938779914944114"/>
    <joint_properties friction="0.0"/>
  </joint>
  <link name="spur_1m_24t_driven_2">
    <visual>
      <origin xyz="0 0 0" rpy="0 -0 0"/>
      <geometry>
        <mesh filename="../assemblies/left_arm_umi/meshes/left_spur_1m_24t_driven_2_visual.stl"/>
      </geometry>
      <material name="spur_1m_24t_driven_2_material">
        <color rgba="0.23137254901960788156 0.38039215686274502337 0.7058823529411765163 1.0"/>
      </material>
    </visual>
    <inertial>
      <origin xyz="-2.7696338792814941323e-18 -1.6891334800965897676e-15 -0.00097237500038395430213" rpy="0 0 0"/>
      <mass value="0.0026999999999999997093"/>
      <inertia ixx="1.2202334915684080498e-07" ixy="7.4096554914502797611e-48" ixz="2.2216384613704353782e-36" iyy="1.2202334915684067263e-07" iyz="-3.3166193968997528155e-38" izz="2.3180293204341257533e-07"/>
    </inertial>
  </link>
  <link name="elb_yaw_link">
    <visual>
      <origin xyz="0 0 0" rpy="0 -0 0"/>
      <geometry>
        <mesh filename="../assemblies/left_arm_umi/meshes/left_elb_yaw_link_visual.stl"/>
      </geometry>
      <material name="elb_yaw_link_material">
        <color rgba="0.61568627450980395466 0.81176470588235294379 0.92941176470588227065 1.0"/>
      </material>
    </visual>
    <inertial>
      <origin xyz="5.3127688027629623281e-08 0.0019833638641961665906 -0.023416643551549959357" rpy="0 0 0"/>
      <mass value="0.017500000000000001665"/>
      <inertia ixx="1.4134344903109199776e-05" ixy="1.6945783921985168561e-12" ixz="-1.1286398721840441603e-11" iyy="6.6435900776211374285e-06" iyz="1.0545227077253063932e-06" izz="8.9925290757999044535e-06"/>
    </inertial>
  </link>
  <link name="spur_1m_24t_driven_3">
    <visual>
      <origin xyz="0 0 0" rpy="0 -0 0"/>
      <geometry>
        <mesh filename="../assemblies/left_arm_umi/meshes/left_spur_1m_24t_driven_3_visual.stl"/>
      </geometry>
      <material name="spur_1m_24t_driven_3_material">
        <color rgba="0.23137254901960788156 0.38039215686274502337 0.7058823529411765163 1.0"/>
      </material>
    </visual>
    <inertial>
      <origin xyz="-2.7696338792817514365e-18 -1.6888946739707584482e-15 -0.0025723750003839619682" rpy="0 0 0"/>
      <mass value="0.0026999999999999997093"/>
      <inertia ixx="1.2202334915684085792e-07" ixy="7.5686617236975896587e-37" ixz="-3.973746367682918447e-37" iyy="1.2202334915684067263e-07" iyz="1.9991124742865135215e-36" izz="2.3180293204341268121e-07"/>
    </inertial>
  </link>
  <link name="2xl430_gears_3">
    <visual>
      <origin xyz="0 0 0" rpy="0 -0 0"/>
      <geometry>
        <mesh filename="../assemblies/left_arm_umi/meshes/left_2xl430_gears_3_visual.stl"/>
      </geometry>
      <material name="2xl430_gears_3_material">
        <color rgba="0.75914767920569226067 0.85560384745670925444 0.90519468321360618823 1.0"/>
      </material>
    </visual>
    <collision name="2xl430_gears_3_collision">
      <origin xyz="-0.0008533845367763171 0.011719140412504325 -0.02433735651741283" rpy="0 0 0"/>
      <geometry>
        <sphere radius="0.03116007186480805"/>
      </geometry>
    </collision>
    <inertial>
      <origin xyz="0.00044890447620203491417 0.011592905379898174253 -0.024576144788197706176" rpy="0 0 0"/>
      <mass value="0.11800003674524907338"/>
      <inertia ixx="3.577573983574154783e-05" ixy="2.334971012357639037e-08" ixz="6.5715119654891581268e-07" iyy="2.7511021050426397682e-05" iyz="9.0043904315388042683e-07" izz="3.279619784334573962e-05"/>
    </inertial>
  </link>
  <link name="spur_1m_24t_drive_3">
    <visual>
      <origin xyz="0 0 0" rpy="0 -0 0"/>
      <geometry>
        <mesh filename="../assemblies/left_arm_umi/meshes/left_spur_1m_24t_drive_3_visual.stl"/>
      </geometry>
      <material name="spur_1m_24t_drive_3_material">
        <color rgba="0.61568627450980406568 0.81176470588235294379 0.92941176470588238168 1.0"/>
      </material>
    </visual>
    <inertial>
      <origin xyz="3.0329768727181610639e-15 -3.3891425476220186578e-16 0.004809645147409304794" rpy="0 0 0"/>
      <mass value="0.0032000000000000001533"/>
      <inertia ixx="1.409759888701696132e-07" ixy="1.5562823188323177284e-15" ixz="-7.1146411252036581317e-36" iyy="1.4097598803636004139e-07" iyz="4.87979885849671193e-37" izz="2.4107776386988830202e-07"/>
    </inertial>
  </link>
  <joint name="left_wrist_pitch_drive" type="revolute">
    <origin xyz="-1.524411552671568168e-10 0.024000000358058659611 -0.008000000000006885284" rpy="9.3688120281041050571e-15 -2.4754138690627644039e-13 -1.570796326794971387"/>
    <parent link="2xl430_gears_3"/>
    <child link="spur_1m_24t_drive_3"/>
    <axis xyz="0 0 1"/>
    <limit effort="1" velocity="20" lower="-1.9198621771937625091" upper="1.3962634015954635824"/>
    <joint_properties friction="0.0"/>
  </joint>
  <link name="hand">
    <visual>
      <origin xyz="0 0 0" rpy="0 -0 0"/>
      <geometry>
        <mesh filename="../assemblies/left_arm_umi/meshes/left_hand_visual.stl"/>
      </geometry>
      <material name="hand_material">
        <color rgba="0.64149913129808888712 0.67624720774385715938 0.69709605361131798951 1.0"/>
      </material>
    </visual>
    <collision name="hand_collision">
      <origin xyz="-0.0044999998062849045 0.023250000085681677 -0.019000000320374966" rpy="0 0 0"/>
      <geometry>
        <box size="0.05000000074505806 0.06749999988824129 0.07400000281631947"/>
      </geometry>
    </collision>
    <inertial>
      <origin xyz="-0.00370786937874344278 0.042127339671143342048 -0.018490328271618890893" rpy="0 0 0"/>
      <mass value="0.039499999999999972633"/>
      <inertia ixx="2.4635502047218475399e-05" ixy="6.2323015589611070721e-07" ixz="1.439144617802384392e-08" iyy="2.5475207220956867695e-05" iyz="-4.0870433587616749489e-08" izz="1.346667924886838862e-05"/>
    </inertial>
  </link>
  <joint name="left_wrist_roll" type="revolute">
    <origin xyz="0.019000000000007885581 -3.580815921555569048e-10 -0.027000000152448064283" rpy="3.141592653589793116 -1.5707963267945475039 0"/>
    <parent link="2xl430_gears_3"/>
    <child link="hand"/>
    <axis xyz="0 0 1"/>
    <limit effort="1" velocity="20" lower="-1.9198621771937625091" upper="1.3962634015954635824"/>
    <joint_properties friction="0.0"/>
  </joint>
  <link name="wrist_bearing_plate">
    <visual>
      <origin xyz="0 0 0" rpy="0 -0 0"/>
      <geometry>
        <mesh filename="../assemblies/left_arm_umi/meshes/left_wrist_bearing_plate_visual.stl"/>
      </geometry>
      <material name="wrist_bearing_plate_material">
        <color rgba="0.71932243125689054875 0.63128434304969727187 0.52422389360984933404 1.0"/>
      </material>
    </visual>
    <inertial>
      <origin xyz="-0.0075835583121500165643 -0.015499999999999977338 -0.0018386323705903283732" rpy="0 0 0"/>
      <mass value="0.0049000367468305557062"/>
      <inertia ixx="4.9707430109150129132e-07" ixy="1.2128080407254277364e-22" ixz="1.8100904820814061718e-08" iyy="7.1268523603538553059e-07" iyz="6.3917125174818354979e-24" izz="1.1919657811600107117e-06"/>
    </inertial>
  </link>
  <joint name="left_wrist_pitch_fixed" type="fixed">
    <origin xyz="0.015500000000007495629 -1.7430501486614957685e-14 -0.044999999999998895051" rpy="4.0578651550042264519e-14 -2.8213542612434331081e-13 -1.570796326794906328"/>
    <parent link="2xl430_gears_3"/>
    <child link="wrist_bearing_plate"/>
    <axis xyz="0 0 1"/>
    <limit effort="1" velocity="20"/>
    <joint_properties friction="0.0"/>
  </joint>
  <joint name="left_wrist_pitch_driven" type="revolute">
    <origin xyz="5.5511151231257827021e-17 -4.7331654313260708325e-30 -0.0015999999999999989925" rpy="-2.6917187154893159429e-14 -2.6645352591003750659e-14 -1.570796326794896558"/>
    <parent link="spur_1m_24t_driven_3"/>
    <child link="2xl430_gears_3"/>
    <axis xyz="0 0 1"/>
    <limit effort="1" velocity="20" lower="-1.3962634015954635824" upper="1.9198621771937625091"/>
    <joint_properties friction="0.0"/>
  </joint>
  <joint name="left_wrist_roll_fixed" type="fixed">
    <origin xyz="-3.1554436208840472216e-30 -0.025300000000000003042 -0.052000000000000046185" rpy="1.5707963267949236474 -1.5707963267948696906 0"/>
    <parent link="elb_yaw_link"/>
    <child link="spur_1m_24t_driven_3"/>
    <axis xyz="0 0 1"/>
    <limit effort="1" velocity="20"/>
    <joint_properties friction="0.0"/>
  </joint>
  <joint name="left_elbow_yaw_fixed" type="fixed">
    <origin xyz="3.1554436208840472216e-30 0 0.0015999999999999764411" rpy="-3.141592653589793116 6.8585119145426910438e-26 -7.6666465467942038555e-26"/>
    <parent link="spur_1m_24t_driven_2"/>
    <child link="elb_yaw_link"/>
    <axis xyz="0 0 1"/>
    <limit effort="1" velocity="20"/>
    <joint_properties friction="0.0"/>
  </joint>
  <joint name="left_elbow_yaw_driven" type="revolute">
    <origin xyz="-3.5806395001780622067e-10 -0.027000000152452907631 -0.019000000000006608825" rpy="1.5707963267949571762 1.5707963267947377961 0"/>
    <parent link="2xl430_gears_2"/>
    <child link="spur_1m_24t_driven_2"/>
    <axis xyz="0 0 1"/>
    <limit effort="1" velocity="20" lower="-2.6179938779914944114" upper="2.6179938779914944114"/>
    <joint_properties friction="0.0"/>
  </joint>
  <joint name="left_elbow_roll" type="revolute">
    <origin xyz="0 -0.018999999999999999528 -0.05900000000000000383" rpy="1.570796326794896558 -8.2694607970959069176e-16 -2.2204460490005989148e-16"/>
    <parent link="sho_yaw_link"/>
    <child link="2xl430_gears_2"/>
    <axis xyz="0 0 1"/>
    <limit effort="1" velocity="20" lower="-1.9198621771937625091" upper="2.4434609527920612138"/>
    <joint_properties friction="0.0"/>
  </joint>
  <joint name="left_sho_yaw_fixed" type="fixed">
    <origin xyz="0 -3.9443045261050590271e-31 0.0016000000000000041966" rpy="-3.1415926535897917837 7.7715611727616959238e-16 7.7715611725338728944e-16"/>
    <parent link="spur_1m_24t_driven"/>
    <child link="sho_yaw_link"/>
    <axis xyz="0 0 1"/>
    <limit effort="1" velocity="20"/>
    <joint_properties friction="0.0"/>
  </joint>
  <joint name="left_sho_yaw_driven" type="revolute">
    <origin xyz="-3.5807028869738743992e-10 -0.027000000152450923108 -0.018999999999999878098" rpy="1.5707963267948492625 8.0395273179087848749e-14 9.4924068605497912938e-14"/>
    <parent link="2xl430_gears"/>
    <child link="spur_1m_24t_driven"/>
    <axis xyz="0 0 1"/>
    <limit effort="1" velocity="20" lower="-2.6179938779914944114" upper="2.6179938779914944114"/>
    <joint_properties friction="0.0"/>
  </joint>
  <joint name="left_sho_roll" type="revolute">
    <origin xyz="-0.018999999999999999528 9.3241386866726118567e-18 0.027000000000000006634" rpy="-3.141592653589793116 1.5707963267948936714 0"/>
    <parent link="sho_pitch_link"/>
    <child link="2xl430_gears"/>
    <axis xyz="0 0 1"/>
    <limit effort="1" velocity="20" lower="-1.570796326794896558" upper="0.34906585039886589561"/>
    <joint_properties friction="0.0"/>
  </joint>
  <link name="sho_pitch_link_2">
    <visual>
      <origin xyz="0 0 0" rpy="0 -0 0"/>
      <geometry>
        <mesh filename="../assemblies/right_arm_umi/meshes/right_sho_pitch_link_visual.stl"/>
      </geometry>
      <material name="sho_pitch_link_material">
        <color rgba="0.61568627450980395466 0.81176470588235294379 0.9294117647058824927 1.0"/>
      </material>
    </visual>
    <inertial>
      <origin xyz="-6.4657779715960017825e-19 -2.2052288447398900024e-18 0.012913250798677600867" rpy="0 0 0"/>
      <mass value="0.0085999999999999895972"/>
      <inertia ixx="1.8365636406635799556e-06" ixy="2.7052466620977941747e-97" ixz="-6.0867229013657627499e-136" iyy="4.0110869076839109814e-06" iyz="-1.6935833339184735773e-44" izz="3.5160516450492455693e-06"/>
    </inertial>
  </link>
  <link name="2xl430_gears_4">
    <visual>
      <origin xyz="0 0 0" rpy="0 -0 0"/>
      <geometry>
        <mesh filename="../assemblies/right_arm_umi/meshes/right_2xl430_gears_visual.stl"/>
      </geometry>
      <material name="2xl430_gears_material">
        <color rgba="0.75914767920569226067 0.85560384745670925444 0.90519468321360618823 1.0"/>
      </material>
    </visual>
    <collision name="2xl430_gears_4_collision">
      <origin xyz="-0.011708624550579453 -0.0026631594046431385 -0.01986897463774038" rpy="0 0 0"/>
      <geometry>
        <sphere radius="0.031173983743527797"/>
      </geometry>
    </collision>
    <inertial>
      <origin xyz="-0.01159290573797869435 -0.0024238553642522849517 -0.018551095523803726173" rpy="0 0 0"/>
      <mass value="0.11800003674524907338"/>
      <inertia ixx="2.7511021050424639241e-05" ixy="9.004390431513549981e-07" ixz="-2.3349710123960741496e-08" iyy="3.2796197843346213958e-05" iyz="-6.5715119654693364971e-07" izz="3.5775739835740998952e-05"/>
    </inertial>
  </link>
  <link name="spur_1m_24t_drive_4">
    <visual>
      <origin xyz="0 0 0" rpy="0 -0 0"/>
      <geometry>
        <mesh filename="../assemblies/right_arm_umi/meshes/right_spur_1m_24t_drive_visual.stl"/>
      </geometry>
      <material name="spur_1m_24t_drive_material">
        <color rgba="0.61568627450980406568 0.81176470588235294379 0.92941176470588238168 1.0"/>
      </material>
    </visual>
    <inertial>
      <origin xyz="3.0329768727181610639e-15 -3.3891425476220191508e-16 0.0048096451474093039266" rpy="0 0 0"/>
      <mass value="0.0032000000000000001533"/>
      <inertia ixx="1.4097598887016958673e-07" ixy="1.5562823134806672036e-15" ixz="3.9554371954666049354e-37" iyy="1.4097598803635998845e-07" iyz="-1.3068306635892903836e-36" izz="2.4107776386988830202e-07"/>
    </inertial>
  </link>
  <joint name="right_sho_yaw_drive" type="revolute">
    <origin xyz="-0.024000000716138267243 -0.019000000152445337132 -0.019000000152448424939" rpy="1.5707963267949289765 -7.4062049324254792929e-14 1.9645226351351914911e-14"/>
    <parent link="2xl430_gears_4"/>
    <child link="spur_1m_24t_drive_4"/>
    <axis xyz="0 0 1"/>
    <limit effort="1" velocity="20" lower="-2.6179938779914944114" upper="2.6179938779914944114"/>
    <joint_properties friction="0.0"/>
  </joint>
  <link name="spur_1m_24t_driven_4">
    <visual>
      <origin xyz="0 0 0" rpy="0 -0 0"/>
      <geometry>
        <mesh filename="../assemblies/right_arm_umi/meshes/right_spur_1m_24t_driven_visual.stl"/>
      </geometry>
      <material name="spur_1m_24t_driven_material">
        <color rgba="0.23137254901960788156 0.38039215686274502337 0.7058823529411765163 1.0"/>
      </material>
    </visual>
    <inertial>
      <origin xyz="-2.7696338792816901919e-18 -1.6888946739707558844e-15 -0.00097237500038396124102" rpy="0 0 0"/>
      <mass value="0.0026999999999999997093"/>
      <inertia ixx="1.2202334915684080498e-07" ixy="0" ixz="0" iyy="1.2202334915684067263e-07" iyz="-3.1611202962161965154e-37" izz="2.3180293204341257533e-07"/>
    </inertial>
  </link>
  <link name="sho_yaw_link_2">
    <visual>
      <origin xyz="0 0 0" rpy="0 -0 0"/>
      <geometry>
        <mesh filename="../assemblies/right_arm_umi/meshes/right_sho_yaw_link_visual.stl"/>
      </geometry>
      <material name="sho_yaw_link_material">
        <color rgba="0.61568627450980384364 0.81176470588235294379 0.92941176470588238168 1.0"/>
      </material>
    </visual>
    <inertial>
      <origin xyz="-1.1660583139255996671e-18 3.5695430205025619071e-18 -0.024649285094360089132" rpy="0 0 0"/>
      <mass value="0.01450000000000000247"/>
      <inertia ixx="9.2365904614004439553e-06" ixy="3.5862833440698297613e-13" ixz="3.9137616104661151467e-44" iyy="5.8163826335078774773e-06" iyz="-5.7710285861749289932e-36" izz="4.5074356741562122031e-06"/>
    </inertial>
  </link>
  <link name="2xl430_gears_5">
    <visual>
      <origin xyz="0 0 0" rpy="0 -0 0"/>
      <geometry>
        <mesh filename="../assemblies/right_arm_umi/meshes/right_2xl430_gears_2_visual.stl"/>
      </geometry>
      <material name="2xl430_gears_2_material">
        <color rgba="0.75914767920569226067 0.85560384745670925444 0.90519468321360618823 1.0"/>
      </material>
    </visual>
    <collision name="2xl430_gears_5_collision">
      <origin xyz="-0.011709972049291249 -0.0026636168082209365 -0.019868886738201058" rpy="0 0 0"/>
      <geometry>
        <sphere radius="0.03117333339067767"/>
      </geometry>
    </collision>
    <inertial>
      <origin xyz="-0.011592905737984599349 -0.002423855364252071147 -0.018551095523805887638" rpy="0 0 0"/>
      <mass value="0.11800003674524907338"/>
      <inertia ixx="2.751102105042605548e-05" ixy="9.0043904315050627108e-07" ixz="-2.3349710123665758963e-08" iyy="3.2796197843347230398e-05" iyz="-6.5715119654724556959e-07" izz="3.5775739835742266114e-05"/>
    </inertial>
  </link>
  <link name="spur_1m_24t_drive_5">
    <visual>
      <origin xyz="0 0 0" rpy="0 -0 0"/>
      <geometry>
        <mesh filename="../assemblies/right_arm_umi/meshes/right_spur_1m_24t_drive_2_visual.stl"/>
      </geometry>
      <material name="spur_1m_24t_drive_2_material">
        <color rgba="0.61568627450980406568 0.81176470588235294379 0.92941176470588238168 1.0"/>
      </material>
    </visual>
    <inertial>
      <origin xyz="3.02603797881425423e-15 -3.3891425476220191508e-16 0.0048096451474092995898" rpy="0 0 0"/>
      <mass value="0.0032000000000000001533"/>
      <inertia ixx="1.4097598887016958673e-07" ixy="1.5562823081573231774e-15" ixz="1.1756804446533630512e-37" iyy="1.4097598803635996198e-07" iyz="2.3035732543170599666e-36" izz="2.4107776386988830202e-07"/>
    </inertial>
  </link>
  <joint name="right_elbow_yaw_drive" type="revolute">
    <origin xyz="-0.024000000716147162905 -0.019000000152450874369 -0.019000000152450294971" rpy="1.5707963267949573982 3.0456550330441217593e-14 -3.9968028886506279166e-14"/>
    <parent link="2xl430_gears_5"/>
    <child link="spur_1m_24t_drive_5"/>
    <axis xyz="0 0 1"/>
    <limit effort="1" velocity="20" lower="-2.6179938779914944114" upper="2.6179938779914944114"/>
    <joint_properties friction="0.0"/>
  </joint>
  <link name="spur_1m_24t_driven_5">
    <visual>
      <origin xyz="0 0 0" rpy="0 -0 0"/>
      <geometry>
        <mesh filename="../assemblies/right_arm_umi/meshes/right_spur_1m_24t_driven_2_visual.stl"/>
      </geometry>
      <material name="spur_1m_24t_driven_2_material">
        <color rgba="0.23137254901960788156 0.38039215686274502337 0.7058823529411765163 1.0"/>
      </material>
    </visual>
    <inertial>
      <origin xyz="6.998130726719240932e-19 -1.6888946739707574622e-15 -0.00097237500038395430213" rpy="0 0 0"/>
      <mass value="0.0026999999999999997093"/>
      <inertia ixx="1.2202334915684080498e-07" ixy="3.8503779869585968261e-37" ixz="-5.0252529353177581452e-67" iyy="1.2202334915684067263e-07" iyz="-1.5292377512497487578e-36" izz="2.3180293204341257533e-07"/>
    </inertial>
  </link>
  <link name="elb_yaw_link_2">
    <visual>
      <origin xyz="0 0 0" rpy="0 -0 0"/>
      <geometry>
        <mesh filename="../assemblies/right_arm_umi/meshes/right_elb_yaw_link_visual.stl"/>
      </geometry>
      <material name="elb_yaw_link_material">
        <color rgba="0.61568627450980395466 0.81176470588235294379 0.92941176470588227065 1.0"/>
      </material>
    </visual>
    <inertial>
      <origin xyz="5.3127688027629623281e-08 0.0019833638641961626875 -0.023416643551549952418" rpy="0 0 0"/>
      <mass value="0.017500000000000001665"/>
      <inertia ixx="1.4134344903109199776e-05" ixy="1.6945783921985164522e-12" ixz="-1.1286398721840438372e-11" iyy="6.6435900776211340404e-06" iyz="1.0545227077253059697e-06" izz="8.9925290757999010654e-06"/>
    </inertial>
  </link>
  <link name="spur_1m_24t_driven_6">
    <visual>
      <origin xyz="0 0 0" rpy="0 -0 0"/>
      <geometry>
        <mesh filename="../assemblies/right_arm_umi/meshes/right_spur_1m_24t_driven_3_visual.stl"/>
      </geometry>
      <material name="spur_1m_24t_driven_3_material">
        <color rgba="0.23137254901960788156 0.38039215686274502337 0.7058823529411765163 1.0"/>
      </material>
    </visual>
    <inertial>
      <origin xyz="2.4985941736347222548e-17 -1.6888946739707539123e-15 -0.0025723750003839584988" rpy="0 0 0"/>
      <mass value="0.0026999999999999997093"/>
      <inertia ixx="1.2202334915684080498e-07" ixy="1.2024235126300533086e-36" ixz="-1.9251889934793005011e-37" iyy="1.2202334915684067263e-07" iyz="-6.5691309546560350094e-67" izz="2.3180293204341257533e-07"/>
    </inertial>
  </link>
  <link name="2xl430_gears_6">
    <visual>
      <origin xyz="0 0 0" rpy="0 -0 0"/>
      <geometry>
        <mesh filename="../assemblies/right_arm_umi/meshes/right_2xl430_gears_3_visual.stl"/>
      </geometry>
      <material name="2xl430_gears_3_material">
        <color rgba="0.75914767920569226067 0.85560384745670925444 0.90519468321360618823 1.0"/>
      </material>
    </visual>
    <collision name="2xl430_gears_6_collision">
      <origin xyz="-0.0008533845367763458 0.0117191404125043 -0.02433735651741291" rpy="0 0 0"/>
      <geometry>
        <sphere radius="0.031160071864808042"/>
      </geometry>
    </collision>
    <inertial>
      <origin xyz="0.00044890447620015046237 0.011592905379911784894 -0.024576144788197196167" rpy="0 0 0"/>
      <mass value="0.11800003674524907338"/>
      <inertia ixx="3.5775739835742767557e-05" ixy="2.3349710123599005488e-08" ixz="6.5715119654677451339e-07" iyy="2.7511021050425879297e-05" iyz="9.0043904315183399523e-07" izz="3.2796197843346695073e-05"/>
    </inertial>
  </link>
  <link name="spur_1m_24t_drive_6">
    <visual>
      <origin xyz="0 0 0" rpy="0 -0 0"/>
      <geometry>
        <mesh filename="../assemblies/right_arm_umi/meshes/right_spur_1m_24t_drive_3_visual.stl"/>
      </geometry>
      <material name="spur_1m_24t_drive_3_material">
        <color rgba="0.61568627450980406568 0.81176470588235294379 0.92941176470588238168 1.0"/>
      </material>
    </visual>
    <inertial>
      <origin xyz="3.0329768727181610639e-15 -3.3891425478805135853e-16 0.0048096451474093039266" rpy="0 0 0"/>
      <mass value="0.0032000000000000001533"/>
      <inertia ixx="1.409759888701696132e-07" ixy="1.5562823155235952782e-15" ixz="5.3447756147290179682e-37" iyy="1.4097598803636004139e-07" iyz="-7.82962044161536043e-37" izz="2.4107776386988830202e-07"/>
    </inertial>
  </link>
  <joint name="right_wrist_pitch_drive" type="revolute">
    <origin xyz="-1.5244312511681577095e-10 0.024000000358071760242 -0.0080000000000008727324" rpy="1.2483159056318501391e-14 7.3485321852726251993e-14 -1.5707963267948599206"/>
    <parent link="2xl430_gears_6"/>
    <child link="spur_1m_24t_drive_6"/>
    <axis xyz="0 0 1"/>
    <limit effort="1" velocity="20" lower="-1.3962634015954635824" upper="1.9198621771937625091"/>
    <joint_properties friction="0.0"/>
  </joint>
  <link name="hand_2">
    <visual>
      <origin xyz="0 0 0" rpy="0 -0 0"/>
      <geometry>
        <mesh filename="../assemblies/right_arm_umi/meshes/right_hand_visual.stl"/>
      </geometry>
      <material name="hand_material">
        <color rgba="0.64149913129808899814 0.67624720774385715938 0.69709605361131798951 1.0"/>
      </material>
    </visual>
    <collision name="hand_2_collision">
      <origin xyz="0.0044999998062849045 -0.023250000085681677 -0.019000000320374966" rpy="0 0 0"/>
      <geometry>
        <box size="0.05000000074505806 0.06749999988824129 0.07400000281631947"/>
      </geometry>
    </collision>
    <inertial>
      <origin xyz="0.0037078693754091780581 -0.042127339671143418376 -0.019509671728381139388" rpy="0 0 0"/>
      <mass value="0.039499999999999979572"/>
      <inertia ixx="2.463550204721900056e-05" ixy="6.2323015740443222902e-07" ixz="1.4391447736752212052e-08" iyy="2.54752072219337203e-05" iyz="-4.0870433587618370763e-08" izz="1.3466679249845188709e-05"/>
    </inertial>
  </link>
  <joint name="right_wrist_roll" type="revolute">
    <origin xyz="0.019000000000002754269 -3.5806785314562716849e-10 -0.02700000015244990656" rpy="-1.9648186021258132771e-29 1.570796326794851927 0"/>
    <parent link="2xl430_gears_6"/>
    <child link="hand_2"/>
    <axis xyz="0 0 1"/>
    <limit effort="1" velocity="20" lower="-1.3962634015954635824" upper="1.9198621771937625091"/>
    <joint_properties friction="0.0"/>
  </joint>
  <link name="wrist_bearing_plate_2">
    <visual>
      <origin xyz="0 0 0" rpy="0 -0 0"/>
      <geometry>
        <mesh filename="../assemblies/right_arm_umi/meshes/right_wrist_bearing_plate_visual.stl"/>
      </geometry>
      <material name="wrist_bearing_plate_material">
        <color rgba="0.71932243125689054875 0.63128434304969727187 0.52422389360984933404 1.0"/>
      </material>
    </visual>
    <inertial>
      <origin xyz="-0.007583558312149987074 -0.015499999999999977338 -0.0018386323705903283732" rpy="0 0 0"/>
      <mass value="0.0049000367468305557062"/>
      <inertia ixx="4.9707430109150118544e-07" ixy="8.4884857117213009255e-23" ixz="1.8100904820814061718e-08" iyy="7.1268523603538563647e-07" iyz="4.7142878042649513411e-24" izz="1.1919657811600109234e-06"/>
    </inertial>
  </link>
  <joint name="right_wrist_pitch_fixed" type="fixed">
    <origin xyz="0.015500000000003963732 4.5519144009631418157e-15 -0.04500000000000373146" rpy="-3.0531133177156822825e-15 1.2051470932306205513e-13 -1.570796326794896558"/>
    <parent link="2xl430_gears_6"/>
    <child link="wrist_bearing_plate_2"/>
    <axis xyz="0 0 1"/>
    <limit effort="1" velocity="20"/>
    <joint_properties friction="0.0"/>
  </joint>
  <joint name="right_wrist_pitch_driven" type="revolute">
    <origin xyz="2.7755575615628913511e-17 3.1554436208840472216e-30 -0.0015999999999999972577" rpy="-3.8285686988021856593e-16 -1.2621774483536197294e-29 1.570796326794896558"/>
    <parent link="spur_1m_24t_driven_6"/>
    <child link="2xl430_gears_6"/>
    <axis xyz="0 0 1"/>
    <limit effort="1" velocity="20" lower="-1.9198621771937625091" upper="1.3962634015954635824"/>
    <joint_properties friction="0.0"/>
  </joint>
  <joint name="right_wrist_roll_fixed" type="fixed">
    <origin xyz="3.1554436208840472216e-30 -0.025299999999999999573 -0.051999999999999976796" rpy="1.570796326794896558 1.570796326794896558 0"/>
    <parent link="elb_yaw_link_2"/>
    <child link="spur_1m_24t_driven_6"/>
    <axis xyz="0 0 1"/>
    <limit effort="1" velocity="20"/>
    <joint_properties friction="0.0"/>
  </joint>
  <joint name="right_elbow_yaw_fixed" type="fixed">
    <origin xyz="3.4694469519536141888e-18 0 0.0016000000000000180744" rpy="3.141592653589793116 5.5511151240344703462e-17 -1.57079632679489678"/>
    <parent link="spur_1m_24t_driven_5"/>
    <child link="elb_yaw_link_2"/>
    <axis xyz="0 0 1"/>
    <limit effort="1" velocity="20"/>
    <joint_properties friction="0.0"/>
  </joint>
  <joint name="right_elbow_yaw_driven" type="revolute">
    <origin xyz="-3.5807115952857238028e-10 -0.027000000152453032531 -0.01900000000000281325" rpy="1.5707963267949576203 3.0519690799675378401e-14 -4.0239863453830675462e-14"/>
    <parent link="2xl430_gears_5"/>
    <child link="spur_1m_24t_driven_5"/>
    <axis xyz="0 0 1"/>
    <limit effort="1" velocity="20" lower="-2.6179938779914944114" upper="2.6179938779914944114"/>
    <joint_properties friction="0.0"/>
  </joint>
  <joint name="right_elbow_roll" type="revolute">
    <origin xyz="0 -0.018999999999999999528 -0.059000000000000024647" rpy="1.5707963267948952257 -4.3465231414242792334e-14 -2.6978419498660684154e-14"/>
    <parent link="sho_yaw_link_2"/>
    <child link="2xl430_gears_5"/>
    <axis xyz="0 0 1"/>
    <limit effort="1" velocity="20" lower="-1.9198621771937625091" upper="2.4434609527920612138"/>
    <joint_properties friction="0.0"/>
  </joint>
  <joint name="right_sho_yaw_fixed" type="fixed">
    <origin xyz="0 3.9443045261050590271e-31 0.0015999999999999972577" rpy="3.141592653589793116 -5.0487097934144755546e-29 -1.8301573001127473886e-28"/>
    <parent link="spur_1m_24t_driven_4"/>
    <child link="sho_yaw_link_2"/>
    <axis xyz="0 0 1"/>
    <limit effort="1" velocity="20"/>
    <joint_properties friction="0.0"/>
  </joint>
  <joint name="right_sho_yaw_driven" type="revolute">
    <origin xyz="-3.5806816886529979627e-10 -0.027000000152446666096 -0.019000000000003354483" rpy="1.5707963267949260899 -2.2055090607973039157e-14 7.6050277186033683693e-15"/>
    <parent link="2xl430_gears_4"/>
    <child link="spur_1m_24t_driven_4"/>
    <axis xyz="0 0 1"/>
    <limit effort="1" velocity="20" lower="-2.6179938779914944114" upper="2.6179938779914944114"/>
    <joint_properties friction="0.0"/>
  </joint>
  <joint name="right_sho_roll" type="revolute">
    <origin xyz="-0.018999999999999999528 9.3241386833306442318e-18 0.027000000000000006634" rpy="3.141592653589793116 1.5707963267948952257 0"/>
    <parent link="sho_pitch_link_2"/>
    <child link="2xl430_gears_4"/>
    <axis xyz="0 0 1"/>
    <limit effort="1" velocity="20" lower="-1.570796326794896558" upper="0.34906585039886589561"/>
    <joint_properties friction="0.0"/>
  </joint>
</robot>