<?xml version="1.0" ?><robot name="left_leg_OP3">  
  <link name="hip_yaw_link">    
    <visual>      
      <origin xyz="0 0 0" rpy="0 -0 0"/>      
      <geometry>        
        <mesh filename="package:///meshes/left_hip_yaw_link_visual.stl"/>        
      </geometry>      
      <material name="hip_yaw_link_material">        
        <color rgba="0.61568627450980395466 0.81176470588235294379 0.92941176470588238168 1.0"/>        
      </material>      
    </visual>    
    <collision>      
      <origin xyz="0 0 0" rpy="0 -0 0"/>      
      <geometry>        
        <mesh filename="package:///meshes/left_hip_yaw_link_collision.stl"/>        
      </geometry>      
    </collision>    
    <inertial>      
      <origin xyz="-4.8161475668077511176e-19 6.2050558167851175879e-21 -0.0098919667346054444834" rpy="0 0 0"/>      
      <mass value="0.017999999999999991701"/>      
      <inertia ixx="2.6483505271519536081e-06" ixy="0" ixz="0" iyy="7.7055357996008217629e-06" iyz="0" izz="7.773668280680532449e-06"/>      
    </inertial>    
  </link>  

  <link name="hip_roll_link">    
    <visual>      
      <origin xyz="0 0 0" rpy="0 -0 0"/>      
      <geometry>        
        <mesh filename="package:///meshes/left_hip_roll_link_visual.stl"/>        
      </geometry>      
      <material name="hip_roll_link_material">        
        <color rgba="0.51698661238356058423 0.5034781595109349972 0.49050589017722023844 1.0"/>        
      </material>      
    </visual>    
    <collision>      
      <origin xyz="0 0 0" rpy="0 -0 0"/>      
      <geometry>        
        <mesh filename="package:///meshes/left_hip_roll_link_collision.stl"/>        
      </geometry>      
    </collision>    
    <inertial>      
      <origin xyz="-0.011999849582186208896 -0.00049598090793881205625 -0.018504111838599408835" rpy="0 0 0"/>      
      <mass value="0.11059999999836231388"/>      
      <inertia ixx="2.2818802599019004628e-05" ixy="-4.6520143286869583124e-08" ixz="-4.6888548260596732511e-08" iyy="3.0871632082339549546e-05" iyz="-5.7477343899715808414e-07" izz="3.0871666424470027622e-05"/>      
    </inertial>    
  </link>  

  <link name="left_hip_pitch_link_xm430">    
    <visual>      
      <origin xyz="0 0 0" rpy="0 -0 0"/>      
      <geometry>        
        <mesh filename="package:///meshes/left_hip_pitch_link_xm430_visual.stl"/>        
      </geometry>      
      <material name="left_hip_pitch_link_xm430_material">        
        <color rgba="0.87072221357329560032 0.72641010956094276274 0.24785169615220692396 1.0"/>        
      </material>      
    </visual>    
    <collision>      
      <origin xyz="0 0 0" rpy="0 -0 0"/>      
      <geometry>        
        <mesh filename="package:///meshes/left_hip_pitch_link_xm430_collision.stl"/>        
      </geometry>      
    </collision>    
    <inertial>      
      <origin xyz="-0.00075729214155254573945 -0.050714785675264800746 -0.012656155119959967836" rpy="0 0 0"/>      
      <mass value="0.11480090135030571186"/>      
      <inertia ixx="6.6072773889430891575e-05" ixy="-4.6080149277680264912e-07" ixz="-1.8170739115383792803e-07" iyy="2.363363868537060128e-05" iyz="1.412525392535058454e-06" izz="6.2221728804333952868e-05"/>      
    </inertial>    
  </link>  

  <link name="left_calf_link">    
    <visual>      
      <origin xyz="0 0 0" rpy="0 -0 0"/>      
      <geometry>        
        <mesh filename="package:///meshes/left_calf_link_visual.stl"/>        
      </geometry>      
      <material name="left_calf_link_material">        
        <color rgba="0.522707147375079062 0.70740037950664136357 0.87533206831119547697 1.0"/>        
      </material>      
    </visual>    
    <collision>      
      <origin xyz="0 0 0" rpy="0 -0 0"/>      
      <geometry>        
        <mesh filename="package:///meshes/left_calf_link_collision.stl"/>        
      </geometry>      
    </collision>    
    <inertial>      
      <origin xyz="-0.0044698992063319873541 -0.040537655000345604317 -0.0094043191617600094268" rpy="0 0 0"/>      
      <mass value="0.031000000000000003247"/>      
      <inertia ixx="3.2349006752264489986e-05" ixy="1.49109562744182882e-06" ixz="1.9651815973589677934e-07" iyy="7.7183393965099210795e-06" iyz="-6.2686077155114589651e-07" izz="2.7323441483284245429e-05"/>      
    </inertial>    
  </link>  

  <link name="bearing_683">    
    <visual>      
      <origin xyz="0 0 0" rpy="0 -0 0"/>      
      <geometry>        
        <mesh filename="package:///meshes/left_bearing_683_visual.stl"/>        
      </geometry>      
      <material name="bearing_683_material">        
        <color rgba="0.64705882352941179736 0.64705882352941179736 0.64705882352941179736 1.0"/>        
      </material>      
    </visual>    
    <collision>      
      <origin xyz="0 0 0" rpy="0 -0 0"/>      
      <geometry>        
        <mesh filename="package:///meshes/left_bearing_683_collision.stl"/>        
      </geometry>      
    </collision>    
    <inertial>      
      <origin xyz="1.0732094295234589938e-19 -1.1092294808200096612e-18 -0.0015500000000000036318" rpy="0 0 0"/>      
      <mass value="0.00048694686130641804279"/>      
      <inertia ixx="2.1551456503319891521e-09" ixy="-1.641432842897370597e-27" ixz="1.4124781681235786249e-37" iyy="2.1551456503319874977e-09" iyz="1.5075576954774402725e-38" izz="3.5303647444715305817e-09"/>      
    </inertial>    
  </link>  

  <joint name="left_knee_front_rev_2" type="revolute">    
    <origin xyz="-0.005740251485476489772 0.01385819298766921559 -0.026199999999999820655" rpy="-8.9608725300154706869e-15 4.6129922847757146423e-15 1.5765933876572442163"/>    
    <parent link="left_calf_link"/>    
    <child link="bearing_683"/>    
    <axis xyz="0 0 1"/>    
    <limit effort="1" velocity="20" lower="-6.283185307179586232" upper="6.283185307179586232"/>    
    <joint_properties friction="0.0"/>    
  </joint>  

  <link name="bearing_683_2">    
    <visual>      
      <origin xyz="0 0 0" rpy="0 -0 0"/>      
      <geometry>        
        <mesh filename="package:///meshes/left_bearing_683_2_visual.stl"/>        
      </geometry>      
      <material name="bearing_683_2_material">        
        <color rgba="0.64705882352941179736 0.64705882352941179736 0.64705882352941179736 1.0"/>        
      </material>      
    </visual>    
    <collision>      
      <origin xyz="0 0 0" rpy="0 -0 0"/>      
      <geometry>        
        <mesh filename="package:///meshes/left_bearing_683_2_collision.stl"/>        
      </geometry>      
    </collision>    
    <inertial>      
      <origin xyz="-2.7648254672676440704e-17 -2.4186774283159990285e-19 -0.0015499999999999966929" rpy="0 0 0"/>      
      <mass value="0.00048694686130641804279"/>      
      <inertia ixx="2.1551456503319891521e-09" ixy="-1.3589423179364439532e-27" ixz="-1.8325046965530175966e-37" iyy="2.1551456503319874977e-09" iyz="-6.8551174496216249854e-38" izz="3.5303647444715305817e-09"/>      
    </inertial>    
  </link>  

  <joint name="left_knee_back_rev_2" type="revolute">    
    <origin xyz="0.0057402514854762824725 -0.013858192987669576413 -0.026200000000000028821" rpy="-6.5544379830050492951e-15 -5.7215737298236230488e-15 1.5736949077299540178"/>    
    <parent link="left_calf_link"/>    
    <child link="bearing_683_2"/>    
    <axis xyz="0 0 1"/>    
    <limit effort="1" velocity="20" lower="-6.283185307179586232" upper="6.283185307179586232"/>    
    <joint_properties friction="0.0"/>    
  </joint>  

  <link name="ank_pitch_link">    
    <visual>      
      <origin xyz="0 0 0" rpy="0 -0 0"/>      
      <geometry>        
        <mesh filename="package:///meshes/left_ank_pitch_link_visual.stl"/>        
      </geometry>      
      <material name="ank_pitch_link_material">        
        <color rgba="0.42838831031765539636 0.55128652208657225042 0.74128917770314906033 1.0"/>        
      </material>      
    </visual>    
    <collision>      
      <origin xyz="0 0 0" rpy="0 -0 0"/>      
      <geometry>        
        <mesh filename="package:///meshes/left_ank_pitch_link_collision.stl"/>        
      </geometry>      
    </collision>    
    <inertial>      
      <origin xyz="-0.012383885521091757276 -0.019663604311318489543 -0.018862066178913977632" rpy="0 0 0"/>      
      <mass value="0.15976376693924945749"/>      
      <inertia ixx="9.8184006245893959593e-05" ixy="-1.0738445982478892634e-06" ixz="-4.3555854013797547485e-08" iyy="4.2237181854198917923e-05" iyz="-4.1061630166272787775e-07" izz="0.00011168324060677566794"/>      
    </inertial>    
  </link>  

  <link name="ank_roll_link">    
    <visual>      
      <origin xyz="0 0 0" rpy="0 -0 0"/>      
      <geometry>        
        <mesh filename="package:///meshes/left_ank_roll_link_visual.stl"/>        
      </geometry>      
      <material name="ank_roll_link_material">        
        <color rgba="0.61568627450980395466 0.81176470588235283277 0.92941176470588227065 1.0"/>        
      </material>      
    </visual>    
    <collision>      
      <origin xyz="0 0 0" rpy="0 -0 0"/>      
      <geometry>        
        <mesh filename="package:///meshes/left_ank_roll_link_collision.stl"/>        
      </geometry>      
    </collision>    
    <inertial>      
      <origin xyz="-0.026981230777523939474 2.0010908493969122226e-12 -0.033733185742545704344" rpy="0 0 0"/>      
      <mass value="0.042600000000000012856"/>      
      <inertia ixx="3.7270477448017191749e-05" ixy="5.5466856520512913837e-16" ixz="-2.3925937758709647462e-06" iyy="3.7621548160199798892e-05" iyz="5.0816858843127805848e-12" izz="1.0126192914158308817e-05"/>      
    </inertial>    
  </link>  

  <joint name="left_ank_roll" type="revolute">    
    <origin xyz="-4.9960036108132044319e-16 -0.022750000000003208628 -0.019000000000006171674" rpy="-1.5707963267948434893 -1.0354577980633209865e-13 -3.141592653589788231"/>    
    <parent link="ank_pitch_link"/>    
    <child link="ank_roll_link"/>    
    <axis xyz="0 0 1"/>    
    <limit effort="1" velocity="20" lower="-1.570796326794896558" upper="1.570796326794896558"/>    
    <joint_properties friction="0.0"/>    
  </joint>  

  <joint name="left_ank_pitch" type="revolute">    
    <origin xyz="0.00049999999999989310807 -0.099999999999999977796 -0.029400000000000373751" rpy="-3.141592653589793116 5.1278425949876957843e-15 -1.5707963267948956698"/>    
    <parent link="left_calf_link"/>    
    <child link="ank_pitch_link"/>    
    <axis xyz="0 0 1"/>    
    <limit effort="1" velocity="20" lower="-0.785398163397448279" upper="1.8325957145940461324"/>    
    <joint_properties friction="0.0"/>    
  </joint>  

  <joint name="left_knee_pitch" type="revolute">    
    <origin xyz="1.549471946950906618e-16 -0.095999999999999932609 -0.009200000000000154235" rpy="-4.3715031594638534075e-15 -1.6535574677587582148e-16 3.720971275579667282e-17"/>    
    <parent link="left_hip_pitch_link_xm430"/>    
    <child link="left_calf_link"/>    
    <axis xyz="0 0 1"/>    
    <limit effort="1" velocity="20" lower="0" upper="1.9198621771937625091"/>    
    <joint_properties friction="0.0"/>    
  </joint>  

  <link name="xm430_plate">    
    <visual>      
      <origin xyz="0 0 0" rpy="0 -0 0"/>      
      <geometry>        
        <mesh filename="package:///meshes/left_xm430_plate_visual.stl"/>        
      </geometry>      
      <material name="xm430_plate_material">        
        <color rgba="0.61568627450980395466 0.81176470588235294379 0.92941176470588227065 1.0"/>        
      </material>      
    </visual>    
    <collision>      
      <origin xyz="0 0 0" rpy="0 -0 0"/>      
      <geometry>        
        <mesh filename="package:///meshes/left_xm430_plate_collision.stl"/>        
      </geometry>      
    </collision>    
    <inertial>      
      <origin xyz="3.1734841589327951698e-18 2.0382002117659448766e-18 -0.0024039046431217920424" rpy="0 0 0"/>      
      <mass value="0.0026999999999999997093"/>      
      <inertia ixx="1.293311664536341083e-07" ixy="-6.8936588702566453648e-08" ixz="2.0225744000250145272e-35" iyy="2.6720434385876693618e-07" iyz="6.3731332970867780622e-36" izz="3.8533537562751439267e-07"/>      
    </inertial>    
  </link>  

  <link name="knee_rod">    
    <visual>      
      <origin xyz="0 0 0" rpy="0 -0 0"/>      
      <geometry>        
        <mesh filename="package:///meshes/left_knee_rod_visual.stl"/>        
      </geometry>      
      <material name="knee_rod_material">        
        <color rgba="0.62051618944235198416 0.78640765248647581664 0.88594253031295022716 1.0"/>        
      </material>      
    </visual>    
    <collision>      
      <origin xyz="0 0 0" rpy="0 -0 0"/>      
      <geometry>        
        <mesh filename="package:///meshes/left_knee_rod_collision.stl"/>        
      </geometry>      
    </collision>    
    <inertial>      
      <origin xyz="0.01459454669113442217 -4.2302323076716512068e-05 -0.0015996227373186188998" rpy="0 0 0"/>      
      <mass value="0.0031629468613064179276"/>      
      <inertia ixx="2.589615283858449296e-08" ixy="3.5533843515669891641e-10" ixz="4.1682972813677818655e-10" iyy="6.0153250027080726266e-07" iyz="-1.2081818164427927846e-12" izz="6.2266858883153040768e-07"/>      
    </inertial>    
  </link>  

  <joint name="left_knee_front_rev_1" type="revolute">    
    <origin xyz="0.013858192987669298857 0.0057402514854763683413 -0.004999999999999966277" rpy="6.8152281266059555871e-15 1.7362503496778251608e-15 -3.1357955927274376862"/>    
    <parent link="xm430_plate"/>    
    <child link="knee_rod"/>    
    <axis xyz="0 0 1"/>    
    <limit effort="1" velocity="20" lower="-6.283185307179586232" upper="6.283185307179586232"/>    
    <joint_properties friction="0.0"/>    
  </joint>  

  <link name="knee_rod_2">    
    <visual>      
      <origin xyz="0 0 0" rpy="0 -0 0"/>      
      <geometry>        
        <mesh filename="package:///meshes/left_knee_rod_2_visual.stl"/>        
      </geometry>      
      <material name="knee_rod_2_material">        
        <color rgba="0.62051618944235198416 0.78640765248647581664 0.88594253031295022716 1.0"/>        
      </material>      
    </visual>    
    <collision>      
      <origin xyz="0 0 0" rpy="0 -0 0"/>      
      <geometry>        
        <mesh filename="package:///meshes/left_knee_rod_2_collision.stl"/>        
      </geometry>      
    </collision>    
    <inertial>      
      <origin xyz="0.014594546693013762603 4.2301026627538472068e-05 -0.0015996227373187487872" rpy="0 0 0"/>      
      <mass value="0.0031629468613064179276"/>      
      <inertia ixx="2.5896152775456331776e-08" ixy="-3.5532754507527878699e-10" ixz="4.1682972819100768222e-10" iyy="6.0153250030241281478e-07" iyz="1.2081447876865759557e-12" izz="6.22668588799920091e-07"/>      
    </inertial>    
  </link>  

  <joint name="left_knee_back_rev_1" type="revolute">    
    <origin xyz="-0.013858192987669284979 -0.0057402514854763379837 -0.0050000000000000321965" rpy="-1.7902130110758088672e-15 1.2957208404619350222e-14 -3.1386940726547267744"/>    
    <parent link="xm430_plate"/>    
    <child link="knee_rod_2"/>    
    <axis xyz="0 0 1"/>    
    <limit effort="1" velocity="20" lower="-6.283185307179586232" upper="6.283185307179586232"/>    
    <joint_properties friction="0.0"/>    
  </joint>  

  <joint name="left_knee_act" type="revolute">    
    <origin xyz="-0.00014999999999966212236 -0.061500000000000276668 -0.030400000000000156064" rpy="-1.2184487414508649095e-14 1.1572329706963895349e-14 1.5707963267948876762"/>    
    <parent link="left_hip_pitch_link_xm430"/>    
    <child link="xm430_plate"/>    
    <axis xyz="0 0 1"/>    
    <limit effort="1" velocity="20" lower="0" upper="1.9198621771937625091"/>    
    <joint_properties friction="0.0"/>    
  </joint>  

  <joint name="left_hip_pitch" type="revolute">    
    <origin xyz="-0.02400000071615559713 -0.019000000152441166856 -0.019000000152458167146" rpy="1.5707963267953672926 1.5707963267945022068 0"/>    
    <parent link="hip_roll_link"/>    
    <child link="left_hip_pitch_link_xm430"/>    
    <axis xyz="0 0 1"/>    
    <limit effort="1" velocity="20" lower="-1.570796326794896558" upper="1.570796326794896558"/>    
    <joint_properties friction="0.0"/>    
  </joint>  

  <joint name="left_hip_roll" type="revolute">    
    <origin xyz="0.019000000000000002998 -3.3408590380431292134e-18 -0.025999999999999998807" rpy="3.141592653589793116 -1.5707963267948943376 0"/>    
    <parent link="hip_yaw_link"/>    
    <child link="hip_roll_link"/>    
    <axis xyz="0 0 1"/>    
    <limit effort="1" velocity="20" lower="-0.785398163397448279" upper="0.785398163397448279"/>    
    <joint_properties friction="0.0"/>    
  </joint>  


</robot>