<?xml version="1.0" ?><robot name="left_leg_OP3">  
  <link name="hip_yaw_link">    
    <visual>      
      <origin xyz="0 0 0" rpy="0 -0 0"/>      
      <geometry>        
        <mesh filename="package:///meshes/left_hip_yaw_link_visual.stl"/>        
      </geometry>      
      <material name="hip_yaw_link_material">        
        <color rgba="0.61568627450980395466 0.81176470588235294379 0.92941176470588238168 1.0"/>        
      </material>      
    </visual>    
    <collision>      
      <origin xyz="0 0 0" rpy="0 -0 0"/>      
      <geometry>        
        <mesh filename="package:///meshes/left_hip_yaw_link_collision.stl"/>        
      </geometry>      
    </collision>    
    <inertial>      
      <origin xyz="-1.6124133946295534145e-19 -5.1127973666334958827e-19 -0.0098919667346054462181" rpy="0 0 0"/>      
      <mass value="0.01799999999999999864"/>      
      <inertia ixx="2.6483505271519540317e-06" ixy="0" ixz="0" iyy="7.7055357996008251511e-06" iyz="0" izz="7.7736682806805358371e-06"/>      
    </inertial>    
  </link>  

  <link name="hip_roll_link">    
    <visual>      
      <origin xyz="0 0 0" rpy="0 -0 0"/>      
      <geometry>        
        <mesh filename="package:///meshes/left_hip_roll_link_visual.stl"/>        
      </geometry>      
      <material name="hip_roll_link_material">        
        <color rgba="0.51698661238356058423 0.5034781595109349972 0.49050589017722023844 1.0"/>        
      </material>      
    </visual>    
    <collision>      
      <origin xyz="0 0 0" rpy="0 -0 0"/>      
      <geometry>        
        <mesh filename="package:///meshes/left_hip_roll_link_collision.stl"/>        
      </geometry>      
    </collision>    
    <inertial>      
      <origin xyz="-0.011999849582186212366 -0.00049598090793881194783 -0.018504111838599408835" rpy="0 0 0"/>      
      <mass value="0.11059999999836234164"/>      
      <inertia ixx="2.2818802599019004628e-05" ixy="-4.6520143286869794882e-08" ixz="-4.6888548260596878095e-08" iyy="3.0871632082339529218e-05" iyz="-5.7477343899715755475e-07" izz="3.0871666424470027622e-05"/>      
    </inertial>    
  </link>  

  <link name="left_hip_pitch_link_xm430">    
    <visual>      
      <origin xyz="0 0 0" rpy="0 -0 0"/>      
      <geometry>        
        <mesh filename="package:///meshes/left_hip_pitch_link_xm430_visual.stl"/>        
      </geometry>      
      <material name="left_hip_pitch_link_xm430_material">        
        <color rgba="0.87072221357329560032 0.72641010956094287376 0.24785169615220703498 1.0"/>        
      </material>      
    </visual>    
    <collision>      
      <origin xyz="0 0 0" rpy="0 -0 0"/>      
      <geometry>        
        <mesh filename="package:///meshes/left_hip_pitch_link_xm430_collision.stl"/>        
      </geometry>      
    </collision>    
    <inertial>      
      <origin xyz="-0.00075729214155312188448 -0.050714785675264786868 -0.012656155119959877631" rpy="0 0 0"/>      
      <mass value="0.1148009013503056841"/>      
      <inertia ixx="6.6072773889429766716e-05" ixy="-4.6080149277706459406e-07" ixz="-1.817073911531639545e-07" iyy="2.3633638685369937207e-05" iyz="1.4125253925344530372e-06" izz="6.2221728804333288794e-05"/>      
    </inertial>    
  </link>  

  <link name="left_calf_link">    
    <visual>      
      <origin xyz="0 0 0" rpy="0 -0 0"/>      
      <geometry>        
        <mesh filename="package:///meshes/left_calf_link_visual.stl"/>        
      </geometry>      
      <material name="left_calf_link_material">        
        <color rgba="0.52270714737507917302 0.70740037950664147459 0.87533206831119547697 1.0"/>        
      </material>      
    </visual>    
    <collision>      
      <origin xyz="0 0 0" rpy="0 -0 0"/>      
      <geometry>        
        <mesh filename="package:///meshes/left_calf_link_collision.stl"/>        
      </geometry>      
    </collision>    
    <inertial>      
      <origin xyz="-0.0044698992063320801618 -0.040537655000345430845 -0.0094043191617602540228" rpy="0 0 0"/>      
      <mass value="0.030999999999999999778"/>      
      <inertia ixx="3.2349006752263256706e-05" ixy="1.4910956274417595751e-06" ixz="1.9651815973586297743e-07" iyy="7.7183393965098499287e-06" iyz="-6.268607715511545786e-07" izz="2.7323441483284109904e-05"/>      
    </inertial>    
  </link>  

  <link name="bearing_683">    
    <visual>      
      <origin xyz="0 0 0" rpy="0 -0 0"/>      
      <geometry>        
        <mesh filename="package:///meshes/left_bearing_683_visual.stl"/>        
      </geometry>      
      <material name="bearing_683_material">        
        <color rgba="0.64705882352941179736 0.64705882352941179736 0.64705882352941179736 1.0"/>        
      </material>      
    </visual>    
    <collision>      
      <origin xyz="0 0 0" rpy="0 -0 0"/>      
      <geometry>        
        <mesh filename="package:///meshes/left_bearing_683_collision.stl"/>        
      </geometry>      
    </collision>    
    <inertial>      
      <origin xyz="1.0732094295242863011e-19 6.2549399515679300359e-19 -0.0015500000000000042823" rpy="0 0 0"/>      
      <mass value="0.00048694686130641793437"/>      
      <inertia ixx="2.1551456503319887385e-09" ixy="-2.5117832293793330346e-27" ixz="1.2351863617911424991e-37" iyy="2.1551456503319874977e-09" iyz="3.5328244942237977619e-38" izz="3.5303647444715322361e-09"/>      
    </inertial>    
  </link>  

  <joint name="left_knee_front_rev_2" type="revolute">    
    <origin xyz="-0.0057402514854767707972 0.013858192987668854768 -0.026199999999999168399" rpy="9.6260126850146175027e-15 -2.5081324750790058604e-14 1.5765933876572388872"/>    
    <parent link="left_calf_link"/>    
    <child link="bearing_683"/>    
    <axis xyz="0 0 1"/>    
    <limit effort="1" velocity="20" lower="-6.283185307179586232" upper="6.283185307179586232"/>    
    <joint_properties friction="0.0"/>    
  </joint>  

  <link name="bearing_683_2">    
    <visual>      
      <origin xyz="0 0 0" rpy="0 -0 0"/>      
      <geometry>        
        <mesh filename="package:///meshes/left_bearing_683_2_visual.stl"/>        
      </geometry>      
      <material name="bearing_683_2_material">        
        <color rgba="0.64705882352941179736 0.64705882352941179736 0.64705882352941179736 1.0"/>        
      </material>      
    </visual>    
    <collision>      
      <origin xyz="0 0 0" rpy="0 -0 0"/>      
      <geometry>        
        <mesh filename="package:///meshes/left_bearing_683_2_collision.stl"/>        
      </geometry>      
    </collision>    
    <inertial>      
      <origin xyz="1.0732094295230777801e-19 -2.418677428316055362e-19 -0.0015500000000000042823" rpy="0 0 0"/>      
      <mass value="0.00048694686130641793437"/>      
      <inertia ixx="2.1551456503319887385e-09" ixy="-1.3780027454701905363e-27" ixz="1.7697072896735004236e-37" iyy="2.1551456503319883249e-09" iyz="9.4913848506895919628e-39" izz="3.5303647444715322361e-09"/>      
    </inertial>    
  </link>  

  <joint name="left_knee_back_rev_2" type="revolute">    
    <origin xyz="0.0057402514854756501658 -0.013858192987669437635 -0.026199999999999720041" rpy="4.9560921740722585935e-15 -2.1168138603303528903e-14 1.5736949077299444699"/>    
    <parent link="left_calf_link"/>    
    <child link="bearing_683_2"/>    
    <axis xyz="0 0 1"/>    
    <limit effort="1" velocity="20" lower="-6.283185307179586232" upper="6.283185307179586232"/>    
    <joint_properties friction="0.0"/>    
  </joint>  

  <link name="ank_pitch_link">    
    <visual>      
      <origin xyz="0 0 0" rpy="0 -0 0"/>      
      <geometry>        
        <mesh filename="package:///meshes/left_ank_pitch_link_visual.stl"/>        
      </geometry>      
      <material name="ank_pitch_link_material">        
        <color rgba="0.42838831031765539636 0.55128652208657225042 0.74128917770314906033 1.0"/>        
      </material>      
    </visual>    
    <collision>      
      <origin xyz="0 0 0" rpy="0 -0 0"/>      
      <geometry>        
        <mesh filename="package:///meshes/left_ank_pitch_link_collision.stl"/>        
      </geometry>      
    </collision>    
    <inertial>      
      <origin xyz="-0.012383885521092090343 0.019663604311318874651 0.018862066178914671521" rpy="0 0 0"/>      
      <mass value="0.15976376693924948524"/>      
      <inertia ixx="9.8184006245898269296e-05" ixy="1.0738445982480728578e-06" ixz="4.3555854013565407518e-08" iyy="4.223718185419924996e-05" iyz="-4.1061630166343525614e-07" izz="0.0001116832406067800454"/>      
    </inertial>    
  </link>  

  <link name="ank_roll_link">    
    <visual>      
      <origin xyz="0 0 0" rpy="0 -0 0"/>      
      <geometry>        
        <mesh filename="package:///meshes/left_ank_roll_link_visual.stl"/>        
      </geometry>      
      <material name="ank_roll_link_material">        
        <color rgba="0.61568627450980395466 0.81176470588235305481 0.9294117647058824927 1.0"/>        
      </material>      
    </visual>    
    <collision>      
      <origin xyz="0 0 0" rpy="0 -0 0"/>      
      <geometry>        
        <mesh filename="package:///meshes/left_ank_roll_link_collision.stl"/>        
      </geometry>      
    </collision>    
    <inertial>      
      <origin xyz="-0.026981230777523998454 2.0010901539705145943e-12 -0.033733185742545857" rpy="0 0 0"/>      
      <mass value="0.042599999999999998979"/>      
      <inertia ixx="3.7270477448018181083e-05" ixy="5.5380108492315631755e-16" ixz="-2.3925937758710058273e-06" iyy="3.7621548160201323551e-05" iyz="5.0816858853237229248e-12" izz="1.012619291415873911e-05"/>      
    </inertial>    
  </link>  

  <joint name="left_ank_roll" type="revolute">    
    <origin xyz="-7.771561172376095783e-16 0.022750000000003930273 0.019000000000007229856" rpy="1.5707963267949729413 8.7734350778775080161e-14 3.1415926535897842342"/>    
    <parent link="ank_pitch_link"/>    
    <child link="ank_roll_link"/>    
    <axis xyz="0 0 1"/>    
    <limit effort="1" velocity="20" lower="-1.570796326794896558" upper="1.570796326794896558"/>    
    <joint_properties friction="0.0"/>    
  </joint>  

  <joint name="left_ank_pitch" type="revolute">    
    <origin xyz="0.00050000000000004402902 -0.099999999999997202238 -0.029400000000001407646" rpy="-2.1321242293024632049e-15 1.8823484437772641304e-14 -1.5707963267948981123"/>    
    <parent link="left_calf_link"/>    
    <child link="ank_pitch_link"/>    
    <axis xyz="0 0 1"/>    
    <limit effort="1" velocity="20" lower="-0.785398163397448279" upper="1.8325957145940461324"/>    
    <joint_properties friction="0.0"/>    
  </joint>  

  <joint name="left_knee_pitch" type="revolute">    
    <origin xyz="2.6591951153791853136e-17 -0.096000000000000029754 -0.0091999999999999634154" rpy="-1.3783391157486681965e-14 -1.4843341659320182562e-14 4.5251917072955735634e-15"/>    
    <parent link="left_hip_pitch_link_xm430"/>    
    <child link="left_calf_link"/>    
    <axis xyz="0 0 1"/>    
    <limit effort="1" velocity="20" lower="0" upper="1.9198621771937625091"/>    
    <joint_properties friction="0.0"/>    
  </joint>  

  <link name="xm430_plate">    
    <visual>      
      <origin xyz="0 0 0" rpy="0 -0 0"/>      
      <geometry>        
        <mesh filename="package:///meshes/left_xm430_plate_visual.stl"/>        
      </geometry>      
      <material name="xm430_plate_material">        
        <color rgba="0.61568627450980395466 0.81176470588235294379 0.92941176470588227065 1.0"/>        
      </material>      
    </visual>    
    <collision>      
      <origin xyz="0 0 0" rpy="0 -0 0"/>      
      <geometry>        
        <mesh filename="package:///meshes/left_xm430_plate_collision.stl"/>        
      </geometry>      
    </collision>    
    <inertial>      
      <origin xyz="3.3086273192764551093e-18 2.0177424182845293718e-18 -0.0024039046431217937771" rpy="0 0 0"/>      
      <mass value="0.0026999999999999997093"/>      
      <inertia ixx="1.293311664536341083e-07" ixy="-6.8936588702566453648e-08" ixz="1.4861959830666080916e-35" iyy="2.6720434385876693618e-07" iyz="-5.8703791399741623603e-36" izz="3.8533537562751439267e-07"/>      
    </inertial>    
  </link>  

  <link name="knee_rod">    
    <visual>      
      <origin xyz="0 0 0" rpy="0 -0 0"/>      
      <geometry>        
        <mesh filename="package:///meshes/left_knee_rod_visual.stl"/>        
      </geometry>      
      <material name="knee_rod_material">        
        <color rgba="0.62051618944235198416 0.78640765248647581664 0.88594253031295000511 1.0"/>        
      </material>      
    </visual>    
    <collision>      
      <origin xyz="0 0 0" rpy="0 -0 0"/>      
      <geometry>        
        <mesh filename="package:///meshes/left_knee_rod_collision.stl"/>        
      </geometry>      
    </collision>    
    <inertial>      
      <origin xyz="0.014594546691135086569 -4.23023230762537407e-05 -0.0015996227373175258071" rpy="0 0 0"/>      
      <mass value="0.0031629468613064183613"/>      
      <inertia ixx="2.5896152838585326758e-08" ixy="3.5533843516683890995e-10" ixz="4.1682972813638103646e-10" iyy="6.0153250027083944991e-07" iyz="-1.2081818132196025465e-12" izz="6.2266858883152744307e-07"/>      
    </inertial>    
  </link>  

  <joint name="left_knee_front_rev_1" type="revolute">    
    <origin xyz="0.013858192987669312735 0.0057402514854763449226 -0.0049999999999999992367" rpy="2.3955576787343955856e-15 2.4557124758423299065e-14 -3.1357955927274510088"/>    
    <parent link="xm430_plate"/>    
    <child link="knee_rod"/>    
    <axis xyz="0 0 1"/>    
    <limit effort="1" velocity="20" lower="-6.283185307179586232" upper="6.283185307179586232"/>    
    <joint_properties friction="0.0"/>    
  </joint>  

  <link name="knee_rod_2">    
    <visual>      
      <origin xyz="0 0 0" rpy="0 -0 0"/>      
      <geometry>        
        <mesh filename="package:///meshes/left_knee_rod_2_visual.stl"/>        
      </geometry>      
      <material name="knee_rod_2_material">        
        <color rgba="0.62051618944235198416 0.78640765248647581664 0.88594253031295000511 1.0"/>        
      </material>      
    </visual>    
    <collision>      
      <origin xyz="0 0 0" rpy="0 -0 0"/>      
      <geometry>        
        <mesh filename="package:///meshes/left_knee_rod_2_collision.stl"/>        
      </geometry>      
    </collision>    
    <inertial>      
      <origin xyz="0.014594546693013455557 4.2301026627630812212e-05 -0.0015996227373180340811" rpy="0 0 0"/>      
      <mass value="0.0031629468613064183613"/>      
      <inertia ixx="2.5896152775454644328e-08" ixy="-3.5532754507239285723e-10" ixz="4.1682972818975915649e-10" iyy="6.0153250030238083928e-07" iyz="1.2081447851119857907e-12" izz="6.2266858879995280765e-07"/>      
    </inertial>    
  </link>  

  <joint name="left_knee_back_rev_1" type="revolute">    
    <origin xyz="-0.013858192987669284979 -0.0057402514854763466573 -0.0050000000000000027062" rpy="-1.7626513399117519762e-14 2.0655748330454469805e-14 -3.1386940726547454261"/>    
    <parent link="xm430_plate"/>    
    <child link="knee_rod_2"/>    
    <axis xyz="0 0 1"/>    
    <limit effort="1" velocity="20" lower="-6.283185307179586232" upper="6.283185307179586232"/>    
    <joint_properties friction="0.0"/>    
  </joint>  

  <joint name="left_knee_act" type="revolute">    
    <origin xyz="-0.00015000000000014844124 -0.06150000000000001299 -0.030399999999999711975" rpy="-1.0766672541727743252e-14 1.3282815320613851332e-14 1.5707963267949027752"/>    
    <parent link="left_hip_pitch_link_xm430"/>    
    <child link="xm430_plate"/>    
    <axis xyz="0 0 1"/>    
    <limit effort="1" velocity="20" lower="0" upper="1.9198621771937625091"/>    
    <joint_properties friction="0.0"/>    
  </joint>  

  <joint name="left_hip_pitch" type="revolute">    
    <origin xyz="-0.024000000716156176528 -0.019000000152439990714 -0.019000000152458156738" rpy="1.5707963267953688469 1.5707963267944595742 0"/>    
    <parent link="hip_roll_link"/>    
    <child link="left_hip_pitch_link_xm430"/>    
    <axis xyz="0 0 1"/>    
    <limit effort="1" velocity="20" lower="-1.570796326794896558" upper="1.570796326794896558"/>    
    <joint_properties friction="0.0"/>    
  </joint>  

  <joint name="left_hip_roll" type="revolute">    
    <origin xyz="0.018999999999999434008 3.7043493321931432202e-16 -0.026000000000000141054" rpy="-3.141592653589793116 -1.5707963267948932273 0"/>    
    <parent link="hip_yaw_link"/>    
    <child link="hip_roll_link"/>    
    <axis xyz="0 0 1"/>    
    <limit effort="1" velocity="20" lower="-0.785398163397448279" upper="0.785398163397448279"/>    
    <joint_properties friction="0.0"/>    
  </joint>  


</robot>