<?xml version="1.0" ?><robot name="left_arm_gripper">  
  <link name="sho_pitch_link">    
    <visual>      
      <origin xyz="0 0 0" rpy="0 -0 0"/>      
      <geometry>        
        <mesh filename="package:///meshes/left_sho_pitch_link_visual.stl"/>        
      </geometry>      
      <material name="sho_pitch_link_material">        
        <color rgba="0.61568627450980395466 0.81176470588235294379 0.92941176470588238168 1.0"/>        
      </material>      
    </visual>    
    <collision>      
      <origin xyz="0 0 0" rpy="0 -0 0"/>      
      <geometry>        
        <mesh filename="package:///meshes/left_sho_pitch_link_collision.stl"/>        
      </geometry>      
    </collision>    
    <inertial>      
      <origin xyz="5.8254247020704377566e-11 -5.1264642561120945413e-05 0.0082440788127094641324" rpy="0 0 0"/>      
      <mass value="0.0086000000000000017403"/>      
      <inertia ixx="1.2272887040545705052e-06" ixy="-2.142993685402355376e-14" ixz="-8.5847197951622052158e-15" iyy="2.910730606036440833e-06" iyz="7.4623841398182389178e-09" izz="3.0803135950773263229e-06"/>      
    </inertial>    
  </link>  

  <link name="2xl430_gears">    
    <visual>      
      <origin xyz="0 0 0" rpy="0 -0 0"/>      
      <geometry>        
        <mesh filename="package:///meshes/left_2xl430_gears_visual.stl"/>        
      </geometry>      
      <material name="2xl430_gears_material">        
        <color rgba="0.7560598568794409946 0.8580469596269301169 0.91320266199377464478 1.0"/>        
      </material>      
    </visual>    
    <collision>      
      <origin xyz="0 0 0" rpy="0 -0 0"/>      
      <geometry>        
        <mesh filename="package:///meshes/left_2xl430_gears_collision.stl"/>        
      </geometry>      
    </collision>    
    <inertial>      
      <origin xyz="-0.011579403981036684446 -0.0024225766141425563241 -0.018551095523804701087" rpy="0 0 0"/>      
      <mass value="0.11800003674524910113"/>      
      <inertia ixx="2.7482298083239080344e-05" ixy="9.2729623433086684104e-07" ixz="-2.2634512004348376455e-08" iyy="3.2770742486673543319e-05" iyz="-6.5708346020177654519e-07" izz="3.5767957544057911369e-05"/>      
    </inertial>    
  </link>  

  <link name="spur_1m_24t_drive">    
    <visual>      
      <origin xyz="0 0 0" rpy="0 -0 0"/>      
      <geometry>        
        <mesh filename="package:///meshes/left_spur_1m_24t_drive_visual.stl"/>        
      </geometry>      
      <material name="spur_1m_24t_drive_material">        
        <color rgba="0.61568627450980406568 0.81176470588235294379 0.92941176470588238168 1.0"/>        
      </material>      
    </visual>    
    <collision>      
      <origin xyz="0 0 0" rpy="0 -0 0"/>      
      <geometry>        
        <mesh filename="package:///meshes/left_spur_1m_24t_drive_collision.stl"/>        
      </geometry>      
    </collision>    
    <inertial>      
      <origin xyz="-7.7588488539628132308e-15 -1.2127011873982159862e-16 0.0047949116178401399516" rpy="0 0 0"/>      
      <mass value="0.0032000000000000001533"/>      
      <inertia ixx="1.4019331346159892996e-07" ixy="1.6002409955622246819e-15" ixz="-2.1697588368762560743e-35" iyy="1.4019331260388783538e-07" iyz="2.6753973599902932927e-37" izz="2.3838919844264065941e-07"/>      
    </inertial>    
  </link>  

  <joint name="left_sho_yaw_drive" type="revolute">    
    <origin xyz="-0.024000000716139804208 -0.019000000152455391589 -0.019000000152449823126" rpy="1.570796326794926312 -3.985731521495478076e-14 1.5953258481899601487e-13"/>    
    <parent link="2xl430_gears"/>    
    <child link="spur_1m_24t_drive"/>    
    <axis xyz="0 0 1"/>    
    <limit effort="1" velocity="20" lower="-2.6179938779914944114" upper="2.6179938779914944114"/>    
    <joint_properties friction="0.0"/>    
  </joint>  

  <link name="spur_1m_24t_driven">    
    <visual>      
      <origin xyz="0 0 0" rpy="0 -0 0"/>      
      <geometry>        
        <mesh filename="package:///meshes/left_spur_1m_24t_driven_visual.stl"/>        
      </geometry>      
      <material name="spur_1m_24t_driven_material">        
        <color rgba="0.2313725490196078538 0.38039215686274507888 0.7058823529411765163 1.0"/>        
      </material>      
    </visual>    
    <collision>      
      <origin xyz="0 0 0" rpy="0 -0 0"/>      
      <geometry>        
        <mesh filename="package:///meshes/left_spur_1m_24t_driven_collision.stl"/>        
      </geometry>      
    </collision>    
    <inertial>      
      <origin xyz="2.01343209655368647e-18 -5.805102064921943026e-15 -0.00097054817521927832808" rpy="0 0 0"/>      
      <mass value="0.0026999999999999988419"/>      
      <inertia ixx="1.2036234079571060415e-07" ixy="-1.6319384257293200994e-38" ixz="-7.4397344778318253523e-36" iyy="1.2036234079571041886e-07" iyz="-1.1133336890428623179e-36" izz="2.2847261745924527375e-07"/>      
    </inertial>    
  </link>  

  <link name="sho_yaw_link">    
    <visual>      
      <origin xyz="0 0 0" rpy="0 -0 0"/>      
      <geometry>        
        <mesh filename="package:///meshes/left_sho_yaw_link_visual.stl"/>        
      </geometry>      
      <material name="sho_yaw_link_material">        
        <color rgba="0.61568627450980384364 0.81176470588235294379 0.92941176470588238168 1.0"/>        
      </material>      
    </visual>    
    <collision>      
      <origin xyz="0 0 0" rpy="0 -0 0"/>      
      <geometry>        
        <mesh filename="package:///meshes/left_sho_yaw_link_collision.stl"/>        
      </geometry>      
    </collision>    
    <inertial>      
      <origin xyz="2.1876905239562415376e-18 2.7707682582209097921e-18 -0.024303257848520151696" rpy="0 0 0"/>      
      <mass value="0.01450000000000000247"/>      
      <inertia ixx="9.0846670053041315019e-06" ixy="3.6224092806674809746e-13" ixz="2.905162411258700791e-35" iyy="5.6910950712097499617e-06" iyz="6.6361009573089289005e-36" izz="4.4819609845548967459e-06"/>      
    </inertial>    
  </link>  

  <link name="2xl430_gears_2">    
    <visual>      
      <origin xyz="0 0 0" rpy="0 -0 0"/>      
      <geometry>        
        <mesh filename="package:///meshes/left_2xl430_gears_2_visual.stl"/>        
      </geometry>      
      <material name="2xl430_gears_2_material">        
        <color rgba="0.7560598568794409946 0.8580469596269301169 0.91320266199377464478 1.0"/>        
      </material>      
    </visual>    
    <collision>      
      <origin xyz="0 0 0" rpy="0 -0 0"/>      
      <geometry>        
        <mesh filename="package:///meshes/left_2xl430_gears_2_collision.stl"/>        
      </geometry>      
    </collision>    
    <inertial>      
      <origin xyz="-0.011579403981035943719 -0.0024225766141466650166 -0.018551095523804794762" rpy="0 0 0"/>      
      <mass value="0.11800003674524910113"/>      
      <inertia ixx="2.7482298083242519298e-05" ixy="9.2729623433075217396e-07" ixz="-2.2634512004085309859e-08" iyy="3.2770742486673638187e-05" iyz="-6.570834602008262801e-07" izz="3.5767957544061780616e-05"/>      
    </inertial>    
  </link>  

  <link name="spur_1m_24t_drive_2">    
    <visual>      
      <origin xyz="0 0 0" rpy="0 -0 0"/>      
      <geometry>        
        <mesh filename="package:///meshes/left_spur_1m_24t_drive_2_visual.stl"/>        
      </geometry>      
      <material name="spur_1m_24t_drive_2_material">        
        <color rgba="0.61568627450980406568 0.81176470588235294379 0.92941176470588238168 1.0"/>        
      </material>      
    </visual>    
    <collision>      
      <origin xyz="0 0 0" rpy="0 -0 0"/>      
      <geometry>        
        <mesh filename="package:///meshes/left_spur_1m_24t_drive_2_collision.stl"/>        
      </geometry>      
    </collision>    
    <inertial>      
      <origin xyz="-7.7588488539628132308e-15 -1.2127011871397220448e-16 0.0047949116178401512273" rpy="0 0 0"/>      
      <mass value="0.0032000000000000001533"/>      
      <inertia ixx="1.4019331346159890349e-07" ixy="1.6002409968393611024e-15" ixz="-1.3435922781713994053e-35" iyy="1.4019331260388780891e-07" iyz="-6.7008882729667834827e-36" izz="2.3838919844264065941e-07"/>      
    </inertial>    
  </link>  

  <joint name="left_elbow_yaw_drive" type="revolute">    
    <origin xyz="-0.024000000716140737489 -0.019000000152457868774 -0.019000000152442970969" rpy="1.5707963267946287722 -5.6813306574568390567e-14 9.3319541222405133527e-14"/>    
    <parent link="2xl430_gears_2"/>    
    <child link="spur_1m_24t_drive_2"/>    
    <axis xyz="0 0 1"/>    
    <limit effort="1" velocity="20" lower="-2.6179938779914944114" upper="2.6179938779914944114"/>    
    <joint_properties friction="0.0"/>    
  </joint>  

  <link name="spur_1m_24t_driven_2">    
    <visual>      
      <origin xyz="0 0 0" rpy="0 -0 0"/>      
      <geometry>        
        <mesh filename="package:///meshes/left_spur_1m_24t_driven_2_visual.stl"/>        
      </geometry>      
      <material name="spur_1m_24t_driven_2_material">        
        <color rgba="0.2313725490196078538 0.38039215686274507888 0.7058823529411765163 1.0"/>        
      </material>      
    </visual>    
    <collision>      
      <origin xyz="0 0 0" rpy="0 -0 0"/>      
      <geometry>        
        <mesh filename="package:///meshes/left_spur_1m_24t_driven_2_collision.stl"/>        
      </geometry>      
    </collision>    
    <inertial>      
      <origin xyz="2.0134320965536013439e-18 -5.8051020649219382929e-15 -0.00097054817521928515855" rpy="0 0 0"/>      
      <mass value="0.0026999999999999988419"/>      
      <inertia ixx="1.2036234079571060415e-07" ixy="-2.1363557651178307935e-37" ixz="-3.5017353875817823724e-36" iyy="1.2036234079571041886e-07" iyz="2.4467597591869467297e-36" izz="2.2847261745924527375e-07"/>      
    </inertial>    
  </link>  

  <link name="elb_yaw_link">    
    <visual>      
      <origin xyz="0 0 0" rpy="0 -0 0"/>      
      <geometry>        
        <mesh filename="package:///meshes/left_elb_yaw_link_visual.stl"/>        
      </geometry>      
      <material name="elb_yaw_link_material">        
        <color rgba="0.61568627450980395466 0.81176470588235294379 0.92941176470588227065 1.0"/>        
      </material>      
    </visual>    
    <collision>      
      <origin xyz="0 0 0" rpy="0 -0 0"/>      
      <geometry>        
        <mesh filename="package:///meshes/left_elb_yaw_link_collision.stl"/>        
      </geometry>      
    </collision>    
    <inertial>      
      <origin xyz="5.3127688027669281628e-08 0.0019833638641961639885 -0.023416643551549952418" rpy="0 0 0"/>      
      <mass value="0.017500000000000001665"/>      
      <inertia ixx="1.4134344903109199776e-05" ixy="1.6945783921970149659e-12" ixz="-1.1286398721803475354e-11" iyy="6.6435900776211348874e-06" iyz="1.0545227077253059697e-06" izz="8.9925290757998993713e-06"/>      
    </inertial>    
  </link>  

  <link name="spur_1m_24t_driven_3">    
    <visual>      
      <origin xyz="0 0 0" rpy="0 -0 0"/>      
      <geometry>        
        <mesh filename="package:///meshes/left_spur_1m_24t_driven_3_visual.stl"/>        
      </geometry>      
      <material name="spur_1m_24t_driven_3_material">        
        <color rgba="0.2313725490196078538 0.38039215686274507888 0.7058823529411765163 1.0"/>        
      </material>      
    </visual>    
    <collision>      
      <origin xyz="0 0 0" rpy="0 -0 0"/>      
      <geometry>        
        <mesh filename="package:///meshes/left_spur_1m_24t_driven_3_collision.stl"/>        
      </geometry>      
    </collision>    
    <inertial>      
      <origin xyz="2.0134320965542003081e-18 -5.8051020649219469703e-15 -0.0025705481752192754774" rpy="0 0 0"/>      
      <mass value="0.0026999999999999988419"/>      
      <inertia ixx="1.2036234079571060415e-07" ixy="-6.9401384648807241474e-37" ixz="-1.8010930410254700166e-36" iyy="1.2036234079571041886e-07" iyz="-1.982963722125094476e-38" izz="2.2847261745924527375e-07"/>      
    </inertial>    
  </link>  

  <link name="2xl430_gears_3">    
    <visual>      
      <origin xyz="0 0 0" rpy="0 -0 0"/>      
      <geometry>        
        <mesh filename="package:///meshes/left_2xl430_gears_3_visual.stl"/>        
      </geometry>      
      <material name="2xl430_gears_3_material">        
        <color rgba="0.7560598568794409946 0.8580469596269301169 0.91320266199377464478 1.0"/>        
      </material>      
    </visual>    
    <collision>      
      <origin xyz="0 0 0" rpy="0 -0 0"/>      
      <geometry>        
        <mesh filename="package:///meshes/left_2xl430_gears_3_collision.stl"/>        
      </geometry>      
    </collision>    
    <inertial>      
      <origin xyz="0.00044890447619850019825 0.011579403622961125658 -0.024577423538310834428" rpy="0 0 0"/>      
      <mass value="0.11800003674524910113"/>      
      <inertia ixx="3.5767957544053940479e-05" ixy="2.2634512004660120975e-08" ixz="6.5708346020372101519e-07" iyy="2.7482298083236996643e-05" iyz="9.2729623432845004428e-07" izz="3.2770742486673224835e-05"/>      
    </inertial>    
  </link>  

  <link name="spur_1m_24t_drive_3">    
    <visual>      
      <origin xyz="0 0 0" rpy="0 -0 0"/>      
      <geometry>        
        <mesh filename="package:///meshes/left_spur_1m_24t_drive_3_visual.stl"/>        
      </geometry>      
      <material name="spur_1m_24t_drive_3_material">        
        <color rgba="0.61568627450980406568 0.81176470588235294379 0.92941176470588238168 1.0"/>        
      </material>      
    </visual>    
    <collision>      
      <origin xyz="0 0 0" rpy="0 -0 0"/>      
      <geometry>        
        <mesh filename="package:///meshes/left_spur_1m_24t_drive_3_collision.stl"/>        
      </geometry>      
    </collision>    
    <inertial>      
      <origin xyz="-7.7519099600589060025e-15 -1.2127011873982159862e-16 0.004794911617840143421" rpy="0 0 0"/>      
      <mass value="0.0032000000000000001533"/>      
      <inertia ixx="1.4019331346159890349e-07" ixy="1.6002409955622246819e-15" ixz="5.9600482537811428683e-36" iyy="1.4019331260388783538e-07" iyz="-4.385875400175586336e-37" izz="2.3838919844264055353e-07"/>      
    </inertial>    
  </link>  

  <joint name="left_wrist_pitch_drive" type="revolute">    
    <origin xyz="-1.5244435917471109994e-10 0.024000000358067929973 -0.0080000000000045659587" rpy="-5.3096416152614807834e-14 -6.1274079212673509226e-14 -1.5707963267947160357"/>    
    <parent link="2xl430_gears_3"/>    
    <child link="spur_1m_24t_drive_3"/>    
    <axis xyz="0 0 1"/>    
    <limit effort="1" velocity="20" lower="-1.9198621771937625091" upper="1.3962634015954635824"/>    
    <joint_properties friction="0.0"/>    
  </joint>  

  <link name="gripper_connector">    
    <visual>      
      <origin xyz="0 0 0" rpy="0 -0 0"/>      
      <geometry>        
        <mesh filename="package:///meshes/left_gripper_connector_visual.stl"/>        
      </geometry>      
      <material name="gripper_connector_material">        
        <color rgba="0.61568627450980395466 0.81176470588235283277 0.92941176470588238168 1.0"/>        
      </material>      
    </visual>    
    <collision>      
      <origin xyz="0 0 0" rpy="0 -0 0"/>      
      <geometry>        
        <mesh filename="package:///meshes/left_gripper_connector_collision.stl"/>        
      </geometry>      
    </collision>    
    <inertial>      
      <origin xyz="-0.00020299682521053517815 0.023971521766976103263 0.0085969861498480307227" rpy="0 0 0"/>      
      <mass value="0.009999999999999995004"/>      
      <inertia ixx="5.3001475666257255205e-06" ixy="2.3401437868255168398e-08" ixz="4.811583299767815884e-08" iyy="3.824595446707140777e-06" iyz="1.9316561248438855537e-08" izz="2.2623415168893589331e-06"/>      
    </inertial>    
  </link>  

  <link name="left_rail_guide">    
    <visual>      
      <origin xyz="0 0 0" rpy="0 -0 0"/>      
      <geometry>        
        <mesh filename="package:///meshes/left_rail_guide_visual.stl"/>        
      </geometry>      
      <material name="left_rail_guide_material">        
        <color rgba="0.61996873695689813655 0.81385103374119360797 0.93007060508235828156 1.0"/>        
      </material>      
    </visual>    
    <collision>      
      <origin xyz="0 0 0" rpy="0 -0 0"/>      
      <geometry>        
        <mesh filename="package:///meshes/left_rail_guide_collision.stl"/>        
      </geometry>      
    </collision>    
    <inertial>      
      <origin xyz="0.0092700665834928325931 0.0022613527845001648101 6.7965382068788760895e-05" rpy="0 0 0"/>      
      <mass value="0.032142035224833366558"/>      
      <inertia ixx="7.5992490868921683584e-06" ixy="2.1661862170734335066e-06" ixz="4.0652418928980950372e-06" iyy="2.7370569943527394969e-05" iyz="-9.4757783140872186427e-07" izz="3.0022397080929685896e-05"/>      
    </inertial>    
  </link>  

  <link name="rail">    
    <visual>      
      <origin xyz="0 0 0" rpy="0 -0 0"/>      
      <geometry>        
        <mesh filename="package:///meshes/left_rail_visual.stl"/>        
      </geometry>      
      <material name="rail_material">        
        <color rgba="0.64705882352941179736 0.64705882352941179736 0.64705882352941179736 1.0"/>        
      </material>      
    </visual>    
    <collision>      
      <origin xyz="0 0 0" rpy="0 -0 0"/>      
      <geometry>        
        <mesh filename="package:///meshes/left_rail_collision.stl"/>        
      </geometry>      
    </collision>    
    <inertial>      
      <origin xyz="0.022744777800883853036 -0.014233439403357412215 -0.0079907133176532404994" rpy="0 0 0"/>      
      <mass value="0.011899999999999995651"/>      
      <inertia ixx="2.9161025366903498589e-06" ixy="4.4570835808163398958e-09" ixz="-7.5225164550604597845e-07" iyy="3.6201306422454488178e-06" iyz="2.6765050785959659386e-08" izz="4.4681807873990682717e-06"/>      
    </inertial>    
  </link>  

  <joint name="left_gripper_pinion_1" type="prismatic">    
    <origin xyz="-0.028872600000000105819 -0.014175000000000003569 -0.0053499999999986058707" rpy="3.1415926535897518157 1.5707963267948832353 0"/>    
    <parent link="left_rail_guide"/>    
    <child link="rail"/>    
    <axis xyz="0 0 1"/>    
    <limit effort="1" velocity="20" lower="-0.036872599999999998432" upper="0"/>    
    <joint_properties friction="0.0"/>    
  </joint>  

  <link name="rail_2">    
    <visual>      
      <origin xyz="0 0 0" rpy="0 -0 0"/>      
      <geometry>        
        <mesh filename="package:///meshes/left_rail_2_visual.stl"/>        
      </geometry>      
      <material name="rail_2_material">        
        <color rgba="0.64705882352941179736 0.64705882352941179736 0.64705882352941179736 1.0"/>        
      </material>      
    </visual>    
    <collision>      
      <origin xyz="0 0 0" rpy="0 -0 0"/>      
      <geometry>        
        <mesh filename="package:///meshes/left_rail_2_collision.stl"/>        
      </geometry>      
    </collision>    
    <inertial>      
      <origin xyz="0.022744777800883853036 -0.014233439403357412215 -0.0079907133176532404994" rpy="0 0 0"/>      
      <mass value="0.011899999999999995651"/>      
      <inertia ixx="2.9161025366903498589e-06" ixy="4.4570835808163398958e-09" ixz="-7.5225164550604597845e-07" iyy="3.6201306422454488178e-06" iyz="2.6765050785959659386e-08" izz="4.4681807873990682717e-06"/>      
    </inertial>    
  </link>  

  <joint name="left_gripper_pinion_2" type="prismatic">    
    <origin xyz="0.062872600000001249709 0.014174999999999989692 -0.0053499999999986058707" rpy="-4.163336342340698169e-14 1.5707963267948832353 0"/>    
    <parent link="left_rail_guide"/>    
    <child link="rail_2"/>    
    <axis xyz="0 0 1"/>    
    <limit effort="1" velocity="20" lower="-0.036872599999999998432" upper="0"/>    
    <joint_properties friction="0.0"/>    
  </joint>  

  <link name="xc330">    
    <visual>      
      <origin xyz="0 0 0" rpy="0 -0 0"/>      
      <geometry>        
        <mesh filename="package:///meshes/left_xc330_visual.stl"/>        
      </geometry>      
      <material name="xc330_material">        
        <color rgba="0.66932535752643762539 0.72911795671409951325 0.67547870389434383487 1.0"/>        
      </material>      
    </visual>    
    <collision>      
      <origin xyz="0 0 0" rpy="0 -0 0"/>      
      <geometry>        
        <mesh filename="package:///meshes/left_xc330_collision.stl"/>        
      </geometry>      
    </collision>    
    <inertial>      
      <origin xyz="0.0080045171539631608526 -0.015558009851635294651 -0.011717805512819584948" rpy="0 0 0"/>      
      <mass value="0.026599999993091760775"/>      
      <inertia ixx="3.8683410666516270828e-06" ixy="-7.7688424002116287477e-10" ixz="5.7969695829175103584e-10" iyy="2.1626767907497007514e-06" iyz="8.3590274790168228173e-09" izz="3.3158761130056377969e-06"/>      
    </inertial>    
  </link>  

  <link name="spur_gear_(14_teeth)">    
    <visual>      
      <origin xyz="0 0 0" rpy="0 -0 0"/>      
      <geometry>        
        <mesh filename="package:///meshes/left_spur_gear_(14_teeth)_visual.stl"/>        
      </geometry>      
      <material name="spur_gear_(14_teeth)_material">        
        <color rgba="0.9176470588235294823 0.9176470588235294823 0.9176470588235294823 1.0"/>        
      </material>      
    </visual>    
    <collision>      
      <origin xyz="0 0 0" rpy="0 -0 0"/>      
      <geometry>        
        <mesh filename="package:///meshes/left_spur_gear_(14_teeth)_collision.stl"/>        
      </geometry>      
    </collision>    
    <inertial>      
      <origin xyz="5.0520117152175192388e-09 -3.0586955572509122447e-09 -0.0069037287088334906363" rpy="0 0 0"/>      
      <mass value="0.0012999999999999997235"/>      
      <inertia ixx="2.6445547365951355406e-08" ixy="2.5401821979637149987e-10" ixz="1.9678356781305539878e-14" iyy="2.6850679146645040953e-08" iyz="-1.191408660820745649e-14" izz="3.402743462305303444e-08"/>      
    </inertial>    
  </link>  

  <joint name="left_gripper_rack" type="revolute">    
    <origin xyz="0.0079999999999986401433 -0.02250000000000004427 -0.020000000000001599831" rpy="-1.5014551190391114451e-15 -9.4941075965749556743e-16 -6.694912156253297952e-18"/>    
    <parent link="xc330"/>    
    <child link="spur_gear_(14_teeth)"/>    
    <axis xyz="0 0 1"/>    
    <limit effort="1" velocity="20" lower="0" upper="5.2359877559829888227"/>    
    <joint_properties friction="0.0"/>    
  </joint>  

  <joint name="left_gripper_motor" type="fixed">    
    <origin xyz="-0.021950000000000021577 0.022600000000000005501 0.023299999999999959632" rpy="-1.2800691559891638774e-14 -5.2435289262723915078e-30 8.0982650358454429916e-30"/>    
    <parent link="left_rail_guide"/>    
    <child link="xc330"/>    
    <axis xyz="0 0 1"/>    
    <limit effort="1" velocity="20"/>    
    <joint_properties friction="0.0"/>    
  </joint>  

  <joint name="left_gripper_fixed" type="fixed">    
    <origin xyz="3.4694469519536141888e-18 0.037000000000000005107 0.03599999999999999728" rpy="1.5707963267948976682 1.570796326794896558 0"/>    
    <parent link="gripper_connector"/>    
    <child link="left_rail_guide"/>    
    <axis xyz="0 0 1"/>    
    <limit effort="1" velocity="20"/>    
    <joint_properties friction="0.0"/>    
  </joint>  

  <joint name="left_wrist_roll" type="revolute">    
    <origin xyz="0.019000000000008614165 -3.5807912190932711383e-10 -0.02700000015245084678" rpy="3.1415926535897877869 1.5707963267947964159 0"/>    
    <parent link="2xl430_gears_3"/>    
    <child link="gripper_connector"/>    
    <axis xyz="0 0 1"/>    
    <limit effort="1" velocity="20" lower="-1.9198621771937625091" upper="1.3962634015954635824"/>    
    <joint_properties friction="0.0"/>    
  </joint>  

  <link name="wrist_bearing_plate">    
    <visual>      
      <origin xyz="0 0 0" rpy="0 -0 0"/>      
      <geometry>        
        <mesh filename="package:///meshes/left_wrist_bearing_plate_visual.stl"/>        
      </geometry>      
      <material name="wrist_bearing_plate_material">        
        <color rgba="0.64496316278892629192 0.69011804996940528945 0.71706771073555886087 1.0"/>        
      </material>      
    </visual>    
    <collision>      
      <origin xyz="0 0 0" rpy="0 -0 0"/>      
      <geometry>        
        <mesh filename="package:///meshes/left_wrist_bearing_plate_collision.stl"/>        
      </geometry>      
    </collision>    
    <inertial>      
      <origin xyz="-0.0075835583121499619205 -0.015499999999999977338 -0.0018386323705903249038" rpy="0 0 0"/>      
      <mass value="0.0049000367468305539714"/>      
      <inertia ixx="4.9707430109150118544e-07" ixy="1.1845417796864442676e-22" ixz="1.8100904820813995543e-08" iyy="7.1268523603538510707e-07" iyz="1.9015146386035238466e-23" izz="1.1919657811600104999e-06"/>      
    </inertial>    
  </link>  

  <joint name="left_wrist_pitch_fixed" type="fixed">    
    <origin xyz="0.015500000000004770379 -6.3282712403633922804e-15 -0.045000000000001996736" rpy="-2.0039525594392854835e-14 -1.2819656091163158021e-13 -1.5707963267947810948"/>    
    <parent link="2xl430_gears_3"/>    
    <child link="wrist_bearing_plate"/>    
    <axis xyz="0 0 1"/>    
    <limit effort="1" velocity="20"/>    
    <joint_properties friction="0.0"/>    
  </joint>  

  <joint name="left_wrist_pitch_driven" type="revolute">    
    <origin xyz="-2.7755575615628913511e-17 -3.1554436208840472216e-30 -0.0015999999999999987756" rpy="3.1872271311673666698e-15 -9.0981076131151630778e-15 -1.570796326794896558"/>    
    <parent link="spur_1m_24t_driven_3"/>    
    <child link="2xl430_gears_3"/>    
    <axis xyz="0 0 1"/>    
    <limit effort="1" velocity="20" lower="-1.3962634015954635824" upper="1.9198621771937625091"/>    
    <joint_properties friction="0.0"/>    
  </joint>  

  <joint name="left_wrist_roll_fixed" type="fixed">    
    <origin xyz="3.1554436208840472216e-30 -0.025299999999999996103 -0.052000000000000032307" rpy="1.5707963267948923392 -1.5707963267948330532 0"/>    
    <parent link="elb_yaw_link"/>    
    <child link="spur_1m_24t_driven_3"/>    
    <axis xyz="0 0 1"/>    
    <limit effort="1" velocity="20"/>    
    <joint_properties friction="0.0"/>    
  </joint>  

  <joint name="left_elbow_yaw_fixed" type="fixed">    
    <origin xyz="3.4694469519536141888e-18 9.4663308626521416649e-30 0.0015999999999999903189" rpy="-3.1415926535897327199 -1.0860743139248627811e-15 -1.5707963267948983344"/>    
    <parent link="spur_1m_24t_driven_2"/>    
    <child link="elb_yaw_link"/>    
    <axis xyz="0 0 1"/>    
    <limit effort="1" velocity="20"/>    
    <joint_properties friction="0.0"/>    
  </joint>  

  <joint name="left_elbow_yaw_driven" type="revolute">    
    <origin xyz="-3.5806480697120335321e-10 -0.027000000152458680791 -0.018999999999996700084" rpy="1.5707963267946756236 9.4368957093097095842e-15 -7.876460240842920118e-14"/>    
    <parent link="2xl430_gears_2"/>    
    <child link="spur_1m_24t_driven_2"/>    
    <axis xyz="0 0 1"/>    
    <limit effort="1" velocity="20" lower="-2.6179938779914944114" upper="2.6179938779914944114"/>    
    <joint_properties friction="0.0"/>    
  </joint>  

  <joint name="left_elbow_roll" type="revolute">    
    <origin xyz="0 -0.018999999999999999528 -0.058999999999999996891" rpy="1.570796326794896558 -3.6926048046507072339e-14 -1.4375687432866819107e-15"/>    
    <parent link="sho_yaw_link"/>    
    <child link="2xl430_gears_2"/>    
    <axis xyz="0 0 1"/>    
    <limit effort="1" velocity="20" lower="-1.9198621771937625091" upper="2.4434609527920612138"/>    
    <joint_properties friction="0.0"/>    
  </joint>  

  <joint name="left_sho_yaw_fixed" type="fixed">    
    <origin xyz="3.4694469519536141888e-18 3.9443045261050590271e-31 0.0016000000000000007272" rpy="3.1415926535897877869 6.3478650967004975275e-30 -3.9477588016902497579e-30"/>    
    <parent link="spur_1m_24t_driven"/>    
    <child link="sho_yaw_link"/>    
    <axis xyz="0 0 1"/>    
    <limit effort="1" velocity="20"/>    
    <joint_properties friction="0.0"/>    
  </joint>  

  <joint name="left_sho_yaw_driven" type="revolute">    
    <origin xyz="-3.5806519207981502007e-10 -0.02700000015245392071 -0.019000000000003951228" rpy="1.570796326794921205 -4.6816437663822621511e-14 9.1955847476605894374e-14"/>    
    <parent link="2xl430_gears"/>    
    <child link="spur_1m_24t_driven"/>    
    <axis xyz="0 0 1"/>    
    <limit effort="1" velocity="20" lower="-2.6179938779914944114" upper="2.6179938779914944114"/>    
    <joint_properties friction="0.0"/>    
  </joint>  

  <joint name="left_sho_roll" type="revolute">    
    <origin xyz="-0.018999999999999930139 0.00099999999999997031368 0.026999999999999909489" rpy="3.1415926535897913396 1.5707963267947897545 0"/>    
    <parent link="sho_pitch_link"/>    
    <child link="2xl430_gears"/>    
    <axis xyz="0 0 1"/>    
    <limit effort="1" velocity="20" lower="-1.570796326794896558" upper="0.34906585039886589561"/>    
    <joint_properties friction="0.0"/>    
  </joint>  


</robot>