<?xml version="1.0" ?><robot name="sysID_XC330">  
  <link name="xc330">    
    <visual>      
      <origin xyz="0 0 0" rpy="0 -0 0"/>      
      <geometry>        
        <mesh filename="package:///meshes/xc330_visual.stl"/>        
      </geometry>      
      <material name="xc330_material">        
        <color rgba="0.66223384147661523702 0.70298350489095329241 0.66642745066522135478 1.0"/>        
      </material>      
    </visual>    
    <collision>      
      <origin xyz="0 0 0" rpy="0 -0 0"/>      
      <geometry>        
        <mesh filename="package:///meshes/xc330_collision.stl"/>        
      </geometry>      
    </collision>    
    <inertial>      
      <origin xyz="0.066714690229073753125 0.0084758273204493129321 0.0041230297691222921735" rpy="0 0 0"/>      
      <mass value="0.033753747264525735261"/>      
      <inertia ixx="6.5665698520956751865e-06" ixy="-4.2499540361030912073e-06" ixz="3.6918239891780174714e-07" iyy="1.5868647696393695199e-05" iyz="3.215363904117477846e-07" izz="2.009611369969435568e-05"/>      
    </inertial>    
  </link>  

  <link name="arm_330">    
    <visual>      
      <origin xyz="0 0 0" rpy="0 -0 0"/>      
      <geometry>        
        <mesh filename="package:///meshes/arm_330_visual.stl"/>        
      </geometry>      
      <material name="arm_330_material">        
        <color rgba="0.60471418196908388598 0.66722689075630248201 0.72422035480859026091 1.0"/>        
      </material>      
    </visual>    
    <collision>      
      <origin xyz="0 0 0" rpy="0 -0 0"/>      
      <geometry>        
        <mesh filename="package:///meshes/arm_330_collision.stl"/>        
      </geometry>      
    </collision>    
    <inertial>      
      <origin xyz="0.069949643575130365791 8.4075862912649064416e-18 -0.014500000000000025022" rpy="0 0 0"/>      
      <mass value="0.094500000000000014544"/>      
      <inertia ixx="9.6648053576060851517e-05" ixy="-8.2956289271718039458e-20" ixz="2.308164781267968424e-20" iyy="0.00017555912455268309937" iyz="3.8996094578431584124e-16" izz="9.8086683715700086358e-05"/>      
    </inertial>    
  </link>  

  <joint name="joint_0" type="revolute">    
    <origin xyz="0.089400000000000048872 0.021949857927858893586 0.0034193959459662037932" rpy="1.57079632679489678 -2.5673907444456749928e-16 1.5707963267948961139"/>    
    <parent link="xc330"/>    
    <child link="arm_330"/>    
    <axis xyz="0 0 1"/>    
    <limit effort="1" velocity="20" lower="-1.570796326794896558" upper="1.570796326794896558"/>    
    <joint_properties friction="0.0"/>    
  </joint>  


</robot>