<?xml version="1.0" ?>
<robot name="sysID_XC330">
  <link name="xc330">
    <visual>
      <origin xyz="0 0 0" rpy="0 -0 0"/>
      <geometry>
        <mesh filename="package:///meshes/xc330_visual.stl"/>
      </geometry>
      <material name="xc330_material">
        <color rgba="0.66223384147661523702 0.70298350489095318139 0.66642745066522124375 1.0"/>
      </material>
    </visual>
    <collision>
      <origin xyz="0 0 0" rpy="0 -0 0"/>
      <geometry>
        <mesh filename="package:///meshes/xc330_collision.stl"/>
      </geometry>
    </collision>
    <inertial>
      <origin xyz="0.067045862671275713307 0.0086608910511881617711 0.0041222017357433436702" rpy="0 0 0"/>
      <mass value="0.0337537472645257422"/>
      <inertia ixx="6.4808662584696902136e-06" ixy="-4.1297757912061726872e-06" ixz="3.5490498700440204987e-07" iyy="1.5492252679530571979e-05" iyz="3.1297490799071719933e-07" izz="1.9627489127736090014e-05"/>
    </inertial>
  </link>

  <link name="arm_330">
    <visual>
      <origin xyz="0 0 0" rpy="0 -0 0"/>
      <geometry>
        <mesh filename="package:///meshes/arm_330_visual.stl"/>
      </geometry>
      <material name="arm_330_material">
        <color rgba="0.60471418196908388598 0.66722689075630248201 0.72422035480858992784 1.0"/>
      </material>
    </visual>
    <collision>
      <origin xyz="0 0 0" rpy="0 -0 0"/>
      <geometry>
        <mesh filename="package:///meshes/arm_330_collision.stl"/>
      </geometry>
    </collision>
    <inertial>
      <origin xyz="0.069949643575130379669 -1.7550164134644652734e-17 -0.014500000000000021552" rpy="0 0 0"/>
      <mass value="0.094500000000000014544"/>
      <inertia ixx="9.6648053576060919279e-05" ixy="2.3134587371883078011e-20" ixz="2.4352197233561134748e-20" iyy="0.00017555912455268309937" iyz="3.8998349803653648699e-16" izz="9.808668371570015412e-05"/>
    </inertial>
  </link>

  <joint name="joint_0" type="revolute">
    <origin xyz="0.089400000000000034994 0.021949857927858897055 0.0034193959459662111658" rpy="1.5707963267948978903 -1.6653345369377634068e-16 1.5707963267948961139"/>
    <parent link="xc330"/>
    <child link="arm_330"/>
    <axis xyz="0 0 1"/>
    <limit effort="1" velocity="20" lower="-1.3962634015954635824" upper="1.3962634015954635824"/>
    <joint_properties friction="0.0"/>
  </joint>


</robot>