<?xml version="1.0" ?><robot name="left_leg">  
  <link name="hip_yaw_link">    
    <visual>      
      <origin xyz="0 0 0" rpy="0 -0 0"/>      
      <geometry>        
        <mesh filename="package:///meshes/left_hip_yaw_link_visual.stl"/>        
      </geometry>      
      <material name="hip_yaw_link_material">        
        <color rgba="0.61568627450980395466 0.81176470588235294379 0.92941176470588238168 1.0"/>        
      </material>      
    </visual>    
    <collision>      
      <origin xyz="0 0 0" rpy="0 -0 0"/>      
      <geometry>        
        <mesh filename="package:///meshes/left_hip_yaw_link_collision.stl"/>        
      </geometry>      
    </collision>    
    <inertial>      
      <origin xyz="-5.5101789230161046531e-19 -9.400948879750256241e-20 -0.0098390489054829069482" rpy="0 0 0"/>      
      <mass value="0.014999999999999990771"/>      
      <inertia ixx="2.1987528242868777693e-06" ixy="0" ixz="0" iyy="6.3830609964205725014e-06" iyz="0" izz="6.43505900590789551e-06"/>      
    </inertial>    
  </link>  

  <link name="hip_roll_link">    
    <visual>      
      <origin xyz="0 0 0" rpy="0 -0 0"/>      
      <geometry>        
        <mesh filename="package:///meshes/left_hip_roll_link_visual.stl"/>        
      </geometry>      
      <material name="hip_roll_link_material">        
        <color rgba="0.51698661238356036218 0.50347815951093466413 0.49050589017722012741 1.0"/>        
      </material>      
    </visual>    
    <collision>      
      <origin xyz="0 0 0" rpy="0 -0 0"/>      
      <geometry>        
        <mesh filename="package:///meshes/left_hip_roll_link_collision.stl"/>        
      </geometry>      
    </collision>    
    <inertial>      
      <origin xyz="-0.011999849582183095068 -0.00049598090794401926244 -0.018504111838595654893" rpy="0 0 0"/>      
      <mass value="0.1069997065911066636"/>      
      <inertia ixx="2.2075996228674991587e-05" ixy="-4.5005801829287202249e-08" ixz="-4.5362214342477961119e-08" iyy="2.9866686933523032459e-05" iyz="-5.5606319466522363485e-07" izz="2.9866720157734995072e-05"/>      
    </inertial>    
  </link>  

  <link name="left_hip_pitch_link">    
    <visual>      
      <origin xyz="0 0 0" rpy="0 -0 0"/>      
      <geometry>        
        <mesh filename="package:///meshes/left_hip_pitch_link_visual.stl"/>        
      </geometry>      
      <material name="left_hip_pitch_link_material">        
        <color rgba="0.60761611741666043951 0.79846263680522922002 0.91833701394314359856 1.0"/>        
      </material>      
    </visual>    
    <collision>      
      <origin xyz="0 0 0" rpy="0 -0 0"/>      
      <geometry>        
        <mesh filename="package:///meshes/left_hip_pitch_link_collision.stl"/>        
      </geometry>      
    </collision>    
    <inertial>      
      <origin xyz="-0.00027050657435686269051 -0.052544233896243547344 -0.011708030540600624508" rpy="0 0 0"/>      
      <mass value="0.12009145853012412331"/>      
      <inertia ixx="9.2171114293683332054e-05" ixy="-8.1626909615574738179e-07" ixz="9.1361764625058803553e-08" iyy="2.749851788394372005e-05" iyz="-7.0374231047573233814e-07" izz="9.3087169061334415292e-05"/>      
    </inertial>    
  </link>  

  <link name="left_calf_link">    
    <visual>      
      <origin xyz="0 0 0" rpy="0 -0 0"/>      
      <geometry>        
        <mesh filename="package:///meshes/left_calf_link_visual.stl"/>        
      </geometry>      
      <material name="left_calf_link_material">        
        <color rgba="0.64161931050581799685 0.73230206884914084142 0.73021281586259834118 1.0"/>        
      </material>      
    </visual>    
    <collision>      
      <origin xyz="0 0 0" rpy="0 -0 0"/>      
      <geometry>        
        <mesh filename="package:///meshes/left_calf_link_collision.stl"/>        
      </geometry>      
    </collision>    
    <inertial>      
      <origin xyz="0.0030643809491421114891 -0.051918376473646568603 -0.010859274740000894252" rpy="0 0 0"/>      
      <mass value="0.063407494529051477983"/>      
      <inertia ixx="2.8402167026679982985e-05" ixy="1.7540668239291480263e-06" ixz="3.8446529657821296979e-08" iyy="1.1034151088862593557e-05" iyz="9.0366527202502362276e-07" izz="3.1463822351439257375e-05"/>      
    </inertial>    
  </link>  

  <link name="ank_pitch_link">    
    <visual>      
      <origin xyz="0 0 0" rpy="0 -0 0"/>      
      <geometry>        
        <mesh filename="package:///meshes/left_ank_pitch_link_visual.stl"/>        
      </geometry>      
      <material name="ank_pitch_link_material">        
        <color rgba="0.63189161126160264814 0.7266866879354088038 0.78356373393969258601 1.0"/>        
      </material>      
    </visual>    
    <collision>      
      <origin xyz="0 0 0" rpy="0 -0 0"/>      
      <geometry>        
        <mesh filename="package:///meshes/left_ank_pitch_link_collision.stl"/>        
      </geometry>      
    </collision>    
    <inertial>      
      <origin xyz="0.00059528282565969061185 -4.0269682124278117109e-08 7.7616093800603145463e-08" rpy="0 0 0"/>      
      <mass value="0.0042238381753791614387"/>      
      <inertia ixx="3.9782741364676169024e-07" ixy="-1.6834347678987483542e-13" ixz="2.0919195898224290227e-14" iyy="4.3705254067418524844e-07" iyz="-1.6428822103450162122e-12" izz="8.885857453459039712e-08"/>      
    </inertial>    
  </link>  

  <link name="ank_roll_link">    
    <visual>      
      <origin xyz="0 0 0" rpy="0 -0 0"/>      
      <geometry>        
        <mesh filename="package:///meshes/left_ank_roll_link_visual.stl"/>        
      </geometry>      
      <material name="ank_roll_link_material">        
        <color rgba="0.61568627450980406568 0.81176470588235305481 0.92941176470588238168 1.0"/>        
      </material>      
    </visual>    
    <collision>      
      <origin xyz="0 0 0" rpy="0 -0 0"/>      
      <geometry>        
        <mesh filename="package:///meshes/left_ank_roll_link_collision.stl"/>        
      </geometry>      
    </collision>    
    <inertial>      
      <origin xyz="-1.5355491727298272213e-07 0.028527176446002854016 0.00033056891385439813019" rpy="0 0 0"/>      
      <mass value="0.016673310305476595622"/>      
      <inertia ixx="1.4264385574634784001e-05" ixy="2.1722527643768668096e-11" ixz="1.1340328062399660425e-11" iyy="1.3727735347489623458e-05" iyz="-1.0837574262194425641e-06" izz="3.2785855102133900423e-06"/>      
    </inertial>    
  </link>  

  <link name="ank_rr_link">    
    <visual>      
      <origin xyz="0 0 0" rpy="0 -0 0"/>      
      <geometry>        
        <mesh filename="package:///meshes/left_ank_rr_link_visual.stl"/>        
      </geometry>      
      <material name="ank_rr_link_material">        
        <color rgba="0.61568627450980395466 0.81176470588235294379 0.92941176470588238168 1.0"/>        
      </material>      
    </visual>    
    <collision>      
      <origin xyz="0 0 0" rpy="0 -0 0"/>      
      <geometry>        
        <mesh filename="package:///meshes/left_ank_rr_link_collision.stl"/>        
      </geometry>      
    </collision>    
    <inertial>      
      <origin xyz="-4.5249610960602415272e-05 0.0063096429836314591247 -2.0068527260727738741e-19" rpy="0 0 0"/>      
      <mass value="0.00044406186452863177783"/>      
      <inertia ixx="9.1077331171855694404e-09" ixy="7.4152655953211025158e-11" ixz="1.087902411501761198e-14" iyy="8.4004339691196273494e-09" iyz="-7.6387268954577241633e-34" izz="1.3144828106018414972e-08"/>      
    </inertial>    
  </link>  

  <link name="closing_left_ank_rev_L2_2">    
    <inertial>      
      <origin xyz="0 0 0" rpy="0 0 0"/>      
      <mass value="1e-9"/>      
      <inertia ixx="0" ixy="0" ixz="0" iyy="0" iyz="0" izz="0"/>      
    </inertial>    
  </link>  
  <joint name="closing_left_ank_rev_L2_2_frame" type="fixed">    
    <origin xyz="0 0.010000000000000008882 3.4694469519536141888e-18" rpy="7.0209964047544403985e-20 1.570796326794896558 0"/>    
    <parent link="ank_rr_link"/>    
    <child link="closing_left_ank_rev_L2_2"/>    
    <axis xyz="0 0 0"/>    
  </joint>  

  <joint name="left_ank_rev_L1" type="revolute">    
    <origin xyz="-0.018000000000000009048 0.015999999999999875433 -0.020600000000000513734" rpy="7.4037391911877385894e-16 3.3309192919083955654e-15 3.1233695685467846026"/>    
    <parent link="ank_roll_link"/>    
    <child link="ank_rr_link"/>    
    <axis xyz="0 0 1"/>    
    <limit effort="1" velocity="20" lower="-1.570796326794896558" upper="1.570796326794896558"/>    
    <joint_properties friction="0.0"/>    
  </joint>  

  <link name="ank_rr_link_2">    
    <visual>      
      <origin xyz="0 0 0" rpy="0 -0 0"/>      
      <geometry>        
        <mesh filename="package:///meshes/left_ank_rr_link_2_visual.stl"/>        
      </geometry>      
      <material name="ank_rr_link_2_material">        
        <color rgba="0.61568627450980395466 0.81176470588235294379 0.92941176470588238168 1.0"/>        
      </material>      
    </visual>    
    <collision>      
      <origin xyz="0 0 0" rpy="0 -0 0"/>      
      <geometry>        
        <mesh filename="package:///meshes/left_ank_rr_link_2_collision.stl"/>        
      </geometry>      
    </collision>    
    <inertial>      
      <origin xyz="-4.5249610960602415272e-05 -0.0063096429836314591247 2.0068527260725834478e-19" rpy="0 0 0"/>      
      <mass value="0.00044406186452863177783"/>      
      <inertia ixx="9.1077331171855694404e-09" ixy="-7.4152655953211012234e-11" ixz="-1.087902411501761198e-14" iyy="8.4004339691196273494e-09" iyz="-3.7801626426269979951e-32" izz="1.3144828106018414972e-08"/>      
    </inertial>    
  </link>  

  <link name="closing_left_ank_rev_S2_2">    
    <inertial>      
      <origin xyz="0 0 0" rpy="0 0 0"/>      
      <mass value="1e-9"/>      
      <inertia ixx="0" ixy="0" ixz="0" iyy="0" iyz="0" izz="0"/>      
    </inertial>    
  </link>  
  <joint name="closing_left_ank_rev_S2_2_frame" type="fixed">    
    <origin xyz="-3.4694469519536141888e-18 -0.010000000000000008882 0" rpy="-3.141592653589793116 -1.570796326794896558 0"/>    
    <parent link="ank_rr_link_2"/>    
    <child link="closing_left_ank_rev_S2_2"/>    
    <axis xyz="0 0 0"/>    
  </joint>  

  <joint name="left_ank_rev_S1" type="revolute">    
    <origin xyz="0.017999999999999995171 0.016000000000000097478 -0.020600000000000388833" rpy="-7.926878562135764579e-15 2.6891288333172127523e-15 0.026118548507318702784"/>    
    <parent link="ank_roll_link"/>    
    <child link="ank_rr_link_2"/>    
    <axis xyz="0 0 1"/>    
    <limit effort="1" velocity="20" lower="-1.570796326794896558" upper="1.570796326794896558"/>    
    <joint_properties friction="0.0"/>    
  </joint>  

  <joint name="left_ank_roll" type="revolute">    
    <origin xyz="0.001500000000000003067 -2.7755575615628913511e-17 -7.8062556418956319249e-18" rpy="2.2204460498118395574e-16 1.570796326794896336 0"/>    
    <parent link="ank_pitch_link"/>    
    <child link="ank_roll_link"/>    
    <axis xyz="0 0 1"/>    
    <limit effort="1" velocity="20" lower="-0.785398163397448279" upper="0.785398163397448279"/>    
    <joint_properties friction="0.0"/>    
  </joint>  

  <joint name="left_ank_pitch" type="revolute">    
    <origin xyz="3.1736313088862846164e-17 -0.099999999999999977796 -0.010800000000000118533" rpy="-6.6613381472604472254e-16 -2.7755575615334569785e-16 -3.141592653589793116"/>    
    <parent link="left_calf_link"/>    
    <child link="ank_pitch_link"/>    
    <axis xyz="0 0 1"/>    
    <limit effort="1" velocity="20" lower="-0.785398163397448279" upper="0.95993108859688125456"/>    
    <joint_properties friction="0.0"/>    
  </joint>  

  <link name="ank_motor_arm">    
    <visual>      
      <origin xyz="0 0 0" rpy="0 -0 0"/>      
      <geometry>        
        <mesh filename="package:///meshes/left_ank_motor_arm_visual.stl"/>        
      </geometry>      
      <material name="ank_motor_arm_material">        
        <color rgba="0.61568627450980395466 0.81176470588235294379 0.92941176470588238168 1.0"/>        
      </material>      
    </visual>    
    <collision>      
      <origin xyz="0 0 0" rpy="0 -0 0"/>      
      <geometry>        
        <mesh filename="package:///meshes/left_ank_motor_arm_collision.stl"/>        
      </geometry>      
    </collision>    
    <inertial>      
      <origin xyz="0.0060871522238996099777 -1.670823323238840618e-18 0.0014415996041339243158" rpy="0 0 0"/>      
      <mass value="0.00081249023041677498336"/>      
      <inertia ixx="1.258116822607804934e-08" ixy="1.9400109205511231185e-24" ixz="-3.0436827602313046902e-10" iyy="5.1146616052620583155e-08" iyz="-6.0031040072595639588e-27" izz="6.2546224268964395239e-08"/>      
    </inertial>    
  </link>  

  <link name="ball_joint_ball">    
    <visual>      
      <origin xyz="0 0 0" rpy="0 -0 0"/>      
      <geometry>        
        <mesh filename="package:///meshes/left_ball_joint_ball_visual.stl"/>        
      </geometry>      
      <material name="ball_joint_ball_material">        
        <color rgba="0.46677092258406521763 0.53140243424371769176 0.67257126234243258533 1.0"/>        
      </material>      
    </visual>    
    <collision>      
      <origin xyz="0 0 0" rpy="0 -0 0"/>      
      <geometry>        
        <mesh filename="package:///meshes/left_ball_joint_ball_collision.stl"/>        
      </geometry>      
    </collision>    
    <inertial>      
      <origin xyz="1.5123864871673479193e-17 -2.0055880864182788372e-17 0.0027461895781546361538" rpy="0 0 0"/>      
      <mass value="0.00010858471987832157455"/>      
      <inertia ixx="6.6064515645819380727e-10" ixy="3.9251294555153911806e-24" ixz="-4.8558691675758596705e-26" iyy="6.6066781021721444354e-10" iyz="9.2891545702760248622e-25" izz="4.0240894440645258492e-10"/>      
    </inertial>    
  </link>  

  <link name="ball_joint_container">    
    <visual>      
      <origin xyz="0 0 0" rpy="0 -0 0"/>      
      <geometry>        
        <mesh filename="package:///meshes/left_ball_joint_container_visual.stl"/>        
      </geometry>      
      <material name="ball_joint_container_material">        
        <color rgba="0.61568627450980395466 0.81176470588235294379 0.92941176470588238168 1.0"/>        
      </material>      
    </visual>    
    <collision>      
      <origin xyz="0 0 0" rpy="0 -0 0"/>      
      <geometry>        
        <mesh filename="package:///meshes/left_ball_joint_container_collision.stl"/>        
      </geometry>      
    </collision>    
    <inertial>      
      <origin xyz="-4.1400971897425941893e-19 -0.0027410199203514737723 1.449403213090352608e-17" rpy="0 0 0"/>      
      <mass value="0.00012018994143287794086"/>      
      <inertia ixx="3.7034315414442082721e-09" ixy="-2.0604994569612822723e-27" ixz="-5.907498195772848585e-16" iyy="9.098720990618852956e-10" iyz="-2.8169384865689208011e-26" izz="3.0460653612632305448e-09"/>      
    </inertial>    
  </link>  

  <link name="ank_motor_rod_long">    
    <visual>      
      <origin xyz="0 0 0" rpy="0 -0 0"/>      
      <geometry>        
        <mesh filename="package:///meshes/left_ank_motor_rod_long_visual.stl"/>        
      </geometry>      
      <material name="ank_motor_rod_long_material">        
        <color rgba="0.64705882352941179736 0.64705882352941179736 0.64705882352941179736 1.0"/>        
      </material>      
    </visual>    
    <collision>      
      <origin xyz="0 0 0" rpy="0 -0 0"/>      
      <geometry>        
        <mesh filename="package:///meshes/left_ank_motor_rod_long_collision.stl"/>        
      </geometry>      
    </collision>    
    <inertial>      
      <origin xyz="-9.7346416373000218777e-05 1.0182869582458364612e-06 -0.024100608682741352096" rpy="0 0 0"/>      
      <mass value="0.0013712857268636708969"/>      
      <inertia ixx="2.3699073636531176053e-07" ixy="-2.6102107799919155293e-12" ixz="-2.6767215486535000074e-09" iyy="2.3674128656418915843e-07" iyz="2.7996932450539530308e-11" izz="7.1763054928101012602e-09"/>      
    </inertial>    
  </link>  

  <link name="closing_left_ank_rev_L2_1">    
    <inertial>      
      <origin xyz="0 0 0" rpy="0 0 0"/>      
      <mass value="1e-9"/>      
      <inertia ixx="0" ixy="0" ixz="0" iyy="0" iyz="0" izz="0"/>      
    </inertial>    
  </link>  
  <joint name="closing_left_ank_rev_L2_1_frame" type="fixed">    
    <origin xyz="-0.00099994533629822399123 1.0455831645647672978e-05 -0.046000000000000040856" rpy="1.570796326794896558 4.2120208357513646006e-17 1.5603403046269419541"/>    
    <parent link="ank_motor_rod_long"/>    
    <child link="closing_left_ank_rev_L2_1"/>    
    <axis xyz="0 0 0"/>    
  </joint>  

  <joint name="left_ank_ball_L3" type="revolute">    
    <origin xyz="-6.9388939039072283776e-18 -0.012999999999999983791 0" rpy="1.570796326794896558 -0.014766188892399390031 3.1415926535897926719"/>    
    <parent link="ball_joint_container"/>    
    <child link="ank_motor_rod_long"/>    
    <axis xyz="0 0 1"/>    
    <limit effort="1" velocity="20" lower="-1.570796326794896558" upper="1.570796326794896558"/>    
    <joint_properties friction="0.0"/>    
  </joint>  

  <joint name="left_ank_ball_L2" type="revolute">    
    <origin xyz="0 -1.3877787807814456755e-17 0.0028266588050199839555" rpy="1.5707963267948932273 1.5530902478181201065 -1.9023473190431795717e-13"/>    
    <parent link="ball_joint_ball"/>    
    <child link="ball_joint_container"/>    
    <axis xyz="0 0 1"/>    
    <limit effort="1" velocity="20" lower="-0.785398163397448279" upper="0.785398163397448279"/>    
    <joint_properties friction="0.0"/>    
  </joint>  

  <joint name="left_ank_ball_L1" type="revolute">    
    <origin xyz="0.020000000000000010825 -2.7755575615628913511e-17 0.0029999999999999957256" rpy="-3.4619281425424893989e-15 -7.6118586548101139265e-16 1.5437324815808439737"/>    
    <parent link="ank_motor_arm"/>    
    <child link="ball_joint_ball"/>    
    <axis xyz="0 0 1"/>    
    <limit effort="1" velocity="20" lower="-1.570796326794896558" upper="1.570796326794896558"/>    
    <joint_properties friction="0.0"/>    
  </joint>  

  <joint name="left_ank_act_1" type="revolute">    
    <origin xyz="0.013499999999996870406 -0.044499999999992989608 0.0036000000000018725355" rpy="-2.8418571064124319536e-13 -1.8951096108239836653e-13 -0.2117339413023767436"/>    
    <parent link="left_calf_link"/>    
    <child link="ank_motor_arm"/>    
    <axis xyz="0 0 1"/>    
    <limit effort="1" velocity="20" lower="-1.570796326794896558" upper="1.570796326794896558"/>    
    <joint_properties friction="0.0"/>    
  </joint>  

  <link name="ank_motor_arm_2">    
    <visual>      
      <origin xyz="0 0 0" rpy="0 -0 0"/>      
      <geometry>        
        <mesh filename="package:///meshes/left_ank_motor_arm_2_visual.stl"/>        
      </geometry>      
      <material name="ank_motor_arm_2_material">        
        <color rgba="0.61568627450980395466 0.81176470588235294379 0.92941176470588238168 1.0"/>        
      </material>      
    </visual>    
    <collision>      
      <origin xyz="0 0 0" rpy="0 -0 0"/>      
      <geometry>        
        <mesh filename="package:///meshes/left_ank_motor_arm_2_collision.stl"/>        
      </geometry>      
    </collision>    
    <inertial>      
      <origin xyz="0.0060871522238996238555 2.5730388461129014546e-17 0.0014415996041339225811" rpy="0 0 0"/>      
      <mass value="0.00081249023041677498336"/>      
      <inertia ixx="1.258116822607804934e-08" ixy="-7.1067517580877391636e-25" ixz="-3.0436827602313046902e-10" iyy="5.1146616052620583155e-08" iyz="1.1715708408130232653e-26" izz="6.2546224268964395239e-08"/>      
    </inertial>    
  </link>  

  <link name="ball_joint_ball_2">    
    <visual>      
      <origin xyz="0 0 0" rpy="0 -0 0"/>      
      <geometry>        
        <mesh filename="package:///meshes/left_ball_joint_ball_2_visual.stl"/>        
      </geometry>      
      <material name="ball_joint_ball_2_material">        
        <color rgba="0.46677092258406521763 0.53140243424371769176 0.67257126234243258533 1.0"/>        
      </material>      
    </visual>    
    <collision>      
      <origin xyz="0 0 0" rpy="0 -0 0"/>      
      <geometry>        
        <mesh filename="package:///meshes/left_ball_joint_ball_2_collision.stl"/>        
      </geometry>      
    </collision>    
    <inertial>      
      <origin xyz="-1.6301596596295365312e-17 -1.3919131966227833821e-17 0.0027461895781546040614" rpy="0 0 0"/>      
      <mass value="0.00010858471987832157455"/>      
      <inertia ixx="6.6064515645822079404e-10" ixy="2.0431273111326108901e-24" ixz="-7.1807695416767398161e-24" iyy="6.6066781021724939192e-10" iyz="5.9408263992394913411e-24" izz="4.0240894440645584194e-10"/>      
    </inertial>    
  </link>  

  <link name="ball_joint_container_2">    
    <visual>      
      <origin xyz="0 0 0" rpy="0 -0 0"/>      
      <geometry>        
        <mesh filename="package:///meshes/left_ball_joint_container_2_visual.stl"/>        
      </geometry>      
      <material name="ball_joint_container_2_material">        
        <color rgba="0.61568627450980395466 0.81176470588235294379 0.92941176470588238168 1.0"/>        
      </material>      
    </visual>    
    <collision>      
      <origin xyz="0 0 0" rpy="0 -0 0"/>      
      <geometry>        
        <mesh filename="package:///meshes/left_ball_joint_container_2_collision.stl"/>        
      </geometry>      
    </collision>    
    <inertial>      
      <origin xyz="-4.1208874977212706031e-19 -0.0027410199203514451494 1.4662097118603990529e-17" rpy="0 0 0"/>      
      <mass value="0.00012018994143287794086"/>      
      <inertia ixx="3.7034315414442082721e-09" ixy="1.12787582079448234e-26" ixz="-5.907498195714668121e-16" iyy="9.0987209906188467521e-10" iyz="2.1797517416955128605e-25" izz="3.0460653612632321991e-09"/>      
    </inertial>    
  </link>  

  <link name="ank_motor_rod_short">    
    <visual>      
      <origin xyz="0 0 0" rpy="0 -0 0"/>      
      <geometry>        
        <mesh filename="package:///meshes/left_ank_motor_rod_short_visual.stl"/>        
      </geometry>      
      <material name="ank_motor_rod_short_material">        
        <color rgba="0.2313725490196078538 0.38039215686274507888 0.70588235294117662733 1.0"/>        
      </material>      
    </visual>    
    <collision>      
      <origin xyz="0 0 0" rpy="0 -0 0"/>      
      <geometry>        
        <mesh filename="package:///meshes/left_ank_motor_rod_short_collision.stl"/>        
      </geometry>      
    </collision>    
    <inertial>      
      <origin xyz="-0.00018125718822255970641 1.8957901221514275507e-06 -0.014161547524153638919" rpy="0 0 0"/>      
      <mass value="0.00073646453671346689789"/>      
      <inertia ixx="4.826821633760022957e-08" ixy="-2.7267361279491395417e-12" ixz="-1.40043213192764502e-09" iyy="4.8007565255284142283e-08" iyz="1.4646474015460089032e-11" izz="3.9909990774867184227e-09"/>      
    </inertial>    
  </link>  

  <link name="closing_left_ank_rev_S2_1">    
    <inertial>      
      <origin xyz="0 0 0" rpy="0 0 0"/>      
      <mass value="1e-9"/>      
      <inertia ixx="0" ixy="0" ixz="0" iyy="0" iyz="0" izz="0"/>      
    </inertial>    
  </link>  
  <joint name="closing_left_ank_rev_S2_1_frame" type="fixed">    
    <origin xyz="-0.00099994533629823439957 1.0455831645606039615e-05 -0.026499999999999995781" rpy="1.570796326794896558 3.7006396000235973601e-17 1.5603403046269499477"/>    
    <parent link="ank_motor_rod_short"/>    
    <child link="closing_left_ank_rev_S2_1"/>    
    <axis xyz="0 0 0"/>    
  </joint>  

  <joint name="left_ank_ball_S3" type="revolute">    
    <origin xyz="-3.4694469519536141888e-18 -0.012999999999999956035 1.3877787807814456755e-17" rpy="-1.57079632679489678 0.0012806128728100093627 2.0484006062427578669e-15"/>    
    <parent link="ball_joint_container_2"/>    
    <child link="ank_motor_rod_short"/>    
    <axis xyz="0 0 1"/>    
    <limit effort="1" velocity="20" lower="-1.570796326794896558" upper="1.570796326794896558"/>    
    <joint_properties friction="0.0"/>    
  </joint>  

  <joint name="left_ank_ball_S2" type="revolute">    
    <origin xyz="-2.7755575615628913511e-17 -1.3877787807814456755e-17 0.0028266588050205147808" rpy="1.5707963267949007768 -1.5463421405913249096 3.1415926535897660266"/>    
    <parent link="ball_joint_ball_2"/>    
    <child link="ball_joint_container_2"/>    
    <axis xyz="0 0 1"/>    
    <limit effort="1" velocity="20" lower="-0.785398163397448279" upper="0.785398163397448279"/>    
    <joint_properties friction="0.0"/>    
  </joint>  

  <joint name="left_ank_ball_S1" type="revolute">    
    <origin xyz="0.019999999999999941436 2.7755575615628913511e-17 0.0030000000000000009298" rpy="-9.581950962637239762e-16 -2.6688370162663054986e-15 -1.4417572640027598307"/>    
    <parent link="ank_motor_arm_2"/>    
    <child link="ball_joint_ball_2"/>    
    <axis xyz="0 0 1"/>    
    <limit effort="1" velocity="20" lower="-1.570796326794896558" upper="1.570796326794896558"/>    
    <joint_properties friction="0.0"/>    
  </joint>  

  <joint name="left_ank_act_2" type="revolute">    
    <origin xyz="0.013500000000003722564 -0.064499999999992174704 -0.025200000000000430389" rpy="-3.1415926535894738159 -6.5359609279554394162e-14 -0.22995607267359510772"/>    
    <parent link="left_calf_link"/>    
    <child link="ank_motor_arm_2"/>    
    <axis xyz="0 0 1"/>    
    <limit effort="1" velocity="20" lower="-1.570796326794896558" upper="1.570796326794896558"/>    
    <joint_properties friction="0.0"/>    
  </joint>  

  <joint name="left_knee" type="revolute">    
    <origin xyz="1.8578426952953642538e-17 -0.096000000000000015876 -0.0092000000000002270933" rpy="3.8302694346186014501e-15 -1.0361503322495635862e-14 -7.9936057778244984363e-15"/>    
    <parent link="left_hip_pitch_link"/>    
    <child link="left_calf_link"/>    
    <axis xyz="0 0 1"/>    
    <limit effort="1" velocity="20" lower="0" upper="1.9198621771937625091"/>    
    <joint_properties friction="0.0"/>    
  </joint>  

  <joint name="left_hip_pitch" type="revolute">    
    <origin xyz="-0.024000000716142607521 -0.0190000001524444663 -0.019000000152450565588" rpy="1.5707963267950835196 1.5707963267947200325 0"/>    
    <parent link="hip_roll_link"/>    
    <child link="left_hip_pitch_link"/>    
    <axis xyz="0 0 1"/>    
    <limit effort="1" velocity="20" lower="-1.570796326794896558" upper="1.570796326794896558"/>    
    <joint_properties friction="0.0"/>    
  </joint>  

  <joint name="left_hip_roll" type="revolute">    
    <origin xyz="0.01900000000000011402 -1.171599360750613133e-17 -0.025999999999999003075" rpy="-3.1415926535897917837 -1.5707963267948941155 0"/>    
    <parent link="hip_yaw_link"/>    
    <child link="hip_roll_link"/>    
    <axis xyz="0 0 1"/>    
    <limit effort="1" velocity="20" lower="-0.785398163397448279" upper="1.570796326794896558"/>    
    <joint_properties friction="0.0"/>    
  </joint>  


</robot>