<robot name="sysID_2XL430">
  <mujoco>
    <compiler strippath="false" balanceinertia="true" discardvisual="false" />
  </mujoco>
  <link name="2xl430">
    <visual>
      <origin xyz="0 0 0" rpy="0 -0 0" />
      <geometry>
        <mesh filename="../assemblies/sysID_2XL430/meshes/2xl430_visual.stl" />
      </geometry>
      <material name="2xl430_material">
        <color rgba="0.89659481946997110491 0.69622904450734190984 0.16511792881747547335 1.0" />
      </material>
    </visual>
    <inertial>
      <origin xyz="0.074499986305259030539 0.017588796249223753038 0.0051690504908866235709" rpy="0 0 0" />
      <mass value="0.1190623914835286512" />
      <inertia ixx="4.2349732073519884474e-05" ixy="-5.9033832120437049648e-06" ixz="-4.4962365618504234069e-07" iyy="4.1908376948263963342e-05" iyz="1.342781558304443756e-07" izz="5.4857461162179014353e-05" />
    </inertial>
  </link>

  <link name="arm_430">
    <visual>
      <origin xyz="0 0 0" rpy="0 -0 0" />
      <geometry>
        <mesh filename="../assemblies/sysID_2XL430/meshes/arm_430_visual.stl" />
      </geometry>
      <material name="arm_430_material">
        <color rgba="0.60471418196908388598 0.66722689075630237099 0.72422035480858992784 1.0" />
      </material>
    </visual>
    <inertial>
      <origin xyz="-0.070000487132978753135 5.2525006041377751977e-17 -0.018999999999999992589" rpy="0 0 0" />
      <mass value="0.094500000000000042299" />
      <inertia ixx="9.7686465200450792352e-05" ixy="-7.6232965252887030516e-20" ixz="-5.0610218598444445259e-20" iyy="0.00017605681504883534481" iyz="1.4671658849716709069e-16" izz="9.7562052053041468372e-05" />
    </inertial>
  </link>

  <joint name="joint_0" type="revolute">
    <origin xyz="0.057999999847552184684 0.032699858643998928887 0.0046193957935183882491" rpy="1.5707963267948972241 -5.7592819402422363305e-16 -1.5707963267948974462" />
    <parent link="2xl430" />
    <child link="arm_430" />
    <axis xyz="0 0 1" />
    <limit effort="1" velocity="20" lower="-1.570796326794896558" upper="1.570796326794896558" />
    <joint_properties friction="0.0" />
  </joint>


</robot>