<?xml version="1.0" ?><robot name="left_OP3_arm">  
  <link name="sho_pitch_link">    
    <visual>      
      <origin xyz="0 0 0" rpy="0 -0 0"/>      
      <geometry>        
        <mesh filename="package:///meshes/left_sho_pitch_link_visual.stl"/>        
      </geometry>      
      <material name="sho_pitch_link_material">        
        <color rgba="0.61568627450980395466 0.81176470588235283277 0.92941176470588227065 1.0"/>        
      </material>      
    </visual>    
    <collision>      
      <origin xyz="0 0 0" rpy="0 -0 0"/>      
      <geometry>        
        <mesh filename="package:///meshes/left_sho_pitch_link_collision.stl"/>        
      </geometry>      
    </collision>    
    <inertial>      
      <origin xyz="-3.0491385322450835177e-09 0.0021980515983192182999 -0.0084441034778716152209" rpy="0 0 0"/>      
      <mass value="0.0053168741776095304608"/>      
      <inertia ixx="8.004236836171299241e-07" ixy="1.1695537858705935527e-13" ixz="1.0217073886595013911e-14" iyy="1.8515753414330839236e-06" iyz="1.1638006198091620256e-07" izz="1.9553421197543973429e-06"/>      
    </inertial>    
  </link>  

  <link name="sho_roll_link">    
    <visual>      
      <origin xyz="0 0 0" rpy="0 -0 0"/>      
      <geometry>        
        <mesh filename="package:///meshes/left_sho_roll_link_visual.stl"/>        
      </geometry>      
      <material name="sho_roll_link_material">        
        <color rgba="0.41316897434350019491 0.53241982866399872876 0.7282853555714716709 1.0"/>        
      </material>      
    </visual>    
    <collision>      
      <origin xyz="0 0 0" rpy="0 -0 0"/>      
      <geometry>        
        <mesh filename="package:///meshes/left_sho_roll_link_collision.stl"/>        
      </geometry>      
    </collision>    
    <inertial>      
      <origin xyz="-0.044750001376316579649 -2.2393377634863600994e-09 -0.018770420156107039955" rpy="0 0 0"/>      
      <mass value="0.14104718485994710564"/>      
      <inertia ixx="2.5744677667987862931e-05" ixy="3.3646118940713150311e-08" ixz="-3.0796530997963203869e-12" iyy="0.00018303238190424636449" iyz="-7.9852770998995561417e-12" izz="0.00017803089038969846904"/>      
    </inertial>    
  </link>  

  <link name="elb_link">    
    <visual>      
      <origin xyz="0 0 0" rpy="0 -0 0"/>      
      <geometry>        
        <mesh filename="package:///meshes/left_elb_link_visual.stl"/>        
      </geometry>      
      <material name="elb_link_material">        
        <color rgba="0.632763333624367319 0.72211014553089536427 0.77571823267481221365 1.0"/>        
      </material>      
    </visual>    
    <collision>      
      <origin xyz="0 0 0" rpy="0 -0 0"/>      
      <geometry>        
        <mesh filename="package:///meshes/left_elb_link_collision.stl"/>        
      </geometry>      
    </collision>    
    <inertial>      
      <origin xyz="0.0035809919318981042052 0.051692930824585224536 0.01899999963962420782" rpy="0 0 0"/>      
      <mass value="0.012147845014428809707"/>      
      <inertia ixx="1.027507046601793286e-05" ixy="-8.3735105743537730385e-07" ixz="2.4555248808517769692e-13" iyy="3.0584432934239921256e-06" iyz="2.6984977430863263703e-14" izz="8.4465004716585834205e-06"/>      
    </inertial>    
  </link>  

  <joint name="left_elb" type="revolute">    
    <origin xyz="-0.089499999999999663158 -3.2265856653168611956e-16 5.9049987122250513494e-15" rpy="3.1415926535897367167 2.2793048768987009608e-14 -1.5707963267948858999"/>    
    <parent link="sho_roll_link"/>    
    <child link="elb_link"/>    
    <axis xyz="0 0 1"/>    
    <limit effort="1" velocity="20" lower="-1.570796326794896558" upper="1.570796326794896558"/>    
    <joint_properties friction="0.0"/>    
  </joint>  

  <joint name="left_sho_roll" type="revolute">    
    <origin xyz="-0.018999999999999999528 0.0089999999999999646255 -0.027499999999999986261" rpy="-6.3254956828146051492e-14 -1.5707963267948947816 0"/>    
    <parent link="sho_pitch_link"/>    
    <child link="sho_roll_link"/>    
    <axis xyz="0 0 1"/>    
    <limit effort="1" velocity="20" lower="-1.570796326794896558" upper="1.570796326794896558"/>    
    <joint_properties friction="0.0"/>    
  </joint>  


</robot>