<?xml version="1.0" ?><robot name="left_arm_hand">  
  <link name="sho_pitch_link">    
    <visual>      
      <origin xyz="0 0 0" rpy="0 -0 0"/>      
      <geometry>        
        <mesh filename="package:///meshes/left_sho_pitch_link_visual.stl"/>        
      </geometry>      
      <material name="sho_pitch_link_material">        
        <color rgba="0.61568627450980395466 0.81176470588235294379 0.92941176470588227065 1.0"/>        
      </material>      
    </visual>    
    <collision>      
      <origin xyz="0 0 0" rpy="0 -0 0"/>      
      <geometry>        
        <mesh filename="package:///meshes/left_sho_pitch_link_collision.stl"/>        
      </geometry>      
    </collision>    
    <inertial>      
      <origin xyz="5.8254247665095031947e-11 -5.1264642561120918308e-05 0.008244078812709491888" rpy="0 0 0"/>      
      <mass value="0.0085999999999999982708"/>      
      <inertia ixx="1.2272887040545796108e-06" ixy="-2.1429944209410366436e-14" ixz="-8.5847198183600595731e-15" iyy="2.9107306060364624323e-06" iyz="7.4623841398183100553e-09" izz="3.0803135950773496163e-06"/>      
    </inertial>    
  </link>  

  <link name="2xl430_gears">    
    <visual>      
      <origin xyz="0 0 0" rpy="0 -0 0"/>      
      <geometry>        
        <mesh filename="package:///meshes/left_2xl430_gears_visual.stl"/>        
      </geometry>      
      <material name="2xl430_gears_material">        
        <color rgba="0.7560598568794409946 0.8580469596269301169 0.91320266199377464478 1.0"/>        
      </material>      
    </visual>    
    <collision>      
      <origin xyz="0 0 0" rpy="0 -0 0"/>      
      <geometry>        
        <mesh filename="package:///meshes/left_2xl430_gears_collision.stl"/>        
      </geometry>      
    </collision>    
    <inertial>      
      <origin xyz="-0.011579403981036557811 -0.00242257661414001799 -0.018551095523803538823" rpy="0 0 0"/>      
      <mass value="0.1180000367452490595"/>      
      <inertia ixx="2.7482298083236085236e-05" ixy="9.2729623432982064947e-07" ixz="-2.2634512003761591072e-08" iyy="3.2770742486672784378e-05" iyz="-6.5708346020130210086e-07" izz="3.5767957544054292845e-05"/>      
    </inertial>    
  </link>  

  <link name="spur_1m_24t_drive">    
    <visual>      
      <origin xyz="0 0 0" rpy="0 -0 0"/>      
      <geometry>        
        <mesh filename="package:///meshes/left_spur_1m_24t_drive_visual.stl"/>        
      </geometry>      
      <material name="spur_1m_24t_drive_material">        
        <color rgba="0.61568627450980406568 0.81176470588235294379 0.92941176470588238168 1.0"/>        
      </material>      
    </visual>    
    <collision>      
      <origin xyz="0 0 0" rpy="0 -0 0"/>      
      <geometry>        
        <mesh filename="package:///meshes/left_spur_1m_24t_drive_collision.stl"/>        
      </geometry>      
    </collision>    
    <inertial>      
      <origin xyz="-7.7451324365296108088e-15 -1.2123883496324656278e-16 0.0047949116178401416863" rpy="0 0 0"/>      
      <mass value="0.0032000000000000001533"/>      
      <inertia ixx="1.4019331346159890349e-07" ixy="1.6002409988426406335e-15" ixz="-2.7590023788381681633e-36" iyy="1.4019331260388786185e-07" iyz="1.4447886653902400212e-37" izz="2.3838919844264058e-07"/>      
    </inertial>    
  </link>  

  <joint name="left_sho_yaw_drive" type="revolute">    
    <origin xyz="-0.024000000716141271784 -0.019000000152448497798 -0.019000000152447297369" rpy="1.570796326794886788 -1.6649913824689159326e-15 2.951073631457867516e-14"/>    
    <parent link="2xl430_gears"/>    
    <child link="spur_1m_24t_drive"/>    
    <axis xyz="0 0 1"/>    
    <limit effort="1" velocity="20" lower="-1.570796326794896558" upper="1.570796326794896558"/>    
    <joint_properties friction="0.0"/>    
  </joint>  

  <link name="spur_1m_24t_driven">    
    <visual>      
      <origin xyz="0 0 0" rpy="0 -0 0"/>      
      <geometry>        
        <mesh filename="package:///meshes/left_spur_1m_24t_driven_visual.stl"/>        
      </geometry>      
      <material name="spur_1m_24t_driven_material">        
        <color rgba="0.2313725490196078538 0.38039215686274507888 0.7058823529411765163 1.0"/>        
      </material>      
    </visual>    
    <collision>      
      <origin xyz="0 0 0" rpy="0 -0 0"/>      
      <geometry>        
        <mesh filename="package:///meshes/left_spur_1m_24t_driven_collision.stl"/>        
      </geometry>      
    </collision>    
    <inertial>      
      <origin xyz="2.3220762588065675388e-18 -5.798730325463341593e-15 -0.00096866348640038332785" rpy="0 0 0"/>      
      <mass value="0.0026999999999999992756"/>      
      <inertia ixx="1.2026541119643504741e-07" ixy="-4.4954231945806923146e-48" ixz="1.2986909681774403234e-36" iyy="1.2026541119643483565e-07" iyz="1.1676358468496116926e-37" izz="2.2827257365099366486e-07"/>      
    </inertial>    
  </link>  

  <link name="sho_yaw_link">    
    <visual>      
      <origin xyz="0 0 0" rpy="0 -0 0"/>      
      <geometry>        
        <mesh filename="package:///meshes/left_sho_yaw_link_visual.stl"/>        
      </geometry>      
      <material name="sho_yaw_link_material">        
        <color rgba="0.61568627450980395466 0.81176470588235294379 0.92941176470588238168 1.0"/>        
      </material>      
    </visual>    
    <collision>      
      <origin xyz="0 0 0" rpy="0 -0 0"/>      
      <geometry>        
        <mesh filename="package:///meshes/left_sho_yaw_link_collision.stl"/>        
      </geometry>      
    </collision>    
    <inertial>      
      <origin xyz="1.0511337010315895262e-18 4.8247714301903735524e-18 -0.024214576156328403156" rpy="0 0 0"/>      
      <mass value="0.014500000000000012879"/>      
      <inertia ixx="9.0490855102914924716e-06" ixy="3.599772940163048001e-13" ixz="-1.9687833522128349656e-35" iyy="5.6767199180624702083e-06" iyz="2.0673322214327139842e-36" izz="4.4590603637468125451e-06"/>      
    </inertial>    
  </link>  

  <link name="2xl430_gears_2">    
    <visual>      
      <origin xyz="0 0 0" rpy="0 -0 0"/>      
      <geometry>        
        <mesh filename="package:///meshes/left_2xl430_gears_2_visual.stl"/>        
      </geometry>      
      <material name="2xl430_gears_2_material">        
        <color rgba="0.7560598568794409946 0.8580469596269301169 0.91320266199377464478 1.0"/>        
      </material>      
    </visual>    
    <collision>      
      <origin xyz="0 0 0" rpy="0 -0 0"/>      
      <geometry>        
        <mesh filename="package:///meshes/left_2xl430_gears_2_collision.stl"/>        
      </geometry>      
    </collision>    
    <inertial>      
      <origin xyz="-0.011579403981034347773 -0.0024225766141400457455 -0.018551095523803212695" rpy="0 0 0"/>      
      <mass value="0.1180000367452490595"/>      
      <inertia ixx="2.7482298083235241591e-05" ixy="9.2729623433063994209e-07" ixz="-2.2634512003851717363e-08" iyy="3.2770742486672987666e-05" iyz="-6.5708346020124651432e-07" izz="3.5767957544053737191e-05"/>      
    </inertial>    
  </link>  

  <link name="spur_1m_24t_drive_2">    
    <visual>      
      <origin xyz="0 0 0" rpy="0 -0 0"/>      
      <geometry>        
        <mesh filename="package:///meshes/left_spur_1m_24t_drive_2_visual.stl"/>        
      </geometry>      
      <material name="spur_1m_24t_drive_2_material">        
        <color rgba="0.61568627450980406568 0.81176470588235294379 0.92941176470588238168 1.0"/>        
      </material>      
    </visual>    
    <collision>      
      <origin xyz="0 0 0" rpy="0 -0 0"/>      
      <geometry>        
        <mesh filename="package:///meshes/left_spur_1m_24t_drive_2_collision.stl"/>        
      </geometry>      
    </collision>    
    <inertial>      
      <origin xyz="-7.7451324365296108088e-15 -1.2123883496324676e-16 0.0047949116178401382168" rpy="0 0 0"/>      
      <mass value="0.0032000000000000001533"/>      
      <inertia ixx="1.4019331346159892996e-07" ixy="1.6002410041546426147e-15" ixz="3.0907108770750589246e-37" iyy="1.4019331260388791479e-07" iyz="-9.9147138716248503567e-38" izz="2.3838919844264058e-07"/>      
    </inertial>    
  </link>  

  <joint name="left_elbow_yaw_drive" type="revolute">    
    <origin xyz="-0.024000000716138836232 -0.019000000152446974711 -0.01900000015244691226" rpy="1.5707963267948983344 5.4262918776078815822e-15 5.0024824484551637689e-15"/>    
    <parent link="2xl430_gears_2"/>    
    <child link="spur_1m_24t_drive_2"/>    
    <axis xyz="0 0 1"/>    
    <limit effort="1" velocity="20" lower="-1.570796326794896558" upper="1.570796326794896558"/>    
    <joint_properties friction="0.0"/>    
  </joint>  

  <link name="spur_1m_24t_driven_2">    
    <visual>      
      <origin xyz="0 0 0" rpy="0 -0 0"/>      
      <geometry>        
        <mesh filename="package:///meshes/left_spur_1m_24t_driven_2_visual.stl"/>        
      </geometry>      
      <material name="spur_1m_24t_driven_2_material">        
        <color rgba="0.2313725490196078538 0.38039215686274507888 0.7058823529411765163 1.0"/>        
      </material>      
    </visual>    
    <collision>      
      <origin xyz="0 0 0" rpy="0 -0 0"/>      
      <geometry>        
        <mesh filename="package:///meshes/left_spur_1m_24t_driven_2_collision.stl"/>        
      </geometry>      
    </collision>    
    <inertial>      
      <origin xyz="2.3220762588070840732e-18 -5.8024355169241300519e-15 -0.00096866348640037638895" rpy="0 0 0"/>      
      <mass value="0.0026999999999999992756"/>      
      <inertia ixx="1.2026541119643504741e-07" ixy="0" ixz="-4.2376867976628461944e-38" iyy="1.2026541119643483565e-07" iyz="0" izz="2.2827257365099366486e-07"/>      
    </inertial>    
  </link>  

  <link name="elb_yaw_link">    
    <visual>      
      <origin xyz="0 0 0" rpy="0 -0 0"/>      
      <geometry>        
        <mesh filename="package:///meshes/left_elb_yaw_link_visual.stl"/>        
      </geometry>      
      <material name="elb_yaw_link_material">        
        <color rgba="0.61568627450980395466 0.81176470588235294379 0.9294117647058824927 1.0"/>        
      </material>      
    </visual>    
    <collision>      
      <origin xyz="0 0 0" rpy="0 -0 0"/>      
      <geometry>        
        <mesh filename="package:///meshes/left_elb_yaw_link_collision.stl"/>        
      </geometry>      
    </collision>    
    <inertial>      
      <origin xyz="5.2870889172999410497e-08 0.0019873558182742449146 -0.023365661199828729327" rpy="0 0 0"/>      
      <mass value="0.017499999999999998196"/>      
      <inertia ixx="1.4097804991252558057e-05" ixy="1.6900809684103730477e-12" ixz="-1.1184673662102780372e-11" iyy="6.6367696417680293553e-06" iyz="1.057990872258833363e-06" izz="8.9601142768980663591e-06"/>      
    </inertial>    
  </link>  

  <link name="spur_1m_24t_driven_3">    
    <visual>      
      <origin xyz="0 0 0" rpy="0 -0 0"/>      
      <geometry>        
        <mesh filename="package:///meshes/left_spur_1m_24t_driven_3_visual.stl"/>        
      </geometry>      
      <material name="spur_1m_24t_driven_3_material">        
        <color rgba="0.2313725490196078538 0.38039215686274507888 0.7058823529411765163 1.0"/>        
      </material>      
    </visual>    
    <collision>      
      <origin xyz="0 0 0" rpy="0 -0 0"/>      
      <geometry>        
        <mesh filename="package:///meshes/left_spur_1m_24t_driven_3_collision.stl"/>        
      </geometry>      
    </collision>    
    <inertial>      
      <origin xyz="-2.5433499356822610595e-17 -5.7954966230202228235e-15 -0.0025686634864003771161" rpy="0 0 0"/>      
      <mass value="0.0026999999999999992756"/>      
      <inertia ixx="1.2026541119643504741e-07" ixy="0" ixz="1.8719165699834955332e-37" iyy="1.2026541119643483565e-07" iyz="0" izz="2.2827257365099366486e-07"/>      
    </inertial>    
  </link>  

  <link name="2xl430_gears_3">    
    <visual>      
      <origin xyz="0 0 0" rpy="0 -0 0"/>      
      <geometry>        
        <mesh filename="package:///meshes/left_2xl430_gears_3_visual.stl"/>        
      </geometry>      
      <material name="2xl430_gears_3_material">        
        <color rgba="0.7560598568794409946 0.8580469596269301169 0.91320266199377464478 1.0"/>        
      </material>      
    </visual>    
    <collision>      
      <origin xyz="0 0 0" rpy="0 -0 0"/>      
      <geometry>        
        <mesh filename="package:///meshes/left_2xl430_gears_3_collision.stl"/>        
      </geometry>      
    </collision>    
    <inertial>      
      <origin xyz="0.00044890447620181747742 0.011579403622954375849 -0.02457742353831019258" rpy="0 0 0"/>      
      <mass value="0.1180000367452490595"/>      
      <inertia ixx="3.5767957544054143767e-05" ixy="2.2634512003808637796e-08" ixz="6.5708346020219582649e-07" iyy="2.7482298083236979703e-05" iyz="9.2729623433153303245e-07" izz="3.2770742486671795043e-05"/>      
    </inertial>    
  </link>  

  <link name="spur_1m_24t_drive_3">    
    <visual>      
      <origin xyz="0 0 0" rpy="0 -0 0"/>      
      <geometry>        
        <mesh filename="package:///meshes/left_spur_1m_24t_drive_3_visual.stl"/>        
      </geometry>      
      <material name="spur_1m_24t_drive_3_material">        
        <color rgba="0.61568627450980406568 0.81176470588235294379 0.92941176470588238168 1.0"/>        
      </material>      
    </visual>    
    <collision>      
      <origin xyz="0 0 0" rpy="0 -0 0"/>      
      <geometry>        
        <mesh filename="package:///meshes/left_spur_1m_24t_drive_3_collision.stl"/>        
      </geometry>      
    </collision>    
    <inertial>      
      <origin xyz="-7.7798269060491469507e-15 -1.1802132825242130039e-16 0.0047949116178401460231" rpy="0 0 0"/>      
      <mass value="0.0032000000000000001533"/>      
      <inertia ixx="1.4019331346159890349e-07" ixy="1.6002409988426406335e-15" ixz="7.8604389108627940054e-37" iyy="1.4019331260388786185e-07" iyz="-7.1848091828131645846e-37" izz="2.3838919844264058e-07"/>      
    </inertial>    
  </link>  

  <joint name="left_wrist_pitch_drive" type="revolute">    
    <origin xyz="-1.5244092793631480731e-10 0.024000000358059436767 -0.0080000000000068592632" rpy="7.9382516163034810891e-16 -8.2213715709867981657e-15 -1.5707963267949174302"/>    
    <parent link="2xl430_gears_3"/>    
    <child link="spur_1m_24t_drive_3"/>    
    <axis xyz="0 0 1"/>    
    <limit effort="1" velocity="20" lower="-1.570796326794896558" upper="1.570796326794896558"/>    
    <joint_properties friction="0.0"/>    
  </joint>  

  <link name="wrist_bearing_plate">    
    <visual>      
      <origin xyz="0 0 0" rpy="0 -0 0"/>      
      <geometry>        
        <mesh filename="package:///meshes/left_wrist_bearing_plate_visual.stl"/>        
      </geometry>      
      <material name="wrist_bearing_plate_material">        
        <color rgba="0.64496316278892629192 0.69011804996940528945 0.71706771073555886087 1.0"/>        
      </material>      
    </visual>    
    <collision>      
      <origin xyz="0 0 0" rpy="0 -0 0"/>      
      <geometry>        
        <mesh filename="package:///meshes/left_wrist_bearing_plate_collision.stl"/>        
      </geometry>      
    </collision>    
    <inertial>      
      <origin xyz="-0.0075896393545961402319 -0.015499999999999972133 -0.0018386110045718368107" rpy="0 0 0"/>      
      <mass value="0.0049000367468305548388"/>      
      <inertia ixx="4.9747313520140109893e-07" ixy="1.1209637001029811002e-22" ixz="1.8097509420524786327e-08" iyy="7.129502562758226908e-07" iyz="1.3782490438152935122e-23" izz="1.1926297952291895432e-06"/>      
    </inertial>    
  </link>  

  <joint name="left_wrist_roll_fixed" type="fixed">    
    <origin xyz="0.01550000000000526304 -1.7097434579227410723e-14 -0.04500000000000015099" rpy="-4.0578651550049919625e-14 -2.8349544933803382357e-13 -1.5707963267949061059"/>    
    <parent link="2xl430_gears_3"/>    
    <child link="wrist_bearing_plate"/>    
    <axis xyz="0 0 1"/>    
    <limit effort="1" velocity="20"/>    
    <joint_properties friction="0.0"/>    
  </joint>  

  <link name="hand">    
    <visual>      
      <origin xyz="0 0 0" rpy="0 -0 0"/>      
      <geometry>        
        <mesh filename="package:///meshes/left_hand_visual.stl"/>        
      </geometry>      
      <material name="hand_material">        
        <color rgba="0.61568627450980395466 0.81176470588235294379 0.92941176470588238168 1.0"/>        
      </material>      
    </visual>    
    <collision>      
      <origin xyz="0 0 0" rpy="0 -0 0"/>      
      <geometry>        
        <mesh filename="package:///meshes/left_hand_collision.stl"/>        
      </geometry>      
    </collision>    
    <inertial>      
      <origin xyz="-4.3038382212799598302e-08 -0.049723778585231907801 -0.017933572005390342741" rpy="0 0 0"/>      
      <mass value="0.017000000000001441042"/>      
      <inertia ixx="9.4921414617726207659e-06" ixy="-1.5549215897381269282e-11" ixz="-1.0809694196504873285e-11" iyy="4.0745028295199771232e-06" iyz="2.4719408559837088828e-07" izz="6.6623859523002746793e-06"/>      
    </inertial>    
  </link>  

  <joint name="left_wrist_roll" type="revolute">    
    <origin xyz="0.019000000000005953099 -3.5808089826616651408e-10 -0.027000000152448959401" rpy="3.3651291228740167001e-14 1.5707963267946079 0"/>    
    <parent link="2xl430_gears_3"/>    
    <child link="hand"/>    
    <axis xyz="0 0 1"/>    
    <limit effort="1" velocity="20" lower="-1.570796326794896558" upper="1.570796326794896558"/>    
    <joint_properties friction="0.0"/>    
  </joint>  

  <joint name="left_wrist_pitch_driven" type="revolute">    
    <origin xyz="0 0 -0.0015999999999999972577" rpy="2.6611337865898239456e-16 -4.9789962509675426656e-17 -1.57079632679489678"/>    
    <parent link="spur_1m_24t_driven_3"/>    
    <child link="2xl430_gears_3"/>    
    <axis xyz="0 0 1"/>    
    <limit effort="1" velocity="20" lower="-1.570796326794896558" upper="1.570796326794896558"/>    
    <joint_properties friction="0.0"/>    
  </joint>  

  <joint name="left_wrist_pitch_fixed" type="fixed">    
    <origin xyz="3.4694469519536141888e-18 -0.025300000000000003042 -0.05200000000000001843" rpy="1.570796326794896558 -1.570796326794896558 0"/>    
    <parent link="elb_yaw_link"/>    
    <child link="spur_1m_24t_driven_3"/>    
    <axis xyz="0 0 1"/>    
    <limit effort="1" velocity="20"/>    
    <joint_properties friction="0.0"/>    
  </joint>  

  <joint name="left_elbow_yaw_fixed" type="fixed">    
    <origin xyz="-1.498879432863449632e-17 3.1225022567582527699e-17 0.0015999999999999903189" rpy="3.141592653589793116 6.1232339945831272199e-17 -1.57079632679489678"/>    
    <parent link="spur_1m_24t_driven_2"/>    
    <child link="elb_yaw_link"/>    
    <axis xyz="0 0 1"/>    
    <limit effort="1" velocity="20"/>    
    <joint_properties friction="0.0"/>    
  </joint>  

  <joint name="left_elbow_yaw_driven" type="revolute">    
    <origin xyz="-3.5806832845985958613e-10 -0.027000000152447967139 -0.019000000000002903455" rpy="1.5707963267948912289 1.5707963267948950037 0"/>    
    <parent link="2xl430_gears_2"/>    
    <child link="spur_1m_24t_driven_2"/>    
    <axis xyz="0 0 1"/>    
    <limit effort="1" velocity="20" lower="-1.570796326794896558" upper="1.570796326794896558"/>    
    <joint_properties friction="0.0"/>    
  </joint>  

  <joint name="left_elbow_roll" type="revolute">    
    <origin xyz="0 -0.019000000000000002998 -0.059000000000000010769" rpy="1.570796326794896558 7.8238344481275579773e-14 -2.6785925512137038591e-14"/>    
    <parent link="sho_yaw_link"/>    
    <child link="2xl430_gears_2"/>    
    <axis xyz="0 0 1"/>    
    <limit effort="1" velocity="20" lower="-1.570796326794896558" upper="1.570796326794896558"/>    
    <joint_properties friction="0.0"/>    
  </joint>  

  <joint name="left_sho_yaw_fixed" type="fixed">    
    <origin xyz="-6.9388939039072283776e-18 -3.9443045261050590271e-31 0.0015999999999999972577" rpy="-3.141592653589793116 3.4918029198749163057e-28 2.4932009224355828724e-30"/>    
    <parent link="spur_1m_24t_driven"/>    
    <child link="sho_yaw_link"/>    
    <axis xyz="0 0 1"/>    
    <limit effort="1" velocity="20"/>    
    <joint_properties friction="0.0"/>    
  </joint>  

  <joint name="left_sho_yaw_driven" type="revolute">    
    <origin xyz="-3.5807099299511868651e-10 -0.027000000152450111257 -0.019000000000003024886" rpy="1.5707963267949034414 2.5500465800399195135e-14 -4.8895009770147760892e-15"/>    
    <parent link="2xl430_gears"/>    
    <child link="spur_1m_24t_driven"/>    
    <axis xyz="0 0 1"/>    
    <limit effort="1" velocity="20" lower="-1.570796326794896558" upper="1.570796326794896558"/>    
    <joint_properties friction="0.0"/>    
  </joint>  

  <joint name="left_sho_roll" type="revolute">    
    <origin xyz="-0.018999999999999999528 0.0010000000000000076102 0.027000000000000003164" rpy="-3.141592653589793116 1.5707963267947588903 0"/>    
    <parent link="sho_pitch_link"/>    
    <child link="2xl430_gears"/>    
    <axis xyz="0 0 1"/>    
    <limit effort="1" velocity="20" lower="-1.570796326794896558" upper="0"/>    
    <joint_properties friction="0.0"/>    
  </joint>  


</robot>