<?xml version="1.0" ?><robot name="left_arm_hand">  
  <link name="sho_pitch_link">    
    <visual>      
      <origin xyz="0 0 0" rpy="0 -0 0"/>      
      <geometry>        
        <mesh filename="package:///meshes/left_sho_pitch_link_visual.stl"/>        
      </geometry>      
      <material name="sho_pitch_link_material">        
        <color rgba="0.61568627450980395466 0.81176470588235294379 0.92941176470588238168 1.0"/>        
      </material>      
    </visual>    
    <collision>      
      <origin xyz="0 0 0" rpy="0 -0 0"/>      
      <geometry>        
        <mesh filename="package:///meshes/left_sho_pitch_link_collision.stl"/>        
      </geometry>      
    </collision>    
    <inertial>      
      <origin xyz="5.8254248833227925391e-11 -5.1264642561120870874e-05 0.0082440788127094936227" rpy="0 0 0"/>      
      <mass value="0.0086000000000000017403"/>      
      <inertia ixx="1.2272887040545796108e-06" ixy="-2.1429944210751515172e-14" ixz="-8.5847198977296208559e-15" iyy="2.9107306060364624323e-06" iyz="7.4623841398182868942e-09" izz="3.0803135950773496163e-06"/>      
    </inertial>    
  </link>  

  <link name="2xl430_gears">    
    <visual>      
      <origin xyz="0 0 0" rpy="0 -0 0"/>      
      <geometry>        
        <mesh filename="package:///meshes/left_2xl430_gears_visual.stl"/>        
      </geometry>      
      <material name="2xl430_gears_material">        
        <color rgba="0.7560598568794409946 0.8580469596269301169 0.91320266199377464478 1.0"/>        
      </material>      
    </visual>    
    <collision>      
      <origin xyz="0 0 0" rpy="0 -0 0"/>      
      <geometry>        
        <mesh filename="package:///meshes/left_2xl430_gears_collision.stl"/>        
      </geometry>      
    </collision>    
    <inertial>      
      <origin xyz="-0.011579403981037355784 -0.0024225766141417279936 -0.018551095523800655712" rpy="0 0 0"/>      
      <mass value="0.11800003674524910113"/>      
      <inertia ixx="2.7482298083236796743e-05" ixy="9.2729623432893200603e-07" ixz="-2.2634512003524170384e-08" iyy="3.2770742486672269382e-05" iyz="-6.5708346020024828599e-07" izz="3.5767957544055383823e-05"/>      
    </inertial>    
  </link>  

  <link name="spur_1m_24t_drive">    
    <visual>      
      <origin xyz="0 0 0" rpy="0 -0 0"/>      
      <geometry>        
        <mesh filename="package:///meshes/left_spur_1m_24t_drive_visual.stl"/>        
      </geometry>      
      <material name="spur_1m_24t_drive_material">        
        <color rgba="0.61568627450980406568 0.81176470588235294379 0.92941176470588238168 1.0"/>        
      </material>      
    </visual>    
    <collision>      
      <origin xyz="0 0 0" rpy="0 -0 0"/>      
      <geometry>        
        <mesh filename="package:///meshes/left_spur_1m_24t_drive_collision.stl"/>        
      </geometry>      
    </collision>    
    <inertial>      
      <origin xyz="-7.7587979572458248242e-15 -1.2122842274909869457e-16 0.0047949116178401416863" rpy="0 0 0"/>      
      <mass value="0.0032000000000000001533"/>      
      <inertia ixx="1.4019331346159885055e-07" ixy="1.6002409988709471321e-15" ixz="-1.6238956637125511228e-36" iyy="1.4019331260388783538e-07" iyz="2.7687586474031118888e-36" izz="2.3838919844264060647e-07"/>      
    </inertial>    
  </link>  

  <joint name="left_sho_yaw_drive" type="revolute">    
    <origin xyz="-0.024000000716141011575 -0.01900000015245061416 -0.019000000152443286688" rpy="1.5707963267948328312 -1.2486577482345307449e-15 8.257939689134084871e-14"/>    
    <parent link="2xl430_gears"/>    
    <child link="spur_1m_24t_drive"/>    
    <axis xyz="0 0 1"/>    
    <limit effort="1" velocity="20" lower="-2.6179938779914944114" upper="2.6179938779914944114"/>    
    <joint_properties friction="0.0"/>    
  </joint>  

  <link name="spur_1m_24t_driven">    
    <visual>      
      <origin xyz="0 0 0" rpy="0 -0 0"/>      
      <geometry>        
        <mesh filename="package:///meshes/left_spur_1m_24t_driven_visual.stl"/>        
      </geometry>      
      <material name="spur_1m_24t_driven_material">        
        <color rgba="0.23137254901960788156 0.38039215686274507888 0.7058823529411765163 1.0"/>        
      </material>      
    </visual>    
    <collision>      
      <origin xyz="0 0 0" rpy="0 -0 0"/>      
      <geometry>        
        <mesh filename="package:///meshes/left_spur_1m_24t_driven_collision.stl"/>        
      </geometry>      
    </collision>    
    <inertial>      
      <origin xyz="2.3351569794101925615e-18 -5.8049097389032868557e-15 -0.00097054817521928168911" rpy="0 0 0"/>      
      <mass value="0.0027000000000000001429"/>      
      <inertia ixx="1.2036234079571068356e-07" ixy="5.6376054914688044946e-37" ixz="-8.0895196499276315451e-37" iyy="1.203623407957104718e-07" iyz="-2.2046503577944594466e-37" izz="2.2847261745924543257e-07"/>      
    </inertial>    
  </link>  

  <link name="sho_yaw_link">    
    <visual>      
      <origin xyz="0 0 0" rpy="0 -0 0"/>      
      <geometry>        
        <mesh filename="package:///meshes/left_sho_yaw_link_visual.stl"/>        
      </geometry>      
      <material name="sho_yaw_link_material">        
        <color rgba="0.61568627450980395466 0.81176470588235294379 0.92941176470588238168 1.0"/>        
      </material>      
    </visual>    
    <collision>      
      <origin xyz="0 0 0" rpy="0 -0 0"/>      
      <geometry>        
        <mesh filename="package:///meshes/left_sho_yaw_link_collision.stl"/>        
      </geometry>      
    </collision>    
    <inertial>      
      <origin xyz="-1.2274982304783899612e-18 3.1874712151651496211e-18 -0.024303257848520158635" rpy="0 0 0"/>      
      <mass value="0.014500000000000007674"/>      
      <inertia ixx="9.084667005304133196e-06" ixy="3.6224092806514836327e-13" ixz="7.009907785322203879e-43" iyy="5.6910950712097499617e-06" iyz="3.789581740462215203e-36" izz="4.4819609845548958989e-06"/>      
    </inertial>    
  </link>  

  <link name="2xl430_gears_2">    
    <visual>      
      <origin xyz="0 0 0" rpy="0 -0 0"/>      
      <geometry>        
        <mesh filename="package:///meshes/left_2xl430_gears_2_visual.stl"/>        
      </geometry>      
      <material name="2xl430_gears_2_material">        
        <color rgba="0.7560598568794409946 0.8580469596269301169 0.91320266199377464478 1.0"/>        
      </material>      
    </visual>    
    <collision>      
      <origin xyz="0 0 0" rpy="0 -0 0"/>      
      <geometry>        
        <mesh filename="package:///meshes/left_2xl430_gears_2_collision.stl"/>        
      </geometry>      
    </collision>    
    <inertial>      
      <origin xyz="-0.011579403981033423165 -0.0024225766141409096378 -0.018551095523809995463" rpy="0 0 0"/>      
      <mass value="0.11800003674524910113"/>      
      <inertia ixx="2.748229808323711184e-05" ixy="9.2729623433255243661e-07" ixz="-2.263451200491700026e-08" iyy="3.2770742486674024434e-05" iyz="-6.5708346020396570184e-07" izz="3.5767957544055749741e-05"/>      
    </inertial>    
  </link>  

  <link name="spur_1m_24t_drive_2">    
    <visual>      
      <origin xyz="0 0 0" rpy="0 -0 0"/>      
      <geometry>        
        <mesh filename="package:///meshes/left_spur_1m_24t_drive_2_visual.stl"/>        
      </geometry>      
      <material name="spur_1m_24t_drive_2_material">        
        <color rgba="0.61568627450980406568 0.81176470588235294379 0.92941176470588238168 1.0"/>        
      </material>      
    </visual>    
    <collision>      
      <origin xyz="0 0 0" rpy="0 -0 0"/>      
      <geometry>        
        <mesh filename="package:///meshes/left_spur_1m_24t_drive_2_collision.stl"/>        
      </geometry>      
    </collision>    
    <inertial>      
      <origin xyz="-7.7518590633419175958e-15 -1.2122842272324949764e-16 0.0047949116178401382168" rpy="0 0 0"/>      
      <mass value="0.0032000000000000001533"/>      
      <inertia ixx="1.4019331346159885055e-07" ixy="1.6002410054600855339e-15" ixz="-1.7607335968947669733e-37" iyy="1.4019331260388783538e-07" iyz="-1.8747184623252096922e-36" izz="2.3838919844264060647e-07"/>      
    </inertial>    
  </link>  

  <joint name="left_elbow_yaw_drive" type="revolute">    
    <origin xyz="-0.024000000716137528251 -0.0190000001524475437 -0.019000000152459547986" rpy="1.570796326795050879 -2.46739603138074785e-13 -6.062193916416980129e-14"/>    
    <parent link="2xl430_gears_2"/>    
    <child link="spur_1m_24t_drive_2"/>    
    <axis xyz="0 0 1"/>    
    <limit effort="1" velocity="20" lower="-2.6179938779914944114" upper="2.6179938779914944114"/>    
    <joint_properties friction="0.0"/>    
  </joint>  

  <link name="spur_1m_24t_driven_2">    
    <visual>      
      <origin xyz="0 0 0" rpy="0 -0 0"/>      
      <geometry>        
        <mesh filename="package:///meshes/left_spur_1m_24t_driven_2_visual.stl"/>        
      </geometry>      
      <material name="spur_1m_24t_driven_2_material">        
        <color rgba="0.23137254901960788156 0.38039215686274507888 0.7058823529411765163 1.0"/>        
      </material>      
    </visual>    
    <collision>      
      <origin xyz="0 0 0" rpy="0 -0 0"/>      
      <geometry>        
        <mesh filename="package:///meshes/left_spur_1m_24t_driven_2_collision.stl"/>        
      </geometry>      
    </collision>    
    <inertial>      
      <origin xyz="2.3351569794102591987e-18 -5.8051485450291195555e-15 -0.00097054817521927485863" rpy="0 0 0"/>      
      <mass value="0.0027000000000000001429"/>      
      <inertia ixx="1.2036234079571068356e-07" ixy="1.5191863218340771746e-36" ixz="2.7687530035427808049e-37" iyy="1.203623407957104718e-07" iyz="-1.1902129569651023072e-37" izz="2.2847261745924543257e-07"/>      
    </inertial>    
  </link>  

  <link name="elb_yaw_link">    
    <visual>      
      <origin xyz="0 0 0" rpy="0 -0 0"/>      
      <geometry>        
        <mesh filename="package:///meshes/left_elb_yaw_link_visual.stl"/>        
      </geometry>      
      <material name="elb_yaw_link_material">        
        <color rgba="0.61568627450980395466 0.81176470588235294379 0.92941176470588227065 1.0"/>        
      </material>      
    </visual>    
    <collision>      
      <origin xyz="0 0 0" rpy="0 -0 0"/>      
      <geometry>        
        <mesh filename="package:///meshes/left_elb_yaw_link_collision.stl"/>        
      </geometry>      
    </collision>    
    <inertial>      
      <origin xyz="5.3127688027648185214e-08 0.001983363864196168759 -0.023416643551549952418" rpy="0 0 0"/>      
      <mass value="0.017500000000000001665"/>      
      <inertia ixx="1.4134344903109199776e-05" ixy="1.694578392200579355e-12" ixz="-1.1286398721858038578e-11" iyy="6.6435900776211340404e-06" iyz="1.0545227077253057579e-06" izz="8.9925290757998976773e-06"/>      
    </inertial>    
  </link>  

  <link name="spur_1m_24t_driven_3">    
    <visual>      
      <origin xyz="0 0 0" rpy="0 -0 0"/>      
      <geometry>        
        <mesh filename="package:///meshes/left_spur_1m_24t_driven_3_visual.stl"/>        
      </geometry>      
      <material name="spur_1m_24t_driven_3_material">        
        <color rgba="0.23137254901960788156 0.38039215686274507888 0.7058823529411765163 1.0"/>        
      </material>      
    </visual>    
    <collision>      
      <origin xyz="0 0 0" rpy="0 -0 0"/>      
      <geometry>        
        <mesh filename="package:///meshes/left_spur_1m_24t_driven_3_collision.stl"/>        
      </geometry>      
    </collision>    
    <inertial>      
      <origin xyz="2.3351569794096402048e-18 -5.8049097389032868557e-15 -0.0025705481752192789469" rpy="0 0 0"/>      
      <mass value="0.0027000000000000001429"/>      
      <inertia ixx="1.203623407957107365e-07" ixy="3.6684824624552391902e-37" ixz="-4.4245178596109467319e-36" iyy="1.203623407957104718e-07" iyz="7.883773541559373366e-38" izz="2.2847261745924553845e-07"/>      
    </inertial>    
  </link>  

  <link name="2xl430_gears_3">    
    <visual>      
      <origin xyz="0 0 0" rpy="0 -0 0"/>      
      <geometry>        
        <mesh filename="package:///meshes/left_2xl430_gears_3_visual.stl"/>        
      </geometry>      
      <material name="2xl430_gears_3_material">        
        <color rgba="0.7560598568794409946 0.8580469596269301169 0.91320266199377464478 1.0"/>        
      </material>      
    </visual>    
    <collision>      
      <origin xyz="0 0 0" rpy="0 -0 0"/>      
      <geometry>        
        <mesh filename="package:///meshes/left_2xl430_gears_3_collision.stl"/>        
      </geometry>      
    </collision>    
    <inertial>      
      <origin xyz="0.00044890447620269378383 0.011579403622953142461 -0.02457742353830994278" rpy="0 0 0"/>      
      <mass value="0.11800003674524910113"/>      
      <inertia ixx="3.5767957544054841722e-05" ixy="2.2634512003715325206e-08" ixz="6.5708346020249419385e-07" iyy="2.7482298083237877558e-05" iyz="9.2729623433226052788e-07" izz="3.2770742486671869582e-05"/>      
    </inertial>    
  </link>  

  <link name="spur_1m_24t_drive_3">    
    <visual>      
      <origin xyz="0 0 0" rpy="0 -0 0"/>      
      <geometry>        
        <mesh filename="package:///meshes/left_spur_1m_24t_drive_3_visual.stl"/>        
      </geometry>      
      <material name="spur_1m_24t_drive_3_material">        
        <color rgba="0.61568627450980406568 0.81176470588235294379 0.92941176470588238168 1.0"/>        
      </material>      
    </visual>    
    <collision>      
      <origin xyz="0 0 0" rpy="0 -0 0"/>      
      <geometry>        
        <mesh filename="package:///meshes/left_spur_1m_24t_drive_3_collision.stl"/>        
      </geometry>      
    </collision>    
    <inertial>      
      <origin xyz="-7.7518590633419175958e-15 -1.2122842274909869457e-16 0.004794911617840143421" rpy="0 0 0"/>      
      <mass value="0.0032000000000000001533"/>      
      <inertia ixx="1.4019331346159885055e-07" ixy="1.6002409981164973256e-15" ixz="-1.867282443471297714e-36" iyy="1.4019331260388778244e-07" iyz="-6.050604832481745408e-37" izz="2.3838919844264060647e-07"/>      
    </inertial>    
  </link>  

  <joint name="left_wrist_pitch_drive" type="revolute">    
    <origin xyz="-1.5244060454932558359e-10 0.024000000358057327343 -0.0080000000000068835493" rpy="4.57965832526558921e-14 -2.10309717636365493e-13 -1.5707963267949176522"/>    
    <parent link="2xl430_gears_3"/>    
    <child link="spur_1m_24t_drive_3"/>    
    <axis xyz="0 0 1"/>    
    <limit effort="1" velocity="20" lower="-1.9198621771937625091" upper="1.3962634015954635824"/>    
    <joint_properties friction="0.0"/>    
  </joint>  

  <link name="hand">    
    <visual>      
      <origin xyz="0 0 0" rpy="0 -0 0"/>      
      <geometry>        
        <mesh filename="package:///meshes/left_hand_visual.stl"/>        
      </geometry>      
      <material name="hand_material">        
        <color rgba="0.61568627450980395466 0.81176470588235294379 0.92941176470588238168 1.0"/>        
      </material>      
    </visual>    
    <collision>      
      <origin xyz="0 0 0" rpy="0 -0 0"/>      
      <geometry>        
        <mesh filename="package:///meshes/left_hand_collision.stl"/>        
      </geometry>      
    </collision>    
    <inertial>      
      <origin xyz="-2.4899508580538796352e-10 -0.040594531666389037372 -0.019479063914252029571" rpy="0 0 0"/>      
      <mass value="0.017000000000001441042"/>      
      <inertia ixx="9.2187594185322302979e-06" ixy="1.5922040707505715438e-15" ixz="1.0539511468854035967e-13" iyy="6.6718567758212696226e-06" iyz="2.153359677520097301e-08" izz="3.778869841187656458e-06"/>      
    </inertial>    
  </link>  

  <joint name="left_wrist_roll" type="revolute">    
    <origin xyz="0.019000000000007045975 -3.5808098153289336096e-10 -0.027000000152448057344" rpy="-8.1915604995110887341e-29 1.5707963267945390662 0"/>    
    <parent link="2xl430_gears_3"/>    
    <child link="hand"/>    
    <axis xyz="0 0 1"/>    
    <limit effort="1" velocity="20" lower="-1.9198621771937625091" upper="1.3962634015954635824"/>    
    <joint_properties friction="0.0"/>    
  </joint>  

  <link name="wrist_bearing_plate">    
    <visual>      
      <origin xyz="0 0 0" rpy="0 -0 0"/>      
      <geometry>        
        <mesh filename="package:///meshes/left_wrist_bearing_plate_visual.stl"/>        
      </geometry>      
      <material name="wrist_bearing_plate_material">        
        <color rgba="0.64496316278892629192 0.69011804996940528945 0.71706771073555886087 1.0"/>        
      </material>      
    </visual>    
    <collision>      
      <origin xyz="0 0 0" rpy="0 -0 0"/>      
      <geometry>        
        <mesh filename="package:///meshes/left_wrist_bearing_plate_collision.stl"/>        
      </geometry>      
    </collision>    
    <inertial>      
      <origin xyz="-0.0075835583121499584511 -0.015499999999999982542 -0.0018386323705903353121" rpy="0 0 0"/>      
      <mass value="0.0049000367468305548388"/>      
      <inertia ixx="4.9707430109150107956e-07" ixy="1.0473719169319772396e-22" ixz="1.8100904820814432294e-08" iyy="7.1268523603538563647e-07" iyz="-3.2485619130822956112e-22" izz="1.1919657811600109234e-06"/>      
    </inertial>    
  </link>  

  <joint name="left_wrist_pitch_fixed" type="fixed">    
    <origin xyz="0.015500000000007821757 -1.8096635301390051609e-14 -0.044999999999998901989" rpy="8.1212814267639654023e-14 -2.8213542612434270497e-13 -1.570796326794906328"/>    
    <parent link="2xl430_gears_3"/>    
    <child link="wrist_bearing_plate"/>    
    <axis xyz="0 0 1"/>    
    <limit effort="1" velocity="20"/>    
    <joint_properties friction="0.0"/>    
  </joint>  

  <joint name="left_wrist_pitch_driven" type="revolute">    
    <origin xyz="0 -1.5777218104420236108e-30 -0.0015999999999999953062" rpy="-2.8253475236412191385e-15 -3.552713678800508818e-15 -1.570796326794896558"/>    
    <parent link="spur_1m_24t_driven_3"/>    
    <child link="2xl430_gears_3"/>    
    <axis xyz="0 0 1"/>    
    <limit effort="1" velocity="20" lower="-1.3962634015954635824" upper="1.9198621771937625091"/>    
    <joint_properties friction="0.0"/>    
  </joint>  

  <joint name="left_wrist_roll_fixed" type="fixed">    
    <origin xyz="-7.8886090522101180541e-30 -0.025299999999999999573 -0.052000000000000032307" rpy="1.5707963267948985564 -1.5707963267948945596 0"/>    
    <parent link="elb_yaw_link"/>    
    <child link="spur_1m_24t_driven_3"/>    
    <axis xyz="0 0 1"/>    
    <limit effort="1" velocity="20"/>    
    <joint_properties friction="0.0"/>    
  </joint>  

  <joint name="left_elbow_yaw_fixed" type="fixed">    
    <origin xyz="1.5777218104420236108e-30 0 0.0015999999999999903189" rpy="-3.141592653589793116 -1.5029469787693842406e-27 -1.0914409670812147614e-28"/>    
    <parent link="spur_1m_24t_driven_2"/>    
    <child link="elb_yaw_link"/>    
    <axis xyz="0 0 1"/>    
    <limit effort="1" velocity="20"/>    
    <joint_properties friction="0.0"/>    
  </joint>  

  <joint name="left_elbow_yaw_driven" type="revolute">    
    <origin xyz="-3.5806395001780622067e-10 -0.027000000152452921509 -0.019000000000006608825" rpy="1.5707963267949589525 1.5707963267947417929 0"/>    
    <parent link="2xl430_gears_2"/>    
    <child link="spur_1m_24t_driven_2"/>    
    <axis xyz="0 0 1"/>    
    <limit effort="1" velocity="20" lower="-2.6179938779914944114" upper="2.6179938779914944114"/>    
    <joint_properties friction="0.0"/>    
  </joint>  

  <joint name="left_elbow_roll" type="revolute">    
    <origin xyz="3.4694469519536141888e-18 -0.018999999999999996059 -0.058999999999999983014" rpy="1.570796326794896336 -2.4424906541778151013e-14 3.0649833342774549336e-16"/>    
    <parent link="sho_yaw_link"/>    
    <child link="2xl430_gears_2"/>    
    <axis xyz="0 0 1"/>    
    <limit effort="1" velocity="20" lower="-1.9198621771937625091" upper="2.4434609527920612138"/>    
    <joint_properties friction="0.0"/>    
  </joint>  

  <joint name="left_sho_yaw_fixed" type="fixed">    
    <origin xyz="3.4694469519536141888e-18 3.9443045261050590271e-31 0.0016000000000000007272" rpy="3.1415926535897757965 -0 0"/>    
    <parent link="spur_1m_24t_driven"/>    
    <child link="sho_yaw_link"/>    
    <axis xyz="0 0 1"/>    
    <limit effort="1" velocity="20"/>    
    <joint_properties friction="0.0"/>    
  </joint>  

  <joint name="left_sho_yaw_driven" type="revolute">    
    <origin xyz="-3.5807090625894488767e-10 -0.027000000152451124336 -0.018999999999999364619" rpy="1.5707963267948492625 7.961811706183572413e-14 1.2023715356687380766e-13"/>    
    <parent link="2xl430_gears"/>    
    <child link="spur_1m_24t_driven"/>    
    <axis xyz="0 0 1"/>    
    <limit effort="1" velocity="20" lower="-2.6179938779914944114" upper="2.6179938779914944114"/>    
    <joint_properties friction="0.0"/>    
  </joint>  

  <joint name="left_sho_roll" type="revolute">    
    <origin xyz="-0.018999999999999999528 0.0010000000000000034903 0.027000000000000006634" rpy="-3.141592653589793116 1.570796326794896336 0"/>    
    <parent link="sho_pitch_link"/>    
    <child link="2xl430_gears"/>    
    <axis xyz="0 0 1"/>    
    <limit effort="1" velocity="20" lower="-1.570796326794896558" upper="0.34906585039886589561"/>    
    <joint_properties friction="0.0"/>    
  </joint>  


</robot>