<?xml version="1.0" ?><robot name="left_arm_hand">  
  <link name="sho_pitch_link">    
    <visual>      
      <origin xyz="0 0 0" rpy="0 -0 0"/>      
      <geometry>        
        <mesh filename="package:///meshes/left_sho_pitch_link_visual.stl"/>        
      </geometry>      
      <material name="sho_pitch_link_material">        
        <color rgba="0.61568627450980395466 0.81176470588235294379 0.92941176470588227065 1.0"/>        
      </material>      
    </visual>    
    <collision>      
      <origin xyz="0 0 0" rpy="0 -0 0"/>      
      <geometry>        
        <mesh filename="package:///meshes/left_sho_pitch_link_collision.stl"/>        
      </geometry>      
    </collision>    
    <inertial>      
      <origin xyz="5.8254249669365172068e-11 -5.1264642561120511732e-05 0.0082440788127094901533" rpy="0 0 0"/>      
      <mass value="0.0085999999999999948014"/>      
      <inertia ixx="1.227288704054578552e-06" ixy="-2.142994421442472607e-14" ixz="-8.5847199972402478199e-15" iyy="2.9107306060364603147e-06" iyz="7.4623841398182653875e-09" izz="3.0803135950773474987e-06"/>      
    </inertial>    
  </link>  

  <link name="2xl430_gears">    
    <visual>      
      <origin xyz="0 0 0" rpy="0 -0 0"/>      
      <geometry>        
        <mesh filename="package:///meshes/left_2xl430_gears_visual.stl"/>        
      </geometry>      
      <material name="2xl430_gears_material">        
        <color rgba="0.75605985687944088358 0.8580469596269301169 0.91320266199377453376 1.0"/>        
      </material>      
    </visual>    
    <collision>      
      <origin xyz="0 0 0" rpy="0 -0 0"/>      
      <geometry>        
        <mesh filename="package:///meshes/left_2xl430_gears_collision.stl"/>        
      </geometry>      
    </collision>    
    <inertial>      
      <origin xyz="-0.011579403981036556076 -0.00242257661414001799 -0.018551095523803531884" rpy="0 0 0"/>      
      <mass value="0.11800003674524907338"/>      
      <inertia ixx="2.7482298083236092012e-05" ixy="9.2729623432982075535e-07" ixz="-2.2634512003761296596e-08" iyy="3.2770742486672784378e-05" iyz="-6.5708346020130284201e-07" izz="3.5767957544054292845e-05"/>      
    </inertial>    
  </link>  

  <link name="spur_1m_24t_drive">    
    <visual>      
      <origin xyz="0 0 0" rpy="0 -0 0"/>      
      <geometry>        
        <mesh filename="package:///meshes/left_spur_1m_24t_drive_visual.stl"/>        
      </geometry>      
      <material name="spur_1m_24t_drive_material">        
        <color rgba="0.61568627450980406568 0.81176470588235294379 0.92941176470588238168 1.0"/>        
      </material>      
    </visual>    
    <collision>      
      <origin xyz="0 0 0" rpy="0 -0 0"/>      
      <geometry>        
        <mesh filename="package:///meshes/left_spur_1m_24t_drive_collision.stl"/>        
      </geometry>      
    </collision>    
    <inertial>      
      <origin xyz="-7.7589517893534835836e-15 -1.211050839611185126e-16 0.0047949116178401460231" rpy="0 0 0"/>      
      <mass value="0.0032000000000000001533"/>      
      <inertia ixx="1.4019331346159890349e-07" ixy="1.6002409955622246819e-15" ixz="-8.0106568502533350833e-38" iyy="1.4019331260388783538e-07" iyz="3.5707617447061284037e-38" izz="2.3838919844264060647e-07"/>      
    </inertial>    
  </link>  

  <joint name="left_sho_yaw_drive" type="revolute">    
    <origin xyz="-0.024000000716141278723 -0.019000000152448490859 -0.0190000001524472939" rpy="1.570796326794886566 -1.7772407460995643501e-15 2.9721983312145830671e-14"/>    
    <parent link="2xl430_gears"/>    
    <child link="spur_1m_24t_drive"/>    
    <axis xyz="0 0 1"/>    
    <limit effort="1" velocity="20" lower="-1.570796326794896558" upper="1.570796326794896558"/>    
    <joint_properties friction="0.0"/>    
  </joint>  

  <link name="spur_1m_24t_driven">    
    <visual>      
      <origin xyz="0 0 0" rpy="0 -0 0"/>      
      <geometry>        
        <mesh filename="package:///meshes/left_spur_1m_24t_driven_visual.stl"/>        
      </geometry>      
      <material name="spur_1m_24t_driven_material">        
        <color rgba="0.23137254901960788156 0.38039215686274507888 0.7058823529411765163 1.0"/>        
      </material>      
    </visual>    
    <collision>      
      <origin xyz="0 0 0" rpy="0 -0 0"/>      
      <geometry>        
        <mesh filename="package:///meshes/left_spur_1m_24t_driven_collision.stl"/>        
      </geometry>      
    </collision>    
    <inertial>      
      <origin xyz="2.4350898561930652746e-18 -5.798576291048762493e-15 -0.00096866348640038332785" rpy="0 0 0"/>      
      <mass value="0.0027000000000000001429"/>      
      <inertia ixx="1.2026541119643502094e-07" ixy="-4.0474500803410873683e-47" ixz="-1.0726060653955529023e-38" iyy="1.2026541119643483565e-07" iyz="5.980474480612833222e-38" izz="2.2827257365099366486e-07"/>      
    </inertial>    
  </link>  

  <link name="sho_yaw_link">    
    <visual>      
      <origin xyz="0 0 0" rpy="0 -0 0"/>      
      <geometry>        
        <mesh filename="package:///meshes/left_sho_yaw_link_visual.stl"/>        
      </geometry>      
      <material name="sho_yaw_link_material">        
        <color rgba="0.61568627450980395466 0.81176470588235294379 0.92941176470588238168 1.0"/>        
      </material>      
    </visual>    
    <collision>      
      <origin xyz="0 0 0" rpy="0 -0 0"/>      
      <geometry>        
        <mesh filename="package:///meshes/left_sho_yaw_link_collision.stl"/>        
      </geometry>      
    </collision>    
    <inertial>      
      <origin xyz="-1.1573942515719326726e-18 3.7205074538890822836e-18 -0.024214576156328417034" rpy="0 0 0"/>      
      <mass value="0.014500000000000014613"/>      
      <inertia ixx="9.0490855102914958597e-06" ixy="3.5997729401630495156e-13" ixz="8.4928747802388958028e-37" iyy="5.6767199180624702083e-06" iyz="1.6087043138114345405e-36" izz="4.4590603637468133921e-06"/>      
    </inertial>    
  </link>  

  <link name="2xl430_gears_2">    
    <visual>      
      <origin xyz="0 0 0" rpy="0 -0 0"/>      
      <geometry>        
        <mesh filename="package:///meshes/left_2xl430_gears_2_visual.stl"/>        
      </geometry>      
      <material name="2xl430_gears_2_material">        
        <color rgba="0.75605985687944088358 0.8580469596269301169 0.91320266199377453376 1.0"/>        
      </material>      
    </visual>    
    <collision>      
      <origin xyz="0 0 0" rpy="0 -0 0"/>      
      <geometry>        
        <mesh filename="package:///meshes/left_2xl430_gears_2_collision.stl"/>        
      </geometry>      
    </collision>    
    <inertial>      
      <origin xyz="-0.01157940398103590382 -0.0024225766141403098572 -0.018551095523804767007" rpy="0 0 0"/>      
      <mass value="0.11800003674524907338"/>      
      <inertia ixx="2.7482298083236647666e-05" ixy="9.2729623433076127956e-07" ixz="-2.2634512003935616638e-08" iyy="3.2770742486673184177e-05" iyz="-6.5708346020168263041e-07" izz="3.5767957544054916261e-05"/>      
    </inertial>    
  </link>  

  <link name="spur_1m_24t_drive_2">    
    <visual>      
      <origin xyz="0 0 0" rpy="0 -0 0"/>      
      <geometry>        
        <mesh filename="package:///meshes/left_spur_1m_24t_drive_2_visual.stl"/>        
      </geometry>      
      <material name="spur_1m_24t_drive_2_material">        
        <color rgba="0.61568627450980406568 0.81176470588235294379 0.92941176470588238168 1.0"/>        
      </material>      
    </visual>    
    <collision>      
      <origin xyz="0 0 0" rpy="0 -0 0"/>      
      <geometry>        
        <mesh filename="package:///meshes/left_spur_1m_24t_drive_2_collision.stl"/>        
      </geometry>      
    </collision>    
    <inertial>      
      <origin xyz="-7.7520128954495763552e-15 -1.2110508396111870982e-16 0.0047949116178401382168" rpy="0 0 0"/>      
      <mass value="0.0032000000000000001533"/>      
      <inertia ixx="1.4019331346159890349e-07" ixy="1.6002409988709471321e-15" ixz="2.601989679508350391e-37" iyy="1.4019331260388783538e-07" iyz="-1.1857416576551865918e-36" izz="2.3838919844264060647e-07"/>      
    </inertial>    
  </link>  

  <joint name="left_elbow_yaw_drive" type="revolute">    
    <origin xyz="-0.024000000716141011575 -0.019000000152448556778 -0.019000000152448452695" rpy="1.5707963267949249797 5.3833632274240703492e-15 -6.2781152873576405876e-14"/>    
    <parent link="2xl430_gears_2"/>    
    <child link="spur_1m_24t_drive_2"/>    
    <axis xyz="0 0 1"/>    
    <limit effort="1" velocity="20" lower="-1.570796326794896558" upper="1.570796326794896558"/>    
    <joint_properties friction="0.0"/>    
  </joint>  

  <link name="spur_1m_24t_driven_2">    
    <visual>      
      <origin xyz="0 0 0" rpy="0 -0 0"/>      
      <geometry>        
        <mesh filename="package:///meshes/left_spur_1m_24t_driven_2_visual.stl"/>        
      </geometry>      
      <material name="spur_1m_24t_driven_2_material">        
        <color rgba="0.23137254901960788156 0.38039215686274507888 0.7058823529411765163 1.0"/>        
      </material>      
    </visual>    
    <collision>      
      <origin xyz="0 0 0" rpy="0 -0 0"/>      
      <geometry>        
        <mesh filename="package:///meshes/left_spur_1m_24t_driven_2_collision.stl"/>        
      </geometry>      
    </collision>    
    <inertial>      
      <origin xyz="2.4350898561930425487e-18 -5.7988120355575981266e-15 -0.00096866348640039037516" rpy="0 0 0"/>      
      <mass value="0.0027000000000000001429"/>      
      <inertia ixx="1.2026541119643502094e-07" ixy="0" ixz="-3.9131793608196566436e-37" iyy="1.2026541119643483565e-07" iyz="0" izz="2.2827257365099366486e-07"/>      
    </inertial>    
  </link>  

  <link name="elb_yaw_link">    
    <visual>      
      <origin xyz="0 0 0" rpy="0 -0 0"/>      
      <geometry>        
        <mesh filename="package:///meshes/left_elb_yaw_link_visual.stl"/>        
      </geometry>      
      <material name="elb_yaw_link_material">        
        <color rgba="0.61568627450980395466 0.81176470588235294379 0.92941176470588227065 1.0"/>        
      </material>      
    </visual>    
    <collision>      
      <origin xyz="0 0 0" rpy="0 -0 0"/>      
      <geometry>        
        <mesh filename="package:///meshes/left_elb_yaw_link_collision.stl"/>        
      </geometry>      
    </collision>    
    <inertial>      
      <origin xyz="5.2870889172758376684e-08 0.0019873558182742436136 -0.02336566119982871545" rpy="0 0 0"/>      
      <mass value="0.017500000000000005135"/>      
      <inertia ixx="1.4097804991252561445e-05" ixy="1.6900809684077683173e-12" ixz="-1.1184673662168510534e-11" iyy="6.6367696417680327434e-06" iyz="1.057990872258833363e-06" izz="8.9601142768980646651e-06"/>      
    </inertial>    
  </link>  

  <link name="spur_1m_24t_driven_3">    
    <visual>      
      <origin xyz="0 0 0" rpy="0 -0 0"/>      
      <geometry>        
        <mesh filename="package:///meshes/left_spur_1m_24t_driven_3_visual.stl"/>        
      </geometry>      
      <material name="spur_1m_24t_driven_3_material">        
        <color rgba="0.23137254901960788156 0.38039215686274507888 0.7058823529411765163 1.0"/>        
      </material>      
    </visual>    
    <collision>      
      <origin xyz="0 0 0" rpy="0 -0 0"/>      
      <geometry>        
        <mesh filename="package:///meshes/left_spur_1m_24t_driven_3_collision.stl"/>        
      </geometry>      
    </collision>    
    <inertial>      
      <origin xyz="-2.5320485759435755406e-17 -5.8022814825095517408e-15 -0.0025686634864003805856" rpy="0 0 0"/>      
      <mass value="0.0027000000000000001429"/>      
      <inertia ixx="1.2026541119643502094e-07" ixy="7.589814491455755124e-37" ixz="1.0368687130951098114e-36" iyy="1.2026541119643483565e-07" iyz="7.7514145192038011191e-67" izz="2.2827257365099366486e-07"/>      
    </inertial>    
  </link>  

  <link name="2xl430_gears_3">    
    <visual>      
      <origin xyz="0 0 0" rpy="0 -0 0"/>      
      <geometry>        
        <mesh filename="package:///meshes/left_2xl430_gears_3_visual.stl"/>        
      </geometry>      
      <material name="2xl430_gears_3_material">        
        <color rgba="0.75605985687944088358 0.8580469596269301169 0.91320266199377453376 1.0"/>        
      </material>      
    </visual>    
    <collision>      
      <origin xyz="0 0 0" rpy="0 -0 0"/>      
      <geometry>        
        <mesh filename="package:///meshes/left_2xl430_gears_3_collision.stl"/>        
      </geometry>      
    </collision>    
    <inertial>      
      <origin xyz="0.0004489044762018264763 0.01157940362295437238 -0.024577423538310185641" rpy="0 0 0"/>      
      <mass value="0.11800003674524907338"/>      
      <inertia ixx="3.5767957544054143767e-05" ixy="2.2634512003808455817e-08" ixz="6.5708346020219752056e-07" iyy="2.7482298083236972926e-05" iyz="9.2729623433153800877e-07" izz="3.277074248667180182e-05"/>      
    </inertial>    
  </link>  

  <link name="spur_1m_24t_drive_3">    
    <visual>      
      <origin xyz="0 0 0" rpy="0 -0 0"/>      
      <geometry>        
        <mesh filename="package:///meshes/left_spur_1m_24t_drive_3_visual.stl"/>        
      </geometry>      
      <material name="spur_1m_24t_drive_3_material">        
        <color rgba="0.61568627450980406568 0.81176470588235294379 0.92941176470588238168 1.0"/>        
      </material>      
    </visual>    
    <collision>      
      <origin xyz="0 0 0" rpy="0 -0 0"/>      
      <geometry>        
        <mesh filename="package:///meshes/left_spur_1m_24t_drive_3_collision.stl"/>        
      </geometry>      
    </collision>    
    <inertial>      
      <origin xyz="-7.7797684710652052688e-15 -1.2135702417639747025e-16 0.0047949116178401460231" rpy="0 0 0"/>      
      <mass value="0.0032000000000000001533"/>      
      <inertia ixx="1.4019331346159890349e-07" ixy="1.6002409955622246819e-15" ixz="1.353024793676005448e-36" iyy="1.4019331260388783538e-07" iyz="-6.353552390351152457e-37" izz="2.3838919844264060647e-07"/>      
    </inertial>    
  </link>  

  <joint name="left_wrist_roll_drive" type="revolute">    
    <origin xyz="-1.5244091752797395145e-10 0.024000000358059436767 -0.0080000000000068592632" rpy="1.9871762375367660116e-15 -2.337019466836035928e-14 -1.5707963267949176522"/>    
    <parent link="2xl430_gears_3"/>    
    <child link="spur_1m_24t_drive_3"/>    
    <axis xyz="0 0 1"/>    
    <limit effort="1" velocity="20" lower="-1.570796326794896558" upper="1.570796326794896558"/>    
    <joint_properties friction="0.0"/>    
  </joint>  

  <link name="hand">    
    <visual>      
      <origin xyz="0 0 0" rpy="0 -0 0"/>      
      <geometry>        
        <mesh filename="package:///meshes/left_hand_visual.stl"/>        
      </geometry>      
      <material name="hand_material">        
        <color rgba="0.61568627450980395466 0.81176470588235294379 0.92941176470588238168 1.0"/>        
      </material>      
    </visual>    
    <collision>      
      <origin xyz="0 0 0" rpy="0 -0 0"/>      
      <geometry>        
        <mesh filename="package:///meshes/left_hand_collision.stl"/>        
      </geometry>      
    </collision>    
    <inertial>      
      <origin xyz="-4.3038382212369557027e-08 -0.049723778585225218707 -0.017933572005385645109" rpy="0 0 0"/>      
      <mass value="0.01700000000000000816"/>      
      <inertia ixx="9.4921414617707132477e-06" ixy="-1.5549215897341496758e-11" ixz="-1.0809694196525066509e-11" iyy="4.0745028295219371575e-06" iyz="2.4719408559888000802e-07" izz="6.6623859522963571519e-06"/>      
    </inertial>    
  </link>  

  <joint name="left_wrist_pitch" type="revolute">    
    <origin xyz="0.019000000000005953099 -3.5808089826616651408e-10 -0.027000000152448959401" rpy="3.3651291228739927188e-14 1.5707963267946487562 0"/>    
    <parent link="2xl430_gears_3"/>    
    <child link="hand"/>    
    <axis xyz="0 0 1"/>    
    <limit effort="1" velocity="20" lower="-1.570796326794896558" upper="1.570796326794896558"/>    
    <joint_properties friction="0.0"/>    
  </joint>  

  <link name="wrist_bearing_plate">    
    <visual>      
      <origin xyz="0 0 0" rpy="0 -0 0"/>      
      <geometry>        
        <mesh filename="package:///meshes/left_wrist_bearing_plate_visual.stl"/>        
      </geometry>      
      <material name="wrist_bearing_plate_material">        
        <color rgba="0.64496316278892629192 0.69011804996940528945 0.71706771073555886087 1.0"/>        
      </material>      
    </visual>    
    <collision>      
      <origin xyz="0 0 0" rpy="0 -0 0"/>      
      <geometry>        
        <mesh filename="package:///meshes/left_wrist_bearing_plate_collision.stl"/>        
      </geometry>      
    </collision>    
    <inertial>      
      <origin xyz="-0.0075896393545961350277 -0.015499999999999973868 -0.0018386110045718368107" rpy="0 0 0"/>      
      <mass value="0.0049000367468305548388"/>      
      <inertia ixx="4.9747313520140109893e-07" ixy="5.5640336275171808945e-23" ixz="1.8097509420524730079e-08" iyy="7.1295025627582332608e-07" iyz="1.0346027163095738089e-23" izz="1.1926297952291908138e-06"/>      
    </inertial>    
  </link>  

  <joint name="left_wrist_pitch_fixed" type="fixed">    
    <origin xyz="0.015500000000005269979 -1.7125190154843039636e-14 -0.04500000000000015099" rpy="-4.057865155005087888e-14 -2.9093394360302217044e-13 -1.5707963267949061059"/>    
    <parent link="2xl430_gears_3"/>    
    <child link="wrist_bearing_plate"/>    
    <axis xyz="0 0 1"/>    
    <limit effort="1" velocity="20"/>    
    <joint_properties friction="0.0"/>    
  </joint>  

  <joint name="left_wrist_roll_driven" type="revolute">    
    <origin xyz="-2.7755575615628913511e-17 0 -0.0015999999999999937883" rpy="2.1632341616309662631e-16 -1.4384639448392080473e-27 -1.57079632679489678"/>    
    <parent link="spur_1m_24t_driven_3"/>    
    <child link="2xl430_gears_3"/>    
    <axis xyz="0 0 1"/>    
    <limit effort="1" velocity="20" lower="-1.570796326794896558" upper="1.570796326794896558"/>    
    <joint_properties friction="0.0"/>    
  </joint>  

  <joint name="left_wrist_roll_fixed" type="fixed">    
    <origin xyz="-3.4694469519536141888e-18 -0.025300000000000003042 -0.051999999999999976796" rpy="1.570796326794896558 -1.570796326794896558 0"/>    
    <parent link="elb_yaw_link"/>    
    <child link="spur_1m_24t_driven_3"/>    
    <axis xyz="0 0 1"/>    
    <limit effort="1" velocity="20"/>    
    <joint_properties friction="0.0"/>    
  </joint>  

  <joint name="left_elbow_yaw_fixed" type="fixed">    
    <origin xyz="7.8886090522101180541e-31 3.4694469519536141888e-18 0.0015999999999999625633" rpy="3.141592653589793116 6.123233994422830684e-17 -1.57079632679489678"/>    
    <parent link="spur_1m_24t_driven_2"/>    
    <child link="elb_yaw_link"/>    
    <axis xyz="0 0 1"/>    
    <limit effort="1" velocity="20"/>    
    <joint_properties friction="0.0"/>    
  </joint>  

  <joint name="left_elbow_yaw_driven" type="revolute">    
    <origin xyz="-3.5806929990500613314e-10 -0.027000000152451131274 -0.019000000000003351014" rpy="1.5707963267949591746 1.5707963267948683583 0"/>    
    <parent link="2xl430_gears_2"/>    
    <child link="spur_1m_24t_driven_2"/>    
    <axis xyz="0 0 1"/>    
    <limit effort="1" velocity="20" lower="-1.570796326794896558" upper="1.570796326794896558"/>    
    <joint_properties friction="0.0"/>    
  </joint>  

  <joint name="left_elbow_roll" type="revolute">    
    <origin xyz="2.185751579730776939e-16 -0.018999999999999329925 -0.058999999999999733213" rpy="1.570796326794896558 -1.3443939455351824662e-14 1.2212453270787430779e-15"/>    
    <parent link="sho_yaw_link"/>    
    <child link="2xl430_gears_2"/>    
    <axis xyz="0 0 1"/>    
    <limit effort="1" velocity="20" lower="-1.570796326794896558" upper="1.570796326794896558"/>    
    <joint_properties friction="0.0"/>    
  </joint>  

  <joint name="left_sho_yaw_fixed" type="fixed">    
    <origin xyz="1.7347234759768070944e-17 -1.6375789611241112762e-17 0.0015999999999999972577" rpy="-3.1415926535897926719 2.775557561593911827e-16 4.4408920984097454411e-16"/>    
    <parent link="spur_1m_24t_driven"/>    
    <child link="sho_yaw_link"/>    
    <axis xyz="0 0 1"/>    
    <limit effort="1" velocity="20"/>    
    <joint_properties friction="0.0"/>    
  </joint>  

  <joint name="left_sho_yaw_driven" type="revolute">    
    <origin xyz="-3.5807098258677783065e-10 -0.027000000152450111257 -0.019000000000003021416" rpy="1.5707963267949009989 2.5840015203544507292e-14 -4.9507333169721578628e-15"/>    
    <parent link="2xl430_gears"/>    
    <child link="spur_1m_24t_driven"/>    
    <axis xyz="0 0 1"/>    
    <limit effort="1" velocity="20" lower="-1.570796326794896558" upper="1.570796326794896558"/>    
    <joint_properties friction="0.0"/>    
  </joint>  

  <joint name="left_sho_roll" type="revolute">    
    <origin xyz="-0.018999999999999947486 0.0010000000000000076102 0.027000000000000003164" rpy="-3.141592653589793116 1.570796326794896558 0"/>    
    <parent link="sho_pitch_link"/>    
    <child link="2xl430_gears"/>    
    <axis xyz="0 0 1"/>    
    <limit effort="1" velocity="20" lower="-1.570796326794896558" upper="0"/>    
    <joint_properties friction="0.0"/>    
  </joint>  


</robot>