<?xml version="1.0" ?><robot name="left_arm_hand">  
  <link name="xc430">    
    <visual>      
      <origin xyz="0 0 0" rpy="0 -0 0"/>      
      <geometry>        
        <mesh filename="package:///meshes/left_xc430_visual.stl"/>        
      </geometry>      
      <material name="xc430_material">        
        <color rgba="0.39603348637483432038 0.50878377002232877402 0.7112675543215366547 1.0"/>        
      </material>      
    </visual>    
    <collision>      
      <origin xyz="0 0 0" rpy="0 -0 0"/>      
      <geometry>        
        <mesh filename="package:///meshes/left_xc430_collision.stl"/>        
      </geometry>      
    </collision>    
    <inertial>      
      <origin xyz="0.0076499389484203641695 -0.0056800345415021161882 -0.014255781343936728411" rpy="0 0 0"/>      
      <mass value="0.065021926915724281848"/>      
      <inertia ixx="1.0685477757330404797e-05" ixy="2.4991048730004099899e-08" ixz="-4.3793050176056603612e-09" iyy="1.6030858372951694338e-05" iyz="-9.5846760480290978638e-09" izz="1.8186829094811185627e-05"/>      
    </inertial>    
  </link>  

  <link name="sho_pitch_link">    
    <visual>      
      <origin xyz="0 0 0" rpy="0 -0 0"/>      
      <geometry>        
        <mesh filename="package:///meshes/left_sho_pitch_link_visual.stl"/>        
      </geometry>      
      <material name="sho_pitch_link_material">        
        <color rgba="0.61568627450980395466 0.81176470588235294379 0.9294117647058824927 1.0"/>        
      </material>      
    </visual>    
    <collision>      
      <origin xyz="0 0 0" rpy="0 -0 0"/>      
      <geometry>        
        <mesh filename="package:///meshes/left_sho_pitch_link_collision.stl"/>        
      </geometry>      
    </collision>    
    <inertial>      
      <origin xyz="5.8254246533850555188e-11 -5.1264642561120633705e-05 0.0082440788127094866838" rpy="0 0 0"/>      
      <mass value="0.0085999999999999930667"/>      
      <inertia ixx="1.2272887040545789755e-06" ixy="-2.1429944218825389786e-14" ixz="-8.5847197649333819161e-15" iyy="2.9107306060364620088e-06" iyz="7.4623841398182868942e-09" izz="3.0803135950773479222e-06"/>      
    </inertial>    
  </link>  

  <link name="2xl430_gears">    
    <visual>      
      <origin xyz="0 0 0" rpy="0 -0 0"/>      
      <geometry>        
        <mesh filename="package:///meshes/left_2xl430_gears_visual.stl"/>        
      </geometry>      
      <material name="2xl430_gears_material">        
        <color rgba="0.91900666046079215743 0.7025956886054134376 0.12479235365575502836 1.0"/>        
      </material>      
    </visual>    
    <collision>      
      <origin xyz="0 0 0" rpy="0 -0 0"/>      
      <geometry>        
        <mesh filename="package:///meshes/left_2xl430_gears_collision.stl"/>        
      </geometry>      
    </collision>    
    <inertial>      
      <origin xyz="-0.011545549214475142943 -0.0025776045975616475661 -0.018554883443549097938" rpy="0 0 0"/>      
      <mass value="0.10921242823035924585"/>      
      <inertia ixx="2.5633987199176192553e-05" ixy="9.2332485824732332927e-07" ixz="-1.9126365492205904953e-08" iyy="3.0316164317563583114e-05" iyz="-6.1055425070402856933e-07" izz="3.3278157643470436923e-05"/>      
    </inertial>    
  </link>  

  <link name="spur_1m_24t_drive">    
    <visual>      
      <origin xyz="0 0 0" rpy="0 -0 0"/>      
      <geometry>        
        <mesh filename="package:///meshes/left_spur_1m_24t_drive_visual.stl"/>        
      </geometry>      
      <material name="spur_1m_24t_drive_material">        
        <color rgba="0.61568627450980406568 0.81176470588235294379 0.92941176470588238168 1.0"/>        
      </material>      
    </visual>    
    <collision>      
      <origin xyz="0 0 0" rpy="0 -0 0"/>      
      <geometry>        
        <mesh filename="package:///meshes/left_spur_1m_24t_drive_collision.stl"/>        
      </geometry>      
    </collision>    
    <inertial>      
      <origin xyz="-7.7519472167040379473e-15 -1.2127696869027378682e-16 0.0047949116178401460231" rpy="0 0 0"/>      
      <mass value="0.0032000000000000001533"/>      
      <inertia ixx="1.4019331346159892996e-07" ixy="1.6002409988143339376e-15" ixz="-8.7717508276537448259e-37" iyy="1.4019331260388786185e-07" iyz="1.1548227992196320289e-37" izz="2.3838919844264060647e-07"/>      
    </inertial>    
  </link>  

  <joint name="left_sho_yaw_drive" type="revolute">    
    <origin xyz="-0.024000000716149078039 -0.019000000152453292573 -0.019000000152451651525" rpy="1.5707963267948956698 -4.5091784937906777239e-14 2.4545027507744066908e-14"/>    
    <parent link="2xl430_gears"/>    
    <child link="spur_1m_24t_drive"/>    
    <axis xyz="0 0 1"/>    
    <limit effort="1" velocity="20" lower="-3.141592653589793116" upper="3.141592653589793116"/>    
    <joint_properties friction="0.0"/>    
  </joint>  

  <link name="spur_1m_24t_driven">    
    <visual>      
      <origin xyz="0 0 0" rpy="0 -0 0"/>      
      <geometry>        
        <mesh filename="package:///meshes/left_spur_1m_24t_driven_visual.stl"/>        
      </geometry>      
      <material name="spur_1m_24t_driven_material">        
        <color rgba="0.23137254901960788156 0.38039215686274507888 0.7058823529411765163 1.0"/>        
      </material>      
    </visual>    
    <collision>      
      <origin xyz="0 0 0" rpy="0 -0 0"/>      
      <geometry>        
        <mesh filename="package:///meshes/left_spur_1m_24t_driven_collision.stl"/>        
      </geometry>      
    </collision>    
    <inertial>      
      <origin xyz="2.2938228594596052967e-18 -5.7989635076863972055e-15 -0.00096866348640038332785" rpy="0 0 0"/>      
      <mass value="0.0027000000000000001429"/>      
      <inertia ixx="1.2026541119643507388e-07" ixy="-2.1120706372726563048e-36" ixz="0" iyy="1.2026541119643486212e-07" iyz="0" izz="2.2827257365099369132e-07"/>      
    </inertial>    
  </link>  

  <link name="sho_yaw_link">    
    <visual>      
      <origin xyz="0 0 0" rpy="0 -0 0"/>      
      <geometry>        
        <mesh filename="package:///meshes/left_sho_yaw_link_visual.stl"/>        
      </geometry>      
      <material name="sho_yaw_link_material">        
        <color rgba="0.61568627450980384364 0.81176470588235294379 0.92941176470588238168 1.0"/>        
      </material>      
    </visual>    
    <collision>      
      <origin xyz="0 0 0" rpy="0 -0 0"/>      
      <geometry>        
        <mesh filename="package:///meshes/left_sho_yaw_link_collision.stl"/>        
      </geometry>      
    </collision>    
    <inertial>      
      <origin xyz="5.7814996523352868457e-18 3.4508249259427939065e-18 -0.024214576156328403156" rpy="0 0 0"/>      
      <mass value="0.01450000000000000247"/>      
      <inertia ixx="9.0490855102914907775e-06" ixy="3.5997729401569193722e-13" ixz="0" iyy="5.6767199180624685142e-06" iyz="0" izz="4.459060363746810004e-06"/>      
    </inertial>    
  </link>  

  <link name="2xl430_gears_2">    
    <visual>      
      <origin xyz="0 0 0" rpy="0 -0 0"/>      
      <geometry>        
        <mesh filename="package:///meshes/left_2xl430_gears_2_visual.stl"/>        
      </geometry>      
      <material name="2xl430_gears_2_material">        
        <color rgba="0.91900666046079215743 0.7025956886054134376 0.12479235365575502836 1.0"/>        
      </material>      
    </visual>    
    <collision>      
      <origin xyz="0 0 0" rpy="0 -0 0"/>      
      <geometry>        
        <mesh filename="package:///meshes/left_2xl430_gears_2_collision.stl"/>        
      </geometry>      
    </collision>    
    <inertial>      
      <origin xyz="-0.01154554921447331281 -0.0025776045975613760819 -0.018554883443544802762" rpy="0 0 0"/>      
      <mass value="0.10921242823035924585"/>      
      <inertia ixx="2.5633987199174789866e-05" ixy="9.2332485824667196093e-07" ixz="-1.9126365492399451982e-08" iyy="3.031616431756243115e-05" iyz="-6.1055425070424752735e-07" izz="3.327815764346942726e-05"/>      
    </inertial>    
  </link>  

  <link name="spur_1m_24t_drive_2">    
    <visual>      
      <origin xyz="0 0 0" rpy="0 -0 0"/>      
      <geometry>        
        <mesh filename="package:///meshes/left_spur_1m_24t_drive_2_visual.stl"/>        
      </geometry>      
      <material name="spur_1m_24t_drive_2_material">        
        <color rgba="0.61568627450980406568 0.81176470588235294379 0.92941176470588238168 1.0"/>        
      </material>      
    </visual>    
    <collision>      
      <origin xyz="0 0 0" rpy="0 -0 0"/>      
      <geometry>        
        <mesh filename="package:///meshes/left_spur_1m_24t_drive_2_collision.stl"/>        
      </geometry>      
    </collision>    
    <inertial>      
      <origin xyz="-7.7519472167040379473e-15 -1.2127696869027398403e-16 0.0047949116178401512273" rpy="0 0 0"/>      
      <mass value="0.0032000000000000001533"/>      
      <inertia ixx="1.4019331346159892996e-07" ixy="1.6002410021230563878e-15" ixz="3.3868739208338279975e-37" iyy="1.4019331260388786185e-07" iyz="2.3470577016292310921e-36" izz="2.3838919844264071235e-07"/>      
    </inertial>    
  </link>  

  <joint name="left_elbow_yaw_drive" type="revolute">    
    <origin xyz="-0.024000000716143922441 -0.019000000152449375568 -0.019000000152448702495" rpy="1.5707963267948812369 -8.0032142329674811068e-15 1.2365412156371141215e-13"/>    
    <parent link="2xl430_gears_2"/>    
    <child link="spur_1m_24t_drive_2"/>    
    <axis xyz="0 0 1"/>    
    <limit effort="1" velocity="20" lower="-3.141592653589793116" upper="3.141592653589793116"/>    
    <joint_properties friction="0.0"/>    
  </joint>  

  <link name="spur_1m_24t_driven_2">    
    <visual>      
      <origin xyz="0 0 0" rpy="0 -0 0"/>      
      <geometry>        
        <mesh filename="package:///meshes/left_spur_1m_24t_driven_2_visual.stl"/>        
      </geometry>      
      <material name="spur_1m_24t_driven_2_material">        
        <color rgba="0.23137254901960788156 0.38039215686274507888 0.7058823529411765163 1.0"/>        
      </material>      
    </visual>    
    <collision>      
      <origin xyz="0 0 0" rpy="0 -0 0"/>      
      <geometry>        
        <mesh filename="package:///meshes/left_spur_1m_24t_driven_2_collision.stl"/>        
      </geometry>      
    </collision>    
    <inertial>      
      <origin xyz="2.2938228594596052967e-18 -5.7989635076863972055e-15 -0.00096866348640037638895" rpy="0 0 0"/>      
      <mass value="0.0027000000000000001429"/>      
      <inertia ixx="1.2026541119643507388e-07" ixy="-6.5732337140722154164e-38" ixz="0" iyy="1.2026541119643486212e-07" iyz="0" izz="2.2827257365099369132e-07"/>      
    </inertial>    
  </link>  

  <link name="elb_yaw_link">    
    <visual>      
      <origin xyz="0 0 0" rpy="0 -0 0"/>      
      <geometry>        
        <mesh filename="package:///meshes/left_elb_yaw_link_visual.stl"/>        
      </geometry>      
      <material name="elb_yaw_link_material">        
        <color rgba="0.61568627450980395466 0.81176470588235294379 0.9294117647058824927 1.0"/>        
      </material>      
    </visual>    
    <collision>      
      <origin xyz="0 0 0" rpy="0 -0 0"/>      
      <geometry>        
        <mesh filename="package:///meshes/left_elb_yaw_link_collision.stl"/>        
      </geometry>      
    </collision>    
    <inertial>      
      <origin xyz="5.2870889172653179162e-08 0.001987355818274245782 -0.023365661199828722389" rpy="0 0 0"/>      
      <mass value="0.017499999999999998196"/>      
      <inertia ixx="1.4097804991252561445e-05" ixy="1.6900809684089973752e-12" ixz="-1.1184673662179512683e-11" iyy="6.6367696417680327434e-06" iyz="1.0579908722588339983e-06" izz="8.9601142768980714413e-06"/>      
    </inertial>    
  </link>  

  <link name="spur_1m_24t_driven_3">    
    <visual>      
      <origin xyz="0 0 0" rpy="0 -0 0"/>      
      <geometry>        
        <mesh filename="package:///meshes/left_spur_1m_24t_driven_3_visual.stl"/>        
      </geometry>      
      <material name="spur_1m_24t_driven_3_material">        
        <color rgba="0.23137254901960788156 0.38039215686274507888 0.7058823529411765163 1.0"/>        
      </material>      
    </visual>    
    <collision>      
      <origin xyz="0 0 0" rpy="0 -0 0"/>      
      <geometry>        
        <mesh filename="package:///meshes/left_spur_1m_24t_driven_3_collision.stl"/>        
      </geometry>      
    </collision>    
    <inertial>      
      <origin xyz="-2.5461752756169335177e-17 -5.7989635076863972055e-15 -0.0025686634864003805856" rpy="0 0 0"/>      
      <mass value="0.0027000000000000001429"/>      
      <inertia ixx="1.2026541119643507388e-07" ixy="-2.9625477072638557134e-36" ixz="-1.5730367353383818768e-37" iyy="1.2026541119643486212e-07" iyz="1.1070062413737891266e-37" izz="2.2827257365099369132e-07"/>      
    </inertial>    
  </link>  

  <link name="2xl430_gears_3">    
    <visual>      
      <origin xyz="0 0 0" rpy="0 -0 0"/>      
      <geometry>        
        <mesh filename="package:///meshes/left_2xl430_gears_3_visual.stl"/>        
      </geometry>      
      <material name="2xl430_gears_3_material">        
        <color rgba="0.91900666046079215743 0.7025956886054134376 0.12479235365575502836 1.0"/>        
      </material>      
    </visual>    
    <collision>      
      <origin xyz="0 0 0" rpy="0 -0 0"/>      
      <geometry>        
        <mesh filename="package:///meshes/left_2xl430_gears_3_collision.stl"/>        
      </geometry>      
    </collision>    
    <inertial>      
      <origin xyz="0.00044511655645805531896 0.011545548856396192772 -0.024422395554887000452" rpy="0 0 0"/>      
      <mass value="0.10921242823035924585"/>      
      <inertia ixx="3.3278157643469847388e-05" ixy="1.9126365494094470788e-08" ixz="6.1055425070499333986e-07" iyy="2.5633987199175325191e-05" iyz="9.2332485824892220983e-07" izz="3.0316164317561431651e-05"/>      
    </inertial>    
  </link>  

  <link name="spur_1m_24t_drive_3">    
    <visual>      
      <origin xyz="0 0 0" rpy="0 -0 0"/>      
      <geometry>        
        <mesh filename="package:///meshes/left_spur_1m_24t_drive_3_visual.stl"/>        
      </geometry>      
      <material name="spur_1m_24t_drive_3_material">        
        <color rgba="0.61568627450980406568 0.81176470588235294379 0.92941176470588238168 1.0"/>        
      </material>      
    </visual>    
    <collision>      
      <origin xyz="0 0 0" rpy="0 -0 0"/>      
      <geometry>        
        <mesh filename="package:///meshes/left_spur_1m_24t_drive_3_collision.stl"/>        
      </geometry>      
    </collision>    
    <inertial>      
      <origin xyz="-7.7241916410884090338e-15 -1.2821586259418121241e-16 0.0047949116178401399516" rpy="0 0 0"/>      
      <mass value="0.0032000000000000001533"/>      
      <inertia ixx="1.4019331346159892996e-07" ixy="1.6002410008742266632e-15" ixz="-6.4318290562543542602e-36" iyy="1.4019331260388791479e-07" iyz="-3.5497739011481709691e-36" izz="2.3838919844264060647e-07"/>      
    </inertial>    
  </link>  

  <joint name="left_wrist_pitch_drive" type="revolute">    
    <origin xyz="-1.5244678436276970501e-10 0.024000000358067485884 -0.0080000000000028173575" rpy="-6.0688227754444846318e-17 9.0954925662261794972e-16 -1.5707963267950935116"/>    
    <parent link="2xl430_gears_3"/>    
    <child link="spur_1m_24t_drive_3"/>    
    <axis xyz="0 0 1"/>    
    <limit effort="1" velocity="20" lower="-1.570796326794896558" upper="1.570796326794896558"/>    
    <joint_properties friction="0.0"/>    
  </joint>  

  <link name="wrist_bearing_plate">    
    <visual>      
      <origin xyz="0 0 0" rpy="0 -0 0"/>      
      <geometry>        
        <mesh filename="package:///meshes/left_wrist_bearing_plate_visual.stl"/>        
      </geometry>      
      <material name="wrist_bearing_plate_material">        
        <color rgba="0.64496316278892629192 0.69011804996940528945 0.71706771073555886087 1.0"/>        
      </material>      
    </visual>    
    <collision>      
      <origin xyz="0 0 0" rpy="0 -0 0"/>      
      <geometry>        
        <mesh filename="package:///meshes/left_wrist_bearing_plate_collision.stl"/>        
      </geometry>      
    </collision>    
    <inertial>      
      <origin xyz="-0.0075896393545961445687 -0.015499999999999980807 -0.0018386110045718409307" rpy="0 0 0"/>      
      <mass value="0.0049000367468305548388"/>      
      <inertia ixx="4.9747313520140109893e-07" ixy="2.4215325079326760439e-22" ixz="1.8097509420524938529e-08" iyy="7.1295025627582438487e-07" iyz="3.0016154882842111316e-23" izz="1.192629795229191449e-06"/>      
    </inertial>    
  </link>  

  <joint name="left_wrist_roll_fixed" type="fixed">    
    <origin xyz="0.015500000000005648149 -4.3853809472693683347e-15 -0.044999999999999262812" rpy="-1.5598633495994326207e-14 -1.730560139634137368e-13 -1.5707963267946343233"/>    
    <parent link="2xl430_gears_3"/>    
    <child link="wrist_bearing_plate"/>    
    <axis xyz="0 0 1"/>    
    <limit effort="1" velocity="20"/>    
    <joint_properties friction="0.0"/>    
  </joint>  

  <link name="hand">    
    <visual>      
      <origin xyz="0 0 0" rpy="0 -0 0"/>      
      <geometry>        
        <mesh filename="package:///meshes/left_hand_visual.stl"/>        
      </geometry>      
      <material name="hand_material">        
        <color rgba="0.61568627450980395466 0.81176470588235294379 0.92941176470588238168 1.0"/>        
      </material>      
    </visual>    
    <collision>      
      <origin xyz="0 0 0" rpy="0 -0 0"/>      
      <geometry>        
        <mesh filename="package:///meshes/left_hand_collision.stl"/>        
      </geometry>      
    </collision>    
    <inertial>      
      <origin xyz="-4.3038382213233279171e-08 -0.049723778585231907801 -0.01793357200539034968" rpy="0 0 0"/>      
      <mass value="0.017000000000001441042"/>      
      <inertia ixx="9.492141461772624154e-06" ixy="-1.5549215897336582142e-11" ixz="-1.0809694196523374989e-11" iyy="4.0745028295199771232e-06" iyz="2.4719408559837120591e-07" izz="6.6623859523002763733e-06"/>      
    </inertial>    
  </link>  

  <joint name="left_wrist_roll" type="revolute">    
    <origin xyz="0.019000000000001057709 -3.5807262710463305666e-10 -0.027000000152450100849" rpy="1.2848055952475997313e-13 1.5707963267946998265 0"/>    
    <parent link="2xl430_gears_3"/>    
    <child link="hand"/>    
    <axis xyz="0 0 1"/>    
    <limit effort="1" velocity="20" lower="-1.570796326794896558" upper="1.570796326794896558"/>    
    <joint_properties friction="0.0"/>    
  </joint>  

  <joint name="left_wrist_pitch_driven" type="revolute">    
    <origin xyz="-8.3266726846886740532e-17 5.4817261840867104183e-16 -0.0016000000000001152189" rpy="-5.7142471032373773212e-16 5.5511151217739912712e-17 -1.570796326794896336"/>    
    <parent link="spur_1m_24t_driven_3"/>    
    <child link="2xl430_gears_3"/>    
    <axis xyz="0 0 1"/>    
    <limit effort="1" velocity="20" lower="-1.570796326794896558" upper="1.570796326794896558"/>    
    <joint_properties friction="0.0"/>    
  </joint>  

  <joint name="left_wrist_pitch_fixed" type="fixed">    
    <origin xyz="2.0816681711721685133e-17 -0.025299999999999989164 -0.051999999999999990674" rpy="1.5707963267948958919 -1.570796326794896336 0"/>    
    <parent link="elb_yaw_link"/>    
    <child link="spur_1m_24t_driven_3"/>    
    <axis xyz="0 0 1"/>    
    <limit effort="1" velocity="20"/>    
    <joint_properties friction="0.0"/>    
  </joint>  

  <joint name="left_elbow_yaw_fixed" type="fixed">    
    <origin xyz="1.3097162243624893563e-16 6.2450045135165055399e-17 0.0015999999999997960298" rpy="-3.141592653589793116 -5.5511151231207524813e-17 -1.570796326794896336"/>    
    <parent link="spur_1m_24t_driven_2"/>    
    <child link="elb_yaw_link"/>    
    <axis xyz="0 0 1"/>    
    <limit effort="1" velocity="20"/>    
    <joint_properties friction="0.0"/>    
  </joint>  

  <joint name="left_elbow_yaw_driven" type="revolute">    
    <origin xyz="-3.5807262710463305666e-10 -0.027000000152449854518 -0.01900000000000161629" rpy="1.570796326794891673 1.5707963267948441555 0"/>    
    <parent link="2xl430_gears_2"/>    
    <child link="spur_1m_24t_driven_2"/>    
    <axis xyz="0 0 1"/>    
    <limit effort="1" velocity="20" lower="-3.141592653589793116" upper="3.141592653589793116"/>    
    <joint_properties friction="0.0"/>    
  </joint>  

  <joint name="left_elbow_roll" type="revolute">    
    <origin xyz="7.6327832942979512154e-17 -0.018999999999999992589 -0.059000000000000031586" rpy="1.570796326794896558 -7.0029629609134176679e-16 7.044195017682708143e-15"/>    
    <parent link="sho_yaw_link"/>    
    <child link="2xl430_gears_2"/>    
    <axis xyz="0 0 1"/>    
    <limit effort="1" velocity="20" lower="-1.570796326794896558" upper="1.570796326794896558"/>    
    <joint_properties friction="0.0"/>    
  </joint>  

  <joint name="left_sho_yaw_fixed" type="fixed">    
    <origin xyz="0 1.561251128379126385e-17 0.0015999999999999903189" rpy="-3.1415926535897922278 1.4418079614154122748e-16 -6.106226635437282205e-16"/>    
    <parent link="spur_1m_24t_driven"/>    
    <child link="sho_yaw_link"/>    
    <axis xyz="0 0 1"/>    
    <limit effort="1" velocity="20"/>    
    <joint_properties friction="0.0"/>    
  </joint>  

  <joint name="left_sho_yaw_driven" type="revolute">    
    <origin xyz="-3.5807536102883119611e-10 -0.027000000152448761642 -0.019000000000006084938" rpy="1.5707963267949398567 1.8984813721086286179e-14 -7.1310113557521486963e-14"/>    
    <parent link="2xl430_gears"/>    
    <child link="spur_1m_24t_driven"/>    
    <axis xyz="0 0 1"/>    
    <limit effort="1" velocity="20" lower="-3.141592653589793116" upper="3.141592653589793116"/>    
    <joint_properties friction="0.0"/>    
  </joint>  

  <joint name="left_sho_roll" type="revolute">    
    <origin xyz="-0.018999999999999992589 0.00099999999999997833677 0.026999999999999996225" rpy="-3.141592653589793116 1.5707963267948954478 0"/>    
    <parent link="sho_pitch_link"/>    
    <child link="2xl430_gears"/>    
    <axis xyz="0 0 1"/>    
    <limit effort="1" velocity="20" lower="-1.570796326794896558" upper="1.570796326794896558"/>    
    <joint_properties friction="0.0"/>    
  </joint>  

  <joint name="left_sho_pitch" type="revolute">    
    <origin xyz="-0.0039999999999985160273 0.012999999999999725317 -0.01424999999999848263" rpy="-1.5707963267948332753 -5.5178084323870191707e-14 -1.1649761152065636686e-13"/>    
    <parent link="xc430"/>    
    <child link="sho_pitch_link"/>    
    <axis xyz="0 0 1"/>    
    <limit effort="1" velocity="20" lower="-1.570796326794896558" upper="1.570796326794896558"/>    
    <joint_properties friction="0.0"/>    
  </joint>  


</robot>