<?xml version="1.0" ?><robot name="left_arm">  
  <link name="xc430">    
    <visual>      
      <origin xyz="0 0 0" rpy="0 -0 0"/>      
      <geometry>        
        <mesh filename="package:///meshes/left_xc430_visual.stl"/>        
      </geometry>      
      <material name="xc430_material">        
        <color rgba="0.3960334863748344314 0.50878377002232877402 0.71126755432153676573 1.0"/>        
      </material>      
    </visual>    
    <collision>      
      <origin xyz="0 0 0" rpy="0 -0 0"/>      
      <geometry>        
        <mesh filename="package:///meshes/left_xc430_collision.stl"/>        
      </geometry>      
    </collision>    
    <inertial>      
      <origin xyz="0.007649938948420367639 -0.0056800345415021161882 -0.014255781343936730146" rpy="0 0 0"/>      
      <mass value="0.065021926915724281848"/>      
      <inertia ixx="1.0685477757330408185e-05" ixy="2.4991048730003623443e-08" ixz="-4.3793050176056901397e-09" iyy="1.6030858372951694338e-05" iyz="-9.5846760480286561493e-09" izz="1.8186829094811185627e-05"/>      
    </inertial>    
  </link>  

  <link name="sho_pitch_link">    
    <visual>      
      <origin xyz="0 0 0" rpy="0 -0 0"/>      
      <geometry>        
        <mesh filename="package:///meshes/left_sho_pitch_link_visual.stl"/>        
      </geometry>      
      <material name="sho_pitch_link_material">        
        <color rgba="0.61568627450980395466 0.81176470588235294379 0.92941176470588238168 1.0"/>        
      </material>      
    </visual>    
    <collision>      
      <origin xyz="0 0 0" rpy="0 -0 0"/>      
      <geometry>        
        <mesh filename="package:///meshes/left_sho_pitch_link_collision.stl"/>        
      </geometry>      
    </collision>    
    <inertial>      
      <origin xyz="5.8254248120052071971e-11 -5.1264642561120891203e-05 0.0082440788127094884186" rpy="0 0 0"/>      
      <mass value="0.0054658167229830727923"/>      
      <inertia ixx="7.8001571192438926207e-07" ixy="-1.362001715498003601e-14" ixz="-5.4561052933656508776e-15" iyy="1.8499441886712514344e-06" iyz="4.7427934912491398702e-09" izz="1.9577243674425458058e-06"/>      
    </inertial>    
  </link>  

  <link name="2xl430_gears">    
    <visual>      
      <origin xyz="0 0 0" rpy="0 -0 0"/>      
      <geometry>        
        <mesh filename="package:///meshes/left_2xl430_gears_visual.stl"/>        
      </geometry>      
      <material name="2xl430_gears_material">        
        <color rgba="0.92986371788500021829 0.70481290401000895596 0.1039417481935485249 1.0"/>        
      </material>      
    </visual>    
    <collision>      
      <origin xyz="0 0 0" rpy="0 -0 0"/>      
      <geometry>        
        <mesh filename="package:///meshes/left_2xl430_gears_collision.stl"/>        
      </geometry>      
    </collision>    
    <inertial>      
      <origin xyz="-0.01169099042949864678 -0.0018640254999320031871 -0.018537112917890789104" rpy="0 0 0"/>      
      <mass value="0.10501969455283197141"/>      
      <inertia ixx="2.3730855574653463973e-05" ixy="6.3698299422680390943e-07" ixz="-2.6196591648175582968e-08" iyy="2.9185546824402445624e-05" iyz="-5.7586555809654170624e-07" izz="3.1247581181374436705e-05"/>      
    </inertial>    
  </link>  

  <link name="spur_1m_24t_drive">    
    <visual>      
      <origin xyz="0 0 0" rpy="0 -0 0"/>      
      <geometry>        
        <mesh filename="package:///meshes/left_spur_1m_24t_drive_visual.stl"/>        
      </geometry>      
      <material name="spur_1m_24t_drive_material">        
        <color rgba="0.61568627450980395466 0.81176470588235294379 0.92941176470588238168 1.0"/>        
      </material>      
    </visual>    
    <collision>      
      <origin xyz="0 0 0" rpy="0 -0 0"/>      
      <geometry>        
        <mesh filename="package:///meshes/left_spur_1m_24t_drive_collision.stl"/>        
      </geometry>      
    </collision>    
    <inertial>      
      <origin xyz="-7.7519087863383936372e-15 -1.2153135340684706176e-16 0.0047949116178401442884" rpy="0 0 0"/>      
      <mass value="0.0028390468118397902894"/>      
      <inertia ixx="1.2437980613262772114e-07" ixy="1.4197372144770222767e-15" ixz="-1.5495887109503665114e-37" iyy="1.243798053716646504e-07" iyz="-4.8230046432124436823e-37" izz="2.1149940431738185887e-07"/>      
    </inertial>    
  </link>  

  <joint name="left_sho_yaw_drive" type="revolute">    
    <origin xyz="-0.024000000716149091917 -0.019000000152453261348 -0.019000000152451658464" rpy="1.5707963267948958919 -4.4976359533854379418e-14 2.4607735454933739048e-14"/>    
    <parent link="2xl430_gears"/>    
    <child link="spur_1m_24t_drive"/>    
    <axis xyz="0 0 1"/>    
    <limit effort="1" velocity="20" lower="-3.141592653589793116" upper="3.141592653589793116"/>    
    <joint_properties friction="0.0"/>    
  </joint>  

  <link name="spur_1m_24t_driven">    
    <visual>      
      <origin xyz="0 0 0" rpy="0 -0 0"/>      
      <geometry>        
        <mesh filename="package:///meshes/left_spur_1m_24t_driven_visual.stl"/>        
      </geometry>      
      <material name="spur_1m_24t_driven_material">        
        <color rgba="0.23137254901960788156 0.38039215686274507888 0.7058823529411765163 1.0"/>        
      </material>      
    </visual>    
    <collision>      
      <origin xyz="0 0 0" rpy="0 -0 0"/>      
      <geometry>        
        <mesh filename="package:///meshes/left_spur_1m_24t_driven_collision.stl"/>        
      </geometry>      
    </collision>    
    <inertial>      
      <origin xyz="-4.7580846418343935286e-18 -5.7993764787103834268e-15 -0.00096866348640038679729" rpy="0 0 0"/>      
      <mass value="0.0019107037020329885237"/>      
      <inertia ixx="8.5107987555388190322e-08" ixy="-3.6559376044217627684e-37" ixz="0" iyy="8.5107987555388057973e-08" iyz="0" izz="1.61541204276871012e-07"/>      
    </inertial>    
  </link>  

  <link name="sho_yaw_link">    
    <visual>      
      <origin xyz="0 0 0" rpy="0 -0 0"/>      
      <geometry>        
        <mesh filename="package:///meshes/left_sho_yaw_link_visual.stl"/>        
      </geometry>      
      <material name="sho_yaw_link_material">        
        <color rgba="0.61568627450980395466 0.81176470588235294379 0.92941176470588238168 1.0"/>        
      </material>      
    </visual>    
    <collision>      
      <origin xyz="0 0 0" rpy="0 -0 0"/>      
      <geometry>        
        <mesh filename="package:///meshes/left_sho_yaw_link_collision.stl"/>        
      </geometry>      
    </collision>    
    <inertial>      
      <origin xyz="-1.2954272486096536888e-18 4.6931218992822002367e-18 -0.024214576156328396217" rpy="0 0 0"/>      
      <mass value="0.012515007486099719372"/>      
      <inertia ixx="7.8103015795623802274e-06" ixy="3.1069782961625653339e-13" ixz="0" iyy="4.8995994669684958124e-06" iyz="0" izz="3.8486326781559904804e-06"/>      
    </inertial>    
  </link>  

  <link name="2xl430_gears_2">    
    <visual>      
      <origin xyz="0 0 0" rpy="0 -0 0"/>      
      <geometry>        
        <mesh filename="package:///meshes/left_2xl430_gears_2_visual.stl"/>        
      </geometry>      
      <material name="2xl430_gears_2_material">        
        <color rgba="0.92986371788500021829 0.70481290401000895596 0.1039417481935485249 1.0"/>        
      </material>      
    </visual>    
    <collision>      
      <origin xyz="0 0 0" rpy="0 -0 0"/>      
      <geometry>        
        <mesh filename="package:///meshes/left_2xl430_gears_2_collision.stl"/>        
      </geometry>      
    </collision>    
    <inertial>      
      <origin xyz="-0.011690990429496775013 -0.0018640254999317382081 -0.018537112917886455765" rpy="0 0 0"/>      
      <mass value="0.10501969455283197141"/>      
      <inertia ixx="2.373085557465203757e-05" ixy="6.36982994226230574e-07" ixz="-2.6196591648377547386e-08" iyy="2.9185546824401300436e-05" iyz="-5.7586555809669438393e-07" izz="3.1247581181373433818e-05"/>      
    </inertial>    
  </link>  

  <link name="spur_1m_24t_drive_2">    
    <visual>      
      <origin xyz="0 0 0" rpy="0 -0 0"/>      
      <geometry>        
        <mesh filename="package:///meshes/left_spur_1m_24t_drive_2_visual.stl"/>        
      </geometry>      
      <material name="spur_1m_24t_drive_2_material">        
        <color rgba="0.61568627450980395466 0.81176470588235294379 0.92941176470588238168 1.0"/>        
      </material>      
    </visual>    
    <collision>      
      <origin xyz="0 0 0" rpy="0 -0 0"/>      
      <geometry>        
        <mesh filename="package:///meshes/left_spur_1m_24t_drive_2_collision.stl"/>        
      </geometry>      
    </collision>    
    <inertial>      
      <origin xyz="-7.7519087863383936372e-15 -1.2153135340684745619e-16 0.0047949116178401364821" rpy="0 0 0"/>      
      <mass value="0.0028390468118397902894"/>      
      <inertia ixx="1.2437980613262777408e-07" ixy="1.419737221362293343e-15" ixz="-1.3786460596123746092e-37" iyy="1.2437980537166470334e-07" iyz="-9.9920846415556119903e-38" izz="2.1149940431738196475e-07"/>      
    </inertial>    
  </link>  

  <joint name="left_elbow_yaw_drive" type="revolute">    
    <origin xyz="-0.024000000716143943258 -0.019000000152449458835 -0.019000000152448723312" rpy="1.5707963267948803487 -8.8097374115804582929e-15 1.2391989173894776153e-13"/>    
    <parent link="2xl430_gears_2"/>    
    <child link="spur_1m_24t_drive_2"/>    
    <axis xyz="0 0 1"/>    
    <limit effort="1" velocity="20" lower="-3.141592653589793116" upper="3.141592653589793116"/>    
    <joint_properties friction="0.0"/>    
  </joint>  

  <link name="spur_1m_24t_driven_2">    
    <visual>      
      <origin xyz="0 0 0" rpy="0 -0 0"/>      
      <geometry>        
        <mesh filename="package:///meshes/left_spur_1m_24t_driven_2_visual.stl"/>        
      </geometry>      
      <material name="spur_1m_24t_driven_2_material">        
        <color rgba="0.23137254901960788156 0.38039215686274507888 0.7058823529411765163 1.0"/>        
      </material>      
    </visual>    
    <collision>      
      <origin xyz="0 0 0" rpy="0 -0 0"/>      
      <geometry>        
        <mesh filename="package:///meshes/left_spur_1m_24t_driven_2_collision.stl"/>        
      </geometry>      
    </collision>    
    <inertial>      
      <origin xyz="-4.7580846418342417653e-18 -5.7993764787103826379e-15 -0.00096866348640036251116" rpy="0 0 0"/>      
      <mass value="0.0019107037020329885237"/>      
      <inertia ixx="8.5107987555388216792e-08" ixy="-1.6901296385098867282e-36" ixz="1.7653430435007051828e-36" iyy="8.5107987555388057973e-08" iyz="3.3761471308164658484e-36" izz="1.6154120427687106494e-07"/>      
    </inertial>    
  </link>  

  <link name="elb_yaw_link">    
    <visual>      
      <origin xyz="0 0 0" rpy="0 -0 0"/>      
      <geometry>        
        <mesh filename="package:///meshes/left_elb_yaw_link_visual.stl"/>        
      </geometry>      
      <material name="elb_yaw_link_material">        
        <color rgba="0.61568627450980406568 0.81176470588235294379 0.92941176470588238168 1.0"/>        
      </material>      
    </visual>    
    <collision>      
      <origin xyz="0 0 0" rpy="0 -0 0"/>      
      <geometry>        
        <mesh filename="package:///meshes/left_elb_yaw_link_collision.stl"/>        
      </geometry>      
    </collision>    
    <inertial>      
      <origin xyz="5.2870889172994923869e-08 0.001987355818274245782 -0.023365661199828750144" rpy="0 0 0"/>      
      <mass value="0.014606428020591945977"/>      
      <inertia ixx="1.17667756487469936e-05" ixy="1.4106312007994768316e-12" ixz="-9.3353217587898983128e-12" iyy="5.5393998892419725165e-06" iyz="8.8305528697668242434e-07" izz="7.4785865281022818806e-06"/>      
    </inertial>    
  </link>  

  <link name="spur_1m_24t_driven_3">    
    <visual>      
      <origin xyz="0 0 0" rpy="0 -0 0"/>      
      <geometry>        
        <mesh filename="package:///meshes/left_spur_1m_24t_driven_3_visual.stl"/>        
      </geometry>      
      <material name="spur_1m_24t_driven_3_material">        
        <color rgba="0.23137254901960788156 0.38039215686274507888 0.7058823529411765163 1.0"/>        
      </material>      
    </visual>    
    <collision>      
      <origin xyz="0 0 0" rpy="0 -0 0"/>      
      <geometry>        
        <mesh filename="package:///meshes/left_spur_1m_24t_driven_3_collision.stl"/>        
      </geometry>      
    </collision>    
    <inertial>      
      <origin xyz="-2.5574766353556168795e-17 -5.7993764787103834268e-15 -0.002568663486400384055" rpy="0 0 0"/>      
      <mass value="0.0019107037020329885237"/>      
      <inertia ixx="8.5107987555388190322e-08" ixy="5.7697031649781155731e-39" ixz="-3.0252491959815126819e-37" iyy="8.5107987555388057973e-08" iyz="3.5356000143236472845e-37" izz="1.61541204276871012e-07"/>      
    </inertial>    
  </link>  

  <link name="2xl430_gears_3">    
    <visual>      
      <origin xyz="0 0 0" rpy="0 -0 0"/>      
      <geometry>        
        <mesh filename="package:///meshes/left_2xl430_gears_3_visual.stl"/>        
      </geometry>      
      <material name="2xl430_gears_3_material">        
        <color rgba="0.92986371788500021829 0.70481290401000895596 0.1039417481935485249 1.0"/>        
      </material>      
    </visual>    
    <collision>      
      <origin xyz="0 0 0" rpy="0 -0 0"/>      
      <geometry>        
        <mesh filename="package:///meshes/left_2xl430_gears_3_collision.stl"/>        
      </geometry>      
    </collision>    
    <inertial>      
      <origin xyz="0.00046288708211645056322 0.011690990071419760793 -0.025135974652516782091" rpy="0 0 0"/>      
      <mass value="0.10501969455283197141"/>      
      <inertia ixx="3.1247581181373250859e-05" ixy="2.6196591650102477044e-08" ixz="5.7586555809730191831e-07" iyy="2.3730855574652068063e-05" iyz="6.36982994228104105e-07" izz="2.9185546824400209457e-05"/>      
    </inertial>    
  </link>  

  <link name="spur_1m_24t_drive_3">    
    <visual>      
      <origin xyz="0 0 0" rpy="0 -0 0"/>      
      <geometry>        
        <mesh filename="package:///meshes/left_spur_1m_24t_drive_3_visual.stl"/>        
      </geometry>      
      <material name="spur_1m_24t_drive_3_material">        
        <color rgba="0.61568627450980395466 0.81176470588235294379 0.92941176470588238168 1.0"/>        
      </material>      
    </visual>    
    <collision>      
      <origin xyz="0 0 0" rpy="0 -0 0"/>      
      <geometry>        
        <mesh filename="package:///meshes/left_spur_1m_24t_drive_3_collision.stl"/>        
      </geometry>      
    </collision>    
    <inertial>      
      <origin xyz="-7.7519087863383936372e-15 -1.2153135340684745619e-16 0.0047949116178401408189" rpy="0 0 0"/>      
      <mass value="0.0028390468118397902894"/>      
      <inertia ixx="1.2437980613262772114e-07" ixy="1.4197372228685881373e-15" ixz="-5.0969005492588067135e-36" iyy="1.2437980537166467687e-07" iyz="1.1616087853964260718e-36" izz="2.1149940431738185887e-07"/>      
    </inertial>    
  </link>  

  <joint name="left_wrist_pitch_drive" type="revolute">    
    <origin xyz="-1.5244679043430187093e-10 0.024000000358067236084 -0.0080000000000028867464" rpy="-2.7483519458837874956e-17 4.1567008429808215919e-16 -1.5707963267950932895"/>    
    <parent link="2xl430_gears_3"/>    
    <child link="spur_1m_24t_drive_3"/>    
    <axis xyz="0 0 1"/>    
    <limit effort="1" velocity="20" lower="-1.570796326794896558" upper="1.570796326794896558"/>    
    <joint_properties friction="0.0"/>    
  </joint>  

  <link name="wrist_bearing_plate">    
    <visual>      
      <origin xyz="0 0 0" rpy="0 -0 0"/>      
      <geometry>        
        <mesh filename="package:///meshes/left_wrist_bearing_plate_visual.stl"/>        
      </geometry>      
      <material name="wrist_bearing_plate_material">        
        <color rgba="0.64524122402591754799 0.68440476750126189032 0.7077786319257823866 1.0"/>        
      </material>      
    </visual>    
    <collision>      
      <origin xyz="0 0 0" rpy="0 -0 0"/>      
      <geometry>        
        <mesh filename="package:///meshes/left_wrist_bearing_plate_collision.stl"/>        
      </geometry>      
    </collision>    
    <inertial>      
      <origin xyz="-0.0077108207619254994294 -0.015499999999999986011 -0.001856060779943109534" rpy="0 0 0"/>      
      <mass value="0.0056496574836909499093"/>      
      <inertia ixx="5.9171079900928515775e-07" ixy="6.2097736507831445947e-23" ixz="1.8301204254972737854e-08" iyy="8.216220249489035397e-07" iyz="1.1608938254982709686e-23" izz="1.3935387964192944345e-06"/>      
    </inertial>    
  </link>  

  <joint name="left_wrist_roll_fixed" type="fixed">    
    <origin xyz="0.015500000000005634271 -4.4964032497318839887e-15 -0.044999999999999221179" rpy="-1.5321077739861447308e-14 -1.7302825838780371196e-13 -1.5707963267946343233"/>    
    <parent link="2xl430_gears_3"/>    
    <child link="wrist_bearing_plate"/>    
    <axis xyz="0 0 1"/>    
    <limit effort="1" velocity="20"/>    
    <joint_properties friction="0.0"/>    
  </joint>  

  <link name="gripper_connector">    
    <visual>      
      <origin xyz="0 0 0" rpy="0 -0 0"/>      
      <geometry>        
        <mesh filename="package:///meshes/left_gripper_connector_visual.stl"/>        
      </geometry>      
      <material name="gripper_connector_material">        
        <color rgba="0.61568627450980395466 0.81176470588235283277 0.92941176470588238168 1.0"/>        
      </material>      
    </visual>    
    <collision>      
      <origin xyz="0 0 0" rpy="0 -0 0"/>      
      <geometry>        
        <mesh filename="package:///meshes/left_gripper_connector_collision.stl"/>        
      </geometry>      
    </collision>    
    <inertial>      
      <origin xyz="-0.00020299682521053772602 -0.023971521766976134488 -0.0085969861498480203144" rpy="0 0 0"/>      
      <mass value="0.010749847783550764077"/>      
      <inertia ixx="5.6975779571583543608e-06" ixy="-2.5156189499996475804e-08" ixz="-5.172378807037867625e-08" iyy="4.1113818885763115619e-06" iyz="2.0765009312234069726e-08" izz="2.4319826940967949828e-06"/>      
    </inertial>    
  </link>  

  <link name="gripper">    
    <visual>      
      <origin xyz="0 0 0" rpy="0 -0 0"/>      
      <geometry>        
        <mesh filename="package:///meshes/left_gripper_visual.stl"/>        
      </geometry>      
      <material name="gripper_material">        
        <color rgba="0.6457630783199683755 0.73322359874460429907 0.76035515688353960684 1.0"/>        
      </material>      
    </visual>    
    <collision>      
      <origin xyz="0 0 0" rpy="0 -0 0"/>      
      <geometry>        
        <mesh filename="package:///meshes/left_gripper_collision.stl"/>        
      </geometry>      
    </collision>    
    <inertial>      
      <origin xyz="0.00515417891931551405 0.002776236535944844562 -0.0064249550239260291157" rpy="0 0 0"/>      
      <mass value="0.08131732839378616462"/>      
      <inertia ixx="4.3304520380580929068e-05" ixy="4.8646698778636967135e-06" ixz="1.8050387215175781258e-05" iyy="0.00011082035907674373442" iyz="-4.2102691126519959104e-06" izz="9.1484178053678687453e-05"/>      
    </inertial>    
  </link>  

  <joint name="left_gripper" type="fixed">    
    <origin xyz="-2.0816681711721685133e-17 -0.037000000000000060618 -0.036000000000000004219" rpy="-1.570796326794896558 -1.570796326794896558 0"/>    
    <parent link="gripper_connector"/>    
    <child link="gripper"/>    
    <axis xyz="0 0 1"/>    
    <limit effort="1" velocity="20"/>    
    <joint_properties friction="0.0"/>    
  </joint>  

  <joint name="left_wrist_roll" type="revolute">    
    <origin xyz="0.019000000000000946687 -3.5807279363808675043e-10 -0.027000000152449934315" rpy="2.2204460492518493875e-16 1.5707963267947431252 0"/>    
    <parent link="2xl430_gears_3"/>    
    <child link="gripper_connector"/>    
    <axis xyz="0 0 1"/>    
    <limit effort="1" velocity="20" lower="-1.570796326794896558" upper="1.570796326794896558"/>    
    <joint_properties friction="0.0"/>    
  </joint>  

  <joint name="left_wrist_pitch_driven" type="revolute">    
    <origin xyz="8.3266726846886740532e-17 -9.0205620750793968909e-17 -0.0016000000000000319522" rpy="-5.8286708792805808901e-16 5.5511151231420603539e-17 -1.570796326794896558"/>    
    <parent link="spur_1m_24t_driven_3"/>    
    <child link="2xl430_gears_3"/>    
    <axis xyz="0 0 1"/>    
    <limit effort="1" velocity="20" lower="-1.570796326794896558" upper="1.570796326794896558"/>    
    <joint_properties friction="0.0"/>    
  </joint>  

  <joint name="left_wrist_pitch_fixed" type="fixed">    
    <origin xyz="2.6020852139652106416e-18 -0.025299999999999975286 -0.052000000000000073941" rpy="1.570796326794896558 -1.570796326794896558 0"/>    
    <parent link="elb_yaw_link"/>    
    <child link="spur_1m_24t_driven_3"/>    
    <axis xyz="0 0 1"/>    
    <limit effort="1" velocity="20"/>    
    <joint_properties friction="0.0"/>    
  </joint>  

  <joint name="left_elbow_yaw_fixed" type="fixed">    
    <origin xyz="0 4.336808689942017736e-18 0.0015999999999999625633" rpy="3.141592653589793116 -2.7755575615638071693e-17 -1.570796326794896558"/>    
    <parent link="spur_1m_24t_driven_2"/>    
    <child link="elb_yaw_link"/>    
    <axis xyz="0 0 1"/>    
    <limit effort="1" velocity="20"/>    
    <joint_properties friction="0.0"/>    
  </joint>  

  <joint name="left_elbow_yaw_driven" type="revolute">    
    <origin xyz="-3.5807171117063774091e-10 -0.02700000015244839735 -0.019000000000001713435" rpy="1.5707963267949496267 -7.3274719625257223556e-15 2.0539125955574310126e-15"/>    
    <parent link="2xl430_gears_2"/>    
    <child link="spur_1m_24t_driven_2"/>    
    <axis xyz="0 0 1"/>    
    <limit effort="1" velocity="20" lower="-3.141592653589793116" upper="3.141592653589793116"/>    
    <joint_properties friction="0.0"/>    
  </joint>  

  <joint name="left_elbow_roll" type="revolute">    
    <origin xyz="-2.0816681711721685133e-17 -0.019000000000000332595 -0.058999999999999955258" rpy="1.570796326794896558 2.3770770070187202115e-16 1.6653345369375180711e-15"/>    
    <parent link="sho_yaw_link"/>    
    <child link="2xl430_gears_2"/>    
    <axis xyz="0 0 1"/>    
    <limit effort="1" velocity="20" lower="-1.570796326794896558" upper="1.570796326794896558"/>    
    <joint_properties friction="0.0"/>    
  </joint>  

  <joint name="left_sho_yaw_fixed" type="fixed">    
    <origin xyz="0 0 0.0015999999999999972577" rpy="-3.1415926535897926719 2.5818166553570186493e-16 2.2203585271973257171e-29"/>    
    <parent link="spur_1m_24t_driven"/>    
    <child link="sho_yaw_link"/>    
    <axis xyz="0 0 1"/>    
    <limit effort="1" velocity="20"/>    
    <joint_properties friction="0.0"/>    
  </joint>  

  <joint name="left_sho_yaw_driven" type="revolute">    
    <origin xyz="-3.5807542347887633127e-10 -0.027000000152448758173 -0.01900000000000607106" rpy="1.5707963267949391906 1.9206858326011355353e-14 -7.0419123741435993116e-14"/>    
    <parent link="2xl430_gears"/>    
    <child link="spur_1m_24t_driven"/>    
    <axis xyz="0 0 1"/>    
    <limit effort="1" velocity="20" lower="-3.141592653589793116" upper="3.141592653589793116"/>    
    <joint_properties friction="0.0"/>    
  </joint>  

  <joint name="left_sho_roll" type="revolute">    
    <origin xyz="-0.018999999999999975242 0.0010000000000000217049 0.027000000000000023981" rpy="-3.141592653589793116 1.5707963267948961139 0"/>    
    <parent link="sho_pitch_link"/>    
    <child link="2xl430_gears"/>    
    <axis xyz="0 0 1"/>    
    <limit effort="1" velocity="20" lower="-1.570796326794896558" upper="1.570796326794896558"/>    
    <joint_properties friction="0.0"/>    
  </joint>  

  <joint name="left_sho_pitch" type="revolute">    
    <origin xyz="-0.0039999999999985160273 0.012999999999999725317 -0.01424999999999848263" rpy="-1.5707963267948332753 -5.5178084323870191707e-14 -1.1649761152065636686e-13"/>    
    <parent link="xc430"/>    
    <child link="sho_pitch_link"/>    
    <axis xyz="0 0 1"/>    
    <limit effort="1" velocity="20" lower="-1.570796326794896558" upper="1.570796326794896558"/>    
    <joint_properties friction="0.0"/>    
  </joint>  


</robot>