<?xml version="1.0" ?><robot name="toddlerbot">  
  <link name="torso">    
    <visual>      
      <origin xyz="0 0 0" rpy="0 -0 0"/>      
      <geometry>        
        <mesh filename="package:///meshes/torso_visual.stl"/>        
      </geometry>      
      <material name="torso_material">        
        <color rgba="0.58593977560074728128 0.73200332251165178832 0.84622153029708702121 1.0"/>        
      </material>      
    </visual>    
    <collision>      
      <origin xyz="0 0 0" rpy="0 -0 0"/>      
      <geometry>        
        <mesh filename="package:///meshes/torso_collision.stl"/>        
      </geometry>      
    </collision>    
    <inertial>      
      <origin xyz="-0.0074402562279124312417 0.0025066622175970347877 0.07243445560768882463" rpy="0 0 0"/>      
      <mass value="0.58475267652546303321"/>      
      <inertia ixx="0.0016161156662577464554" ixy="-1.474745924858701948e-05" ixz="3.3560094571361662986e-07" iyy="0.0013094545225363026821" iyz="2.4218994132079873523e-05" izz="0.0011897783104580597104"/>      
    </inertial>    
  </link>  

  <link name="spur_1m_20t">    
    <visual>      
      <origin xyz="0 0 0" rpy="0 -0 0"/>      
      <geometry>        
        <mesh filename="package:///meshes/spur_1m_20t_visual.stl"/>        
      </geometry>      
      <material name="spur_1m_20t_material">        
        <color rgba="0.64705882352941179736 0.64705882352941179736 0.64705882352941179736 1.0"/>        
      </material>      
    </visual>    
    <collision>      
      <origin xyz="0 0 0" rpy="0 -0 0"/>      
      <geometry>        
        <mesh filename="package:///meshes/spur_1m_20t_collision.stl"/>        
      </geometry>      
    </collision>    
    <inertial>      
      <origin xyz="-2.9678192710719268851e-18 -7.2909235904444700427e-18 0.0033745971730663282089" rpy="0 0 0"/>      
      <mass value="0.0015534950290892286448"/>      
      <inertia ixx="4.4726508287871812856e-08" ixy="5.898867711257843534e-24" ixz="-1.4055384018007298852e-37" iyy="4.4726508287871759916e-08" iyz="-4.7306831784492834109e-38" izz="7.9558906764902019844e-08"/>      
    </inertial>    
  </link>  

  <joint name="neck_yaw_drive" type="revolute">    
    <origin xyz="-0.0050000000000043915566 2.1780059937422389857e-15 0.12148651076282247774" rpy="-4.6722658561527960149e-15 -3.0241828739332580702e-14 3.0478935990547233347e-14"/>    
    <parent link="torso"/>    
    <child link="spur_1m_20t"/>    
    <axis xyz="0 0 1"/>    
    <limit effort="1" velocity="20" lower="-2.2689280275926284602" upper="2.2689280275926284602"/>    
    <joint_properties friction="0.0"/>    
  </joint>  

  <link name="neck_yaw_link">    
    <visual>      
      <origin xyz="0 0 0" rpy="0 -0 0"/>      
      <geometry>        
        <mesh filename="package:///meshes/neck_yaw_link_visual.stl"/>        
      </geometry>      
      <material name="neck_yaw_link_material">        
        <color rgba="0.33636252417476658616 0.48680769190259876034 0.74976123534949790095 1.0"/>        
      </material>      
    </visual>    
    <collision>      
      <origin xyz="0 0 0" rpy="0 -0 0"/>      
      <geometry>        
        <mesh filename="package:///meshes/neck_yaw_link_collision.stl"/>        
      </geometry>      
    </collision>    
    <inertial>      
      <origin xyz="2.7291286460607713451e-05 -0.00019798992283530673832 0.011527412037194864278" rpy="0 0 0"/>      
      <mass value="0.0085168305947458285143"/>      
      <inertia ixx="1.0407116999274153436e-06" ixy="2.421015046618271679e-11" ixz="-4.7246803216679303407e-10" iyy="1.1240009954110310649e-06" iyz="3.0834841754636015976e-08" izz="3.1587565167291864821e-07"/>      
    </inertial>    
  </link>  

  <link name="neck_pitch_link">    
    <visual>      
      <origin xyz="0 0 0" rpy="0 -0 0"/>      
      <geometry>        
        <mesh filename="package:///meshes/neck_pitch_link_visual.stl"/>        
      </geometry>      
      <material name="neck_pitch_link_material">        
        <color rgba="0.74911126277760042846 0.80002799398726853752 0.87441258869524285391 1.0"/>        
      </material>      
    </visual>    
    <collision>      
      <origin xyz="0 0 0" rpy="0 -0 0"/>      
      <geometry>        
        <mesh filename="package:///meshes/neck_pitch_link_collision.stl"/>        
      </geometry>      
    </collision>    
    <inertial>      
      <origin xyz="-0.003437049761572200015 0.032876793988991251383 -0.00036476492134670401466" rpy="0 0 0"/>      
      <mass value="0.11211553874797881847"/>      
      <inertia ixx="7.70157554598498086e-05" ixy="-2.1757968319829864274e-06" ixz="-2.8732209413525655209e-06" iyy="6.3502636688154214277e-05" iyz="-1.2492352737635124786e-05" izz="2.8610002383976241419e-05"/>      
    </inertial>    
  </link>  

  <link name="spur_gear_(13_teeth)">    
    <visual>      
      <origin xyz="0 0 0" rpy="0 -0 0"/>      
      <geometry>        
        <mesh filename="package:///meshes/spur_gear_(13_teeth)_visual.stl"/>        
      </geometry>      
      <material name="spur_gear_(13_teeth)_material">        
        <color rgba="0.64705882352941179736 0.64705882352941179736 0.64705882352941179736 1.0"/>        
      </material>      
    </visual>    
    <collision>      
      <origin xyz="0 0 0" rpy="0 -0 0"/>      
      <geometry>        
        <mesh filename="package:///meshes/spur_gear_(13_teeth)_collision.stl"/>        
      </geometry>      
    </collision>    
    <inertial>      
      <origin xyz="9.1521557942323573101e-10 -5.4872578735152555475e-10 0.0092751511485596373902" rpy="0 0 0"/>      
      <mass value="0.00081469437497230865874"/>      
      <inertia ixx="2.0244841463618384181e-08" ixy="2.9781775006960639087e-15" ixz="-8.2976066070018727639e-15" iyy="2.0244839778533685891e-08" iyz="1.3142117784831662071e-15" izz="1.8905472907863310999e-08"/>      
    </inertial>    
  </link>  

  <joint name="neck_pitch_drive" type="revolute">    
    <origin xyz="-1.7971735211119721498e-15 0.015649999999999192335 -0.008799999999996657718" rpy="-9.1684649781985877855e-16 7.2823649231784177849e-17 -1.5707963267948912289"/>    
    <parent link="neck_pitch_link"/>    
    <child link="spur_gear_(13_teeth)"/>    
    <axis xyz="0 0 1"/>    
    <limit effort="1" velocity="20" lower="-1.4279966607226330932" upper="1.4279966607226330932"/>    
    <joint_properties friction="0.0"/>    
  </joint>  

  <joint name="neck_pitch_driven" type="revolute">    
    <origin xyz="3.7499998592482874926e-10 -0.0051500000614754029571 0.027499999999999941158" rpy="1.570796326794896336 8.6610484296623782615e-16 3.1415926535897926719"/>    
    <parent link="neck_yaw_link"/>    
    <child link="neck_pitch_link"/>    
    <axis xyz="0 0 1"/>    
    <limit effort="1" velocity="20" lower="-1.570796326794896558" upper="1.570796326794896558"/>    
    <joint_properties friction="0.0"/>    
  </joint>  

  <joint name="neck_yaw_driven" type="revolute">    
    <origin xyz="0.015999999999998633371 3.2287696509065600056e-15 0.12248651076282091044" rpy="2.3436576345318096491e-14 3.3282183470283369239e-14 -3.1415926535897926719"/>    
    <parent link="torso"/>    
    <child link="neck_yaw_link"/>    
    <axis xyz="0 0 1"/>    
    <limit effort="1" velocity="20" lower="-3.141592653589793116" upper="3.141592653589793116"/>    
    <joint_properties friction="0.0"/>    
  </joint>  

  <link name="waist_gears">    
    <visual>      
      <origin xyz="0 0 0" rpy="0 -0 0"/>      
      <geometry>        
        <mesh filename="package:///meshes/waist_gears_visual.stl"/>        
      </geometry>      
      <material name="waist_gears_material">        
        <color rgba="0.2632766275256509525 0.51746399844275281499 0.70128653634567073016 1.0"/>        
      </material>      
    </visual>    
    <collision>      
      <origin xyz="0 0 0" rpy="0 -0 0"/>      
      <geometry>        
        <mesh filename="package:///meshes/waist_gears_collision.stl"/>        
      </geometry>      
    </collision>    
    <inertial>      
      <origin xyz="-2.968876492998927051e-07 5.6464343502689201109e-08 -0.012588230079602458905" rpy="0 0 0"/>      
      <mass value="0.025809950030454161668"/>      
      <inertia ixx="1.5121316248348977609e-06" ixy="1.8766601005581730155e-11" ixz="4.0584247103936108173e-10" iyy="7.2540386700465116487e-06" iyz="3.1280091563205133452e-12" izz="6.9379699728509380057e-06"/>      
    </inertial>    
  </link>  

  <link name="waist_link">    
    <visual>      
      <origin xyz="0 0 0" rpy="0 -0 0"/>      
      <geometry>        
        <mesh filename="package:///meshes/waist_link_visual.stl"/>        
      </geometry>      
      <material name="waist_link_material">        
        <color rgba="0.6341178154858730931 0.68176322249315746138 0.66892316089122350053 1.0"/>        
      </material>      
    </visual>    
    <collision>      
      <origin xyz="0 0 0" rpy="0 -0 0"/>      
      <geometry>        
        <mesh filename="package:///meshes/waist_link_collision.stl"/>        
      </geometry>      
    </collision>    
    <inertial>      
      <origin xyz="-9.0347036015879724889e-07 0.026095270919262961162 -0.030130047301118945829" rpy="0 0 0"/>      
      <mass value="0.16767948617484731977"/>      
      <inertia ixx="6.9102611966451489025e-05" ixy="-5.9672595151003787181e-10" ixz="-3.6786883474394307472e-06" iyy="0.00020080820223840280172" iyz="-3.5903589490715789653e-06" izz="0.00015797022372487427269"/>      
    </inertial>    
  </link>  

  <link name="spur_gear_19_teeth">    
    <visual>      
      <origin xyz="0 0 0" rpy="0 -0 0"/>      
      <geometry>        
        <mesh filename="package:///meshes/spur_gear_19_teeth_visual.stl"/>        
      </geometry>      
      <material name="spur_gear_19_teeth_material">        
        <color rgba="0.61568627450980395466 0.81176470588235294379 0.92941176470588238168 1.0"/>        
      </material>      
    </visual>    
    <collision>      
      <origin xyz="0 0 0" rpy="0 -0 0"/>      
      <geometry>        
        <mesh filename="package:///meshes/spur_gear_19_teeth_collision.stl"/>        
      </geometry>      
    </collision>    
    <inertial>      
      <origin xyz="-4.9968063137826185009e-09 -7.9242214131433856263e-11 0.0045295192537419867035" rpy="0 0 0"/>      
      <mass value="0.0010993711450650535313"/>      
      <inertia ixx="2.9215018435433078735e-08" ixy="2.5903313826161381487e-16" ixz="8.5599808499104664123e-15" iyy="2.9215021540034071703e-08" iyz="1.1526881384966657422e-16" izz="4.5709977027671355031e-08"/>      
    </inertial>    
  </link>  

  <joint name="left_hip_yaw_drive" type="revolute">    
    <origin xyz="-0.036999999999998312017 0.037100000000006030931 -0.0395000000000006804" rpy="-1.5707963267949798247 -4.6304776107371661452e-13 -3.868919074001414487e-13"/>    
    <parent link="waist_link"/>    
    <child link="spur_gear_19_teeth"/>    
    <axis xyz="0 0 1"/>    
    <limit effort="1" velocity="20" lower="-1.4211966766239538806" upper="1.4211966766239538806"/>    
    <joint_properties friction="0.0"/>    
  </joint>  

  <link name="spur_gear_21_teeth">    
    <visual>      
      <origin xyz="0 0 0" rpy="0 -0 0"/>      
      <geometry>        
        <mesh filename="package:///meshes/spur_gear_21_teeth_visual.stl"/>        
      </geometry>      
      <material name="spur_gear_21_teeth_material">        
        <color rgba="0.61568627450980395466 0.81176470588235294379 0.92941176470588238168 1.0"/>        
      </material>      
    </visual>    
    <collision>      
      <origin xyz="0 0 0" rpy="0 -0 0"/>      
      <geometry>        
        <mesh filename="package:///meshes/spur_gear_21_teeth_collision.stl"/>        
      </geometry>      
    </collision>    
    <inertial>      
      <origin xyz="-4.7814841798942682476e-10 -1.2610156409555453111e-12 0.0024944618616143370698" rpy="0 0 0"/>      
      <mass value="0.0010063046528317974842"/>      
      <inertia ixx="3.1842855421068475048e-08" ixy="2.2030744720874237327e-39" ixz="-4.4935557363611089879e-38" iyy="3.1842855426953779079e-08" iyz="-6.7412745706619689465e-38" izz="5.9529380586728028132e-08"/>      
    </inertial>    
  </link>  

  <link name="left_leg_xm430">    
    <visual>      
      <origin xyz="0 0 0" rpy="0 -0 0"/>      
      <geometry>        
        <mesh filename="package:///meshes/left_leg_xm430_visual.stl"/>        
      </geometry>      
      <material name="left_leg_xm430_material">        
        <color rgba="0.61568627450980395466 0.81176470588235294379 0.92941176470588238168 1.0"/>        
      </material>      
    </visual>    
    <collision>      
      <origin xyz="0 0 0" rpy="0 -0 0"/>      
      <geometry>        
        <mesh filename="package:///meshes/left_leg_xm430_collision.stl"/>        
      </geometry>      
    </collision>    
    <inertial>      
      <origin xyz="-9.1960418512498486936e-19 -5.5625627936851733319e-19 -0.0098390489054829052135" rpy="0 0 0"/>      
      <mass value="0.017999999999999995171"/>      
      <inertia ixx="2.638503389144252815e-06" ixy="-4.2497782781222058568e-36" ixz="-1.8781255597560568713e-37" iyy="7.6596731957046856464e-06" iyz="1.1749924264563529118e-35" izz="7.7220708070894735956e-06"/>      
    </inertial>    
  </link>  

  <joint name="left_leg_fixed" type="fixed">    
    <origin xyz="-4.336808689942017736e-19 0 0.004999999999999997502" rpy="3.1415926535897851224 -1.1045608006607374766e-30 -4.2552910532817472121e-31"/>    
    <parent link="spur_gear_21_teeth"/>    
    <child link="left_leg_xm430"/>    
    <axis xyz="0 0 1"/>    
    <limit effort="1" velocity="20"/>    
    <joint_properties friction="0.0"/>    
  </joint>  

  <joint name="left_hip_yaw_driven" type="revolute">    
    <origin xyz="-0.037000000000000005107 0.041099999999999997646 -0.019499999999999979156" rpy="-1.5707963267948923392 -1.5707963267948932273 0"/>    
    <parent link="waist_link"/>    
    <child link="spur_gear_21_teeth"/>    
    <axis xyz="0 0 1"/>    
    <limit effort="1" velocity="20" lower="-1.570796326794896558" upper="1.570796326794896558"/>    
    <joint_properties friction="0.0"/>    
  </joint>  

  <link name="spur_gear_19_teeth_2">    
    <visual>      
      <origin xyz="0 0 0" rpy="0 -0 0"/>      
      <geometry>        
        <mesh filename="package:///meshes/spur_gear_19_teeth_2_visual.stl"/>        
      </geometry>      
      <material name="spur_gear_19_teeth_2_material">        
        <color rgba="0.61568627450980395466 0.81176470588235294379 0.92941176470588238168 1.0"/>        
      </material>      
    </visual>    
    <collision>      
      <origin xyz="0 0 0" rpy="0 -0 0"/>      
      <geometry>        
        <mesh filename="package:///meshes/spur_gear_19_teeth_2_collision.stl"/>        
      </geometry>      
    </collision>    
    <inertial>      
      <origin xyz="-4.996806306843724597e-09 -7.9242214131433752865e-11 0.0045295192537419936424" rpy="0 0 0"/>      
      <mass value="0.0010993711450650535313"/>      
      <inertia ixx="2.9215018435433078735e-08" ixy="2.5903313731374078717e-16" ixz="8.5599808499104664123e-15" iyy="2.9215021540034058468e-08" iyz="1.15268813849666377e-16" izz="4.5709977027671355031e-08"/>      
    </inertial>    
  </link>  

  <joint name="right_hip_yaw_drive" type="revolute">    
    <origin xyz="0.037000000000001607992 0.037100000000003560685 -0.039500000000000486111" rpy="-1.5707963267949798247 -4.6304330256338374643e-13 -3.8689190740014134773e-13"/>    
    <parent link="waist_link"/>    
    <child link="spur_gear_19_teeth_2"/>    
    <axis xyz="0 0 1"/>    
    <limit effort="1" velocity="20" lower="-1.4211966766239538806" upper="1.4211966766239538806"/>    
    <joint_properties friction="0.0"/>    
  </joint>  

  <link name="spur_gear_21_teeth_2">    
    <visual>      
      <origin xyz="0 0 0" rpy="0 -0 0"/>      
      <geometry>        
        <mesh filename="package:///meshes/spur_gear_21_teeth_2_visual.stl"/>        
      </geometry>      
      <material name="spur_gear_21_teeth_2_material">        
        <color rgba="0.61568627450980395466 0.81176470588235294379 0.92941176470588238168 1.0"/>        
      </material>      
    </visual>    
    <collision>      
      <origin xyz="0 0 0" rpy="0 -0 0"/>      
      <geometry>        
        <mesh filename="package:///meshes/spur_gear_21_teeth_2_collision.stl"/>        
      </geometry>      
    </collision>    
    <inertial>      
      <origin xyz="-4.7814841755574595577e-10 1.2610156409555453111e-12 0.002505538138385667371" rpy="0 0 0"/>      
      <mass value="0.0010063046528317974842"/>      
      <inertia ixx="3.1842855421068475048e-08" ixy="-3.5918388336506837553e-39" ixz="-6.6630596444937123218e-38" iyy="3.1842855426953779079e-08" iyz="9.0125987776356224395e-38" izz="5.9529380586728028132e-08"/>      
    </inertial>    
  </link>  

  <link name="right_leg_xm430">    
    <visual>      
      <origin xyz="0 0 0" rpy="0 -0 0"/>      
      <geometry>        
        <mesh filename="package:///meshes/right_leg_xm430_visual.stl"/>        
      </geometry>      
      <material name="right_leg_xm430_material">        
        <color rgba="0.61568627450980395466 0.81176470588235294379 0.92941176470588238168 1.0"/>        
      </material>      
    </visual>    
    <collision>      
      <origin xyz="0 0 0" rpy="0 -0 0"/>      
      <geometry>        
        <mesh filename="package:///meshes/right_leg_xm430_collision.stl"/>        
      </geometry>      
    </collision>    
    <inertial>      
      <origin xyz="-9.196041851249839064e-19 -5.5625627936855642957e-19 -0.0098390489054829121524" rpy="0 0 0"/>      
      <mass value="0.017999999999999995171"/>      
      <inertia ixx="2.638503389144252815e-06" ixy="-2.0212297228868841463e-36" ixz="3.5190567116450991312e-37" iyy="7.6596731957046856464e-06" iyz="1.3791701339531919259e-35" izz="7.7220708070894735956e-06"/>      
    </inertial>    
  </link>  

  <joint name="right_leg_fixed" type="fixed">    
    <origin xyz="0 0 0.004999999999999997502" rpy="-3.1415926535897797933 -7.5781949123851955204e-18 -3.340101530512157196e-16"/>    
    <parent link="spur_gear_21_teeth_2"/>    
    <child link="right_leg_xm430"/>    
    <axis xyz="0 0 1"/>    
    <limit effort="1" velocity="20"/>    
    <joint_properties friction="0.0"/>    
  </joint>  

  <joint name="right_hip_yaw_driven" type="revolute">    
    <origin xyz="0.037000000000000005107 0.041099999999999997646 -0.019499999999999986094" rpy="-1.5707963267949132113 -1.5707963267948950037 0"/>    
    <parent link="waist_link"/>    
    <child link="spur_gear_21_teeth_2"/>    
    <axis xyz="0 0 1"/>    
    <limit effort="1" velocity="20" lower="-1.570796326794896558" upper="1.570796326794896558"/>    
    <joint_properties friction="0.0"/>    
  </joint>  

  <joint name="waist_roll" type="revolute">    
    <origin xyz="-0.022707865260692145642 -3.2904492237211951884e-18 -0.014000000000000064476" rpy="-1.5707963267949034414 -6.2265052416776424318e-15 1.5707963267948885644"/>    
    <parent link="waist_gears"/>    
    <child link="waist_link"/>    
    <axis xyz="0 0 1"/>    
    <limit effort="1" velocity="20" lower="-0.52359877559829881566" upper="0.52359877559829881566"/>    
    <joint_properties friction="0.0"/>    
  </joint>  

  <joint name="waist_yaw" type="revolute">    
    <origin xyz="0 -4.3140830754274083108e-32 0" rpy="9.7872132923950749268e-15 4.0244775309734053704e-14 -3.1415926535897926719"/>    
    <parent link="torso"/>    
    <child link="waist_gears"/>    
    <axis xyz="0 0 1"/>    
    <limit effort="1" velocity="20" lower="-1.570796326794896558" upper="1.570796326794896558"/>    
    <joint_properties friction="0.0"/>    
  </joint>  

  <link name="left_arm_hand">    
    <visual>      
      <origin xyz="0 0 0" rpy="0 -0 0"/>      
      <geometry>        
        <mesh filename="package:///meshes/left_arm_hand_visual.stl"/>        
      </geometry>      
      <material name="left_arm_hand_material">        
        <color rgba="0.61568627450980395466 0.81176470588235294379 0.92941176470588227065 1.0"/>        
      </material>      
    </visual>    
    <collision>      
      <origin xyz="0 0 0" rpy="0 -0 0"/>      
      <geometry>        
        <mesh filename="package:///meshes/left_arm_hand_collision.stl"/>        
      </geometry>      
    </collision>    
    <inertial>      
      <origin xyz="5.8254249521811582877e-11 -5.1264642561120958965e-05 0.008244078812709491888" rpy="0 0 0"/>      
      <mass value="0.0085999999999999965361"/>      
      <inertia ixx="1.2272887040545793991e-06" ixy="-2.1429944230882620695e-14" ixz="-8.5847199149485390626e-15" iyy="2.9107306060364624323e-06" iyz="7.4623841398183150184e-09" izz="3.0803135950773496163e-06"/>      
    </inertial>    
  </link>  

  <joint name="left_sho_pitch" type="revolute">    
    <origin xyz="-0.0030000000000067082381 0.062000000000004690248 0.10423651076282114403" rpy="-1.5707963267949092145 -3.6755753074147472872e-14 3.4347079465292731775e-14"/>    
    <parent link="torso"/>    
    <child link="left_arm_hand"/>    
    <axis xyz="0 0 1"/>    
    <limit effort="1" velocity="20" lower="-1.570796326794896558" upper="1.570796326794896558"/>    
    <joint_properties friction="0.0"/>    
  </joint>  

  <link name="right_arm_hand">    
    <visual>      
      <origin xyz="0 0 0" rpy="0 -0 0"/>      
      <geometry>        
        <mesh filename="package:///meshes/right_arm_hand_visual.stl"/>        
      </geometry>      
      <material name="right_arm_hand_material">        
        <color rgba="0.61568627450980395466 0.81176470588235294379 0.92941176470588227065 1.0"/>        
      </material>      
    </visual>    
    <collision>      
      <origin xyz="0 0 0" rpy="0 -0 0"/>      
      <geometry>        
        <mesh filename="package:///meshes/right_arm_hand_collision.stl"/>        
      </geometry>      
    </collision>    
    <inertial>      
      <origin xyz="5.8254249521811582877e-11 -5.1264642561120958965e-05 0.0082440788127094849491" rpy="0 0 0"/>      
      <mass value="0.0085999999999999965361"/>      
      <inertia ixx="1.2272887040545793991e-06" ixy="-2.1429944230882620695e-14" ixz="-8.5847199149485390626e-15" iyy="2.9107306060364624323e-06" iyz="7.4623841398183150184e-09" izz="3.0803135950773496163e-06"/>      
    </inertial>    
  </link>  

  <joint name="right_sho_pitch" type="revolute">    
    <origin xyz="-0.0030000000000024208691 -0.061999999999999777511 0.10423651076282194894" rpy="-1.5707963267948847896 2.9071281258321823756e-14 -3.1415926535897589211"/>    
    <parent link="torso"/>    
    <child link="right_arm_hand"/>    
    <axis xyz="0 0 1"/>    
    <limit effort="1" velocity="20" lower="-1.570796326794896558" upper="1.570796326794896558"/>    
    <joint_properties friction="0.0"/>    
  </joint>  


</robot>