<?xml version="1.0" ?><robot name="toddlerbot">  
  <link name="torso">    
    <visual>      
      <origin xyz="0 0 0" rpy="0 -0 0"/>      
      <geometry>        
        <mesh filename="package:///meshes/torso_visual.stl"/>        
      </geometry>      
      <material name="torso_material">        
        <color rgba="0.61978521215541182432 0.80497509985632864637 0.91238666069265506042 1.0"/>        
      </material>      
    </visual>    
    <collision>      
      <origin xyz="0 0 0" rpy="0 -0 0"/>      
      <geometry>        
        <mesh filename="package:///meshes/torso_collision.stl"/>        
      </geometry>      
    </collision>    
    <inertial>      
      <origin xyz="-0.017582789998871067166 -0.00088924128506133025968 0.066328103881054270574" rpy="0 0 0"/>      
      <mass value="0.38210896478124972697"/>      
      <inertia ixx="0.00097913100143531286122" ixy="1.3687542665749137009e-05" ixz="5.3060955780646105681e-05" iyy="0.00088767318813584355705" iyz="-1.8064914536012934021e-05" izz="0.00068582374333484887041"/>      
    </inertial>    
  </link>  

  <link name="spur_1m_20t">    
    <visual>      
      <origin xyz="0 0 0" rpy="0 -0 0"/>      
      <geometry>        
        <mesh filename="package:///meshes/spur_1m_20t_visual.stl"/>        
      </geometry>      
      <material name="spur_1m_20t_material">        
        <color rgba="0.64705882352941190838 0.64705882352941190838 0.64705882352941190838 1.0"/>        
      </material>      
    </visual>    
    <collision>      
      <origin xyz="0 0 0" rpy="0 -0 0"/>      
      <geometry>        
        <mesh filename="package:///meshes/spur_1m_20t_collision.stl"/>        
      </geometry>      
    </collision>    
    <inertial>      
      <origin xyz="-5.0947794673102296609e-18 6.23162891085252905e-18 -0.0033745971730663112953" rpy="0 0 0"/>      
      <mass value="0.0015534950290892282111"/>      
      <inertia ixx="4.4726508287871806238e-08" ixy="6.0398339042765388102e-24" ixz="2.7597381312606824945e-39" iyy="4.4726508287871793003e-08" iyz="-4.880475641083096215e-38" izz="7.9558906764902019844e-08"/>      
    </inertial>    
  </link>  

  <joint name="neck_yaw_drive" type="revolute">    
    <origin xyz="-0.004999999999999059884 -1.8020791195763170554e-16 0.12248651076281816263" rpy="-3.1415926535897913396 1.7995135580561967136e-15 9.6455933634066887197e-16"/>    
    <parent link="torso"/>    
    <child link="spur_1m_20t"/>    
    <axis xyz="0 0 1"/>    
    <limit effort="1" velocity="20" lower="-3.141592653589793116" upper="3.141592653589793116"/>    
    <joint_properties friction="0.0"/>    
  </joint>  

  <link name="neck_yaw_link">    
    <visual>      
      <origin xyz="0 0 0" rpy="0 -0 0"/>      
      <geometry>        
        <mesh filename="package:///meshes/neck_yaw_link_visual.stl"/>        
      </geometry>      
      <material name="neck_yaw_link_material">        
        <color rgba="0.33636252417476658616 0.48680769190259876034 0.74976123534949778993 1.0"/>        
      </material>      
    </visual>    
    <collision>      
      <origin xyz="0 0 0" rpy="0 -0 0"/>      
      <geometry>        
        <mesh filename="package:///meshes/neck_yaw_link_collision.stl"/>        
      </geometry>      
    </collision>    
    <inertial>      
      <origin xyz="2.7291286461380542924e-05 0.00019798992283539501949 -0.011527412037194843461" rpy="0 0 0"/>      
      <mass value="0.0085168305947458267796"/>      
      <inertia ixx="1.0407116999274384252e-06" ixy="-2.4210150464765691778e-11" ixz="4.7246803220845781133e-10" iyy="1.1240009954110494879e-06" iyz="3.0834841754646663444e-08" izz="3.1587565167292071285e-07"/>      
    </inertial>    
  </link>  

  <link name="neck_pitch_link">    
    <visual>      
      <origin xyz="0 0 0" rpy="0 -0 0"/>      
      <geometry>        
        <mesh filename="package:///meshes/neck_pitch_link_visual.stl"/>        
      </geometry>      
      <material name="neck_pitch_link_material">        
        <color rgba="0.75175531149912755424 0.80237790269364173135 0.88100511756510224703 1.0"/>        
      </material>      
    </visual>    
    <collision>      
      <origin xyz="0 0 0" rpy="0 -0 0"/>      
      <geometry>        
        <mesh filename="package:///meshes/neck_pitch_link_collision.stl"/>        
      </geometry>      
    </collision>    
    <inertial>      
      <origin xyz="-0.0033208985050365326386 -0.033447827507434774175 -0.00017266927552015304834" rpy="0 0 0"/>      
      <mass value="0.10851928601941274177"/>      
      <inertia ixx="7.4643011916861726944e-05" ixy="1.9512994501134157789e-06" ixz="2.6631618432505425465e-06" iyy="6.1956827409922899243e-05" iyz="-1.1454163205103217525e-05" izz="2.7012883362027665534e-05"/>      
    </inertial>    
  </link>  

  <link name="spur_gear_(13_teeth)">    
    <visual>      
      <origin xyz="0 0 0" rpy="0 -0 0"/>      
      <geometry>        
        <mesh filename="package:///meshes/spur_gear_(13_teeth)_visual.stl"/>        
      </geometry>      
      <material name="spur_gear_(13_teeth)_material">        
        <color rgba="0.64705882352941179736 0.64705882352941179736 0.64705882352941179736 1.0"/>        
      </material>      
    </visual>    
    <collision>      
      <origin xyz="0 0 0" rpy="0 -0 0"/>      
      <geometry>        
        <mesh filename="package:///meshes/spur_gear_(13_teeth)_collision.stl"/>        
      </geometry>      
    </collision>    
    <inertial>      
      <origin xyz="1.039987334203130658e-09 2.390520682198548835e-10 -0.0092751511485596356554" rpy="0 0 0"/>      
      <mass value="0.00081469437497230855032"/>      
      <inertia ixx="2.0244839552178298687e-08" ixy="-2.9046301772392211175e-15" ixz="8.2976066069888565589e-15" iyy="2.0244841689973771385e-08" iyz="-1.3142117784811047164e-15" izz="1.8905472907863310999e-08"/>      
    </inertial>    
  </link>  

  <joint name="neck_pitch_drive" type="revolute">    
    <origin xyz="-1.4571677198205179593e-16 -0.015650000000000330314 0.0087999999999993777644" rpy="-2.1434555572207676319e-16 -1.5880065549567459396e-15 1.570796326794896558"/>    
    <parent link="neck_pitch_link"/>    
    <child link="spur_gear_(13_teeth)"/>    
    <axis xyz="0 0 1"/>    
    <limit effort="1" velocity="20" lower="-1.570796326794896558" upper="1.570796326794896558"/>    
    <joint_properties friction="0.0"/>    
  </joint>  

  <joint name="neck_pitch_driven" type="revolute">    
    <origin xyz="3.7500079430596855445e-10 0.0051500000614755261225 -0.02749999999999992728" rpy="1.57079632679489678 4.0384474451367016523e-16 -3.141592653589793116"/>    
    <parent link="neck_yaw_link"/>    
    <child link="neck_pitch_link"/>    
    <axis xyz="0 0 1"/>    
    <limit effort="1" velocity="20" lower="-1.570796326794896558" upper="1.570796326794896558"/>    
    <joint_properties friction="0.0"/>    
  </joint>  

  <joint name="neck_yaw_driven" type="revolute">    
    <origin xyz="0.016000000000001915468 1.4752314067929373936e-17 0.12348651076281796923" rpy="-3.141592653589793116 -2.1972867704039169433e-15 -3.1415926535897926719"/>    
    <parent link="torso"/>    
    <child link="neck_yaw_link"/>    
    <axis xyz="0 0 1"/>    
    <limit effort="1" velocity="20" lower="-3.141592653589793116" upper="3.141592653589793116"/>    
    <joint_properties friction="0.0"/>    
  </joint>  

  <link name="waist_gears">    
    <visual>      
      <origin xyz="0 0 0" rpy="0 -0 0"/>      
      <geometry>        
        <mesh filename="package:///meshes/waist_gears_visual.stl"/>        
      </geometry>      
      <material name="waist_gears_material">        
        <color rgba="0.2705751638183052088 0.53648836590125015267 0.70305495274644791426 1.0"/>        
      </material>      
    </visual>    
    <collision>      
      <origin xyz="0 0 0" rpy="0 -0 0"/>      
      <geometry>        
        <mesh filename="package:///meshes/waist_gears_collision.stl"/>        
      </geometry>      
    </collision>    
    <inertial>      
      <origin xyz="6.546945446268474082e-08 -5.678589769108444202e-10 -0.012726165583898677025" rpy="0 0 0"/>      
      <mass value="0.023315805669179824611"/>      
      <inertia ixx="6.9043104388291928151e-06" ixy="-1.8428638769603772386e-11" ixz="9.9668712610669700131e-13" iyy="1.162409197167636598e-06" iyz="-3.3260430300288233958e-10" izz="6.8701920560919842564e-06"/>      
    </inertial>    
  </link>  

  <link name="waist_link">    
    <visual>      
      <origin xyz="0 0 0" rpy="0 -0 0"/>      
      <geometry>        
        <mesh filename="package:///meshes/waist_link_visual.stl"/>        
      </geometry>      
      <material name="waist_link_material">        
        <color rgba="0.63066856640767576803 0.67759035867951045162 0.66849819411858013574 1.0"/>        
      </material>      
    </visual>    
    <collision>      
      <origin xyz="0 0 0" rpy="0 -0 0"/>      
      <geometry>        
        <mesh filename="package:///meshes/waist_link_collision.stl"/>        
      </geometry>      
    </collision>    
    <inertial>      
      <origin xyz="-7.8326157945834567194e-07 -0.026309055188168655598 0.029773273854826105139" rpy="0 0 0"/>      
      <mass value="0.15193452399186060942"/>      
      <inertia ixx="6.3853955317574341826e-05" ixy="6.7244006991677519528e-10" ixz="3.1782521385896500694e-06" iyy="0.000185540673502072054" iyz="-3.2622478832003326383e-06" izz="0.00014578323476960403592"/>      
    </inertial>    
  </link>  

  <link name="spiral_bevel_1m_14t_30deg">    
    <visual>      
      <origin xyz="0 0 0" rpy="0 -0 0"/>      
      <geometry>        
        <mesh filename="package:///meshes/spiral_bevel_1m_14t_30deg_visual.stl"/>        
      </geometry>      
      <material name="spiral_bevel_1m_14t_30deg_material">        
        <color rgba="0.64705882352941179736 0.64705882352941179736 0.64705882352941179736 1.0"/>        
      </material>      
    </visual>    
    <collision>      
      <origin xyz="0 0 0" rpy="0 -0 0"/>      
      <geometry>        
        <mesh filename="package:///meshes/spiral_bevel_1m_14t_30deg_collision.stl"/>        
      </geometry>      
    </collision>    
    <inertial>      
      <origin xyz="8.2641075233036431769e-10 3.4055789872172725907e-10 0.0068612577407481719488" rpy="0 0 0"/>      
      <mass value="0.00067997563436136246491"/>      
      <inertia ixx="1.2174575798018973838e-08" ixy="3.8216073728371227098e-18" ixz="4.720454783863198132e-16" iyy="1.2174575801813731073e-08" iyz="-2.618409774997137937e-16" izz="1.3178653206314311711e-08"/>      
    </inertial>    
  </link>  

  <joint name="waist_act_1" type="revolute">    
    <origin xyz="3.5815341505539062119e-17 -0.019600000000000016714 0.012750000000000042549" rpy="-1.570796326794896336 -1.5707963267948215069 0"/>    
    <parent link="waist_link"/>    
    <child link="spiral_bevel_1m_14t_30deg"/>    
    <axis xyz="0 0 1"/>    
    <limit effort="1" velocity="20" lower="-6.283185307179586232" upper="6.283185307179586232"/>    
    <joint_properties friction="0.0"/>    
  </joint>  

  <link name="spiral_bevel_1m_14t_30deg_2">    
    <visual>      
      <origin xyz="0 0 0" rpy="0 -0 0"/>      
      <geometry>        
        <mesh filename="package:///meshes/spiral_bevel_1m_14t_30deg_2_visual.stl"/>        
      </geometry>      
      <material name="spiral_bevel_1m_14t_30deg_2_material">        
        <color rgba="0.64705882352941179736 0.64705882352941179736 0.64705882352941179736 1.0"/>        
      </material>      
    </visual>    
    <collision>      
      <origin xyz="0 0 0" rpy="0 -0 0"/>      
      <geometry>        
        <mesh filename="package:///meshes/spiral_bevel_1m_14t_30deg_2_collision.stl"/>        
      </geometry>      
    </collision>    
    <inertial>      
      <origin xyz="7.2990964661290291815e-10 5.1591309333227129234e-10 0.0068612577407481710814" rpy="0 0 0"/>      
      <mass value="0.00067997563436136246491"/>      
      <inertia ixx="1.2174575796548749635e-08" ixy="2.6199053431044343109e-18" ixz="5.1847541160688376365e-16" iyy="1.2174575803283976783e-08" iyz="-1.5023607679690313333e-16" izz="1.3178653206314315019e-08"/>      
    </inertial>    
  </link>  

  <joint name="waist_act_2" type="revolute">    
    <origin xyz="-6.3212258568462825292e-16 -0.019600000000000079164 0.032750000000000834" rpy="-1.5707963267948976682 -1.3463968515393018865 1.5503953316521244903e-14"/>    
    <parent link="waist_link"/>    
    <child link="spiral_bevel_1m_14t_30deg_2"/>    
    <axis xyz="0 0 1"/>    
    <limit effort="1" velocity="20" lower="-6.283185307179586232" upper="6.283185307179586232"/>    
    <joint_properties friction="0.0"/>    
  </joint>  

  <link name="spur_gear_19_teeth">    
    <visual>      
      <origin xyz="0 0 0" rpy="0 -0 0"/>      
      <geometry>        
        <mesh filename="package:///meshes/spur_gear_19_teeth_visual.stl"/>        
      </geometry>      
      <material name="spur_gear_19_teeth_material">        
        <color rgba="0.61568627450980395466 0.81176470588235294379 0.92941176470588238168 1.0"/>        
      </material>      
    </visual>    
    <collision>      
      <origin xyz="0 0 0" rpy="0 -0 0"/>      
      <geometry>        
        <mesh filename="package:///meshes/spur_gear_19_teeth_collision.stl"/>        
      </geometry>      
    </collision>    
    <inertial>      
      <origin xyz="-4.9156135350294024201e-09 9.006087406040677985e-10 -0.0045295192537419936424" rpy="0 0 0"/>      
      <mass value="0.0010993711450650535313"/>      
      <inertia ixx="2.9215018435433082044e-08" ixy="2.5903313772733109345e-16" ixz="-8.4242612451073836103e-15" iyy="2.9215021540034058468e-08" iyz="1.5226232382724447964e-15" izz="4.5709977027671368266e-08"/>      
    </inertial>    
  </link>  

  <joint name="left_hip_yaw_drive" type="revolute">    
    <origin xyz="-0.036999999999999179379 -0.037100000000004823564 0.039500000000000423661" rpy="-1.5707963267950579844 5.71102443800098102e-13 2.6906455702027046663e-13"/>    
    <parent link="waist_link"/>    
    <child link="spur_gear_19_teeth"/>    
    <axis xyz="0 0 1"/>    
    <limit effort="1" velocity="20" lower="-1.570796326794896558" upper="1.570796326794896558"/>    
    <joint_properties friction="0.0"/>    
  </joint>  

  <link name="spur_gear_21_teeth">    
    <visual>      
      <origin xyz="0 0 0" rpy="0 -0 0"/>      
      <geometry>        
        <mesh filename="package:///meshes/spur_gear_21_teeth_visual.stl"/>        
      </geometry>      
      <material name="spur_gear_21_teeth_material">        
        <color rgba="0.61568627450980395466 0.81176470588235294379 0.92941176470588238168 1.0"/>        
      </material>      
    </visual>    
    <collision>      
      <origin xyz="0 0 0" rpy="0 -0 0"/>      
      <geometry>        
        <mesh filename="package:///meshes/spur_gear_21_teeth_collision.stl"/>        
      </geometry>      
    </collision>    
    <inertial>      
      <origin xyz="-4.7814841746391350153e-10 1.2610016837558293022e-12 -0.0024944618616143366362" rpy="0 0 0"/>      
      <mass value="0.0010063046528317972673"/>      
      <inertia ixx="3.1842855421068481665e-08" ixy="2.1452075797961539371e-37" ixz="-1.1964366566353854637e-38" iyy="3.1842855426953785697e-08" iyz="1.1823805759568236218e-38" izz="5.9529380586728028132e-08"/>      
    </inertial>    
  </link>  

  <link name="left_leg_xm430">    
    <visual>      
      <origin xyz="0 0 0" rpy="0 -0 0"/>      
      <geometry>        
        <mesh filename="package:///meshes/left_leg_xm430_visual.stl"/>        
      </geometry>      
      <material name="left_leg_xm430_material">        
        <color rgba="0.57264277713291233951 0.6565338049154016975 0.69976527523230791505 1.0"/>        
      </material>      
    </visual>    
    <collision>      
      <origin xyz="0 0 0" rpy="0 -0 0"/>      
      <geometry>        
        <mesh filename="package:///meshes/left_leg_xm430_collision.stl"/>        
      </geometry>      
    </collision>    
    <inertial>      
      <origin xyz="-0.00081541414847775795741 0.00014645608381673290042 -0.12086628583540216797" rpy="0 0 0"/>      
      <mass value="0.28007018314906156897"/>      
      <inertia ixx="0.0023087531285643494647" ixy="-8.4819413465746402346e-08" ixz="-4.0318927115056623852e-05" iyy="0.0023324981162634187207" iyz="-8.1954078622779990285e-06" izz="8.6295030527309588789e-05"/>      
    </inertial>    
  </link>  

  <joint name="left_leg_fixed" type="fixed">    
    <origin xyz="-4.336808689942017736e-19 -1.3877787807814456755e-17 -0.004999999999999997502" rpy="-1.0439449364097525548e-14 -1.9757585399875400437e-31 5.7250078249404190712e-30"/>    
    <parent link="spur_gear_21_teeth"/>    
    <child link="left_leg_xm430"/>    
    <axis xyz="0 0 1"/>    
    <limit effort="1" velocity="20"/>    
    <joint_properties friction="0.0"/>    
  </joint>  

  <joint name="left_hip_yaw_driven" type="revolute">    
    <origin xyz="-0.037000000000000005107 -0.041100000000000080913 0.019500000000000003442" rpy="-1.5707963267948841235 1.5707963267948932273 0"/>    
    <parent link="waist_link"/>    
    <child link="spur_gear_21_teeth"/>    
    <axis xyz="0 0 1"/>    
    <limit effort="1" velocity="20" lower="-1.570796326794896558" upper="1.570796326794896558"/>    
    <joint_properties friction="0.0"/>    
  </joint>  

  <link name="spur_gear_19_teeth_2">    
    <visual>      
      <origin xyz="0 0 0" rpy="0 -0 0"/>      
      <geometry>        
        <mesh filename="package:///meshes/spur_gear_19_teeth_2_visual.stl"/>        
      </geometry>      
      <material name="spur_gear_19_teeth_2_material">        
        <color rgba="0.61568627450980395466 0.81176470588235294379 0.92941176470588238168 1.0"/>        
      </material>      
    </visual>    
    <collision>      
      <origin xyz="0 0 0" rpy="0 -0 0"/>      
      <geometry>        
        <mesh filename="package:///meshes/spur_gear_19_teeth_2_collision.stl"/>        
      </geometry>      
    </collision>    
    <inertial>      
      <origin xyz="-4.9156135419682971512e-09 9.0060874060406821209e-10 -0.0045295192537419867035" rpy="0 0 0"/>      
      <mass value="0.0010993711450650535313"/>      
      <inertia ixx="2.9215018435433095279e-08" ixy="2.5903313743443320232e-16" ixz="-8.424261245107385188e-15" iyy="2.9215021540034071703e-08" iyz="1.5226232382724451908e-15" izz="4.5709977027671368266e-08"/>      
    </inertial>    
  </link>  

  <joint name="right_hip_yaw_drive" type="revolute">    
    <origin xyz="0.037000000000000358991 -0.037100000000003852119 0.039500000000000069778" rpy="-1.5707963267949709429 3.0776023904592405576e-13 2.7738547283800353153e-13"/>    
    <parent link="waist_link"/>    
    <child link="spur_gear_19_teeth_2"/>    
    <axis xyz="0 0 1"/>    
    <limit effort="1" velocity="20" lower="-1.570796326794896558" upper="1.570796326794896558"/>    
    <joint_properties friction="0.0"/>    
  </joint>  

  <link name="spur_gear_21_teeth_2">    
    <visual>      
      <origin xyz="0 0 0" rpy="0 -0 0"/>      
      <geometry>        
        <mesh filename="package:///meshes/spur_gear_21_teeth_2_visual.stl"/>        
      </geometry>      
      <material name="spur_gear_21_teeth_2_material">        
        <color rgba="0.61568627450980395466 0.81176470588235294379 0.92941176470588238168 1.0"/>        
      </material>      
    </visual>    
    <collision>      
      <origin xyz="0 0 0" rpy="0 -0 0"/>      
      <geometry>        
        <mesh filename="package:///meshes/spur_gear_21_teeth_2_collision.stl"/>        
      </geometry>      
    </collision>    
    <inertial>      
      <origin xyz="-4.7814841746391350153e-10 -1.2610155615436371167e-12 -0.0025055381383856678047" rpy="0 0 0"/>      
      <mass value="0.0010063046528317972673"/>      
      <inertia ixx="3.1842855421068481665e-08" ixy="1.560614116831243518e-38" ixz="2.0210367250077923995e-39" iyy="3.1842855426953785697e-08" iyz="5.2356557841516804612e-39" izz="5.9529380586728028132e-08"/>      
    </inertial>    
  </link>  

  <link name="right_leg_xm430">    
    <visual>      
      <origin xyz="0 0 0" rpy="0 -0 0"/>      
      <geometry>        
        <mesh filename="package:///meshes/right_leg_xm430_visual.stl"/>        
      </geometry>      
      <material name="right_leg_xm430_material">        
        <color rgba="0.57264277713291222849 0.65653380491540158648 0.69976527523230780403 1.0"/>        
      </material>      
    </visual>    
    <collision>      
      <origin xyz="0 0 0" rpy="0 -0 0"/>      
      <geometry>        
        <mesh filename="package:///meshes/right_leg_xm430_collision.stl"/>        
      </geometry>      
    </collision>    
    <inertial>      
      <origin xyz="-0.0011946391684490294087 -0.00014644113154546573941 -0.12086648721217842228" rpy="0 0 0"/>      
      <mass value="0.28007018314906162448"/>      
      <inertia ixx="0.002308767469762749297" ixy="1.1609797994553681643e-06" ixz="-3.1427684528793263736e-05" iyy="0.002332292845516217069" iyz="8.1991419149682655818e-06" izz="8.6075478345021150402e-05"/>      
    </inertial>    
  </link>  

  <joint name="right_leg_fixed" type="fixed">    
    <origin xyz="0 0 -0.004999999999999997502" rpy="1.0732181508787092545e-15 5.1822669723995480778e-16 -1.6653345369374924824e-16"/>    
    <parent link="spur_gear_21_teeth_2"/>    
    <child link="right_leg_xm430"/>    
    <axis xyz="0 0 1"/>    
    <limit effort="1" velocity="20"/>    
    <joint_properties friction="0.0"/>    
  </joint>  

  <joint name="right_hip_yaw_driven" type="revolute">    
    <origin xyz="0.037000000000000005107 -0.041100000000000011524 0.019500000000000010381" rpy="-1.5707963267948983344 1.5707963267948950037 0"/>    
    <parent link="waist_link"/>    
    <child link="spur_gear_21_teeth_2"/>    
    <axis xyz="0 0 1"/>    
    <limit effort="1" velocity="20" lower="-1.570796326794896558" upper="1.570796326794896558"/>    
    <joint_properties friction="0.0"/>    
  </joint>  

  <joint name="waist_roll" type="revolute">    
    <origin xyz="-6.2255683189587157383e-20 0.022707865260692461362 -0.013000000000000004607" rpy="1.5707963267948952257 1.2017992026080351615e-15 4.2181022606678868535e-16"/>    
    <parent link="waist_gears"/>    
    <child link="waist_link"/>    
    <axis xyz="0 0 1"/>    
    <limit effort="1" velocity="20" lower="-0.52359877559829881566" upper="0.52359877559829881566"/>    
    <joint_properties friction="0.0"/>    
  </joint>  

  <joint name="waist_yaw" type="revolute">    
    <origin xyz="-1.7347234759768070944e-18 -9.8607613152626475676e-32 0" rpy="2.0946901476030943553e-15 7.1861600448343401911e-16 -1.5707963267948228392"/>    
    <parent link="torso"/>    
    <child link="waist_gears"/>    
    <axis xyz="0 0 1"/>    
    <limit effort="1" velocity="20" lower="-1.570796326794896558" upper="1.570796326794896558"/>    
    <joint_properties friction="0.0"/>    
  </joint>  

  <link name="left_arm_hand">    
    <visual>      
      <origin xyz="0 0 0" rpy="0 -0 0"/>      
      <geometry>        
        <mesh filename="package:///meshes/left_arm_hand_visual.stl"/>        
      </geometry>      
      <material name="left_arm_hand_material">        
        <color rgba="0.78936869067351234097 0.68581087162853371364 0.33587667190439268738 1.0"/>        
      </material>      
    </visual>    
    <collision>      
      <origin xyz="0 0 0" rpy="0 -0 0"/>      
      <geometry>        
        <mesh filename="package:///meshes/left_arm_hand_collision.stl"/>        
      </geometry>      
    </collision>    
    <inertial>      
      <origin xyz="-0.002933968885491299982 0.039176653016987951494 -0.0926306072817933146" rpy="0 0 0"/>      
      <mass value="0.47285924835363390972"/>      
      <inertia ixx="0.0025778889091023615004" ixy="3.6002415653721211455e-05" ixz="-7.1072500170806098907e-05" iyy="0.002422856282897296442" iyz="0.0001705571130104588471" izz="0.00031178066840935781019"/>      
    </inertial>    
  </link>  

  <joint name="left_arm_fixed" type="fixed">    
    <origin xyz="0.0010000000000009051128 0.049000000000000341893 0.11948651076281792405" rpy="-5.9230088976703815107e-16 1.7322096859285544219e-15 1.6762794059802379347e-29"/>    
    <parent link="torso"/>    
    <child link="left_arm_hand"/>    
    <axis xyz="0 0 1"/>    
    <limit effort="1" velocity="20"/>    
    <joint_properties friction="0.0"/>    
  </joint>  

  <link name="right_arm_hand">    
    <visual>      
      <origin xyz="0 0 0" rpy="0 -0 0"/>      
      <geometry>        
        <mesh filename="package:///meshes/right_arm_hand_visual.stl"/>        
      </geometry>      
      <material name="right_arm_hand_material">        
        <color rgba="0.78936869067351222995 0.68581087162853371364 0.33587667190439268738 1.0"/>        
      </material>      
    </visual>    
    <collision>      
      <origin xyz="0 0 0" rpy="0 -0 0"/>      
      <geometry>        
        <mesh filename="package:///meshes/right_arm_hand_collision.stl"/>        
      </geometry>      
    </collision>    
    <inertial>      
      <origin xyz="-0.0025227522828374284586 -0.038971039253902987898 -0.09262901731977556119" rpy="0 0 0"/>      
      <mass value="0.47285924835363390972"/>      
      <inertia ixx="0.0025778266721208646824" ixy="-3.2238812185553510645e-05" ixz="-7.9542347472923906424e-05" iyy="0.002422479614470644891" iyz="-0.00016286414549132740507" izz="0.00031110605037434137547"/>      
    </inertial>    
  </link>  

  <joint name="right_arm_fixed" type="fixed">    
    <origin xyz="0.0010000000000010308802 -0.049000000000000321076 0.11948651076281791017" rpy="-5.9230088976591895466e-16 1.732209685967738918e-15 1.6762794059934078982e-29"/>    
    <parent link="torso"/>    
    <child link="right_arm_hand"/>    
    <axis xyz="0 0 1"/>    
    <limit effort="1" velocity="20"/>    
    <joint_properties friction="0.0"/>    
  </joint>  


</robot>