<?xml version="1.0" ?><robot name="toddlerbot">  
  <link name="torso">    
    <visual>      
      <origin xyz="0 0 0" rpy="0 -0 0"/>      
      <geometry>        
        <mesh filename="package:///meshes/torso_visual.stl"/>        
      </geometry>      
      <material name="torso_material">        
        <color rgba="0.57966228766239313863 0.74125456887618423885 0.86359135833205546984 1.0"/>        
      </material>      
    </visual>    
    <collision>      
      <origin xyz="0 0 0" rpy="0 -0 0"/>      
      <geometry>        
        <mesh filename="package:///meshes/torso_collision.stl"/>        
      </geometry>      
    </collision>    
    <inertial>      
      <origin xyz="-0.0083672516032260706859 0.002860630977202488056 0.072227274344631609004" rpy="0 0 0"/>      
      <mass value="0.66652685450988358173"/>      
      <inertia ixx="0.0019434685147573988774" ixy="-3.0196901537300176253e-05" ixz="-4.8453284405565760393e-05" iyy="0.0015666474025509457071" iyz="3.8807867182524833965e-05" izz="0.0013960060525913834881"/>      
    </inertial>    
  </link>  

  <link name="spur_1m_20t">    
    <visual>      
      <origin xyz="0 0 0" rpy="0 -0 0"/>      
      <geometry>        
        <mesh filename="package:///meshes/spur_1m_20t_visual.stl"/>        
      </geometry>      
      <material name="spur_1m_20t_material">        
        <color rgba="0.64705882352941190838 0.64705882352941190838 0.64705882352941190838 1.0"/>        
      </material>      
    </visual>    
    <collision>      
      <origin xyz="0 0 0" rpy="0 -0 0"/>      
      <geometry>        
        <mesh filename="package:///meshes/spur_1m_20t_collision.stl"/>        
      </geometry>      
    </collision>    
    <inertial>      
      <origin xyz="-2.1850838947992497008e-18 -7.6451634925929813506e-18 0.0033745971730663112953" rpy="0 0 0"/>      
      <mass value="0.0015534950290892282111"/>      
      <inertia ixx="4.4726508287871826091e-08" ixy="4.3152578044168224931e-24" ixz="-4.0749910772758008994e-38" iyy="4.4726508287871786386e-08" iyz="-7.464720539392493928e-38" izz="7.9558906764902019844e-08"/>      
    </inertial>    
  </link>  

  <joint name="neck_yaw_drive" type="revolute">    
    <origin xyz="-0.004999999999999517851 2.6555840535020396321e-18 0.121486510762817565" rpy="1.1318451824181020002e-14 2.6985403517595457696e-15 -5.3863140912757267331e-15"/>    
    <parent link="torso"/>    
    <child link="spur_1m_20t"/>    
    <axis xyz="0 0 1"/>    
    <limit effort="1" velocity="20" lower="-2.8797932657906435416" upper="2.8797932657906435416"/>    
    <joint_properties friction="0.0"/>    
  </joint>  

  <link name="neck_yaw_link">    
    <visual>      
      <origin xyz="0 0 0" rpy="0 -0 0"/>      
      <geometry>        
        <mesh filename="package:///meshes/neck_yaw_link_visual.stl"/>        
      </geometry>      
      <material name="neck_yaw_link_material">        
        <color rgba="0.33636252417476658616 0.48680769190259876034 0.74976123534949790095 1.0"/>        
      </material>      
    </visual>    
    <collision>      
      <origin xyz="0 0 0" rpy="0 -0 0"/>      
      <geometry>        
        <mesh filename="package:///meshes/neck_yaw_link_collision.stl"/>        
      </geometry>      
    </collision>    
    <inertial>      
      <origin xyz="2.7291286461003325272e-05 -0.00019798992283532061611 0.011527412037194517333" rpy="0 0 0"/>      
      <mass value="0.0085168305947458267796"/>      
      <inertia ixx="1.0407116999274250844e-06" ixy="2.4210150466104690394e-11" ixz="-4.7246803217913839452e-10" iyy="1.1240009954110452527e-06" iyz="3.0834841754639529839e-08" izz="3.158756516729143601e-07"/>      
    </inertial>    
  </link>  

  <link name="neck_pitch_link">    
    <visual>      
      <origin xyz="0 0 0" rpy="0 -0 0"/>      
      <geometry>        
        <mesh filename="package:///meshes/neck_pitch_link_visual.stl"/>        
      </geometry>      
      <material name="neck_pitch_link_material">        
        <color rgba="0.63488949938200522904 0.78217650228196211604 0.83850167834705646719 1.0"/>        
      </material>      
    </visual>    
    <collision>      
      <origin xyz="0 0 0" rpy="0 -0 0"/>      
      <geometry>        
        <mesh filename="package:///meshes/neck_pitch_link_collision.stl"/>        
      </geometry>      
    </collision>    
    <inertial>      
      <origin xyz="0.0074941752208601492349 0.036106451965378968949 -0.0026450432675129155989" rpy="0 0 0"/>      
      <mass value="0.074299999993091794814"/>      
      <inertia ixx="5.6163162401070805888e-05" ixy="-1.8328324981472120296e-05" ixz="-1.0415620464442773316e-05" iyy="4.3358519502837511255e-05" iyz="-1.5323447827270369174e-05" izz="5.0515578568673296983e-05"/>      
    </inertial>    
  </link>  

  <link name="spur_gear_(13_teeth)">    
    <visual>      
      <origin xyz="0 0 0" rpy="0 -0 0"/>      
      <geometry>        
        <mesh filename="package:///meshes/spur_gear_(13_teeth)_visual.stl"/>        
      </geometry>      
      <material name="spur_gear_(13_teeth)_material">        
        <color rgba="0.64705882352941179736 0.64705882352941179736 0.64705882352941179736 1.0"/>        
      </material>      
    </visual>    
    <collision>      
      <origin xyz="0 0 0" rpy="0 -0 0"/>      
      <geometry>        
        <mesh filename="package:///meshes/spur_gear_(13_teeth)_collision.stl"/>        
      </geometry>      
    </collision>    
    <inertial>      
      <origin xyz="9.1521555177215050094e-10 -5.4872578743306736518e-10 0.0092751511485596356554" rpy="0 0 0"/>      
      <mass value="0.00081469437497230865874"/>      
      <inertia ixx="2.0244841463618390798e-08" ixy="2.9781774994552929898e-15" ixz="-8.2976066067935977077e-15" iyy="2.0244839778533685891e-08" iyz="1.3142117784501784106e-15" izz="1.8905472907863310999e-08"/>      
    </inertial>    
  </link>  

  <joint name="neck_pitch_drive" type="revolute">    
    <origin xyz="-6.9735883734267645195e-16 0.015649999999999053557 -0.0087999999999970532349" rpy="-1.1409718301987536487e-15 4.409645192886135633e-16 -1.5707963267948976682"/>    
    <parent link="neck_pitch_link"/>    
    <child link="spur_gear_(13_teeth)"/>    
    <axis xyz="0 0 1"/>    
    <limit effort="1" velocity="20" lower="-2.174948760177549012" upper="2.174948760177549012"/>    
    <joint_properties friction="0.0"/>    
  </joint>  

  <joint name="neck_pitch_driven" type="revolute">    
    <origin xyz="3.7499979510524639181e-10 -0.0051500000614751947903 0.027499999999999941158" rpy="1.5707963267948978903 -2.0825786444073518345e-16 3.141592653589793116"/>    
    <parent link="neck_yaw_link"/>    
    <child link="neck_pitch_link"/>    
    <axis xyz="0 0 1"/>    
    <limit effort="1" velocity="20" lower="-1.570796326794896558" upper="1.570796326794896558"/>    
    <joint_properties friction="0.0"/>    
  </joint>  

  <joint name="neck_yaw_driven" type="revolute">    
    <origin xyz="0.016000000000001235456 2.2310681558151314601e-17 0.12248651076281746874" rpy="-4.8668742840765556337e-16 -4.0649010562893427138e-15 3.141592653589793116"/>    
    <parent link="torso"/>    
    <child link="neck_yaw_link"/>    
    <axis xyz="0 0 1"/>    
    <limit effort="1" velocity="20" lower="-2.6179938779914944114" upper="2.6179938779914944114"/>    
    <joint_properties friction="0.0"/>    
  </joint>  

  <link name="waist_gears">    
    <visual>      
      <origin xyz="0 0 0" rpy="0 -0 0"/>      
      <geometry>        
        <mesh filename="package:///meshes/waist_gears_visual.stl"/>        
      </geometry>      
      <material name="waist_gears_material">        
        <color rgba="0.26906161272592882261 0.5227921908325551259 0.70491767355474532764 1.0"/>        
      </material>      
    </visual>    
    <collision>      
      <origin xyz="0 0 0" rpy="0 -0 0"/>      
      <geometry>        
        <mesh filename="package:///meshes/waist_gears_collision.stl"/>        
      </geometry>      
    </collision>    
    <inertial>      
      <origin xyz="-2.9089024307205922448e-07 5.5035553754057889814e-08 -0.012592985430860237361" rpy="0 0 0"/>      
      <mass value="0.026337180140419174518"/>      
      <inertia ixx="1.5367047941033243237e-06" ixy="1.8828487086285523381e-11" ixz="4.0600521952100202395e-10" iyy="7.3024712275451816255e-06" iyz="3.2911737855039681129e-12" izz="6.9859065635060806773e-06"/>      
    </inertial>    
  </link>  

  <link name="waist_link">    
    <visual>      
      <origin xyz="0 0 0" rpy="0 -0 0"/>      
      <geometry>        
        <mesh filename="package:///meshes/waist_link_visual.stl"/>        
      </geometry>      
      <material name="waist_link_material">        
        <color rgba="0.63430343020834178969 0.68126545235342628182 0.66860955758476392496 1.0"/>        
      </material>      
    </visual>    
    <collision>      
      <origin xyz="0 0 0" rpy="0 -0 0"/>      
      <geometry>        
        <mesh filename="package:///meshes/waist_link_collision.stl"/>        
      </geometry>      
    </collision>    
    <inertial>      
      <origin xyz="-8.5002682137410777584e-07 0.026211295803431747253 -0.030029904564842540421" rpy="0 0 0"/>      
      <mass value="0.17011953490612458095"/>      
      <inertia ixx="7.1026883624131716979e-05" ixy="-6.8862247339408054903e-10" ixz="-3.67690781727648149e-06" iyy="0.00020623657496089139269" iyz="-3.6672941929504773996e-06" izz="0.00016183916500619549518"/>      
    </inertial>    
  </link>  

  <link name="spiral_bevel_1m_14t_30deg">    
    <visual>      
      <origin xyz="0 0 0" rpy="0 -0 0"/>      
      <geometry>        
        <mesh filename="package:///meshes/spiral_bevel_1m_14t_30deg_visual.stl"/>        
      </geometry>      
      <material name="spiral_bevel_1m_14t_30deg_material">        
        <color rgba="0.64705882352941179736 0.64705882352941179736 0.64705882352941179736 1.0"/>        
      </material>      
    </visual>    
    <collision>      
      <origin xyz="0 0 0" rpy="0 -0 0"/>      
      <geometry>        
        <mesh filename="package:///meshes/spiral_bevel_1m_14t_30deg_collision.stl"/>        
      </geometry>      
    </collision>    
    <inertial>      
      <origin xyz="7.4971447279470471159e-10 7.1802237332913031801e-10 0.0066868955018979121113" rpy="0 0 0"/>      
      <mass value="0.00073261524436595481732"/>      
      <inertia ixx="1.3495056019478195011e-08" ixy="4.0596681656909248509e-17" ixz="8.5992550146682431063e-16" iyy="1.3495056150237195634e-08" iyz="-6.7913008215000759895e-16" izz="1.4355986549816408408e-08"/>      
    </inertial>    
  </link>  

  <joint name="waist_act_1" type="revolute">    
    <origin xyz="5.7457652915638341522e-17 0.019599999999999964673 -0.012750000000000025202" rpy="1.5707963267948954478 1.570796326794896336 0"/>    
    <parent link="waist_link"/>    
    <child link="spiral_bevel_1m_14t_30deg"/>    
    <axis xyz="0 0 1"/>    
    <limit effort="1" velocity="20" lower="-4.6774823953448034786" upper="4.6774823953448034786"/>    
    <joint_properties friction="0.0"/>    
  </joint>  

  <link name="spiral_bevel_1m_14t_30deg_2">    
    <visual>      
      <origin xyz="0 0 0" rpy="0 -0 0"/>      
      <geometry>        
        <mesh filename="package:///meshes/spiral_bevel_1m_14t_30deg_2_visual.stl"/>        
      </geometry>      
      <material name="spiral_bevel_1m_14t_30deg_2_material">        
        <color rgba="0.64705882352941179736 0.64705882352941179736 0.64705882352941179736 1.0"/>        
      </material>      
    </visual>    
    <collision>      
      <origin xyz="0 0 0" rpy="0 -0 0"/>      
      <geometry>        
        <mesh filename="package:///meshes/spiral_bevel_1m_14t_30deg_2_collision.stl"/>        
      </geometry>      
    </collision>    
    <inertial>      
      <origin xyz="5.711425533905245544e-10 8.6684721904770158123e-10 0.0066868955018979207849" rpy="0 0 0"/>      
      <mass value="0.00073261524436595481732"/>      
      <inertia ixx="1.3495056008338566936e-08" ixy="8.2092443012234500669e-18" ixz="9.8948603397653497318e-16" iyy="1.3495056161376838597e-08" iyz="-4.707514473727866566e-16" izz="1.43559865498164051e-08"/>      
    </inertial>    
  </link>  

  <joint name="waist_act_2" type="revolute">    
    <origin xyz="4.2745485696894321379e-17 0.019600000000000013245 -0.032749999999999994393" rpy="1.5707963267948956698 1.3463968515392303882 6.7698458176426589005e-15"/>    
    <parent link="waist_link"/>    
    <child link="spiral_bevel_1m_14t_30deg_2"/>    
    <axis xyz="0 0 1"/>    
    <limit effort="1" velocity="20" lower="-4.6774823953448034786" upper="4.6774823953448034786"/>    
    <joint_properties friction="0.0"/>    
  </joint>  

  <link name="spur_gear_19_teeth">    
    <visual>      
      <origin xyz="0 0 0" rpy="0 -0 0"/>      
      <geometry>        
        <mesh filename="package:///meshes/spur_gear_19_teeth_visual.stl"/>        
      </geometry>      
      <material name="spur_gear_19_teeth_material">        
        <color rgba="0.61568627450980395466 0.81176470588235294379 0.92941176470588238168 1.0"/>        
      </material>      
    </visual>    
    <collision>      
      <origin xyz="0 0 0" rpy="0 -0 0"/>      
      <geometry>        
        <mesh filename="package:///meshes/spur_gear_19_teeth_collision.stl"/>        
      </geometry>      
    </collision>    
    <inertial>      
      <origin xyz="-4.740324259514682441e-08 1.5460070763910080297e-08 0.0045456071298370023803" rpy="0 0 0"/>      
      <mass value="0.0011084409433758843876"/>      
      <inertia ixx="2.9582691212226697356e-08" ixy="-2.8904821292481544943e-14" ixz="7.8892082291023494389e-14" iyy="2.9582612758414119977e-08" iyz="-2.5767358059532384785e-14" izz="4.6351510704080129527e-08"/>      
    </inertial>    
  </link>  

  <joint name="left_hip_yaw_drive" type="revolute">    
    <origin xyz="-0.036999999999998457734 0.037100000000005961542 -0.03950000000000024325" rpy="-1.5707963267949545116 -4.8003070743589248247e-13 -3.5749181392930616155e-13"/>    
    <parent link="waist_link"/>    
    <child link="spur_gear_19_teeth"/>    
    <axis xyz="0 0 1"/>    
    <limit effort="1" velocity="20" lower="-1.7361433085627806516" upper="1.7361433085627806516"/>    
    <joint_properties friction="0.0"/>    
  </joint>  

  <link name="spur_gear_21_teeth">    
    <visual>      
      <origin xyz="0 0 0" rpy="0 -0 0"/>      
      <geometry>        
        <mesh filename="package:///meshes/spur_gear_21_teeth_visual.stl"/>        
      </geometry>      
      <material name="spur_gear_21_teeth_material">        
        <color rgba="0.61568627450980395466 0.81176470588235294379 0.92941176470588238168 1.0"/>        
      </material>      
    </visual>    
    <collision>      
      <origin xyz="0 0 0" rpy="0 -0 0"/>      
      <geometry>        
        <mesh filename="package:///meshes/spur_gear_21_teeth_collision.stl"/>        
      </geometry>      
    </collision>    
    <inertial>      
      <origin xyz="-6.7030728161863890058e-12 1.7758939917663256745e-11 0.0024945285429905619985" rpy="0 0 0"/>      
      <mass value="0.0010185686142775145658"/>      
      <inertia ixx="3.2129731492034445208e-08" ixy="-4.9636019526914142744e-39" ixz="-1.6642362224115499855e-38" iyy="3.2129731493285658455e-08" iyz="-2.1293885848650906672e-38" izz="6.0052191739644090562e-08"/>      
    </inertial>    
  </link>  

  <link name="left_leg_xm430">    
    <visual>      
      <origin xyz="0 0 0" rpy="0 -0 0"/>      
      <geometry>        
        <mesh filename="package:///meshes/left_leg_xm430_visual.stl"/>        
      </geometry>      
      <material name="left_leg_xm430_material">        
        <color rgba="0.61568627450980395466 0.81176470588235294379 0.92941176470588238168 1.0"/>        
      </material>      
    </visual>    
    <collision>      
      <origin xyz="0 0 0" rpy="0 -0 0"/>      
      <geometry>        
        <mesh filename="package:///meshes/left_leg_xm430_collision.stl"/>        
      </geometry>      
    </collision>    
    <inertial>      
      <origin xyz="-9.7729125808214886046e-19 -5.2615716382371595361e-19 -0.0098919667346054462181" rpy="0 0 0"/>      
      <mass value="0.01799999999999999864"/>      
      <inertia ixx="2.6483505271519540317e-06" ixy="-3.9546438834739668623e-37" ixz="-6.0467931211320102945e-36" iyy="7.7055357996008251511e-06" iyz="2.9628982853916960634e-36" izz="7.7736682806805392252e-06"/>      
    </inertial>    
  </link>  

  <joint name="left_leg_fixed" type="fixed">    
    <origin xyz="0 0 0.004999999999999997502" rpy="3.1415926535897926719 -1.9428902930939016723e-16 -7.6327832942984196016e-16"/>    
    <parent link="spur_gear_21_teeth"/>    
    <child link="left_leg_xm430"/>    
    <axis xyz="0 0 1"/>    
    <limit effort="1" velocity="20"/>    
    <joint_properties friction="0.0"/>    
  </joint>  

  <joint name="left_hip_yaw_driven" type="revolute">    
    <origin xyz="-0.036999999999999998168 0.041100000000000011524 -0.019500000000000027728" rpy="-1.5707963267948947816 -1.570796326794896558 0"/>    
    <parent link="waist_link"/>    
    <child link="spur_gear_21_teeth"/>    
    <axis xyz="0 0 1"/>    
    <limit effort="1" velocity="20" lower="-1.570796326794896558" upper="1.570796326794896558"/>    
    <joint_properties friction="0.0"/>    
  </joint>  

  <link name="spur_gear_19_teeth_2">    
    <visual>      
      <origin xyz="0 0 0" rpy="0 -0 0"/>      
      <geometry>        
        <mesh filename="package:///meshes/spur_gear_19_teeth_2_visual.stl"/>        
      </geometry>      
      <material name="spur_gear_19_teeth_2_material">        
        <color rgba="0.61568627450980395466 0.81176470588235294379 0.92941176470588238168 1.0"/>        
      </material>      
    </visual>    
    <collision>      
      <origin xyz="0 0 0" rpy="0 -0 0"/>      
      <geometry>        
        <mesh filename="package:///meshes/spur_gear_19_teeth_2_collision.stl"/>        
      </geometry>      
    </collision>    
    <inertial>      
      <origin xyz="-4.740324259514682441e-08 1.5460070763910083606e-08 0.0045456071298370023803" rpy="0 0 0"/>      
      <mass value="0.0011084409433758843876"/>      
      <inertia ixx="2.9582691212226697356e-08" ixy="-2.8904821292352701869e-14" ixz="7.8892082291023494389e-14" iyy="2.9582612758414133212e-08" iyz="-2.5767358059532391096e-14" izz="4.6351510704080129527e-08"/>      
    </inertial>    
  </link>  

  <joint name="right_hip_yaw_drive" type="revolute">    
    <origin xyz="0.037000000000001719014 0.03710000000000327619 -0.0394999999999998061" rpy="-1.5707963267949545116 -4.8002361403961149694e-13 -3.5216274341110541015e-13"/>    
    <parent link="waist_link"/>    
    <child link="spur_gear_19_teeth_2"/>    
    <axis xyz="0 0 1"/>    
    <limit effort="1" velocity="20" lower="-1.7361433085627806516" upper="1.7361433085627806516"/>    
    <joint_properties friction="0.0"/>    
  </joint>  

  <link name="spur_gear_21_teeth_2">    
    <visual>      
      <origin xyz="0 0 0" rpy="0 -0 0"/>      
      <geometry>        
        <mesh filename="package:///meshes/spur_gear_21_teeth_2_visual.stl"/>        
      </geometry>      
      <material name="spur_gear_21_teeth_2_material">        
        <color rgba="0.61568627450980395466 0.81176470588235294379 0.92941176470588238168 1.0"/>        
      </material>      
    </visual>    
    <collision>      
      <origin xyz="0 0 0" rpy="0 -0 0"/>      
      <geometry>        
        <mesh filename="package:///meshes/spur_gear_21_teeth_2_collision.stl"/>        
      </geometry>      
    </collision>    
    <inertial>      
      <origin xyz="-6.7030728161863890058e-12 -1.7758939917663256745e-11 0.0025054714570094424424" rpy="0 0 0"/>      
      <mass value="0.0010185686142775145658"/>      
      <inertia ixx="3.2129731492034445208e-08" ixy="8.6393532392513229022e-40" ixz="1.7228833550883347423e-38" iyy="3.2129731493285658455e-08" iyz="2.0352762502078849582e-38" izz="6.0052191739644090562e-08"/>      
    </inertial>    
  </link>  

  <link name="right_leg_xm430">    
    <visual>      
      <origin xyz="0 0 0" rpy="0 -0 0"/>      
      <geometry>        
        <mesh filename="package:///meshes/right_leg_xm430_visual.stl"/>        
      </geometry>      
      <material name="right_leg_xm430_material">        
        <color rgba="0.61568627450980395466 0.81176470588235294379 0.92941176470588238168 1.0"/>        
      </material>      
    </visual>    
    <collision>      
      <origin xyz="0 0 0" rpy="0 -0 0"/>      
      <geometry>        
        <mesh filename="package:///meshes/right_leg_xm430_collision.stl"/>        
      </geometry>      
    </collision>    
    <inertial>      
      <origin xyz="-9.7729125808215406047e-19 -5.2615716382370680545e-19 -0.0098919667346054514223" rpy="0 0 0"/>      
      <mass value="0.01799999999999999864"/>      
      <inertia ixx="2.6483505271519540317e-06" ixy="3.1271056766026369484e-37" ixz="-1.2070602226855989009e-36" iyy="7.7055357996008251511e-06" iyz="-1.3357758531161339703e-36" izz="7.7736682806805358371e-06"/>      
    </inertial>    
  </link>  

  <joint name="right_leg_fixed" type="fixed">    
    <origin xyz="0 -6.9388939039072283776e-18 0.0050000000000000044409" rpy="-3.1415926535897926719 1.8281169925220331315e-17 -3.5772536718062127375e-16"/>    
    <parent link="spur_gear_21_teeth_2"/>    
    <child link="right_leg_xm430"/>    
    <axis xyz="0 0 1"/>    
    <limit effort="1" velocity="20"/>    
    <joint_properties friction="0.0"/>    
  </joint>  

  <joint name="right_hip_yaw_driven" type="revolute">    
    <origin xyz="0.036999999999999991229 0.041100000000000011524 -0.019500000000000017319" rpy="-1.570796326794896558 -1.5707963267948961139 0"/>    
    <parent link="waist_link"/>    
    <child link="spur_gear_21_teeth_2"/>    
    <axis xyz="0 0 1"/>    
    <limit effort="1" velocity="20" lower="-1.570796326794896558" upper="1.570796326794896558"/>    
    <joint_properties friction="0.0"/>    
  </joint>  

  <joint name="waist_roll" type="revolute">    
    <origin xyz="-0.022707865260692617487 -2.4393502827093082036e-16 -0.013999999999999814676" rpy="-1.5707963267948974462 1.8675461532229772614e-15 1.5707963267948952257"/>    
    <parent link="waist_gears"/>    
    <child link="waist_link"/>    
    <axis xyz="0 0 1"/>    
    <limit effort="1" velocity="20" lower="-0.52359877559829881566" upper="0.52359877559829881566"/>    
    <joint_properties friction="0.0"/>    
  </joint>  

  <joint name="waist_yaw" type="revolute">    
    <origin xyz="0 -3.1104917983741196655e-18 -7.5188305028877687703e-30" rpy="-1.4111145075746007461e-16 -4.1376224834060906822e-15 3.1415926535897922278"/>    
    <parent link="torso"/>    
    <child link="waist_gears"/>    
    <axis xyz="0 0 1"/>    
    <limit effort="1" velocity="20" lower="-1.570796326794896558" upper="1.570796326794896558"/>    
    <joint_properties friction="0.0"/>    
  </joint>  

  <link name="left_arm_hand">    
    <visual>      
      <origin xyz="0 0 0" rpy="0 -0 0"/>      
      <geometry>        
        <mesh filename="package:///meshes/left_arm_hand_visual.stl"/>        
      </geometry>      
      <material name="left_arm_hand_material">        
        <color rgba="0.61568627450980395466 0.81176470588235294379 0.92941176470588227065 1.0"/>        
      </material>      
    </visual>    
    <collision>      
      <origin xyz="0 0 0" rpy="0 -0 0"/>      
      <geometry>        
        <mesh filename="package:///meshes/left_arm_hand_collision.stl"/>        
      </geometry>      
    </collision>    
    <inertial>      
      <origin xyz="5.8254248488936148346e-11 -5.1264642561120755677e-05 0.0082440788127094866838" rpy="0 0 0"/>      
      <mass value="0.0085999999999999948014"/>      
      <inertia ixx="1.2272887040545789755e-06" ixy="-2.1429944218861188293e-14" ixz="-8.5847198874678704984e-15" iyy="2.9107306060364611617e-06" iyz="7.4623841398182935117e-09" izz="3.0803135950773483457e-06"/>      
    </inertial>    
  </link>  

  <joint name="left_sho_pitch" type="revolute">    
    <origin xyz="-0.0030000000000002949654 0.062000000000001082023 0.10423651076281743866" rpy="-1.5707963267949081043 -4.127643409825574977e-14 3.4723733359249779961e-14"/>    
    <parent link="torso"/>    
    <child link="left_arm_hand"/>    
    <axis xyz="0 0 1"/>    
    <limit effort="1" velocity="20" lower="-3.141592653589793116" upper="1.570796326794896558"/>    
    <joint_properties friction="0.0"/>    
  </joint>  

  <link name="right_arm_hand">    
    <visual>      
      <origin xyz="0 0 0" rpy="0 -0 0"/>      
      <geometry>        
        <mesh filename="package:///meshes/right_arm_hand_visual.stl"/>        
      </geometry>      
      <material name="right_arm_hand_material">        
        <color rgba="0.61568627450980395466 0.81176470588235294379 0.92941176470588227065 1.0"/>        
      </material>      
    </visual>    
    <collision>      
      <origin xyz="0 0 0" rpy="0 -0 0"/>      
      <geometry>        
        <mesh filename="package:///meshes/right_arm_hand_collision.stl"/>        
      </geometry>      
    </collision>    
    <inertial>      
      <origin xyz="5.8254248488936148346e-11 -5.1264642561120755677e-05 0.0082440788127094866838" rpy="0 0 0"/>      
      <mass value="0.0085999999999999948014"/>      
      <inertia ixx="1.2272887040545789755e-06" ixy="-2.1429944218861188293e-14" ixz="-8.5847198874678704984e-15" iyy="2.9107306060364611617e-06" iyz="7.4623841398182935117e-09" izz="3.0803135950773483457e-06"/>      
    </inertial>    
  </link>  

  <joint name="right_sho_pitch" type="revolute">    
    <origin xyz="-0.0029999999999986998872 -0.06200000000000097794 0.10423651076281731376" rpy="-1.5707963267948885644 3.4812325502379109658e-14 -3.1415926535897562566"/>    
    <parent link="torso"/>    
    <child link="right_arm_hand"/>    
    <axis xyz="0 0 1"/>    
    <limit effort="1" velocity="20" lower="-1.570796326794896558" upper="3.141592653589793116"/>    
    <joint_properties friction="0.0"/>    
  </joint>  


</robot>