<?xml version="1.0" ?><robot name="toddlerbot">  
  <link name="torso">    
    <visual>      
      <origin xyz="0 0 0" rpy="0 -0 0"/>      
      <geometry>        
        <mesh filename="package:///meshes/torso_visual.stl"/>        
      </geometry>      
      <material name="torso_material">        
        <color rgba="0.57526495232380758793 0.73266844006799192179 0.85558105253853178329 1.0"/>        
      </material>      
    </visual>    
    <collision>      
      <origin xyz="0 0 0" rpy="0 -0 0"/>      
      <geometry>        
        <mesh filename="package:///meshes/torso_collision.stl"/>        
      </geometry>      
    </collision>    
    <inertial>      
      <origin xyz="-0.0093223985227781167723 0.0030925680084462618853 0.074559030864462999544" rpy="0 0 0"/>      
      <mass value="0.59420757418972602881"/>      
      <inertia ixx="0.0016633654779389475155" ixy="-3.0220749509887614401e-05" ixz="-8.2040194394370237192e-05" iyy="0.0013125271972333264238" iyz="5.261042686544689271e-05" izz="0.0012467109872239517249"/>      
    </inertial>    
  </link>  

  <link name="spur_1m_20t">    
    <visual>      
      <origin xyz="0 0 0" rpy="0 -0 0"/>      
      <geometry>        
        <mesh filename="package:///meshes/spur_1m_20t_visual.stl"/>        
      </geometry>      
      <material name="spur_1m_20t_material">        
        <color rgba="0.64705882352941179736 0.64705882352941179736 0.64705882352941179736 1.0"/>        
      </material>      
    </visual>    
    <collision>      
      <origin xyz="0 0 0" rpy="0 -0 0"/>      
      <geometry>        
        <mesh filename="package:///meshes/spur_1m_20t_collision.stl"/>        
      </geometry>      
    </collision>    
    <inertial>      
      <origin xyz="-3.1289358658087331283e-18 -7.7972790579980648195e-18 0.0033745971730663147647" rpy="0 0 0"/>      
      <mass value="0.0015534950290892286448"/>      
      <inertia ixx="4.4726508287871799621e-08" ixy="5.9288831656506451097e-24" ixz="3.4848601612707237069e-38" iyy="4.4726508287871773151e-08" iyz="5.5194762625213689042e-39" izz="7.9558906764901993374e-08"/>      
    </inertial>    
  </link>  

  <joint name="neck_yaw_drive" type="revolute">    
    <origin xyz="-0.0049999999999993625932 3.342147474086756384e-17 0.12148651076281766215" rpy="7.9879995913373272052e-15 8.0038275409654909883e-15 -5.4161669716995088817e-15"/>    
    <parent link="torso"/>    
    <child link="spur_1m_20t"/>    
    <axis xyz="0 0 1"/>    
    <limit effort="1" velocity="20" lower="-2.2689280275926284602" upper="2.2689280275926284602"/>    
    <joint_properties friction="0.0"/>    
  </joint>  

  <link name="neck_yaw_link">    
    <visual>      
      <origin xyz="0 0 0" rpy="0 -0 0"/>      
      <geometry>        
        <mesh filename="package:///meshes/neck_yaw_link_visual.stl"/>        
      </geometry>      
      <material name="neck_yaw_link_material">        
        <color rgba="0.33636252417476653065 0.48680769190259864931 0.74976123534949778993 1.0"/>        
      </material>      
    </visual>    
    <collision>      
      <origin xyz="0 0 0" rpy="0 -0 0"/>      
      <geometry>        
        <mesh filename="package:///meshes/neck_yaw_link_collision.stl"/>        
      </geometry>      
    </collision>    
    <inertial>      
      <origin xyz="2.7291286460612910846e-05 -0.00019798992283530790384 0.011527412037194890299" rpy="0 0 0"/>      
      <mass value="0.0085168305947458285143"/>      
      <inertia ixx="1.0407116999274356724e-06" ixy="2.4210150467242865068e-11" ixz="-4.7246803216717395074e-10" iyy="1.124000995411033606e-06" iyz="3.0834841754636201264e-08" izz="3.1587565167291838351e-07"/>      
    </inertial>    
  </link>  

  <link name="neck_pitch_link">    
    <visual>      
      <origin xyz="0 0 0" rpy="0 -0 0"/>      
      <geometry>        
        <mesh filename="package:///meshes/neck_pitch_link_visual.stl"/>        
      </geometry>      
      <material name="neck_pitch_link_material">        
        <color rgba="0.74911126277760053949 0.80002799398726853752 0.87441258869524285391 1.0"/>        
      </material>      
    </visual>    
    <collision>      
      <origin xyz="0 0 0" rpy="0 -0 0"/>      
      <geometry>        
        <mesh filename="package:///meshes/neck_pitch_link_collision.stl"/>        
      </geometry>      
    </collision>    
    <inertial>      
      <origin xyz="-0.0034370497615717919213 0.032876793988991216688 -0.00036476492134655293109" rpy="0 0 0"/>      
      <mass value="0.11211553874797880459"/>      
      <inertia ixx="7.7015755459848385584e-05" ixy="-2.1757968319821465942e-06" ixz="-2.8732209413518214024e-06" iyy="6.3502636688153401125e-05" iyz="-1.2492352737634858817e-05" izz="2.861000238397549603e-05"/>      
    </inertial>    
  </link>  

  <link name="spur_gear_(13_teeth)">    
    <visual>      
      <origin xyz="0 0 0" rpy="0 -0 0"/>      
      <geometry>        
        <mesh filename="package:///meshes/spur_gear_(13_teeth)_visual.stl"/>        
      </geometry>      
      <material name="spur_gear_(13_teeth)_material">        
        <color rgba="0.64705882352941168634 0.64705882352941168634 0.64705882352941168634 1.0"/>        
      </material>      
    </visual>    
    <collision>      
      <origin xyz="0 0 0" rpy="0 -0 0"/>      
      <geometry>        
        <mesh filename="package:///meshes/spur_gear_(13_teeth)_collision.stl"/>        
      </geometry>      
    </collision>    
    <inertial>      
      <origin xyz="9.1521560716909342201e-10 -5.4872578741288209028e-10 0.0092751511485596356554" rpy="0 0 0"/>      
      <mass value="0.00081469437497230876716"/>      
      <inertia ixx="2.0244841463618384181e-08" ixy="2.9781774993984019191e-15" ixz="-8.2976066070669600994e-15" iyy="2.0244839778533692508e-08" iyz="1.3142117784934752386e-15" izz="1.8905472907863310999e-08"/>      
    </inertial>    
  </link>  

  <joint name="neck_pitch_drive" type="revolute">    
    <origin xyz="-8.3266726846886740532e-17 0.015649999999999109068 -0.0087999999999961303621" rpy="-6.1232340018137966949e-17 -1.865637580072612815e-26 -1.570796326794896558"/>    
    <parent link="neck_pitch_link"/>    
    <child link="spur_gear_(13_teeth)"/>    
    <axis xyz="0 0 1"/>    
    <limit effort="1" velocity="20" lower="-1.4279966607226330932" upper="1.4279966607226330932"/>    
    <joint_properties friction="0.0"/>    
  </joint>  

  <joint name="neck_pitch_driven" type="revolute">    
    <origin xyz="3.7500132513135220336e-10 -0.0051500000614755217856 0.027499999999999982792" rpy="1.570796326794896558 2.1758709533710261129e-15 3.141592653589793116"/>    
    <parent link="neck_yaw_link"/>    
    <child link="neck_pitch_link"/>    
    <axis xyz="0 0 1"/>    
    <limit effort="1" velocity="20" lower="-1.570796326794896558" upper="1.570796326794896558"/>    
    <joint_properties friction="0.0"/>    
  </joint>  

  <joint name="neck_yaw_driven" type="revolute">    
    <origin xyz="0.016000000000001415867 8.8819348604293101922e-19 0.12248651076281755201" rpy="-9.9708248341698016912e-16 -2.8278563730017396217e-15 3.1415926535897922278"/>    
    <parent link="torso"/>    
    <child link="neck_yaw_link"/>    
    <axis xyz="0 0 1"/>    
    <limit effort="1" velocity="20" lower="-3.141592653589793116" upper="3.141592653589793116"/>    
    <joint_properties friction="0.0"/>    
  </joint>  

  <link name="waist_gears">    
    <visual>      
      <origin xyz="0 0 0" rpy="0 -0 0"/>      
      <geometry>        
        <mesh filename="package:///meshes/waist_gears_visual.stl"/>        
      </geometry>      
      <material name="waist_gears_material">        
        <color rgba="0.2632766275256509525 0.51746399844275281499 0.70128653634567073016 1.0"/>        
      </material>      
    </visual>    
    <collision>      
      <origin xyz="0 0 0" rpy="0 -0 0"/>      
      <geometry>        
        <mesh filename="package:///meshes/waist_gears_collision.stl"/>        
      </geometry>      
    </collision>    
    <inertial>      
      <origin xyz="-2.9688764928860329116e-07 5.6464343506679163041e-08 -0.012588230079602481457" rpy="0 0 0"/>      
      <mass value="0.025809950030454161668"/>      
      <inertia ixx="1.5121316248349413831e-06" ixy="1.8766601008086830485e-11" ixz="4.0584247104119644041e-10" iyy="7.2540386700467505119e-06" iyz="3.1280091580766916988e-12" izz="6.9379699728511675516e-06"/>      
    </inertial>    
  </link>  

  <link name="waist_link">    
    <visual>      
      <origin xyz="0 0 0" rpy="0 -0 0"/>      
      <geometry>        
        <mesh filename="package:///meshes/waist_link_visual.stl"/>        
      </geometry>      
      <material name="waist_link_material">        
        <color rgba="0.63401200025306070351 0.68204699127249923674 0.6691019398503622595 1.0"/>        
      </material>      
    </visual>    
    <collision>      
      <origin xyz="0 0 0" rpy="0 -0 0"/>      
      <geometry>        
        <mesh filename="package:///meshes/waist_link_collision.stl"/>        
      </geometry>      
    </collision>    
    <inertial>      
      <origin xyz="-9.1086191349789797966e-07 0.02620448375530874674 -0.030190392008842503041" rpy="0 0 0"/>      
      <mass value="0.16631953490612461088"/>      
      <inertia ixx="6.8622997376114214674e-05" ixy="-6.1328048449208935454e-10" ixz="-3.6786792027270259281e-06" iyy="0.0002005711742921652285" iyz="-3.7255079147357792621e-06" izz="0.00015770127977213121615"/>      
    </inertial>    
  </link>  

  <link name="spiral_bevel_1m_14t_30deg">    
    <visual>      
      <origin xyz="0 0 0" rpy="0 -0 0"/>      
      <geometry>        
        <mesh filename="package:///meshes/spiral_bevel_1m_14t_30deg_visual.stl"/>        
      </geometry>      
      <material name="spiral_bevel_1m_14t_30deg_material">        
        <color rgba="0.64705882352941179736 0.64705882352941179736 0.64705882352941179736 1.0"/>        
      </material>      
    </visual>    
    <collision>      
      <origin xyz="0 0 0" rpy="0 -0 0"/>      
      <geometry>        
        <mesh filename="package:///meshes/spiral_bevel_1m_14t_30deg_collision.stl"/>        
      </geometry>      
    </collision>    
    <inertial>      
      <origin xyz="8.2641075406508779366e-10 3.4055789828804644178e-10 0.0068612577407481710814" rpy="0 0 0"/>      
      <mass value="0.00067997563436136246491"/>      
      <inertia ixx="1.2174575798018973838e-08" ixy="3.8216077022272332133e-18" ixz="4.7204547808092641463e-16" iyy="1.2174575801813732727e-08" iyz="-2.6184097759530825402e-16" izz="1.3178653206314315019e-08"/>      
    </inertial>    
  </link>  

  <joint name="waist_act_1" type="revolute">    
    <origin xyz="-5.1956727612250319334e-16 0.019600000000000002837 -0.012749999999999961017" rpy="1.570796326794896336 1.5707963267948870101 0"/>    
    <parent link="waist_link"/>    
    <child link="spiral_bevel_1m_14t_30deg"/>    
    <axis xyz="0 0 1"/>    
    <limit effort="1" velocity="20" lower="-4.6774823953448034786" upper="4.6774823953448034786"/>    
    <joint_properties friction="0.0"/>    
  </joint>  

  <link name="spiral_bevel_1m_14t_30deg_2">    
    <visual>      
      <origin xyz="0 0 0" rpy="0 -0 0"/>      
      <geometry>        
        <mesh filename="package:///meshes/spiral_bevel_1m_14t_30deg_2_visual.stl"/>        
      </geometry>      
      <material name="spiral_bevel_1m_14t_30deg_2_material">        
        <color rgba="0.64705882352941179736 0.64705882352941179736 0.64705882352941179736 1.0"/>        
      </material>      
    </visual>    
    <collision>      
      <origin xyz="0 0 0" rpy="0 -0 0"/>      
      <geometry>        
        <mesh filename="package:///meshes/spiral_bevel_1m_14t_30deg_2_collision.stl"/>        
      </geometry>      
    </collision>    
    <inertial>      
      <origin xyz="7.2990964834762629073e-10 5.1591309195404415221e-10 0.0068612577407481598057" rpy="0 0 0"/>      
      <mass value="0.00067997563436136246491"/>      
      <inertia ixx="1.2174575796548746326e-08" ixy="2.6199055579273861548e-18" ixz="5.1847541126784564469e-16" iyy="1.2174575803283975128e-08" iyz="-1.5023607697752326534e-16" izz="1.3178653206314318328e-08"/>      
    </inertial>    
  </link>  

  <joint name="waist_act_2" type="revolute">    
    <origin xyz="2.5285386378767095671e-17 0.019599999999999995898 -0.032749999999999987454" rpy="1.5707963267948974462 1.3463968515392308323 3.4406882288644243018e-15"/>    
    <parent link="waist_link"/>    
    <child link="spiral_bevel_1m_14t_30deg_2"/>    
    <axis xyz="0 0 1"/>    
    <limit effort="1" velocity="20" lower="-4.6774823953448034786" upper="4.6774823953448034786"/>    
    <joint_properties friction="0.0"/>    
  </joint>  

  <link name="spur_gear_19_teeth">    
    <visual>      
      <origin xyz="0 0 0" rpy="0 -0 0"/>      
      <geometry>        
        <mesh filename="package:///meshes/spur_gear_19_teeth_visual.stl"/>        
      </geometry>      
      <material name="spur_gear_19_teeth_material">        
        <color rgba="0.61568627450980395466 0.81176470588235294379 0.92941176470588238168 1.0"/>        
      </material>      
    </visual>    
    <collision>      
      <origin xyz="0 0 0" rpy="0 -0 0"/>      
      <geometry>        
        <mesh filename="package:///meshes/spur_gear_19_teeth_collision.stl"/>        
      </geometry>      
    </collision>    
    <inertial>      
      <origin xyz="-4.9968063064138528947e-09 -7.9242210841379786801e-11 0.0045295192537419875708" rpy="0 0 0"/>      
      <mass value="0.0010993711450650535313"/>      
      <inertia ixx="2.9215018435433085353e-08" ixy="2.5903313828525144025e-16" ixz="8.5599808506680773816e-15" iyy="2.9215021540034051851e-08" iyz="1.1526881407611493956e-16" izz="4.5709977027671374883e-08"/>      
    </inertial>    
  </link>  

  <joint name="left_hip_yaw_drive" type="revolute">    
    <origin xyz="-0.03699999999999847855 0.037100000000005933787 -0.039500000000000194678" rpy="-1.5707963267949540676 -4.7732588435988597417e-13 -3.5949390257278751872e-13"/>    
    <parent link="waist_link"/>    
    <child link="spur_gear_19_teeth"/>    
    <axis xyz="0 0 1"/>    
    <limit effort="1" velocity="20" lower="-1.4211966766239538806" upper="1.4211966766239538806"/>    
    <joint_properties friction="0.0"/>    
  </joint>  

  <link name="spur_gear_21_teeth">    
    <visual>      
      <origin xyz="0 0 0" rpy="0 -0 0"/>      
      <geometry>        
        <mesh filename="package:///meshes/spur_gear_21_teeth_visual.stl"/>        
      </geometry>      
      <material name="spur_gear_21_teeth_material">        
        <color rgba="0.61568627450980395466 0.81176470588235294379 0.92941176470588238168 1.0"/>        
      </material>      
    </visual>    
    <collision>      
      <origin xyz="0 0 0" rpy="0 -0 0"/>      
      <geometry>        
        <mesh filename="package:///meshes/spur_gear_21_teeth_collision.stl"/>        
      </geometry>      
    </collision>    
    <inertial>      
      <origin xyz="-4.7814841719676404558e-10 -1.2610157577314885413e-12 0.0024944618616143366362" rpy="0 0 0"/>      
      <mass value="0.0010063046528317972673"/>      
      <inertia ixx="3.1842855421068481665e-08" ixy="-8.8385836052879639588e-42" ixz="-3.108490655579927479e-38" iyy="3.1842855426953785697e-08" iyz="4.4807157636322001073e-50" izz="5.9529380586728028132e-08"/>      
    </inertial>    
  </link>  

  <link name="left_leg_xm430">    
    <visual>      
      <origin xyz="0 0 0" rpy="0 -0 0"/>      
      <geometry>        
        <mesh filename="package:///meshes/left_leg_xm430_visual.stl"/>        
      </geometry>      
      <material name="left_leg_xm430_material">        
        <color rgba="0.61568627450980395466 0.81176470588235294379 0.92941176470588238168 1.0"/>        
      </material>      
    </visual>    
    <collision>      
      <origin xyz="0 0 0" rpy="0 -0 0"/>      
      <geometry>        
        <mesh filename="package:///meshes/left_leg_xm430_collision.stl"/>        
      </geometry>      
    </collision>    
    <inertial>      
      <origin xyz="-9.1960418512498486936e-19 -5.5625627936854410362e-19 -0.0098390489054829121524" rpy="0 0 0"/>      
      <mass value="0.017999999999999995171"/>      
      <inertia ixx="2.638503389144252815e-06" ixy="-3.3466178601467236125e-38" ixz="0" iyy="7.6596731957046856464e-06" iyz="0" izz="7.7220708070894735956e-06"/>      
    </inertial>    
  </link>  

  <joint name="left_leg_fixed" type="fixed">    
    <origin xyz="4.7704895589362195096e-18 -6.9388939039072283776e-18 0.0050000000000000113798" rpy="3.141592653589793116 -2.7755575615623496255e-17 -3.3306690738754706073e-16"/>    
    <parent link="spur_gear_21_teeth"/>    
    <child link="left_leg_xm430"/>    
    <axis xyz="0 0 1"/>    
    <limit effort="1" velocity="20"/>    
    <joint_properties friction="0.0"/>    
  </joint>  

  <joint name="left_hip_yaw_driven" type="revolute">    
    <origin xyz="-0.036999999999999998168 0.04110000000000003928 -0.019500000000000027728" rpy="-1.5707963267948961139 -1.5707963267948883423 0"/>    
    <parent link="waist_link"/>    
    <child link="spur_gear_21_teeth"/>    
    <axis xyz="0 0 1"/>    
    <limit effort="1" velocity="20" lower="-1.570796326794896558" upper="1.570796326794896558"/>    
    <joint_properties friction="0.0"/>    
  </joint>  

  <link name="spur_gear_19_teeth_2">    
    <visual>      
      <origin xyz="0 0 0" rpy="0 -0 0"/>      
      <geometry>        
        <mesh filename="package:///meshes/spur_gear_19_teeth_2_visual.stl"/>        
      </geometry>      
      <material name="spur_gear_19_teeth_2_material">        
        <color rgba="0.61568627450980395466 0.81176470588235294379 0.92941176470588238168 1.0"/>        
      </material>      
    </visual>    
    <collision>      
      <origin xyz="0 0 0" rpy="0 -0 0"/>      
      <geometry>        
        <mesh filename="package:///meshes/spur_gear_19_teeth_2_collision.stl"/>        
      </geometry>      
    </collision>    
    <inertial>      
      <origin xyz="-4.9968063064138528947e-09 -7.9242210841379786801e-11 0.0045295192537419875708" rpy="0 0 0"/>      
      <mass value="0.0010993711450650535313"/>      
      <inertia ixx="2.9215018435433085353e-08" ixy="2.5903313840735645875e-16" ixz="8.5599808506680773816e-15" iyy="2.9215021540034065086e-08" iyz="1.1526881407611503817e-16" izz="4.5709977027671374883e-08"/>      
    </inertial>    
  </link>  

  <joint name="right_hip_yaw_drive" type="revolute">    
    <origin xyz="0.037000000000001344314 0.037100000000003394152 -0.039499999999999368949" rpy="-1.5707963267949540676 -4.7918343317333855547e-13 -3.3767433293974656194e-13"/>    
    <parent link="waist_link"/>    
    <child link="spur_gear_19_teeth_2"/>    
    <axis xyz="0 0 1"/>    
    <limit effort="1" velocity="20" lower="-1.4211966766239538806" upper="1.4211966766239538806"/>    
    <joint_properties friction="0.0"/>    
  </joint>  

  <link name="spur_gear_21_teeth_2">    
    <visual>      
      <origin xyz="0 0 0" rpy="0 -0 0"/>      
      <geometry>        
        <mesh filename="package:///meshes/spur_gear_21_teeth_2_visual.stl"/>        
      </geometry>      
      <material name="spur_gear_21_teeth_2_material">        
        <color rgba="0.61568627450980395466 0.81176470588235294379 0.92941176470588238168 1.0"/>        
      </material>      
    </visual>    
    <collision>      
      <origin xyz="0 0 0" rpy="0 -0 0"/>      
      <geometry>        
        <mesh filename="package:///meshes/spur_gear_21_teeth_2_collision.stl"/>        
      </geometry>      
    </collision>    
    <inertial>      
      <origin xyz="-4.7814841719676404558e-10 1.2610157577314885413e-12 0.0025055381383856747436" rpy="0 0 0"/>      
      <mass value="0.0010063046528317972673"/>      
      <inertia ixx="3.1842855421068481665e-08" ixy="2.040090653859849558e-39" ixz="-4.9410685769297806706e-39" iyy="3.1842855426953785697e-08" iyz="3.4126277035795834641e-40" izz="5.9529380586728028132e-08"/>      
    </inertial>    
  </link>  

  <link name="right_leg_xm430">    
    <visual>      
      <origin xyz="0 0 0" rpy="0 -0 0"/>      
      <geometry>        
        <mesh filename="package:///meshes/right_leg_xm430_visual.stl"/>        
      </geometry>      
      <material name="right_leg_xm430_material">        
        <color rgba="0.61568627450980395466 0.81176470588235294379 0.92941176470588238168 1.0"/>        
      </material>      
    </visual>    
    <collision>      
      <origin xyz="0 0 0" rpy="0 -0 0"/>      
      <geometry>        
        <mesh filename="package:///meshes/right_leg_xm430_collision.stl"/>        
      </geometry>      
    </collision>    
    <inertial>      
      <origin xyz="-9.1960418512498121009e-19 -5.5625627936854535547e-19 -0.0098390489054829121524" rpy="0 0 0"/>      
      <mass value="0.017999999999999995171"/>      
      <inertia ixx="2.638503389144252815e-06" ixy="-5.8294137562931924602e-38" ixz="-1.8673461332934760962e-36" iyy="7.6596731957046856464e-06" iyz="9.522032685736859703e-37" izz="7.7220708070894735956e-06"/>      
    </inertial>    
  </link>  

  <joint name="right_leg_fixed" type="fixed">    
    <origin xyz="-4.7704895589362195096e-18 0 0.0050000000000000044409" rpy="-3.141592653589793116 -8.3266726846891486023e-17 -4.1633363423432264583e-17"/>    
    <parent link="spur_gear_21_teeth_2"/>    
    <child link="right_leg_xm430"/>    
    <axis xyz="0 0 1"/>    
    <limit effort="1" velocity="20"/>    
    <joint_properties friction="0.0"/>    
  </joint>  

  <joint name="right_hip_yaw_driven" type="revolute">    
    <origin xyz="0.036999999999999991229 0.041099999999999997646 -0.019499999999999999972" rpy="-1.5707963267948961139 -1.5707963267948952257 0"/>    
    <parent link="waist_link"/>    
    <child link="spur_gear_21_teeth_2"/>    
    <axis xyz="0 0 1"/>    
    <limit effort="1" velocity="20" lower="-1.570796326794896558" upper="1.570796326794896558"/>    
    <joint_properties friction="0.0"/>    
  </joint>  

  <joint name="waist_roll" type="revolute">    
    <origin xyz="-0.022707865260692197684 -2.2800061759205613016e-17 -0.01399999999999972447" rpy="-1.570796326794896558 -1.4470091796846119987e-16 1.5707963267948970021"/>    
    <parent link="waist_gears"/>    
    <child link="waist_link"/>    
    <axis xyz="0 0 1"/>    
    <limit effort="1" velocity="20" lower="-0.52359877559829881566" upper="0.52359877559829881566"/>    
    <joint_properties friction="0.0"/>    
  </joint>  

  <joint name="waist_yaw" type="revolute">    
    <origin xyz="0 6.1629758220391547298e-33 -2.4651903288156618919e-30" rpy="1.3285483818409156951e-16 -3.8508827433200160488e-15 3.1415926535897922278"/>    
    <parent link="torso"/>    
    <child link="waist_gears"/>    
    <axis xyz="0 0 1"/>    
    <limit effort="1" velocity="20" lower="-1.570796326794896558" upper="1.570796326794896558"/>    
    <joint_properties friction="0.0"/>    
  </joint>  

  <link name="left_arm_hand">    
    <visual>      
      <origin xyz="0 0 0" rpy="0 -0 0"/>      
      <geometry>        
        <mesh filename="package:///meshes/left_arm_hand_visual.stl"/>        
      </geometry>      
      <material name="left_arm_hand_material">        
        <color rgba="0.61568627450980395466 0.81176470588235294379 0.92941176470588227065 1.0"/>        
      </material>      
    </visual>    
    <collision>      
      <origin xyz="0 0 0" rpy="0 -0 0"/>      
      <geometry>        
        <mesh filename="package:///meshes/left_arm_hand_collision.stl"/>        
      </geometry>      
    </collision>    
    <inertial>      
      <origin xyz="5.8254249521811582877e-11 -5.1264642561120958965e-05 0.008244078812709491888" rpy="0 0 0"/>      
      <mass value="0.0085999999999999965361"/>      
      <inertia ixx="1.2272887040545793991e-06" ixy="-2.1429944230882620695e-14" ixz="-8.5847199149485390626e-15" iyy="2.9107306060364624323e-06" iyz="7.4623841398183150184e-09" izz="3.0803135950773496163e-06"/>      
    </inertial>    
  </link>  

  <joint name="left_sho_pitch" type="revolute">    
    <origin xyz="-0.0030000000000002949654 0.062000000000001082023 0.10423651076281743866" rpy="-1.5707963267949081043 -4.127643409825574977e-14 3.4723733359249779961e-14"/>    
    <parent link="torso"/>    
    <child link="left_arm_hand"/>    
    <axis xyz="0 0 1"/>    
    <limit effort="1" velocity="20" lower="-1.570796326794896558" upper="1.570796326794896558"/>    
    <joint_properties friction="0.0"/>    
  </joint>  

  <link name="right_arm_hand">    
    <visual>      
      <origin xyz="0 0 0" rpy="0 -0 0"/>      
      <geometry>        
        <mesh filename="package:///meshes/right_arm_hand_visual.stl"/>        
      </geometry>      
      <material name="right_arm_hand_material">        
        <color rgba="0.61568627450980395466 0.81176470588235294379 0.92941176470588227065 1.0"/>        
      </material>      
    </visual>    
    <collision>      
      <origin xyz="0 0 0" rpy="0 -0 0"/>      
      <geometry>        
        <mesh filename="package:///meshes/right_arm_hand_collision.stl"/>        
      </geometry>      
    </collision>    
    <inertial>      
      <origin xyz="5.8254249521811582877e-11 -5.1264642561120958965e-05 0.008244078812709491888" rpy="0 0 0"/>      
      <mass value="0.0085999999999999965361"/>      
      <inertia ixx="1.2272887040545793991e-06" ixy="-2.1429944230882620695e-14" ixz="-8.5847199149485390626e-15" iyy="2.9107306060364624323e-06" iyz="7.4623841398183150184e-09" izz="3.0803135950773496163e-06"/>      
    </inertial>    
  </link>  

  <joint name="right_sho_pitch" type="revolute">    
    <origin xyz="-0.0029999999999986998872 -0.06200000000000097794 0.10423651076281731376" rpy="-1.5707963267948885644 3.4812325502379109658e-14 -3.1415926535897562566"/>    
    <parent link="torso"/>    
    <child link="right_arm_hand"/>    
    <axis xyz="0 0 1"/>    
    <limit effort="1" velocity="20" lower="-1.570796326794896558" upper="1.570796326794896558"/>    
    <joint_properties friction="0.0"/>    
  </joint>  


</robot>