<?xml version="1.0" ?><robot name="toddlerbot">  
  <link name="torso">    
    <visual>      
      <origin xyz="0 0 0" rpy="0 -0 0"/>      
      <geometry>        
        <mesh filename="package:///meshes/torso_visual.stl"/>        
      </geometry>      
      <material name="torso_material">        
        <color rgba="0.63610649049495060492 0.78875589083051733663 0.89504203757263367525 1.0"/>        
      </material>      
    </visual>    
    <collision>      
      <origin xyz="0 0 0" rpy="0 -0 0"/>      
      <geometry>        
        <mesh filename="package:///meshes/torso_collision.stl"/>        
      </geometry>      
    </collision>    
    <inertial>      
      <origin xyz="-0.0028324690810366632762 -0.0031814941915546341225 0.065687884028609519471" rpy="0 0 0"/>      
      <mass value="1.071065963101194507"/>      
      <inertia ixx="0.0028313982462222276638" ixy="6.957844733714890794e-05" ixz="1.4097849458143929096e-05" iyy="0.0022544064796858891316" iyz="-2.5946844160172894257e-05" izz="0.002296516304035425924"/>      
    </inertial>    
  </link>  

  <link name="spur_1m_20t">    
    <visual>      
      <origin xyz="0 0 0" rpy="0 -0 0"/>      
      <geometry>        
        <mesh filename="package:///meshes/spur_1m_20t_visual.stl"/>        
      </geometry>      
      <material name="spur_1m_20t_material">        
        <color rgba="0.64705882352941179736 0.64705882352941179736 0.64705882352941179736 1.0"/>        
      </material>      
    </visual>    
    <collision>      
      <origin xyz="0 0 0" rpy="0 -0 0"/>      
      <geometry>        
        <mesh filename="package:///meshes/spur_1m_20t_collision.stl"/>        
      </geometry>      
    </collision>    
    <inertial>      
      <origin xyz="6.5694143564442681753e-19 -8.161386652865521683e-18 0.0033842321054344537412" rpy="0 0 0"/>      
      <mass value="0.0015778025963745999881"/>      
      <inertia ixx="4.5874424196602117996e-08" ixy="3.9799061064085007145e-24" ixz="-4.1882861322929882735e-38" iyy="4.5874424196602071674e-08" iyz="-7.6583723681862653207e-38" izz="8.1737050837173876176e-08"/>      
    </inertial>    
  </link>  

  <joint name="neck_yaw_drive" type="revolute">    
    <origin xyz="-0.004999999999999517851 2.6555840535020396321e-18 0.121486510762817565" rpy="1.1318451824181020002e-14 2.6985403517595457696e-15 -5.3863140912757267331e-15"/>    
    <parent link="torso"/>    
    <child link="spur_1m_20t"/>    
    <axis xyz="0 0 1"/>    
    <limit effort="1" velocity="20" lower="-2.8797932657906435416" upper="2.8797932657906435416"/>    
    <joint_properties friction="0.0"/>    
  </joint>  

  <link name="neck_yaw_link">    
    <visual>      
      <origin xyz="0 0 0" rpy="0 -0 0"/>      
      <geometry>        
        <mesh filename="package:///meshes/neck_yaw_link_visual.stl"/>        
      </geometry>      
      <material name="neck_yaw_link_material">        
        <color rgba="0.33636252417476658616 0.48680769190259876034 0.74976123534949778993 1.0"/>        
      </material>      
    </visual>    
    <collision>      
      <origin xyz="0 0 0" rpy="0 -0 0"/>      
      <geometry>        
        <mesh filename="package:///meshes/neck_yaw_link_collision.stl"/>        
      </geometry>      
    </collision>    
    <inertial>      
      <origin xyz="2.7225920453770411245e-05 -0.00019941424914293758887 0.01151350293965750296" rpy="0 0 0"/>      
      <mass value="0.0085168305947458267796"/>      
      <inertia ixx="1.0437924002160781335e-06" ixy="1.8902154134667430412e-11" ixz="-4.8455966955762836612e-10" iyy="1.1269053641669183658e-06" iyz="3.1095322714391099842e-08" izz="3.1736817316311681954e-07"/>      
    </inertial>    
  </link>  

  <link name="neck_pitch_link">    
    <visual>      
      <origin xyz="0 0 0" rpy="0 -0 0"/>      
      <geometry>        
        <mesh filename="package:///meshes/neck_pitch_link_visual.stl"/>        
      </geometry>      
      <material name="neck_pitch_link_material">        
        <color rgba="0.634889499382005007 0.78217650228196200501 0.83850167834705624514 1.0"/>        
      </material>      
    </visual>    
    <collision>      
      <origin xyz="0 0 0" rpy="0 -0 0"/>      
      <geometry>        
        <mesh filename="package:///meshes/neck_pitch_link_collision.stl"/>        
      </geometry>      
    </collision>    
    <inertial>      
      <origin xyz="0.0074941752208605950589 0.036106451965378913438 -0.0026450432675133497135" rpy="0 0 0"/>      
      <mass value="0.07429999999309182257"/>      
      <inertia ixx="5.6163162401071686802e-05" ixy="-1.8328324981471452834e-05" ixz="-1.0415620464442886819e-05" iyy="4.3358519502837179218e-05" iyz="-1.5323447827271053577e-05" izz="5.051557856867261258e-05"/>      
    </inertial>    
  </link>  

  <link name="spur_gear_13_teeth">    
    <visual>      
      <origin xyz="0 0 0" rpy="0 -0 0"/>      
      <geometry>        
        <mesh filename="package:///meshes/spur_gear_13_teeth_visual.stl"/>        
      </geometry>      
      <material name="spur_gear_13_teeth_material">        
        <color rgba="0.64705882352941179736 0.64705882352941179736 0.64705882352941179736 1.0"/>        
      </material>      
    </visual>    
    <collision>      
      <origin xyz="0 0 0" rpy="0 -0 0"/>      
      <geometry>        
        <mesh filename="package:///meshes/spur_gear_13_teeth_collision.stl"/>        
      </geometry>      
    </collision>    
    <inertial>      
      <origin xyz="4.9205447788601796943e-09 1.1447063319911771128e-08 0.0089707086943746384977" rpy="0 0 0"/>      
      <mass value="0.00091877519177533870359"/>      
      <inertia ixx="2.2662869467663507022e-08" ixy="-2.358516796247192344e-15" ixz="-1.6015315386735980841e-14" iyy="2.2662849933507481197e-08" iyz="6.2213197336147593987e-15" izz="2.0984691696790200045e-08"/>      
    </inertial>    
  </link>  

  <joint name="neck_pitch_drive" type="revolute">    
    <origin xyz="2.2030988144905450099e-15 0.015649999999998998046 -0.0087999999999980177412" rpy="-2.2204460492487858954e-16 -6.1232339955881360132e-17 -1.5707963267948970021"/>    
    <parent link="neck_pitch_link"/>    
    <child link="spur_gear_13_teeth"/>    
    <axis xyz="0 0 1"/>    
    <limit effort="1" velocity="20" lower="-2.174948760177549012" upper="2.174948760177549012"/>    
    <joint_properties friction="0.0"/>    
  </joint>  

  <joint name="neck_pitch_driven" type="revolute">    
    <origin xyz="3.7500001714985131684e-10 -0.0051500000614753864772 0.027499999999999982792" rpy="1.5707963267948976682 -2.0825786444061155416e-16 3.141592653589793116"/>    
    <parent link="neck_yaw_link"/>    
    <child link="neck_pitch_link"/>    
    <axis xyz="0 0 1"/>    
    <limit effort="1" velocity="20" lower="-1.570796326794896558" upper="1.570796326794896558"/>    
    <joint_properties friction="0.0"/>    
  </joint>  

  <joint name="neck_yaw_driven" type="revolute">    
    <origin xyz="0.016000000000000298706 -1.0553952915478177074e-17 0.12248651076281746874" rpy="3.1251798320819254749e-16 -4.2234156679321592005e-15 3.1415926535897926719"/>    
    <parent link="torso"/>    
    <child link="neck_yaw_link"/>    
    <axis xyz="0 0 1"/>    
    <limit effort="1" velocity="20" lower="-2.6179938779914944114" upper="2.6179938779914944114"/>    
    <joint_properties friction="0.0"/>    
  </joint>  

  <link name="waist_gears">    
    <visual>      
      <origin xyz="0 0 0" rpy="0 -0 0"/>      
      <geometry>        
        <mesh filename="package:///meshes/waist_gears_visual.stl"/>        
      </geometry>      
      <material name="waist_gears_material">        
        <color rgba="0.26906161272592882261 0.5227921908325551259 0.70491767355474521661 1.0"/>        
      </material>      
    </visual>    
    <collision>      
      <origin xyz="0 0 0" rpy="0 -0 0"/>      
      <geometry>        
        <mesh filename="package:///meshes/waist_gears_collision.stl"/>        
      </geometry>      
    </collision>    
    <inertial>      
      <origin xyz="-2.9089024313128832095e-07 5.5035553754110650702e-08 -0.012592985430860466345" rpy="0 0 0"/>      
      <mass value="0.026337180140419177987"/>      
      <inertia ixx="1.5367047941033378762e-06" ixy="1.8828487086084004735e-11" ixz="4.0600521958969797795e-10" iyy="7.3024712275451028514e-06" iyz="3.2911737859821277824e-12" izz="6.9859065635060035973e-06"/>      
    </inertial>    
  </link>  

  <link name="waist_link">    
    <visual>      
      <origin xyz="0 0 0" rpy="0 -0 0"/>      
      <geometry>        
        <mesh filename="package:///meshes/waist_link_visual.stl"/>        
      </geometry>      
      <material name="waist_link_material">        
        <color rgba="0.63430343020834178969 0.68126545235342628182 0.66860955758476392496 1.0"/>        
      </material>      
    </visual>    
    <collision>      
      <origin xyz="0 0 0" rpy="0 -0 0"/>      
      <geometry>        
        <mesh filename="package:///meshes/waist_link_collision.stl"/>        
      </geometry>      
    </collision>    
    <inertial>      
      <origin xyz="-7.9740521615456569522e-06 0.026228931551963298452 -0.02998428051279700135" rpy="0 0 0"/>      
      <mass value="0.17011953490612460871"/>      
      <inertia ixx="7.02750244019059115e-05" ixy="6.4268611251567220029e-09" ixz="-3.6642841622778985362e-06" iyy="0.00020583820676506122565" iyz="-3.5576438610753806473e-06" izz="0.0001621866976539304572"/>      
    </inertial>    
  </link>  

  <link name="spiral_bevel_1m_14t_30deg">    
    <visual>      
      <origin xyz="0 0 0" rpy="0 -0 0"/>      
      <geometry>        
        <mesh filename="package:///meshes/spiral_bevel_1m_14t_30deg_visual.stl"/>        
      </geometry>      
      <material name="spiral_bevel_1m_14t_30deg_material">        
        <color rgba="0.64705882352941179736 0.64705882352941179736 0.64705882352941179736 1.0"/>        
      </material>      
    </visual>    
    <collision>      
      <origin xyz="0 0 0" rpy="0 -0 0"/>      
      <geometry>        
        <mesh filename="package:///meshes/spiral_bevel_1m_14t_30deg_collision.stl"/>        
      </geometry>      
    </collision>    
    <inertial>      
      <origin xyz="7.4971447279470471159e-10 7.1802237376281108361e-10 0.0066868955018979277238" rpy="0 0 0"/>      
      <mass value="0.00073261524436595481732"/>      
      <inertia ixx="1.3495056019478193356e-08" ixy="4.0596682438573597559e-17" ixz="8.5992550158701614423e-16" iyy="1.3495056150237198942e-08" iyz="-6.7913008252156700177e-16" izz="1.4355986549816403445e-08"/>      
    </inertial>    
  </link>  

  <joint name="waist_act_1" type="revolute">    
    <origin xyz="1.414969124206259699e-16 0.019599999999999985489 -0.01275000000000047623" rpy="1.5707963267948943376 1.5707963267948952257 0"/>    
    <parent link="waist_link"/>    
    <child link="spiral_bevel_1m_14t_30deg"/>    
    <axis xyz="0 0 1"/>    
    <limit effort="1" velocity="20" lower="-4.6774823953448034786" upper="4.6774823953448034786"/>    
    <joint_properties friction="0.0"/>    
  </joint>  

  <link name="spiral_bevel_1m_14t_30deg_2">    
    <visual>      
      <origin xyz="0 0 0" rpy="0 -0 0"/>      
      <geometry>        
        <mesh filename="package:///meshes/spiral_bevel_1m_14t_30deg_2_visual.stl"/>        
      </geometry>      
      <material name="spiral_bevel_1m_14t_30deg_2_material">        
        <color rgba="0.64705882352941179736 0.64705882352941179736 0.64705882352941179736 1.0"/>        
      </material>      
    </visual>    
    <collision>      
      <origin xyz="0 0 0" rpy="0 -0 0"/>      
      <geometry>        
        <mesh filename="package:///meshes/spiral_bevel_1m_14t_30deg_2_collision.stl"/>        
      </geometry>      
    </collision>    
    <inertial>      
      <origin xyz="5.7114255859469498233e-10 8.6684721865013748573e-10 0.0066868955018979190502" rpy="0 0 0"/>      
      <mass value="0.00073261524436595481732"/>      
      <inertia ixx="1.3495056008338566936e-08" ixy="8.2092433640957556051e-18" ixz="9.894860339716495576e-16" iyy="1.3495056161376838597e-08" iyz="-4.707514477431321997e-16" izz="1.4355986549816406754e-08"/>      
    </inertial>    
  </link>  

  <joint name="waist_act_2" type="revolute">    
    <origin xyz="1.5688834189823429471e-16 0.01960000000000029774 -0.032750000000000542566" rpy="1.5707963267948947816 1.3463968515392290559 2.1929231817633944674e-14"/>    
    <parent link="waist_link"/>    
    <child link="spiral_bevel_1m_14t_30deg_2"/>    
    <axis xyz="0 0 1"/>    
    <limit effort="1" velocity="20" lower="-4.6774823953448034786" upper="4.6774823953448034786"/>    
    <joint_properties friction="0.0"/>    
  </joint>  

  <link name="spur_gear_19_teeth">    
    <visual>      
      <origin xyz="0 0 0" rpy="0 -0 0"/>      
      <geometry>        
        <mesh filename="package:///meshes/spur_gear_19_teeth_visual.stl"/>        
      </geometry>      
      <material name="spur_gear_19_teeth_material">        
        <color rgba="0.61568627450980395466 0.81176470588235294379 0.92941176470588238168 1.0"/>        
      </material>      
    </visual>    
    <collision>      
      <origin xyz="0 0 0" rpy="0 -0 0"/>      
      <geometry>        
        <mesh filename="package:///meshes/spur_gear_19_teeth_collision.stl"/>        
      </geometry>      
    </collision>    
    <inertial>      
      <origin xyz="3.9826206803695150985e-10 -1.6001614931093530558e-10 0.010108515802794638266" rpy="0 0 0"/>      
      <mass value="0.0010324984452316546789"/>      
      <inertia ixx="3.3238560252068702938e-08" ixy="-2.6893322089861573998e-16" ixz="-1.3807194537080874063e-15" iyy="3.3238560155295354151e-08" iyz="1.5293509760134411876e-16" izz="4.0687617484182906052e-08"/>      
    </inertial>    
  </link>  

  <joint name="left_hip_yaw_drive" type="revolute">    
    <origin xyz="-0.036999999999999783062 0.031099999999999981826 -0.039200000000000179146" rpy="1.570796326794896558 -7.8039718066171778704e-18 -3.1415926535897740202"/>    
    <parent link="waist_link"/>    
    <child link="spur_gear_19_teeth"/>    
    <axis xyz="0 0 1"/>    
    <limit effort="1" velocity="20" lower="-1.7361433085627806516" upper="1.7361433085627806516"/>    
    <joint_properties friction="0.0"/>    
  </joint>  

  <link name="spur_gear_21_teeth">    
    <visual>      
      <origin xyz="0 0 0" rpy="0 -0 0"/>      
      <geometry>        
        <mesh filename="package:///meshes/spur_gear_21_teeth_visual.stl"/>        
      </geometry>      
      <material name="spur_gear_21_teeth_material">        
        <color rgba="0.61568627450980395466 0.81176470588235294379 0.92941176470588238168 1.0"/>        
      </material>      
    </visual>    
    <collision>      
      <origin xyz="0 0 0" rpy="0 -0 0"/>      
      <geometry>        
        <mesh filename="package:///meshes/spur_gear_21_teeth_collision.stl"/>        
      </geometry>      
    </collision>    
    <inertial>      
      <origin xyz="-4.3729138592572817178e-11 1.6127133639547656774e-11 0.0024945650973685578981" rpy="0 0 0"/>      
      <mass value="0.0010254193609188259288"/>      
      <inertia ixx="3.252427873344092869e-08" ixy="-3.6902073647097775944e-39" ixz="1.9413131531732644195e-38" iyy="3.2524278732748128531e-08" iyz="-5.8132141973613747648e-38" izz="6.0814076151188739369e-08"/>      
    </inertial>    
  </link>  

  <link name="left_leg_xm430">    
    <visual>      
      <origin xyz="0 0 0" rpy="0 -0 0"/>      
      <geometry>        
        <mesh filename="package:///meshes/left_leg_xm430_visual.stl"/>        
      </geometry>      
      <material name="left_leg_xm430_material">        
        <color rgba="0.61568627450980395466 0.81176470588235294379 0.92941176470588238168 1.0"/>        
      </material>      
    </visual>    
    <collision>      
      <origin xyz="0 0 0" rpy="0 -0 0"/>      
      <geometry>        
        <mesh filename="package:///meshes/left_leg_xm430_collision.stl"/>        
      </geometry>      
    </collision>    
    <inertial>      
      <origin xyz="-3.4240348394676997042e-19 6.3553305359028579719e-18 -0.0098919667346054479529" rpy="0 0 0"/>      
      <mass value="0.01799999999999999864"/>      
      <inertia ixx="2.6483505271519540317e-06" ixy="3.3669137036967698065e-36" ixz="0" iyy="7.705535799600823457e-06" iyz="0" izz="7.7736682806805358371e-06"/>      
    </inertial>    
  </link>  

  <joint name="left_leg_fixed" type="fixed">    
    <origin xyz="4.336808689942017736e-19 6.9388939039072283776e-18 0.004999999999999997502" rpy="3.1415926535897873428 4.1823223096112866159e-31 9.0864025441047529406e-31"/>    
    <parent link="spur_gear_21_teeth"/>    
    <child link="left_leg_xm430"/>    
    <axis xyz="0 0 1"/>    
    <limit effort="1" velocity="20"/>    
    <joint_properties friction="0.0"/>    
  </joint>  

  <joint name="left_hip_yaw_driven" type="revolute">    
    <origin xyz="-0.036999999999999991229 0.041100000000000011524 -0.019500000000000006911" rpy="-1.5707963267948903408 -1.5707963267948950037 0"/>    
    <parent link="waist_link"/>    
    <child link="spur_gear_21_teeth"/>    
    <axis xyz="0 0 1"/>    
    <limit effort="1" velocity="20" lower="-1.570796326794896558" upper="1.570796326794896558"/>    
    <joint_properties friction="0.0"/>    
  </joint>  

  <link name="spur_gear_19_teeth_2">    
    <visual>      
      <origin xyz="0 0 0" rpy="0 -0 0"/>      
      <geometry>        
        <mesh filename="package:///meshes/spur_gear_19_teeth_2_visual.stl"/>        
      </geometry>      
      <material name="spur_gear_19_teeth_2_material">        
        <color rgba="0.61568627450980395466 0.81176470588235294379 0.92941176470588238168 1.0"/>        
      </material>      
    </visual>    
    <collision>      
      <origin xyz="0 0 0" rpy="0 -0 0"/>      
      <geometry>        
        <mesh filename="package:///meshes/spur_gear_19_teeth_2_collision.stl"/>        
      </geometry>      
    </collision>    
    <inertial>      
      <origin xyz="3.9826206803695140645e-10 -1.6001614931093530558e-10 0.010108515802794638266" rpy="0 0 0"/>      
      <mass value="0.0010324984452316546789"/>      
      <inertia ixx="3.3238560252068689703e-08" ixy="-2.6893322090002834334e-16" ixz="-1.3807194537080870119e-15" iyy="3.3238560155295354151e-08" iyz="1.5293509760134411876e-16" izz="4.0687617484182906052e-08"/>      
    </inertial>    
  </link>  

  <joint name="right_hip_yaw_drive" type="revolute">    
    <origin xyz="0.03699999999999992184 0.031100000000000113665 -0.03920000000000027629" rpy="1.5707963267948945596 3.4666037472893071652e-15 -3.1415926535897917837"/>    
    <parent link="waist_link"/>    
    <child link="spur_gear_19_teeth_2"/>    
    <axis xyz="0 0 1"/>    
    <limit effort="1" velocity="20" lower="-1.7361433085627806516" upper="1.7361433085627806516"/>    
    <joint_properties friction="0.0"/>    
  </joint>  

  <link name="spur_gear_21_teeth_2">    
    <visual>      
      <origin xyz="0 0 0" rpy="0 -0 0"/>      
      <geometry>        
        <mesh filename="package:///meshes/spur_gear_21_teeth_2_visual.stl"/>        
      </geometry>      
      <material name="spur_gear_21_teeth_2_material">        
        <color rgba="0.61568627450980395466 0.81176470588235294379 0.92941176470588238168 1.0"/>        
      </material>      
    </visual>    
    <collision>      
      <origin xyz="0 0 0" rpy="0 -0 0"/>      
      <geometry>        
        <mesh filename="package:///meshes/spur_gear_21_teeth_2_collision.stl"/>        
      </geometry>      
    </collision>    
    <inertial>      
      <origin xyz="-4.3729139026253686172e-11 -1.6127126700653752866e-11 0.0025054349026314396039" rpy="0 0 0"/>      
      <mass value="0.0010254193609188259288"/>      
      <inertia ixx="3.252427873344092869e-08" ixy="2.969653368675063312e-39" ixz="0" iyy="3.2524278732748128531e-08" iyz="0" izz="6.0814076151188739369e-08"/>      
    </inertial>    
  </link>  

  <link name="right_leg_xm430">    
    <visual>      
      <origin xyz="0 0 0" rpy="0 -0 0"/>      
      <geometry>        
        <mesh filename="package:///meshes/right_leg_xm430_visual.stl"/>        
      </geometry>      
      <material name="right_leg_xm430_material">        
        <color rgba="0.61568627450980395466 0.81176470588235294379 0.92941176470588238168 1.0"/>        
      </material>      
    </visual>    
    <collision>      
      <origin xyz="0 0 0" rpy="0 -0 0"/>      
      <geometry>        
        <mesh filename="package:///meshes/right_leg_xm430_collision.stl"/>        
      </geometry>      
    </collision>    
    <inertial>      
      <origin xyz="-3.4240348394677165561e-19 -5.835633680043676131e-19 -0.0098919667346054479529" rpy="0 0 0"/>      
      <mass value="0.01799999999999999864"/>      
      <inertia ixx="2.6483505271519540317e-06" ixy="-4.0452811467303668408e-36" ixz="2.3281858238444292523e-36" iyy="7.705535799600823457e-06" iyz="-1.3548592298978518399e-36" izz="7.7736682806805358371e-06"/>      
    </inertial>    
  </link>  

  <joint name="right_leg_fixed" type="fixed">    
    <origin xyz="-4.336808689942017736e-19 6.9388939039072283776e-18 0.004999999999999997502" rpy="3.1415926535897904515 8.3266726857062000968e-16 -7.4940054151664101128e-16"/>    
    <parent link="spur_gear_21_teeth_2"/>    
    <child link="right_leg_xm430"/>    
    <axis xyz="0 0 1"/>    
    <limit effort="1" velocity="20"/>    
    <joint_properties friction="0.0"/>    
  </joint>  

  <joint name="right_hip_yaw_driven" type="revolute">    
    <origin xyz="0.037000000000000005107 0.041099999999999997646 -0.019500000000000003442" rpy="-1.5707963267948943376 -1.5707963267948945596 0"/>    
    <parent link="waist_link"/>    
    <child link="spur_gear_21_teeth_2"/>    
    <axis xyz="0 0 1"/>    
    <limit effort="1" velocity="20" lower="-1.570796326794896558" upper="1.570796326794896558"/>    
    <joint_properties friction="0.0"/>    
  </joint>  

  <joint name="waist_roll" type="revolute">    
    <origin xyz="-0.022707865260693019943 -1.1379796490832543078e-16 -0.013999999999999696715" rpy="-1.570796326794896558 5.9153252221758794299e-15 1.5707963267948923392"/>    
    <parent link="waist_gears"/>    
    <child link="waist_link"/>    
    <axis xyz="0 0 1"/>    
    <limit effort="1" velocity="20" lower="-0.52359877559829881566" upper="0.52359877559829881566"/>    
    <joint_properties friction="0.0"/>    
  </joint>  

  <joint name="waist_yaw" type="revolute">    
    <origin xyz="0 3.3155877990083308985e-18 -2.2531839605375149692e-29" rpy="1.5032209321489623492e-16 -4.1376224834056962518e-15 3.1415926535897917837"/>    
    <parent link="torso"/>    
    <child link="waist_gears"/>    
    <axis xyz="0 0 1"/>    
    <limit effort="1" velocity="20" lower="-1.570796326794896558" upper="1.570796326794896558"/>    
    <joint_properties friction="0.0"/>    
  </joint>  

  <link name="left_arm_hand">    
    <visual>      
      <origin xyz="0 0 0" rpy="0 -0 0"/>      
      <geometry>        
        <mesh filename="package:///meshes/left_arm_hand_visual.stl"/>        
      </geometry>      
      <material name="left_arm_hand_material">        
        <color rgba="0.61568627450980395466 0.81176470588235294379 0.9294117647058824927 1.0"/>        
      </material>      
    </visual>    
    <collision>      
      <origin xyz="0 0 0" rpy="0 -0 0"/>      
      <geometry>        
        <mesh filename="package:///meshes/left_arm_hand_collision.stl"/>        
      </geometry>      
    </collision>    
    <inertial>      
      <origin xyz="5.8254248144644345452e-11 -5.1264642561120335549e-05 0.0082440788127094884186" rpy="0 0 0"/>      
      <mass value="0.0085999999999999930667"/>      
      <inertia ixx="1.2272887040545787638e-06" ixy="-2.1429944204251825117e-14" ixz="-8.5847198664662112122e-15" iyy="2.9107306060364598912e-06" iyz="7.4623841398182670419e-09" izz="3.0803135950773470752e-06"/>      
    </inertial>    
  </link>  

  <joint name="left_sho_pitch" type="revolute">    
    <origin xyz="-0.0035000000000004693156 0.067000000000001086464 0.104236510762817286" rpy="-1.5707963267949081043 -4.127643409825574977e-14 3.4723733359249779961e-14"/>    
    <parent link="torso"/>    
    <child link="left_arm_hand"/>    
    <axis xyz="0 0 1"/>    
    <limit effort="1" velocity="20" lower="-3.141592653589793116" upper="1.570796326794896558"/>    
    <joint_properties friction="0.0"/>    
  </joint>  

  <link name="right_arm_hand">    
    <visual>      
      <origin xyz="0 0 0" rpy="0 -0 0"/>      
      <geometry>        
        <mesh filename="package:///meshes/right_arm_hand_visual.stl"/>        
      </geometry>      
      <material name="right_arm_hand_material">        
        <color rgba="0.61568627450980395466 0.81176470588235294379 0.9294117647058824927 1.0"/>        
      </material>      
    </visual>    
    <collision>      
      <origin xyz="0 0 0" rpy="0 -0 0"/>      
      <geometry>        
        <mesh filename="package:///meshes/right_arm_hand_collision.stl"/>        
      </geometry>      
    </collision>    
    <inertial>      
      <origin xyz="5.8254248144644345452e-11 -5.1264642561120335549e-05 0.0082440788127094884186" rpy="0 0 0"/>      
      <mass value="0.0085999999999999930667"/>      
      <inertia ixx="1.2272887040545787638e-06" ixy="-2.1429944204251825117e-14" ixz="-8.5847198664662112122e-15" iyy="2.9107306060364598912e-06" iyz="7.4623841398182670419e-09" izz="3.0803135950773470752e-06"/>      
    </inertial>    
  </link>  

  <joint name="right_sho_pitch" type="revolute">    
    <origin xyz="-0.003499999999998689923 -0.067000000000001030953 0.10423651076281729988" rpy="-1.5707963267948885644 3.4812325502379109658e-14 -3.1415926535897562566"/>    
    <parent link="torso"/>    
    <child link="right_arm_hand"/>    
    <axis xyz="0 0 1"/>    
    <limit effort="1" velocity="20" lower="-1.570796326794896558" upper="3.141592653589793116"/>    
    <joint_properties friction="0.0"/>    
  </joint>  


</robot>