<?xml version="1.0" ?><robot name="toddlerbot">  
  <link name="torso">    
    <visual>      
      <origin xyz="0 0 0" rpy="0 -0 0"/>      
      <geometry>        
        <mesh filename="package:///meshes/torso_visual.stl"/>        
      </geometry>      
      <material name="torso_material">        
        <color rgba="0.58602628355191022091 0.73205173766587605666 0.84624015779321404285 1.0"/>        
      </material>      
    </visual>    
    <collision>      
      <origin xyz="0 0 0" rpy="0 -0 0"/>      
      <geometry>        
        <mesh filename="package:///meshes/torso_collision.stl"/>        
      </geometry>      
    </collision>    
    <inertial>      
      <origin xyz="-0.0074328354797873951929 0.0025059801105640597436 0.073401015491149051995" rpy="0 0 0"/>      
      <mass value="0.5849052174992360742"/>      
      <inertia ixx="0.001616819104734650665" ixy="-1.4736281865313569496e-05" ixz="3.2221053182212498246e-07" iyy="0.001310156579434457267" iyz="2.4169833425786298821e-05" izz="0.0011896913602930953707"/>      
    </inertial>    
  </link>  

  <link name="spur_1m_20t">    
    <visual>      
      <origin xyz="0 0 0" rpy="0 -0 0"/>      
      <geometry>        
        <mesh filename="package:///meshes/spur_1m_20t_visual.stl"/>        
      </geometry>      
      <material name="spur_1m_20t_material">        
        <color rgba="0.64705882352941179736 0.64705882352941179736 0.64705882352941179736 1.0"/>        
      </material>      
    </visual>    
    <collision>      
      <origin xyz="0 0 0" rpy="0 -0 0"/>      
      <geometry>        
        <mesh filename="package:///meshes/spur_1m_20t_collision.stl"/>        
      </geometry>      
    </collision>    
    <inertial>      
      <origin xyz="-5.3890758640437683033e-18 5.8683689274605119589e-18 -0.0033745971730663147647" rpy="0 0 0"/>      
      <mass value="0.0015534950290892286448"/>      
      <inertia ixx="4.4726508287871799621e-08" ixy="5.2024693257554525847e-24" ixz="2.7597381312606821682e-39" iyy="4.4726508287871786386e-08" iyz="-4.880475641083095171e-38" izz="7.9558906764902006609e-08"/>      
    </inertial>    
  </link>  

  <joint name="neck_yaw_drive" type="revolute">    
    <origin xyz="-0.004999999999999059884 -1.8020791195763170554e-16 0.12248651076281816263" rpy="-3.1415926535897913396 1.7995135580561967136e-15 9.6455933634066887197e-16"/>    
    <parent link="torso"/>    
    <child link="spur_1m_20t"/>    
    <axis xyz="0 0 1"/>    
    <limit effort="1" velocity="20" lower="-3.141592653589793116" upper="3.141592653589793116"/>    
    <joint_properties friction="0.0"/>    
  </joint>  

  <link name="neck_yaw_link">    
    <visual>      
      <origin xyz="0 0 0" rpy="0 -0 0"/>      
      <geometry>        
        <mesh filename="package:///meshes/neck_yaw_link_visual.stl"/>        
      </geometry>      
      <material name="neck_yaw_link_material">        
        <color rgba="0.33636252417476664167 0.48680769190259887136 0.74976123534949801197 1.0"/>        
      </material>      
    </visual>    
    <collision>      
      <origin xyz="0 0 0" rpy="0 -0 0"/>      
      <geometry>        
        <mesh filename="package:///meshes/neck_yaw_link_collision.stl"/>        
      </geometry>      
    </collision>    
    <inertial>      
      <origin xyz="2.7291286461155648901e-05 0.00019798992283532579318 -0.011527412037194841726" rpy="0 0 0"/>      
      <mass value="0.0085168305947458250449"/>      
      <inertia ixx="1.0407116999274142848e-06" ixy="-2.4210150466643223747e-11" ixz="4.7246803218799873965e-10" iyy="1.1240009954110278886e-06" iyz="3.0834841754638146793e-08" izz="3.1587565167291907172e-07"/>      
    </inertial>    
  </link>  

  <link name="neck_pitch_link">    
    <visual>      
      <origin xyz="0 0 0" rpy="0 -0 0"/>      
      <geometry>        
        <mesh filename="package:///meshes/neck_pitch_link_visual.stl"/>        
      </geometry>      
      <material name="neck_pitch_link_material">        
        <color rgba="0.74911126277760042846 0.80002799398726853752 0.87441258869524285391 1.0"/>        
      </material>      
    </visual>    
    <collision>      
      <origin xyz="0 0 0" rpy="0 -0 0"/>      
      <geometry>        
        <mesh filename="package:///meshes/neck_pitch_link_collision.stl"/>        
      </geometry>      
    </collision>    
    <inertial>      
      <origin xyz="-0.003437049761571804498 -0.032876793988991417916 0.00036476492134716469217" rpy="0 0 0"/>      
      <mass value="0.11211553874797881847"/>      
      <inertia ixx="7.7015755459849957677e-05" ixy="2.1757968319820868784e-06" ixz="2.8732209413521026174e-06" iyy="6.3502636688155217164e-05" iyz="-1.2492352737635673663e-05" izz="2.8610002383974706596e-05"/>      
    </inertial>    
  </link>  

  <link name="spur_gear_(13_teeth)">    
    <visual>      
      <origin xyz="0 0 0" rpy="0 -0 0"/>      
      <geometry>        
        <mesh filename="package:///meshes/spur_gear_(13_teeth)_visual.stl"/>        
      </geometry>      
      <material name="spur_gear_(13_teeth)_material">        
        <color rgba="0.64705882352941179736 0.64705882352941179736 0.64705882352941179736 1.0"/>        
      </material>      
    </visual>    
    <collision>      
      <origin xyz="0 0 0" rpy="0 -0 0"/>      
      <geometry>        
        <mesh filename="package:///meshes/spur_gear_(13_teeth)_collision.stl"/>        
      </geometry>      
    </collision>    
    <inertial>      
      <origin xyz="1.0399873341600411655e-09 2.3905206815959089847e-10 -0.0092751511485596356554" rpy="0 0 0"/>      
      <mass value="0.00081469437497230855032"/>      
      <inertia ixx="2.0244839552178298687e-08" ixy="-2.9046301772392211175e-15" ixz="8.2976066069498047887e-15" iyy="2.0244841689973771385e-08" iyz="-1.3142117784749194552e-15" izz="1.8905472907863310999e-08"/>      
    </inertial>    
  </link>  

  <joint name="neck_pitch_drive" type="revolute">    
    <origin xyz="-1.4571677198205179593e-16 -0.015650000000000330314 0.0087999999999993777644" rpy="-2.1434555572207676319e-16 -1.5880065549567459396e-15 1.570796326794896558"/>    
    <parent link="neck_pitch_link"/>    
    <child link="spur_gear_(13_teeth)"/>    
    <axis xyz="0 0 1"/>    
    <limit effort="1" velocity="20" lower="-1.570796326794896558" upper="1.570796326794896558"/>    
    <joint_properties friction="0.0"/>    
  </joint>  

  <joint name="neck_pitch_driven" type="revolute">    
    <origin xyz="3.7500078736707465055e-10 0.0051500000614755261225 -0.027499999999999941158" rpy="1.570796326794896558 7.3154045537456631165e-17 -3.141592653589793116"/>    
    <parent link="neck_yaw_link"/>    
    <child link="neck_pitch_link"/>    
    <axis xyz="0 0 1"/>    
    <limit effort="1" velocity="20" lower="-1.570796326794896558" upper="1.570796326794896558"/>    
    <joint_properties friction="0.0"/>    
  </joint>  

  <joint name="neck_yaw_driven" type="revolute">    
    <origin xyz="0.016000000000001915468 1.75992996990887874e-17 0.12348651076281796923" rpy="3.141592653589793116 -1.8665960714277032613e-15 -3.141592653589793116"/>    
    <parent link="torso"/>    
    <child link="neck_yaw_link"/>    
    <axis xyz="0 0 1"/>    
    <limit effort="1" velocity="20" lower="-3.141592653589793116" upper="3.141592653589793116"/>    
    <joint_properties friction="0.0"/>    
  </joint>  

  <link name="waist_gears">    
    <visual>      
      <origin xyz="0 0 0" rpy="0 -0 0"/>      
      <geometry>        
        <mesh filename="package:///meshes/waist_gears_visual.stl"/>        
      </geometry>      
      <material name="waist_gears_material">        
        <color rgba="0.2705751638183052088 0.53648836590125015267 0.70305495274644791426 1.0"/>        
      </material>      
    </visual>    
    <collision>      
      <origin xyz="0 0 0" rpy="0 -0 0"/>      
      <geometry>        
        <mesh filename="package:///meshes/waist_gears_collision.stl"/>        
      </geometry>      
    </collision>    
    <inertial>      
      <origin xyz="6.5469454461777740587e-08 5.6785896935447445789e-10 0.012726165583898670086" rpy="0 0 0"/>      
      <mass value="0.023315805669179824611"/>      
      <inertia ixx="6.9043104388291792625e-06" ixy="1.8428638770370908087e-11" ixz="-9.9668712552151659918e-13" iyy="1.1624091971676391391e-06" iyz="-3.3260430299263522616e-10" izz="6.8701920560919723979e-06"/>      
    </inertial>    
  </link>  

  <link name="waist_link">    
    <visual>      
      <origin xyz="0 0 0" rpy="0 -0 0"/>      
      <geometry>        
        <mesh filename="package:///meshes/waist_link_visual.stl"/>        
      </geometry>      
      <material name="waist_link_material">        
        <color rgba="0.63401200025306059249 0.68204699127249923674 0.6691019398503622595 1.0"/>        
      </material>      
    </visual>    
    <collision>      
      <origin xyz="0 0 0" rpy="0 -0 0"/>      
      <geometry>        
        <mesh filename="package:///meshes/waist_link_collision.stl"/>        
      </geometry>      
    </collision>    
    <inertial>      
      <origin xyz="-9.1086191307873980818e-07 0.026204483755308483062 -0.030190392008842579369" rpy="0 0 0"/>      
      <mass value="0.16631953490612461088"/>      
      <inertia ixx="6.8622997376114865196e-05" ixy="-6.1328048292105499562e-10" ixz="-3.678679202726610035e-06" iyy="0.00020057117429216598744" iyz="-3.7255079147360503126e-06" izz="0.00015770127977213013195"/>      
    </inertial>    
  </link>  

  <link name="spiral_bevel_1m_14t_30deg">    
    <visual>      
      <origin xyz="0 0 0" rpy="0 -0 0"/>      
      <geometry>        
        <mesh filename="package:///meshes/spiral_bevel_1m_14t_30deg_visual.stl"/>        
      </geometry>      
      <material name="spiral_bevel_1m_14t_30deg_material">        
        <color rgba="0.64705882352941179736 0.64705882352941179736 0.64705882352941179736 1.0"/>        
      </material>      
    </visual>    
    <collision>      
      <origin xyz="0 0 0" rpy="0 -0 0"/>      
      <geometry>        
        <mesh filename="package:///meshes/spiral_bevel_1m_14t_30deg_collision.stl"/>        
      </geometry>      
    </collision>    
    <inertial>      
      <origin xyz="8.2641075406508779366e-10 3.4055789742068460039e-10 0.0068612577407481598057" rpy="0 0 0"/>      
      <mass value="0.00067997563436136235649"/>      
      <inertia ixx="1.2174575798018973838e-08" ixy="3.8216074570373192531e-18" ixz="4.7204547840164412653e-16" iyy="1.2174575801813732727e-08" iyz="-2.6184097788467663355e-16" izz="1.3178653206314315019e-08"/>      
    </inertial>    
  </link>  

  <joint name="waist_act_1" type="revolute">    
    <origin xyz="-6.2837407918937052528e-16 0.01959999999999966977 -0.012749999999999159575" rpy="1.570796326794896558 1.570796326794493103 0"/>    
    <parent link="waist_link"/>    
    <child link="spiral_bevel_1m_14t_30deg"/>    
    <axis xyz="0 0 1"/>    
    <limit effort="1" velocity="20" lower="-2.7925268031909271649" upper="2.7925268031909271649"/>    
    <joint_properties friction="0.0"/>    
  </joint>  

  <link name="spiral_bevel_1m_14t_30deg_2">    
    <visual>      
      <origin xyz="0 0 0" rpy="0 -0 0"/>      
      <geometry>        
        <mesh filename="package:///meshes/spiral_bevel_1m_14t_30deg_2_visual.stl"/>        
      </geometry>      
      <material name="spiral_bevel_1m_14t_30deg_2_material">        
        <color rgba="0.64705882352941179736 0.64705882352941179736 0.64705882352941179736 1.0"/>        
      </material>      
    </visual>    
    <collision>      
      <origin xyz="0 0 0" rpy="0 -0 0"/>      
      <geometry>        
        <mesh filename="package:///meshes/spiral_bevel_1m_14t_30deg_2_collision.stl"/>        
      </geometry>      
    </collision>    
    <inertial>      
      <origin xyz="7.2990964834762639413e-10 5.159130923874479157e-10 0.0068612577407481667446" rpy="0 0 0"/>      
      <mass value="0.00067997563436136235649"/>      
      <inertia ixx="1.2174575796548746326e-08" ixy="2.6199065386911604042e-18" ixz="5.1847541165558655682e-16" iyy="1.2174575803283978437e-08" iyz="-1.5023607716950052919e-16" izz="1.3178653206314315019e-08"/>      
    </inertial>    
  </link>  

  <joint name="waist_act_2" type="revolute">    
    <origin xyz="1.7857132216672699403e-18 0.019600000000000002837 -0.03275000000000001521" rpy="1.5707963267948883423 1.3463968515392001901 -8.4737581302220905773e-15"/>    
    <parent link="waist_link"/>    
    <child link="spiral_bevel_1m_14t_30deg_2"/>    
    <axis xyz="0 0 1"/>    
    <limit effort="1" velocity="20" lower="-2.7925268031909271649" upper="2.7925268031909271649"/>    
    <joint_properties friction="0.0"/>    
  </joint>  

  <link name="spur_gear_19_teeth">    
    <visual>      
      <origin xyz="0 0 0" rpy="0 -0 0"/>      
      <geometry>        
        <mesh filename="package:///meshes/spur_gear_19_teeth_visual.stl"/>        
      </geometry>      
      <material name="spur_gear_19_teeth_material">        
        <color rgba="0.61568627450980395466 0.81176470588235294379 0.92941176470588238168 1.0"/>        
      </material>      
    </visual>    
    <collision>      
      <origin xyz="0 0 0" rpy="0 -0 0"/>      
      <geometry>        
        <mesh filename="package:///meshes/spur_gear_19_teeth_collision.stl"/>        
      </geometry>      
    </collision>    
    <inertial>      
      <origin xyz="-4.9156135418512965894e-09 9.0060873697348523604e-10 -0.0045295192537419875708" rpy="0 0 0"/>      
      <mass value="0.0010993711450650533144"/>      
      <inertia ixx="2.9215018435433095279e-08" ixy="2.590331374580708277e-16" ixz="-8.4242612452402814292e-15" iyy="2.921502154003405516e-08" iyz="1.5226232385810775537e-15" izz="4.5709977027671374883e-08"/>      
    </inertial>    
  </link>  

  <joint name="left_hip_yaw_drive" type="revolute">    
    <origin xyz="-0.0369999999999981663 0.037100000000004268452 -0.039500000000001450617" rpy="1.5707963267947455677 -6.8515340787203273188e-13 -2.5801190558218208173e-13"/>    
    <parent link="waist_link"/>    
    <child link="spur_gear_19_teeth"/>    
    <axis xyz="0 0 1"/>    
    <limit effort="1" velocity="20" lower="-1.570796326794896558" upper="1.570796326794896558"/>    
    <joint_properties friction="0.0"/>    
  </joint>  

  <link name="spur_gear_21_teeth">    
    <visual>      
      <origin xyz="0 0 0" rpy="0 -0 0"/>      
      <geometry>        
        <mesh filename="package:///meshes/spur_gear_21_teeth_visual.stl"/>        
      </geometry>      
      <material name="spur_gear_21_teeth_material">        
        <color rgba="0.61568627450980395466 0.81176470588235294379 0.92941176470588238168 1.0"/>        
      </material>      
    </visual>    
    <collision>      
      <origin xyz="0 0 0" rpy="0 -0 0"/>      
      <geometry>        
        <mesh filename="package:///meshes/spur_gear_21_teeth_collision.stl"/>        
      </geometry>      
    </collision>    
    <inertial>      
      <origin xyz="-4.7814841807291116546e-10 1.261015606518316409e-12 -0.0024944618616143296973" rpy="0 0 0"/>      
      <mass value="0.0010063046528317972673"/>      
      <inertia ixx="3.1842855421068488283e-08" ixy="2.3102497982291840404e-37" ixz="3.9865261597844170004e-39" iyy="3.1842855426953792314e-08" iyz="8.4454990525371346054e-39" izz="5.9529380586728047984e-08"/>      
    </inertial>    
  </link>  

  <link name="left_leg_xm430">    
    <visual>      
      <origin xyz="0 0 0" rpy="0 -0 0"/>      
      <geometry>        
        <mesh filename="package:///meshes/left_leg_xm430_visual.stl"/>        
      </geometry>      
      <material name="left_leg_xm430_material">        
        <color rgba="0.66383680736315153759 0.67022570765366251688 0.54700842102268187883 1.0"/>        
      </material>      
    </visual>    
    <collision>      
      <origin xyz="0 0 0" rpy="0 -0 0"/>      
      <geometry>        
        <mesh filename="package:///meshes/left_leg_xm430_collision.stl"/>        
      </geometry>      
    </collision>    
    <inertial>      
      <origin xyz="-0.00068596312001988784569 0.0015532308536411719175 -0.11693678766568851857" rpy="0 0 0"/>      
      <mass value="0.38011498201789889473"/>      
      <inertia ixx="0.0024437861054827560853" ixy="-5.5640993855425138097e-07" ixz="-4.580139809972952992e-05" iyy="0.0024604659707488426429" iyz="-1.98883990117179908e-05" izz="0.00010747836274467605631"/>      
    </inertial>    
  </link>  

  <joint name="left_leg_fixed" type="fixed">    
    <origin xyz="-4.336808689942017736e-19 0 -0.004999999999999997502" rpy="3.9256239966020548641e-16 6.0371007920787862203e-16 5.9674487573614440696e-16"/>    
    <parent link="spur_gear_21_teeth"/>    
    <child link="left_leg_xm430"/>    
    <axis xyz="0 0 1"/>    
    <limit effort="1" velocity="20"/>    
    <joint_properties friction="0.0"/>    
  </joint>  

  <joint name="left_hip_yaw_driven" type="revolute">    
    <origin xyz="-0.03699999999999998429 0.041100000000000011524 -0.019499999999999999972" rpy="1.5707963267948956698 -1.5707963267948861219 0"/>    
    <parent link="waist_link"/>    
    <child link="spur_gear_21_teeth"/>    
    <axis xyz="0 0 1"/>    
    <limit effort="1" velocity="20" lower="-1.570796326794896558" upper="1.570796326794896558"/>    
    <joint_properties friction="0.0"/>    
  </joint>  

  <link name="spur_gear_19_teeth_2">    
    <visual>      
      <origin xyz="0 0 0" rpy="0 -0 0"/>      
      <geometry>        
        <mesh filename="package:///meshes/spur_gear_19_teeth_2_visual.stl"/>        
      </geometry>      
      <material name="spur_gear_19_teeth_2_material">        
        <color rgba="0.61568627450980395466 0.81176470588235294379 0.92941176470588238168 1.0"/>        
      </material>      
    </visual>    
    <collision>      
      <origin xyz="0 0 0" rpy="0 -0 0"/>      
      <geometry>        
        <mesh filename="package:///meshes/spur_gear_19_teeth_2_collision.stl"/>        
      </geometry>      
    </collision>    
    <inertial>      
      <origin xyz="-4.9156135418512965894e-09 9.0060873697348523604e-10 -0.0045295192537419945097" rpy="0 0 0"/>      
      <mass value="0.0010993711450650533144"/>      
      <inertia ixx="2.9215018435433095279e-08" ixy="2.5903313731232818381e-16" ixz="-8.4242612452402814292e-15" iyy="2.9215021540034061777e-08" iyz="1.5226232385810777509e-15" izz="4.5709977027671374883e-08"/>      
    </inertial>    
  </link>  

  <joint name="right_hip_yaw_drive" type="revolute">    
    <origin xyz="0.037000000000000601852 0.037100000000004115797 -0.039499999999999833855" rpy="1.5707963267948861219 -4.0933607639229270295e-13 -3.6944432958726287967e-13"/>    
    <parent link="waist_link"/>    
    <child link="spur_gear_19_teeth_2"/>    
    <axis xyz="0 0 1"/>    
    <limit effort="1" velocity="20" lower="-1.570796326794896558" upper="1.570796326794896558"/>    
    <joint_properties friction="0.0"/>    
  </joint>  

  <link name="spur_gear_21_teeth_2">    
    <visual>      
      <origin xyz="0 0 0" rpy="0 -0 0"/>      
      <geometry>        
        <mesh filename="package:///meshes/spur_gear_21_teeth_2_visual.stl"/>        
      </geometry>      
      <material name="spur_gear_21_teeth_2_material">        
        <color rgba="0.61568627450980395466 0.81176470588235294379 0.92941176470588238168 1.0"/>        
      </material>      
    </visual>    
    <collision>      
      <origin xyz="0 0 0" rpy="0 -0 0"/>      
      <geometry>        
        <mesh filename="package:///meshes/spur_gear_21_teeth_2_collision.stl"/>        
      </geometry>      
    </collision>    
    <inertial>      
      <origin xyz="-4.7814841763923029646e-10 -1.2610156065183166109e-12 -0.0025055381383856678047" rpy="0 0 0"/>      
      <mass value="0.0010063046528317972673"/>      
      <inertia ixx="3.1842855421068488283e-08" ixy="2.8197916970140418123e-36" ixz="-5.1368559626832086278e-40" iyy="3.1842855426953805549e-08" iyz="-1.6564068439911513797e-37" izz="5.9529380586728047984e-08"/>      
    </inertial>    
  </link>  

  <link name="right_leg_xm430">    
    <visual>      
      <origin xyz="0 0 0" rpy="0 -0 0"/>      
      <geometry>        
        <mesh filename="package:///meshes/right_leg_xm430_visual.stl"/>        
      </geometry>      
      <material name="right_leg_xm430_material">        
        <color rgba="0.66383680736315164861 0.67022570765366262791 0.54700842102268187883 1.0"/>        
      </material>      
    </visual>    
    <collision>      
      <origin xyz="0 0 0" rpy="0 -0 0"/>      
      <geometry>        
        <mesh filename="package:///meshes/right_leg_xm430_collision.stl"/>        
      </geometry>      
    </collision>    
    <inertial>      
      <origin xyz="-0.00097398523736316180641 -0.0015532198367556766805 -0.11693679110428019385" rpy="0 0 0"/>      
      <mass value="0.38011498201789883922"/>      
      <inertia ixx="0.0024437931671718740936" ixy="1.8173357803152018554e-06" ixz="-3.7053958518276868103e-05" iyy="0.0024602973424229048795" iyz="1.9891472297055539774e-05" izz="0.00010730275605749191911"/>      
    </inertial>    
  </link>  

  <joint name="right_leg_fixed" type="fixed">    
    <origin xyz="4.336808689942017736e-19 -6.9388939039072283776e-18 -0.0050000000000000044409" rpy="-4.6198149465961399771e-14 1.8953383221571858275e-31 2.6475889041157274137e-29"/>    
    <parent link="spur_gear_21_teeth_2"/>    
    <child link="right_leg_xm430"/>    
    <axis xyz="0 0 1"/>    
    <limit effort="1" velocity="20"/>    
    <joint_properties friction="0.0"/>    
  </joint>  

  <joint name="right_hip_yaw_driven" type="revolute">    
    <origin xyz="0.036999999999999998168 0.041100000000000011524 -0.01950000000000001385" rpy="1.5707963267949343056 -1.5707963267948712449 0"/>    
    <parent link="waist_link"/>    
    <child link="spur_gear_21_teeth_2"/>    
    <axis xyz="0 0 1"/>    
    <limit effort="1" velocity="20" lower="-1.570796326794896558" upper="1.570796326794896558"/>    
    <joint_properties friction="0.0"/>    
  </joint>  

  <joint name="waist_roll" type="revolute">    
    <origin xyz="4.3613235720115761641e-19 -0.022707865260692444015 0.013000000000000013281" rpy="1.570796326794896558 -2.3897582906932224823e-15 2.1266135278953062992e-16"/>    
    <parent link="waist_gears"/>    
    <child link="waist_link"/>    
    <axis xyz="0 0 1"/>    
    <limit effort="1" velocity="20" lower="-0.52359877559829881566" upper="0.52359877559829881566"/>    
    <joint_properties friction="0.0"/>    
  </joint>  

  <joint name="waist_yaw" type="revolute">    
    <origin xyz="-7.6501305290577192864e-16 -3.9884543972351746136e-15 -7.771561172376095783e-16" rpy="-3.1415926535897922278 -2.0665189604238262613e-16 -1.5707963267945077579"/>    
    <parent link="torso"/>    
    <child link="waist_gears"/>    
    <axis xyz="0 0 1"/>    
    <limit effort="1" velocity="20" lower="-1.570796326794896558" upper="1.570796326794896558"/>    
    <joint_properties friction="0.0"/>    
  </joint>  

  <link name="left_arm_hand">    
    <visual>      
      <origin xyz="0 0 0" rpy="0 -0 0"/>      
      <geometry>        
        <mesh filename="package:///meshes/left_arm_hand_visual.stl"/>        
      </geometry>      
      <material name="left_arm_hand_material">        
        <color rgba="0.72329282556618290645 0.84007822047190727766 0.90963032034360469247 1.0"/>        
      </material>      
    </visual>    
    <collision>      
      <origin xyz="0 0 0" rpy="0 -0 0"/>      
      <geometry>        
        <mesh filename="package:///meshes/left_arm_hand_collision.stl"/>        
      </geometry>      
    </collision>    
    <inertial>      
      <origin xyz="-0.00066047240157889584335 0.090373334068669999852 0.033439749977265842418" rpy="0 0 0"/>      
      <mass value="0.43420014698257952679"/>      
      <inertia ixx="0.002069424183657272813" ixy="9.826043875572944568e-06" ixz="9.8094532376426473296e-08" iyy="0.0001410773184035605751" iyz="0.00010237892223595592518" izz="0.0020501949018751223011"/>      
    </inertial>    
  </link>  

  <joint name="left_sho_pitch" type="revolute">    
    <origin xyz="-0.0029999999999997528644 0.062000000000000436706 0.10523651076281793915" rpy="-1.5707963267948983344 6.3108872417680944433e-30 -1.215300360748803713e-15"/>    
    <parent link="torso"/>    
    <child link="left_arm_hand"/>    
    <axis xyz="0 0 1"/>    
    <limit effort="1" velocity="20" lower="-1.570796326794896558" upper="1.570796326794896558"/>    
    <joint_properties friction="0.0"/>    
  </joint>  

  <link name="right_arm_hand">    
    <visual>      
      <origin xyz="0 0 0" rpy="0 -0 0"/>      
      <geometry>        
        <mesh filename="package:///meshes/right_arm_hand_visual.stl"/>        
      </geometry>      
      <material name="right_arm_hand_material">        
        <color rgba="0.72329282556618279543 0.84007822047190716663 0.90963032034360458145 1.0"/>        
      </material>      
    </visual>    
    <collision>      
      <origin xyz="0 0 0" rpy="0 -0 0"/>      
      <geometry>        
        <mesh filename="package:///meshes/right_arm_hand_collision.stl"/>        
      </geometry>      
    </collision>    
    <inertial>      
      <origin xyz="0.0001724911930217580948 0.090373334068664323837 0.033195753424943560961" rpy="0 0 0"/>      
      <mass value="0.4342001469825795823"/>      
      <inertia ixx="0.002070762830924093717" ixy="-2.1597507841786005349e-05" ixz="2.2892499013958109785e-06" iyy="0.00014259246491477221386" iyz="0.00010954853687151533176" izz="0.0020503714011189150442"/>      
    </inertial>    
  </link>  

  <joint name="right_sho_pitch" type="revolute">    
    <origin xyz="-0.0030000000000001275646 -0.061999999999999985678 0.10523651076281731465" rpy="-1.570796326794896558 -9.4663308626521416649e-30 3.1415926535897922278"/>    
    <parent link="torso"/>    
    <child link="right_arm_hand"/>    
    <axis xyz="0 0 1"/>    
    <limit effort="1" velocity="20" lower="-1.570796326794896558" upper="1.570796326794896558"/>    
    <joint_properties friction="0.0"/>    
  </joint>  


</robot>