<?xml version="1.0" ?><robot name="toddlerbot">  
  <link name="torso">    
    <visual>      
      <origin xyz="0 0 0" rpy="0 -0 0"/>      
      <geometry>        
        <mesh filename="package:///meshes/torso_visual.stl"/>        
      </geometry>      
      <material name="torso_material">        
        <color rgba="0.6818034357231282927 0.83942766095864118636 0.9302832428780117846 1.0"/>        
      </material>      
    </visual>    
    <collision>      
      <origin xyz="0 0 0" rpy="0 -0 0"/>      
      <geometry>        
        <mesh filename="package:///meshes/torso_collision.stl"/>        
      </geometry>      
    </collision>    
    <inertial>      
      <origin xyz="-0.0036253061535589164652 -0.0037247127431361075865 0.060214681647539410048" rpy="0 0 0"/>      
      <mass value="0.69674983343590768392"/>      
      <inertia ixx="0.0011862872525882138617" ixy="4.1829863011680777011e-05" ixz="0.00011921057579198400327" iyy="0.0011646734298373570809" iyz="-2.8296972418690330984e-05" izz="0.0010680621296118237087"/>      
    </inertial>    
  </link>  

  <link name="spur_1m_20t">    
    <visual>      
      <origin xyz="0 0 0" rpy="0 -0 0"/>      
      <geometry>        
        <mesh filename="package:///meshes/spur_1m_20t_visual.stl"/>        
      </geometry>      
      <material name="spur_1m_20t_material">        
        <color rgba="0.64705882352941179736 0.64705882352941179736 0.64705882352941179736 1.0"/>        
      </material>      
    </visual>    
    <collision>      
      <origin xyz="0 0 0" rpy="0 -0 0"/>      
      <geometry>        
        <mesh filename="package:///meshes/spur_1m_20t_collision.stl"/>        
      </geometry>      
    </collision>    
    <inertial>      
      <origin xyz="-5.5432586839091055883e-18 6.2309630063133807115e-18 -0.0033745971730663147647" rpy="0 0 0"/>      
      <mass value="0.0015534950290892286448"/>      
      <inertia ixx="4.4726508287871826091e-08" ixy="4.3152578044168224931e-24" ixz="7.3322813375464709564e-39" iyy="4.4726508287871786386e-08" iyz="1.0092019468807148883e-38" izz="7.9558906764902019844e-08"/>      
    </inertial>    
  </link>  

  <joint name="neck_yaw_drive" type="revolute">    
    <origin xyz="-0.0050000000000004034273 -1.6379685402262321054e-17 0.1190000000000009106" rpy="-3.1415926535897922278 -5.7160964521679751328e-16 1.1468819124646444987e-16"/>    
    <parent link="torso"/>    
    <child link="spur_1m_20t"/>    
    <axis xyz="0 0 1"/>    
    <limit effort="1" velocity="20" lower="-3.141592653589793116" upper="3.141592653589793116"/>    
    <joint_properties friction="0.0"/>    
  </joint>  

  <link name="neck_yaw_link">    
    <visual>      
      <origin xyz="0 0 0" rpy="0 -0 0"/>      
      <geometry>        
        <mesh filename="package:///meshes/neck_yaw_link_visual.stl"/>        
      </geometry>      
      <material name="neck_yaw_link_material">        
        <color rgba="0.31014785498775915284 0.45714061885145945707 0.734149387704831069 1.0"/>        
      </material>      
    </visual>    
    <collision>      
      <origin xyz="0 0 0" rpy="0 -0 0"/>      
      <geometry>        
        <mesh filename="package:///meshes/neck_yaw_link_collision.stl"/>        
      </geometry>      
    </collision>    
    <inertial>      
      <origin xyz="-7.9154796387197032494e-07 0.00019896819490732760576 -0.011558954971798755806" rpy="0 0 0"/>      
      <mass value="0.0083399357899977735048"/>      
      <inertia ixx="1.0832465864829039312e-06" ixy="-2.2575766070645705703e-11" ixz="7.6344518622829961063e-11" iyy="1.125697684063039942e-06" iyz="3.0881661804819100891e-08" izz="2.7889697026704133394e-07"/>      
    </inertial>    
  </link>  

  <link name="neck_pitch_link">    
    <visual>      
      <origin xyz="0 0 0" rpy="0 -0 0"/>      
      <geometry>        
        <mesh filename="package:///meshes/neck_pitch_link_visual.stl"/>        
      </geometry>      
      <material name="neck_pitch_link_material">        
        <color rgba="0.7501270961334514098 0.8024902260959719813 0.88158435622526620801 1.0"/>        
      </material>      
    </visual>    
    <collision>      
      <origin xyz="0 0 0" rpy="0 -0 0"/>      
      <geometry>        
        <mesh filename="package:///meshes/neck_pitch_link_collision.stl"/>        
      </geometry>      
    </collision>    
    <inertial>      
      <origin xyz="-0.0033218208080305960603 -0.033249902621750405951 -0.00010622123998355442992" rpy="0 0 0"/>      
      <mass value="0.10983356517090181459"/>      
      <inertia ixx="7.5469799513683087774e-05" ixy="1.9294938710883902318e-06" ixz="2.6762695218025526846e-06" iyy="6.2384952064286312845e-05" iyz="-1.1596137026767107004e-05" izz="2.7649846975442898063e-05"/>      
    </inertial>    
  </link>  

  <link name="spur_gear_(13_teeth)">    
    <visual>      
      <origin xyz="0 0 0" rpy="0 -0 0"/>      
      <geometry>        
        <mesh filename="package:///meshes/spur_gear_(13_teeth)_visual.stl"/>        
      </geometry>      
      <material name="spur_gear_(13_teeth)_material">        
        <color rgba="0.64705882352941179736 0.64705882352941179736 0.64705882352941179736 1.0"/>        
      </material>      
    </visual>    
    <collision>      
      <origin xyz="0 0 0" rpy="0 -0 0"/>      
      <geometry>        
        <mesh filename="package:///meshes/spur_gear_(13_teeth)_collision.stl"/>        
      </geometry>      
    </collision>    
    <inertial>      
      <origin xyz="1.0399873618082905103e-09 2.3905206827617440609e-10 -0.0092751511485596339207" rpy="0 0 0"/>      
      <mass value="0.00081469437497230865874"/>      
      <inertia ixx="2.0244839552178305304e-08" ixy="-2.9046301772494053117e-15" ixz="8.2976066070669616771e-15" iyy="2.0244841689973774694e-08" iyz="-1.3142117784934752386e-15" izz="1.8905472907863310999e-08"/>      
    </inertial>    
  </link>  

  <joint name="neck_pitch_drive" type="revolute">    
    <origin xyz="7.8756445809347042086e-16 -0.01565000000000016378 0.0088000000000000751232" rpy="-4.0745469014326526366e-16 -2.3702869945998008583e-15 1.5707963267948961139"/>    
    <parent link="neck_pitch_link"/>    
    <child link="spur_gear_(13_teeth)"/>    
    <axis xyz="0 0 1"/>    
    <limit effort="1" velocity="20" lower="-1.570796326794896558" upper="1.570796326794896558"/>    
    <joint_properties friction="0.0"/>    
  </joint>  

  <joint name="neck_pitch_driven" type="revolute">    
    <origin xyz="9.0205620750793968909e-16 0.0050500000000000683231 -0.027400000000000382383" rpy="1.5707963267948952257 -4.5338833253354086122e-17 -3.141592653589793116"/>    
    <parent link="neck_yaw_link"/>    
    <child link="neck_pitch_link"/>    
    <axis xyz="0 0 1"/>    
    <limit effort="1" velocity="20" lower="-1.570796326794896558" upper="1.570796326794896558"/>    
    <joint_properties friction="0.0"/>    
  </joint>  

  <joint name="neck_yaw_driven" type="revolute">    
    <origin xyz="0.015999999999999660327 -2.181319053771458285e-17 0.12000000000000014821" rpy="-3.1415926535897922278 -8.5689205541652391364e-16 3.1415926535897922278"/>    
    <parent link="torso"/>    
    <child link="neck_yaw_link"/>    
    <axis xyz="0 0 1"/>    
    <limit effort="1" velocity="20" lower="-3.141592653589793116" upper="3.141592653589793116"/>    
    <joint_properties friction="0.0"/>    
  </joint>  

  <link name="waist_gears">    
    <visual>      
      <origin xyz="0 0 0" rpy="0 -0 0"/>      
      <geometry>        
        <mesh filename="package:///meshes/waist_gears_visual.stl"/>        
      </geometry>      
      <material name="waist_gears_material">        
        <color rgba="0.37671615293068444474 0.59901087845022393807 0.73825508826546337726 1.0"/>        
      </material>      
    </visual>    
    <collision>      
      <origin xyz="0 0 0" rpy="0 -0 0"/>      
      <geometry>        
        <mesh filename="package:///meshes/waist_gears_collision.stl"/>        
      </geometry>      
    </collision>    
    <inertial>      
      <origin xyz="-5.4737436723536955447e-08 4.7479897656332207666e-10 -0.013842543430851915465" rpy="0 0 0"/>      
      <mass value="0.027890812659386823857"/>      
      <inertia ixx="8.194072324720986833e-06" ixy="-1.8428638625882401113e-11" ixz="-4.6116459597017341551e-12" iyy="2.4381774297629505045e-06" iyz="3.3263565429293591944e-10" izz="7.8287576287166995014e-06"/>      
    </inertial>    
  </link>  

  <link name="waist_link">    
    <visual>      
      <origin xyz="0 0 0" rpy="0 -0 0"/>      
      <geometry>        
        <mesh filename="package:///meshes/waist_link_visual.stl"/>        
      </geometry>      
      <material name="waist_link_material">        
        <color rgba="0.63022248767317301521 0.6784213077281454618 0.66908168998627304269 1.0"/>        
      </material>      
    </visual>    
    <collision>      
      <origin xyz="0 0 0" rpy="0 -0 0"/>      
      <geometry>        
        <mesh filename="package:///meshes/waist_link_collision.stl"/>        
      </geometry>      
    </collision>    
    <inertial>      
      <origin xyz="-8.539113746055305752e-07 -0.026303601291073619439 0.029957462336345819925" rpy="0 0 0"/>      
      <mass value="0.14790901863438235542"/>      
      <inertia ixx="6.1321382050894180813e-05" ixy="5.937447385914579109e-10" ixz="3.1801330093347631357e-06" iyy="0.00017955283611677442688" iyz="-3.3269315329635100345e-06" izz="0.00014139999285076818589"/>      
    </inertial>    
  </link>  

  <link name="spiral_bevel_1m_14t_30deg">    
    <visual>      
      <origin xyz="0 0 0" rpy="0 -0 0"/>      
      <geometry>        
        <mesh filename="package:///meshes/spiral_bevel_1m_14t_30deg_visual.stl"/>        
      </geometry>      
      <material name="spiral_bevel_1m_14t_30deg_material">        
        <color rgba="0.64705882352941179736 0.64705882352941179736 0.64705882352941179736 1.0"/>        
      </material>      
    </visual>    
    <collision>      
      <origin xyz="0 0 0" rpy="0 -0 0"/>      
      <geometry>        
        <mesh filename="package:///meshes/spiral_bevel_1m_14t_30deg_collision.stl"/>        
      </geometry>      
    </collision>    
    <inertial>      
      <origin xyz="8.2641075059564084171e-10 3.4055789785436552108e-10 0.0068612577407481632752" rpy="0 0 0"/>      
      <mass value="0.00067997563436136246491"/>      
      <inertia ixx="1.2174575798018972184e-08" ixy="3.8216075412375150261e-18" ixz="4.720454784945167209e-16" iyy="1.2174575801813740999e-08" iyz="-2.6184097746259488058e-16" izz="1.3178653206314315019e-08"/>      
    </inertial>    
  </link>  

  <joint name="waist_act_1" type="revolute">    
    <origin xyz="-1.5932779411205202199e-17 -0.019599999999999999367 0.012750000000000021733" rpy="-1.570796326794896558 -1.570796326794896558 0"/>    
    <parent link="waist_link"/>    
    <child link="spiral_bevel_1m_14t_30deg"/>    
    <axis xyz="0 0 1"/>    
    <limit effort="1" velocity="20" lower="-6.283185307179586232" upper="6.283185307179586232"/>    
    <joint_properties friction="0.0"/>    
  </joint>  

  <link name="spiral_bevel_1m_14t_30deg_2">    
    <visual>      
      <origin xyz="0 0 0" rpy="0 -0 0"/>      
      <geometry>        
        <mesh filename="package:///meshes/spiral_bevel_1m_14t_30deg_2_visual.stl"/>        
      </geometry>      
      <material name="spiral_bevel_1m_14t_30deg_2_material">        
        <color rgba="0.64705882352941179736 0.64705882352941179736 0.64705882352941179736 1.0"/>        
      </material>      
    </visual>    
    <collision>      
      <origin xyz="0 0 0" rpy="0 -0 0"/>      
      <geometry>        
        <mesh filename="package:///meshes/spiral_bevel_1m_14t_30deg_2_collision.stl"/>        
      </geometry>      
    </collision>    
    <inertial>      
      <origin xyz="7.2990964487817954557e-10 5.159130924029311858e-10 0.0068612577407481598057" rpy="0 0 0"/>      
      <mass value="0.00067997563436136246491"/>      
      <inertia ixx="1.2174575796548744672e-08" ixy="2.6199065843345791949e-18" ixz="5.1847541157803837439e-16" iyy="1.2174575803283978437e-08" iyz="-1.5023607673965559605e-16" izz="1.3178653206314318328e-08"/>      
    </inertial>    
  </link>  

  <joint name="waist_act_2" type="revolute">    
    <origin xyz="4.6517265723957437313e-17 -0.019600000000000006306 0.032750000000000022149" rpy="-1.5707963267948883423 -1.3463968515392308323 -7.0941368479903392883e-15"/>    
    <parent link="waist_link"/>    
    <child link="spiral_bevel_1m_14t_30deg_2"/>    
    <axis xyz="0 0 1"/>    
    <limit effort="1" velocity="20" lower="-6.283185307179586232" upper="6.283185307179586232"/>    
    <joint_properties friction="0.0"/>    
  </joint>  

  <link name="spur_gear_19_teeth">    
    <visual>      
      <origin xyz="0 0 0" rpy="0 -0 0"/>      
      <geometry>        
        <mesh filename="package:///meshes/spur_gear_19_teeth_visual.stl"/>        
      </geometry>      
      <material name="spur_gear_19_teeth_material">        
        <color rgba="0.61568627450980395466 0.81176470588235294379 0.92941176470588238168 1.0"/>        
      </material>      
    </visual>    
    <collision>      
      <origin xyz="0 0 0" rpy="0 -0 0"/>      
      <geometry>        
        <mesh filename="package:///meshes/spur_gear_19_teeth_collision.stl"/>        
      </geometry>      
    </collision>    
    <inertial>      
      <origin xyz="-4.9156135419839192842e-09 9.0060873703862953499e-10 -0.0045295192537419858361" rpy="0 0 0"/>      
      <mass value="0.0010993711450650533144"/>      
      <inertia ixx="2.9215018435433075427e-08" ixy="2.5903313716941079595e-16" ixz="-8.4242612452429162247e-15" iyy="2.9215021540034065086e-08" iyz="1.5226232384499183841e-15" izz="4.5709977027671394736e-08"/>      
    </inertial>    
  </link>  

  <joint name="left_hip_yaw_drive" type="revolute">    
    <origin xyz="-0.036999999999999082234 -0.037100000000004428047 0.039500000000000479172" rpy="-1.5707963267950366681 5.151402335645982677e-13 2.7395991650844820822e-13"/>    
    <parent link="waist_link"/>    
    <child link="spur_gear_19_teeth"/>    
    <axis xyz="0 0 1"/>    
    <limit effort="1" velocity="20" lower="-1.570796326794896558" upper="1.570796326794896558"/>    
    <joint_properties friction="0.0"/>    
  </joint>  

  <link name="spur_gear_21_teeth">    
    <visual>      
      <origin xyz="0 0 0" rpy="0 -0 0"/>      
      <geometry>        
        <mesh filename="package:///meshes/spur_gear_21_teeth_visual.stl"/>        
      </geometry>      
      <material name="spur_gear_21_teeth_material">        
        <color rgba="0.61568627450980395466 0.81176470588235294379 0.92941176470588238168 1.0"/>        
      </material>      
    </visual>    
    <collision>      
      <origin xyz="0 0 0" rpy="0 -0 0"/>      
      <geometry>        
        <mesh filename="package:///meshes/spur_gear_21_teeth_collision.stl"/>        
      </geometry>      
    </collision>    
    <inertial>      
      <origin xyz="-4.7814841765549008236e-10 1.2610155114531217991e-12 -0.0024944618616143370698" rpy="0 0 0"/>      
      <mass value="0.0010063046528317974842"/>      
      <inertia ixx="3.1842855421068481665e-08" ixy="4.460946188958470755e-37" ixz="4.1458682991372841656e-39" iyy="3.1842855426953798932e-08" iyz="2.4390428046167478637e-39" izz="5.9529380586728028132e-08"/>      
    </inertial>    
  </link>  

  <link name="left_leg">    
    <visual>      
      <origin xyz="0 0 0" rpy="0 -0 0"/>      
      <geometry>        
        <mesh filename="package:///meshes/left_leg_visual.stl"/>        
      </geometry>      
      <material name="left_leg_material">        
        <color rgba="0.58524786793638838844 0.68932274371067636665 0.74192474090382853902 1.0"/>        
      </material>      
    </visual>    
    <collision>      
      <origin xyz="0 0 0" rpy="0 -0 0"/>      
      <geometry>        
        <mesh filename="package:///meshes/left_leg_collision.stl"/>        
      </geometry>      
    </collision>    
    <inertial>      
      <origin xyz="-0.00057240627173089312502 0.0025583987890611067408 -0.10811412384984289692" rpy="0 0 0"/>      
      <mass value="0.33147421190722820006"/>      
      <inertia ixx="0.001962418829181020348" ixy="-2.9355551612295395554e-07" ixz="-2.9065494285768934951e-05" iyy="0.0019785859386950988004" iyz="-1.7310372949662013338e-05" izz="9.0568963194789610708e-05"/>      
    </inertial>    
  </link>  

  <joint name="left_leg_fixed" type="fixed">    
    <origin xyz="-4.336808689942017736e-19 0 -0.0050000000000000044409" rpy="1.6445178552343805731e-15 1.0304257450873186578e-15 -5.1391183078733626487e-17"/>    
    <parent link="spur_gear_21_teeth"/>    
    <child link="left_leg"/>    
    <axis xyz="0 0 1"/>    
    <limit effort="1" velocity="20"/>    
    <joint_properties friction="0.0"/>    
  </joint>  

  <joint name="left_hip_yaw_driven" type="revolute">    
    <origin xyz="-0.037000000000000005107 -0.041100000000000004585 0.019500000000000006911" rpy="-1.5707963267949003328 1.5707963267948015229 0"/>    
    <parent link="waist_link"/>    
    <child link="spur_gear_21_teeth"/>    
    <axis xyz="0 0 1"/>    
    <limit effort="1" velocity="20" lower="-1.570796326794896558" upper="1.570796326794896558"/>    
    <joint_properties friction="0.0"/>    
  </joint>  

  <link name="spur_gear_19_teeth_2">    
    <visual>      
      <origin xyz="0 0 0" rpy="0 -0 0"/>      
      <geometry>        
        <mesh filename="package:///meshes/spur_gear_19_teeth_2_visual.stl"/>        
      </geometry>      
      <material name="spur_gear_19_teeth_2_material">        
        <color rgba="0.61568627450980395466 0.81176470588235294379 0.92941176470588238168 1.0"/>        
      </material>      
    </visual>    
    <collision>      
      <origin xyz="0 0 0" rpy="0 -0 0"/>      
      <geometry>        
        <mesh filename="package:///meshes/spur_gear_19_teeth_2_collision.stl"/>        
      </geometry>      
    </collision>    
    <inertial>      
      <origin xyz="-4.9156135419839192842e-09 9.0060873703862953499e-10 -0.0045295192537419867035" rpy="0 0 0"/>      
      <mass value="0.0010993711450650533144"/>      
      <inertia ixx="2.9215018435433075427e-08" ixy="2.5903313716941079595e-16" ixz="-8.4242612452429146469e-15" iyy="2.9215021540034065086e-08" iyz="1.5226232384499179897e-15" izz="4.5709977027671368266e-08"/>      
    </inertial>    
  </link>  

  <joint name="right_hip_yaw_drive" type="revolute">    
    <origin xyz="0.037000000000000525524 -0.03710000000000365783 0.039500000000000125289" rpy="-1.5707963267950380004 3.2507852438900622217e-13 2.6634828451263301925e-13"/>    
    <parent link="waist_link"/>    
    <child link="spur_gear_19_teeth_2"/>    
    <axis xyz="0 0 1"/>    
    <limit effort="1" velocity="20" lower="-1.570796326794896558" upper="1.570796326794896558"/>    
    <joint_properties friction="0.0"/>    
  </joint>  

  <link name="spur_gear_21_teeth_2">    
    <visual>      
      <origin xyz="0 0 0" rpy="0 -0 0"/>      
      <geometry>        
        <mesh filename="package:///meshes/spur_gear_21_teeth_2_visual.stl"/>        
      </geometry>      
      <material name="spur_gear_21_teeth_2_material">        
        <color rgba="0.61568627450980395466 0.81176470588235294379 0.92941176470588238168 1.0"/>        
      </material>      
    </visual>    
    <collision>      
      <origin xyz="0 0 0" rpy="0 -0 0"/>      
      <geometry>        
        <mesh filename="package:///meshes/spur_gear_21_teeth_2_collision.stl"/>        
      </geometry>      
    </collision>    
    <inertial>      
      <origin xyz="-4.7814841722180921337e-10 -1.2610155114531215972e-12 -0.0025055381383856743099" rpy="0 0 0"/>      
      <mass value="0.0010063046528317974842"/>      
      <inertia ixx="3.1842855421068481665e-08" ixy="-9.9410077469375813982e-39" ixz="-1.2874656189276223701e-39" iyy="3.1842855426953785697e-08" iyz="3.5868299173178424635e-38" izz="5.9529380586728028132e-08"/>      
    </inertial>    
  </link>  

  <link name="right_leg">    
    <visual>      
      <origin xyz="0 0 0" rpy="0 -0 0"/>      
      <geometry>        
        <mesh filename="package:///meshes/right_leg_visual.stl"/>        
      </geometry>      
      <material name="right_leg_material">        
        <color rgba="0.58524785554304348256 0.68932269385703326403 0.74192466456634575955 1.0"/>        
      </material>      
    </visual>    
    <collision>      
      <origin xyz="0 0 0" rpy="0 -0 0"/>      
      <geometry>        
        <mesh filename="package:///meshes/right_leg_collision.stl"/>        
      </geometry>      
    </collision>    
    <inertial>      
      <origin xyz="0.00096126845696026632423 0.0025773080903913406225 -0.10812752502027726809" rpy="0 0 0"/>      
      <mass value="0.33147407694377267751"/>      
      <inertia ixx="0.0019625090540969320971" ixy="1.4193360568536144357e-06" ixz="2.1618728968103750789e-05" iyy="0.0019785512111179228908" iyz="-1.7464251664398651627e-05" izz="9.0358926703686055825e-05"/>      
    </inertial>    
  </link>  

  <joint name="right_leg_fixed" type="fixed">    
    <origin xyz="0 0 -0.0049999999999999905631" rpy="4.5102810376649177882e-17 3.1225022585831228531e-17 3.141592653589793116"/>    
    <parent link="spur_gear_21_teeth_2"/>    
    <child link="right_leg"/>    
    <axis xyz="0 0 1"/>    
    <limit effort="1" velocity="20"/>    
    <joint_properties friction="0.0"/>    
  </joint>  

  <joint name="right_hip_yaw_driven" type="revolute">    
    <origin xyz="0.036999999999999998168 -0.041099999999999997646 0.01950000000000001385" rpy="-1.570796326794896558 1.5707963267948898967 0"/>    
    <parent link="waist_link"/>    
    <child link="spur_gear_21_teeth_2"/>    
    <axis xyz="0 0 1"/>    
    <limit effort="1" velocity="20" lower="-1.570796326794896558" upper="1.570796326794896558"/>    
    <joint_properties friction="0.0"/>    
  </joint>  

  <joint name="waist_roll" type="revolute">    
    <origin xyz="3.3370324681271502984e-16 -0.022707865260692169929 -0.016486510762818328696" rpy="1.5707963267948943376 -7.3650913441789240746e-15 -3.141592653589793116"/>    
    <parent link="waist_gears"/>    
    <child link="waist_link"/>    
    <axis xyz="0 0 1"/>    
    <limit effort="1" velocity="20" lower="-0.52359877559829881566" upper="0.52359877559829881566"/>    
    <joint_properties friction="0.0"/>    
  </joint>  

  <joint name="waist_yaw" type="revolute">    
    <origin xyz="1.9721522630525295135e-31 0 3.4694469519536141888e-18" rpy="-4.710068554273424296e-16 7.1819243396509704024e-20 1.570796326794896558"/>    
    <parent link="torso"/>    
    <child link="waist_gears"/>    
    <axis xyz="0 0 1"/>    
    <limit effort="1" velocity="20" lower="-1.570796326794896558" upper="1.570796326794896558"/>    
    <joint_properties friction="0.0"/>    
  </joint>  

  <link name="left_arm">    
    <visual>      
      <origin xyz="0 0 0" rpy="0 -0 0"/>      
      <geometry>        
        <mesh filename="package:///meshes/left_arm_visual.stl"/>        
      </geometry>      
      <material name="left_arm_material">        
        <color rgba="0.77791740158427680196 0.69172775136194553092 0.37562289555352063042 1.0"/>        
      </material>      
    </visual>    
    <collision>      
      <origin xyz="0 0 0" rpy="0 -0 0"/>      
      <geometry>        
        <mesh filename="package:///meshes/left_arm_collision.stl"/>        
      </geometry>      
    </collision>    
    <inertial>      
      <origin xyz="-0.0042717125101533913109 0.040487114570970025862 -0.11097313729701395457" rpy="0 0 0"/>      
      <mass value="0.52463434800654151768"/>      
      <inertia ixx="0.0036330103547704798057" ixy="4.5316498449026043215e-05" ixz="-0.00014705580697217372917" iyy="0.003534021178409230135" iyz="0.00023859754067096519909" izz="0.00041008124580960169693"/>      
    </inertial>    
  </link>  

  <joint name="left_arm_fixed" type="fixed">    
    <origin xyz="0.00099999999999985040092 0.049000000000000022704 0.11600000000000017242" rpy="-1.9038884465842659478e-15 -3.5601304011234204199e-15 -7.7715611723737469496e-16"/>    
    <parent link="torso"/>    
    <child link="left_arm"/>    
    <axis xyz="0 0 1"/>    
    <limit effort="1" velocity="20"/>    
    <joint_properties friction="0.0"/>    
  </joint>  

  <link name="right_arm">    
    <visual>      
      <origin xyz="0 0 0" rpy="0 -0 0"/>      
      <geometry>        
        <mesh filename="package:///meshes/right_arm_visual.stl"/>        
      </geometry>      
      <material name="right_arm_material">        
        <color rgba="0.77791740158427680196 0.69172775136194553092 0.37562289555352057491 1.0"/>        
      </material>      
    </visual>    
    <collision>      
      <origin xyz="0 0 0" rpy="0 -0 0"/>      
      <geometry>        
        <mesh filename="package:///meshes/right_arm_collision.stl"/>        
      </geometry>      
    </collision>    
    <inertial>      
      <origin xyz="-0.0040863968243904985264 -0.039634810660789741854 -0.11097170424512531328" rpy="0 0 0"/>      
      <mass value="0.52463434800654151768"/>      
      <inertia ixx="0.0036302593847901375168" ixy="-2.9503425795122724016e-05" ixz="-0.00016505559992672315167" iyy="0.0035051533979753740113" iyz="-0.00019521147220785689405" izz="0.00037817162080345579668"/>      
    </inertial>    
  </link>  

  <joint name="right_arm_fixed" type="fixed">    
    <origin xyz="0.00099999999999963919833 -0.049000000000000078215 0.11600000000000071365" rpy="-6.4923497675071347722e-16 -2.3063737247115780209e-15 -8.326672684688632638e-16"/>    
    <parent link="torso"/>    
    <child link="right_arm"/>    
    <axis xyz="0 0 1"/>    
    <limit effort="1" velocity="20"/>    
    <joint_properties friction="0.0"/>    
  </joint>  


</robot>