<?xml version="1.0" ?><robot name="toddlerbot">  
  <link name="torso">    
    <visual>      
      <origin xyz="0 0 0" rpy="0 -0 0"/>      
      <geometry>        
        <mesh filename="package:///meshes/torso_visual.stl"/>        
      </geometry>      
      <material name="torso_material">        
        <color rgba="0.6197852121554117133 0.80497509985632864637 0.91238666069265517145 1.0"/>        
      </material>      
    </visual>    
    <collision>      
      <origin xyz="0 0 0" rpy="0 -0 0"/>      
      <geometry>        
        <mesh filename="package:///meshes/torso_collision.stl"/>        
      </geometry>      
    </collision>    
    <inertial>      
      <origin xyz="-0.017582789998871049819 -0.0008892412850613319944 0.066328103881054256696" rpy="0 0 0"/>      
      <mass value="0.38210896478125000453"/>      
      <inertia ixx="0.00097913100143531372858" ixy="1.368754266574914548e-05" ixz="5.3060955780646044695e-05" iyy="0.00088767318813584431599" iyz="-1.8064914536012927244e-05" izz="0.00068582374333484930409"/>      
    </inertial>    
  </link>  

  <link name="spur_1m_20t">    
    <visual>      
      <origin xyz="0 0 0" rpy="0 -0 0"/>      
      <geometry>        
        <mesh filename="package:///meshes/spur_1m_20t_visual.stl"/>        
      </geometry>      
      <material name="spur_1m_20t_material">        
        <color rgba="0.64705882352941179736 0.64705882352941179736 0.64705882352941179736 1.0"/>        
      </material>      
    </visual>    
    <collision>      
      <origin xyz="0 0 0" rpy="0 -0 0"/>      
      <geometry>        
        <mesh filename="package:///meshes/spur_1m_20t_collision.stl"/>        
      </geometry>      
    </collision>    
    <inertial>      
      <origin xyz="-5.0044775065590171545e-18 6.0502252725870090006e-18 -0.0033745971730663147647" rpy="0 0 0"/>      
      <mass value="0.0015534950290892286448"/>      
      <inertia ixx="4.4726508287871812856e-08" ixy="7.684011163414536344e-24" ixz="2.7597381312606821682e-39" iyy="4.4726508287871786386e-08" iyz="-4.880475641083095171e-38" izz="7.9558906764902006609e-08"/>      
    </inertial>    
  </link>  

  <joint name="neck_yaw_drive" type="revolute">    
    <origin xyz="-0.004999999999999059884 -1.8020791195763170554e-16 0.12248651076281816263" rpy="-3.1415926535897913396 1.7995135580561967136e-15 9.6455933634066887197e-16"/>    
    <parent link="torso"/>    
    <child link="spur_1m_20t"/>    
    <axis xyz="0 0 1"/>    
    <limit effort="1" velocity="20" lower="-3.141592653589793116" upper="3.141592653589793116"/>    
    <joint_properties friction="0.0"/>    
  </joint>  

  <link name="neck_yaw_link">    
    <visual>      
      <origin xyz="0 0 0" rpy="0 -0 0"/>      
      <geometry>        
        <mesh filename="package:///meshes/neck_yaw_link_visual.stl"/>        
      </geometry>      
      <material name="neck_yaw_link_material">        
        <color rgba="0.33636252417476664167 0.48680769190259887136 0.74976123534949801197 1.0"/>        
      </material>      
    </visual>    
    <collision>      
      <origin xyz="0 0 0" rpy="0 -0 0"/>      
      <geometry>        
        <mesh filename="package:///meshes/neck_yaw_link_collision.stl"/>        
      </geometry>      
    </collision>    
    <inertial>      
      <origin xyz="2.7291286461356290677e-05 0.00019798992283539515501 -0.0115274120371948504" rpy="0 0 0"/>      
      <mass value="0.0085168305947458250449"/>      
      <inertia ixx="1.0407116999274388487e-06" ixy="-2.4210150464746039776e-11" ixz="4.7246803220671246024e-10" iyy="1.1240009954110499114e-06" iyz="3.0834841754646676679e-08" izz="3.1587565167292060697e-07"/>      
    </inertial>    
  </link>  

  <link name="neck_pitch_link">    
    <visual>      
      <origin xyz="0 0 0" rpy="0 -0 0"/>      
      <geometry>        
        <mesh filename="package:///meshes/neck_pitch_link_visual.stl"/>        
      </geometry>      
      <material name="neck_pitch_link_material">        
        <color rgba="0.75175531149912766526 0.80237790269364195339 0.88100511756510224703 1.0"/>        
      </material>      
    </visual>    
    <collision>      
      <origin xyz="0 0 0" rpy="0 -0 0"/>      
      <geometry>        
        <mesh filename="package:///meshes/neck_pitch_link_collision.stl"/>        
      </geometry>      
    </collision>    
    <inertial>      
      <origin xyz="-0.0033208985050365335059 -0.033447827507434767236 -0.00017266927552015079862" rpy="0 0 0"/>      
      <mass value="0.10851928601941271402"/>      
      <inertia ixx="7.4643011916861726944e-05" ixy="1.9512994501134094261e-06" ixz="2.6631618432505370407e-06" iyy="6.1956827409922912795e-05" iyz="-1.1454163205103217525e-05" izz="2.701288336202765537e-05"/>      
    </inertial>    
  </link>  

  <link name="spur_gear_(13_teeth)">    
    <visual>      
      <origin xyz="0 0 0" rpy="0 -0 0"/>      
      <geometry>        
        <mesh filename="package:///meshes/spur_gear_(13_teeth)_visual.stl"/>        
      </geometry>      
      <material name="spur_gear_(13_teeth)_material">        
        <color rgba="0.64705882352941179736 0.64705882352941179736 0.64705882352941179736 1.0"/>        
      </material>      
    </visual>    
    <collision>      
      <origin xyz="0 0 0" rpy="0 -0 0"/>      
      <geometry>        
        <mesh filename="package:///meshes/spur_gear_(13_teeth)_collision.stl"/>        
      </geometry>      
    </collision>    
    <inertial>      
      <origin xyz="1.0399873342418501553e-09 2.3905206814663368286e-10 -0.0092751511485596373902" rpy="0 0 0"/>      
      <mass value="0.00081469437497230855032"/>      
      <inertia ixx="2.0244839552178295378e-08" ixy="-2.9046301764120405049e-15" ixz="8.297606606936787006e-15" iyy="2.0244841689973771385e-08" iyz="-1.31421177847285757e-15" izz="1.8905472907863310999e-08"/>      
    </inertial>    
  </link>  

  <joint name="neck_pitch_drive" type="revolute">    
    <origin xyz="-1.4571677198205179593e-16 -0.015650000000000330314 0.0087999999999993777644" rpy="-2.1434555572207676319e-16 -1.5880065549567459396e-15 1.570796326794896558"/>    
    <parent link="neck_pitch_link"/>    
    <child link="spur_gear_(13_teeth)"/>    
    <axis xyz="0 0 1"/>    
    <limit effort="1" velocity="20" lower="-1.570796326794896558" upper="1.570796326794896558"/>    
    <joint_properties friction="0.0"/>    
  </joint>  

  <joint name="neck_pitch_driven" type="revolute">    
    <origin xyz="3.7500073185592341929e-10 0.0051500000614755261225 -0.027499999999999941158" rpy="1.57079632679489678 -1.7934420258902467287e-15 -3.1415926535897922278"/>    
    <parent link="neck_yaw_link"/>    
    <child link="neck_pitch_link"/>    
    <axis xyz="0 0 1"/>    
    <limit effort="1" velocity="20" lower="-1.570796326794896558" upper="1.570796326794896558"/>    
    <joint_properties friction="0.0"/>    
  </joint>  

  <joint name="neck_yaw_driven" type="revolute">    
    <origin xyz="0.016000000000001915468 1.4752314067929367773e-17 0.12348651076281796923" rpy="-3.141592653589793116 -0 -3.1415926535897922278"/>    
    <parent link="torso"/>    
    <child link="neck_yaw_link"/>    
    <axis xyz="0 0 1"/>    
    <limit effort="1" velocity="20" lower="-3.141592653589793116" upper="3.141592653589793116"/>    
    <joint_properties friction="0.0"/>    
  </joint>  

  <link name="waist_gears">    
    <visual>      
      <origin xyz="0 0 0" rpy="0 -0 0"/>      
      <geometry>        
        <mesh filename="package:///meshes/waist_gears_visual.stl"/>        
      </geometry>      
      <material name="waist_gears_material">        
        <color rgba="0.2705751638183052088 0.53648836590125015267 0.70305495274644791426 1.0"/>        
      </material>      
    </visual>    
    <collision>      
      <origin xyz="0 0 0" rpy="0 -0 0"/>      
      <geometry>        
        <mesh filename="package:///meshes/waist_gears_collision.stl"/>        
      </geometry>      
    </collision>    
    <inertial>      
      <origin xyz="6.5469454462684754055e-08 -5.678589769108444202e-10 -0.012726165583898677025" rpy="0 0 0"/>      
      <mass value="0.023315805669179824611"/>      
      <inertia ixx="6.9043104388291928151e-06" ixy="-1.8428638769590440561e-11" ixz="9.9668712610669700131e-13" iyy="1.162409197167636598e-06" iyz="-3.3260430300288233958e-10" izz="6.8701920560919842564e-06"/>      
    </inertial>    
  </link>  

  <link name="waist_link">    
    <visual>      
      <origin xyz="0 0 0" rpy="0 -0 0"/>      
      <geometry>        
        <mesh filename="package:///meshes/waist_link_visual.stl"/>        
      </geometry>      
      <material name="waist_link_material">        
        <color rgba="0.63066856640767587905 0.67759035867951045162 0.66849819411858002471 1.0"/>        
      </material>      
    </visual>    
    <collision>      
      <origin xyz="0 0 0" rpy="0 -0 0"/>      
      <geometry>        
        <mesh filename="package:///meshes/waist_link_collision.stl"/>        
      </geometry>      
    </collision>    
    <inertial>      
      <origin xyz="-7.8326157945763225844e-07 -0.026309055188168648659 0.029773273854826105139" rpy="0 0 0"/>      
      <mass value="0.15193452399186058166"/>      
      <inertia ixx="6.3853955317574355379e-05" ixy="6.7244006990957541522e-10" ixz="3.1782521385896526105e-06" iyy="0.00018554067350207199979" iyz="-3.2622478832003394146e-06" izz="0.00014578323476960398171"/>      
    </inertial>    
  </link>  

  <link name="spiral_bevel_1m_14t_30deg">    
    <visual>      
      <origin xyz="0 0 0" rpy="0 -0 0"/>      
      <geometry>        
        <mesh filename="package:///meshes/spiral_bevel_1m_14t_30deg_visual.stl"/>        
      </geometry>      
      <material name="spiral_bevel_1m_14t_30deg_material">        
        <color rgba="0.64705882352941179736 0.64705882352941179736 0.64705882352941179736 1.0"/>        
      </material>      
    </visual>    
    <collision>      
      <origin xyz="0 0 0" rpy="0 -0 0"/>      
      <geometry>        
        <mesh filename="package:///meshes/spiral_bevel_1m_14t_30deg_collision.stl"/>        
      </geometry>      
    </collision>    
    <inertial>      
      <origin xyz="8.2641075233036431769e-10 3.4055789828804639008e-10 0.0068612577407481684794" rpy="0 0 0"/>      
      <mass value="0.00067997563436136235649"/>      
      <inertia ixx="1.2174575798018975493e-08" ixy="3.8216070047630807068e-18" ixz="4.7204547823421934484e-16" iyy="1.2174575801813732727e-08" iyz="-2.6184097732597935737e-16" izz="1.3178653206314311711e-08"/>      
    </inertial>    
  </link>  

  <joint name="waist_act_1" type="revolute">    
    <origin xyz="4.8392086706372466624e-17 -0.019600000000000009776 0.012750000000000042549" rpy="-1.5707963267948961139 -1.5707963267948215069 0"/>    
    <parent link="waist_link"/>    
    <child link="spiral_bevel_1m_14t_30deg"/>    
    <axis xyz="0 0 1"/>    
    <limit effort="1" velocity="20" lower="-2.7925268031909271649" upper="2.7925268031909271649"/>    
    <joint_properties friction="0.0"/>    
  </joint>  

  <link name="spiral_bevel_1m_14t_30deg_2">    
    <visual>      
      <origin xyz="0 0 0" rpy="0 -0 0"/>      
      <geometry>        
        <mesh filename="package:///meshes/spiral_bevel_1m_14t_30deg_2_visual.stl"/>        
      </geometry>      
      <material name="spiral_bevel_1m_14t_30deg_2_material">        
        <color rgba="0.64705882352941179736 0.64705882352941179736 0.64705882352941179736 1.0"/>        
      </material>      
    </visual>    
    <collision>      
      <origin xyz="0 0 0" rpy="0 -0 0"/>      
      <geometry>        
        <mesh filename="package:///meshes/spiral_bevel_1m_14t_30deg_2_collision.stl"/>        
      </geometry>      
    </collision>    
    <inertial>      
      <origin xyz="7.2990964661290291815e-10 5.1591309341166232978e-10 0.0068612577407481702141" rpy="0 0 0"/>      
      <mass value="0.00067997563436136235649"/>      
      <inertia ixx="1.2174575796548751289e-08" ixy="2.6199053407227811934e-18" ixz="5.1847541137723511287e-16" iyy="1.2174575803283978437e-08" iyz="-1.502360766603294444e-16" izz="1.3178653206314315019e-08"/>      
    </inertial>    
  </link>  

  <joint name="waist_act_2" type="revolute">    
    <origin xyz="-6.321225856846266752e-16 -0.019600000000000079164 0.032750000000000834" rpy="-1.5707963267948976682 -1.3463968515393018865 1.5503953316521244903e-14"/>    
    <parent link="waist_link"/>    
    <child link="spiral_bevel_1m_14t_30deg_2"/>    
    <axis xyz="0 0 1"/>    
    <limit effort="1" velocity="20" lower="-2.7925268031909271649" upper="2.7925268031909271649"/>    
    <joint_properties friction="0.0"/>    
  </joint>  

  <link name="spur_gear_19_teeth">    
    <visual>      
      <origin xyz="0 0 0" rpy="0 -0 0"/>      
      <geometry>        
        <mesh filename="package:///meshes/spur_gear_19_teeth_visual.stl"/>        
      </geometry>      
      <material name="spur_gear_19_teeth_material">        
        <color rgba="0.61568627450980395466 0.81176470588235294379 0.92941176470588238168 1.0"/>        
      </material>      
    </visual>    
    <collision>      
      <origin xyz="0 0 0" rpy="0 -0 0"/>      
      <geometry>        
        <mesh filename="package:///meshes/spur_gear_19_teeth_collision.stl"/>        
      </geometry>      
    </collision>    
    <inertial>      
      <origin xyz="-4.9156135348702214374e-09 9.0060874048927839393e-10 -0.0045295192537419945097" rpy="0 0 0"/>      
      <mass value="0.0010993711450650535313"/>      
      <inertia ixx="2.9215018435433082044e-08" ixy="2.5903313772733109345e-16" ixz="-8.424261245563750688e-15" iyy="2.9215021540034058468e-08" iyz="1.5226232384526170773e-15" izz="4.5709977027671368266e-08"/>      
    </inertial>    
  </link>  

  <joint name="left_hip_yaw_drive" type="revolute">    
    <origin xyz="-0.036999999999999179379 -0.037100000000004823564 0.039500000000000423661" rpy="-1.5707963267950579844 5.71102443800098102e-13 2.6906455702027046663e-13"/>    
    <parent link="waist_link"/>    
    <child link="spur_gear_19_teeth"/>    
    <axis xyz="0 0 1"/>    
    <limit effort="1" velocity="20" lower="-1.570796326794896558" upper="1.570796326794896558"/>    
    <joint_properties friction="0.0"/>    
  </joint>  

  <link name="spur_gear_21_teeth">    
    <visual>      
      <origin xyz="0 0 0" rpy="0 -0 0"/>      
      <geometry>        
        <mesh filename="package:///meshes/spur_gear_21_teeth_visual.stl"/>        
      </geometry>      
      <material name="spur_gear_21_teeth_material">        
        <color rgba="0.61568627450980395466 0.81176470588235294379 0.92941176470588238168 1.0"/>        
      </material>      
    </visual>    
    <collision>      
      <origin xyz="0 0 0" rpy="0 -0 0"/>      
      <geometry>        
        <mesh filename="package:///meshes/spur_gear_21_teeth_collision.stl"/>        
      </geometry>      
    </collision>    
    <inertial>      
      <origin xyz="-4.7814841733033882526e-10 1.2610017463689733481e-12 -0.0024944618616143366362" rpy="0 0 0"/>      
      <mass value="0.0010063046528317972673"/>      
      <inertia ixx="3.1842855421068488283e-08" ixy="2.1452075797961618719e-37" ixz="-1.1964366566353525762e-38" iyy="3.1842855426953779079e-08" iyz="1.1823805759556976152e-38" izz="5.9529380586728028132e-08"/>      
    </inertial>    
  </link>  

  <link name="left_leg_xm430">    
    <visual>      
      <origin xyz="0 0 0" rpy="0 -0 0"/>      
      <geometry>        
        <mesh filename="package:///meshes/left_leg_xm430_visual.stl"/>        
      </geometry>      
      <material name="left_leg_xm430_material">        
        <color rgba="0.57264277713291222849 0.65653380491540147545 0.69976527523230769301 1.0"/>        
      </material>      
    </visual>    
    <collision>      
      <origin xyz="0 0 0" rpy="0 -0 0"/>      
      <geometry>        
        <mesh filename="package:///meshes/left_leg_xm430_collision.stl"/>        
      </geometry>      
    </collision>    
    <inertial>      
      <origin xyz="-0.00081541414847775860793 0.00014645608381670988823 -0.12086628583540215409" rpy="0 0 0"/>      
      <mass value="0.28007018314906162448"/>      
      <inertia ixx="0.0023087531285643494647" ixy="-8.4819413465790262771e-08" ixz="-4.0318927115056657734e-05" iyy="0.002332498116263418287" iyz="-8.19540786227829549e-06" izz="8.6295030527309588789e-05"/>      
    </inertial>    
  </link>  

  <joint name="left_leg_fixed" type="fixed">    
    <origin xyz="3.0357660829594124152e-18 -1.3877787807814456755e-17 -0.0049999999999999697464" rpy="-1.0439449364097525548e-14 1.9685459861175557675e-31 1.834678230847674038e-29"/>    
    <parent link="spur_gear_21_teeth"/>    
    <child link="left_leg_xm430"/>    
    <axis xyz="0 0 1"/>    
    <limit effort="1" velocity="20"/>    
    <joint_properties friction="0.0"/>    
  </joint>  

  <joint name="left_hip_yaw_driven" type="revolute">    
    <origin xyz="-0.037000000000000005107 -0.041100000000000108669 0.019500000000000006911" rpy="-1.5707963267948841235 1.5707963267948932273 0"/>    
    <parent link="waist_link"/>    
    <child link="spur_gear_21_teeth"/>    
    <axis xyz="0 0 1"/>    
    <limit effort="1" velocity="20" lower="-1.570796326794896558" upper="1.570796326794896558"/>    
    <joint_properties friction="0.0"/>    
  </joint>  

  <link name="spur_gear_19_teeth_2">    
    <visual>      
      <origin xyz="0 0 0" rpy="0 -0 0"/>      
      <geometry>        
        <mesh filename="package:///meshes/spur_gear_19_teeth_2_visual.stl"/>        
      </geometry>      
      <material name="spur_gear_19_teeth_2_material">        
        <color rgba="0.61568627450980395466 0.81176470588235294379 0.92941176470588238168 1.0"/>        
      </material>      
    </visual>    
    <collision>      
      <origin xyz="0 0 0" rpy="0 -0 0"/>      
      <geometry>        
        <mesh filename="package:///meshes/spur_gear_19_teeth_2_collision.stl"/>        
      </geometry>      
    </collision>    
    <inertial>      
      <origin xyz="-4.9156135418091161685e-09 9.0060873701983133858e-10 -0.0045295192537419875708" rpy="0 0 0"/>      
      <mass value="0.0010993711450650535313"/>      
      <inertia ixx="2.9215018435433095279e-08" ixy="2.5903313731232818381e-16" ixz="-8.4242612455637522657e-15" iyy="2.9215021540034058468e-08" iyz="1.5226232384526170773e-15" izz="4.5709977027671368266e-08"/>      
    </inertial>    
  </link>  

  <joint name="right_hip_yaw_drive" type="revolute">    
    <origin xyz="0.037000000000000358991 -0.037100000000003852119 0.039500000000000062839" rpy="-1.5707963267949709429 3.0764921674346154011e-13 2.7727445053553844104e-13"/>    
    <parent link="waist_link"/>    
    <child link="spur_gear_19_teeth_2"/>    
    <axis xyz="0 0 1"/>    
    <limit effort="1" velocity="20" lower="-1.570796326794896558" upper="1.570796326794896558"/>    
    <joint_properties friction="0.0"/>    
  </joint>  

  <link name="spur_gear_21_teeth_2">    
    <visual>      
      <origin xyz="0 0 0" rpy="0 -0 0"/>      
      <geometry>        
        <mesh filename="package:///meshes/spur_gear_21_teeth_2_visual.stl"/>        
      </geometry>      
      <material name="spur_gear_21_teeth_2_material">        
        <color rgba="0.61568627450980395466 0.81176470588235294379 0.92941176470588238168 1.0"/>        
      </material>      
    </visual>    
    <collision>      
      <origin xyz="0 0 0" rpy="0 -0 0"/>      
      <geometry>        
        <mesh filename="package:///meshes/spur_gear_21_teeth_2_collision.stl"/>        
      </geometry>      
    </collision>    
    <inertial>      
      <origin xyz="-4.7814841733033882526e-10 -1.2610156241567811626e-12 -0.0025055381383856678047" rpy="0 0 0"/>      
      <mass value="0.0010063046528317972673"/>      
      <inertia ixx="3.1842855421068488283e-08" ixy="1.560614116831242474e-38" ixz="2.021036725007793052e-39" iyy="3.1842855426953779079e-08" iyz="5.2356557841516804612e-39" izz="5.9529380586728028132e-08"/>      
    </inertial>    
  </link>  

  <link name="right_leg_xm430">    
    <visual>      
      <origin xyz="0 0 0" rpy="0 -0 0"/>      
      <geometry>        
        <mesh filename="package:///meshes/right_leg_xm430_visual.stl"/>        
      </geometry>      
      <material name="right_leg_xm430_material">        
        <color rgba="0.57264277713291222849 0.65653380491540147545 0.69976527523230769301 1.0"/>        
      </material>      
    </visual>    
    <collision>      
      <origin xyz="0 0 0" rpy="0 -0 0"/>      
      <geometry>        
        <mesh filename="package:///meshes/right_leg_xm430_collision.stl"/>        
      </geometry>      
    </collision>    
    <inertial>      
      <origin xyz="-0.0011946391684647928409 -0.00014644113154792221627 -0.1208664872121804762" rpy="0 0 0"/>      
      <mass value="0.28007018314906162448"/>      
      <inertia ixx="0.0023087674697628052418" ixy="1.1609797994564864596e-06" ixz="-3.1427684529193998411e-05" iyy="0.0023322928455162855906" iyz="8.1991419149207978555e-06" izz="8.6075478345032480315e-05"/>      
    </inertial>    
  </link>  

  <joint name="right_leg_fixed" type="fixed">    
    <origin xyz="0 0 -0.004999999999999997502" rpy="1.0732181508787092545e-15 5.1822669723995480778e-16 -1.6653345369374924824e-16"/>    
    <parent link="spur_gear_21_teeth_2"/>    
    <child link="right_leg_xm430"/>    
    <axis xyz="0 0 1"/>    
    <limit effort="1" velocity="20"/>    
    <joint_properties friction="0.0"/>    
  </joint>  

  <joint name="right_hip_yaw_driven" type="revolute">    
    <origin xyz="0.037000000000000005107 -0.041100000000000011524 0.019500000000000010381" rpy="-1.5707963267948983344 1.5707963267948950037 0"/>    
    <parent link="waist_link"/>    
    <child link="spur_gear_21_teeth_2"/>    
    <axis xyz="0 0 1"/>    
    <limit effort="1" velocity="20" lower="-1.570796326794896558" upper="1.570796326794896558"/>    
    <joint_properties friction="0.0"/>    
  </joint>  

  <joint name="waist_roll" type="revolute">    
    <origin xyz="-6.2255683191263486807e-20 0.022707865260692461362 -0.013000000000000004607" rpy="1.5707963267948952257 1.2017992026080351615e-15 4.2181022606678868535e-16"/>    
    <parent link="waist_gears"/>    
    <child link="waist_link"/>    
    <axis xyz="0 0 1"/>    
    <limit effort="1" velocity="20" lower="-0.52359877559829881566" upper="0.52359877559829881566"/>    
    <joint_properties friction="0.0"/>    
  </joint>  

  <joint name="waist_yaw" type="revolute">    
    <origin xyz="-1.7347234759768070944e-18 -1.9721522630525295135e-31 0" rpy="2.0946901476030943553e-15 7.1861600448343401911e-16 -1.5707963267948228392"/>    
    <parent link="torso"/>    
    <child link="waist_gears"/>    
    <axis xyz="0 0 1"/>    
    <limit effort="1" velocity="20" lower="-1.570796326794896558" upper="1.570796326794896558"/>    
    <joint_properties friction="0.0"/>    
  </joint>  

  <link name="left_arm_hand">    
    <visual>      
      <origin xyz="0 0 0" rpy="0 -0 0"/>      
      <geometry>        
        <mesh filename="package:///meshes/left_arm_hand_visual.stl"/>        
      </geometry>      
      <material name="left_arm_hand_material">        
        <color rgba="0.78936869067351289608 0.6858108716285334916 0.33587667190439085552 1.0"/>        
      </material>      
    </visual>    
    <collision>      
      <origin xyz="0 0 0" rpy="0 -0 0"/>      
      <geometry>        
        <mesh filename="package:///meshes/left_arm_hand_collision.stl"/>        
      </geometry>      
    </collision>    
    <inertial>      
      <origin xyz="-0.0029339688854886397835 0.039176653017021299819 -0.092630607281791024765" rpy="0 0 0"/>      
      <mass value="0.47285924835363246643"/>      
      <inertia ixx="0.0025778889091026347194" ixy="3.6002415653747699869e-05" ixz="-7.1072500170699616701e-05" iyy="0.0024228562828973749382" iyz="0.00017055711301122459199" izz="0.00031178066840954174509"/>      
    </inertial>    
  </link>  

  <joint name="left_arm_fixed" type="fixed">    
    <origin xyz="0.0010000000000009051128 0.049000000000000341893 0.11948651076281792405" rpy="-5.9230088976703815107e-16 1.7322096859285544219e-15 1.6762794059802379347e-29"/>    
    <parent link="torso"/>    
    <child link="left_arm_hand"/>    
    <axis xyz="0 0 1"/>    
    <limit effort="1" velocity="20"/>    
    <joint_properties friction="0.0"/>    
  </joint>  

  <link name="right_arm_hand">    
    <visual>      
      <origin xyz="0 0 0" rpy="0 -0 0"/>      
      <geometry>        
        <mesh filename="package:///meshes/right_arm_hand_visual.stl"/>        
      </geometry>      
      <material name="right_arm_hand_material">        
        <color rgba="0.78936869067351289608 0.6858108716285334916 0.33587667190439085552 1.0"/>        
      </material>      
    </visual>    
    <collision>      
      <origin xyz="0 0 0" rpy="0 -0 0"/>      
      <geometry>        
        <mesh filename="package:///meshes/right_arm_hand_collision.stl"/>        
      </geometry>      
    </collision>    
    <inertial>      
      <origin xyz="-0.0025227522828371899341 -0.038971039253888881126 -0.092629017319775699968" rpy="0 0 0"/>      
      <mass value="0.47285924835363246643"/>      
      <inertia ixx="0.0025778266721206686586" ixy="-3.2238812185541028768e-05" ixz="-7.9542347472916181484e-05" iyy="0.0024224796144705247614" iyz="-0.00016286414549101781114" izz="0.0003111060503742621745"/>      
    </inertial>    
  </link>  

  <joint name="right_arm_fixed" type="fixed">    
    <origin xyz="0.0010000000000010308802 -0.049000000000000321076 0.11948651076281791017" rpy="-5.9230088976591895466e-16 1.732209685967738918e-15 1.6762794059934078982e-29"/>    
    <parent link="torso"/>    
    <child link="right_arm_hand"/>    
    <axis xyz="0 0 1"/>    
    <limit effort="1" velocity="20"/>    
    <joint_properties friction="0.0"/>    
  </joint>  


</robot>