<?xml version="1.0" ?><robot name="toddlerbot">  
  <link name="torso">    
    <visual>      
      <origin xyz="0 0 0" rpy="0 -0 0"/>      
      <geometry>        
        <mesh filename="package:///meshes/torso_visual.stl"/>        
      </geometry>      
      <material name="torso_material">        
        <color rgba="0.58602628355191022091 0.73205173766587616768 0.84624015779321404285 1.0"/>        
      </material>      
    </visual>    
    <collision>      
      <origin xyz="0 0 0" rpy="0 -0 0"/>      
      <geometry>        
        <mesh filename="package:///meshes/torso_collision.stl"/>        
      </geometry>      
    </collision>    
    <inertial>      
      <origin xyz="-0.0074328354797873830498 0.0025059801105640623457 0.073401015491149065872" rpy="0 0 0"/>      
      <mass value="0.58490521749923585215"/>      
      <inertia ixx="0.0016168191047346513155" ixy="-1.4736281865313549167e-05" ixz="3.2221053182213636447e-07" iyy="0.0013101565794344581344" iyz="2.4169833425786339478e-05" izz="0.0011896913602930955876"/>      
    </inertial>    
  </link>  

  <link name="spur_1m_20t">    
    <visual>      
      <origin xyz="0 0 0" rpy="0 -0 0"/>      
      <geometry>        
        <mesh filename="package:///meshes/spur_1m_20t_visual.stl"/>        
      </geometry>      
      <material name="spur_1m_20t_material">        
        <color rgba="0.64705882352941190838 0.64705882352941190838 0.64705882352941190838 1.0"/>        
      </material>      
    </visual>    
    <collision>      
      <origin xyz="0 0 0" rpy="0 -0 0"/>      
      <geometry>        
        <mesh filename="package:///meshes/spur_1m_20t_collision.stl"/>        
      </geometry>      
    </collision>    
    <inertial>      
      <origin xyz="-2.4334996767091156826e-18 -7.8538274165156240587e-18 0.0033745971730663251731" rpy="0 0 0"/>      
      <mass value="0.0015534950290892282111"/>      
      <inertia ixx="4.4726508287871799621e-08" ixy="2.6608965793107671434e-24" ixz="2.7597381312606834733e-39" iyy="4.4726508287871786386e-08" iyz="-1.7424300806353613314e-38" izz="7.9558906764902019844e-08"/>      
    </inertial>    
  </link>  

  <joint name="neck_yaw_drive" type="revolute">    
    <origin xyz="-0.0049999999999990590166 -1.7787571338323640394e-16 0.12248651076281813488" rpy="1.900955487881492792e-15 1.6770488781412432481e-15 9.8514697225632145493e-16"/>    
    <parent link="torso"/>    
    <child link="spur_1m_20t"/>    
    <axis xyz="0 0 1"/>    
    <limit effort="1" velocity="20" lower="-2.2689280275926284602" upper="2.2689280275926284602"/>    
    <joint_properties friction="0.0"/>    
  </joint>  

  <link name="neck_yaw_link">    
    <visual>      
      <origin xyz="0 0 0" rpy="0 -0 0"/>      
      <geometry>        
        <mesh filename="package:///meshes/neck_yaw_link_visual.stl"/>        
      </geometry>      
      <material name="neck_yaw_link_material">        
        <color rgba="0.33636252417476653065 0.48680769190259864931 0.74976123534949778993 1.0"/>        
      </material>      
    </visual>    
    <collision>      
      <origin xyz="0 0 0" rpy="0 -0 0"/>      
      <geometry>        
        <mesh filename="package:///meshes/neck_yaw_link_collision.stl"/>        
      </geometry>      
    </collision>    
    <inertial>      
      <origin xyz="2.7291286460608435124e-05 -0.00019798992283530681964 0.011527412037194878155" rpy="0 0 0"/>      
      <mass value="0.0085168305947458285143"/>      
      <inertia ixx="1.0407116999274151318e-06" ixy="2.4210150466155122562e-11" ixz="-4.7246803216687554533e-10" iyy="1.1240009954110308532e-06" iyz="3.083484175463602921e-08" izz="3.1587565167291864821e-07"/>      
    </inertial>    
  </link>  

  <link name="neck_pitch_link">    
    <visual>      
      <origin xyz="0 0 0" rpy="0 -0 0"/>      
      <geometry>        
        <mesh filename="package:///meshes/neck_pitch_link_visual.stl"/>        
      </geometry>      
      <material name="neck_pitch_link_material">        
        <color rgba="0.74911126277760042846 0.80002799398726853752 0.87441258869524285391 1.0"/>        
      </material>      
    </visual>    
    <collision>      
      <origin xyz="0 0 0" rpy="0 -0 0"/>      
      <geometry>        
        <mesh filename="package:///meshes/neck_pitch_link_collision.stl"/>        
      </geometry>      
    </collision>    
    <inertial>      
      <origin xyz="-0.0034370497615721063399 0.032876793988991494244 -0.0003647649213469508875" rpy="0 0 0"/>      
      <mass value="0.11211553874797881847"/>      
      <inertia ixx="7.7015755459850933459e-05" ixy="-2.1757968319823676698e-06" ixz="-2.8732209413522855765e-06" iyy="6.350263668815466151e-05" iyz="-1.2492352737635124786e-05" izz="2.861000238397491666e-05"/>      
    </inertial>    
  </link>  

  <link name="spur_gear_(13_teeth)">    
    <visual>      
      <origin xyz="0 0 0" rpy="0 -0 0"/>      
      <geometry>        
        <mesh filename="package:///meshes/spur_gear_(13_teeth)_visual.stl"/>        
      </geometry>      
      <material name="spur_gear_(13_teeth)_material">        
        <color rgba="0.64705882352941168634 0.64705882352941168634 0.64705882352941168634 1.0"/>        
      </material>      
    </visual>    
    <collision>      
      <origin xyz="0 0 0" rpy="0 -0 0"/>      
      <geometry>        
        <mesh filename="package:///meshes/spur_gear_(13_teeth)_collision.stl"/>        
      </geometry>      
    </collision>    
    <inertial>      
      <origin xyz="9.1521557941667763632e-10 -5.4872578397643168315e-10 0.0092751511485596356554" rpy="0 0 0"/>      
      <mass value="0.00081469437497230876716"/>      
      <inertia ixx="2.0244841463618394107e-08" ixy="2.9781775002671977054e-15" ixz="-8.2976066068196316953e-15" iyy="2.02448397785336892e-08" iyz="1.3142117784543017866e-15" izz="1.8905472907863310999e-08"/>      
    </inertial>    
  </link>  

  <joint name="neck_pitch_drive" type="revolute">    
    <origin xyz="-1.1692036228083679816e-15 0.01565000000000066338 -0.0087999999999981218246" rpy="1.2246467991513517459e-16 -6.1232339957502284403e-17 -1.5707963267949054398"/>    
    <parent link="neck_pitch_link"/>    
    <child link="spur_gear_(13_teeth)"/>    
    <axis xyz="0 0 1"/>    
    <limit effort="1" velocity="20" lower="-1.4279966607226330932" upper="1.4279966607226330932"/>    
    <joint_properties friction="0.0"/>    
  </joint>  

  <joint name="neck_pitch_driven" type="revolute">    
    <origin xyz="3.7499999980261655708e-10 -0.0051500000614753986203 0.027500000000000010547" rpy="1.570796326794896558 8.661048429666698261e-16 3.1415926535897926719"/>    
    <parent link="neck_yaw_link"/>    
    <child link="neck_pitch_link"/>    
    <axis xyz="0 0 1"/>    
    <limit effort="1" velocity="20" lower="-1.570796326794896558" upper="1.570796326794896558"/>    
    <joint_properties friction="0.0"/>    
  </joint>  

  <joint name="neck_yaw_driven" type="revolute">    
    <origin xyz="0.016000000000001790568 1.3355656282555062267e-17 0.12348651076281798311" rpy="5.2022234352156643924e-17 -1.693050922709124266e-15 -3.1415926535897926719"/>    
    <parent link="torso"/>    
    <child link="neck_yaw_link"/>    
    <axis xyz="0 0 1"/>    
    <limit effort="1" velocity="20" lower="-3.141592653589793116" upper="3.141592653589793116"/>    
    <joint_properties friction="0.0"/>    
  </joint>  

  <link name="waist_gears">    
    <visual>      
      <origin xyz="0 0 0" rpy="0 -0 0"/>      
      <geometry>        
        <mesh filename="package:///meshes/waist_gears_visual.stl"/>        
      </geometry>      
      <material name="waist_gears_material">        
        <color rgba="0.2705751638183052088 0.53648836590125015267 0.70305495274644791426 1.0"/>        
      </material>      
    </visual>    
    <collision>      
      <origin xyz="0 0 0" rpy="0 -0 0"/>      
      <geometry>        
        <mesh filename="package:///meshes/waist_gears_collision.stl"/>        
      </geometry>      
    </collision>    
    <inertial>      
      <origin xyz="6.546945447531986512e-08 5.678591623325374745e-10 0.012726165583898526104" rpy="0 0 0"/>      
      <mass value="0.023315805669179824611"/>      
      <inertia ixx="6.9043104388290759245e-06" ixy="1.8428638775971751246e-11" ixz="-9.9668712564048197337e-13" iyy="1.1624091971676541739e-06" iyz="-3.3260430305085550639e-10" izz="6.8701920560918665188e-06"/>      
    </inertial>    
  </link>  

  <link name="waist_link">    
    <visual>      
      <origin xyz="0 0 0" rpy="0 -0 0"/>      
      <geometry>        
        <mesh filename="package:///meshes/waist_link_visual.stl"/>        
      </geometry>      
      <material name="waist_link_material">        
        <color rgba="0.63401200025306070351 0.68204699127249923674 0.66910193985036237052 1.0"/>        
      </material>      
    </visual>    
    <collision>      
      <origin xyz="0 0 0" rpy="0 -0 0"/>      
      <geometry>        
        <mesh filename="package:///meshes/waist_link_collision.stl"/>        
      </geometry>      
    </collision>    
    <inertial>      
      <origin xyz="-9.1086191341836857393e-07 0.026204483755308718984 -0.030190392008842527327" rpy="0 0 0"/>      
      <mass value="0.16631953490612463864"/>      
      <inertia ixx="6.8622997376114526383e-05" ixy="-6.1328048361138684763e-10" ixz="-3.6786792027265986e-06" iyy="0.00020057117429216650244" iyz="-3.7255079147357470748e-06" izz="0.00015770127977213151431"/>      
    </inertial>    
  </link>  

  <link name="spiral_bevel_1m_14t_30deg">    
    <visual>      
      <origin xyz="0 0 0" rpy="0 -0 0"/>      
      <geometry>        
        <mesh filename="package:///meshes/spiral_bevel_1m_14t_30deg_visual.stl"/>        
      </geometry>      
      <material name="spiral_bevel_1m_14t_30deg_material">        
        <color rgba="0.64705882352941179736 0.64705882352941179736 0.64705882352941179736 1.0"/>        
      </material>      
    </visual>    
    <collision>      
      <origin xyz="0 0 0" rpy="0 -0 0"/>      
      <geometry>        
        <mesh filename="package:///meshes/spiral_bevel_1m_14t_30deg_collision.stl"/>        
      </geometry>      
    </collision>    
    <inertial>      
      <origin xyz="8.2641075059564084171e-10 3.4055789828804644178e-10 0.0068612577407481710814" rpy="0 0 0"/>      
      <mass value="0.00067997563436136246491"/>      
      <inertia ixx="1.2174575798018978801e-08" ixy="3.8216067208892337065e-18" ixz="4.7204547843348541229e-16" iyy="1.2174575801813734381e-08" iyz="-2.6184097792419969889e-16" izz="1.3178653206314315019e-08"/>      
    </inertial>    
  </link>  

  <joint name="waist_act_1" type="revolute">    
    <origin xyz="-5.4541005536440740413e-16 0.019599999999999950795 -0.012750000000000089387" rpy="1.5707963267948983344 1.5707963267948863439 0"/>    
    <parent link="waist_link"/>    
    <child link="spiral_bevel_1m_14t_30deg"/>    
    <axis xyz="0 0 1"/>    
    <limit effort="1" velocity="20" lower="-2.7825534678416246059" upper="2.7825534678416246059"/>    
    <joint_properties friction="0.0"/>    
  </joint>  

  <link name="spiral_bevel_1m_14t_30deg_2">    
    <visual>      
      <origin xyz="0 0 0" rpy="0 -0 0"/>      
      <geometry>        
        <mesh filename="package:///meshes/spiral_bevel_1m_14t_30deg_2_visual.stl"/>        
      </geometry>      
      <material name="spiral_bevel_1m_14t_30deg_2_material">        
        <color rgba="0.64705882352941179736 0.64705882352941179736 0.64705882352941179736 1.0"/>        
      </material>      
    </visual>    
    <collision>      
      <origin xyz="0 0 0" rpy="0 -0 0"/>      
      <geometry>        
        <mesh filename="package:///meshes/spiral_bevel_1m_14t_30deg_2_collision.stl"/>        
      </geometry>      
    </collision>    
    <inertial>      
      <origin xyz="7.2990964661290291815e-10 5.1591309311023058013e-10 0.0068612577407481684794" rpy="0 0 0"/>      
      <mass value="0.00067997563436136246491"/>      
      <inertia ixx="1.2174575796548744672e-08" ixy="2.619906587730623466e-18" ixz="5.184754117236686056e-16" iyy="1.2174575803283975128e-08" iyz="-1.5023607718873399344e-16" izz="1.3178653206314321637e-08"/>      
    </inertial>    
  </link>  

  <joint name="waist_act_2" type="revolute">    
    <origin xyz="-2.5130149897002749361e-16 0.019599999999999936917 -0.032749999999999550304" rpy="1.5707963267949001107 1.3463968515392203962 -1.4991504265429651005e-13"/>    
    <parent link="waist_link"/>    
    <child link="spiral_bevel_1m_14t_30deg_2"/>    
    <axis xyz="0 0 1"/>    
    <limit effort="1" velocity="20" lower="-2.7825534678416246059" upper="2.7825534678416246059"/>    
    <joint_properties friction="0.0"/>    
  </joint>  

  <link name="spur_gear_19_teeth">    
    <visual>      
      <origin xyz="0 0 0" rpy="0 -0 0"/>      
      <geometry>        
        <mesh filename="package:///meshes/spur_gear_19_teeth_visual.stl"/>        
      </geometry>      
      <material name="spur_gear_19_teeth_material">        
        <color rgba="0.61568627450980395466 0.81176470588235294379 0.92941176470588238168 1.0"/>        
      </material>      
    </visual>    
    <collision>      
      <origin xyz="0 0 0" rpy="0 -0 0"/>      
      <geometry>        
        <mesh filename="package:///meshes/spur_gear_19_teeth_collision.stl"/>        
      </geometry>      
    </collision>    
    <inertial>      
      <origin xyz="-4.9968063063607437635e-09 -7.9242210755682841365e-11 0.0045295192537419875708" rpy="0 0 0"/>      
      <mass value="0.0010993711450650535313"/>      
      <inertia ixx="2.9215018435433075427e-08" ixy="2.5903313731374078717e-16" ixz="8.559980850070259655e-15" iyy="2.9215021540034058468e-08" iyz="1.152688137911182053e-16" izz="4.5709977027671368266e-08"/>      
    </inertial>    
  </link>  

  <joint name="left_hip_yaw_drive" type="revolute">    
    <origin xyz="-0.036999999999998325895 0.03710000000000578807 -0.0395000000000009302" rpy="-1.5707963267950055819 -5.5860808452836958954e-13 -3.9012105568284431132e-13"/>    
    <parent link="waist_link"/>    
    <child link="spur_gear_19_teeth"/>    
    <axis xyz="0 0 1"/>    
    <limit effort="1" velocity="20" lower="-1.4211966766239538806" upper="1.4211966766239538806"/>    
    <joint_properties friction="0.0"/>    
  </joint>  

  <link name="spur_gear_21_teeth">    
    <visual>      
      <origin xyz="0 0 0" rpy="0 -0 0"/>      
      <geometry>        
        <mesh filename="package:///meshes/spur_gear_21_teeth_visual.stl"/>        
      </geometry>      
      <material name="spur_gear_21_teeth_material">        
        <color rgba="0.61568627450980395466 0.81176470588235294379 0.92941176470588238168 1.0"/>        
      </material>      
    </visual>    
    <collision>      
      <origin xyz="0 0 0" rpy="0 -0 0"/>      
      <geometry>        
        <mesh filename="package:///meshes/spur_gear_21_teeth_collision.stl"/>        
      </geometry>      
    </collision>    
    <inertial>      
      <origin xyz="-4.7814841745556497441e-10 -1.2610225839217328832e-12 0.002494461861614330131" rpy="0 0 0"/>      
      <mass value="0.0010063046528317974842"/>      
      <inertia ixx="3.1842855421068488283e-08" ixy="2.8803584912472002524e-40" ixz="0" iyy="3.1842855426953785697e-08" iyz="0" izz="5.9529380586728034749e-08"/>      
    </inertial>    
  </link>  

  <link name="left_leg_xm430">    
    <visual>      
      <origin xyz="0 0 0" rpy="0 -0 0"/>      
      <geometry>        
        <mesh filename="package:///meshes/left_leg_xm430_visual.stl"/>        
      </geometry>      
      <material name="left_leg_xm430_material">        
        <color rgba="0.61568627450980395466 0.81176470588235294379 0.92941176470588238168 1.0"/>        
      </material>      
    </visual>    
    <collision>      
      <origin xyz="0 0 0" rpy="0 -0 0"/>      
      <geometry>        
        <mesh filename="package:///meshes/left_leg_xm430_collision.stl"/>        
      </geometry>      
    </collision>    
    <inertial>      
      <origin xyz="-9.1960418512498486936e-19 -5.5625627936854410362e-19 -0.0098390489054829121524" rpy="0 0 0"/>      
      <mass value="0.017999999999999995171"/>      
      <inertia ixx="2.638503389144252815e-06" ixy="-4.6576288426178805576e-38" ixz="0" iyy="7.6596731957046856464e-06" iyz="0" izz="7.7220708070894735956e-06"/>      
    </inertial>    
  </link>  

  <joint name="left_leg_fixed" type="fixed">    
    <origin xyz="-7.3725747729014301513e-18 -6.9388939039072283776e-18 0.004999999999999997502" rpy="-3.141592653589793116 1.9721522630525295135e-31 -1.1102230246249028723e-16"/>    
    <parent link="spur_gear_21_teeth"/>    
    <child link="left_leg_xm430"/>    
    <axis xyz="0 0 1"/>    
    <limit effort="1" velocity="20"/>    
    <joint_properties friction="0.0"/>    
  </joint>  

  <joint name="left_hip_yaw_driven" type="revolute">    
    <origin xyz="-0.03699999999999998429 0.041100000000000004585 -0.019499999999999979156" rpy="-1.5707963267948983344 -1.570796326794896558 0"/>    
    <parent link="waist_link"/>    
    <child link="spur_gear_21_teeth"/>    
    <axis xyz="0 0 1"/>    
    <limit effort="1" velocity="20" lower="-1.570796326794896558" upper="1.570796326794896558"/>    
    <joint_properties friction="0.0"/>    
  </joint>  

  <link name="spur_gear_19_teeth_2">    
    <visual>      
      <origin xyz="0 0 0" rpy="0 -0 0"/>      
      <geometry>        
        <mesh filename="package:///meshes/spur_gear_19_teeth_2_visual.stl"/>        
      </geometry>      
      <material name="spur_gear_19_teeth_2_material">        
        <color rgba="0.61568627450980395466 0.81176470588235294379 0.92941176470588238168 1.0"/>        
      </material>      
    </visual>    
    <collision>      
      <origin xyz="0 0 0" rpy="0 -0 0"/>      
      <geometry>        
        <mesh filename="package:///meshes/spur_gear_19_teeth_2_collision.stl"/>        
      </geometry>      
    </collision>    
    <inertial>      
      <origin xyz="-4.9968063063607454179e-09 -7.9242210755682737967e-11 0.0045295192537419875708" rpy="0 0 0"/>      
      <mass value="0.0010993711450650535313"/>      
      <inertia ixx="2.9215018435433088662e-08" ixy="2.5903313716658553992e-16" ixz="8.5599808500702612327e-15" iyy="2.9215021540034065086e-08" iyz="1.152688137911182053e-16" izz="4.5709977027671368266e-08"/>      
    </inertial>    
  </link>  

  <joint name="right_hip_yaw_drive" type="revolute">    
    <origin xyz="0.037000000000001108391 0.037100000000003796607 -0.039500000000000472233" rpy="-1.5707963267950055819 -5.5860638843048369188e-13 -3.8568016358434373564e-13"/>    
    <parent link="waist_link"/>    
    <child link="spur_gear_19_teeth_2"/>    
    <axis xyz="0 0 1"/>    
    <limit effort="1" velocity="20" lower="-1.4211966766239538806" upper="1.4211966766239538806"/>    
    <joint_properties friction="0.0"/>    
  </joint>  

  <link name="spur_gear_21_teeth_2">    
    <visual>      
      <origin xyz="0 0 0" rpy="0 -0 0"/>      
      <geometry>        
        <mesh filename="package:///meshes/spur_gear_21_teeth_2_visual.stl"/>        
      </geometry>      
      <material name="spur_gear_21_teeth_2_material">        
        <color rgba="0.61568627450980395466 0.81176470588235294379 0.92941176470588238168 1.0"/>        
      </material>      
    </visual>    
    <collision>      
      <origin xyz="0 0 0" rpy="0 -0 0"/>      
      <geometry>        
        <mesh filename="package:///meshes/spur_gear_21_teeth_2_collision.stl"/>        
      </geometry>      
    </collision>    
    <inertial>      
      <origin xyz="-4.7814841745556497441e-10 1.2610156450278289759e-12 0.002505538138385667371" rpy="0 0 0"/>      
      <mass value="0.0010063046528317974842"/>      
      <inertia ixx="3.1842855421068488283e-08" ixy="-3.7656769811774246715e-39" ixz="9.0009329324296215955e-39" iyy="3.1842855426953785697e-08" iyz="-4.3959137544666170172e-38" izz="5.9529380586728034749e-08"/>      
    </inertial>    
  </link>  

  <link name="right_leg_xm430">    
    <visual>      
      <origin xyz="0 0 0" rpy="0 -0 0"/>      
      <geometry>        
        <mesh filename="package:///meshes/right_leg_xm430_visual.stl"/>        
      </geometry>      
      <material name="right_leg_xm430_material">        
        <color rgba="0.61568627450980395466 0.81176470588235294379 0.92941176470588238168 1.0"/>        
      </material>      
    </visual>    
    <collision>      
      <origin xyz="0 0 0" rpy="0 -0 0"/>      
      <geometry>        
        <mesh filename="package:///meshes/right_leg_xm430_collision.stl"/>        
      </geometry>      
    </collision>    
    <inertial>      
      <origin xyz="-9.1960418512498486936e-19 -5.5625627936854410362e-19 -0.0098390489054829121524" rpy="0 0 0"/>      
      <mass value="0.017999999999999995171"/>      
      <inertia ixx="2.638503389144252815e-06" ixy="-4.7210723484443542159e-37" ixz="0" iyy="7.6596731957046856464e-06" iyz="0" izz="7.7220708070894735956e-06"/>      
    </inertial>    
  </link>  

  <joint name="right_leg_fixed" type="fixed">    
    <origin xyz="6.9388939039072283776e-18 0 0.004999999999999997502" rpy="-3.1415926535897784611 1.8262365126862931582e-15 -3.6959871191238926143e-16"/>    
    <parent link="spur_gear_21_teeth_2"/>    
    <child link="right_leg_xm430"/>    
    <axis xyz="0 0 1"/>    
    <limit effort="1" velocity="20"/>    
    <joint_properties friction="0.0"/>    
  </joint>  

  <joint name="right_hip_yaw_driven" type="revolute">    
    <origin xyz="0.036999999999999998168 0.041100000000000011524 -0.019499999999999979156" rpy="-1.5707963267949129893 -1.570796326794896558 0"/>    
    <parent link="waist_link"/>    
    <child link="spur_gear_21_teeth_2"/>    
    <axis xyz="0 0 1"/>    
    <limit effort="1" velocity="20" lower="-1.570796326794896558" upper="1.570796326794896558"/>    
    <joint_properties friction="0.0"/>    
  </joint>  

  <joint name="waist_roll" type="revolute">    
    <origin xyz="-5.6460850897507995335e-16 -0.022707865260693318316 0.012999999999999227451" rpy="1.57079632679489678 9.8097267041675110992e-15 1.1042194747589474972e-14"/>    
    <parent link="waist_gears"/>    
    <child link="waist_link"/>    
    <axis xyz="0 0 1"/>    
    <limit effort="1" velocity="20" lower="-0.52359877559829881566" upper="0.52359877559829881566"/>    
    <joint_properties friction="0.0"/>    
  </joint>  

  <joint name="waist_yaw" type="revolute">    
    <origin xyz="3.7643499428696713949e-16 3.9043635660773690095e-17 -3.1571967262777889118e-16" rpy="3.1415926535897917837 -1.9359568790009725236e-16 -1.57079632679489678"/>    
    <parent link="torso"/>    
    <child link="waist_gears"/>    
    <axis xyz="0 0 1"/>    
    <limit effort="1" velocity="20" lower="-1.570796326794896558" upper="1.570796326794896558"/>    
    <joint_properties friction="0.0"/>    
  </joint>  

  <link name="left_arm_hand">    
    <visual>      
      <origin xyz="0 0 0" rpy="0 -0 0"/>      
      <geometry>        
        <mesh filename="package:///meshes/left_arm_hand_visual.stl"/>        
      </geometry>      
      <material name="left_arm_hand_material">        
        <color rgba="0.61568627450980395466 0.81176470588235294379 0.92941176470588227065 1.0"/>        
      </material>      
    </visual>    
    <collision>      
      <origin xyz="0 0 0" rpy="0 -0 0"/>      
      <geometry>        
        <mesh filename="package:///meshes/left_arm_hand_collision.stl"/>        
      </geometry>      
    </collision>    
    <inertial>      
      <origin xyz="5.8254249521811582877e-11 -5.1264642561120958965e-05 0.008244078812709491888" rpy="0 0 0"/>      
      <mass value="0.0085999999999999965361"/>      
      <inertia ixx="1.2272887040545793991e-06" ixy="-2.1429944230882620695e-14" ixz="-8.5847199149485390626e-15" iyy="2.9107306060364624323e-06" iyz="7.4623841398183150184e-09" izz="3.0803135950773496163e-06"/>      
    </inertial>    
  </link>  

  <joint name="left_sho_pitch" type="revolute">    
    <origin xyz="-0.0029999999999997528644 0.062000000000000436706 0.10523651076281793915" rpy="-1.5707963267948983344 8.0214786879603172751e-16 1.532501625198463655e-15"/>    
    <parent link="torso"/>    
    <child link="left_arm_hand"/>    
    <axis xyz="0 0 1"/>    
    <limit effort="1" velocity="20" lower="-1.570796326794896558" upper="1.570796326794896558"/>    
    <joint_properties friction="0.0"/>    
  </joint>  

  <link name="right_arm_hand">    
    <visual>      
      <origin xyz="0 0 0" rpy="0 -0 0"/>      
      <geometry>        
        <mesh filename="package:///meshes/right_arm_hand_visual.stl"/>        
      </geometry>      
      <material name="right_arm_hand_material">        
        <color rgba="0.61568627450980395466 0.81176470588235294379 0.92941176470588227065 1.0"/>        
      </material>      
    </visual>    
    <collision>      
      <origin xyz="0 0 0" rpy="0 -0 0"/>      
      <geometry>        
        <mesh filename="package:///meshes/right_arm_hand_collision.stl"/>        
      </geometry>      
    </collision>    
    <inertial>      
      <origin xyz="5.8254249521811582877e-11 -5.1264642561120958965e-05 0.008244078812709491888" rpy="0 0 0"/>      
      <mass value="0.0085999999999999965361"/>      
      <inertia ixx="1.2272887040545793991e-06" ixy="-2.1429944230882620695e-14" ixz="-8.5847199149485390626e-15" iyy="2.9107306060364624323e-06" iyz="7.4623841398183150184e-09" izz="3.0803135950773496163e-06"/>      
    </inertial>    
  </link>  

  <joint name="right_sho_pitch" type="revolute">    
    <origin xyz="-0.0030000000000001275646 -0.061999999999999985678 0.10523651076281731465" rpy="-1.570796326794896558 -6.5632891966464542239e-16 -3.1415926535897917837"/>    
    <parent link="torso"/>    
    <child link="right_arm_hand"/>    
    <axis xyz="0 0 1"/>    
    <limit effort="1" velocity="20" lower="-1.570796326794896558" upper="1.570796326794896558"/>    
    <joint_properties friction="0.0"/>    
  </joint>  


</robot>