<?xml version="1.0" ?><robot name="toddlerbot">  
  <link name="torso">    
    <visual>      
      <origin xyz="0 0 0" rpy="0 -0 0"/>      
      <geometry>        
        <mesh filename="package:///meshes/torso_visual.stl"/>        
      </geometry>      
      <material name="torso_material">        
        <color rgba="0.58602628355191022091 0.73205173766587616768 0.84624015779321404285 1.0"/>        
      </material>      
    </visual>    
    <collision>      
      <origin xyz="0 0 0" rpy="0 -0 0"/>      
      <geometry>        
        <mesh filename="package:///meshes/torso_collision.stl"/>        
      </geometry>      
    </collision>    
    <inertial>      
      <origin xyz="-0.0074328354797873856519 0.0025059801105640597436 0.073401015491149065872" rpy="0 0 0"/>      
      <mass value="0.58490521749923585215"/>      
      <inertia ixx="0.0016168191047346508818" ixy="-1.4736281865313545779e-05" ixz="3.2221053182213641741e-07" iyy="0.0013101565794344577007" iyz="2.4169833425786332702e-05" izz="0.0011896913602930953707"/>      
    </inertial>    
  </link>  

  <link name="spur_1m_20t">    
    <visual>      
      <origin xyz="0 0 0" rpy="0 -0 0"/>      
      <geometry>        
        <mesh filename="package:///meshes/spur_1m_20t_visual.stl"/>        
      </geometry>      
      <material name="spur_1m_20t_material">        
        <color rgba="0.64705882352941179736 0.64705882352941179736 0.64705882352941179736 1.0"/>        
      </material>      
    </visual>    
    <collision>      
      <origin xyz="0 0 0" rpy="0 -0 0"/>      
      <geometry>        
        <mesh filename="package:///meshes/spur_1m_20t_collision.stl"/>        
      </geometry>      
    </collision>    
    <inertial>      
      <origin xyz="-5.3115843702594968093e-18 6.267656612818368267e-18 -0.0033745971730663147647" rpy="0 0 0"/>      
      <mass value="0.0015534950290892286448"/>      
      <inertia ixx="4.4726508287871799621e-08" ixy="5.2024693257554525847e-24" ixz="2.7597381312606821682e-39" iyy="4.4726508287871786386e-08" iyz="-4.880475641083095171e-38" izz="7.9558906764902006609e-08"/>      
    </inertial>    
  </link>  

  <joint name="neck_yaw_drive" type="revolute">    
    <origin xyz="-0.004999999999999059884 -1.8020791195763170554e-16 0.12248651076281816263" rpy="-3.1415926535897913396 1.7995135580561967136e-15 9.6455933634066887197e-16"/>    
    <parent link="torso"/>    
    <child link="spur_1m_20t"/>    
    <axis xyz="0 0 1"/>    
    <limit effort="1" velocity="20" lower="-3.141592653589793116" upper="3.141592653589793116"/>    
    <joint_properties friction="0.0"/>    
  </joint>  

  <link name="neck_yaw_link">    
    <visual>      
      <origin xyz="0 0 0" rpy="0 -0 0"/>      
      <geometry>        
        <mesh filename="package:///meshes/neck_yaw_link_visual.stl"/>        
      </geometry>      
      <material name="neck_yaw_link_material">        
        <color rgba="0.33636252417476653065 0.48680769190259864931 0.74976123534949778993 1.0"/>        
      </material>      
    </visual>    
    <collision>      
      <origin xyz="0 0 0" rpy="0 -0 0"/>      
      <geometry>        
        <mesh filename="package:///meshes/neck_yaw_link_collision.stl"/>        
      </geometry>      
    </collision>    
    <inertial>      
      <origin xyz="2.729128646113388693e-05 0.00019798992283532641659 -0.011527412037194836522" rpy="0 0 0"/>      
      <mass value="0.0085168305947458285143"/>      
      <inertia ixx="1.0407116999274144965e-06" ixy="-2.4210150466633400977e-11" ixz="4.724680321864392974e-10" iyy="1.1240009954110278886e-06" iyz="3.0834841754638120323e-08" izz="3.158756516729191776e-07"/>      
    </inertial>    
  </link>  

  <link name="neck_pitch_link">    
    <visual>      
      <origin xyz="0 0 0" rpy="0 -0 0"/>      
      <geometry>        
        <mesh filename="package:///meshes/neck_pitch_link_visual.stl"/>        
      </geometry>      
      <material name="neck_pitch_link_material">        
        <color rgba="0.74911126277760053949 0.80002799398726853752 0.87441258869524285391 1.0"/>        
      </material>      
    </visual>    
    <collision>      
      <origin xyz="0 0 0" rpy="0 -0 0"/>      
      <geometry>        
        <mesh filename="package:///meshes/neck_pitch_link_collision.stl"/>        
      </geometry>      
    </collision>    
    <inertial>      
      <origin xyz="-0.0034370497615718049317 -0.032876793988991424855 0.00036476492134716474638" rpy="0 0 0"/>      
      <mass value="0.11211553874797880459"/>      
      <inertia ixx="7.7015755459849957677e-05" ixy="2.1757968319820864549e-06" ixz="2.8732209413521026174e-06" iyy="6.3502636688155217164e-05" iyz="-1.2492352737635673663e-05" izz="2.8610002383974706596e-05"/>      
    </inertial>    
  </link>  

  <link name="spur_gear_(13_teeth)">    
    <visual>      
      <origin xyz="0 0 0" rpy="0 -0 0"/>      
      <geometry>        
        <mesh filename="package:///meshes/spur_gear_(13_teeth)_visual.stl"/>        
      </geometry>      
      <material name="spur_gear_(13_teeth)_material">        
        <color rgba="0.64705882352941179736 0.64705882352941179736 0.64705882352941179736 1.0"/>        
      </material>      
    </visual>    
    <collision>      
      <origin xyz="0 0 0" rpy="0 -0 0"/>      
      <geometry>        
        <mesh filename="package:///meshes/spur_gear_(13_teeth)_collision.stl"/>        
      </geometry>      
    </collision>    
    <inertial>      
      <origin xyz="1.0399873341738908573e-09 2.3905206819408639796e-10 -0.0092751511485596373902" rpy="0 0 0"/>      
      <mass value="0.00081469437497230865874"/>      
      <inertia ixx="2.0244839552178295378e-08" ixy="-2.9046301764120405049e-15" ixz="8.2976066066373874712e-15" iyy="2.0244841689973771385e-08" iyz="-1.3142117784254373661e-15" izz="1.8905472907863310999e-08"/>      
    </inertial>    
  </link>  

  <joint name="neck_pitch_drive" type="revolute">    
    <origin xyz="-1.4571677198205179593e-16 -0.015650000000000330314 0.0087999999999993777644" rpy="-2.1434555572207676319e-16 -1.5880065549567459396e-15 1.570796326794896558"/>    
    <parent link="neck_pitch_link"/>    
    <child link="spur_gear_(13_teeth)"/>    
    <axis xyz="0 0 1"/>    
    <limit effort="1" velocity="20" lower="-1.570796326794896558" upper="1.570796326794896558"/>    
    <joint_properties friction="0.0"/>    
  </joint>  

  <joint name="neck_pitch_driven" type="revolute">    
    <origin xyz="3.7500073185592341929e-10 0.0051500000614755261225 -0.027499999999999941158" rpy="1.57079632679489678 -1.7934420258902467287e-15 -3.1415926535897922278"/>    
    <parent link="neck_yaw_link"/>    
    <child link="neck_pitch_link"/>    
    <axis xyz="0 0 1"/>    
    <limit effort="1" velocity="20" lower="-1.570796326794896558" upper="1.570796326794896558"/>    
    <joint_properties friction="0.0"/>    
  </joint>  

  <joint name="neck_yaw_driven" type="revolute">    
    <origin xyz="0.016000000000001915468 1.4752314067929367773e-17 0.12348651076281796923" rpy="-3.141592653589793116 -0 -3.1415926535897922278"/>    
    <parent link="torso"/>    
    <child link="neck_yaw_link"/>    
    <axis xyz="0 0 1"/>    
    <limit effort="1" velocity="20" lower="-3.141592653589793116" upper="3.141592653589793116"/>    
    <joint_properties friction="0.0"/>    
  </joint>  

  <link name="waist_gears">    
    <visual>      
      <origin xyz="0 0 0" rpy="0 -0 0"/>      
      <geometry>        
        <mesh filename="package:///meshes/waist_gears_visual.stl"/>        
      </geometry>      
      <material name="waist_gears_material">        
        <color rgba="0.27057516381830515328 0.53648836590125015267 0.70305495274644802528 1.0"/>        
      </material>      
    </visual>    
    <collision>      
      <origin xyz="0 0 0" rpy="0 -0 0"/>      
      <geometry>        
        <mesh filename="package:///meshes/waist_gears_collision.stl"/>        
      </geometry>      
    </collision>    
    <inertial>      
      <origin xyz="6.5469454462562728371e-08 -5.6785897865462200837e-10 -0.012726165583898677025" rpy="0 0 0"/>      
      <mass value="0.02331580566917982808"/>      
      <inertia ixx="6.9043104388291945091e-06" ixy="-1.8428638769651587303e-11" ixz="9.9668712610592374092e-13" iyy="1.1624091971676370215e-06" iyz="-3.3260430300241911844e-10" izz="6.8701920560919859505e-06"/>      
    </inertial>    
  </link>  

  <link name="waist_link">    
    <visual>      
      <origin xyz="0 0 0" rpy="0 -0 0"/>      
      <geometry>        
        <mesh filename="package:///meshes/waist_link_visual.stl"/>        
      </geometry>      
      <material name="waist_link_material">        
        <color rgba="0.63401200025306059249 0.68204699127249923674 0.66910193985036237052 1.0"/>        
      </material>      
    </visual>    
    <collision>      
      <origin xyz="0 0 0" rpy="0 -0 0"/>      
      <geometry>        
        <mesh filename="package:///meshes/waist_link_collision.stl"/>        
      </geometry>      
    </collision>    
    <inertial>      
      <origin xyz="-9.1086191324708718293e-07 -0.02620448375530855592 0.030190392008842433652" rpy="0 0 0"/>      
      <mass value="0.1663195349061246664"/>      
      <inertia ixx="6.8622997376113035605e-05" ixy="6.1328048221653534174e-10" ixz="3.6786792027264541809e-06" iyy="0.00020057117429216707164" iyz="-3.7255079147351952329e-06" izz="0.00015770127977213045721"/>      
    </inertial>    
  </link>  

  <link name="spiral_bevel_1m_14t_30deg">    
    <visual>      
      <origin xyz="0 0 0" rpy="0 -0 0"/>      
      <geometry>        
        <mesh filename="package:///meshes/spiral_bevel_1m_14t_30deg_visual.stl"/>        
      </geometry>      
      <material name="spiral_bevel_1m_14t_30deg_material">        
        <color rgba="0.64705882352941179736 0.64705882352941179736 0.64705882352941179736 1.0"/>        
      </material>      
    </visual>    
    <collision>      
      <origin xyz="0 0 0" rpy="0 -0 0"/>      
      <geometry>        
        <mesh filename="package:///meshes/spiral_bevel_1m_14t_30deg_collision.stl"/>        
      </geometry>      
    </collision>    
    <inertial>      
      <origin xyz="8.2641075233036431769e-10 3.4055789742068465209e-10 0.0068612577407481641426" rpy="0 0 0"/>      
      <mass value="0.00067997563436136246491"/>      
      <inertia ixx="1.2174575798018973838e-08" ixy="3.8216070434470129766e-18" ixz="4.7204547854141617805e-16" iyy="1.2174575801813732727e-08" iyz="-2.6184097762970973854e-16" izz="1.3178653206314311711e-08"/>      
    </inertial>    
  </link>  

  <joint name="waist_act_1" type="revolute">    
    <origin xyz="-4.3158571269690260163e-16 -0.019600000000000134676 0.012750000000000493577" rpy="-1.5707963267948961139 -1.5707963267948088504 0"/>    
    <parent link="waist_link"/>    
    <child link="spiral_bevel_1m_14t_30deg"/>    
    <axis xyz="0 0 1"/>    
    <limit effort="1" velocity="20" lower="-2.7925268031909271649" upper="2.7925268031909271649"/>    
    <joint_properties friction="0.0"/>    
  </joint>  

  <link name="spiral_bevel_1m_14t_30deg_2">    
    <visual>      
      <origin xyz="0 0 0" rpy="0 -0 0"/>      
      <geometry>        
        <mesh filename="package:///meshes/spiral_bevel_1m_14t_30deg_2_visual.stl"/>        
      </geometry>      
      <material name="spiral_bevel_1m_14t_30deg_2_material">        
        <color rgba="0.64705882352941179736 0.64705882352941179736 0.64705882352941179736 1.0"/>        
      </material>      
    </visual>    
    <collision>      
      <origin xyz="0 0 0" rpy="0 -0 0"/>      
      <geometry>        
        <mesh filename="package:///meshes/spiral_bevel_1m_14t_30deg_2_collision.stl"/>        
      </geometry>      
    </collision>    
    <inertial>      
      <origin xyz="7.299096500823498701e-10 5.1591309282916804967e-10 0.0068612577407481632752" rpy="0 0 0"/>      
      <mass value="0.00067997563436136246491"/>      
      <inertia ixx="1.2174575796548749635e-08" ixy="2.6199054052568876071e-18" ixz="5.1847541181367891679e-16" iyy="1.2174575803283978437e-08" iyz="-1.5023607688884004006e-16" izz="1.3178653206314315019e-08"/>      
    </inertial>    
  </link>  

  <joint name="waist_act_2" type="revolute">    
    <origin xyz="-5.8109383000701193055e-16 -0.019600000000000120798 0.03275000000000045236" rpy="-1.5707963267948927832 -1.3463968515393145431 1.0161280646543158659e-14"/>    
    <parent link="waist_link"/>    
    <child link="spiral_bevel_1m_14t_30deg_2"/>    
    <axis xyz="0 0 1"/>    
    <limit effort="1" velocity="20" lower="-2.7925268031909271649" upper="2.7925268031909271649"/>    
    <joint_properties friction="0.0"/>    
  </joint>  

  <link name="spur_gear_19_teeth">    
    <visual>      
      <origin xyz="0 0 0" rpy="0 -0 0"/>      
      <geometry>        
        <mesh filename="package:///meshes/spur_gear_19_teeth_visual.stl"/>        
      </geometry>      
      <material name="spur_gear_19_teeth_material">        
        <color rgba="0.61568627450980395466 0.81176470588235294379 0.92941176470588238168 1.0"/>        
      </material>      
    </visual>    
    <collision>      
      <origin xyz="0 0 0" rpy="0 -0 0"/>      
      <geometry>        
        <mesh filename="package:///meshes/spur_gear_19_teeth_collision.stl"/>        
      </geometry>      
    </collision>    
    <inertial>      
      <origin xyz="-4.9156135350749387128e-09 9.0060874060975807733e-10 -0.0045295192537419875708" rpy="0 0 0"/>      
      <mass value="0.0010993711450650535313"/>      
      <inertia ixx="2.9215018435433075427e-08" ixy="2.5903313814092139973e-16" ixz="-8.4242612454600564997e-15" iyy="2.9215021540034058468e-08" iyz="1.522623238362820646e-15" izz="4.5709977027671355031e-08"/>      
    </inertial>    
  </link>  

  <joint name="left_hip_yaw_drive" type="revolute">    
    <origin xyz="-0.036999999999999207134 -0.037100000000004823564 0.039500000000000437539" rpy="-1.5707963267950579844 5.7109166702824404977e-13 2.6938840543896956895e-13"/>    
    <parent link="waist_link"/>    
    <child link="spur_gear_19_teeth"/>    
    <axis xyz="0 0 1"/>    
    <limit effort="1" velocity="20" lower="-1.570796326794896558" upper="1.570796326794896558"/>    
    <joint_properties friction="0.0"/>    
  </joint>  

  <link name="spur_gear_21_teeth">    
    <visual>      
      <origin xyz="0 0 0" rpy="0 -0 0"/>      
      <geometry>        
        <mesh filename="package:///meshes/spur_gear_21_teeth_visual.stl"/>        
      </geometry>      
      <material name="spur_gear_21_teeth_material">        
        <color rgba="0.61568627450980395466 0.81176470588235294379 0.92941176470588238168 1.0"/>        
      </material>      
    </visual>    
    <collision>      
      <origin xyz="0 0 0" rpy="0 -0 0"/>      
      <geometry>        
        <mesh filename="package:///meshes/spur_gear_21_teeth_collision.stl"/>        
      </geometry>      
    </collision>    
    <inertial>      
      <origin xyz="-4.7814841776401959085e-10 1.2610226465348769291e-12 -0.0024944618616143370698" rpy="0 0 0"/>      
      <mass value="0.0010063046528317974842"/>      
      <inertia ixx="3.1842855421068481665e-08" ixy="-5.9730587676548820251e-38" ixz="5.4199104819300928604e-39" iyy="3.1842855426953785697e-08" iyz="-3.7144429244050308014e-38" izz="5.9529380586728028132e-08"/>      
    </inertial>    
  </link>  

  <link name="left_leg_xm430">    
    <visual>      
      <origin xyz="0 0 0" rpy="0 -0 0"/>      
      <geometry>        
        <mesh filename="package:///meshes/left_leg_xm430_visual.stl"/>        
      </geometry>      
      <material name="left_leg_xm430_material">        
        <color rgba="0.66383680736315153759 0.67022570765366251688 0.54700842102268187883 1.0"/>        
      </material>      
    </visual>    
    <collision>      
      <origin xyz="0 0 0" rpy="0 -0 0"/>      
      <geometry>        
        <mesh filename="package:///meshes/left_leg_xm430_collision.stl"/>        
      </geometry>      
    </collision>    
    <inertial>      
      <origin xyz="-0.0006860168493777058776 0.0015532308536420004648 -0.11693678749720842758" rpy="0 0 0"/>      
      <mass value="0.38011498201789889473"/>      
      <inertia ixx="0.0024437861070583186823" ixy="-5.5680945726362885034e-07" ixz="-4.5801147261780993537e-05" iyy="0.0024604656988605555848" iyz="-1.9888397758929099159e-05" izz="0.0001074780892808252763"/>      
    </inertial>    
  </link>  

  <joint name="left_leg_fixed" type="fixed">    
    <origin xyz="-4.336808689942017736e-19 6.9388939039072283776e-18 -0.0050000000000000044409" rpy="-1.0439449364097535015e-14 3.7110850528220658615e-31 -4.3084061976207498209e-30"/>    
    <parent link="spur_gear_21_teeth"/>    
    <child link="left_leg_xm430"/>    
    <axis xyz="0 0 1"/>    
    <limit effort="1" velocity="20"/>    
    <joint_properties friction="0.0"/>    
  </joint>  

  <joint name="left_hip_yaw_driven" type="revolute">    
    <origin xyz="-0.036999999999999998168 -0.041100000000000067035 0.019500000000000006911" rpy="-1.5707963267948841235 1.5707963267948956698 0"/>    
    <parent link="waist_link"/>    
    <child link="spur_gear_21_teeth"/>    
    <axis xyz="0 0 1"/>    
    <limit effort="1" velocity="20" lower="-1.570796326794896558" upper="1.570796326794896558"/>    
    <joint_properties friction="0.0"/>    
  </joint>  

  <link name="spur_gear_19_teeth_2">    
    <visual>      
      <origin xyz="0 0 0" rpy="0 -0 0"/>      
      <geometry>        
        <mesh filename="package:///meshes/spur_gear_19_teeth_2_visual.stl"/>        
      </geometry>      
      <material name="spur_gear_19_teeth_2_material">        
        <color rgba="0.61568627450980395466 0.81176470588235294379 0.92941176470588238168 1.0"/>        
      </material>      
    </visual>    
    <collision>      
      <origin xyz="0 0 0" rpy="0 -0 0"/>      
      <geometry>        
        <mesh filename="package:///meshes/spur_gear_19_teeth_2_collision.stl"/>        
      </geometry>      
    </collision>    
    <inertial>      
      <origin xyz="-4.91561353507493954e-09 9.0060873714031122877e-10 -0.0045295192537419875708" rpy="0 0 0"/>      
      <mass value="0.0010993711450650535313"/>      
      <inertia ixx="2.9215018435433088662e-08" ixy="2.5903313826161381487e-16" ixz="-8.4242612454600580774e-15" iyy="2.9215021540034071703e-08" iyz="1.5226232383628210404e-15" izz="4.5709977027671355031e-08"/>      
    </inertial>    
  </link>  

  <joint name="right_hip_yaw_drive" type="revolute">    
    <origin xyz="0.037000000000000352052 -0.037100000000003852119 0.039500000000000062839" rpy="-1.5707963267949709429 3.0763843997160748787e-13 2.7733309074151655565e-13"/>    
    <parent link="waist_link"/>    
    <child link="spur_gear_19_teeth_2"/>    
    <axis xyz="0 0 1"/>    
    <limit effort="1" velocity="20" lower="-1.570796326794896558" upper="1.570796326794896558"/>    
    <joint_properties friction="0.0"/>    
  </joint>  

  <link name="spur_gear_21_teeth_2">    
    <visual>      
      <origin xyz="0 0 0" rpy="0 -0 0"/>      
      <geometry>        
        <mesh filename="package:///meshes/spur_gear_21_teeth_2_visual.stl"/>        
      </geometry>      
      <material name="spur_gear_21_teeth_2_material">        
        <color rgba="0.61568627450980395466 0.81176470588235294379 0.92941176470588238168 1.0"/>        
      </material>      
    </visual>    
    <collision>      
      <origin xyz="0 0 0" rpy="0 -0 0"/>      
      <geometry>        
        <mesh filename="package:///meshes/spur_gear_21_teeth_2_collision.stl"/>        
      </geometry>      
    </collision>    
    <inertial>      
      <origin xyz="-4.7814841733033872186e-10 -1.2610157076409730219e-12 -0.002505538138385667371" rpy="0 0 0"/>      
      <mass value="0.0010063046528317974842"/>      
      <inertia ixx="3.1842855421068481665e-08" ixy="-5.6450446515323895372e-38" ixz="-1.2410298257532391259e-39" iyy="3.1842855426953785697e-08" iyz="3.0480208504147716512e-38" izz="5.9529380586728028132e-08"/>      
    </inertial>    
  </link>  

  <link name="right_leg_xm430">    
    <visual>      
      <origin xyz="0 0 0" rpy="0 -0 0"/>      
      <geometry>        
        <mesh filename="package:///meshes/right_leg_xm430_visual.stl"/>        
      </geometry>      
      <material name="right_leg_xm430_material">        
        <color rgba="0.66383680736315164861 0.67022570765366262791 0.54700842102268187883 1.0"/>        
      </material>      
    </visual>    
    <collision>      
      <origin xyz="0 0 0" rpy="0 -0 0"/>      
      <geometry>        
        <mesh filename="package:///meshes/right_leg_xm430_collision.stl"/>        
      </geometry>      
    </collision>    
    <inertial>      
      <origin xyz="-0.00097392650350175489615 -0.0015532198367548615773 -0.11693679001400852924" rpy="0 0 0"/>      
      <mass value="0.38011498201789883922"/>      
      <inertia ixx="0.0024437957603120849005" ixy="1.8168990501910384001e-06" ixz="-3.7047039385191091892e-05" iyy="0.0024602937798241094822" iyz="1.9891464190069814953e-05" izz="0.00010729660031849125789"/>      
    </inertial>    
  </link>  

  <joint name="right_leg_fixed" type="fixed">    
    <origin xyz="0 -6.9388939039072283776e-18 -0.004999999999999997502" rpy="1.60982722631807463e-15 -3.5340660733628542786e-32 -3.0121122483794329866e-31"/>    
    <parent link="spur_gear_21_teeth_2"/>    
    <child link="right_leg_xm430"/>    
    <axis xyz="0 0 1"/>    
    <limit effort="1" velocity="20"/>    
    <joint_properties friction="0.0"/>    
  </joint>  

  <joint name="right_hip_yaw_driven" type="revolute">    
    <origin xyz="0.036999999999999991229 -0.041099999999999997646 0.019500000000000006911" rpy="-1.5707963267948983344 1.5707963267948956698 0"/>    
    <parent link="waist_link"/>    
    <child link="spur_gear_21_teeth_2"/>    
    <axis xyz="0 0 1"/>    
    <limit effort="1" velocity="20" lower="-1.570796326794896558" upper="1.570796326794896558"/>    
    <joint_properties friction="0.0"/>    
  </joint>  

  <joint name="waist_roll" type="revolute">    
    <origin xyz="-1.2306064131348466017e-19 0.022707865260692457893 -0.013000000000000011546" rpy="1.5707963267948952257 -4.14087346736882539e-15 4.2181022606674638269e-16"/>    
    <parent link="waist_gears"/>    
    <child link="waist_link"/>    
    <axis xyz="0 0 1"/>    
    <limit effort="1" velocity="20" lower="-0.52359877559829881566" upper="0.52359877559829881566"/>    
    <joint_properties friction="0.0"/>    
  </joint>  

  <joint name="waist_yaw" type="revolute">    
    <origin xyz="0 -3.9443045261050590271e-31 0" rpy="2.0946901476026454934e-15 7.1861600448342810266e-16 -1.5707963267948101826"/>    
    <parent link="torso"/>    
    <child link="waist_gears"/>    
    <axis xyz="0 0 1"/>    
    <limit effort="1" velocity="20" lower="-1.570796326794896558" upper="1.570796326794896558"/>    
    <joint_properties friction="0.0"/>    
  </joint>  

  <link name="left_arm_hand">    
    <visual>      
      <origin xyz="0 0 0" rpy="0 -0 0"/>      
      <geometry>        
        <mesh filename="package:///meshes/left_arm_hand_visual.stl"/>        
      </geometry>      
      <material name="left_arm_hand_material">        
        <color rgba="0.72329282556618279543 0.84007822047190716663 0.90963032034360458145 1.0"/>        
      </material>      
    </visual>    
    <collision>      
      <origin xyz="0 0 0" rpy="0 -0 0"/>      
      <geometry>        
        <mesh filename="package:///meshes/left_arm_hand_collision.stl"/>        
      </geometry>      
    </collision>    
    <inertial>      
      <origin xyz="-0.00066047240158165828206 0.090373334068669000652 0.033439749977260256608" rpy="0 0 0"/>      
      <mass value="0.4342001469825795823"/>      
      <inertia ixx="0.0020694241836572042914" ixy="9.8260438756537294883e-06" ixz="9.8094532373841011103e-08" iyy="0.00014107731840357496788" iyz="0.00010237892223604870578" izz="0.0020501949018750533459"/>      
    </inertial>    
  </link>  

  <joint name="left_sho_pitch" type="revolute">    
    <origin xyz="-0.0029999999999997389866 0.062000000000000464462 0.10523651076281793915" rpy="-1.5707963267948983344 -3.4972025276127318207e-15 -2.4598039012687864683e-16"/>    
    <parent link="torso"/>    
    <child link="left_arm_hand"/>    
    <axis xyz="0 0 1"/>    
    <limit effort="1" velocity="20" lower="-1.570796326794896558" upper="1.570796326794896558"/>    
    <joint_properties friction="0.0"/>    
  </joint>  

  <link name="right_arm_hand">    
    <visual>      
      <origin xyz="0 0 0" rpy="0 -0 0"/>      
      <geometry>        
        <mesh filename="package:///meshes/right_arm_hand_visual.stl"/>        
      </geometry>      
      <material name="right_arm_hand_material">        
        <color rgba="0.72329282556618279543 0.84007822047190716663 0.90963032034360458145 1.0"/>        
      </material>      
    </visual>    
    <collision>      
      <origin xyz="0 0 0" rpy="0 -0 0"/>      
      <geometry>        
        <mesh filename="package:///meshes/right_arm_hand_collision.stl"/>        
      </geometry>      
    </collision>    
    <inertial>      
      <origin xyz="0.00017249119302055381723 0.090373334068664518126 0.033195753424943068299" rpy="0 0 0"/>      
      <mass value="0.4342001469825795823"/>      
      <inertia ixx="0.002070762830924084176" ixy="-2.1597507841810884401e-05" ixz="2.2892499014005090468e-06" iyy="0.00014259246491477237649" iyz="0.00010954853687152265012" izz="0.0020503714011189037685"/>      
    </inertial>    
  </link>  

  <joint name="right_sho_pitch" type="revolute">    
    <origin xyz="-0.0030000000000001136868 -0.061999999999999992617 0.10523651076281731465" rpy="-1.570796326794896558 -3.3306690742370509197e-16 3.141592653589793116"/>    
    <parent link="torso"/>    
    <child link="right_arm_hand"/>    
    <axis xyz="0 0 1"/>    
    <limit effort="1" velocity="20" lower="-1.570796326794896558" upper="1.570796326794896558"/>    
    <joint_properties friction="0.0"/>    
  </joint>  


</robot>